File: polyN_optimization/AA7020-T6_results/DATA/UT_15_2.csv
Time[s],Displacement[mm],Force[kN],EngStrain_longi,EngStress[MPa],TrueStrain,TrueStress[MPa],TrueStrainRate[1/s],PlasticStrain_longi,PlasticStress[MPa],PlasticStrain_thick,PlasticStrain_width,R-Value,Thickness[mm],Width[mm], Young's Modulus [MPa]
0.64000000,0.00000000,-0.01000000,0.00000000,-0.98519644,0.00000000,-0.98519644,0.00000000,0.00064567,314.43371167,0.00041911,-0.00106478,0.70992185,1.01300000,10.02000000,77088.85378323
1.64000000,0.00175200,-0.01500000,0.00004067,-1.47779466,0.00004067,-1.47785475,0.00006578,0.00132045,317.63177979,0.00006843,-0.00138888,0.00000000,0.00000000,0.00000000,0.00000000
2.64000000,0.00618100,0.11300000,0.00016756,11.13271975,0.00016754,11.13458510,0.00017420,0.00199766,321.73128844,-0.00035074,-0.00164692,0.00000000,0.00000000,0.00000000,0.00000000
3.64000000,0.00952500,0.28500000,0.00026878,28.07809849,0.00026874,28.08564526,0.00017574,0.00271301,325.45049815,-0.00081535,-0.00189766,0.00000000,0.00000000,0.00000000,0.00000000
4.64000000,0.01432700,0.42500000,0.00042033,41.87084863,0.00042025,41.88844834,0.00007886,0.00345430,328.58535312,-0.00126833,-0.00218597,0.00000000,0.00000000,0.00000000,0.00000000
5.64000000,0.01976100,0.54800000,0.00057522,53.98876482,0.00057506,54.01982036,0.00026520,0.00410691,331.89503126,-0.00163371,-0.00247321,0.00000000,0.00000000,0.00000000,0.00000000
6.64000000,0.02327700,0.68500000,0.00065422,67.48595602,0.00065401,67.53010684,-0.00007595,0.00495948,334.97679179,-0.00216266,-0.00279683,0.00000000,0.00000000,0.00000000,0.00000000
7.64000000,0.03009600,0.82700000,0.00099033,81.47574545,0.00098984,81.55643360,0.00037411,0.00560880,337.89482119,-0.00251090,-0.00309790,0.00000000,0.00000000,0.00000000,0.00000000
8.64000000,0.03600400,0.99300000,0.00103578,97.83000632,0.00103524,97.93133647,0.00001954,0.00641585,340.67059563,-0.00302022,-0.00339563,0.00000000,0.00000000,0.00000000,0.00000000
9.64000000,0.04118800,1.15400000,0.00138433,113.69166898,0.00138338,113.84905615,0.00032291,0.00713833,343.32151084,-0.00338050,-0.00375784,0.00000000,0.00000000,0.00000000,0.00000000
10.64000000,0.04783700,1.30900000,0.00143289,128.96221378,0.00143186,129.14700230,0.00018330,0.00800839,345.72683360,-0.00397927,-0.00402912,0.00000000,0.00000000,0.00000000,0.00000000
11.64000000,0.05348800,1.44400000,0.00169756,142.26236569,0.00169612,142.50386396,0.00000821,0.00864462,348.35540912,-0.00426659,-0.00437804,0.00000000,0.00000000,0.00000000,0.00000000
12.64000000,0.05857000,1.59500000,0.00188811,157.13883191,0.00188633,157.43552749,0.00039929,0.00948597,350.85890598,-0.00478902,-0.00469695,0.00000000,0.00000000,0.00000000,0.00000000
13.64000000,0.06500600,1.72800000,0.00197233,170.24194454,0.00197039,170.57771840,-0.00012176,0.01024211,353.03481608,-0.00525254,-0.00498957,0.00000000,0.00000000,0.00000000,0.00000000
14.64000000,0.07084300,1.87800000,0.00232167,185.01989112,0.00231898,185.44944563,0.00038492,0.01102563,355.32429109,-0.00572490,-0.00530072,0.00000000,0.00000000,0.00000000,0.00000000
15.64000000,0.07598300,2.02800000,0.00234156,199.79783769,0.00233882,200.26567543,0.00002771,0.01173023,357.38762107,-0.00617418,-0.00555605,0.00000000,0.00000000,0.00000000,0.00000000
16.64000000,0.08245000,2.17600000,0.00265700,214.37874498,0.00265348,214.94834930,0.00016269,0.01258597,359.70987935,-0.00672263,-0.00586334,0.00000000,0.00000000,0.00000000,0.00000000
17.64000000,0.08844200,2.32400000,0.00282511,228.95965227,0.00282113,229.60648872,0.00034882,0.01329534,361.88192854,-0.00715680,-0.00613854,0.00000000,0.00000000,0.00000000,0.00000000
18.64000000,0.09333900,2.46900000,0.00299311,243.24500062,0.00298864,243.97305993,0.00005694,0.01404448,364.07155863,-0.00759837,-0.00644611,0.00000000,0.00000000,0.00000000,0.00000000
19.64000000,0.09971700,2.61300000,0.00324089,257.43182933,0.00323565,258.26613729,0.00034469,0.01482962,366.27764510,-0.00808431,-0.00674531,0.00000000,0.00000000,0.00000000,0.00000000
20.64000000,0.10608200,2.75600000,0.00338756,271.52013840,0.00338183,272.43992795,0.00015747,0.01560350,368.17972335,-0.00860372,-0.00699978,0.00000000,0.00000000,0.00000000,0.00000000
21.64000000,0.11227500,2.88200000,0.00363944,283.93361352,0.00363284,284.96697414,0.00028476,0.01633374,370.27068929,-0.00898770,-0.00734603,0.00000000,0.00000000,0.00000000,0.00000000
22.64000000,0.12202000,3.03300000,0.00389511,298.81007974,0.00388754,299.97397820,0.00025458,0.01710590,372.48155817,-0.00946163,-0.00764427,0.00000000,0.00000000,0.00000000,0.00000000
23.64000000,0.13985400,3.14300000,0.00442167,309.64724056,0.00441192,311.01639745,0.00062179,0.01790329,374.40129048,-0.00996400,-0.00793929,0.00000000,0.00000000,0.00000000,0.00000000
24.64000000,0.16374400,3.18800000,0.00522622,314.08062454,0.00521261,315.72207968,0.00063567,0.01862930,376.39834823,-0.01034730,-0.00828200,0.00000000,0.00000000,0.00000000,0.00000000
25.64000000,0.18651700,3.22200000,0.00606467,317.43029243,0.00604635,319.35540134,0.00086715,0.01939851,378.41464519,-0.01081887,-0.00857964,0.00000000,0.00000000,0.00000000,0.00000000
26.64000000,0.20834300,3.25700000,0.00668133,320.87847996,0.00665911,323.02237604,0.00062746,0.02015615,380.42951248,-0.01123645,-0.00891970,0.00000000,0.00000000,0.00000000,0.00000000
27.64000000,0.23131900,3.29100000,0.00752356,324.22814785,0.00749539,326.66749633,0.00076881,0.02092894,382.35149832,-0.01172608,-0.00920287,0.00000000,0.00000000,0.00000000,0.00000000
28.64000000,0.25514100,3.32300000,0.00831689,327.38077645,0.00828249,330.10356600,0.00077570,0.02165017,384.25640798,-0.01211848,-0.00953169,0.00000000,0.00000000,0.00000000,0.00000000
29.64000000,0.27896400,3.35300000,0.00909522,330.33636577,0.00905411,333.34084842,0.00092425,0.02244861,386.09212913,-0.01260367,-0.00984494,0.00000000,0.00000000,0.00000000,0.00000000
30.64000000,0.30265100,3.37700000,0.00983589,332.70083722,0.00978783,335.97324569,0.00060327,0.02316860,388.00192389,-0.01301273,-0.01015587,0.00000000,0.00000000,0.00000000,0.00000000
31.64000000,0.32637200,3.40600000,0.01070444,335.55790689,0.01064756,339.14986786,0.00094522,0.02392063,389.92692868,-0.01343378,-0.01048685,0.00000000,0.00000000,0.00000000,0.00000000
32.64000000,0.35053200,3.43100000,0.01152411,338.02089799,0.01145821,341.91628837,0.00087742,0.02469300,391.65860408,-0.01390419,-0.01078880,0.00000000,0.00000000,0.00000000,0.00000000
33.64000000,0.37526800,3.45200000,0.01222722,340.08981051,0.01215307,344.24816420,0.00075052,0.02543064,393.48120902,-0.01432395,-0.01110669,0.00000000,0.00000000,0.00000000,0.00000000
34.64000000,0.39932800,3.47500000,0.01312578,342.35576232,0.01304038,346.84944797,0.00072001,0.02621115,395.32341595,-0.01478452,-0.01142663,0.00000000,0.00000000,0.00000000,0.00000000
35.64000000,0.42382600,3.49700000,0.01394167,344.52319448,0.01384538,349.32642202,0.00098649,0.02692946,397.14351196,-0.01521929,-0.01171017,0.00000000,0.00000000,0.00000000,0.00000000
36.64000000,0.44805500,3.51800000,0.01472378,346.59210700,0.01461644,351.69525216,0.00077825,0.02770866,398.99053601,-0.01567803,-0.01203063,0.00000000,0.00000000,0.00000000,0.00000000
37.64000000,0.47275700,3.53900000,0.01550956,348.66101952,0.01539051,354.06859697,0.00075532,0.02842349,400.71188604,-0.01613252,-0.01229098,0.00000000,0.00000000,0.00000000,0.00000000
38.64000000,0.49708700,3.55900000,0.01638189,350.63141240,0.01624915,356.37541724,0.00084369,0.02918033,402.24747390,-0.01655741,-0.01262293,0.00000000,0.00000000,0.00000000,0.00000000
39.64000000,0.52107800,3.57900000,0.01711500,352.60180527,0.01697019,358.63658517,0.00082079,0.02989625,404.07647989,-0.01696049,-0.01293576,0.00000000,0.00000000,0.00000000,0.00000000
40.64000000,0.54534000,3.60100000,0.01797222,354.76923744,0.01781263,361.14522901,0.00073144,0.03068374,405.93720360,-0.01745772,-0.01322601,0.00000000,0.00000000,0.00000000,0.00000000
41.64000000,0.56973800,3.61800000,0.01878067,356.44407138,0.01860649,363.13832867,0.00084171,0.03137734,407.45384206,-0.01785158,-0.01352576,0.00000000,0.00000000,0.00000000,0.00000000
42.64000000,0.59396600,3.63600000,0.01962278,358.21742497,0.01943273,365.24664590,0.00093673,0.03215044,409.21088611,-0.01833552,-0.01381492,0.00000000,0.00000000,0.00000000,0.00000000
43.64000000,0.61805800,3.65500000,0.02034089,360.08929821,0.02013678,367.41383461,0.00071492,0.03285238,410.83813171,-0.01871281,-0.01413957,0.00000000,0.00000000,0.00000000,0.00000000
44.64000000,0.64218500,3.67300000,0.02120200,361.86265179,0.02098036,369.53486374,0.00080292,0.03365300,412.61150018,-0.01921353,-0.01443947,0.00000000,0.00000000,0.00000000,0.00000000
45.64000000,0.66634600,3.69100000,0.02199522,363.63600538,0.02175682,371.63426013,0.00083884,0.03433710,414.13275550,-0.01956918,-0.01476793,0.00000000,0.00000000,0.00000000,0.00000000
46.64000000,0.69070900,3.70800000,0.02278856,365.31083933,0.02253278,373.63574569,0.00078668,0.03512569,415.90603223,-0.02003982,-0.01508587,0.00000000,0.00000000,0.00000000,0.00000000
47.64000000,0.71483600,3.72300000,0.02358944,366.78863399,0.02331551,375.44097409,0.00070549,0.03586391,417.35094269,-0.02044543,-0.01541848,0.00000000,0.00000000,0.00000000,0.00000000
48.64000000,0.73886100,3.74100000,0.02445044,368.56198757,0.02415632,377.57349198,0.00088110,0.03659515,419.00159188,-0.02087147,-0.01572368,0.00000000,0.00000000,0.00000000,0.00000000
49.64000000,0.76288600,3.75900000,0.02520611,370.33534116,0.02489368,379.67005492,0.00076292,0.03731002,420.75101286,-0.02130021,-0.01600981,0.00000000,0.00000000,0.00000000,0.00000000
50.64000000,0.78684400,3.77400000,0.02603700,371.81313582,0.02570381,381.49403444,0.00081343,0.03811805,422.23182099,-0.02177422,-0.01634383,0.00000000,0.00000000,0.00000000,0.00000000
51.64000000,0.81066600,3.79000000,0.02681156,373.38945012,0.02645842,383.40060211,0.00072514,0.03881813,423.66880464,-0.02218570,-0.01663243,0.00000000,0.00000000,0.00000000,0.00000000
52.64000000,0.83482600,3.80600000,0.02764244,374.96576442,0.02726729,385.33073474,0.00084894,0.03952913,425.31967825,-0.02259191,-0.01693722,0.00000000,0.00000000,0.00000000,0.00000000
53.64000000,0.85912200,3.82200000,0.02840578,376.54207873,0.02800981,387.23804934,0.00068748,0.04029805,426.89386391,-0.02301315,-0.01728489,0.00000000,0.00000000,0.00000000,0.00000000
54.64000000,0.88304600,3.83800000,0.02919900,378.11839303,0.02878083,389.15907198,0.00073793,0.04109129,428.48077181,-0.02350453,-0.01758676,0.00000000,0.00000000,0.00000000,0.00000000
55.64000000,0.90693500,3.85300000,0.03004500,379.59618768,0.02960249,391.00115514,0.00082516,0.04177346,430.02195092,-0.02388331,-0.01789015,0.00000000,0.00000000,0.00000000,0.00000000
56.64000000,0.93123100,3.86700000,0.03080444,380.97546270,0.03033951,392.71120017,0.00070766,0.04254685,431.39667603,-0.02434449,-0.01820236,0.00000000,0.00000000,0.00000000,0.00000000
57.64000000,0.95505300,3.88100000,0.03161278,382.35473771,0.03112338,394.44203307,0.00075085,0.04330399,432.87034142,-0.02479584,-0.01850815,0.00000000,0.00000000,0.00000000,0.00000000
58.64000000,0.97911200,3.89800000,0.03241733,384.02957166,0.03190298,396.47878629,0.00069924,0.04400790,434.53113061,-0.02518657,-0.01882133,0.00000000,0.00000000,0.00000000,0.00000000
59.64000000,1.00310300,3.91100000,0.03323700,385.31032703,0.03269659,398.11688637,0.00080066,0.04477583,435.90944784,-0.02568228,-0.01909355,0.00000000,0.00000000,0.00000000,0.00000000
60.64000000,1.02685800,3.92600000,0.03401533,386.78812168,0.03344961,399.94484857,0.00069837,0.04550982,437.37908297,-0.02607455,-0.01943527,0.00000000,0.00000000,0.00000000,0.00000000
61.64000000,1.05105200,3.94000000,0.03483122,388.16739670,0.03423834,401.68774155,0.00079965,0.04626095,438.85825931,-0.02654404,-0.01971691,0.00000000,0.00000000,0.00000000,0.00000000
62.64000000,1.07477200,3.95400000,0.03562822,389.54667171,0.03500822,403.42552710,0.00078422,0.04698306,440.32662070,-0.02693670,-0.02004636,0.00000000,0.00000000,0.00000000,0.00000000
63.64000000,1.09869600,3.96800000,0.03640656,390.92594672,0.03575949,405.15821392,0.00080551,0.04775918,441.71635307,-0.02741599,-0.02034319,0.00000000,0.00000000,0.00000000,0.00000000
64.64000000,1.12238300,3.98200000,0.03718856,392.30522174,0.03651374,406.89448627,0.00068873,0.04848152,443.08405369,-0.02784029,-0.02064123,0.00000000,0.00000000,0.00000000,0.00000000
65.64000000,1.14640800,3.99400000,0.03800822,393.48745746,0.03730371,408.44321619,0.00084046,0.04921965,444.56535312,-0.02822653,-0.02099312,0.00000000,0.00000000,0.00000000,0.00000000
66.64000000,1.17077100,4.00800000,0.03879400,394.86673248,0.03806042,410.18519250,0.00076021,0.04996986,446.15890890,-0.02868102,-0.02128884,0.00000000,0.00000000,0.00000000,0.00000000
67.64000000,1.19503300,4.02200000,0.03954967,396.24600749,0.03878761,411.91740501,0.00076672,0.05076240,447.45899715,-0.02915107,-0.02161133,0.00000000,0.00000000,0.00000000,0.00000000
68.64000000,1.21861800,4.03400000,0.04043700,397.42824322,0.03964082,413.49904909,0.00082397,0.05146475,448.82518448,-0.02953883,-0.02192592,0.00000000,0.00000000,0.00000000,0.00000000
69.64000000,1.24271100,4.04700000,0.04117767,398.70899859,0.04035244,415.12690483,0.00083790,0.05221251,450.21368684,-0.02997802,-0.02223449,0.00000000,0.00000000,0.00000000,0.00000000
70.64000000,1.26687100,4.06000000,0.04195600,399.98975396,0.04109972,416.77172407,0.00070734,0.05296794,451.50239698,-0.03040001,-0.02256793,0.00000000,0.00000000,0.00000000,0.00000000
71.64000000,1.29099800,4.07300000,0.04275300,401.27050933,0.04186433,418.42602741,0.00072108,0.05371437,452.89397995,-0.03088437,-0.02283000,0.00000000,0.00000000,0.00000000,0.00000000
72.64000000,1.31495500,4.08500000,0.04359900,402.45274505,0.04267532,419.99928228,0.00083596,0.05443708,454.17127924,-0.03125266,-0.02318442,0.00000000,0.00000000,0.00000000,0.00000000
73.64000000,1.33887800,4.09800000,0.04434344,403.73350042,0.04338841,421.63643447,0.00078512,0.05519069,455.46439375,-0.03171982,-0.02347087,0.00000000,0.00000000,0.00000000,0.00000000
74.64000000,1.36270000,4.10800000,0.04514800,404.71869686,0.04415850,422.99093659,0.00066924,0.05595286,456.86866095,-0.03216751,-0.02378535,0.00000000,0.00000000,0.00000000,0.00000000
75.64000000,1.38689400,4.12000000,0.04596011,405.90093259,0.04493523,424.55618455,0.00078370,0.05669687,458.26648460,-0.03259681,-0.02410006,0.00000000,0.00000000,0.00000000,0.00000000
76.64000000,1.41102100,4.13400000,0.04675344,407.28020760,0.04569342,426.32196016,0.00083344,0.05742913,459.44945261,-0.03302479,-0.02440434,0.00000000,0.00000000,0.00000000,0.00000000
77.64000000,1.43575600,4.14500000,0.04755800,408.36392368,0.04646174,427.78489517,0.00078972,0.05820484,460.75982109,-0.03350771,-0.02469714,0.00000000,0.00000000,0.00000000,0.00000000
78.64000000,1.45964600,4.15700000,0.04838522,409.54615941,0.04725110,429.36214134,0.00073905,0.05891349,462.04080977,-0.03391685,-0.02499664,0.00000000,0.00000000,0.00000000,0.00000000
79.64000000,1.48397600,4.16800000,0.04917844,410.62987549,0.04800742,430.82401401,0.00084571,0.05967752,463.34924712,-0.03435844,-0.02531908,0.00000000,0.00000000,0.00000000,0.00000000
80.64000000,1.50786500,4.17900000,0.04992667,411.71359157,0.04872032,432.26907882,0.00068757,0.06045135,464.66404259,-0.03482974,-0.02562161,0.00000000,0.00000000,0.00000000,0.00000000
81.64000000,1.53222900,4.19100000,0.05073511,412.89582730,0.04949003,433.84414297,0.00067287,0.06118065,465.85369592,-0.03525979,-0.02592086,0.00000000,0.00000000,0.00000000,0.00000000
82.64000000,1.55632100,4.20200000,0.05158856,413.97954338,0.05030193,435.33615005,0.00084398,0.06188494,467.03311797,-0.03565213,-0.02623281,0.00000000,0.00000000,0.00000000,0.00000000
83.64000000,1.58044800,4.21200000,0.05235178,414.96473982,0.05102745,436.68888166,0.00072190,0.06268485,468.36529961,-0.03614072,-0.02654414,0.00000000,0.00000000,0.00000000,0.00000000
84.64000000,1.60447300,4.22300000,0.05316756,416.04845590,0.05180234,438.16873529,0.00076398,0.06341580,469.56044810,-0.03655271,-0.02686309,0.00000000,0.00000000,0.00000000,0.00000000
85.64000000,1.62934400,4.23500000,0.05399100,417.23069163,0.05258391,439.75739390,0.00078490,0.06415534,470.86759755,-0.03698681,-0.02716854,0.00000000,0.00000000,0.00000000,0.00000000
86.64000000,1.65333500,4.24400000,0.05478056,418.11736842,0.05333274,441.02207015,0.00079864,0.06492284,471.87031553,-0.03744032,-0.02748252,0.00000000,0.00000000,0.00000000,0.00000000
87.64000000,1.67739400,4.25400000,0.05556256,419.10256486,0.05407385,442.38897440,0.00069106,0.06567844,473.18834752,-0.03787704,-0.02780140,0.00000000,0.00000000,0.00000000,0.00000000
88.64000000,1.70141900,4.26400000,0.05640100,420.08776130,0.05486785,443.78113112,0.00079742,0.06640149,474.27931449,-0.03830274,-0.02809875,0.00000000,0.00000000,0.00000000,0.00000000
89.64000000,1.72578200,4.27500000,0.05720933,421.17147738,0.05563273,445.26641682,0.00081089,0.06717127,475.50072942,-0.03873919,-0.02843208,0.00000000,0.00000000,0.00000000,0.00000000
90.64000000,1.75014600,4.28500000,0.05802144,422.15667382,0.05640060,446.65081382,0.00080313,0.06794174,476.61730153,-0.03919721,-0.02874452,0.00000000,0.00000000,0.00000000,0.00000000
91.64000000,1.77457600,4.29500000,0.05881100,423.14187026,0.05714658,448.02726679,0.00067487,0.06869151,477.93918579,-0.03965979,-0.02903171,0.00000000,0.00000000,0.00000000,0.00000000
92.64000000,1.79914300,4.30500000,0.05964567,424.12706670,0.05793458,449.42440834,0.00080924,0.06936382,479.01152351,-0.04000313,-0.02936069,0.00000000,0.00000000,0.00000000,0.00000000
93.64000000,1.82313400,4.31400000,0.06042767,425.01374349,0.05867229,450.69633231,0.00075162,0.07018995,480.26651025,-0.04054127,-0.02964868,0.00000000,0.00000000,0.00000000,0.00000000
94.64000000,1.84753200,4.32400000,0.06125489,425.99893993,0.05945207,452.09345766,0.00076549,0.07093720,481.37790929,-0.04096120,-0.02997599,0.00000000,0.00000000,0.00000000,0.00000000
95.64000000,1.87165800,4.33500000,0.06206322,427.08265601,0.06021345,453.58878180,0.00075779,0.07166323,482.48042932,-0.04139352,-0.03026971,0.00000000,0.00000000,0.00000000,0.00000000
96.64000000,1.89608900,4.34300000,0.06286033,427.87081316,0.06096370,454.76691510,0.00077835,0.07240237,483.59070763,-0.04180134,-0.03060103,0.00000000,0.00000000,0.00000000,0.00000000
97.64000000,1.92068900,4.35300000,0.06365733,428.85600960,0.06171328,456.15583955,0.00073533,0.07319819,484.83745428,-0.04227295,-0.03092524,0.00000000,0.00000000,0.00000000,0.00000000
98.64000000,1.94515400,4.36200000,0.06451456,429.74268639,0.06251888,457.46734481,0.00078424,0.07393276,485.94846345,-0.04268046,-0.03125230,0.00000000,0.00000000,0.00000000,0.00000000
99.64000000,1.96951700,4.37100000,0.06532667,430.62936319,0.06328148,458.76094405,0.00078364,0.07471152,487.08254644,-0.04316226,-0.03154926,0.00000000,0.00000000,0.00000000,0.00000000
100.64000000,1.99405000,4.38000000,0.06612378,431.51603998,0.06402943,460.04951072,0.00078305,0.07548964,488.21781697,-0.04361402,-0.03187562,0.00000000,0.00000000,0.00000000,0.00000000
101.64000000,2.01871800,4.38900000,0.06691333,432.40271678,0.06476974,461.33622390,0.00067683,0.07625139,489.23878594,-0.04404550,-0.03220589,0.00000000,0.00000000,0.00000000,0.00000000
102.64000000,2.04308100,4.39700000,0.06779678,433.19087393,0.06559744,462.55981934,0.00088030,0.07695606,490.34070300,-0.04444058,-0.03251547,0.00000000,0.00000000,0.00000000,0.00000000
103.64000000,2.06791800,4.40700000,0.06854500,434.17607037,0.06629791,463.93666911,0.00071782,0.07773721,491.37389715,-0.04491615,-0.03282106,0.00000000,0.00000000,0.00000000,0.00000000
104.64000000,2.09245100,4.41600000,0.06934967,435.06274716,0.06705068,465.23420366,0.00064016,0.07849560,492.50513992,-0.04532587,-0.03316973,0.00000000,0.00000000,0.00000000,0.00000000
105.64000000,2.11671200,4.42300000,0.07021433,435.75238467,0.06785894,466.34844786,0.00076593,0.07923980,493.63079963,-0.04575625,-0.03348355,0.00000000,0.00000000,0.00000000,0.00000000
106.64000000,2.14131300,4.43300000,0.07102267,436.73758111,0.06861396,467.75584875,0.00083551,0.07999164,494.65353776,-0.04620146,-0.03379018,0.00000000,0.00000000,0.00000000,0.00000000
107.64000000,2.16615000,4.44000000,0.07179344,437.42721861,0.06933336,468.83162533,0.00063849,0.08081134,495.71142677,-0.04670883,-0.03410251,0.00000000,0.00000000,0.00000000,0.00000000
108.64000000,2.19088500,4.44800000,0.07266578,438.21537576,0.07014693,470.05863688,0.00077144,0.08155017,496.83863960,-0.04713204,-0.03441813,0.00000000,0.00000000,0.00000000,0.00000000
109.64000000,2.21572200,4.45700000,0.07348533,439.10205256,0.07091068,471.36961326,0.00078451,0.08228654,497.85762621,-0.04755640,-0.03473013,0.00000000,0.00000000,0.00000000,0.00000000
110.64000000,2.24045800,4.46500000,0.07429000,439.89020971,0.07165998,472.56965339,0.00072102,0.08305300,498.89298612,-0.04800921,-0.03504379,0.00000000,0.00000000,0.00000000,0.00000000
111.64000000,2.26556600,4.47300000,0.07512089,440.67836686,0.07243311,473.78251749,0.00072046,0.08382902,499.93447951,-0.04847231,-0.03535671,0.00000000,0.00000000,0.00000000,0.00000000
112.64000000,2.29104600,4.48100000,0.07598556,441.46652401,0.07323704,475.01160310,0.00085273,0.08456215,501.06436129,-0.04887559,-0.03568656,0.00000000,0.00000000,0.00000000,0.00000000
113.64000000,2.31568000,4.48800000,0.07677144,442.15616152,0.07396716,476.10112871,0.00074042,0.08537593,502.01890520,-0.04938720,-0.03598873,0.00000000,0.00000000,0.00000000,0.00000000
114.64000000,2.34044900,4.49600000,0.07760611,442.94431867,0.07474202,477.31950468,0.00071901,0.08612631,503.05144262,-0.04981797,-0.03630835,0.00000000,0.00000000,0.00000000,0.00000000
115.64000000,2.36555700,4.50400000,0.07848211,443.73247582,0.07555460,478.55753729,0.00080891,0.08687756,503.97677533,-0.05026223,-0.03661533,0.00000000,0.00000000,0.00000000,0.00000000
116.64000000,2.39069900,4.51100000,0.07928300,444.42211333,0.07629693,479.65723174,0.00091996,0.08759623,504.99569189,-0.05065605,-0.03694017,0.00000000,0.00000000,0.00000000,0.00000000
117.64000000,2.41536600,4.51900000,0.08008378,445.21027048,0.07703861,480.86439084,0.00071715,0.08840059,505.95039303,-0.05114757,-0.03725302,0.00000000,0.00000000,0.00000000,0.00000000
118.64000000,2.44077900,4.52700000,0.08095600,445.99842763,0.07784583,482.10467633,0.00080706,0.08915528,506.99017453,-0.05158794,-0.03756735,0.00000000,0.00000000,0.00000000,0.00000000
119.64000000,2.46568300,4.53300000,0.08179067,446.58954549,0.07861769,483.11640214,0.00086891,0.08993128,507.93287660,-0.05203789,-0.03789339,0.00000000,0.00000000,0.00000000,0.00000000
120.64000000,2.49069000,4.54100000,0.08257644,447.37770264,0.07934380,484.32056265,0.00081284,0.09068963,508.86771592,-0.05248728,-0.03820234,0.00000000,0.00000000,0.00000000,0.00000000
121.64000000,2.51586500,4.54800000,0.08342244,448.06734015,0.08012496,485.44621294,0.00074982,0.09145417,509.80688344,-0.05293076,-0.03852341,0.00000000,0.00000000,0.00000000,0.00000000
122.64000000,2.54144700,4.55500000,0.08429467,448.75697765,0.08092970,486.58479750,0.00086014,0.09220461,510.73995724,-0.05334195,-0.03886266,0.00000000,0.00000000,0.00000000,0.00000000
123.64000000,2.56638500,4.56200000,0.08512189,449.44661516,0.08169232,487.70436000,0.00079720,0.09298141,511.68775206,-0.05381823,-0.03916318,0.00000000,0.00000000,0.00000000,0.00000000
124.64000000,2.59159500,4.56900000,0.08592267,450.13625267,0.08243001,488.81315986,0.00068566,0.09374943,512.74191037,-0.05426105,-0.03948838,0.00000000,0.00000000,0.00000000,0.00000000
125.64000000,2.61680400,4.57500000,0.08679122,450.72737053,0.08322952,489.84654991,0.00073359,0.09453514,513.69676617,-0.05474561,-0.03978953,0.00000000,0.00000000,0.00000000,0.00000000
126.64000000,2.64241900,4.58200000,0.08762956,451.41700804,0.08400061,490.97447982,0.00083665,0.09527637,514.62977776,-0.05515190,-0.04012447,0.00000000,0.00000000,0.00000000,0.00000000
127.64000000,2.66722300,4.58900000,0.08843800,452.10664554,0.08474364,492.09005306,0.00073248,0.09602707,515.56883124,-0.05561232,-0.04041475,0.00000000,0.00000000,0.00000000,0.00000000
128.64000000,2.69222900,4.59600000,0.08928011,452.79628305,0.08551703,493.22198551,0.00073191,0.09681090,516.52625584,-0.05605727,-0.04075363,0.00000000,0.00000000,0.00000000,0.00000000
129.64000000,2.71777700,4.60200000,0.09016744,453.38740091,0.08633130,494.26818420,0.00084164,0.09761098,517.49335495,-0.05654356,-0.04106742,0.00000000,0.00000000,0.00000000,0.00000000
130.64000000,2.74352700,4.60800000,0.09100589,453.97851878,0.08710010,495.29323741,0.00084792,0.09840353,518.45776596,-0.05697660,-0.04142692,0.00000000,0.00000000,0.00000000,0.00000000
131.64000000,2.76934600,4.61400000,0.09182922,454.56963664,0.08785448,496.31241282,0.00068867,0.09916337,519.29596089,-0.05741321,-0.04175016,0.00000000,0.00000000,0.00000000,0.00000000
132.64000000,2.79458900,4.62000000,0.09269022,455.16075450,0.08864275,497.34970598,0.00075709,0.09993787,520.25325016,-0.05790086,-0.04203701,0.00000000,0.00000000,0.00000000,0.00000000
133.64000000,2.81979800,4.62600000,0.09355500,455.75187237,0.08943386,498.38973879,0.00083903,0.10071660,521.10344126,-0.05831194,-0.04240466,0.00000000,0.00000000,0.00000000,0.00000000
134.64000000,2.84544800,4.63200000,0.09435211,456.34299023,0.09016251,499.39991475,0.00073543,0.10149657,522.06591089,-0.05877723,-0.04271934,0.00000000,0.00000000,0.00000000,0.00000000
135.64000000,2.87096100,4.63800000,0.09523933,456.93410809,0.09097291,500.45220792,0.00077603,0.10231082,522.93695222,-0.05929887,-0.04301195,0.00000000,0.00000000,0.00000000,0.00000000
136.64000000,2.89708400,4.64400000,0.09611533,457.52522595,0.09177241,501.50041556,0.00087824,0.10309098,523.79110033,-0.05973243,-0.04335855,0.00000000,0.00000000,0.00000000,0.00000000
137.64000000,2.92242900,4.65000000,0.09693133,458.11634382,0.09251658,502.52217185,0.00071323,0.10386901,524.75602579,-0.06019676,-0.04367225,0.00000000,0.00000000,0.00000000,0.00000000
138.64000000,2.94828200,4.65500000,0.09776222,458.60894204,0.09327376,503.44357134,0.00069892,0.10463122,525.60282745,-0.06060082,-0.04403040,0.00000000,0.00000000,0.00000000,0.00000000
139.64000000,2.97393100,4.66000000,0.09861567,459.10154026,0.09405090,504.37614472,0.00072569,0.10540800,526.56939757,-0.06110011,-0.04430788,0.00000000,0.00000000,0.00000000,0.00000000
140.64000000,2.99917400,4.66600000,0.09948033,459.69265812,0.09483764,505.42303698,0.00083431,0.10621371,527.33028238,-0.06155851,-0.04465520,0.00000000,0.00000000,0.00000000,0.00000000
141.64000000,3.02499200,4.67200000,0.10031878,460.28377598,0.09559994,506.45888182,0.00072437,0.10697740,528.18093556,-0.06201356,-0.04496384,0.00000000,0.00000000,0.00000000,0.00000000
142.64000000,3.05118300,4.67800000,0.10119111,460.87489385,0.09639242,507.51133644,0.00077184,0.10781689,529.07298927,-0.06254343,-0.04527347,0.00000000,0.00000000,0.00000000,0.00000000
143.64000000,3.07733900,4.68300000,0.10207089,461.36749206,0.09719104,508.45968208,0.00079160,0.10857412,529.81087162,-0.06292843,-0.04564570,0.00000000,0.00000000,0.00000000,0.00000000
144.64000000,3.10346300,4.68800000,0.10289422,461.86009028,0.09793784,509.38282505,0.00074323,0.10934769,530.78130325,-0.06340565,-0.04594204,0.00000000,0.00000000,0.00000000,0.00000000
145.64000000,3.12901100,4.69400000,0.10374022,462.45120815,0.09870461,510.42599925,0.00072232,0.11012546,531.64360968,-0.06387011,-0.04625536,0.00000000,0.00000000,0.00000000,0.00000000
146.64000000,3.15462600,4.69800000,0.10459744,462.84528672,0.09948096,511.25772089,0.00074893,0.11094723,532.41887479,-0.06436236,-0.04658488,0.00000000,0.00000000,0.00000000,0.00000000
147.64000000,3.18102000,4.70400000,0.10549233,463.43640458,0.10029079,512.32539226,0.00078935,0.11169384,533.26646588,-0.06480985,-0.04688399,0.00000000,0.00000000,0.00000000,0.00000000
148.64000000,3.20653300,4.70900000,0.10631189,463.92900280,0.10103186,513.25017140,0.00070698,0.11247776,534.02327001,-0.06524716,-0.04723060,0.00000000,0.00000000,0.00000000,0.00000000
149.64000000,3.23275800,4.71400000,0.10720678,464.42160102,0.10184043,514.21074440,0.00072689,0.11329603,534.91138977,-0.06575974,-0.04753629,0.00000000,0.00000000,0.00000000,0.00000000
150.64000000,3.25867800,4.71900000,0.10807900,464.91419924,0.10262789,515.16166098,0.00079412,0.11408379,535.78416480,-0.06624002,-0.04784377,0.00000000,0.00000000,0.00000000,0.00000000
151.64000000,3.28476700,4.72400000,0.10897000,465.40679746,0.10343166,516.12217618,0.00087488,0.11491054,536.67907712,-0.06671489,-0.04819565,0.00000000,0.00000000,0.00000000,0.00000000
152.64000000,3.31082200,4.72800000,0.10980100,465.80087604,0.10418072,516.94627803,0.00077947,0.11569345,537.32693496,-0.06717576,-0.04851769,0.00000000,0.00000000,0.00000000,0.00000000
153.64000000,3.33735100,4.73200000,0.11070333,466.19495461,0.10499345,517.80429007,0.00077864,0.11646268,538.19269789,-0.06762805,-0.04883463,0.00000000,0.00000000,0.00000000,0.00000000
154.64000000,3.36357600,4.73800000,0.11158311,466.78607247,0.10578523,518.87151467,0.00075102,0.11723952,538.95122194,-0.06810754,-0.04913198,0.00000000,0.00000000,0.00000000,0.00000000
155.64000000,3.39024000,4.74300000,0.11246289,467.27867069,0.10657638,519.83017992,0.00079099,0.11801091,539.82014549,-0.06854274,-0.04946818,0.00000000,0.00000000,0.00000000,0.00000000
156.64000000,3.41649900,4.74600000,0.11335400,467.57422963,0.10737708,520.57563885,0.00081752,0.11878640,540.57975677,-0.06898475,-0.04980165,0.00000000,0.00000000,0.00000000,0.00000000
157.64000000,3.44289200,4.75100000,0.11426389,468.06682784,0.10819400,521.54996385,0.00087092,0.11962053,541.37221356,-0.06950065,-0.05011988,0.00000000,0.00000000,0.00000000,0.00000000
158.64000000,3.46891400,4.75500000,0.11515111,468.46090642,0.10898992,522.40470031,0.00087680,0.12042612,542.26281542,-0.06992916,-0.05049697,0.00000000,0.00000000,0.00000000,0.00000000
159.64000000,3.49544300,4.75900000,0.11601211,468.85498500,0.10976172,523.24784161,0.00076836,0.12119647,543.02237479,-0.07041582,-0.05078065,0.00000000,0.00000000,0.00000000,0.00000000
160.64000000,3.52207300,4.76400000,0.11689567,469.34758321,0.11055311,524.21228185,0.00076775,0.12201685,543.69725023,-0.07090979,-0.05110706,0.00000000,0.00000000,0.00000000,0.00000000
161.64000000,3.54883900,4.76900000,0.11778300,469.84018143,0.11134726,525.17936752,0.00077390,0.12275639,544.44158838,-0.07132040,-0.05143599,0.00000000,0.00000000,0.00000000,0.00000000
162.64000000,3.57553700,4.77300000,0.11865144,470.23426001,0.11212389,526.02823419,0.00077986,0.12358229,545.34731016,-0.07183210,-0.05175019,0.00000000,0.00000000,0.00000000,0.00000000
163.64000000,3.60206600,4.77700000,0.11960267,470.62833858,0.11297386,526.91674289,0.00090012,0.12434025,546.10356889,-0.07224899,-0.05209126,0.00000000,0.00000000,0.00000000,0.00000000
164.64000000,3.62866200,4.78100000,0.12045611,471.02241716,0.11373584,527.75994578,0.00079210,0.12517768,546.79113000,-0.07275528,-0.05242240,0.00000000,0.00000000,0.00000000,0.00000000
165.64000000,3.65536000,4.78500000,0.12132467,471.41649574,0.11451072,528.61094494,0.00079148,0.12596055,547.56279399,-0.07318963,-0.05277092,0.00000000,0.00000000,0.00000000,0.00000000
166.64000000,3.68243100,4.78900000,0.12226456,471.81057431,0.11534857,529.49628448,0.00076408,0.12674430,548.22232974,-0.07366058,-0.05308372,0.00000000,0.00000000,0.00000000,0.00000000
167.64000000,3.70929800,4.79400000,0.12313311,472.30317253,0.11612220,530.45933155,0.00077695,0.12752908,548.99673457,-0.07410860,-0.05342048,0.00000000,0.00000000,0.00000000,0.00000000
168.64000000,3.73606400,4.79700000,0.12405044,472.59873146,0.11693863,531.22481414,0.00083644,0.12837196,549.80420968,-0.07462684,-0.05374512,0.00000000,0.00000000,0.00000000,0.00000000
169.64000000,3.76323600,4.80100000,0.12493778,472.99281004,0.11772773,532.08748063,0.00083578,0.12918485,550.59603974,-0.07511316,-0.05407169,0.00000000,0.00000000,0.00000000,0.00000000
170.64000000,3.78983200,4.80400000,0.12586644,473.28836897,0.11855291,532.85949317,0.00082166,0.12995946,551.25366354,-0.07550928,-0.05445018,0.00000000,0.00000000,0.00000000,0.00000000
171.64000000,3.81659800,4.80800000,0.12672744,473.68244754,0.11931736,533.71101360,0.00083445,0.13076439,552.04281708,-0.07597787,-0.05478653,0.00000000,0.00000000,0.00000000,0.00000000
172.64000000,3.84363400,4.81200000,0.12760722,474.07652612,0.12009789,534.57211474,0.00080718,0.13153458,552.69948144,-0.07642058,-0.05511399,0.00000000,0.00000000,0.00000000,0.00000000
173.64000000,3.87087300,4.81600000,0.12852456,474.47060469,0.12091108,535.45172829,0.00077304,0.13238365,553.51498407,-0.07692730,-0.05545635,0.00000000,0.00000000,0.00000000,0.00000000
174.64000000,3.89862100,4.82000000,0.12945322,474.86468327,0.12173364,536.33744664,0.00081905,0.13318167,554.18872324,-0.07738299,-0.05579868,0.00000000,0.00000000,0.00000000,0.00000000
175.64000000,3.92555600,4.82200000,0.13034056,475.06172256,0.12251896,536.98153140,0.00071201,0.13397751,554.97632048,-0.07785815,-0.05611936,0.00000000,0.00000000,0.00000000,0.00000000
176.64000000,3.95296400,4.82500000,0.13128800,475.35728149,0.12335681,537.76598826,0.00080436,0.13478397,555.65634527,-0.07831158,-0.05647239,0.00000000,0.00000000,0.00000000,0.00000000
177.64000000,3.98010200,4.82800000,0.13215278,475.65284042,0.12412093,538.51168454,0.00077076,0.13558643,556.33486545,-0.07879022,-0.05679620,0.00000000,0.00000000,0.00000000,0.00000000
178.64000000,4.00737600,4.83200000,0.13305133,476.04691900,0.12491429,539.38559630,0.00078329,0.13638191,557.01021728,-0.07927274,-0.05710917,0.00000000,0.00000000,0.00000000,0.00000000
179.64000000,4.03441200,4.83500000,0.13397244,476.34247793,0.12572691,540.15924409,0.00084225,0.13722827,557.71488807,-0.07975485,-0.05747343,0.00000000,0.00000000,0.00000000,0.00000000
180.64000000,4.06212500,4.83900000,0.13488989,476.73655650,0.12653563,541.04349764,0.00088819,0.13803195,558.39634759,-0.08025516,-0.05777679,0.00000000,0.00000000,0.00000000,0.00000000
181.64000000,4.08936500,4.84200000,0.13576589,477.03211543,0.12730722,541.79680461,0.00074168,0.13883675,559.19410704,-0.08069170,-0.05814505,0.00000000,0.00000000,0.00000000,0.00000000
182.64000000,4.11714600,4.84500000,0.13670578,477.32767436,0.12813441,542.58112534,0.00076082,0.13965518,559.88547485,-0.08113151,-0.05852368,0.00000000,0.00000000,0.00000000,0.00000000
183.64000000,4.14458800,4.84800000,0.13758933,477.62323330,0.12891140,543.33909555,0.00075359,0.14046978,560.57544786,-0.08158883,-0.05888096,0.00000000,0.00000000,0.00000000,0.00000000
184.64000000,4.17216600,4.85100000,0.13851800,477.91879223,0.12972742,544.11914749,0.00072661,0.14130453,561.16236957,-0.08208773,-0.05921681,0.00000000,0.00000000,0.00000000,0.00000000
185.64000000,4.19933800,4.85400000,0.13945422,478.21435116,0.13054940,544.90336156,0.00087137,0.14210339,561.96017852,-0.08256625,-0.05953714,0.00000000,0.00000000,0.00000000,0.00000000
186.64000000,4.22742300,4.85700000,0.14036400,478.50991009,0.13134751,545.67547511,0.00079133,0.14293665,562.54762061,-0.08304416,-0.05989249,0.00000000,0.00000000,0.00000000,0.00000000
187.64000000,4.25490000,4.86000000,0.14127389,478.80546902,0.13214508,546.44817965,0.00085011,0.14373570,563.23174894,-0.08351842,-0.06021729,0.00000000,0.00000000,0.00000000,0.00000000
188.64000000,4.28285000,4.86200000,0.14222889,479.00250831,0.13298152,547.13050284,0.00082954,0.14459812,563.95262571,-0.08401537,-0.06058275,0.00000000,0.00000000,0.00000000,0.00000000
189.64000000,4.31029200,4.86500000,0.14310489,479.29806724,0.13374815,547.88796390,0.00077620,0.14536374,564.61925947,-0.08445009,-0.06091365,0.00000000,0.00000000,0.00000000,0.00000000
190.64000000,4.33814100,4.86800000,0.14402611,479.59362617,0.13455372,548.66763106,0.00080201,0.14622635,565.22606125,-0.08496985,-0.06125650,0.00000000,0.00000000,0.00000000,0.00000000
191.64000000,4.36578700,4.87100000,0.14492467,479.88918510,0.13533884,549.43696529,0.00078177,0.14705464,565.92980841,-0.08541741,-0.06163722,0.00000000,0.00000000,0.00000000,0.00000000
192.64000000,4.39400800,4.87300000,0.14590222,480.08622439,0.13619229,550.13187139,0.00078110,0.14788212,566.63388692,-0.08591059,-0.06197153,0.00000000,0.00000000,0.00000000,0.00000000
193.64000000,4.42219500,4.87600000,0.14679700,480.38178332,0.13697284,550.90038797,0.00069500,0.14870899,567.33840452,-0.08637093,-0.06233806,0.00000000,0.00000000,0.00000000,0.00000000
194.64000000,4.44987400,4.87900000,0.14774456,480.67734226,0.13779876,551.69480255,0.00077985,0.14950487,567.90978944,-0.08681418,-0.06269069,0.00000000,0.00000000,0.00000000,0.00000000
195.64000000,4.47816300,4.88100000,0.14866944,480.87438154,0.13860427,552.36570869,0.00075967,0.15036218,568.63320721,-0.08732885,-0.06303333,0.00000000,0.00000000,0.00000000,0.00000000
196.64000000,4.50624800,4.88300000,0.14963189,481.07142083,0.13944179,553.05504622,0.00087661,0.15122030,569.24153677,-0.08782617,-0.06339413,0.00000000,0.00000000,0.00000000,0.00000000
197.64000000,4.53477300,4.88600000,0.15056811,481.36697976,0.14025583,553.84549666,0.00078450,0.15204434,569.94741009,-0.08829609,-0.06374825,0.00000000,0.00000000,0.00000000,0.00000000
198.64000000,4.56323100,4.88800000,0.15153433,481.56401905,0.14109526,554.53750163,0.00084910,0.15286924,570.53798780,-0.08879667,-0.06407257,0.00000000,0.00000000,0.00000000,0.00000000
199.64000000,4.59219700,4.89100000,0.15247056,481.85957798,0.14190795,555.32897554,0.00086152,0.15372515,571.14701002,-0.08927134,-0.06445381,0.00000000,0.00000000,0.00000000,0.00000000
200.64000000,4.62068800,4.89300000,0.15336167,482.05661727,0.14268087,555.98562352,0.00077605,0.15454707,571.85385383,-0.08976003,-0.06478704,0.00000000,0.00000000,0.00000000,0.00000000
201.64000000,4.64914600,4.89500000,0.15431667,482.25365656,0.14350854,556.67343332,0.00080814,0.15540152,572.46337239,-0.09026826,-0.06513326,0.00000000,0.00000000,0.00000000,0.00000000
202.64000000,4.67746800,4.89700000,0.15524522,482.45069584,0.14431264,557.34886133,0.00080711,0.15628537,573.20749262,-0.09077861,-0.06550676,0.00000000,0.00000000,0.00000000,0.00000000
203.64000000,4.70616200,4.89900000,0.15627922,482.64773513,0.14520728,558.07554779,0.00088464,0.15710670,573.79924083,-0.09124043,-0.06586626,0.00000000,0.00000000,0.00000000,0.00000000
204.64000000,4.73478900,4.90200000,0.15715522,482.94329406,0.14596460,558.84035476,0.00077350,0.15799048,574.42773726,-0.09174842,-0.06624206,0.00000000,0.00000000,0.00000000,0.00000000
205.64000000,4.76368700,4.90400000,0.15814778,483.14033335,0.14682199,559.54790343,0.00085711,0.15884192,575.03815961,-0.09224992,-0.06659200,0.00000000,0.00000000,0.00000000,0.00000000
206.64000000,4.79319400,4.90600000,0.15909533,483.33737264,0.14763982,560.23409305,0.00083723,0.15972423,575.66712128,-0.09275402,-0.06697021,0.00000000,0.00000000,0.00000000,0.00000000
207.64000000,4.82144900,4.90800000,0.16005400,483.53441193,0.14846656,560.92602869,0.00084286,0.16054267,576.25965847,-0.09321779,-0.06732488,0.00000000,0.00000000,0.00000000,0.00000000
208.64000000,4.85095500,4.90900000,0.16099400,483.63293157,0.14927653,561.49493176,0.00077745,0.16148479,577.04230488,-0.09379860,-0.06768619,0.00000000,0.00000000,0.00000000,0.00000000
209.64000000,4.88012300,4.91100000,0.16197156,483.82997086,0.15011818,562.19666386,0.00084147,0.16230176,577.63533843,-0.09427840,-0.06802336,0.00000000,0.00000000,0.00000000,0.00000000
210.64000000,4.90898700,4.91300000,0.16291144,484.02701015,0.15092673,562.88054952,0.00077617,0.16318253,578.14833404,-0.09477469,-0.06840783,0.00000000,0.00000000,0.00000000,0.00000000
211.64000000,4.93862900,4.91500000,0.16388900,484.22404943,0.15176698,563.58304467,0.00084008,0.16405925,578.89526714,-0.09526452,-0.06879473,0.00000000,0.00000000,0.00000000,0.00000000
212.64000000,4.96779700,4.91700000,0.16490411,484.42108872,0.15263878,564.30411776,0.00083935,0.16493686,579.52556972,-0.09577645,-0.06916042,0.00000000,0.00000000,0.00000000,0.00000000
213.64000000,4.99720300,4.91900000,0.16580644,484.61812801,0.15341307,564.97093673,0.00083870,0.16584659,580.05718760,-0.09630061,-0.06954598,0.00000000,0.00000000,0.00000000,0.00000000
214.64000000,5.02647200,4.92000000,0.16678400,484.71664765,0.15425125,565.55962901,0.00077341,0.16668963,580.78674301,-0.09678251,-0.06990712,0.00000000,0.00000000,0.00000000,0.00000000
215.64000000,5.05560700,4.92200000,0.16776156,484.91368694,0.15508872,566.26356137,0.00077276,0.16759774,581.31857573,-0.09732173,-0.07027600,0.00000000,0.00000000,0.00000000,0.00000000
216.64000000,5.08552000,4.92400000,0.16881433,485.11072623,0.15598984,567.00437007,0.00090102,0.16844085,581.93123162,-0.09778647,-0.07065438,0.00000000,0.00000000,0.00000000,0.00000000
217.64000000,5.11526300,4.92500000,0.16975422,485.20924587,0.15679366,567.57556402,0.00083587,0.16937864,582.48154817,-0.09834704,-0.07103160,0.00000000,0.00000000,0.00000000,0.00000000
218.64000000,5.14541300,4.92700000,0.17076933,485.40628516,0.15766108,568.29879287,0.00096351,0.17025141,583.11284112,-0.09887147,-0.07137993,0.00000000,0.00000000,0.00000000,0.00000000
219.64000000,5.17505500,4.92900000,0.17174689,485.60332445,0.15849570,569.00418465,0.00089858,0.17115463,583.76272531,-0.09938708,-0.07176755,0.00000000,0.00000000,0.00000000,0.00000000
220.64000000,5.20500100,4.93000000,0.17272444,485.70184409,0.15932963,569.59442528,0.00083375,0.17208824,584.43121189,-0.09993023,-0.07215801,0.00000000,0.00000000,0.00000000,0.00000000
221.64000000,5.23508300,4.93100000,0.17370200,485.80036373,0.16016286,570.18485852,0.00083306,0.17299137,584.96347428,-0.10045465,-0.07253672,0.00000000,0.00000000,0.00000000,0.00000000
222.64000000,5.26489400,4.93300000,0.17467956,485.99740302,0.16099539,570.89121338,0.00083236,0.17386092,585.59550803,-0.10095630,-0.07290462,0.00000000,0.00000000,0.00000000,0.00000000
223.64000000,5.29487500,4.93400000,0.17569467,486.09592267,0.16185918,571.50038377,0.00083164,0.17476242,586.12787784,-0.10148096,-0.07328146,0.00000000,0.00000000,0.00000000,0.00000000
224.64000000,5.32499000,4.93600000,0.17670978,486.29296195,0.16272222,572.22568320,0.00089478,0.17569260,586.79701635,-0.10203867,-0.07365393,0.00000000,0.00000000,0.00000000,0.00000000
225.64000000,5.35534300,4.93700000,0.17772489,486.39148160,0.16358452,572.83535362,0.00089401,0.17659082,587.44797845,-0.10253422,-0.07405659,0.00000000,0.00000000,0.00000000,0.00000000
226.64000000,5.38562800,4.93900000,0.17870244,486.58852089,0.16441421,573.54307901,0.00076558,0.17751916,588.11750349,-0.10311009,-0.07440908,0.00000000,0.00000000,0.00000000,0.00000000
227.64000000,5.41614900,4.93900000,0.17983044,486.58852089,0.16537074,574.09195086,0.00101999,0.00000000,0.00000000,0.00000000,0.00000000,0.00000000,0.00000000,0.00000000,0.00000000
228.64000000,5.44673900,4.94100000,0.18080789,486.78556017,0.16619886,574.80022965,0.00089168,0.00000000,0.00000000,0.00000000,0.00000000,0.00000000,0.00000000,0.00000000,0.00000000
229.64000000,5.47743000,4.94100000,0.18182311,486.78556017,0.16705826,575.29442517,0.00089110,0.00000000,0.00000000,0.00000000,0.00000000,0.00000000,0.00000000,0.00000000,0.00000000
230.64000000,5.50862900,4.94300000,0.18283822,486.98259946,0.16791682,576.02163220,0.00082662,0.00000000,0.00000000,0.00000000,0.00000000,0.00000000,0.00000000,0.00000000,0.00000000
231.64000000,5.53938700,4.94400000,0.18385333,487.08111910,0.16877465,576.63260646,0.00088938,0.00000000,0.00000000,0.00000000,0.00000000,0.00000000,0.00000000,0.00000000,0.00000000
232.64000000,5.57011200,4.94500000,0.18486844,487.17963875,0.16963175,577.24378073,0.00069818,0.00000000,0.00000000,0.00000000,0.00000000,0.00000000,0.00000000,0.00000000,0.00000000
233.64000000,5.60120900,4.94600000,0.18599644,487.27815839,0.17058330,577.91016331,0.00095133,0.00000000,0.00000000,0.00000000,0.00000000,0.00000000,0.00000000,0.00000000,0.00000000
234.64000000,5.63213700,4.94700000,0.18701156,487.37667804,0.17143885,578.52174874,0.00088702,0.00000000,0.00000000,0.00000000,0.00000000,0.00000000,0.00000000,0.00000000,0.00000000
235.64000000,5.66286200,4.94800000,0.18802667,487.47519768,0.17229367,579.13353418,0.00082301,0.00000000,0.00000000,0.00000000,0.00000000,0.00000000,0.00000000,0.00000000,0.00000000
236.64000000,5.69419600,4.94900000,0.18911700,487.57371732,0.17321101,579.78219602,0.00088545,0.00000000,0.00000000,0.00000000,0.00000000,0.00000000,0.00000000,0.00000000,0.00000000
237.64000000,5.72617200,4.95000000,0.19013211,487.67223697,0.17406432,580.39438891,0.00075823,0.00000000,0.00000000,0.00000000,0.00000000,0.00000000,0.00000000,0.00000000,0.00000000
238.64000000,5.75770900,4.95100000,0.19126011,487.77075661,0.17501166,581.06184572,0.00094712,0.00000000,0.00000000,0.00000000,0.00000000,0.00000000,0.00000000,0.00000000,0.00000000
239.64000000,5.78921200,4.95200000,0.19231278,487.86927625,0.17589493,581.69277196,0.00088307,0.00000000,0.00000000,0.00000000,0.00000000,0.00000000,0.00000000,0.00000000,0.00000000
240.64000000,5.82139200,4.95200000,0.19336556,487.86927625,0.17677751,582.20638990,0.00094545,0.00000000,0.00000000,0.00000000,0.00000000,0.00000000,0.00000000,0.00000000,0.00000000
241.64000000,5.85326700,4.95300000,0.19445589,487.96779590,0.17769076,582.85600740,0.00088149,0.00000000,0.00000000,0.00000000,0.00000000,0.00000000,0.00000000,0.00000000,0.00000000
242.64000000,5.88531200,4.95400000,0.19554622,488.06631554,0.17860317,583.50583974,0.00094372,0.00000000,0.00000000,0.00000000,0.00000000,0.00000000,0.00000000,0.00000000,0.00000000
243.64000000,5.91766100,4.95500000,0.19667411,488.16483519,0.17954613,584.17422022,0.00100563,0.00000000,0.00000000,0.00000000,0.00000000,0.00000000,0.00000000,0.00000000,0.00000000
244.64000000,5.95034800,4.95500000,0.19772689,488.16483519,0.18042550,584.68814931,0.00087908,0.00000000,0.00000000,0.00000000,0.00000000,0.00000000,0.00000000,0.00000000,0.00000000
245.64000000,5.98256200,4.95500000,0.19881722,488.16483519,0.18133542,585.22041170,0.00087828,0.00000000,0.00000000,0.00000000,0.00000000,0.00000000,0.00000000,0.00000000,0.00000000
246.64000000,6.01487700,4.95600000,0.19990756,488.26335483,0.18224452,585.87088856,0.00094029,0.00000000,0.00000000,0.00000000,0.00000000,0.00000000,0.00000000,0.00000000,0.00000000
247.64000000,6.04729400,4.95700000,0.20099789,488.36187447,0.18315279,586.52158026,0.00093944,0.00000000,0.00000000,0.00000000,0.00000000,0.00000000,0.00000000,0.00000000,0.00000000
248.64000000,6.08028600,4.95700000,0.20208822,488.36187447,0.18406023,587.05405749,0.00087589,0.00000000,0.00000000,0.00000000,0.00000000,0.00000000,0.00000000,0.00000000,0.00000000
249.64000000,6.11354900,4.95800000,0.20325378,488.46039412,0.18502937,587.74181452,0.00100013,0.00000000,0.00000000,0.00000000,0.00000000,0.00000000,0.00000000,0.00000000,0.00000000
250.64000000,6.14677800,4.95900000,0.20438167,488.55891376,0.00000000,0.00000000,0.00000000,0.00000000,0.00000000,0.00000000,0.00000000,0.00000000,0.00000000,0.00000000,0.00000000
251.64000000,6.18054800,4.95800000,0.20550967,488.46039412,0.00000000,0.00000000,0.00000000,0.00000000,0.00000000,0.00000000,0.00000000,0.00000000,0.00000000,0.00000000,0.00000000
252.64000000,6.21374300,4.95800000,0.20656233,488.46039412,0.00000000,0.00000000,0.00000000,0.00000000,0.00000000,0.00000000,0.00000000,0.00000000,0.00000000,0.00000000,0.00000000
253.64000000,6.24700600,4.95800000,0.20769022,488.46039412,0.00000000,0.00000000,0.00000000,0.00000000,0.00000000,0.00000000,0.00000000,0.00000000,0.00000000,0.00000000,0.00000000
254.64000000,6.28114800,4.95900000,0.20878056,488.55891376,0.00000000,0.00000000,0.00000000,0.00000000,0.00000000,0.00000000,0.00000000,0.00000000,0.00000000,0.00000000,0.00000000
255.64000000,6.31508700,4.95800000,0.20990856,488.46039412,0.00000000,0.00000000,0.00000000,0.00000000,0.00000000,0.00000000,0.00000000,0.00000000,0.00000000,0.00000000,0.00000000
256.64000000,6.34936500,4.95800000,0.21096122,488.46039412,0.00000000,0.00000000,0.00000000,0.00000000,0.00000000,0.00000000,0.00000000,0.00000000,0.00000000,0.00000000,0.00000000
257.64000000,6.38543500,4.95700000,0.21186356,488.36187447,0.00000000,0.00000000,0.00000000,0.00000000,0.00000000,0.00000000,0.00000000,0.00000000,0.00000000,0.00000000,0.00000000