File: polyN_optimization/AA7020-T6_results/DATA/UT_15_1.csv
Time[s],Displacement[mm],Force[kN],EngStrain_longi,EngStress[MPa],TrueStrain,TrueStress[MPa],TrueStrainRate[1/s],PlasticStrain_longi,PlasticStress[MPa],PlasticStrain_thick,PlasticStrain_width,R-Value,Thickness[mm],Width[mm], Young's Modulus [MPa]
0.59000000,0.00000000,-0.00900000,0.00000000,-0.89284651,0.00000000,-0.89284651,0.00000000,0.00065587,317.83577502,0.00036561,-0.00102148,0.71100794,1.00600000,10.02000000,78135.66707835
2.09000000,0.00339700,0.00000000,0.00008622,0.00000000,0.00008622,0.00000000,0.00014399,0.00163668,323.56164951,-0.00011630,-0.00152038,0.00000000,0.00000000,0.00000000,0.00000000
3.59000000,0.00971800,0.30400000,0.00024178,30.15837113,0.00024175,30.16566275,0.00005421,0.00268384,328.71912757,-0.00076198,-0.00192187,0.00000000,0.00000000,0.00000000,0.00000000
5.09000000,0.01643200,0.49800000,0.00049144,49.40417376,0.00049132,49.42845317,0.00007596,0.00386382,334.43479441,-0.00146649,-0.00239733,0.00000000,0.00000000,0.00000000,0.00000000
6.59000000,0.02414700,0.73000000,0.00077822,72.41977278,0.00077792,72.47613146,0.00023738,0.00498219,338.53340921,-0.00206655,-0.00291564,0.00000000,0.00000000,0.00000000,0.00000000
8.09000000,0.03190200,0.92200000,0.00103211,91.46716507,0.00103158,91.56156935,0.00036899,0.00608395,342.93773685,-0.00271348,-0.00337047,0.00000000,0.00000000,0.00000000,0.00000000
9.59000000,0.03971200,1.16300000,0.00123544,115.37561061,0.00123468,115.51815076,0.00033495,0.00722424,346.86099940,-0.00334482,-0.00387942,0.00000000,0.00000000,0.00000000,0.00000000
11.09000000,0.04813100,1.35700000,0.00144522,134.62141324,0.00144418,134.81597110,0.00016066,0.00842204,350.81345504,-0.00408761,-0.00433443,0.00000000,0.00000000,0.00000000,0.00000000
12.59000000,0.05672600,1.58400000,0.00166222,157.14098642,0.00166084,157.40218966,0.00000377,0.00953150,354.33933245,-0.00474290,-0.00478860,0.00000000,0.00000000,0.00000000,0.00000000
14.09000000,0.06511100,1.77900000,0.00196222,176.48599421,0.00196030,176.83229895,-0.00008716,0.01064115,357.46804703,-0.00539118,-0.00524997,0.00000000,0.00000000,0.00000000,0.00000000
15.59000000,0.07341500,2.02400000,0.00235022,200.79126042,0.00234746,201.26316450,0.00008314,0.01180619,361.33318611,-0.00609761,-0.00570858,0.00000000,0.00000000,0.00000000,0.00000000
17.09000000,0.08237500,2.21900000,0.00267467,220.13626822,0.00267110,220.72505936,0.00025644,0.01296578,364.39328183,-0.00680037,-0.00616542,0.00000000,0.00000000,0.00000000,0.00000000
18.59000000,0.09126500,2.45900000,0.00296044,243.94550859,0.00295607,244.66769571,0.00039221,0.01405475,367.94224229,-0.00745555,-0.00659921,0.00000000,0.00000000,0.00000000,0.00000000
20.09000000,0.09964300,2.64800000,0.00319956,262.69528537,0.00319445,263.53579353,0.00035224,0.01520305,370.80880376,-0.00813246,-0.00707059,0.00000000,0.00000000,0.00000000,0.00000000
21.59000000,0.10875600,2.88200000,0.00348156,285.90929473,0.00347551,286.90470382,0.00023232,0.01638843,374.10309257,-0.00889728,-0.00749115,0.00000000,0.00000000,0.00000000,0.00000000
23.09000000,0.12330900,3.07200000,0.00391411,304.75827669,0.00390647,305.95113444,0.00034490,0.01749865,376.86649914,-0.00952964,-0.00796900,0.00000000,0.00000000,0.00000000,0.00000000
24.59000000,0.15353100,3.18800000,0.00496322,316.26607620,0.00495095,317.83577502,0.00095062,0.01861014,380.24895568,-0.01020506,-0.00840509,0.00000000,0.00000000,0.00000000,0.00000000
26.09000000,0.18747400,3.24200000,0.00602722,321.62315528,0.00600913,323.56164951,0.00085216,0.01978094,382.94595021,-0.01087829,-0.00890265,0.00000000,0.00000000,0.00000000,0.00000000
27.59000000,0.22253200,3.29000000,0.00715144,326.38500335,0.00712599,328.71912757,0.00075430,0.02093234,386.15325479,-0.01157652,-0.00935582,0.00000000,0.00000000,0.00000000,0.00000000
29.09000000,0.25748700,3.34300000,0.00841844,331.64287727,0.00838321,334.43479441,0.00090239,0.02202728,388.83317553,-0.01220603,-0.00982124,0.00000000,0.00000000,0.00000000,0.00000000
30.59000000,0.29396500,3.38000000,0.00960278,335.31346849,0.00955696,338.53340921,0.00105041,0.02318353,391.74805986,-0.01284238,-0.01034115,0.00000000,0.00000000,0.00000000,0.00000000
32.09000000,0.32963100,3.42000000,0.01077589,339.28167522,0.01071824,342.93773685,0.00094515,0.02430023,394.24276166,-0.01352247,-0.01077776,0.00000000,0.00000000,0.00000000,0.00000000
33.59000000,0.36597300,3.45500000,0.01198278,342.75385610,0.01191155,346.86099940,0.00088449,0.02539633,397.35163148,-0.01414384,-0.01125249,0.00000000,0.00000000,0.00000000,0.00000000
35.09000000,0.40316200,3.49000000,0.01324978,346.22603699,0.01316277,350.81345504,0.00097247,0.02655020,399.87246642,-0.01487530,-0.01167490,0.00000000,0.00000000,0.00000000,0.00000000
36.59000000,0.43950300,3.52100000,0.01442289,349.30139721,0.01431987,354.33933245,0.00094920,0.02767524,402.79952461,-0.01552860,-0.01214664,0.00000000,0.00000000,0.00000000,0.00000000
38.09000000,0.47574400,3.54800000,0.01559211,351.97993675,0.01547180,357.46804703,0.00077014,0.02880002,405.11340725,-0.01615265,-0.01264737,0.00000000,0.00000000,0.00000000,0.00000000
39.59000000,0.51229000,3.58200000,0.01682911,355.35291247,0.01668907,361.33318611,0.00074712,0.02989258,407.83232581,-0.01679062,-0.01310195,0.00000000,0.00000000,0.00000000,0.00000000
41.09000000,0.54890200,3.60800000,0.01805100,357.93224684,0.01789002,364.39328183,0.00086437,0.03100223,410.25354857,-0.01742408,-0.01357815,0.00000000,0.00000000,0.00000000,0.00000000
42.59000000,0.58497400,3.63900000,0.01920911,361.00760705,0.01902695,367.94224229,0.00073055,0.03213028,413.10181669,-0.01809154,-0.01403874,0.00000000,0.00000000,0.00000000,0.00000000
44.09000000,0.62172200,3.66300000,0.02041967,363.38853109,0.02021398,370.80880376,0.00066324,0.03322573,415.32026889,-0.01871119,-0.01451453,0.00000000,0.00000000,0.00000000,0.00000000
45.59000000,0.65799700,3.69100000,0.02167544,366.16627580,0.02144387,374.10309257,0.00072878,0.03434654,417.96922947,-0.01938405,-0.01496249,0.00000000,0.00000000,0.00000000,0.00000000
47.09000000,0.69450800,3.71400000,0.02284856,368.44799467,0.02259144,376.86649914,0.00072078,0.03546443,420.20671034,-0.02005245,-0.01541199,0.00000000,0.00000000,0.00000000,0.00000000
48.59000000,0.73074900,3.74300000,0.02403289,371.32494454,0.02374864,380.24895568,0.00066111,0.03659466,422.76630542,-0.02073959,-0.01585507,0.00000000,0.00000000,0.00000000,0.00000000
50.09000000,0.76705700,3.76500000,0.02526989,373.50745824,0.02495588,382.94595021,0.00071907,0.03767033,424.99537433,-0.02134201,-0.01632833,0.00000000,0.00000000,0.00000000,0.00000000
51.59000000,0.80323000,3.79200000,0.02649556,376.18599779,0.02615063,386.15325479,0.00082801,0.03881206,427.57026067,-0.02203417,-0.01677789,0.00000000,0.00000000,0.00000000,0.00000000
53.09000000,0.83926700,3.81400000,0.02765733,378.36851149,0.02728178,388.83317553,0.00070269,0.03996512,429.73772413,-0.02272494,-0.01724018,0.00000000,0.00000000,0.00000000,0.00000000
54.59000000,0.87517000,3.83800000,0.02888678,380.74943552,0.02847742,391.74805986,0.00078957,0.04105051,432.29865775,-0.02334351,-0.01770700,0.00000000,0.00000000,0.00000000,0.00000000
56.09000000,0.91097100,3.85800000,0.03007111,382.73353889,0.02962784,394.24276166,0.00079579,0.04219500,434.36714603,-0.02404911,-0.01814588,0.00000000,0.00000000,0.00000000,0.00000000
57.59000000,0.94711000,3.88400000,0.03124411,385.31287326,0.03076595,397.35163148,0.00079488,0.04331173,436.53256183,-0.02473486,-0.01857687,0.00000000,0.00000000,0.00000000,0.00000000
59.09000000,0.98352000,3.90400000,0.03246989,387.29697662,0.03195388,399.87246642,0.00078683,0.04443358,439.01951397,-0.02538237,-0.01905121,0.00000000,0.00000000,0.00000000,0.00000000
60.59000000,1.01959100,3.92800000,0.03367300,389.67790066,0.03311848,402.79952461,0.00080033,0.04551709,441.07434446,-0.02601100,-0.01950609,0.00000000,0.00000000,0.00000000,0.00000000
62.09000000,1.05532400,3.94600000,0.03486867,391.46359369,0.03427453,405.11340725,0.00087223,0.04669572,443.38603817,-0.02675238,-0.01994334,0.00000000,0.00000000,0.00000000,0.00000000
63.59000000,1.09092200,3.96800000,0.03603800,393.64610739,0.03540382,407.83232581,0.00082768,0.04778713,445.45295459,-0.02738354,-0.02040359,0.00000000,0.00000000,0.00000000,0.00000000
65.09000000,1.12682400,3.98700000,0.03722222,395.53100558,0.03654620,410.25354857,0.00081195,0.04889704,447.63774785,-0.02800254,-0.02089450,0.00000000,0.00000000,0.00000000,0.00000000
66.59000000,1.16306500,4.01000000,0.03843289,397.81272445,0.03771274,413.10181669,0.00081828,0.05002264,449.62292810,-0.02868257,-0.02134007,0.00000000,0.00000000,0.00000000,0.00000000
68.09000000,1.19957600,4.02700000,0.03960222,399.49921231,0.03883816,415.32026889,0.00075235,0.05116013,451.93460991,-0.02939484,-0.02176530,0.00000000,0.00000000,0.00000000,0.00000000
69.59000000,1.23564800,4.04800000,0.04080533,401.58252084,0.03999477,417.96922947,0.00070812,0.05224564,453.80407982,-0.02999657,-0.02224907,0.00000000,0.00000000,0.00000000,0.00000000
71.09000000,1.27151600,4.06500000,0.04200100,403.26900870,0.04114290,420.20671034,0.00070731,0.05335158,455.89842074,-0.03064901,-0.02270257,0.00000000,0.00000000,0.00000000,0.00000000
72.59000000,1.30782500,4.08500000,0.04321544,405.25311207,0.04230772,422.76630542,0.00076424,0.05448013,457.79524498,-0.03132966,-0.02315048,0.00000000,0.00000000,0.00000000,0.00000000
74.09000000,1.34379500,4.10200000,0.04436967,406.93959993,0.04341351,424.99537433,0.00064802,0.05560656,460.01345877,-0.03196540,-0.02364117,0.00000000,0.00000000,0.00000000,0.00000000
75.59000000,1.37990000,4.12200000,0.04559911,408.92370329,0.04459003,427.57026067,0.00072635,0.05672685,461.80809389,-0.03264171,-0.02408513,0.00000000,0.00000000,0.00000000,0.00000000
77.09000000,1.41631000,4.13800000,0.04683611,410.51098598,0.04577239,429.73772413,0.00082615,0.05782037,463.91308767,-0.03327578,-0.02454459,0.00000000,0.00000000,0.00000000,0.00000000
78.59000000,1.45288900,4.15800000,0.04800922,412.49508934,0.04689239,432.29865775,0.00071768,0.05897085,465.62270121,-0.03396533,-0.02500552,0.00000000,0.00000000,0.00000000,0.00000000
80.09000000,1.48902900,4.17300000,0.04923867,413.98316687,0.04806482,434.36714603,0.00074544,0.06010168,467.64654258,-0.03463925,-0.02546243,0.00000000,0.00000000,0.00000000,0.00000000
81.59000000,1.52540500,4.18900000,0.05044178,415.57044956,0.04921082,436.53256183,0.00078755,0.06118364,469.54456450,-0.03526586,-0.02591778,0.00000000,0.00000000,0.00000000,0.00000000
83.09000000,1.56157800,4.20800000,0.05165622,417.45534775,0.05036628,439.01951397,0.00081539,0.06230268,471.46383505,-0.03592302,-0.02637966,0.00000000,0.00000000,0.00000000,0.00000000
84.59000000,1.59758200,4.22300000,0.05282556,418.94342528,0.05147756,441.07434446,0.00072157,0.06343024,473.17684313,-0.03657839,-0.02685186,0.00000000,0.00000000,0.00000000,0.00000000
86.09000000,1.63436300,4.24000000,0.05410011,420.62991314,0.05268743,443.38603817,0.00084197,0.06455902,475.21534413,-0.03721443,-0.02734459,0.00000000,0.00000000,0.00000000,0.00000000
87.59000000,1.67070600,4.25500000,0.05528067,422.11799066,0.05380677,445.45295459,0.00081975,0.06569783,476.94081588,-0.03790191,-0.02779592,0.00000000,0.00000000,0.00000000,0.00000000
89.09000000,1.70714900,4.27100000,0.05648378,423.70527335,0.05494620,447.63774785,0.00079735,0.06683719,478.77739402,-0.03853739,-0.02829980,0.00000000,0.00000000,0.00000000,0.00000000
90.59000000,1.74339000,4.28500000,0.05770200,425.09414570,0.05609863,449.62292810,0.00083910,0.06794196,480.49332728,-0.03918038,-0.02876158,0.00000000,0.00000000,0.00000000,0.00000000
92.09000000,1.78051100,4.30200000,0.05893889,426.78063356,0.05726736,451.93460991,0.00081671,0.06909936,482.34578557,-0.03986900,-0.02923036,0.00000000,0.00000000,0.00000000,0.00000000
93.59000000,1.81692000,4.31500000,0.06011578,428.07030075,0.05837813,453.80407982,0.00075205,0.07019103,484.06212516,-0.04049558,-0.02969545,0.00000000,0.00000000,0.00000000,0.00000000
95.09000000,1.85360100,4.33000000,0.06131889,429.55837827,0.05951237,455.89842074,0.00072983,0.07136590,485.71444091,-0.04119925,-0.03016664,0.00000000,0.00000000,0.00000000,0.00000000
96.59000000,1.88997700,4.34300000,0.06254456,430.84804546,0.06066656,457.79524498,0.00070075,0.07248593,487.45122457,-0.04185257,-0.03063336,0.00000000,0.00000000,0.00000000,0.00000000
98.09000000,1.92655600,4.35900000,0.06377400,432.43532815,0.06182296,460.01345877,0.00078478,0.07363378,489.09685875,-0.04253633,-0.03109745,0.00000000,0.00000000,0.00000000,0.00000000
99.59000000,1.96360900,4.37100000,0.06499222,433.62579017,0.06296750,461.80809389,0.00074861,0.07475802,490.84237043,-0.04318930,-0.03156872,0.00000000,0.00000000,0.00000000,0.00000000
101.09000000,2.00042400,4.38600000,0.06618778,435.11386769,0.06408946,463.91308767,0.00069835,0.07588928,492.48628360,-0.04386957,-0.03201970,0.00000000,0.00000000,0.00000000,0.00000000
102.59000000,2.03724000,4.39700000,0.06743978,436.20512454,0.06526305,465.62270121,0.00076792,0.07702607,494.13611455,-0.04450770,-0.03251837,0.00000000,0.00000000,0.00000000,0.00000000
104.09000000,2.07409000,4.41100000,0.06867678,437.59399690,0.06642123,467.64654258,0.00078118,0.07813547,495.66674206,-0.04512322,-0.03301226,0.00000000,0.00000000,0.00000000,0.00000000
105.59000000,2.11131200,4.42400000,0.06986111,438.88366408,0.06752884,469.54456450,0.00070302,0.07931119,497.55996291,-0.04583597,-0.03347522,0.00000000,0.00000000,0.00000000,0.00000000
107.09000000,2.14819500,4.43700000,0.07108678,440.17333127,0.06867381,471.46383505,0.00068810,0.08043645,498.99576526,-0.04644229,-0.03399417,0.00000000,0.00000000,0.00000000,0.00000000
108.59000000,2.18497700,4.44800000,0.07232000,441.26458812,0.06982453,473.17684313,0.00071550,0.08156432,500.65374354,-0.04705564,-0.03450868,0.00000000,0.00000000,0.00000000,0.00000000
110.09000000,2.22243500,4.46200000,0.07356067,442.65346047,0.07098085,475.21534413,0.00075650,0.08270406,502.10243441,-0.04778375,-0.03492032,0.00000000,0.00000000,0.00000000,0.00000000
111.59000000,2.25982700,4.47300000,0.07480900,443.74471732,0.07214297,476.94081588,0.00075583,0.08387356,503.78765240,-0.04848369,-0.03538988,0.00000000,0.00000000,0.00000000,0.00000000
113.09000000,2.29755600,4.48500000,0.07606100,444.93517934,0.07330715,478.77739402,0.00076177,0.08500015,505.23537218,-0.04910594,-0.03589421,0.00000000,0.00000000,0.00000000,0.00000000
114.59000000,2.33433900,4.49600000,0.07727544,446.02643619,0.07443512,480.49332728,0.00074007,0.08613771,506.80098556,-0.04978118,-0.03635653,0.00000000,0.00000000,0.00000000,0.00000000
116.09000000,2.37210200,4.50800000,0.07855000,447.21689821,0.07561755,482.34578557,0.00079505,0.08728541,508.26500982,-0.05044848,-0.03683692,0.00000000,0.00000000,0.00000000,0.00000000
117.59000000,2.40905300,4.51900000,0.07975311,448.30815506,0.07673241,484.06212516,0.00073837,0.08844592,509.95813061,-0.05112421,-0.03732171,0.00000000,0.00000000,0.00000000,0.00000000
119.09000000,2.44732400,4.52900000,0.08104656,449.30020674,0.07792960,485.71444091,0.00078622,0.08958549,511.31373039,-0.05177079,-0.03781470,0.00000000,0.00000000,0.00000000,0.00000000
120.59000000,2.48502000,4.54000000,0.08228344,450.39146359,0.07907311,487.45122457,0.00074342,0.09072083,512.88991490,-0.05242178,-0.03829906,0.00000000,0.00000000,0.00000000,0.00000000
122.09000000,2.52288400,4.55000000,0.08355056,451.38351528,0.08024320,489.09685875,0.00080513,0.09185256,514.13638412,-0.05310853,-0.03874402,0.00000000,0.00000000,0.00000000,0.00000000
123.59000000,2.56108700,4.56100000,0.08479500,452.47477213,0.08139103,490.84237043,0.00072797,0.09301372,515.62114963,-0.05379157,-0.03922215,0.00000000,0.00000000,0.00000000,0.00000000
125.09000000,2.59868100,4.57100000,0.08604700,453.46682381,0.08254450,492.48628360,0.00072713,0.09417198,517.21775208,-0.05448107,-0.03969091,0.00000000,0.00000000,0.00000000,0.00000000
126.59000000,2.63614000,4.58100000,0.08730656,454.45887549,0.08370359,494.13611455,0.00082320,0.09532989,518.48522956,-0.05517191,-0.04015798,0.00000000,0.00000000,0.00000000,0.00000000
128.09000000,2.67393700,4.59000000,0.08853600,455.35172200,0.08483367,495.66674206,0.00071853,0.09652043,519.99368295,-0.05589172,-0.04062871,0.00000000,0.00000000,0.00000000,0.00000000
129.59000000,2.71237700,4.60200000,0.08984444,456.54218402,0.08603497,497.55996291,0.00078681,0.09767738,521.37647161,-0.05653510,-0.04114228,0.00000000,0.00000000,0.00000000,0.00000000
131.09000000,2.75030900,4.61000000,0.09109267,457.33582537,0.08717964,498.99576526,0.00077206,0.09879929,522.74336020,-0.05717107,-0.04162822,0.00000000,0.00000000,0.00000000,0.00000000
132.59000000,2.78790200,4.62000000,0.09234844,458.32787705,0.08832991,500.65374354,0.00077117,0.10002722,524.16867670,-0.05792317,-0.04210406,0.00000000,0.00000000,0.00000000,0.00000000
134.09000000,2.82661400,4.62800000,0.09361556,459.12151839,0.08948923,502.10243441,0.00074283,0.10119488,525.45350741,-0.05863278,-0.04256210,0.00000000,0.00000000,0.00000000,0.00000000
135.59000000,2.86539200,4.63800000,0.09492022,460.11357008,0.09068150,503.78765240,0.00083819,0.10235093,526.73450615,-0.05931218,-0.04303875,0.00000000,0.00000000,0.00000000,0.00000000
137.09000000,2.90396800,4.64600000,0.09617589,460.90721142,0.09182766,505.23537218,0.00075468,0.10349747,528.12435414,-0.05996449,-0.04353298,0.00000000,0.00000000,0.00000000,0.00000000
138.59000000,2.94193300,4.65500000,0.09744678,461.80005794,0.09298637,506.80098556,0.00081559,0.10471612,529.55520470,-0.06067544,-0.04404068,0.00000000,0.00000000,0.00000000,0.00000000
140.09000000,2.98030600,4.66300000,0.09872878,462.59369928,0.09415385,508.26500982,0.00074605,0.10585796,530.83585553,-0.06129719,-0.04456077,0.00000000,0.00000000,0.00000000,0.00000000
141.59000000,3.01938900,4.67300000,0.10002978,463.58575096,0.09533725,509.95813061,0.00082742,0.10704659,532.03184054,-0.06201624,-0.04503035,0.00000000,0.00000000,0.00000000,0.00000000
143.09000000,3.05816700,4.68000000,0.10130422,464.28018714,0.09649513,511.31373039,0.00080587,0.10823883,533.34404672,-0.06271853,-0.04552031,0.00000000,0.00000000,0.00000000,0.00000000
144.59000000,3.09687700,4.68900000,0.10257878,465.17303365,0.09765178,512.88991490,0.00071603,0.10939975,534.64179756,-0.06336493,-0.04603482,0.00000000,0.00000000,0.00000000,0.00000000
146.09000000,3.13552000,4.69500000,0.10384589,465.76826466,0.09880034,514.13638412,0.00066083,0.11053935,535.93037883,-0.06402086,-0.04651850,0.00000000,0.00000000,0.00000000,0.00000000
147.59000000,3.17443400,4.70300000,0.10515056,466.56190601,0.09998158,515.62114963,0.00071456,0.11171736,537.24202578,-0.06468878,-0.04702858,0.00000000,0.00000000,0.00000000,0.00000000
149.09000000,3.21301000,4.71200000,0.10645522,467.45475252,0.10116141,517.21775208,0.00074787,0.11295841,538.47756832,-0.06545900,-0.04749941,0.00000000,0.00000000,0.00000000,0.00000000
150.59000000,3.25212600,4.71800000,0.10775611,468.04998353,0.10233645,518.48522956,0.00070606,0.11413164,539.67851004,-0.06608240,-0.04804924,0.00000000,0.00000000,0.00000000,0.00000000
152.09000000,3.29124300,4.72600000,0.10909833,468.84362488,0.10354737,519.99368295,0.00082747,0.11531188,540.99835319,-0.06681281,-0.04849907,0.00000000,0.00000000,0.00000000,0.00000000
153.59000000,3.33059600,4.73300000,0.11040300,469.53806105,0.10472301,521.37647161,0.00079927,0.11653657,542.11866058,-0.06752455,-0.04901201,0.00000000,0.00000000,0.00000000,0.00000000
155.09000000,3.36961100,4.74000000,0.11167000,470.23249723,0.10586339,522.74336020,0.00072397,0.11770874,543.32544374,-0.06822799,-0.04948076,0.00000000,0.00000000,0.00000000,0.00000000
156.59000000,3.40967600,4.74700000,0.11305733,470.92693341,0.10711058,524.16867670,0.00081754,0.11885976,544.52273657,-0.06890098,-0.04995878,0.00000000,0.00000000,0.00000000,0.00000000
158.09000000,3.44936800,4.75300000,0.11437711,471.52216442,0.10829560,525.45350741,0.00089776,0.12009154,545.76650468,-0.06960151,-0.05049002,0.00000000,0.00000000,0.00000000,0.00000000
159.59000000,3.48838300,4.75900000,0.11568544,472.11739543,0.10946896,526.73450615,0.00083593,0.12125939,546.97731799,-0.07025083,-0.05100856,0.00000000,0.00000000,0.00000000,0.00000000
161.09000000,3.52777000,4.76600000,0.11698633,472.81183161,0.11063428,528.12435414,0.00079456,0.12245030,548.08918311,-0.07095840,-0.05149190,0.00000000,0.00000000,0.00000000,0.00000000
162.59000000,3.56813900,4.77300000,0.11837000,473.50626778,0.11187227,529.55520470,0.00086772,0.12362988,549.19667764,-0.07161580,-0.05201408,0.00000000,0.00000000,0.00000000,0.00000000
164.09000000,3.60823800,4.77900000,0.11966711,474.10149879,0.11303142,530.83585553,0.00086652,0.12484243,550.43841629,-0.07233061,-0.05251183,0.00000000,0.00000000,0.00000000,0.00000000
165.59000000,3.64782900,4.78400000,0.12101689,474.59752463,0.11423621,532.03184054,0.00075819,0.12604687,551.44943513,-0.07301005,-0.05303682,0.00000000,0.00000000,0.00000000,0.00000000
167.09000000,3.68850200,4.79000000,0.12237411,475.19275564,0.11544618,533.34404672,0.00077727,0.12725146,552.57656448,-0.07374623,-0.05350524,0.00000000,0.00000000,0.00000000,0.00000000
168.59000000,3.72853300,4.79600000,0.12369756,475.78798665,0.11662464,534.64179756,0.00082325,0.12847911,553.83300780,-0.07444675,-0.05403236,0.00000000,0.00000000,0.00000000,0.00000000
170.09000000,3.76876600,4.80200000,0.12499844,476.38321766,0.11778165,535.93037883,0.00074859,0.12965461,554.94793309,-0.07513826,-0.05451635,0.00000000,0.00000000,0.00000000,0.00000000
171.59000000,3.80862800,4.80800000,0.12634444,476.97844867,0.11897738,537.24202578,0.00069420,0.13088073,556.09310236,-0.07583191,-0.05504882,0.00000000,0.00000000,0.00000000,0.00000000
173.09000000,3.84947000,4.81300000,0.12776200,477.47447451,0.12023514,538.47756832,0.00087370,0.13207921,557.22475636,-0.07655044,-0.05552877,0.00000000,0.00000000,0.00000000,0.00000000
174.59000000,3.89061800,4.81800000,0.12910422,477.97050035,0.12142459,539.67851004,0.00078603,0.13333781,558.16201712,-0.07732100,-0.05601681,0.00000000,0.00000000,0.00000000,0.00000000
176.09000000,3.93105400,4.82400000,0.13045778,478.56573136,0.12262266,540.99835319,0.00077171,0.13452359,559.29019006,-0.07798145,-0.05654215,0.00000000,0.00000000,0.00000000,0.00000000
177.59000000,3.97199900,4.82800000,0.13186022,478.96255203,0.12386249,542.11866058,0.00084402,0.13577090,560.33965991,-0.07871543,-0.05705547,0.00000000,0.00000000,0.00000000,0.00000000
179.09000000,4.01307800,4.83300000,0.13320622,479.45857787,0.12505098,543.32544374,0.00088951,0.13696668,561.47726264,-0.07938311,-0.05758356,0.00000000,0.00000000,0.00000000,0.00000000
180.59000000,4.05331100,4.83800000,0.13452967,479.95460372,0.12621817,544.52273657,0.00068959,0.13819798,562.52129912,-0.08008224,-0.05811575,0.00000000,0.00000000,0.00000000,0.00000000
182.09000000,4.09456000,4.84300000,0.13594711,480.45062956,0.12746676,545.76650468,0.00083433,0.13945999,563.58451764,-0.08084161,-0.05861838,0.00000000,0.00000000,0.00000000,0.00000000
183.59000000,4.13604500,4.84800000,0.13729311,480.94665540,0.12865097,546.97731799,0.00082669,0.14069127,564.63206453,-0.08156238,-0.05912889,0.00000000,0.00000000,0.00000000,0.00000000
185.09000000,4.17736200,4.85200000,0.13866544,481.34347607,0.12985691,548.08918311,0.00079270,0.14192432,565.68236500,-0.08225782,-0.05966650,0.00000000,0.00000000,0.00000000,0.00000000
186.59000000,4.21864500,4.85600000,0.14002644,481.74029674,0.13105146,549.19667764,0.00077187,0.14313968,566.72432075,-0.08294992,-0.06018976,0.00000000,0.00000000,0.00000000,0.00000000
188.09000000,4.26070500,4.86100000,0.14142878,482.23632258,0.13228079,550.43841629,0.00083655,0.14441772,567.80386640,-0.08371854,-0.06069919,0.00000000,0.00000000,0.00000000,0.00000000
189.59000000,4.30219000,4.86400000,0.14282000,482.53393809,0.13349889,551.44943513,0.00084234,0.14569556,568.76860267,-0.08443755,-0.06125801,0.00000000,0.00000000,0.00000000,0.00000000
191.09000000,4.34387900,4.86800000,0.14421489,482.93075876,0.13471872,552.57656448,0.00082169,0.14690630,569.81306690,-0.08516412,-0.06174219,0.00000000,0.00000000,0.00000000,0.00000000
192.59000000,4.38549900,4.87300000,0.14563989,483.42678460,0.13596334,553.83300780,0.00087326,0.14814890,570.76073509,-0.08586122,-0.06228768,0.00000000,0.00000000,0.00000000,0.00000000
194.09000000,4.42766200,4.87700000,0.14700467,483.82360527,0.13715391,554.94793309,0.00084586,0.14942038,571.84352957,-0.08661603,-0.06280435,0.00000000,0.00000000,0.00000000,0.00000000
195.59000000,4.46982400,4.88100000,0.14842967,484.22042595,0.13839550,556.09310236,0.00075964,0.15072347,572.82928925,-0.08737972,-0.06334375,0.00000000,0.00000000,0.00000000,0.00000000
197.09000000,4.51198600,4.88500000,0.14982444,484.61724662,0.13960927,557.22475636,0.00076529,0.15196131,573.77892514,-0.08806240,-0.06389891,0.00000000,0.00000000,0.00000000,0.00000000
198.59000000,4.55479200,4.88700000,0.15128711,484.81565696,0.14088054,558.16201712,0.00087554,0.15326111,574.76594763,-0.08884525,-0.06441586,0.00000000,0.00000000,0.00000000,0.00000000
200.09000000,4.59742700,4.89100000,0.15267067,485.21247763,0.14208157,559.29019006,0.00080911,0.15449563,575.71670780,-0.08958141,-0.06491422,0.00000000,0.00000000,0.00000000,0.00000000
201.59000000,4.64030000,4.89400000,0.15412567,485.51009313,0.14334306,560.33965991,0.00083409,0.15579048,576.82177528,-0.09032798,-0.06546250,0.00000000,0.00000000,0.00000000,0.00000000
203.09000000,4.68263200,4.89800000,0.15552433,485.90691381,0.14455421,561.47726264,0.00081365,0.15711678,577.82917217,-0.09115253,-0.06596425,0.00000000,0.00000000,0.00000000,0.00000000
204.59000000,4.72584300,4.90100000,0.15696433,486.20452931,0.14579962,562.52129912,0.00081898,0.15837966,578.68318146,-0.09186874,-0.06651092,0.00000000,0.00000000,0.00000000,0.00000000
206.09000000,4.76837800,4.90400000,0.15844200,486.50214482,0.14707600,563.58451764,0.00090257,0.15970404,579.57436102,-0.09267595,-0.06702808,0.00000000,0.00000000,0.00000000,0.00000000
207.59000000,4.81250200,4.90700000,0.15988567,486.79976032,0.14832144,564.63206453,0.00088189,0.16102504,580.58330955,-0.09343364,-0.06759139,0.00000000,0.00000000,0.00000000,0.00000000
209.09000000,4.85574800,4.91000000,0.16133322,487.09737582,0.14956867,565.68236500,0.00081609,0.16228130,581.55598296,-0.09415390,-0.06812740,0.00000000,0.00000000,0.00000000,0.00000000
210.59000000,4.89970300,4.91300000,0.16276189,487.39499133,0.15079811,566.72432075,0.00084070,0.16363180,582.46683565,-0.09491787,-0.06871392,0.00000000,0.00000000,0.00000000,0.00000000
212.09000000,4.94284700,4.91600000,0.16426589,487.69260683,0.15209075,567.80386640,0.00090454,0.16494749,583.47749992,-0.09567097,-0.06927652,0.00000000,0.00000000,0.00000000,0.00000000
213.59000000,4.98676900,4.91800000,0.16576978,487.89101717,0.15338162,568.76860267,0.00083873,0.16623171,584.35227375,-0.09642850,-0.06980321,0.00000000,0.00000000,0.00000000,0.00000000
215.09000000,5.03086100,4.92100000,0.16719856,488.18863268,0.15460648,569.81306690,0.00077332,0.16757517,585.38247313,-0.09719197,-0.07038320,0.00000000,0.00000000,0.00000000,0.00000000
216.59000000,5.07474900,4.92300000,0.16866478,488.38704301,0.15586188,570.76073509,0.00077216,0.16894970,586.31342272,-0.09800932,-0.07094038,0.00000000,0.00000000,0.00000000,0.00000000
218.09000000,5.11951700,4.92600000,0.17016878,488.68465852,0.15714799,571.84352957,0.00083557,0.17032229,587.24470056,-0.09882035,-0.07150194,0.00000000,0.00000000,0.00000000,0.00000000
219.59000000,5.16438600,4.92800000,0.17171022,488.88306885,0.15846441,572.82928925,0.00089860,0.17169288,588.17625202,-0.09964857,-0.07204431,0.00000000,0.00000000,0.00000000,0.00000000
221.09000000,5.20928900,4.93000000,0.17317656,489.08147919,0.15971507,573.77892514,0.00076938,0.17306164,589.10818632,-0.10043754,-0.07262410,0.00000000,0.00000000,0.00000000,0.00000000
222.59000000,5.25399000,4.93200000,0.17471811,489.27988953,0.16102821,574.76594763,0.00089649,0.17445954,590.05891345,-0.10127623,-0.07318331,0.00000000,0.00000000,0.00000000,0.00000000
224.09000000,5.29821600,4.93400000,0.17618433,489.47829986,0.16227558,575.71670780,0.00083111,0.17585545,591.00997627,-0.10205950,-0.07379595,0.00000000,0.00000000,0.00000000,0.00000000
225.59000000,5.34376200,4.93700000,0.17772589,489.77591537,0.16358537,576.82177528,0.00089401,0.17721841,591.94290273,-0.10283768,-0.07438073,0.00000000,0.00000000,0.00000000,0.00000000
227.09000000,5.38954600,4.93900000,0.17930500,489.97432570,0.16492528,577.82917217,0.00089282,0.17864292,592.79354593,-0.10369438,-0.07494854,0.00000000,0.00000000,0.00000000,0.00000000
228.59000000,5.43488900,4.94000000,0.18080889,490.07353087,0.16619970,578.68318146,0.00089168,0.18006546,593.64424379,-0.10454494,-0.07552052,0.00000000,0.00000000,0.00000000,0.00000000
230.09000000,5.48053600,4.94100000,0.18238800,490.17273604,0.16753612,579.57436102,0.00089049,0.18151506,594.63326895,-0.10544105,-0.07607401,0.00000000,0.00000000,0.00000000,0.00000000
231.59000000,5.52679300,4.94300000,0.18396711,490.37114638,0.16887076,580.58330955,0.00088930,0.18299509,595.52114459,-0.10627489,-0.07672021,0.00000000,0.00000000,0.00000000,0.00000000
233.09000000,5.57301600,4.94500000,0.18547100,490.56955671,0.17014016,581.55598296,0.00082478,0.18444037,596.51069939,-0.10709164,-0.07734873,0.00000000,0.00000000,0.00000000,0.00000000
234.59000000,5.61930700,4.94600000,0.18708767,490.66876188,0.17150297,582.46683565,0.00082366,0.18594669,597.41723357,-0.10796449,-0.07798220,0.00000000,0.00000000,0.00000000,0.00000000
236.09000000,5.66539500,4.94800000,0.18866678,490.86717222,0.17283232,583.47749992,0.00088578,0.18745072,598.32376775,-0.10889500,-0.07855571,0.00000000,0.00000000,0.00000000,0.00000000
237.59000000,5.71236200,4.94900000,0.19020833,490.96637738,0.17412836,584.35227375,0.00082150,0.18904430,599.28579510,-0.10985118,-0.07919311,0.00000000,0.00000000,0.00000000,0.00000000
239.09000000,5.75946500,4.95100000,0.19182500,491.16478772,0.17548575,585.38247313,0.00088343,0.00000000,0.00000000,0.00000000,0.00000000,0.00000000,0.00000000,0.00000000,0.00000000
240.59000000,5.80707600,4.95200000,0.19347933,491.26399289,0.17687285,586.31342272,0.00094536,0.00000000,0.00000000,0.00000000,0.00000000,0.00000000,0.00000000,0.00000000,0.00000000
242.09000000,5.85461800,4.95300000,0.19513367,491.36319806,0.17825803,587.24470056,0.00094405,0.00000000,0.00000000,0.00000000,0.00000000,0.00000000,0.00000000,0.00000000,0.00000000
243.59000000,5.90273600,4.95400000,0.19678789,491.46240323,0.17964121,588.17625202,0.00094256,0.00000000,0.00000000,0.00000000,0.00000000,0.00000000,0.00000000,0.00000000,0.00000000
245.09000000,5.95095600,4.95500000,0.19844222,491.56160839,0.18102257,589.10818632,0.00100415,0.00000000,0.00000000,0.00000000,0.00000000,0.00000000,0.00000000,0.00000000,0.00000000
246.59000000,5.99897200,4.95600000,0.20013411,491.66081356,0.18243331,590.05891345,0.00094012,0.00000000,0.00000000,0.00000000,0.00000000,0.00000000,0.00000000,0.00000000,0.00000000
248.09000000,6.04719100,4.95700000,0.20182600,491.76001873,0.18384207,591.00997627,0.00106385,0.00000000,0.00000000,0.00000000,0.00000000,0.00000000,0.00000000,0.00000000,0.00000000
249.59000000,6.09662800,4.95800000,0.20348033,491.85922390,0.18521764,591.94290273,0.00093750,0.00000000,0.00000000,0.00000000,0.00000000,0.00000000,0.00000000,0.00000000,0.00000000
251.09000000,6.14603200,4.95800000,0.20520978,491.85922390,0.18665364,592.79354593,0.00087381,0.00000000,0.00000000,0.00000000,0.00000000,0.00000000,0.00000000,0.00000000,0.00000000
252.59000000,6.19547000,4.95800000,0.20693933,491.85922390,0.18808768,593.64424379,0.00087255,0.00000000,0.00000000,0.00000000,0.00000000,0.00000000,0.00000000,0.00000000,0.00000000
254.09000000,6.24484000,4.95900000,0.20870633,491.95842907,0.18955064,594.63326895,0.00093326,0.00000000,0.00000000,0.00000000,0.00000000,0.00000000,0.00000000,0.00000000,0.00000000
255.59000000,6.29488600,4.95900000,0.21051111,491.95842907,0.19104268,595.52114459,0.00099413,0.00000000,0.00000000,0.00000000,0.00000000,0.00000000,0.00000000,0.00000000,0.00000000
257.09000000,6.34537300,4.96000000,0.21227811,492.05763423,0.19250133,596.51069939,0.00093051,0.00000000,0.00000000,0.00000000,0.00000000,0.00000000,0.00000000,0.00000000,0.00000000
258.59000000,6.39589300,4.96000000,0.21412044,492.05763423,0.19401990,597.41723357,0.00099118,0.00000000,0.00000000,0.00000000,0.00000000,0.00000000,0.00000000,0.00000000,0.00000000
260.09000000,6.44671800,4.96000000,0.21596278,492.05763423,0.19553617,598.32376775,0.00092788,0.00000000,0.00000000,0.00000000,0.00000000,0.00000000,0.00000000,0.00000000,0.00000000
261.59000000,6.49778000,4.96000000,0.21791789,492.05763423,0.19714275,599.28579510,0.00117357,0.00000000,0.00000000,0.00000000,0.00000000,0.00000000,0.00000000,0.00000000,0.00000000
263.09000000,6.54972100,4.96100000,0.21976011,492.15683940,0.00000000,0.00000000,0.00000000,0.00000000,0.00000000,0.00000000,0.00000000,0.00000000,0.00000000,0.00000000,0.00000000
264.59000000,6.60176400,4.96000000,0.22175278,492.05763423,0.00000000,0.00000000,0.00000000,0.00000000,0.00000000,0.00000000,0.00000000,0.00000000,0.00000000,0.00000000,0.00000000
266.09000000,6.65428100,4.96000000,0.22370789,492.05763423,0.00000000,0.00000000,0.00000000,0.00000000,0.00000000,0.00000000,0.00000000,0.00000000,0.00000000,0.00000000,0.00000000
267.59000000,6.70642600,4.96000000,0.22566300,492.05763423,0.00000000,0.00000000,0.00000000,0.00000000,0.00000000,0.00000000,0.00000000,0.00000000,0.00000000,0.00000000,0.00000000
269.09000000,6.75880700,4.96000000,0.22769333,492.05763423,0.00000000,0.00000000,0.00000000,0.00000000,0.00000000,0.00000000,0.00000000,0.00000000,0.00000000,0.00000000,0.00000000
270.59000000,6.81237300,4.95900000,0.22976111,491.95842907,0.00000000,0.00000000,0.00000000,0.00000000,0.00000000,0.00000000,0.00000000,0.00000000,0.00000000,0.00000000,0.00000000
272.09000000,6.86593800,4.95800000,0.23182900,491.85922390,0.00000000,0.00000000,0.00000000,0.00000000,0.00000000,0.00000000,0.00000000,0.00000000,0.00000000,0.00000000,0.00000000
273.59000000,6.91926700,4.95800000,0.23397211,491.85922390,0.00000000,0.00000000,0.00000000,0.00000000,0.00000000,0.00000000,0.00000000,0.00000000,0.00000000,0.00000000,0.00000000
275.09000000,6.97330600,4.95700000,0.23611511,491.76001873,0.00000000,0.00000000,0.00000000,0.00000000,0.00000000,0.00000000,0.00000000,0.00000000,0.00000000,0.00000000,0.00000000
276.59000000,7.02809000,4.95600000,0.23840867,491.66081356,0.00000000,0.00000000,0.00000000,0.00000000,0.00000000,0.00000000,0.00000000,0.00000000,0.00000000,0.00000000,0.00000000
278.09000000,7.08250100,4.95400000,0.24058933,491.46240323,0.00000000,0.00000000,0.00000000,0.00000000,0.00000000,0.00000000,0.00000000,0.00000000,0.00000000,0.00000000,0.00000000
279.59000000,7.13742000,4.95300000,0.24288278,491.36319806,0.00000000,0.00000000,0.00000000,0.00000000,0.00000000,0.00000000,0.00000000,0.00000000,0.00000000,0.00000000,0.00000000
281.09000000,7.19284600,4.95100000,0.24521389,491.16478772,0.00000000,0.00000000,0.00000000,0.00000000,0.00000000,0.00000000,0.00000000,0.00000000,0.00000000,0.00000000,0.00000000
282.59000000,7.24918600,4.95000000,0.24762011,491.06558255,0.00000000,0.00000000,0.00000000,0.00000000,0.00000000,0.00000000,0.00000000,0.00000000,0.00000000,0.00000000,0.00000000
284.09000000,7.30623600,4.94600000,0.25002644,490.66876188,0.00000000,0.00000000,0.00000000,0.00000000,0.00000000,0.00000000,0.00000000,0.00000000,0.00000000,0.00000000,0.00000000
285.59000000,7.36284700,4.94300000,0.25243267,490.37114638,0.00000000,0.00000000,0.00000000,0.00000000,0.00000000,0.00000000,0.00000000,0.00000000,0.00000000,0.00000000,0.00000000
287.09000000,7.41976200,4.94000000,0.25483900,490.07353087,0.00000000,0.00000000,0.00000000,0.00000000,0.00000000,0.00000000,0.00000000,0.00000000,0.00000000,0.00000000,0.00000000
288.59000000,7.47718600,4.93500000,0.25724522,489.57750503,0.00000000,0.00000000,0.00000000,0.00000000,0.00000000,0.00000000,0.00000000,0.00000000,0.00000000,0.00000000,0.00000000
290.09000000,7.53589400,4.93100000,0.25961400,489.18068436,0.00000000,0.00000000,0.00000000,0.00000000,0.00000000,0.00000000,0.00000000,0.00000000,0.00000000,0.00000000,0.00000000
291.59000000,7.59392600,4.92400000,0.26186989,488.48624818,0.00000000,0.00000000,0.00000000,0.00000000,0.00000000,0.00000000,0.00000000,0.00000000,0.00000000,0.00000000,0.00000000
293.09000000,7.65239800,4.91800000,0.26405067,487.89101717,0.00000000,0.00000000,0.00000000,0.00000000,0.00000000,0.00000000,0.00000000,0.00000000,0.00000000,0.00000000,0.00000000
294.59000000,7.71218900,4.90900000,0.26608100,486.99817066,0.00000000,0.00000000,0.00000000,0.00000000,0.00000000,0.00000000,0.00000000,0.00000000,0.00000000,0.00000000,0.00000000
296.09000000,7.77235100,4.90000000,0.26773567,486.10532414,0.00000000,0.00000000,0.00000000,0.00000000,0.00000000,0.00000000,0.00000000,0.00000000,0.00000000,0.00000000,0.00000000
297.59000000,7.83339000,4.88300000,0.26912744,484.41883628,0.00000000,0.00000000,0.00000000,0.00000000,0.00000000,0.00000000,0.00000000,0.00000000,0.00000000,0.00000000,0.00000000
299.09000000,7.89645600,4.86200000,0.27006889,482.33552775,0.00000000,0.00000000,0.00000000,0.00000000,0.00000000,0.00000000,0.00000000,0.00000000,0.00000000,0.00000000,0.00000000
300.59000000,7.96530400,4.81600000,0.27040967,477.77209001,0.00000000,0.00000000,0.00000000,0.00000000,0.00000000,0.00000000,0.00000000,0.00000000,0.00000000,0.00000000,0.00000000
301.09000000,7.99176100,4.79300000,0.27033600,475.49037115,0.00000000,0.00000000,0.00000000,0.00000000,0.00000000,0.00000000,0.00000000,0.00000000,0.00000000,0.00000000,0.00000000