File: polyN_optimization/AA7020-T6_results/DATA/UT_30_1.csv
Time[s],Displacement[mm],Force[kN],EngStrain_longi,EngStress[MPa],TrueStrain,TrueStress[MPa],TrueStrainRate[1/s],PlasticStrain_longi,PlasticStress[MPa],PlasticStrain_thick,PlasticStrain_width,R-Value,Thickness[mm],Width[mm], Young's Modulus [MPa]
0.62000000,0.00000000,-0.01100000,0.00000000,-1.07943885,0.00000000,-1.07943885,0.00000000,0.00055161,285.34359324,0.00037008,-0.00092169,0.74881145,1.01600000,10.03000000,76583.11149938
1.62000000,0.00336400,-0.01400000,0.00009856,-1.37383126,0.00009855,-1.37396666,0.00012044,0.00124174,292.17592611,-0.00007770,-0.00116404,0.00000000,0.00000000,0.00000000,0.00000000
2.62000000,0.00945200,0.11300000,0.00027100,11.08878090,0.00027096,11.09178596,0.00026772,0.00173457,297.77042006,-0.00036243,-0.00137215,0.00000000,0.00000000,0.00000000,0.00000000
3.62000000,0.01302800,0.29400000,0.00038956,28.85045650,0.00038948,28.86169536,0.00005487,0.00230326,302.99764551,-0.00066218,-0.00164108,0.00000000,0.00000000,0.00000000,0.00000000
4.62000000,0.02002900,0.44500000,0.00065389,43.66820797,0.00065368,43.69676213,0.00038334,0.00297939,307.96697833,-0.00108397,-0.00189542,0.00000000,0.00000000,0.00000000,0.00000000
5.62000000,0.02342000,0.59000000,0.00069222,57.89717462,0.00069198,57.93725233,0.00005263,0.00366713,312.05326208,-0.00150846,-0.00215866,0.00000000,0.00000000,0.00000000,0.00000000
6.62000000,0.03006300,0.73500000,0.00102011,72.12614126,0.00101959,72.19971794,0.00034190,0.00421372,316.59762670,-0.00172712,-0.00248659,0.00000000,0.00000000,0.00000000,0.00000000
7.62000000,0.03504800,0.86700000,0.00104567,85.07940745,0.00104512,85.16837215,0.00016139,0.00497685,320.52091691,-0.00219148,-0.00278537,0.00000000,0.00000000,0.00000000,0.00000000
8.62000000,0.04098100,1.03400000,0.00127311,101.46725179,0.00127230,101.59643087,-0.00004594,0.00570187,323.64152408,-0.00260623,-0.00309564,0.00000000,0.00000000,0.00000000,0.00000000
9.62000000,0.04591100,1.18500000,0.00152100,116.28500326,0.00151984,116.46187275,0.00053393,0.00635681,326.94301941,-0.00290609,-0.00345072,0.00000000,0.00000000,0.00000000,0.00000000
10.62000000,0.05361300,1.31900000,0.00155744,129.43453105,0.00155623,129.63611814,-0.00021166,0.00707791,330.27094370,-0.00332736,-0.00375055,0.00000000,0.00000000,0.00000000,0.00000000
11.62000000,0.05715400,1.46900000,0.00195900,144.15415172,0.00195708,144.43654970,0.00050729,0.00794412,333.25319004,-0.00385828,-0.00408584,0.00000000,0.00000000,0.00000000,0.00000000
12.62000000,0.06417700,1.61800000,0.00191922,158.77564158,0.00191738,159.08036732,-0.00001198,0.00854106,336.04978285,-0.00416276,-0.00437830,0.00000000,0.00000000,0.00000000,0.00000000
13.62000000,0.06971100,1.76600000,0.00228933,173.29900064,0.00228672,173.69573981,0.00015166,0.00933267,338.41626724,-0.00461803,-0.00471464,0.00000000,0.00000000,0.00000000,0.00000000
14.62000000,0.07554600,1.91400000,0.00241156,187.82235969,0.00240865,188.27530375,0.00035651,0.01011570,341.08364566,-0.00510452,-0.00501118,0.00000000,0.00000000,0.00000000,0.00000000
15.62000000,0.08082200,2.06200000,0.00256567,202.34571875,0.00256238,202.86487042,-0.00005031,0.01085526,343.64004382,-0.00554543,-0.00530984,0.00000000,0.00000000,0.00000000,0.00000000
16.62000000,0.08836600,2.19200000,0.00285178,215.10272333,0.00284772,215.71614849,0.00040710,0.01154159,345.98129351,-0.00589678,-0.00564481,0.00000000,0.00000000,0.00000000,0.00000000
17.62000000,0.09230800,2.35200000,0.00292444,230.80365204,0.00292018,231.47862449,0.00002038,0.01241860,348.39248473,-0.00646942,-0.00594918,0.00000000,0.00000000,0.00000000,0.00000000
18.62000000,0.09967600,2.49300000,0.00322011,244.64009546,0.00321494,245.42786375,0.00022352,0.01312953,350.74926108,-0.00684117,-0.00628836,0.00000000,0.00000000,0.00000000,0.00000000
19.62000000,0.10691200,2.63100000,0.00344133,258.18214647,0.00343543,259.07063730,0.00029434,0.01384111,353.00914003,-0.00724667,-0.00659445,0.00000000,0.00000000,0.00000000,0.00000000
20.62000000,0.11661400,2.76000000,0.00372778,270.84102025,0.00372085,271.85065538,0.00030799,0.01463045,355.19941924,-0.00770041,-0.00693004,0.00000000,0.00000000,0.00000000,0.00000000
21.62000000,0.13070600,2.85700000,0.00419511,280.35970828,0.00418634,281.53584840,0.00042781,0.01546665,357.40989428,-0.00819256,-0.00727409,0.00000000,0.00000000,0.00000000,0.00000000
22.62000000,0.14823000,2.94200000,0.00489511,288.70082665,0.00488317,290.11404928,0.00095113,0.01614367,359.36502422,-0.00853133,-0.00761234,0.00000000,0.00000000,0.00000000,0.00000000
23.62000000,0.16877900,2.99900000,0.00536522,294.29428251,0.00535088,295.87323673,0.00032163,0.01692872,361.46275857,-0.00897937,-0.00794935,0.00000000,0.00000000,0.00000000,0.00000000
24.62000000,0.18959800,3.04600000,0.00621144,298.90643032,0.00619223,300.76307100,0.00086747,0.01772263,363.66779485,-0.00947048,-0.00825215,0.00000000,0.00000000,0.00000000,0.00000000
25.62000000,0.20973800,3.09500000,0.00676811,303.71483973,0.00674531,305.77041551,0.00069497,0.01844039,365.74728533,-0.00986372,-0.00857667,0.00000000,0.00000000,0.00000000,0.00000000
26.62000000,0.23058900,3.14100000,0.00749022,308.22885674,0.00746231,310.53755937,0.00064240,0.01916992,367.73301297,-0.01023580,-0.00893412,0.00000000,0.00000000,0.00000000,0.00000000
27.62000000,0.25279300,3.18200000,0.00820478,312.25221972,0.00817130,314.81417979,0.00057448,0.01997552,369.74981470,-0.01075661,-0.00921891,0.00000000,0.00000000,0.00000000,0.00000000
28.62000000,0.27502800,3.22000000,0.00906956,315.98119029,0.00902867,318.84699925,0.00107322,0.02069656,371.73814554,-0.01115188,-0.00954469,0.00000000,0.00000000,0.00000000,0.00000000
29.62000000,0.29689200,3.25400000,0.00961867,319.31763764,0.00957270,322.38904756,0.00052898,0.02140362,373.62273416,-0.01152881,-0.00987482,0.00000000,0.00000000,0.00000000,0.00000000
30.62000000,0.31980300,3.28200000,0.01050600,322.06530016,0.01045120,325.44891821,0.00075158,0.02223978,375.65998827,-0.01205794,-0.01018184,0.00000000,0.00000000,0.00000000,0.00000000
31.62000000,0.34335700,3.31500000,0.01125056,325.30361671,0.01118774,328.96346312,0.00082555,0.02298853,377.36298829,-0.01248370,-0.01050483,0.00000000,0.00000000,0.00000000,0.00000000
32.62000000,0.36701200,3.33600000,0.01201767,327.36436360,0.01194603,331.29851940,0.00080999,0.02369387,379.25490501,-0.01288122,-0.01081265,0.00000000,0.00000000,0.00000000,0.00000000
33.62000000,0.39036300,3.36300000,0.01275478,330.01389532,0.01267412,334.22314922,0.00045316,0.02448704,381.08144628,-0.01334629,-0.01114075,0.00000000,0.00000000,0.00000000,0.00000000
34.62000000,0.41476300,3.38800000,0.01369089,332.46716543,0.01359802,337.01893645,0.00103148,0.02524566,382.99912395,-0.01380486,-0.01144080,0.00000000,0.00000000,0.00000000,0.00000000
35.62000000,0.43939900,3.41200000,0.01439789,334.82230474,0.01429522,339.64303908,0.00077872,0.02597732,384.70562939,-0.01421774,-0.01175958,0.00000000,0.00000000,0.00000000,0.00000000
36.62000000,0.46372900,3.43500000,0.01517989,337.07931324,0.01506583,342.19613976,0.00068177,0.02672000,386.62247823,-0.01461411,-0.01210589,0.00000000,0.00000000,0.00000000,0.00000000
37.62000000,0.48755200,3.45700000,0.01604089,339.23819094,0.01591359,344.67987307,0.00082910,0.02753958,388.47016490,-0.01511898,-0.01242060,0.00000000,0.00000000,0.00000000,0.00000000
38.62000000,0.51140900,3.47900000,0.01683433,341.39706864,0.01669421,347.14426069,0.00095439,0.02826937,390.18346486,-0.01549035,-0.01277902,0.00000000,0.00000000,0.00000000,0.00000000
39.62000000,0.53604400,3.49900000,0.01756000,343.35968473,0.01740760,349.38908079,0.00056199,0.02900209,391.90029194,-0.01591786,-0.01308423,0.00000000,0.00000000,0.00000000,0.00000000
40.62000000,0.56044200,3.51800000,0.01842844,345.22417001,0.01826070,351.58611445,0.00078262,0.02977891,393.53477660,-0.01635453,-0.01342438,0.00000000,0.00000000,0.00000000,0.00000000
41.62000000,0.58436700,3.53700000,0.01925567,347.08865529,0.01907262,353.77207874,0.00092224,0.03050314,395.25300505,-0.01674820,-0.01375495,0.00000000,0.00000000,0.00000000,0.00000000
42.62000000,0.60822500,3.55700000,0.02000011,349.05127138,0.01980274,356.03233559,0.00074458,0.03122415,397.17698004,-0.01716498,-0.01405917,0.00000000,0.00000000,0.00000000,0.00000000
43.62000000,0.63255300,3.57500000,0.02082344,350.81762586,0.02060960,358.12285720,0.00062617,0.03200553,398.61574085,-0.01758361,-0.01442191,0.00000000,0.00000000,0.00000000,0.00000000
44.62000000,0.65712000,3.59400000,0.02169956,352.68211115,0.02146747,360.33515621,0.00093504,0.03276265,400.45681939,-0.01804974,-0.01471291,0.00000000,0.00000000,0.00000000,0.00000000
45.62000000,0.68141700,3.61200000,0.02245533,354.44846563,0.02220692,362.40772407,0.00078715,0.03350381,402.08892580,-0.01841514,-0.01508867,0.00000000,0.00000000,0.00000000,0.00000000
46.62000000,0.70544300,3.63000000,0.02323367,356.21482011,0.02296787,364.49099650,0.00066163,0.03425180,403.72607388,-0.01884048,-0.01541132,0.00000000,0.00000000,0.00000000,0.00000000
47.62000000,0.72957100,3.64800000,0.02409467,357.98117459,0.02380897,366.60661166,0.00085210,0.03504342,405.28055146,-0.01930606,-0.01573736,0.00000000,0.00000000,0.00000000,0.00000000
48.62000000,0.75403600,3.66600000,0.02484667,359.74752907,0.02454301,368.68605601,0.00080744,0.03577423,407.01808769,-0.01971905,-0.01605519,0.00000000,0.00000000,0.00000000,0.00000000
49.62000000,0.77812900,3.68000000,0.02564367,361.12136033,0.02532038,370.38183612,0.00069649,0.03652290,408.45662869,-0.02015015,-0.01637275,0.00000000,0.00000000,0.00000000,0.00000000
50.62000000,0.80222200,3.69700000,0.02649722,362.78958400,0.02615225,372.40250023,0.00086440,0.03730279,410.21901471,-0.02060746,-0.01669533,0.00000000,0.00000000,0.00000000,0.00000000
51.62000000,0.82634800,3.71400000,0.02727178,364.45780768,0.02690653,374.39722002,0.00090790,0.03801887,411.85447171,-0.02102174,-0.01699713,0.00000000,0.00000000,0.00000000,0.00000000
52.62000000,0.85071200,3.73000000,0.02803500,366.02790055,0.02764921,376.28949274,0.00066589,0.03879073,413.30901174,-0.02148123,-0.01730950,0.00000000,0.00000000,0.00000000,0.00000000
53.62000000,0.87483900,3.74600000,0.02888844,367.59799342,0.02847904,378.21732763,0.00078201,0.03951907,414.74745318,-0.02189261,-0.01762646,0.00000000,0.00000000,0.00000000,0.00000000
54.62000000,0.89889900,3.76200000,0.02969678,369.16808629,0.02926437,380.13118891,0.00089086,0.04025841,416.39906691,-0.02232357,-0.01793484,0.00000000,0.00000000,0.00000000,0.00000000
55.62000000,0.92316200,3.77700000,0.03042633,370.64004836,0.02997263,381.91726602,0.00067168,0.04102699,417.96186473,-0.02281279,-0.01821421,0.00000000,0.00000000,0.00000000,0.00000000
56.62000000,0.94722200,3.79200000,0.03128356,372.11201043,0.03080420,383.75299718,0.00076575,0.04178081,419.52065379,-0.02322024,-0.01856057,0.00000000,0.00000000,0.00000000,0.00000000
57.62000000,0.97117900,3.80700000,0.03208067,373.58397249,0.03157683,385.56879539,0.00080156,0.04253518,420.97828753,-0.02365982,-0.01887536,0.00000000,0.00000000,0.00000000,0.00000000
58.62000000,0.99523800,3.82100000,0.03287033,374.95780375,0.03234166,387.28279175,0.00079406,0.04327633,422.32867284,-0.02407894,-0.01919739,0.00000000,0.00000000,0.00000000,0.00000000
59.62000000,1.01966900,3.83700000,0.03368611,376.52789663,0.03313116,389.21165719,0.00068397,0.04402679,423.99603569,-0.02452240,-0.01950439,0.00000000,0.00000000,0.00000000,0.00000000
60.62000000,1.04362700,3.85000000,0.03452467,377.80359708,0.03394206,390.84714034,0.00079988,0.04477942,425.45903726,-0.02494098,-0.01983844,0.00000000,0.00000000,0.00000000,0.00000000
61.62000000,1.06768600,3.86400000,0.03530289,379.17742834,0.03469403,392.56348697,0.00079198,0.04551508,426.81288178,-0.02536010,-0.02015498,0.00000000,0.00000000,0.00000000,0.00000000
62.62000000,1.09150800,3.87800000,0.03608100,380.55125961,0.03544533,394.28192960,0.00069676,0.04626291,428.27775401,-0.02578265,-0.02048026,0.00000000,0.00000000,0.00000000,0.00000000
63.62000000,1.11556800,3.89200000,0.03690056,381.92509087,0.03623603,396.01833890,0.00078326,0.04702645,429.85548080,-0.02623954,-0.02078690,0.00000000,0.00000000,0.00000000,0.00000000
64.62000000,1.13993100,3.90600000,0.03770156,383.29892213,0.03700822,397.74988774,0.00083364,0.04778502,431.22499518,-0.02665733,-0.02112768,0.00000000,0.00000000,0.00000000,0.00000000
65.62000000,1.16426100,3.92000000,0.03848733,384.67275339,0.03776517,399.47778188,0.00074588,0.04850770,432.58077719,-0.02707409,-0.02143361,0.00000000,0.00000000,0.00000000,0.00000000
66.62000000,1.18832000,3.93300000,0.03929944,385.94845385,0.03854688,401.11601367,0.00074530,0.04924243,434.04789908,-0.02746480,-0.02177763,0.00000000,0.00000000,0.00000000,0.00000000
67.62000000,1.21248000,3.94500000,0.04011911,387.12602350,0.03933524,402.65717546,0.00079558,0.05000423,435.32009053,-0.02791125,-0.02209298,0.00000000,0.00000000,0.00000000,0.00000000
68.62000000,1.23674200,3.96000000,0.04092000,388.59798557,0.04010494,404.49941514,0.00079475,0.05072851,436.68199982,-0.02828914,-0.02243937,0.00000000,0.00000000,0.00000000,0.00000000
69.62000000,1.26124200,3.97300000,0.04173200,389.87368603,0.04088471,406.14389469,0.00072905,0.05148628,438.16500586,-0.02873641,-0.02274987,0.00000000,0.00000000,0.00000000,0.00000000
70.62000000,1.28523300,3.98400000,0.04253289,390.95312488,0.04165322,407.58149070,0.00075749,0.05225534,439.55043359,-0.02918663,-0.02306872,0.00000000,0.00000000,0.00000000,0.00000000
71.62000000,1.30912400,3.99700000,0.04336389,392.22882534,0.04245000,409.23739254,0.00081484,0.05302023,440.93592909,-0.02961991,-0.02340032,0.00000000,0.00000000,0.00000000,0.00000000
72.62000000,1.33348700,4.00900000,0.04414211,393.40639499,0.04319560,410.77218379,0.00069862,0.05374011,442.19851584,-0.03006331,-0.02367680,0.00000000,0.00000000,0.00000000,0.00000000
73.62000000,1.35774900,4.02200000,0.04497667,394.68209545,0.04399456,412.43358049,0.00082018,0.05448973,443.58088006,-0.03045248,-0.02403725,0.00000000,0.00000000,0.00000000,0.00000000
74.62000000,1.38197700,4.03400000,0.04575133,395.85966510,0.04473561,413.97077259,0.00071923,0.05520705,444.95066212,-0.03083746,-0.02436959,0.00000000,0.00000000,0.00000000,0.00000000
75.62000000,1.40576600,4.04600000,0.04657100,397.03723475,0.04551911,415.52765581,0.00079067,0.05599207,446.24758733,-0.03132669,-0.02466538,0.00000000,0.00000000,0.00000000,0.00000000
76.62000000,1.42996000,4.05700000,0.04737933,398.11667360,0.04629117,416.97917619,0.00081150,0.05674963,447.42882738,-0.03178208,-0.02496754,0.00000000,0.00000000,0.00000000,0.00000000
77.62000000,1.45476400,4.07000000,0.04819889,399.39237406,0.04707335,418.64264272,0.00079645,0.05747224,448.80627653,-0.03218234,-0.02528990,0.00000000,0.00000000,0.00000000,0.00000000
78.62000000,1.47919600,4.08200000,0.04897733,400.56994371,0.04781572,420.18879137,0.00073143,0.05822023,450.09174396,-0.03263217,-0.02558807,0.00000000,0.00000000,0.00000000,0.00000000
79.62000000,1.50339100,4.09200000,0.04978933,401.55125176,0.04858951,421.54422088,0.00073086,0.05899567,451.39138784,-0.03307376,-0.02592191,0.00000000,0.00000000,0.00000000,0.00000000
80.62000000,1.52761900,4.10300000,0.05061278,402.63069061,0.04937359,423.00894828,0.00078023,0.05974034,452.57335217,-0.03350947,-0.02623087,0.00000000,0.00000000,0.00000000,0.00000000
81.62000000,1.55204900,4.11500000,0.05143611,403.80826026,0.05015695,424.57858680,0.00080097,0.06047455,453.96316379,-0.03393833,-0.02653622,0.00000000,0.00000000,0.00000000,0.00000000
82.62000000,1.57675100,4.12600000,0.05224456,404.88769911,0.05092555,426.04087700,0.00079338,0.06121321,455.25124075,-0.03437124,-0.02684197,0.00000000,0.00000000,0.00000000,0.00000000
83.62000000,1.60081000,4.13700000,0.05303400,405.96713796,0.05167552,427.49719915,0.00078540,0.06195259,456.43564985,-0.03477931,-0.02717328,0.00000000,0.00000000,0.00000000,0.00000000
84.62000000,1.62486800,4.14800000,0.05385744,407.04657681,0.05245719,428.96906520,0.00081347,0.06272140,457.74093533,-0.03521352,-0.02750788,0.00000000,0.00000000,0.00000000,0.00000000
85.62000000,1.64960400,4.15800000,0.05465444,408.02788485,0.05321317,430.32842221,0.00075574,0.06345050,458.81792814,-0.03563594,-0.02781456,0.00000000,0.00000000,0.00000000,0.00000000
86.62000000,1.67410500,4.16900000,0.05545167,409.10732370,0.05396880,431.79300664,0.00071283,0.06420408,460.11950358,-0.03607082,-0.02813325,0.00000000,0.00000000,0.00000000,0.00000000
87.62000000,1.69856800,4.17900000,0.05627122,410.08863174,0.05474499,433.16482027,0.00078320,0.06494665,461.41771765,-0.03645725,-0.02848940,0.00000000,0.00000000,0.00000000,0.00000000
88.62000000,1.72256000,4.18900000,0.05707956,411.06993979,0.05550997,434.53362925,0.00080405,0.06569006,462.61192223,-0.03690686,-0.02878320,0.00000000,0.00000000,0.00000000,0.00000000
89.62000000,1.74699100,4.20000000,0.05788789,412.14937864,0.05627436,436.00783607,0.00077486,0.06642948,463.80582645,-0.03729004,-0.02913944,0.00000000,0.00000000,0.00000000,0.00000000
90.62000000,1.77169300,4.21000000,0.05869244,413.13068668,0.05703460,437.37833656,0.00080997,0.06719406,464.90677116,-0.03773961,-0.02945445,0.00000000,0.00000000,0.00000000,0.00000000
91.62000000,1.79639500,4.22000000,0.05950833,414.11199472,0.05780496,438.75510934,0.00079508,0.06793905,466.10634043,-0.03813514,-0.02980391,0.00000000,0.00000000,0.00000000,0.00000000
92.62000000,1.82106200,4.23000000,0.06033544,415.09330277,0.05858532,440.13814168,0.00078020,0.06868018,467.30565499,-0.03856878,-0.03011140,0.00000000,0.00000000,0.00000000,0.00000000
93.62000000,1.84485000,4.24000000,0.06113633,416.07461081,0.05934035,441.51188691,0.00072305,0.06946021,468.41834568,-0.03899854,-0.03046168,0.00000000,0.00000000,0.00000000,0.00000000
94.62000000,1.86911200,4.24800000,0.06195211,416.85965725,0.06010883,442.68499305,0.00078613,0.07020483,469.51578406,-0.03941312,-0.03079171,0.00000000,0.00000000,0.00000000,0.00000000
95.62000000,1.89361200,4.25800000,0.06272678,417.84096529,0.06083804,444.05078267,0.00070795,0.07093577,470.82154235,-0.03984324,-0.03109253,0.00000000,0.00000000,0.00000000,0.00000000
96.62000000,1.91828000,4.26800000,0.06357256,418.82227334,0.06163358,445.44787558,0.00082736,0.07167237,471.91813640,-0.04024247,-0.03142991,0.00000000,0.00000000,0.00000000,0.00000000
97.62000000,1.94284700,4.27700000,0.06438844,419.70545058,0.06240040,446.72963166,0.00075592,0.07242554,473.02400672,-0.04069104,-0.03173449,0.00000000,0.00000000,0.00000000,0.00000000
98.62000000,1.96765100,4.28700000,0.06519311,420.68675862,0.06315611,448.11263722,0.00072029,0.07318166,474.13272117,-0.04112537,-0.03205629,0.00000000,0.00000000,0.00000000,0.00000000
99.62000000,1.99228400,4.29600000,0.06600900,421.56993586,0.06392177,449.39734576,0.00076916,0.07393025,475.23926885,-0.04156170,-0.03236855,0.00000000,0.00000000,0.00000000,0.00000000
100.62000000,2.01698600,4.30500000,0.06686233,422.45311310,0.06472194,450.69931397,0.00083877,0.07472995,476.37174513,-0.04203259,-0.03269736,0.00000000,0.00000000,0.00000000,0.00000000
101.62000000,2.04128200,4.31400000,0.06765200,423.33629034,0.06546184,451.97583706,0.00073258,0.07550833,477.49551262,-0.04248661,-0.03302172,0.00000000,0.00000000,0.00000000,0.00000000
102.62000000,2.06598300,4.32300000,0.06843022,424.21946758,0.06619049,453.24890002,0.00066859,0.07623443,478.59559314,-0.04291543,-0.03331900,0.00000000,0.00000000,0.00000000,0.00000000
103.62000000,2.09055000,4.33100000,0.06931000,425.00451402,0.06701358,454.46157688,0.00080878,0.07701990,479.61834514,-0.04335221,-0.03366770,0.00000000,0.00000000,0.00000000,0.00000000
104.62000000,2.11586100,4.34000000,0.07009578,425.88769126,0.06774816,455.74062022,0.00076581,0.07780184,480.85564374,-0.04381361,-0.03398823,0.00000000,0.00000000,0.00000000,0.00000000
105.62000000,2.14022500,4.34800000,0.07091544,426.67273769,0.06851384,456.93042452,0.00078640,0.07853795,481.85730309,-0.04423734,-0.03430061,0.00000000,0.00000000,0.00000000,0.00000000
106.62000000,2.16496000,4.35600000,0.07174633,427.45778413,0.06928941,458.12631279,0.00076463,0.07925282,482.84987827,-0.04463335,-0.03461947,0.00000000,0.00000000,0.00000000,0.00000000
107.62000000,2.18959400,4.36500000,0.07254356,428.34096137,0.07003298,459.41433770,0.00076448,0.08007045,484.10912695,-0.04512895,-0.03494150,0.00000000,0.00000000,0.00000000,0.00000000
108.62000000,2.21466800,4.37300000,0.07335556,429.12600780,0.07078977,460.60478451,0.00073573,0.08080823,485.11555000,-0.04553953,-0.03526869,0.00000000,0.00000000,0.00000000,0.00000000
109.62000000,2.23950600,4.38100000,0.07417900,429.91105424,0.07155665,461.80142633,0.00074924,0.08157615,486.13797348,-0.04599095,-0.03558521,0.00000000,0.00000000,0.00000000,0.00000000
110.62000000,2.26451300,4.39000000,0.07499489,430.79423148,0.07231591,463.10159700,0.00074867,0.08231629,487.14808017,-0.04639537,-0.03592092,0.00000000,0.00000000,0.00000000,0.00000000
111.62000000,2.28945000,4.39800000,0.07582967,431.57927791,0.07309215,464.30579070,0.00079004,0.08308632,488.17413246,-0.04684027,-0.03624605,0.00000000,0.00000000,0.00000000,0.00000000
112.62000000,2.31452500,4.40400000,0.07661556,432.16806274,0.07382238,465.27885896,0.00069159,0.08384907,489.19791688,-0.04729069,-0.03655838,0.00000000,0.00000000,0.00000000,0.00000000
113.62000000,2.33980100,4.41300000,0.07748778,433.05123998,0.07463220,466.60741823,0.00078882,0.08459947,490.32513444,-0.04768473,-0.03691474,0.00000000,0.00000000,0.00000000,0.00000000
114.62000000,2.36477300,4.42100000,0.07831122,433.83628642,0.07539613,467.81053625,0.00080203,0.08537594,491.25008086,-0.04812296,-0.03725298,0.00000000,0.00000000,0.00000000,0.00000000
115.62000000,2.38940700,4.42800000,0.07912344,434.52320205,0.07614909,468.90417448,0.00071779,0.08611984,492.26844467,-0.04853384,-0.03758599,0.00000000,0.00000000,0.00000000,0.00000000
116.62000000,2.41465000,4.43500000,0.07996189,435.21011768,0.07692575,470.01034075,0.00075223,0.08689858,493.19690310,-0.04895100,-0.03794758,0.00000000,0.00000000,0.00000000,0.00000000
117.62000000,2.43982600,4.44300000,0.08079267,435.99516411,0.07769472,471.22037608,0.00079299,0.08765474,494.22386063,-0.04941154,-0.03824320,0.00000000,0.00000000,0.00000000,0.00000000
118.62000000,2.46452800,4.45100000,0.08160111,436.78021055,0.07844245,472.42196104,0.00078562,0.08843564,495.15579866,-0.04983941,-0.03859623,0.00000000,0.00000000,0.00000000,0.00000000
119.62000000,2.48960200,4.45700000,0.08240956,437.36899538,0.07918963,473.41237990,0.00074375,0.08920761,496.19319629,-0.05029964,-0.03890797,0.00000000,0.00000000,0.00000000,0.00000000
120.62000000,2.51450700,4.46500000,0.08326289,438.15404181,0.07997768,474.63601311,0.00077764,0.08995181,497.21802004,-0.05070947,-0.03924234,0.00000000,0.00000000,0.00000000,0.00000000
121.62000000,2.54018900,4.47200000,0.08410122,438.84095744,0.08075128,475.74801832,0.00079775,0.09072741,498.15096803,-0.05116413,-0.03956329,0.00000000,0.00000000,0.00000000,0.00000000
122.62000000,2.56522900,4.47900000,0.08493589,439.52787307,0.08152090,476.85956366,0.00070698,0.09148732,499.18619218,-0.05159424,-0.03989308,0.00000000,0.00000000,0.00000000,0.00000000
123.62000000,2.59064200,4.48600000,0.08582322,440.21478870,0.08233843,477.99544034,0.00075492,0.09225817,500.11916106,-0.05202793,-0.04023024,0.00000000,0.00000000,0.00000000,0.00000000
124.62000000,2.61615500,4.49300000,0.08666533,440.90170434,0.08311368,479.11259751,0.00082348,0.09303868,501.05816808,-0.05251363,-0.04052505,0.00000000,0.00000000,0.00000000,0.00000000
125.62000000,2.64170200,4.49900000,0.08751144,441.49048916,0.08389201,480.12595958,0.00078155,0.09380159,501.98946016,-0.05292443,-0.04087716,0.00000000,0.00000000,0.00000000,0.00000000
126.62000000,2.66670900,4.50600000,0.08834989,442.17740479,0.08466269,481.24372938,0.00072559,0.09456920,503.03362668,-0.05338573,-0.04118347,0.00000000,0.00000000,0.00000000,0.00000000
127.62000000,2.69174800,4.51200000,0.08919578,442.76618962,0.08543961,482.25906428,0.00078014,0.09535449,503.97867151,-0.05384589,-0.04150860,0.00000000,0.00000000,0.00000000,0.00000000
128.62000000,2.71688900,4.52000000,0.09003033,443.55123606,0.08620552,483.48430169,0.00085541,0.09610210,504.90575509,-0.05425634,-0.04184576,0.00000000,0.00000000,0.00000000,0.00000000
129.62000000,2.74287800,4.52600000,0.09088022,444.14002088,0.08698491,484.50356468,0.00074490,0.09686741,505.73337457,-0.05469999,-0.04216741,0.00000000,0.00000000,0.00000000,0.00000000
130.62000000,2.76687200,4.53200000,0.09162478,444.72880571,0.08766721,485.47698370,0.00060673,0.09762905,506.77949524,-0.05514007,-0.04248898,0.00000000,0.00000000,0.00000000,0.00000000
131.62000000,2.79380300,4.53900000,0.09256456,445.41572134,0.08852774,486.64542962,0.00076430,0.09841149,507.50824146,-0.05559920,-0.04281229,0.00000000,0.00000000,0.00000000,0.00000000
132.62000000,2.81941700,4.54500000,0.09338800,446.00450617,0.08928113,487.65597499,0.00076352,0.09923044,508.47625431,-0.05606106,-0.04316938,0.00000000,0.00000000,0.00000000,0.00000000
133.62000000,2.84472800,4.55000000,0.09424144,446.49516019,0.09006138,488.57350902,0.00075622,0.09998502,509.41251966,-0.05646562,-0.04351940,0.00000000,0.00000000,0.00000000,0.00000000
134.62000000,2.87020900,4.55700000,0.09511378,447.18207582,0.09085826,489.71525241,0.00079683,0.10074912,510.35481624,-0.05690413,-0.04384498,0.00000000,0.00000000,0.00000000,0.00000000
135.62000000,2.89548400,4.56300000,0.09592578,447.77086065,0.09159947,490.72362872,0.00074796,0.10152744,511.19547283,-0.05735170,-0.04417573,0.00000000,0.00000000,0.00000000,0.00000000
136.62000000,2.92245300,4.56900000,0.09678689,448.35964547,0.09238490,491.75498066,0.00074089,0.10227822,512.02294641,-0.05779229,-0.04448593,0.00000000,0.00000000,0.00000000,0.00000000
137.62000000,2.94773000,4.57500000,0.09767400,448.94843030,0.09319340,492.79901928,0.00084256,0.10306054,512.97798432,-0.05820777,-0.04485277,0.00000000,0.00000000,0.00000000,0.00000000
138.62000000,2.97314200,4.58000000,0.09849000,449.43908432,0.09393651,493.70433974,0.00074621,0.10384033,513.82252790,-0.05865754,-0.04518280,0.00000000,0.00000000,0.00000000,0.00000000
139.62000000,2.99875700,4.58600000,0.09935478,450.02786915,0.09472344,494.74028808,0.00078000,0.10458940,514.65216498,-0.05907256,-0.04551684,0.00000000,0.00000000,0.00000000,0.00000000
140.62000000,3.02477800,4.59200000,0.10021200,450.61665398,0.09550289,495.77385010,0.00075192,0.10538639,515.61822267,-0.05953035,-0.04585604,0.00000000,0.00000000,0.00000000,0.00000000
141.62000000,3.05002100,4.59800000,0.10106544,451.20543880,0.09627830,496.80671701,0.00073074,0.10616291,516.57486677,-0.05997893,-0.04618397,0.00000000,0.00000000,0.00000000,0.00000000
142.62000000,3.07624500,4.60200000,0.10188511,451.59796202,0.09702245,497.60907056,0.00070296,0.10693182,517.30725200,-0.06039300,-0.04653882,0.00000000,0.00000000,0.00000000,0.00000000
143.62000000,3.10267000,4.60800000,0.10279489,452.18674685,0.09784777,498.66923325,0.00077717,0.10769509,518.14836030,-0.06085285,-0.04684224,0.00000000,0.00000000,0.00000000,0.00000000
144.62000000,3.12831900,4.61300000,0.10366733,452.67740087,0.09863857,499.60525988,0.00081100,0.10848773,519.00582033,-0.06131379,-0.04717394,0.00000000,0.00000000,0.00000000,0.00000000
145.62000000,3.15430500,4.61800000,0.10455456,453.16805489,0.09944214,500.54883946,0.00085120,0.10926656,519.85709839,-0.06175635,-0.04751021,0.00000000,0.00000000,0.00000000,0.00000000
146.62000000,3.18029300,4.62300000,0.10538178,453.65870891,0.10019078,501.46607016,0.00076207,0.11006447,520.71941743,-0.06222937,-0.04783511,0.00000000,0.00000000,0.00000000,0.00000000
147.62000000,3.20584100,4.62800000,0.10624267,454.14936293,0.10096929,502.39940232,0.00076811,0.11082201,521.56159003,-0.06265983,-0.04816218,0.00000000,0.00000000,0.00000000,0.00000000
148.62000000,3.23179600,4.63400000,0.10709633,454.73814776,0.10174067,503.43893601,0.00074744,0.11160034,522.30441262,-0.06310192,-0.04849841,0.00000000,0.00000000,0.00000000,0.00000000
149.62000000,3.25808800,4.63900000,0.10796856,455.22880178,0.10252821,504.37919796,0.00072639,0.11235343,523.14616472,-0.06353719,-0.04881624,0.00000000,0.00000000,0.00000000,0.00000000
150.62000000,3.28444700,4.64400000,0.10885589,455.71945581,0.10332875,505.32720225,0.00080720,0.11318185,524.02865594,-0.06403334,-0.04914850,0.00000000,0.00000000,0.00000000,0.00000000
151.62000000,3.31026400,4.64900000,0.10975822,456.21010983,0.10414217,506.28292044,0.00088107,0.11391034,524.85944447,-0.06443697,-0.04947337,0.00000000,0.00000000,0.00000000,0.00000000
152.62000000,3.33686000,4.65400000,0.11058900,456.70076385,0.10489051,507.20684462,0.00082616,0.11476065,525.75568697,-0.06495438,-0.04980627,0.00000000,0.00000000,0.00000000,0.00000000
153.62000000,3.36288000,4.65800000,0.11148756,457.09328707,0.10569926,508.05350030,0.00085909,0.11552925,526.49802286,-0.06540011,-0.05012914,0.00000000,0.00000000,0.00000000,0.00000000
154.62000000,3.38954400,4.66300000,0.11234856,457.58394109,0.10647360,508.99283592,0.00074371,0.11630036,527.24253378,-0.06585529,-0.05044508,0.00000000,0.00000000,0.00000000,0.00000000
155.62000000,3.41620900,4.66800000,0.11322833,458.07459511,0.10726420,509.94161806,0.00079045,0.11707768,527.99119178,-0.06628096,-0.05079671,0.00000000,0.00000000,0.00000000,0.00000000
156.62000000,3.44253500,4.67100000,0.11404800,458.36898753,0.10800023,510.64505381,0.00070885,0.11788888,528.87075820,-0.06675160,-0.05113728,0.00000000,0.00000000,0.00000000,0.00000000
157.62000000,3.46913100,4.67600000,0.11493144,458.85964155,0.10879292,511.59704295,0.00071487,0.11863855,529.60650320,-0.06718216,-0.05145639,0.00000000,0.00000000,0.00000000,0.00000000
158.62000000,3.49545600,4.68000000,0.11584511,459.25216477,0.10961207,512.45428282,0.00082924,0.11944003,530.37074123,-0.06764436,-0.05179566,0.00000000,0.00000000,0.00000000,0.00000000
159.62000000,3.52218800,4.68500000,0.11671733,459.74281879,0.11039343,513.40277462,0.00080152,0.12023632,531.24537660,-0.06808588,-0.05215044,0.00000000,0.00000000,0.00000000,0.00000000
160.62000000,3.54881700,4.68900000,0.11758578,460.13534201,0.11117080,514.24071408,0.00077384,0.12099387,531.98796123,-0.06853751,-0.05245636,0.00000000,0.00000000,0.00000000,0.00000000
161.62000000,3.57555000,4.69400000,0.11847689,460.62599603,0.11196784,515.19953098,0.00084736,0.12179998,532.75743919,-0.06897303,-0.05282695,0.00000000,0.00000000,0.00000000,0.00000000
162.62000000,3.60211200,4.69800000,0.11934911,461.01851925,0.11274737,516.04066972,0.00078633,0.12259582,533.52230955,-0.06944194,-0.05315389,0.00000000,0.00000000,0.00000000,0.00000000
163.62000000,3.62887900,4.70200000,0.12023656,461.41104246,0.11353987,516.88951690,0.00079245,0.12338095,534.28230211,-0.06985805,-0.05352290,0.00000000,0.00000000,0.00000000,0.00000000
164.62000000,3.65642300,4.70500000,0.12109378,461.70543488,0.11430480,517.61509021,0.00076468,0.12416543,535.04282811,-0.07027868,-0.05388675,0.00000000,0.00000000,0.00000000,0.00000000
165.62000000,3.68298500,4.71000000,0.12200378,462.19608890,0.11511617,518.58575782,0.00083816,0.12502005,535.95491200,-0.07081930,-0.05420076,0.00000000,0.00000000,0.00000000,0.00000000
166.62000000,3.70992000,4.71400000,0.12286089,462.58861212,0.11587979,519.42266019,0.00075694,0.12576551,536.58333101,-0.07121164,-0.05455387,0.00000000,0.00000000,0.00000000,0.00000000
167.62000000,3.73678700,4.71900000,0.12377833,463.07926614,0.11669652,520.39844590,0.00080973,0.12658732,537.36672507,-0.07166648,-0.05492084,0.00000000,0.00000000,0.00000000,0.00000000
168.62000000,3.76389100,4.72300000,0.12464689,463.47178936,0.11746911,521.24210599,0.00073577,0.12732849,537.99425015,-0.07206427,-0.05526422,0.00000000,0.00000000,0.00000000,0.00000000
169.62000000,3.79099600,4.72600000,0.12554178,463.76618177,0.11826450,521.98821270,0.00078871,0.12814233,538.77503589,-0.07256466,-0.05557767,0.00000000,0.00000000,0.00000000,0.00000000
170.62000000,3.81745900,4.72900000,0.12641778,464.06057418,0.11904249,522.72608073,0.00076797,0.12891157,539.41923540,-0.07299402,-0.05591756,0.00000000,0.00000000,0.00000000,0.00000000
171.62000000,3.84486800,4.73200000,0.12733889,464.35496660,0.11985989,523.48541209,0.00087383,0.12969669,540.29948467,-0.07345422,-0.05624247,0.00000000,0.00000000,0.00000000,0.00000000
172.62000000,3.87187000,4.73600000,0.12821489,464.74748981,0.12063664,524.33503758,0.00074665,0.13053609,540.98347333,-0.07395956,-0.05657654,0.00000000,0.00000000,0.00000000,0.00000000
173.62000000,3.89951600,4.74000000,0.12911344,465.14001303,0.12143276,525.19584226,0.00085946,0.13135386,541.76998905,-0.07441927,-0.05693458,0.00000000,0.00000000,0.00000000,0.00000000
174.62000000,3.92706000,4.74400000,0.13001200,465.53253625,0.12222825,526.05735235,0.00072559,0.13212381,542.41766485,-0.07489711,-0.05722670,0.00000000,0.00000000,0.00000000,0.00000000
175.62000000,3.95443400,4.74700000,0.13091811,465.82692866,0.12302979,526.81211027,0.00077140,0.13296611,543.21935399,-0.07538237,-0.05758374,0.00000000,0.00000000,0.00000000,0.00000000
176.62000000,3.98191200,4.75000000,0.13183544,466.12132108,0.12384060,527.57263261,0.00083068,0.13376707,543.88552223,-0.07586147,-0.05790559,0.00000000,0.00000000,0.00000000,0.00000000
177.62000000,4.00905000,4.75400000,0.13271144,466.51384429,0.12461427,528.42557042,0.00080315,0.13455281,544.65800987,-0.07629772,-0.05825509,0.00000000,0.00000000,0.00000000,0.00000000
178.62000000,4.03652700,4.75700000,0.13362889,466.80823671,0.12542389,529.18730270,0.00077622,0.13533649,545.31622560,-0.07674099,-0.05859549,0.00000000,0.00000000,0.00000000,0.00000000
179.62000000,4.06410400,4.76000000,0.13447111,467.10262912,0.12616656,529.91443866,0.00074233,0.13620007,546.01910345,-0.07727817,-0.05892190,0.00000000,0.00000000,0.00000000,0.00000000
180.62000000,4.09141200,4.76400000,0.13541100,467.49515234,0.12699470,530.79913841,0.00077500,0.13695808,546.55043806,-0.07767589,-0.05928219,0.00000000,0.00000000,0.00000000,0.00000000
181.62000000,4.11926000,4.76700000,0.13634356,467.78954475,0.12781570,531.56963453,0.00080078,0.13775411,547.33184227,-0.07814963,-0.05960448,0.00000000,0.00000000,0.00000000,0.00000000
182.62000000,4.14636500,4.77000000,0.13723833,468.08393716,0.12860281,532.32299656,0.00083983,0.13854313,547.88148377,-0.07858090,-0.05996223,0.00000000,0.00000000,0.00000000,0.00000000
183.62000000,4.17424800,4.77300000,0.13812200,468.37832958,0.12937954,533.07168122,0.00076027,0.13935899,548.78997292,-0.07905477,-0.06030422,0.00000000,0.00000000,0.00000000,0.00000000
184.62000000,4.20152200,4.77600000,0.13909189,468.67272199,0.13023136,533.86129616,0.00085154,0.14010977,549.43439105,-0.07947360,-0.06063616,0.00000000,0.00000000,0.00000000,0.00000000
185.62000000,4.22879200,4.78000000,0.13997922,469.06524521,0.13101004,534.72463341,0.00081812,0.14094021,550.12363019,-0.07994519,-0.06099502,0.00000000,0.00000000,0.00000000,0.00000000
186.62000000,4.25748800,4.78300000,0.14091167,469.35963762,0.13182765,535.49788643,0.00086382,0.14174270,550.68335917,-0.08042108,-0.06132162,0.00000000,0.00000000,0.00000000,0.00000000
187.62000000,4.28557400,4.78600000,0.14179156,469.65403004,0.13259857,536.24700553,0.00067177,0.14251081,551.33940855,-0.08085613,-0.06165468,0.00000000,0.00000000,0.00000000,0.00000000
188.62000000,4.31325400,4.78800000,0.14279533,469.85029164,0.13347731,536.94272066,0.00092135,0.14327986,551.88171624,-0.08129829,-0.06198157,0.00000000,0.00000000,0.00000000,0.00000000
189.62000000,4.34147400,4.79000000,0.14364511,470.04655325,0.13422063,537.56644262,0.00074318,0.14407879,552.55621888,-0.08176768,-0.06231111,0.00000000,0.00000000,0.00000000,0.00000000
190.62000000,4.36915300,4.79300000,0.14455489,470.34094567,0.13501582,538.33102881,0.00083427,0.14481305,553.19540882,-0.08214511,-0.06266794,0.00000000,0.00000000,0.00000000,0.00000000
191.62000000,4.39727200,4.79600000,0.14544222,470.63533808,0.13579078,539.08558751,0.00073542,0.14554830,553.72058038,-0.08258805,-0.06296024,0.00000000,0.00000000,0.00000000,0.00000000
192.62000000,4.42549300,4.79900000,0.14637456,470.92973049,0.13660440,539.86186049,0.00080676,0.14628299,554.24592167,-0.08299702,-0.06328597,0.00000000,0.00000000,0.00000000,0.00000000
193.62000000,4.45354500,4.80200000,0.14731844,471.22412291,0.13742743,540.64412768,0.00085880,0.00000000,0.00000000,0.00000000,0.00000000,0.00000000,0.00000000,0.00000000,0.00000000
194.62000000,4.48183300,4.80400000,0.14823200,471.42038452,0.13822337,541.29997095,0.00075338,0.00000000,0.00000000,0.00000000,0.00000000,0.00000000,0.00000000,0.00000000,0.00000000
195.62000000,4.51005400,4.80700000,0.14918700,471.71477693,0.13905474,542.08848935,0.00075933,0.00000000,0.00000000,0.00000000,0.00000000,0.00000000,0.00000000,0.00000000,0.00000000
196.62000000,4.53871400,4.80900000,0.15010433,471.91103854,0.13985266,542.74693037,0.00079777,0.00000000,0.00000000,0.00000000,0.00000000,0.00000000,0.00000000,0.00000000,0.00000000
197.62000000,4.56717100,4.81200000,0.15107800,472.20543095,0.14069889,543.54528305,0.00078396,0.00000000,0.00000000,0.00000000,0.00000000,0.00000000,0.00000000,0.00000000,0.00000000
198.62000000,4.59566300,4.81400000,0.15198778,472.40169256,0.14148895,544.20097603,0.00074417,0.00000000,0.00000000,0.00000000,0.00000000,0.00000000,0.00000000,0.00000000,0.00000000
199.62000000,4.62439000,4.81600000,0.15294267,472.59795417,0.14231751,544.87834554,0.00080892,0.00000000,0.00000000,0.00000000,0.00000000,0.00000000,0.00000000,0.00000000,0.00000000
200.62000000,4.65328800,4.81900000,0.15389022,472.89234658,0.14313904,545.66585489,0.00086682,0.00000000,0.00000000,0.00000000,0.00000000,0.00000000,0.00000000,0.00000000,0.00000000
201.62000000,4.68181400,4.82000000,0.15483756,472.99047739,0.14395969,546.22716671,0.00076196,0.00000000,0.00000000,0.00000000,0.00000000,0.00000000,0.00000000,0.00000000,0.00000000
202.62000000,4.71088100,4.82300000,0.15575867,473.28486980,0.14475698,547.00309007,0.00082618,0.00000000,0.00000000,0.00000000,0.00000000,0.00000000,0.00000000,0.00000000,0.00000000
203.62000000,4.73913600,4.82400000,0.15669111,473.38300060,0.14556344,547.55790895,0.00082590,0.00000000,0.00000000,0.00000000,0.00000000,0.00000000,0.00000000,0.00000000,0.00000000
204.62000000,4.76793100,4.82800000,0.15757456,473.77552382,0.14632692,548.43049142,0.00075997,0.00000000,0.00000000,0.00000000,0.00000000,0.00000000,0.00000000,0.00000000,0.00000000
205.62000000,4.79689700,4.82900000,0.15849944,473.87365463,0.14712559,548.98236562,0.00070103,0.00000000,0.00000000,0.00000000,0.00000000,0.00000000,0.00000000,0.00000000,0.00000000
206.62000000,4.82650600,4.83200000,0.15949589,474.16804704,0.14798533,549.79590119,0.00090155,0.00000000,0.00000000,0.00000000,0.00000000,0.00000000,0.00000000,0.00000000,0.00000000
207.62000000,4.85543600,4.83300000,0.16039822,474.26617784,0.14876324,550.33762963,0.00077785,0.00000000,0.00000000,0.00000000,0.00000000,0.00000000,0.00000000,0.00000000,0.00000000
208.62000000,4.88474100,4.83500000,0.16130056,474.46243945,0.14954055,550.99349453,0.00071236,0.00000000,0.00000000,0.00000000,0.00000000,0.00000000,0.00000000,0.00000000,0.00000000
209.62000000,4.91421400,4.83600000,0.16227800,474.56057026,0.15038187,551.57131048,0.00084105,0.00000000,0.00000000,0.00000000,0.00000000,0.00000000,0.00000000,0.00000000,0.00000000
210.62000000,4.94331400,4.83800000,0.16314289,474.75683187,0.15112573,552.21003294,0.00077602,0.00000000,0.00000000,0.00000000,0.00000000,0.00000000,0.00000000,0.00000000,0.00000000
211.62000000,4.97299100,4.84000000,0.16404511,474.95309348,0.15190110,552.86682647,0.00071068,0.00000000,0.00000000,0.00000000,0.00000000,0.00000000,0.00000000,0.00000000,0.00000000
212.62000000,5.00266800,4.84200000,0.16491000,475.14935508,0.15264383,553.50623523,0.00071034,0.00000000,0.00000000,0.00000000,0.00000000,0.00000000,0.00000000,0.00000000,0.00000000
213.62000000,5.03227800,4.84300000,0.16584989,475.24748589,0.15345034,554.06722862,0.00083867,0.00000000,0.00000000,0.00000000,0.00000000,0.00000000,0.00000000,0.00000000,0.00000000
214.62000000,5.06205900,4.84400000,0.16671467,475.34561669,0.15419182,554.59270273,0.00083805,0.00000000,0.00000000,0.00000000,0.00000000,0.00000000,0.00000000,0.00000000,0.00000000
215.62000000,5.09303700,4.84400000,0.16750489,475.34561669,0.00000000,0.00000000,0.00000000,0.00000000,0.00000000,0.00000000,0.00000000,0.00000000,0.00000000,0.00000000,0.00000000