File: polyN_optimization/AA7020-T6_results/DATA/UT_30_2.csv
Time[s],Displacement[mm],Force[kN],EngStrain_longi,EngStress[MPa],TrueStrain,TrueStress[MPa],TrueStrainRate[1/s],PlasticStrain_longi,PlasticStress[MPa],PlasticStrain_thick,PlasticStrain_width,R-Value,Thickness[mm],Width[mm], Young's Modulus [MPa]
0.64000000,0.00000000,-0.01200000,0.00000000,-1.18577075,0.00000000,-1.18577075,0.00000000,0.00058188,288.84200560,0.00036728,-0.00094915,0.75711853,1.01200000,10.00000000,75829.14149333
1.64000000,0.00203300,-0.01600000,0.00001511,-1.58102767,0.00001511,-1.58105156,0.00004578,0.00122034,294.51174418,0.00001753,-0.00123788,0.00000000,0.00000000,0.00000000,0.00000000
2.64000000,0.00726000,0.10800000,0.00016456,10.67193676,0.00016454,10.67369289,0.00014731,0.00172532,300.04945377,-0.00022650,-0.00149882,0.00000000,0.00000000,0.00000000,0.00000000
3.64000000,0.01069300,0.28700000,0.00029444,28.35968379,0.00029440,28.36803415,0.00009553,0.00233439,305.32585903,-0.00057093,-0.00176347,0.00000000,0.00000000,0.00000000,0.00000000
4.64000000,0.01708500,0.43700000,0.00050078,43.18181818,0.00050065,43.20344268,0.00024034,0.00302181,309.73423707,-0.00099043,-0.00203138,0.00000000,0.00000000,0.00000000,0.00000000
5.64000000,0.02058800,0.58200000,0.00059067,57.50988142,0.00059049,57.54385059,0.00012704,0.00367637,314.33874348,-0.00138213,-0.00229424,0.00000000,0.00000000,0.00000000,0.00000000
6.64000000,0.02680100,0.72800000,0.00086211,71.93675889,0.00086174,71.99877637,0.00025691,0.00427604,318.53175419,-0.00168230,-0.00259375,0.00000000,0.00000000,0.00000000,0.00000000
7.64000000,0.03217100,0.87800000,0.00094522,86.75889328,0.00094478,86.84089971,0.00018095,0.00506233,322.38990637,-0.00220231,-0.00286002,0.00000000,0.00000000,0.00000000,0.00000000
8.64000000,0.03764000,1.03000000,0.00117122,101.77865613,0.00117054,101.89786155,-0.00002486,0.00576679,325.92672508,-0.00261948,-0.00314731,0.00000000,0.00000000,0.00000000,0.00000000
9.64000000,0.04293900,1.16600000,0.00141300,115.21739130,0.00141200,115.38019348,0.00043477,0.00644120,329.15772952,-0.00300604,-0.00343516,0.00000000,0.00000000,0.00000000,0.00000000
10.64000000,0.05015300,1.33500000,0.00145244,131.91699605,0.00145139,132.10859816,-0.00012626,0.00717192,332.31160817,-0.00342741,-0.00374451,0.00000000,0.00000000,0.00000000,0.00000000
11.64000000,0.05419700,1.47000000,0.00185967,145.25691700,0.00185794,145.52704644,0.00046763,0.00803526,335.21332894,-0.00397156,-0.00406370,0.00000000,0.00000000,0.00000000,0.00000000
12.64000000,0.06118600,1.63700000,0.00187589,161.75889328,0.00187413,162.06233499,0.00008784,0.00863929,338.03197084,-0.00426053,-0.00437876,0.00000000,0.00000000,0.00000000,0.00000000
13.64000000,0.06668500,1.78800000,0.00218422,176.67984190,0.00218184,177.06574993,0.00017252,0.00949328,340.43631504,-0.00476592,-0.00472735,0.00000000,0.00000000,0.00000000,0.00000000
14.64000000,0.07274300,1.92200000,0.00234822,189.92094862,0.00234547,190.36692521,0.00039179,0.01022055,343.10331304,-0.00515427,-0.00506629,0.00000000,0.00000000,0.00000000,0.00000000
15.64000000,0.07793100,2.07200000,0.00247756,204.74308300,0.00247449,205.25034537,-0.00005098,0.01099297,345.68904216,-0.00560386,-0.00538912,0.00000000,0.00000000,0.00000000,0.00000000
16.64000000,0.08556700,2.23600000,0.00279911,220.94861660,0.00279520,221.56707633,0.00045234,0.01167157,348.04407065,-0.00594716,-0.00572441,0.00000000,0.00000000,0.00000000,0.00000000
17.64000000,0.09015700,2.36700000,0.00286500,233.89328063,0.00286090,234.56338488,0.00001064,0.01254462,350.47075876,-0.00646618,-0.00607844,0.00000000,0.00000000,0.00000000,0.00000000
18.64000000,0.09772600,2.50800000,0.00317444,247.82608696,0.00316942,248.61279710,0.00024302,0.01325869,352.84520741,-0.00682228,-0.00643641,0.00000000,0.00000000,0.00000000,0.00000000
19.64000000,0.10489500,2.64700000,0.00335811,261.56126482,0.00335249,262.43961661,0.00028130,0.01404330,355.14702083,-0.00727583,-0.00676747,0.00000000,0.00000000,0.00000000,0.00000000
20.64000000,0.11546000,2.77400000,0.00373089,274.11067194,0.00372395,275.13334840,0.00035294,0.01477222,357.43237389,-0.00765233,-0.00711989,0.00000000,0.00000000,0.00000000,0.00000000
21.64000000,0.13095900,2.85700000,0.00419033,282.31225296,0.00418158,283.49523541,0.00050993,0.01560806,359.65831091,-0.00818336,-0.00742471,0.00000000,0.00000000,0.00000000,0.00000000
22.64000000,0.14915200,2.93900000,0.00490522,290.41501976,0.00489323,291.83956997,0.00081616,0.01627027,361.62186744,-0.00850841,-0.00776186,0.00000000,0.00000000,0.00000000,0.00000000
23.64000000,0.16966500,2.99600000,0.00538300,296.04743083,0.00536856,297.64105415,0.00033666,0.01708420,363.74492524,-0.00897786,-0.00810633,0.00000000,0.00000000,0.00000000,0.00000000
24.64000000,0.19041400,3.04800000,0.00624800,301.18577075,0.00622856,303.06757945,0.00089704,0.01787176,365.86162886,-0.00944145,-0.00843031,0.00000000,0.00000000,0.00000000,0.00000000
25.64000000,0.21092700,3.09700000,0.00681600,306.02766798,0.00679288,308.11355257,0.00066491,0.01864761,367.97722860,-0.00990679,-0.00874082,0.00000000,0.00000000,0.00000000,0.00000000
26.64000000,0.23225100,3.14200000,0.00757578,310.47430830,0.00754723,312.82639267,0.00067963,0.01938411,369.97961581,-0.01031167,-0.00907244,0.00000000,0.00000000,0.00000000,0.00000000
27.64000000,0.25465700,3.18300000,0.00827522,314.52569170,0.00824117,317.12846169,0.00063397,0.02015726,372.20225325,-0.01078486,-0.00937239,0.00000000,0.00000000,0.00000000,0.00000000
28.64000000,0.27716500,3.22000000,0.00913633,318.18181818,0.00909485,321.08883333,0.00102865,0.02089879,374.00863188,-0.01123522,-0.00966357,0.00000000,0.00000000,0.00000000,0.00000000
29.64000000,0.29919800,3.25000000,0.00973800,321.14624506,0.00969089,324.27356719,0.00054389,0.02165159,376.02585211,-0.01165974,-0.00999185,0.00000000,0.00000000,0.00000000,0.00000000
30.64000000,0.32207600,3.28200000,0.01063300,324.30830040,0.01057687,327.75667055,0.00081132,0.02242707,377.95252672,-0.01212489,-0.01030218,0.00000000,0.00000000,0.00000000,0.00000000
31.64000000,0.34583200,3.31100000,0.01136611,327.17391304,0.01130200,330.89260809,0.00082546,0.02315802,379.86506528,-0.01254131,-0.01061671,0.00000000,0.00000000,0.00000000,0.00000000
32.64000000,0.36992600,3.33800000,0.01214078,329.84189723,0.01206767,333.84643441,0.00081011,0.02392123,381.79267352,-0.01299759,-0.01092364,0.00000000,0.00000000,0.00000000,0.00000000
33.64000000,0.39358100,3.36400000,0.01289633,332.41106719,0.01281388,336.69795112,0.00049743,0.02468869,383.62240501,-0.01343726,-0.01125143,0.00000000,0.00000000,0.00000000,0.00000000
34.64000000,0.41760700,3.39000000,0.01382133,334.98023715,0.01372669,339.61011067,0.00103880,0.02545676,385.35262238,-0.01386081,-0.01159595,0.00000000,0.00000000,0.00000000,0.00000000
35.64000000,0.44210700,3.41300000,0.01453578,337.25296443,0.01443115,342.15519857,0.00067475,0.02619477,387.38116865,-0.01427971,-0.01191506,0.00000000,0.00000000,0.00000000,0.00000000
36.64000000,0.46630200,3.43600000,0.01535533,339.52569170,0.01523863,344.73922187,0.00076310,0.02698939,389.22958757,-0.01474593,-0.01224345,0.00000000,0.00000000,0.00000000,0.00000000
37.64000000,0.49026200,3.45900000,0.01616378,341.79841897,0.01603453,347.32317266,0.00074018,0.02769902,390.84203914,-0.01510108,-0.01259794,0.00000000,0.00000000,0.00000000,0.00000000
38.64000000,0.51445700,3.47800000,0.01700222,343.67588933,0.01685930,349.51914317,0.00096888,0.02846687,392.68513377,-0.01555438,-0.01291249,0.00000000,0.00000000,0.00000000,0.00000000
39.64000000,0.53838000,3.49800000,0.01773156,345.65217391,0.01757619,351.78112464,0.00059094,0.02920662,394.41693790,-0.01595476,-0.01325185,0.00000000,0.00000000,0.00000000,0.00000000
40.64000000,0.56365800,3.51800000,0.01860011,347.62845850,0.01842924,354.09438645,0.00080475,0.02997445,396.16235672,-0.01641781,-0.01355664,0.00000000,0.00000000,0.00000000,0.00000000
41.64000000,0.58778500,3.53800000,0.01943100,349.60474308,0.01924463,356.39791285,0.00080410,0.03071285,397.89852925,-0.01678289,-0.01392996,0.00000000,0.00000000,0.00000000,0.00000000
42.64000000,0.61201300,3.55800000,0.02019422,351.58102767,0.01999302,358.68093307,0.00078127,0.03149377,399.65421932,-0.01726540,-0.01422837,0.00000000,0.00000000,0.00000000,0.00000000
43.64000000,0.63614100,3.57600000,0.02102522,353.35968379,0.02080724,360.78914967,0.00067787,0.03216898,401.16351010,-0.01759480,-0.01457418,0.00000000,0.00000000,0.00000000,0.00000000
44.64000000,0.66053900,3.59500000,0.02183744,355.23715415,0.02160242,362.99462577,0.00089075,0.03296172,403.03204024,-0.01806926,-0.01489245,0.00000000,0.00000000,0.00000000,0.00000000
45.64000000,0.68493800,3.61300000,0.02265700,357.01581028,0.02240414,365.10471749,0.00080895,0.03375302,404.69612778,-0.01854306,-0.01520996,0.00000000,0.00000000,0.00000000,0.00000000
46.64000000,0.70920000,3.63100000,0.02344278,358.79446640,0.02317222,367.20560535,0.00071275,0.03446954,406.22870334,-0.01894697,-0.01552257,0.00000000,0.00000000,0.00000000,0.00000000
47.64000000,0.73366500,3.64800000,0.02431133,360.47430830,0.02402052,369.23791937,0.00080048,0.03522346,407.88215903,-0.01937193,-0.01585153,0.00000000,0.00000000,0.00000000,0.00000000
48.64000000,0.75799400,3.66600000,0.02510089,362.25296443,0.02479104,371.34583584,0.00081439,0.03596254,409.53184155,-0.01980546,-0.01615708,0.00000000,0.00000000,0.00000000,0.00000000
49.64000000,0.78215500,3.68300000,0.02590922,363.93280632,0.02557927,373.36202228,0.00078450,0.03675622,411.10272604,-0.02026838,-0.01648783,0.00000000,0.00000000,0.00000000,0.00000000
50.64000000,0.80628200,3.69700000,0.02669133,365.31620553,0.02634133,375.06698215,0.00077676,0.03746408,412.84777879,-0.02064574,-0.01681833,0.00000000,0.00000000,0.00000000,0.00000000
51.64000000,0.83030800,3.71500000,0.02751467,367.09486166,0.02714294,377.19535441,0.00081984,0.03825274,414.42121680,-0.02114261,-0.01711013,0.00000000,0.00000000,0.00000000,0.00000000
52.64000000,0.85457200,3.73200000,0.02830811,368.77470356,0.02791484,379.21401884,0.00076062,0.03901717,415.88290404,-0.02156069,-0.01745649,0.00000000,0.00000000,0.00000000,0.00000000
53.64000000,0.87910500,3.74600000,0.02913533,370.15810277,0.02871897,380.94278248,0.00085527,0.03977459,417.55167767,-0.02199093,-0.01778366,0.00000000,0.00000000,0.00000000,0.00000000
54.64000000,0.90323100,3.76100000,0.02991733,371.64031621,0.02947854,382.75880343,0.00079591,0.04047211,419.09349308,-0.02236223,-0.01810988,0.00000000,0.00000000,0.00000000,0.00000000
55.64000000,0.92722200,3.77700000,0.03072944,373.22134387,0.03026675,384.69022843,0.00078795,0.04125250,420.56822654,-0.02283019,-0.01842231,0.00000000,0.00000000,0.00000000,0.00000000
56.64000000,0.95148400,3.79200000,0.03154533,374.70355731,0.03105800,386.52370593,0.00078754,0.04198448,422.12875194,-0.02323071,-0.01875377,0.00000000,0.00000000,0.00000000,0.00000000
57.64000000,0.97561100,3.80700000,0.03234622,376.18577075,0.03183410,388.35395929,0.00080889,0.04271727,423.58743105,-0.02364309,-0.01907418,0.00000000,0.00000000,0.00000000,0.00000000
58.64000000,0.99984100,3.82200000,0.03313956,377.66798419,0.03260228,390.18373333,0.00070606,0.04349792,425.17293983,-0.02407899,-0.01941893,0.00000000,0.00000000,0.00000000,0.00000000
59.64000000,1.02444100,3.83500000,0.03394789,378.95256917,0.03338438,391.81720888,0.00080742,0.04426501,426.65042823,-0.02452995,-0.01973506,0.00000000,0.00000000,0.00000000,0.00000000
60.64000000,1.04829800,3.85100000,0.03474500,380.53359684,0.03415502,393.75523666,0.00076319,0.04499240,428.11289545,-0.02492310,-0.02006930,0.00000000,0.00000000,0.00000000,0.00000000
61.64000000,1.07225600,3.86500000,0.03554956,381.91699605,0.03493226,395.49397552,0.00079136,0.04573132,429.47765481,-0.02534964,-0.02038168,0.00000000,0.00000000,0.00000000,0.00000000
62.64000000,1.09573900,3.87800000,0.03635422,383.20158103,0.03570900,397.13257646,0.00076200,0.04654126,431.08450000,-0.02582843,-0.02071283,0.00000000,0.00000000,0.00000000,0.00000000
63.64000000,1.11976500,3.89100000,0.03712867,384.48616601,0.03645600,398.76162470,0.00073228,0.04722441,432.53374425,-0.02620059,-0.02102382,0.00000000,0.00000000,0.00000000,0.00000000
64.64000000,1.14453300,3.90500000,0.03796333,385.86956522,0.03726046,400.51846014,0.00073191,0.04801459,433.92665049,-0.02667059,-0.02134401,0.00000000,0.00000000,0.00000000,0.00000000
65.64000000,1.16859300,3.91900000,0.03877922,387.25296443,0.03804620,402.27033319,0.00091218,0.04876875,435.30576471,-0.02709336,-0.02167539,0.00000000,0.00000000,0.00000000,0.00000000
66.64000000,1.19261800,3.93300000,0.03956500,388.63636364,0.03880236,404.01276136,0.00078852,0.04953854,436.79869657,-0.02753883,-0.02199971,0.00000000,0.00000000,0.00000000,0.00000000
67.64000000,1.21694800,3.94600000,0.04037344,389.92094862,0.03957973,405.66340037,0.00071568,0.05023485,438.15618902,-0.02793463,-0.02230022,0.00000000,0.00000000,0.00000000,0.00000000
68.64000000,1.24060000,3.95700000,0.04117044,391.00790514,0.04034551,407.10587437,0.00077278,0.05102600,439.55734251,-0.02841795,-0.02260804,0.00000000,0.00000000,0.00000000,0.00000000
69.64000000,1.26550600,3.97200000,0.04203144,392.49011858,0.04117212,408.98704519,0.00087348,0.05176564,441.04295616,-0.02881323,-0.02295241,0.00000000,0.00000000,0.00000000,0.00000000
70.64000000,1.28936100,3.98400000,0.04277589,393.67588933,0.04188628,410.51572543,0.00077906,0.05251601,442.21917312,-0.02924930,-0.02326671,0.00000000,0.00000000,0.00000000,0.00000000
71.64000000,1.31416500,3.99600000,0.04361056,394.86166008,0.04268639,412.08179644,0.00074946,0.05327720,443.61273160,-0.02966950,-0.02360770,0.00000000,0.00000000,0.00000000,0.00000000
72.64000000,1.33825800,4.00800000,0.04443778,396.04743083,0.04347873,413.64689855,0.00087126,0.05402210,445.10647437,-0.03010459,-0.02391751,0.00000000,0.00000000,0.00000000,0.00000000
73.64000000,1.36241900,4.02100000,0.04520100,397.33201581,0.04420921,415.29182026,0.00071238,0.05476569,446.39037833,-0.03051439,-0.02425130,0.00000000,0.00000000,0.00000000,0.00000000
74.64000000,1.38647800,4.03200000,0.04601689,398.41897233,0.04498951,416.75297391,0.00070460,0.05552270,447.68203426,-0.03093969,-0.02458301,0.00000000,0.00000000,0.00000000,0.00000000
75.64000000,1.41047000,4.04500000,0.04688167,399.70355731,0.04581590,418.44232625,0.00079745,0.05630237,449.09148353,-0.03139795,-0.02490442,0.00000000,0.00000000,0.00000000,0.00000000
76.64000000,1.43469900,4.05700000,0.04759244,400.88932806,0.04649462,419.96863114,0.00071818,0.05702650,450.37184408,-0.03179832,-0.02522818,0.00000000,0.00000000,0.00000000,0.00000000
77.64000000,1.45926500,4.06700000,0.04843456,401.87747036,0.04729815,421.34222702,0.00072460,0.05779576,451.67437084,-0.03221764,-0.02557811,0.00000000,0.00000000,0.00000000,0.00000000
78.64000000,1.48356200,4.08000000,0.04925422,403.16205534,0.04807965,423.01948880,0.00078145,0.05852938,452.96244263,-0.03265073,-0.02587865,0.00000000,0.00000000,0.00000000,0.00000000
79.64000000,1.50775700,4.09200000,0.05009267,404.34782609,0.04887841,424.60268696,0.00087398,0.05929891,454.16246937,-0.03304409,-0.02625482,0.00000000,0.00000000,0.00000000,0.00000000
80.64000000,1.53218800,4.10200000,0.05084467,405.33596838,0.04959429,425.94514058,0.00070157,0.06005925,455.46613307,-0.03347997,-0.02657928,0.00000000,0.00000000,0.00000000,0.00000000
81.64000000,1.55685600,4.11300000,0.05169056,406.42292490,0.05039892,427.43115168,0.00073673,0.06083499,456.88495859,-0.03393927,-0.02689572,0.00000000,0.00000000,0.00000000,0.00000000
82.64000000,1.58084700,4.12500000,0.05251767,407.60869565,0.05118507,429.01535326,0.00081472,0.06158157,458.07951120,-0.03433625,-0.02724532,0.00000000,0.00000000,0.00000000,0.00000000
83.64000000,1.60490600,4.13500000,0.05330733,408.59683794,0.05193506,430.37804578,0.00079997,0.06234146,459.28178656,-0.03476980,-0.02757166,0.00000000,0.00000000,0.00000000,0.00000000
84.64000000,1.62937100,4.14600000,0.05411933,409.68379447,0.05270566,431.85560830,0.00067788,0.06306241,460.46761695,-0.03518540,-0.02787701,0.00000000,0.00000000,0.00000000,0.00000000
85.64000000,1.65380200,4.15700000,0.05496522,410.77075099,0.05350780,433.34885660,0.00087668,0.06382327,461.78014667,-0.03560114,-0.02822213,0.00000000,0.00000000,0.00000000,0.00000000
86.64000000,1.67850400,4.16600000,0.05576611,411.66007905,0.05426668,434.61676076,0.00077642,0.06456941,463.08759396,-0.03602355,-0.02854586,0.00000000,0.00000000,0.00000000,0.00000000
87.64000000,1.70296900,4.17800000,0.05657078,412.84584980,0.05502855,436.20086063,0.00075457,0.06533745,464.30019605,-0.03647895,-0.02885851,0.00000000,0.00000000,0.00000000,0.00000000
88.64000000,1.72719700,4.18900000,0.05740922,413.93280632,0.05582179,437.69636679,0.00076112,0.06609983,465.61867885,-0.03693130,-0.02916854,0.00000000,0.00000000,0.00000000,0.00000000
89.64000000,1.75189800,4.19800000,0.05819867,414.82213439,0.05656809,438.96422951,0.00082442,0.06685594,466.82901073,-0.03732479,-0.02953115,0.00000000,0.00000000,0.00000000,0.00000000
90.64000000,1.77636200,4.20800000,0.05899211,415.81027668,0.05731762,440.33980272,0.00070331,0.06762692,467.94087437,-0.03777987,-0.02984705,0.00000000,0.00000000,0.00000000,0.00000000
91.64000000,1.80092800,4.21800000,0.05983422,416.79841897,0.05811250,441.73722819,0.00077365,0.06837697,469.25864707,-0.03821463,-0.03016233,0.00000000,0.00000000,0.00000000,0.00000000
92.64000000,1.82515700,4.22800000,0.06065767,417.78656126,0.05888916,443.12851924,0.00079442,0.06913769,470.26149957,-0.03862714,-0.03051056,0.00000000,0.00000000,0.00000000,0.00000000
93.64000000,1.84975900,4.23700000,0.06143589,418.67588933,0.05962260,444.39761475,0.00070127,0.06990873,471.48518516,-0.03911203,-0.03079670,0.00000000,0.00000000,0.00000000,0.00000000
94.64000000,1.87432600,4.24700000,0.06230078,419.66403162,0.06043710,445.80942720,0.00080010,0.07064468,472.69382659,-0.03950485,-0.03113984,0.00000000,0.00000000,0.00000000,0.00000000
95.64000000,1.89865600,4.25600000,0.06309789,420.55335968,0.06118718,447.08938884,0.00077838,0.07141110,473.91856166,-0.03997001,-0.03144110,0.00000000,0.00000000,0.00000000,0.00000000
96.64000000,1.92285000,4.26500000,0.06394000,421.44268775,0.06197900,448.38973320,0.00081308,0.07219201,475.04427826,-0.04041124,-0.03178077,0.00000000,0.00000000,0.00000000,0.00000000
97.64000000,1.94778800,4.27600000,0.06473711,422.52964427,0.06272792,449.88299280,0.00071350,0.07292068,476.14645804,-0.04078001,-0.03214067,0.00000000,0.00000000,0.00000000,0.00000000
98.64000000,1.97252500,4.28400000,0.06559811,423.32015810,0.06353625,451.08916087,0.00084728,0.07369697,477.27290244,-0.04124743,-0.03244954,0.00000000,0.00000000,0.00000000,0.00000000
99.64000000,1.99678600,4.29300000,0.06637633,424.20948617,0.06426630,452.36695642,0.00073367,0.07445185,478.39053206,-0.04164959,-0.03280225,0.00000000,0.00000000,0.00000000,0.00000000
100.64000000,2.02158900,4.30200000,0.06720722,425.09881423,0.06504516,453.66852470,0.00078934,0.07523244,479.62994822,-0.04213848,-0.03309396,0.00000000,0.00000000,0.00000000,0.00000000
101.64000000,2.04619000,4.31100000,0.06804956,425.98814229,0.06583414,454.97644605,0.00079579,0.07599935,480.54038469,-0.04252040,-0.03347895,0.00000000,0.00000000,0.00000000,0.00000000
102.64000000,2.07096000,4.32000000,0.06888033,426.87747036,0.06661168,456.28093281,0.00079497,0.07676975,481.66984470,-0.04299971,-0.03377003,0.00000000,0.00000000,0.00000000,0.00000000
103.64000000,2.09572900,4.32900000,0.06969622,427.76679842,0.06737470,457.58052826,0.00073118,0.07754076,482.69290682,-0.04345102,-0.03408975,0.00000000,0.00000000,0.00000000,0.00000000
104.64000000,2.12029500,4.33600000,0.07051211,428.45849802,0.06813714,458.67001124,0.00073062,0.07832014,483.82963184,-0.04387243,-0.03444770,0.00000000,0.00000000,0.00000000,0.00000000
105.64000000,2.14513300,4.34500000,0.07133933,429.34782609,0.06890958,459.97721377,0.00072321,0.07905428,484.94578991,-0.04428898,-0.03476530,0.00000000,0.00000000,0.00000000,0.00000000
106.64000000,2.17007100,4.35400000,0.07216267,430.23715415,0.06967779,461.28421449,0.00078569,0.07982009,485.97040641,-0.04471146,-0.03510863,0.00000000,0.00000000,0.00000000,0.00000000
107.64000000,2.19473900,4.36200000,0.07298611,431.02766798,0.07044552,462.48670125,0.00076395,0.08057360,487.09883439,-0.04511906,-0.03545454,0.00000000,0.00000000,0.00000000,0.00000000
108.64000000,2.21913600,4.37000000,0.07379444,431.81818182,0.07119859,463.68396465,0.00074247,0.08135056,488.24024649,-0.04559493,-0.03575563,0.00000000,0.00000000,0.00000000,0.00000000
109.64000000,2.24465200,4.37900000,0.07467056,432.70750988,0.07201415,465.01802004,0.00080475,0.08210076,489.26129015,-0.04599590,-0.03610486,0.00000000,0.00000000,0.00000000,0.00000000
110.64000000,2.26969100,4.38600000,0.07549756,433.39920949,0.07278340,466.11979038,0.00078284,0.08289155,490.30364726,-0.04646236,-0.03642919,0.00000000,0.00000000,0.00000000,0.00000000
111.64000000,2.29506700,4.39400000,0.07634356,434.18972332,0.07356970,467.33731058,0.00081052,0.08364395,491.32839287,-0.04684891,-0.03679504,0.00000000,0.00000000,0.00000000,0.00000000
112.64000000,2.31997300,4.40100000,0.07717444,434.88142292,0.07434136,468.44315514,0.00078183,0.08441974,492.36601950,-0.04734160,-0.03707814,0.00000000,0.00000000,0.00000000,0.00000000
113.64000000,2.34508100,4.40900000,0.07799411,435.67193676,0.07510201,469.65178220,0.00076742,0.08520164,493.40802229,-0.04776256,-0.03743908,0.00000000,0.00000000,0.00000000,0.00000000
114.64000000,2.36985100,4.41700000,0.07883622,436.46245059,0.07588289,470.87150134,0.00078062,0.08595915,494.43924119,-0.04820462,-0.03775453,0.00000000,0.00000000,0.00000000,0.00000000
115.64000000,2.39506100,4.42400000,0.07966722,437.15415020,0.07665287,471.98100703,0.00074543,0.08674651,495.48665651,-0.04869418,-0.03805233,0.00000000,0.00000000,0.00000000,0.00000000
116.64000000,2.42023600,4.43200000,0.08052078,437.94466403,0.07744313,473.20830900,0.00082138,0.08748386,496.40113518,-0.04903210,-0.03845175,0.00000000,0.00000000,0.00000000,0.00000000
117.64000000,2.44564900,4.43900000,0.08136678,438.63636364,0.07822578,474.32679116,0.00082073,0.08825650,497.44378109,-0.04950591,-0.03875059,0.00000000,0.00000000,0.00000000,0.00000000
118.64000000,2.47028200,4.44700000,0.08218256,439.42687747,0.07897989,475.54010124,0.00073671,0.08902841,498.48740211,-0.04994833,-0.03908007,0.00000000,0.00000000,0.00000000,0.00000000
119.64000000,2.49589700,4.45300000,0.08301344,440.01976285,0.07974738,476.54731898,0.00078459,0.08978616,499.52524506,-0.05038549,-0.03940066,0.00000000,0.00000000,0.00000000,0.00000000
120.64000000,2.52107200,4.46100000,0.08387822,440.81027668,0.08054556,477.78465903,0.00079791,0.09058212,500.47400044,-0.05085646,-0.03972566,0.00000000,0.00000000,0.00000000,0.00000000
121.64000000,2.54618000,4.46800000,0.08472422,441.50197628,0.08132578,478.90788783,0.00081840,0.09133872,501.51384954,-0.05124638,-0.04009234,0.00000000,0.00000000,0.00000000,0.00000000
122.64000000,2.57172700,4.47500000,0.08555511,442.19367589,0.08209148,480.02560496,0.00075511,0.09212648,502.46094425,-0.05175018,-0.04037630,0.00000000,0.00000000,0.00000000,0.00000000
123.64000000,2.59686900,4.48200000,0.08641233,442.88537549,0.08288083,481.15613419,0.00077538,0.09288673,503.39529358,-0.05216185,-0.04072487,0.00000000,0.00000000,0.00000000,0.00000000
124.64000000,2.62255200,4.48900000,0.08725833,443.57707510,0.08365924,482.28287138,0.00076088,0.09367139,504.23318736,-0.05263676,-0.04103463,0.00000000,0.00000000,0.00000000,0.00000000
125.64000000,2.64789600,4.49600000,0.08810800,444.26877470,0.08444041,483.41240791,0.00075354,0.09440179,505.26469606,-0.05306285,-0.04133895,0.00000000,0.00000000,0.00000000,0.00000000
126.64000000,2.67317200,4.50200000,0.08895011,444.86166008,0.08521403,484.43215417,0.00071131,0.09520725,506.22554684,-0.05349825,-0.04170900,0.00000000,0.00000000,0.00000000,0.00000000
127.64000000,2.69865300,4.50800000,0.08978489,445.45454545,0.08598033,485.44963232,0.00074544,0.09597032,507.27626693,-0.05394666,-0.04202366,0.00000000,0.00000000,0.00000000,0.00000000
128.64000000,2.72379400,4.51500000,0.09065333,446.14624506,0.08677691,486.59088933,0.00077930,0.09674749,508.22517861,-0.05438065,-0.04236684,0.00000000,0.00000000,0.00000000,0.00000000
129.64000000,2.74961200,4.52300000,0.09149556,446.93675889,0.08754883,487.82948595,0.00078562,0.09753574,509.07051548,-0.05487085,-0.04266489,0.00000000,0.00000000,0.00000000,0.00000000
130.64000000,2.77505900,4.52900000,0.09235278,447.52964427,0.08833388,488.86025005,0.00077096,0.09827815,510.00388687,-0.05521831,-0.04305985,0.00000000,0.00000000,0.00000000,0.00000000
131.64000000,2.80104600,4.53500000,0.09319500,448.12252964,0.08910460,489.88530879,0.00078440,0.09910743,510.98307502,-0.05574626,-0.04336117,0.00000000,0.00000000,0.00000000,0.00000000
132.64000000,2.82652600,4.54100000,0.09404089,448.71541502,0.08987808,490.91301151,0.00072161,0.09985179,511.91978762,-0.05614541,-0.04370638,0.00000000,0.00000000,0.00000000,0.00000000
133.64000000,2.85214000,4.54700000,0.09489433,449.30830040,0.09065786,491.94511202,0.00074866,0.10068633,512.90420833,-0.05663051,-0.04405582,0.00000000,0.00000000,0.00000000,0.00000000
134.64000000,2.87785700,4.55300000,0.09579289,449.90118577,0.09147820,492.99852007,0.00080972,0.10144777,513.74121756,-0.05710313,-0.04434464,0.00000000,0.00000000,0.00000000,0.00000000
135.64000000,2.90337100,4.55900000,0.09662378,450.49407115,0.09223617,494.02251017,0.00073370,0.10224551,514.59802828,-0.05753089,-0.04471462,0.00000000,0.00000000,0.00000000,0.00000000
136.64000000,2.92959400,4.56400000,0.09748100,450.98814229,0.09301755,494.95091739,0.00075358,0.10299909,515.43297744,-0.05795538,-0.04504371,0.00000000,0.00000000,0.00000000,0.00000000
137.64000000,2.95534600,4.57000000,0.09835333,451.58102767,0.09381209,495.99552701,0.00073963,0.10384235,516.31553557,-0.05846916,-0.04537319,0.00000000,0.00000000,0.00000000,0.00000000
138.64000000,2.98079200,4.57600000,0.09921433,452.17391304,0.09459568,497.03604638,0.00080741,0.10457660,517.25371702,-0.05885191,-0.04572469,0.00000000,0.00000000,0.00000000,0.00000000
139.64000000,3.00633800,4.58100000,0.10008278,452.66798419,0.09538543,497.97225346,0.00081344,0.10535497,518.10469855,-0.05929613,-0.04605884,0.00000000,0.00000000,0.00000000,0.00000000
140.64000000,3.03225800,4.58700000,0.10092500,453.26086957,0.09615074,499.00622283,0.00077203,0.10616806,519.08629270,-0.05973992,-0.04642814,0.00000000,0.00000000,0.00000000,0.00000000
141.64000000,3.05817800,4.59300000,0.10180478,453.85375494,0.09694954,500.05823561,0.00082609,0.10696187,519.94753788,-0.06019845,-0.04676342,0.00000000,0.00000000,0.00000000,0.00000000
142.64000000,3.08433400,4.59900000,0.10265822,454.44664032,0.09772383,501.09932451,0.00075710,0.10776506,520.81475875,-0.06068984,-0.04707521,0.00000000,0.00000000,0.00000000,0.00000000
143.64000000,3.11018600,4.60300000,0.10354178,454.84189723,0.09852481,501.93703588,0.00081774,0.10856757,521.68270189,-0.06113435,-0.04743322,0.00000000,0.00000000,0.00000000,0.00000000
144.64000000,3.13617300,4.60900000,0.10441033,455.43478261,0.09931156,502.98688007,0.00079012,0.10933946,522.53560494,-0.06158179,-0.04775767,0.00000000,0.00000000,0.00000000,0.00000000
145.64000000,3.16219500,4.61300000,0.10524867,455.83003953,0.10007035,503.80554341,0.00076196,0.11013064,523.39970339,-0.06200933,-0.04812131,0.00000000,0.00000000,0.00000000,0.00000000
146.64000000,3.18838500,4.61800000,0.10612844,456.32411067,0.10086603,504.75307870,0.00076136,0.11091127,524.25928662,-0.06248261,-0.04842866,0.00000000,0.00000000,0.00000000,0.00000000
147.64000000,3.21389900,4.62300000,0.10698944,456.81818182,0.10164412,505.69290530,0.00082885,0.11171255,525.01876028,-0.06294763,-0.04876492,0.00000000,0.00000000,0.00000000,0.00000000
148.64000000,3.24029200,4.62900000,0.10786167,457.41106719,0.10243173,506.74818725,0.00076719,0.11248524,525.87614776,-0.06337720,-0.04910803,0.00000000,0.00000000,0.00000000,0.00000000
149.64000000,3.26638100,4.63400000,0.10876022,457.90513834,0.10324247,507.70700294,0.00083414,0.11326718,526.73947444,-0.06382108,-0.04944609,0.00000000,0.00000000,0.00000000,0.00000000
150.64000000,3.29243600,4.63800000,0.10965133,458.30039526,0.10404585,508.55364466,0.00086092,0.11407324,527.50432166,-0.06426563,-0.04980761,0.00000000,0.00000000,0.00000000,0.00000000
151.64000000,3.31852400,4.64300000,0.11050111,458.79446640,0.10481136,509.49176471,0.00079259,0.11486727,528.37610429,-0.06475312,-0.05011415,0.00000000,0.00000000,0.00000000,0.00000000
152.64000000,3.34471500,4.64800000,0.11135444,459.28853755,0.10557949,510.43235749,0.00081879,0.11567039,529.25380721,-0.06519564,-0.05047475,0.00000000,0.00000000,0.00000000,0.00000000
153.64000000,3.37093900,4.65300000,0.11221178,459.78260870,0.10635063,511.37563261,0.00067604,0.11646781,530.01693281,-0.06564545,-0.05082236,0.00000000,0.00000000,0.00000000,0.00000000
154.64000000,3.39794100,4.65800000,0.11316289,460.27667984,0.10720541,512.36291862,0.00087158,0.11725635,530.88891436,-0.06610885,-0.05114750,0.00000000,0.00000000,0.00000000,0.00000000
155.64000000,3.42473900,4.66300000,0.11403511,460.77075099,0.10798866,513.31479477,0.00074238,0.11808697,531.55887826,-0.06659242,-0.05149455,0.00000000,0.00000000,0.00000000,0.00000000
156.64000000,3.45106600,4.66600000,0.11494122,461.06719368,0.10880169,514.06282044,0.00082293,0.11887748,532.43390426,-0.06704011,-0.05183737,0.00000000,0.00000000,0.00000000,0.00000000
157.64000000,3.47762900,4.67100000,0.11583611,461.56126482,0.10960400,515.02672678,0.00080892,0.11967886,533.20284325,-0.06746515,-0.05221372,0.00000000,0.00000000,0.00000000,0.00000000
158.64000000,3.50419100,4.67500000,0.11671211,461.95652174,0.11038875,515.87244263,0.00084870,0.12046317,533.96350360,-0.06792423,-0.05253895,0.00000000,0.00000000,0.00000000,0.00000000
159.64000000,3.53051800,4.68000000,0.11760322,462.45059289,0.11118641,516.83627273,0.00073365,0.12126153,534.84578744,-0.06836122,-0.05290031,0.00000000,0.00000000,0.00000000,0.00000000
160.64000000,3.55725100,4.68400000,0.11847178,462.84584980,0.11196327,517.68002047,0.00079350,0.12206423,535.61822838,-0.06884250,-0.05322172,0.00000000,0.00000000,0.00000000,0.00000000
161.64000000,3.58401600,4.68900000,0.11940422,463.33992095,0.11279660,518.66466383,0.00088042,0.12289418,536.51967404,-0.06928566,-0.05360851,0.00000000,0.00000000,0.00000000,0.00000000
162.64000000,3.61139100,4.69300000,0.12027267,463.73517787,0.11357211,519.50984433,0.00077873,0.12368387,537.17355210,-0.06973901,-0.05394487,0.00000000,0.00000000,0.00000000,0.00000000
163.64000000,3.63805500,4.69700000,0.12121267,464.13043478,0.11441084,520.38892246,0.00084530,0.12447131,537.94046592,-0.07017633,-0.05429498,0.00000000,0.00000000,0.00000000,0.00000000
164.64000000,3.66519300,4.70000000,0.12212244,464.42687747,0.11522193,521.14382301,0.00083768,0.12527629,538.83143478,-0.07064921,-0.05462708,0.00000000,0.00000000,0.00000000,0.00000000
165.64000000,3.69175600,4.70400000,0.12299478,464.82213439,0.11599903,521.99282951,0.00076338,0.12607555,539.60665998,-0.07109497,-0.05498058,0.00000000,0.00000000,0.00000000,0.00000000
166.64000000,3.71859000,4.70900000,0.12390833,465.31620553,0.11681219,522.97276103,0.00082289,0.12690519,540.28549274,-0.07156552,-0.05533967,0.00000000,0.00000000,0.00000000,0.00000000
167.64000000,3.74552600,4.71300000,0.12482956,465.71146245,0.11763152,523.84601733,0.00085582,0.12771929,541.07055758,-0.07204357,-0.05567573,0.00000000,0.00000000,0.00000000,0.00000000
168.64000000,3.77286700,4.71600000,0.12571689,466.00790514,0.11842007,524.59296917,0.00084843,0.12855398,541.75376074,-0.07251152,-0.05604246,0.00000000,0.00000000,0.00000000,0.00000000
169.64000000,3.79993700,4.72000000,0.12658911,466.40316206,0.11919458,525.44472376,0.00077436,0.12932446,542.51677524,-0.07295562,-0.05636884,0.00000000,0.00000000,0.00000000,0.00000000
170.64000000,3.82660100,4.72300000,0.12748767,466.69960474,0.11999185,526.19804839,0.00080037,0.13016268,543.31772815,-0.07342437,-0.05673830,0.00000000,0.00000000,0.00000000,0.00000000
171.64000000,3.85360300,4.72700000,0.12841267,467.09486166,0.12081193,527.07575843,0.00085330,0.13096443,544.09967408,-0.07386116,-0.05710327,0.00000000,0.00000000,0.00000000,0.00000000
172.64000000,3.88053900,4.73100000,0.12931511,467.49011858,0.12161135,527.94365520,0.00081935,0.13179297,544.78282875,-0.07435498,-0.05743799,0.00000000,0.00000000,0.00000000,0.00000000
173.64000000,3.90825200,4.73500000,0.13025500,467.88537549,0.12244327,528.82978508,0.00087158,0.13260315,545.57117260,-0.07479714,-0.05780602,0.00000000,0.00000000,0.00000000,0.00000000
174.64000000,3.93576400,4.73900000,0.13117622,468.28063241,0.12325800,529.70791671,0.00087106,0.13345625,546.26946741,-0.07531369,-0.05814257,0.00000000,0.00000000,0.00000000,0.00000000
175.64000000,3.96327400,4.74200000,0.13206344,468.57707510,0.12404202,530.45897762,0.00082364,0.13427471,547.06417990,-0.07577379,-0.05850092,0.00000000,0.00000000,0.00000000,0.00000000
176.64000000,3.99037800,4.74500000,0.13299211,468.87351779,0.12486202,531.22999676,0.00086299,0.13510367,547.75084167,-0.07623923,-0.05886444,0.00000000,0.00000000,0.00000000,0.00000000
177.64000000,4.01829400,4.74900000,0.13390956,469.26877470,0.12567145,532.10834776,0.00080250,0.13593373,548.55377778,-0.07670480,-0.05922893,0.00000000,0.00000000,0.00000000,0.00000000
178.64000000,4.04546600,4.75200000,0.13483444,469.56521739,0.12648678,532.87878261,0.00082849,0.13674019,549.11464094,-0.07714246,-0.05959773,0.00000000,0.00000000,0.00000000,0.00000000
179.64000000,4.07318000,4.75500000,0.13569167,469.86166008,0.12724186,533.61797184,0.00071511,0.13758821,549.92925619,-0.07761430,-0.05997391,0.00000000,0.00000000,0.00000000,0.00000000
180.64000000,4.10052100,4.75800000,0.13664289,470.15810277,0.12807908,534.40186416,0.00080037,0.13840627,550.49787154,-0.07808449,-0.06032178,0.00000000,0.00000000,0.00000000,0.00000000
181.64000000,4.12782900,4.76100000,0.13757533,470.45454545,0.12889910,535.17748636,0.00081985,0.13923988,551.30626232,-0.07854126,-0.06069862,0.00000000,0.00000000,0.00000000,0.00000000
182.64000000,4.15547500,4.76400000,0.13850411,470.75098814,0.12971522,535.95193531,0.00082582,0.14006461,551.99531181,-0.07900498,-0.06105964,0.00000000,0.00000000,0.00000000,0.00000000
183.64000000,4.18349300,4.76800000,0.13942522,471.14624506,0.13052394,536.83591498,0.00075901,0.14092903,552.82271301,-0.07948784,-0.06144118,0.00000000,0.00000000,0.00000000,0.00000000
184.64000000,4.21103700,4.77100000,0.14034644,471.44268775,0.13133211,537.60799273,0.00077828,0.14177807,553.52698781,-0.07998786,-0.06179021,0.00000000,0.00000000,0.00000000,0.00000000
185.64000000,4.23898600,4.77400000,0.14131267,471.73913043,0.13217906,538.40184493,0.00087657,0.14261346,554.22444878,-0.08046625,-0.06214720,0.00000000,0.00000000,0.00000000,0.00000000
186.64000000,4.26700400,4.77600000,0.14221122,471.93675889,0.13296605,539.05146219,0.00081652,0.14346580,554.81639447,-0.08093710,-0.06252870,0.00000000,0.00000000,0.00000000,0.00000000
187.64000000,4.29492000,4.78000000,0.14317744,472.33201581,0.13381162,539.95930676,0.00088817,0.14429662,555.51278788,-0.08141373,-0.06288289,0.00000000,0.00000000,0.00000000,0.00000000
188.64000000,4.32280300,4.78200000,0.14409489,472.52964427,0.13461383,540.61875086,0.00081498,0.14516037,556.11243908,-0.08190546,-0.06325491,0.00000000,0.00000000,0.00000000,0.00000000
189.64000000,4.35071900,4.78500000,0.14503856,472.82608696,0.13543831,541.40409964,0.00081450,0.14598809,556.92467295,-0.08236864,-0.06361945,0.00000000,0.00000000,0.00000000,0.00000000
190.64000000,4.37883800,4.78800000,0.14595967,473.12252964,0.13624242,542.17933636,0.00073489,0.14684878,557.64023254,-0.08282782,-0.06402097,0.00000000,0.00000000,0.00000000,0.00000000
191.64000000,4.40682200,4.79100000,0.14692222,473.41897233,0.13708203,542.97473979,0.00085251,0.14767671,558.33818636,-0.08330423,-0.06437248,0.00000000,0.00000000,0.00000000,0.00000000
192.64000000,4.43494000,4.79300000,0.14785100,473.61660079,0.13789150,543.64128883,0.00077338,0.14856926,558.95693844,-0.08384245,-0.06472681,0.00000000,0.00000000,0.00000000,0.00000000
193.64000000,4.46285700,4.79600000,0.14882089,473.91304348,0.13873610,544.44120386,0.00083794,0.14939729,559.53997585,-0.08429793,-0.06509936,0.00000000,0.00000000,0.00000000,0.00000000
194.64000000,4.49168700,4.79900000,0.14979478,474.20948617,0.13958347,545.24359077,0.00085715,0.15031872,560.29292312,-0.08484273,-0.06547600,0.00000000,0.00000000,0.00000000,0.00000000
195.64000000,4.52051700,4.80100000,0.15073467,474.40711462,0.14040058,545.91671291,0.00084969,0.15114380,560.99231963,-0.08528104,-0.06586275,0.00000000,0.00000000,0.00000000,0.00000000
196.64000000,4.54877100,4.80400000,0.15170467,474.70355731,0.14124316,546.71830224,0.00080979,0.15200151,561.59417408,-0.08576656,-0.06623494,0.00000000,0.00000000,0.00000000,0.00000000
197.64000000,4.57719400,4.80500000,0.15264089,474.80237154,0.14205573,547.27662758,0.00077653,0.15289031,562.21426599,-0.08629465,-0.06659566,0.00000000,0.00000000,0.00000000,0.00000000
198.64000000,4.60588900,4.80800000,0.15365600,475.09881423,0.14293603,548.10059763,0.00086064,0.15371486,562.79859132,-0.08673619,-0.06697867,0.00000000,0.00000000,0.00000000,0.00000000
199.64000000,4.63485300,4.81000000,0.15462600,475.29644269,0.14377648,548.78963043,0.00085972,0.00000000,0.00000000,0.00000000,0.00000000,0.00000000,0.00000000,0.00000000,0.00000000
200.64000000,4.66337900,4.81300000,0.15557344,475.59288538,0.14459671,549.58250871,0.00087210,0.00000000,0.00000000,0.00000000,0.00000000,0.00000000,0.00000000,0.00000000,0.00000000
201.64000000,4.69231000,4.81500000,0.15655111,475.79051383,0.14544240,550.27604743,0.00084541,0.00000000,0.00000000,0.00000000,0.00000000,0.00000000,0.00000000,0.00000000,0.00000000
202.64000000,4.72066700,4.81700000,0.15753233,475.98814229,0.14629044,550.97166499,0.00089002,0.00000000,0.00000000,0.00000000,0.00000000,0.00000000,0.00000000,0.00000000,0.00000000
203.64000000,4.74970000,4.81900000,0.15849867,476.18577075,0.14712491,551.66058050,0.00086990,0.00000000,0.00000000,0.00000000,0.00000000,0.00000000,0.00000000,0.00000000,0.00000000
204.64000000,4.77842900,4.82200000,0.15945367,476.48221344,0.14794892,552.45904947,0.00084981,0.00000000,0.00000000,0.00000000,0.00000000,0.00000000,0.00000000,0.00000000,0.00000000
205.64000000,4.80783400,4.82400000,0.16048767,476.67984190,0.14884032,553.18107747,0.00088143,0.00000000,0.00000000,0.00000000,0.00000000,0.00000000,0.00000000,0.00000000,0.00000000
206.64000000,4.83730600,4.82600000,0.16148767,476.87747036,0.14970165,553.88730033,0.00088699,0.00000000,0.00000000,0.00000000,0.00000000,0.00000000,0.00000000,0.00000000,0.00000000
207.64000000,4.86691400,4.82800000,0.16247278,477.07509881,0.15054944,554.58681533,0.00089293,0.00000000,0.00000000,0.00000000,0.00000000,0.00000000,0.00000000,0.00000000,0.00000000
208.64000000,4.89635400,4.83000000,0.16340522,477.27272727,0.15135124,555.26158333,0.00077584,0.00000000,0.00000000,0.00000000,0.00000000,0.00000000,0.00000000,0.00000000,0.00000000
209.64000000,4.92555500,4.83100000,0.16442033,477.37154150,0.15222340,555.86112948,0.00083970,0.00000000,0.00000000,0.00000000,0.00000000,0.00000000,0.00000000,0.00000000,0.00000000
210.64000000,4.95492700,4.83300000,0.16543544,477.56916996,0.15309479,556.57603785,0.00083878,0.00000000,0.00000000,0.00000000,0.00000000,0.00000000,0.00000000,0.00000000,0.00000000
211.64000000,4.98463700,4.83500000,0.16645067,477.76679842,0.15396552,557.29140053,0.00090285,0.00000000,0.00000000,0.00000000,0.00000000,0.00000000,0.00000000,0.00000000,0.00000000
212.64000000,5.01428000,4.83700000,0.16742822,477.96442688,0.15480323,557.98916116,0.00083753,0.00000000,0.00000000,0.00000000,0.00000000,0.00000000,0.00000000,0.00000000,0.00000000
213.64000000,5.04412400,4.83800000,0.16844333,478.06324111,0.15567238,558.58980698,0.00090112,0.00000000,0.00000000,0.00000000,0.00000000,0.00000000,0.00000000,0.00000000,0.00000000
214.64000000,5.07396900,4.84000000,0.16945844,478.26086957,0.15654077,559.30621256,0.00083608,0.00000000,0.00000000,0.00000000,0.00000000,0.00000000,0.00000000,0.00000000,0.00000000
215.64000000,5.10364500,4.84100000,0.17047378,478.35968379,0.15740861,559.90746623,0.00089993,0.00000000,0.00000000,0.00000000,0.00000000,0.00000000,0.00000000,0.00000000,0.00000000
216.64000000,5.13386300,4.84300000,0.17148889,478.55731225,0.15827549,560.62457400,0.00077049,0.00000000,0.00000000,0.00000000,0.00000000,0.00000000,0.00000000,0.00000000,0.00000000
217.64000000,5.16472300,4.84400000,0.17254167,478.65612648,0.15917376,561.24425231,0.00089797,0.00000000,0.00000000,0.00000000,0.00000000,0.00000000,0.00000000,0.00000000,0.00000000
218.64000000,5.19500800,4.84600000,0.17355700,478.85375494,0.16003931,561.96217609,0.00089738,0.00000000,0.00000000,0.00000000,0.00000000,0.00000000,0.00000000,0.00000000,0.00000000
219.64000000,5.22593700,4.84700000,0.17457233,478.95256917,0.16090411,562.56443673,0.00083263,0.00000000,0.00000000,0.00000000,0.00000000,0.00000000,0.00000000,0.00000000,0.00000000
220.64000000,5.25723900,4.84800000,0.17555011,479.05138340,0.16173622,563.14890698,0.00083193,0.00000000,0.00000000,0.00000000,0.00000000,0.00000000,0.00000000,0.00000000,0.00000000
221.64000000,5.28915300,4.84700000,0.17652833,478.95256917,0.00000000,0.00000000,0.00000000,0.00000000,0.00000000,0.00000000,0.00000000,0.00000000,0.00000000,0.00000000,0.00000000