File: polyN_optimization/AA7020-T6_results/DATA/UT_45_2.csv
Time[s],Displacement[mm],Force[kN],EngStrain_longi,EngStress[MPa],TrueStrain,TrueStress[MPa],TrueStrainRate[1/s],PlasticStrain_longi,PlasticStress[MPa],PlasticStrain_thick,PlasticStrain_width,R-Value,Thickness[mm],Width[mm], Young's Modulus [MPa]
0.65000000,0.00000000,-0.00900000,0.00000000,-0.88490355,0.00000000,-0.88490355,0.00000000,0.00051309,239.92156140,-0.00025343,-0.00025966,0.75114807,1.01200000,10.05000000,67934.25659979
1.65000000,0.00524100,-0.01300000,0.00016489,-1.27819401,0.00016488,-1.27840477,0.00031953,0.00071300,252.45001091,-0.00033023,-0.00038276,0.00000000,0.00000000,0.00000000,0.00000000
2.65000000,0.01355900,0.09900000,0.00044711,9.73393900,0.00044701,9.73829115,0.00028167,0.00088359,263.69141381,-0.00035867,-0.00052492,0.00000000,0.00000000,0.00000000,0.00000000
3.65000000,0.01830300,0.28500000,0.00059100,28.02194561,0.00059083,28.03850658,0.00000444,0.00134769,273.13651038,-0.00062299,-0.00072470,0.00000000,0.00000000,0.00000000,0.00000000
4.65000000,0.02534500,0.43600000,0.00089789,42.86866065,0.00089749,42.90715194,0.00037437,0.00183284,280.71283439,-0.00087767,-0.00095516,0.00000000,0.00000000,0.00000000,0.00000000
5.65000000,0.03020100,0.57800000,0.00098956,56.83047215,0.00098907,56.88670905,0.00005484,0.00230241,287.20098532,-0.00112823,-0.00117418,0.00000000,0.00000000,0.00000000,0.00000000
6.65000000,0.03614400,0.72300000,0.00134267,71.08725149,0.00134177,71.18269797,0.00042880,0.00297201,292.96008544,-0.00155429,-0.00141772,0.00000000,0.00000000,0.00000000,0.00000000
7.65000000,0.04261800,0.85400000,0.00136333,83.96751421,0.00136240,84.08198992,0.00014647,0.00353649,297.60197829,-0.00188625,-0.00165025,0.00000000,0.00000000,0.00000000,0.00000000
8.65000000,0.04800600,1.02100000,0.00169656,100.38739111,0.00169512,100.55770389,0.00018170,0.00412461,302.95355930,-0.00221232,-0.00191229,0.00000000,0.00000000,0.00000000,0.00000000
9.65000000,0.05405300,1.15500000,0.00184167,113.56262167,0.00183997,113.77176617,0.00039110,0.00484590,306.95857815,-0.00266614,-0.00217976,0.00000000,0.00000000,0.00000000,0.00000000
10.65000000,0.06063900,1.30500000,0.00201467,128.31101410,0.00201264,128.56951802,-0.00007806,0.00549109,311.04559156,-0.00306118,-0.00242992,0.00000000,0.00000000,0.00000000,0.00000000
11.65000000,0.06580700,1.45300000,0.00230911,142.86276129,0.00230645,143.19264728,0.00049536,0.00612869,314.83648057,-0.00341477,-0.00271392,0.00000000,0.00000000,0.00000000,0.00000000
12.65000000,0.07171200,1.60000000,0.00234033,157.31618587,0.00233760,157.68435818,-0.00003059,0.00687700,318.36832478,-0.00387303,-0.00300397,0.00000000,0.00000000,0.00000000,0.00000000
13.65000000,0.07888700,1.74700000,0.00272911,171.76961045,0.00272539,172.23838880,0.00027150,0.00763979,321.61047097,-0.00434964,-0.00329015,0.00000000,0.00000000,0.00000000,0.00000000
14.65000000,0.08385500,1.89300000,0.00282544,186.12471241,0.00282146,186.65059744,0.00022205,0.00829596,324.72285830,-0.00470616,-0.00358979,0.00000000,0.00000000,0.00000000,0.00000000
15.65000000,0.08994800,2.03600000,0.00307356,200.18484652,0.00306884,200.80012577,0.00010125,0.00907236,327.67884845,-0.00513104,-0.00394132,0.00000000,0.00000000,0.00000000,0.00000000
16.65000000,0.09684300,2.16100000,0.00329700,212.47517354,0.00329158,213.17570419,0.00031787,0.00981669,330.22807881,-0.00554955,-0.00426714,0.00000000,0.00000000,0.00000000,0.00000000
17.65000000,0.10339400,2.31300000,0.00350011,227.42021120,0.00349400,228.21620721,0.00014173,0.01057552,333.28728423,-0.00600552,-0.00457000,0.00000000,0.00000000,0.00000000,0.00000000
18.65000000,0.11036300,2.43100000,0.00376233,239.02227990,0.00375527,239.92156140,0.00021498,0.01125626,335.52206599,-0.00635738,-0.00489888,0.00000000,0.00000000,0.00000000,0.00000000
19.65000000,0.12114000,2.55700000,0.00413300,251.41092954,0.00412448,252.45001091,0.00032136,0.01209428,338.11454054,-0.00683441,-0.00525987,0.00000000,0.00000000,0.00000000,0.00000000
20.65000000,0.13281000,2.67000000,0.00445689,262.52138517,0.00444699,263.69141381,0.00041973,0.01280426,340.56697321,-0.00722958,-0.00557468,0.00000000,0.00000000,0.00000000,0.00000000
21.65000000,0.14843600,2.76400000,0.00505144,271.76371109,0.00503873,273.13651038,0.00048693,0.01356256,342.93894138,-0.00766548,-0.00589708,0.00000000,0.00000000,0.00000000,0.00000000
22.65000000,0.16614200,2.83900000,0.00564211,279.13790730,0.00562625,280.71283439,0.00083789,0.01431662,345.31298966,-0.00809277,-0.00622385,0.00000000,0.00000000,0.00000000,0.00000000
23.65000000,0.18390500,2.90300000,0.00620267,285.43055474,0.00618351,287.20098532,0.00039647,0.01512265,347.60796981,-0.00854271,-0.00657994,0.00000000,0.00000000,0.00000000,0.00000000
24.65000000,0.20401200,2.95900000,0.00695500,290.93662124,0.00693093,292.96008544,0.00084453,0.01580829,349.76340454,-0.00894046,-0.00686783,0.00000000,0.00000000,0.00000000,0.00000000
25.65000000,0.22516700,3.00400000,0.00758678,295.36113897,0.00755814,297.60197829,0.00067941,0.01660976,351.76086712,-0.00941779,-0.00719197,0.00000000,0.00000000,0.00000000,0.00000000
26.65000000,0.24544200,3.05600000,0.00825244,300.47391501,0.00821858,302.95355930,0.00067146,0.01735895,354.04585315,-0.00984546,-0.00751349,0.00000000,0.00000000,0.00000000,0.00000000
27.65000000,0.26625700,3.09400000,0.00903456,304.21017442,0.00899399,306.95857815,0.00064847,0.01816257,356.05041590,-0.01032520,-0.00783738,0.00000000,0.00000000,0.00000000,0.00000000
28.65000000,0.28859500,3.13300000,0.00974156,308.04475645,0.00969441,311.04559156,0.00089394,0.01885598,358.01842684,-0.01065564,-0.00820034,0.00000000,0.00000000,0.00000000,0.00000000
29.65000000,0.31100000,3.16900000,0.01043733,311.58437064,0.01038324,314.83648057,0.00054351,0.01967878,360.13717187,-0.01116242,-0.00851636,0.00000000,0.00000000,0.00000000,0.00000000
30.65000000,0.33269400,3.20200000,0.01124200,314.82901697,0.01117928,318.36832478,0.00085524,0.02043654,362.13426111,-0.01157863,-0.00885791,0.00000000,0.00000000,0.00000000,0.00000000
31.65000000,0.35536900,3.23200000,0.01205800,317.77869546,0.01198588,321.61047097,0.00084005,0.02115356,364.11937703,-0.01199953,-0.00915403,0.00000000,0.00000000,0.00000000,0.00000000
32.65000000,0.37956500,3.26100000,0.01276489,320.63005132,0.01268410,324.72285830,0.00078722,0.02193714,366.03023958,-0.01243065,-0.00950649,0.00000000,0.00000000,0.00000000,0.00000000
33.65000000,0.40318500,3.28800000,0.01359200,323.28476196,0.01350046,327.67884845,0.00064533,0.02271980,367.94363754,-0.01289512,-0.00982468,0.00000000,0.00000000,0.00000000,0.00000000
34.65000000,0.42629800,3.31100000,0.01438167,325.54618213,0.01427923,330.22807881,0.00080832,0.02344501,369.73688256,-0.01328581,-0.01015920,0.00000000,0.00000000,0.00000000,0.00000000
35.65000000,0.45015600,3.33900000,0.01519367,328.29921539,0.01507940,333.28728423,0.00079256,0.02422123,371.75516961,-0.01372773,-0.01049349,0.00000000,0.00000000,0.00000000,0.00000000
36.65000000,0.47452000,3.35900000,0.01591567,330.26566771,0.01579034,335.52206599,0.00064408,0.02496482,373.45872556,-0.01415735,-0.01080747,0.00000000,0.00000000,0.00000000,0.00000000
37.65000000,0.49847800,3.38200000,0.01680300,332.52708788,0.01666339,338.11454054,0.00078409,0.02570996,375.26718557,-0.01458063,-0.01112933,0.00000000,0.00000000,0.00000000,0.00000000
38.65000000,0.52298000,3.40400000,0.01755889,334.69018544,0.01740651,340.56697321,0.00090193,0.02646177,377.08074620,-0.01498549,-0.01147627,0.00000000,0.00000000,0.00000000,0.00000000
39.65000000,0.54663500,3.42500000,0.01836344,336.75496038,0.01819687,342.93894138,0.00070168,0.02722374,378.90078598,-0.01541856,-0.01180518,0.00000000,0.00000000,0.00000000,0.00000000
40.65000000,0.57123600,3.44600000,0.01916433,338.81973532,0.01898301,345.31298966,0.00078228,0.02800325,380.73017831,-0.01585545,-0.01214780,0.00000000,0.00000000,0.00000000,0.00000000
41.65000000,0.59563300,3.46600000,0.02001778,340.78618764,0.01982006,347.60796981,0.00091414,0.02873633,382.44218871,-0.01629817,-0.01243817,0.00000000,0.00000000,0.00000000,0.00000000
42.65000000,0.61945600,3.48500000,0.02074711,342.65431735,0.02053482,349.76340454,0.00067043,0.02950490,384.17028769,-0.01671649,-0.01278841,0.00000000,0.00000000,0.00000000,0.00000000
43.65000000,0.64361700,3.50200000,0.02159311,344.32580182,0.02136328,351.76086712,0.00074342,0.03028155,385.80162310,-0.01720191,-0.01307964,0.00000000,0.00000000,0.00000000,0.00000000
44.65000000,0.66747400,3.52200000,0.02239033,346.29225414,0.02214335,354.04585315,0.00077981,0.03098261,387.61086664,-0.01757009,-0.01341253,0.00000000,0.00000000,0.00000000,0.00000000
45.65000000,0.69278700,3.53900000,0.02324000,347.96373862,0.02297406,356.05041590,0.00088214,0.03174840,389.14017574,-0.01802249,-0.01372591,0.00000000,0.00000000,0.00000000,0.00000000
46.65000000,0.71688000,3.55600000,0.02397700,349.63522309,0.02369407,358.01842684,0.00067591,0.03250013,390.87144711,-0.01844610,-0.01405403,0.00000000,0.00000000,0.00000000,0.00000000
47.65000000,0.74090500,3.57400000,0.02484922,351.40503019,0.02454550,360.13717187,0.00080006,0.03330653,392.52402081,-0.01893783,-0.01436871,0.00000000,0.00000000,0.00000000,0.00000000
48.65000000,0.76489600,3.59100000,0.02565378,353.07651466,0.02533024,362.13426111,0.00085796,0.03399353,394.13176546,-0.01931044,-0.01468310,0.00000000,0.00000000,0.00000000,0.00000000
49.65000000,0.78946400,3.60800000,0.02641700,354.74799913,0.02607410,364.11937703,0.00072520,0.03480222,395.79001898,-0.01979511,-0.01500710,0.00000000,0.00000000,0.00000000,0.00000000
50.65000000,0.81335500,3.62400000,0.02724811,356.32116099,0.02688349,366.03023958,0.00076162,0.03557432,397.43615607,-0.02026001,-0.01531432,0.00000000,0.00000000,0.00000000,0.00000000
51.65000000,0.83778700,3.64000000,0.02807900,357.89432285,0.02769201,367.94363754,0.00089269,0.03628610,398.95740354,-0.02063423,-0.01565186,0.00000000,0.00000000,0.00000000,0.00000000
52.65000000,0.86194700,3.65500000,0.02884978,359.36916209,0.02844146,369.73688256,0.00078247,0.03701162,400.48620979,-0.02104202,-0.01596960,0.00000000,0.00000000,0.00000000,0.00000000
53.65000000,0.88620900,3.67200000,0.02967678,361.04064657,0.02924495,371.75516961,0.00078875,0.03783770,402.26420526,-0.02153024,-0.01630747,0.00000000,0.00000000,0.00000000,0.00000000
54.65000000,0.91040400,3.68600000,0.03046644,362.41716320,0.03001156,373.45872556,0.00077369,0.03856347,403.69426170,-0.02192170,-0.01664177,0.00000000,0.00000000,0.00000000,0.00000000
55.65000000,0.93449800,3.70100000,0.03125978,363.89200244,0.03078114,375.26718557,0.00081686,0.03930293,405.13181261,-0.02234295,-0.01695997,0.00000000,0.00000000,0.00000000,0.00000000
56.65000000,0.95872600,3.71600000,0.03206067,365.36684168,0.03155745,377.08074620,0.00075096,0.04006182,406.68274735,-0.02277607,-0.01728575,0.00000000,0.00000000,0.00000000,0.00000000
57.65000000,0.98265100,3.73100000,0.03287278,366.84168092,0.03234402,378.90078598,0.00077189,0.04085077,408.35176140,-0.02322885,-0.01762192,0.00000000,0.00000000,0.00000000,0.00000000
58.65000000,1.00708300,3.74600000,0.03370378,368.31652017,0.03314825,380.73017831,0.00088784,0.04149929,409.75807576,-0.02356631,-0.01793298,0.00000000,0.00000000,0.00000000,0.00000000
59.65000000,1.03114200,3.76000000,0.03448578,369.69303679,0.03390447,382.44218871,0.00074898,0.04232766,411.34418426,-0.02404503,-0.01828263,0.00000000,0.00000000,0.00000000,0.00000000
60.65000000,1.05554000,3.77400000,0.03530533,371.06955342,0.03469639,384.17028769,0.00078446,0.04307838,412.79665857,-0.02446539,-0.01861300,0.00000000,0.00000000,0.00000000,0.00000000
61.65000000,1.07980300,3.78700000,0.03613256,372.34774743,0.03549509,385.80162310,0.00079113,0.04382609,414.14600047,-0.02488186,-0.01894423,0.00000000,0.00000000,0.00000000,0.00000000
62.65000000,1.10372600,3.80200000,0.03688456,373.82258667,0.03622060,387.61086664,0.00078348,0.04454789,415.79824195,-0.02528204,-0.01926585,0.00000000,0.00000000,0.00000000,0.00000000
63.65000000,1.12744700,3.81400000,0.03770033,375.00245807,0.03700705,389.14017574,0.00068111,0.04536698,417.07736041,-0.02579187,-0.01957512,0.00000000,0.00000000,0.00000000,0.00000000
64.65000000,1.15164200,3.82800000,0.03850500,376.37897469,0.03778218,390.87144711,0.00070241,0.04606905,418.51736513,-0.02616092,-0.01990813,0.00000000,0.00000000,0.00000000,0.00000000
65.65000000,1.17651400,3.84100000,0.03936600,377.65716870,0.03861091,392.52402081,0.00088278,0.04684144,419.98894474,-0.02660337,-0.02023807,0.00000000,0.00000000,0.00000000,0.00000000
66.65000000,1.20064100,3.85400000,0.04010289,378.93536271,0.03931964,394.13176546,0.00066522,0.04757076,421.44434857,-0.02705166,-0.02051910,0.00000000,0.00000000,0.00000000,0.00000000
67.65000000,1.22459800,3.86700000,0.04096767,380.21355672,0.04015073,395.79001898,0.00068645,0.04834544,422.92100406,-0.02748428,-0.02086116,0.00000000,0.00000000,0.00000000,0.00000000
68.65000000,1.24889500,3.88000000,0.04179489,381.49175073,0.04094508,397.43615607,0.00085917,0.04906063,424.26990099,-0.02789430,-0.02116634,0.00000000,0.00000000,0.00000000,0.00000000
69.65000000,1.27305600,3.89200000,0.04255811,382.67162213,0.04167742,398.95740354,0.00075043,0.04981780,425.63852870,-0.02831727,-0.02150053,0.00000000,0.00000000,0.00000000,0.00000000
70.65000000,1.29769000,3.90400000,0.04333633,383.85149352,0.04242359,400.48620979,0.00072068,0.05061814,426.92294968,-0.02880343,-0.02181471,0.00000000,0.00000000,0.00000000,0.00000000
71.65000000,1.32147900,3.91800000,0.04422367,385.22801015,0.04327371,402.26420526,0.00082098,0.05132166,428.48161918,-0.02922826,-0.02209339,0.00000000,0.00000000,0.00000000,0.00000000
72.65000000,1.34567300,3.92900000,0.04500200,386.30955892,0.04401880,403.69426170,0.00080590,0.05207837,429.75097339,-0.02964607,-0.02243230,0.00000000,0.00000000,0.00000000,0.00000000
73.65000000,1.36997000,3.94000000,0.04579533,387.39110770,0.04477768,405.13181261,0.00074790,0.05282738,431.01870719,-0.03008874,-0.02273864,0.00000000,0.00000000,0.00000000,0.00000000
74.65000000,1.39419900,3.95200000,0.04661122,388.57097910,0.04555754,406.68274735,0.00077599,0.05360258,432.40448876,-0.03051332,-0.02308926,0.00000000,0.00000000,0.00000000,0.00000000
75.65000000,1.41808900,3.96500000,0.04746089,389.84917311,0.04636903,408.35176140,0.00090483,0.05432925,433.66599341,-0.03094548,-0.02338376,0.00000000,0.00000000,0.00000000,0.00000000
76.65000000,1.44221800,3.97600000,0.04816033,390.93072188,0.04703656,409.75807576,0.00063147,0.05507513,435.04267325,-0.03135085,-0.02372428,0.00000000,0.00000000,0.00000000,0.00000000
77.65000000,1.46691900,3.98800000,0.04905144,392.11059328,0.04788637,411.34418426,0.00078139,0.05583916,436.32397975,-0.03179564,-0.02404352,0.00000000,0.00000000,0.00000000,0.00000000
78.65000000,1.49141900,3.99900000,0.04985989,393.19214206,0.04865672,412.79665857,0.00077380,0.05660488,437.71306688,-0.03222374,-0.02438114,0.00000000,0.00000000,0.00000000,0.00000000
79.65000000,1.51588300,4.00900000,0.05066433,394.17536822,0.04942266,414.14600047,0.00081616,0.05733060,438.87566919,-0.03261240,-0.02471820,0.00000000,0.00000000,0.00000000,0.00000000
80.65000000,1.54007800,4.02200000,0.05144644,395.45356223,0.05016678,415.79824195,0.00064366,0.05809146,440.26622487,-0.03305185,-0.02503961,0.00000000,0.00000000,0.00000000,0.00000000
81.65000000,1.56433900,4.03100000,0.05232622,396.33846577,0.05100316,417.07736041,0.00087191,0.05880897,441.42837311,-0.03342797,-0.02538100,0.00000000,0.00000000,0.00000000,0.00000000
82.65000000,1.58877000,4.04200000,0.05308578,397.42001455,0.05172469,418.51736513,0.00077143,0.05958772,442.72487916,-0.03389281,-0.02569491,0.00000000,0.00000000,0.00000000,0.00000000
83.65000000,1.61337100,4.05300000,0.05392044,398.50156333,0.05251697,419.98894474,0.00074213,0.06034111,444.01185522,-0.03431799,-0.02602312,0.00000000,0.00000000,0.00000000,0.00000000
84.65000000,1.63726300,4.06400000,0.05471011,399.58311211,0.05326595,421.44434857,0.00067033,0.06108829,445.19199540,-0.03473915,-0.02634913,0.00000000,0.00000000,0.00000000,0.00000000
85.65000000,1.66213400,4.07500000,0.05554856,400.66466089,0.05406059,422.92100406,0.00089789,0.06183003,446.47711638,-0.03515521,-0.02667483,0.00000000,0.00000000,0.00000000,0.00000000
86.65000000,1.68649700,4.08500000,0.05632300,401.64788705,0.05479401,424.26990099,0.00069751,0.06260055,447.67095357,-0.03558766,-0.02701290,0.00000000,0.00000000,0.00000000,0.00000000
87.65000000,1.71096200,4.09500000,0.05714267,402.63111321,0.05556967,425.63852870,0.00076132,0.06335150,448.96359638,-0.03600173,-0.02734977,0.00000000,0.00000000,0.00000000,0.00000000
88.65000000,1.73522300,4.10400000,0.05800744,403.51601675,0.05638737,426.92294968,0.00082478,0.06412229,450.05472471,-0.03645096,-0.02767132,0.00000000,0.00000000,0.00000000,0.00000000
89.65000000,1.75931600,4.11600000,0.05877433,404.69588815,0.05711195,428.48161918,0.00081704,0.06486511,451.34700686,-0.03683837,-0.02802674,0.00000000,0.00000000,0.00000000,0.00000000
90.65000000,1.78418700,4.12500000,0.05959400,405.58079169,0.05788582,429.75097339,0.00072410,0.06559129,452.52714294,-0.03726489,-0.02832640,0.00000000,0.00000000,0.00000000,0.00000000
91.65000000,1.80882200,4.13400000,0.06040611,406.46569524,0.05865196,431.01870719,0.00076589,0.06639342,453.74346511,-0.03775091,-0.02864250,0.00000000,0.00000000,0.00000000,0.00000000
92.65000000,1.83325300,4.14400000,0.06124833,407.44892140,0.05944589,432.40448876,0.00080781,0.06717054,454.95003791,-0.03816504,-0.02900550,0.00000000,0.00000000,0.00000000,0.00000000
93.65000000,1.85724600,4.15300000,0.06203789,408.33382495,0.06018960,433.66599341,0.00075760,0.06789851,456.13569216,-0.03860384,-0.02929466,0.00000000,0.00000000,0.00000000,0.00000000
94.65000000,1.88171100,4.16300000,0.06285011,409.31705111,0.06095408,435.04267325,0.00075012,0.06867232,457.23734107,-0.03901273,-0.02965959,0.00000000,0.00000000,0.00000000,0.00000000
95.65000000,1.90644700,4.17200000,0.06368089,410.20195465,0.06173543,436.32397975,0.00078464,0.06944765,458.44786070,-0.03948411,-0.02996353,0.00000000,0.00000000,0.00000000,0.00000000
96.65000000,1.93135100,4.18200000,0.06451567,411.18518082,0.06251992,437.71306688,0.00077713,0.07017517,459.53112118,-0.03990227,-0.03027291,0.00000000,0.00000000,0.00000000,0.00000000
97.65000000,1.95574900,4.19000000,0.06530522,411.97176174,0.06326135,438.87566919,0.00079096,0.07093535,460.73775569,-0.04029895,-0.03063640,0.00000000,0.00000000,0.00000000,0.00000000
98.65000000,1.98021400,4.20000000,0.06613611,412.95498791,0.06404100,440.26622487,0.00074780,0.07172739,461.85384731,-0.04078085,-0.03094654,0.00000000,0.00000000,0.00000000,0.00000000
99.65000000,2.00525400,4.20800000,0.06691811,413.74156884,0.06477422,441.42837311,0.00069767,0.07245662,462.94218499,-0.04117239,-0.03128423,0.00000000,0.00000000,0.00000000,0.00000000
100.65000000,2.02971900,4.21700000,0.06776800,414.62647238,0.06557049,442.72487916,0.00080329,0.07318874,464.03324927,-0.04156384,-0.03162490,0.00000000,0.00000000,0.00000000,0.00000000
101.65000000,2.05438800,4.22600000,0.06859133,415.51137593,0.06634127,444.01185522,0.00082348,0.07401006,465.16744763,-0.04206409,-0.03194597,0.00000000,0.00000000,0.00000000,0.00000000
102.65000000,2.07881900,4.23400000,0.06940711,416.29795686,0.06710439,445.19199540,0.00078065,0.07477193,466.27532791,-0.04247731,-0.03229462,0.00000000,0.00000000,0.00000000,0.00000000
103.65000000,2.10358800,4.24300000,0.07021922,417.18286040,0.06786351,446.47711638,0.00071670,0.07551800,467.48461485,-0.04291734,-0.03260066,0.00000000,0.00000000,0.00000000,0.00000000
104.65000000,2.12839200,4.25100000,0.07106144,417.96944133,0.06865016,447.67095357,0.00081452,0.07626991,468.48330319,-0.04333615,-0.03293376,0.00000000,0.00000000,0.00000000,0.00000000
105.65000000,2.15333000,4.26000000,0.07188478,418.85434488,0.06941857,448.96359638,0.00075769,0.07707473,469.61581248,-0.04379644,-0.03327829,0.00000000,0.00000000,0.00000000,0.00000000
106.65000000,2.17772700,4.26700000,0.07272711,419.54260319,0.07020411,450.05472471,0.00081346,0.07779636,470.71045956,-0.04418385,-0.03361251,0.00000000,0.00000000,0.00000000,0.00000000
107.65000000,2.20273500,4.27600000,0.07354300,420.42750674,0.07096439,451.34700686,0.00078489,0.07856349,471.72035878,-0.04459167,-0.03397183,0.00000000,0.00000000,0.00000000,0.00000000
108.65000000,2.22750400,4.28400000,0.07434000,421.21408766,0.07170652,452.52714294,0.00068602,0.07935746,472.74432564,-0.04510942,-0.03424804,0.00000000,0.00000000,0.00000000,0.00000000
109.65000000,2.25285000,4.29200000,0.07521978,422.00066859,0.07252509,453.74346511,0.00076940,0.08011510,473.86022129,-0.04548627,-0.03462883,0.00000000,0.00000000,0.00000000,0.00000000
110.65000000,2.27799100,4.30000000,0.07607322,422.78724952,0.07331851,454.95003791,0.00083862,0.08085837,474.97069880,-0.04593424,-0.03492413,0.00000000,0.00000000,0.00000000,0.00000000
111.65000000,2.30299800,4.30800000,0.07687411,423.57383045,0.07406250,456.13569216,0.00075438,0.08165051,475.99794794,-0.04638360,-0.03526691,0.00000000,0.00000000,0.00000000,0.00000000
112.65000000,2.32759800,4.31500000,0.07772378,424.26208877,0.07485120,457.23734107,0.00078164,0.08242482,477.01799111,-0.04681937,-0.03560545,0.00000000,0.00000000,0.00000000,0.00000000
113.65000000,2.35270500,4.32300000,0.07857733,425.04866970,0.07564289,458.44786070,0.00085089,0.08319496,478.03735052,-0.04727889,-0.03591608,0.00000000,0.00000000,0.00000000,0.00000000
114.65000000,2.37781300,4.33000000,0.07937811,425.73692801,0.07638505,459.53112118,0.00080145,0.08393392,479.04298754,-0.04767971,-0.03625421,0.00000000,0.00000000,0.00000000,0.00000000
115.65000000,2.40326000,4.33800000,0.08021656,426.52350894,0.07716154,460.73775569,0.00070327,0.08471508,480.17868339,-0.04815617,-0.03655891,0.00000000,0.00000000,0.00000000,0.00000000
116.65000000,2.42833400,4.34500000,0.08108878,427.21176725,0.07796866,461.85384731,0.00080696,0.08546976,481.19456630,-0.04855810,-0.03691167,0.00000000,0.00000000,0.00000000,0.00000000
117.65000000,2.45306900,4.35200000,0.08189333,427.90002556,0.07871259,462.94218499,0.00078561,0.08624935,482.11523412,-0.04901653,-0.03723281,0.00000000,0.00000000,0.00000000,0.00000000
118.65000000,2.47834600,4.35900000,0.08270167,428.58828388,0.07945946,464.03324927,0.00067353,0.08703347,483.14794795,-0.04946263,-0.03757084,0.00000000,0.00000000,0.00000000,0.00000000
119.65000000,2.50382600,4.36600000,0.08360789,429.27654219,0.08029611,465.16744763,0.00079155,0.08780679,484.17675103,-0.04992706,-0.03787973,0.00000000,0.00000000,0.00000000,0.00000000
120.65000000,2.52890000,4.37300000,0.08445000,429.96480050,0.08107295,466.27532791,0.00083911,0.08852985,485.07349310,-0.05032856,-0.03820130,0.00000000,0.00000000,0.00000000,0.00000000
121.65000000,2.55444700,4.38100000,0.08527711,430.75138143,0.08183536,467.48461485,0.00075530,0.08935436,486.02092689,-0.05082223,-0.03853213,0.00000000,0.00000000,0.00000000,0.00000000
122.65000000,2.57986000,4.38700000,0.08610811,431.34131713,0.08260077,468.48330319,0.00074797,0.09012423,487.16087780,-0.05123369,-0.03889054,0.00000000,0.00000000,0.00000000,0.00000000
123.65000000,2.60523900,4.39400000,0.08699922,432.02957544,0.08342089,469.61581248,0.00085125,0.09087617,488.07529949,-0.05164389,-0.03923228,0.00000000,0.00000000,0.00000000,0.00000000
124.65000000,2.63041500,4.40100000,0.08780000,432.71783376,0.08415731,470.71045956,0.00076765,0.09164102,488.99719785,-0.05206715,-0.03957387,0.00000000,0.00000000,0.00000000,0.00000000
125.65000000,2.65555600,4.40700000,0.08864967,433.30776945,0.08493809,471.72035878,0.00070456,0.09244254,489.93832919,-0.05253294,-0.03990960,0.00000000,0.00000000,0.00000000,0.00000000
126.65000000,2.68089900,4.41300000,0.08952944,433.89770515,0.08574590,472.74432564,0.00082826,0.09319245,490.85517157,-0.05296742,-0.04022502,0.00000000,0.00000000,0.00000000,0.00000000
127.65000000,2.70610800,4.42000000,0.09037167,434.58596346,0.08651862,473.86022129,0.00084148,0.09397919,491.79137155,-0.05341159,-0.04056760,0.00000000,0.00000000,0.00000000,0.00000000
128.65000000,2.73175700,4.42700000,0.09119878,435.27422178,0.08727689,474.97069880,0.00070984,0.09475693,492.83384449,-0.05387072,-0.04088621,0.00000000,0.00000000,0.00000000,0.00000000
129.65000000,2.75737200,4.43300000,0.09207867,435.86415747,0.08808291,475.99794794,0.00076464,0.09550192,493.75175497,-0.05424451,-0.04125741,0.00000000,0.00000000,0.00000000,0.00000000
130.65000000,2.78258200,4.43900000,0.09293967,436.45409317,0.08887101,477.01799111,0.00083971,0.09627979,494.68715130,-0.05470926,-0.04157053,0.00000000,0.00000000,0.00000000,0.00000000
131.65000000,2.80819800,4.44500000,0.09379678,437.04402887,0.08965493,478.03735052,0.00080429,0.09707560,495.52287331,-0.05515929,-0.04191631,0.00000000,0.00000000,0.00000000,0.00000000
132.65000000,2.83377900,4.45100000,0.09462022,437.63396456,0.09040747,479.04298754,0.00074885,0.09785218,496.45991531,-0.05561140,-0.04224078,0.00000000,0.00000000,0.00000000,0.00000000
133.65000000,2.85932600,4.45800000,0.09549244,438.32222288,0.09120398,480.17868339,0.00078255,0.09861819,497.39284447,-0.05603969,-0.04257850,0.00000000,0.00000000,0.00000000,0.00000000
134.65000000,2.88504300,4.46400000,0.09633456,438.91215857,0.09197239,481.19456630,0.00077506,0.09942388,498.34684065,-0.05652366,-0.04290022,0.00000000,0.00000000,0.00000000,0.00000000
135.65000000,2.91055600,4.46900000,0.09720322,439.40377166,0.09276442,482.11523412,0.00074709,0.10023900,499.30681612,-0.05699060,-0.04324841,0.00000000,0.00000000,0.00000000,0.00000000
136.65000000,2.93637400,4.47500000,0.09807922,439.99370735,0.09356249,483.14794795,0.00077403,0.10098773,500.12435402,-0.05738822,-0.04359951,0.00000000,0.00000000,0.00000000,0.00000000
137.65000000,2.96236300,4.48100000,0.09894400,440.58364305,0.09434972,484.17675103,0.00079405,0.10177459,501.07242759,-0.05786778,-0.04390681,0.00000000,0.00000000,0.00000000,0.00000000
138.65000000,2.98733500,4.48600000,0.09975222,441.07525613,0.09508490,485.07349310,0.00067683,0.10254566,501.90329512,-0.05831864,-0.04422702,0.00000000,0.00000000,0.00000000,0.00000000
139.65000000,3.01366000,4.49100000,0.10067344,441.56686921,0.09592221,486.02092689,0.00079947,0.10334942,502.75171070,-0.05877643,-0.04457299,0.00000000,0.00000000,0.00000000,0.00000000
140.65000000,3.03903900,4.49800000,0.10153811,442.25512752,0.09670749,487.16087780,0.00083981,0.10411250,503.58055991,-0.05922455,-0.04488795,0.00000000,0.00000000,0.00000000,0.00000000
141.65000000,3.06533000,4.50300000,0.10238033,442.74674061,0.09747178,488.07529949,0.00074358,0.10489017,504.52850309,-0.05963207,-0.04525810,0.00000000,0.00000000,0.00000000,0.00000000
142.65000000,3.09101200,4.50800000,0.10323756,443.23835369,0.09824909,488.99719785,0.00070895,0.10569403,505.49096621,-0.06012432,-0.04556971,0.00000000,0.00000000,0.00000000,0.00000000
143.65000000,3.11713500,4.51300000,0.10413622,443.72996677,0.09906333,489.93832919,0.00081065,0.10650994,506.23905423,-0.06059547,-0.04591447,0.00000000,0.00000000,0.00000000,0.00000000
144.65000000,3.14295300,4.51800000,0.10497822,444.22157985,0.09982563,490.85517157,0.00076195,0.10727571,507.18438716,-0.06099980,-0.04627592,0.00000000,0.00000000,0.00000000,0.00000000
145.65000000,3.16873700,4.52300000,0.10586189,444.71319293,0.10062502,491.79137155,0.00075491,0.10806223,508.03044695,-0.06149607,-0.04656616,0.00000000,0.00000000,0.00000000,0.00000000
146.65000000,3.19492800,4.52900000,0.10673789,445.30312863,0.10141685,492.83384449,0.00082220,0.10883159,508.86874958,-0.06192291,-0.04690868,0.00000000,0.00000000,0.00000000,0.00000000
147.65000000,3.22101800,4.53400000,0.10757644,445.79474171,0.10217424,493.75175497,0.00080813,0.10961683,509.71620966,-0.06237978,-0.04723705,0.00000000,0.00000000,0.00000000,0.00000000
148.65000000,3.24666700,4.53900000,0.10845233,446.28635479,0.10296475,494.68715130,0.00067814,0.11045461,510.59171770,-0.06286562,-0.04758899,0.00000000,0.00000000,0.00000000,0.00000000
149.65000000,3.27302700,4.54300000,0.10934733,446.67964525,0.10377185,495.52287331,0.00074592,0.11123862,511.44065959,-0.06328308,-0.04795554,0.00000000,0.00000000,0.00000000,0.00000000
150.65000000,3.29915000,4.54800000,0.11022322,447.17125833,0.10456110,496.45991531,0.00082643,0.11201499,512.06366971,-0.06376628,-0.04824871,0.00000000,0.00000000,0.00000000,0.00000000
151.65000000,3.32547500,4.55300000,0.11108800,447.66287141,0.10533972,497.39284447,0.00075816,0.11279280,513.02289740,-0.06418733,-0.04860547,0.00000000,0.00000000,0.00000000,0.00000000
152.65000000,3.35193500,4.55800000,0.11199789,448.15448449,0.10615830,498.34684065,0.00081172,0.11365259,513.80236105,-0.06471721,-0.04893538,0.00000000,0.00000000,0.00000000,0.00000000
153.65000000,3.37822800,4.56300000,0.11291911,448.64609758,0.10698639,499.30681612,0.00085859,0.11437620,514.73580414,-0.06511973,-0.04925647,0.00000000,0.00000000,0.00000000,0.00000000
154.65000000,3.40451900,4.56700000,0.11376500,449.03938804,0.10774617,500.12435402,0.00081702,0.11521638,515.61900707,-0.06560282,-0.04961356,0.00000000,0.00000000,0.00000000,0.00000000
155.65000000,3.43131900,4.57200000,0.11465600,449.53100112,0.10854584,501.07242759,0.00078944,0.11597337,516.46008719,-0.06604843,-0.04992495,0.00000000,0.00000000,0.00000000,0.00000000
156.65000000,3.45784700,4.57600000,0.11552833,449.92429159,0.10932813,501.90329512,0.00070791,0.11680049,517.22663136,-0.06650428,-0.05029622,0.00000000,0.00000000,0.00000000,0.00000000
157.65000000,3.48366500,4.58000000,0.11643811,450.31758205,0.11014336,502.75171070,0.00084891,0.11758896,517.86178790,-0.06696555,-0.05062341,0.00000000,0.00000000,0.00000000,0.00000000
158.65000000,3.51043000,4.58400000,0.11730289,450.71087251,0.11091765,503.58055991,0.00076727,0.11839675,518.73221219,-0.06742144,-0.05097531,0.00000000,0.00000000,0.00000000,0.00000000
159.65000000,3.53689200,4.58900000,0.11818644,451.20248560,0.11170813,504.52850309,0.00078694,0.11917580,519.47634976,-0.06782978,-0.05134601,0.00000000,0.00000000,0.00000000,0.00000000
160.65000000,3.56369300,4.59400000,0.11910022,451.69409868,0.11252499,505.49096621,0.00080001,0.11999036,520.23995350,-0.06833456,-0.05165580,0.00000000,0.00000000,0.00000000,0.00000000
161.65000000,3.59052700,4.59700000,0.12002500,451.98906653,0.11335101,506.23905423,0.00085949,0.12078764,520.99539847,-0.06876257,-0.05202507,0.00000000,0.00000000,0.00000000,0.00000000
162.66000000,3.61719200,4.60200000,0.12089733,452.48067961,0.11412956,507.18438716,0.00076965,0.12159284,521.86850689,-0.06925574,-0.05233710,0.00000000,0.00000000,0.00000000,0.00000000
163.65000000,3.64412800,4.60600000,0.12179211,452.87397007,0.11492751,508.03044695,0.00081791,0.12239708,522.51678702,-0.06971995,-0.05267713,0.00000000,0.00000000,0.00000000,0.00000000
164.65000000,3.67079100,4.61000000,0.12266822,453.26726054,0.11570819,508.86874958,0.00074380,0.12320413,523.39285714,-0.07015560,-0.05304853,0.00000000,0.00000000,0.00000000,0.00000000
165.65000000,3.69786200,4.61400000,0.12356300,453.66055100,0.11650489,509.71620966,0.00074301,0.12396624,524.13340264,-0.07060270,-0.05336353,0.00000000,0.00000000,0.00000000,0.00000000
166.65000000,3.72462800,4.61800000,0.12451800,454.05384146,0.11735450,510.59171770,0.00081592,0.12480935,524.91760983,-0.07110316,-0.05370619,0.00000000,0.00000000,0.00000000,0.00000000
167.65000000,3.75139500,4.62200000,0.12541289,454.44713193,0.11814998,511.44065959,0.00086901,0.12559956,525.67477064,-0.07155436,-0.05404519,0.00000000,0.00000000,0.00000000,0.00000000
168.65000000,3.77785700,4.62400000,0.12629644,454.64377716,0.11893477,512.06366971,0.00082135,0.12641518,526.44628969,-0.07203539,-0.05437979,0.00000000,0.00000000,0.00000000,0.00000000
169.65000000,3.80526500,4.62900000,0.12718744,455.13539024,0.11972554,513.02289740,0.00079368,0.12724466,527.11281676,-0.07250068,-0.05474398,0.00000000,0.00000000,0.00000000,0.00000000
170.65000000,3.83223400,4.63200000,0.12816889,455.43035809,0.12059587,513.80236105,0.00089349,0.12798402,527.84554970,-0.07292893,-0.05505509,0.00000000,0.00000000,0.00000000,0.00000000
171.65000000,3.85930500,4.63700000,0.12899978,455.92197117,0.12133209,514.73580414,0.00078630,0.12884655,528.64467008,-0.07343238,-0.05541416,0.00000000,0.00000000,0.00000000,0.00000000
172.65000000,3.88671300,4.64100000,0.12996222,456.31526164,0.12218420,515.61900707,0.00087849,0.12964152,529.29521972,-0.07390252,-0.05573900,0.00000000,0.00000000,0.00000000,0.00000000
173.65000000,3.91432500,4.64500000,0.13083078,456.70855210,0.12295256,516.46008719,0.00074492,0.13047827,530.19606630,-0.07442016,-0.05605811,0.00000000,0.00000000,0.00000000,0.00000000
174.65000000,3.94180200,4.64800000,0.13177822,457.00351995,0.12379004,517.22663136,0.00086372,0.13124251,530.83181674,-0.07479037,-0.05645214,0.00000000,0.00000000,0.00000000,0.00000000
175.65000000,3.96887300,4.65000000,0.13268067,457.20016518,0.12458709,517.86178790,0.00082339,0.13213151,531.64885979,-0.07535650,-0.05677500,0.00000000,0.00000000,0.00000000,0.00000000
176.65000000,3.99574100,4.65400000,0.13360933,457.59345565,0.12540664,518.73221219,0.00084272,0.13288793,532.28192822,-0.07576834,-0.05711958,0.00000000,0.00000000,0.00000000,0.00000000
177.65000000,4.02338800,4.65700000,0.13450422,457.88842350,0.12619575,519.47634976,0.00072252,0.13372990,533.07560797,-0.07624091,-0.05748899,0.00000000,0.00000000,0.00000000,0.00000000
178.65000000,4.05066100,4.66000000,0.13544044,458.18339134,0.12702063,520.23995350,0.00082804,0.13452088,533.72872326,-0.07666048,-0.05786040,0.00000000,0.00000000,0.00000000,0.00000000
179.65000000,4.07847500,4.66300000,0.13635767,458.47835919,0.12782812,520.99539847,0.00080722,0.13540351,534.54610629,-0.07721696,-0.05818655,0.00000000,0.00000000,0.00000000,0.00000000
180.65000000,4.10568100,4.66700000,0.13728644,458.87164966,0.12864511,521.86850689,0.00077373,0.13622543,535.21747232,-0.07767259,-0.05855284,0.00000000,0.00000000,0.00000000,0.00000000
181.65000000,4.13288700,4.66900000,0.13821144,459.06829489,0.12945812,522.51678702,0.00083931,0.13705305,535.89266880,-0.07814691,-0.05890614,0.00000000,0.00000000,0.00000000,0.00000000
182.65000000,4.16066900,4.67300000,0.13914389,459.46158535,0.13027701,523.39285714,0.00087824,0.13783798,536.54555680,-0.07856994,-0.05926804,0.00000000,0.00000000,0.00000000,0.00000000
183.65000000,4.18807800,4.67600000,0.14002378,459.75655320,0.13104912,524.13340264,0.00079839,0.13869501,537.35276515,-0.07909475,-0.05960026,0.00000000,0.00000000,0.00000000,0.00000000
184.65000000,4.21575600,4.67900000,0.14099744,460.05152105,0.13190283,524.91760983,0.00084369,0.13952863,537.91888681,-0.07954221,-0.05998642,0.00000000,0.00000000,0.00000000,0.00000000
185.65000000,4.24363900,4.68200000,0.14191111,460.34648890,0.13270327,525.67477064,0.00075073,0.14031810,538.80602128,-0.08001752,-0.06030058,0.00000000,0.00000000,0.00000000,0.00000000
186.65000000,4.27152100,4.68500000,0.14285478,460.64145675,0.13352932,526.44628969,0.00084893,0.14116641,539.38153983,-0.08053303,-0.06063338,0.00000000,0.00000000,0.00000000,0.00000000
187.65000000,4.29916600,4.68700000,0.14381344,460.83810198,0.13436781,527.11281676,0.00089409,0.14201736,540.18908064,-0.08100443,-0.06101292,0.00000000,0.00000000,0.00000000,0.00000000
188.65000000,4.32660800,4.69000000,0.14467078,461.13306983,0.13511707,527.84554970,0.00070309,0.14284805,540.75639539,-0.08150182,-0.06134623,0.00000000,0.00000000,0.00000000,0.00000000
189.65000000,4.35476100,4.69300000,0.14567089,461.42803768,0.13599039,528.64467008,0.00084025,0.14367981,541.44006024,-0.08199258,-0.06168724,0.00000000,0.00000000,0.00000000,0.00000000
190.65000000,4.38261100,4.69500000,0.14659211,461.62468291,0.13679416,529.29521972,0.00082018,0.14457492,542.15909291,-0.08249730,-0.06207762,0.00000000,0.00000000,0.00000000,0.00000000
191.65000000,4.41056100,4.69900000,0.14756589,462.01797337,0.13764308,530.19606630,0.00087160,0.14540511,542.84348976,-0.08299097,-0.06241413,0.00000000,0.00000000,0.00000000,0.00000000
192.65000000,4.43868000,4.70100000,0.14845311,462.21461861,0.13841592,530.83181674,0.00078575,0.14626656,543.54577751,-0.08351184,-0.06275472,0.00000000,0.00000000,0.00000000,0.00000000
193.65000000,4.46686600,4.70400000,0.14948722,462.50958646,0.13931595,531.64885979,0.00090302,0.14709549,544.23105431,-0.08398921,-0.06310629,0.00000000,0.00000000,0.00000000,0.00000000
194.65000000,4.49539200,4.70600000,0.15036689,462.70623169,0.14008093,532.28192822,0.00075836,0.14798737,544.95165439,-0.08454116,-0.06344621,0.00000000,0.00000000,0.00000000,0.00000000
195.65000000,4.52381500,4.70900000,0.15134822,463.00119954,0.14093362,533.07560797,0.00088187,0.14881629,545.52271947,-0.08499253,-0.06382377,0.00000000,0.00000000,0.00000000,0.00000000
196.65000000,4.55230600,4.71100000,0.15226944,463.19784477,0.14173343,533.72872326,0.00071157,0.14964287,546.20896475,-0.08547749,-0.06416538,0.00000000,0.00000000,0.00000000,0.00000000
197.65000000,4.58056000,4.71400000,0.15329967,463.49281262,0.14262711,534.54610629,0.00088057,0.15050067,546.91318605,-0.08596405,-0.06453662,0.00000000,0.00000000,0.00000000,0.00000000
198.65000000,4.60945900,4.71600000,0.15425844,463.68945785,0.14345810,535.21747232,0.00086674,0.15135771,547.61780662,-0.08643927,-0.06491845,0.00000000,0.00000000,0.00000000,0.00000000
199.65000000,4.63781500,4.71800000,0.15522467,463.88610308,0.14429484,535.89266880,0.00091778,0.15227756,548.35793533,-0.08702185,-0.06525571,0.00000000,0.00000000,0.00000000,0.00000000
200.65000000,4.66644200,4.72000000,0.15614200,464.08274831,0.14508860,536.54555680,0.00074803,0.15310285,548.93036465,-0.08746723,-0.06563562,0.00000000,0.00000000,0.00000000,0.00000000
201.65000000,4.69513700,4.72300000,0.15714589,464.37771616,0.14595653,537.35276515,0.00086438,0.15399088,549.53810985,-0.08799712,-0.06599376,0.00000000,0.00000000,0.00000000,0.00000000
202.65000000,4.72376300,4.72400000,0.15811978,464.47603878,0.14679781,537.91888681,0.00082507,0.15487821,550.14611404,-0.08850963,-0.06636858,0.00000000,0.00000000,0.00000000,0.00000000
203.65000000,4.75232300,4.72800000,0.15904833,464.86932924,0.14759927,538.80602128,0.00081731,0.15573141,550.85245372,-0.08900529,-0.06672611,0.00000000,0.00000000,0.00000000,0.00000000
204.65000000,4.78166200,4.72900000,0.16004100,464.96765186,0.14845535,539.38153983,0.00077790,0.15661706,551.46091982,-0.08953514,-0.06708191,0.00000000,0.00000000,0.00000000,0.00000000
205.65000000,4.81069500,4.73200000,0.16104122,465.26261971,0.14931721,540.18908064,0.00088771,0.15750044,552.18560161,-0.09006759,-0.06743284,0.00000000,0.00000000,0.00000000,0.00000000
206.65000000,4.83949200,4.73300000,0.16201500,465.36094232,0.15015557,540.75639539,0.00080910,0.15838467,552.79468936,-0.09057695,-0.06780773,0.00000000,0.00000000,0.00000000,0.00000000
207.65000000,4.86893100,4.73500000,0.16299267,465.55758756,0.15099657,541.44006024,0.00077612,0.15923490,553.50250078,-0.09108509,-0.06814980,0.00000000,0.00000000,0.00000000,0.00000000
208.65000000,4.89803100,4.73700000,0.16404544,465.75423279,0.15190139,542.15909291,0.00084016,0.00000000,0.00000000,0.00000000,0.00000000,0.00000000,0.00000000,0.00000000,0.00000000
209.65000000,4.92740200,4.73900000,0.16502300,465.95087802,0.15274083,542.84348976,0.00083926,0.00000000,0.00000000,0.00000000,0.00000000,0.00000000,0.00000000,0.00000000,0.00000000
210.65000000,4.95673900,4.74100000,0.16603811,466.14752325,0.15361177,543.54577751,0.00096742,0.00000000,0.00000000,0.00000000,0.00000000,0.00000000,0.00000000,0.00000000,0.00000000
211.65000000,4.98607700,4.74300000,0.16701589,466.34416849,0.15444997,544.23105431,0.00083802,0.00000000,0.00000000,0.00000000,0.00000000,0.00000000,0.00000000,0.00000000,0.00000000
212.65000000,5.01548200,4.74500000,0.16806856,466.54081372,0.15535158,544.95165439,0.00090141,0.00000000,0.00000000,0.00000000,0.00000000,0.00000000,0.00000000,0.00000000,0.00000000
213.65000000,5.04522500,4.74600000,0.16904622,466.63913633,0.15618822,545.52271947,0.00096512,0.00000000,0.00000000,0.00000000,0.00000000,0.00000000,0.00000000,0.00000000,0.00000000
214.65000000,5.07476600,4.74800000,0.17002378,466.83578157,0.15702407,546.20896475,0.00083568,0.00000000,0.00000000,0.00000000,0.00000000,0.00000000,0.00000000,0.00000000,0.00000000
215.65000000,5.10417200,4.75000000,0.17103900,467.03242680,0.15789139,546.91318605,0.00083495,0.00000000,0.00000000,0.00000000,0.00000000,0.00000000,0.00000000,0.00000000,0.00000000
216.65000000,5.13411800,4.75200000,0.17205422,467.22907203,0.15875795,547.61780662,0.00083423,0.00000000,0.00000000,0.00000000,0.00000000,0.00000000,0.00000000,0.00000000,0.00000000
217.65000000,5.16423400,4.75400000,0.17314456,467.42571726,0.15968780,548.35793533,0.00096175,0.00000000,0.00000000,0.00000000,0.00000000,0.00000000,0.00000000,0.00000000,0.00000000
218.65000000,5.19431700,4.75500000,0.17412222,467.52403988,0.16052082,548.93036465,0.00089695,0.00000000,0.00000000,0.00000000,0.00000000,0.00000000,0.00000000,0.00000000,0.00000000
219.65000000,5.22416200,4.75600000,0.17517500,467.62236250,0.16141707,549.53810985,0.00083201,0.00000000,0.00000000,0.00000000,0.00000000,0.00000000,0.00000000,0.00000000,0.00000000
220.65000000,5.25417600,4.75700000,0.17622789,467.72068511,0.16231261,550.14611404,0.00095942,0.00000000,0.00000000,0.00000000,0.00000000,0.00000000,0.00000000,0.00000000,0.00000000
221.65000000,5.28419000,4.75900000,0.17724311,467.91733034,0.16317536,550.85245372,0.00089476,0.00000000,0.00000000,0.00000000,0.00000000,0.00000000,0.00000000,0.00000000,0.00000000
222.65000000,5.31440800,4.76000000,0.17829589,468.01565296,0.16406923,551.46091982,0.00089377,0.00000000,0.00000000,0.00000000,0.00000000,0.00000000,0.00000000,0.00000000,0.00000000
223.65000000,5.34496300,4.76200000,0.17934878,468.21229819,0.16496240,552.18560161,0.00095669,0.00000000,0.00000000,0.00000000,0.00000000,0.00000000,0.00000000,0.00000000,0.00000000
224.65000000,5.37592500,4.76300000,0.18040178,468.31062081,0.16585487,552.79468936,0.00095602,0.00000000,0.00000000,0.00000000,0.00000000,0.00000000,0.00000000,0.00000000,0.00000000
225.65000000,5.40644800,4.76500000,0.18141711,468.50726604,0.16671466,553.50250078,0.00082799,0.00000000,0.00000000,0.00000000,0.00000000,0.00000000,0.00000000,0.00000000,0.00000000
226.65000000,5.43747800,4.76500000,0.18250778,468.50726604,0.00000000,0.00000000,0.00000000,0.00000000,0.00000000,0.00000000,0.00000000,0.00000000,0.00000000,0.00000000,0.00000000
227.65000000,5.46847600,4.76500000,0.18363656,468.50726604,0.00000000,0.00000000,0.00000000,0.00000000,0.00000000,0.00000000,0.00000000,0.00000000,0.00000000,0.00000000,0.00000000
228.15000000,5.48475800,4.76500000,0.18420189,468.50726604,0.00000000,0.00000000,0.00000000,0.00000000,0.00000000,0.00000000,0.00000000,0.00000000,0.00000000,0.00000000,0.00000000