File: polyN_optimization/AA7020-T6_results/DATA/UT_60_1.csv
Time[s],Displacement[mm],Force[kN],EngStrain_longi,EngStress[MPa],TrueStrain,TrueStress[MPa],TrueStrainRate[1/s],PlasticStrain_longi,PlasticStress[MPa],PlasticStrain_thick,PlasticStrain_width,R-Value,Thickness[mm],Width[mm], Young's Modulus [MPa]
0.59000000,0.00000000,-0.01000000,0.00000000,-0.99303880,0.00000000,-0.99303880,0.00000000,0.00053264,276.94835142,0.00075261,-0.00128524,0.71581875,1.00500000,10.02000000,78694.00009898
2.09000000,0.00196500,0.00300000,0.00002600,0.29791164,0.00002600,0.29791939,0.00012089,0.00121252,288.35844937,0.00037458,-0.00158711,0.00000000,0.00000000,0.00000000,0.00000000
3.59000000,0.00783300,0.30200000,0.00017944,29.98977170,0.00017943,29.99515320,0.00011865,0.00208394,296.23373171,-0.00017149,-0.00191245,0.00000000,0.00000000,0.00000000,0.00000000
5.09000000,0.01450700,0.49600000,0.00037044,49.25472438,0.00037038,49.27297052,0.00002621,0.00299598,304.73916716,-0.00072282,-0.00227316,0.00000000,0.00000000,0.00000000,0.00000000
6.59000000,0.02268700,0.73200000,0.00067533,72.69044002,0.00067511,72.73953029,0.00016012,0.00387800,310.73902892,-0.00125233,-0.00262567,0.00000000,0.00000000,0.00000000,0.00000000
8.09000000,0.03032100,0.92700000,0.00097144,92.05469658,0.00097097,92.14412260,0.00036812,0.00489248,316.79235781,-0.00183972,-0.00305276,0.00000000,0.00000000,0.00000000,0.00000000
9.59000000,0.03839300,1.15700000,0.00122944,114.89458893,0.00122869,115.03584545,0.00042796,0.00597090,321.97241782,-0.00246296,-0.00350794,0.00000000,0.00000000,0.00000000,0.00000000
11.09000000,0.04695500,1.36900000,0.00143467,135.94701145,0.00143364,136.14205010,0.00031091,0.00700980,326.64657484,-0.00302509,-0.00398471,0.00000000,0.00000000,0.00000000,0.00000000
12.59000000,0.05574200,1.59600000,0.00164078,158.48899216,0.00163943,158.74903738,0.00009096,0.00804914,331.02781736,-0.00359974,-0.00444940,0.00000000,0.00000000,0.00000000,0.00000000
14.09000000,0.06440000,1.78800000,0.00188911,177.55533709,0.00188733,177.89075885,-0.00007231,0.00917706,335.65045524,-0.00428899,-0.00488807,0.00000000,0.00000000,0.00000000,0.00000000
15.59000000,0.07281400,2.00900000,0.00225767,199.50149452,0.00225512,199.95190240,-0.00002905,0.01032795,339.27892017,-0.00495995,-0.00536801,0.00000000,0.00000000,0.00000000,0.00000000
17.09000000,0.08335000,2.20600000,0.00265778,219.06435884,0.00265425,219.64658323,0.00020192,0.01139964,343.19250388,-0.00561752,-0.00578212,0.00000000,0.00000000,0.00000000,0.00000000
18.59000000,0.09466500,2.40800000,0.00301056,239.12374256,0.00300603,239.84363788,0.00030112,0.01250983,346.62042166,-0.00629811,-0.00621172,0.00000000,0.00000000,0.00000000,0.00000000
20.09000000,0.10822600,2.58000000,0.00343656,256.20400989,0.00343066,257.08446920,0.00039070,0.01368074,350.17883483,-0.00703259,-0.00664815,0.00000000,0.00000000,0.00000000,0.00000000
21.59000000,0.12843800,2.73800000,0.00405911,271.89402290,0.00405090,272.99767095,0.00042632,0.01483402,353.23040491,-0.00778304,-0.00705097,0.00000000,0.00000000,0.00000000,0.00000000
23.09000000,0.15218200,2.84400000,0.00495922,282.42023416,0.00494697,283.82081886,0.00065331,0.01594161,356.57807674,-0.00841327,-0.00752834,0.00000000,0.00000000,0.00000000,0.00000000
24.59000000,0.18156500,2.94700000,0.00591200,292.64853378,0.00589459,294.37867191,0.00084187,0.01706336,359.63215619,-0.00903514,-0.00802822,0.00000000,0.00000000,0.00000000,0.00000000
26.09000000,0.20987200,3.01600000,0.00682456,299.50050148,0.00680137,301.54445930,0.00091596,0.01824054,362.81522527,-0.00974278,-0.00849776,0.00000000,0.00000000,0.00000000,0.00000000
27.59000000,0.24081700,3.08500000,0.00779911,306.35246919,0.00776886,308.74174614,0.00068522,0.01936450,365.78148909,-0.01035713,-0.00900738,0.00000000,0.00000000,0.00000000,0.00000000
29.09000000,0.27327400,3.14200000,0.00894222,312.01279034,0.00890248,314.80287805,0.00075847,0.02050127,368.75894380,-0.01102123,-0.00948004,0.00000000,0.00000000,0.00000000,0.00000000
30.59000000,0.30612700,3.19500000,0.01006744,317.27589597,0.01001711,320.47005343,0.00095880,0.02161120,371.42541835,-0.01162340,-0.00998780,0.00000000,0.00000000,0.00000000,0.00000000
32.09000000,0.34072400,3.24000000,0.01112922,321.74457056,0.01106775,325.32533738,0.00082411,0.02276495,374.31927429,-0.01230085,-0.01046409,0.00000000,0.00000000,0.00000000,0.00000000
33.59000000,0.37496000,3.28100000,0.01226378,325.81602963,0.01218919,329.81176502,0.00066155,0.02389805,377.00621700,-0.01292868,-0.01096937,0.00000000,0.00000000,0.00000000,0.00000000
35.09000000,0.41029400,3.31800000,0.01352211,329.49027318,0.01343150,333.94567727,0.00093645,0.02502437,379.79924612,-0.01356914,-0.01145523,0.00000000,0.00000000,0.00000000,0.00000000
36.59000000,0.44598600,3.35600000,0.01463678,333.26382062,0.01453069,338.14172910,0.00085128,0.02613778,382.38734908,-0.01419369,-0.01194409,0.00000000,0.00000000,0.00000000,0.00000000
38.09000000,0.48071300,3.38800000,0.01577189,336.44154477,0.01564881,341.74786343,0.00065774,0.02727046,385.09150321,-0.01487819,-0.01239227,0.00000000,0.00000000,0.00000000,0.00000000
39.59000000,0.51703400,3.42200000,0.01697467,339.81787668,0.01683221,345.58617187,0.00063597,0.02839796,387.48974644,-0.01551400,-0.01288395,0.00000000,0.00000000,0.00000000,0.00000000
41.09000000,0.55308800,3.44900000,0.01821467,342.49908144,0.01805077,348.73758804,0.00084894,0.02948199,390.08274800,-0.01615584,-0.01332615,0.00000000,0.00000000,0.00000000,0.00000000
42.59000000,0.58864100,3.48200000,0.01936122,345.77610947,0.01917618,352.47075757,0.00074461,0.03061440,392.49322949,-0.01682469,-0.01378972,0.00000000,0.00000000,0.00000000,0.00000000
44.09000000,0.62506700,3.50700000,0.02057133,348.25870647,0.02036260,355.42285240,0.00067773,0.03175337,395.11864867,-0.01750672,-0.01424665,0.00000000,0.00000000,0.00000000,0.00000000
45.59000000,0.66098600,3.53500000,0.02179689,351.03921510,0.02156273,358.69077787,0.00072804,0.03286475,397.53122980,-0.01811389,-0.01475086,0.00000000,0.00000000,0.00000000,0.00000000
47.09000000,0.69745300,3.56100000,0.02297311,353.62111598,0.02271320,361.74489317,0.00070482,0.03397336,400.05158592,-0.01880999,-0.01516337,0.00000000,0.00000000,0.00000000,0.00000000
48.59000000,0.73331300,3.58700000,0.02415756,356.20301685,0.02387038,364.80801102,0.00068274,0.03511527,402.17477636,-0.01947012,-0.01564515,0.00000000,0.00000000,0.00000000,0.00000000
50.09000000,0.76920100,3.60900000,0.02538300,358.38770221,0.02506620,367.48465725,0.00071726,0.03625124,404.61231218,-0.02014265,-0.01610860,0.00000000,0.00000000,0.00000000,0.00000000
51.59000000,0.80545900,3.63600000,0.02659767,361.06890696,0.02625010,370.67249739,0.00073352,0.03736930,406.94346802,-0.02079740,-0.01657191,0.00000000,0.00000000,0.00000000,0.00000000
53.09000000,0.84145600,3.65800000,0.02777767,363.25359232,0.02739887,373.34392952,0.00073094,0.03842550,409.25401919,-0.02135013,-0.01707537,0.00000000,0.00000000,0.00000000,0.00000000
54.59000000,0.87728300,3.68200000,0.02899956,365.63688543,0.02858702,376.24019261,0.00078906,0.03962424,411.52366528,-0.02207476,-0.01754948,0.00000000,0.00000000,0.00000000,0.00000000
56.09000000,0.91337900,3.70300000,0.03017644,367.72226691,0.02973009,378.81881747,0.00071586,0.04073825,413.86764790,-0.02272233,-0.01801592,0.00000000,0.00000000,0.00000000,0.00000000
57.59000000,0.94978700,3.72600000,0.03139078,370.00625614,0.03090816,381.62104031,0.00072968,0.04183384,415.89461991,-0.02331946,-0.01851438,0.00000000,0.00000000,0.00000000,0.00000000
59.09000000,0.98591600,3.74500000,0.03260856,371.89302986,0.03208818,384.01992439,0.00075766,0.04297508,418.15452475,-0.02396667,-0.01900841,0.00000000,0.00000000,0.00000000,0.00000000
60.59000000,1.02191400,3.76800000,0.03378911,374.17701910,0.03323080,386.82012797,0.00080067,0.04410341,420.20379116,-0.02464448,-0.01945894,0.00000000,0.00000000,0.00000000,0.00000000
62.09000000,1.05730300,3.78700000,0.03497722,376.06379281,0.03437942,389.21745966,0.00074132,0.04522030,422.46258338,-0.02531805,-0.01990224,0.00000000,0.00000000,0.00000000,0.00000000
63.59000000,1.09323400,3.80700000,0.03618044,378.04987041,0.03554130,391.72788274,0.00077736,0.04632794,424.51165830,-0.02596589,-0.02036205,0.00000000,0.00000000,0.00000000,0.00000000
65.09000000,1.12980600,3.82700000,0.03736044,380.03594800,0.03667945,394.23425993,0.00077519,0.04745441,426.67828403,-0.02662565,-0.02082876,0.00000000,0.00000000,0.00000000,0.00000000
66.59000000,1.16580100,3.84700000,0.03855256,382.02202560,0.03782797,396.74995097,0.00074605,0.04858761,428.74681542,-0.02728867,-0.02129894,0.00000000,0.00000000,0.00000000,0.00000000
68.09000000,1.20220500,3.86400000,0.03975589,383.71019156,0.03898596,398.96493130,0.00072402,0.04969009,430.91187923,-0.02793877,-0.02175133,0.00000000,0.00000000,0.00000000,0.00000000
69.59000000,1.23820400,3.88500000,0.04098089,385.79557303,0.04016343,401.60581855,0.00075050,0.05081173,432.87824090,-0.02853495,-0.02227677,0.00000000,0.00000000,0.00000000,0.00000000
71.09000000,1.27467900,3.90200000,0.04217622,387.48373899,0.04131105,403.82633927,0.00077161,0.05194363,434.74723367,-0.02922785,-0.02271579,0.00000000,0.00000000,0.00000000,0.00000000
72.59000000,1.31071300,3.92000000,0.04337244,389.27120883,0.04245820,406.15485270,0.00073578,0.05308700,436.73099373,-0.02990479,-0.02318222,0.00000000,0.00000000,0.00000000,0.00000000
74.09000000,1.34678200,3.93800000,0.04458256,391.05867866,0.04361734,408.49307393,0.00077068,0.05419412,438.70282652,-0.03057232,-0.02362179,0.00000000,0.00000000,0.00000000,0.00000000
75.59000000,1.38301300,3.95600000,0.04581200,392.84614850,0.04479362,410.84321625,0.00086289,0.05533813,440.69495340,-0.03126467,-0.02407346,0.00000000,0.00000000,0.00000000,0.00000000
77.09000000,1.41934800,3.97100000,0.04700756,394.33570670,0.04593615,412.87246434,0.00081880,0.05645655,442.67977306,-0.03189377,-0.02456279,0.00000000,0.00000000,0.00000000,0.00000000
78.59000000,1.45626100,3.99000000,0.04821056,396.22248041,0.04708448,415.32458632,0.00073133,0.05759557,444.57133523,-0.03258791,-0.02500766,0.00000000,0.00000000,0.00000000,0.00000000
80.09000000,1.49169100,4.00500000,0.04945156,397.71203861,0.04826770,417.37951758,0.00084634,0.05872789,446.35712999,-0.03323796,-0.02548993,0.00000000,0.00000000,0.00000000,0.00000000
81.59000000,1.52813500,4.02200000,0.05061333,399.40020457,0.04937412,419.61518025,0.00078086,0.05983092,448.13327684,-0.03385993,-0.02597099,0.00000000,0.00000000,0.00000000,0.00000000
83.09000000,1.56450100,4.03700000,0.05183511,400.88976276,0.05053636,421.66992816,0.00074360,0.06095228,450.02801685,-0.03451418,-0.02643810,0.00000000,0.00000000,0.00000000,0.00000000
84.59000000,1.60077000,4.05400000,0.05305689,402.57792872,0.05169726,423.93746115,0.00076490,0.06210507,451.83386682,-0.03517904,-0.02692603,0.00000000,0.00000000,0.00000000,0.00000000
86.09000000,1.63747500,4.06700000,0.05427100,403.86887916,0.05284953,425.78724710,0.00079924,0.06320256,453.72521580,-0.03580540,-0.02739716,0.00000000,0.00000000,0.00000000,0.00000000
87.59000000,1.67381600,4.08500000,0.05547044,405.65634899,0.05398659,428.15828696,0.00075578,0.06436224,455.32712217,-0.03646657,-0.02789567,0.00000000,0.00000000,0.00000000,0.00000000
89.09000000,1.71002100,4.09800000,0.05669233,406.94729943,0.05514359,430.01809138,0.00071157,0.06551638,457.25169405,-0.03717764,-0.02833874,0.00000000,0.00000000,0.00000000,0.00000000
90.59000000,1.74696700,4.11400000,0.05791789,408.53616151,0.05630272,432.19771352,0.00076748,0.06661313,458.93874879,-0.03775707,-0.02885607,0.00000000,0.00000000,0.00000000,0.00000000
92.09000000,1.78353900,4.12700000,0.05913589,409.82711195,0.05745338,434.06260250,0.00073218,0.06774255,460.64416626,-0.03837732,-0.02936523,0.00000000,0.00000000,0.00000000,0.00000000
93.59000000,1.81987500,4.14100000,0.06036111,411.21736626,0.05860952,436.03890340,0.00075146,0.06891618,462.37349962,-0.03908498,-0.02983120,0.00000000,0.00000000,0.00000000,0.00000000
95.09000000,1.85655400,4.15500000,0.06157189,412.60762058,0.05975072,438.01265115,0.00074390,0.07005356,464.08940659,-0.03975438,-0.03029918,0.00000000,0.00000000,0.00000000,0.00000000
96.59000000,1.89340400,4.17000000,0.06281644,414.09717878,0.06092241,440.10929120,0.00079281,0.07118395,465.69744006,-0.04038836,-0.03079560,0.00000000,0.00000000,0.00000000,0.00000000
98.09000000,1.92977500,4.18200000,0.06403800,415.28882533,0.06207110,441.88309113,0.00078396,0.07231029,467.52289491,-0.04106761,-0.03124269,0.00000000,0.00000000,0.00000000,0.00000000
99.59000000,1.96699300,4.19600000,0.06529367,416.67907965,0.06325050,443.88558459,0.00082540,0.07348795,469.05147154,-0.04177412,-0.03171383,0.00000000,0.00000000,0.00000000,0.00000000
101.09000000,2.00343300,4.20800000,0.06648178,417.87072621,0.06436517,445.65151497,0.00076174,0.07459535,470.76652519,-0.04241344,-0.03218191,0.00000000,0.00000000,0.00000000,0.00000000
102.59000000,2.04031500,4.22100000,0.06771111,419.16167665,0.06551721,447.54357951,0.00078189,0.07572886,472.28030668,-0.04307749,-0.03265138,0.00000000,0.00000000,0.00000000,0.00000000
104.09000000,2.07746800,4.23400000,0.06894033,420.45262708,0.06666782,449.43877135,0.00074522,0.07688343,473.91563793,-0.04376366,-0.03311977,0.00000000,0.00000000,0.00000000,0.00000000
105.59000000,2.11437900,4.24600000,0.07015489,421.64427364,0.06780339,451.22468081,0.00074437,0.07801984,475.54549528,-0.04443154,-0.03358830,0.00000000,0.00000000,0.00000000,0.00000000
107.09000000,2.15149500,4.25700000,0.07137278,422.73661632,0.06894080,452.90850289,0.00069414,0.07915102,477.17600518,-0.04508084,-0.03407018,0.00000000,0.00000000,0.00000000,0.00000000
108.59000000,2.18874800,4.27100000,0.07264367,424.12687064,0.07012632,454.93700165,0.00077829,0.08029587,478.70724047,-0.04575664,-0.03453923,0.00000000,0.00000000,0.00000000,0.00000000
110.09000000,2.22620400,4.28200000,0.07389178,425.21921331,0.07128923,456.63941693,0.00077014,0.08142057,480.12254417,-0.04639674,-0.03502384,0.00000000,0.00000000,0.00000000,0.00000000
111.59000000,2.26339200,4.29300000,0.07512867,426.31155599,0.07244034,458.33977478,0.00075561,0.08256651,481.66003555,-0.04705036,-0.03551615,0.00000000,0.00000000,0.00000000,0.00000000
113.09000000,2.30122200,4.30300000,0.07638089,427.30459479,0.07360439,459.94249957,0.00072705,0.08372437,483.20628077,-0.04772920,-0.03599518,0.00000000,0.00000000,0.00000000,0.00000000
114.59000000,2.33847200,4.31600000,0.07764400,428.59554523,0.07477718,461.87341774,0.00078169,0.08490147,484.76490750,-0.04843158,-0.03646988,0.00000000,0.00000000,0.00000000,0.00000000
116.09000000,2.37583000,4.32600000,0.07888078,429.58858403,0.07592419,463.47486566,0.00082263,0.08603225,486.08460613,-0.04907259,-0.03695965,0.00000000,0.00000000,0.00000000,0.00000000
117.59000000,2.41331500,4.33800000,0.08012511,430.78023058,0.07707688,465.29654442,0.00077949,0.08717944,487.63434552,-0.04974064,-0.03743880,0.00000000,0.00000000,0.00000000,0.00000000
119.09000000,2.45117800,4.34700000,0.08141100,431.67396550,0.07826667,466.81697471,0.00082790,0.08834863,489.19789432,-0.05041062,-0.03793801,0.00000000,0.00000000,0.00000000,0.00000000
120.59000000,2.48904200,4.35900000,0.08263656,432.86561206,0.07939932,468.63613526,0.00075078,0.08950121,490.64623522,-0.05110480,-0.03839641,0.00000000,0.00000000,0.00000000,0.00000000
122.09000000,2.52703700,4.36800000,0.08389222,433.75934698,0.08055847,470.14838251,0.00074868,0.09062662,491.97368282,-0.05172851,-0.03889811,0.00000000,0.00000000,0.00000000,0.00000000
123.59000000,2.56506700,4.37900000,0.08517433,434.85168966,0.08174065,471.88989242,0.00078364,0.09180994,493.44261434,-0.05243673,-0.03937321,0.00000000,0.00000000,0.00000000,0.00000000
125.09000000,2.60252600,4.38700000,0.08643778,435.64612069,0.08290425,473.30240326,0.00085230,0.09294282,494.77881153,-0.05309908,-0.03984375,0.00000000,0.00000000,0.00000000,0.00000000
126.59000000,2.64035500,4.39800000,0.08768933,436.73846337,0.08405557,475.03576807,0.00081555,0.09409971,496.24001847,-0.05376009,-0.04033962,0.00000000,0.00000000,0.00000000,0.00000000
128.09000000,2.67828400,4.40700000,0.08896767,437.63219829,0.08523015,476.56731383,0.00084951,0.09529385,497.61194968,-0.05449485,-0.04079900,0.00000000,0.00000000,0.00000000,0.00000000
129.59000000,2.71675400,4.41700000,0.09026478,438.62523709,0.08642058,478.21764664,0.00088336,0.09642946,498.95709388,-0.05513363,-0.04129583,0.00000000,0.00000000,0.00000000,0.00000000
131.09000000,2.75491900,4.42500000,0.09149378,439.41966813,0.08754720,479.62383359,0.00080579,0.09759354,500.31904013,-0.05582821,-0.04176533,0.00000000,0.00000000,0.00000000,0.00000000
132.59000000,2.79288600,4.43400000,0.09276467,440.31340304,0.08871088,481.15892911,0.00075033,0.09876981,501.68968193,-0.05651539,-0.04225442,0.00000000,0.00000000,0.00000000,0.00000000
134.09000000,2.83138700,4.44400000,0.09405411,441.30644184,0.08989016,482.81312696,0.00081812,0.09993490,503.05724540,-0.05716859,-0.04276631,0.00000000,0.00000000,0.00000000,0.00000000
135.59000000,2.87002800,4.45200000,0.09532478,442.10087288,0.09105092,484.24404034,0.00079668,0.10110491,504.42985869,-0.05787216,-0.04323275,0.00000000,0.00000000,0.00000000,0.00000000
137.09000000,2.90836700,4.46000000,0.09661767,442.89530392,0.09223059,485.68681476,0.00078094,0.10225826,505.68504537,-0.05853371,-0.04372456,0.00000000,0.00000000,0.00000000,0.00000000
138.59000000,2.94713900,4.46800000,0.09787744,443.68973496,0.09337872,487.11695234,0.00070532,0.10342573,507.06134481,-0.05920018,-0.04422554,0.00000000,0.00000000,0.00000000,0.00000000
140.09000000,2.98564400,4.47700000,0.09919322,444.58346988,0.09457648,488.68313680,0.00080722,0.10460769,508.22407550,-0.05988411,-0.04472358,0.00000000,0.00000000,0.00000000,0.00000000
141.59000000,3.02438600,4.48500000,0.10045244,445.37790091,0.09572141,490.11719976,0.00076488,0.10573730,509.47394233,-0.06054154,-0.04519577,0.00000000,0.00000000,0.00000000,0.00000000
143.09000000,3.06319300,4.49300000,0.10173833,446.17233195,0.09688924,491.56516139,0.00072323,0.10694181,510.76453660,-0.06121435,-0.04572746,0.00000000,0.00000000,0.00000000,0.00000000
144.59000000,3.10203700,4.50000000,0.10303511,446.86745911,0.09806557,492.91049741,0.00077740,0.10813486,512.05163974,-0.06189990,-0.04623496,0.00000000,0.00000000,0.00000000,0.00000000
146.09000000,3.14057200,4.50800000,0.10431344,447.66189015,0.09922382,494.35904386,0.00076301,0.10927319,513.31283887,-0.06252837,-0.04674482,0.00000000,0.00000000,0.00000000,0.00000000
147.59000000,3.17961700,4.51500000,0.10561400,448.35701731,0.10040084,495.70979533,0.00074080,0.11044827,514.48287405,-0.06323370,-0.04721457,0.00000000,0.00000000,0.00000000,0.00000000
149.09000000,3.21866500,4.52300000,0.10696011,449.15144835,0.10161762,497.19273717,0.00085638,0.11161678,515.76416219,-0.06392135,-0.04769542,0.00000000,0.00000000,0.00000000,0.00000000
150.59000000,3.25801800,4.53000000,0.10823078,449.84657551,0.10276485,498.53382025,0.00077997,0.11284557,516.96643787,-0.06468673,-0.04815884,0.00000000,0.00000000,0.00000000,0.00000000
152.09000000,3.29723400,4.53700000,0.10951278,450.54170266,0.10392098,499.88177603,0.00067729,0.11402123,518.25606940,-0.06534510,-0.04867613,0.00000000,0.00000000,0.00000000,0.00000000
153.59000000,3.33695600,4.54400000,0.11091511,451.23682982,0.10518410,501.28581294,0.00088715,0.11521488,519.33145693,-0.06603868,-0.04917620,0.00000000,0.00000000,0.00000000,0.00000000
155.09000000,3.37643700,4.55100000,0.11221578,451.93195698,0.10635422,502.64585304,0.00085253,0.11641929,520.52748685,-0.06674525,-0.04967405,0.00000000,0.00000000,0.00000000,0.00000000
156.59000000,3.41633400,4.55700000,0.11351656,452.52778026,0.10752308,503.89717517,0.00076329,0.11758236,521.70395686,-0.06744585,-0.05013652,0.00000000,0.00000000,0.00000000,0.00000000
158.09000000,3.45592200,4.56300000,0.11484744,453.12360354,0.10871757,505.16369142,0.00079588,0.11879344,522.90777697,-0.06813450,-0.05065895,0.00000000,0.00000000,0.00000000,0.00000000
159.59000000,3.49510100,4.57000000,0.11616322,453.81873070,0.10989711,506.53577676,0.00080829,0.11996006,524.09031057,-0.06876636,-0.05119369,0.00000000,0.00000000,0.00000000,0.00000000
161.09000000,3.53513600,4.57700000,0.11744178,454.51385786,0.11104195,507.89277335,0.00072043,0.12115667,525.17709682,-0.06949380,-0.05166287,0.00000000,0.00000000,0.00000000,0.00000000
162.59000000,3.57496000,4.58200000,0.11879144,455.01037726,0.11224904,509.06171721,0.00074559,0.12235338,526.37965010,-0.07018896,-0.05216442,0.00000000,0.00000000,0.00000000,0.00000000
164.09000000,3.61542800,4.58800000,0.12015256,455.60620053,0.11346489,510.34844986,0.00083300,0.12355003,527.47035533,-0.07086598,-0.05268405,0.00000000,0.00000000,0.00000000,0.00000000
165.59000000,3.65508900,4.59400000,0.12143067,456.20202381,0.11460525,511.59893970,0.00075097,0.12473553,528.55700936,-0.07159345,-0.05314208,0.00000000,0.00000000,0.00000000,0.00000000
167.09000000,3.69566100,4.59900000,0.12277667,456.69854321,0.11580478,512.77046802,0.00072314,0.12593590,529.65345693,-0.07228522,-0.05365068,0.00000000,0.00000000,0.00000000,0.00000000
168.59000000,3.73555400,4.60500000,0.12412644,457.29436649,0.11700624,514.05669027,0.00078991,0.12712813,530.74744895,-0.07299513,-0.05413300,0.00000000,0.00000000,0.00000000,0.00000000
170.09000000,3.77561700,4.61000000,0.12548344,457.79088589,0.11821267,515.23606309,0.00084900,0.12835983,531.97901411,-0.07374460,-0.05461523,0.00000000,0.00000000,0.00000000,0.00000000
171.59000000,3.81635400,4.61600000,0.12681822,458.38670917,0.11939793,516.51849672,0.00078131,0.12957359,532.97384249,-0.07442634,-0.05514725,0.00000000,0.00000000,0.00000000,0.00000000
173.09000000,3.85740300,4.62200000,0.12818678,458.98253245,0.12061172,517.81802434,0.00077347,0.13076787,534.07466780,-0.07514196,-0.05562592,0.00000000,0.00000000,0.00000000,0.00000000
174.59000000,3.89790300,4.62700000,0.12955522,459.47905185,0.12182395,519.00696251,0.00081858,0.13199964,535.19760052,-0.07586276,-0.05613688,0.00000000,0.00000000,0.00000000,0.00000000
176.09000000,3.93891400,4.63100000,0.13090856,459.87626737,0.12302134,520.07800526,0.00081760,0.13319583,536.18818310,-0.07654706,-0.05664877,0.00000000,0.00000000,0.00000000,0.00000000
177.59000000,3.97938300,4.63700000,0.13227322,460.47209064,0.12422731,521.38021782,0.00077696,0.13443247,537.20228449,-0.07727094,-0.05716153,0.00000000,0.00000000,0.00000000,0.00000000
179.09000000,4.02073400,4.64100000,0.13364933,460.86930616,0.12544193,522.46418169,0.00087583,0.13566600,538.33180678,-0.07801384,-0.05765215,0.00000000,0.00000000,0.00000000,0.00000000
180.59000000,4.06157700,4.64600000,0.13497644,461.36582556,0.12661190,523.63934429,0.00073554,0.13689653,539.34615854,-0.07871386,-0.05818267,0.00000000,0.00000000,0.00000000,0.00000000
182.09000000,4.10258800,4.65100000,0.13638233,461.86234496,0.12784982,524.85220925,0.00082677,0.13813026,540.47964147,-0.07945494,-0.05867532,0.00000000,0.00000000,0.00000000,0.00000000
183.59000000,4.14400300,4.65500000,0.13779267,462.25956048,0.12909013,525.95553801,0.00084626,0.13935415,541.49392720,-0.08017269,-0.05918146,0.00000000,0.00000000,0.00000000,0.00000000
185.09000000,4.18568900,4.66000000,0.13914233,462.75607988,0.13027564,527.14504060,0.00079959,0.14061846,542.53199436,-0.08090740,-0.05971106,0.00000000,0.00000000,0.00000000,0.00000000
186.59000000,4.22727300,4.66400000,0.14053311,463.15329540,0.13149579,528.24166892,0.00079764,0.14180562,543.41347593,-0.08160001,-0.06020562,0.00000000,0.00000000,0.00000000,0.00000000
188.09000000,4.26865700,4.66800000,0.14189767,463.55051092,0.13269150,529.32724680,0.00076982,0.14303458,544.43549057,-0.08231071,-0.06072387,0.00000000,0.00000000,0.00000000,0.00000000
189.59000000,4.31027700,4.67200000,0.14328167,463.94772644,0.13390278,530.42292993,0.00079650,0.14431334,545.48659232,-0.08304951,-0.06126383,0.00000000,0.00000000,0.00000000,0.00000000
191.09000000,4.35141800,4.67500000,0.14468000,464.24563808,0.13512512,531.41269699,0.00089982,0.14552810,546.38770307,-0.08375421,-0.06177390,0.00000000,0.00000000,0.00000000,0.00000000
192.59000000,4.39408400,4.68000000,0.14607489,464.74215748,0.13634296,532.62931649,0.00083316,0.14680350,547.44037299,-0.08454324,-0.06226027,0.00000000,0.00000000,0.00000000,0.00000000
194.09000000,4.43611400,4.68400000,0.14749611,465.13937300,0.13758227,533.74562164,0.00079939,0.14807742,548.49404316,-0.08529201,-0.06278541,0.00000000,0.00000000,0.00000000,0.00000000
195.59000000,4.47850800,4.68800000,0.14891344,465.53658851,0.13881666,534.86124543,0.00081156,0.14931917,549.41470580,-0.08599891,-0.06332027,0.00000000,0.00000000,0.00000000,0.00000000
197.09000000,4.52111000,4.69000000,0.15032300,465.73519627,0.14004277,535.74590818,0.00087647,0.15058951,550.46985081,-0.08671541,-0.06387410,0.00000000,0.00000000,0.00000000,0.00000000
198.59000000,4.56380900,4.69400000,0.15175533,466.13241179,0.14128716,536.87049132,0.00080917,0.15189202,551.42735772,-0.08751517,-0.06437686,0.00000000,0.00000000,0.00000000,0.00000000
200.09000000,4.60630800,4.69800000,0.15318011,466.52962731,0.14252344,537.99268746,0.00082803,0.15306711,552.19805943,-0.08814192,-0.06492519,0.00000000,0.00000000,0.00000000,0.00000000
201.59000000,4.64884200,4.70100000,0.15462778,466.82753895,0.14377802,539.01204391,0.00083392,0.15436289,553.38994912,-0.08890955,-0.06545333,0.00000000,0.00000000,0.00000000,0.00000000
203.09000000,4.69201800,4.70300000,0.15601511,467.02614671,0.14497884,539.88928288,0.00076061,0.15572518,554.26782423,-0.08977902,-0.06594616,0.00000000,0.00000000,0.00000000,0.00000000
204.59000000,4.73526000,4.70800000,0.15754522,467.52266611,0.14630158,541.17862844,0.00094840,0.15695733,555.19223136,-0.09045152,-0.06650581,0.00000000,0.00000000,0.00000000,0.00000000
206.09000000,4.77874500,4.71100000,0.15894767,467.82057775,0.14751241,542.17956700,0.00086381,0.15828276,556.17036143,-0.09128687,-0.06699590,0.00000000,0.00000000,0.00000000,0.00000000
207.59000000,4.82215400,4.71400000,0.16039844,468.11848939,0.14876343,543.20396690,0.00083590,0.15954323,557.11365929,-0.09199050,-0.06755273,0.00000000,0.00000000,0.00000000,0.00000000
209.09000000,4.86537100,4.71600000,0.16185744,468.31709715,0.15001997,544.11770568,0.00083524,0.16083366,558.07531786,-0.09274126,-0.06809240,0.00000000,0.00000000,0.00000000,0.00000000
210.59000000,4.90925500,4.71900000,0.16330489,468.61500879,0.15126500,545.14213073,0.00090567,0.16215553,558.93768847,-0.09352765,-0.06862788,0.00000000,0.00000000,0.00000000,0.00000000
212.09000000,4.95277000,4.72200000,0.16477089,468.91292043,0.15252441,546.17611914,0.00083925,0.16350534,559.93587035,-0.09433006,-0.06917527,0.00000000,0.00000000,0.00000000,0.00000000
213.59000000,4.99696100,4.72500000,0.16627489,469.21083207,0.15381481,547.22881103,0.00083836,0.16479223,560.78130284,-0.09504166,-0.06975057,0.00000000,0.00000000,0.00000000,0.00000000
215.09000000,5.04108100,4.72700000,0.16770322,469.40943983,0.15503876,548.13091543,0.00083696,0.16613690,561.89879125,-0.09585815,-0.07027875,0.00000000,0.00000000,0.00000000,0.00000000
216.59000000,5.08554600,4.73000000,0.16920689,469.70735147,0.15632565,549.18507110,0.00077104,0.16748451,562.66232554,-0.09660474,-0.07087977,0.00000000,0.00000000,0.00000000,0.00000000
218.09000000,5.13055000,4.73200000,0.17074833,469.90595923,0.15764315,550.14161859,0.00089896,0.16879752,563.52663784,-0.09737909,-0.07141843,0.00000000,0.00000000,0.00000000,0.00000000
219.59000000,5.17480600,4.73400000,0.17217689,470.10456699,0.15886261,551.04570878,0.00083376,0.17020191,564.44423491,-0.09823745,-0.07196446,0.00000000,0.00000000,0.00000000,0.00000000
221.09000000,5.21880200,4.73600000,0.17368111,470.30317475,0.16014506,551.98595269,0.00083364,0.17157191,565.46342451,-0.09903852,-0.07253338,0.00000000,0.00000000,0.00000000,0.00000000
222.59000000,5.26461300,4.73900000,0.17522222,470.60108638,0.16145726,553.06085452,0.00089516,0.17291048,566.34655634,-0.09982431,-0.07308617,0.00000000,0.00000000,0.00000000,0.00000000
224.09000000,5.30988700,4.74100000,0.17672633,470.79969414,0.16273629,554.00239782,0.00095882,0.17424874,567.11084081,-0.10059113,-0.07365761,0.00000000,0.00000000,0.00000000,0.00000000
225.59000000,5.35483000,4.74300000,0.17823011,470.99830190,0.16401341,554.94438159,0.00076646,0.17567711,568.04794281,-0.10143620,-0.07424091,0.00000000,0.00000000,0.00000000,0.00000000
227.09000000,5.40044100,4.74500000,0.17977122,471.19690966,0.16532054,555.90455402,0.00076470,0.17700811,569.05112654,-0.10218058,-0.07482753,0.00000000,0.00000000,0.00000000,0.00000000
228.59000000,5.44578100,4.74600000,0.18131300,471.29621354,0.16662653,556.74834391,0.00082788,0.17849604,569.90504258,-0.10308730,-0.07540874,0.00000000,0.00000000,0.00000000,0.00000000
230.09000000,5.49244800,4.74800000,0.18292944,471.49482130,0.16799394,557.74510702,0.00089046,0.17994876,570.86073177,-0.10396922,-0.07597955,0.00000000,0.00000000,0.00000000,0.00000000
231.59000000,5.53809100,4.74900000,0.18450844,471.59412518,0.16932787,558.60722363,0.00095233,0.18133792,571.78138088,-0.10478637,-0.07655155,0.00000000,0.00000000,0.00000000,0.00000000
233.09000000,5.58448500,4.75100000,0.18601211,471.79273294,0.17059651,559.55189520,0.00088739,0.18278816,572.61767068,-0.10565419,-0.07713397,0.00000000,0.00000000,0.00000000,0.00000000
234.59000000,5.63057200,4.75300000,0.18759100,471.99134070,0.17192689,560.53266830,0.00088621,0.18426548,573.59211305,-0.10650549,-0.07775998,0.00000000,0.00000000,0.00000000,0.00000000
236.09000000,5.67740200,4.75400000,0.18917022,472.09064458,0.17325577,561.39613673,0.00088503,0.18571122,574.42847314,-0.10735052,-0.07836070,0.00000000,0.00000000,0.00000000,0.00000000
237.59000000,5.72491500,4.75600000,0.19078711,472.28925234,0.17461453,562.39595440,0.00088458,0.18721654,575.30059983,-0.10823212,-0.07898441,0.00000000,0.00000000,0.00000000,0.00000000
239.09000000,5.77211900,4.75700000,0.19240389,472.38855622,0.17597134,563.27795150,0.00088375,0.00000000,0.00000000,0.00000000,0.00000000,0.00000000,0.00000000,0.00000000,0.00000000
240.59000000,5.82017100,4.75900000,0.19405800,472.58716398,0.17735759,564.29648385,0.00094471,0.00000000,0.00000000,0.00000000,0.00000000,0.00000000,0.00000000,0.00000000,0.00000000
242.09000000,5.86764500,4.75900000,0.19571211,472.58716398,0.17874192,565.07819553,0.00100663,0.00000000,0.00000000,0.00000000,0.00000000,0.00000000,0.00000000,0.00000000,0.00000000
243.59000000,5.91572700,4.76100000,0.19736644,472.78577174,0.18012452,566.09781849,0.00100542,0.00000000,0.00000000,0.00000000,0.00000000,0.00000000,0.00000000,0.00000000,0.00000000
245.09000000,5.96343800,4.76100000,0.19902056,472.78577174,0.18150502,566.87985869,0.00094099,0.00000000,0.00000000,0.00000000,0.00000000,0.00000000,0.00000000,0.00000000,0.00000000
246.59000000,6.01233600,4.76200000,0.20067500,472.88507562,0.18288390,567.78128817,0.00093988,0.00000000,0.00000000,0.00000000,0.00000000,0.00000000,0.00000000,0.00000000,0.00000000
248.09000000,6.06109400,4.76400000,0.20232878,473.08368338,0.18426032,568.80212682,0.00087479,0.00000000,0.00000000,0.00000000,0.00000000,0.00000000,0.00000000,0.00000000,0.00000000
249.59000000,6.11079700,4.76400000,0.20409578,473.08368338,0.18572889,569.63806569,0.00093647,0.00000000,0.00000000,0.00000000,0.00000000,0.00000000,0.00000000,0.00000000,0.00000000
251.09000000,6.16017600,4.76400000,0.20575000,473.08368338,0.18710178,570.42065123,0.00081017,0.00000000,0.00000000,0.00000000,0.00000000,0.00000000,0.00000000,0.00000000,0.00000000
252.59000000,6.21008200,4.76500000,0.20747956,473.18298726,0.18853518,571.35878315,0.00080938,0.00000000,0.00000000,0.00000000,0.00000000,0.00000000,0.00000000,0.00000000,0.00000000
254.09000000,6.25948600,4.76600000,0.20928467,473.28229114,0.19002900,572.33301768,0.00105784,0.00000000,0.00000000,0.00000000,0.00000000,0.00000000,0.00000000,0.00000000,0.00000000
255.59000000,6.30919300,4.76700000,0.21101389,473.38159502,0.19145793,573.27168631,0.00099390,0.00000000,0.00000000,0.00000000,0.00000000,0.00000000,0.00000000,0.00000000,0.00000000
257.09000000,6.36008600,4.76700000,0.21289389,473.38159502,0.19300915,574.16164371,0.00105414,0.00000000,0.00000000,0.00000000,0.00000000,0.00000000,0.00000000,0.00000000,0.00000000
258.59000000,6.41115000,4.76700000,0.21469844,473.38159502,0.19449585,575.01588710,0.00111517,0.00000000,0.00000000,0.00000000,0.00000000,0.00000000,0.00000000,0.00000000,0.00000000
260.09000000,6.46159900,4.76700000,0.21650289,473.38159502,0.00000000,0.00000000,0.00000000,0.00000000,0.00000000,0.00000000,0.00000000,0.00000000,0.00000000,0.00000000,0.00000000
261.59000000,6.51364500,4.76800000,0.21842056,473.48089890,0.00000000,0.00000000,0.00000000,0.00000000,0.00000000,0.00000000,0.00000000,0.00000000,0.00000000,0.00000000,0.00000000
263.09000000,6.56568700,4.76800000,0.22033767,473.48089890,0.00000000,0.00000000,0.00000000,0.00000000,0.00000000,0.00000000,0.00000000,0.00000000,0.00000000,0.00000000,0.00000000
264.59000000,6.61725300,4.76700000,0.22225511,473.38159502,0.00000000,0.00000000,0.00000000,0.00000000,0.00000000,0.00000000,0.00000000,0.00000000,0.00000000,0.00000000,0.00000000
266.09000000,6.66987200,4.76800000,0.22421011,473.48089890,0.00000000,0.00000000,0.00000000,0.00000000,0.00000000,0.00000000,0.00000000,0.00000000,0.00000000,0.00000000,0.00000000
267.59000000,6.72218600,4.76800000,0.22620267,473.48089890,0.00000000,0.00000000,0.00000000,0.00000000,0.00000000,0.00000000,0.00000000,0.00000000,0.00000000,0.00000000,0.00000000
269.09000000,6.77551300,4.76800000,0.22823300,473.48089890,0.00000000,0.00000000,0.00000000,0.00000000,0.00000000,0.00000000,0.00000000,0.00000000,0.00000000,0.00000000,0.00000000
270.59000000,6.82890800,4.76700000,0.23037556,473.38159502,0.00000000,0.00000000,0.00000000,0.00000000,0.00000000,0.00000000,0.00000000,0.00000000,0.00000000,0.00000000,0.00000000
272.09000000,6.88156000,4.76600000,0.23244344,473.28229114,0.00000000,0.00000000,0.00000000,0.00000000,0.00000000,0.00000000,0.00000000,0.00000000,0.00000000,0.00000000,0.00000000
273.59000000,6.93562800,4.76600000,0.23466122,473.28229114,0.00000000,0.00000000,0.00000000,0.00000000,0.00000000,0.00000000,0.00000000,0.00000000,0.00000000,0.00000000,0.00000000
275.09000000,6.99034100,4.76500000,0.23684133,473.18298726,0.00000000,0.00000000,0.00000000,0.00000000,0.00000000,0.00000000,0.00000000,0.00000000,0.00000000,0.00000000,0.00000000
276.59000000,7.04394100,4.76500000,0.23913478,473.18298726,0.00000000,0.00000000,0.00000000,0.00000000,0.00000000,0.00000000,0.00000000,0.00000000,0.00000000,0.00000000,0.00000000
278.09000000,7.09868200,4.76300000,0.24142778,472.98437950,0.00000000,0.00000000,0.00000000,0.00000000,0.00000000,0.00000000,0.00000000,0.00000000,0.00000000,0.00000000,0.00000000
279.59000000,7.15407600,4.76300000,0.24387122,472.98437950,0.00000000,0.00000000,0.00000000,0.00000000,0.00000000,0.00000000,0.00000000,0.00000000,0.00000000,0.00000000,0.00000000
281.09000000,7.20959800,4.76200000,0.24639000,472.88507562,0.00000000,0.00000000,0.00000000,0.00000000,0.00000000,0.00000000,0.00000000,0.00000000,0.00000000,0.00000000,0.00000000
282.59000000,7.26600700,4.76000000,0.24902156,472.68646786,0.00000000,0.00000000,0.00000000,0.00000000,0.00000000,0.00000000,0.00000000,0.00000000,0.00000000,0.00000000,0.00000000
284.09000000,7.32220800,4.75700000,0.25169011,472.38855622,0.00000000,0.00000000,0.00000000,0.00000000,0.00000000,0.00000000,0.00000000,0.00000000,0.00000000,0.00000000,0.00000000
285.59000000,7.37868000,4.75500000,0.25450967,472.18994846,0.00000000,0.00000000,0.00000000,0.00000000,0.00000000,0.00000000,0.00000000,0.00000000,0.00000000,0.00000000,0.00000000
287.09000000,7.43563000,4.75300000,0.25740433,471.99134070,0.00000000,0.00000000,0.00000000,0.00000000,0.00000000,0.00000000,0.00000000,0.00000000,0.00000000,0.00000000,0.00000000
288.59000000,7.49261500,4.74900000,0.26037367,471.59412518,0.00000000,0.00000000,0.00000000,0.00000000,0.00000000,0.00000000,0.00000000,0.00000000,0.00000000,0.00000000,0.00000000
290.09000000,7.55027500,4.74500000,0.26349400,471.19690966,0.00000000,0.00000000,0.00000000,0.00000000,0.00000000,0.00000000,0.00000000,0.00000000,0.00000000,0.00000000,0.00000000
291.59000000,7.60871400,4.74100000,0.26665156,470.79969414,0.00000000,0.00000000,0.00000000,0.00000000,0.00000000,0.00000000,0.00000000,0.00000000,0.00000000,0.00000000,0.00000000
293.09000000,7.66728400,4.73600000,0.26999689,470.30317475,0.00000000,0.00000000,0.00000000,0.00000000,0.00000000,0.00000000,0.00000000,0.00000000,0.00000000,0.00000000,0.00000000
294.59000000,7.72643300,4.72900000,0.27341789,469.60804759,0.00000000,0.00000000,0.00000000,0.00000000,0.00000000,0.00000000,0.00000000,0.00000000,0.00000000,0.00000000,0.00000000
296.09000000,7.78598700,4.72300000,0.27680089,469.01222431,0.00000000,0.00000000,0.00000000,0.00000000,0.00000000,0.00000000,0.00000000,0.00000000,0.00000000,0.00000000,0.00000000
297.59000000,7.84469200,4.71300000,0.28025844,468.01918551,0.00000000,0.00000000,0.00000000,0.00000000,0.00000000,0.00000000,0.00000000,0.00000000,0.00000000,0.00000000,0.00000000
299.09000000,7.90491500,4.70500000,0.28371578,467.22475447,0.00000000,0.00000000,0.00000000,0.00000000,0.00000000,0.00000000,0.00000000,0.00000000,0.00000000,0.00000000,0.00000000
300.59000000,7.96584700,4.69000000,0.28735978,465.73519627,0.00000000,0.00000000,0.00000000,0.00000000,0.00000000,0.00000000,0.00000000,0.00000000,0.00000000,0.00000000,0.00000000
302.09000000,8.02823400,4.67200000,0.29104000,463.94772644,0.00000000,0.00000000,0.00000000,0.00000000,0.00000000,0.00000000,0.00000000,0.00000000,0.00000000,0.00000000,0.00000000
303.59000000,8.09317700,4.64000000,0.29524189,460.77000228,0.00000000,0.00000000,0.00000000,0.00000000,0.00000000,0.00000000,0.00000000,0.00000000,0.00000000,0.00000000,0.00000000
304.59000000,8.14312800,4.60300000,0.29869189,457.09575873,0.00000000,0.00000000,0.00000000,0.00000000,0.00000000,0.00000000,0.00000000,0.00000000,0.00000000,0.00000000,0.00000000