File: polyN_optimization/AA7020-T6_results/DATA/UT_75_1.csv
Time[s],Displacement[mm],Force[kN],EngStrain_longi,EngStress[MPa],TrueStrain,TrueStress[MPa],TrueStrainRate[1/s],PlasticStrain_longi,PlasticStress[MPa],PlasticStrain_thick,PlasticStrain_width,R-Value,Thickness[mm],Width[mm], Young's Modulus [MPa]
0.65000000,0.00000000,-0.00900000,0.00000000,-0.88929731,0.00000000,-0.88929731,0.00000000,0.00054005,268.49894151,0.00015893,-0.00069898,0.64409715,1.00700000,10.05000000,74121.06444256
2.15000000,0.00424000,0.03500000,0.00010756,3.45837842,0.00010755,3.45875038,0.00016666,0.00090299,277.96235418,0.00003604,-0.00093904,0.00000000,0.00000000,0.00000000,0.00000000
3.65000000,0.01092700,0.27000000,0.00028167,26.67891921,0.00028163,26.68643377,0.00007909,0.00161170,286.53740192,-0.00036945,-0.00124225,0.00000000,0.00000000,0.00000000,0.00000000
5.15000000,0.01844400,0.48400000,0.00052233,47.82443295,0.00052220,47.84941324,0.00020235,0.00220567,293.89461445,-0.00085969,-0.00134597,0.00000000,0.00000000,0.00000000,0.00000000
6.65000000,0.02440100,0.64600000,0.00071256,63.83178447,0.00071230,63.87726817,0.00022696,0.00283600,301.07313214,-0.00107312,-0.00176288,0.00000000,0.00000000,0.00000000,0.00000000
8.15000000,0.03014600,0.83400000,0.00087733,82.40821711,0.00087695,82.48051658,0.00010369,0.00374191,307.14717679,-0.00176481,-0.00197711,0.00000000,0.00000000,0.00000000,0.00000000
9.65000000,0.03716200,1.00600000,0.00118611,99.40367675,0.00118541,99.52158056,0.00011254,0.00458904,313.11438498,-0.00225405,-0.00233499,0.00000000,0.00000000,0.00000000,0.00000000
11.15000000,0.04352200,1.18600000,0.00136200,117.18962289,0.00136107,117.34923515,0.00024590,0.00544227,318.19251324,-0.00274564,-0.00269663,0.00000000,0.00000000,0.00000000,0.00000000
12.65000000,0.05095700,1.33600000,0.00147644,132.01124467,0.00147536,132.20615194,-0.00015421,0.00648656,322.84019163,-0.00344425,-0.00304231,0.00000000,0.00000000,0.00000000,0.00000000
14.15000000,0.05612200,1.51900000,0.00189433,150.09362324,0.00189254,150.37795060,0.00023002,0.00750280,327.28771050,-0.00406475,-0.00343805,0.00000000,0.00000000,0.00000000,0.00000000
15.65000000,0.06309200,1.66300000,0.00194767,164.32238015,0.00194577,164.64242538,0.00024886,0.00848334,331.53147944,-0.00454245,-0.00394089,0.00000000,0.00000000,0.00000000,0.00000000
17.15000000,0.06977000,1.82700000,0.00219667,180.52735330,0.00219426,180.92391172,-0.00011308,0.00961917,335.43342625,-0.00525725,-0.00436192,0.00000000,0.00000000,0.00000000,0.00000000
18.65000000,0.07710100,1.97300000,0.00250778,194.95373184,0.00250464,195.44263247,0.00040414,0.01069019,339.32213315,-0.00597084,-0.00471935,0.00000000,0.00000000,0.00000000,0.00000000
20.15000000,0.08223000,2.12500000,0.00257922,209.97297524,0.00257590,210.51454221,0.00005032,0.01172077,342.80162310,-0.00663436,-0.00508641,0.00000000,0.00000000,0.00000000,0.00000000
21.65000000,0.09123200,2.25100000,0.00297233,222.42313754,0.00296792,223.08425325,0.00024152,0.01284117,346.11744664,-0.00737894,-0.00546222,0.00000000,0.00000000,0.00000000,0.00000000
23.15000000,0.09991800,2.40000000,0.00314389,237.14594851,0.00313896,237.89150902,0.00031371,0.01396126,349.33931172,-0.00806964,-0.00589162,0.00000000,0.00000000,0.00000000,0.00000000
24.65000000,0.11031100,2.51300000,0.00354522,248.31157025,0.00353895,249.19188995,0.00022499,0.01501622,352.64643561,-0.00863097,-0.00638525,0.00000000,0.00000000,0.00000000,0.00000000
26.15000000,0.12155000,2.63400000,0.00385767,260.26767849,0.00385024,261.27170444,0.00030706,0.01612162,355.67432533,-0.00929814,-0.00682347,0.00000000,0.00000000,0.00000000,0.00000000
27.65000000,0.13726300,2.73600000,0.00438400,270.34638130,0.00437442,271.53157984,0.00041201,0.01722026,358.80779934,-0.00998882,-0.00723143,0.00000000,0.00000000,0.00000000,0.00000000
29.15000000,0.15627600,2.83400000,0.00490722,280.02984087,0.00489522,281.40400952,0.00047196,0.01829118,361.73466776,-0.01065851,-0.00763267,0.00000000,0.00000000,0.00000000,0.00000000
30.65000000,0.17699200,2.90700000,0.00558233,287.24303013,0.00556681,288.84651647,0.00016597,0.01938544,364.47269116,-0.01138100,-0.00800444,0.00000000,0.00000000,0.00000000,0.00000000
32.15000000,0.20128800,2.98700000,0.00650178,295.14789508,0.00648073,297.06688111,0.00060703,0.02050964,367.32939263,-0.01209561,-0.00841404,0.00000000,0.00000000,0.00000000,0.00000000
33.65000000,0.22691300,3.04500000,0.00729778,300.87892217,0.00727128,303.07466968,0.00073345,0.02163150,369.98743118,-0.01277253,-0.00885896,0.00000000,0.00000000,0.00000000,0.00000000
35.15000000,0.25565700,3.10500000,0.00825956,306.80757088,0.00822563,309.34166506,0.00066617,0.02271205,372.63569571,-0.01339668,-0.00931537,0.00000000,0.00000000,0.00000000,0.00000000
36.65000000,0.28545400,3.15600000,0.00930356,311.84692229,0.00926054,314.74820746,0.00088045,0.02379050,375.59531739,-0.01400055,-0.00978995,0.00000000,0.00000000,0.00000000,0.00000000
38.15000000,0.31456700,3.20600000,0.01024156,316.78746288,0.01018947,320.03185928,0.00089460,0.02491246,377.96361044,-0.01468352,-0.01022894,0.00000000,0.00000000,0.00000000,0.00000000
39.65000000,0.34645600,3.24500000,0.01126244,320.64108455,0.01119950,324.25228695,0.00070046,0.02600941,380.73719387,-0.01536575,-0.01064366,0.00000000,0.00000000,0.00000000,0.00000000
41.15000000,0.37948900,3.29000000,0.01242644,325.08757108,0.01234987,329.12725372,0.00084853,0.02712112,383.11196110,-0.01608750,-0.01103361,0.00000000,0.00000000,0.00000000,0.00000000
42.65000000,0.41204300,3.32300000,0.01351856,328.34832787,0.01342800,332.78712299,0.00092899,0.02821800,385.69135894,-0.01679116,-0.01142684,0.00000000,0.00000000,0.00000000,0.00000000
44.15000000,0.44571200,3.36000000,0.01461400,332.00432791,0.01450824,336.85623916,0.00071238,0.02933660,388.18178307,-0.01752366,-0.01181294,0.00000000,0.00000000,0.00000000,0.00000000
45.65000000,0.48056500,3.39200000,0.01582167,335.16627389,0.01569781,340.46916296,0.00084438,0.03045232,390.77928253,-0.01820028,-0.01225204,0.00000000,0.00000000,0.00000000,0.00000000
47.15000000,0.51405900,3.42400000,0.01695422,338.32821987,0.01681210,344.06431170,0.00091777,0.03151435,392.94878508,-0.01880594,-0.01270841,0.00000000,0.00000000,0.00000000,0.00000000
48.65000000,0.54896900,3.45100000,0.01807156,340.99611179,0.01791021,347.15844197,0.00078355,0.03259758,395.33737074,-0.01941814,-0.01317945,0.00000000,0.00000000,0.00000000,0.00000000
50.15000000,0.58384400,3.48300000,0.01924522,344.15805777,0.01906238,350.78145608,0.00076062,0.03373010,397.75053430,-0.02009878,-0.01363132,0.00000000,0.00000000,0.00000000,0.00000000
51.65000000,0.61756700,3.50800000,0.02041500,346.62832807,0.02020941,353.70474539,0.00085539,0.03484294,400.16089870,-0.02076325,-0.01407969,0.00000000,0.00000000,0.00000000,0.00000000
53.15000000,0.65278000,3.53500000,0.02152467,349.29621999,0.02129628,356.81470470,0.00073651,0.03591765,402.35376443,-0.02139979,-0.01451787,0.00000000,0.00000000,0.00000000,0.00000000
54.65000000,0.68836200,3.56000000,0.02270567,351.76649029,0.02245173,359.75358296,0.00076544,0.03699932,404.76117047,-0.02206699,-0.01493232,0.00000000,0.00000000,0.00000000,0.00000000
56.15000000,0.72268700,3.58600000,0.02388267,354.33557140,0.02360194,362.79804974,0.00084489,0.03813149,406.77899774,-0.02280589,-0.01532560,0.00000000,0.00000000,0.00000000,0.00000000
57.65000000,0.75796000,3.60700000,0.02501867,356.41059845,0.02471082,365.32751641,0.00080015,0.03919395,409.08403986,-0.02346059,-0.01573336,0.00000000,0.00000000,0.00000000,0.00000000
59.15000000,0.79296100,3.63400000,0.02617322,359.07849037,0.02583657,368.47673149,0.00072602,0.04026165,411.18778912,-0.02409680,-0.01616485,0.00000000,0.00000000,0.00000000,0.00000000
60.65000000,0.82758700,3.65600000,0.02738033,361.25232823,0.02701220,371.14353739,0.00076174,0.04138700,413.42379125,-0.02478331,-0.01660369,0.00000000,0.00000000,0.00000000,0.00000000
62.15000000,0.86302200,3.67600000,0.02854589,363.22854447,0.02814605,373.59722614,0.00079675,0.04248046,415.54684413,-0.02544860,-0.01703186,0.00000000,0.00000000,0.00000000,0.00000000
63.65000000,0.89788600,3.69800000,0.02969667,365.40238233,0.02926426,376.25361508,0.00079629,0.04357478,417.77891602,-0.02608838,-0.01748640,0.00000000,0.00000000,0.00000000,0.00000000
65.15000000,0.93271500,3.72100000,0.03086633,367.67503100,0.03039955,379.02381107,0.00075894,0.04468986,419.71075460,-0.02675893,-0.01793093,0.00000000,0.00000000,0.00000000,0.00000000
66.65000000,0.96815200,3.74100000,0.03206222,369.65124724,0.03155896,381.50308767,0.00080890,0.04581516,421.86007697,-0.02744037,-0.01837478,0.00000000,0.00000000,0.00000000,0.00000000
68.15000000,1.00335400,3.76200000,0.03321289,371.72627429,0.03267326,384.07237773,0.00074991,0.04688466,423.78053921,-0.02808395,-0.01880071,0.00000000,0.00000000,0.00000000,0.00000000
69.65000000,1.03861900,3.78200000,0.03441622,373.70249053,0.03383723,386.56391849,0.00081437,0.04797513,425.92343836,-0.02876451,-0.01921061,0.00000000,0.00000000,0.00000000,0.00000000
71.15000000,1.07368300,3.80300000,0.03555189,375.77751758,0.03493451,389.13711813,0.00070442,0.04913079,427.88871335,-0.02951710,-0.01961369,0.00000000,0.00000000,0.00000000,0.00000000
72.65000000,1.10918700,3.82000000,0.03673622,377.45730138,0.03607753,391.32365668,0.00068882,0.05017608,430.02056423,-0.03014040,-0.02003568,0.00000000,0.00000000,0.00000000,0.00000000
74.15000000,1.14451600,3.84200000,0.03790178,379.63113924,0.03720115,394.01983432,0.00075337,0.05129666,431.76831893,-0.03086054,-0.02043612,0.00000000,0.00000000,0.00000000,0.00000000
75.65000000,1.17964600,3.85800000,0.03906000,381.21211223,0.03831646,396.10225733,0.00075296,0.05239190,433.71919579,-0.03150997,-0.02088194,0.00000000,0.00000000,0.00000000,0.00000000
77.15000000,1.21511300,3.87800000,0.04024044,383.18832847,0.03945188,398.60799711,0.00069355,0.05352083,435.68868764,-0.03222740,-0.02129343,0.00000000,0.00000000,0.00000000,0.00000000
78.65000000,1.25078500,3.89500000,0.04145133,384.86811227,0.04061525,400.82140868,0.00072946,0.05458869,437.63529748,-0.03281843,-0.02177026,0.00000000,0.00000000,0.00000000,0.00000000
80.15000000,1.28608100,3.91400000,0.04263544,386.74551769,0.04175159,403.23458473,0.00079345,0.05569184,439.49555210,-0.03348639,-0.02220544,0.00000000,0.00000000,0.00000000,0.00000000
81.65000000,1.32154800,3.93000000,0.04377078,388.32649068,0.04283990,405.32384321,0.00074168,0.05680988,441.47193012,-0.03416167,-0.02264822,0.00000000,0.00000000,0.00000000,0.00000000
83.15000000,1.35711800,3.94800000,0.04495156,390.10508530,0.04397053,407.64091571,0.00068404,0.05794473,443.14186905,-0.03486346,-0.02308127,0.00000000,0.00000000,0.00000000,0.00000000
84.65000000,1.39224800,3.96400000,0.04613967,391.68605829,0.04510688,409.75832246,0.00076954,0.05903553,445.11366435,-0.03553796,-0.02349757,0.00000000,0.00000000,0.00000000,0.00000000
86.15000000,1.42819000,3.98100000,0.04729389,393.36584209,0.04620959,411.96964252,0.00078270,0.06013955,446.77664723,-0.03620499,-0.02393456,0.00000000,0.00000000,0.00000000,0.00000000
87.65000000,1.46365400,3.99700000,0.04847444,394.94681508,0.04733620,414.09164253,0.00072478,0.06123621,448.65218001,-0.03689634,-0.02433987,0.00000000,0.00000000,0.00000000,0.00000000
89.15000000,1.49918900,4.01400000,0.04966622,396.62659888,0.04847223,416.32554368,0.00075255,0.06238179,450.44709304,-0.03762835,-0.02475344,0.00000000,0.00000000,0.00000000,0.00000000
90.65000000,1.53506100,4.02800000,0.05087678,398.00995025,0.04962484,418.25941404,0.00080880,0.06348610,452.33342578,-0.03829624,-0.02518987,0.00000000,0.00000000,0.00000000,0.00000000
92.15000000,1.57096600,4.04600000,0.05204622,399.78854486,0.05073705,420.59602831,0.00075085,0.06460379,453.90945702,-0.03896828,-0.02563552,0.00000000,0.00000000,0.00000000,0.00000000
93.65000000,1.60663500,4.05900000,0.05324567,401.07308542,0.05187651,422.42848923,0.00072108,0.06572078,455.70185357,-0.03966725,-0.02605353,0.00000000,0.00000000,0.00000000,0.00000000
95.15000000,1.64226600,4.07500000,0.05443000,402.65405841,0.05300034,424.57051881,0.00077782,0.06685521,457.39884466,-0.04036389,-0.02649132,0.00000000,0.00000000,0.00000000,0.00000000
96.65000000,1.67800000,4.08900000,0.05562167,404.03740977,0.05412985,426.51064390,0.00079800,0.06795924,459.19221766,-0.04100678,-0.02695247,0.00000000,0.00000000,0.00000000,0.00000000
98.15000000,1.71387100,4.10400000,0.05681722,405.51957195,0.05526177,428.56006759,0.00069739,0.06909250,460.78821604,-0.04169731,-0.02739518,0.00000000,0.00000000,0.00000000,0.00000000
99.65000000,1.75004400,4.11800000,0.05801656,406.90292332,0.05639598,430.51002937,0.00081763,0.07023317,462.49809779,-0.04238431,-0.02784886,0.00000000,0.00000000,0.00000000,0.00000000
101.15000000,1.78605100,4.13400000,0.05920856,408.48389631,0.05752198,432.66963778,0.00078124,0.07132589,464.08149428,-0.04304553,-0.02828036,0.00000000,0.00000000,0.00000000,0.00000000
102.65000000,1.82205600,4.14600000,0.06039289,409.66962605,0.05863949,434.41075826,0.00077303,0.07243956,465.78526913,-0.04371241,-0.02872714,0.00000000,0.00000000,0.00000000,0.00000000
104.15000000,1.85826300,4.16000000,0.06159611,411.05297742,0.05977354,436.37224229,0.00073006,0.07357983,467.50485586,-0.04440198,-0.02917785,0.00000000,0.00000000,0.00000000,0.00000000
105.65000000,1.89430300,4.17300000,0.06278044,412.33751797,0.06088853,438.22425061,0.00077171,0.07468855,468.88943187,-0.04508571,-0.02960284,0.00000000,0.00000000,0.00000000,0.00000000
107.15000000,1.93040800,4.18700000,0.06397967,413.72086934,0.06201628,440.19059265,0.00077063,0.07580700,470.49707866,-0.04577978,-0.03002722,0.00000000,0.00000000,0.00000000,0.00000000
108.65000000,1.96651400,4.19900000,0.06516400,414.90659908,0.06312878,441.94357270,0.00070612,0.07694423,472.11672644,-0.04648079,-0.03046344,0.00000000,0.00000000,0.00000000,0.00000000
110.15000000,2.00299200,4.21300000,0.06639711,416.28995045,0.06428578,443.93040054,0.00070530,0.07808719,473.74224864,-0.04717978,-0.03090741,0.00000000,0.00000000,0.00000000,0.00000000
111.65000000,2.03953800,4.22500000,0.06760411,417.47568019,0.06541699,445.69875246,0.00073282,0.07923042,475.26272417,-0.04787036,-0.03136006,0.00000000,0.00000000,0.00000000,0.00000000
113.15000000,2.07611600,4.23700000,0.06883344,418.66140993,0.06656781,447.47931683,0.00078148,0.08032564,476.65461489,-0.04853945,-0.03178620,0.00000000,0.00000000,0.00000000,0.00000000
114.65000000,2.11296900,4.24900000,0.07001011,419.84713967,0.06766810,449.24068457,0.00073803,0.08147138,478.29053031,-0.04924456,-0.03222682,0.00000000,0.00000000,0.00000000,0.00000000
116.15000000,2.14934400,4.26200000,0.07125467,421.13168023,0.06883055,451.13927773,0.00072327,0.08260345,479.81431266,-0.04993477,-0.03266868,0.00000000,0.00000000,0.00000000,0.00000000
117.65000000,2.18623100,4.27200000,0.07249133,422.11978835,0.06998429,452.71981463,0.00077115,0.08373779,481.34209408,-0.05063915,-0.03309864,0.00000000,0.00000000,0.00000000,0.00000000
119.15000000,2.22281200,4.28500000,0.07369078,423.40432890,0.07110204,454.60532321,0.00072867,0.08487359,482.65553892,-0.05129742,-0.03357617,0.00000000,0.00000000,0.00000000,0.00000000
120.65000000,2.25976100,4.29500000,0.07490889,424.39243702,0.07223590,456.18320293,0.00071399,0.08601528,484.19246880,-0.05198148,-0.03403379,0.00000000,0.00000000,0.00000000,0.00000000
122.15000000,2.29668200,4.30700000,0.07617211,425.57816676,0.07341040,457.99535417,0.00074826,0.08715588,485.73181283,-0.05268777,-0.03446811,0.00000000,0.00000000,0.00000000,0.00000000
123.65000000,2.33380000,4.31800000,0.07740500,426.66508569,0.07455537,459.69109665,0.00078166,0.08827726,487.04594562,-0.05336174,-0.03491553,0.00000000,0.00000000,0.00000000,0.00000000
125.15000000,2.37122900,4.32900000,0.07861933,427.75200462,0.07568183,461.38158206,0.00072493,0.08941311,488.47905734,-0.05405852,-0.03535459,0.00000000,0.00000000,0.00000000,0.00000000
126.65000000,2.40760700,4.33900000,0.07987133,428.74011274,0.07684190,462.98415720,0.00071750,0.09054769,489.91422770,-0.05474207,-0.03580561,0.00000000,0.00000000,0.00000000,0.00000000
128.15000000,2.44452300,4.35000000,0.08110078,429.82703167,0.07797976,464.68633825,0.00076500,0.09172250,491.26222585,-0.05547696,-0.03624554,0.00000000,0.00000000,0.00000000,0.00000000
129.65000000,2.48198100,4.36000000,0.08233011,430.81513979,0.07911623,466.28419812,0.00076455,0.09286092,492.70459557,-0.05621871,-0.03664220,0.00000000,0.00000000,0.00000000,0.00000000
131.15000000,2.51924000,4.37000000,0.08357467,431.80324791,0.08026545,467.89106042,0.00073597,0.09398917,494.03459716,-0.05688313,-0.03710604,0.00000000,0.00000000,0.00000000,0.00000000
132.65000000,2.55636100,4.38000000,0.08480000,432.79135603,0.08139564,469.49206302,0.00074149,0.09514668,495.38161313,-0.05757678,-0.03756990,0.00000000,0.00000000,0.00000000,0.00000000
134.15000000,2.59385300,4.38900000,0.08606333,433.68065334,0.08255954,471.00465597,0.00078894,0.09628567,496.72186502,-0.05827513,-0.03801054,0.00000000,0.00000000,0.00000000,0.00000000
135.65000000,2.63168300,4.39900000,0.08730011,434.66876146,0.08369766,472.61539263,0.00074694,0.09738640,498.04538973,-0.05891540,-0.03847100,0.00000000,0.00000000,0.00000000,0.00000000
137.15000000,2.66920900,4.40900000,0.08855189,435.65686957,0.08484827,474.23510828,0.00071831,0.09856989,499.41288282,-0.05963040,-0.03893949,0.00000000,0.00000000,0.00000000,0.00000000
138.65000000,2.70683900,4.41800000,0.08982644,436.54616688,0.08601846,475.75955689,0.00073114,0.09974170,500.77707014,-0.06034912,-0.03939258,0.00000000,0.00000000,0.00000000,0.00000000
140.15000000,2.74466800,4.42700000,0.09108233,437.43546419,0.08717017,477.27810695,0.00080650,0.10088353,502.01786515,-0.06104121,-0.03984232,0.00000000,0.00000000,0.00000000,0.00000000
141.65000000,2.78223100,4.43500000,0.09234178,438.22595068,0.08832381,478.69251404,0.00077809,0.10204943,503.38400434,-0.06173807,-0.04031135,0.00000000,0.00000000,0.00000000,0.00000000
143.15000000,2.81999200,4.44500000,0.09358978,439.21405880,0.08946566,480.32000496,0.00075647,0.10318663,504.51599421,-0.06244021,-0.04074642,0.00000000,0.00000000,0.00000000,0.00000000
144.65000000,2.85809600,4.45300000,0.09486089,440.00454530,0.09062731,481.74376758,0.00076980,0.10439101,505.79533360,-0.06318672,-0.04120429,0.00000000,0.00000000,0.00000000,0.00000000
146.15000000,2.89643600,4.46200000,0.09613900,440.89384260,0.09179401,483.28093574,0.00079608,0.10552246,507.15115584,-0.06387954,-0.04164291,0.00000000,0.00000000,0.00000000,0.00000000
147.65000000,2.93409700,4.47000000,0.09739844,441.68432910,0.09294233,484.70369569,0.00076782,0.10669070,508.41682564,-0.06459304,-0.04209766,0.00000000,0.00000000,0.00000000,0.00000000
149.15000000,2.97192800,4.47800000,0.09866922,442.47481559,0.09409965,486.13346150,0.00075965,0.10787415,509.69260223,-0.06531391,-0.04256024,0.00000000,0.00000000,0.00000000,0.00000000
150.65000000,3.01013000,4.48600000,0.09994389,443.26530209,0.09525917,487.56696019,0.00080040,0.10904621,510.96486831,-0.06604268,-0.04300353,0.00000000,0.00000000,0.00000000,0.00000000
152.15000000,3.04840100,4.49400000,0.10118056,444.05578858,0.09638284,488.98559997,0.00073732,0.11015339,511.98227813,-0.06669755,-0.04345584,0.00000000,0.00000000,0.00000000,0.00000000
153.65000000,3.08663800,4.50100000,0.10247011,444.74746427,0.09755322,490.32078635,0.00077014,0.11133914,513.26591318,-0.06743988,-0.04389926,0.00000000,0.00000000,0.00000000,0.00000000
155.15000000,3.12626600,4.51000000,0.10374089,445.63676157,0.09870522,491.86751534,0.00068808,0.11249032,514.53400487,-0.06813516,-0.04435516,0.00000000,0.00000000,0.00000000,0.00000000
156.65000000,3.16446900,4.51600000,0.10505689,446.22962645,0.09989682,493.10912273,0.00075546,0.11363830,515.69045300,-0.06879525,-0.04484305,0.00000000,0.00000000,0.00000000,0.00000000
158.15000000,3.20307700,4.52400000,0.10628233,447.02011294,0.10100514,494.53045359,0.00067967,0.11483806,516.87585647,-0.06953868,-0.04529938,0.00000000,0.00000000,0.00000000,0.00000000
159.65000000,3.24195800,4.53100000,0.10759089,447.71178862,0.10218729,495.88149793,0.00069251,0.11601290,518.05040041,-0.07027640,-0.04573650,0.00000000,0.00000000,0.00000000,0.00000000
161.15000000,3.28086800,4.53700000,0.10891789,448.30465350,0.10338466,497.13304993,0.00077308,0.11723449,519.36414408,-0.07102568,-0.04620881,0.00000000,0.00000000,0.00000000,0.00000000
162.65000000,3.31974800,4.54500000,0.11019611,449.09513999,0.10453668,498.58367794,0.00083987,0.11838826,520.41918818,-0.07173362,-0.04665464,0.00000000,0.00000000,0.00000000,0.00000000
164.15000000,3.35852200,4.55100000,0.11150444,449.68800486,0.10571445,499.83021602,0.00079148,0.11957691,521.49432085,-0.07243699,-0.04713992,0.00000000,0.00000000,0.00000000,0.00000000
165.65000000,3.39750200,4.55800000,0.11284311,450.37968054,0.10691810,501.20192488,0.00081829,0.12075411,522.56526945,-0.07314838,-0.04760573,0.00000000,0.00000000,0.00000000,0.00000000
167.15000000,3.43661800,4.56500000,0.11415511,451.07135623,0.10809637,502.56345702,0.00085763,0.12192864,523.74985806,-0.07385349,-0.04807515,0.00000000,0.00000000,0.00000000,0.00000000
168.65000000,3.47620800,4.57000000,0.11543678,451.56541029,0.10924606,503.69266621,0.00078829,0.12317030,524.97203806,-0.07461351,-0.04855679,0.00000000,0.00000000,0.00000000,0.00000000
170.15000000,3.51538800,4.57700000,0.11674522,452.25708597,0.11041840,505.05593997,0.00082797,0.12432677,526.03783361,-0.07527600,-0.04905077,0.00000000,0.00000000,0.00000000,0.00000000
171.65000000,3.55453900,4.58200000,0.11805389,452.75114003,0.11158957,506.20017281,0.00072699,0.12555217,527.02837540,-0.07605004,-0.04950213,0.00000000,0.00000000,0.00000000,0.00000000
173.15000000,3.59426200,4.59000000,0.11937322,453.54162652,0.11276891,507.68235189,0.00078611,0.12671749,528.21617526,-0.07673287,-0.04998462,0.00000000,0.00000000,0.00000000,0.00000000
174.65000000,3.63398600,4.59600000,0.12068522,454.13449140,0.11394030,508.94181341,0.00075821,0.12790895,529.30608526,-0.07744085,-0.05046810,0.00000000,0.00000000,0.00000000,0.00000000
176.15000000,3.67391500,4.60100000,0.12201611,454.62854546,0.11512717,510.10055257,0.00073056,0.12910212,530.39878300,-0.07816684,-0.05093528,0.00000000,0.00000000,0.00000000,0.00000000
177.65000000,3.71397800,4.60600000,0.12335433,455.12259951,0.11631915,511.26394436,0.00073603,0.13028573,531.37405550,-0.07891024,-0.05137549,0.00000000,0.00000000,0.00000000,0.00000000
179.15000000,3.75332700,4.61200000,0.12463256,455.71546439,0.11745637,512.51244732,0.00076860,0.13149729,532.59456811,-0.07965071,-0.05184657,0.00000000,0.00000000,0.00000000,0.00000000
180.65000000,3.79345900,4.61700000,0.12597489,456.20951845,0.11864923,513.68046184,0.00074813,0.13268767,533.57695633,-0.08036049,-0.05232718,0.00000000,0.00000000,0.00000000,0.00000000
182.15000000,3.83335100,4.62200000,0.12733189,456.70357250,0.11985368,514.85650105,0.00082039,0.13391538,534.58105441,-0.08111179,-0.05280359,0.00000000,0.00000000,0.00000000,0.00000000
183.65000000,3.87361600,4.62800000,0.12865911,457.29643738,0.12103030,516.13179052,0.00084641,0.13512231,535.57562538,-0.08184205,-0.05328027,0.00000000,0.00000000,0.00000000,0.00000000
185.15000000,3.91368000,4.63300000,0.13000889,457.79049144,0.12222550,517.30732457,0.00080527,0.13632611,536.68504537,-0.08258503,-0.05374108,0.00000000,0.00000000,0.00000000,0.00000000
186.65000000,3.95441700,4.63700000,0.13135111,458.18573468,0.12341259,518.36894003,0.00079803,0.13755093,537.80777807,-0.08331325,-0.05423768,0.00000000,0.00000000,0.00000000,0.00000000
188.15000000,3.99478500,4.64300000,0.13278344,458.77859955,0.12467783,519.69680224,0.00084981,0.13873724,538.79639288,-0.08401393,-0.05472331,0.00000000,0.00000000,0.00000000,0.00000000
189.65000000,4.03549100,4.64700000,0.13411067,459.17384280,0.12584879,520.75395298,0.00085567,0.13996849,539.69572414,-0.08475117,-0.05521731,0.00000000,0.00000000,0.00000000,0.00000000
191.15000000,4.07558700,4.65200000,0.13543400,459.66789686,0.12701496,521.92255880,0.00078165,0.14114697,540.79867449,-0.08545602,-0.05569096,0.00000000,0.00000000,0.00000000,0.00000000
192.65000000,4.11636200,4.65600000,0.13682133,460.06314011,0.12823606,523.00959236,0.00084053,0.14242842,541.84409104,-0.08622366,-0.05620476,0.00000000,0.00000000,0.00000000,0.00000000
194.15000000,4.15676200,4.66100000,0.13815589,460.55719417,0.12940931,524.18588271,0.00080595,0.14364542,542.74032062,-0.08695770,-0.05668773,0.00000000,0.00000000,0.00000000,0.00000000
195.65000000,4.19841400,4.66500000,0.13952067,460.95243742,0.13060771,525.26482879,0.00068637,0.14486092,543.63711482,-0.08768196,-0.05717895,0.00000000,0.00000000,0.00000000,0.00000000
197.15000000,4.23936000,4.67000000,0.14090433,461.44649148,0.13182122,526.46630173,0.00077166,0.14610532,544.66721540,-0.08843968,-0.05766563,0.00000000,0.00000000,0.00000000,0.00000000
198.65000000,4.28077500,4.67300000,0.14230644,461.74292391,0.13304942,527.45191766,0.00075047,0.14734831,545.69828906,-0.08920343,-0.05814488,0.00000000,0.00000000,0.00000000,0.00000000
200.15000000,4.32212600,4.67800000,0.14367133,462.23697797,0.13424356,528.64718091,0.00077601,0.14858972,546.73023206,-0.08996547,-0.05862424,0.00000000,0.00000000,0.00000000,0.00000000
201.65000000,4.36374500,4.68100000,0.14506244,462.53341041,0.13545917,529.62963756,0.00079487,0.14983091,547.64730539,-0.09067463,-0.05915628,0.00000000,0.00000000,0.00000000,0.00000000
203.15000000,4.40492200,4.68500000,0.14644211,462.92865365,0.13666333,530.72090299,0.00078732,0.15110253,548.58264445,-0.09149815,-0.05960438,0.00000000,0.00000000,0.00000000,0.00000000
204.65000000,4.44654300,4.68900000,0.14781433,463.32389690,0.13785955,531.80980984,0.00078619,0.15237239,549.51852587,-0.09227159,-0.06010080,0.00000000,0.00000000,0.00000000,0.00000000
206.15000000,4.48890700,4.69200000,0.14926189,463.62032934,0.13911990,532.82117542,0.00085078,0.15357567,550.53593295,-0.09295865,-0.06061702,0.00000000,0.00000000,0.00000000,0.00000000
207.65000000,4.53126900,4.69600000,0.15063811,464.01557258,0.14031667,533.91400196,0.00083701,0.15487587,551.37467565,-0.09377761,-0.06109826,0.00000000,0.00000000,0.00000000,0.00000000
209.15000000,4.57295600,4.69900000,0.15204767,464.31200502,0.14154094,534.90956199,0.00080298,0.15610909,552.29466879,-0.09452958,-0.06157951,0.00000000,0.00000000,0.00000000,0.00000000
210.65000000,4.61562400,4.70300000,0.15346511,464.70724827,0.14277055,536.02359776,0.00082146,0.15737080,553.34937988,-0.09527823,-0.06209257,0.00000000,0.00000000,0.00000000,0.00000000
212.15000000,4.65792000,4.70600000,0.15487867,465.00368070,0.14399529,537.02283077,0.00083335,0.15866410,554.30599734,-0.09605781,-0.06260629,0.00000000,0.00000000,0.00000000,0.00000000
213.65000000,4.70011400,4.70900000,0.15628844,465.30011314,0.14521526,538.02114402,0.00079331,0.15992426,555.24563831,-0.09679217,-0.06313209,0.00000000,0.00000000,0.00000000,0.00000000
215.15000000,4.74271300,4.71300000,0.15767956,465.69535639,0.14641762,539.12599321,0.00079869,0.16121586,556.08654663,-0.09757699,-0.06363887,0.00000000,0.00000000,0.00000000,0.00000000
216.65000000,4.78582200,4.71600000,0.15913833,465.99178882,0.14767691,540.14894544,0.00083048,0.16250576,556.92775958,-0.09834394,-0.06416182,0.00000000,0.00000000,0.00000000,0.00000000
218.15000000,4.82872800,4.71800000,0.16056689,466.18941045,0.14890858,541.04399371,0.00090704,0.16382387,557.90425908,-0.09915113,-0.06467274,0.00000000,0.00000000,0.00000000,0.00000000
219.65000000,4.87183500,4.72200000,0.16199567,466.58465369,0.15013893,542.16934572,0.00077659,0.16507898,558.72858086,-0.09991500,-0.06516398,0.00000000,0.00000000,0.00000000,0.00000000
221.15000000,4.91500900,4.72400000,0.16346189,466.78227532,0.15139995,543.08338774,0.00084039,0.16639354,559.70610547,-0.10071051,-0.06568302,0.00000000,0.00000000,0.00000000,0.00000000
222.65000000,4.95818700,4.72600000,0.16492800,466.97989694,0.15265928,543.99795738,0.00090384,0.16770642,560.68430644,-0.10149979,-0.06620663,0.00000000,0.00000000,0.00000000,0.00000000
224.15000000,5.00143000,4.72900000,0.16635667,467.27632938,0.15388493,545.01086194,0.00083849,0.16901913,561.54523416,-0.10227612,-0.06674300,0.00000000,0.00000000,0.00000000,0.00000000
225.65000000,5.04538200,4.73200000,0.16782300,467.57276181,0.15514133,546.04222542,0.00083744,0.17036128,562.42415266,-0.10311431,-0.06724696,0.00000000,0.00000000,0.00000000,0.00000000
227.15000000,5.08876300,4.73400000,0.16932689,467.77038344,0.15642827,546.97648718,0.00090063,0.17170159,563.30339064,-0.10393790,-0.06776369,0.00000000,0.00000000,0.00000000,0.00000000
228.65000000,5.13291700,4.73700000,0.17075544,468.06681587,0.15764922,547.99177304,0.00083534,0.17303998,564.18289578,-0.10473914,-0.06830084,0.00000000,0.00000000,0.00000000,0.00000000
230.15000000,5.17737700,4.73900000,0.17225922,468.26443749,0.15893285,548.92730529,0.00083408,0.17434548,565.04503056,-0.10552335,-0.06882213,0.00000000,0.00000000,0.00000000,0.00000000
231.65000000,5.22126500,4.74100000,0.17376311,468.46205912,0.16021492,549.86348395,0.00083320,0.17571138,565.94291682,-0.10635983,-0.06935155,0.00000000,0.00000000,0.00000000,0.00000000
233.15000000,5.26626700,4.74300000,0.17522944,468.65968074,0.16146340,550.78265623,0.00089610,0.17707539,566.84112999,-0.10716547,-0.06990991,0.00000000,0.00000000,0.00000000,0.00000000
234.65000000,5.31012100,4.74500000,0.17669567,468.85730237,0.16271023,551.70235598,0.00076670,0.17846995,567.63829198,-0.10802951,-0.07044044,0.00000000,0.00000000,0.00000000,0.00000000
236.15000000,5.35488500,4.74700000,0.17819944,469.05492399,0.16398738,552.64025086,0.00082969,0.17982870,568.65629412,-0.10885033,-0.07097837,0.00000000,0.00000000,0.00000000,0.00000000
237.65000000,5.40015500,4.75000000,0.17974078,469.35135643,0.16529473,553.71293428,0.00089249,0.18121954,569.45389518,-0.10966964,-0.07154990,0.00000000,0.00000000,0.00000000,0.00000000
239.15000000,5.44580100,4.75200000,0.18120689,469.54897805,0.16653670,554.63448754,0.00076396,0.18260824,570.25139148,-0.11051065,-0.07209759,0.00000000,0.00000000,0.00000000,0.00000000
240.65000000,5.49148200,4.75300000,0.18278611,469.64778886,0.16787277,555.49288178,0.00089038,0.18402432,571.18639261,-0.11133906,-0.07268526,0.00000000,0.00000000,0.00000000,0.00000000
242.15000000,5.53699000,4.75400000,0.18428989,469.74659967,0.16914335,556.31614833,0.00082561,0.18540934,571.98421324,-0.11217576,-0.07323358,0.00000000,0.00000000,0.00000000,0.00000000
243.65000000,5.58334600,4.75600000,0.18583122,469.94422130,0.17044398,557.27453032,0.00082435,0.00000000,0.00000000,0.00000000,0.00000000,0.00000000,0.00000000,0.00000000,0.00000000
245.15000000,5.62885400,4.75800000,0.18737278,470.14184292,0.17174312,558.23362598,0.00075999,0.00000000,0.00000000,0.00000000,0.00000000,0.00000000,0.00000000,0.00000000,0.00000000
246.65000000,5.67538100,4.75900000,0.18898933,470.24065373,0.17310365,559.11112139,0.00094856,0.00000000,0.00000000,0.00000000,0.00000000,0.00000000,0.00000000,0.00000000,0.00000000
248.15000000,5.72160600,4.76000000,0.19053089,470.33946454,0.17439933,559.95366080,0.00088439,0.00000000,0.00000000,0.00000000,0.00000000,0.00000000,0.00000000,0.00000000,0.00000000
249.65000000,5.76830000,4.76200000,0.19214767,470.53708617,0.17575644,560.94968936,0.00094642,0.00000000,0.00000000,0.00000000,0.00000000,0.00000000,0.00000000,0.00000000,0.00000000
251.15000000,5.81590800,4.76300000,0.19376433,470.63589698,0.17711162,561.82834780,0.00100808,0.00000000,0.00000000,0.00000000,0.00000000,0.00000000,0.00000000,0.00000000,0.00000000
252.65000000,5.86287500,4.76400000,0.19530567,470.73470779,0.17840194,562.67186372,0.00088068,0.00000000,0.00000000,0.00000000,0.00000000,0.00000000,0.00000000,0.00000000,0.00000000
254.15000000,5.91031400,4.76400000,0.19688467,470.73470779,0.17972207,563.41515382,0.00081655,0.00000000,0.00000000,0.00000000,0.00000000,0.00000000,0.00000000,0.00000000,0.00000000
255.65000000,5.95778800,4.76600000,0.19853900,470.93232942,0.18110332,564.43076317,0.00087848,0.00000000,0.00000000,0.00000000,0.00000000,0.00000000,0.00000000,0.00000000,0.00000000
257.15000000,6.00576900,4.76700000,0.20015578,471.03114023,0.18245136,565.31074446,0.00094028,0.00000000,0.00000000,0.00000000,0.00000000,0.00000000,0.00000000,0.00000000,0.00000000
258.65000000,6.05374700,4.76800000,0.20177222,471.12995104,0.18379732,566.19088822,0.00087612,0.00000000,0.00000000,0.00000000,0.00000000,0.00000000,0.00000000,0.00000000,0.00000000
260.15000000,6.10217000,4.76900000,0.20346411,471.22876185,0.18520416,567.10690301,0.00093751,0.00000000,0.00000000,0.00000000,0.00000000,0.00000000,0.00000000,0.00000000,0.00000000
261.65000000,6.15069100,4.76900000,0.20515589,471.22876185,0.18660893,567.90411736,0.00093638,0.00000000,0.00000000,0.00000000,0.00000000,0.00000000,0.00000000,0.00000000,0.00000000
263.15000000,6.19989000,4.77100000,0.20677244,471.42638347,0.18794939,568.90436916,0.00087231,0.00000000,0.00000000,0.00000000,0.00000000,0.00000000,0.00000000,0.00000000,0.00000000
264.65000000,6.24980000,4.77100000,0.20850200,471.42638347,0.18938158,569.71972728,0.00093342,0.00000000,0.00000000,0.00000000,0.00000000,0.00000000,0.00000000,0.00000000,0.00000000
266.15000000,6.29869700,4.77100000,0.21019389,471.42638347,0.19078059,570.51732834,0.00093248,0.00000000,0.00000000,0.00000000,0.00000000,0.00000000,0.00000000,0.00000000,0.00000000
267.65000000,6.34836700,4.77200000,0.21192344,471.52519429,0.19220872,571.45243760,0.00093134,0.00000000,0.00000000,0.00000000,0.00000000,0.00000000,0.00000000,0.00000000,0.00000000
269.15000000,6.39824300,4.77200000,0.21361522,471.52519429,0.19360369,572.25015345,0.00092967,0.00000000,0.00000000,0.00000000,0.00000000,0.00000000,0.00000000,0.00000000,0.00000000
270.65000000,6.44845900,4.77300000,0.21534467,471.62400510,0.00000000,0.00000000,0.00000000,0.00000000,0.00000000,0.00000000,0.00000000,0.00000000,0.00000000,0.00000000,0.00000000
272.15000000,6.49921500,4.77300000,0.21711189,471.62400510,0.00000000,0.00000000,0.00000000,0.00000000,0.00000000,0.00000000,0.00000000,0.00000000,0.00000000,0.00000000,0.00000000
273.65000000,6.55044800,4.77300000,0.21895422,471.62400510,0.00000000,0.00000000,0.00000000,0.00000000,0.00000000,0.00000000,0.00000000,0.00000000,0.00000000,0.00000000,0.00000000
275.15000000,6.60140700,4.77300000,0.22068367,471.62400510,0.00000000,0.00000000,0.00000000,0.00000000,0.00000000,0.00000000,0.00000000,0.00000000,0.00000000,0.00000000,0.00000000
276.65000000,6.65250200,4.77300000,0.22248833,471.62400510,0.00000000,0.00000000,0.00000000,0.00000000,0.00000000,0.00000000,0.00000000,0.00000000,0.00000000,0.00000000,0.00000000
278.15000000,6.70447900,4.77300000,0.22425556,471.62400510,0.00000000,0.00000000,0.00000000,0.00000000,0.00000000,0.00000000,0.00000000,0.00000000,0.00000000,0.00000000,0.00000000
279.65000000,6.75618300,4.77200000,0.22613556,471.52519429,0.00000000,0.00000000,0.00000000,0.00000000,0.00000000,0.00000000,0.00000000,0.00000000,0.00000000,0.00000000,0.00000000
281.15000000,6.80863200,4.77200000,0.22794033,471.52519429,0.00000000,0.00000000,0.00000000,0.00000000,0.00000000,0.00000000,0.00000000,0.00000000,0.00000000,0.00000000,0.00000000
282.65000000,6.86226900,4.77200000,0.22982044,471.52519429,0.00000000,0.00000000,0.00000000,0.00000000,0.00000000,0.00000000,0.00000000,0.00000000,0.00000000,0.00000000,0.00000000
284.15000000,6.91576400,4.77100000,0.23166244,471.42638347,0.00000000,0.00000000,0.00000000,0.00000000,0.00000000,0.00000000,0.00000000,0.00000000,0.00000000,0.00000000,0.00000000
285.65000000,6.96909300,4.77100000,0.23346744,471.42638347,0.00000000,0.00000000,0.00000000,0.00000000,0.00000000,0.00000000,0.00000000,0.00000000,0.00000000,0.00000000,0.00000000
287.15000000,7.02353800,4.77000000,0.23530967,471.32757266,0.00000000,0.00000000,0.00000000,0.00000000,0.00000000,0.00000000,0.00000000,0.00000000,0.00000000,0.00000000,0.00000000
288.65000000,7.07706800,4.76900000,0.23707689,471.22876185,0.00000000,0.00000000,0.00000000,0.00000000,0.00000000,0.00000000,0.00000000,0.00000000,0.00000000,0.00000000,0.00000000
290.15000000,7.13161300,4.76800000,0.23884400,471.12995104,0.00000000,0.00000000,0.00000000,0.00000000,0.00000000,0.00000000,0.00000000,0.00000000,0.00000000,0.00000000,0.00000000
291.65000000,7.18609000,4.76700000,0.24049822,471.03114023,0.00000000,0.00000000,0.00000000,0.00000000,0.00000000,0.00000000,0.00000000,0.00000000,0.00000000,0.00000000,0.00000000
293.15000000,7.24191900,4.76500000,0.24215256,470.83351860,0.00000000,0.00000000,0.00000000,0.00000000,0.00000000,0.00000000,0.00000000,0.00000000,0.00000000,0.00000000,0.00000000
294.65000000,7.29799000,4.76300000,0.24373167,470.63589698,0.00000000,0.00000000,0.00000000,0.00000000,0.00000000,0.00000000,0.00000000,0.00000000,0.00000000,0.00000000,0.00000000
296.15000000,7.35408900,4.76000000,0.24516044,470.33946454,0.00000000,0.00000000,0.00000000,0.00000000,0.00000000,0.00000000,0.00000000,0.00000000,0.00000000,0.00000000,0.00000000
297.65000000,7.41097000,4.75700000,0.24640111,470.04303211,0.00000000,0.00000000,0.00000000,0.00000000,0.00000000,0.00000000,0.00000000,0.00000000,0.00000000,0.00000000,0.00000000
299.15000000,7.46748000,4.75300000,0.24760411,469.64778886,0.00000000,0.00000000,0.00000000,0.00000000,0.00000000,0.00000000,0.00000000,0.00000000,0.00000000,0.00000000,0.00000000
300.65000000,7.52456300,4.74900000,0.24858156,469.25254561,0.00000000,0.00000000,0.00000000,0.00000000,0.00000000,0.00000000,0.00000000,0.00000000,0.00000000,0.00000000,0.00000000
302.15000000,7.58266300,4.74400000,0.24940856,468.75849155,0.00000000,0.00000000,0.00000000,0.00000000,0.00000000,0.00000000,0.00000000,0.00000000,0.00000000,0.00000000,0.00000000
303.65000000,7.64117300,4.73700000,0.25012267,468.06681587,0.00000000,0.00000000,0.00000000,0.00000000,0.00000000,0.00000000,0.00000000,0.00000000,0.00000000,0.00000000,0.00000000
305.15000000,7.70005400,4.72900000,0.25064867,467.27632938,0.00000000,0.00000000,0.00000000,0.00000000,0.00000000,0.00000000,0.00000000,0.00000000,0.00000000,0.00000000,0.00000000
306.65000000,7.76016200,4.71800000,0.25109944,466.18941045,0.00000000,0.00000000,0.00000000,0.00000000,0.00000000,0.00000000,0.00000000,0.00000000,0.00000000,0.00000000,0.00000000
308.15000000,7.82089400,4.70300000,0.25143689,464.70724827,0.00000000,0.00000000,0.00000000,0.00000000,0.00000000,0.00000000,0.00000000,0.00000000,0.00000000,0.00000000,0.00000000
309.15000000,7.86352800,4.68500000,0.25151078,462.92865365,0.00000000,0.00000000,0.00000000,0.00000000,0.00000000,0.00000000,0.00000000,0.00000000,0.00000000,0.00000000,0.00000000