File: polyN_optimization/AA7020-T6_results/DATA/UT_90_2.csv
Time[s],Displacement[mm],Force[kN],EngStrain_longi,EngStress[MPa],TrueStrain,TrueStress[MPa],TrueStrainRate[1/s],PlasticStrain_longi,PlasticStress[MPa],PlasticStrain_thick,PlasticStrain_width,R-Value,Thickness[mm],Width[mm], Young's Modulus [MPa]
0.61000000,0.00000000,-0.00900000,0.00000000,-0.89284651,0.00000000,-0.89284651,0.00000000,0.00053687,272.17328374,0.00017471,-0.00071157,0.61634689,1.00600000,10.02000000,75726.56219582
2.12000000,0.00430900,0.01000000,0.00013878,0.99205168,0.00013877,0.99218936,0.00020478,0.00120101,284.96434738,-0.00016710,-0.00103391,0.00000000,0.00000000,0.00000000,0.00000000
3.62000000,0.01183400,0.31200000,0.00036622,30.95201248,0.00036616,30.96334779,0.00012885,0.00200551,293.30958292,-0.00062742,-0.00137809,0.00000000,0.00000000,0.00000000,0.00000000
5.12000000,0.01956000,0.51700000,0.00061044,51.28907196,0.00061026,51.32038108,0.00018256,0.00282580,302.27655674,-0.00108552,-0.00174028,0.00000000,0.00000000,0.00000000,0.00000000
6.62000000,0.02774500,0.74700000,0.00091967,74.10626064,0.00091924,74.17441370,0.00033240,0.00380816,308.59948975,-0.00172290,-0.00208526,0.00000000,0.00000000,0.00000000,0.00000000
8.12000000,0.03560900,0.95900000,0.00120278,95.13775630,0.00120206,95.25218588,0.00046438,0.00479314,315.23808306,-0.00238513,-0.00240801,0.00000000,0.00000000,0.00000000,0.00000000
9.61000000,0.04382400,1.18700000,0.00141089,117.75653464,0.00140989,117.92267603,0.00037434,0.00574179,320.67113839,-0.00296183,-0.00277996,0.00000000,0.00000000,0.00000000,0.00000000
11.12000000,0.05262600,1.39900000,0.00162533,138.78803030,0.00162401,139.01360711,0.00021383,0.00679847,326.04964579,-0.00368938,-0.00310909,0.00000000,0.00000000,0.00000000,0.00000000
12.61000000,0.06144100,1.62600000,0.00186922,161.30760348,0.00186748,161.60912324,0.00003039,0.00793181,330.35563345,-0.00446668,-0.00346513,0.00000000,0.00000000,0.00000000,0.00000000
14.12000000,0.06983000,1.82000000,0.00218322,180.55340611,0.00218084,180.94759432,-0.00007029,0.00899450,335.15278353,-0.00511296,-0.00388153,0.00000000,0.00000000,0.00000000,0.00000000
15.62000000,0.07848100,2.05800000,0.00252500,204.16423614,0.00252182,204.67975084,0.00000456,0.01004235,338.74174878,-0.00575944,-0.00428291,0.00000000,0.00000000,0.00000000,0.00000000
17.11000000,0.08894200,2.24400000,0.00291322,222.61639742,0.00290899,223.26492846,0.00017838,0.01115983,342.86843073,-0.00646681,-0.00469301,0.00000000,0.00000000,0.00000000,0.00000000
18.61000000,0.10094800,2.45200000,0.00328700,243.25107241,0.00328161,244.05063868,0.00029705,0.01230079,346.50566627,-0.00719361,-0.00510718,0.00000000,0.00000000,0.00000000,0.00000000
20.11000000,0.11558100,2.62800000,0.00375822,260.71118201,0.00375118,261.69099257,0.00033964,0.01340038,350.13656160,-0.00784693,-0.00555345,0.00000000,0.00000000,0.00000000,0.00000000
21.61000000,0.13738000,2.78100000,0.00439578,275.88957274,0.00438614,277.10232200,0.00034252,0.01449063,353.26396107,-0.00848172,-0.00600891,0.00000000,0.00000000,0.00000000,0.00000000
23.11000000,0.16409900,2.88000000,0.00533689,285.71088439,0.00532270,287.23569164,0.00054163,0.01564255,356.92885022,-0.00918317,-0.00645939,0.00000000,0.00000000,0.00000000,0.00000000
24.61000000,0.19347100,2.97000000,0.00634244,294.63934953,0.00632242,296.50808324,0.00070653,0.01677045,359.77840859,-0.00984430,-0.00692616,0.00000000,0.00000000,0.00000000,0.00000000
26.11000000,0.22289200,3.04100000,0.00732067,301.68291647,0.00729400,303.89143654,0.00076676,0.01787234,363.13463510,-0.01053414,-0.00733820,0.00000000,0.00000000,0.00000000,0.00000000
27.61000000,0.25537100,3.11000000,0.00827289,308.52807308,0.00823886,311.08049155,0.00052087,0.01901102,366.10321534,-0.01123896,-0.00777206,0.00000000,0.00000000,0.00000000,0.00000000
29.11000000,0.28688200,3.16500000,0.00942822,313.98435733,0.00938405,316.94467162,0.00066187,0.02015408,369.18219144,-0.01196108,-0.00819300,0.00000000,0.00000000,0.00000000,0.00000000
30.61000000,0.32022600,3.21800000,0.01054289,319.24223124,0.01048770,322.60796662,0.00082503,0.02125001,371.84090851,-0.01265550,-0.00859450,0.00000000,0.00000000,0.00000000,0.00000000
32.11000000,0.35520000,3.26000000,0.01160567,323.40884831,0.01153884,327.16222360,0.00066858,0.02237941,374.92774000,-0.01340148,-0.00897793,0.00000000,0.00000000,0.00000000,0.00000000
33.61000000,0.38880200,3.30600000,0.01274000,327.97228604,0.01265953,332.15065297,0.00053767,0.02347678,377.59873752,-0.01410818,-0.00936860,0.00000000,0.00000000,0.00000000,0.00000000
35.12000000,0.42450300,3.34100000,0.01394567,331.44446693,0.01384932,336.06668099,0.00065147,0.02462196,380.39634378,-0.01483675,-0.00978521,0.00000000,0.00000000,0.00000000,0.00000000
36.61000000,0.45997500,3.37900000,0.01512556,335.21426332,0.01501230,340.28456529,0.00080075,0.02573404,383.08447439,-0.01555599,-0.01017805,0.00000000,0.00000000,0.00000000,0.00000000
38.11000000,0.49510800,3.41200000,0.01626778,338.48803387,0.01613688,343.99448199,0.00068738,0.02685629,385.78225550,-0.01627819,-0.01057810,0.00000000,0.00000000,0.00000000,0.00000000
39.62000000,0.53122500,3.44600000,0.01745944,341.86100959,0.01730878,347.82971290,0.00065096,0.02800129,388.28848903,-0.01702838,-0.01097291,0.00000000,0.00000000,0.00000000,0.00000000
41.11000000,0.56646800,3.47300000,0.01868078,344.53954913,0.01850844,350.97581589,0.00075297,0.02911877,391.09898832,-0.01771588,-0.01140289,0.00000000,0.00000000,0.00000000,0.00000000
42.61000000,0.60258800,3.50600000,0.01984600,347.81331968,0.01965164,354.71602283,0.00077434,0.03023167,393.39695355,-0.01843773,-0.01179393,0.00000000,0.00000000,0.00000000,0.00000000
44.11000000,0.63837600,3.53100000,0.02100356,350.29344889,0.02078602,357.65085680,0.00064021,0.03134585,396.01060225,-0.01911524,-0.01223061,0.00000000,0.00000000,0.00000000,0.00000000
45.61000000,0.67437000,3.56000000,0.02222133,353.17039877,0.02197804,361.01831592,0.00069142,0.03244194,398.51893690,-0.01975847,-0.01268346,0.00000000,0.00000000,0.00000000,0.00000000
47.11000000,0.71029700,3.58500000,0.02346200,355.65052797,0.02319100,363.99480066,0.00082287,0.03355104,401.03771146,-0.02043462,-0.01311642,0.00000000,0.00000000,0.00000000,0.00000000
48.61000000,0.74625600,3.61200000,0.02461211,358.32906751,0.02431411,367.14830234,0.00071151,0.03468079,403.25863498,-0.02111456,-0.01356623,0.00000000,0.00000000,0.00000000,0.00000000
50.11000000,0.78207800,3.63500000,0.02583767,360.61078638,0.02550951,369.92812767,0.00073298,0.03578978,405.89155019,-0.02178095,-0.01400883,0.00000000,0.00000000,0.00000000,0.00000000
51.61000000,0.81784400,3.66200000,0.02704422,363.28932592,0.02668499,373.11420318,0.00082021,0.03691095,408.01460756,-0.02245803,-0.01445291,0.00000000,0.00000000,0.00000000,0.00000000
53.11000000,0.85373500,3.68300000,0.02822078,365.37263445,0.02782991,375.68373438,0.00076782,0.03799840,410.44072758,-0.02313350,-0.01486490,0.00000000,0.00000000,0.00000000,0.00000000
54.62000000,0.88936200,3.70700000,0.02939000,367.75355849,0.02896639,378.56183557,0.00077385,0.03915888,412.69346873,-0.02385376,-0.01530512,0.00000000,0.00000000,0.00000000,0.00000000
56.11000000,0.92549300,3.72900000,0.03060056,369.93607219,0.03014170,381.25632152,0.00077397,0.04027311,415.03617219,-0.02455890,-0.01571420,0.00000000,0.00000000,0.00000000,0.00000000
57.61000000,0.96152300,3.75200000,0.03179589,372.21779106,0.03130087,384.05278658,0.00078002,0.04135445,417.05622417,-0.02518353,-0.01617092,0.00000000,0.00000000,0.00000000,0.00000000
59.11000000,0.99769400,3.77100000,0.03299911,374.10268925,0.03246633,386.44774546,0.00079353,0.04248638,419.52036010,-0.02594418,-0.01654219,0.00000000,0.00000000,0.00000000,0.00000000
60.61000000,1.03348600,3.79500000,0.03418700,376.48361329,0.03361561,389.35445858,0.00073437,0.04359749,421.56160867,-0.02667843,-0.01691906,0.00000000,0.00000000,0.00000000,0.00000000
62.11000000,1.06935000,3.81400000,0.03538267,378.36851149,0.03477108,391.75619841,0.00073438,0.04472598,423.82426730,-0.02740406,-0.01732191,0.00000000,0.00000000,0.00000000,0.00000000
63.61000000,1.10582600,3.83500000,0.03659311,380.45182002,0.03593948,394.37373574,0.00078327,0.04583611,425.97870925,-0.02812921,-0.01770690,0.00000000,0.00000000,0.00000000,0.00000000
65.11000000,1.14118300,3.85400000,0.03776978,382.33671821,0.03707397,396.77749110,0.00075325,0.04697414,428.14954767,-0.02887139,-0.01810275,0.00000000,0.00000000,0.00000000,0.00000000
66.61000000,1.17708500,3.87500000,0.03892433,384.42002675,0.03818588,399.38332001,0.00071711,0.04804921,430.08703869,-0.02952264,-0.01852657,0.00000000,0.00000000,0.00000000,0.00000000
68.11000000,1.21318300,3.89200000,0.04014967,386.10651460,0.03936461,401.60856246,0.00078829,0.04916478,432.36219327,-0.03022464,-0.01894014,0.00000000,0.00000000,0.00000000,0.00000000
69.61000000,1.24934900,3.91400000,0.04135233,388.28902831,0.04052019,404.34568563,0.00077991,0.05029166,434.22474605,-0.03092905,-0.01936260,0.00000000,0.00000000,0.00000000,0.00000000
71.11000000,1.28544900,3.93000000,0.04254444,389.87631100,0.04166431,406.46338205,0.00077902,0.05139214,436.39649837,-0.03160009,-0.01979205,0.00000000,0.00000000,0.00000000,0.00000000
72.61000000,1.32104100,3.94900000,0.04373967,391.76120919,0.04281010,408.89671389,0.00077088,0.05249748,438.36317063,-0.03225724,-0.02024024,0.00000000,0.00000000,0.00000000,0.00000000
74.11000000,1.35714700,3.96600000,0.04492822,393.44769705,0.04394820,411.12460262,0.00080660,0.05360826,440.33617067,-0.03295055,-0.02065771,0.00000000,0.00000000,0.00000000,0.00000000
75.61000000,1.39321800,3.98500000,0.04613444,395.33259525,0.04510189,413.57104490,0.00073214,0.05473863,442.10974036,-0.03359050,-0.02114813,0.00000000,0.00000000,0.00000000,0.00000000
77.11000000,1.42938200,4.00000000,0.04736000,396.82067277,0.04627271,415.61409983,0.00078201,0.05583328,444.29556648,-0.03430898,-0.02152429,0.00000000,0.00000000,0.00000000,0.00000000
78.61000000,1.46545200,4.01900000,0.04855611,398.70557097,0.04741409,418.06516297,0.00084748,0.05693131,446.16841722,-0.03496185,-0.02196946,0.00000000,0.00000000,0.00000000,0.00000000
80.11000000,1.50131600,4.03400000,0.04971711,400.19364849,0.04852071,420.09012058,0.00073028,0.05809122,448.07283445,-0.03567765,-0.02241357,0.00000000,0.00000000,0.00000000,0.00000000
81.61000000,1.53792500,4.05100000,0.05094656,401.88013635,0.04969124,422.35454504,0.00079394,0.05923520,449.97395351,-0.03642445,-0.02281075,0.00000000,0.00000000,0.00000000,0.00000000
83.11000000,1.57382700,4.06700000,0.05216889,403.46741904,0.05085364,424.51586599,0.00080062,0.06033261,451.85776139,-0.03707296,-0.02325965,0.00000000,0.00000000,0.00000000,0.00000000
84.61000000,1.61016200,4.08300000,0.05335656,405.05470173,0.05198179,426.66702543,0.00077840,0.06144430,453.64497793,-0.03776363,-0.02368066,0.00000000,0.00000000,0.00000000,0.00000000
86.11000000,1.64596100,4.09700000,0.05453711,406.44357408,0.05310191,428.60983244,0.00068393,0.06259684,455.66826356,-0.03851555,-0.02408129,0.00000000,0.00000000,0.00000000,0.00000000
87.61000000,1.68223600,4.11500000,0.05576656,408.22926711,0.05426710,430.99480722,0.00081179,0.06372929,457.25826478,-0.03922971,-0.02449958,0.00000000,0.00000000,0.00000000,0.00000000
89.11000000,1.71874200,4.12800000,0.05693233,409.51893430,0.05537069,432.83380277,0.00072634,0.06483528,459.16065493,-0.03993881,-0.02489647,0.00000000,0.00000000,0.00000000,0.00000000
90.61000000,1.75491700,4.14300000,0.05812778,411.00701182,0.05650110,434.89793607,0.00068308,0.06596707,460.86416132,-0.04065368,-0.02531340,0.00000000,0.00000000,0.00000000,0.00000000
92.11000000,1.79122200,4.15700000,0.05934189,412.39588418,0.05764786,436.86823491,0.00071693,0.06712242,462.79683509,-0.04140553,-0.02571690,0.00000000,0.00000000,0.00000000,0.00000000
93.61000000,1.82786100,4.17300000,0.06057867,413.98316687,0.05881467,439.06171514,0.00078673,0.06824110,464.50119712,-0.04209550,-0.02614560,0.00000000,0.00000000,0.00000000,0.00000000
95.11000000,1.86393000,4.18600000,0.06177778,415.27283405,0.05994465,440.92746691,0.00077181,0.06932935,466.30227422,-0.04273295,-0.02659640,0.00000000,0.00000000,0.00000000,0.00000000
96.61000000,1.90057500,4.20100000,0.06297333,416.76091158,0.06107001,443.00573538,0.00071385,0.07046914,467.80766920,-0.04344055,-0.02702859,0.00000000,0.00000000,0.00000000,0.00000000
98.11000000,1.93674200,4.21300000,0.06421422,417.95137359,0.06223671,444.78979598,0.00079887,0.07161207,469.74916635,-0.04415870,-0.02745336,0.00000000,0.00000000,0.00000000,0.00000000
99.61000000,1.97332000,4.22700000,0.06542844,419.34024595,0.06337701,446.77702593,0.00083281,0.07270224,471.34537882,-0.04480592,-0.02789633,0.00000000,0.00000000,0.00000000,0.00000000
101.11000000,2.01084700,4.24000000,0.06662044,420.62991314,0.06449519,448.65246490,0.00069786,0.07381803,473.06495071,-0.04550595,-0.02831208,0.00000000,0.00000000,0.00000000,0.00000000
102.61000000,2.04755800,4.25400000,0.06789133,422.01878549,0.06568599,450.67020353,0.00074012,0.07499350,474.59974584,-0.04625053,-0.02874297,0.00000000,0.00000000,0.00000000,0.00000000
104.11000000,2.08400000,4.26500000,0.06914311,423.11004234,0.06685750,452.36518701,0.00083740,0.07612814,476.22643161,-0.04695355,-0.02917459,0.00000000,0.00000000,0.00000000,0.00000000
105.61000000,2.12064200,4.27900000,0.07034200,424.49891470,0.06797822,454.35901735,0.00080717,0.07722059,477.83597825,-0.04762697,-0.02959363,0.00000000,0.00000000,0.00000000,0.00000000
107.11000000,2.15800100,4.29100000,0.07154933,425.68937671,0.06910558,456.14716782,0.00070212,0.07835169,479.57588349,-0.04833295,-0.03001875,0.00000000,0.00000000,0.00000000,0.00000000
108.61000000,2.19488100,4.30300000,0.07281611,426.87983873,0.07028707,457.96356850,0.00075724,0.07950901,481.00542183,-0.04906037,-0.03044864,0.00000000,0.00000000,0.00000000,0.00000000
110.11000000,2.23172700,4.31500000,0.07405656,428.07030075,0.07144265,459.77171276,0.00080500,0.08061631,482.74023832,-0.04972378,-0.03089252,0.00000000,0.00000000,0.00000000,0.00000000
111.61000000,2.26853400,4.32700000,0.07525578,429.26076277,0.07255857,461.56511534,0.00072719,0.08179020,484.29270052,-0.05044504,-0.03134516,0.00000000,0.00000000,0.00000000,0.00000000
113.11000000,2.30569100,4.33800000,0.07653067,430.35201962,0.07374352,463.28714658,0.00073418,0.08292176,485.82750122,-0.05114218,-0.03177958,0.00000000,0.00000000,0.00000000,0.00000000
114.61000000,2.34331700,4.35000000,0.07774844,431.54248164,0.07487409,465.09423830,0.00071190,0.08406361,487.26092815,-0.05185556,-0.03220805,0.00000000,0.00000000,0.00000000,0.00000000
116.11000000,2.38026300,4.36000000,0.07898144,432.53453332,0.07601749,466.69673553,0.00077351,0.08517690,488.68299716,-0.05254233,-0.03263457,0.00000000,0.00000000,0.00000000,0.00000000
117.61000000,2.41710800,4.37200000,0.08019944,433.72499534,0.07714569,468.50949901,0.00070967,0.08632326,490.34318295,-0.05326905,-0.03305421,0.00000000,0.00000000,0.00000000,0.00000000
119.11000000,2.45432400,4.38200000,0.08146244,434.71704702,0.07831424,470.13016031,0.00070843,0.08747106,491.78787131,-0.05399753,-0.03347352,0.00000000,0.00000000,0.00000000,0.00000000
120.61000000,2.49195000,4.39400000,0.08275211,435.90750904,0.07950605,471.97977566,0.00086855,0.08859038,493.22114199,-0.05468257,-0.03390781,0.00000000,0.00000000,0.00000000,0.00000000
122.11000000,2.52913800,4.40300000,0.08395122,436.80035555,0.08061290,473.47027927,0.00080422,0.08971850,494.66144063,-0.05534997,-0.03436853,0.00000000,0.00000000,0.00000000,0.00000000
123.61000000,2.56655900,4.41400000,0.08519578,437.89161240,0.08176041,475.19812890,0.00070681,0.09086793,496.22516683,-0.05609072,-0.03477721,0.00000000,0.00000000,0.00000000,0.00000000
125.11000000,2.60411600,4.42300000,0.08647011,438.78445892,0.08293401,476.72619983,0.00074076,0.09202044,497.68319822,-0.05680569,-0.03521475,0.00000000,0.00000000,0.00000000,0.00000000
126.61000000,2.64180600,4.43300000,0.08773689,439.77651060,0.08409929,478.36113344,0.00084291,0.09315776,499.13635636,-0.05748658,-0.03567119,0.00000000,0.00000000,0.00000000,0.00000000
128.11000000,2.67916100,4.44300000,0.08894767,440.76856228,0.08521179,479.97389743,0.00075867,0.09432073,500.38414409,-0.05825035,-0.03607038,0.00000000,0.00000000,0.00000000,0.00000000
129.61000000,2.71685900,4.45200000,0.09024122,441.66140879,0.08639898,481.51747413,0.00077980,0.09543429,501.94114153,-0.05893982,-0.03649447,0.00000000,0.00000000,0.00000000,0.00000000
131.11000000,2.75451200,4.46300000,0.09153033,442.75266564,0.08758069,483.27796471,0.00088173,0.09657280,503.29216898,-0.05961544,-0.03695736,0.00000000,0.00000000,0.00000000,0.00000000
132.61000000,2.79274800,4.47200000,0.09281600,443.64551216,0.08875785,484.82291401,0.00084631,0.09772168,504.76183218,-0.06033486,-0.03738681,0.00000000,0.00000000,0.00000000,0.00000000
134.11000000,2.83070900,4.48000000,0.09407200,444.43915350,0.08990652,486.24843355,0.00083904,0.09889597,506.02516078,-0.06103474,-0.03786123,0.00000000,0.00000000,0.00000000,0.00000000
135.61000000,2.86846400,4.48800000,0.09530867,445.23279485,0.09103621,487.66733888,0.00077598,0.10002697,507.37984640,-0.06173484,-0.03829213,0.00000000,0.00000000,0.00000000,0.00000000
137.11000000,2.90626800,4.49700000,0.09654533,446.12564136,0.09216463,489.19699012,0.00076781,0.10116990,508.74310620,-0.06246466,-0.03870524,0.00000000,0.00000000,0.00000000,0.00000000
138.61000000,2.94422500,4.50700000,0.09782733,447.11769304,0.09333308,490.85802464,0.00076712,0.10234016,510.01148055,-0.06321986,-0.03912030,0.00000000,0.00000000,0.00000000,0.00000000
140.11000000,2.98225300,4.51500000,0.09910933,447.91133439,0.09450015,492.30352813,0.00076663,0.10348378,511.38000606,-0.06389200,-0.03959178,0.00000000,0.00000000,0.00000000,0.00000000
141.61000000,3.02011700,4.52300000,0.10035378,448.70497573,0.09563174,493.73421516,0.00075242,0.10466424,512.65837245,-0.06463806,-0.04002618,0.00000000,0.00000000,0.00000000,0.00000000
143.11000000,3.05861900,4.53200000,0.10162800,449.59782225,0.09678909,495.28954973,0.00077194,0.10582184,514.03907490,-0.06535289,-0.04046895,0.00000000,0.00000000,0.00000000,0.00000000
144.61000000,3.09722800,4.53900000,0.10288722,450.29225843,0.09793149,496.62157808,0.00071562,0.10698947,515.31558702,-0.06606496,-0.04092451,0.00000000,0.00000000,0.00000000,0.00000000
146.11000000,3.13616900,4.54800000,0.10422200,451.18510494,0.09914101,498.20851895,0.00079025,0.10810703,516.45628381,-0.06673744,-0.04136959,0.00000000,0.00000000,0.00000000,0.00000000
147.61000000,3.17423200,4.55500000,0.10547344,451.87954112,0.10027370,499.54083279,0.00074170,0.10928838,517.74439389,-0.06748898,-0.04179940,0.00000000,0.00000000,0.00000000,0.00000000
149.11000000,3.21277300,4.56200000,0.10677044,452.57397729,0.10144626,500.89550199,0.00072717,0.11049192,519.04646409,-0.06825699,-0.04223493,0.00000000,0.00000000,0.00000000,0.00000000
150.61000000,3.25151300,4.57000000,0.10804511,453.36761864,0.10259730,502.35177337,0.00076004,0.11162398,520.31350850,-0.06895134,-0.04267265,0.00000000,0.00000000,0.00000000,0.00000000
152.11000000,3.28978600,4.57800000,0.10933456,454.16125999,0.10376034,503.81677950,0.00077258,0.11275965,521.47205993,-0.06960517,-0.04315448,0.00000000,0.00000000,0.00000000,0.00000000
153.61000000,3.32896700,4.58500000,0.11062022,454.85569616,0.10491862,505.17193435,0.00075167,0.11395008,522.66143300,-0.07034890,-0.04360118,0.00000000,0.00000000,0.00000000,0.00000000
155.11000000,3.36808200,4.59100000,0.11194344,455.45092717,0.10610934,506.43567273,0.00075038,0.11512625,524.07120677,-0.07107695,-0.04404929,0.00000000,0.00000000,0.00000000,0.00000000
156.61000000,3.40710000,4.59800000,0.11329733,456.14536335,0.10732618,507.82541663,0.00088545,0.11626572,525.35116817,-0.07177515,-0.04449057,0.00000000,0.00000000,0.00000000,0.00000000
158.11000000,3.44648900,4.60400000,0.11454522,456.74059436,0.10844645,509.05804724,0.00080328,0.11747008,526.44148152,-0.07251793,-0.04495214,0.00000000,0.00000000,0.00000000,0.00000000
159.61000000,3.48540200,4.61100000,0.11585344,457.43503054,0.10961953,510.43045443,0.00077464,0.11863335,527.51185393,-0.07326023,-0.04537312,0.00000000,0.00000000,0.00000000,0.00000000
161.11000000,3.52451100,4.61800000,0.11719178,458.12946671,0.11081820,511.81847337,0.00084774,0.11979661,528.69747018,-0.07396678,-0.04582983,0.00000000,0.00000000,0.00000000,0.00000000
162.61000000,3.56407100,4.62400000,0.11844389,458.72469772,0.11193833,513.05783485,0.00069255,0.12097004,530.00417323,-0.07472833,-0.04624171,0.00000000,0.00000000,0.00000000,0.00000000
164.11000000,3.60393000,4.63100000,0.11979344,459.41913390,0.11314424,514.45453439,0.00075187,0.12214208,531.08507756,-0.07544458,-0.04669750,0.00000000,0.00000000,0.00000000,0.00000000
165.61000000,3.64321500,4.63700000,0.12113944,460.01436491,0.11434553,515.74024951,0.00078467,0.12334041,532.29576339,-0.07620646,-0.04713395,0.00000000,0.00000000,0.00000000,0.00000000
167.11000000,3.68277600,4.64200000,0.12245556,460.51039075,0.11551875,516.90244649,0.00086516,0.12451954,533.38430812,-0.07694518,-0.04757436,0.00000000,0.00000000,0.00000000,0.00000000
168.61000000,3.72229300,4.64800000,0.12374078,461.10562176,0.11666310,518.16319003,0.00075635,0.12570369,534.47741673,-0.07767251,-0.04803119,0.00000000,0.00000000,0.00000000,0.00000000
170.11000000,3.76229200,4.65400000,0.12510200,461.70085277,0.11787370,519.46055285,0.00073528,0.12692384,535.70608405,-0.07838204,-0.04854180,0.00000000,0.00000000,0.00000000,0.00000000
171.61000000,3.80218600,4.66000000,0.12639911,462.29608378,0.11902592,520.72989784,0.00074134,0.12805755,536.66142367,-0.07906715,-0.04899040,0.00000000,0.00000000,0.00000000,0.00000000
173.11000000,3.84157000,4.66500000,0.12774133,462.79210962,0.12021681,521.90979076,0.00082049,0.12925701,537.76841994,-0.07978730,-0.04946971,0.00000000,0.00000000,0.00000000,0.00000000
174.61000000,3.88139700,4.67000000,0.12904200,463.28813546,0.12136949,523.07176303,0.00071283,0.13045334,538.99032333,-0.08054260,-0.04991074,0.00000000,0.00000000,0.00000000,0.00000000
176.11000000,3.92149100,4.67700000,0.13041389,463.98257164,0.12258384,524.49234318,0.00075110,0.13162870,540.20300265,-0.08121755,-0.05041115,0.00000000,0.00000000,0.00000000,0.00000000
177.61000000,3.96172100,4.68200000,0.13175967,464.47859748,0.12377365,525.67814265,0.00081718,0.13281866,541.19584273,-0.08195949,-0.05085917,0.00000000,0.00000000,0.00000000,0.00000000
179.11000000,4.00188300,4.68600000,0.13309433,464.87541815,0.12495224,526.74770201,0.00073617,0.13406863,542.22308498,-0.08276174,-0.05130689,0.00000000,0.00000000,0.00000000,0.00000000
180.61000000,4.04215500,4.69100000,0.13444056,465.37144399,0.12613963,527.93623946,0.00075548,0.13525225,543.21576158,-0.08346926,-0.05178299,0.00000000,0.00000000,0.00000000,0.00000000
182.11000000,4.08238100,4.69500000,0.13579744,465.76826466,0.12733500,529.01840471,0.00078766,0.13642531,544.43505127,-0.08419742,-0.05222790,0.00000000,0.00000000,0.00000000,0.00000000
183.61000000,4.12258000,4.70100000,0.13714689,466.36349567,0.12852240,530.32379820,0.00078027,0.13766435,545.46167330,-0.08496544,-0.05269891,0.00000000,0.00000000,0.00000000,0.00000000
185.11000000,4.16317800,4.70600000,0.13848133,466.85952151,0.12969521,531.51085053,0.00075261,0.13886598,546.46943294,-0.08568836,-0.05317762,0.00000000,0.00000000,0.00000000,0.00000000
186.61000000,4.20432400,4.71000000,0.13991000,467.25634219,0.13094931,532.63017702,0.00083143,0.14002444,547.45503848,-0.08639140,-0.05363303,0.00000000,0.00000000,0.00000000,0.00000000
188.11000000,4.24519900,4.71400000,0.14126367,467.65316286,0.13213613,533.71556337,0.00081739,0.14129934,548.62253322,-0.08720261,-0.05409674,0.00000000,0.00000000,0.00000000,0.00000000
189.61000000,4.28597300,4.71900000,0.14262478,468.14918870,0.13332805,534.91886271,0.00080338,0.14248376,549.62591110,-0.08790150,-0.05458226,0.00000000,0.00000000,0.00000000,0.00000000
191.11000000,4.32721300,4.72300000,0.14401189,468.54600937,0.13454129,536.02220521,0.00075635,0.14366848,550.51483436,-0.08862928,-0.05503919,0.00000000,0.00000000,0.00000000,0.00000000
192.61000000,4.36785300,4.72700000,0.14539533,468.94283005,0.13574985,537.12492913,0.00088024,0.14491431,551.55546102,-0.08941588,-0.05549843,0.00000000,0.00000000,0.00000000,0.00000000
194.11000000,4.40906400,4.73000000,0.14674167,469.24044555,0.13692459,538.09757060,0.00080088,0.14615835,552.59685519,-0.09017999,-0.05597837,0.00000000,0.00000000,0.00000000,0.00000000
195.61000000,4.45028000,4.73500000,0.14809122,469.73647139,0.13810076,539.30031956,0.00072752,0.14730511,553.58574810,-0.09083375,-0.05647136,0.00000000,0.00000000,0.00000000,0.00000000
197.11000000,4.49227400,4.73900000,0.14950478,470.13329206,0.13933122,540.42046542,0.00080495,0.14857984,554.53087020,-0.09162331,-0.05695653,0.00000000,0.00000000,0.00000000,0.00000000
198.61000000,4.53371800,4.74300000,0.15091056,470.53011274,0.14055342,541.53807346,0.00084260,0.14978735,555.55688722,-0.09234115,-0.05744620,0.00000000,0.00000000,0.00000000,0.00000000
200.11000000,4.57547200,4.74600000,0.15230178,470.82772824,0.14176149,542.53562828,0.00073104,0.15105679,556.61932636,-0.09311515,-0.05794164,0.00000000,0.00000000,0.00000000,0.00000000
201.61000000,4.61689100,4.75000000,0.15371533,471.22454891,0.14298746,543.65898753,0.00078891,0.15229318,557.66502178,-0.09386653,-0.05842665,0.00000000,0.00000000,0.00000000,0.00000000
203.11000000,4.65888200,4.75300000,0.15511033,471.52216442,0.14419587,544.66012452,0.00082664,0.15356278,558.49630291,-0.09466323,-0.05889954,0.00000000,0.00000000,0.00000000,0.00000000
204.61000000,4.70046800,4.75700000,0.15646378,471.91898509,0.14536688,545.75721230,0.00066286,0.15479775,559.42687673,-0.09539453,-0.05940322,0.00000000,0.00000000,0.00000000,0.00000000
206.11000000,4.74323700,4.76000000,0.15796033,472.21660060,0.14666012,546.80809223,0.00081885,0.15606095,560.49258471,-0.09620176,-0.05985920,0.00000000,0.00000000,0.00000000,0.00000000
207.61000000,4.78499100,4.76400000,0.15931733,472.61342127,0.14783133,547.90893124,0.00081770,0.15735402,561.57701826,-0.09698465,-0.06036937,0.00000000,0.00000000,0.00000000,0.00000000
209.11000000,4.82769400,4.76700000,0.16071600,472.91103677,0.14903706,548.91540696,0.00064779,0.15861716,562.41029171,-0.09775847,-0.06085869,0.00000000,0.00000000,0.00000000,0.00000000
210.61000000,4.87016000,4.77000000,0.16218233,473.20865228,0.15029956,549.95473566,0.00077685,0.15987709,563.36115714,-0.09851700,-0.06136009,0.00000000,0.00000000,0.00000000,0.00000000
212.11000000,4.91286000,4.77200000,0.16361100,473.40706261,0.15152810,550.86166554,0.00084047,0.16116696,564.33057433,-0.09934178,-0.06182519,0.00000000,0.00000000,0.00000000,0.00000000
213.61000000,4.95522500,4.77500000,0.16507744,473.70467812,0.15278756,551.90263580,0.00083961,0.16245504,565.30055025,-0.10014297,-0.06231207,0.00000000,0.00000000,0.00000000,0.00000000
215.11000000,4.99806300,4.77800000,0.16650600,474.00229362,0.15401296,552.92651953,0.00077416,0.16374114,566.27097882,-0.10092570,-0.06281544,0.00000000,0.00000000,0.00000000,0.00000000
216.61000000,5.04110700,4.78100000,0.16800967,474.29990913,0.15530116,553.98687876,0.00103032,0.16502910,567.00642053,-0.10169295,-0.06333615,0.00000000,0.00000000,0.00000000,0.00000000
218.11000000,5.08421700,4.78300000,0.16940078,474.49831946,0.15649146,554.87870384,0.00083593,0.16634173,568.11385883,-0.10251768,-0.06382406,0.00000000,0.00000000,0.00000000,0.00000000
219.61000000,5.12762300,4.78600000,0.17090456,474.79593497,0.15777657,555.94072321,0.00096340,0.16768582,569.12216620,-0.10334567,-0.06434016,0.00000000,0.00000000,0.00000000,0.00000000
221.11000000,5.17157800,4.78800000,0.17240833,474.99434531,0.15906004,556.88732872,0.00096273,0.16899816,569.99463399,-0.10414298,-0.06485518,0.00000000,0.00000000,0.00000000,0.00000000
222.61000000,5.21492600,4.79000000,0.17379922,475.19275564,0.16024569,557.78088698,0.00083299,0.17033956,570.88514572,-0.10496702,-0.06537254,0.00000000,0.00000000,0.00000000,0.00000000
224.11000000,5.25853700,4.79300000,0.17530311,475.49037115,0.16152608,558.84531251,0.00083211,0.17171082,571.79424341,-0.10580324,-0.06590758,0.00000000,0.00000000,0.00000000,0.00000000
225.61000000,5.30232700,4.79500000,0.17676933,475.68878148,0.16277283,559.77597026,0.00083051,0.17301645,572.78668162,-0.10660530,-0.06641115,0.00000000,0.00000000,0.00000000,0.00000000
227.11000000,5.34641600,4.79800000,0.17827311,475.98639699,0.16404990,560.84197282,0.00082945,0.17438407,573.69664559,-0.10741111,-0.06697295,0.00000000,0.00000000,0.00000000,0.00000000
228.61000000,5.39094500,4.80000000,0.17977678,476.18480732,0.16532525,561.79177761,0.00076470,0.17571687,574.70800134,-0.10826180,-0.06745507,0.00000000,0.00000000,0.00000000,0.00000000
230.11000000,5.43612300,4.80200000,0.18131844,476.38321766,0.16663114,562.76028165,0.00082768,0.17708215,575.49932719,-0.10903845,-0.06804370,0.00000000,0.00000000,0.00000000,0.00000000
231.61000000,5.48082000,4.80400000,0.18278467,476.58162800,0.16787155,563.69344201,0.00076294,0.17850578,576.44610398,-0.10992002,-0.06858576,0.00000000,0.00000000,0.00000000,0.00000000
233.11000000,5.52552300,4.80500000,0.18436367,476.68083316,0.16920564,564.56345940,0.00082518,0.17992753,577.39333024,-0.11077589,-0.06915164,0.00000000,0.00000000,0.00000000,0.00000000
234.61000000,5.57113300,4.80800000,0.18594267,476.97844867,0.17053796,565.66909336,0.00088744,0.18134722,578.34089966,-0.11165888,-0.06968834,0.00000000,0.00000000,0.00000000,0.00000000
236.11000000,5.61626900,4.80900000,0.18748389,477.07765384,0.17183669,566.52202768,0.00088648,0.18276477,579.28875904,-0.11249260,-0.07027217,0.00000000,0.00000000,0.00000000,0.00000000
237.61000000,5.66178100,4.81100000,0.18906322,477.27606417,0.17316579,567.51141476,0.00094887,0.18421264,580.13473528,-0.11340407,-0.07080857,0.00000000,0.00000000,0.00000000,0.00000000
239.11000000,5.70780000,4.81300000,0.19064200,477.47447451,0.17449266,568.50116328,0.00094743,0.18571826,581.13711824,-0.11432542,-0.07139284,0.00000000,0.00000000,0.00000000,0.00000000
240.61000000,5.75385200,4.81400000,0.19218356,477.57367968,0.17578655,569.35548748,0.00081977,0.18719109,582.12198545,-0.11525414,-0.07193696,0.00000000,0.00000000,0.00000000,0.00000000
242.11000000,5.80034200,4.81500000,0.19387544,477.67288485,0.17720469,570.28192770,0.00100780,0.18866317,582.98635320,-0.11613880,-0.07252437,0.00000000,0.00000000,0.00000000,0.00000000
243.61000000,5.84699900,4.81600000,0.19545433,477.77209001,0.17852631,571.15471535,0.00094417,0.19022483,583.90473729,-0.11707588,-0.07314894,0.00000000,0.00000000,0.00000000,0.00000000
245.11000000,5.89308900,4.81800000,0.19703300,477.97050035,0.17984600,572.14646195,0.00081644,0.19175186,584.92626149,-0.11799672,-0.07375515,0.00000000,0.00000000,0.00000000,0.00000000
246.61000000,5.93988700,4.81900000,0.19868789,478.06970552,0.18122753,573.05636605,0.00094144,0.19330827,585.84462288,-0.11895057,-0.07435770,0.00000000,0.00000000,0.00000000,0.00000000
248.11000000,5.98695400,4.82100000,0.20030456,478.26811586,0.18257532,574.06739824,0.00087719,0.19489326,586.78134830,-0.11995252,-0.07494074,0.00000000,0.00000000,0.00000000,0.00000000
249.61000000,6.03476700,4.82200000,0.20199622,478.36732102,0.18398369,574.99571271,0.00100099,0.19650408,587.85756188,-0.12094640,-0.07555767,0.00000000,0.00000000,0.00000000,0.00000000
251.11000000,6.08224000,4.82200000,0.20365044,478.36732102,0.18535898,575.78703856,0.00099962,0.00000000,0.00000000,0.00000000,0.00000000,0.00000000,0.00000000,0.00000000,0.00000000
252.61000000,6.13045500,4.82400000,0.20537956,478.56573136,0.18679450,576.85334857,0.00099781,0.00000000,0.00000000,0.00000000,0.00000000,0.00000000,0.00000000,0.00000000,0.00000000
254.11000000,6.17881100,4.82500000,0.20710933,478.66493653,0.18822852,577.80091242,0.00099675,0.00000000,0.00000000,0.00000000,0.00000000,0.00000000,0.00000000,0.00000000,0.00000000
255.61000000,6.22682800,4.82500000,0.20880133,478.66493653,0.18962923,578.61081350,0.00093319,0.00000000,0.00000000,0.00000000,0.00000000,0.00000000,0.00000000,0.00000000,0.00000000
257.11000000,6.27565200,4.82600000,0.21056833,478.76414170,0.19108995,579.57670907,0.00099390,0.00000000,0.00000000,0.00000000,0.00000000,0.00000000,0.00000000,0.00000000,0.00000000
258.61000000,6.32431500,4.82700000,0.21233556,478.86334686,0.19254871,580.54306166,0.00099282,0.00000000,0.00000000,0.00000000,0.00000000,0.00000000,0.00000000,0.00000000,0.00000000
260.11000000,6.37391700,4.82800000,0.21414000,478.96255203,0.19403601,581.52759293,0.00092909,0.00000000,0.00000000,0.00000000,0.00000000,0.00000000,0.00000000,0.00000000,0.00000000
261.61000000,6.42352200,4.82800000,0.21598222,478.96255203,0.19555216,582.40994838,0.00098911,0.00000000,0.00000000,0.00000000,0.00000000,0.00000000,0.00000000,0.00000000,0.00000000
263.11000000,6.47302900,4.82800000,0.21782489,478.96255203,0.19706639,583.29251671,0.00105005,0.00000000,0.00000000,0.00000000,0.00000000,0.00000000,0.00000000,0.00000000,0.00000000
264.61000000,6.52300300,4.82900000,0.21974222,479.06175720,0.19863954,584.33185231,0.00104822,0.00000000,0.00000000,0.00000000,0.00000000,0.00000000,0.00000000,0.00000000,0.00000000
266.11000000,6.57345000,4.82900000,0.22162200,479.06175720,0.20017948,585.23238196,0.00104642,0.00000000,0.00000000,0.00000000,0.00000000,0.00000000,0.00000000,0.00000000,0.00000000
267.61000000,6.62386300,4.82900000,0.22357689,479.06175720,0.20177845,586.16889446,0.00110672,0.00000000,0.00000000,0.00000000,0.00000000,0.00000000,0.00000000,0.00000000,0.00000000
269.11000000,6.67461600,4.82900000,0.22549422,479.06175720,0.20334421,587.08741554,0.00104294,0.00000000,0.00000000,0.00000000,0.00000000,0.00000000,0.00000000,0.00000000,0.00000000
270.61000000,6.72682600,4.82900000,0.22748667,479.06175720,0.00000000,0.00000000,0.00000000,0.00000000,0.00000000,0.00000000,0.00000000,0.00000000,0.00000000,0.00000000,0.00000000
272.11000000,6.77832200,4.83000000,0.22966733,479.16096237,0.00000000,0.00000000,0.00000000,0.00000000,0.00000000,0.00000000,0.00000000,0.00000000,0.00000000,0.00000000,0.00000000
273.61000000,6.83130500,4.82900000,0.23177278,479.06175720,0.00000000,0.00000000,0.00000000,0.00000000,0.00000000,0.00000000,0.00000000,0.00000000,0.00000000,0.00000000,0.00000000
275.11000000,6.88399000,4.82800000,0.23399100,478.96255203,0.00000000,0.00000000,0.00000000,0.00000000,0.00000000,0.00000000,0.00000000,0.00000000,0.00000000,0.00000000,0.00000000
276.61000000,6.93610100,4.82800000,0.23624689,478.96255203,0.00000000,0.00000000,0.00000000,0.00000000,0.00000000,0.00000000,0.00000000,0.00000000,0.00000000,0.00000000,0.00000000
278.11000000,6.98949600,4.82800000,0.23854089,478.96255203,0.00000000,0.00000000,0.00000000,0.00000000,0.00000000,0.00000000,0.00000000,0.00000000,0.00000000,0.00000000,0.00000000
279.61000000,7.04292600,4.82700000,0.24094700,478.86334686,0.00000000,0.00000000,0.00000000,0.00000000,0.00000000,0.00000000,0.00000000,0.00000000,0.00000000,0.00000000,0.00000000
281.11000000,7.09736900,4.82600000,0.24342878,478.76414170,0.00000000,0.00000000,0.00000000,0.00000000,0.00000000,0.00000000,0.00000000,0.00000000,0.00000000,0.00000000,0.00000000
282.61000000,7.15198500,4.82500000,0.24602300,478.66493653,0.00000000,0.00000000,0.00000000,0.00000000,0.00000000,0.00000000,0.00000000,0.00000000,0.00000000,0.00000000,0.00000000
284.11000000,7.20687200,4.82300000,0.24873067,478.46652619,0.00000000,0.00000000,0.00000000,0.00000000,0.00000000,0.00000000,0.00000000,0.00000000,0.00000000,0.00000000,0.00000000
285.61000000,7.26223300,4.82200000,0.25158878,478.36732102,0.00000000,0.00000000,0.00000000,0.00000000,0.00000000,0.00000000,0.00000000,0.00000000,0.00000000,0.00000000,0.00000000
287.11000000,7.31793000,4.81900000,0.25467244,478.06970552,0.00000000,0.00000000,0.00000000,0.00000000,0.00000000,0.00000000,0.00000000,0.00000000,0.00000000,0.00000000,0.00000000
288.61000000,7.37430300,4.81600000,0.25779467,477.77209001,0.00000000,0.00000000,0.00000000,0.00000000,0.00000000,0.00000000,0.00000000,0.00000000,0.00000000,0.00000000,0.00000000
290.11000000,7.43084700,4.81300000,0.26114300,477.47447451,0.00000000,0.00000000,0.00000000,0.00000000,0.00000000,0.00000000,0.00000000,0.00000000,0.00000000,0.00000000,0.00000000
291.61000000,7.48868400,4.80700000,0.26468289,476.87924350,0.00000000,0.00000000,0.00000000,0.00000000,0.00000000,0.00000000,0.00000000,0.00000000,0.00000000,0.00000000,0.00000000
292.11000000,7.50974500,4.80500000,0.26604300,476.68083316,0.00000000,0.00000000,0.00000000,0.00000000,0.00000000,0.00000000,0.00000000,0.00000000,0.00000000,0.00000000,0.00000000