File: polyN_optimization/results_exp/DP600/UT_00_2.csv
Time[s],Displacement[mm],Force[kN],EngStrain_longi,EngStress[MPa],TrueStrain,TrueStress[MPa],TrueStrainRate[1/s],PlasticStrain_longi,PlasticStress[MPa],PlasticStrain_thick,PlasticStrain_width,R-Value,Thickness[mm],Width[mm], Young's Modulus [MPa]
0.61000000,0.00000000,-0.01200000,0.00000000,-0.79443893,0.00000000,-0.79443893,0.00000000,0.00065111,322.38561611,0.00010430,-0.00075541,0.86419801,1.51050000,10.00000000,213729.86852373
2.11000000,0.00168300,0.07000000,0.00004411,4.63422708,0.00004411,4.63443150,0.00000356,0.00097626,338.11266216,-0.00009045,-0.00088581,0.00000000,0.00000000,0.00000000,0.00000000
3.61000000,0.00344000,0.42900000,0.00009567,28.40119166,0.00009566,28.40390871,0.00001600,0.00138820,353.28435500,-0.00030374,-0.00108446,0.00000000,0.00000000,0.00000000,0.00000000
5.12000000,0.00641600,0.78400000,0.00019533,51.90334326,0.00019531,51.91348172,0.00010238,0.00201827,364.95647908,-0.00058618,-0.00143210,0.00000000,0.00000000,0.00000000,0.00000000
6.61000000,0.00848500,1.08600000,0.00022289,71.89672294,0.00022286,71.91274792,0.00005799,0.00277720,377.15948187,-0.00092347,-0.00185373,0.00000000,0.00000000,0.00000000,0.00000000
8.11000000,0.01019300,1.44500000,0.00031078,95.66368752,0.00031073,95.69341767,0.00008153,0.00349100,387.16415006,-0.00126222,-0.00222877,0.00000000,0.00000000,0.00000000,0.00000000
9.61000000,0.01226900,1.75200000,0.00037478,115.98808342,0.00037471,116.03155317,0.00004125,0.00424490,397.06635589,-0.00165438,-0.00259052,0.00000000,0.00000000,0.00000000,0.00000000
11.12000000,0.01455300,2.13500000,0.00044178,141.34392585,0.00044168,141.40636846,-0.00007419,0.00506013,405.47288534,-0.00212666,-0.00293347,0.00000000,0.00000000,0.00000000,0.00000000
12.61000000,0.01770500,2.43900000,0.00054289,161.46971202,0.00054274,161.55737213,-0.00008751,0.00596512,413.99762736,-0.00266141,-0.00330371,0.00000000,0.00000000,0.00000000,0.00000000
14.11000000,0.02167700,2.81900000,0.00071878,186.62694472,0.00071852,186.76108802,0.00001244,0.00688008,421.00303034,-0.00315048,-0.00372960,0.00000000,0.00000000,0.00000000,0.00000000
15.61000000,0.02541800,3.12000000,0.00088756,206.55412115,0.00088716,206.73744941,0.00026237,0.00769221,428.78112528,-0.00350258,-0.00418963,0.00000000,0.00000000,0.00000000,0.00000000
17.11000000,0.02951300,3.46300000,0.00102256,229.26183383,0.00102203,229.49626679,0.00041295,0.00857639,435.79906139,-0.00391692,-0.00465947,0.00000000,0.00000000,0.00000000,0.00000000
18.61000000,0.03327400,3.75500000,0.00108289,248.59318107,0.00108230,248.86237986,0.00029970,0.00953127,443.06228203,-0.00442500,-0.00510627,0.00000000,0.00000000,0.00000000,0.00000000
20.11000000,0.03903100,4.11200000,0.00116978,272.22773916,0.00116909,272.54618512,0.00011032,0.01047767,449.59659143,-0.00496527,-0.00551240,0.00000000,0.00000000,0.00000000,0.00000000
21.61000000,0.04684500,4.38400000,0.00136844,290.23502152,0.00136751,290.63219202,-0.00010275,0.01135309,456.37984305,-0.00542759,-0.00592550,0.00000000,0.00000000,0.00000000,0.00000000
23.11000000,0.05644600,4.68300000,0.00169211,310.02979146,0.00169068,310.55439631,-0.00019832,0.01227624,462.12015389,-0.00594279,-0.00633345,0.00000000,0.00000000,0.00000000,0.00000000
24.61000000,0.06786800,4.93400000,0.00222178,326.64680569,0.00221931,327.37254231,0.00006608,0.01320997,468.48240485,-0.00647959,-0.00673038,0.00000000,0.00000000,0.00000000,0.00000000
26.11000000,0.08379300,5.17800000,0.00279933,342.80039722,0.00279542,343.76000980,0.00041821,0.01420001,474.20878336,-0.00702650,-0.00717352,0.00000000,0.00000000,0.00000000,0.00000000
27.61000000,0.10094300,5.36500000,0.00334744,355.18040384,0.00334185,356.36935051,0.00054270,0.01514487,480.12718755,-0.00747361,-0.00767126,0.00000000,0.00000000,0.00000000,0.00000000
29.11000000,0.12110600,5.57200000,0.00396922,368.88447534,0.00396137,370.34865980,0.00041041,0.01608728,485.58237470,-0.00788395,-0.00820333,0.00000000,0.00000000,0.00000000,0.00000000
30.61000000,0.14484500,5.71800000,0.00475289,378.55014896,0.00474163,380.34935575,0.00033687,0.01705719,491.12890281,-0.00837144,-0.00868576,0.00000000,0.00000000,0.00000000,0.00000000
32.11000000,0.16928000,5.87000000,0.00566900,388.61304204,0.00565299,390.81608937,0.00063671,0.01806785,496.23220814,-0.00894559,-0.00912226,0.00000000,0.00000000,0.00000000,0.00000000
33.61000000,0.19560000,6.00000000,0.00654078,397.21946375,0.00651948,399.81758800,0.00076757,0.01905666,501.13120040,-0.00952749,-0.00952918,0.00000000,0.00000000,0.00000000,0.00000000
35.11000000,0.22119300,6.12700000,0.00732078,405.62727574,0.00729411,408.59678288,0.00060632,0.02005199,505.97506433,-0.01007848,-0.00997351,0.00000000,0.00000000,0.00000000,0.00000000
36.61000000,0.24993000,6.22900000,0.00821100,412.38000662,0.00817747,415.76605885,0.00048188,0.02104928,510.96518722,-0.01066829,-0.01038099,0.00000000,0.00000000,0.00000000,0.00000000
38.11000000,0.27658100,6.35100000,0.00917100,420.45680238,0.00912920,424.31281172,0.00048869,0.02206581,515.43084166,-0.01122359,-0.01084222,0.00000000,0.00000000,0.00000000,0.00000000
39.61000000,0.30425900,6.44400000,0.01014578,426.61370407,0.01009465,430.94203191,0.00072126,0.02308705,520.18004588,-0.01173060,-0.01135646,0.00000000,0.00000000,0.00000000,0.00000000
41.11000000,0.33312800,6.54900000,0.01102122,433.56504469,0.01096093,438.34346139,0.00061861,0.02412034,524.46784934,-0.01227549,-0.01184484,0.00000000,0.00000000,0.00000000,0.00000000
42.61000000,0.36163400,6.64300000,0.01193711,439.78814962,0.01186643,445.03794963,0.00045067,0.02515647,528.62917881,-0.01276753,-0.01238893,0.00000000,0.00000000,0.00000000,0.00000000
44.11000000,0.39017200,6.74000000,0.01291567,446.20986428,0.01283297,451.97296215,0.00042873,0.02623140,532.68284745,-0.01337113,-0.01286026,0.00000000,0.00000000,0.00000000,0.00000000
45.61000000,0.41970400,6.82100000,0.01391622,451.57232704,0.01382028,457.85650790,0.00058791,0.02729358,536.94307174,-0.01393817,-0.01335542,0.00000000,0.00000000,0.00000000,0.00000000
47.11000000,0.44959900,6.91700000,0.01487267,457.92783846,0.01476315,464.73844656,0.00057268,0.02834222,540.79381927,-0.01449713,-0.01384509,0.00000000,0.00000000,0.00000000,0.00000000
48.61000000,0.47810400,6.99200000,0.01580711,462.89308176,0.01568348,470.21008414,0.00048528,0.02940674,544.79794027,-0.01513365,-0.01427309,0.00000000,0.00000000,0.00000000,0.00000000
50.11000000,0.50929000,7.07500000,0.01681144,468.38795101,0.01667170,476.26222903,0.00042709,0.03044327,548.45168995,-0.01570437,-0.01473890,0.00000000,0.00000000,0.00000000,0.00000000
51.61000000,0.53802500,7.15000000,0.01785989,473.35319431,0.01770227,481.80722976,0.00054217,0.03151808,552.06506433,-0.01630529,-0.01521279,0.00000000,0.00000000,0.00000000,0.00000000
53.11000000,0.56984000,7.22800000,0.01888256,478.51704734,0.01870649,487.55267207,0.00061384,0.03260292,555.55376213,-0.01690047,-0.01570245,0.00000000,0.00000000,0.00000000,0.00000000
54.61000000,0.60046400,7.29200000,0.01986844,482.75405495,0.01967364,492.34562707,0.00055549,0.03369578,559.32934999,-0.01747209,-0.01622369,0.00000000,0.00000000,0.00000000,0.00000000
56.11000000,0.63151700,7.37000000,0.02094989,487.91790798,0.02073346,498.13973394,0.00060519,0.03476853,562.61891157,-0.01801583,-0.01675270,0.00000000,0.00000000,0.00000000,0.00000000
57.61000000,0.66306800,7.42900000,0.02200567,491.82389937,0.02176704,502.64681216,0.00064807,0.03585701,566.06189853,-0.01854877,-0.01730824,0.00000000,0.00000000,0.00000000,0.00000000
59.11000000,0.69478500,7.50100000,0.02307600,496.59053294,0.02281378,508.04985607,0.00070475,0.03696642,569.31657023,-0.01912287,-0.01784354,0.00000000,0.00000000,0.00000000,0.00000000
60.61000000,0.72626900,7.55700000,0.02414278,500.29791460,0.02385595,512.37649597,0.00074700,0.03807870,572.44122209,-0.01969428,-0.01838441,0.00000000,0.00000000,0.00000000,0.00000000
62.11000000,0.75835000,7.61900000,0.02520589,504.40251572,0.02489346,517.11642949,0.00074644,0.03918224,575.63639617,-0.02028486,-0.01889738,0.00000000,0.00000000,0.00000000,0.00000000
63.61000000,0.79099200,7.67100000,0.02627622,507.84508441,0.02593693,521.18933470,0.00074566,0.04029161,578.84141013,-0.02086774,-0.01942386,0.00000000,0.00000000,0.00000000,0.00000000
65.11000000,0.82307300,7.73500000,0.02736878,512.08209202,0.02700095,526.09715300,0.00076629,0.04144320,581.80001624,-0.02153101,-0.01991219,0.00000000,0.00000000,0.00000000,0.00000000
66.61000000,0.85611400,7.78300000,0.02846489,515.25984773,0.02806729,529.92666205,0.00078709,0.04256775,584.95730029,-0.02211655,-0.02045120,0.00000000,0.00000000,0.00000000,0.00000000
68.11000000,0.88918700,7.84100000,0.02957578,519.09963588,0.02914685,534.45241136,0.00075774,0.04366470,587.75703796,-0.02272058,-0.02094412,0.00000000,0.00000000,0.00000000,0.00000000
69.61000000,0.92179700,7.88700000,0.03062778,522.14498510,0.03016811,538.13712568,0.00063531,0.04478142,590.57399831,-0.02332655,-0.02145488,0.00000000,0.00000000,0.00000000,0.00000000
71.11000000,0.95530000,7.93800000,0.03176078,525.52135055,0.03126684,542.21231738,0.00069882,0.04593200,593.34703281,-0.02398332,-0.02194868,0.00000000,0.00000000,0.00000000,0.00000000
72.61000000,0.98883700,7.98000000,0.03287533,528.30188679,0.03234650,545.66998742,0.00069096,0.04705609,596.24948030,-0.02456805,-0.02248804,0.00000000,0.00000000,0.00000000,0.00000000
74.11000000,1.02247300,8.03200000,0.03399722,531.74445548,0.03343209,549.82228990,0.00075428,0.04816259,598.93761348,-0.02512401,-0.02303858,0.00000000,0.00000000,0.00000000,0.00000000
75.61000000,1.05617600,8.07100000,0.03511922,534.32638199,0.03451661,553.09150894,0.00073929,0.04933722,601.67214535,-0.02575730,-0.02357992,0.00000000,0.00000000,0.00000000,0.00000000
77.11000000,1.09050700,8.12100000,0.03627789,537.63654419,0.03563534,557.14086300,0.00077386,0.05048346,604.25507136,-0.02635634,-0.02412712,0.00000000,0.00000000,0.00000000,0.00000000
78.61000000,1.12440800,8.15800000,0.03741822,540.08606422,0.03673515,560.29512459,0.00075179,0.05163549,606.77660062,-0.02698996,-0.02464553,0.00000000,0.00000000,0.00000000,0.00000000
80.11000000,1.15857300,8.20000000,0.03858433,542.86660046,0.03785857,563.81274633,0.00082180,0.05278615,609.30235926,-0.02758442,-0.02520173,0.00000000,0.00000000,0.00000000,0.00000000
81.61000000,1.19323500,8.23600000,0.03970633,545.24991725,0.03893830,566.89979221,0.00077152,0.05395949,611.91738918,-0.02820183,-0.02575767,0.00000000,0.00000000,0.00000000,0.00000000
83.11000000,1.22756600,8.27900000,0.04086500,548.09665674,0.04005210,570.49462661,0.00074930,0.05509770,614.30503824,-0.02881521,-0.02628250,0.00000000,0.00000000,0.00000000,0.00000000
84.61000000,1.26285700,8.31300000,0.04207522,550.34756703,0.04121413,573.50356321,0.00081905,0.05627580,616.79250292,-0.02944858,-0.02682722,0.00000000,0.00000000,0.00000000,0.00000000
86.11000000,1.29814900,8.35400000,0.04323767,553.06190003,0.04232902,576.97500611,0.00081131,0.05747378,619.15631657,-0.03011404,-0.02735974,0.00000000,0.00000000,0.00000000,0.00000000
87.61000000,1.33310900,8.38500000,0.04436333,555.11420060,0.04340745,579.74091691,0.00071891,0.05862229,621.42350365,-0.03072605,-0.02789623,0.00000000,0.00000000,0.00000000,0.00000000
89.11000000,1.36876400,8.42100000,0.04553311,557.49751738,0.04452691,582.88211378,0.00062647,0.05978017,623.63029805,-0.03132659,-0.02845358,0.00000000,0.00000000,0.00000000,0.00000000
90.61000000,1.40408800,8.45200000,0.04676533,559.54981794,0.04570477,585.71735169,0.00070303,0.06099108,626.01627629,-0.03203402,-0.02895706,0.00000000,0.00000000,0.00000000,0.00000000
92.11000000,1.43994200,8.48700000,0.04796089,561.86693148,0.04684627,588.81456895,0.00076544,0.06216327,628.24102269,-0.03264004,-0.02952323,0.00000000,0.00000000,0.00000000,0.00000000
93.61000000,1.47569700,8.51500000,0.04909756,563.72062231,0.04793032,591.39792688,0.00067328,0.06330315,630.44974153,-0.03322165,-0.03008150,0.00000000,0.00000000,0.00000000,0.00000000
95.11000000,1.51112100,8.55000000,0.05030044,566.03773585,0.04907626,594.50968553,0.00063759,0.06451058,632.63454882,-0.03387552,-0.03063506,0.00000000,0.00000000,0.00000000,0.00000000
96.61000000,1.54770300,8.57800000,0.05154733,567.89142668,0.05026273,597.16471535,0.00073471,0.06571013,634.74761042,-0.03453095,-0.03117918,0.00000000,0.00000000,0.00000000,0.00000000
98.11000000,1.58385500,8.60800000,0.05278333,569.87752400,0.05143745,599.95755931,0.00084556,0.06689776,636.85726536,-0.03516453,-0.03173324,0.00000000,0.00000000,0.00000000,0.00000000
99.61000000,1.62080200,8.63200000,0.05398622,571.46640185,0.05257938,602.31771402,0.00075411,0.06807044,638.96148763,-0.03582486,-0.03224558,0.00000000,0.00000000,0.00000000,0.00000000
101.11000000,1.65711800,8.66300000,0.05523322,573.51870242,0.05376181,605.19598836,0.00080188,0.06929349,640.95942809,-0.03647263,-0.03282085,0.00000000,0.00000000,0.00000000,0.00000000
102.61000000,1.69393200,8.68700000,0.05646178,575.10758027,0.05492538,607.57917667,0.00080095,0.07049079,643.01620708,-0.03712592,-0.03336487,0.00000000,0.00000000,0.00000000,0.00000000
104.11000000,1.73111000,8.71700000,0.05771622,577.09367759,0.05611208,610.40134453,0.00084897,0.07168323,645.07388578,-0.03776311,-0.03392011,0.00000000,0.00000000,0.00000000,0.00000000
105.61000000,1.76775900,8.73900000,0.05894111,578.55014896,0.05726946,612.65053757,0.00079214,0.07292263,647.02277790,-0.03840444,-0.03451819,0.00000000,0.00000000,0.00000000,0.00000000
107.11000000,1.80516900,8.76400000,0.06016978,580.20523006,0.05842906,615.11604981,0.00081219,0.07415010,648.96778097,-0.03907551,-0.03507459,0.00000000,0.00000000,0.00000000,0.00000000
108.61000000,1.84238000,8.78600000,0.06141300,581.66170142,0.05960104,617.38329149,0.00077626,0.07534214,650.89348030,-0.03969813,-0.03564401,0.00000000,0.00000000,0.00000000,0.00000000
110.11000000,1.87995500,8.81300000,0.06266378,583.44918901,0.06077875,620.01031934,0.00071322,0.07650258,652.73028026,-0.04029608,-0.03620650,0.00000000,0.00000000,0.00000000,0.00000000
111.61000000,1.91749700,8.83300000,0.06395856,584.77325389,0.06199644,622.17450654,0.00082999,0.07777634,654.71691334,-0.04100205,-0.03677429,0.00000000,0.00000000,0.00000000,0.00000000
113.11000000,1.95480800,8.85700000,0.06515778,586.36213174,0.06312294,624.56818522,0.00074619,0.07900851,656.53600132,-0.04166772,-0.03734080,0.00000000,0.00000000,0.00000000,0.00000000
114.61000000,1.99225100,8.87600000,0.06644144,587.61999338,0.06432735,626.66231452,0.00071048,0.08021570,658.34210595,-0.04233105,-0.03788466,0.00000000,0.00000000,0.00000000,0.00000000
116.11000000,2.03038900,8.89900000,0.06774000,589.14266799,0.06554427,629.05119232,0.00077874,0.08144852,660.09633830,-0.04300645,-0.03844207,0.00000000,0.00000000,0.00000000,0.00000000
117.61000000,2.06829500,8.91700000,0.06900900,590.33432638,0.06673205,631.07270791,0.00085352,0.08271955,662.02403438,-0.04370219,-0.03901736,0.00000000,0.00000000,0.00000000,0.00000000
119.11000000,2.10640000,8.94000000,0.07027800,591.85700099,0.06791843,633.45152731,0.00079061,0.08395301,663.71319993,-0.04436802,-0.03958499,0.00000000,0.00000000,0.00000000,0.00000000
120.61000000,2.14470400,8.95700000,0.07157656,592.98245614,0.06913098,635.42609786,0.00079649,0.08517444,665.47006610,-0.04498559,-0.04018885,0.00000000,0.00000000,0.00000000,0.00000000
122.11000000,2.18327200,8.97800000,0.07289711,594.37272426,0.07036257,637.70077879,0.00086431,0.08640481,667.16361406,-0.04561245,-0.04079236,0.00000000,0.00000000,0.00000000,0.00000000
123.61000000,2.22197200,8.99500000,0.07415511,595.49817941,0.07153441,639.65741307,0.00084260,0.08767346,668.95875565,-0.04631515,-0.04135831,0.00000000,0.00000000,0.00000000,0.00000000
125.11000000,2.26027600,9.01200000,0.07542778,596.62363456,0.07271852,641.62562948,0.00074568,0.08893448,670.60663290,-0.04699868,-0.04193581,0.00000000,0.00000000,0.00000000,0.00000000
126.61000000,2.29914200,9.02800000,0.07676678,597.68288646,0.07396283,643.56507579,0.00082011,0.09016348,672.30894295,-0.04761812,-0.04254536,0.00000000,0.00000000,0.00000000,0.00000000
128.11000000,2.33820700,9.04800000,0.07807633,599.00695134,0.07517828,645.77521774,0.00084654,0.09142499,673.89041215,-0.04832794,-0.04309705,0.00000000,0.00000000,0.00000000,0.00000000
129.61000000,2.37783500,9.06300000,0.07935633,600.00000000,0.07636488,647.61380000,0.00072237,0.09267457,675.53984241,-0.04900946,-0.04366511,0.00000000,0.00000000,0.00000000,0.00000000
131.11000000,2.41663500,9.08100000,0.08068433,601.19165839,0.07759448,649.69840655,0.00070811,0.09396909,677.22289966,-0.04973763,-0.04423146,0.00000000,0.00000000,0.00000000,0.00000000
132.61000000,2.45632900,9.09500000,0.08204533,602.11850381,0.07885308,651.51951716,0.00082289,0.09521603,678.73022306,-0.05041148,-0.04480455,0.00000000,0.00000000,0.00000000,0.00000000
134.11000000,2.49582400,9.11000000,0.08335844,603.11155247,0.08006589,653.38599331,0.00091013,0.09645087,680.37877690,-0.05107950,-0.04537137,0.00000000,0.00000000,0.00000000,0.00000000
135.61000000,2.53578300,9.12400000,0.08469000,604.03839788,0.08129423,655.19440980,0.00080039,0.09774443,681.92361306,-0.05176536,-0.04597908,0.00000000,0.00000000,0.00000000,0.00000000
137.11000000,2.57521200,9.14000000,0.08603267,605.09764978,0.08253130,657.15581419,0.00079285,0.09900944,683.52532720,-0.05245360,-0.04655584,0.00000000,0.00000000,0.00000000,0.00000000
138.61000000,2.61517000,9.15300000,0.08739367,605.95829196,0.08378370,658.91520894,0.00086607,0.10029340,684.99571265,-0.05311096,-0.04718245,0.00000000,0.00000000,0.00000000,0.00000000
140.11000000,2.65585700,9.16900000,0.08872889,607.01754386,0.08501086,660.87753606,0.00083805,0.10156218,686.53206797,-0.05377674,-0.04778544,0.00000000,0.00000000,0.00000000,0.00000000
141.61000000,2.69598100,9.18100000,0.09008989,607.81198279,0.08626016,662.56969678,0.00077623,0.10284938,688.01010912,-0.05447300,-0.04837639,0.00000000,0.00000000,0.00000000,0.00000000
143.11000000,2.73650300,9.19400000,0.09147300,608.67262496,0.08752816,664.34973598,0.00082922,0.10414123,689.56799496,-0.05519281,-0.04894842,0.00000000,0.00000000,0.00000000,0.00000000
144.61000000,2.77692500,9.20600000,0.09283033,609.46706389,0.08877097,666.04409458,0.00085525,0.10542179,691.04690932,-0.05588103,-0.04954076,0.00000000,0.00000000,0.00000000,0.00000000
146.11000000,2.81704900,9.21800000,0.09416922,610.26150281,0.08999537,667.72935389,0.00082718,0.10665839,692.42380441,-0.05652700,-0.05013138,0.00000000,0.00000000,0.00000000,0.00000000
147.61000000,2.85783500,9.23100000,0.09555600,611.12214499,0.09126200,669.51853267,0.00080604,0.10796813,694.00246659,-0.05726303,-0.05070510,0.00000000,0.00000000,0.00000000,0.00000000
149.11000000,2.89911700,9.24300000,0.09696111,611.91658391,0.09254373,671.24869580,0.00083176,0.10927031,695.43013976,-0.05792842,-0.05134189,0.00000000,0.00000000,0.00000000,0.00000000
150.61000000,2.93953900,9.25300000,0.09831844,612.57861635,0.09378032,672.80639301,0.00083074,0.11058707,696.87057036,-0.05865101,-0.05193607,0.00000000,0.00000000,0.00000000,0.00000000
152.11000000,2.98082300,9.26300000,0.09972356,613.24064879,0.09505884,674.39518670,0.00084969,0.11189938,698.23594302,-0.05937793,-0.05252145,0.00000000,0.00000000,0.00000000,0.00000000
153.61000000,3.02184000,9.27500000,0.10112500,614.03508772,0.09633238,676.12938596,0.00088192,0.11320929,699.67666923,-0.06006035,-0.05314894,0.00000000,0.00000000,0.00000000,0.00000000
155.11000000,3.06362000,9.28500000,0.10252289,614.69712016,0.09760109,677.71764471,0.00081426,0.11452425,701.12354347,-0.06078816,-0.05373609,0.00000000,0.00000000,0.00000000,0.00000000
156.61000000,3.10460400,9.29500000,0.10391700,615.35915260,0.09886476,679.30542966,0.00083337,0.11583438,702.49478723,-0.06148120,-0.05435318,0.00000000,0.00000000,0.00000000,0.00000000
158.11000000,3.14625000,9.30400000,0.10534422,615.95498179,0.10015680,680.84228028,0.00093205,0.11716564,703.88336239,-0.06219525,-0.05497039,0.00000000,0.00000000,0.00000000,0.00000000
159.61000000,3.18816200,9.31500000,0.10673822,616.68321748,0.10141715,682.50688779,0.00085093,0.11846292,705.17532370,-0.06290255,-0.05556037,0.00000000,0.00000000,0.00000000,0.00000000
161.11000000,3.23033800,9.32300000,0.10812867,617.21284343,0.10267271,683.95124524,0.00081676,0.11980347,706.57527350,-0.06359786,-0.05620561,0.00000000,0.00000000,0.00000000,0.00000000
162.61000000,3.27211800,9.33300000,0.10962211,617.87487587,0.10401952,685.60762416,0.00092846,0.12111972,707.96045851,-0.06431728,-0.05680243,0.00000000,0.00000000,0.00000000,0.00000000
164.11000000,3.31386300,9.34000000,0.11101611,618.33829858,0.10527501,686.98381184,0.00088727,0.12244771,709.20577728,-0.06501904,-0.05742867,0.00000000,0.00000000,0.00000000,0.00000000
165.61000000,3.35571000,9.34900000,0.11241400,618.93412777,0.10653243,688.51098881,0.00081361,0.12378654,710.53632308,-0.06572829,-0.05805825,0.00000000,0.00000000,0.00000000,0.00000000
167.11000000,3.39818400,9.35700000,0.11388178,619.46375372,0.10785101,690.00938727,0.00085226,0.12513284,711.95004857,-0.06646643,-0.05866641,0.00000000,0.00000000,0.00000000,0.00000000
168.61000000,3.44062500,9.36500000,0.11529056,619.99337968,0.10911496,691.47276086,0.00080493,0.12647491,713.21199923,-0.06718064,-0.05929428,0.00000000,0.00000000,0.00000000,0.00000000
170.11000000,3.48286700,9.37300000,0.11674711,620.52300563,0.11042009,692.96727391,0.00092890,0.12784996,714.57545476,-0.06792804,-0.05992192,0.00000000,0.00000000,0.00000000,0.00000000
171.61000000,3.52587200,9.38100000,0.11818911,621.05263158,0.11171051,694.45429006,0.00087522,0.12920801,715.77741331,-0.06867034,-0.06053767,0.00000000,0.00000000,0.00000000,0.00000000
173.11000000,3.56907500,9.38800000,0.11966789,621.51605429,0.11303211,695.89156841,0.00090047,0.13055406,717.04864670,-0.06940036,-0.06115369,0.00000000,0.00000000,0.00000000,0.00000000
174.61000000,3.61181400,9.39600000,0.12116133,622.04568024,0.11436505,697.41356425,0.00091910,0.13193002,718.41964135,-0.07012315,-0.06180688,0.00000000,0.00000000,0.00000000,0.00000000
176.11000000,3.65551300,9.40100000,0.12259211,622.37669646,0.11564040,698.67516958,0.00083218,0.13326636,719.61211936,-0.07081307,-0.06245329,0.00000000,0.00000000,0.00000000,0.00000000
177.61000000,3.69825100,9.40800000,0.12407822,622.84011917,0.11696334,700.12101388,0.00084452,0.13464201,720.91121181,-0.07156728,-0.06307473,0.00000000,0.00000000,0.00000000,0.00000000
179.11000000,3.74172000,9.41400000,0.12556067,623.23733863,0.11828128,701.49143436,0.00083670,0.13600984,722.13049701,-0.07229148,-0.06371837,0.00000000,0.00000000,0.00000000,0.00000000
180.61000000,3.78542000,9.42200000,0.12704300,623.76696458,0.11959739,703.01219106,0.00083560,0.13741034,723.45196893,-0.07302885,-0.06438149,0.00000000,0.00000000,0.00000000,0.00000000
182.11000000,3.82905400,9.42700000,0.12854756,624.09798080,0.12093146,704.32425066,0.00082798,0.13880887,724.77429802,-0.07377948,-0.06502939,0.00000000,0.00000000,0.00000000,0.00000000
183.61000000,3.87242100,9.43200000,0.13003367,624.42899702,0.12224743,705.62578908,0.00085306,0.14020624,725.94469151,-0.07453745,-0.06566878,0.00000000,0.00000000,0.00000000,0.00000000
185.11000000,3.91688300,9.43800000,0.13153811,624.82621648,0.12357787,707.01467677,0.00081950,0.14163288,727.21511533,-0.07533145,-0.06630143,0.00000000,0.00000000,0.00000000,0.00000000
186.61000000,3.96104700,9.44400000,0.13308678,625.22343595,0.12494557,708.43240843,0.00090923,0.14302581,728.46305621,-0.07608345,-0.06694236,0.00000000,0.00000000,0.00000000,0.00000000
188.11000000,4.00560700,9.44900000,0.13461700,625.55445217,0.12629515,709.76471586,0.00094053,0.14441689,729.71170990,-0.07682330,-0.06759359,0.00000000,0.00000000,0.00000000,0.00000000
189.61000000,4.04973800,9.45300000,0.13614356,625.81926514,0.12763968,711.02052504,0.00093926,0.14586951,730.93044934,-0.07762268,-0.06824682,0.00000000,0.00000000,0.00000000,0.00000000
191.11000000,4.09409900,9.45900000,0.13767367,626.21648461,0.12898553,712.43000417,0.00092491,0.14728802,732.20338625,-0.07838248,-0.06890554,0.00000000,0.00000000,0.00000000,0.00000000
192.61000000,4.13912300,9.46300000,0.13917811,626.48129758,0.13030705,713.67378123,0.00087177,0.14873634,733.42305903,-0.07915214,-0.06958420,0.00000000,0.00000000,0.00000000,0.00000000
194.11000000,4.18411500,9.46700000,0.14075989,626.74611056,0.13169461,714.96682344,0.00088382,0.15015122,734.62008024,-0.07987771,-0.07027351,0.00000000,0.00000000,0.00000000,0.00000000
195.61000000,4.22927000,9.47100000,0.14231956,627.01092354,0.13306089,716.24683950,0.00088884,0.15162685,735.86388881,-0.08068918,-0.07093767,0.00000000,0.00000000,0.00000000,0.00000000
197.11000000,4.27439300,9.47500000,0.14386456,627.27573651,0.13441249,717.51848156,0.00088783,0.15310009,737.10801515,-0.08148527,-0.07161482,0.00000000,0.00000000,0.00000000,0.00000000
198.61000000,4.31925200,9.48000000,0.14545367,627.60675273,0.13580077,718.89445614,0.00089941,0.15454051,738.25208581,-0.08226181,-0.07227870,0.00000000,0.00000000,0.00000000,0.00000000
200.11000000,4.36460600,9.48300000,0.14702067,627.80536246,0.13716786,720.10572539,0.00094954,0.15604087,739.52033522,-0.08308413,-0.07295673,0.00000000,0.00000000,0.00000000,0.00000000
201.61000000,4.40989500,9.48600000,0.14862078,628.00397219,0.13856190,721.33841099,0.00097397,0.15753886,740.78898213,-0.08389454,-0.07364432,0.00000000,0.00000000,0.00000000,0.00000000
203.11000000,4.45587900,9.49000000,0.15019133,628.26878517,0.13992831,722.62931171,0.00095949,0.15900381,741.95701259,-0.08467595,-0.07432786,0.00000000,0.00000000,0.00000000,0.00000000
204.61000000,4.50169700,9.49300000,0.15180989,628.46739490,0.14133452,723.87496029,0.00095834,0.16046670,743.12534203,-0.08544140,-0.07502530,0.00000000,0.00000000,0.00000000,0.00000000
206.11000000,4.54811100,9.49600000,0.15342833,628.66600463,0.14273867,725.12118195,0.00095699,0.16198945,744.34022800,-0.08627890,-0.07571056,0.00000000,0.00000000,0.00000000,0.00000000
207.61000000,4.59366500,9.49900000,0.15508367,628.86461437,0.14417278,726.39124460,0.00101933,0.16347896,745.53222143,-0.08706643,-0.07641253,0.00000000,0.00000000,0.00000000,0.00000000
209.11000000,4.63981400,9.50200000,0.15666533,629.06322410,0.14554115,727.61562379,0.00089069,0.16505949,746.71569736,-0.08791312,-0.07714637,0.00000000,0.00000000,0.00000000,0.00000000
210.61000000,4.68629300,9.50500000,0.15828389,629.26183383,0.14693950,728.86384402,0.00088964,0.16660575,748.03287031,-0.08873193,-0.07787382,0.00000000,0.00000000,0.00000000,0.00000000
212.11000000,4.73323700,9.50700000,0.15993911,629.39424032,0.14836751,730.05899565,0.00095162,0.16815036,749.19331837,-0.08954676,-0.07860360,0.00000000,0.00000000,0.00000000,0.00000000
213.61000000,4.77998300,9.51000000,0.16163122,629.59285005,0.14982524,731.35471191,0.00095023,0.00000000,0.00000000,0.00000000,0.00000000,0.00000000,0.00000000,0.00000000,0.00000000
215.11000000,4.82686000,9.51300000,0.16328644,629.79145978,0.15124914,732.62786799,0.00094888,0.00000000,0.00000000,0.00000000,0.00000000,0.00000000,0.00000000,0.00000000,0.00000000
216.61000000,4.87453200,9.51500000,0.16501522,629.92386627,0.15273415,733.87089304,0.00101064,0.00000000,0.00000000,0.00000000,0.00000000,0.00000000,0.00000000,0.00000000,0.00000000
218.11000000,4.92200600,9.51700000,0.16674411,630.05627276,0.15421706,735.11444591,0.00113529,0.00000000,0.00000000,0.00000000,0.00000000,0.00000000,0.00000000,0.00000000,0.00000000
219.61000000,4.96984400,9.51800000,0.16839933,630.12247600,0.15563472,736.23468088,0.00100752,0.00000000,0.00000000,0.00000000,0.00000000,0.00000000,0.00000000,0.00000000,0.00000000
221.11000000,5.01758200,9.52000000,0.17009144,630.25488249,0.15708190,737.45584582,0.00094355,0.00000000,0.00000000,0.00000000,0.00000000,0.00000000,0.00000000,0.00000000,0.00000000
222.61000000,5.06518800,9.52200000,0.17182033,630.38728898,0.15855838,738.70064310,0.00100477,0.00000000,0.00000000,0.00000000,0.00000000,0.00000000,0.00000000,0.00000000,0.00000000
224.11000000,5.11375300,9.52400000,0.17351244,630.51969547,0.16000134,739.92270910,0.00087790,0.00000000,0.00000000,0.00000000,0.00000000,0.00000000,0.00000000,0.00000000,0.00000000
225.61000000,5.16218700,9.52500000,0.17531478,630.58589871,0.16153601,741.13692541,0.00093917,0.00000000,0.00000000,0.00000000,0.00000000,0.00000000,0.00000000,0.00000000,0.00000000
227.11000000,5.21078600,9.52600000,0.17708033,630.65210195,0.16303708,742.32818638,0.00100028,0.00000000,0.00000000,0.00000000,0.00000000,0.00000000,0.00000000,0.00000000,0.00000000
228.61000000,5.25971600,9.52700000,0.17884600,630.71830520,0.16453599,743.51975121,0.00106121,0.00000000,0.00000000,0.00000000,0.00000000,0.00000000,0.00000000,0.00000000,0.00000000
230.11000000,5.30897600,9.52800000,0.18064833,630.78450844,0.16606372,744.73467858,0.00105959,0.00000000,0.00000000,0.00000000,0.00000000,0.00000000,0.00000000,0.00000000,0.00000000
231.61000000,5.35794000,9.52900000,0.18245067,630.85071168,0.16758912,745.94984460,0.00112002,0.00000000,0.00000000,0.00000000,0.00000000,0.00000000,0.00000000,0.00000000,0.00000000
233.11000000,5.40716800,9.52900000,0.18421644,630.85071168,0.16908133,747.06378677,0.00093210,0.00000000,0.00000000,0.00000000,0.00000000,0.00000000,0.00000000,0.00000000,0.00000000
234.61000000,5.45669400,9.53100000,0.18609233,630.98311817,0.17066415,748.40423893,0.00099267,0.00000000,0.00000000,0.00000000,0.00000000,0.00000000,0.00000000,0.00000000,0.00000000
236.11000000,5.50651700,9.53100000,0.18800511,630.98311817,0.17227552,749.61116941,0.00111516,0.00000000,0.00000000,0.00000000,0.00000000,0.00000000,0.00000000,0.00000000,0.00000000
237.61000000,5.55710200,9.53200000,0.18984433,631.04932142,0.00000000,0.00000000,0.00000000,0.00000000,0.00000000,0.00000000,0.00000000,0.00000000,0.00000000,0.00000000,0.00000000
239.11000000,5.60712500,9.53100000,0.19172022,630.98311817,0.00000000,0.00000000,0.00000000,0.00000000,0.00000000,0.00000000,0.00000000,0.00000000,0.00000000,0.00000000,0.00000000
240.61000000,5.65695000,9.53100000,0.19370644,630.98311817,0.00000000,0.00000000,0.00000000,0.00000000,0.00000000,0.00000000,0.00000000,0.00000000,0.00000000,0.00000000,0.00000000
242.11000000,5.70756900,9.53100000,0.19561933,630.98311817,0.00000000,0.00000000,0.00000000,0.00000000,0.00000000,0.00000000,0.00000000,0.00000000,0.00000000,0.00000000,0.00000000
243.61000000,5.75798900,9.53200000,0.19753222,631.04932142,0.00000000,0.00000000,0.00000000,0.00000000,0.00000000,0.00000000,0.00000000,0.00000000,0.00000000,0.00000000,0.00000000
245.11000000,5.80940200,9.53100000,0.19948178,630.98311817,0.00000000,0.00000000,0.00000000,0.00000000,0.00000000,0.00000000,0.00000000,0.00000000,0.00000000,0.00000000,0.00000000
246.61000000,5.86045000,9.53100000,0.20150478,630.98311817,0.00000000,0.00000000,0.00000000,0.00000000,0.00000000,0.00000000,0.00000000,0.00000000,0.00000000,0.00000000,0.00000000
248.11000000,5.91202900,9.53100000,0.20356467,630.98311817,0.00000000,0.00000000,0.00000000,0.00000000,0.00000000,0.00000000,0.00000000,0.00000000,0.00000000,0.00000000,0.00000000
249.61000000,5.96383900,9.53100000,0.20558778,630.98311817,0.00000000,0.00000000,0.00000000,0.00000000,0.00000000,0.00000000,0.00000000,0.00000000,0.00000000,0.00000000,0.00000000
251.11000000,6.01584800,9.53000000,0.20764778,630.91691493,0.00000000,0.00000000,0.00000000,0.00000000,0.00000000,0.00000000,0.00000000,0.00000000,0.00000000,0.00000000,0.00000000
252.61000000,6.06742700,9.52900000,0.20974444,630.85071168,0.00000000,0.00000000,0.00000000,0.00000000,0.00000000,0.00000000,0.00000000,0.00000000,0.00000000,0.00000000,0.00000000
254.11000000,6.11963500,9.52800000,0.21187789,630.78450844,0.00000000,0.00000000,0.00000000,0.00000000,0.00000000,0.00000000,0.00000000,0.00000000,0.00000000,0.00000000,0.00000000
255.61000000,6.17223900,9.52700000,0.21408511,630.71830520,0.00000000,0.00000000,0.00000000,0.00000000,0.00000000,0.00000000,0.00000000,0.00000000,0.00000000,0.00000000,0.00000000
257.11000000,6.22527600,9.52700000,0.21629189,630.71830520,0.00000000,0.00000000,0.00000000,0.00000000,0.00000000,0.00000000,0.00000000,0.00000000,0.00000000,0.00000000,0.00000000
258.61000000,6.27854200,9.52400000,0.21846211,630.51969547,0.00000000,0.00000000,0.00000000,0.00000000,0.00000000,0.00000000,0.00000000,0.00000000,0.00000000,0.00000000,0.00000000
260.11000000,6.33243700,9.52300000,0.22077956,630.45349222,0.00000000,0.00000000,0.00000000,0.00000000,0.00000000,0.00000000,0.00000000,0.00000000,0.00000000,0.00000000,0.00000000
261.61000000,6.38636600,9.52200000,0.22313378,630.38728898,0.00000000,0.00000000,0.00000000,0.00000000,0.00000000,0.00000000,0.00000000,0.00000000,0.00000000,0.00000000,0.00000000
263.11000000,6.44023000,9.52000000,0.22548800,630.25488249,0.00000000,0.00000000,0.00000000,0.00000000,0.00000000,0.00000000,0.00000000,0.00000000,0.00000000,0.00000000,0.00000000
264.61000000,6.49406000,9.51800000,0.22784200,630.12247600,0.00000000,0.00000000,0.00000000,0.00000000,0.00000000,0.00000000,0.00000000,0.00000000,0.00000000,0.00000000,0.00000000
266.11000000,6.54874900,9.51600000,0.23030656,629.99006951,0.00000000,0.00000000,0.00000000,0.00000000,0.00000000,0.00000000,0.00000000,0.00000000,0.00000000,0.00000000,0.00000000
267.61000000,6.60400200,9.51400000,0.23291822,629.85766303,0.00000000,0.00000000,0.00000000,0.00000000,0.00000000,0.00000000,0.00000000,0.00000000,0.00000000,0.00000000,0.00000000
269.11000000,6.65872600,9.51200000,0.23541956,629.72525654,0.00000000,0.00000000,0.00000000,0.00000000,0.00000000,0.00000000,0.00000000,0.00000000,0.00000000,0.00000000,0.00000000
270.61000000,6.71434400,9.50900000,0.23810478,629.52664681,0.00000000,0.00000000,0.00000000,0.00000000,0.00000000,0.00000000,0.00000000,0.00000000,0.00000000,0.00000000,0.00000000
272.11000000,6.76962900,9.50600000,0.24075322,629.32803707,0.00000000,0.00000000,0.00000000,0.00000000,0.00000000,0.00000000,0.00000000,0.00000000,0.00000000,0.00000000,0.00000000
273.61000000,6.82534500,9.50300000,0.24358556,629.12942734,0.00000000,0.00000000,0.00000000,0.00000000,0.00000000,0.00000000,0.00000000,0.00000000,0.00000000,0.00000000,0.00000000
275.11000000,6.88162300,9.50100000,0.24638111,628.99702085,0.00000000,0.00000000,0.00000000,0.00000000,0.00000000,0.00000000,0.00000000,0.00000000,0.00000000,0.00000000,0.00000000
276.61000000,6.93760600,9.49800000,0.24928700,628.79841112,0.00000000,0.00000000,0.00000000,0.00000000,0.00000000,0.00000000,0.00000000,0.00000000,0.00000000,0.00000000,0.00000000
278.11000000,6.99411700,9.49400000,0.25230322,628.53359815,0.00000000,0.00000000,0.00000000,0.00000000,0.00000000,0.00000000,0.00000000,0.00000000,0.00000000,0.00000000,0.00000000
279.61000000,7.05095900,9.49100000,0.25531956,628.33498841,0.00000000,0.00000000,0.00000000,0.00000000,0.00000000,0.00000000,0.00000000,0.00000000,0.00000000,0.00000000,0.00000000
281.11000000,7.10833100,9.48700000,0.25859333,628.07017544,0.00000000,0.00000000,0.00000000,0.00000000,0.00000000,0.00000000,0.00000000,0.00000000,0.00000000,0.00000000,0.00000000
282.61000000,7.16556900,9.48400000,0.26183033,627.87156571,0.00000000,0.00000000,0.00000000,0.00000000,0.00000000,0.00000000,0.00000000,0.00000000,0.00000000,0.00000000,0.00000000
284.11000000,7.22297400,9.47800000,0.26521433,627.47434624,0.00000000,0.00000000,0.00000000,0.00000000,0.00000000,0.00000000,0.00000000,0.00000000,0.00000000,0.00000000,0.00000000
285.61000000,7.28031300,9.47400000,0.26870878,627.20953327,0.00000000,0.00000000,0.00000000,0.00000000,0.00000000,0.00000000,0.00000000,0.00000000,0.00000000,0.00000000,0.00000000
287.11000000,7.33804800,9.46900000,0.27223989,626.87851705,0.00000000,0.00000000,0.00000000,0.00000000,0.00000000,0.00000000,0.00000000,0.00000000,0.00000000,0.00000000,0.00000000
288.61000000,7.39634600,9.46400000,0.27606544,626.54750083,0.00000000,0.00000000,0.00000000,0.00000000,0.00000000,0.00000000,0.00000000,0.00000000,0.00000000,0.00000000,0.00000000
290.11000000,7.45487600,9.45800000,0.27996444,626.15028136,0.00000000,0.00000000,0.00000000,0.00000000,0.00000000,0.00000000,0.00000000,0.00000000,0.00000000,0.00000000,0.00000000
291.61000000,7.51347300,9.45300000,0.28401067,625.81926514,0.00000000,0.00000000,0.00000000,0.00000000,0.00000000,0.00000000,0.00000000,0.00000000,0.00000000,0.00000000,0.00000000
293.11000000,7.57200300,9.44600000,0.28820411,625.35584244,0.00000000,0.00000000,0.00000000,0.00000000,0.00000000,0.00000000,0.00000000,0.00000000,0.00000000,0.00000000,0.00000000
294.61000000,7.63086500,9.43900000,0.29258133,624.89241973,0.00000000,0.00000000,0.00000000,0.00000000,0.00000000,0.00000000,0.00000000,0.00000000,0.00000000,0.00000000,0.00000000
296.11000000,7.68995700,9.43100000,0.29710567,624.36279378,0.00000000,0.00000000,0.00000000,0.00000000,0.00000000,0.00000000,0.00000000,0.00000000,0.00000000,0.00000000,0.00000000
297.61000000,7.74904900,9.42300000,0.30185067,623.83316783,0.00000000,0.00000000,0.00000000,0.00000000,0.00000000,0.00000000,0.00000000,0.00000000,0.00000000,0.00000000,0.00000000
299.11000000,7.80880400,9.41400000,0.30677967,623.23733863,0.00000000,0.00000000,0.00000000,0.00000000,0.00000000,0.00000000,0.00000000,0.00000000,0.00000000,0.00000000,0.00000000
300.61000000,7.86932000,9.40600000,0.31192933,622.70771268,0.00000000,0.00000000,0.00000000,0.00000000,0.00000000,0.00000000,0.00000000,0.00000000,0.00000000,0.00000000,0.00000000
302.11000000,7.92927300,9.39400000,0.31733644,621.91327375,0.00000000,0.00000000,0.00000000,0.00000000,0.00000000,0.00000000,0.00000000,0.00000000,0.00000000,0.00000000,0.00000000
303.61000000,7.98952500,9.38300000,0.32281722,621.18503807,0.00000000,0.00000000,0.00000000,0.00000000,0.00000000,0.00000000,0.00000000,0.00000000,0.00000000,0.00000000,0.00000000
305.11000000,8.04990800,9.37000000,0.32855544,620.32439590,0.00000000,0.00000000,0.00000000,0.00000000,0.00000000,0.00000000,0.00000000,0.00000000,0.00000000,0.00000000,0.00000000
306.61000000,8.11055700,9.35600000,0.33447756,619.39755048,0.00000000,0.00000000,0.00000000,0.00000000,0.00000000,0.00000000,0.00000000,0.00000000,0.00000000,0.00000000,0.00000000
308.11000000,8.17087400,9.34000000,0.34047333,618.33829858,0.00000000,0.00000000,0.00000000,0.00000000,0.00000000,0.00000000,0.00000000,0.00000000,0.00000000,0.00000000,0.00000000
309.61000000,8.23179000,9.32500000,0.34668978,617.34524992,0.00000000,0.00000000,0.00000000,0.00000000,0.00000000,0.00000000,0.00000000,0.00000000,0.00000000,0.00000000,0.00000000
311.11000000,8.29296800,9.30800000,0.35309011,616.21979477,0.00000000,0.00000000,0.00000000,0.00000000,0.00000000,0.00000000,0.00000000,0.00000000,0.00000000,0.00000000,0.00000000
312.61000000,8.35431200,9.28900000,0.35960078,614.96193313,0.00000000,0.00000000,0.00000000,0.00000000,0.00000000,0.00000000,0.00000000,0.00000000,0.00000000,0.00000000,0.00000000
314.11000000,8.41625200,9.26600000,0.36618522,613.43925852,0.00000000,0.00000000,0.00000000,0.00000000,0.00000000,0.00000000,0.00000000,0.00000000,0.00000000,0.00000000,0.00000000
315.61000000,8.47719800,9.24400000,0.37287967,611.98278716,0.00000000,0.00000000,0.00000000,0.00000000,0.00000000,0.00000000,0.00000000,0.00000000,0.00000000,0.00000000,0.00000000
317.11000000,8.53857500,9.21800000,0.37953756,610.26150281,0.00000000,0.00000000,0.00000000,0.00000000,0.00000000,0.00000000,0.00000000,0.00000000,0.00000000,0.00000000,0.00000000
318.61000000,8.60048300,9.19300000,0.38634267,608.60642171,0.00000000,0.00000000,0.00000000,0.00000000,0.00000000,0.00000000,0.00000000,0.00000000,0.00000000,0.00000000,0.00000000
320.11000000,8.66222400,9.16500000,0.39325800,606.75273088,0.00000000,0.00000000,0.00000000,0.00000000,0.00000000,0.00000000,0.00000000,0.00000000,0.00000000,0.00000000,0.00000000
321.61000000,8.72416400,9.13700000,0.40013644,604.89904005,0.00000000,0.00000000,0.00000000,0.00000000,0.00000000,0.00000000,0.00000000,0.00000000,0.00000000,0.00000000,0.00000000
323.11000000,8.78600400,9.09900000,0.40697822,602.38331678,0.00000000,0.00000000,0.00000000,0.00000000,0.00000000,0.00000000,0.00000000,0.00000000,0.00000000,0.00000000,0.00000000
324.61000000,8.84837400,9.06400000,0.41393044,600.06620324,0.00000000,0.00000000,0.00000000,0.00000000,0.00000000,0.00000000,0.00000000,0.00000000,0.00000000,0.00000000,0.00000000
326.11000000,8.91084500,9.02200000,0.42088256,597.28566700,0.00000000,0.00000000,0.00000000,0.00000000,0.00000000,0.00000000,0.00000000,0.00000000,0.00000000,0.00000000,0.00000000
327.61000000,8.97361100,8.98300000,0.42794500,594.70374048,0.00000000,0.00000000,0.00000000,0.00000000,0.00000000,0.00000000,0.00000000,0.00000000,0.00000000,0.00000000,0.00000000
329.11000000,9.03611400,8.93400000,0.43497056,591.45978153,0.00000000,0.00000000,0.00000000,0.00000000,0.00000000,0.00000000,0.00000000,0.00000000,0.00000000,0.00000000,0.00000000
330.61000000,9.09957600,8.88500000,0.44199611,588.21582258,0.00000000,0.00000000,0.00000000,0.00000000,0.00000000,0.00000000,0.00000000,0.00000000,0.00000000,0.00000000,0.00000000
332.11000000,9.16353300,8.82500000,0.44920544,584.24362794,0.00000000,0.00000000,0.00000000,0.00000000,0.00000000,0.00000000,0.00000000,0.00000000,0.00000000,0.00000000,0.00000000
333.61000000,9.22788900,8.76300000,0.45637800,580.13902681,0.00000000,0.00000000,0.00000000,0.00000000,0.00000000,0.00000000,0.00000000,0.00000000,0.00000000,0.00000000,0.00000000
335.11000000,9.29230800,8.68800000,0.46366078,575.17378352,0.00000000,0.00000000,0.00000000,0.00000000,0.00000000,0.00000000,0.00000000,0.00000000,0.00000000,0.00000000,0.00000000
336.61000000,9.35702500,8.61500000,0.47094356,570.34094671,0.00000000,0.00000000,0.00000000,0.00000000,0.00000000,0.00000000,0.00000000,0.00000000,0.00000000,0.00000000,0.00000000
338.11000000,9.42343000,8.52100000,0.47844678,564.11784177,0.00000000,0.00000000,0.00000000,0.00000000,0.00000000,0.00000000,0.00000000,0.00000000,0.00000000,0.00000000,0.00000000
339.61000000,9.49036200,8.41800000,0.48609700,557.29890765,0.00000000,0.00000000,0.00000000,0.00000000,0.00000000,0.00000000,0.00000000,0.00000000,0.00000000,0.00000000,0.00000000
341.11000000,9.55914600,8.28600000,0.49385744,548.56007944,0.00000000,0.00000000,0.00000000,0.00000000,0.00000000,0.00000000,0.00000000,0.00000000,0.00000000,0.00000000,0.00000000
342.61000000,9.63054300,8.14000000,0.50202244,538.89440583,0.00000000,0.00000000,0.00000000,0.00000000,0.00000000,0.00000000,0.00000000,0.00000000,0.00000000,0.00000000,0.00000000
344.11000000,9.70736800,7.93900000,0.51081256,525.58755379,0.00000000,0.00000000,0.00000000,0.00000000,0.00000000,0.00000000,0.00000000,0.00000000,0.00000000,0.00000000,0.00000000