File: polyN_optimization/results_exp/DP600/UT_30_2.csv
Time[s],Displacement[mm],Force[kN],EngStrain_longi,EngStress[MPa],TrueStrain,TrueStress[MPa],TrueStrainRate[1/s],PlasticStrain_longi,PlasticStress[MPa],PlasticStrain_thick,PlasticStrain_width,R-Value,Thickness[mm],Width[mm], Young's Modulus [MPa]
0.59000000,0.00000000,-0.01400000,0.00000000,-0.91629033,0.00000000,-0.91629033,0.00000000,0.00065963,327.58012095,-0.00012121,-0.00053842,0.89100402,1.52790000,10.00000000,212223.02648808
2.09000000,0.00218700,0.06800000,0.00009889,4.45055305,0.00009888,4.45099316,0.00005022,0.00099198,342.60848137,-0.00030261,-0.00068936,0.00000000,0.00000000,0.00000000,0.00000000
3.59000000,0.00483300,0.43200000,0.00017800,28.27410171,0.00017798,28.27913450,0.00006199,0.00138731,358.26339370,-0.00037072,-0.00101658,0.00000000,0.00000000,0.00000000,0.00000000
5.09000000,0.00851500,0.79900000,0.00027622,52.29399830,0.00027618,52.30844306,0.00016685,0.00193139,371.15891201,-0.00053477,-0.00139663,0.00000000,0.00000000,0.00000000,0.00000000
6.59000000,0.01140100,1.11300000,0.00035456,72.84508148,0.00035449,72.87090911,0.00018461,0.00264208,383.60715154,-0.00094023,-0.00170185,0.00000000,0.00000000,0.00000000,0.00000000
8.09000000,0.01311600,1.48300000,0.00042667,97.06132600,0.00042658,97.10273884,0.00008530,0.00343535,393.14066984,-0.00139437,-0.00204098,0.00000000,0.00000000,0.00000000,0.00000000
9.59000000,0.01523800,1.79800000,0.00049322,117.67785850,0.00049310,117.73589983,0.00002776,0.00416420,403.78554007,-0.00181721,-0.00234699,0.00000000,0.00000000,0.00000000,0.00000000
11.09000000,0.01794600,2.18700000,0.00058489,143.13763990,0.00058472,143.22135951,-0.00009261,0.00496797,411.57238995,-0.00222316,-0.00274481,0.00000000,0.00000000,0.00000000,0.00000000
12.59000000,0.02143600,2.49900000,0.00070733,163.55782446,0.00070708,163.67351437,-0.00014700,0.00585893,420.06969927,-0.00271960,-0.00313933,0.00000000,0.00000000,0.00000000,0.00000000
14.09000000,0.02525600,2.88600000,0.00085044,188.88670725,0.00085008,189.04734490,-0.00003020,0.00682631,427.62283867,-0.00321363,-0.00361268,0.00000000,0.00000000,0.00000000,0.00000000
15.59000000,0.02861300,3.19500000,0.00104022,209.11054388,0.00103968,209.32806532,0.00032702,0.00770855,435.28607823,-0.00365682,-0.00405173,0.00000000,0.00000000,0.00000000,0.00000000
17.09000000,0.03170500,3.54700000,0.00114033,232.14870083,0.00113968,232.41342773,0.00042112,0.00854166,441.61547504,-0.00405346,-0.00448820,0.00000000,0.00000000,0.00000000,0.00000000
18.59000000,0.03541300,3.84400000,0.00118844,251.58714576,0.00118774,251.88614310,0.00032830,0.00942309,449.10517702,-0.00453474,-0.00488835,0.00000000,0.00000000,0.00000000,0.00000000
20.09000000,0.04058800,4.20700000,0.00127278,275.34524511,0.00127197,275.69569842,0.00016180,0.01044159,455.07682830,-0.00514941,-0.00529218,0.00000000,0.00000000,0.00000000,0.00000000
21.59000000,0.04787300,4.48400000,0.00143100,293.47470384,0.00142998,293.89466614,-0.00002929,0.01135440,461.67657099,-0.00564391,-0.00571049,0.00000000,0.00000000,0.00000000,0.00000000
23.09000000,0.05671500,4.81200000,0.00174378,314.94207736,0.00174226,315.49126636,-0.00011735,0.01228384,467.63066966,-0.00614276,-0.00614109,0.00000000,0.00000000,0.00000000,0.00000000
24.59000000,0.06741200,5.05300000,0.00219633,330.71536095,0.00219392,331.44172212,-0.00005122,0.01317121,473.84227680,-0.00655627,-0.00661494,0.00000000,0.00000000,0.00000000,0.00000000
26.09000000,0.08171900,5.30900000,0.00275200,347.47038419,0.00274822,348.42662268,0.00024955,0.01417507,478.98727717,-0.00704702,-0.00712806,0.00000000,0.00000000,0.00000000,0.00000000
27.59000000,0.09851300,5.50400000,0.00328589,360.23299954,0.00328050,361.41668515,0.00037436,0.01518323,485.27935912,-0.00759764,-0.00758559,0.00000000,0.00000000,0.00000000,0.00000000
29.09000000,0.11722800,5.71900000,0.00390822,374.30460109,0.00390060,375.76746665,0.00040357,0.01611759,490.14434708,-0.00806280,-0.00805478,0.00000000,0.00000000,0.00000000,0.00000000
30.59000000,0.14130800,5.87100000,0.00461878,384.25289613,0.00460814,386.02767487,0.00027873,0.01707378,495.56419587,-0.00858277,-0.00849101,0.00000000,0.00000000,0.00000000,0.00000000
32.09000000,0.16502500,6.04000000,0.00548367,395.31382944,0.00546869,397.48159871,0.00032248,0.01808168,500.48451647,-0.00915016,-0.00893151,0.00000000,0.00000000,0.00000000,0.00000000
33.59000000,0.19096000,6.16100000,0.00640733,403.23319589,0.00638689,405.81684539,0.00059980,0.01915196,505.71424232,-0.00972934,-0.00942262,0.00000000,0.00000000,0.00000000,0.00000000
35.09000000,0.21632800,6.28900000,0.00723156,411.61070751,0.00720553,414.58729321,0.00055539,0.02016035,510.11785806,-0.01026081,-0.00989954,0.00000000,0.00000000,0.00000000,0.00000000
36.59000000,0.24606500,6.39300000,0.00809256,418.41743570,0.00805999,421.80350204,0.00040146,0.02115320,515.26096400,-0.01073317,-0.01042002,0.00000000,0.00000000,0.00000000,0.00000000
38.09000000,0.27235900,6.51600000,0.00905667,426.46770077,0.00901590,430.33007658,0.00030658,0.02220014,519.36624651,-0.01125979,-0.01094035,0.00000000,0.00000000,0.00000000,0.00000000
39.59000000,0.30166300,6.60900000,0.01007589,432.55448655,0.01002547,436.91285750,0.00048825,0.02326001,524.29440224,-0.01180607,-0.01145394,0.00000000,0.00000000,0.00000000,0.00000000
41.09000000,0.32991000,6.72000000,0.01101056,439.81935991,0.01095038,444.66201540,0.00061158,0.02428419,528.20276772,-0.01233373,-0.01195046,0.00000000,0.00000000,0.00000000,0.00000000
42.59000000,0.35875100,6.80400000,0.01187533,445.31710190,0.01180537,450.60539093,0.00048738,0.02532624,532.60055728,-0.01288185,-0.01244439,0.00000000,0.00000000,0.00000000,0.00000000
44.09000000,0.38696600,6.90000000,0.01285411,451.60023562,0.01277220,457.40515522,0.00032716,0.02638863,536.27509450,-0.01346795,-0.01292069,0.00000000,0.00000000,0.00000000,0.00000000
45.59000000,0.41805900,6.97900000,0.01389533,456.77073107,0.01379968,463.11771263,0.00049365,0.02746404,540.70782459,-0.01406306,-0.01340097,0.00000000,0.00000000,0.00000000,0.00000000
47.09000000,0.44690100,7.07300000,0.01492544,462.92296616,0.01481516,469.83229718,0.00060900,0.02853852,544.33681730,-0.01462576,-0.01391275,0.00000000,0.00000000,0.00000000,0.00000000
48.59000000,0.47749500,7.14700000,0.01588933,467.76621507,0.01576442,475.19870838,0.00067363,0.02960909,548.51312171,-0.01520222,-0.01440687,0.00000000,0.00000000,0.00000000,0.00000000
50.09000000,0.50772700,7.23500000,0.01686800,473.52575430,0.01672732,481.51318673,0.00054270,0.03069313,551.89123131,-0.01577608,-0.01491705,0.00000000,0.00000000,0.00000000,0.00000000
51.59000000,0.53808900,7.30300000,0.01794956,477.97630735,0.01779036,486.55576963,0.00059256,0.03178096,555.68576708,-0.01632572,-0.01545525,0.00000000,0.00000000,0.00000000,0.00000000
53.09000000,0.56974200,7.37900000,0.01902767,482.95045487,0.01884890,492.13987514,0.00079460,0.03285290,558.86716271,-0.01685908,-0.01599382,0.00000000,0.00000000,0.00000000,0.00000000
54.59000000,0.60023700,7.44100000,0.02002467,487.00831206,0.01982681,496.76049118,0.00078641,0.03400853,562.78277950,-0.01751239,-0.01649615,0.00000000,0.00000000,0.00000000,0.00000000
56.09000000,0.63205600,7.51700000,0.02105100,491.98245959,0.02083249,502.33918234,0.00073511,0.03511734,565.86237810,-0.01813427,-0.01698307,0.00000000,0.00000000,0.00000000,0.00000000
57.59000000,0.66367700,7.57700000,0.02211422,495.90941816,0.02187325,506.87606923,0.00062625,0.03620544,569.34577974,-0.01870862,-0.01749682,0.00000000,0.00000000,0.00000000,0.00000000
59.09000000,0.69599400,7.64800000,0.02322544,500.55631913,0.02295984,512.18196211,0.00074071,0.03728283,572.55683196,-0.01930138,-0.01798145,0.00000000,0.00000000,0.00000000,0.00000000
60.59000000,0.72811100,7.70200000,0.02430700,504.09058184,0.02401629,516.34351162,0.00081893,0.03845375,575.89663047,-0.01997300,-0.01848074,0.00000000,0.00000000,0.00000000,0.00000000
62.09000000,0.76039400,7.76400000,0.02535189,508.14843903,0.02503586,521.03096180,0.00072509,0.03954074,578.78403363,-0.02054416,-0.01899658,0.00000000,0.00000000,0.00000000,0.00000000
63.59000000,0.79257700,7.82000000,0.02643700,511.81360037,0.02609358,525.34441652,0.00067386,0.04063505,582.09263797,-0.02110697,-0.01952807,0.00000000,0.00000000,0.00000000,0.00000000
65.09000000,0.82529000,7.87700000,0.02753700,515.54421101,0.02716468,529.74075195,0.00073047,0.04172742,584.85780130,-0.02167405,-0.02005337,0.00000000,0.00000000,0.00000000,0.00000000
66.59000000,0.85856400,7.92500000,0.02862589,518.68577787,0.02822382,533.53361931,0.00072278,0.04289027,588.01342741,-0.02229701,-0.02059326,0.00000000,0.00000000,0.00000000,0.00000000
68.09000000,0.89177200,7.98300000,0.02973678,522.48183782,0.02930321,538.01876412,0.00072178,0.04404266,590.89436161,-0.02289757,-0.02114509,0.00000000,0.00000000,0.00000000,0.00000000
69.59000000,0.92534500,8.02800000,0.03086622,525.42705674,0.03039944,541.64500504,0.00072121,0.04513378,593.81361095,-0.02343036,-0.02170342,0.00000000,0.00000000,0.00000000,0.00000000
71.09000000,0.95914900,8.08000000,0.03201011,528.83042084,0.03150846,545.75834137,0.00075573,0.04626031,596.41510884,-0.02399040,-0.02226991,0.00000000,0.00000000,0.00000000,0.00000000
72.59000000,0.99278700,8.12500000,0.03313589,531.77563977,0.03259873,549.39649828,0.00075534,0.04742919,599.39232860,-0.02463703,-0.02279216,0.00000000,0.00000000,0.00000000,0.00000000
74.09000000,1.02649100,8.17300000,0.03427978,534.91720662,0.03370532,553.25404960,0.00076826,0.04860925,601.96790052,-0.02525381,-0.02335544,0.00000000,0.00000000,0.00000000,0.00000000
75.59000000,1.06059200,8.21300000,0.03544967,537.53517900,0.03483579,556.59062192,0.00081742,0.04973129,604.65197388,-0.02584406,-0.02388723,0.00000000,0.00000000,0.00000000,0.00000000
77.09000000,1.09502500,8.26100000,0.03657533,540.67674586,0.03592233,560.45217807,0.00081632,0.05092228,607.24484912,-0.02649681,-0.02442547,0.00000000,0.00000000,0.00000000,0.00000000
78.59000000,1.12899300,8.29900000,0.03772300,543.16381962,0.03702889,563.65358839,0.00068088,0.05212154,609.98686225,-0.02713607,-0.02498546,0.00000000,0.00000000,0.00000000,0.00000000
80.09000000,1.16398900,8.34100000,0.03887800,545.91269062,0.03814128,567.13668421,0.00065872,0.05327634,612.29073098,-0.02776041,-0.02551593,0.00000000,0.00000000,0.00000000,0.00000000
81.59000000,1.19848900,8.37600000,0.04007000,548.20341645,0.03928802,570.16992735,0.00074282,0.05440698,615.00134753,-0.02835756,-0.02604942,0.00000000,0.00000000,0.00000000,0.00000000
83.09000000,1.23371600,8.42000000,0.04120300,551.08318607,0.04037678,573.78946659,0.00073497,0.05557298,617.25210485,-0.02897177,-0.02660121,0.00000000,0.00000000,0.00000000,0.00000000
84.59000000,1.26881000,8.45200000,0.04233600,553.17756398,0.04146435,576.59688933,0.00053647,0.05676401,619.80160867,-0.02960565,-0.02715837,0.00000000,0.00000000,0.00000000,0.00000000
86.09000000,1.30347500,8.49300000,0.04354978,555.86098567,0.04262815,580.06860807,0.00066259,0.05790277,622.11445007,-0.03017905,-0.02772373,0.00000000,0.00000000,0.00000000,0.00000000
87.59000000,1.33913200,8.52400000,0.04475644,557.88991426,0.04378379,582.85908322,0.00075375,0.05907109,624.52016970,-0.03080070,-0.02827040,0.00000000,0.00000000,0.00000000,0.00000000
89.09000000,1.37462400,8.56000000,0.04590422,560.24608940,0.04488180,585.96375039,0.00073868,0.06025318,626.58972250,-0.03140374,-0.02884944,0.00000000,0.00000000,0.00000000,0.00000000
90.59000000,1.41021600,8.59100000,0.04711078,562.27501800,0.04603473,588.76423142,0.00068879,0.06144223,629.08781412,-0.03200508,-0.02943715,0.00000000,0.00000000,0.00000000,0.00000000
92.09000000,1.44670000,8.62600000,0.04836133,564.56574383,0.04722831,591.86889596,0.00074373,0.06262487,631.16635853,-0.03263757,-0.02998730,0.00000000,0.00000000,0.00000000,0.00000000
93.59000000,1.48248900,8.65400000,0.04960844,566.39832450,0.04841718,594.49646431,0.00091145,0.06379293,633.16954126,-0.03322468,-0.03056825,0.00000000,0.00000000,0.00000000,0.00000000
95.09000000,1.51894100,8.68900000,0.05078556,568.68905033,0.04953803,597.57023969,0.00087530,0.06497490,635.53677597,-0.03384802,-0.03112688,0.00000000,0.00000000,0.00000000,0.00000000
96.59000000,1.55516300,8.71600000,0.05198844,570.45618169,0.05068213,600.11331120,0.00079738,0.06617767,637.57031677,-0.03448644,-0.03169124,0.00000000,0.00000000,0.00000000,0.00000000
98.09000000,1.59148100,8.74600000,0.05326133,572.41966097,0.05189138,602.90749534,0.00083124,0.06736445,639.73848928,-0.03511057,-0.03225389,0.00000000,0.00000000,0.00000000,0.00000000
99.59000000,1.62829700,8.77200000,0.05447533,574.12134302,0.05304333,605.39679455,0.00086549,0.06857425,641.85524927,-0.03577778,-0.03279647,0.00000000,0.00000000,0.00000000,0.00000000
101.09000000,1.66561000,8.80300000,0.05568922,576.15027161,0.05419384,608.23563212,0.00075984,0.06977249,643.89815296,-0.03639082,-0.03338166,0.00000000,0.00000000,0.00000000,0.00000000
102.59000000,1.70226000,8.82700000,0.05691789,577.72105504,0.05535702,610.60371786,0.00066157,0.07097012,645.80329038,-0.03702459,-0.03394553,0.00000000,0.00000000,0.00000000,0.00000000
104.09000000,1.73947200,8.85600000,0.05818700,579.61908502,0.05655707,613.34538072,0.00073010,0.07216169,647.92050402,-0.03764040,-0.03452128,0.00000000,0.00000000,0.00000000,0.00000000
105.59000000,1.77625600,8.87900000,0.05942300,581.12441914,0.05772442,615.65657550,0.00077772,0.07337322,649.84230198,-0.03825173,-0.03512149,0.00000000,0.00000000,0.00000000,0.00000000
107.09000000,1.81326900,8.90400000,0.06063322,582.76065188,0.05886611,618.09530798,0.00070767,0.07459330,651.77342456,-0.03891206,-0.03568124,0.00000000,0.00000000,0.00000000,0.00000000
108.59000000,1.85094500,8.92600000,0.06191333,584.20053668,0.06007231,620.37033925,0.00071372,0.07580531,653.70303219,-0.03952466,-0.03628064,0.00000000,0.00000000,0.00000000,0.00000000
110.09000000,1.88845500,8.95200000,0.06318978,585.90221873,0.06127361,622.92524973,0.00081679,0.07699850,655.69515322,-0.04016480,-0.03683370,0.00000000,0.00000000,0.00000000,0.00000000
111.59000000,1.92619700,8.97300000,0.06445156,587.27665423,0.06245970,625.12754814,0.00082939,0.07820844,657.41730640,-0.04080817,-0.03740026,0.00000000,0.00000000,0.00000000,0.00000000
113.09000000,1.96354200,8.99800000,0.06572433,588.91288697,0.06365469,627.61879386,0.00083550,0.07943606,659.36830857,-0.04145560,-0.03798046,0.00000000,0.00000000,0.00000000,0.00000000
114.59000000,2.00187900,9.01700000,0.06701544,590.15642385,0.06486545,629.70601889,0.00085511,0.08063973,661.09307246,-0.04209656,-0.03854317,0.00000000,0.00000000,0.00000000,0.00000000
116.09000000,2.03985400,9.03700000,0.06826622,591.46541004,0.06603698,631.84251916,0.00081311,0.08188464,663.06294136,-0.04274885,-0.03913580,0.00000000,0.00000000,0.00000000,0.00000000
117.59000000,2.07772800,9.05900000,0.06952067,592.90529485,0.06721057,634.12446622,0.00080509,0.08313249,664.75237661,-0.04342170,-0.03971079,0.00000000,0.00000000,0.00000000,0.00000000
119.09000000,2.11566900,9.07800000,0.07082278,594.14883173,0.06842730,636.22810241,0.00085207,0.08437482,666.58466539,-0.04408301,-0.04029181,0.00000000,0.00000000,0.00000000,0.00000000
120.59000000,2.15427200,9.09700000,0.07209189,595.39236861,0.06961178,638.31532909,0.00079611,0.08563007,668.21390968,-0.04476344,-0.04086663,0.00000000,0.00000000,0.00000000,0.00000000
122.09000000,2.19257600,9.11600000,0.07337556,596.63590549,0.07080841,640.41439652,0.00079516,0.08684586,670.03522895,-0.04538731,-0.04145855,0.00000000,0.00000000,0.00000000,0.00000000
123.59000000,2.23121100,9.13500000,0.07467044,597.87944237,0.07201405,642.52336606,0.00076669,0.08811096,671.74938587,-0.04605883,-0.04205213,0.00000000,0.00000000,0.00000000,0.00000000
125.09000000,2.26997900,9.15200000,0.07598378,598.99208063,0.07323539,644.50576178,0.00079344,0.08938408,673.54428446,-0.04672420,-0.04265989,0.00000000,0.00000000,0.00000000,0.00000000
126.59000000,2.30878000,9.17100000,0.07728589,600.23561751,0.07444481,646.62536076,0.00079887,0.09061367,675.02471671,-0.04735717,-0.04325650,0.00000000,0.00000000,0.00000000,0.00000000
128.09000000,2.34751400,9.18700000,0.07857700,601.28280647,0.07564258,648.52980555,0.00079112,0.09187026,676.81496285,-0.04803571,-0.04383455,0.00000000,0.00000000,0.00000000,0.00000000
129.59000000,2.38687800,9.20300000,0.07989400,602.32999542,0.07686289,650.45254807,0.00079036,0.09309917,678.44522547,-0.04864496,-0.04445421,0.00000000,0.00000000,0.00000000,0.00000000
131.09000000,2.42561400,9.21900000,0.08121078,603.37718437,0.07808150,652.37791481,0.00076904,0.09439998,680.12755034,-0.04935743,-0.04504254,0.00000000,0.00000000,0.00000000,0.00000000
132.59000000,2.46514200,9.23600000,0.08252400,604.48982263,0.07929535,654.37474076,0.00075435,0.09565641,681.63780122,-0.05000364,-0.04565277,0.00000000,0.00000000,0.00000000,0.00000000
134.09000000,2.50503600,9.25100000,0.08385200,605.47156228,0.08052136,656.24156371,0.00080101,0.09692729,683.30585408,-0.05066565,-0.04626164,0.00000000,0.00000000,0.00000000,0.00000000
135.59000000,2.54440000,9.26700000,0.08519456,606.51875123,0.08175928,658.19084667,0.00084058,0.09818711,684.82412070,-0.05136311,-0.04682400,0.00000000,0.00000000,0.00000000,0.00000000
137.09000000,2.58426100,9.28100000,0.08652256,607.43504156,0.08298228,659.99187369,0.00081275,0.09945506,686.42351876,-0.05205380,-0.04740126,0.00000000,0.00000000,0.00000000,0.00000000
138.59000000,2.62422000,9.29400000,0.08786889,608.28588258,0.08422063,661.73528721,0.00086569,0.10068180,687.92458795,-0.05270957,-0.04797223,0.00000000,0.00000000,0.00000000,0.00000000
140.09000000,2.66404800,9.30800000,0.08922256,609.20217292,0.08546419,663.55674763,0.00084421,0.10199304,689.48677674,-0.05344073,-0.04855231,0.00000000,0.00000000,0.00000000,0.00000000
141.59000000,2.70413800,9.32200000,0.09058356,610.11846325,0.08671293,665.38516296,0.00082990,0.10325988,690.94806575,-0.05409896,-0.04916092,0.00000000,0.00000000,0.00000000,0.00000000
143.09000000,2.74496100,9.33500000,0.09194467,610.96930427,0.08796020,667.14467330,0.00082235,0.10453796,692.49292580,-0.05474890,-0.04978906,0.00000000,0.00000000,0.00000000,0.00000000
144.59000000,2.78511700,9.34800000,0.09331289,611.82014530,0.08921243,668.91085054,0.00080079,0.10580208,693.88442501,-0.05542379,-0.05037829,0.00000000,0.00000000,0.00000000,0.00000000
146.09000000,2.82583800,9.35900000,0.09468133,612.54008770,0.09046330,670.53619993,0.00085360,0.10711332,695.38455673,-0.05611541,-0.05099791,0.00000000,0.00000000,0.00000000,0.00000000
147.59000000,2.86649300,9.37200000,0.09607556,613.39092873,0.09173612,672.32280298,0.00085272,0.10841607,696.88152052,-0.05680108,-0.05161499,0.00000000,0.00000000,0.00000000,0.00000000
149.09000000,2.90780900,9.38400000,0.09741433,614.17632044,0.09295681,674.00589724,0.00073074,0.10971424,698.37800736,-0.05749093,-0.05222332,0.00000000,0.00000000,0.00000000,0.00000000
150.59000000,2.94783400,9.39500000,0.09885256,614.89626284,0.09426650,675.68032983,0.00087686,0.11098794,699.78641709,-0.05813270,-0.05285524,0.00000000,0.00000000,0.00000000,0.00000000
152.09000000,2.98948200,9.40600000,0.10023944,615.61620525,0.09552783,677.32523165,0.00086929,0.11227962,701.20995295,-0.05883162,-0.05344800,0.00000000,0.00000000,0.00000000,0.00000000
153.59000000,3.03076500,9.41700000,0.10162633,616.33614765,0.09678757,678.97213044,0.00091542,0.11356627,702.63246203,-0.05951775,-0.05404852,0.00000000,0.00000000,0.00000000,0.00000000
155.09000000,3.07191600,9.42700000,0.10304989,616.99064075,0.09807897,680.57145772,0.00088058,0.11489085,704.01037137,-0.06021824,-0.05467260,0.00000000,0.00000000,0.00000000,0.00000000
156.59000000,3.11313200,9.43800000,0.10444400,617.71058315,0.09934204,682.22674730,0.00087947,0.11619075,705.37325297,-0.06089906,-0.05529170,0.00000000,0.00000000,0.00000000,0.00000000
158.09000000,3.15497900,9.44700000,0.10582722,618.29962694,0.10059367,683.73255896,0.00082509,0.11749209,706.73951693,-0.06160068,-0.05589141,0.00000000,0.00000000,0.00000000,0.00000000
159.59000000,3.19629600,9.45800000,0.10723967,619.01956934,0.10187013,685.40302162,0.00084392,0.11881798,708.12560032,-0.06232264,-0.05649534,0.00000000,0.00000000,0.00000000,0.00000000
161.09000000,3.23840600,9.46600000,0.10862656,619.54316382,0.10312191,686.84200372,0.00079634,0.12016782,709.53118982,-0.06305020,-0.05711762,0.00000000,0.00000000,0.00000000,0.00000000
162.59000000,3.28005100,9.47500000,0.11002422,620.13220761,0.10438184,688.36177142,0.00084841,0.12147693,710.91023625,-0.06376628,-0.05771064,0.00000000,0.00000000,0.00000000,0.00000000
164.09000000,3.32189700,9.48400000,0.11149933,620.72125139,0.10570985,689.93125711,0.00086709,0.12278817,712.21871274,-0.06442616,-0.05836201,0.00000000,0.00000000,0.00000000,0.00000000
165.59000000,3.36394300,9.49400000,0.11294856,621.37574449,0.10701285,691.55923728,0.00092548,0.12412064,713.47000752,-0.06512350,-0.05899713,0.00000000,0.00000000,0.00000000,0.00000000
167.09000000,3.40644900,9.50100000,0.11439044,621.83388965,0.10830757,692.96574466,0.00094404,0.12540861,714.76617644,-0.06579243,-0.05961619,0.00000000,0.00000000,0.00000000,0.00000000
168.59000000,3.44875900,9.50900000,0.11579211,622.35748413,0.10956457,694.42157108,0.00091655,0.12677194,716.19346289,-0.06650012,-0.06027182,0.00000000,0.00000000,0.00000000,0.00000000
170.09000000,3.49060500,9.51700000,0.11721200,622.88107860,0.11083630,695.89021559,0.00082325,0.12813119,717.47057502,-0.06721325,-0.06091794,0.00000000,0.00000000,0.00000000,0.00000000
171.59000000,3.53347600,9.52500000,0.11867600,623.40467308,0.11214584,697.38784606,0.00082257,0.12946279,718.72990281,-0.06791626,-0.06154653,0.00000000,0.00000000,0.00000000,0.00000000
173.09000000,3.57591900,9.53200000,0.12010700,623.86281825,0.11342422,698.79310976,0.00076873,0.13082115,720.01066543,-0.06866615,-0.06215500,0.00000000,0.00000000,0.00000000,0.00000000
174.59000000,3.61898800,9.54000000,0.12157100,624.38641272,0.11473038,700.29369330,0.00082025,0.13222564,721.40219316,-0.06943139,-0.06279425,0.00000000,0.00000000,0.00000000,0.00000000
176.09000000,3.66159700,9.54600000,0.12301289,624.77910858,0.11601515,701.63499164,0.00079287,0.13357131,722.60292384,-0.07014851,-0.06342280,0.00000000,0.00000000,0.00000000,0.00000000
177.59000000,3.70555800,9.55200000,0.12450978,625.17180444,0.11734719,703.01180688,0.00087010,0.13492086,723.88383651,-0.07085085,-0.06407001,0.00000000,0.00000000,0.00000000,0.00000000
179.09000000,3.74879500,9.56000000,0.12602544,625.69539891,0.11869413,704.54893965,0.00090170,0.13629111,725.18195948,-0.07162498,-0.06466613,0.00000000,0.00000000,0.00000000,0.00000000
180.59000000,3.79183200,9.56600000,0.12750789,626.08809477,0.12000979,705.91926599,0.00092023,0.13765982,726.40554175,-0.07235164,-0.06530818,0.00000000,0.00000000,0.00000000,0.00000000
182.09000000,3.83520200,9.57100000,0.12898656,626.41534132,0.12132038,707.21449854,0.00092572,0.13902655,727.62967507,-0.07304537,-0.06598118,0.00000000,0.00000000,0.00000000,0.00000000
183.59000000,3.87909900,9.57700000,0.13048733,626.80803718,0.12264881,708.59854646,0.00091761,0.14042332,728.87778365,-0.07378917,-0.06663415,0.00000000,0.00000000,0.00000000,0.00000000
185.09000000,3.92306400,9.58200000,0.13194411,627.13528372,0.12393661,709.88209128,0.00078013,0.14181803,730.12645772,-0.07452262,-0.06729541,0.00000000,0.00000000,0.00000000,0.00000000
186.59000000,3.96620500,9.58800000,0.13344867,627.52797958,0.12526490,711.27075175,0.00080537,0.14321032,731.45148744,-0.07523738,-0.06797294,0.00000000,0.00000000,0.00000000,0.00000000
188.09000000,4.01096200,9.59400000,0.13495322,627.92067544,0.12659144,712.66059389,0.00082350,0.14463317,732.64894821,-0.07600766,-0.06862551,0.00000000,0.00000000,0.00000000,0.00000000
189.59000000,4.05539000,9.59800000,0.13649078,628.18247267,0.12794525,713.92358696,0.00085427,0.14605369,733.84663172,-0.07678008,-0.06927362,0.00000000,0.00000000,0.00000000,0.00000000
191.09000000,4.09955300,9.60400000,0.13804322,628.57516853,0.12931032,715.34571021,0.00099611,0.14747218,735.04474854,-0.07755803,-0.06991415,0.00000000,0.00000000,0.00000000,0.00000000
192.59000000,4.14408100,9.60700000,0.13956233,628.77151646,0.13064427,716.52433643,0.00092376,0.14888857,736.31973297,-0.07833083,-0.07055774,0.00000000,0.00000000,0.00000000,0.00000000
194.09000000,4.18824600,9.61200000,0.14109256,629.09876301,0.13198619,717.85991518,0.00087693,0.15036614,737.56554997,-0.07915241,-0.07121373,0.00000000,0.00000000,0.00000000,0.00000000
195.59000000,4.23340100,9.61700000,0.14268178,629.42600956,0.13337794,719.23363158,0.00098525,0.15174710,738.74182272,-0.07988378,-0.07186332,0.00000000,0.00000000,0.00000000,0.00000000
197.09000000,4.27872400,9.62100000,0.14418611,629.68780679,0.13469356,720.48004287,0.00088758,0.15322032,739.98846024,-0.08065818,-0.07256214,0.00000000,0.00000000,0.00000000,0.00000000
198.59000000,4.32344900,9.62500000,0.14574211,629.94960403,0.13605256,721.75978922,0.00078334,0.15469182,741.15895171,-0.08146029,-0.07323153,0.00000000,0.00000000,0.00000000,0.00000000
200.09000000,4.36860700,9.62800000,0.14736811,630.14595196,0.13747072,723.00937062,0.00091690,0.15616049,742.40624070,-0.08221132,-0.07394917,0.00000000,0.00000000,0.00000000,0.00000000
201.59000000,4.41383000,9.63200000,0.14887633,630.40774920,0.13878436,724.26054340,0.00083287,0.15765873,743.60050411,-0.08300656,-0.07465217,0.00000000,0.00000000,0.00000000,0.00000000
203.09000000,4.46004500,9.63600000,0.15045789,630.66954644,0.14016003,725.55875498,0.00083134,0.15915471,744.79499863,-0.08381199,-0.07534272,0.00000000,0.00000000,0.00000000,0.00000000
204.59000000,4.50513600,9.63900000,0.15207644,630.86589436,0.14156592,726.80573650,0.00089404,0.16061725,745.96637267,-0.08458910,-0.07602814,0.00000000,0.00000000,0.00000000,0.00000000
206.09000000,4.55052300,9.64200000,0.15369522,631.06224229,0.14297003,728.05349386,0.00095715,0.16210850,747.23863932,-0.08539893,-0.07670957,0.00000000,0.00000000,0.00000000,0.00000000
207.59000000,4.59683800,9.64500000,0.15531356,631.25859022,0.14437178,729.30160634,0.00095524,0.16365971,748.48044702,-0.08619825,-0.07746145,0.00000000,0.00000000,0.00000000,0.00000000
209.09000000,4.64245800,9.64900000,0.15693222,631.52038746,0.14577187,730.62628524,0.00095409,0.16514704,749.59850612,-0.08698191,-0.07816513,0.00000000,0.00000000,0.00000000,0.00000000
210.59000000,4.68920300,9.65100000,0.15858744,631.65128608,0.14720154,731.82324932,0.00101625,0.16666325,750.73999444,-0.08779710,-0.07886614,0.00000000,0.00000000,0.00000000,0.00000000
212.09000000,4.73532100,9.65300000,0.16020589,631.78218470,0.14859748,732.99741118,0.00095102,0.16826907,752.02885823,-0.08867887,-0.07959020,0.00000000,0.00000000,0.00000000,0.00000000
213.59000000,4.78160000,9.65500000,0.16182444,631.91308332,0.14999157,734.17206696,0.00088673,0.16984196,753.21690561,-0.08950726,-0.08033470,0.00000000,0.00000000,0.00000000,0.00000000
215.09000000,4.82871000,9.65800000,0.16347967,632.10943125,0.15141523,735.44647036,0.00088566,0.17141236,754.40495300,-0.09033453,-0.08107783,0.00000000,0.00000000,0.00000000,0.00000000
216.59000000,4.87535500,9.66100000,0.16513489,632.30577917,0.15283686,736.72152376,0.00088402,0.17298009,755.67123053,-0.09114421,-0.08183588,0.00000000,0.00000000,0.00000000,0.00000000
218.09000000,4.92223300,9.66200000,0.16686400,632.37122848,0.15431981,737.89122115,0.00088290,0.17454553,756.85940070,-0.09198171,-0.08256382,0.00000000,0.00000000,0.00000000,0.00000000
219.59000000,4.97000500,9.66400000,0.16855600,632.50212710,0.15576880,739.11415564,0.00100777,0.00000000,0.00000000,0.00000000,0.00000000,0.00000000,0.00000000,0.00000000,0.00000000
221.09000000,5.01761000,9.66600000,0.17028467,632.63302572,0.15724702,740.36072963,0.00100590,0.00000000,0.00000000,0.00000000,0.00000000,0.00000000,0.00000000,0.00000000,0.00000000
222.59000000,5.06587800,9.66800000,0.17201378,632.76392434,0.15872345,741.60803741,0.00100460,0.00000000,0.00000000,0.00000000,0.00000000,0.00000000,0.00000000,0.00000000,0.00000000
224.09000000,5.11378400,9.66900000,0.17370556,632.82937365,0.16016589,742.75535157,0.00094026,0.00000000,0.00000000,0.00000000,0.00000000,0.00000000,0.00000000,0.00000000,0.00000000
225.59000000,5.16142300,9.67000000,0.17547122,632.89482296,0.16166911,743.94965108,0.00093885,0.00000000,0.00000000,0.00000000,0.00000000,0.00000000,0.00000000,0.00000000,0.00000000
227.09000000,5.20995500,9.67100000,0.17720022,632.96027227,0.16313893,745.12097317,0.00087515,0.00000000,0.00000000,0.00000000,0.00000000,0.00000000,0.00000000,0.00000000,0.00000000
228.59000000,5.25852200,9.67300000,0.17896589,633.09117089,0.16463769,746.39289503,0.00093644,0.00000000,0.00000000,0.00000000,0.00000000,0.00000000,0.00000000,0.00000000,0.00000000
230.09000000,5.30784800,9.67400000,0.18076822,633.15662020,0.16616526,747.61121682,0.00099696,0.00000000,0.00000000,0.00000000,0.00000000,0.00000000,0.00000000,0.00000000,0.00000000
231.59000000,5.35691100,9.67500000,0.18260756,633.22206951,0.16772179,748.85320374,0.00099579,0.00000000,0.00000000,0.00000000,0.00000000,0.00000000,0.00000000,0.00000000,0.00000000
233.09000000,5.40518100,9.67500000,0.18444667,633.22206951,0.16927572,750.01776949,0.00111832,0.00000000,0.00000000,0.00000000,0.00000000,0.00000000,0.00000000,0.00000000,0.00000000
234.59000000,5.45483800,9.67600000,0.18624922,633.28751882,0.17079642,751.23682664,0.00111643,0.00000000,0.00000000,0.00000000,0.00000000,0.00000000,0.00000000,0.00000000,0.00000000
236.09000000,5.50489300,9.67700000,0.18808844,633.35296813,0.17234567,752.47934269,0.00099101,0.00000000,0.00000000,0.00000000,0.00000000,0.00000000,0.00000000,0.00000000,0.00000000
237.59000000,5.55435300,9.67600000,0.18996456,633.28751882,0.17392352,753.58970087,0.00098963,0.00000000,0.00000000,0.00000000,0.00000000,0.00000000,0.00000000,0.00000000,0.00000000
239.09000000,5.60447400,9.67700000,0.19187744,633.35296813,0.17552975,754.87911708,0.00104997,0.00000000,0.00000000,0.00000000,0.00000000,0.00000000,0.00000000,0.00000000,0.00000000
240.59000000,5.65456400,9.67700000,0.19371678,633.35296813,0.17707178,756.04406431,0.00098652,0.00000000,0.00000000,0.00000000,0.00000000,0.00000000,0.00000000,0.00000000,0.00000000
242.09000000,5.70501700,9.67800000,0.19566611,633.41841744,0.17870345,757.35693588,0.00110764,0.00000000,0.00000000,0.00000000,0.00000000,0.00000000,0.00000000,0.00000000,0.00000000
243.59000000,5.75533700,9.67700000,0.19761578,633.35296813,0.00000000,0.00000000,0.00000000,0.00000000,0.00000000,0.00000000,0.00000000,0.00000000,0.00000000,0.00000000,0.00000000
245.09000000,5.80635300,9.67700000,0.19960211,633.35296813,0.00000000,0.00000000,0.00000000,0.00000000,0.00000000,0.00000000,0.00000000,0.00000000,0.00000000,0.00000000,0.00000000
246.59000000,5.85740200,9.67600000,0.20158844,633.28751882,0.00000000,0.00000000,0.00000000,0.00000000,0.00000000,0.00000000,0.00000000,0.00000000,0.00000000,0.00000000,0.00000000
248.09000000,5.90789000,9.67600000,0.20353811,633.28751882,0.00000000,0.00000000,0.00000000,0.00000000,0.00000000,0.00000000,0.00000000,0.00000000,0.00000000,0.00000000,0.00000000
249.59000000,5.95999800,9.67500000,0.20559811,633.22206951,0.00000000,0.00000000,0.00000000,0.00000000,0.00000000,0.00000000,0.00000000,0.00000000,0.00000000,0.00000000,0.00000000
251.09000000,6.01154300,9.67400000,0.20765800,633.15662020,0.00000000,0.00000000,0.00000000,0.00000000,0.00000000,0.00000000,0.00000000,0.00000000,0.00000000,0.00000000,0.00000000
252.59000000,6.06318800,9.67300000,0.20975467,633.09117089,0.00000000,0.00000000,0.00000000,0.00000000,0.00000000,0.00000000,0.00000000,0.00000000,0.00000000,0.00000000,0.00000000
254.09000000,6.11536200,9.67300000,0.21188822,633.09117089,0.00000000,0.00000000,0.00000000,0.00000000,0.00000000,0.00000000,0.00000000,0.00000000,0.00000000,0.00000000,0.00000000
255.59000000,6.16776800,9.67200000,0.21405844,633.02572158,0.00000000,0.00000000,0.00000000,0.00000000,0.00000000,0.00000000,0.00000000,0.00000000,0.00000000,0.00000000,0.00000000
257.09000000,6.22017600,9.67000000,0.21626567,632.89482296,0.00000000,0.00000000,0.00000000,0.00000000,0.00000000,0.00000000,0.00000000,0.00000000,0.00000000,0.00000000,0.00000000
258.59000000,6.27254900,9.66900000,0.21843578,632.82937365,0.00000000,0.00000000,0.00000000,0.00000000,0.00000000,0.00000000,0.00000000,0.00000000,0.00000000,0.00000000,0.00000000
260.09000000,6.32618000,9.66700000,0.22075311,632.69847503,0.00000000,0.00000000,0.00000000,0.00000000,0.00000000,0.00000000,0.00000000,0.00000000,0.00000000,0.00000000,0.00000000
261.59000000,6.37964600,9.66600000,0.22307078,632.63302572,0.00000000,0.00000000,0.00000000,0.00000000,0.00000000,0.00000000,0.00000000,0.00000000,0.00000000,0.00000000,0.00000000
263.09000000,6.43317800,9.66400000,0.22538811,632.50212710,0.00000000,0.00000000,0.00000000,0.00000000,0.00000000,0.00000000,0.00000000,0.00000000,0.00000000,0.00000000,0.00000000
264.59000000,6.48727300,9.66200000,0.22781589,632.37122848,0.00000000,0.00000000,0.00000000,0.00000000,0.00000000,0.00000000,0.00000000,0.00000000,0.00000000,0.00000000,0.00000000
266.09000000,6.54163200,9.66100000,0.23024356,632.30577917,0.00000000,0.00000000,0.00000000,0.00000000,0.00000000,0.00000000,0.00000000,0.00000000,0.00000000,0.00000000,0.00000000
267.59000000,6.59665400,9.65800000,0.23281844,632.10943125,0.00000000,0.00000000,0.00000000,0.00000000,0.00000000,0.00000000,0.00000000,0.00000000,0.00000000,0.00000000,0.00000000
269.09000000,6.65074900,9.65600000,0.23539344,631.97853263,0.00000000,0.00000000,0.00000000,0.00000000,0.00000000,0.00000000,0.00000000,0.00000000,0.00000000,0.00000000,0.00000000
270.59000000,6.70553800,9.65200000,0.23796844,631.71673539,0.00000000,0.00000000,0.00000000,0.00000000,0.00000000,0.00000000,0.00000000,0.00000000,0.00000000,0.00000000,0.00000000
272.09000000,6.76145300,9.65000000,0.24065378,631.58583677,0.00000000,0.00000000,0.00000000,0.00000000,0.00000000,0.00000000,0.00000000,0.00000000,0.00000000,0.00000000,0.00000000
273.59000000,6.81733700,9.64800000,0.24352289,631.45493815,0.00000000,0.00000000,0.00000000,0.00000000,0.00000000,0.00000000,0.00000000,0.00000000,0.00000000,0.00000000,0.00000000
275.09000000,6.87325300,9.64500000,0.24639222,631.25859022,0.00000000,0.00000000,0.00000000,0.00000000,0.00000000,0.00000000,0.00000000,0.00000000,0.00000000,0.00000000,0.00000000
276.59000000,6.92943200,9.64000000,0.24929811,630.93134367,0.00000000,0.00000000,0.00000000,0.00000000,0.00000000,0.00000000,0.00000000,0.00000000,0.00000000,0.00000000,0.00000000
278.09000000,6.98531300,9.63700000,0.25231456,630.73499575,0.00000000,0.00000000,0.00000000,0.00000000,0.00000000,0.00000000,0.00000000,0.00000000,0.00000000,0.00000000,0.00000000
279.59000000,7.04238700,9.63400000,0.25540444,630.53864782,0.00000000,0.00000000,0.00000000,0.00000000,0.00000000,0.00000000,0.00000000,0.00000000,0.00000000,0.00000000,0.00000000
281.09000000,7.09913200,9.62900000,0.25856811,630.21140127,0.00000000,0.00000000,0.00000000,0.00000000,0.00000000,0.00000000,0.00000000,0.00000000,0.00000000,0.00000000,0.00000000
282.59000000,7.15627100,9.62500000,0.26191544,629.94960403,0.00000000,0.00000000,0.00000000,0.00000000,0.00000000,0.00000000,0.00000000,0.00000000,0.00000000,0.00000000,0.00000000
284.09000000,7.21387200,9.62000000,0.26529956,629.62235748,0.00000000,0.00000000,0.00000000,0.00000000,0.00000000,0.00000000,0.00000000,0.00000000,0.00000000,0.00000000,0.00000000
285.59000000,7.27121300,9.61600000,0.26883089,629.36056025,0.00000000,0.00000000,0.00000000,0.00000000,0.00000000,0.00000000,0.00000000,0.00000000,0.00000000,0.00000000,0.00000000
287.09000000,7.32977800,9.61100000,0.27254622,629.03331370,0.00000000,0.00000000,0.00000000,0.00000000,0.00000000,0.00000000,0.00000000,0.00000000,0.00000000,0.00000000,0.00000000
288.59000000,7.38757900,9.60400000,0.27633489,628.57516853,0.00000000,0.00000000,0.00000000,0.00000000,0.00000000,0.00000000,0.00000000,0.00000000,0.00000000,0.00000000,0.00000000
290.09000000,7.44591200,9.59800000,0.28023422,628.18247267,0.00000000,0.00000000,0.00000000,0.00000000,0.00000000,0.00000000,0.00000000,0.00000000,0.00000000,0.00000000,0.00000000
291.59000000,7.50430900,9.59100000,0.28442756,627.72432751,0.00000000,0.00000000,0.00000000,0.00000000,0.00000000,0.00000000,0.00000000,0.00000000,0.00000000,0.00000000,0.00000000
293.09000000,7.56310400,9.58400000,0.28865789,627.26618234,0.00000000,0.00000000,0.00000000,0.00000000,0.00000000,0.00000000,0.00000000,0.00000000,0.00000000,0.00000000,0.00000000
294.59000000,7.62243000,9.57800000,0.29307189,626.87348648,0.00000000,0.00000000,0.00000000,0.00000000,0.00000000,0.00000000,0.00000000,0.00000000,0.00000000,0.00000000,0.00000000
296.09000000,7.68132200,9.56800000,0.29770678,626.21899339,0.00000000,0.00000000,0.00000000,0.00000000,0.00000000,0.00000000,0.00000000,0.00000000,0.00000000,0.00000000,0.00000000
297.59000000,7.74081400,9.56000000,0.30252567,625.69539891,0.00000000,0.00000000,0.00000000,0.00000000,0.00000000,0.00000000,0.00000000,0.00000000,0.00000000,0.00000000,0.00000000
299.09000000,7.80063500,9.54900000,0.30752844,624.97545651,0.00000000,0.00000000,0.00000000,0.00000000,0.00000000,0.00000000,0.00000000,0.00000000,0.00000000,0.00000000,0.00000000
300.59000000,7.86055700,9.53900000,0.31267833,624.32096341,0.00000000,0.00000000,0.00000000,0.00000000,0.00000000,0.00000000,0.00000000,0.00000000,0.00000000,0.00000000,0.00000000
302.09000000,7.92011200,9.52600000,0.31801211,623.47012239,0.00000000,0.00000000,0.00000000,0.00000000,0.00000000,0.00000000,0.00000000,0.00000000,0.00000000,0.00000000,0.00000000
303.59000000,7.98042900,9.51400000,0.32356656,622.68473068,0.00000000,0.00000000,0.00000000,0.00000000,0.00000000,0.00000000,0.00000000,0.00000000,0.00000000,0.00000000,0.00000000
305.09000000,8.04107800,9.49800000,0.32934189,621.63754172,0.00000000,0.00000000,0.00000000,0.00000000,0.00000000,0.00000000,0.00000000,0.00000000,0.00000000,0.00000000,0.00000000
306.59000000,8.10238800,9.48400000,0.33533778,620.72125139,0.00000000,0.00000000,0.00000000,0.00000000,0.00000000,0.00000000,0.00000000,0.00000000,0.00000000,0.00000000,0.00000000
308.09000000,8.16323700,9.46500000,0.34144411,619.47771451,0.00000000,0.00000000,0.00000000,0.00000000,0.00000000,0.00000000,0.00000000,0.00000000,0.00000000,0.00000000,0.00000000
309.59000000,8.22428300,9.44700000,0.34762400,618.29962694,0.00000000,0.00000000,0.00000000,0.00000000,0.00000000,0.00000000,0.00000000,0.00000000,0.00000000,0.00000000,0.00000000
311.09000000,8.28566100,9.42500000,0.35406144,616.85974213,0.00000000,0.00000000,0.00000000,0.00000000,0.00000000,0.00000000,0.00000000,0.00000000,0.00000000,0.00000000,0.00000000
312.59000000,8.34693900,9.40500000,0.36053567,615.55075594,0.00000000,0.00000000,0.00000000,0.00000000,0.00000000,0.00000000,0.00000000,0.00000000,0.00000000,0.00000000,0.00000000
314.09000000,8.40818400,9.37800000,0.36715711,613.78362458,0.00000000,0.00000000,0.00000000,0.00000000,0.00000000,0.00000000,0.00000000,0.00000000,0.00000000,0.00000000,0.00000000
315.59000000,8.46999300,9.35300000,0.37385189,612.14739185,0.00000000,0.00000000,0.00000000,0.00000000,0.00000000,0.00000000,0.00000000,0.00000000,0.00000000,0.00000000,0.00000000
317.09000000,8.53226600,9.32400000,0.38058333,610.24936187,0.00000000,0.00000000,0.00000000,0.00000000,0.00000000,0.00000000,0.00000000,0.00000000,0.00000000,0.00000000,0.00000000
318.59000000,8.59470300,9.29300000,0.38749911,608.22043327,0.00000000,0.00000000,0.00000000,0.00000000,0.00000000,0.00000000,0.00000000,0.00000000,0.00000000,0.00000000,0.00000000
320.09000000,8.65677500,9.25700000,0.39434111,605.86425813,0.00000000,0.00000000,0.00000000,0.00000000,0.00000000,0.00000000,0.00000000,0.00000000,0.00000000,0.00000000,0.00000000
321.59000000,8.71904700,9.22400000,0.40129322,603.70443092,0.00000000,0.00000000,0.00000000,0.00000000,0.00000000,0.00000000,0.00000000,0.00000000,0.00000000,0.00000000,0.00000000
323.09000000,8.78108800,9.18000000,0.40817200,600.82466130,0.00000000,0.00000000,0.00000000,0.00000000,0.00000000,0.00000000,0.00000000,0.00000000,0.00000000,0.00000000,0.00000000
324.59000000,8.84425200,9.14100000,0.41523444,598.27213823,0.00000000,0.00000000,0.00000000,0.00000000,0.00000000,0.00000000,0.00000000,0.00000000,0.00000000,0.00000000,0.00000000
326.09000000,8.90781500,9.09200000,0.42229700,595.06512206,0.00000000,0.00000000,0.00000000,0.00000000,0.00000000,0.00000000,0.00000000,0.00000000,0.00000000,0.00000000,0.00000000
327.59000000,8.97134500,9.04000000,0.42935956,591.66175797,0.00000000,0.00000000,0.00000000,0.00000000,0.00000000,0.00000000,0.00000000,0.00000000,0.00000000,0.00000000,0.00000000
329.09000000,9.03507300,8.97900000,0.43656922,587.66935009,0.00000000,0.00000000,0.00000000,0.00000000,0.00000000,0.00000000,0.00000000,0.00000000,0.00000000,0.00000000,0.00000000
330.59000000,9.09890100,8.92100000,0.44374233,583.87329014,0.00000000,0.00000000,0.00000000,0.00000000,0.00000000,0.00000000,0.00000000,0.00000000,0.00000000,0.00000000,0.00000000
332.09000000,9.16362200,8.83900000,0.45102578,578.50644676,0.00000000,0.00000000,0.00000000,0.00000000,0.00000000,0.00000000,0.00000000,0.00000000,0.00000000,0.00000000,0.00000000
333.59000000,9.22857700,8.76600000,0.45841967,573.72864716,0.00000000,0.00000000,0.00000000,0.00000000,0.00000000,0.00000000,0.00000000,0.00000000,0.00000000,0.00000000,0.00000000
335.09000000,9.29455700,8.66800000,0.46581344,567.31461483,0.00000000,0.00000000,0.00000000,0.00000000,0.00000000,0.00000000,0.00000000,0.00000000,0.00000000,0.00000000,0.00000000
336.59000000,9.36202600,8.56400000,0.47342789,560.50788664,0.00000000,0.00000000,0.00000000,0.00000000,0.00000000,0.00000000,0.00000000,0.00000000,0.00000000,0.00000000,0.00000000
338.09000000,9.43075300,8.43100000,0.48126311,551.80312848,0.00000000,0.00000000,0.00000000,0.00000000,0.00000000,0.00000000,0.00000000,0.00000000,0.00000000,0.00000000,0.00000000
339.59000000,9.50126800,8.29600000,0.48931878,542.96747169,0.00000000,0.00000000,0.00000000,0.00000000,0.00000000,0.00000000,0.00000000,0.00000000,0.00000000,0.00000000,0.00000000
341.09000000,9.57485900,8.08600000,0.49774222,529.22311670,0.00000000,0.00000000,0.00000000,0.00000000,0.00000000,0.00000000,0.00000000,0.00000000,0.00000000,0.00000000,0.00000000