File: polyN_optimization/results_exp/DP600/UT_75_1.csv
Time[s],Displacement[mm],Force[kN],EngStrain_longi,EngStress[MPa],TrueStrain,TrueStress[MPa],TrueStrainRate[1/s],PlasticStrain_longi,PlasticStress[MPa],PlasticStrain_thick,PlasticStrain_width,R-Value,Thickness[mm],Width[mm], Young's Modulus [MPa]
0.61000000,0.00000000,-0.01200000,0.00000000,-0.78405750,0.00000000,-0.78405750,0.00000000,0.00071321,345.80038419,0.00036280,-0.00107601,0.99947046,1.53050000,10.00000000,242931.04658590
2.11000000,0.00145500,0.01300000,0.00004178,0.84939562,0.00004178,0.84943111,-0.00000578,0.00111059,363.33056470,0.00008183,-0.00119242,0.00000000,0.00000000,0.00000000,0.00000000
3.61000000,0.00338000,0.44100000,0.00010589,28.81411303,0.00010588,28.81716413,-0.00000822,0.00157518,375.97739036,-0.00020570,-0.00136948,0.00000000,0.00000000,0.00000000,0.00000000
5.11000000,0.00612100,0.72600000,0.00018322,47.43547860,0.00018321,47.44416984,0.00005666,0.00221331,389.09934858,-0.00044981,-0.00176350,0.00000000,0.00000000,0.00000000,0.00000000
6.61000000,0.00806800,1.10600000,0.00024422,72.26396602,0.00024419,72.28161449,0.00008531,0.00296757,399.32611839,-0.00073723,-0.00223034,0.00000000,0.00000000,0.00000000,0.00000000
8.11000000,0.00939900,1.41500000,0.00027222,92.45344659,0.00027219,92.47861447,0.00002422,0.00374459,410.76355913,-0.00108224,-0.00266236,0.00000000,0.00000000,0.00000000,0.00000000
9.61000000,0.01117300,1.80400000,0.00035311,117.86997713,0.00035305,117.91159833,-0.00003088,0.00451715,419.12071860,-0.00147338,-0.00304377,0.00000000,0.00000000,0.00000000,0.00000000
11.11000000,0.01361700,2.11300000,0.00044289,138.05945769,0.00044279,138.12060269,-0.00003532,0.00529829,428.55014871,-0.00184782,-0.00345047,0.00000000,0.00000000,0.00000000,0.00000000
12.61000000,0.01682200,2.47200000,0.00053489,161.51584450,0.00053475,161.60223753,-0.00007351,0.00623162,435.75098620,-0.00232477,-0.00390685,0.00000000,0.00000000,0.00000000,0.00000000
14.11000000,0.02026100,2.78000000,0.00068233,181.63998693,0.00068210,181.76392595,0.00016101,0.00717169,443.62925311,-0.00274913,-0.00442256,0.00000000,0.00000000,0.00000000,0.00000000
15.61000000,0.02362200,3.16300000,0.00081111,206.66448873,0.00081078,206.83211659,0.00030067,0.00804118,450.10147483,-0.00306319,-0.00497799,0.00000000,0.00000000,0.00000000,0.00000000
17.11000000,0.02632100,3.46400000,0.00086344,226.33126429,0.00086307,226.52668877,0.00024336,0.00887859,457.76209998,-0.00339910,-0.00547949,0.00000000,0.00000000,0.00000000,0.00000000
18.61000000,0.02936000,3.83300000,0.00090644,250.44103234,0.00090603,250.66804322,0.00011323,0.00983183,463.83292519,-0.00395567,-0.00587616,0.00000000,0.00000000,0.00000000,0.00000000
20.11000000,0.03363800,4.12500000,0.00099322,269.51976478,0.00099273,269.78745780,-0.00005150,0.01081873,470.99264855,-0.00450254,-0.00631619,0.00000000,0.00000000,0.00000000,0.00000000
21.61000000,0.03963300,4.45600000,0.00114789,291.14668409,0.00114723,291.48088813,-0.00016891,0.01174663,476.61080665,-0.00496685,-0.00677978,0.00000000,0.00000000,0.00000000,0.00000000
23.11000000,0.04734800,4.72800000,0.00147533,308.91865403,0.00147425,309.37441202,-0.00011738,0.01268154,482.84097252,-0.00538473,-0.00729681,0.00000000,0.00000000,0.00000000,0.00000000
24.61000000,0.05662300,5.04600000,0.00189856,329.69617772,0.00189676,330.32212423,0.00019852,0.01362042,488.01999927,-0.00578227,-0.00783815,0.00000000,0.00000000,0.00000000,0.00000000
26.11000000,0.06977400,5.28000000,0.00236267,344.98529892,0.00235988,345.80038419,0.00053636,0.01461473,494.30179506,-0.00625928,-0.00835545,0.00000000,0.00000000,0.00000000,0.00000000
27.61000000,0.08620400,5.54500000,0.00284478,362.29990199,0.00284074,363.33056470,0.00068240,0.01563583,499.27573012,-0.00680793,-0.00882790,0.00000000,0.00000000,0.00000000,0.00000000
29.11000000,0.10287300,5.73500000,0.00337122,374.71414570,0.00336555,375.97739036,0.00054313,0.01659784,505.09745439,-0.00731049,-0.00928735,0.00000000,0.00000000,0.00000000,0.00000000
30.61000000,0.12374400,5.93100000,0.00407444,387.52041816,0.00406617,389.09934858,0.00048431,0.01757931,509.67060888,-0.00781859,-0.00976071,0.00000000,0.00000000,0.00000000,0.00000000
32.11000000,0.14551100,6.08200000,0.00488100,397.38647501,0.00486913,399.32611839,0.00067438,0.01861428,514.88207845,-0.00834527,-0.01026900,0.00000000,0.00000000,0.00000000,0.00000000
33.61000000,0.17128500,6.25100000,0.00571689,408.42861810,0.00570061,410.76355913,0.00089309,0.01963411,519.22562180,-0.00887588,-0.01075823,0.00000000,0.00000000,0.00000000,0.00000000
35.11000000,0.19683000,6.37300000,0.00653422,416.39986932,0.00651297,419.12071860,0.00087050,0.02067781,524.39464532,-0.00932277,-0.01135505,0.00000000,0.00000000,0.00000000,0.00000000
36.61000000,0.22316300,6.51100000,0.00736600,425.41653055,0.00733900,428.55014871,0.00065021,0.02169655,528.55426749,-0.00979993,-0.01189662,0.00000000,0.00000000,0.00000000,0.00000000
38.11000000,0.25085100,6.61400000,0.00834122,432.14635740,0.00830663,435.75098620,0.00068617,0.02275366,533.41430992,-0.01032147,-0.01243220,0.00000000,0.00000000,0.00000000,0.00000000
39.61000000,0.27986300,6.72700000,0.00932744,439.52956550,0.00928421,443.62925311,0.00086060,0.02384265,537.35984450,-0.01091777,-0.01292488,0.00000000,0.00000000,0.00000000,0.00000000
41.11000000,0.30702100,6.81900000,0.01023656,445.54067298,0.01018452,450.10147483,0.00084531,0.02487099,541.75189004,-0.01147364,-0.01339734,0.00000000,0.00000000,0.00000000,0.00000000
42.61000000,0.33719100,6.92900000,0.01111978,452.72786671,0.01105841,457.76209998,0.00064076,0.02594091,545.43390665,-0.01204145,-0.01389946,0.00000000,0.00000000,0.00000000,0.00000000
44.11000000,0.36603800,7.01400000,0.01211333,458.28160732,0.01204055,463.83292519,0.00052351,0.02702062,549.80350088,-0.01263049,-0.01439014,0.00000000,0.00000000,0.00000000,0.00000000
45.61000000,0.39564300,7.11500000,0.01314722,464.88075792,0.01306155,470.99264855,0.00064671,0.02806414,553.28377573,-0.01317865,-0.01488549,0.00000000,0.00000000,0.00000000,0.00000000
47.11000000,0.42521300,7.19300000,0.01411489,469.97713166,0.01401620,476.61080665,0.00066035,0.02913839,557.53190346,-0.01368782,-0.01545058,0.00000000,0.00000000,0.00000000,0.00000000
48.61000000,0.45627100,7.28000000,0.01509356,475.66154851,0.01498078,482.84097252,0.00063803,0.03023371,560.85269299,-0.01421369,-0.01602002,0.00000000,0.00000000,0.00000000,0.00000000
50.11000000,0.48574000,7.35100000,0.01607211,480.30055537,0.01594432,488.01999927,0.00049259,0.03130431,564.64066602,-0.01472399,-0.01658032,0.00000000,0.00000000,0.00000000,0.00000000
51.61000000,0.51719500,7.43800000,0.01711333,485.98497223,0.01696855,494.30179506,0.00047788,0.03236953,567.82249404,-0.01523905,-0.01713048,0.00000000,0.00000000,0.00000000,0.00000000
53.11000000,0.54809000,7.50500000,0.01817656,490.36262659,0.01801334,499.27573012,0.00062147,0.03350472,571.72995097,-0.01584992,-0.01765480,0.00000000,0.00000000,0.00000000,0.00000000
54.61000000,0.57934900,7.58500000,0.01918478,495.58967658,0.01900307,505.09745439,0.00062827,0.03458925,574.80034738,-0.01638738,-0.01820187,0.00000000,0.00000000,0.00000000,0.00000000
56.11000000,0.61153600,7.64600000,0.02020778,499.57530219,0.02000631,509.67060888,0.00057731,0.03567371,578.35337005,-0.01692412,-0.01874959,0.00000000,0.00000000,0.00000000,0.00000000
57.61000000,0.64272900,7.71600000,0.02128956,504.14897092,0.02106610,514.88207845,0.00062001,0.03677069,581.30740031,-0.01748674,-0.01928395,0.00000000,0.00000000,0.00000000,0.00000000
59.11000000,0.67561000,7.77300000,0.02235278,507.87324404,0.02210662,519.22562180,0.00066937,0.03792449,584.64179590,-0.01811278,-0.01981171,0.00000000,0.00000000,0.00000000,0.00000000
60.61000000,0.70726400,7.84200000,0.02344556,512.38157465,0.02317493,524.39464532,0.00078356,0.03905067,587.55701111,-0.01866595,-0.02038472,0.00000000,0.00000000,0.00000000,0.00000000
62.11000000,0.74011100,7.89600000,0.02450900,515.90983339,0.02421347,528.55426749,0.00072547,0.04016976,590.95273074,-0.01919068,-0.02097908,0.00000000,0.00000000,0.00000000,0.00000000
63.61000000,0.77322000,7.96000000,0.02561633,520.09147337,0.02529373,533.41430992,0.00075351,0.04125939,593.65310670,-0.01969427,-0.02156512,0.00000000,0.00000000,0.00000000,0.00000000
65.11000000,0.80646400,8.01000000,0.02675311,523.35837961,0.02640150,537.35984450,0.00083149,0.04240503,596.87212784,-0.02022231,-0.02218273,0.00000000,0.00000000,0.00000000,0.00000000
66.61000000,0.83993700,8.06700000,0.02783100,527.08265273,0.02745076,541.75189004,0.00075881,0.04355529,599.55151998,-0.02080978,-0.02274551,0.00000000,0.00000000,0.00000000,0.00000000
68.11000000,0.87347800,8.11300000,0.02894933,530.08820647,0.02853822,545.43390665,0.00077246,0.04471038,602.44543102,-0.02138021,-0.02333017,0.00000000,0.00000000,0.00000000,0.00000000
69.61000000,0.90708300,8.16900000,0.03008233,533.74714146,0.02963873,549.80350088,0.00078585,0.04581675,604.97174761,-0.02189524,-0.02392151,0.00000000,0.00000000,0.00000000,0.00000000
71.11000000,0.94062400,8.21200000,0.03117489,536.55668082,0.03069882,553.28377573,0.00075656,0.04698913,608.02535113,-0.02251964,-0.02446949,0.00000000,0.00000000,0.00000000,0.00000000
72.61000000,0.97492600,8.26600000,0.03230411,540.08493956,0.03179330,557.53190346,0.00070556,0.04817343,610.54097651,-0.02312878,-0.02504465,0.00000000,0.00000000,0.00000000,0.00000000
74.11000000,1.00889600,8.30600000,0.03345178,542.69846455,0.03290444,560.85269299,0.00076866,0.04927419,613.42464890,-0.02364761,-0.02562658,0.00000000,0.00000000,0.00000000,0.00000000
75.61000000,1.04336200,8.35300000,0.03457744,545.76935642,0.03399308,564.64066602,0.00073237,0.05044920,615.80692014,-0.02426932,-0.02617988,0.00000000,0.00000000,0.00000000,0.00000000
77.11000000,1.07782900,8.39100000,0.03569578,548.25220516,0.03507345,567.82249404,0.00068908,0.05162181,618.40012117,-0.02487718,-0.02674462,0.00000000,0.00000000,0.00000000,0.00000000
78.61000000,1.11259500,8.43900000,0.03689144,551.38843515,0.03622724,571.72995097,0.00077362,0.05279733,620.79256988,-0.02546655,-0.02733077,0.00000000,0.00000000,0.00000000,0.00000000
80.11000000,1.14769200,8.47500000,0.03803178,553.74060764,0.03732640,574.80034738,0.00077277,0.05394258,623.44840693,-0.02602992,-0.02791266,0.00000000,0.00000000,0.00000000,0.00000000
81.61000000,1.18189400,8.51800000,0.03917567,556.55014701,0.03842777,578.35337005,0.00072207,0.05511615,625.71064306,-0.02663248,-0.02848368,0.00000000,0.00000000,0.00000000,0.00000000
83.11000000,1.21788400,8.55200000,0.04033089,558.77164325,0.03953882,581.30740031,0.00070011,0.05629699,628.32964123,-0.02721879,-0.02907821,0.00000000,0.00000000,0.00000000,0.00000000
84.61000000,1.25268100,8.59100000,0.04154844,561.31983012,0.04070849,584.64179590,0.00070677,0.05748525,630.54098608,-0.02781845,-0.02966680,0.00000000,0.00000000,0.00000000,0.00000000
86.11000000,1.28893500,8.62400000,0.04273656,563.47598824,0.04184856,587.55701111,0.00076928,0.05867805,632.96874015,-0.02840484,-0.03027321,0.00000000,0.00000000,0.00000000,0.00000000
87.61000000,1.32482300,8.66400000,0.04392100,566.08951323,0.04298382,590.95273074,0.00078927,0.05986063,635.04598549,-0.02895341,-0.03090721,0.00000000,0.00000000,0.00000000,0.00000000
89.11000000,1.36071400,8.69400000,0.04507256,568.04965697,0.04408631,593.65310670,0.00067609,0.06103315,637.47023951,-0.02956972,-0.03146343,0.00000000,0.00000000,0.00000000,0.00000000
90.61000000,1.39670200,8.73100000,0.04628656,570.46716759,0.04524728,596.87212784,0.00068933,0.06221629,639.55638912,-0.03013201,-0.03208429,0.00000000,0.00000000,0.00000000,0.00000000
92.11000000,1.43311900,8.76000000,0.04750411,572.36197321,0.04641030,599.55151998,0.00076556,0.06343098,641.94709990,-0.03074243,-0.03268855,0.00000000,0.00000000,0.00000000,0.00000000
93.61000000,1.46914300,8.79200000,0.04872922,574.45279320,0.04757917,602.44543102,0.00080685,0.06461827,643.97438144,-0.03132756,-0.03329072,0.00000000,0.00000000,0.00000000,0.00000000
95.11000000,1.50539500,8.81900000,0.04990278,576.21692257,0.04869757,604.97174761,0.00069415,0.06581731,646.15364831,-0.03191208,-0.03390523,0.00000000,0.00000000,0.00000000,0.00000000
96.61000000,1.54274100,8.85300000,0.05114967,578.43841882,0.04988449,608.02535113,0.00082614,0.06700587,648.04925493,-0.03252806,-0.03447781,0.00000000,0.00000000,0.00000000,0.00000000
98.11000000,1.57925900,8.87900000,0.05240789,580.13721006,0.05108077,610.54097651,0.00084607,0.06820154,650.30503673,-0.03310421,-0.03509733,0.00000000,0.00000000,0.00000000,0.00000000
99.61000000,1.61677100,8.91100000,0.05358144,582.22803006,0.05219526,613.42464890,0.00078963,0.06941110,652.22207932,-0.03372197,-0.03568913,0.00000000,0.00000000,0.00000000,0.00000000
101.11000000,1.65338700,8.93500000,0.05483211,583.79614505,0.05338162,615.80692014,0.00076741,0.07065212,654.37516095,-0.03438224,-0.03626988,0.00000000,0.00000000,0.00000000,0.00000000
102.61000000,1.69080000,8.96200000,0.05608278,585.56027442,0.05456657,618.40012117,0.00080144,0.07183864,656.21415481,-0.03497384,-0.03686480,0.00000000,0.00000000,0.00000000,0.00000000
104.11000000,1.72797900,8.98600000,0.05733700,587.12838942,0.05575348,620.79256988,0.00078620,0.07309395,658.31423544,-0.03560479,-0.03748916,0.00000000,0.00000000,0.00000000,0.00000000
105.61000000,1.76562200,9.01400000,0.05856200,588.95785691,0.05691138,623.44840693,0.00072270,0.07431844,660.11488729,-0.03621208,-0.03810636,0.00000000,0.00000000,0.00000000,0.00000000
107.11000000,1.80296600,9.03600000,0.05981644,590.39529566,0.05809573,625.71064306,0.00075667,0.07552687,662.12106143,-0.03683097,-0.03869590,0.00000000,0.00000000,0.00000000,0.00000000
108.61000000,1.84077500,9.06300000,0.06108189,592.15942502,0.05928904,628.32964123,0.00080437,0.07677532,663.94481244,-0.03744634,-0.03932897,0.00000000,0.00000000,0.00000000,0.00000000
110.11000000,1.87901600,9.08400000,0.06235467,593.53152565,0.06048783,630.54098608,0.00084505,0.07800441,665.97245703,-0.03804132,-0.03996309,0.00000000,0.00000000,0.00000000,0.00000000
111.61000000,1.91682300,9.10800000,0.06363489,595.09964064,0.06169218,632.96874015,0.00085825,0.07925340,667.73274002,-0.03868611,-0.04056729,0.00000000,0.00000000,0.00000000,0.00000000
113.11000000,1.95499500,9.12700000,0.06490400,596.34106501,0.06288465,635.04598549,0.00082236,0.08046685,669.54380286,-0.03929227,-0.04117458,0.00000000,0.00000000,0.00000000,0.00000000
114.61000000,1.99253900,9.15100000,0.06616567,597.90918001,0.06406872,637.47023951,0.00081451,0.08170609,671.30432639,-0.03990650,-0.04179958,0.00000000,0.00000000,0.00000000,0.00000000
116.11000000,2.03117600,9.17000000,0.06743844,599.15060438,0.06526180,639.55638912,0.00079271,0.08296321,673.22317685,-0.04053764,-0.04242557,0.00000000,0.00000000,0.00000000,0.00000000
117.61000000,2.06931500,9.19300000,0.06874800,600.65338125,0.06648787,641.94709990,0.00081940,0.08422017,674.85956746,-0.04119103,-0.04302914,0.00000000,0.00000000,0.00000000,0.00000000
119.11000000,2.10854700,9.21100000,0.07002800,601.82946749,0.06768482,643.97438144,0.00082486,0.08545444,676.69851150,-0.04181202,-0.04364242,0.00000000,0.00000000,0.00000000,0.00000000
120.61000000,2.14718200,9.23100000,0.07132289,603.13622999,0.06889423,646.15364831,0.00079668,0.08669465,678.32989141,-0.04238909,-0.04430556,0.00000000,0.00000000,0.00000000,0.00000000
122.11000000,2.18605000,9.24700000,0.07260667,604.18163999,0.07009182,648.04925493,0.00075469,0.08795662,680.05094808,-0.04303368,-0.04492294,0.00000000,0.00000000,0.00000000,0.00000000
123.61000000,2.22478500,9.26800000,0.07390144,605.55374061,0.07129823,650.30503673,0.00076724,0.08922676,681.78088435,-0.04368885,-0.04553791,0.00000000,0.00000000,0.00000000,0.00000000
125.11000000,2.26368500,9.28400000,0.07521100,606.59915060,0.07251692,652.22207932,0.00074604,0.09047861,683.50160841,-0.04430299,-0.04617563,0.00000000,0.00000000,0.00000000,0.00000000
126.61000000,2.30308200,9.30300000,0.07655722,607.84057498,0.07376819,654.37516095,0.00079281,0.09175336,685.02508104,-0.04493117,-0.04682220,0.00000000,0.00000000,0.00000000,0.00000000
128.11000000,2.34244600,9.31800000,0.07784478,608.82064685,0.07496347,656.21415481,0.00077845,0.09303198,686.77054370,-0.04561920,-0.04741278,0.00000000,0.00000000,0.00000000,0.00000000
129.61000000,2.38227300,9.33600000,0.07920944,609.99673309,0.07622878,658.31423544,0.00085966,0.09432307,688.38345157,-0.04628394,-0.04803914,0.00000000,0.00000000,0.00000000,0.00000000
131.11000000,2.42226700,9.35000000,0.08054100,610.91146684,0.07746184,660.11488729,0.00087198,0.09555293,689.88464351,-0.04690824,-0.04864468,0.00000000,0.00000000,0.00000000,0.00000000
132.61000000,2.46173000,9.36700000,0.08185789,612.02221496,0.07867983,662.12106143,0.00083660,0.09680415,691.47578242,-0.04754771,-0.04925643,0.00000000,0.00000000,0.00000000,0.00000000
134.11000000,2.50188800,9.38100000,0.08321878,612.93694871,0.07993696,663.94481244,0.00088316,0.09808714,693.01939137,-0.04818192,-0.04990522,0.00000000,0.00000000,0.00000000,0.00000000
135.61000000,2.54188100,9.39800000,0.08456144,614.04769683,0.08117571,665.97245703,0.00086813,0.09936807,694.70969425,-0.04881550,-0.05055258,0.00000000,0.00000000,0.00000000,0.00000000
137.11000000,2.58220300,9.41100000,0.08592600,614.89709245,0.08243308,667.73274002,0.00085373,0.10065137,696.18665077,-0.04944719,-0.05120418,0.00000000,0.00000000,0.00000000,0.00000000
138.61000000,2.62236100,9.42500000,0.08725389,615.81182620,0.08365515,669.54380286,0.00081874,0.10194615,697.67431318,-0.05007567,-0.05187049,0.00000000,0.00000000,0.00000000,0.00000000
140.11000000,2.66301600,9.43800000,0.08861122,616.66122182,0.08490278,671.30432639,0.00085162,0.10323311,699.08626240,-0.05072120,-0.05251191,0.00000000,0.00000000,0.00000000,0.00000000
141.61000000,2.70353700,9.45300000,0.08999056,617.64129369,0.08616903,673.22317685,0.00082342,0.10452401,700.72254784,-0.05135710,-0.05316692,0.00000000,0.00000000,0.00000000,0.00000000
143.11000000,2.74455400,9.46400000,0.09137000,618.36001307,0.08743379,674.85956746,0.00082910,0.10581123,702.06684797,-0.05197719,-0.05383404,0.00000000,0.00000000,0.00000000,0.00000000
144.61000000,2.78553900,9.47800000,0.09272744,619.27474681,0.08867681,676.69851150,0.00082848,0.10712191,703.64966450,-0.05265341,-0.05446850,0.00000000,0.00000000,0.00000000,0.00000000
146.11000000,2.82629400,9.48900000,0.09409200,619.99346619,0.08992480,678.32989141,0.00081363,0.10842521,705.08359541,-0.05332304,-0.05510217,0.00000000,0.00000000,0.00000000,0.00000000
147.61000000,2.86721200,9.50100000,0.09548256,620.77752369,0.09119496,680.05094808,0.00083979,0.10976931,706.54901196,-0.05405357,-0.05571574,0.00000000,0.00000000,0.00000000,0.00000000
149.11000000,2.90849400,9.51300000,0.09688389,621.56158118,0.09247333,681.78088435,0.00088513,0.11109138,708.07497136,-0.05470882,-0.05638255,0.00000000,0.00000000,0.00000000,0.00000000
150.61000000,2.94987800,9.52500000,0.09826689,622.34563868,0.09373338,683.50160841,0.00091762,0.11237992,709.43267087,-0.05533116,-0.05704876,0.00000000,0.00000000,0.00000000,0.00000000
152.11000000,2.99149200,9.53400000,0.09967578,622.93368180,0.09501539,685.02508104,0.00082304,0.11368639,710.80548996,-0.05597406,-0.05771233,0.00000000,0.00000000,0.00000000,0.00000000
153.61000000,3.03267700,9.54600000,0.10109189,623.71773930,0.09630231,686.77054370,0.00090214,0.11502035,712.20034371,-0.05664522,-0.05837513,0.00000000,0.00000000,0.00000000,0.00000000
155.11000000,3.07459000,9.55600000,0.10252289,624.37112055,0.09760109,688.38345157,0.00093444,0.11637889,713.54136795,-0.05734929,-0.05902960,0.00000000,0.00000000,0.00000000,0.00000000
156.61000000,3.11673200,9.56500000,0.10388756,624.95916367,0.09883809,689.88464351,0.00084668,0.11771184,715.08839412,-0.05798408,-0.05972777,0.00000000,0.00000000,0.00000000,0.00000000
158.11000000,3.15804700,9.57500000,0.10527800,625.61254492,0.10009689,691.47578242,0.00079915,0.11906659,716.43165015,-0.05866609,-0.06040050,0.00000000,0.00000000,0.00000000,0.00000000
159.61000000,3.20025700,9.58400000,0.10670511,626.20058804,0.10138723,693.01939137,0.00081761,0.12041332,717.77147152,-0.05933219,-0.06108113,0.00000000,0.00000000,0.00000000,0.00000000
161.11000000,3.24233500,9.59500000,0.10813256,626.91930742,0.10267622,694.70969425,0.00083662,0.12174824,719.10510186,-0.05997796,-0.06177029,0.00000000,0.00000000,0.00000000,0.00000000
162.61000000,3.28484200,9.60300000,0.10956333,627.44201241,0.10396654,696.18665077,0.00083574,0.12310079,720.45376146,-0.06066031,-0.06244048,0.00000000,0.00000000,0.00000000,0.00000000
164.11000000,3.32728400,9.61100000,0.11100878,627.96471741,0.10526841,697.67431318,0.00083445,0.12442888,721.78705525,-0.06129486,-0.06313401,0.00000000,0.00000000,0.00000000,0.00000000
165.61000000,3.36969300,9.61800000,0.11244700,628.42208429,0.10656209,699.08626240,0.00089273,0.12579105,723.07275945,-0.06201393,-0.06377712,0.00000000,0.00000000,0.00000000,0.00000000
167.11000000,3.41236500,9.62800000,0.11389267,629.07546553,0.10786079,700.72254784,0.00086522,0.12719875,724.54315350,-0.06271632,-0.06448243,0.00000000,0.00000000,0.00000000,0.00000000
168.61000000,3.45510600,9.63400000,0.11533456,629.46749428,0.10915441,702.06684797,0.00080510,0.12857037,725.76554186,-0.06338511,-0.06518526,0.00000000,0.00000000,0.00000000,0.00000000
170.11000000,3.49774600,9.64300000,0.11680578,630.05553741,0.11047263,703.64966450,0.00088287,0.12997172,727.08653812,-0.06408541,-0.06588632,0.00000000,0.00000000,0.00000000,0.00000000
171.61000000,3.54118000,9.65000000,0.11826989,630.51290428,0.11178275,705.08359541,0.00089484,0.13134545,728.38963251,-0.06478942,-0.06655603,0.00000000,0.00000000,0.00000000,0.00000000
173.11000000,3.58474700,9.65700000,0.11978178,630.97027115,0.11313383,706.54901196,0.00092678,0.13272375,729.69829224,-0.06546830,-0.06725545,0.00000000,0.00000000,0.00000000,0.00000000
174.61000000,3.62880900,9.66500000,0.12127133,631.49297615,0.11446316,708.07497136,0.00088590,0.13410058,730.93287630,-0.06615356,-0.06794701,0.00000000,0.00000000,0.00000000,0.00000000
176.11000000,3.67211100,9.67100000,0.12272433,631.88500490,0.11575817,709.43267087,0.00081921,0.13552283,732.27820906,-0.06688083,-0.06864200,0.00000000,0.00000000,0.00000000,0.00000000
177.61000000,3.71541600,9.67700000,0.12419944,632.27703365,0.11707118,710.80548996,0.00077918,0.13692452,733.45985640,-0.06757024,-0.06935428,0.00000000,0.00000000,0.00000000,0.00000000
179.11000000,3.75914700,9.68300000,0.12570756,632.66906240,0.11841178,712.20034371,0.00079097,0.13835551,734.81610685,-0.06828284,-0.07007266,0.00000000,0.00000000,0.00000000,0.00000000
180.61000000,3.80334300,9.68800000,0.12724511,632.99575302,0.11977670,713.54136795,0.00090743,0.13978469,736.09774727,-0.06898597,-0.07079872,0.00000000,0.00000000,0.00000000,0.00000000
182.11000000,3.84773900,9.69600000,0.12875700,633.51845802,0.12111703,715.08839412,0.00091922,0.14124371,737.40364358,-0.06973828,-0.07150543,0.00000000,0.00000000,0.00000000,0.00000000
183.61000000,3.89173700,9.70100000,0.13029444,633.84514864,0.12247817,716.43165015,0.00097009,0.14263788,738.51194610,-0.07038968,-0.07224820,0.00000000,0.00000000,0.00000000,0.00000000
185.11000000,3.93639800,9.70600000,0.13182489,634.17183927,0.12383128,717.77147152,0.00103419,0.14409252,739.81879180,-0.07113873,-0.07295379,0.00000000,0.00000000,0.00000000,0.00000000
186.61000000,3.98109100,9.71100000,0.13334400,634.49852989,0.12517255,719.10510186,0.00095492,0.14554512,741.12637174,-0.07185937,-0.07368575,0.00000000,0.00000000,0.00000000,0.00000000
188.11000000,4.02624800,9.71600000,0.13488522,634.82522052,0.12653152,720.45376146,0.00085607,0.14699576,742.35852074,-0.07256280,-0.07443297,0.00000000,0.00000000,0.00000000,0.00000000
189.61000000,4.07080900,9.72100000,0.13640067,635.15191114,0.12786596,721.78705525,0.00077707,0.14844438,743.59118290,-0.07330740,-0.07513698,0.00000000,0.00000000,0.00000000,0.00000000
191.11000000,4.11536900,9.72500000,0.13795667,635.41326364,0.12923426,723.07275945,0.00080199,0.14995421,744.79517284,-0.07409228,-0.07586193,0.00000000,0.00000000,0.00000000,0.00000000
192.61000000,4.16115500,9.73100000,0.13956767,635.80529239,0.13064895,724.54315350,0.00093605,0.15142999,746.05218833,-0.07480951,-0.07662048,0.00000000,0.00000000,0.00000000,0.00000000
194.11000000,4.20660900,9.73400000,0.14113844,636.00130676,0.13202640,725.76554186,0.00093496,0.15296607,747.35652096,-0.07560865,-0.07735742,0.00000000,0.00000000,0.00000000,0.00000000
195.61000000,4.25226200,9.73800000,0.14274589,636.26265926,0.13343404,727.08653812,0.00097878,0.15446903,748.56143381,-0.07635101,-0.07811802,0.00000000,0.00000000,0.00000000,0.00000000
197.11000000,4.29791500,9.74200000,0.14432389,636.52401176,0.13481397,728.38963251,0.00094537,0.15596962,749.76650637,-0.07708981,-0.07887981,0.00000000,0.00000000,0.00000000,0.00000000
198.61000000,4.34320400,9.74600000,0.14590933,636.78536426,0.13619850,729.69829224,0.00095027,0.15752998,751.09559127,-0.07789098,-0.07963899,0.00000000,0.00000000,0.00000000,0.00000000
200.11000000,4.38945300,9.74900000,0.14749489,636.98137863,0.13758121,730.93287630,0.00082748,0.15908833,752.34834782,-0.07867802,-0.08041032,0.00000000,0.00000000,0.00000000,0.00000000
201.61000000,4.43530500,9.75300000,0.14913544,637.24273113,0.13900987,732.27820906,0.00087099,0.16064415,753.60127365,-0.07940184,-0.08124232,0.00000000,0.00000000,0.00000000,0.00000000
203.11000000,4.48171900,9.75500000,0.15075378,637.37340738,0.14041719,733.45985640,0.00095883,0.16219800,754.77739047,-0.08018434,-0.08201366,0.00000000,0.00000000,0.00000000,0.00000000
204.61000000,4.52799900,9.75900000,0.15240911,637.63475988,0.14185463,734.81610685,0.00089379,0.16378005,756.05426834,-0.08097042,-0.08280963,0.00000000,0.00000000,0.00000000,0.00000000
206.11000000,4.57454800,9.76200000,0.15406433,637.83077426,0.14328991,736.09774727,0.00101984,0.00000000,0.00000000,0.00000000,0.00000000,0.00000000,0.00000000,0.00000000,0.00000000
207.61000000,4.62182300,9.76500000,0.15575656,638.02678863,0.14475516,737.40364358,0.00108241,0.00000000,0.00000000,0.00000000,0.00000000,0.00000000,0.00000000,0.00000000,0.00000000
209.11000000,4.66840100,9.76600000,0.15737511,638.09212676,0.14615461,738.51194610,0.00095392,0.00000000,0.00000000,0.00000000,0.00000000,0.00000000,0.00000000,0.00000000,0.00000000
210.61000000,4.71527700,9.76900000,0.15906711,638.28814113,0.14761547,739.81879180,0.00095253,0.00000000,0.00000000,0.00000000,0.00000000,0.00000000,0.00000000,0.00000000,0.00000000
212.11000000,4.76265200,9.77200000,0.16075922,638.48415550,0.14907429,741.12637174,0.00095133,0.00000000,0.00000000,0.00000000,0.00000000,0.00000000,0.00000000,0.00000000,0.00000000
213.61000000,4.81019100,9.77400000,0.16245111,638.61483175,0.15053080,742.35852074,0.00094956,0.00000000,0.00000000,0.00000000,0.00000000,0.00000000,0.00000000,0.00000000,0.00000000
215.11000000,4.85812800,9.77600000,0.16414311,638.74550800,0.15198529,743.59118290,0.00094780,0.00000000,0.00000000,0.00000000,0.00000000,0.00000000,0.00000000,0.00000000,0.00000000
216.61000000,4.90629600,9.77700000,0.16590878,638.81084613,0.15350085,744.79517284,0.00107298,0.00000000,0.00000000,0.00000000,0.00000000,0.00000000,0.00000000,0.00000000,0.00000000
218.11000000,4.95459600,9.77900000,0.16763767,638.94152238,0.15498262,746.05218833,0.00094553,0.00000000,0.00000000,0.00000000,0.00000000,0.00000000,0.00000000,0.00000000,0.00000000
219.61000000,5.00302900,9.78100000,0.16943989,639.07219863,0.15652491,747.35652096,0.00100662,0.00000000,0.00000000,0.00000000,0.00000000,0.00000000,0.00000000,0.00000000,0.00000000
221.11000000,5.05136400,9.78200000,0.17120556,639.13753675,0.15803361,748.56143381,0.00094265,0.00000000,0.00000000,0.00000000,0.00000000,0.00000000,0.00000000,0.00000000,0.00000000
222.61000000,5.10019500,9.78300000,0.17297111,639.20287488,0.15953994,749.76650637,0.00100378,0.00000000,0.00000000,0.00000000,0.00000000,0.00000000,0.00000000,0.00000000,0.00000000
224.11000000,5.14932500,9.78500000,0.17481022,639.33355113,0.16110662,751.09559127,0.00106447,0.00000000,0.00000000,0.00000000,0.00000000,0.00000000,0.00000000,0.00000000,0.00000000
225.61000000,5.19881700,9.78600000,0.17664944,639.39888925,0.16267095,752.34834782,0.00106319,0.00000000,0.00000000,0.00000000,0.00000000,0.00000000,0.00000000,0.00000000,0.00000000
227.11000000,5.24860600,9.78700000,0.17848856,639.46422738,0.16423273,753.60127365,0.00106153,0.00000000,0.00000000,0.00000000,0.00000000,0.00000000,0.00000000,0.00000000,0.00000000
228.61000000,5.29790200,9.78700000,0.18032778,639.46422738,0.16579218,754.77739047,0.00105969,0.00000000,0.00000000,0.00000000,0.00000000,0.00000000,0.00000000,0.00000000,0.00000000
230.11000000,5.34749500,9.78800000,0.18220378,639.52956550,0.16738030,756.05426834,0.00105838,0.00000000,0.00000000,0.00000000,0.00000000,0.00000000,0.00000000,0.00000000,0.00000000
231.61000000,5.39754900,9.78900000,0.18411644,639.59490363,0.00000000,0.00000000,0.00000000,0.00000000,0.00000000,0.00000000,0.00000000,0.00000000,0.00000000,0.00000000,0.00000000
233.11000000,5.44836700,9.78900000,0.18599244,639.59490363,0.00000000,0.00000000,0.00000000,0.00000000,0.00000000,0.00000000,0.00000000,0.00000000,0.00000000,0.00000000,0.00000000
234.61000000,5.49872000,9.78900000,0.18794189,639.59490363,0.00000000,0.00000000,0.00000000,0.00000000,0.00000000,0.00000000,0.00000000,0.00000000,0.00000000,0.00000000,0.00000000
236.11000000,5.54907400,9.78900000,0.18989144,639.59490363,0.00000000,0.00000000,0.00000000,0.00000000,0.00000000,0.00000000,0.00000000,0.00000000,0.00000000,0.00000000,0.00000000
237.61000000,5.60038800,9.78900000,0.19191467,639.59490363,0.00000000,0.00000000,0.00000000,0.00000000,0.00000000,0.00000000,0.00000000,0.00000000,0.00000000,0.00000000,0.00000000
239.11000000,5.65160100,9.78900000,0.19393778,639.59490363,0.00000000,0.00000000,0.00000000,0.00000000,0.00000000,0.00000000,0.00000000,0.00000000,0.00000000,0.00000000,0.00000000
240.61000000,5.70268300,9.78800000,0.19596089,639.52956550,0.00000000,0.00000000,0.00000000,0.00000000,0.00000000,0.00000000,0.00000000,0.00000000,0.00000000,0.00000000,0.00000000
242.11000000,5.75452800,9.78800000,0.19802067,639.52956550,0.00000000,0.00000000,0.00000000,0.00000000,0.00000000,0.00000000,0.00000000,0.00000000,0.00000000,0.00000000,0.00000000
243.61000000,5.80617300,9.78700000,0.20004389,639.46422738,0.00000000,0.00000000,0.00000000,0.00000000,0.00000000,0.00000000,0.00000000,0.00000000,0.00000000,0.00000000,0.00000000
245.11000000,5.85818100,9.78700000,0.20214044,639.46422738,0.00000000,0.00000000,0.00000000,0.00000000,0.00000000,0.00000000,0.00000000,0.00000000,0.00000000,0.00000000,0.00000000
246.61000000,5.91065300,9.78500000,0.20431078,639.33355113,0.00000000,0.00000000,0.00000000,0.00000000,0.00000000,0.00000000,0.00000000,0.00000000,0.00000000,0.00000000,0.00000000
248.11000000,5.96309100,9.78500000,0.20651778,639.33355113,0.00000000,0.00000000,0.00000000,0.00000000,0.00000000,0.00000000,0.00000000,0.00000000,0.00000000,0.00000000,0.00000000
249.61000000,6.01599300,9.78300000,0.20876156,639.20287488,0.00000000,0.00000000,0.00000000,0.00000000,0.00000000,0.00000000,0.00000000,0.00000000,0.00000000,0.00000000,0.00000000
251.11000000,6.06942700,9.78200000,0.21096878,639.13753675,0.00000000,0.00000000,0.00000000,0.00000000,0.00000000,0.00000000,0.00000000,0.00000000,0.00000000,0.00000000,0.00000000
252.61000000,6.12216300,9.78000000,0.21324911,639.00686050,0.00000000,0.00000000,0.00000000,0.00000000,0.00000000,0.00000000,0.00000000,0.00000000,0.00000000,0.00000000,0.00000000
254.11000000,6.17530000,9.77800000,0.21556678,638.87618425,0.00000000,0.00000000,0.00000000,0.00000000,0.00000000,0.00000000,0.00000000,0.00000000,0.00000000,0.00000000,0.00000000
255.61000000,6.22916300,9.77700000,0.21795744,638.81084613,0.00000000,0.00000000,0.00000000,0.00000000,0.00000000,0.00000000,0.00000000,0.00000000,0.00000000,0.00000000,0.00000000
257.11000000,6.28381800,9.77600000,0.22038544,638.74550800,0.00000000,0.00000000,0.00000000,0.00000000,0.00000000,0.00000000,0.00000000,0.00000000,0.00000000,0.00000000,0.00000000
258.61000000,6.33778100,9.77300000,0.22284967,638.54949363,0.00000000,0.00000000,0.00000000,0.00000000,0.00000000,0.00000000,0.00000000,0.00000000,0.00000000,0.00000000,0.00000000
260.11000000,6.39313200,9.77100000,0.22542467,638.41881738,0.00000000,0.00000000,0.00000000,0.00000000,0.00000000,0.00000000,0.00000000,0.00000000,0.00000000,0.00000000,0.00000000
261.61000000,6.44809000,9.76800000,0.22796267,638.22280301,0.00000000,0.00000000,0.00000000,0.00000000,0.00000000,0.00000000,0.00000000,0.00000000,0.00000000,0.00000000,0.00000000
263.11000000,6.50357400,9.76600000,0.23064789,638.09212676,0.00000000,0.00000000,0.00000000,0.00000000,0.00000000,0.00000000,0.00000000,0.00000000,0.00000000,0.00000000,0.00000000
264.61000000,6.55942100,9.76300000,0.23333300,637.89611238,0.00000000,0.00000000,0.00000000,0.00000000,0.00000000,0.00000000,0.00000000,0.00000000,0.00000000,0.00000000,0.00000000
266.11000000,6.61464000,9.75900000,0.23612867,637.63475988,0.00000000,0.00000000,0.00000000,0.00000000,0.00000000,0.00000000,0.00000000,0.00000000,0.00000000,0.00000000,0.00000000
267.61000000,6.67102000,9.75600000,0.23896100,637.43874551,0.00000000,0.00000000,0.00000000,0.00000000,0.00000000,0.00000000,0.00000000,0.00000000,0.00000000,0.00000000,0.00000000
269.11000000,6.72769800,9.75300000,0.24183011,637.24273113,0.00000000,0.00000000,0.00000000,0.00000000,0.00000000,0.00000000,0.00000000,0.00000000,0.00000000,0.00000000,0.00000000
270.61000000,6.78490300,9.74900000,0.24484644,636.98137863,0.00000000,0.00000000,0.00000000,0.00000000,0.00000000,0.00000000,0.00000000,0.00000000,0.00000000,0.00000000,0.00000000
272.11000000,6.84137900,9.74500000,0.24793622,636.72002614,0.00000000,0.00000000,0.00000000,0.00000000,0.00000000,0.00000000,0.00000000,0.00000000,0.00000000,0.00000000,0.00000000
273.61000000,6.89825500,9.74000000,0.25106289,636.39333551,0.00000000,0.00000000,0.00000000,0.00000000,0.00000000,0.00000000,0.00000000,0.00000000,0.00000000,0.00000000,0.00000000
275.11000000,6.95589200,9.73600000,0.25429978,636.13198301,0.00000000,0.00000000,0.00000000,0.00000000,0.00000000,0.00000000,0.00000000,0.00000000,0.00000000,0.00000000,0.00000000
276.61000000,7.01369600,9.73100000,0.25761044,635.80529239,0.00000000,0.00000000,0.00000000,0.00000000,0.00000000,0.00000000,0.00000000,0.00000000,0.00000000,0.00000000,0.00000000
278.11000000,7.07172900,9.72600000,0.26103133,635.47860176,0.00000000,0.00000000,0.00000000,0.00000000,0.00000000,0.00000000,0.00000000,0.00000000,0.00000000,0.00000000,0.00000000
279.61000000,7.12929800,9.72100000,0.26459933,635.15191114,0.00000000,0.00000000,0.00000000,0.00000000,0.00000000,0.00000000,0.00000000,0.00000000,0.00000000,0.00000000,0.00000000
281.11000000,7.18835800,9.71400000,0.26824078,634.69454427,0.00000000,0.00000000,0.00000000,0.00000000,0.00000000,0.00000000,0.00000000,0.00000000,0.00000000,0.00000000,0.00000000
282.61000000,7.24708700,9.70800000,0.27202944,634.30251552,0.00000000,0.00000000,0.00000000,0.00000000,0.00000000,0.00000000,0.00000000,0.00000000,0.00000000,0.00000000,0.00000000
284.11000000,7.30581700,9.70000000,0.27589211,633.77981052,0.00000000,0.00000000,0.00000000,0.00000000,0.00000000,0.00000000,0.00000000,0.00000000,0.00000000,0.00000000,0.00000000
285.61000000,7.36441300,9.69300000,0.27993822,633.32244365,0.00000000,0.00000000,0.00000000,0.00000000,0.00000000,0.00000000,0.00000000,0.00000000,0.00000000,0.00000000,0.00000000
287.11000000,7.42350400,9.68400000,0.28394756,632.73440052,0.00000000,0.00000000,0.00000000,0.00000000,0.00000000,0.00000000,0.00000000,0.00000000,0.00000000,0.00000000,0.00000000
288.61000000,7.48332500,9.67600000,0.28821444,632.21169552,0.00000000,0.00000000,0.00000000,0.00000000,0.00000000,0.00000000,0.00000000,0.00000000,0.00000000,0.00000000,0.00000000
290.11000000,7.54298100,9.66700000,0.29270189,631.62365240,0.00000000,0.00000000,0.00000000,0.00000000,0.00000000,0.00000000,0.00000000,0.00000000,0.00000000,0.00000000,0.00000000
291.61000000,7.60273600,9.65500000,0.29726311,630.83959490,0.00000000,0.00000000,0.00000000,0.00000000,0.00000000,0.00000000,0.00000000,0.00000000,0.00000000,0.00000000,0.00000000
293.11000000,7.66242400,9.64500000,0.30193478,630.18621366,0.00000000,0.00000000,0.00000000,0.00000000,0.00000000,0.00000000,0.00000000,0.00000000,0.00000000,0.00000000,0.00000000
294.61000000,7.72270800,9.63200000,0.30675333,629.33681803,0.00000000,0.00000000,0.00000000,0.00000000,0.00000000,0.00000000,0.00000000,0.00000000,0.00000000,0.00000000,0.00000000
296.11000000,7.78302600,9.61900000,0.31168244,628.48742241,0.00000000,0.00000000,0.00000000,0.00000000,0.00000000,0.00000000,0.00000000,0.00000000,0.00000000,0.00000000,0.00000000
297.61000000,7.84337500,9.60400000,0.31675856,627.50735054,0.00000000,0.00000000,0.00000000,0.00000000,0.00000000,0.00000000,0.00000000,0.00000000,0.00000000,0.00000000,0.00000000
299.11000000,7.90342800,9.59000000,0.32190844,626.59261679,0.00000000,0.00000000,0.00000000,0.00000000,0.00000000,0.00000000,0.00000000,0.00000000,0.00000000,0.00000000,0.00000000
300.61000000,7.96463800,9.57200000,0.32731567,625.41653055,0.00000000,0.00000000,0.00000000,0.00000000,0.00000000,0.00000000,0.00000000,0.00000000,0.00000000,0.00000000,0.00000000
302.11000000,8.02624700,9.55600000,0.33283322,624.37112055,0.00000000,0.00000000,0.00000000,0.00000000,0.00000000,0.00000000,0.00000000,0.00000000,0.00000000,0.00000000,0.00000000
303.61000000,8.08778800,9.53500000,0.33838756,622.99901993,0.00000000,0.00000000,0.00000000,0.00000000,0.00000000,0.00000000,0.00000000,0.00000000,0.00000000,0.00000000,0.00000000
305.11000000,8.14880000,9.51500000,0.34408900,621.69225743,0.00000000,0.00000000,0.00000000,0.00000000,0.00000000,0.00000000,0.00000000,0.00000000,0.00000000,0.00000000,0.00000000
306.61000000,8.21011300,9.48900000,0.34986433,619.99346619,0.00000000,0.00000000,0.00000000,0.00000000,0.00000000,0.00000000,0.00000000,0.00000000,0.00000000,0.00000000,0.00000000
308.11000000,8.27162300,9.46800000,0.35586011,618.62136557,0.00000000,0.00000000,0.00000000,0.00000000,0.00000000,0.00000000,0.00000000,0.00000000,0.00000000,0.00000000,0.00000000
309.61000000,8.33300000,9.44000000,0.36181922,616.79189807,0.00000000,0.00000000,0.00000000,0.00000000,0.00000000,0.00000000,0.00000000,0.00000000,0.00000000,0.00000000,0.00000000
311.11000000,8.39517300,9.41300000,0.36799911,615.02776870,0.00000000,0.00000000,0.00000000,0.00000000,0.00000000,0.00000000,0.00000000,0.00000000,0.00000000,0.00000000,0.00000000
312.61000000,8.45724600,9.38200000,0.37428944,613.00228683,0.00000000,0.00000000,0.00000000,0.00000000,0.00000000,0.00000000,0.00000000,0.00000000,0.00000000,0.00000000,0.00000000
314.11000000,8.51931800,9.35300000,0.38057956,611.10748122,0.00000000,0.00000000,0.00000000,0.00000000,0.00000000,0.00000000,0.00000000,0.00000000,0.00000000,0.00000000,0.00000000
315.61000000,8.58222000,9.31500000,0.38709044,608.62463247,0.00000000,0.00000000,0.00000000,0.00000000,0.00000000,0.00000000,0.00000000,0.00000000,0.00000000,0.00000000,0.00000000
317.11000000,8.64402800,9.27900000,0.39360133,606.27245998,0.00000000,0.00000000,0.00000000,0.00000000,0.00000000,0.00000000,0.00000000,0.00000000,0.00000000,0.00000000,0.00000000
318.61000000,8.70626800,9.24100000,0.40025944,603.78961124,0.00000000,0.00000000,0.00000000,0.00000000,0.00000000,0.00000000,0.00000000,0.00000000,0.00000000,0.00000000,0.00000000
320.11000000,8.76963200,9.20300000,0.40699111,601.30676250,0.00000000,0.00000000,0.00000000,0.00000000,0.00000000,0.00000000,0.00000000,0.00000000,0.00000000,0.00000000,0.00000000
321.61000000,8.83240200,9.15200000,0.41387011,597.97451813,0.00000000,0.00000000,0.00000000,0.00000000,0.00000000,0.00000000,0.00000000,0.00000000,0.00000000,0.00000000,0.00000000
323.11000000,8.89593400,9.10800000,0.42074922,595.09964064,0.00000000,0.00000000,0.00000000,0.00000000,0.00000000,0.00000000,0.00000000,0.00000000,0.00000000,0.00000000,0.00000000
324.61000000,8.95887300,9.04700000,0.42773889,591.11401503,0.00000000,0.00000000,0.00000000,0.00000000,0.00000000,0.00000000,0.00000000,0.00000000,0.00000000,0.00000000,0.00000000
326.11000000,9.02283900,8.99500000,0.43483900,587.71643254,0.00000000,0.00000000,0.00000000,0.00000000,0.00000000,0.00000000,0.00000000,0.00000000,0.00000000,0.00000000,0.00000000
327.61000000,9.08687200,8.92600000,0.44201322,583.20810193,0.00000000,0.00000000,0.00000000,0.00000000,0.00000000,0.00000000,0.00000000,0.00000000,0.00000000,0.00000000,0.00000000
329.11000000,9.15160500,8.85500000,0.44918756,578.56909507,0.00000000,0.00000000,0.00000000,0.00000000,0.00000000,0.00000000,0.00000000,0.00000000,0.00000000,0.00000000,0.00000000
330.61000000,9.21693400,8.76800000,0.45658322,572.88467821,0.00000000,0.00000000,0.00000000,0.00000000,0.00000000,0.00000000,0.00000000,0.00000000,0.00000000,0.00000000,0.00000000
332.11000000,9.28336000,8.68400000,0.46405300,567.39627573,0.00000000,0.00000000,0.00000000,0.00000000,0.00000000,0.00000000,0.00000000,0.00000000,0.00000000,0.00000000,0.00000000
333.61000000,9.35174500,8.56100000,0.47185522,559.35968638,0.00000000,0.00000000,0.00000000,0.00000000,0.00000000,0.00000000,0.00000000,0.00000000,0.00000000,0.00000000,0.00000000
335.11000000,9.42222200,8.44400000,0.47987922,551.71512578,0.00000000,0.00000000,0.00000000,0.00000000,0.00000000,0.00000000,0.00000000,0.00000000,0.00000000,0.00000000,0.00000000
336.61000000,9.49820600,8.27900000,0.48845722,540.93433518,0.00000000,0.00000000,0.00000000,0.00000000,0.00000000,0.00000000,0.00000000,0.00000000,0.00000000,0.00000000,0.00000000
337.11000000,9.52510400,8.22200000,0.49154967,537.21006207,0.00000000,0.00000000,0.00000000,0.00000000,0.00000000,0.00000000,0.00000000,0.00000000,0.00000000,0.00000000,0.00000000