File: polyN_optimization/results_exp/DP600/UT_90_2.csv
Time[s],Displacement[mm],Force[kN],EngStrain_longi,EngStress[MPa],TrueStrain,TrueStress[MPa],TrueStrainRate[1/s],PlasticStrain_longi,PlasticStress[MPa],PlasticStrain_thick,PlasticStrain_width,R-Value,Thickness[mm],Width[mm], Young's Modulus [MPa]
0.64000000,0.00000000,-0.01500000,0.00000000,-0.98135427,0.00000000,-0.98135427,0.00000000,0.00061316,339.78245735,0.00020784,-0.00082101,1.05731357,1.52850000,10.00000000,234630.35826721
2.14000000,0.00153600,0.01000000,0.00004056,0.65423618,0.00004055,0.65426271,-0.00001489,0.00097568,353.96657775,0.00026028,-0.00123596,0.00000000,0.00000000,0.00000000,0.00000000
3.64000000,0.00326400,0.43500000,0.00009567,28.45927380,0.00009566,28.46199640,0.00003155,0.00146475,370.05054906,0.00015836,-0.00162311,0.00000000,0.00000000,0.00000000,0.00000000
5.14000000,0.00611100,0.74600000,0.00018800,48.80601897,0.00018798,48.81519450,0.00008621,0.00215409,381.68957784,-0.00022341,-0.00193068,0.00000000,0.00000000,0.00000000,0.00000000
6.64000000,0.00792600,1.10200000,0.00025744,72.09682695,0.00025741,72.11538788,0.00005221,0.00281092,393.85980289,-0.00058358,-0.00222734,0.00000000,0.00000000,0.00000000,0.00000000
8.14000000,0.00943900,1.41100000,0.00030711,92.31272489,0.00030706,92.34107516,0.00004332,0.00352058,403.30062511,-0.00091589,-0.00260469,0.00000000,0.00000000,0.00000000,0.00000000
9.64000000,0.01147100,1.77400000,0.00034578,116.06149820,0.00034572,116.10162969,-0.00000600,0.00428205,414.03024498,-0.00121127,-0.00307078,0.00000000,0.00000000,0.00000000,0.00000000
11.14000000,0.01382900,2.10900000,0.00045289,137.97841021,0.00045279,138.04089909,-0.00002266,0.00519873,421.93780190,-0.00163483,-0.00356390,0.00000000,0.00000000,0.00000000,0.00000000
12.64000000,0.01711000,2.46600000,0.00056244,161.33464181,0.00056229,161.42538358,-0.00009928,0.00611604,431.05010115,-0.00214097,-0.00397507,0.00000000,0.00000000,0.00000000,0.00000000
14.14000000,0.02058000,2.79700000,0.00072389,182.98985934,0.00072363,183.12232367,0.00015878,0.00692613,437.94917758,-0.00250417,-0.00442196,0.00000000,0.00000000,0.00000000,0.00000000
15.64000000,0.02407200,3.12700000,0.00084311,204.57965325,0.00084276,204.75213663,0.00032420,0.00779702,445.68129909,-0.00297081,-0.00482621,0.00000000,0.00000000,0.00000000,0.00000000
17.14000000,0.02691700,3.45200000,0.00090056,225.84232908,0.00090015,226.04571264,0.00030419,0.00873144,452.13035162,-0.00344209,-0.00528934,0.00000000,0.00000000,0.00000000,0.00000000
18.64000000,0.03009000,3.79400000,0.00097778,248.21720641,0.00097730,248.45990768,0.00019471,0.00976128,459.69700661,-0.00396454,-0.00579674,0.00000000,0.00000000,0.00000000,0.00000000
20.14000000,0.03463200,4.10700000,0.00104111,268.69479882,0.00104057,268.97453996,-0.00001465,0.01067777,465.69857064,-0.00431195,-0.00636582,0.00000000,0.00000000,0.00000000,0.00000000
21.64000000,0.04135600,4.43300000,0.00122156,290.02289827,0.00122081,290.37717735,-0.00018355,0.01156640,472.76165590,-0.00468698,-0.00687943,0.00000000,0.00000000,0.00000000,0.00000000
23.14000000,0.04910700,4.72000000,0.00154544,308.79947661,0.00154425,309.27670905,-0.00021299,0.01257369,478.36371932,-0.00521201,-0.00736168,0.00000000,0.00000000,0.00000000,0.00000000
24.64000000,0.05881300,5.01000000,0.00200533,327.77232581,0.00200333,328.42961858,0.00016900,0.01358431,484.51151073,-0.00578922,-0.00779509,0.00000000,0.00000000,0.00000000,0.00000000
26.14000000,0.07263000,5.23700000,0.00247667,342.62348708,0.00247360,343.47205125,0.00048486,0.01454045,489.71112129,-0.00629067,-0.00824978,0.00000000,0.00000000,0.00000000,0.00000000
27.64000000,0.08853200,5.48000000,0.00297767,358.52142623,0.00297324,359.58898354,0.00062402,0.01548027,495.84701218,-0.00668898,-0.00879129,0.00000000,0.00000000,0.00000000,0.00000000
29.14000000,0.10572900,5.68300000,0.00350822,371.80242067,0.00350208,373.10678619,0.00055037,0.01650073,500.76516493,-0.00716139,-0.00933933,0.00000000,0.00000000,0.00000000,0.00000000
30.64000000,0.12690400,5.87800000,0.00421144,384.56002617,0.00420260,386.17957936,0.00046189,0.01751180,506.62493474,-0.00757313,-0.00993867,0.00000000,0.00000000,0.00000000,0.00000000
32.14000000,0.14880600,6.03900000,0.00505078,395.09322866,0.00503807,397.08875675,0.00070324,0.01852126,511.15609921,-0.00807358,-0.01044768,0.00000000,0.00000000,0.00000000,0.00000000
33.64000000,0.17477700,6.19500000,0.00589378,405.29931305,0.00587648,407.68805714,0.00087084,0.01949781,516.28244277,-0.00850876,-0.01098905,0.00000000,0.00000000,0.00000000,0.00000000
35.14000000,0.19982400,6.31800000,0.00671122,413.34641806,0.00668880,416.12047772,0.00087035,0.02050974,520.56460687,-0.00903078,-0.01147895,0.00000000,0.00000000,0.00000000,0.00000000
36.64000000,0.22599600,6.44700000,0.00756911,421.78606477,0.00754061,424.97861036,0.00066530,0.02159172,525.76538175,-0.00962630,-0.01196542,0.00000000,0.00000000,0.00000000,0.00000000
38.14000000,0.25385500,6.56000000,0.00849656,429.17893360,0.00846066,432.82547625,0.00058401,0.02262026,529.87246523,-0.01013774,-0.01248252,0.00000000,0.00000000,0.00000000,0.00000000
39.64000000,0.28240500,6.67400000,0.00947911,436.63722604,0.00943447,440.77615882,0.00084572,0.02364101,534.65674376,-0.01059151,-0.01304950,0.00000000,0.00000000,0.00000000,0.00000000
41.14000000,0.30969400,6.77500000,0.01039544,443.24501145,0.01034178,447.85274034,0.00084495,0.02474687,538.62018045,-0.01110847,-0.01363839,0.00000000,0.00000000,0.00000000,0.00000000
42.64000000,0.33966400,6.87900000,0.01128233,450.04906771,0.01121916,455.12667131,0.00066945,0.02583539,542.91987130,-0.01160981,-0.01422558,0.00000000,0.00000000,0.00000000,0.00000000
44.14000000,0.36817700,6.96400000,0.01227222,455.61007524,0.01219753,461.20142333,0.00049444,0.02688292,546.59795861,-0.01207196,-0.01481096,0.00000000,0.00000000,0.00000000,0.00000000
45.64000000,0.39794900,7.06100000,0.01333944,461.95616618,0.01325126,468.11840479,0.00071175,0.02795101,550.97095116,-0.01259631,-0.01535470,0.00000000,0.00000000,0.00000000,0.00000000
47.14000000,0.42792200,7.14600000,0.01430378,467.51717370,0.01420244,474.20443546,0.00076959,0.02908959,554.51184277,-0.01319858,-0.01589101,0.00000000,0.00000000,0.00000000,0.00000000
48.64000000,0.45878700,7.23500000,0.01525311,473.33987570,0.01513795,480.55978141,0.00057268,0.03013501,558.61814333,-0.01364241,-0.01649260,0.00000000,0.00000000,0.00000000,0.00000000
50.14000000,0.48815900,7.31300000,0.01623933,478.44291789,0.01610889,486.21251192,0.00043477,0.03121129,562.00354055,-0.01418109,-0.01703021,0.00000000,0.00000000,0.00000000,0.00000000
51.64000000,0.51938500,7.39400000,0.01731011,483.74223095,0.01716200,492.11586271,0.00057917,0.03231728,565.61633843,-0.01474599,-0.01757129,0.00000000,0.00000000,0.00000000,0.00000000
53.14000000,0.55060900,7.46200000,0.01834756,488.19103696,0.01818127,497.14814914,0.00067965,0.03345543,568.91484394,-0.01531491,-0.01814053,0.00000000,0.00000000,0.00000000,0.00000000
54.64000000,0.58176900,7.53900000,0.01934811,493.22865554,0.01916332,502.77169838,0.00055599,0.03457940,572.68876022,-0.01586194,-0.01871746,0.00000000,0.00000000,0.00000000,0.00000000
56.14000000,0.61398600,7.60600000,0.02039289,497.61203795,0.02018774,507.75978495,0.00052688,0.03565228,575.69116139,-0.01638502,-0.01926726,0.00000000,0.00000000,0.00000000,0.00000000
57.64000000,0.64504500,7.67600000,0.02146711,502.19169120,0.02123994,512.97229603,0.00056920,0.03678131,579.34627907,-0.01693573,-0.01984559,0.00000000,0.00000000,0.00000000,0.00000000
59.14000000,0.67749700,7.73900000,0.02255600,506.31337913,0.02230538,517.73378371,0.00069815,0.03791598,582.26070403,-0.01748249,-0.02043349,0.00000000,0.00000000,0.00000000,0.00000000
60.64000000,0.70991300,7.80500000,0.02362667,510.63133791,0.02335188,522.69585432,0.00072653,0.03904736,585.58960375,-0.01803223,-0.02101513,0.00000000,0.00000000,0.00000000,0.00000000
62.14000000,0.74259600,7.85800000,0.02472644,514.09878966,0.02442569,526.81062482,0.00066066,0.04015515,588.43205775,-0.01855825,-0.02159690,0.00000000,0.00000000,0.00000000,0.00000000
63.64000000,0.77590600,7.91900000,0.02585222,518.08963036,0.02552370,531.48339861,0.00076049,0.04134049,591.73757729,-0.01918238,-0.02215811,0.00000000,0.00000000,0.00000000,0.00000000
65.14000000,0.80878500,7.97400000,0.02692633,521.68792934,0.02657020,535.73507242,0.00076640,0.04247031,594.53653157,-0.01972253,-0.02274779,0.00000000,0.00000000,0.00000000,0.00000000
66.64000000,0.84259300,8.03100000,0.02804856,525.41707556,0.02766240,540.15426560,0.00070134,0.04359696,597.75160090,-0.02026657,-0.02333039,0.00000000,0.00000000,0.00000000,0.00000000
68.14000000,0.87642900,8.08200000,0.02919256,528.75368008,0.02877457,544.18935126,0.00070769,0.04475658,600.37384146,-0.02086267,-0.02389391,0.00000000,0.00000000,0.00000000,0.00000000
69.64000000,0.91036700,8.13400000,0.03033311,532.15570821,0.02988216,548.29764644,0.00079278,0.04592101,603.21100724,-0.02141547,-0.02450554,0.00000000,0.00000000,0.00000000,0.00000000
71.14000000,0.94384000,8.17800000,0.03144422,535.03434740,0.03095998,551.85808632,0.00077059,0.04707132,605.76956772,-0.02200789,-0.02506344,0.00000000,0.00000000,0.00000000,0.00000000
72.64000000,0.97834000,8.22800000,0.03257356,538.30552830,0.03205428,555.84005333,0.00064832,0.04818660,608.79527288,-0.02248472,-0.02570188,0.00000000,0.00000000,0.00000000,0.00000000
74.14000000,1.01247700,8.27300000,0.03371767,541.24959110,0.03316169,559.49926440,0.00073320,0.04938680,611.25694036,-0.02306445,-0.02632236,0.00000000,0.00000000,0.00000000,0.00000000
75.64000000,1.04734000,8.31900000,0.03488756,544.25907753,0.03429278,563.24694633,0.00081056,0.05056307,614.12428751,-0.02364328,-0.02691980,0.00000000,0.00000000,0.00000000,0.00000000
77.14000000,1.08190600,8.36100000,0.03603178,547.00686948,0.03539782,566.71649944,0.00077426,0.05175741,616.52365775,-0.02419581,-0.02756159,0.00000000,0.00000000,0.00000000,0.00000000
78.64000000,1.11686800,8.40600000,0.03720167,549.95093229,0.03652638,570.41002355,0.00072366,0.05292163,619.11740530,-0.02478307,-0.02813856,0.00000000,0.00000000,0.00000000,0.00000000
80.14000000,1.15209600,8.44200000,0.03839722,552.30618253,0.03767839,573.51320576,0.00074381,0.05408868,621.50977520,-0.02536280,-0.02872587,0.00000000,0.00000000,0.00000000,0.00000000
81.64000000,1.18689500,8.48200000,0.03957444,554.92312725,0.03881144,576.88390172,0.00083556,0.05526766,624.05351857,-0.02593670,-0.02933096,0.00000000,0.00000000,0.00000000,0.00000000
83.14000000,1.22215400,8.52000000,0.04069278,557.40922473,0.03988662,580.09175444,0.00069303,0.05642576,626.31078672,-0.02648183,-0.02994393,0.00000000,0.00000000,0.00000000,0.00000000
84.64000000,1.25807600,8.55900000,0.04195822,559.96074583,0.04110185,583.45570324,0.00082639,0.05764309,628.88872476,-0.02713889,-0.03050420,0.00000000,0.00000000,0.00000000,0.00000000
86.14000000,1.29373300,8.59500000,0.04312811,562.31599607,0.04222400,586.56762283,0.00077624,0.05883326,631.10583957,-0.02769971,-0.03113355,0.00000000,0.00000000,0.00000000,0.00000000
87.64000000,1.32972300,8.63200000,0.04430878,564.73666994,0.04335521,589.75946155,0.00079601,0.06002464,633.46793789,-0.02829804,-0.03172660,0.00000000,0.00000000,0.00000000,0.00000000
89.14000000,1.36607700,8.66200000,0.04550444,566.69937848,0.04449949,592.48671886,0.00068240,0.06121555,635.62459512,-0.02889571,-0.03231984,0.00000000,0.00000000,0.00000000,0.00000000
90.64000000,1.40213000,8.69700000,0.04675144,568.98920510,0.04569151,595.59027231,0.00078013,0.06241803,637.93306241,-0.02946517,-0.03295286,0.00000000,0.00000000,0.00000000,0.00000000
92.14000000,1.43884800,8.72900000,0.04795811,571.08276088,0.04684361,598.47081138,0.00080045,0.06361671,640.03332615,-0.03006485,-0.03355186,0.00000000,0.00000000,0.00000000,0.00000000
93.64000000,1.47543200,8.76100000,0.04915356,573.17631665,0.04798370,601.34997057,0.00073639,0.06482956,642.42781085,-0.03062755,-0.03420201,0.00000000,0.00000000,0.00000000,0.00000000
95.14000000,1.51168600,8.79000000,0.05038589,575.07360157,0.04915761,604.04919616,0.00072833,0.06603299,644.32888658,-0.03120595,-0.03482704,0.00000000,0.00000000,0.00000000,0.00000000
96.64000000,1.54933100,8.82200000,0.05162200,577.16715734,0.05033373,606.96168034,0.00075559,0.06726788,646.53566765,-0.03182657,-0.03544131,0.00000000,0.00000000,0.00000000,0.00000000
98.14000000,1.58604800,8.84800000,0.05285433,578.86817141,0.05150489,609.46386270,0.00083853,0.06845699,648.64667888,-0.03242846,-0.03602854,0.00000000,0.00000000,0.00000000,0.00000000
99.64000000,1.62329400,8.87700000,0.05407933,580.76545633,0.05266772,612.17286503,0.00074033,0.06963840,650.68622792,-0.03295319,-0.03668521,0.00000000,0.00000000,0.00000000,0.00000000
101.14000000,1.66070600,8.90400000,0.05534822,582.53189401,0.05387078,614.77399874,0.00076661,0.07088365,652.63019658,-0.03359522,-0.03728842,0.00000000,0.00000000,0.00000000,0.00000000
102.64000000,1.69765300,8.93100000,0.05661389,584.29833170,0.05506935,617.37773253,0.00075223,0.07209253,654.69566294,-0.03416362,-0.03792891,0.00000000,0.00000000,0.00000000,0.00000000
104.14000000,1.73559400,8.95700000,0.05785344,585.99934576,0.05624180,619.90142636,0.00074399,0.07331095,656.62980896,-0.03474453,-0.03856642,0.00000000,0.00000000,0.00000000,0.00000000
105.64000000,1.77350400,8.98300000,0.05911156,587.70035983,0.05743040,622.44024230,0.00076431,0.07455761,658.72825498,-0.03536068,-0.03919693,0.00000000,0.00000000,0.00000000,0.00000000
107.14000000,1.81114600,9.00500000,0.06041000,589.13967942,0.05865563,624.72960746,0.00083256,0.07579728,660.54222898,-0.03594843,-0.03984885,0.00000000,0.00000000,0.00000000,0.00000000
108.64000000,1.84928500,9.03200000,0.06166444,590.90611711,0.05983791,627.34401454,0.00085942,0.07704155,662.50499988,-0.03654589,-0.04049566,0.00000000,0.00000000,0.00000000,0.00000000
110.14000000,1.88762300,9.05200000,0.06295189,592.21458947,0.06104984,629.49561650,0.00082408,0.07827484,664.25074741,-0.03716386,-0.04111098,0.00000000,0.00000000,0.00000000,0.00000000
111.64000000,1.92572900,9.07700000,0.06425033,593.85017991,0.06227064,632.00525192,0.00086423,0.07953279,666.23016847,-0.03777443,-0.04175836,0.00000000,0.00000000,0.00000000,0.00000000
113.14000000,1.96390100,9.09600000,0.06551200,595.09322866,0.06345543,634.07897625,0.00082857,0.08077333,667.98774584,-0.03839795,-0.04237538,0.00000000,0.00000000,0.00000000,0.00000000
114.64000000,2.00220800,9.11900000,0.06675556,596.59797187,0.06462185,636.42420092,0.00075904,0.08201868,669.82338524,-0.03899489,-0.04302379,0.00000000,0.00000000,0.00000000,0.00000000
116.14000000,2.04084200,9.13800000,0.06807244,597.84102061,0.06585557,638.53752027,0.00079952,0.08328236,671.67494046,-0.03960790,-0.04367446,0.00000000,0.00000000,0.00000000,0.00000000
117.64000000,2.07954500,9.16100000,0.06938544,599.34576382,0.06708413,640.93163602,0.00083929,0.08454170,673.45555532,-0.04025278,-0.04428892,0.00000000,0.00000000,0.00000000,0.00000000
119.14000000,2.11834600,9.17900000,0.07066933,600.52338894,0.06828400,642.96197649,0.00079052,0.08577626,675.15108669,-0.04080374,-0.04497252,0.00000000,0.00000000,0.00000000,0.00000000
120.64000000,2.15734700,9.19900000,0.07193833,601.83186130,0.06946854,645.12664235,0.00073463,0.08705568,676.95210138,-0.04149598,-0.04555970,0.00000000,0.00000000,0.00000000,0.00000000
122.14000000,2.19664400,9.21500000,0.07328833,602.87863919,0.07072714,647.06260986,0.00076105,0.08830056,678.58927554,-0.04207319,-0.04622737,0.00000000,0.00000000,0.00000000,0.00000000
123.64000000,2.23561000,9.23700000,0.07459789,604.31795878,0.07194653,649.39880273,0.00080149,0.08956024,680.38363680,-0.04267034,-0.04688990,0.00000000,0.00000000,0.00000000,0.00000000
125.14000000,2.27530400,9.25200000,0.07588533,605.29931305,0.07314389,651.23265319,0.00081397,0.09082901,681.97135516,-0.04327642,-0.04755259,0.00000000,0.00000000,0.00000000,0.00000000
126.64000000,2.31430500,9.27100000,0.07723156,606.54236179,0.07439438,653.38657190,0.00080593,0.09209257,683.63066642,-0.04387299,-0.04821958,0.00000000,0.00000000,0.00000000,0.00000000
128.14000000,2.35413100,9.28600000,0.07858889,607.52371606,0.07565360,655.26832988,0.00088695,0.09339111,685.31715320,-0.04449058,-0.04890053,0.00000000,0.00000000,0.00000000,0.00000000
129.64000000,2.39405800,9.30400000,0.07990211,608.70134118,0.07687040,657.33786338,0.00086529,0.09467800,686.99885816,-0.04511415,-0.04956384,0.00000000,0.00000000,0.00000000,0.00000000
131.14000000,2.43425000,9.31900000,0.08125589,609.68269545,0.07812323,659.22300481,0.00085762,0.09597061,688.54275979,-0.04575228,-0.05021832,0.00000000,0.00000000,0.00000000,0.00000000
132.64000000,2.47417700,9.33600000,0.08261311,610.79489696,0.07937767,661.25456365,0.00086990,0.09723774,690.14446712,-0.04635827,-0.05087947,0.00000000,0.00000000,0.00000000,0.00000000
134.14000000,2.51479700,9.34900000,0.08397411,611.64540399,0.08063402,663.00778311,0.00087537,0.09848058,691.65961799,-0.04696563,-0.05151495,0.00000000,0.00000000,0.00000000,0.00000000
135.64000000,2.55505400,9.36600000,0.08531678,612.75760550,0.08187191,665.03610996,0.00086793,0.09974163,693.19015466,-0.04757464,-0.05216698,0.00000000,0.00000000,0.00000000,0.00000000
137.14000000,2.59521400,9.37900000,0.08665956,613.60811253,0.08310836,666.78311885,0.00080610,0.10106018,694.83641589,-0.04825978,-0.05280040,0.00000000,0.00000000,0.00000000,0.00000000
138.64000000,2.63593200,9.39300000,0.08802789,614.52404318,0.08436678,668.61929737,0.00082511,0.10236804,696.25949060,-0.04888598,-0.05348206,0.00000000,0.00000000,0.00000000,0.00000000
140.14000000,2.67665500,9.40600000,0.08939633,615.37455021,0.08562372,670.38677863,0.00083081,0.10364393,697.80883498,-0.04947780,-0.05416612,0.00000000,0.00000000,0.00000000,0.00000000
141.64000000,2.71823400,9.42100000,0.09076100,616.35590448,0.08687562,672.29698273,0.00078961,0.10498464,699.26020829,-0.05015828,-0.05482636,0.00000000,0.00000000,0.00000000,0.00000000
143.14000000,2.75879000,9.43200000,0.09215133,617.07556428,0.08814945,673.93990029,0.00080164,0.10628319,700.90433682,-0.05080407,-0.05547912,0.00000000,0.00000000,0.00000000,0.00000000
144.64000000,2.80014000,9.44600000,0.09352356,617.99149493,0.08940510,675.78825684,0.00082767,0.10759113,702.26482115,-0.05146113,-0.05613000,0.00000000,0.00000000,0.00000000,0.00000000
146.14000000,2.84119100,9.45700000,0.09492878,618.71115473,0.09068932,677.44464844,0.00082011,0.10890001,703.77522473,-0.05205298,-0.05684703,0.00000000,0.00000000,0.00000000,0.00000000
147.64000000,2.88254100,9.47000000,0.09630433,619.56166176,0.09194483,679.22813455,0.00082577,0.11022000,705.29626240,-0.05268655,-0.05753345,0.00000000,0.00000000,0.00000000,0.00000000
149.14000000,2.92395500,9.48100000,0.09773878,620.28132156,0.09325241,680.90685980,0.00090449,0.11153216,706.74091528,-0.05331194,-0.05822022,0.00000000,0.00000000,0.00000000,0.00000000
150.64000000,2.96576700,9.49200000,0.09914400,621.00098135,0.09453170,682.56950265,0.00091041,0.11283652,708.10888322,-0.05395088,-0.05888564,0.00000000,0.00000000,0.00000000,0.00000000
152.14000000,3.00767900,9.50200000,0.10055667,621.65521753,0.09581611,684.16679402,0.00093631,0.11418139,709.50807519,-0.05461341,-0.05956798,0.00000000,0.00000000,0.00000000,0.00000000
153.64000000,3.04892900,9.51400000,0.10196533,622.44030095,0.09709525,685.90763371,0.00088145,0.11552742,710.98452915,-0.05526151,-0.06026592,0.00000000,0.00000000,0.00000000,0.00000000
155.14000000,3.09163700,9.52300000,0.10336322,623.02911351,0.09836299,687.42741022,0.00082714,0.11687203,712.31459858,-0.05592533,-0.06094670,0.00000000,0.00000000,0.00000000,0.00000000
156.64000000,3.13417600,9.53400000,0.10472422,623.74877331,0.09959573,689.07037845,0.00069270,0.11822152,713.72460408,-0.05659001,-0.06163151,0.00000000,0.00000000,0.00000000,0.00000000
158.14000000,3.17575600,9.54300000,0.10615489,624.33758587,0.10088994,690.61407293,0.00073160,0.11952990,715.10763494,-0.05719247,-0.06233743,0.00000000,0.00000000,0.00000000,0.00000000
159.64000000,3.21770100,9.55200000,0.10761167,624.92639843,0.10220605,692.17576971,0.00086371,0.12087304,716.36940210,-0.05785343,-0.06301961,0.00000000,0.00000000,0.00000000,0.00000000
161.14000000,3.26083700,9.56100000,0.10906456,625.51521099,0.10351692,693.73674947,0.00094877,0.12223209,717.94248339,-0.05849293,-0.06373917,0.00000000,0.00000000,0.00000000,0.00000000
162.64000000,3.30354300,9.57000000,0.11052111,626.10402355,0.10482937,695.30173591,0.00092090,0.12362306,719.24341517,-0.05920389,-0.06441918,0.00000000,0.00000000,0.00000000,0.00000000
164.14000000,3.34651300,9.57900000,0.11198511,626.69283611,0.10614681,696.87310300,0.00092649,0.12497647,720.59407589,-0.05985671,-0.06511976,0.00000000,0.00000000,0.00000000,0.00000000
165.64000000,3.38902000,9.58600000,0.11345278,627.15080144,0.10746580,698.30280195,0.00099795,0.12634093,721.88034627,-0.06049410,-0.06584683,0.00000000,0.00000000,0.00000000,0.00000000
167.14000000,3.43215800,9.59500000,0.11486178,627.73961400,0.10873043,699.84290205,0.00083197,0.12771627,723.25153985,-0.06118535,-0.06653091,0.00000000,0.00000000,0.00000000,0.00000000
168.64000000,3.47519500,9.60200000,0.11633311,628.19757933,0.11004931,701.27775812,0.00085696,0.12912509,724.64950307,-0.06189407,-0.06723102,0.00000000,0.00000000,0.00000000,0.00000000
170.14000000,3.51826700,9.60900000,0.11779356,628.65554465,0.11135670,702.70711648,0.00084291,0.13046501,725.84967694,-0.06249621,-0.06796880,0.00000000,0.00000000,0.00000000,0.00000000
171.64000000,3.56183300,9.61800000,0.11921322,629.24435721,0.11262596,704.25860460,0.00074928,0.13186051,727.16748437,-0.06322241,-0.06863810,0.00000000,0.00000000,0.00000000,0.00000000
173.14000000,3.60526600,9.62500000,0.12075433,629.70232254,0.11400197,705.74160670,0.00084683,0.13326062,728.49093197,-0.06387718,-0.06938343,0.00000000,0.00000000,0.00000000,0.00000000
174.64000000,3.64946300,9.63200000,0.12227733,630.16028786,0.11535995,707.21460744,0.00092472,0.13469391,729.76560237,-0.06462775,-0.07006616,0.00000000,0.00000000,0.00000000,0.00000000
176.14000000,3.69382400,9.63900000,0.12378900,630.61825319,0.11670601,708.68185613,0.00099510,0.13608336,731.08576688,-0.06527570,-0.07080767,0.00000000,0.00000000,0.00000000,0.00000000
177.64000000,3.73755600,9.64500000,0.12528244,631.01079490,0.11803407,710.06536975,0.00094813,0.13747495,732.25858952,-0.06592585,-0.07154910,0.00000000,0.00000000,0.00000000,0.00000000
179.14000000,3.78198500,9.65000000,0.12676856,631.33791299,0.11935385,711.37170828,0.00088157,0.13890516,733.61309654,-0.06664243,-0.07226273,0.00000000,0.00000000,0.00000000,0.00000000
180.64000000,3.82621300,9.65700000,0.12827311,631.79587831,0.12068824,712.83830121,0.00084848,0.14027000,734.84597065,-0.06727608,-0.07299392,0.00000000,0.00000000,0.00000000,0.00000000
182.14000000,3.87084100,9.66300000,0.12979967,632.18842002,0.12204033,714.24626621,0.00084025,0.14172823,736.14984937,-0.06797132,-0.07375692,0.00000000,0.00000000,0.00000000,0.00000000
183.64000000,3.91569800,9.66800000,0.13128189,632.51553811,0.12335140,715.55337270,0.00083246,0.14318459,737.37856088,-0.06874738,-0.07443720,0.00000000,0.00000000,0.00000000,0.00000000
185.14000000,3.96012600,9.67400000,0.13284522,632.90807982,0.12473236,716.98689433,0.00089608,0.14457570,738.56093850,-0.06941343,-0.07516227,0.00000000,0.00000000,0.00000000,0.00000000
186.64000000,4.00561300,9.67900000,0.13443800,633.23519791,0.12613737,718.36607144,0.00097301,0.14605917,739.89000497,-0.07015639,-0.07590278,0.00000000,0.00000000,0.00000000,0.00000000
188.14000000,4.05053900,9.68400000,0.13596078,633.56231600,0.12747879,719.70194125,0.00086152,0.14750936,741.12029237,-0.07083237,-0.07667700,0.00000000,0.00000000,0.00000000,0.00000000
189.64000000,4.09589300,9.68800000,0.13755011,633.82401047,0.12887692,721.00657353,0.00093810,0.14892560,742.32729878,-0.07151581,-0.07740979,0.00000000,0.00000000,0.00000000,0.00000000
191.14000000,4.14098200,9.69200000,0.13908767,634.08570494,0.13022765,722.27920611,0.00089839,0.15040284,743.58177071,-0.07219880,-0.07820404,0.00000000,0.00000000,0.00000000,0.00000000
192.64000000,4.18729800,9.69700000,0.14065456,634.41282303,0.13160227,723.64587669,0.00088390,0.15194072,744.88366630,-0.07299688,-0.07894384,0.00000000,0.00000000,0.00000000,0.00000000
194.14000000,4.23351300,9.70200000,0.14228411,634.73994112,0.13302986,725.05334943,0.00090813,0.15344499,746.16264942,-0.07370764,-0.07973735,0.00000000,0.00000000,0.00000000,0.00000000
195.64000000,4.27923400,9.70600000,0.14389522,635.00163559,0.13443930,726.37533706,0.00103572,0.15488451,747.31830649,-0.07438829,-0.08049622,0.00000000,0.00000000,0.00000000,0.00000000
197.14000000,4.32504900,9.70900000,0.14545111,635.19790644,0.13579854,727.58814771,0.00095065,0.15638459,748.52124632,-0.07510872,-0.08127587,0.00000000,0.00000000,0.00000000,0.00000000
198.64000000,4.37090100,9.71200000,0.14706600,635.39417730,0.13720738,728.83905738,0.00095552,0.15791359,749.74787941,-0.07585000,-0.08206359,0.00000000,0.00000000,0.00000000,0.00000000
200.14000000,4.41794500,9.71700000,0.14869200,635.72129539,0.13862390,730.24796624,0.00090984,0.15947101,751.07522264,-0.07663179,-0.08283922,0.00000000,0.00000000,0.00000000,0.00000000
201.64000000,4.46449200,9.71900000,0.15028089,635.85214262,0.14000616,731.40856782,0.00088288,0.16102644,752.32598809,-0.07741184,-0.08361460,0.00000000,0.00000000,0.00000000,0.00000000
203.14000000,4.51097200,9.72200000,0.15189567,636.04841348,0.14140899,732.66141127,0.00089419,0.16254858,753.47613264,-0.07815580,-0.08439278,0.00000000,0.00000000,0.00000000,0.00000000
204.64000000,4.55765000,9.72600000,0.15355111,636.31010795,0.14284511,734.01623204,0.00089309,0.16409910,754.72718577,-0.07890515,-0.08519395,0.00000000,0.00000000,0.00000000,0.00000000
206.14000000,4.60489200,9.72900000,0.15520622,636.50637880,0.14427888,735.29612928,0.00101922,0.16567842,755.92439192,-0.07965202,-0.08602640,0.00000000,0.00000000,0.00000000,0.00000000
207.64000000,4.65213300,9.73200000,0.15686156,636.70264966,0.14571078,736.57681771,0.00095415,0.16728603,757.14499902,-0.08041888,-0.08686715,0.00000000,0.00000000,0.00000000,0.00000000
209.14000000,4.69983700,9.73300000,0.15855367,636.76807327,0.14717239,737.72998611,0.00095295,0.16886001,758.42001492,-0.08119629,-0.08766373,0.00000000,0.00000000,0.00000000,0.00000000
210.64000000,4.74664900,9.73600000,0.16017222,636.96434413,0.14856846,738.98833860,0.00095162,0.17049392,759.58656777,-0.08199758,-0.08849634,0.00000000,0.00000000,0.00000000,0.00000000
212.14000000,4.79475000,9.73900000,0.16182722,637.16061498,0.14999396,740.27054741,0.00082301,0.17212431,760.90878247,-0.08280084,-0.08932347,0.00000000,0.00000000,0.00000000,0.00000000
213.64000000,4.84262100,9.74100000,0.16355622,637.29146222,0.15148102,741.52444623,0.00088503,0.00000000,0.00000000,0.00000000,0.00000000,0.00000000,0.00000000,0.00000000,0.00000000
215.14000000,4.89092100,9.74300000,0.16532189,637.42230945,0.15299735,742.80216967,0.00107372,0.00000000,0.00000000,0.00000000,0.00000000,0.00000000,0.00000000,0.00000000,0.00000000
216.64000000,4.93975000,9.74500000,0.16701389,637.55315669,0.15444825,744.03338876,0.00100910,0.00000000,0.00000000,0.00000000,0.00000000,0.00000000,0.00000000,0.00000000,0.00000000
218.14000000,4.98805000,9.74700000,0.16877944,637.68400393,0.15595999,745.31195584,0.00094442,0.00000000,0.00000000,0.00000000,0.00000000,0.00000000,0.00000000,0.00000000,0.00000000
219.64000000,5.03724700,9.74900000,0.17054511,637.81485116,0.15746955,746.59105582,0.00094280,0.00000000,0.00000000,0.00000000,0.00000000,0.00000000,0.00000000,0.00000000,0.00000000
221.14000000,5.08578000,9.74900000,0.17227400,637.81485116,0.15894545,747.69376683,0.00100457,0.00000000,0.00000000,0.00000000,0.00000000,0.00000000,0.00000000,0.00000000,0.00000000
222.64000000,5.13546900,9.75000000,0.17403944,637.88027478,0.16045032,748.89660342,0.00100268,0.00000000,0.00000000,0.00000000,0.00000000,0.00000000,0.00000000,0.00000000,0.00000000
224.14000000,5.18463200,9.75100000,0.17584211,637.94569840,0.16198458,750.12341678,0.00100152,0.00000000,0.00000000,0.00000000,0.00000000,0.00000000,0.00000000,0.00000000,0.00000000
225.64000000,5.23462000,9.75300000,0.17768133,638.07654563,0.16354753,751.45083703,0.00099995,0.00000000,0.00000000,0.00000000,0.00000000,0.00000000,0.00000000,0.00000000,0.00000000
227.14000000,5.28438100,9.75400000,0.17948367,638.14196925,0.16507677,752.67802975,0.00093566,0.00000000,0.00000000,0.00000000,0.00000000,0.00000000,0.00000000,0.00000000,0.00000000
228.64000000,5.33426900,9.75400000,0.18132278,638.14196925,0.16663481,753.85164373,0.00099649,0.00000000,0.00000000,0.00000000,0.00000000,0.00000000,0.00000000,0.00000000,0.00000000
230.14000000,5.38448900,9.75500000,0.18319867,638.20739287,0.16822151,755.12613630,0.00105693,0.00000000,0.00000000,0.00000000,0.00000000,0.00000000,0.00000000,0.00000000,0.00000000
231.64000000,5.43523900,9.75600000,0.18507467,638.27281649,0.16980578,756.40094524,0.00105544,0.00000000,0.00000000,0.00000000,0.00000000,0.00000000,0.00000000,0.00000000,0.00000000
233.14000000,5.48615600,9.75500000,0.18698744,638.20739287,0.17141854,757.54416229,0.00105411,0.00000000,0.00000000,0.00000000,0.00000000,0.00000000,0.00000000,0.00000000,0.00000000
234.64000000,5.53661200,9.75500000,0.18890022,638.20739287,0.17302870,758.76491121,0.00111432,0.00000000,0.00000000,0.00000000,0.00000000,0.00000000,0.00000000,0.00000000,0.00000000
236.14000000,5.58755900,9.75600000,0.19084978,638.27281649,0.17466715,760.08704167,0.00111231,0.00000000,0.00000000,0.00000000,0.00000000,0.00000000,0.00000000,0.00000000,0.00000000
237.64000000,5.63920400,9.75600000,0.19283622,638.27281649,0.17633385,761.35493517,0.00117234,0.00000000,0.00000000,0.00000000,0.00000000,0.00000000,0.00000000,0.00000000,0.00000000
239.14000000,5.69081500,9.75600000,0.19478578,638.27281649,0.00000000,0.00000000,0.00000000,0.00000000,0.00000000,0.00000000,0.00000000,0.00000000,0.00000000,0.00000000,0.00000000
240.64000000,5.74298800,9.75500000,0.19677200,638.20739287,0.00000000,0.00000000,0.00000000,0.00000000,0.00000000,0.00000000,0.00000000,0.00000000,0.00000000,0.00000000,0.00000000
242.14000000,5.79393900,9.75400000,0.19879500,638.14196925,0.00000000,0.00000000,0.00000000,0.00000000,0.00000000,0.00000000,0.00000000,0.00000000,0.00000000,0.00000000,0.00000000
243.64000000,5.84631300,9.75400000,0.20081811,638.14196925,0.00000000,0.00000000,0.00000000,0.00000000,0.00000000,0.00000000,0.00000000,0.00000000,0.00000000,0.00000000,0.00000000
245.14000000,5.89908100,9.75400000,0.20295167,638.14196925,0.00000000,0.00000000,0.00000000,0.00000000,0.00000000,0.00000000,0.00000000,0.00000000,0.00000000,0.00000000,0.00000000
246.64000000,5.95115800,9.75200000,0.20493800,638.01112202,0.00000000,0.00000000,0.00000000,0.00000000,0.00000000,0.00000000,0.00000000,0.00000000,0.00000000,0.00000000,0.00000000
248.14000000,6.00409400,9.75100000,0.20710822,637.94569840,0.00000000,0.00000000,0.00000000,0.00000000,0.00000000,0.00000000,0.00000000,0.00000000,0.00000000,0.00000000,0.00000000
249.64000000,6.05722800,9.75100000,0.20927844,637.94569840,0.00000000,0.00000000,0.00000000,0.00000000,0.00000000,0.00000000,0.00000000,0.00000000,0.00000000,0.00000000,0.00000000
251.14000000,6.11052900,9.75000000,0.21144867,637.88027478,0.00000000,0.00000000,0.00000000,0.00000000,0.00000000,0.00000000,0.00000000,0.00000000,0.00000000,0.00000000,0.00000000
252.64000000,6.16452400,9.74800000,0.21361889,637.74942754,0.00000000,0.00000000,0.00000000,0.00000000,0.00000000,0.00000000,0.00000000,0.00000000,0.00000000,0.00000000,0.00000000
254.14000000,6.21769200,9.74600000,0.21589956,637.61858031,0.00000000,0.00000000,0.00000000,0.00000000,0.00000000,0.00000000,0.00000000,0.00000000,0.00000000,0.00000000,0.00000000
255.64000000,6.27145600,9.74400000,0.21821689,637.48773307,0.00000000,0.00000000,0.00000000,0.00000000,0.00000000,0.00000000,0.00000000,0.00000000,0.00000000,0.00000000,0.00000000
257.14000000,6.32511900,9.74300000,0.22053444,637.42230945,0.00000000,0.00000000,0.00000000,0.00000000,0.00000000,0.00000000,0.00000000,0.00000000,0.00000000,0.00000000,0.00000000
258.64000000,6.38093600,9.74200000,0.22296222,637.35688584,0.00000000,0.00000000,0.00000000,0.00000000,0.00000000,0.00000000,0.00000000,0.00000000,0.00000000,0.00000000,0.00000000
260.14000000,6.43605600,9.73900000,0.22542667,637.16061498,0.00000000,0.00000000,0.00000000,0.00000000,0.00000000,0.00000000,0.00000000,0.00000000,0.00000000,0.00000000,0.00000000
261.64000000,6.49044900,9.73700000,0.22785444,637.02976775,0.00000000,0.00000000,0.00000000,0.00000000,0.00000000,0.00000000,0.00000000,0.00000000,0.00000000,0.00000000,0.00000000
263.14000000,6.54652900,9.73400000,0.23042922,636.83349689,0.00000000,0.00000000,0.00000000,0.00000000,0.00000000,0.00000000,0.00000000,0.00000000,0.00000000,0.00000000,0.00000000
264.64000000,6.60181400,9.73100000,0.23293056,636.63722604,0.00000000,0.00000000,0.00000000,0.00000000,0.00000000,0.00000000,0.00000000,0.00000000,0.00000000,0.00000000,0.00000000
266.14000000,6.65749900,9.72900000,0.23561578,636.50637880,0.00000000,0.00000000,0.00000000,0.00000000,0.00000000,0.00000000,0.00000000,0.00000000,0.00000000,0.00000000,0.00000000
267.64000000,6.71371200,9.72600000,0.23830111,636.31010795,0.00000000,0.00000000,0.00000000,0.00000000,0.00000000,0.00000000,0.00000000,0.00000000,0.00000000,0.00000000,0.00000000
269.14000000,6.77035500,9.72300000,0.24105989,636.11383710,0.00000000,0.00000000,0.00000000,0.00000000,0.00000000,0.00000000,0.00000000,0.00000000,0.00000000,0.00000000,0.00000000
270.64000000,6.82683200,9.72000000,0.24400244,635.91756624,0.00000000,0.00000000,0.00000000,0.00000000,0.00000000,0.00000000,0.00000000,0.00000000,0.00000000,0.00000000,0.00000000
272.14000000,6.88360900,9.71600000,0.24683489,635.65587177,0.00000000,0.00000000,0.00000000,0.00000000,0.00000000,0.00000000,0.00000000,0.00000000,0.00000000,0.00000000,0.00000000
273.64000000,6.94025200,9.71300000,0.24988800,635.45960092,0.00000000,0.00000000,0.00000000,0.00000000,0.00000000,0.00000000,0.00000000,0.00000000,0.00000000,0.00000000,0.00000000
275.14000000,6.99768900,9.70800000,0.25290411,635.13248283,0.00000000,0.00000000,0.00000000,0.00000000,0.00000000,0.00000000,0.00000000,0.00000000,0.00000000,0.00000000,0.00000000
276.64000000,7.05506200,9.70400000,0.25614122,634.87078835,0.00000000,0.00000000,0.00000000,0.00000000,0.00000000,0.00000000,0.00000000,0.00000000,0.00000000,0.00000000,0.00000000
278.14000000,7.11269800,9.70000000,0.25934133,634.60909388,0.00000000,0.00000000,0.00000000,0.00000000,0.00000000,0.00000000,0.00000000,0.00000000,0.00000000,0.00000000,0.00000000
279.64000000,7.17046600,9.69500000,0.26272544,634.28197579,0.00000000,0.00000000,0.00000000,0.00000000,0.00000000,0.00000000,0.00000000,0.00000000,0.00000000,0.00000000,0.00000000
281.14000000,7.22869900,9.69000000,0.26625667,633.95485770,0.00000000,0.00000000,0.00000000,0.00000000,0.00000000,0.00000000,0.00000000,0.00000000,0.00000000,0.00000000,0.00000000
282.64000000,7.28755900,9.68500000,0.26989833,633.62773961,0.00000000,0.00000000,0.00000000,0.00000000,0.00000000,0.00000000,0.00000000,0.00000000,0.00000000,0.00000000,0.00000000
284.14000000,7.34612200,9.67900000,0.27365011,633.23519791,0.00000000,0.00000000,0.00000000,0.00000000,0.00000000,0.00000000,0.00000000,0.00000000,0.00000000,0.00000000,0.00000000
285.64000000,7.40422200,9.67200000,0.27747578,632.77723258,0.00000000,0.00000000,0.00000000,0.00000000,0.00000000,0.00000000,0.00000000,0.00000000,0.00000000,0.00000000,0.00000000
287.14000000,7.46278500,9.66600000,0.28148533,632.38469087,0.00000000,0.00000000,0.00000000,0.00000000,0.00000000,0.00000000,0.00000000,0.00000000,0.00000000,0.00000000,0.00000000
288.64000000,7.52214400,9.66000000,0.28567856,631.99214917,0.00000000,0.00000000,0.00000000,0.00000000,0.00000000,0.00000000,0.00000000,0.00000000,0.00000000,0.00000000,0.00000000
290.14000000,7.58169900,9.65200000,0.29005600,631.46876022,0.00000000,0.00000000,0.00000000,0.00000000,0.00000000,0.00000000,0.00000000,0.00000000,0.00000000,0.00000000,0.00000000
291.64000000,7.64142000,9.64300000,0.29454356,630.87994766,0.00000000,0.00000000,0.00000000,0.00000000,0.00000000,0.00000000,0.00000000,0.00000000,0.00000000,0.00000000,0.00000000
293.14000000,7.70037900,9.63500000,0.29917822,630.35655872,0.00000000,0.00000000,0.00000000,0.00000000,0.00000000,0.00000000,0.00000000,0.00000000,0.00000000,0.00000000,0.00000000
294.64000000,7.76036700,9.62600000,0.30399722,629.76774616,0.00000000,0.00000000,0.00000000,0.00000000,0.00000000,0.00000000,0.00000000,0.00000000,0.00000000,0.00000000,0.00000000
296.14000000,7.82065100,9.61700000,0.30903644,629.17893360,0.00000000,0.00000000,0.00000000,0.00000000,0.00000000,0.00000000,0.00000000,0.00000000,0.00000000,0.00000000,0.00000000
297.64000000,7.88060200,9.60500000,0.31429633,628.39385018,0.00000000,0.00000000,0.00000000,0.00000000,0.00000000,0.00000000,0.00000000,0.00000000,0.00000000,0.00000000,0.00000000
299.14000000,7.94025800,9.59500000,0.31974033,627.73961400,0.00000000,0.00000000,0.00000000,0.00000000,0.00000000,0.00000000,0.00000000,0.00000000,0.00000000,0.00000000,0.00000000
300.64000000,8.00067400,9.58200000,0.32529467,626.88910697,0.00000000,0.00000000,0.00000000,0.00000000,0.00000000,0.00000000,0.00000000,0.00000000,0.00000000,0.00000000,0.00000000
302.14000000,8.06152000,9.56900000,0.33110656,626.03859993,0.00000000,0.00000000,0.00000000,0.00000000,0.00000000,0.00000000,0.00000000,0.00000000,0.00000000,0.00000000,0.00000000
303.64000000,8.12243400,9.55400000,0.33713911,625.05724567,0.00000000,0.00000000,0.00000000,0.00000000,0.00000000,0.00000000,0.00000000,0.00000000,0.00000000,0.00000000,0.00000000
305.14000000,8.18367700,9.53800000,0.34317178,624.01046778,0.00000000,0.00000000,0.00000000,0.00000000,0.00000000,0.00000000,0.00000000,0.00000000,0.00000000,0.00000000,0.00000000
306.64000000,8.24416000,9.52000000,0.34949856,622.83284266,0.00000000,0.00000000,0.00000000,0.00000000,0.00000000,0.00000000,0.00000000,0.00000000,0.00000000,0.00000000,0.00000000
308.14000000,8.30550300,9.50400000,0.35582533,621.78606477,0.00000000,0.00000000,0.00000000,0.00000000,0.00000000,0.00000000,0.00000000,0.00000000,0.00000000,0.00000000,0.00000000
309.64000000,8.36592200,9.48200000,0.36229933,620.34674518,0.00000000,0.00000000,0.00000000,0.00000000,0.00000000,0.00000000,0.00000000,0.00000000,0.00000000,0.00000000,0.00000000
311.14000000,8.42776300,9.46300000,0.36888356,619.10369643,0.00000000,0.00000000,0.00000000,0.00000000,0.00000000,0.00000000,0.00000000,0.00000000,0.00000000,0.00000000,0.00000000
312.64000000,8.48956800,9.43900000,0.37554133,617.53352960,0.00000000,0.00000000,0.00000000,0.00000000,0.00000000,0.00000000,0.00000000,0.00000000,0.00000000,0.00000000,0.00000000
314.14000000,8.55140900,9.41500000,0.38230944,615.96336277,0.00000000,0.00000000,0.00000000,0.00000000,0.00000000,0.00000000,0.00000000,0.00000000,0.00000000,0.00000000,0.00000000
315.64000000,8.61321500,9.38700000,0.38907744,614.13150147,0.00000000,0.00000000,0.00000000,0.00000000,0.00000000,0.00000000,0.00000000,0.00000000,0.00000000,0.00000000,0.00000000
317.14000000,8.67459200,9.36200000,0.39584544,612.49591102,0.00000000,0.00000000,0.00000000,0.00000000,0.00000000,0.00000000,0.00000000,0.00000000,0.00000000,0.00000000,0.00000000
318.64000000,8.73649600,9.32900000,0.40268722,610.33693163,0.00000000,0.00000000,0.00000000,0.00000000,0.00000000,0.00000000,0.00000000,0.00000000,0.00000000,0.00000000,0.00000000
320.14000000,8.79883300,9.30100000,0.40960222,608.50507033,0.00000000,0.00000000,0.00000000,0.00000000,0.00000000,0.00000000,0.00000000,0.00000000,0.00000000,0.00000000,0.00000000
321.64000000,8.86086900,9.26600000,0.41659078,606.21524370,0.00000000,0.00000000,0.00000000,0.00000000,0.00000000,0.00000000,0.00000000,0.00000000,0.00000000,0.00000000,0.00000000
323.14000000,8.92313700,9.23000000,0.42350556,603.85999346,0.00000000,0.00000000,0.00000000,0.00000000,0.00000000,0.00000000,0.00000000,0.00000000,0.00000000,0.00000000,0.00000000
324.64000000,8.98547100,9.18900000,0.43045722,601.17762512,0.00000000,0.00000000,0.00000000,0.00000000,0.00000000,0.00000000,0.00000000,0.00000000,0.00000000,0.00000000,0.00000000
326.14000000,9.04826700,9.15300000,0.43748211,598.82237488,0.00000000,0.00000000,0.00000000,0.00000000,0.00000000,0.00000000,0.00000000,0.00000000,0.00000000,0.00000000,0.00000000
327.64000000,9.11122600,9.10200000,0.44450700,595.48577036,0.00000000,0.00000000,0.00000000,0.00000000,0.00000000,0.00000000,0.00000000,0.00000000,0.00000000,0.00000000,0.00000000
329.14000000,9.17421600,9.05700000,0.45156856,592.54170756,0.00000000,0.00000000,0.00000000,0.00000000,0.00000000,0.00000000,0.00000000,0.00000000,0.00000000,0.00000000,0.00000000
330.64000000,9.23723900,9.00200000,0.45866667,588.94340857,0.00000000,0.00000000,0.00000000,0.00000000,0.00000000,0.00000000,0.00000000,0.00000000,0.00000000,0.00000000,0.00000000
332.14000000,9.30065700,8.94500000,0.46580133,585.21426235,0.00000000,0.00000000,0.00000000,0.00000000,0.00000000,0.00000000,0.00000000,0.00000000,0.00000000,0.00000000,0.00000000
333.64000000,9.36549300,8.87800000,0.47304589,580.83087995,0.00000000,0.00000000,0.00000000,0.00000000,0.00000000,0.00000000,0.00000000,0.00000000,0.00000000,0.00000000,0.00000000
335.14000000,9.43002900,8.81300000,0.48036389,576.57834478,0.00000000,0.00000000,0.00000000,0.00000000,0.00000000,0.00000000,0.00000000,0.00000000,0.00000000,0.00000000,0.00000000
336.64000000,9.49528900,8.72100000,0.48764467,570.55937193,0.00000000,0.00000000,0.00000000,0.00000000,0.00000000,0.00000000,0.00000000,0.00000000,0.00000000,0.00000000,0.00000000
338.14000000,9.56094000,8.63900000,0.49507244,565.19463526,0.00000000,0.00000000,0.00000000,0.00000000,0.00000000,0.00000000,0.00000000,0.00000000,0.00000000,0.00000000,0.00000000
339.64000000,9.62797400,8.52800000,0.50272089,557.93261367,0.00000000,0.00000000,0.00000000,0.00000000,0.00000000,0.00000000,0.00000000,0.00000000,0.00000000,0.00000000,0.00000000
341.14000000,9.69771700,8.40600000,0.51055367,549.95093229,0.00000000,0.00000000,0.00000000,0.00000000,0.00000000,0.00000000,0.00000000,0.00000000,0.00000000,0.00000000,0.00000000
342.14000000,9.74611700,8.30800000,0.51614389,543.53941773,0.00000000,0.00000000,0.00000000,0.00000000,0.00000000,0.00000000,0.00000000,0.00000000,0.00000000,0.00000000,0.00000000