File: lab_data/DP600_results/DATA/UT_15_2.csv
Time[s],Displacement[mm],Force[kN],EngStrain_longi,EngStress[MPa],TrueStrain,TrueStress[MPa],TrueStrainRate[1/s],PlasticStrain_longi,PlasticStress[MPa],PlasticStrain_thick,PlasticStrain_width,R-Value,Thickness[mm],Width[mm], Young's Modulus [MPa]
0.60000000,0.00000000,-0.01300000,0.00000000,-0.85251492,0.00000000,-0.85251492,0.00000000,0.00082826,339.14486592,-0.00006942,-0.00075884,0.86331515,1.52490000,10.00000000,215645.24569064
2.10000000,0.00150500,0.03500000,0.00005167,2.29523247,0.00005167,2.29535106,0.00003689,0.00119610,353.56441646,-0.00018604,-0.00101006,0.00000000,0.00000000,0.00000000,0.00000000
3.60000000,0.00356500,0.46300000,0.00009089,30.36264673,0.00009088,30.36540636,-0.00001422,0.00174998,367.40587166,-0.00035590,-0.00139409,0.00000000,0.00000000,0.00000000,0.00000000
5.10000000,0.00602200,0.75100000,0.00016556,49.24913109,0.00016554,49.25728456,0.00007866,0.00247613,378.82297896,-0.00068882,-0.00178731,0.00000000,0.00000000,0.00000000,0.00000000
6.60000000,0.00797200,1.13500000,0.00023244,74.43111024,0.00023242,74.44841133,0.00006976,0.00322273,389.67140834,-0.00111307,-0.00210966,0.00000000,0.00000000,0.00000000,0.00000000
8.10000000,0.00955100,1.44900000,0.00031189,95.02262443,0.00031184,95.05226094,0.00012863,0.00393197,398.20890593,-0.00154983,-0.00238215,0.00000000,0.00000000,0.00000000,0.00000000
9.60000000,0.01119300,1.81400000,0.00033400,118.95862024,0.00033394,118.99835242,0.00000955,0.00467466,407.30177753,-0.00193790,-0.00273675,0.00000000,0.00000000,0.00000000,0.00000000
11.10000000,0.01399400,2.12300000,0.00041789,139.22224408,0.00041780,139.28042351,-0.00010440,0.00559753,415.22596519,-0.00245942,-0.00313811,0.00000000,0.00000000,0.00000000,0.00000000
12.60000000,0.01712900,2.50800000,0.00052522,164.46980130,0.00052508,164.55618449,-0.00012948,0.00652935,423.36765572,-0.00295533,-0.00357402,0.00000000,0.00000000,0.00000000,0.00000000
14.10000000,0.02103800,2.81500000,0.00067644,184.60226900,0.00067622,184.72714218,0.00003886,0.00734451,430.54569191,-0.00329081,-0.00405371,0.00000000,0.00000000,0.00000000,0.00000000
15.60000000,0.02480300,3.19700000,0.00086844,209.65309201,0.00086807,209.83516407,0.00033729,0.00815071,437.93088640,-0.00369354,-0.00445717,0.00000000,0.00000000,0.00000000,0.00000000
17.10000000,0.02817300,3.49700000,0.00096922,229.32651321,0.00096875,229.54878157,0.00037256,0.00908604,444.05670982,-0.00428041,-0.00480563,0.00000000,0.00000000,0.00000000,0.00000000
18.60000000,0.03220500,3.83800000,0.00102256,251.68863532,0.00102203,251.94600093,0.00027041,0.01007091,451.01465122,-0.00486805,-0.00520287,0.00000000,0.00000000,0.00000000,0.00000000
20.10000000,0.03764100,4.12400000,0.00111089,270.44396354,0.00111027,270.74439673,0.00012498,0.01095674,457.20838368,-0.00536555,-0.00559119,0.00000000,0.00000000,0.00000000,0.00000000
21.60000000,0.04562000,4.46600000,0.00127644,292.87166372,0.00127563,293.24549812,-0.00020573,0.01178651,463.58701752,-0.00574503,-0.00604149,0.00000000,0.00000000,0.00000000,0.00000000
23.10000000,0.05412800,4.72100000,0.00159278,309.59407174,0.00159151,310.08718630,-0.00026445,0.01277238,468.98234569,-0.00631233,-0.00646005,0.00000000,0.00000000,0.00000000,0.00000000
24.60000000,0.06432500,5.01500000,0.00206000,328.87402453,0.00205788,329.55150502,-0.00009536,0.01377169,475.12921233,-0.00681828,-0.00695341,0.00000000,0.00000000,0.00000000,0.00000000
26.10000000,0.07912400,5.22800000,0.00263744,342.84215358,0.00263397,343.74638072,0.00038147,0.01472968,480.59976519,-0.00729694,-0.00743275,0.00000000,0.00000000,0.00000000,0.00000000
27.60000000,0.09587600,5.45300000,0.00317089,357.59721949,0.00316587,358.73112054,0.00057227,0.01562050,486.31560373,-0.00775235,-0.00786815,0.00000000,0.00000000,0.00000000,0.00000000
29.10000000,0.11435100,5.62300000,0.00374844,368.74549151,0.00374144,370.12771350,0.00048380,0.01661456,491.42258004,-0.00832249,-0.00829207,0.00000000,0.00000000,0.00000000,0.00000000
30.60000000,0.13746000,5.81100000,0.00445111,381.07416880,0.00444123,382.77037226,0.00032237,0.01762440,496.74851958,-0.00893680,-0.00868760,0.00000000,0.00000000,0.00000000,0.00000000
32.10000000,0.16109900,5.94500000,0.00534867,389.86163027,0.00533441,391.94687018,0.00051222,0.01859754,501.26097274,-0.00949413,-0.00910341,0.00000000,0.00000000,0.00000000,0.00000000
33.60000000,0.18705400,6.09500000,0.00621678,399.69834087,0.00619753,402.18317664,0.00073866,0.01956711,506.31769755,-0.00998045,-0.00958665,0.00000000,0.00000000,0.00000000,0.00000000
35.10000000,0.21204900,6.20600000,0.00701500,406.97750672,0.00699051,409.83245393,0.00075264,0.02058457,510.93767500,-0.01048225,-0.01010232,0.00000000,0.00000000,0.00000000,0.00000000
36.60000000,0.24048700,6.32700000,0.00784256,414.91245328,0.00781196,418.16642724,0.00047434,0.02157485,515.75470279,-0.01094596,-0.01062889,0.00000000,0.00000000,0.00000000,0.00000000
38.10000000,0.26756800,6.42500000,0.00883944,421.33910420,0.00880061,425.06350781,0.00051044,0.02261667,520.06860096,-0.01150800,-0.01110867,0.00000000,0.00000000,0.00000000,0.00000000
39.60000000,0.29547700,6.54300000,0.00979211,429.07731655,0.00974448,433.27888930,0.00069950,0.02363487,524.58114359,-0.01205648,-0.01157839,0.00000000,0.00000000,0.00000000,0.00000000
41.10000000,0.32302100,6.63200000,0.01066400,434.91376484,0.01060754,439.55168523,0.00074288,0.02467318,528.43763923,-0.01266712,-0.01200605,0.00000000,0.00000000,0.00000000,0.00000000
42.60000000,0.35232000,6.73800000,0.01154311,441.86504033,0.01147700,446.96553759,0.00055281,0.02569763,532.70009553,-0.01322400,-0.01247364,0.00000000,0.00000000,0.00000000,0.00000000
44.10000000,0.37963300,6.82000000,0.01250689,447.24244213,0.01242932,452.83605366,0.00042144,0.02674743,536.64604394,-0.01377467,-0.01297276,0.00000000,0.00000000,0.00000000,0.00000000
45.60000000,0.40939600,6.91400000,0.01350389,453.40678077,0.01341352,459.52953556,0.00055919,0.02779875,540.80398715,-0.01437875,-0.01342000,0.00000000,0.00000000,0.00000000,0.00000000
47.10000000,0.43872700,6.99000000,0.01445656,458.39071415,0.01435306,465.01746497,0.00071797,0.02886144,544.56936904,-0.01494226,-0.01391919,0.00000000,0.00000000,0.00000000,0.00000000
48.60000000,0.46782700,7.08200000,0.01538722,464.42389665,0.01527004,471.57009035,0.00052882,0.02992627,548.41137357,-0.01548202,-0.01444424,0.00000000,0.00000000,0.00000000,0.00000000
50.10000000,0.49805300,7.15300000,0.01639144,469.07993967,0.01625855,476.76883744,0.00044870,0.03094135,551.96156093,-0.01599155,-0.01494979,0.00000000,0.00000000,0.00000000,0.00000000
51.60000000,0.52867500,7.23300000,0.01744711,474.32618532,0.01729666,482.60180698,0.00055681,0.03204429,555.49938056,-0.01658561,-0.01545867,0.00000000,0.00000000,0.00000000,0.00000000
53.10000000,0.55906600,7.30500000,0.01843289,479.04780641,0.01826506,487.87804140,0.00065755,0.03312092,559.09785783,-0.01715850,-0.01596242,0.00000000,0.00000000,0.00000000,0.00000000
54.60000000,0.58949000,7.37900000,0.01942600,483.90058364,0.01923972,493.30083638,0.00057012,0.03415257,562.20063364,-0.01767933,-0.01647324,0.00000000,0.00000000,0.00000000,0.00000000
56.10000000,0.62077600,7.44000000,0.02045222,487.90084596,0.02024588,497.87950248,0.00051204,0.03523418,565.74741120,-0.01828465,-0.01694953,0.00000000,0.00000000,0.00000000,0.00000000
57.60000000,0.65123300,7.51500000,0.02152622,492.81920126,0.02129781,503.42773690,0.00062661,0.03635166,568.91155361,-0.01893106,-0.01742060,0.00000000,0.00000000,0.00000000,0.00000000
59.10000000,0.68367700,7.57200000,0.02260033,496.55715129,0.02234873,507.77950843,0.00074117,0.03742087,572.32827018,-0.01950160,-0.01791928,0.00000000,0.00000000,0.00000000,0.00000000
60.60000000,0.71512700,7.63700000,0.02363022,500.81972588,0.02335535,512.65420730,0.00067549,0.03847351,575.26250880,-0.02008417,-0.01838933,0.00000000,0.00000000,0.00000000,0.00000000
62.10000000,0.74664400,7.69500000,0.02469700,504.62325398,0.02439696,517.08593449,0.00073227,0.03956584,578.49980225,-0.02070179,-0.01886405,0.00000000,0.00000000,0.00000000,0.00000000
63.60000000,0.77928600,7.75600000,0.02577844,508.62351630,0.02545178,521.73503935,0.00071720,0.04070100,581.35647347,-0.02134808,-0.01935292,0.00000000,0.00000000,0.00000000,0.00000000
65.10000000,0.81100100,7.80600000,0.02683789,511.90241983,0.02648407,525.64080010,0.00070239,0.04177068,584.38687494,-0.02188000,-0.01989068,0.00000000,0.00000000,0.00000000,0.00000000
66.60000000,0.84427200,7.86600000,0.02793033,515.83710407,0.02754740,530.24460633,0.00071570,0.04289243,587.31618100,-0.02249544,-0.02039698,0.00000000,0.00000000,0.00000000,0.00000000
68.10000000,0.87681400,7.91300000,0.02898978,518.91927339,0.02857752,533.96262782,0.00068644,0.04401994,590.25482246,-0.02307814,-0.02094180,0.00000000,0.00000000,0.00000000,0.00000000
69.60000000,0.90962200,7.96600000,0.03008600,522.39491114,0.02964229,538.11168444,0.00067881,0.04513655,592.98595652,-0.02362411,-0.02151244,0.00000000,0.00000000,0.00000000,0.00000000
71.10000000,0.94345600,8.01500000,0.03119311,525.60823661,0.03071649,542.00359273,0.00068498,0.04625121,595.85950606,-0.02420677,-0.02204444,0.00000000,0.00000000,0.00000000,0.00000000
72.60000000,0.97685900,8.06400000,0.03230400,528.82156207,0.03179320,545.90461381,0.00067713,0.04736622,598.39325069,-0.02478104,-0.02258518,0.00000000,0.00000000,0.00000000,0.00000000
74.10000000,1.01032800,8.10900000,0.03341489,531.77257525,0.03286874,549.54169677,0.00066199,0.04850011,601.08181719,-0.02539529,-0.02310482,0.00000000,0.00000000,0.00000000,0.00000000
75.60000000,1.04386400,8.15200000,0.03452578,534.59243229,0.03394314,553.04965181,0.00074680,0.04960872,603.69115651,-0.02598079,-0.02362793,0.00000000,0.00000000,0.00000000,0.00000000
77.10000000,1.07809400,8.19800000,0.03562567,537.60902354,0.03500575,556.76170341,0.00063246,0.05073662,606.38672910,-0.02661414,-0.02412248,0.00000000,0.00000000,0.00000000,0.00000000
78.60000000,1.11199400,8.23600000,0.03681378,540.10099023,0.03615234,559.98414806,0.00073808,0.05187446,608.88534505,-0.02723536,-0.02463910,0.00000000,0.00000000,0.00000000,0.00000000
80.10000000,1.14622600,8.28100000,0.03793933,543.05200341,0.03723734,563.65503438,0.00081524,0.05302468,611.46605867,-0.02785705,-0.02516762,0.00000000,0.00000000,0.00000000,0.00000000
81.60000000,1.18082100,8.31700000,0.03905022,545.41281396,0.03830705,566.71130554,0.00075767,0.05415079,613.68896001,-0.02844826,-0.02570253,0.00000000,0.00000000,0.00000000,0.00000000
83.10000000,1.21534900,8.35800000,0.04018311,548.10151485,0.03939677,570.12593892,0.00067200,0.05528818,616.20195718,-0.02908682,-0.02620135,0.00000000,0.00000000,0.00000000,0.00000000
84.60000000,1.24997800,8.39400000,0.04135656,550.46232540,0.04052424,573.22755114,0.00075599,0.05646977,618.60777832,-0.02973059,-0.02673919,0.00000000,0.00000000,0.00000000,0.00000000
86.10000000,1.28460700,8.43100000,0.04249322,552.88871401,0.04161517,576.38273700,0.00080464,0.05759133,620.98108381,-0.03029123,-0.02730010,0.00000000,0.00000000,0.00000000,0.00000000
87.60000000,1.31959900,8.46400000,0.04361144,555.05279035,0.04268724,579.25944428,0.00073327,0.05873321,623.16181411,-0.03091207,-0.02782113,0.00000000,0.00000000,0.00000000,0.00000000
89.10000000,1.35502200,8.50200000,0.04481422,557.54475703,0.04383909,582.53069167,0.00073945,0.05993474,625.59431635,-0.03155640,-0.02837835,0.00000000,0.00000000,0.00000000,0.00000000
90.60000000,1.39004700,8.53300000,0.04600233,559.57767722,0.04497560,585.31955606,0.00084424,0.06108459,627.71875126,-0.03216487,-0.02891972,0.00000000,0.00000000,0.00000000,0.00000000
92.10000000,1.42596700,8.56800000,0.04714633,561.87290970,0.04606869,588.36315719,0.00075903,0.06222579,629.91203361,-0.03276576,-0.02946003,0.00000000,0.00000000,0.00000000,0.00000000
93.60000000,1.46158900,8.59800000,0.04832711,563.84025182,0.04719567,591.08902232,0.00072997,0.06340747,631.99462916,-0.03339098,-0.03001649,0.00000000,0.00000000,0.00000000,0.00000000
95.10000000,1.49734300,8.63100000,0.04950789,566.00432815,0.04832138,594.02600754,0.00072216,0.06457338,634.21203218,-0.03403906,-0.03053431,0.00000000,0.00000000,0.00000000,0.00000000
96.60000000,1.53375900,8.65800000,0.05071067,567.77493606,0.04946676,596.56718159,0.00075624,0.06571808,636.27933903,-0.03465754,-0.03106054,0.00000000,0.00000000,0.00000000,0.00000000
98.10000000,1.56977800,8.69000000,0.05187300,569.87343432,0.05057238,599.43447898,0.00071335,0.06690211,638.44631215,-0.03528548,-0.03161664,0.00000000,0.00000000,0.00000000,0.00000000
99.60000000,1.60576400,8.71600000,0.05307222,571.57846416,0.05171182,601.91340343,0.00069882,0.06810987,640.35029828,-0.03596161,-0.03214827,0.00000000,0.00000000,0.00000000,0.00000000
101.10000000,1.64231300,8.74500000,0.05431544,573.48022821,0.05289169,604.62906169,0.00081649,0.06926743,642.43778138,-0.03656705,-0.03270038,0.00000000,0.00000000,0.00000000,0.00000000
102.60000000,1.67859700,8.77200000,0.05551100,575.25083612,0.05402501,607.18358528,0.00080167,0.07041738,644.38277483,-0.03717485,-0.03324253,0.00000000,0.00000000,0.00000000,0.00000000
104.10000000,1.71557600,8.80000000,0.05671378,577.08702210,0.05516388,609.81580723,0.00077993,0.07162712,646.44106936,-0.03784138,-0.03378575,0.00000000,0.00000000,0.00000000,0.00000000
105.60000000,1.75212400,8.82300000,0.05792767,578.59531773,0.05631196,612.11199443,0.00075109,0.07281584,648.27685866,-0.03846404,-0.03435179,0.00000000,0.00000000,0.00000000,0.00000000
107.10000000,1.78900400,8.85000000,0.05917833,580.36592563,0.05749345,614.71101384,0.00084066,0.07398202,650.24354515,-0.03904459,-0.03493743,0.00000000,0.00000000,0.00000000,0.00000000
108.60000000,1.82578400,8.87200000,0.06036278,581.80864319,0.05861109,616.92822903,0.00077724,0.07519840,652.10452784,-0.03972253,-0.03547587,0.00000000,0.00000000,0.00000000,0.00000000
110.10000000,1.86342500,8.89700000,0.06159133,583.44809496,0.05976904,619.38344106,0.00070703,0.07640246,654.10348319,-0.04036707,-0.03603538,0.00000000,0.00000000,0.00000000,0.00000000
111.60000000,1.90057000,8.91900000,0.06282733,584.89081251,0.06093265,621.63794255,0.00076854,0.07757887,655.87420965,-0.04102036,-0.03655851,0.00000000,0.00000000,0.00000000,0.00000000
113.10000000,1.93787900,8.94300000,0.06405578,586.46468621,0.06208781,624.03113782,0.00077434,0.07880098,657.74977746,-0.04167409,-0.03712689,0.00000000,0.00000000,0.00000000,0.00000000
114.60000000,1.97595100,8.96300000,0.06531389,587.77624762,0.06326949,626.16620015,0.00071145,0.08001172,659.54996382,-0.04232906,-0.03768266,0.00000000,0.00000000,0.00000000,0.00000000
116.10000000,2.01362500,8.98700000,0.06659033,589.35012132,0.06446696,628.59514235,0.00078646,0.08121760,661.35035294,-0.04298810,-0.03822949,0.00000000,0.00000000,0.00000000,0.00000000
117.60000000,2.05123300,9.00500000,0.06782622,590.53052659,0.06562501,630.58398132,0.00079929,0.08241260,663.00359716,-0.04361507,-0.03879753,0.00000000,0.00000000,0.00000000,0.00000000
119.10000000,2.08903900,9.02600000,0.06908422,591.90766608,0.06680241,632.79914681,0.00077090,0.08362257,664.74159884,-0.04422764,-0.03939493,0.00000000,0.00000000,0.00000000,0.00000000
120.60000000,2.12687900,9.04500000,0.07034589,593.15364942,0.06798186,634.87957014,0.00077685,0.08487801,666.51326295,-0.04494857,-0.03992944,0.00000000,0.00000000,0.00000000,0.00000000
122.10000000,2.16551300,9.06600000,0.07162967,594.53078890,0.06918054,637.11683114,0.00086512,0.08608504,668.25590458,-0.04560860,-0.04047644,0.00000000,0.00000000,0.00000000,0.00000000
123.60000000,2.20345200,9.08200000,0.07288033,595.58003804,0.07034693,638.98610973,0.00080920,0.08730786,669.86838409,-0.04625740,-0.04105046,0.00000000,0.00000000,0.00000000,0.00000000
125.10000000,2.24188800,9.10300000,0.07415311,596.95717752,0.07153255,641.22340943,0.00074677,0.08852892,671.55475174,-0.04692496,-0.04160396,0.00000000,0.00000000,0.00000000,0.00000000
126.60000000,2.28048900,9.11800000,0.07544044,597.94084858,0.07273029,643.04977195,0.00080727,0.08971872,673.15096129,-0.04756268,-0.04215604,0.00000000,0.00000000,0.00000000,0.00000000
128.10000000,2.31938800,9.13700000,0.07672789,599.18683192,0.07392671,645.16117259,0.00088167,0.09097338,674.86622541,-0.04824017,-0.04273321,0.00000000,0.00000000,0.00000000,0.00000000
129.60000000,2.35812100,9.15300000,0.07798600,600.23608105,0.07509449,647.04609207,0.00077815,0.09220019,676.49348832,-0.04886635,-0.04333384,0.00000000,0.00000000,0.00000000,0.00000000
131.10000000,2.39688700,9.17000000,0.07928444,601.35090826,0.07629827,649.02868093,0.00079080,0.09340991,677.89472745,-0.04952856,-0.04388135,0.00000000,0.00000000,0.00000000,0.00000000
132.60000000,2.43558900,9.18400000,0.08059767,602.26900125,0.07751428,650.81047745,0.00087172,0.09466030,679.54376943,-0.05019464,-0.04446567,0.00000000,0.00000000,0.00000000,0.00000000
134.10000000,2.47521600,9.20200000,0.08186300,603.44940652,0.07868456,652.84958528,0.00076179,0.09584967,681.08155085,-0.05080802,-0.04504165,0.00000000,0.00000000,0.00000000,0.00000000
135.60000000,2.51514000,9.21700000,0.08318356,604.43307758,0.07990444,654.71197007,0.00077441,0.09710051,682.66415086,-0.05147982,-0.04562069,0.00000000,0.00000000,0.00000000,0.00000000
137.10000000,2.55470200,9.23100000,0.08452622,605.35117057,0.08114323,656.51921813,0.00088230,0.09834725,684.10119378,-0.05215256,-0.04619469,0.00000000,0.00000000,0.00000000,0.00000000
138.60000000,2.59403100,9.24500000,0.08583200,606.26926356,0.08234651,658.30656699,0.00082678,0.09953876,685.64862403,-0.05275615,-0.04678261,0.00000000,0.00000000,0.00000000,0.00000000
140.10000000,2.63372400,9.25900000,0.08715989,607.18735655,0.08356869,660.10973908,0.00083252,0.10077582,687.08418738,-0.05342227,-0.04735355,0.00000000,0.00000000,0.00000000,0.00000000
141.60000000,2.67381500,9.27200000,0.08849522,608.03987147,0.08479621,661.84849501,0.00085866,0.10203038,688.68055345,-0.05410497,-0.04792541,0.00000000,0.00000000,0.00000000,0.00000000
143.10000000,2.71413800,9.28700000,0.08980100,609.02354253,0.08599511,663.71446567,0.00085069,0.10327418,690.12602808,-0.05479680,-0.04847738,0.00000000,0.00000000,0.00000000,0.00000000
144.60000000,2.75396300,9.29800000,0.09112522,609.74490131,0.08720948,665.30804094,0.00084294,0.10452332,691.50447118,-0.05549789,-0.04902543,0.00000000,0.00000000,0.00000000,0.00000000
146.10000000,2.79435100,9.31200000,0.09247156,610.66299429,0.08844261,667.13195130,0.00078146,0.10575087,692.94366315,-0.05617822,-0.04957265,0.00000000,0.00000000,0.00000000,0.00000000
147.60000000,2.83510500,9.32300000,0.09380678,611.38435307,0.08966407,668.73634922,0.00079372,0.10698661,694.39107021,-0.05682693,-0.05015968,0.00000000,0.00000000,0.00000000,0.00000000
149.10000000,2.87565900,9.33500000,0.09517511,612.17128992,0.09091427,670.43476046,0.00083312,0.10823105,695.77353131,-0.05745804,-0.05077301,0.00000000,0.00000000,0.00000000,0.00000000
150.60000000,2.91601400,9.34600000,0.09649567,612.89264870,0.09211934,672.03413343,0.00078508,0.10949723,697.09992011,-0.05811159,-0.05138563,0.00000000,0.00000000,0.00000000,0.00000000
152.10000000,2.95660200,9.35800000,0.09783467,613.67958555,0.09333975,673.71872324,0.00083110,0.11075456,698.56986504,-0.05876164,-0.05199292,0.00000000,0.00000000,0.00000000,0.00000000
153.60000000,2.99712300,9.37000000,0.09919933,614.46652239,0.09458204,675.42119177,0.00079002,0.11201389,699.96998729,-0.05946409,-0.05254980,0.00000000,0.00000000,0.00000000,0.00000000
155.10000000,3.03814000,9.38100000,0.10057878,615.18788117,0.09583620,677.06272636,0.00082923,0.11333721,701.34363069,-0.06019570,-0.05314151,0.00000000,0.00000000,0.00000000,0.00000000
156.60000000,3.07922400,9.39000000,0.10193233,615.77808381,0.09706531,678.54578071,0.00085464,0.11460000,702.67702416,-0.06089723,-0.05370277,0.00000000,0.00000000,0.00000000,0.00000000
158.10000000,3.12024300,9.39900000,0.10330444,616.36828645,0.09830972,680.04186985,0.00082698,0.11579296,703.96335446,-0.06147805,-0.05431491,0.00000000,0.00000000,0.00000000,0.00000000
159.60000000,3.16126000,9.40900000,0.10466178,617.02406715,0.09953920,681.60290295,0.00089258,0.11708855,705.32439202,-0.06220506,-0.05488349,0.00000000,0.00000000,0.00000000,0.00000000
161.10000000,3.20264200,9.41900000,0.10600067,617.67984786,0.10075051,683.15432352,0.00079843,0.11837577,706.68185727,-0.06289903,-0.05547674,0.00000000,0.00000000,0.00000000,0.00000000
162.60000000,3.24422300,9.42800000,0.10739478,618.27005050,0.10201021,684.66902517,0.00081068,0.11958069,707.90878475,-0.06348969,-0.05609100,0.00000000,0.00000000,0.00000000,0.00000000
164.10000000,3.28537300,9.43600000,0.10875956,618.79467506,0.10324187,686.09450890,0.00087625,0.12089435,709.21504077,-0.06423733,-0.05665703,0.00000000,0.00000000,0.00000000,0.00000000
165.60000000,3.32764800,9.44600000,0.11008733,619.45045577,0.10443869,687.64410458,0.00078207,0.12218675,710.50835036,-0.06493096,-0.05725579,0.00000000,0.00000000,0.00000000,0.00000000
167.10000000,3.36932700,9.45400000,0.11149989,619.97508033,0.10571035,689.10223290,0.00080108,0.12339964,711.82175297,-0.06556256,-0.05783708,0.00000000,0.00000000,0.00000000,0.00000000
168.60000000,3.41114000,9.46300000,0.11295289,620.56528297,0.10701674,690.65992442,0.00091250,0.12471815,713.06329187,-0.06630310,-0.05841504,0.00000000,0.00000000,0.00000000,0.00000000
170.10000000,3.45318400,9.46900000,0.11428444,620.95875139,0.10821245,691.92467732,0.00079249,0.12604784,714.31489431,-0.06702548,-0.05902236,0.00000000,0.00000000,0.00000000,0.00000000
171.60000000,3.49486400,9.47800000,0.11566011,621.54895403,0.10944626,693.43737511,0.00079132,0.12731417,715.59808075,-0.06765467,-0.05965951,0.00000000,0.00000000,0.00000000,0.00000000
173.10000000,3.53717300,9.48500000,0.11710944,622.00800052,0.11074450,694.85101191,0.00090253,0.12862071,716.91230317,-0.06837897,-0.06024174,0.00000000,0.00000000,0.00000000,0.00000000
174.60000000,3.57961400,9.49200000,0.11849978,622.46704702,0.11198830,696.22925377,0.00088809,0.12994232,718.08923361,-0.06906238,-0.06087994,0.00000000,0.00000000,0.00000000,0.00000000
176.10000000,3.62198900,9.49800000,0.11989022,622.86051544,0.11323066,697.53540105,0.00082783,0.13121691,719.30938059,-0.06976856,-0.06144835,0.00000000,0.00000000,0.00000000,0.00000000
177.60000000,3.66416600,9.50700000,0.12134322,623.45071808,0.11452727,699.10223711,0.00089238,0.13252540,720.48060521,-0.07050243,-0.06202296,0.00000000,0.00000000,0.00000000,0.00000000
179.10000000,3.70803000,9.51300000,0.12275567,623.84418650,0.11578608,700.42459551,0.00087799,0.13384772,721.73918329,-0.07121940,-0.06262833,0.00000000,0.00000000,0.00000000,0.00000000
180.60000000,3.75050500,9.51900000,0.12413511,624.23765493,0.11701395,701.72746558,0.00067401,0.13511093,722.95694871,-0.07184292,-0.06326801,0.00000000,0.00000000,0.00000000,0.00000000
182.10000000,3.79390600,9.52500000,0.12564322,624.63112335,0.11835463,703.11179039,0.00081708,0.13641437,724.13021067,-0.07254688,-0.06386749,0.00000000,0.00000000,0.00000000,0.00000000
183.60000000,3.83651300,9.53100000,0.12702633,625.02459178,0.11958260,704.41917391,0.00087486,0.13778319,725.27710401,-0.07331498,-0.06446821,0.00000000,0.00000000,0.00000000,0.00000000
185.10000000,3.87984900,9.53700000,0.12842422,625.41806020,0.12082217,705.73688815,0.00074986,0.13905406,726.50616094,-0.07400791,-0.06504615,0.00000000,0.00000000,0.00000000,0.00000000
186.60000000,3.92328200,9.54200000,0.12989922,625.74595055,0.12212844,707.02986284,0.00077505,0.14041888,727.72980334,-0.07476571,-0.06565317,0.00000000,0.00000000,0.00000000,0.00000000
188.10000000,3.96648700,9.54800000,0.13136322,626.13941898,0.12342330,708.39111062,0.00094323,0.14175057,728.85512571,-0.07550045,-0.06625012,0.00000000,0.00000000,0.00000000,0.00000000
189.60000000,4.01058300,9.55300000,0.13276111,626.46730933,0.12465811,709.63780539,0.00077309,0.14304874,729.95759611,-0.07619996,-0.06684878,0.00000000,0.00000000,0.00000000,0.00000000
191.10000000,4.05418300,9.55800000,0.13427656,626.79519969,0.12599505,710.95910014,0.00084987,0.14440842,731.10684615,-0.07695106,-0.06745736,0.00000000,0.00000000,0.00000000,0.00000000
192.60000000,4.09828000,9.56300000,0.13575167,627.12309004,0.12729469,712.25609472,0.00101084,0.14573441,732.30951587,-0.07764138,-0.06809304,0.00000000,0.00000000,0.00000000,0.00000000
194.10000000,4.14197900,9.56800000,0.13721556,627.45098039,0.12858278,713.54701525,0.00093818,0.14705889,733.43649052,-0.07836065,-0.06869825,0.00000000,0.00000000,0.00000000,0.00000000
195.60000000,4.18607600,9.57100000,0.13872378,627.64771460,0.12990814,714.71737669,0.00091761,0.14847615,734.63356724,-0.07912725,-0.06934891,0.00000000,0.00000000,0.00000000,0.00000000
197.10000000,4.23083500,9.57700000,0.14018033,628.04118303,0.13118644,716.08020541,0.00092931,0.14976554,735.73815314,-0.07980060,-0.06996493,0.00000000,0.00000000,0.00000000,0.00000000
198.60000000,4.27536200,9.58100000,0.14164800,628.30349531,0.13247283,717.30142882,0.00087651,0.15114744,736.91279028,-0.08058267,-0.07056477,0.00000000,0.00000000,0.00000000,0.00000000
200.10000000,4.31988900,9.58500000,0.14318933,628.56580759,0.13382202,718.56972654,0.00092044,0.15252788,738.01126952,-0.08133820,-0.07118968,0.00000000,0.00000000,0.00000000,0.00000000
201.60000000,4.36487900,9.58800000,0.14463122,628.76254181,0.13508251,719.70123671,0.00088063,0.15384359,739.06337397,-0.08203308,-0.07181051,0.00000000,0.00000000,0.00000000,0.00000000
203.10000000,4.40957100,9.59100000,0.14612100,628.95927602,0.13638320,720.86343439,0.00085388,0.15525129,740.26243136,-0.08279812,-0.07245316,0.00000000,0.00000000,0.00000000,0.00000000
204.60000000,4.45446300,9.59500000,0.14765489,629.22158830,0.13772063,722.12923201,0.00087211,0.15653226,741.29188916,-0.08343722,-0.07309504,0.00000000,0.00000000,0.00000000,0.00000000
206.10000000,4.49995000,9.59800000,0.14912256,629.41832251,0.13899866,723.27879128,0.00089015,0.15793641,742.41454703,-0.08422161,-0.07371480,0.00000000,0.00000000,0.00000000,0.00000000
207.60000000,4.54454400,9.60200000,0.15066756,629.68063480,0.14034226,724.55307682,0.00095929,0.15933812,743.61453028,-0.08500616,-0.07433196,0.00000000,0.00000000,0.00000000,0.00000000
209.10000000,4.58989900,9.60500000,0.15221244,629.87736901,0.14168396,725.75254304,0.00089413,0.16067639,744.61389800,-0.08572276,-0.07495363,0.00000000,0.00000000,0.00000000,0.00000000
210.60000000,4.63568400,9.60800000,0.15372056,630.07410322,0.14299199,726.92944441,0.00095675,0.16210575,745.76044261,-0.08651347,-0.07559228,0.00000000,0.00000000,0.00000000,0.00000000
212.10000000,4.68180000,9.61000000,0.15526544,630.20525936,0.14433014,728.05435905,0.00089177,0.16344039,746.75998426,-0.08722110,-0.07621929,0.00000000,0.00000000,0.00000000,0.00000000
213.60000000,4.72715400,9.61200000,0.15677356,630.33641550,0.14563471,729.15649656,0.00082680,0.16486605,747.82917647,-0.08801488,-0.07685117,0.00000000,0.00000000,0.00000000,0.00000000
215.10000000,4.77317100,9.61400000,0.15831856,630.46757164,0.14696943,730.28228691,0.00088942,0.16625847,748.95291503,-0.08879576,-0.07746270,0.00000000,0.00000000,0.00000000,0.00000000
216.60000000,4.81922100,9.61800000,0.15986344,630.72988393,0.14830228,731.56053569,0.00082479,0.16764884,750.07680048,-0.08951650,-0.07813234,0.00000000,0.00000000,0.00000000,0.00000000
218.10000000,4.86536900,9.62000000,0.16144511,630.86104007,0.14966502,732.71047078,0.00088683,0.00000000,0.00000000,0.00000000,0.00000000,0.00000000,0.00000000,0.00000000,0.00000000
219.60000000,4.91237900,9.62200000,0.16295333,630.99219621,0.15096275,733.81447789,0.00082260,0.00000000,0.00000000,0.00000000,0.00000000,0.00000000,0.00000000,0.00000000,0.00000000
221.10000000,4.95915700,9.62400000,0.16457178,631.12335235,0.15235345,734.98844444,0.00075808,0.00000000,0.00000000,0.00000000,0.00000000,0.00000000,0.00000000,0.00000000,0.00000000
222.60000000,5.00593600,9.62600000,0.16615356,631.25450849,0.15371077,736.13968954,0.00088344,0.00000000,0.00000000,0.00000000,0.00000000,0.00000000,0.00000000,0.00000000,0.00000000
224.10000000,5.05324300,9.62800000,0.16773522,631.38566463,0.15506617,737.29127940,0.00081923,0.00000000,0.00000000,0.00000000,0.00000000,0.00000000,0.00000000,0.00000000,0.00000000
225.60000000,5.10078200,9.62800000,0.16935367,631.38566463,0.15645117,738.31314202,0.00081790,0.00000000,0.00000000,0.00000000,0.00000000,0.00000000,0.00000000,0.00000000,0.00000000
227.10000000,5.14775900,9.63000000,0.17093544,631.51682078,0.15780295,739.46542921,0.00088002,0.00000000,0.00000000,0.00000000,0.00000000,0.00000000,0.00000000,0.00000000,0.00000000
228.60000000,5.19563000,9.63100000,0.17251711,631.58239885,0.15915281,740.54116972,0.00075294,0.00000000,0.00000000,0.00000000,0.00000000,0.00000000,0.00000000,0.00000000,0.00000000
230.10000000,5.24343500,9.63300000,0.17413567,631.71355499,0.16053227,741.71741603,0.00094011,0.00000000,0.00000000,0.00000000,0.00000000,0.00000000,0.00000000,0.00000000,0.00000000
231.60000000,5.29210000,9.63400000,0.17575422,631.77913306,0.16190983,742.81698320,0.00087623,0.00000000,0.00000000,0.00000000,0.00000000,0.00000000,0.00000000,0.00000000,0.00000000
233.10000000,5.33993700,9.63400000,0.17744622,631.77913306,0.16334787,743.88595350,0.00093746,0.00000000,0.00000000,0.00000000,0.00000000,0.00000000,0.00000000,0.00000000,0.00000000
234.60000000,5.38860300,9.63500000,0.17902789,631.84471113,0.16469028,744.96253587,0.00093621,0.00000000,0.00000000,0.00000000,0.00000000,0.00000000,0.00000000,0.00000000,0.00000000
236.10000000,5.43733400,9.63600000,0.18072000,631.91028920,0.16612442,746.10911666,0.00093486,0.00000000,0.00000000,0.00000000,0.00000000,0.00000000,0.00000000,0.00000000,0.00000000
237.60000000,5.48570200,9.63600000,0.18233856,631.91028920,0.16749430,747.13189857,0.00099583,0.00000000,0.00000000,0.00000000,0.00000000,0.00000000,0.00000000,0.00000000,0.00000000
239.10000000,5.53483000,9.63700000,0.18395700,631.97586727,0.16886222,748.23225189,0.00087015,0.00000000,0.00000000,0.00000000,0.00000000,0.00000000,0.00000000,0.00000000,0.00000000
240.60000000,5.58366100,9.63700000,0.18564900,631.97586727,0.17029030,749.30155505,0.00093079,0.00000000,0.00000000,0.00000000,0.00000000,0.00000000,0.00000000,0.00000000,0.00000000
242.10000000,5.63312100,9.63700000,0.18734111,631.97586727,0.00000000,0.00000000,0.00000000,0.00000000,0.00000000,0.00000000,0.00000000,0.00000000,0.00000000,0.00000000,0.00000000
243.60000000,5.68291100,9.63700000,0.18907000,631.97586727,0.00000000,0.00000000,0.00000000,0.00000000,0.00000000,0.00000000,0.00000000,0.00000000,0.00000000,0.00000000,0.00000000
245.10000000,5.73233900,9.63700000,0.19068856,631.97586727,0.00000000,0.00000000,0.00000000,0.00000000,0.00000000,0.00000000,0.00000000,0.00000000,0.00000000,0.00000000,0.00000000
246.60000000,5.78309000,9.63600000,0.19238056,631.91028920,0.00000000,0.00000000,0.00000000,0.00000000,0.00000000,0.00000000,0.00000000,0.00000000,0.00000000,0.00000000,0.00000000
248.10000000,5.83225100,9.63600000,0.19407267,631.91028920,0.00000000,0.00000000,0.00000000,0.00000000,0.00000000,0.00000000,0.00000000,0.00000000,0.00000000,0.00000000,0.00000000
249.60000000,5.88270500,9.63600000,0.19583833,631.91028920,0.00000000,0.00000000,0.00000000,0.00000000,0.00000000,0.00000000,0.00000000,0.00000000,0.00000000,0.00000000,0.00000000
251.10000000,5.93381900,9.63600000,0.19753033,631.91028920,0.00000000,0.00000000,0.00000000,0.00000000,0.00000000,0.00000000,0.00000000,0.00000000,0.00000000,0.00000000,0.00000000
252.60000000,5.98397500,9.63500000,0.19925933,631.84471113,0.00000000,0.00000000,0.00000000,0.00000000,0.00000000,0.00000000,0.00000000,0.00000000,0.00000000,0.00000000,0.00000000
254.10000000,6.03555400,9.63400000,0.20095144,631.77913306,0.00000000,0.00000000,0.00000000,0.00000000,0.00000000,0.00000000,0.00000000,0.00000000,0.00000000,0.00000000,0.00000000
255.60000000,6.08736300,9.63300000,0.20264344,631.71355499,0.00000000,0.00000000,0.00000000,0.00000000,0.00000000,0.00000000,0.00000000,0.00000000,0.00000000,0.00000000,0.00000000
257.10000000,6.13884300,9.63100000,0.20440900,631.58239885,0.00000000,0.00000000,0.00000000,0.00000000,0.00000000,0.00000000,0.00000000,0.00000000,0.00000000,0.00000000,0.00000000
258.60000000,6.19081800,9.63000000,0.20610111,631.51682078,0.00000000,0.00000000,0.00000000,0.00000000,0.00000000,0.00000000,0.00000000,0.00000000,0.00000000,0.00000000,0.00000000
260.10000000,6.24216500,9.62800000,0.20786678,631.38566463,0.00000000,0.00000000,0.00000000,0.00000000,0.00000000,0.00000000,0.00000000,0.00000000,0.00000000,0.00000000,0.00000000
261.60000000,6.29447300,9.62800000,0.20955889,631.38566463,0.00000000,0.00000000,0.00000000,0.00000000,0.00000000,0.00000000,0.00000000,0.00000000,0.00000000,0.00000000,0.00000000
263.10000000,6.34770700,9.62700000,0.21132456,631.32008656,0.00000000,0.00000000,0.00000000,0.00000000,0.00000000,0.00000000,0.00000000,0.00000000,0.00000000,0.00000000,0.00000000
264.60000000,6.40037800,9.62300000,0.21312700,631.05777428,0.00000000,0.00000000,0.00000000,0.00000000,0.00000000,0.00000000,0.00000000,0.00000000,0.00000000,0.00000000,0.00000000
266.10000000,6.45410800,9.62200000,0.21481900,630.99219621,0.00000000,0.00000000,0.00000000,0.00000000,0.00000000,0.00000000,0.00000000,0.00000000,0.00000000,0.00000000,0.00000000
267.60000000,6.50760700,9.61900000,0.21662144,630.79546200,0.00000000,0.00000000,0.00000000,0.00000000,0.00000000,0.00000000,0.00000000,0.00000000,0.00000000,0.00000000,0.00000000
269.10000000,6.56137000,9.61700000,0.21835033,630.66430586,0.00000000,0.00000000,0.00000000,0.00000000,0.00000000,0.00000000,0.00000000,0.00000000,0.00000000,0.00000000,0.00000000
270.60000000,6.61586200,9.61400000,0.22000567,630.46757164,0.00000000,0.00000000,0.00000000,0.00000000,0.00000000,0.00000000,0.00000000,0.00000000,0.00000000,0.00000000,0.00000000
272.10000000,6.67012300,9.61100000,0.22173456,630.27083743,0.00000000,0.00000000,0.00000000,0.00000000,0.00000000,0.00000000,0.00000000,0.00000000,0.00000000,0.00000000,0.00000000
273.60000000,6.72540900,9.60800000,0.22346333,630.07410322,0.00000000,0.00000000,0.00000000,0.00000000,0.00000000,0.00000000,0.00000000,0.00000000,0.00000000,0.00000000,0.00000000
275.10000000,6.78062900,9.60500000,0.22519222,629.87736901,0.00000000,0.00000000,0.00000000,0.00000000,0.00000000,0.00000000,0.00000000,0.00000000,0.00000000,0.00000000,0.00000000
276.60000000,6.83627900,9.60000000,0.22677400,629.54947865,0.00000000,0.00000000,0.00000000,0.00000000,0.00000000,0.00000000,0.00000000,0.00000000,0.00000000,0.00000000,0.00000000
278.10000000,6.89196200,9.59600000,0.22835578,629.28716637,0.00000000,0.00000000,0.00000000,0.00000000,0.00000000,0.00000000,0.00000000,0.00000000,0.00000000,0.00000000,0.00000000
279.60000000,6.94751300,9.59100000,0.22993756,628.95927602,0.00000000,0.00000000,0.00000000,0.00000000,0.00000000,0.00000000,0.00000000,0.00000000,0.00000000,0.00000000,0.00000000
281.10000000,7.00372600,9.58700000,0.23137211,628.69696374,0.00000000,0.00000000,0.00000000,0.00000000,0.00000000,0.00000000,0.00000000,0.00000000,0.00000000,0.00000000,0.00000000
282.60000000,7.06050300,9.58100000,0.23288022,628.30349531,0.00000000,0.00000000,0.00000000,0.00000000,0.00000000,0.00000000,0.00000000,0.00000000,0.00000000,0.00000000,0.00000000
284.10000000,7.11780800,9.57600000,0.23435178,627.97560496,0.00000000,0.00000000,0.00000000,0.00000000,0.00000000,0.00000000,0.00000000,0.00000000,0.00000000,0.00000000,0.00000000
285.60000000,7.17534500,9.56800000,0.23560244,627.45098039,0.00000000,0.00000000,0.00000000,0.00000000,0.00000000,0.00000000,0.00000000,0.00000000,0.00000000,0.00000000,0.00000000
287.10000000,7.23337900,9.56100000,0.23688989,626.99193390,0.00000000,0.00000000,0.00000000,0.00000000,0.00000000,0.00000000,0.00000000,0.00000000,0.00000000,0.00000000,0.00000000
288.60000000,7.29157900,9.55400000,0.23803011,626.53288740,0.00000000,0.00000000,0.00000000,0.00000000,0.00000000,0.00000000,0.00000000,0.00000000,0.00000000,0.00000000,0.00000000
290.10000000,7.34964600,9.54300000,0.23909689,625.81152862,0.00000000,0.00000000,0.00000000,0.00000000,0.00000000,0.00000000,0.00000000,0.00000000,0.00000000,0.00000000,0.00000000
291.60000000,7.40890400,9.53500000,0.24005333,625.28690406,0.00000000,0.00000000,0.00000000,0.00000000,0.00000000,0.00000000,0.00000000,0.00000000,0.00000000,0.00000000,0.00000000
293.10000000,7.46760000,9.52400000,0.24089944,624.56554528,0.00000000,0.00000000,0.00000000,0.00000000,0.00000000,0.00000000,0.00000000,0.00000000,0.00000000,0.00000000,0.00000000
294.60000000,7.52755300,9.51200000,0.24163511,623.77860843,0.00000000,0.00000000,0.00000000,0.00000000,0.00000000,0.00000000,0.00000000,0.00000000,0.00000000,0.00000000,0.00000000
296.10000000,7.58760700,9.49700000,0.24226044,622.79493737,0.00000000,0.00000000,0.00000000,0.00000000,0.00000000,0.00000000,0.00000000,0.00000000,0.00000000,0.00000000,0.00000000
297.60000000,7.64769300,9.48300000,0.24277544,621.87684438,0.00000000,0.00000000,0.00000000,0.00000000,0.00000000,0.00000000,0.00000000,0.00000000,0.00000000,0.00000000,0.00000000
299.10000000,7.70837400,9.46700000,0.24318022,620.82759525,0.00000000,0.00000000,0.00000000,0.00000000,0.00000000,0.00000000,0.00000000,0.00000000,0.00000000,0.00000000,0.00000000
300.60000000,7.76809500,9.45000000,0.24351122,619.71276805,0.00000000,0.00000000,0.00000000,0.00000000,0.00000000,0.00000000,0.00000000,0.00000000,0.00000000,0.00000000,0.00000000
302.10000000,7.82910800,9.43000000,0.24380556,618.40120664,0.00000000,0.00000000,0.00000000,0.00000000,0.00000000,0.00000000,0.00000000,0.00000000,0.00000000,0.00000000,0.00000000
303.60000000,7.88992200,9.40900000,0.24402633,617.02406715,0.00000000,0.00000000,0.00000000,0.00000000,0.00000000,0.00000000,0.00000000,0.00000000,0.00000000,0.00000000,0.00000000
305.10000000,7.95159700,9.38600000,0.24417344,615.51577153,0.00000000,0.00000000,0.00000000,0.00000000,0.00000000,0.00000000,0.00000000,0.00000000,0.00000000,0.00000000,0.00000000
306.60000000,8.01386700,9.36100000,0.24428378,613.87631976,0.00000000,0.00000000,0.00000000,0.00000000,0.00000000,0.00000000,0.00000000,0.00000000,0.00000000,0.00000000,0.00000000
308.10000000,8.07550700,9.33100000,0.24432067,611.90897764,0.00000000,0.00000000,0.00000000,0.00000000,0.00000000,0.00000000,0.00000000,0.00000000,0.00000000,0.00000000,0.00000000
309.60000000,8.13764400,9.30400000,0.24435744,610.13836973,0.00000000,0.00000000,0.00000000,0.00000000,0.00000000,0.00000000,0.00000000,0.00000000,0.00000000,0.00000000,0.00000000
311.10000000,8.19905200,9.27100000,0.24439422,607.97429340,0.00000000,0.00000000,0.00000000,0.00000000,0.00000000,0.00000000,0.00000000,0.00000000,0.00000000,0.00000000,0.00000000
312.60000000,8.26125600,9.23600000,0.24435756,605.67906092,0.00000000,0.00000000,0.00000000,0.00000000,0.00000000,0.00000000,0.00000000,0.00000000,0.00000000,0.00000000,0.00000000
314.10000000,8.32395400,9.19600000,0.24435756,603.05593809,0.00000000,0.00000000,0.00000000,0.00000000,0.00000000,0.00000000,0.00000000,0.00000000,0.00000000,0.00000000,0.00000000
315.60000000,8.38701600,9.15400000,0.24439444,600.30165913,0.00000000,0.00000000,0.00000000,0.00000000,0.00000000,0.00000000,0.00000000,0.00000000,0.00000000,0.00000000,0.00000000
317.10000000,8.45024100,9.10600000,0.24435778,597.15391173,0.00000000,0.00000000,0.00000000,0.00000000,0.00000000,0.00000000,0.00000000,0.00000000,0.00000000,0.00000000,0.00000000
318.60000000,8.51376400,9.05500000,0.24428433,593.80943013,0.00000000,0.00000000,0.00000000,0.00000000,0.00000000,0.00000000,0.00000000,0.00000000,0.00000000,0.00000000,0.00000000
320.10000000,8.57768100,8.99900000,0.24428433,590.13705817,0.00000000,0.00000000,0.00000000,0.00000000,0.00000000,0.00000000,0.00000000,0.00000000,0.00000000,0.00000000,0.00000000
321.60000000,8.64202800,8.94200000,0.24424778,586.39910814,0.00000000,0.00000000,0.00000000,0.00000000,0.00000000,0.00000000,0.00000000,0.00000000,0.00000000,0.00000000,0.00000000
323.10000000,8.70693500,8.86100000,0.24421122,581.08728441,0.00000000,0.00000000,0.00000000,0.00000000,0.00000000,0.00000000,0.00000000,0.00000000,0.00000000,0.00000000,0.00000000
324.60000000,8.77233800,8.78800000,0.24421156,576.30008525,0.00000000,0.00000000,0.00000000,0.00000000,0.00000000,0.00000000,0.00000000,0.00000000,0.00000000,0.00000000,0.00000000
326.10000000,8.83896200,8.69000000,0.24413867,569.87343432,0.00000000,0.00000000,0.00000000,0.00000000,0.00000000,0.00000000,0.00000000,0.00000000,0.00000000,0.00000000,0.00000000
327.60000000,8.90618200,8.58400000,0.24406567,562.92215883,0.00000000,0.00000000,0.00000000,0.00000000,0.00000000,0.00000000,0.00000000,0.00000000,0.00000000,0.00000000,0.00000000
329.10000000,8.97618100,8.44800000,0.24399289,554.00354122,0.00000000,0.00000000,0.00000000,0.00000000,0.00000000,0.00000000,0.00000000,0.00000000,0.00000000,0.00000000,0.00000000
330.60000000,9.04760700,8.30900000,0.24392022,544.88818939,0.00000000,0.00000000,0.00000000,0.00000000,0.00000000,0.00000000,0.00000000,0.00000000,0.00000000,0.00000000,0.00000000
332.10000000,9.12291200,8.09000000,0.24381122,530.52659191,0.00000000,0.00000000,0.00000000,0.00000000,0.00000000,0.00000000,0.00000000,0.00000000,0.00000000,0.00000000,0.00000000
332.60000000,9.16607900,8.03800000,0.24421544,527.11653223,0.00000000,0.00000000,0.00000000,0.00000000,0.00000000,0.00000000,0.00000000,0.00000000,0.00000000,0.00000000,0.00000000