File: lab_data/DP600_results/DATA/UT_15_3.csv
Time[s],Displacement[mm],Force[kN],EngStrain_longi,EngStress[MPa],TrueStrain,TrueStress[MPa],TrueStrainRate[1/s],PlasticStrain_longi,PlasticStress[MPa],PlasticStrain_thick,PlasticStrain_width,R-Value,Thickness[mm],Width[mm], Young's Modulus [MPa]
0.65000000,0.00000000,-0.01500000,0.00000000,-0.98515697,0.00000000,-0.98515697,0.00000000,0.00053646,320.24440177,0.00029177,-0.00082822,0.83955462,1.52260000,10.00000000,219753.47151367
2.15000000,0.00142300,0.07900000,0.00003800,5.18849337,0.00003800,5.18869053,0.00002178,0.00082613,338.80000126,0.00004923,-0.00087537,0.00000000,0.00000000,0.00000000,0.00000000
3.65000000,0.00347300,0.44800000,0.00008678,29.42335479,0.00008677,29.42590808,0.00004222,0.00123185,352.19867327,-0.00019147,-0.00104038,0.00000000,0.00000000,0.00000000,0.00000000
5.15000000,0.00590600,0.78000000,0.00020456,51.22816235,0.00020453,51.23864136,0.00020019,0.00179562,366.26199409,-0.00040725,-0.00138837,0.00000000,0.00000000,0.00000000,0.00000000
6.65000000,0.00747200,1.11100000,0.00023722,72.96729279,0.00023719,72.98460225,0.00012709,0.00252790,377.89605936,-0.00075585,-0.00177204,0.00000000,0.00000000,0.00000000,0.00000000
8.15000000,0.00902100,1.44900000,0.00028400,95.16616314,0.00028396,95.19319033,0.00011553,0.00324420,388.94681413,-0.00105830,-0.00218589,0.00000000,0.00000000,0.00000000,0.00000000
9.65000000,0.01088800,1.78400000,0.00032478,117.16800210,0.00032473,117.20605567,0.00002421,0.00397864,397.57261728,-0.00145282,-0.00252582,0.00000000,0.00000000,0.00000000,0.00000000
11.15000000,0.01328500,2.11600000,0.00041311,138.97280967,0.00041303,139.03022088,-0.00009840,0.00473262,407.34571400,-0.00187898,-0.00285364,0.00000000,0.00000000,0.00000000,0.00000000
12.65000000,0.01641700,2.47100000,0.00052567,162.28819125,0.00052553,162.37350074,-0.00011172,0.00569401,414.83361589,-0.00246455,-0.00322945,0.00000000,0.00000000,0.00000000,0.00000000
14.15000000,0.02055200,2.80000000,0.00066722,183.89596742,0.00066700,184.01866690,0.00006174,0.00658886,423.03808474,-0.00292868,-0.00366018,0.00000000,0.00000000,0.00000000,0.00000000
15.65000000,0.02449800,3.15300000,0.00085189,207.07999475,0.00085153,207.25640389,0.00033308,0.00742196,430.30072508,-0.00329076,-0.00413120,0.00000000,0.00000000,0.00000000,0.00000000
17.15000000,0.02815900,3.47700000,0.00096522,228.35938526,0.00096476,228.57980282,0.00037856,0.00826436,437.71276261,-0.00370157,-0.00456280,0.00000000,0.00000000,0.00000000,0.00000000
18.65000000,0.03200900,3.79500000,0.00103511,249.24471299,0.00103458,249.50270896,0.00032347,0.00922113,443.85719184,-0.00423702,-0.00498412,0.00000000,0.00000000,0.00000000,0.00000000
20.15000000,0.03764100,4.10500000,0.00109978,269.60462367,0.00109917,269.90112884,0.00011743,0.01018947,451.21799383,-0.00485814,-0.00533133,0.00000000,0.00000000,0.00000000,0.00000000
21.65000000,0.04535400,4.42600000,0.00128378,290.68698279,0.00128295,291.06016028,-0.00012472,0.01106610,457.01695534,-0.00533968,-0.00572642,0.00000000,0.00000000,0.00000000,0.00000000
23.15000000,0.05445800,4.70500000,0.00161111,309.01090240,0.00160981,309.50875330,-0.00022762,0.01194805,463.82993470,-0.00583330,-0.00611474,0.00000000,0.00000000,0.00000000,0.00000000
24.65000000,0.06452200,4.98200000,0.00210033,327.20346775,0.00209813,327.89070410,0.00007340,0.01294452,469.23875944,-0.00640751,-0.00653701,0.00000000,0.00000000,0.00000000,0.00000000
26.15000000,0.07918800,5.21500000,0.00262633,342.50623933,0.00262289,343.40577488,0.00036685,0.01394381,475.32854280,-0.00693449,-0.00700933,0.00000000,0.00000000,0.00000000,0.00000000
27.65000000,0.09607200,5.42500000,0.00317444,356.29843688,0.00316942,357.42948648,0.00052086,0.01487834,480.39461834,-0.00737383,-0.00750451,0.00000000,0.00000000,0.00000000,0.00000000
29.15000000,0.11477600,5.61200000,0.00376300,368.58006042,0.00375594,369.96702719,0.00043242,0.01578546,486.46213986,-0.00783010,-0.00795536,0.00000000,0.00000000,0.00000000,0.00000000
30.65000000,0.13841400,5.78900000,0.00450600,380.20491265,0.00449588,381.91811599,0.00033695,0.01678481,491.17701074,-0.00839193,-0.00839288,0.00000000,0.00000000,0.00000000,0.00000000
32.15000000,0.16241600,5.93500000,0.00540722,389.79377381,0.00539266,391.90147536,0.00059266,0.01780012,496.84939882,-0.00901250,-0.00878762,0.00000000,0.00000000,0.00000000,0.00000000
33.65000000,0.18820500,6.07700000,0.00626422,399.11992644,0.00624468,401.62010235,0.00074569,0.01880930,501.31961240,-0.00958500,-0.00922429,0.00000000,0.00000000,0.00000000,0.00000000
35.15000000,0.21286900,6.19800000,0.00707722,407.06685932,0.00705230,409.94776194,0.00075988,0.01978903,506.45674228,-0.01012028,-0.00966875,0.00000000,0.00000000,0.00000000,0.00000000
36.65000000,0.24167000,6.31100000,0.00793789,414.48837515,0.00790655,417.77853782,0.00047429,0.02081887,510.68600257,-0.01064014,-0.01017873,0.00000000,0.00000000,0.00000000,0.00000000
38.15000000,0.26878300,6.41800000,0.00890533,421.51582819,0.00886591,425.26956714,0.00052517,0.02183983,515.79598078,-0.01117414,-0.01066569,0.00000000,0.00000000,0.00000000,0.00000000
39.65000000,0.29695600,6.52900000,0.00989844,428.80598975,0.00984978,433.05050202,0.00075754,0.02285074,519.76286606,-0.01167192,-0.01117881,0.00000000,0.00000000,0.00000000,0.00000000
41.15000000,0.32440000,6.62500000,0.01076656,435.11099435,0.01070901,439.79564105,0.00072060,0.02388531,524.56103895,-0.01221667,-0.01166863,0.00000000,0.00000000,0.00000000,0.00000000
42.65000000,0.35393000,6.72400000,0.01166044,441.61303034,0.01159299,446.76243455,0.00051649,0.02494435,528.50200568,-0.01280716,-0.01213719,0.00000000,0.00000000,0.00000000,0.00000000
44.15000000,0.38160600,6.81400000,0.01263889,447.52397215,0.01255968,453.18017791,0.00044312,0.02600436,532.72239877,-0.01341365,-0.01259071,0.00000000,0.00000000,0.00000000,0.00000000
45.65000000,0.41080500,6.89900000,0.01366511,453.10652831,0.01357259,459.29827936,0.00066042,0.02706585,536.40951589,-0.01395880,-0.01310705,0.00000000,0.00000000,0.00000000,0.00000000
47.15000000,0.44093200,6.98200000,0.01461789,458.55773020,0.01451208,465.26087615,0.00071063,0.02812324,540.71286635,-0.01460123,-0.01352201,0.00000000,0.00000000,0.00000000,0.00000000
48.65000000,0.46920400,7.06700000,0.01552644,464.14028635,0.01540714,471.34673472,0.00045630,0.02919394,544.21647130,-0.01517908,-0.01401486,0.00000000,0.00000000,0.00000000,0.00000000
50.15000000,0.50029000,7.14300000,0.01655267,469.13174833,0.01641716,476.89712978,0.00041976,0.03027124,548.34315585,-0.01573168,-0.01453956,0.00000000,0.00000000,0.00000000,0.00000000
51.65000000,0.53084600,7.22400000,0.01761211,474.45159595,0.01745882,482.80769018,0.00058577,0.03131209,551.64058896,-0.01628113,-0.01503096,0.00000000,0.00000000,0.00000000,0.00000000
53.15000000,0.56156700,7.29500000,0.01862356,479.11467227,0.01845226,488.03749099,0.00070063,0.03241362,555.38737076,-0.01684897,-0.01556466,0.00000000,0.00000000,0.00000000,0.00000000
54.65000000,0.59215600,7.36300000,0.01961667,483.58071719,0.01942674,493.06695893,0.00060598,0.03347756,558.57459138,-0.01740027,-0.01607729,0.00000000,0.00000000,0.00000000,0.00000000
56.15000000,0.62360600,7.42900000,0.02067244,487.91540785,0.02046167,498.00181202,0.00059120,0.03456953,562.33067124,-0.01802164,-0.01654789,0.00000000,0.00000000,0.00000000,0.00000000
57.65000000,0.65475800,7.49800000,0.02173178,492.44712991,0.02149901,503.14888150,0.00060495,0.03567415,565.41730202,-0.01863128,-0.01704286,0.00000000,0.00000000,0.00000000,0.00000000
59.15000000,0.68693600,7.56000000,0.02282789,496.51911205,0.02257123,507.85359517,0.00074100,0.03678213,568.99163571,-0.01924147,-0.01754067,0.00000000,0.00000000,0.00000000,0.00000000
60.65000000,0.71888200,7.62400000,0.02385411,500.72244844,0.02357405,512.66673736,0.00064668,0.03787069,571.94489784,-0.01984410,-0.01802659,0.00000000,0.00000000,0.00000000,0.00000000
62.15000000,0.75092800,7.68200000,0.02494300,504.53172205,0.02463700,517.11625680,0.00068200,0.03897456,575.11881899,-0.02045918,-0.01851538,0.00000000,0.00000000,0.00000000,0.00000000
63.65000000,0.78390100,7.73800000,0.02602811,508.20964140,0.02569515,521.43737842,0.00073869,0.04010342,577.96992451,-0.02111950,-0.01898392,0.00000000,0.00000000,0.00000000,0.00000000
65.15000000,0.81621200,7.79200000,0.02711322,511.75620649,0.02675217,525.63156624,0.00073791,0.04124627,581.31671841,-0.02176992,-0.01947634,0.00000000,0.00000000,0.00000000,0.00000000
66.65000000,0.84911800,7.84800000,0.02820933,515.43412584,0.02781878,529.97417890,0.00071550,0.04230998,584.00403914,-0.02228443,-0.02002555,0.00000000,0.00000000,0.00000000,0.00000000
68.15000000,0.88179300,7.89900000,0.02930556,518.78365953,0.02888436,533.98690289,0.00068645,0.04345073,587.22466633,-0.02287042,-0.02058031,0.00000000,0.00000000,0.00000000,0.00000000
69.65000000,0.91546100,7.95100000,0.03042744,522.19887035,0.02997371,538.08804747,0.00070706,0.04463513,589.85626308,-0.02351059,-0.02112454,0.00000000,0.00000000,0.00000000,0.00000000
71.15000000,0.94903000,7.99900000,0.03153833,525.35137265,0.03105122,541.92007936,0.00070630,0.04575734,592.73295504,-0.02411079,-0.02164655,0.00000000,0.00000000,0.00000000,0.00000000
72.65000000,0.98319500,8.04500000,0.03266022,528.37252069,0.03213821,545.62928463,0.00070553,0.04687292,595.26537904,-0.02467869,-0.02219423,0.00000000,0.00000000,0.00000000,0.00000000
74.15000000,1.01676400,8.08900000,0.03377478,531.26231446,0.03321694,549.20558107,0.00066907,0.04804105,598.25009845,-0.02532940,-0.02271165,0.00000000,0.00000000,0.00000000,0.00000000
75.65000000,1.05106100,8.13600000,0.03490400,534.34913963,0.03430867,553.00006200,0.00073944,0.04918252,600.66991707,-0.02593041,-0.02325212,0.00000000,0.00000000,0.00000000,0.00000000
77.15000000,1.08492700,8.17800000,0.03603689,537.10757914,0.03540275,556.46326529,0.00068885,0.05029977,603.49666128,-0.02655689,-0.02374288,0.00000000,0.00000000,0.00000000,0.00000000
78.65000000,1.11925700,8.22100000,0.03720300,539.93169578,0.03652767,560.01877466,0.00078046,0.05144929,605.86186279,-0.02714377,-0.02430552,0.00000000,0.00000000,0.00000000,0.00000000
80.15000000,1.15378600,8.26000000,0.03831756,542.49310390,0.03760167,563.28011355,0.00070875,0.05262390,608.52557508,-0.02783655,-0.02478735,0.00000000,0.00000000,0.00000000,0.00000000
81.65000000,1.18851400,8.29800000,0.03947256,544.98883489,0.03871343,566.50093695,0.00069363,0.05375740,610.75132497,-0.02843011,-0.02532729,0.00000000,0.00000000,0.00000000,0.00000000
83.15000000,1.22367200,8.33600000,0.04067533,547.48456587,0.03986986,569.75368309,0.00075649,0.05492197,613.48903087,-0.02904981,-0.02587216,0.00000000,0.00000000,0.00000000,0.00000000
84.65000000,1.25836600,8.37500000,0.04187078,550.04597399,0.04101792,573.07682674,0.00084737,0.05606356,615.65916549,-0.02967761,-0.02638595,0.00000000,0.00000000,0.00000000,0.00000000
86.15000000,1.29335800,8.41000000,0.04300744,552.34467358,0.04210831,576.09960645,0.00079018,0.05727464,618.22636232,-0.03030267,-0.02697197,0.00000000,0.00000000,0.00000000,0.00000000
87.65000000,1.32825100,8.44600000,0.04417711,554.70905031,0.04322912,579.21449366,0.00074693,0.05841003,620.40160241,-0.03090324,-0.02750679,0.00000000,0.00000000,0.00000000,0.00000000
89.15000000,1.36357500,8.48000000,0.04541678,556.94207277,0.04441564,582.23658712,0.00080239,0.05957787,622.74154265,-0.03153850,-0.02803936,0.00000000,0.00000000,0.00000000,0.00000000
90.65000000,1.39969200,8.51200000,0.04660111,559.04374097,0.04554788,585.09580046,0.00091385,0.06074187,624.87312760,-0.03216362,-0.02857825,0.00000000,0.00000000,0.00000000,0.00000000
92.15000000,1.43528000,8.54400000,0.04776722,561.14540917,0.04666145,587.94976663,0.00082881,0.06194093,627.31209547,-0.03282166,-0.02911927,0.00000000,0.00000000,0.00000000,0.00000000
93.65000000,1.47123300,8.57600000,0.04896633,563.24707737,0.04780523,590.82722151,0.00072253,0.06312330,629.32326251,-0.03347458,-0.02964872,0.00000000,0.00000000,0.00000000,0.00000000
95.15000000,1.50754900,8.60600000,0.05018756,565.21739130,0.04896877,593.58427053,0.00077779,0.06426565,631.52437453,-0.03409434,-0.03017131,0.00000000,0.00000000,0.00000000,0.00000000
96.65000000,1.54360100,8.63700000,0.05138300,567.25338237,0.05010644,596.40056292,0.00079784,0.06546237,633.55267487,-0.03474594,-0.03071643,0.00000000,0.00000000,0.00000000,0.00000000
98.15000000,1.57985100,8.66500000,0.05257478,569.09234205,0.05123933,599.01224546,0.00069894,0.06664970,635.79086439,-0.03541453,-0.03123517,0.00000000,0.00000000,0.00000000,0.00000000
99.65000000,1.61630000,8.69200000,0.05378500,570.86562459,0.05238844,601.56963221,0.00069117,0.06785108,637.68893537,-0.03607151,-0.03177958,0.00000000,0.00000000,0.00000000,0.00000000
101.15000000,1.65278200,8.71900000,0.05502456,572.63890713,0.05356404,604.14810849,0.00078097,0.06902563,639.85667061,-0.03670449,-0.03232114,0.00000000,0.00000000,0.00000000,0.00000000
102.65000000,1.68972800,8.74800000,0.05625689,574.54354394,0.05473142,606.86557625,0.00079416,0.07023123,641.69421633,-0.03733339,-0.03289784,0.00000000,0.00000000,0.00000000,0.00000000
104.15000000,1.72700500,8.77300000,0.05744500,576.18547222,0.05585562,609.28444667,0.00066797,0.07143355,643.88805333,-0.03799817,-0.03343538,0.00000000,0.00000000,0.00000000,0.00000000
105.65000000,1.76332100,8.79900000,0.05868822,577.89307763,0.05703062,611.80859499,0.00072976,0.07265989,645.74653907,-0.03867620,-0.03398370,0.00000000,0.00000000,0.00000000,0.00000000
107.15000000,1.80089600,8.82300000,0.05996467,579.46932878,0.05823557,614.21701392,0.00078446,0.07384703,647.65432578,-0.03931444,-0.03453260,0.00000000,0.00000000,0.00000000,0.00000000
108.65000000,1.83817300,8.84600000,0.06119689,580.97990280,0.05939741,616.53406536,0.00080429,0.07505346,649.50709377,-0.03999979,-0.03505366,0.00000000,0.00000000,0.00000000,0.00000000
110.15000000,1.87578000,8.86900000,0.06242178,582.49047682,0.06055100,618.85056792,0.00066484,0.07625771,651.50465258,-0.04062461,-0.03563311,0.00000000,0.00000000,0.00000000,0.00000000
111.65000000,1.91318900,8.89200000,0.06368722,584.00105083,0.06174138,621.19445554,0.00075412,0.07747196,653.22702132,-0.04127378,-0.03619818,0.00000000,0.00000000,0.00000000,0.00000000
113.15000000,1.95059800,8.91300000,0.06495622,585.38027059,0.06293369,623.40436153,0.00078078,0.07866303,655.22340377,-0.04189500,-0.03676803,0.00000000,0.00000000,0.00000000,0.00000000
114.65000000,1.98860300,8.93600000,0.06623256,586.89084461,0.06413146,625.76212508,0.00082801,0.07989458,656.96399292,-0.04259769,-0.03729689,0.00000000,0.00000000,0.00000000,0.00000000
116.15000000,2.02624400,8.95700000,0.06747222,588.27006436,0.06529344,627.96195287,0.00073062,0.08110734,658.76716319,-0.04324616,-0.03786118,0.00000000,0.00000000,0.00000000,0.00000000
117.65000000,2.06461300,8.97600000,0.06878533,589.51792986,0.06652280,630.06811717,0.00080544,0.08233918,660.51464648,-0.04394741,-0.03839178,0.00000000,0.00000000,0.00000000,0.00000000
119.15000000,2.10242000,8.99500000,0.07002500,590.76579535,0.06768201,632.13417017,0.00081822,0.08355562,662.32708739,-0.04458519,-0.03897044,0.00000000,0.00000000,0.00000000,0.00000000
120.65000000,2.14025900,9.01500000,0.07131244,592.07933797,0.06888448,634.30196287,0.00081039,0.08478507,663.93582762,-0.04528359,-0.03950148,0.00000000,0.00000000,0.00000000,0.00000000
122.15000000,2.17876100,9.03400000,0.07258144,593.32720347,0.07006831,636.39174892,0.00078207,0.08604215,665.78209221,-0.04595909,-0.04008305,0.00000000,0.00000000,0.00000000,0.00000000
123.65000000,2.21756000,9.05300000,0.07391678,594.57506896,0.07131250,638.52414221,0.00084962,0.08728852,667.40843656,-0.04664744,-0.04064107,0.00000000,0.00000000,0.00000000,0.00000000
125.15000000,2.25599500,9.07000000,0.07517478,595.69158019,0.07248323,640.47256236,0.00082133,0.08852595,669.17625780,-0.04730994,-0.04121601,0.00000000,0.00000000,0.00000000,0.00000000
126.65000000,2.29482800,9.08700000,0.07646956,596.80809142,0.07368676,642.44574093,0.00079969,0.08977961,670.74145738,-0.04799244,-0.04178717,0.00000000,0.00000000,0.00000000,0.00000000
128.15000000,2.33366100,9.10400000,0.07778644,597.92460265,0.07490935,644.43503154,0.00081934,0.09100784,672.36479903,-0.04865518,-0.04235265,0.00000000,0.00000000,0.00000000,0.00000000
129.65000000,2.37252700,9.12100000,0.07909956,599.04111388,0.07612695,646.42499975,0.00078414,0.09223131,673.98792346,-0.04932864,-0.04290267,0.00000000,0.00000000,0.00000000,0.00000000
131.15000000,2.41149100,9.13600000,0.08038700,600.02627085,0.07731931,648.26058269,0.00077642,0.09353973,675.67161364,-0.05005906,-0.04348067,0.00000000,0.00000000,0.00000000,0.00000000
132.65000000,2.45058900,9.15200000,0.08168922,601.07710495,0.07852391,650.17862615,0.00075513,0.09476713,677.23085157,-0.05070748,-0.04405965,0.00000000,0.00000000,0.00000000,0.00000000
134.15000000,2.48991800,9.16800000,0.08299867,602.12793905,0.07973374,652.10375516,0.00074724,0.09598627,678.78730148,-0.05136626,-0.04462001,0.00000000,0.00000000,0.00000000,0.00000000
135.65000000,2.52990900,9.18300000,0.08434133,603.11309602,0.08097274,653.98045869,0.00078035,0.09724357,680.37260397,-0.05203721,-0.04520637,0.00000000,0.00000000,0.00000000,0.00000000
137.15000000,2.56996700,9.19600000,0.08568033,603.96689873,0.08220683,655.71498393,0.00084737,0.09853623,681.91207842,-0.05274484,-0.04579139,0.00000000,0.00000000,0.00000000,0.00000000
138.65000000,2.60929600,9.21100000,0.08700089,604.95205569,0.08342243,657.58342227,0.00079889,0.09976129,683.33503328,-0.05339287,-0.04636842,0.00000000,0.00000000,0.00000000,0.00000000
140.15000000,2.64951900,9.22400000,0.08834711,605.80585840,0.08466013,659.32705588,0.00083161,0.10100425,684.84589025,-0.05406978,-0.04693446,0.00000000,0.00000000,0.00000000,0.00000000
141.65000000,2.68904700,9.23800000,0.08968978,606.72533824,0.08589305,661.14239900,0.00081712,0.10230512,686.39935584,-0.05479863,-0.04750649,0.00000000,0.00000000,0.00000000,0.00000000
143.15000000,2.72950200,9.25000000,0.09106544,607.51346381,0.08715469,662.83694740,0.00089026,0.10355154,687.91813292,-0.05546494,-0.04808660,0.00000000,0.00000000,0.00000000,0.00000000
144.65000000,2.76955900,9.26300000,0.09241911,608.36726652,0.08839461,664.59202852,0.00089587,0.10480363,689.29674854,-0.05612798,-0.04867565,0.00000000,0.00000000,0.00000000,0.00000000
146.15000000,2.81031200,9.27500000,0.09379111,609.15539209,0.08964975,666.28875316,0.00087442,0.10611658,690.71992365,-0.05687928,-0.04923730,0.00000000,0.00000000,0.00000000,0.00000000
147.65000000,2.85116400,9.28700000,0.09517422,609.94351767,0.09091346,667.99441756,0.00089361,0.10738153,692.18594039,-0.05759133,-0.04979020,0.00000000,0.00000000,0.00000000,0.00000000
149.15000000,2.89145400,9.29800000,0.09649478,610.66596611,0.09211853,669.59204281,0.00081204,0.10863867,693.57544472,-0.05825362,-0.05038505,0.00000000,0.00000000,0.00000000,0.00000000
150.65000000,2.93210700,9.31000000,0.09787044,611.45409169,0.09337234,671.29737540,0.00079746,0.10994281,695.07393275,-0.05896682,-0.05097600,0.00000000,0.00000000,0.00000000,0.00000000
152.15000000,2.97309100,9.32000000,0.09924611,612.11086300,0.09462459,672.86048572,0.00083003,0.11120357,696.39706152,-0.05963180,-0.05157177,0.00000000,0.00000000,0.00000000,0.00000000
153.65000000,3.01400900,9.33200000,0.10062189,612.89898857,0.09587537,674.57004250,0.00086919,0.11248189,697.80872170,-0.06033474,-0.05214714,0.00000000,0.00000000,0.00000000,0.00000000
155.15000000,3.05519200,9.34200000,0.10200856,613.55575988,0.09713447,676.14369670,0.00075452,0.11380136,699.17765417,-0.06105746,-0.05274390,0.00000000,0.00000000,0.00000000,0.00000000
156.65000000,3.09664100,9.35300000,0.10336589,614.27820833,0.09836541,677.77362136,0.00074674,0.11510563,700.61250017,-0.06176717,-0.05333846,0.00000000,0.00000000,0.00000000,0.00000000
158.15000000,3.13759200,9.36100000,0.10480789,614.80362538,0.09967146,679.23989543,0.00090574,0.11638619,701.88465547,-0.06245541,-0.05393079,0.00000000,0.00000000,0.00000000,0.00000000
159.65000000,3.17910600,9.37200000,0.10616144,615.52607382,0.10089586,680.87121091,0.00082484,0.11768731,703.24781162,-0.06315622,-0.05453109,0.00000000,0.00000000,0.00000000,0.00000000
161.15000000,3.22078600,9.38100000,0.10759600,616.11716800,0.10219190,682.40891081,0.00081695,0.11897756,704.53118683,-0.06385180,-0.05512576,0.00000000,0.00000000,0.00000000,0.00000000
162.65000000,3.26246500,9.39000000,0.10901956,616.70826218,0.10347634,683.94152283,0.00092215,0.12027502,705.97095653,-0.06452317,-0.05575185,0.00000000,0.00000000,0.00000000,0.00000000
164.15000000,3.30371500,9.39800000,0.11038067,617.23367923,0.10470290,685.36434424,0.00087497,0.12159102,707.27711861,-0.06525181,-0.05633921,0.00000000,0.00000000,0.00000000,0.00000000
165.65000000,3.34552700,9.40700000,0.11181878,617.82477341,0.10599721,686.90918446,0.00084704,0.12287966,708.49129060,-0.06595154,-0.05692812,0.00000000,0.00000000,0.00000000,0.00000000
167.15000000,3.38826600,9.41500000,0.11323500,618.35019046,0.10727019,688.36907428,0.00088570,0.12415296,709.84622314,-0.06662235,-0.05753060,0.00000000,0.00000000,0.00000000,0.00000000
168.65000000,3.43050800,9.42200000,0.11461067,618.80993038,0.10850517,689.73214904,0.00083834,0.12552529,711.12422105,-0.06741755,-0.05810775,0.00000000,0.00000000,0.00000000,0.00000000
170.15000000,3.47212100,9.43000000,0.11607467,619.33534743,0.10981777,691.22449144,0.00082409,0.12681524,712.34550755,-0.06809750,-0.05871774,0.00000000,0.00000000,0.00000000,0.00000000
171.65000000,3.51400000,9.43700000,0.11750189,619.79508735,0.11109574,692.62218084,0.00083617,0.12810680,713.56993257,-0.06883417,-0.05927264,0.00000000,0.00000000,0.00000000,0.00000000
173.15000000,3.55683800,9.44500000,0.11894022,620.32050440,0.11238201,694.10156304,0.00088119,0.12945118,714.83421873,-0.06956848,-0.05988270,0.00000000,0.00000000,0.00000000,0.00000000
174.65000000,3.59944500,9.45100000,0.12035267,620.71456719,0.11364352,695.41922059,0.00078165,0.13077739,716.16294383,-0.07030148,-0.06047591,0.00000000,0.00000000,0.00000000,0.00000000
176.15000000,3.64145500,9.45800000,0.12182022,621.17430711,0.11495256,696.84589924,0.00086565,0.13209890,717.41509349,-0.07102033,-0.06107857,0.00000000,0.00000000,0.00000000,0.00000000
177.65000000,3.68488900,9.46500000,0.12328422,621.63404702,0.11625674,698.27171702,0.00090390,0.13347346,718.63200556,-0.07177538,-0.06169808,0.00000000,0.00000000,0.00000000,0.00000000
179.15000000,3.72805900,9.47200000,0.12473722,622.09378694,0.11754943,699.69203789,0.00083731,0.13476264,719.86490910,-0.07249522,-0.06226742,0.00000000,0.00000000,0.00000000,0.00000000
180.65000000,3.77169200,9.47700000,0.12621956,622.42217260,0.11886650,700.98402259,0.00084924,0.13609518,721.05541882,-0.07318662,-0.06290856,0.00000000,0.00000000,0.00000000,0.00000000
182.15000000,3.81449700,9.48300000,0.12766889,622.81623539,0.12015257,702.33049214,0.00084814,0.13746702,722.35219265,-0.07394526,-0.06352176,0.00000000,0.00000000,0.00000000,0.00000000
183.65000000,3.85809700,9.48900000,0.12911822,623.21029817,0.12143699,703.67810395,0.00080177,0.13884393,723.50289308,-0.07473115,-0.06411277,0.00000000,0.00000000,0.00000000,0.00000000
185.15000000,3.90136600,9.49500000,0.13061900,623.60436096,0.12276527,705.05893899,0.00086559,0.14014558,724.67675726,-0.07540812,-0.06473745,0.00000000,0.00000000,0.00000000,0.00000000
186.65000000,3.94533000,9.50000000,0.13208667,623.93274662,0.12406254,706.34594334,0.00085151,0.14154072,725.92056811,-0.07619706,-0.06534366,0.00000000,0.00000000,0.00000000,0.00000000
188.15000000,3.98853300,9.50600000,0.13360589,624.32680940,0.12540360,707.74054773,0.00088920,0.14287049,727.11874408,-0.07690926,-0.06596124,0.00000000,0.00000000,0.00000000,0.00000000
189.65000000,4.03272900,9.51000000,0.13509567,624.58951793,0.12671694,708.96885525,0.00092701,0.14426217,728.28768310,-0.07769958,-0.06656259,0.00000000,0.00000000,0.00000000,0.00000000
191.15000000,4.07689200,9.51500000,0.13655956,624.91790359,0.12800577,710.25641476,0.00094518,0.14562023,729.43386640,-0.07844708,-0.06717315,0.00000000,0.00000000,0.00000000,0.00000000
192.65000000,4.12138500,9.52000000,0.13804933,625.24628924,0.12931569,711.56112264,0.00080817,0.14697643,730.58046521,-0.07920032,-0.06777610,0.00000000,0.00000000,0.00000000,0.00000000
194.15000000,4.16531700,9.52400000,0.13958689,625.50899777,0.13066582,712.82185274,0.00091692,0.14836236,731.75067017,-0.07994914,-0.06841322,0.00000000,0.00000000,0.00000000,0.00000000
195.65000000,4.20941300,9.52700000,0.14107667,625.70602916,0.13197226,713.97855007,0.00093501,0.14977733,733.02091178,-0.08079288,-0.06898445,0.00000000,0.00000000,0.00000000,0.00000000
197.15000000,4.25447000,9.53200000,0.14260322,626.03441482,0.13330919,715.30893959,0.00090807,0.15115926,734.19200838,-0.08152881,-0.06963045,0.00000000,0.00000000,0.00000000,0.00000000
198.65000000,4.29936100,9.53600000,0.14415189,626.29712334,0.13466365,716.57903668,0.00095193,0.15257107,735.30996703,-0.08229377,-0.07027730,0.00000000,0.00000000,0.00000000,0.00000000
200.15000000,4.34458300,9.54000000,0.14565256,626.55983187,0.13597439,717.81987259,0.00091846,0.15394911,736.48181254,-0.08297220,-0.07097691,0.00000000,0.00000000,0.00000000,0.00000000
201.65000000,4.38904400,9.54300000,0.14719389,626.75686326,0.13731886,719.01164335,0.00084669,0.15538822,737.62345487,-0.08376781,-0.07162042,0.00000000,0.00000000,0.00000000,0.00000000
203.15000000,4.43433200,9.54700000,0.14872033,627.01957179,0.13864857,720.27013151,0.00091601,0.15679403,738.74217453,-0.08456457,-0.07222946,0.00000000,0.00000000,0.00000000,0.00000000
204.65000000,4.47975300,9.55000000,0.15027633,627.21660318,0.14000220,721.47241451,0.00094686,0.15819776,739.86104169,-0.08533364,-0.07286412,0.00000000,0.00000000,0.00000000,0.00000000
206.15000000,4.52520700,9.55300000,0.15180644,627.41363457,0.14133153,722.65906763,0.00084947,0.15969252,741.12689708,-0.08619486,-0.07349766,0.00000000,0.00000000,0.00000000,0.00000000
207.65000000,4.57039600,9.55600000,0.15338822,627.61066597,0.14270389,723.87875027,0.00082942,0.16112333,742.26953959,-0.08698317,-0.07414017,0.00000000,0.00000000,0.00000000,0.00000000
209.15000000,4.61604900,9.55900000,0.15489633,627.80769736,0.14401059,725.05280772,0.00082834,0.16261444,743.38109979,-0.08782363,-0.07479080,0.00000000,0.00000000,0.00000000,0.00000000
210.65000000,4.66246200,9.56200000,0.15651489,628.00472875,0.14541108,726.29681910,0.00082718,0.16401005,744.50092351,-0.08856052,-0.07544953,0.00000000,0.00000000,0.00000000,0.00000000
212.15000000,4.70871000,9.56500000,0.15813333,628.20176015,0.14680951,727.54139849,0.00095310,0.16549646,745.69037296,-0.08939326,-0.07610319,0.00000000,0.00000000,0.00000000,0.00000000
213.65000000,4.75452900,9.56700000,0.15971500,628.33311441,0.14817429,728.68733778,0.00088815,0.16701200,746.82539446,-0.09026065,-0.07675136,0.00000000,0.00000000,0.00000000,0.00000000
215.15000000,4.80021400,9.56900000,0.16133356,628.46446867,0.14956896,729.85687594,0.00095047,0.16849429,747.93718657,-0.09103987,-0.07745442,0.00000000,0.00000000,0.00000000,0.00000000
216.65000000,4.84643000,9.57100000,0.16291522,628.59582293,0.15092998,731.00365112,0.00094918,0.16994328,749.10401041,-0.09183806,-0.07810522,0.00000000,0.00000000,0.00000000,0.00000000
218.15000000,4.89334000,9.57300000,0.16449689,628.72717720,0.15228914,732.15084181,0.00088451,0.17145206,750.23915028,-0.09264791,-0.07880416,0.00000000,0.00000000,0.00000000,0.00000000
219.65000000,4.94071400,9.57500000,0.16615222,628.85853146,0.15370963,733.34477392,0.00088344,0.17295818,751.45264810,-0.09343195,-0.07952623,0.00000000,0.00000000,0.00000000,0.00000000
221.15000000,4.98792200,9.57700000,0.16777067,628.98988572,0.15509652,734.51593818,0.00088222,0.00000000,0.00000000,0.00000000,0.00000000,0.00000000,0.00000000,0.00000000,0.00000000
222.65000000,5.03493100,9.57900000,0.16946267,629.12123998,0.15654438,735.73380297,0.00094368,0.00000000,0.00000000,0.00000000,0.00000000,0.00000000,0.00000000,0.00000000,0.00000000
224.15000000,5.08273600,9.58100000,0.17111800,629.25259425,0.15795885,736.92903967,0.00100537,0.00000000,0.00000000,0.00000000,0.00000000,0.00000000,0.00000000,0.00000000,0.00000000
225.65000000,5.13001200,9.58100000,0.17277333,629.25259425,0.15937131,737.97066246,0.00094120,0.00000000,0.00000000,0.00000000,0.00000000,0.00000000,0.00000000,0.00000000,0.00000000
227.15000000,5.17801300,9.58300000,0.17442856,629.38394851,0.16078169,739.16648154,0.00093968,0.00000000,0.00000000,0.00000000,0.00000000,0.00000000,0.00000000,0.00000000,0.00000000
228.65000000,5.22585100,9.58400000,0.17615733,629.44962564,0.16225263,740.33179316,0.00106344,0.00000000,0.00000000,0.00000000,0.00000000,0.00000000,0.00000000,0.00000000,0.00000000
230.15000000,5.27454900,9.58600000,0.17784944,629.58097990,0.16369027,741.55160741,0.00093714,0.00000000,0.00000000,0.00000000,0.00000000,0.00000000,0.00000000,0.00000000,0.00000000
231.65000000,5.32242000,9.58600000,0.17957833,629.58097990,0.16515703,742.64008297,0.00099816,0.00000000,0.00000000,0.00000000,0.00000000,0.00000000,0.00000000,0.00000000,0.00000000
233.15000000,5.37141600,9.58700000,0.18130711,629.64665703,0.16662155,743.80607344,0.00093440,0.00000000,0.00000000,0.00000000,0.00000000,0.00000000,0.00000000,0.00000000,0.00000000
234.65000000,5.41925300,9.58700000,0.18303589,629.64665703,0.16808392,744.89459259,0.00105726,0.00000000,0.00000000,0.00000000,0.00000000,0.00000000,0.00000000,0.00000000,0.00000000
236.15000000,5.46901100,9.58800000,0.18480156,629.71233417,0.16957530,746.08415307,0.00105587,0.00000000,0.00000000,0.00000000,0.00000000,0.00000000,0.00000000,0.00000000,0.00000000
237.65000000,5.51787500,9.58800000,0.18656722,629.71233417,0.17106445,747.19601515,0.00099228,0.00000000,0.00000000,0.00000000,0.00000000,0.00000000,0.00000000,0.00000000,0.00000000
239.15000000,5.56703600,9.58800000,0.18829600,629.71233417,0.17252035,748.28464784,0.00092890,0.00000000,0.00000000,0.00000000,0.00000000,0.00000000,0.00000000,0.00000000,0.00000000
240.65000000,5.61679400,9.58800000,0.19009844,629.71233417,0.17403603,749.41966934,0.00105117,0.00000000,0.00000000,0.00000000,0.00000000,0.00000000,0.00000000,0.00000000,0.00000000
242.15000000,5.66635300,9.58900000,0.19186411,629.77801130,0.17551856,750.60980963,0.00098787,0.00000000,0.00000000,0.00000000,0.00000000,0.00000000,0.00000000,0.00000000,0.00000000
243.65000000,5.71673900,9.58900000,0.19366644,629.77801130,0.00000000,0.00000000,0.00000000,0.00000000,0.00000000,0.00000000,0.00000000,0.00000000,0.00000000,0.00000000,0.00000000
245.15000000,5.76672900,9.58800000,0.19543211,629.71233417,0.00000000,0.00000000,0.00000000,0.00000000,0.00000000,0.00000000,0.00000000,0.00000000,0.00000000,0.00000000,0.00000000
246.65000000,5.81655300,9.58700000,0.19727133,629.64665703,0.00000000,0.00000000,0.00000000,0.00000000,0.00000000,0.00000000,0.00000000,0.00000000,0.00000000,0.00000000,0.00000000
248.15000000,5.86720500,9.58700000,0.19907378,629.64665703,0.00000000,0.00000000,0.00000000,0.00000000,0.00000000,0.00000000,0.00000000,0.00000000,0.00000000,0.00000000,0.00000000
249.65000000,5.91792300,9.58700000,0.20098656,629.64665703,0.00000000,0.00000000,0.00000000,0.00000000,0.00000000,0.00000000,0.00000000,0.00000000,0.00000000,0.00000000,0.00000000
251.15000000,5.96900400,9.58600000,0.20286244,629.58097990,0.00000000,0.00000000,0.00000000,0.00000000,0.00000000,0.00000000,0.00000000,0.00000000,0.00000000,0.00000000,0.00000000
252.65000000,6.01985400,9.58500000,0.20473844,629.51530277,0.00000000,0.00000000,0.00000000,0.00000000,0.00000000,0.00000000,0.00000000,0.00000000,0.00000000,0.00000000,0.00000000
254.15000000,6.07149900,9.58500000,0.20665133,629.51530277,0.00000000,0.00000000,0.00000000,0.00000000,0.00000000,0.00000000,0.00000000,0.00000000,0.00000000,0.00000000,0.00000000
255.65000000,6.12297800,9.58400000,0.20856400,629.44962564,0.00000000,0.00000000,0.00000000,0.00000000,0.00000000,0.00000000,0.00000000,0.00000000,0.00000000,0.00000000,0.00000000
257.15000000,6.17462300,9.58200000,0.21047689,629.31827138,0.00000000,0.00000000,0.00000000,0.00000000,0.00000000,0.00000000,0.00000000,0.00000000,0.00000000,0.00000000,0.00000000
258.65000000,6.22643300,9.58100000,0.21246311,629.25259425,0.00000000,0.00000000,0.00000000,0.00000000,0.00000000,0.00000000,0.00000000,0.00000000,0.00000000,0.00000000,0.00000000
260.15000000,6.27850800,9.57900000,0.21441278,629.12123998,0.00000000,0.00000000,0.00000000,0.00000000,0.00000000,0.00000000,0.00000000,0.00000000,0.00000000,0.00000000,0.00000000
261.65000000,6.33151000,9.57900000,0.21639900,629.12123998,0.00000000,0.00000000,0.00000000,0.00000000,0.00000000,0.00000000,0.00000000,0.00000000,0.00000000,0.00000000,0.00000000
263.15000000,6.38457900,9.57700000,0.21845900,628.98988572,0.00000000,0.00000000,0.00000000,0.00000000,0.00000000,0.00000000,0.00000000,0.00000000,0.00000000,0.00000000,0.00000000
264.65000000,6.43811100,9.57500000,0.22055567,628.85853146,0.00000000,0.00000000,0.00000000,0.00000000,0.00000000,0.00000000,0.00000000,0.00000000,0.00000000,0.00000000,0.00000000
266.15000000,6.49137700,9.57300000,0.22261556,628.72717720,0.00000000,0.00000000,0.00000000,0.00000000,0.00000000,0.00000000,0.00000000,0.00000000,0.00000000,0.00000000,0.00000000
267.65000000,6.54517400,9.57100000,0.22467544,628.59582293,0.00000000,0.00000000,0.00000000,0.00000000,0.00000000,0.00000000,0.00000000,0.00000000,0.00000000,0.00000000,0.00000000
269.15000000,6.59936700,9.56900000,0.22680889,628.46446867,0.00000000,0.00000000,0.00000000,0.00000000,0.00000000,0.00000000,0.00000000,0.00000000,0.00000000,0.00000000,0.00000000
270.65000000,6.65349500,9.56500000,0.22894256,628.20176015,0.00000000,0.00000000,0.00000000,0.00000000,0.00000000,0.00000000,0.00000000,0.00000000,0.00000000,0.00000000,0.00000000
272.15000000,6.70768900,9.56300000,0.23111278,628.07040588,0.00000000,0.00000000,0.00000000,0.00000000,0.00000000,0.00000000,0.00000000,0.00000000,0.00000000,0.00000000,0.00000000
273.65000000,6.76323900,9.56100000,0.23328300,627.93905162,0.00000000,0.00000000,0.00000000,0.00000000,0.00000000,0.00000000,0.00000000,0.00000000,0.00000000,0.00000000,0.00000000
275.15000000,6.81892300,9.55800000,0.23552689,627.74202023,0.00000000,0.00000000,0.00000000,0.00000000,0.00000000,0.00000000,0.00000000,0.00000000,0.00000000,0.00000000,0.00000000
276.65000000,6.87417500,9.55400000,0.23769711,627.47931170,0.00000000,0.00000000,0.00000000,0.00000000,0.00000000,0.00000000,0.00000000,0.00000000,0.00000000,0.00000000,0.00000000
278.15000000,6.92969300,9.55100000,0.23997767,627.28228031,0.00000000,0.00000000,0.00000000,0.00000000,0.00000000,0.00000000,0.00000000,0.00000000,0.00000000,0.00000000,0.00000000
279.65000000,6.98514600,9.54700000,0.24222156,627.01957179,0.00000000,0.00000000,0.00000000,0.00000000,0.00000000,0.00000000,0.00000000,0.00000000,0.00000000,0.00000000,0.00000000
281.15000000,7.04178900,9.54300000,0.24446533,626.75686326,0.00000000,0.00000000,0.00000000,0.00000000,0.00000000,0.00000000,0.00000000,0.00000000,0.00000000,0.00000000,0.00000000
282.65000000,7.09876300,9.53900000,0.24674589,626.49415474,0.00000000,0.00000000,0.00000000,0.00000000,0.00000000,0.00000000,0.00000000,0.00000000,0.00000000,0.00000000,0.00000000
284.15000000,7.15547300,9.53400000,0.24906333,626.16576908,0.00000000,0.00000000,0.00000000,0.00000000,0.00000000,0.00000000,0.00000000,0.00000000,0.00000000,0.00000000,0.00000000
285.65000000,7.21254700,9.53000000,0.25127056,625.90306055,0.00000000,0.00000000,0.00000000,0.00000000,0.00000000,0.00000000,0.00000000,0.00000000,0.00000000,0.00000000,0.00000000
287.15000000,7.27038200,9.52500000,0.25355111,625.57467490,0.00000000,0.00000000,0.00000000,0.00000000,0.00000000,0.00000000,0.00000000,0.00000000,0.00000000,0.00000000,0.00000000
288.65000000,7.32825000,9.51800000,0.25586844,625.11493498,0.00000000,0.00000000,0.00000000,0.00000000,0.00000000,0.00000000,0.00000000,0.00000000,0.00000000,0.00000000,0.00000000
290.15000000,7.38591900,9.51100000,0.25811222,624.65519506,0.00000000,0.00000000,0.00000000,0.00000000,0.00000000,0.00000000,0.00000000,0.00000000,0.00000000,0.00000000,0.00000000
291.65000000,7.44438400,9.50500000,0.26035622,624.26113227,0.00000000,0.00000000,0.00000000,0.00000000,0.00000000,0.00000000,0.00000000,0.00000000,0.00000000,0.00000000,0.00000000
293.15000000,7.50251700,9.49800000,0.26260011,623.80139236,0.00000000,0.00000000,0.00000000,0.00000000,0.00000000,0.00000000,0.00000000,0.00000000,0.00000000,0.00000000,0.00000000
294.65000000,7.56197400,9.49000000,0.26473356,623.27597531,0.00000000,0.00000000,0.00000000,0.00000000,0.00000000,0.00000000,0.00000000,0.00000000,0.00000000,0.00000000,0.00000000
296.15000000,7.62090100,9.48100000,0.26686711,622.68488112,0.00000000,0.00000000,0.00000000,0.00000000,0.00000000,0.00000000,0.00000000,0.00000000,0.00000000,0.00000000,0.00000000
297.65000000,7.68025900,9.47000000,0.26903733,621.96243268,0.00000000,0.00000000,0.00000000,0.00000000,0.00000000,0.00000000,0.00000000,0.00000000,0.00000000,0.00000000,0.00000000
299.15000000,7.73971600,9.46100000,0.27095022,621.37133850,0.00000000,0.00000000,0.00000000,0.00000000,0.00000000,0.00000000,0.00000000,0.00000000,0.00000000,0.00000000,0.00000000
300.65000000,7.79940500,9.44700000,0.27293667,620.45185866,0.00000000,0.00000000,0.00000000,0.00000000,0.00000000,0.00000000,0.00000000,0.00000000,0.00000000,0.00000000,0.00000000
302.15000000,7.85939200,9.43500000,0.27477589,619.66373309,0.00000000,0.00000000,0.00000000,0.00000000,0.00000000,0.00000000,0.00000000,0.00000000,0.00000000,0.00000000,0.00000000
303.65000000,7.91967600,9.42000000,0.27646811,618.67857612,0.00000000,0.00000000,0.00000000,0.00000000,0.00000000,0.00000000,0.00000000,0.00000000,0.00000000,0.00000000,0.00000000
305.15000000,7.98015900,9.40600000,0.27816022,617.75909628,0.00000000,0.00000000,0.00000000,0.00000000,0.00000000,0.00000000,0.00000000,0.00000000,0.00000000,0.00000000,0.00000000
306.65000000,8.04147000,9.38700000,0.27963178,616.51123079,0.00000000,0.00000000,0.00000000,0.00000000,0.00000000,0.00000000,0.00000000,0.00000000,0.00000000,0.00000000,0.00000000
308.15000000,8.10258200,9.36900000,0.28110333,615.32904243,0.00000000,0.00000000,0.00000000,0.00000000,0.00000000,0.00000000,0.00000000,0.00000000,0.00000000,0.00000000,0.00000000
309.65000000,8.16412400,9.34500000,0.28235411,613.75279128,0.00000000,0.00000000,0.00000000,0.00000000,0.00000000,0.00000000,0.00000000,0.00000000,0.00000000,0.00000000,0.00000000
311.15000000,8.22520200,9.32500000,0.28349478,612.43924865,0.00000000,0.00000000,0.00000000,0.00000000,0.00000000,0.00000000,0.00000000,0.00000000,0.00000000,0.00000000,0.00000000
312.65000000,8.28704200,9.29900000,0.28448822,610.73164324,0.00000000,0.00000000,0.00000000,0.00000000,0.00000000,0.00000000,0.00000000,0.00000000,0.00000000,0.00000000,0.00000000
314.15000000,8.34865000,9.27400000,0.28537122,609.08971496,0.00000000,0.00000000,0.00000000,0.00000000,0.00000000,0.00000000,0.00000000,0.00000000,0.00000000,0.00000000,0.00000000
315.65000000,8.41025700,9.24200000,0.28607044,606.98804676,0.00000000,0.00000000,0.00000000,0.00000000,0.00000000,0.00000000,0.00000000,0.00000000,0.00000000,0.00000000,0.00000000
317.15000000,8.47262500,9.21300000,0.28673300,605.08340996,0.00000000,0.00000000,0.00000000,0.00000000,0.00000000,0.00000000,0.00000000,0.00000000,0.00000000,0.00000000,0.00000000
318.65000000,8.53519100,9.17300000,0.28724822,602.45632471,0.00000000,0.00000000,0.00000000,0.00000000,0.00000000,0.00000000,0.00000000,0.00000000,0.00000000,0.00000000,0.00000000
320.15000000,8.59765700,9.13900000,0.28761644,600.22330225,0.00000000,0.00000000,0.00000000,0.00000000,0.00000000,0.00000000,0.00000000,0.00000000,0.00000000,0.00000000,0.00000000
321.65000000,8.66028600,9.09500000,0.28794789,597.33350847,0.00000000,0.00000000,0.00000000,0.00000000,0.00000000,0.00000000,0.00000000,0.00000000,0.00000000,0.00000000,0.00000000
323.15000000,8.72321200,9.05400000,0.28809544,594.64074609,0.00000000,0.00000000,0.00000000,0.00000000,0.00000000,0.00000000,0.00000000,0.00000000,0.00000000,0.00000000,0.00000000
324.65000000,8.78626900,8.99800000,0.28824322,590.96282674,0.00000000,0.00000000,0.00000000,0.00000000,0.00000000,0.00000000,0.00000000,0.00000000,0.00000000,0.00000000,0.00000000
326.15000000,8.85068200,8.94700000,0.28828044,587.61329305,0.00000000,0.00000000,0.00000000,0.00000000,0.00000000,0.00000000,0.00000000,0.00000000,0.00000000,0.00000000,0.00000000
327.65000000,8.91512600,8.87500000,0.28828100,582.88453960,0.00000000,0.00000000,0.00000000,0.00000000,0.00000000,0.00000000,0.00000000,0.00000000,0.00000000,0.00000000,0.00000000
329.15000000,8.97917200,8.81000000,0.28831844,578.61552607,0.00000000,0.00000000,0.00000000,0.00000000,0.00000000,0.00000000,0.00000000,0.00000000,0.00000000,0.00000000,0.00000000
330.65000000,9.04536800,8.72500000,0.28828244,573.03296992,0.00000000,0.00000000,0.00000000,0.00000000,0.00000000,0.00000000,0.00000000,0.00000000,0.00000000,0.00000000,0.00000000
332.15000000,9.11226100,8.63900000,0.28820978,567.38473663,0.00000000,0.00000000,0.00000000,0.00000000,0.00000000,0.00000000,0.00000000,0.00000000,0.00000000,0.00000000,0.00000000
333.65000000,9.17978700,8.51200000,0.28817433,559.04374097,0.00000000,0.00000000,0.00000000,0.00000000,0.00000000,0.00000000,0.00000000,0.00000000,0.00000000,0.00000000,0.00000000
335.15000000,9.25000100,8.38900000,0.28806544,550.96545383,0.00000000,0.00000000,0.00000000,0.00000000,0.00000000,0.00000000,0.00000000,0.00000000,0.00000000,0.00000000,0.00000000
336.65000000,9.32198400,8.19900000,0.28795711,538.48679890,0.00000000,0.00000000,0.00000000,0.00000000,0.00000000,0.00000000,0.00000000,0.00000000,0.00000000,0.00000000,0.00000000
338.15000000,9.39875200,8.00700000,0.28777511,525.87678970,0.00000000,0.00000000,0.00000000,0.00000000,0.00000000,0.00000000,0.00000000,0.00000000,0.00000000,0.00000000,0.00000000
339.15000000,9.45417300,7.82900000,0.28766633,514.18626034,0.00000000,0.00000000,0.00000000,0.00000000,0.00000000,0.00000000,0.00000000,0.00000000,0.00000000,0.00000000,0.00000000