File: lab_data/DP600_results/DATA/UT_30_3.csv
Time[s],Displacement[mm],Force[kN],EngStrain_longi,EngStress[MPa],TrueStrain,TrueStress[MPa],TrueStrainRate[1/s],PlasticStrain_longi,PlasticStress[MPa],PlasticStrain_thick,PlasticStrain_width,R-Value,Thickness[mm],Width[mm], Young's Modulus [MPa]
0.61000000,0.00000000,-0.01300000,0.00000000,-0.85357846,0.00000000,-0.85357846,0.00000000,0.00080427,344.43909893,0.00011556,-0.00091983,0.81499200,1.52300000,10.00000000,245625.95606115
2.11000000,0.00163800,0.01300000,0.00006044,0.85357846,0.00006044,0.85363006,0.00000800,0.00117653,358.02289991,-0.00011642,-0.00106011,0.00000000,0.00000000,0.00000000,0.00000000
3.61000000,0.00350900,0.45100000,0.00008133,29.61260670,0.00008133,29.61501519,-0.00003444,0.00170772,372.07373160,-0.00049451,-0.00121321,0.00000000,0.00000000,0.00000000,0.00000000
5.11000000,0.00606500,0.76800000,0.00019089,50.42678923,0.00019087,50.43641515,0.00009421,0.00247371,383.72167978,-0.00097680,-0.00149692,0.00000000,0.00000000,0.00000000,0.00000000
6.61000000,0.00846800,1.13300000,0.00026378,74.39264609,0.00026374,74.41226922,0.00018329,0.00329277,394.88057530,-0.00144286,-0.00184991,0.00000000,0.00000000,0.00000000,0.00000000
8.11000000,0.00991200,1.47400000,0.00031233,96.78266579,0.00031228,96.81289424,0.00010886,0.00403529,403.51270912,-0.00175678,-0.00227851,0.00000000,0.00000000,0.00000000,0.00000000
9.61000000,0.01180600,1.81400000,0.00037889,119.10702561,0.00037882,119.15215394,0.00008397,0.00480086,413.29368938,-0.00206241,-0.00273845,0.00000000,0.00000000,0.00000000,0.00000000
11.11000000,0.01386800,2.15100000,0.00045433,141.23440578,0.00045423,141.29857328,-0.00002865,0.00574153,420.64501353,-0.00261116,-0.00313036,0.00000000,0.00000000,0.00000000,0.00000000
12.61000000,0.01709300,2.51300000,0.00056167,165.00328299,0.00056151,165.09595984,-0.00008973,0.00668837,428.74305335,-0.00320649,-0.00348188,0.00000000,0.00000000,0.00000000,0.00000000
14.11000000,0.02058900,2.84900000,0.00065544,187.06500328,0.00065523,187.18761400,-0.00007950,0.00757625,436.03365170,-0.00371299,-0.00386325,0.00000000,0.00000000,0.00000000,0.00000000
15.61000000,0.02442300,3.20700000,0.00081922,210.57124097,0.00081889,210.74374561,0.00012790,0.00842295,443.31907833,-0.00418430,-0.00423865,0.00000000,0.00000000,0.00000000,0.00000000
17.11000000,0.02761500,3.53500000,0.00095722,232.10768221,0.00095676,232.32986084,0.00030729,0.00936186,449.46056569,-0.00472057,-0.00464129,0.00000000,0.00000000,0.00000000,0.00000000
18.61000000,0.03154600,3.85600000,0.00108889,253.18450427,0.00108830,253.46019406,0.00042403,0.01039962,456.72485639,-0.00531376,-0.00508586,0.00000000,0.00000000,0.00000000,0.00000000
20.11000000,0.03632000,4.17200000,0.00115144,273.93302692,0.00115078,274.24844558,0.00023508,0.01129493,462.47062670,-0.00571752,-0.00557741,0.00000000,0.00000000,0.00000000,0.00000000
21.61000000,0.04334100,4.49800000,0.00128400,295.33814839,0.00128318,295.71736257,0.00005149,0.01220048,468.89907958,-0.00614108,-0.00605940,0.00000000,0.00000000,0.00000000,0.00000000
23.11000000,0.05221900,4.78100000,0.00153800,313.91989494,0.00153682,314.40270374,-0.00015398,0.01318055,474.70636691,-0.00665068,-0.00652987,0.00000000,0.00000000,0.00000000,0.00000000
24.61000000,0.06265500,5.06500000,0.00194311,332.56730138,0.00194123,333.21351660,-0.00018319,0.01419512,480.67533951,-0.00724584,-0.00694929,0.00000000,0.00000000,0.00000000,0.00000000
26.11000000,0.07623900,5.30300000,0.00253956,348.19435325,0.00253634,349.07861215,0.00018376,0.01518731,485.77469592,-0.00784238,-0.00734493,0.00000000,0.00000000,0.00000000,0.00000000
27.61000000,0.09366700,5.51600000,0.00312478,362.17990808,0.00311991,363.31163980,0.00047701,0.01609865,491.71567339,-0.00835475,-0.00774390,0.00000000,0.00000000,0.00000000,0.00000000
29.11000000,0.11229100,5.70200000,0.00371389,374.39264609,0.00370701,375.78309878,0.00045503,0.01711905,496.51383322,-0.00892002,-0.00819903,0.00000000,0.00000000,0.00000000,0.00000000
30.61000000,0.13601200,5.88000000,0.00444656,386.08010506,0.00443670,387.79683169,0.00027148,0.01817562,501.80996178,-0.00950568,-0.00866994,0.00000000,0.00000000,0.00000000,0.00000000
32.11000000,0.16049400,6.02700000,0.00534489,395.73210768,0.00533066,397.84725183,0.00031501,0.01920077,506.63023263,-0.01002558,-0.00917519,0.00000000,0.00000000,0.00000000,0.00000000
33.61000000,0.18643200,6.16800000,0.00630222,404.99015102,0.00628245,407.54248895,0.00065134,0.02018081,511.63892998,-0.01048769,-0.00969312,0.00000000,0.00000000,0.00000000,0.00000000
35.11000000,0.21207200,6.28800000,0.00714144,412.86933684,0.00711607,415.81782027,0.00069427,0.02123886,515.88881183,-0.01106779,-0.01017107,0.00000000,0.00000000,0.00000000,0.00000000
36.61000000,0.24145000,6.39900000,0.00798444,420.15758372,0.00795274,423.51230860,0.00041628,0.02233134,520.97495601,-0.01170294,-0.01062840,0.00000000,0.00000000,0.00000000,0.00000000
38.11000000,0.26894100,6.50500000,0.00897444,427.11753119,0.00893441,430.95067374,0.00040882,0.02337009,525.03026950,-0.01231473,-0.01105537,0.00000000,0.00000000,0.00000000,0.00000000
39.61000000,0.29775200,6.61500000,0.01001933,434.34011819,0.00996947,438.69191661,0.00063375,0.02440210,529.49575801,-0.01289305,-0.01150905,0.00000000,0.00000000,0.00000000,0.00000000
41.11000000,0.32629800,6.71100000,0.01093556,440.64346684,0.01087619,445.46214795,0.00068441,0.02547110,533.51601933,-0.01350617,-0.01196493,0.00000000,0.00000000,0.00000000,0.00000000
42.61000000,0.35593500,6.80900000,0.01182611,447.07813526,0.01175673,452.36533096,0.00050916,0.02655869,537.82554196,-0.01411849,-0.01244019,0.00000000,0.00000000,0.00000000,0.00000000
44.11000000,0.38418200,6.89600000,0.01281967,452.79054498,0.01273819,458.59516883,0.00032739,0.02765888,541.54018086,-0.01471553,-0.01294335,0.00000000,0.00000000,0.00000000,0.00000000
45.61000000,0.41484500,6.98100000,0.01389400,458.37163493,0.01379836,464.74025043,0.00060239,0.02871912,545.85196310,-0.01521719,-0.01350193,0.00000000,0.00000000,0.00000000,0.00000000
47.11000000,0.44481400,7.06400000,0.01486911,463.82140512,0.01475965,470.71801713,0.00065263,0.02983933,549.32148473,-0.01580819,-0.01403114,0.00000000,0.00000000,0.00000000,0.00000000
48.61000000,0.47458500,7.14900000,0.01581489,469.40249508,0.01569114,476.82604338,0.00050015,0.03091619,553.38690268,-0.01638733,-0.01452886,0.00000000,0.00000000,0.00000000,0.00000000
50.11000000,0.50604200,7.22500000,0.01682678,474.39264609,0.01668678,482.37514573,0.00040544,0.03202770,556.66207638,-0.01699465,-0.01503304,0.00000000,0.00000000,0.00000000,0.00000000
51.61000000,0.53574400,7.30400000,0.01795633,479.57977676,0.01779702,488.19127109,0.00059300,0.03313554,560.41953644,-0.01761873,-0.01551681,0.00000000,0.00000000,0.00000000,0.00000000
53.11000000,0.56789700,7.37400000,0.01900489,484.17596848,0.01882655,493.37767897,0.00077280,0.03425567,563.57690605,-0.01824101,-0.01601466,0.00000000,0.00000000,0.00000000,0.00000000
54.61000000,0.59898700,7.44100000,0.02000189,488.57518056,0.01980448,498.34760704,0.00064215,0.03536443,567.34980143,-0.01884327,-0.01652116,0.00000000,0.00000000,0.00000000,0.00000000
56.11000000,0.63050700,7.50700000,0.02106133,492.90873276,0.02084261,503.29004789,0.00055484,0.03646491,570.37260293,-0.01945378,-0.01701112,0.00000000,0.00000000,0.00000000,0.00000000
57.61000000,0.66249200,7.57600000,0.02220911,497.43926461,0.02196608,508.48694851,0.00070557,0.03760706,574.04237058,-0.02012035,-0.01748671,0.00000000,0.00000000,0.00000000,0.00000000
59.11000000,0.69467400,7.63700000,0.02329067,501.44451740,0.02302358,513.12349451,0.00081279,0.03874792,576.96421865,-0.02073971,-0.01800821,0.00000000,0.00000000,0.00000000,0.00000000
60.61000000,0.72708800,7.70000000,0.02435378,505.58108995,0.02406195,517.89389947,0.00073295,0.03987188,580.15708569,-0.02136426,-0.01850762,0.00000000,0.00000000,0.00000000,0.00000000
62.11000000,0.75996600,7.75700000,0.02546822,509.32370322,0.02514931,522.29527247,0.00067428,0.04100316,583.01682887,-0.02200560,-0.01899756,0.00000000,0.00000000,0.00000000,0.00000000
63.61000000,0.79274300,7.81200000,0.02659033,512.93499672,0.02624295,526.57410926,0.00074543,0.04215243,586.30617494,-0.02260940,-0.01954303,0.00000000,0.00000000,0.00000000,0.00000000
65.11000000,0.82571900,7.86600000,0.02770133,516.48063033,0.02732459,530.78783244,0.00080217,0.04329192,589.11397715,-0.02323533,-0.02005660,0.00000000,0.00000000,0.00000000,0.00000000
66.61000000,0.85886200,7.92100000,0.02878656,520.09192383,0.02838001,535.06357889,0.00073671,0.04446689,592.36275086,-0.02388994,-0.02057695,0.00000000,0.00000000,0.00000000,0.00000000
68.11000000,0.89256600,7.97100000,0.02994167,523.37491793,0.02950217,539.04563526,0.00076481,0.04563259,594.99086954,-0.02453027,-0.02110232,0.00000000,0.00000000,0.00000000,0.00000000
69.61000000,0.92633700,8.02300000,0.03108944,526.78923178,0.03061596,543.16681633,0.00075662,0.04679546,597.89947644,-0.02515448,-0.02164099,0.00000000,0.00000000,0.00000000,0.00000000
71.11000000,0.96047200,8.07100000,0.03222611,529.94090611,0.03171774,547.01884063,0.00079865,0.04796249,600.40093570,-0.02580811,-0.02215438,0.00000000,0.00000000,0.00000000,0.00000000
72.61000000,0.99447200,8.11600000,0.03333700,532.89560079,0.03279337,550.66074143,0.00067646,0.04911202,603.38244115,-0.02640508,-0.02270694,0.00000000,0.00000000,0.00000000,0.00000000
74.11000000,1.02857500,8.16000000,0.03451422,535.78463559,0.03393197,554.27682556,0.00076121,0.05028697,605.82998469,-0.02707614,-0.02321083,0.00000000,0.00000000,0.00000000,0.00000000
75.61000000,1.06304000,8.20600000,0.03566933,538.80499015,0.03504792,558.02380495,0.00073890,0.05146554,608.70189232,-0.02773455,-0.02373100,0.00000000,0.00000000,0.00000000,0.00000000
77.11000000,1.09753800,8.24800000,0.03682811,541.56270519,0.03616616,561.50743667,0.00072392,0.05267578,611.18153502,-0.02843985,-0.02423594,0.00000000,0.00000000,0.00000000,0.00000000
78.61000000,1.13243400,8.29100000,0.03800889,544.38608011,0.03730435,565.07759014,0.00072995,0.05386668,613.79384478,-0.02905494,-0.02481174,0.00000000,0.00000000,0.00000000,0.00000000
80.11000000,1.16696400,8.32700000,0.03921556,546.74983585,0.03846616,568.19093441,0.00080012,0.05505734,616.13228248,-0.02972907,-0.02532827,0.00000000,0.00000000,0.00000000,0.00000000
81.61000000,1.20232300,8.36800000,0.04035967,549.44189100,0.03956649,571.61718258,0.00077104,0.05625565,618.75969923,-0.03037344,-0.02588221,0.00000000,0.00000000,0.00000000,0.00000000
83.11000000,1.23728600,8.40500000,0.04156622,551.87130663,0.04072556,574.81051200,0.00076993,0.05745767,621.04513303,-0.03100452,-0.02645316,0.00000000,0.00000000,0.00000000,0.00000000
84.61000000,1.27281100,8.44400000,0.04277656,554.43204202,0.04188692,578.14873507,0.00078311,0.05866355,623.61779069,-0.03170739,-0.02695616,0.00000000,0.00000000,0.00000000,0.00000000
86.11000000,1.30810200,8.47900000,0.04396100,556.73013789,0.04302213,581.20455148,0.00077519,0.05983902,625.75596228,-0.03232594,-0.02751308,0.00000000,0.00000000,0.00000000,0.00000000
87.61000000,1.34349300,8.51500000,0.04515667,559.09389363,0.04416679,584.34071022,0.00077473,0.06106351,628.13985108,-0.03301093,-0.02805258,0.00000000,0.00000000,0.00000000,0.00000000
89.11000000,1.37954800,8.54500000,0.04634867,561.06369009,0.04530664,587.06824404,0.00072456,0.06227749,630.31114922,-0.03369431,-0.02858318,0.00000000,0.00000000,0.00000000,0.00000000
90.61000000,1.41556900,8.58000000,0.04759200,563.36178595,0.04649420,590.17330007,0.00079394,0.06348490,632.76420887,-0.03436482,-0.02912007,0.00000000,0.00000000,0.00000000,0.00000000
92.11000000,1.45192000,8.61200000,0.04880978,565.46290217,0.04765598,593.06302076,0.00073663,0.06468949,634.79770260,-0.03500161,-0.02968787,0.00000000,0.00000000,0.00000000,0.00000000
93.61000000,1.48817200,8.64400000,0.05004200,567.56401838,0.04883016,595.96605699,0.00072857,0.06591514,637.13090972,-0.03567023,-0.03024491,0.00000000,0.00000000,0.00000000,0.00000000
95.11000000,1.52478900,8.67400000,0.05129644,569.53381484,0.05002411,598.74887453,0.00076301,0.06711025,639.09611253,-0.03630138,-0.03080887,0.00000000,0.00000000,0.00000000,0.00000000
96.61000000,1.56120700,8.70400000,0.05253989,571.50361129,0.05120619,601.53034753,0.00076929,0.06835360,641.37910805,-0.03700260,-0.03135100,0.00000000,0.00000000,0.00000000,0.00000000
98.11000000,1.59779200,8.73000000,0.05377956,573.21076822,0.05238328,604.03778858,0.00079602,0.06957643,643.37028666,-0.03766478,-0.03191165,0.00000000,0.00000000,0.00000000,0.00000000
99.61000000,1.63490400,8.76000000,0.05505978,575.18056467,0.05359743,606.84987875,0.00085111,0.07081062,645.51460277,-0.03832445,-0.03248618,0.00000000,0.00000000,0.00000000,0.00000000
101.11000000,1.67188500,8.78600000,0.05630678,576.88772160,0.05477865,609.37041035,0.00082906,0.07203400,647.44323828,-0.03900069,-0.03303330,0.00000000,0.00000000,0.00000000,0.00000000
102.61000000,1.70926200,8.81500000,0.05757956,578.79185817,0.05598286,612.11843613,0.00079337,0.07328222,649.60512604,-0.03969470,-0.03358753,0.00000000,0.00000000,0.00000000,0.00000000
104.11000000,1.74670700,8.83900000,0.05885989,580.36769534,0.05719275,614.52807340,0.00080648,0.07450602,651.47075241,-0.04035433,-0.03415169,0.00000000,0.00000000,0.00000000,0.00000000
105.61000000,1.78408400,8.86500000,0.06014000,582.07485227,0.05840097,617.08083388,0.00081935,0.07571768,653.47458411,-0.04101540,-0.03470228,0.00000000,0.00000000,0.00000000,0.00000000
107.11000000,1.82139600,8.88700000,0.06141644,583.51936967,0.05960428,619.35705461,0.00080433,0.07700675,655.31917925,-0.04172766,-0.03527909,0.00000000,0.00000000,0.00000000,0.00000000
108.61000000,1.85940300,8.91200000,0.06270400,585.16086671,0.06081660,621.85279370,0.00080314,0.07825888,657.42892099,-0.04243195,-0.03582693,0.00000000,0.00000000,0.00000000,0.00000000
110.11000000,1.89691200,8.93500000,0.06399522,586.67104399,0.06203090,624.21518782,0.00079548,0.07951759,659.26114663,-0.04310084,-0.03641675,0.00000000,0.00000000,0.00000000,0.00000000
111.61000000,1.93521700,8.95900000,0.06527156,588.24688116,0.06322975,626.64267014,0.00082187,0.08080459,661.18737185,-0.04379906,-0.03700553,0.00000000,0.00000000,0.00000000,0.00000000
113.11000000,1.97325500,8.98000000,0.06657389,589.62573867,0.06445154,628.87941709,0.00079377,0.08208397,662.96896972,-0.04446510,-0.03761888,0.00000000,0.00000000,0.00000000,0.00000000
114.61000000,2.01156100,9.00300000,0.06790189,591.13591596,0.06569587,631.27516124,0.00083379,0.08332126,664.72600011,-0.04513241,-0.03818885,0.00000000,0.00000000,0.00000000,0.00000000
116.11000000,2.04996300,9.02200000,0.06921511,592.38345371,0.06692484,633.38534028,0.00085356,0.08460327,666.66012257,-0.04584761,-0.03875566,0.00000000,0.00000000,0.00000000,0.00000000
117.61000000,2.08826900,9.04200000,0.07048778,593.69665135,0.06811441,635.54500897,0.00080416,0.08588095,668.45122513,-0.04656477,-0.03931617,0.00000000,0.00000000,0.00000000,0.00000000
119.11000000,2.12667100,9.06100000,0.07180478,594.94418910,0.06934394,637.66402439,0.00078969,0.08714772,670.09432331,-0.04728914,-0.03985858,0.00000000,0.00000000,0.00000000,0.00000000
120.61000000,2.16524100,9.08200000,0.07313644,596.32304662,0.07058562,639.93599399,0.00086411,0.08843499,671.97091397,-0.04802407,-0.04041091,0.00000000,0.00000000,0.00000000,0.00000000
122.11000000,2.20397600,9.10000000,0.07444222,597.50492449,0.07180166,641.98451886,0.00078775,0.08975221,673.58235780,-0.04876279,-0.04098942,0.00000000,0.00000000,0.00000000,0.00000000
123.61000000,2.24360400,9.11900000,0.07577389,598.75246225,0.07304030,644.12226479,0.00080041,0.09107329,675.41667222,-0.04952331,-0.04154998,0.00000000,0.00000000,0.00000000,0.00000000
125.11000000,2.28243600,9.13500000,0.07713500,599.80302035,0.07430474,646.06882633,0.00084047,0.09230696,676.97787184,-0.05016984,-0.04213712,0.00000000,0.00000000,0.00000000,0.00000000
126.61000000,2.32140400,9.15400000,0.07847011,601.05055811,0.07554347,648.21506219,0.00085283,0.09365500,678.76493306,-0.05093793,-0.04271708,0.00000000,0.00000000,0.00000000,0.00000000
128.10000000,2.36139500,9.16900000,0.07980544,602.03545634,0.07678088,650.08116350,0.00082714,0.09496159,680.45463330,-0.05163632,-0.04332528,0.00000000,0.00000000,0.00000000,0.00000000
129.60000000,2.40032800,9.18600000,0.08119956,603.15167433,0.07807112,652.12732221,0.00092573,0.09623988,682.12824425,-0.05230531,-0.04393457,0.00000000,0.00000000,0.00000000,0.00000000
131.10000000,2.44022200,9.20200000,0.08249067,604.20223244,0.07926456,654.04327739,0.00087020,0.09756335,683.69032489,-0.05303151,-0.04453184,0.00000000,0.00000000,0.00000000,0.00000000
132.60000000,2.47975000,9.21900000,0.08385900,605.31845043,0.08052782,656.07985036,0.00080100,0.09889160,685.33160960,-0.05376702,-0.04512458,0.00000000,0.00000000,0.00000000,0.00000000
134.10000000,2.52060300,9.23300000,0.08528256,606.23768877,0.08184037,657.93918814,0.00090176,0.10021501,686.89967736,-0.05450677,-0.04570824,0.00000000,0.00000000,0.00000000,0.00000000
135.60000000,2.56046400,9.24800000,0.08665100,607.22258700,0.08310049,659.83903139,0.00088712,0.10153944,688.61773114,-0.05525254,-0.04628690,0.00000000,0.00000000,0.00000000,0.00000000
137.10000000,2.60072100,9.26200000,0.08797522,608.14182534,0.08431837,661.64323757,0.00073054,0.10289260,690.13929362,-0.05602783,-0.04686478,0.00000000,0.00000000,0.00000000,0.00000000
138.61000000,2.64107800,9.27700000,0.08940989,609.12672357,0.08563616,663.58867625,0.00077489,0.10417444,691.68758765,-0.05673779,-0.04743666,0.00000000,0.00000000,0.00000000,0.00000000
140.10000000,2.68192900,9.29000000,0.09081133,609.98030204,0.08692176,665.37342657,0.00087029,0.10552434,693.13917663,-0.05747788,-0.04804646,0.00000000,0.00000000,0.00000000,0.00000000
141.60000000,2.72225200,9.30300000,0.09217233,610.83388050,0.08816868,667.13586454,0.00078167,0.10686818,694.80986621,-0.05819071,-0.04867747,0.00000000,0.00000000,0.00000000,0.00000000
143.10000000,2.76343600,9.31500000,0.09363611,611.62179908,0.08950803,668.89168582,0.00088796,0.10821722,696.34015220,-0.05893537,-0.04928185,0.00000000,0.00000000,0.00000000,0.00000000
144.60000000,2.80419000,9.32900000,0.09503756,612.54103743,0.09078866,670.75544030,0.00090002,0.10959469,697.74572239,-0.05969728,-0.04989741,0.00000000,0.00000000,0.00000000,0.00000000
146.10000000,2.84560600,9.34100000,0.09643544,613.32895601,0.09206441,672.47560647,0.00085913,0.11093669,699.35053959,-0.06046386,-0.05047283,0.00000000,0.00000000,0.00000000,0.00000000
147.60000000,2.88682200,9.35400000,0.09789567,614.18253447,0.09339532,674.30834314,0.00087115,0.11227112,700.73123592,-0.06118662,-0.05108449,0.00000000,0.00000000,0.00000000,0.00000000
149.10000000,2.92840300,9.36500000,0.09933033,614.90479317,0.09470121,675.98349125,0.00082330,0.11363249,702.28148453,-0.06194475,-0.05168774,0.00000000,0.00000000,0.00000000,0.00000000
150.60000000,2.96938800,9.37500000,0.10075022,615.56139199,0.09599197,677.57933902,0.00092261,0.11502220,703.70636913,-0.06274532,-0.05227688,0.00000000,0.00000000,0.00000000,0.00000000
152.10000000,3.01060500,9.38600000,0.10215900,616.28365069,0.09727098,679.24257216,0.00076753,0.11637994,705.18551298,-0.06345502,-0.05292492,0.00000000,0.00000000,0.00000000,0.00000000
153.60000000,3.05278300,9.39800000,0.10367467,617.07156927,0.09864522,681.04625852,0.00088673,0.11776812,706.76334976,-0.06423454,-0.05353359,0.00000000,0.00000000,0.00000000,0.00000000
155.10000000,3.09459200,9.40800000,0.10511633,617.72816809,0.09995061,682.66148812,0.00092500,0.11913612,708.10647198,-0.06495782,-0.05417830,0.00000000,0.00000000,0.00000000,0.00000000
156.60000000,3.13657100,9.41800000,0.10655467,618.38476691,0.10125128,684.27654962,0.00086453,0.12051136,709.53168878,-0.06571964,-0.05479171,0.00000000,0.00000000,0.00000000,0.00000000
158.10000000,3.17845100,9.42800000,0.10804822,619.04136573,0.10260011,685.92768477,0.00089005,0.12193046,710.91611924,-0.06653489,-0.05539557,0.00000000,0.00000000,0.00000000,0.00000000
159.60000000,3.22125700,9.43700000,0.10949756,619.63230466,0.10390726,687.48052737,0.00084260,0.12331112,712.42514974,-0.06725740,-0.05605373,0.00000000,0.00000000,0.00000000,0.00000000
161.10000000,3.26270600,9.44600000,0.11098344,620.22324360,0.10524561,689.05775550,0.00085408,0.12474560,713.82578472,-0.06808810,-0.05665750,0.00000000,0.00000000,0.00000000,0.00000000
162.60000000,3.30547800,9.45500000,0.11250633,620.81418253,0.10661543,690.65970989,0.00087289,0.12617790,715.22742475,-0.06893345,-0.05724445,0.00000000,0.00000000,0.00000000,0.00000000
164.10000000,3.34791800,9.46400000,0.11400356,621.40512147,0.10796033,692.24751476,0.00098428,0.12758900,716.61637959,-0.06970915,-0.05787985,0.00000000,0.00000000,0.00000000,0.00000000
165.60000000,3.39102200,9.47300000,0.11548578,621.99606041,0.10928999,693.82775922,0.00092996,0.12904270,718.03854148,-0.07049432,-0.05854838,0.00000000,0.00000000,0.00000000,0.00000000
167.10000000,3.43329800,9.48100000,0.11697556,622.52133946,0.11062464,695.34111899,0.00089567,0.13049456,719.46200709,-0.07131082,-0.05918374,0.00000000,0.00000000,0.00000000,0.00000000
168.60000000,3.47656800,9.48800000,0.11851689,622.98095863,0.11200360,696.81472369,0.00094095,0.13191573,720.79047345,-0.07210743,-0.05980830,0.00000000,0.00000000,0.00000000,0.00000000
170.10000000,3.51973700,9.49500000,0.12002489,623.44057781,0.11335091,698.26896389,0.00086723,0.13335762,722.06074756,-0.07290680,-0.06045082,0.00000000,0.00000000,0.00000000,0.00000000
171.60000000,3.56294000,9.50300000,0.12155533,623.96585686,0.11471641,699.81223458,0.00089895,0.13483826,723.51263705,-0.07375634,-0.06108191,0.00000000,0.00000000,0.00000000,0.00000000
173.10000000,3.60587900,9.51000000,0.12309289,624.42547603,0.11608639,701.28781178,0.00095691,0.13628498,724.86681550,-0.07452884,-0.06175614,0.00000000,0.00000000,0.00000000,0.00000000
174.60000000,3.64931400,9.51700000,0.12463767,624.88509521,0.11746091,702.76931541,0.00096845,0.13779016,726.26601293,-0.07539693,-0.06239323,0.00000000,0.00000000,0.00000000,0.00000000
176.10000000,3.69291300,9.52500000,0.12612744,625.41037426,0.11878471,704.29178650,0.00082305,0.13924263,727.55331215,-0.07617893,-0.06306370,0.00000000,0.00000000,0.00000000,0.00000000
177.60000000,3.73727400,9.53100000,0.12774233,625.80433355,0.12021770,705.74603933,0.00095947,0.14074377,728.87843204,-0.07701181,-0.06373196,0.00000000,0.00000000,0.00000000,0.00000000
179.10000000,3.78170200,9.53700000,0.12928344,626.19829284,0.12158331,707.15536505,0.00089930,0.14227423,730.22738100,-0.07786185,-0.06441238,0.00000000,0.00000000,0.00000000,0.00000000
180.60000000,3.82540200,9.54400000,0.13085411,626.65791202,0.12297320,708.65867606,0.00093029,0.14374186,731.60897762,-0.07866134,-0.06508052,0.00000000,0.00000000,0.00000000,0.00000000
182.10000000,3.86999600,9.54900000,0.13246533,626.98621142,0.12439697,710.04014892,0.00101378,0.14529288,732.97795769,-0.07954874,-0.06574414,0.00000000,0.00000000,0.00000000,0.00000000
183.60000000,3.91425700,9.55500000,0.13404700,627.38017072,0.12579265,711.47860046,0.00095374,0.14681374,734.25062920,-0.08037081,-0.06644293,0.00000000,0.00000000,0.00000000,0.00000000
185.10000000,3.95934700,9.56100000,0.13565078,627.77413001,0.12720586,712.93217901,0.00100447,0.14835673,735.61851973,-0.08120871,-0.06714802,0.00000000,0.00000000,0.00000000,0.00000000
186.60000000,4.00397500,9.56600000,0.13726200,628.10242942,0.12862362,714.31702508,0.00095769,0.14989751,736.98726076,-0.08207592,-0.06782159,0.00000000,0.00000000,0.00000000,0.00000000
188.10000000,4.04873400,9.57100000,0.13889522,628.43072882,0.13005869,715.71675456,0.00094988,0.15146783,738.22649453,-0.08294832,-0.06851950,0.00000000,0.00000000,0.00000000,0.00000000
189.60000000,4.09395700,9.57600000,0.14055411,628.75902823,0.13151421,717.13369455,0.00102550,0.15303521,739.61975610,-0.08387271,-0.06916250,0.00000000,0.00000000,0.00000000,0.00000000
191.10000000,4.13911400,9.58000000,0.14216167,629.02166776,0.13292267,718.44443642,0.00092147,0.15460030,740.93669318,-0.08467941,-0.06992089,0.00000000,0.00000000,0.00000000,0.00000000
192.60000000,4.18476800,9.58500000,0.14383178,629.34996717,0.13438383,719.87049179,0.00092654,0.15622585,742.22368797,-0.08560135,-0.07062451,0.00000000,0.00000000,0.00000000,0.00000000
194.10000000,4.23028800,9.58900000,0.14549433,629.61260670,0.13583628,721.21767317,0.00097643,0.15787966,743.61143562,-0.08651200,-0.07136766,0.00000000,0.00000000,0.00000000,0.00000000
195.60000000,4.27590900,9.59300000,0.14716078,629.87524622,0.13729000,722.56817736,0.00098800,0.15949948,744.97634852,-0.08739406,-0.07210543,0.00000000,0.00000000,0.00000000,0.00000000
197.10000000,4.32192600,9.59700000,0.14886756,630.13788575,0.13877672,723.94497247,0.00098633,0.16120991,746.41160776,-0.08836256,-0.07284735,0.00000000,0.00000000,0.00000000,0.00000000
198.60000000,4.36804200,9.60100000,0.15056689,630.40052528,0.14025477,725.31797112,0.00103609,0.16285570,747.72327748,-0.08925744,-0.07359826,0.00000000,0.00000000,0.00000000,0.00000000
200.10000000,4.41445700,9.60500000,0.15226633,630.66316481,0.14173073,726.69193248,0.00096432,0.16459207,749.02737785,-0.09024364,-0.07434843,0.00000000,0.00000000,0.00000000,0.00000000
201.60000000,4.46054000,9.60800000,0.15402478,630.86014445,0.14325564,728.02823801,0.00109695,0.16623227,750.33943883,-0.09111992,-0.07511235,0.00000000,0.00000000,0.00000000,0.00000000
203.10000000,4.50731900,9.61100000,0.15572044,631.05712410,0.14472391,729.32561993,0.00101858,0.16799324,751.74491010,-0.09206732,-0.07592592,0.00000000,0.00000000,0.00000000,0.00000000
204.60000000,4.55366800,9.61400000,0.15749356,631.25410374,0.14625694,730.67255700,0.00101087,0.16971991,753.20545047,-0.09300601,-0.07671390,0.00000000,0.00000000,0.00000000,0.00000000
206.10000000,4.60064600,9.61700000,0.15920411,631.45108339,0.14773366,731.98069183,0.00101590,0.00000000,0.00000000,0.00000000,0.00000000,0.00000000,0.00000000,0.00000000,0.00000000
207.60000000,4.64775500,9.62100000,0.16098056,631.71372292,0.14926495,733.40734898,0.00096340,0.00000000,0.00000000,0.00000000,0.00000000,0.00000000,0.00000000,0.00000000,0.00000000
209.10000000,4.69516300,9.62400000,0.16278311,631.91070256,0.15081637,734.77509267,0.00101239,0.00000000,0.00000000,0.00000000,0.00000000,0.00000000,0.00000000,0.00000000,0.00000000
210.60000000,4.74260500,9.62600000,0.16458544,632.04202232,0.15236518,736.06693948,0.00101101,0.00000000,0.00000000,0.00000000,0.00000000,0.00000000,0.00000000,0.00000000,0.00000000
212.10000000,4.79037600,9.62800000,0.16642456,632.17334209,0.15394313,737.38250958,0.00107232,0.00000000,0.00000000,0.00000000,0.00000000,0.00000000,0.00000000,0.00000000,0.00000000
213.60000000,4.83761900,9.62900000,0.16826389,632.23900197,0.15551879,738.62199515,0.00107120,0.00000000,0.00000000,0.00000000,0.00000000,0.00000000,0.00000000,0.00000000,0.00000000
215.10000000,4.88601900,9.63200000,0.17013967,632.43598162,0.15712311,740.03842872,0.00113181,0.00000000,0.00000000,0.00000000,0.00000000,0.00000000,0.00000000,0.00000000,0.00000000
216.60000000,4.93435300,9.63400000,0.17201567,632.56730138,0.15872506,741.37878744,0.00119298,0.00000000,0.00000000,0.00000000,0.00000000,0.00000000,0.00000000,0.00000000,0.00000000
218.10000000,4.98301800,9.63600000,0.17392856,632.69862114,0.16035586,742.74297842,0.00119123,0.00000000,0.00000000,0.00000000,0.00000000,0.00000000,0.00000000,0.00000000,0.00000000
219.60000000,5.03115400,9.63800000,0.17584133,632.82994091,0.16198392,744.10760149,0.00112651,0.00000000,0.00000000,0.00000000,0.00000000,0.00000000,0.00000000,0.00000000,0.00000000
221.10000000,5.08068100,9.63900000,0.17775411,632.89560079,0.16360933,745.39539573,0.00112468,0.00000000,0.00000000,0.00000000,0.00000000,0.00000000,0.00000000,0.00000000,0.00000000
222.60000000,5.13020500,9.64100000,0.17970356,633.02692055,0.16526318,746.78410894,0.00099786,0.00000000,0.00000000,0.00000000,0.00000000,0.00000000,0.00000000,0.00000000,0.00000000
224.10000000,5.17959800,9.64200000,0.18172667,633.09258043,0.16697665,748.14238477,0.00112071,0.00000000,0.00000000,0.00000000,0.00000000,0.00000000,0.00000000,0.00000000,0.00000000
225.60000000,5.22915900,9.64200000,0.18371300,633.09258043,0.16865611,749.39991766,0.00099448,0.00000000,0.00000000,0.00000000,0.00000000,0.00000000,0.00000000,0.00000000,0.00000000
227.10000000,5.27878500,9.64300000,0.18577300,633.15824032,0.17039488,750.78194609,0.00117914,0.00000000,0.00000000,0.00000000,0.00000000,0.00000000,0.00000000,0.00000000,0.00000000
228.60000000,5.32874300,9.64400000,0.18783289,633.22390020,0.17213055,752.16417468,0.00111513,0.00000000,0.00000000,0.00000000,0.00000000,0.00000000,0.00000000,0.00000000,0.00000000
230.10000000,5.37949300,9.64500000,0.18992956,633.28956008,0.00000000,0.00000000,0.00000000,0.00000000,0.00000000,0.00000000,0.00000000,0.00000000,0.00000000,0.00000000,0.00000000
231.60000000,5.43021100,9.64500000,0.19206300,633.28956008,0.00000000,0.00000000,0.00000000,0.00000000,0.00000000,0.00000000,0.00000000,0.00000000,0.00000000,0.00000000,0.00000000
233.10000000,5.48102700,9.64600000,0.19423333,633.35521996,0.00000000,0.00000000,0.00000000,0.00000000,0.00000000,0.00000000,0.00000000,0.00000000,0.00000000,0.00000000,0.00000000
234.60000000,5.53250800,9.64600000,0.19640356,633.35521996,0.00000000,0.00000000,0.00000000,0.00000000,0.00000000,0.00000000,0.00000000,0.00000000,0.00000000,0.00000000,0.00000000
236.10000000,5.58352500,9.64600000,0.19864733,633.35521996,0.00000000,0.00000000,0.00000000,0.00000000,0.00000000,0.00000000,0.00000000,0.00000000,0.00000000,0.00000000,0.00000000
237.60000000,5.63543300,9.64600000,0.20089111,633.35521996,0.00000000,0.00000000,0.00000000,0.00000000,0.00000000,0.00000000,0.00000000,0.00000000,0.00000000,0.00000000,0.00000000
239.10000000,5.68684600,9.64500000,0.20320844,633.28956008,0.00000000,0.00000000,0.00000000,0.00000000,0.00000000,0.00000000,0.00000000,0.00000000,0.00000000,0.00000000,0.00000000
240.60000000,5.73869000,9.64500000,0.20552600,633.28956008,0.00000000,0.00000000,0.00000000,0.00000000,0.00000000,0.00000000,0.00000000,0.00000000,0.00000000,0.00000000,0.00000000
242.10000000,5.79129500,9.64500000,0.20791667,633.28956008,0.00000000,0.00000000,0.00000000,0.00000000,0.00000000,0.00000000,0.00000000,0.00000000,0.00000000,0.00000000,0.00000000
243.60000000,5.84413300,9.64400000,0.21030789,633.22390020,0.00000000,0.00000000,0.00000000,0.00000000,0.00000000,0.00000000,0.00000000,0.00000000,0.00000000,0.00000000,0.00000000
245.10000000,5.89680300,9.64300000,0.21277233,633.15824032,0.00000000,0.00000000,0.00000000,0.00000000,0.00000000,0.00000000,0.00000000,0.00000000,0.00000000,0.00000000,0.00000000
246.60000000,5.94954000,9.64100000,0.21531044,633.02692055,0.00000000,0.00000000,0.00000000,0.00000000,0.00000000,0.00000000,0.00000000,0.00000000,0.00000000,0.00000000,0.00000000
248.10000000,6.00284100,9.64100000,0.21784833,633.02692055,0.00000000,0.00000000,0.00000000,0.00000000,0.00000000,0.00000000,0.00000000,0.00000000,0.00000000,0.00000000,0.00000000
249.60000000,6.05630600,9.64000000,0.22046011,632.96126067,0.00000000,0.00000000,0.00000000,0.00000000,0.00000000,0.00000000,0.00000000,0.00000000,0.00000000,0.00000000,0.00000000
251.10000000,6.11036900,9.63800000,0.22314533,632.82994091,0.00000000,0.00000000,0.00000000,0.00000000,0.00000000,0.00000000,0.00000000,0.00000000,0.00000000,0.00000000,0.00000000
252.60000000,6.16456200,9.63600000,0.22590411,632.69862114,0.00000000,0.00000000,0.00000000,0.00000000,0.00000000,0.00000000,0.00000000,0.00000000,0.00000000,0.00000000,0.00000000
254.10000000,6.21931900,9.63400000,0.22873644,632.56730138,0.00000000,0.00000000,0.00000000,0.00000000,0.00000000,0.00000000,0.00000000,0.00000000,0.00000000,0.00000000,0.00000000
255.60000000,6.27328100,9.63100000,0.23160567,632.37032173,0.00000000,0.00000000,0.00000000,0.00000000,0.00000000,0.00000000,0.00000000,0.00000000,0.00000000,0.00000000,0.00000000
257.11000000,6.32823700,9.62900000,0.23458522,632.23900197,0.00000000,0.00000000,0.00000000,0.00000000,0.00000000,0.00000000,0.00000000,0.00000000,0.00000000,0.00000000,0.00000000
258.60000000,6.38335800,9.62600000,0.23760156,632.04202232,0.00000000,0.00000000,0.00000000,0.00000000,0.00000000,0.00000000,0.00000000,0.00000000,0.00000000,0.00000000,0.00000000
260.10000000,6.43900900,9.62300000,0.24076511,631.84504268,0.00000000,0.00000000,0.00000000,0.00000000,0.00000000,0.00000000,0.00000000,0.00000000,0.00000000,0.00000000,0.00000000
261.60000000,6.49495800,9.62100000,0.24400211,631.71372292,0.00000000,0.00000000,0.00000000,0.00000000,0.00000000,0.00000000,0.00000000,0.00000000,0.00000000,0.00000000,0.00000000
263.10000000,6.55150200,9.61700000,0.24742289,631.45108339,0.00000000,0.00000000,0.00000000,0.00000000,0.00000000,0.00000000,0.00000000,0.00000000,0.00000000,0.00000000,0.00000000
264.60000000,6.60794700,9.61200000,0.25088056,631.12278398,0.00000000,0.00000000,0.00000000,0.00000000,0.00000000,0.00000000,0.00000000,0.00000000,0.00000000,0.00000000,0.00000000
266.10000000,6.66455900,9.60900000,0.25444878,630.92580433,0.00000000,0.00000000,0.00000000,0.00000000,0.00000000,0.00000000,0.00000000,0.00000000,0.00000000,0.00000000,0.00000000
267.60000000,6.72222800,9.60400000,0.25816400,630.59750492,0.00000000,0.00000000,0.00000000,0.00000000,0.00000000,0.00000000,0.00000000,0.00000000,0.00000000,0.00000000,0.00000000
269.10000000,6.77960200,9.59900000,0.26202622,630.26920552,0.00000000,0.00000000,0.00000000,0.00000000,0.00000000,0.00000000,0.00000000,0.00000000,0.00000000,0.00000000,0.00000000
270.60000000,6.83683900,9.59300000,0.26599878,629.87524622,0.00000000,0.00000000,0.00000000,0.00000000,0.00000000,0.00000000,0.00000000,0.00000000,0.00000000,0.00000000,0.00000000
272.10000000,6.89484200,9.58700000,0.27015533,629.48128693,0.00000000,0.00000000,0.00000000,0.00000000,0.00000000,0.00000000,0.00000000,0.00000000,0.00000000,0.00000000,0.00000000
273.60000000,6.95370300,9.58200000,0.27449578,629.15298752,0.00000000,0.00000000,0.00000000,0.00000000,0.00000000,0.00000000,0.00000000,0.00000000,0.00000000,0.00000000,0.00000000
275.10000000,7.01279500,9.57300000,0.27898333,628.56204859,0.00000000,0.00000000,0.00000000,0.00000000,0.00000000,0.00000000,0.00000000,0.00000000,0.00000000,0.00000000,0.00000000
276.60000000,7.07162300,9.56600000,0.28365489,628.10242942,0.00000000,0.00000000,0.00000000,0.00000000,0.00000000,0.00000000,0.00000000,0.00000000,0.00000000,0.00000000,0.00000000
278.10000000,7.13028600,9.55600000,0.28847333,627.44583060,0.00000000,0.00000000,0.00000000,0.00000000,0.00000000,0.00000000,0.00000000,0.00000000,0.00000000,0.00000000,0.00000000
279.60000000,7.18914800,9.54700000,0.29343922,626.85489166,0.00000000,0.00000000,0.00000000,0.00000000,0.00000000,0.00000000,0.00000000,0.00000000,0.00000000,0.00000000,0.00000000
281.10000000,7.24930000,9.53600000,0.29873611,626.13263296,0.00000000,0.00000000,0.00000000,0.00000000,0.00000000,0.00000000,0.00000000,0.00000000,0.00000000,0.00000000,0.00000000
282.60000000,7.30968500,9.52500000,0.30406978,625.41037426,0.00000000,0.00000000,0.00000000,0.00000000,0.00000000,0.00000000,0.00000000,0.00000000,0.00000000,0.00000000,0.00000000
284.10000000,7.36967200,9.51000000,0.30966078,624.42547603,0.00000000,0.00000000,0.00000000,0.00000000,0.00000000,0.00000000,0.00000000,0.00000000,0.00000000,0.00000000,0.00000000
285.60000000,7.42995600,9.49700000,0.31543578,623.57189757,0.00000000,0.00000000,0.00000000,0.00000000,0.00000000,0.00000000,0.00000000,0.00000000,0.00000000,0.00000000,0.00000000
287.10000000,7.49050600,9.48000000,0.32135789,622.45567958,0.00000000,0.00000000,0.00000000,0.00000000,0.00000000,0.00000000,0.00000000,0.00000000,0.00000000,0.00000000,0.00000000
288.60000000,7.55151900,9.46300000,0.32746389,621.33946159,0.00000000,0.00000000,0.00000000,0.00000000,0.00000000,0.00000000,0.00000000,0.00000000,0.00000000,0.00000000,0.00000000
290.10000000,7.61200100,9.44300000,0.33368022,620.02626395,0.00000000,0.00000000,0.00000000,0.00000000,0.00000000,0.00000000,0.00000000,0.00000000,0.00000000,0.00000000,0.00000000
291.60000000,7.67317900,9.42400000,0.34004367,618.77872620,0.00000000,0.00000000,0.00000000,0.00000000,0.00000000,0.00000000,0.00000000,0.00000000,0.00000000,0.00000000,0.00000000
293.10000000,7.73412400,9.39900000,0.34655422,617.13722915,0.00000000,0.00000000,0.00000000,0.00000000,0.00000000,0.00000000,0.00000000,0.00000000,0.00000000,0.00000000,0.00000000
294.60000000,7.79593200,9.37700000,0.35324867,615.69271175,0.00000000,0.00000000,0.00000000,0.00000000,0.00000000,0.00000000,0.00000000,0.00000000,0.00000000,0.00000000,0.00000000
296.10000000,7.85747300,9.34600000,0.35994300,613.65725542,0.00000000,0.00000000,0.00000000,0.00000000,0.00000000,0.00000000,0.00000000,0.00000000,0.00000000,0.00000000,0.00000000
297.60000000,7.91924500,9.32000000,0.36667400,611.95009849,0.00000000,0.00000000,0.00000000,0.00000000,0.00000000,0.00000000,0.00000000,0.00000000,0.00000000,0.00000000,0.00000000
299.10000000,7.98098400,9.28700000,0.37351544,609.78332239,0.00000000,0.00000000,0.00000000,0.00000000,0.00000000,0.00000000,0.00000000,0.00000000,0.00000000,0.00000000,0.00000000
300.60000000,8.04252400,9.25600000,0.38028333,607.74786605,0.00000000,0.00000000,0.00000000,0.00000000,0.00000000,0.00000000,0.00000000,0.00000000,0.00000000,0.00000000,0.00000000
302.10000000,8.10469200,9.21400000,0.38723500,604.99015102,0.00000000,0.00000000,0.00000000,0.00000000,0.00000000,0.00000000,0.00000000,0.00000000,0.00000000,0.00000000,0.00000000
303.60000000,8.16699200,9.17700000,0.39418667,602.56073539,0.00000000,0.00000000,0.00000000,0.00000000,0.00000000,0.00000000,0.00000000,0.00000000,0.00000000,0.00000000,0.00000000
305.10000000,8.23021900,9.12800000,0.40128544,599.34340118,0.00000000,0.00000000,0.00000000,0.00000000,0.00000000,0.00000000,0.00000000,0.00000000,0.00000000,0.00000000,0.00000000
306.60000000,8.29410700,9.08300000,0.40842078,596.38870650,0.00000000,0.00000000,0.00000000,0.00000000,0.00000000,0.00000000,0.00000000,0.00000000,0.00000000,0.00000000,0.00000000
308.10000000,8.35753000,9.02600000,0.41551944,592.64609324,0.00000000,0.00000000,0.00000000,0.00000000,0.00000000,0.00000000,0.00000000,0.00000000,0.00000000,0.00000000,0.00000000
309.60000000,8.42158300,8.97200000,0.42265456,589.10045962,0.00000000,0.00000000,0.00000000,0.00000000,0.00000000,0.00000000,0.00000000,0.00000000,0.00000000,0.00000000,0.00000000
311.10000000,8.48599700,8.89700000,0.42986322,584.17596848,0.00000000,0.00000000,0.00000000,0.00000000,0.00000000,0.00000000,0.00000000,0.00000000,0.00000000,0.00000000,0.00000000
312.60000000,8.55120600,8.83000000,0.43721900,579.77675640,0.00000000,0.00000000,0.00000000,0.00000000,0.00000000,0.00000000,0.00000000,0.00000000,0.00000000,0.00000000,0.00000000
314.10000000,8.61710600,8.73300000,0.44457433,573.40774787,0.00000000,0.00000000,0.00000000,0.00000000,0.00000000,0.00000000,0.00000000,0.00000000,0.00000000,0.00000000,0.00000000
315.60000000,8.68402900,8.64400000,0.45211356,567.56401838,0.00000000,0.00000000,0.00000000,0.00000000,0.00000000,0.00000000,0.00000000,0.00000000,0.00000000,0.00000000,0.00000000
317.10000000,8.75210500,8.52300000,0.45979933,559.61917269,0.00000000,0.00000000,0.00000000,0.00000000,0.00000000,0.00000000,0.00000000,0.00000000,0.00000000,0.00000000,0.00000000
318.60000000,8.82196500,8.40100000,0.46781589,551.60866710,0.00000000,0.00000000,0.00000000,0.00000000,0.00000000,0.00000000,0.00000000,0.00000000,0.00000000,0.00000000,0.00000000
320.10000000,8.89443300,8.21400000,0.47608989,539.33026921,0.00000000,0.00000000,0.00000000,0.00000000,0.00000000,0.00000000,0.00000000,0.00000000,0.00000000,0.00000000,0.00000000
321.10000000,8.94459500,8.07500000,0.48186344,530.20354563,0.00000000,0.00000000,0.00000000,0.00000000,0.00000000,0.00000000,0.00000000,0.00000000,0.00000000,0.00000000,0.00000000