File: lab_data/DP600_results/DATA/UT_60_2.csv
Time[s],Displacement[mm],Force[kN],EngStrain_longi,EngStress[MPa],TrueStrain,TrueStress[MPa],TrueStrainRate[1/s],PlasticStrain_longi,PlasticStress[MPa],PlasticStrain_thick,PlasticStrain_width,R-Value,Thickness[mm],Width[mm], Young's Modulus [MPa]
0.61000000,0.00000000,-0.01300000,0.00000000,-0.85061833,0.00000000,-0.85061833,0.00000000,0.00059807,346.65317987,0.00011032,-0.00070839,0.86161498,1.52830000,10.00000000,248799.72070163
2.11000000,0.00185100,0.00300000,0.00007444,0.19629654,0.00007444,0.19631115,0.00005711,0.00101122,360.86065127,-0.00009560,-0.00091562,0.00000000,0.00000000,0.00000000,0.00000000
3.61000000,0.00385300,0.42800000,0.00013422,28.00497285,0.00013421,28.00873174,-0.00001889,0.00142846,375.74087653,-0.00013556,-0.00129290,0.00000000,0.00000000,0.00000000,0.00000000
5.11000000,0.00602500,0.78600000,0.00019900,51.42969312,0.00019898,51.43992763,0.00006621,0.00202316,387.94107623,-0.00035456,-0.00166860,0.00000000,0.00000000,0.00000000,0.00000000
6.61000000,0.00787900,1.08700000,0.00028911,71.12477917,0.00028907,71.14534213,0.00014263,0.00276195,399.75380872,-0.00082533,-0.00193662,0.00000000,0.00000000,0.00000000,0.00000000
8.11000000,0.00998800,1.44300000,0.00034244,94.41863508,0.00034239,94.45096822,0.00006620,0.00358973,408.85298227,-0.00137121,-0.00221851,0.00000000,0.00000000,0.00000000,0.00000000
9.61000000,0.01147400,1.75000000,0.00039944,114.50631421,0.00039936,114.55205312,0.00009774,0.00434598,418.99346751,-0.00177285,-0.00257313,0.00000000,0.00000000,0.00000000,0.00000000
11.11000000,0.01364300,2.13200000,0.00044367,139.50140679,0.00044357,139.56329892,-0.00001533,0.00510327,426.50906771,-0.00209013,-0.00301314,0.00000000,0.00000000,0.00000000,0.00000000
12.61000000,0.01684700,2.43800000,0.00055511,159.52365373,0.00055496,159.61220709,-0.00012482,0.00593019,434.59539251,-0.00248724,-0.00344295,0.00000000,0.00000000,0.00000000,0.00000000
14.11000000,0.02008500,2.82100000,0.00068789,184.58417850,0.00068765,184.71115190,0.00000511,0.00692455,441.84340262,-0.00311279,-0.00381176,0.00000000,0.00000000,0.00000000,0.00000000
15.61000000,0.02321700,3.12500000,0.00081289,204.47556108,0.00081256,204.64177699,0.00022627,0.00782232,449.26112670,-0.00363750,-0.00418483,0.00000000,0.00000000,0.00000000,0.00000000
17.11000000,0.02603100,3.45000000,0.00090744,225.74101943,0.00090703,225.94586687,0.00032484,0.00868874,455.41847052,-0.00409170,-0.00459704,0.00000000,0.00000000,0.00000000,0.00000000
18.61000000,0.02933500,3.79400000,0.00095089,248.24968920,0.00095044,248.48574707,0.00020959,0.00953831,462.64032992,-0.00452705,-0.00501125,0.00000000,0.00000000,0.00000000,0.00000000
20.11000000,0.03277500,4.10700000,0.00100422,268.72996140,0.00100372,268.99982599,0.00002198,0.01054634,468.42155510,-0.00502036,-0.00552598,0.00000000,0.00000000,0.00000000,0.00000000
21.61000000,0.03823700,4.41600000,0.00115500,288.94850487,0.00115433,289.28224040,-0.00012496,0.01151708,474.92795695,-0.00550734,-0.00600974,0.00000000,0.00000000,0.00000000,0.00000000
23.11000000,0.04525600,4.73300000,0.00141256,309.69050579,0.00141156,310.12796084,-0.00016887,0.01242184,480.61647127,-0.00594719,-0.00647465,0.00000000,0.00000000,0.00000000,0.00000000
24.61000000,0.05383300,4.99000000,0.00178422,326.50657593,0.00178263,327.08913622,0.00004414,0.01330293,486.57012689,-0.00641222,-0.00689071,0.00000000,0.00000000,0.00000000,0.00000000
26.11000000,0.06571900,5.28600000,0.00225133,345.87450108,0.00224880,346.65317987,0.00036699,0.01431785,491.60000556,-0.00701966,-0.00729819,0.00000000,0.00000000,0.00000000,0.00000000
27.61000000,0.08095000,5.50000000,0.00273333,359.87698750,0.00272960,360.86065127,0.00060178,0.01531421,497.29817191,-0.00757706,-0.00773715,0.00000000,0.00000000,0.00000000,0.00000000
29.11000000,0.09770600,5.72400000,0.00322289,374.53379572,0.00321771,375.74087653,0.00060880,0.01630145,502.40147929,-0.00808348,-0.00821798,0.00000000,0.00000000,0.00000000,0.00000000
30.61000000,0.11767400,5.90600000,0.00387800,386.44245240,0.00387050,387.94107623,0.00048396,0.01726548,507.63660640,-0.00851974,-0.00874574,0.00000000,0.00000000,0.00000000,0.00000000
32.11000000,0.13999200,6.08100000,0.00467644,397.89308382,0.00466554,399.75380872,0.00050548,0.01827370,512.43559364,-0.00904351,-0.00923019,0.00000000,0.00000000,0.00000000,0.00000000
33.61000000,0.16449600,6.21400000,0.00555200,406.59556370,0.00553664,408.85298227,0.00078314,0.01931608,517.39575238,-0.00961513,-0.00970095,0.00000000,0.00000000,0.00000000,0.00000000
35.11000000,0.19068900,6.36300000,0.00636133,416.34495845,0.00634119,418.99346751,0.00083354,0.02034974,521.69026522,-0.01018987,-0.01015986,0.00000000,0.00000000,0.00000000,0.00000000
36.61000000,0.21605300,6.47200000,0.00715978,423.47706602,0.00713427,426.50906771,0.00070883,0.02136269,526.31826845,-0.01077283,-0.01058986,0.00000000,0.00000000,0.00000000,0.00000000
38.11000000,0.24419700,6.58900000,0.00803178,431.13263103,0.00799969,434.59539251,0.00046719,0.02241191,530.63835351,-0.01133341,-0.01107850,0.00000000,0.00000000,0.00000000,0.00000000
39.61000000,0.27267000,6.69200000,0.00906944,437.87214552,0.00902856,441.84340262,0.00070749,0.02345931,535.10078458,-0.01194455,-0.01151476,0.00000000,0.00000000,0.00000000,0.00000000
41.11000000,0.30058000,6.79800000,0.01001144,444.80795655,0.00996166,449.26112670,0.00082348,0.02455373,539.19318226,-0.01256068,-0.01199305,0.00000000,0.00000000,0.00000000,0.00000000
42.61000000,0.32918600,6.88500000,0.01091656,450.50055617,0.01085740,455.41847052,0.00078624,0.02556758,543.45260166,-0.01305469,-0.01251288,0.00000000,0.00000000,0.00000000,0.00000000
44.11000000,0.35865300,6.98800000,0.01181056,457.24007067,0.01174136,462.64032992,0.00045842,0.02663013,547.00398236,-0.01359624,-0.01303389,0.00000000,0.00000000,0.00000000,0.00000000
45.61000000,0.38788800,7.06800000,0.01285889,462.47464503,0.01277692,468.42155510,0.00056679,0.02769268,551.03578239,-0.01416445,-0.01352823,0.00000000,0.00000000,0.00000000,0.00000000
47.11000000,0.41748600,7.15900000,0.01387400,468.42897337,0.01377864,474.92795695,0.00066774,0.02876294,554.74148630,-0.01473289,-0.01403005,0.00000000,0.00000000,0.00000000,0.00000000
48.61000000,0.44814400,7.23800000,0.01481922,473.59811555,0.01471049,480.61647127,0.00068880,0.02982812,558.51955501,-0.01530535,-0.01452277,0.00000000,0.00000000,0.00000000,0.00000000
50.11000000,0.47704800,7.32100000,0.01574256,479.02898646,0.01561993,486.57012689,0.00048531,0.03088588,562.09745776,-0.01588792,-0.01499796,0.00000000,0.00000000,0.00000000,0.00000000
51.61000000,0.50859900,7.38900000,0.01679833,483.47837466,0.01665880,491.60000556,0.00049945,0.03196729,565.69584265,-0.01647440,-0.01549289,0.00000000,0.00000000,0.00000000,0.00000000
53.11000000,0.53912400,7.46700000,0.01783956,488.58208467,0.01768230,497.29817191,0.00055681,0.03305304,568.89596056,-0.01705321,-0.01599983,0.00000000,0.00000000,0.00000000,0.00000000
54.61000000,0.57051000,7.53600000,0.01886967,493.09690506,0.01869384,502.40147929,0.00065006,0.03418560,572.40162475,-0.01767482,-0.01651078,0.00000000,0.00000000,0.00000000,0.00000000
56.11000000,0.60179700,7.60700000,0.01987778,497.74258981,0.01968279,507.63660640,0.00061346,0.03524759,575.60125852,-0.01823194,-0.01701564,0.00000000,0.00000000,0.00000000,0.00000000
57.61000000,0.63321600,7.67100000,0.02092989,501.93024930,0.02071387,512.43559364,0.00059105,0.03633236,578.95682152,-0.01875885,-0.01757351,0.00000000,0.00000000,0.00000000,0.00000000
59.11000000,0.66509800,7.73700000,0.02201878,506.24877315,0.02177987,517.39575238,0.00066959,0.03745252,582.06653660,-0.01937449,-0.01807803,0.00000000,0.00000000,0.00000000,0.00000000
60.61000000,0.69734600,7.79300000,0.02309667,509.91297520,0.02283398,521.69026522,0.00072647,0.03858125,585.32438276,-0.01996727,-0.01861398,0.00000000,0.00000000,0.00000000,0.00000000
62.11000000,0.72955900,7.85400000,0.02415611,513.90433815,0.02386897,526.31826845,0.00066820,0.03972451,588.18671832,-0.02057248,-0.01915203,0.00000000,0.00000000,0.00000000,0.00000000
63.61000000,0.76173800,7.91000000,0.02525233,517.56854021,0.02493876,530.63835351,0.00073209,0.04080592,591.22388711,-0.02114823,-0.01965769,0.00000000,0.00000000,0.00000000,0.00000000
65.11000000,0.79468000,7.96800000,0.02634856,521.36360662,0.02600741,535.10078458,0.00073153,0.04193571,594.15861223,-0.02172168,-0.02021403,0.00000000,0.00000000,0.00000000,0.00000000
66.61000000,0.82782000,8.02000000,0.02749244,524.76607996,0.02712131,539.19318226,0.00083781,0.04307802,597.17549815,-0.02236480,-0.02071323,0.00000000,0.00000000,0.00000000,0.00000000
68.11000000,0.86115600,8.07500000,0.02855556,528.36484983,0.02815544,543.45260166,0.00072239,0.04419914,599.91070598,-0.02297640,-0.02122274,0.00000000,0.00000000,0.00000000,0.00000000
69.61000000,0.89426300,8.11900000,0.02966644,531.24386573,0.02923491,547.00398236,0.00075745,0.04532221,602.72141054,-0.02355810,-0.02176411,0.00000000,0.00000000,0.00000000,0.00000000
71.11000000,0.92766700,8.17000000,0.03078089,534.58090689,0.03031666,551.03578239,0.00073507,0.04647312,605.27888733,-0.02420041,-0.02227271,0.00000000,0.00000000,0.00000000,0.00000000
72.61000000,0.96176700,8.21600000,0.03190289,537.59078715,0.03140456,554.74148630,0.00074870,0.04765229,608.27289066,-0.02483983,-0.02281247,0.00000000,0.00000000,0.00000000,0.00000000
74.11000000,0.99550300,8.26300000,0.03302122,540.66609959,0.03248773,558.51955501,0.00074811,0.04879695,610.83740889,-0.02545998,-0.02333697,0.00000000,0.00000000,0.00000000,0.00000000
75.61000000,1.02950300,8.30700000,0.03413211,543.54511549,0.03356253,562.09745776,0.00073269,0.04991587,613.39123104,-0.02604272,-0.02387315,0.00000000,0.00000000,0.00000000,0.00000000
77.11000000,1.06406500,8.35100000,0.03526878,546.42413139,0.03466108,565.69584265,0.00070354,0.05107939,615.83908464,-0.02665765,-0.02442174,0.00000000,0.00000000,0.00000000,0.00000000
78.61000000,1.09859600,8.38900000,0.03640922,548.91055421,0.03576207,568.89596056,0.00067467,0.05227242,618.37951384,-0.02732369,-0.02494873,0.00000000,0.00000000,0.00000000,0.00000000
80.11000000,1.13312600,8.43100000,0.03760100,551.65870575,0.03691132,572.40162475,0.00080137,0.05340191,620.81618466,-0.02788515,-0.02551676,0.00000000,0.00000000,0.00000000,0.00000000
81.61000000,1.16759100,8.46900000,0.03871933,554.14512857,0.03798854,575.60125852,0.00077204,0.05455444,623.27203671,-0.02850508,-0.02604936,0.00000000,0.00000000,0.00000000,0.00000000
83.11000000,1.20255100,8.50900000,0.03986333,556.76241576,0.03908929,578.95682152,0.00075708,0.05571650,625.59957059,-0.02912333,-0.02659317,0.00000000,0.00000000,0.00000000,0.00000000
84.61000000,1.23790800,8.54500000,0.04104422,559.11797422,0.04022427,582.06653660,0.00076348,0.05687995,628.07195398,-0.02977442,-0.02710553,0.00000000,0.00000000,0.00000000,0.00000000
86.11000000,1.27296800,8.58300000,0.04223611,561.60439704,0.04136851,585.32438276,0.00076986,0.05804998,630.34417902,-0.03039300,-0.02765697,0.00000000,0.00000000,0.00000000,0.00000000
87.61000000,1.30882300,8.61500000,0.04344256,563.69822679,0.04252540,588.18671832,0.00081797,0.05921882,632.55031612,-0.03100325,-0.02821557,0.00000000,0.00000000,0.00000000,0.00000000
89.11000000,1.34414700,8.65000000,0.04458667,565.98835307,0.04362127,591.22388711,0.00071152,0.06035914,634.67271109,-0.03160572,-0.02875342,0.00000000,0.00000000,0.00000000,0.00000000
90.61000000,1.38020000,8.68300000,0.04578211,568.14761500,0.04476504,594.15861223,0.00073175,0.06155207,637.04279558,-0.03226348,-0.02928858,0.00000000,0.00000000,0.00000000,0.00000000
92.11000000,1.41622000,8.71700000,0.04699244,570.37230910,0.04592172,597.17549815,0.00071710,0.06272398,639.19393208,-0.03291556,-0.02980842,0.00000000,0.00000000,0.00000000,0.00000000
93.61000000,1.45217400,8.74700000,0.04818056,572.33527449,0.04705586,599.91070598,0.00075807,0.06388390,641.41173504,-0.03355168,-0.03033222,0.00000000,0.00000000,0.00000000,0.00000000
95.11000000,1.48796200,8.77800000,0.04937244,574.36367205,0.04819231,602.72141054,0.00070128,0.06507373,643.51265797,-0.03417013,-0.03090361,0.00000000,0.00000000,0.00000000,0.00000000
96.61000000,1.52457800,8.80500000,0.05059367,576.13034090,0.04935540,605.27888733,0.00068629,0.06625606,645.47216314,-0.03479270,-0.03146336,0.00000000,0.00000000,0.00000000,0.00000000
98.11000000,1.56135900,8.83800000,0.05184822,578.28960283,0.05054883,608.27289066,0.00085371,0.06744330,647.57949374,-0.03543536,-0.03200794,0.00000000,0.00000000,0.00000000,0.00000000
99.61000000,1.59787600,8.86500000,0.05306578,580.05627167,0.05170570,610.83740889,0.00080374,0.06861858,649.68316337,-0.03606115,-0.03255743,0.00000000,0.00000000,0.00000000,0.00000000
101.11000000,1.63488800,8.89200000,0.05425756,581.82294052,0.05283678,613.39123104,0.00077479,0.06980725,651.58787638,-0.03668308,-0.03312417,0.00000000,0.00000000,0.00000000,0.00000000
102.61000000,1.67143700,8.91700000,0.05549722,583.45874501,0.05401196,615.83908464,0.00073891,0.07098691,653.63169753,-0.03732370,-0.03366321,0.00000000,0.00000000,0.00000000,0.00000000
104.11000000,1.70855000,8.94300000,0.05677000,585.15998168,0.05521709,618.37951384,0.00092610,0.07219609,655.62811906,-0.03798267,-0.03421342,0.00000000,0.00000000,0.00000000,0.00000000
105.61000000,1.74599300,8.96800000,0.05797656,586.79578617,0.05635817,620.81618466,0.00081388,0.07339767,657.48172244,-0.03862662,-0.03477105,0.00000000,0.00000000,0.00000000,0.00000000
107.11000000,1.78317200,8.99300000,0.05920900,588.43159066,0.05752240,623.27203671,0.00075731,0.07460793,659.34459950,-0.03927698,-0.03533095,0.00000000,0.00000000,0.00000000,0.00000000
108.61000000,1.82074700,9.01600000,0.06045233,589.93653079,0.05869555,625.59957059,0.00077026,0.07583999,661.29655425,-0.03995427,-0.03588573,0.00000000,0.00000000,0.00000000,0.00000000
110.11000000,1.85828900,9.04100000,0.06169933,591.57233527,0.05987077,628.07195398,0.00078317,0.07706093,663.17382547,-0.04062554,-0.03643539,0.00000000,0.00000000,0.00000000,0.00000000
111.61000000,1.89579800,9.06300000,0.06295378,593.01184322,0.06105162,630.34417902,0.00081697,0.07825341,664.96454169,-0.04127140,-0.03698201,0.00000000,0.00000000,0.00000000,0.00000000
113.11000000,1.93344100,9.08400000,0.06420811,594.38591899,0.06223096,632.55031612,0.00078822,0.07947494,666.77803813,-0.04192340,-0.03755154,0.00000000,0.00000000,0.00000000,0.00000000
114.61000000,1.97098300,9.10400000,0.06543311,595.69456259,0.06338139,634.67271109,0.00071137,0.08073538,668.62110057,-0.04262869,-0.03810668,0.00000000,0.00000000,0.00000000,0.00000000
116.11000000,2.00928600,9.12700000,0.06671689,597.19950272,0.06458560,637.04279558,0.00078616,0.08193065,670.35248106,-0.04326443,-0.03866622,0.00000000,0.00000000,0.00000000,0.00000000
117.61000000,2.04716000,9.14700000,0.06797867,598.50814631,0.06576777,639.19393208,0.00081292,0.08316782,672.18687941,-0.04392928,-0.03923854,0.00000000,0.00000000,0.00000000,0.00000000
119.11000000,2.08582800,9.16800000,0.06922944,599.88222208,0.06693824,641.41173504,0.00077100,0.08441438,673.81621574,-0.04462130,-0.03979308,0.00000000,0.00000000,0.00000000,0.00000000
120.61000000,2.12383300,9.18700000,0.07051311,601.12543349,0.06813808,643.51265797,0.00079728,0.08560518,675.55428524,-0.04523390,-0.04037129,0.00000000,0.00000000,0.00000000,0.00000000
122.11000000,2.16246800,9.20400000,0.07178956,602.23778054,0.06932973,645.47216314,0.00083056,0.08686178,677.26844363,-0.04594482,-0.04091695,0.00000000,0.00000000,0.00000000,0.00000000
123.61000000,2.20130100,9.22300000,0.07307356,603.48099195,0.07052701,647.57949374,0.00078192,0.08809988,678.97327499,-0.04660333,-0.04149656,0.00000000,0.00000000,0.00000000,0.00000000
125.11000000,2.24010100,9.24200000,0.07434622,604.72420336,0.07171231,649.68316337,0.00080830,0.08933707,680.60867702,-0.04726779,-0.04206929,0.00000000,0.00000000,0.00000000,0.00000000
126.61000000,2.27877000,9.25800000,0.07563378,605.77111824,0.07291005,651.58787638,0.00077344,0.09056962,682.17182918,-0.04794643,-0.04262319,0.00000000,0.00000000,0.00000000,0.00000000
128.11000000,2.31763600,9.27600000,0.07691389,606.94889747,0.07409944,653.63169753,0.00079956,0.09179353,683.80409072,-0.04860009,-0.04319344,0.00000000,0.00000000,0.00000000,0.00000000
129.61000000,2.35663600,9.29300000,0.07822711,608.06124452,0.07531813,655.62811906,0.00085323,0.09304599,685.45898243,-0.04928050,-0.04376550,0.00000000,0.00000000,0.00000000,0.00000000
131.11000000,2.39656100,9.30800000,0.07953300,609.04272721,0.07652854,657.48172244,0.00079762,0.09430705,687.05051812,-0.04995710,-0.04434995,0.00000000,0.00000000,0.00000000,0.00000000
132.61000000,2.43618900,9.32300000,0.08084989,610.02420991,0.07774767,659.34459950,0.00074893,0.09555369,688.56257344,-0.05060882,-0.04494487,0.00000000,0.00000000,0.00000000,0.00000000
134.11000000,2.47545300,9.33900000,0.08219244,611.07112478,0.07898902,661.29655425,0.00080902,0.09676538,690.05315680,-0.05123929,-0.04552609,0.00000000,0.00000000,0.00000000,0.00000000
135.61000000,2.51531200,9.35400000,0.08352422,612.05260747,0.08021890,663.17382547,0.00082874,0.09805150,691.67064861,-0.05195952,-0.04609198,0.00000000,0.00000000,0.00000000,0.00000000
137.11000000,2.55533900,9.36800000,0.08482633,612.96865799,0.08141991,664.96454169,0.00076627,0.09931329,693.20152075,-0.05262421,-0.04668908,0.00000000,0.00000000,0.00000000,0.00000000
138.61000000,2.59499900,9.38200000,0.08616167,613.88470850,0.08265007,666.77803813,0.00076553,0.10056009,694.72472486,-0.05331319,-0.04724690,0.00000000,0.00000000,0.00000000,0.00000000
140.11000000,2.63512400,9.39600000,0.08754111,614.80075901,0.08391929,668.62110057,0.00085246,0.10181882,696.18607334,-0.05400867,-0.04781015,0.00000000,0.00000000,0.00000000,0.00000000
141.61000000,2.67564500,9.40900000,0.08885078,615.65137735,0.08512281,670.35248106,0.00081795,0.10307251,697.71951006,-0.05468664,-0.04838586,0.00000000,0.00000000,0.00000000,0.00000000
143.11000000,2.71610000,9.42300000,0.09020822,616.56742786,0.08636871,672.18687941,0.00078329,0.10432882,699.03822127,-0.05538400,-0.04894482,0.00000000,0.00000000,0.00000000,0.00000000
144.61000000,2.75639100,9.43400000,0.09157656,617.28718184,0.08762303,673.81621574,0.00082243,0.10557912,700.57454703,-0.05604928,-0.04952984,0.00000000,0.00000000,0.00000000,0.00000000
146.11000000,2.79664600,9.44700000,0.09288622,618.13780017,0.08882211,675.55428524,0.00080150,0.10690093,702.01741497,-0.05676852,-0.05013241,0.00000000,0.00000000,0.00000000,0.00000000
147.61000000,2.83726700,9.45900000,0.09426933,618.92298632,0.09008687,677.26844363,0.00089456,0.10815530,703.41529025,-0.05742586,-0.05072945,0.00000000,0.00000000,0.00000000,0.00000000
149.11000000,2.87785500,9.47100000,0.09563389,619.70817248,0.09133309,678.97327499,0.00085266,0.10944038,704.91078855,-0.05810981,-0.05133057,0.00000000,0.00000000,0.00000000,0.00000000
150.61000000,2.91903800,9.48200000,0.09699878,620.42792645,0.09257807,680.60867702,0.00081187,0.11069197,706.23808676,-0.05877878,-0.05191319,0.00000000,0.00000000,0.00000000,0.00000000
152.11000000,2.96015500,9.49200000,0.09835989,621.08224825,0.09381806,682.17182918,0.00088454,0.11198731,707.67236011,-0.05944395,-0.05254337,0.00000000,0.00000000,0.00000000,0.00000000
153.61000000,3.00087600,9.50300000,0.09971356,621.80200222,0.09504974,683.80409072,0.00084302,0.11326495,709.02280514,-0.06012326,-0.05314169,0.00000000,0.00000000,0.00000000,0.00000000
155.11000000,3.04209300,9.51400000,0.10110044,622.52175620,0.09631008,685.45898243,0.00078200,0.11454698,710.45256421,-0.06081482,-0.05373216,0.00000000,0.00000000,0.00000000,0.00000000
156.61000000,3.08364000,9.52400000,0.10249822,623.17607800,0.09757872,687.05051812,0.00082093,0.11582500,711.73404113,-0.06150839,-0.05431661,0.00000000,0.00000000,0.00000000,0.00000000
158.11000000,3.12508800,9.53300000,0.10388144,623.76496761,0.09883255,688.56257344,0.00090691,0.11714970,713.12511323,-0.06224739,-0.05490231,0.00000000,0.00000000,0.00000000,0.00000000
159.61000000,3.16637100,9.54200000,0.10522767,624.35385723,0.10005135,690.05315680,0.00077888,0.11840774,714.47083750,-0.06291637,-0.05549136,0.00000000,0.00000000,0.00000000,0.00000000
161.11000000,3.20834900,9.55200000,0.10665856,625.00817902,0.10134516,691.67064861,0.00081101,0.11971954,715.78319946,-0.06360991,-0.05610963,0.00000000,0.00000000,0.00000000,0.00000000
162.61000000,3.25036000,9.56100000,0.10806389,625.59706864,0.10261425,693.20152075,0.00086355,0.12101690,717.08739018,-0.06433180,-0.05668510,0.00000000,0.00000000,0.00000000,0.00000000
164.11000000,3.29237300,9.57000000,0.10945433,626.18595825,0.10386830,694.72472486,0.00088211,0.12233814,718.41098855,-0.06500919,-0.05732895,0.00000000,0.00000000,0.00000000,0.00000000
165.61000000,3.33378800,9.57800000,0.11085944,626.70941569,0.10513399,696.18607334,0.00082115,0.12362890,719.64028716,-0.06572344,-0.05790546,0.00000000,0.00000000,0.00000000,0.00000000
167.11000000,3.37652800,9.58700000,0.11226111,627.29830531,0.10639498,697.71951006,0.00087349,0.12493711,720.95884036,-0.06640434,-0.05853277,0.00000000,0.00000000,0.00000000,0.00000000
168.61000000,3.41847300,9.59300000,0.11366633,627.69089838,0.10765758,699.03822127,0.00086580,0.12627257,722.29937752,-0.06715012,-0.05912245,0.00000000,0.00000000,0.00000000,0.00000000
170.11000000,3.46098100,9.60200000,0.11506778,628.27978800,0.10891519,700.57454703,0.00080490,0.12756527,723.46147414,-0.06780613,-0.05975914,0.00000000,0.00000000,0.00000000,0.00000000
171.61000000,3.50305800,9.60900000,0.11655033,628.73781326,0.11024387,702.01741497,0.00084982,0.12887165,724.71026752,-0.06850436,-0.06036728,0.00000000,0.00000000,0.00000000,0.00000000
173.11000000,3.54596500,9.61600000,0.11795922,629.19583851,0.11150490,703.41529025,0.00090165,0.13025386,725.94129755,-0.06930298,-0.06095088,0.00000000,0.00000000,0.00000000,0.00000000
174.61000000,3.58966400,9.62400000,0.11940478,629.71929595,0.11279710,704.91078855,0.00092034,0.13155653,727.26661559,-0.06997251,-0.06158401,0.00000000,0.00000000,0.00000000,0.00000000
176.11000000,3.63223700,9.63000000,0.12081378,630.11188903,0.11405501,706.23808676,0.00078133,0.13287742,728.45698933,-0.07068146,-0.06219596,0.00000000,0.00000000,0.00000000,0.00000000
177.61000000,3.67527500,9.63700000,0.12227422,630.56991428,0.11535718,707.67236011,0.00083954,0.13418690,729.64089507,-0.07139234,-0.06279456,0.00000000,0.00000000,0.00000000,0.00000000
179.11000000,3.71828000,9.64300000,0.12371622,630.96250736,0.11664125,709.02280514,0.00089070,0.13555808,730.94736692,-0.07216237,-0.06339571,0.00000000,0.00000000,0.00000000,0.00000000
180.61000000,3.76181500,9.65000000,0.12516544,631.42053262,0.11793009,710.45256421,0.00088283,0.13689551,732.23126404,-0.07287573,-0.06401979,0.00000000,0.00000000,0.00000000,0.00000000
182.11000000,3.80518400,9.65500000,0.12661122,631.74769352,0.11921421,711.73404113,0.00077711,0.13820015,733.34184349,-0.07353227,-0.06466788,0.00000000,0.00000000,0.00000000,0.00000000
183.61000000,3.84911600,9.66100000,0.12811211,632.14028659,0.12054554,713.12511323,0.00088052,0.13963012,734.54646712,-0.07437525,-0.06525488,0.00000000,0.00000000,0.00000000,0.00000000
185.11000000,3.89278200,9.66700000,0.12953944,632.53287967,0.12180998,714.47083750,0.00085993,0.14093107,735.65778462,-0.07503478,-0.06589629,0.00000000,0.00000000,0.00000000,0.00000000
186.61000000,3.93697900,9.67200000,0.13102922,632.86004057,0.12312803,715.78319946,0.00084562,0.14226107,736.94417828,-0.07571917,-0.06654191,0.00000000,0.00000000,0.00000000,0.00000000
188.11000000,3.98068100,9.67700000,0.13250456,633.18720147,0.12443160,717.08739018,0.00085807,0.14362203,738.10349222,-0.07642474,-0.06719728,0.00000000,0.00000000,0.00000000,0.00000000
189.61000000,4.02504300,9.68200000,0.13400900,633.51436236,0.12575914,718.41098855,0.00090849,0.14501252,739.28651502,-0.07720088,-0.06781164,0.00000000,0.00000000,0.00000000,0.00000000
191.11000000,4.06950300,9.68600000,0.13548033,633.77609108,0.12705576,719.64028716,0.00086835,0.14640106,740.46996144,-0.07793229,-0.06846877,0.00000000,0.00000000,0.00000000,0.00000000
192.61000000,4.11393200,9.69100000,0.13697389,634.10325198,0.12837025,720.95884036,0.00086721,0.14775616,741.63038544,-0.07867591,-0.06908025,0.00000000,0.00000000,0.00000000,0.00000000
194.11000000,4.15842700,9.69600000,0.13850056,634.43041288,0.12971209,722.29937752,0.00089846,0.14917251,742.83826685,-0.07945972,-0.06971278,0.00000000,0.00000000,0.00000000,0.00000000
195.61000000,4.20302200,9.69900000,0.13997956,634.62670942,0.13101033,723.46147414,0.00086511,0.15058701,743.97010389,-0.08024178,-0.07034523,0.00000000,0.00000000,0.00000000,0.00000000
197.11000000,4.24811000,9.70300000,0.14147656,634.88843813,0.13232265,724.71026752,0.00078647,0.15190549,745.03186141,-0.08090844,-0.07099705,0.00000000,0.00000000,0.00000000,0.00000000
198.61000000,4.29257200,9.70600000,0.14306211,635.08473467,0.13371072,725.94129755,0.00096587,0.15328451,746.21728025,-0.08166944,-0.07161507,0.00000000,0.00000000,0.00000000,0.00000000
200.11000000,4.33799400,9.71100000,0.14455933,635.41189557,0.13501970,727.26661559,0.00091954,0.15469280,747.42651713,-0.08240269,-0.07229011,0.00000000,0.00000000,0.00000000,0.00000000
201.61000000,4.38252200,9.71400000,0.14607867,635.60819211,0.13634626,728.45698933,0.00089911,0.15613115,748.50620429,-0.08319982,-0.07293133,0.00000000,0.00000000,0.00000000,0.00000000
203.11000000,4.42751400,9.71700000,0.14758689,635.80448865,0.13766138,729.64089507,0.00089774,0.15753578,749.63922557,-0.08394947,-0.07358630,0.00000000,0.00000000,0.00000000,0.00000000
204.61000000,4.47329800,9.72100000,0.14916867,636.06621737,0.13903878,730.94736692,0.00089650,0.15893851,750.77253438,-0.08469177,-0.07424674,0.00000000,0.00000000,0.00000000,0.00000000
206.11000000,4.51911700,9.72500000,0.15071367,636.32794608,0.14038233,732.23126404,0.00095925,0.16037063,751.85237209,-0.08544520,-0.07492543,0.00000000,0.00000000,0.00000000,0.00000000
207.61000000,4.56467000,9.72700000,0.15222200,636.45881044,0.14169225,733.34184349,0.00083026,0.16176927,752.98593735,-0.08619067,-0.07557859,0.00000000,0.00000000,0.00000000,0.00000000
209.11000000,4.61032400,9.72900000,0.15387744,636.58967480,0.14312796,734.54646712,0.00102059,0.16322852,754.08950011,-0.08698381,-0.07624472,0.00000000,0.00000000,0.00000000,0.00000000
210.61000000,4.65601100,9.73100000,0.15538567,636.72053916,0.14443420,735.65778462,0.00089168,0.16465411,755.24687005,-0.08773281,-0.07692130,0.00000000,0.00000000,0.00000000,0.00000000
212.11000000,4.70249100,9.73500000,0.15693044,636.98226788,0.14577033,736.94417828,0.00082650,0.16610904,756.35047504,-0.08851832,-0.07759072,0.00000000,0.00000000,0.00000000,0.00000000
213.61000000,4.74917000,9.73700000,0.15851244,637.11313224,0.14713681,738.10349222,0.00088946,0.00000000,0.00000000,0.00000000,0.00000000,0.00000000,0.00000000,0.00000000,0.00000000
215.11000000,4.79585000,9.73900000,0.16013100,637.24399660,0.14853293,739.28651502,0.00095165,0.00000000,0.00000000,0.00000000,0.00000000,0.00000000,0.00000000,0.00000000,0.00000000
216.61000000,4.84226400,9.74100000,0.16174956,637.37486096,0.14992711,740.46996144,0.00101367,0.00000000,0.00000000,0.00000000,0.00000000,0.00000000,0.00000000,0.00000000,0.00000000
218.11000000,4.88934100,9.74300000,0.16333133,637.50572532,0.15128773,741.63038544,0.00088539,0.00000000,0.00000000,0.00000000,0.00000000,0.00000000,0.00000000,0.00000000,0.00000000
219.61000000,4.93708000,9.74500000,0.16498689,637.63658967,0.15270983,742.83826685,0.00101085,0.00000000,0.00000000,0.00000000,0.00000000,0.00000000,0.00000000,0.00000000,0.00000000
221.11000000,4.98415600,9.74600000,0.16664222,637.70202185,0.15412973,743.97010389,0.00107250,0.00000000,0.00000000,0.00000000,0.00000000,0.00000000,0.00000000,0.00000000,0.00000000
222.61000000,5.03146500,9.74700000,0.16818733,637.76745403,0.15545326,745.03186141,0.00088190,0.00000000,0.00000000,0.00000000,0.00000000,0.00000000,0.00000000,0.00000000,0.00000000
224.11000000,5.07900500,9.74900000,0.16980600,637.89831839,0.15683792,746.21728025,0.00094378,0.00000000,0.00000000,0.00000000,0.00000000,0.00000000,0.00000000,0.00000000,0.00000000
225.61000000,5.12710800,9.75100000,0.17146133,638.02918275,0.15825197,747.42651713,0.00094226,0.00000000,0.00000000,0.00000000,0.00000000,0.00000000,0.00000000,0.00000000,0.00000000
227.11000000,5.17527800,9.75100000,0.17315356,638.02918275,0.15969547,748.50620429,0.00094090,0.00000000,0.00000000,0.00000000,0.00000000,0.00000000,0.00000000,0.00000000,0.00000000
228.61000000,5.22387800,9.75200000,0.17480889,638.09461493,0.16110549,749.63922557,0.00100240,0.00000000,0.00000000,0.00000000,0.00000000,0.00000000,0.00000000,0.00000000,0.00000000
230.11000000,5.27161500,9.75300000,0.17646433,638.16004711,0.16251361,750.77253438,0.00093825,0.00000000,0.00000000,0.00000000,0.00000000,0.00000000,0.00000000,0.00000000,0.00000000
231.61000000,5.32034600,9.75300000,0.17815644,638.16004711,0.16395088,751.85237209,0.00087463,0.00000000,0.00000000,0.00000000,0.00000000,0.00000000,0.00000000,0.00000000,0.00000000
233.11000000,5.36931200,9.75400000,0.17981178,638.22547929,0.16535492,752.98593735,0.00087302,0.00000000,0.00000000,0.00000000,0.00000000,0.00000000,0.00000000,0.00000000,0.00000000
234.61000000,5.41778000,9.75400000,0.18154089,638.22547929,0.16681942,754.08950011,0.00105878,0.00000000,0.00000000,0.00000000,0.00000000,0.00000000,0.00000000,0.00000000,0.00000000
236.11000000,5.46740400,9.75500000,0.18323300,638.29091147,0.16825052,755.24687005,0.00093288,0.00000000,0.00000000,0.00000000,0.00000000,0.00000000,0.00000000,0.00000000,0.00000000
237.61000000,5.51709600,9.75500000,0.18496200,638.29091147,0.16971071,756.35047504,0.00093152,0.00000000,0.00000000,0.00000000,0.00000000,0.00000000,0.00000000,0.00000000,0.00000000
239.11000000,5.56619300,9.75500000,0.18672778,638.29091147,0.00000000,0.00000000,0.00000000,0.00000000,0.00000000,0.00000000,0.00000000,0.00000000,0.00000000,0.00000000,0.00000000
240.61000000,5.61591800,9.75500000,0.18845667,638.29091147,0.00000000,0.00000000,0.00000000,0.00000000,0.00000000,0.00000000,0.00000000,0.00000000,0.00000000,0.00000000,0.00000000
242.11000000,5.66557800,9.75400000,0.19018589,638.22547929,0.00000000,0.00000000,0.00000000,0.00000000,0.00000000,0.00000000,0.00000000,0.00000000,0.00000000,0.00000000,0.00000000
243.61000000,5.71570000,9.75500000,0.19198844,638.29091147,0.00000000,0.00000000,0.00000000,0.00000000,0.00000000,0.00000000,0.00000000,0.00000000,0.00000000,0.00000000,0.00000000
245.11000000,5.76602200,9.75400000,0.19379100,638.22547929,0.00000000,0.00000000,0.00000000,0.00000000,0.00000000,0.00000000,0.00000000,0.00000000,0.00000000,0.00000000,0.00000000
246.61000000,5.81664200,9.75300000,0.19559344,638.16004711,0.00000000,0.00000000,0.00000000,0.00000000,0.00000000,0.00000000,0.00000000,0.00000000,0.00000000,0.00000000,0.00000000
248.11000000,5.86706200,9.75300000,0.19735933,638.16004711,0.00000000,0.00000000,0.00000000,0.00000000,0.00000000,0.00000000,0.00000000,0.00000000,0.00000000,0.00000000,0.00000000
249.61000000,5.91758200,9.75200000,0.19923556,638.09461493,0.00000000,0.00000000,0.00000000,0.00000000,0.00000000,0.00000000,0.00000000,0.00000000,0.00000000,0.00000000,0.00000000
251.11000000,5.96929300,9.75200000,0.20107489,638.09461493,0.00000000,0.00000000,0.00000000,0.00000000,0.00000000,0.00000000,0.00000000,0.00000000,0.00000000,0.00000000,0.00000000
252.61000000,6.02064100,9.75000000,0.20284056,637.96375057,0.00000000,0.00000000,0.00000000,0.00000000,0.00000000,0.00000000,0.00000000,0.00000000,0.00000000,0.00000000,0.00000000
254.11000000,6.07179000,9.74900000,0.20475367,637.89831839,0.00000000,0.00000000,0.00000000,0.00000000,0.00000000,0.00000000,0.00000000,0.00000000,0.00000000,0.00000000,0.00000000
255.61000000,6.12346900,9.74800000,0.20666678,637.83288621,0.00000000,0.00000000,0.00000000,0.00000000,0.00000000,0.00000000,0.00000000,0.00000000,0.00000000,0.00000000,0.00000000
257.11000000,6.17587600,9.74700000,0.20854278,637.76745403,0.00000000,0.00000000,0.00000000,0.00000000,0.00000000,0.00000000,0.00000000,0.00000000,0.00000000,0.00000000,0.00000000
258.61000000,6.22815200,9.74500000,0.21045578,637.63658967,0.00000000,0.00000000,0.00000000,0.00000000,0.00000000,0.00000000,0.00000000,0.00000000,0.00000000,0.00000000,0.00000000
260.11000000,6.28118800,9.74400000,0.21240567,637.57115750,0.00000000,0.00000000,0.00000000,0.00000000,0.00000000,0.00000000,0.00000000,0.00000000,0.00000000,0.00000000,0.00000000
261.61000000,6.33396000,9.74100000,0.21439211,637.37486096,0.00000000,0.00000000,0.00000000,0.00000000,0.00000000,0.00000000,0.00000000,0.00000000,0.00000000,0.00000000,0.00000000
263.11000000,6.38739300,9.74000000,0.21641544,637.30942878,0.00000000,0.00000000,0.00000000,0.00000000,0.00000000,0.00000000,0.00000000,0.00000000,0.00000000,0.00000000,0.00000000
264.61000000,6.44029600,9.73700000,0.21836533,637.11313224,0.00000000,0.00000000,0.00000000,0.00000000,0.00000000,0.00000000,0.00000000,0.00000000,0.00000000,0.00000000,0.00000000
266.11000000,6.49402800,9.73500000,0.22035189,636.98226788,0.00000000,0.00000000,0.00000000,0.00000000,0.00000000,0.00000000,0.00000000,0.00000000,0.00000000,0.00000000,0.00000000
267.61000000,6.54762500,9.73300000,0.22237533,636.85140352,0.00000000,0.00000000,0.00000000,0.00000000,0.00000000,0.00000000,0.00000000,0.00000000,0.00000000,0.00000000,0.00000000
269.11000000,6.60191900,9.73100000,0.22443544,636.72053916,0.00000000,0.00000000,0.00000000,0.00000000,0.00000000,0.00000000,0.00000000,0.00000000,0.00000000,0.00000000,0.00000000
270.61000000,6.65697500,9.72800000,0.22653233,636.52424262,0.00000000,0.00000000,0.00000000,0.00000000,0.00000000,0.00000000,0.00000000,0.00000000,0.00000000,0.00000000,0.00000000
272.11000000,6.71153300,9.72500000,0.22859256,636.32794608,0.00000000,0.00000000,0.00000000,0.00000000,0.00000000,0.00000000,0.00000000,0.00000000,0.00000000,0.00000000,0.00000000
273.61000000,6.76629100,9.72100000,0.23076300,636.06621737,0.00000000,0.00000000,0.00000000,0.00000000,0.00000000,0.00000000,0.00000000,0.00000000,0.00000000,0.00000000,0.00000000
275.11000000,6.82137800,9.71800000,0.23286011,635.86992083,0.00000000,0.00000000,0.00000000,0.00000000,0.00000000,0.00000000,0.00000000,0.00000000,0.00000000,0.00000000,0.00000000
276.61000000,6.87709600,9.71400000,0.23499378,635.60819211,0.00000000,0.00000000,0.00000000,0.00000000,0.00000000,0.00000000,0.00000000,0.00000000,0.00000000,0.00000000,0.00000000
278.11000000,6.93277900,9.71100000,0.23712767,635.41189557,0.00000000,0.00000000,0.00000000,0.00000000,0.00000000,0.00000000,0.00000000,0.00000000,0.00000000,0.00000000,0.00000000
279.61000000,6.98889300,9.70600000,0.23929822,635.08473467,0.00000000,0.00000000,0.00000000,0.00000000,0.00000000,0.00000000,0.00000000,0.00000000,0.00000000,0.00000000,0.00000000
281.11000000,7.04494300,9.70300000,0.24150578,634.88843813,0.00000000,0.00000000,0.00000000,0.00000000,0.00000000,0.00000000,0.00000000,0.00000000,0.00000000,0.00000000,0.00000000
282.61000000,7.10201600,9.69900000,0.24371311,634.62670942,0.00000000,0.00000000,0.00000000,0.00000000,0.00000000,0.00000000,0.00000000,0.00000000,0.00000000,0.00000000,0.00000000
284.11000000,7.15889200,9.69300000,0.24588389,634.23411634,0.00000000,0.00000000,0.00000000,0.00000000,0.00000000,0.00000000,0.00000000,0.00000000,0.00000000,0.00000000,0.00000000
285.61000000,7.21576800,9.68700000,0.24809122,633.84152326,0.00000000,0.00000000,0.00000000,0.00000000,0.00000000,0.00000000,0.00000000,0.00000000,0.00000000,0.00000000,0.00000000
287.11000000,7.27297500,9.68200000,0.25029878,633.51436236,0.00000000,0.00000000,0.00000000,0.00000000,0.00000000,0.00000000,0.00000000,0.00000000,0.00000000,0.00000000,0.00000000
288.61000000,7.33090900,9.67600000,0.25250656,633.12176929,0.00000000,0.00000000,0.00000000,0.00000000,0.00000000,0.00000000,0.00000000,0.00000000,0.00000000,0.00000000,0.00000000
290.11000000,7.38910900,9.67000000,0.25467722,632.72917621,0.00000000,0.00000000,0.00000000,0.00000000,0.00000000,0.00000000,0.00000000,0.00000000,0.00000000,0.00000000,0.00000000
291.61000000,7.44744100,9.66300000,0.25684833,632.27115095,0.00000000,0.00000000,0.00000000,0.00000000,0.00000000,0.00000000,0.00000000,0.00000000,0.00000000,0.00000000,0.00000000
293.11000000,7.50564100,9.65500000,0.25898233,631.74769352,0.00000000,0.00000000,0.00000000,0.00000000,0.00000000,0.00000000,0.00000000,0.00000000,0.00000000,0.00000000,0.00000000
294.61000000,7.56394100,9.64800000,0.26119033,631.28966826,0.00000000,0.00000000,0.00000000,0.00000000,0.00000000,0.00000000,0.00000000,0.00000000,0.00000000,0.00000000,0.00000000
296.11000000,7.62333100,9.63800000,0.26336144,630.63534646,0.00000000,0.00000000,0.00000000,0.00000000,0.00000000,0.00000000,0.00000000,0.00000000,0.00000000,0.00000000,0.00000000
297.61000000,7.68242400,9.63000000,0.26545922,630.11188903,0.00000000,0.00000000,0.00000000,0.00000000,0.00000000,0.00000000,0.00000000,0.00000000,0.00000000,0.00000000,0.00000000
299.11000000,7.74148500,9.61900000,0.26755700,629.39213505,0.00000000,0.00000000,0.00000000,0.00000000,0.00000000,0.00000000,0.00000000,0.00000000,0.00000000,0.00000000,0.00000000
300.61000000,7.80170400,9.61100000,0.26958111,628.86867762,0.00000000,0.00000000,0.00000000,0.00000000,0.00000000,0.00000000,0.00000000,0.00000000,0.00000000,0.00000000,0.00000000
302.11000000,7.86202300,9.59900000,0.27164256,628.08349146,0.00000000,0.00000000,0.00000000,0.00000000,0.00000000,0.00000000,0.00000000,0.00000000,0.00000000,0.00000000,0.00000000
303.61000000,7.92253900,9.58700000,0.27363033,627.29830531,0.00000000,0.00000000,0.00000000,0.00000000,0.00000000,0.00000000,0.00000000,0.00000000,0.00000000,0.00000000,0.00000000
305.11000000,7.98269000,9.57200000,0.27558189,626.31682261,0.00000000,0.00000000,0.00000000,0.00000000,0.00000000,0.00000000,0.00000000,0.00000000,0.00000000,0.00000000,0.00000000
306.61000000,8.04307400,9.55900000,0.27742289,625.46620428,0.00000000,0.00000000,0.00000000,0.00000000,0.00000000,0.00000000,0.00000000,0.00000000,0.00000000,0.00000000,0.00000000
308.11000000,8.10385600,9.54300000,0.27926467,624.41928941,0.00000000,0.00000000,0.00000000,0.00000000,0.00000000,0.00000000,0.00000000,0.00000000,0.00000000,0.00000000,0.00000000
309.61000000,8.16457100,9.52800000,0.28103289,623.43780671,0.00000000,0.00000000,0.00000000,0.00000000,0.00000000,0.00000000,0.00000000,0.00000000,0.00000000,0.00000000,0.00000000
311.11000000,8.22548500,9.50800000,0.28276511,622.12916312,0.00000000,0.00000000,0.00000000,0.00000000,0.00000000,0.00000000,0.00000000,0.00000000,0.00000000,0.00000000,0.00000000
312.61000000,8.28702700,9.49000000,0.28446111,620.95138389,0.00000000,0.00000000,0.00000000,0.00000000,0.00000000,0.00000000,0.00000000,0.00000000,0.00000000,0.00000000,0.00000000
314.11000000,8.34846900,9.46700000,0.28604700,619.44644376,0.00000000,0.00000000,0.00000000,0.00000000,0.00000000,0.00000000,0.00000000,0.00000000,0.00000000,0.00000000,0.00000000
315.61000000,8.40977700,9.44600000,0.28755944,618.07236799,0.00000000,0.00000000,0.00000000,0.00000000,0.00000000,0.00000000,0.00000000,0.00000000,0.00000000,0.00000000,0.00000000
317.11000000,8.47148400,9.42000000,0.28907311,616.37113132,0.00000000,0.00000000,0.00000000,0.00000000,0.00000000,0.00000000,0.00000000,0.00000000,0.00000000,0.00000000,0.00000000
318.61000000,8.53315300,9.39400000,0.29054989,614.66989465,0.00000000,0.00000000,0.00000000,0.00000000,0.00000000,0.00000000,0.00000000,0.00000000,0.00000000,0.00000000,0.00000000
320.11000000,8.59528400,9.36400000,0.29188078,612.70692927,0.00000000,0.00000000,0.00000000,0.00000000,0.00000000,0.00000000,0.00000000,0.00000000,0.00000000,0.00000000,0.00000000
321.61000000,8.65751300,9.33500000,0.29317556,610.80939606,0.00000000,0.00000000,0.00000000,0.00000000,0.00000000,0.00000000,0.00000000,0.00000000,0.00000000,0.00000000,0.00000000
323.11000000,8.71927500,9.29600000,0.29450833,608.25754106,0.00000000,0.00000000,0.00000000,0.00000000,0.00000000,0.00000000,0.00000000,0.00000000,0.00000000,0.00000000,0.00000000
324.61000000,8.78106800,9.26300000,0.29569467,606.09827913,0.00000000,0.00000000,0.00000000,0.00000000,0.00000000,0.00000000,0.00000000,0.00000000,0.00000000,0.00000000,0.00000000
326.11000000,8.84438200,9.22000000,0.29688133,603.28469541,0.00000000,0.00000000,0.00000000,0.00000000,0.00000000,0.00000000,0.00000000,0.00000000,0.00000000,0.00000000,0.00000000
327.61000000,8.90729400,9.17900000,0.29803278,600.60197605,0.00000000,0.00000000,0.00000000,0.00000000,0.00000000,0.00000000,0.00000000,0.00000000,0.00000000,0.00000000,0.00000000
329.11000000,8.97050100,9.12200000,0.29911011,596.87234182,0.00000000,0.00000000,0.00000000,0.00000000,0.00000000,0.00000000,0.00000000,0.00000000,0.00000000,0.00000000,0.00000000
330.61000000,9.03393800,9.07100000,0.30000478,593.53530066,0.00000000,0.00000000,0.00000000,0.00000000,0.00000000,0.00000000,0.00000000,0.00000000,0.00000000,0.00000000,0.00000000
332.11000000,9.09770200,9.00000000,0.30089856,588.88961591,0.00000000,0.00000000,0.00000000,0.00000000,0.00000000,0.00000000,0.00000000,0.00000000,0.00000000,0.00000000,0.00000000
333.61000000,9.16335100,8.93600000,0.30168122,584.70195642,0.00000000,0.00000000,0.00000000,0.00000000,0.00000000,0.00000000,0.00000000,0.00000000,0.00000000,0.00000000,0.00000000
335.11000000,9.22916500,8.84600000,0.30209833,578.81306026,0.00000000,0.00000000,0.00000000,0.00000000,0.00000000,0.00000000,0.00000000,0.00000000,0.00000000,0.00000000,0.00000000
336.61000000,9.29630200,8.75800000,0.30258444,573.05502846,0.00000000,0.00000000,0.00000000,0.00000000,0.00000000,0.00000000,0.00000000,0.00000000,0.00000000,0.00000000,0.00000000
337.11000000,9.31920100,8.70800000,0.30262533,569.78341949,0.00000000,0.00000000,0.00000000,0.00000000,0.00000000,0.00000000,0.00000000,0.00000000,0.00000000,0.00000000,0.00000000