File: LAB_DATA/DP600_results/DATA/UT_60_3.csv
Time[s],Displacement[mm],Force[kN],EngStrain_longi,EngStress[MPa],TrueStrain,TrueStress[MPa],TrueStrainRate[1/s],PlasticStrain_longi,PlasticStress[MPa],PlasticStrain_thick,PlasticStrain_width,R-Value,Thickness[mm],Width[mm], Young's Modulus [MPa]
0.60000000,0.00000000,-0.01300000,0.00000000,-0.85089671,0.00000000,-0.85089671,0.00000000,0.00060201,346.57105498,0.00014944,-0.00075145,0.87095827,1.52780000,10.00000000,246068.64439102
2.10000000,0.00170100,0.01200000,0.00000356,0.78544312,0.00000356,0.78544591,-0.00004600,0.00100952,364.26566195,0.00014906,-0.00115858,0.00000000,0.00000000,0.00000000,0.00000000
3.60000000,0.00330700,0.44100000,0.00007978,28.86503469,0.00007977,28.86733748,-0.00000267,0.00148467,376.93781254,-0.00008662,-0.00139806,0.00000000,0.00000000,0.00000000,0.00000000
5.10000000,0.00567400,0.72600000,0.00019311,47.51930881,0.00019309,47.52848532,0.00013242,0.00212585,390.08329328,-0.00054839,-0.00157746,0.00000000,0.00000000,0.00000000,0.00000000
6.60000000,0.00767700,1.10300000,0.00022544,72.19531352,0.00022542,72.21158956,0.00013309,0.00289108,400.13430240,-0.00105291,-0.00183817,0.00000000,0.00000000,0.00000000,0.00000000
8.10000000,0.00949800,1.41100000,0.00026778,92.35502029,0.00026774,92.37975091,0.00011553,0.00368674,411.33514638,-0.00139444,-0.00229230,0.00000000,0.00000000,0.00000000,0.00000000
9.60000000,0.01112700,1.79800000,0.00032300,117.68556094,0.00032295,117.72357337,0.00001044,0.00442684,419.49485977,-0.00166770,-0.00275913,0.00000000,0.00000000,0.00000000,0.00000000
11.10000000,0.01355300,2.10600000,0.00038400,137.84526771,0.00038393,137.89820029,-0.00013083,0.00524150,428.75608620,-0.00209740,-0.00314409,0.00000000,0.00000000,0.00000000,0.00000000
12.60000000,0.01672100,2.46800000,0.00049511,161.53946852,0.00049499,161.61944850,-0.00014992,0.00619390,435.71255439,-0.00267657,-0.00351733,0.00000000,0.00000000,0.00000000,0.00000000
14.10000000,0.01989300,2.77700000,0.00065511,181.76462888,0.00065490,181.88370491,0.00015657,0.00711612,443.46336166,-0.00321169,-0.00390443,0.00000000,0.00000000,0.00000000,0.00000000
15.60000000,0.02302100,3.15800000,0.00078867,206.70244796,0.00078836,206.86546730,0.00030223,0.00799986,449.88601021,-0.00361974,-0.00438012,0.00000000,0.00000000,0.00000000,0.00000000
17.10000000,0.02592800,3.45800000,0.00082244,226.33852599,0.00082211,226.52467685,0.00025070,0.00882647,457.42141327,-0.00391716,-0.00490932,0.00000000,0.00000000,0.00000000,0.00000000
18.60000000,0.02896100,3.82900000,0.00085711,250.62180914,0.00085674,250.83661987,0.00012279,0.00979480,463.30939215,-0.00440003,-0.00539477,0.00000000,0.00000000,0.00000000,0.00000000
20.10000000,0.03310500,4.11900000,0.00096011,269.60335122,0.00095965,269.86220040,-0.00005861,0.01081832,470.36449900,-0.00498750,-0.00583081,0.00000000,0.00000000,0.00000000,0.00000000
21.60000000,0.03873300,4.45200000,0.00111822,291.39939783,0.00111760,291.72524711,-0.00022773,0.01173185,475.91781014,-0.00549397,-0.00623788,0.00000000,0.00000000,0.00000000,0.00000000
23.10000000,0.04578500,4.72600000,0.00141989,309.33368242,0.00141888,309.77290188,-0.00013957,0.01261627,482.06643010,-0.00594592,-0.00667034,0.00000000,0.00000000,0.00000000,0.00000000
24.60000000,0.05452600,5.04600000,0.00184656,330.27883231,0.00184485,330.88871052,0.00018367,0.01358091,487.19866003,-0.00643838,-0.00714253,0.00000000,0.00000000,0.00000000,0.00000000
26.10000000,0.06707300,5.28300000,0.00225489,345.79133394,0.00225235,346.57105498,0.00046257,0.01460464,493.37068957,-0.00696675,-0.00763789,0.00000000,0.00000000,0.00000000,0.00000000
27.60000000,0.08326400,5.55000000,0.00274789,363.26744338,0.00274412,364.26566195,0.00060177,0.01560078,498.27221312,-0.00744271,-0.00815807,0.00000000,0.00000000,0.00000000,0.00000000
29.10000000,0.10001800,5.74000000,0.00328500,375.70362613,0.00327962,376.93781254,0.00050596,0.01653385,504.02067696,-0.00790666,-0.00862719,0.00000000,0.00000000,0.00000000,0.00000000
30.60000000,0.12074400,5.93600000,0.00399133,388.53253044,0.00398339,390.08329328,0.00052774,0.01754730,508.61597657,-0.00847549,-0.00907181,0.00000000,0.00000000,0.00000000,0.00000000
32.10000000,0.14262800,6.08400000,0.00480800,398.21966226,0.00479648,400.13430240,0.00071779,0.01859333,513.70610587,-0.00908807,-0.00950526,0.00000000,0.00000000,0.00000000,0.00000000
33.60000000,0.16848600,6.24900000,0.00566144,409.01950517,0.00564548,411.33514638,0.00097317,0.01963453,518.06615886,-0.00966155,-0.00997297,0.00000000,0.00000000,0.00000000,0.00000000
35.10000000,0.19401300,6.36800000,0.00644511,416.80848279,0.00642443,419.49485977,0.00083347,0.02061007,523.13919150,-0.01016130,-0.01044877,0.00000000,0.00000000,0.00000000,0.00000000
36.60000000,0.22073200,6.50300000,0.00730978,425.64471790,0.00728319,428.75608620,0.00058448,0.02163232,527.23827619,-0.01064846,-0.01098386,0.00000000,0.00000000,0.00000000,0.00000000
38.10000000,0.24751600,6.60200000,0.00830300,432.12462364,0.00826872,435.71255439,0.00069325,0.02271109,532.04844325,-0.01121514,-0.01149595,0.00000000,0.00000000,0.00000000,0.00000000
39.60000000,0.27678200,6.71300000,0.00927056,439.38997251,0.00922785,443.46336166,0.00086770,0.02375715,535.97516947,-0.01174835,-0.01200879,0.00000000,0.00000000,0.00000000,0.00000000
41.10000000,0.30439400,6.80400000,0.01019378,445.34624951,0.01014217,449.88601021,0.00088870,0.02480367,540.31459452,-0.01229587,-0.01250780,0.00000000,0.00000000,0.00000000,0.00000000
42.60000000,0.33379300,6.91200000,0.01106544,452.41523760,0.01100467,457.42141327,0.00061111,0.02587355,544.00026797,-0.01288967,-0.01298388,0.00000000,0.00000000,0.00000000,0.00000000
44.10000000,0.36282900,6.99400000,0.01207333,457.78243226,0.01200103,463.30939215,0.00056701,0.02696440,548.31320622,-0.01353451,-0.01342989,0.00000000,0.00000000,0.00000000,0.00000000
45.60000000,0.39259300,7.09300000,0.01314378,464.26233800,0.01305815,470.36449900,0.00075533,0.02803268,551.81054961,-0.01413771,-0.01389497,0.00000000,0.00000000,0.00000000,0.00000000
47.10000000,0.42195900,7.17000000,0.01409656,469.30226469,0.01399812,475.91781014,0.00071121,0.02912166,556.00383781,-0.01473644,-0.01438523,0.00000000,0.00000000,0.00000000,0.00000000
48.60000000,0.45294700,7.25600000,0.01502356,474.93127373,0.01491182,482.06643010,0.00065975,0.03021678,559.39535338,-0.01535222,-0.01486457,0.00000000,0.00000000,0.00000000,0.00000000
50.10000000,0.48260900,7.32600000,0.01602800,479.51302527,0.01590091,487.19866003,0.00050705,0.03127015,563.04176317,-0.01587047,-0.01539968,0.00000000,0.00000000,0.00000000,0.00000000
51.60000000,0.51333100,7.41100000,0.01709856,485.07658070,0.01695402,493.37068957,0.00060049,0.03239885,566.33032266,-0.01648902,-0.01590983,0.00000000,0.00000000,0.00000000,0.00000000
53.10000000,0.54474900,7.47700000,0.01813600,489.39651787,0.01797350,498.27221312,0.00071560,0.03345309,570.05951041,-0.01701957,-0.01643352,0.00000000,0.00000000,0.00000000,0.00000000
54.60000000,0.57547100,7.55600000,0.01911433,494.56735175,0.01893395,504.02067696,0.00060650,0.03459074,573.16276834,-0.01764241,-0.01694832,0.00000000,0.00000000,0.00000000,0.00000000
56.10000000,0.60781600,7.61700000,0.02017000,498.56002095,0.01996928,508.61597657,0.00053375,0.03566825,576.71512344,-0.01821523,-0.01745302,0.00000000,0.00000000,0.00000000,0.00000000
57.60000000,0.63893700,7.68500000,0.02126244,503.01086530,0.02103955,513.70610587,0.00060522,0.03675448,579.66514152,-0.01879157,-0.01796291,0.00000000,0.00000000,0.00000000,0.00000000
59.10000000,0.67128200,7.74200000,0.02234756,506.74172012,0.02210151,518.06615886,0.00074853,0.03789425,582.99404814,-0.01943259,-0.01846165,0.00000000,0.00000000,0.00000000,0.00000000
60.60000000,0.70346300,7.81000000,0.02337011,511.19256447,0.02310121,523.13919150,0.00071889,0.03903109,585.91754025,-0.02006272,-0.01896837,0.00000000,0.00000000,0.00000000,0.00000000
62.10000000,0.73577400,7.86300000,0.02443678,514.66160492,0.02414298,527.23827619,0.00061029,0.04015402,589.24990589,-0.02063005,-0.01952397,0.00000000,0.00000000,0.00000000,0.00000000
63.60000000,0.76858300,7.92600000,0.02556600,518.78518131,0.02524466,532.04844325,0.00067443,0.04126096,591.96224904,-0.02122840,-0.02003256,0.00000000,0.00000000,0.00000000,0.00000000
65.10000000,0.80152400,7.97600000,0.02665856,522.05786098,0.02630941,535.97516947,0.00075253,0.04239251,595.17535770,-0.02182424,-0.02056827,0.00000000,0.00000000,0.00000000,0.00000000
66.60000000,0.83469600,8.03200000,0.02775478,525.72326221,0.02737660,540.31459452,0.00069462,0.04358488,597.88149641,-0.02244535,-0.02113954,0.00000000,0.00000000,0.00000000,0.00000000
68.10000000,0.86810100,8.07800000,0.02887300,528.73412750,0.02846403,544.00026797,0.00069387,0.04467676,600.73929898,-0.02298289,-0.02169386,0.00000000,0.00000000,0.00000000,0.00000000
69.60000000,0.90140500,8.13300000,0.03001711,532.33407514,0.02957541,548.31320622,0.00074317,0.04579286,603.41062275,-0.02355819,-0.02223467,0.00000000,0.00000000,0.00000000,0.00000000
71.10000000,0.93504100,8.17600000,0.03113522,535.14857966,0.03066035,551.81054961,0.00076349,0.04697341,606.26440799,-0.02421610,-0.02275731,0.00000000,0.00000000,0.00000000,0.00000000
72.60000000,0.96887500,8.22900000,0.03227933,538.61762011,0.03176930,556.00383781,0.00074843,0.04815014,608.84550615,-0.02482832,-0.02332183,0.00000000,0.00000000,0.00000000,0.00000000
74.10000000,1.00297400,8.27000000,0.03342711,541.30121744,0.03288057,559.39535338,0.00079062,0.04931069,611.62946548,-0.02547272,-0.02383797,0.00000000,0.00000000,0.00000000,0.00000000
75.60000000,1.03661100,8.31500000,0.03453422,544.24662914,0.03395130,563.04176317,0.00074680,0.05041613,613.96973976,-0.02603582,-0.02438031,0.00000000,0.00000000,0.00000000,0.00000000
77.10000000,1.07140400,8.35400000,0.03571878,546.79931928,0.03509566,566.33032266,0.00083824,0.05160576,616.64383408,-0.02670917,-0.02489660,0.00000000,0.00000000,0.00000000,0.00000000
78.60000000,1.10576900,8.40000000,0.03682967,549.81018458,0.03616766,570.05951041,0.00072370,0.05278497,619.03938139,-0.02735991,-0.02542507,0.00000000,0.00000000,0.00000000,0.00000000
80.10000000,1.14046300,8.43600000,0.03802522,552.16651394,0.03732008,573.16276834,0.00079397,0.05391655,621.61855569,-0.02797577,-0.02594078,0.00000000,0.00000000,0.00000000,0.00000000
81.60000000,1.17522500,8.47900000,0.03916189,554.98101846,0.03841451,576.71512344,0.00077898,0.05508305,623.87684038,-0.02857593,-0.02650712,0.00000000,0.00000000,0.00000000,0.00000000
83.10000000,1.20978800,8.51300000,0.04030589,557.20644063,0.03951479,579.66514152,0.00074265,0.05627126,626.43185626,-0.02916762,-0.02710365,0.00000000,0.00000000,0.00000000,0.00000000
84.60000000,1.24541000,8.55200000,0.04150878,559.75913078,0.04067041,582.99404814,0.00073475,0.05742838,628.62381639,-0.02980771,-0.02762067,0.00000000,0.00000000,0.00000000,0.00000000
86.10000000,1.28076700,8.58500000,0.04270800,561.91909936,0.04182118,585.91754025,0.00075523,0.05861084,631.04555494,-0.03044231,-0.02816853,0.00000000,0.00000000,0.00000000,0.00000000
87.60000000,1.31655400,8.62400000,0.04389611,564.47178950,0.04295997,589.24990589,0.00075416,0.05978941,633.26001071,-0.03105698,-0.02873244,0.00000000,0.00000000,0.00000000,0.00000000
89.10000000,1.35227600,8.65400000,0.04506578,566.43539730,0.04407983,591.96224904,0.00075331,0.06094887,635.53666239,-0.03167669,-0.02927218,0.00000000,0.00000000,0.00000000,0.00000000
90.60000000,1.38786500,8.69100000,0.04626500,568.85718026,0.04522668,595.17535770,0.00072419,0.06216306,637.64257297,-0.03233454,-0.02982851,0.00000000,0.00000000,0.00000000,0.00000000
92.10000000,1.42398300,8.72000000,0.04752678,570.75533447,0.04643194,597.88149641,0.00082900,0.06332630,640.00065017,-0.03294712,-0.03037917,0.00000000,0.00000000,0.00000000,0.00000000
93.60000000,1.46010200,8.75200000,0.04868544,572.84984946,0.04753742,600.73929898,0.00077890,0.06452110,641.96227261,-0.03358442,-0.03093668,0.00000000,0.00000000,0.00000000,0.00000000
95.10000000,1.49605500,8.78100000,0.04986989,574.74800367,0.04866624,603.41062275,0.00070095,0.06569276,644.12373961,-0.03420796,-0.03148479,0.00000000,0.00000000,0.00000000,0.00000000
96.60000000,1.53247300,8.81200000,0.05112433,576.77706506,0.04986038,606.26440799,0.00077710,0.06690137,646.17256349,-0.03484710,-0.03205428,0.00000000,0.00000000,0.00000000,0.00000000
98.10000000,1.56941800,8.83900000,0.05237489,578.54431208,0.05104941,608.84550615,0.00085307,0.06811827,648.30132205,-0.03551371,-0.03260456,0.00000000,0.00000000,0.00000000,0.00000000
99.60000000,1.60583500,8.86900000,0.05361089,580.50791988,0.05222321,611.62946548,0.00087296,0.06926960,650.25040944,-0.03613364,-0.03313597,0.00000000,0.00000000,0.00000000,0.00000000
101.10000000,1.64261600,8.89300000,0.05478800,582.07880613,0.05333980,613.96973976,0.00072550,0.07046700,652.30396383,-0.03676900,-0.03369800,0.00000000,0.00000000,0.00000000,0.00000000
102.60000000,1.67933100,8.92100000,0.05605700,583.91150674,0.05454216,616.64383408,0.00080125,0.07169073,654.23731418,-0.03743976,-0.03425097,0.00000000,0.00000000,0.00000000,0.00000000
104.10000000,1.71631000,8.94500000,0.05731511,585.48239298,0.05573278,619.03938139,0.00084908,0.07290582,656.23961036,-0.03809488,-0.03481094,0.00000000,0.00000000,0.00000000,0.00000000
105.60000000,1.75388500,8.97200000,0.05852522,587.24964001,0.05687664,621.61855569,0.00082711,0.07411297,658.16966697,-0.03875984,-0.03535313,0.00000000,0.00000000,0.00000000,0.00000000
107.10000000,1.79116200,8.99400000,0.05977211,588.68961906,0.05805390,623.87684038,0.00079131,0.07532539,660.10694960,-0.03935081,-0.03597458,0.00000000,0.00000000,0.00000000,0.00000000
108.60000000,1.82863900,9.02000000,0.06104500,590.39141249,0.05925427,626.43185626,0.00078366,0.07654396,661.83876301,-0.03999074,-0.03655322,0.00000000,0.00000000,0.00000000,0.00000000
110.10000000,1.86618000,9.04100000,0.06228456,591.76593795,0.06042183,628.62381639,0.00078965,0.07777335,663.86583322,-0.04062865,-0.03714470,0.00000000,0.00000000,0.00000000,0.00000000
111.60000000,1.90418600,9.06500000,0.06355367,593.33682419,0.06161582,631.04555494,0.00076801,0.07899919,665.60940653,-0.04127414,-0.03772505,0.00000000,0.00000000,0.00000000,0.00000000
113.10000000,1.94156300,9.08600000,0.06481911,594.71134965,0.06280494,633.26001071,0.00076731,0.08023660,667.43541079,-0.04193653,-0.03830007,0.00000000,0.00000000,0.00000000,0.00000000
114.60000000,1.97920400,9.10800000,0.06606600,596.15132871,0.06397524,635.53666239,0.00078664,0.08146909,669.26164114,-0.04260569,-0.03886340,0.00000000,0.00000000,0.00000000,0.00000000
116.10000000,2.01707700,9.12700000,0.06737189,597.39494698,0.06519945,637.64257297,0.00087545,0.08269356,671.01443714,-0.04326259,-0.03943097,0.00000000,0.00000000,0.00000000,0.00000000
117.60000000,2.05528200,9.15000000,0.06862622,598.90037963,0.06637392,640.00065017,0.00079869,0.08389305,672.75369085,-0.04392669,-0.03996636,0.00000000,0.00000000,0.00000000,0.00000000
119.10000000,2.09338700,9.16700000,0.06991378,600.01309072,0.06757806,641.96227261,0.00085300,0.08513109,674.59399147,-0.04462769,-0.04050340,0.00000000,0.00000000,0.00000000,0.00000000
120.60000000,2.13182300,9.18700000,0.07117911,601.32216259,0.06876001,644.12373961,0.00077624,0.08641193,676.25142443,-0.04535749,-0.04105444,0.00000000,0.00000000,0.00000000,0.00000000
122.10000000,2.17055700,9.20500000,0.07248500,602.50032727,0.06997839,646.17256349,0.00076846,0.08762401,677.93717160,-0.04602047,-0.04160354,0.00000000,0.00000000,0.00000000,0.00000000
123.60000000,2.20872700,9.22400000,0.07380178,603.74394554,0.07120541,648.30132205,0.00084971,0.08883792,679.62728920,-0.04668162,-0.04215630,0.00000000,0.00000000,0.00000000,0.00000000
125.10000000,2.24749400,9.24100000,0.07504878,604.85665663,0.07236604,650.25040944,0.00076662,0.09008764,681.20082908,-0.04732738,-0.04276026,0.00000000,0.00000000,0.00000000,0.00000000
126.60000000,2.28629400,9.25900000,0.07634733,606.03482131,0.07357321,652.30396383,0.00073162,0.09136223,682.86648201,-0.04798593,-0.04337630,0.00000000,0.00000000,0.00000000,0.00000000
128.10000000,2.32516100,9.27500000,0.07767522,607.08207881,0.07480615,654.23731418,0.00079219,0.09258184,684.49753836,-0.04862590,-0.04395594,0.00000000,0.00000000,0.00000000,0.00000000
129.60000000,2.36425800,9.29200000,0.07899578,608.19478989,0.07603077,656.23961036,0.00083902,0.09381652,686.14195412,-0.04923632,-0.04458020,0.00000000,0.00000000,0.00000000,0.00000000
131.10000000,2.40428400,9.30800000,0.08030900,609.24204739,0.07724711,658.16966697,0.00081742,0.09509018,687.67139979,-0.04992181,-0.04516836,0.00000000,0.00000000,0.00000000,0.00000000
132.60000000,2.44348100,9.32400000,0.08162956,610.28930488,0.07846875,660.10694960,0.00080286,0.09632239,689.17499136,-0.05055535,-0.04576704,0.00000000,0.00000000,0.00000000,0.00000000
134.10000000,2.48314200,9.33700000,0.08295733,611.14020160,0.07969557,661.83876301,0.00082220,0.09759928,690.78485885,-0.05126516,-0.04633413,0.00000000,0.00000000,0.00000000,0.00000000
135.60000000,2.52270300,9.35400000,0.08430000,612.25291268,0.08093462,663.86583322,0.00087531,0.09881166,692.28019592,-0.05190332,-0.04690834,0.00000000,0.00000000,0.00000000,0.00000000
137.10000000,2.56276200,9.36700000,0.08563900,613.10380940,0.08216875,665.60940653,0.00086747,0.10015177,693.86708083,-0.05266633,-0.04748544,0.00000000,0.00000000,0.00000000,0.00000000
138.60000000,2.60248800,9.38100000,0.08699267,614.02015971,0.08341486,667.43541079,0.00083939,0.10136156,695.29314609,-0.05329775,-0.04806381,0.00000000,0.00000000,0.00000000,0.00000000
140.10000000,2.64267900,9.39500000,0.08834267,614.93651001,0.08465605,669.26164114,0.00085878,0.10264238,696.77131969,-0.05403497,-0.04860741,0.00000000,0.00000000,0.00000000,0.00000000
141.60000000,2.68310000,9.40800000,0.08968522,615.78740673,0.08588887,671.01443714,0.00090485,0.10389179,698.23015343,-0.05469104,-0.04920075,0.00000000,0.00000000,0.00000000,0.00000000
143.10000000,2.72329000,9.42100000,0.09100211,616.63830344,0.08709664,672.75369085,0.00075541,0.10516942,699.71137640,-0.05536846,-0.04980096,0.00000000,0.00000000,0.00000000,0.00000000
144.60000000,2.76371300,9.43500000,0.09236322,617.55465375,0.08834344,674.59399147,0.00070746,0.10644530,701.19402819,-0.05603440,-0.05041089,0.00000000,0.00000000,0.00000000,0.00000000
146.10000000,2.80383700,9.44600000,0.09377189,618.27464328,0.08963217,676.25142443,0.00086752,0.10770352,702.59350914,-0.05668056,-0.05102296,0.00000000,0.00000000,0.00000000,0.00000000
147.60000000,2.84472200,9.45800000,0.09510722,619.06008640,0.09085228,677.93717160,0.00089367,0.10901215,704.10450520,-0.05737234,-0.05163981,0.00000000,0.00000000,0.00000000,0.00000000
149.10000000,2.88547500,9.47000000,0.09644622,619.84552952,0.09207424,679.62728920,0.00079201,0.11029972,705.52978440,-0.05804525,-0.05225447,0.00000000,0.00000000,0.00000000,0.00000000
150.60000000,2.92652600,9.48000000,0.09782556,620.50006545,0.09333146,681.20082908,0.00077076,0.11162825,706.98664057,-0.05876970,-0.05285856,0.00000000,0.00000000,0.00000000,0.00000000
152.10000000,2.96698200,9.49100000,0.09923444,621.22005498,0.09461398,682.86648201,0.00091054,0.11288674,708.32257561,-0.05942895,-0.05345779,0.00000000,0.00000000,0.00000000,0.00000000
153.60000000,3.00846200,9.50200000,0.10058444,621.94004451,0.09584135,684.49753836,0.00084256,0.11421854,709.71297814,-0.06016793,-0.05405061,0.00000000,0.00000000,0.00000000,0.00000000
155.10000000,3.04931500,9.51300000,0.10195278,622.66003404,0.09708386,686.14195412,0.00074125,0.11548996,711.06275190,-0.06086431,-0.05462564,0.00000000,0.00000000,0.00000000,0.00000000
156.60000000,3.09099500,9.52200000,0.10336522,623.24911638,0.09836480,687.67139979,0.00082029,0.11680863,712.44861259,-0.06157818,-0.05523046,0.00000000,0.00000000,0.00000000,0.00000000
158.10000000,3.13217700,9.53100000,0.10473356,623.83819872,0.09960418,689.17499136,0.00079250,0.11808328,713.80537338,-0.06225302,-0.05583027,0.00000000,0.00000000,0.00000000,0.00000000
159.60000000,3.17356000,9.54100000,0.10615356,624.49273465,0.10088873,690.78485885,0.00090484,0.11941456,715.20508781,-0.06299112,-0.05642344,0.00000000,0.00000000,0.00000000,0.00000000
161.10000000,3.21547100,9.55000000,0.10750333,625.08181699,0.10210823,692.28019592,0.00073071,0.12073840,716.45320720,-0.06369166,-0.05704674,0.00000000,0.00000000,0.00000000,0.00000000
162.60000000,3.25721700,9.55900000,0.10899689,625.67089933,0.10345590,693.86708083,0.00086283,0.12203413,717.75760593,-0.06432950,-0.05770463,0.00000000,0.00000000,0.00000000,0.00000000
164.10000000,3.29906300,9.56700000,0.11034689,626.19452808,0.10467248,695.29314609,0.00079531,0.12340571,719.11892573,-0.06513019,-0.05827552,0.00000000,0.00000000,0.00000000,0.00000000
165.60000000,3.34130500,9.57500000,0.11177778,626.71815683,0.10596034,696.77131969,0.00087367,0.12468840,720.41838302,-0.06578107,-0.05890734,0.00000000,0.00000000,0.00000000,0.00000000
167.10000000,3.38275400,9.58300000,0.11317544,627.24178557,0.10721669,698.23015343,0.00077990,0.12603078,721.68847454,-0.06651704,-0.05951375,0.00000000,0.00000000,0.00000000,0.00000000
168.60000000,3.42499800,9.59100000,0.11460644,627.76541432,0.10850138,699.71137640,0.00084492,0.12736477,723.02945918,-0.06724151,-0.06012326,0.00000000,0.00000000,0.00000000,0.00000000
170.10000000,3.46733900,9.59900000,0.11603733,628.28904307,0.10978432,701.19402819,0.00092950,0.12872933,724.32001257,-0.06799221,-0.06073712,0.00000000,0.00000000,0.00000000,0.00000000
171.60000000,3.51001200,9.60600000,0.11744989,628.74721822,0.11104920,702.59350914,0.00080358,0.13002823,725.48988367,-0.06868936,-0.06133888,0.00000000,0.00000000,0.00000000,0.00000000
173.10000000,3.55278400,9.61400000,0.11892122,629.27084697,0.11236503,704.10450520,0.00082199,0.13137307,726.77023869,-0.06943483,-0.06193824,0.00000000,0.00000000,0.00000000,0.00000000
174.60000000,3.59535800,9.62100000,0.12037044,629.72902212,0.11365938,705.52978440,0.00086677,0.13271617,728.05147325,-0.07016092,-0.06255525,0.00000000,0.00000000,0.00000000,0.00000000
176.10000000,3.63895800,9.62800000,0.12186767,630.18719728,0.11499486,706.98664057,0.00091178,0.13408657,729.27945688,-0.07087487,-0.06321170,0.00000000,0.00000000,0.00000000,0.00000000
177.60000000,3.68149800,9.63400000,0.12328756,630.57991884,0.11625970,708.32257561,0.00079247,0.13539436,730.46355772,-0.07154860,-0.06384576,0.00000000,0.00000000,0.00000000,0.00000000
179.10000000,3.72447000,9.64000000,0.12479200,630.97264040,0.11759813,709.71297814,0.00090269,0.13676423,731.69509892,-0.07227695,-0.06448728,0.00000000,0.00000000,0.00000000,0.00000000
180.60000000,3.76797100,9.64600000,0.12623022,631.36536196,0.11887597,711.06275190,0.00089502,0.13816366,733.02607148,-0.07305453,-0.06510912,0.00000000,0.00000000,0.00000000,0.00000000
182.10000000,3.81117400,9.65200000,0.12772378,631.75808352,0.12020125,712.44861259,0.00088753,0.13946607,734.21208398,-0.07371681,-0.06574926,0.00000000,0.00000000,0.00000000,0.00000000
183.60000000,3.85520500,9.65800000,0.12916944,632.15080508,0.12148236,713.80537338,0.00081473,0.14086241,735.39337901,-0.07450171,-0.06636070,0.00000000,0.00000000,0.00000000,0.00000000
185.10000000,3.89840800,9.66400000,0.13068122,632.54352664,0.12282030,715.20508781,0.00089799,0.14222464,736.62733424,-0.07523543,-0.06698921,0.00000000,0.00000000,0.00000000,0.00000000
186.60000000,3.94257100,9.66800000,0.13218578,632.80534101,0.12415008,716.45320720,0.00093607,0.14358546,737.78615547,-0.07597521,-0.06761025,0.00000000,0.00000000,0.00000000,0.00000000
188.10000000,3.98623800,9.67300000,0.13366078,633.13260898,0.12545202,717.75760593,0.00086955,0.14497565,739.04474994,-0.07672338,-0.06825226,0.00000000,0.00000000,0.00000000,0.00000000
189.60000000,4.03053500,9.67800000,0.13522411,633.45987695,0.12683009,719.11892573,0.00094629,0.14639615,740.17533650,-0.07749544,-0.06890071,0.00000000,0.00000000,0.00000000,0.00000000
191.10000000,4.07486200,9.68300000,0.13668822,633.78714491,0.12811897,720.41838302,0.00086117,0.14778230,741.43492678,-0.07822623,-0.06955607,0.00000000,0.00000000,0.00000000,0.00000000
192.60000000,4.11915800,9.68700000,0.13822200,634.04895929,0.12946740,721.68847454,0.00091157,0.14916733,742.54271933,-0.07895777,-0.07020957,0.00000000,0.00000000,0.00000000,0.00000000
194.10000000,4.16395000,9.69200000,0.13974867,634.37622725,0.13080777,723.02945918,0.00090391,0.15058149,743.75052828,-0.07972983,-0.07085166,0.00000000,0.00000000,0.00000000,0.00000000
195.60000000,4.20831100,9.69600000,0.14131200,634.63804163,0.13217848,724.32001257,0.00090267,0.15199389,744.88223101,-0.08046748,-0.07152641,0.00000000,0.00000000,0.00000000,0.00000000
197.10000000,4.25320300,9.69900000,0.14280178,634.83440241,0.13348295,725.48988367,0.00084994,0.15340448,746.01429211,-0.08119127,-0.07221321,0.00000000,0.00000000,0.00000000,0.00000000
198.60000000,4.29779700,9.70300000,0.14434667,635.09621678,0.13483388,726.77023869,0.00083597,0.15487516,747.27009678,-0.08201110,-0.07286407,0.00000000,0.00000000,0.00000000,0.00000000
200.10000000,4.34278700,9.70700000,0.14589167,635.35803116,0.13618308,728.05147325,0.00092468,0.15634366,748.52635410,-0.08280821,-0.07353546,0.00000000,0.00000000,0.00000000,0.00000000
201.60000000,4.38777800,9.71000000,0.14746978,635.55439194,0.13755933,729.27945688,0.00096196,0.15781072,749.62923086,-0.08364633,-0.07416439,0.00000000,0.00000000,0.00000000,0.00000000
203.10000000,4.43276900,9.71300000,0.14897789,635.75075272,0.13887275,730.46355772,0.00096070,0.15924411,750.78567404,-0.08442445,-0.07481966,0.00000000,0.00000000,0.00000000,0.00000000
204.60000000,4.47845500,9.71600000,0.15055967,635.94711350,0.14024849,731.69509892,0.00089542,0.16070690,751.88866396,-0.08523038,-0.07547652,0.00000000,0.00000000,0.00000000,0.00000000
206.10000000,4.52450400,9.72000000,0.15217822,636.20892787,0.14165426,733.02607148,0.00102209,0.16219821,753.09237332,-0.08603934,-0.07615887,0.00000000,0.00000000,0.00000000,0.00000000
207.60000000,4.57022300,9.72300000,0.15368633,636.40528865,0.14296232,734.21208398,0.00082921,0.00000000,0.00000000,0.00000000,0.00000000,0.00000000,0.00000000,0.00000000,0.00000000
209.10000000,4.61600800,9.72500000,0.15530489,636.53619584,0.14436428,735.39337901,0.00095544,0.00000000,0.00000000,0.00000000,0.00000000,0.00000000,0.00000000,0.00000000,0.00000000
210.60000000,4.66139600,9.72800000,0.15688656,636.73255662,0.14573239,736.62733424,0.00089033,0.00000000,0.00000000,0.00000000,0.00000000,0.00000000,0.00000000,0.00000000,0.00000000
212.10000000,4.70807400,9.73000000,0.15846833,636.86346380,0.14709873,737.78615547,0.00095263,0.00000000,0.00000000,0.00000000,0.00000000,0.00000000,0.00000000,0.00000000,0.00000000
213.60000000,4.75491800,9.73300000,0.16008689,637.05982458,0.14849491,739.04474994,0.00095150,0.00000000,0.00000000,0.00000000,0.00000000,0.00000000,0.00000000,0.00000000,0.00000000
215.10000000,4.80163000,9.73400000,0.16174222,637.12527818,0.14992079,740.17533650,0.00095033,0.00000000,0.00000000,0.00000000,0.00000000,0.00000000,0.00000000,0.00000000,0.00000000
216.60000000,4.84860800,9.73700000,0.16336067,637.32163896,0.15131294,741.43492678,0.00094882,0.00000000,0.00000000,0.00000000,0.00000000,0.00000000,0.00000000,0.00000000,0.00000000
218.10000000,4.89588200,9.73800000,0.16497922,637.38709255,0.15270325,742.54271933,0.00082117,0.00000000,0.00000000,0.00000000,0.00000000,0.00000000,0.00000000,0.00000000,0.00000000
219.60000000,4.94322300,9.74000000,0.16663456,637.51799974,0.15412316,743.75052828,0.00094615,0.00000000,0.00000000,0.00000000,0.00000000,0.00000000,0.00000000,0.00000000,0.00000000
221.10000000,4.99089500,9.74100000,0.16828978,637.58345333,0.15554095,744.88223101,0.00094462,0.00000000,0.00000000,0.00000000,0.00000000,0.00000000,0.00000000,0.00000000,0.00000000
222.60000000,5.03823600,9.74200000,0.16994522,637.64890692,0.15695693,746.01429211,0.00088058,0.00000000,0.00000000,0.00000000,0.00000000,0.00000000,0.00000000,0.00000000,0.00000000
224.10000000,5.08627300,9.74400000,0.17167411,637.77981411,0.15843359,747.27009678,0.00094208,0.00000000,0.00000000,0.00000000,0.00000000,0.00000000,0.00000000,0.00000000,0.00000000
225.60000000,5.13477300,9.74600000,0.17340300,637.91072130,0.15990807,748.52635410,0.00100360,0.00000000,0.00000000,0.00000000,0.00000000,0.00000000,0.00000000,0.00000000,0.00000000
227.10000000,5.18300800,9.74600000,0.17513189,637.91072130,0.16138039,749.62923086,0.00106475,0.00000000,0.00000000,0.00000000,0.00000000,0.00000000,0.00000000,0.00000000,0.00000000
228.60000000,5.23180600,9.74700000,0.17682400,637.97617489,0.16281928,750.78567404,0.00093777,0.00000000,0.00000000,0.00000000,0.00000000,0.00000000,0.00000000,0.00000000,0.00000000
230.10000000,5.28023900,9.74700000,0.17855289,637.97617489,0.16428732,751.88866396,0.00099903,0.00000000,0.00000000,0.00000000,0.00000000,0.00000000,0.00000000,0.00000000,0.00000000
231.60000000,5.32946700,9.74800000,0.18031856,638.04162849,0.16578436,753.09237332,0.00099772,0.00000000,0.00000000,0.00000000,0.00000000,0.00000000,0.00000000,0.00000000,0.00000000
233.10000000,5.37872800,9.74800000,0.18208422,638.04162849,0.00000000,0.00000000,0.00000000,0.00000000,0.00000000,0.00000000,0.00000000,0.00000000,0.00000000,0.00000000,0.00000000
234.60000000,5.42779000,9.74800000,0.18388667,638.04162849,0.00000000,0.00000000,0.00000000,0.00000000,0.00000000,0.00000000,0.00000000,0.00000000,0.00000000,0.00000000,0.00000000
236.10000000,5.47728400,9.74900000,0.18561556,638.10708208,0.00000000,0.00000000,0.00000000,0.00000000,0.00000000,0.00000000,0.00000000,0.00000000,0.00000000,0.00000000,0.00000000
237.60000000,5.52787000,9.74900000,0.18741800,638.10708208,0.00000000,0.00000000,0.00000000,0.00000000,0.00000000,0.00000000,0.00000000,0.00000000,0.00000000,0.00000000,0.00000000
239.10000000,5.57795800,9.74900000,0.18925733,638.10708208,0.00000000,0.00000000,0.00000000,0.00000000,0.00000000,0.00000000,0.00000000,0.00000000,0.00000000,0.00000000,0.00000000
240.60000000,5.62774900,9.74800000,0.19109644,638.04162849,0.00000000,0.00000000,0.00000000,0.00000000,0.00000000,0.00000000,0.00000000,0.00000000,0.00000000,0.00000000,0.00000000
242.10000000,5.67806900,9.74800000,0.19289900,638.04162849,0.00000000,0.00000000,0.00000000,0.00000000,0.00000000,0.00000000,0.00000000,0.00000000,0.00000000,0.00000000,0.00000000
243.60000000,5.72868900,9.74700000,0.19477500,637.97617489,0.00000000,0.00000000,0.00000000,0.00000000,0.00000000,0.00000000,0.00000000,0.00000000,0.00000000,0.00000000,0.00000000
245.10000000,5.77967100,9.74700000,0.19672478,637.97617489,0.00000000,0.00000000,0.00000000,0.00000000,0.00000000,0.00000000,0.00000000,0.00000000,0.00000000,0.00000000,0.00000000
246.60000000,5.83108400,9.74600000,0.19856389,637.91072130,0.00000000,0.00000000,0.00000000,0.00000000,0.00000000,0.00000000,0.00000000,0.00000000,0.00000000,0.00000000,0.00000000
248.10000000,5.88209900,9.74500000,0.20051356,637.84526771,0.00000000,0.00000000,0.00000000,0.00000000,0.00000000,0.00000000,0.00000000,0.00000000,0.00000000,0.00000000,0.00000000
249.60000000,5.93430700,9.74400000,0.20249989,637.77981411,0.00000000,0.00000000,0.00000000,0.00000000,0.00000000,0.00000000,0.00000000,0.00000000,0.00000000,0.00000000,0.00000000
251.10000000,5.98638200,9.74400000,0.20448644,637.77981411,0.00000000,0.00000000,0.00000000,0.00000000,0.00000000,0.00000000,0.00000000,0.00000000,0.00000000,0.00000000,0.00000000
252.60000000,6.03822600,9.74100000,0.20639922,637.58345333,0.00000000,0.00000000,0.00000000,0.00000000,0.00000000,0.00000000,0.00000000,0.00000000,0.00000000,0.00000000,0.00000000
254.10000000,6.09059900,9.74000000,0.20845911,637.51799974,0.00000000,0.00000000,0.00000000,0.00000000,0.00000000,0.00000000,0.00000000,0.00000000,0.00000000,0.00000000,0.00000000
255.60000000,6.14337000,9.73800000,0.21048256,637.38709255,0.00000000,0.00000000,0.00000000,0.00000000,0.00000000,0.00000000,0.00000000,0.00000000,0.00000000,0.00000000,0.00000000
257.10000000,6.19693400,9.73600000,0.21257933,637.25618536,0.00000000,0.00000000,0.00000000,0.00000000,0.00000000,0.00000000,0.00000000,0.00000000,0.00000000,0.00000000,0.00000000
258.60000000,6.25056600,9.73500000,0.21471289,637.19073177,0.00000000,0.00000000,0.00000000,0.00000000,0.00000000,0.00000000,0.00000000,0.00000000,0.00000000,0.00000000,0.00000000
260.10000000,6.30466000,9.73200000,0.21680967,636.99437099,0.00000000,0.00000000,0.00000000,0.00000000,0.00000000,0.00000000,0.00000000,0.00000000,0.00000000,0.00000000,0.00000000
261.60000000,6.35935100,9.72900000,0.21898000,636.79801021,0.00000000,0.00000000,0.00000000,0.00000000,0.00000000,0.00000000,0.00000000,0.00000000,0.00000000,0.00000000,0.00000000
263.10000000,6.41404200,9.72600000,0.22122411,636.60164943,0.00000000,0.00000000,0.00000000,0.00000000,0.00000000,0.00000000,0.00000000,0.00000000,0.00000000,0.00000000,0.00000000
264.60000000,6.46903000,9.72300000,0.22339444,636.40528865,0.00000000,0.00000000,0.00000000,0.00000000,0.00000000,0.00000000,0.00000000,0.00000000,0.00000000,0.00000000,0.00000000
266.10000000,6.52395100,9.71800000,0.22567533,636.07802068,0.00000000,0.00000000,0.00000000,0.00000000,0.00000000,0.00000000,0.00000000,0.00000000,0.00000000,0.00000000,0.00000000
267.60000000,6.57963500,9.71500000,0.22795600,635.88165990,0.00000000,0.00000000,0.00000000,0.00000000,0.00000000,0.00000000,0.00000000,0.00000000,0.00000000,0.00000000,0.00000000
269.10000000,6.63588200,9.71100000,0.23027356,635.61984553,0.00000000,0.00000000,0.00000000,0.00000000,0.00000000,0.00000000,0.00000000,0.00000000,0.00000000,0.00000000,0.00000000
270.60000000,6.69206100,9.70600000,0.23259133,635.29257756,0.00000000,0.00000000,0.00000000,0.00000000,0.00000000,0.00000000,0.00000000,0.00000000,0.00000000,0.00000000,0.00000000
272.10000000,6.74897000,9.70000000,0.23498256,634.89985600,0.00000000,0.00000000,0.00000000,0.00000000,0.00000000,0.00000000,0.00000000,0.00000000,0.00000000,0.00000000,0.00000000
273.60000000,6.80611000,9.69400000,0.23737367,634.50713444,0.00000000,0.00000000,0.00000000,0.00000000,0.00000000,0.00000000,0.00000000,0.00000000,0.00000000,0.00000000,0.00000000
275.10000000,6.86335000,9.68800000,0.23976511,634.11441288,0.00000000,0.00000000,0.00000000,0.00000000,0.00000000,0.00000000,0.00000000,0.00000000,0.00000000,0.00000000,0.00000000
276.60000000,6.92178100,9.68100000,0.24223000,633.65623773,0.00000000,0.00000000,0.00000000,0.00000000,0.00000000,0.00000000,0.00000000,0.00000000,0.00000000,0.00000000,0.00000000
278.10000000,6.97968200,9.67200000,0.24462144,633.06715539,0.00000000,0.00000000,0.00000000,0.00000000,0.00000000,0.00000000,0.00000000,0.00000000,0.00000000,0.00000000,0.00000000
279.60000000,7.03821200,9.66400000,0.24704944,632.54352664,0.00000000,0.00000000,0.00000000,0.00000000,0.00000000,0.00000000,0.00000000,0.00000000,0.00000000,0.00000000,0.00000000
281.10000000,7.09717300,9.65300000,0.24951444,631.82353711,0.00000000,0.00000000,0.00000000,0.00000000,0.00000000,0.00000000,0.00000000,0.00000000,0.00000000,0.00000000,0.00000000
282.60000000,7.15719300,9.64300000,0.25194278,631.16900118,0.00000000,0.00000000,0.00000000,0.00000000,0.00000000,0.00000000,0.00000000,0.00000000,0.00000000,0.00000000,0.00000000
284.10000000,7.21681600,9.63100000,0.25433433,630.38355806,0.00000000,0.00000000,0.00000000,0.00000000,0.00000000,0.00000000,0.00000000,0.00000000,0.00000000,0.00000000,0.00000000
285.60000000,7.27604100,9.61600000,0.25668933,629.40175416,0.00000000,0.00000000,0.00000000,0.00000000,0.00000000,0.00000000,0.00000000,0.00000000,0.00000000,0.00000000,0.00000000
287.10000000,7.33609300,9.60100000,0.25904433,628.41995026,0.00000000,0.00000000,0.00000000,0.00000000,0.00000000,0.00000000,0.00000000,0.00000000,0.00000000,0.00000000,0.00000000
288.60000000,7.39657700,9.58400000,0.26128900,627.30723917,0.00000000,0.00000000,0.00000000,0.00000000,0.00000000,0.00000000,0.00000000,0.00000000,0.00000000,0.00000000,0.00000000
290.10000000,7.45785400,9.56700000,0.26353422,626.19452808,0.00000000,0.00000000,0.00000000,0.00000000,0.00000000,0.00000000,0.00000000,0.00000000,0.00000000,0.00000000,0.00000000
291.60000000,7.51850200,9.54700000,0.26570578,624.88545621,0.00000000,0.00000000,0.00000000,0.00000000,0.00000000,0.00000000,0.00000000,0.00000000,0.00000000,0.00000000,0.00000000
293.10000000,7.57924800,9.52600000,0.26784078,623.51093075,0.00000000,0.00000000,0.00000000,0.00000000,0.00000000,0.00000000,0.00000000,0.00000000,0.00000000,0.00000000,0.00000000
294.60000000,7.64045800,9.50100000,0.26986556,621.87459092,0.00000000,0.00000000,0.00000000,0.00000000,0.00000000,0.00000000,0.00000000,0.00000000,0.00000000,0.00000000,0.00000000
296.10000000,7.70193200,9.47600000,0.27181744,620.23825108,0.00000000,0.00000000,0.00000000,0.00000000,0.00000000,0.00000000,0.00000000,0.00000000,0.00000000,0.00000000,0.00000000
297.60000000,7.76357000,9.44700000,0.27369578,618.34009687,0.00000000,0.00000000,0.00000000,0.00000000,0.00000000,0.00000000,0.00000000,0.00000000,0.00000000,0.00000000,0.00000000
299.10000000,7.82517400,9.41700000,0.27546456,616.37648907,0.00000000,0.00000000,0.00000000,0.00000000,0.00000000,0.00000000,0.00000000,0.00000000,0.00000000,0.00000000,0.00000000
300.60000000,7.88743900,9.38600000,0.27712267,614.34742767,0.00000000,0.00000000,0.00000000,0.00000000,0.00000000,0.00000000,0.00000000,0.00000000,0.00000000,0.00000000,0.00000000
302.10000000,7.95039800,9.35100000,0.27870778,612.05655190,0.00000000,0.00000000,0.00000000,0.00000000,0.00000000,0.00000000,0.00000000,0.00000000,0.00000000,0.00000000,0.00000000
303.60000000,8.01272600,9.30900000,0.28021967,609.30750098,0.00000000,0.00000000,0.00000000,0.00000000,0.00000000,0.00000000,0.00000000,0.00000000,0.00000000,0.00000000,0.00000000
305.10000000,8.07568100,9.26700000,0.28162156,606.55845006,0.00000000,0.00000000,0.00000000,0.00000000,0.00000000,0.00000000,0.00000000,0.00000000,0.00000000,0.00000000,0.00000000
306.60000000,8.13883200,9.21700000,0.28283967,603.28577039,0.00000000,0.00000000,0.00000000,0.00000000,0.00000000,0.00000000,0.00000000,0.00000000,0.00000000,0.00000000,0.00000000
308.10000000,8.20241100,9.16600000,0.28387500,599.94763713,0.00000000,0.00000000,0.00000000,0.00000000,0.00000000,0.00000000,0.00000000,0.00000000,0.00000000,0.00000000,0.00000000
309.60000000,8.26625400,9.10900000,0.28487300,596.21678230,0.00000000,0.00000000,0.00000000,0.00000000,0.00000000,0.00000000,0.00000000,0.00000000,0.00000000,0.00000000,0.00000000
311.10000000,8.33016200,9.04600000,0.28565067,592.09320592,0.00000000,0.00000000,0.00000000,0.00000000,0.00000000,0.00000000,0.00000000,0.00000000,0.00000000,0.00000000,0.00000000
312.60000000,8.39582000,8.96900000,0.28635478,587.05327923,0.00000000,0.00000000,0.00000000,0.00000000,0.00000000,0.00000000,0.00000000,0.00000000,0.00000000,0.00000000,0.00000000
314.10000000,8.46230700,8.88600000,0.28687522,581.62063097,0.00000000,0.00000000,0.00000000,0.00000000,0.00000000,0.00000000,0.00000000,0.00000000,0.00000000,0.00000000,0.00000000
315.60000000,8.52949000,8.78200000,0.28710100,574.81345726,0.00000000,0.00000000,0.00000000,0.00000000,0.00000000,0.00000000,0.00000000,0.00000000,0.00000000,0.00000000,0.00000000
317.10000000,8.59797000,8.66600000,0.28732767,567.22084042,0.00000000,0.00000000,0.00000000,0.00000000,0.00000000,0.00000000,0.00000000,0.00000000,0.00000000,0.00000000,0.00000000
318.60000000,8.66894200,8.52800000,0.28733422,558.18824453,0.00000000,0.00000000,0.00000000,0.00000000,0.00000000,0.00000000,0.00000000,0.00000000,0.00000000,0.00000000,0.00000000
320.10000000,8.74873500,8.35600000,0.28715700,546.93022647,0.00000000,0.00000000,0.00000000,0.00000000,0.00000000,0.00000000,0.00000000,0.00000000,0.00000000,0.00000000,0.00000000
321.60000000,8.83766000,8.09600000,0.28705822,529.91229218,0.00000000,0.00000000,0.00000000,0.00000000,0.00000000,0.00000000,0.00000000,0.00000000,0.00000000,0.00000000,0.00000000
322.10000000,8.87072000,8.00200000,0.28698856,523.75965441,0.00000000,0.00000000,0.00000000,0.00000000,0.00000000,0.00000000,0.00000000,0.00000000,0.00000000,0.00000000,0.00000000