File: LAB_DATA/DP600_results/DATA/UT_75_2.csv
Time[s],Displacement[mm],Force[kN],EngStrain_longi,EngStress[MPa],TrueStrain,TrueStress[MPa],TrueStrainRate[1/s],PlasticStrain_longi,PlasticStress[MPa],PlasticStrain_thick,PlasticStrain_width,R-Value,Thickness[mm],Width[mm], Young's Modulus [MPa]
0.64000000,0.00000000,-0.01400000,0.00000000,-0.91569102,0.00000000,-0.91569102,0.00000000,0.00050029,340.18022674,0.00053100,-0.00103129,1.01430274,1.52890000,10.00000000,245766.35515329
2.14000000,0.00126500,-0.00000000,0.00004944,-0.00000000,0.00004944,-0.00000000,0.00001022,0.00083742,354.67868180,0.00037081,-0.00120823,0.00000000,0.00000000,0.00000000,0.00000000
3.64000000,0.00292600,0.42600000,0.00009644,27.86316960,0.00009644,27.86585685,0.00000044,0.00131285,371.01457944,0.00000328,-0.00131613,0.00000000,0.00000000,0.00000000,0.00000000
5.14000000,0.00539400,0.73400000,0.00017389,48.00837203,0.00017387,48.01672015,0.00007799,0.00197780,382.70610201,-0.00033313,-0.00164468,0.00000000,0.00000000,0.00000000,0.00000000
6.64000000,0.00778500,1.08700000,0.00024500,71.09686703,0.00024497,71.11428576,0.00009509,0.00265057,394.87819645,-0.00051526,-0.00213531,0.00000000,0.00000000,0.00000000,0.00000000
8.14000000,0.00948700,1.42000000,0.00030978,92.87723200,0.00030973,92.90600330,0.00007131,0.00333640,405.03097914,-0.00076929,-0.00256710,0.00000000,0.00000000,0.00000000,0.00000000
9.64000000,0.01119000,1.78200000,0.00034767,116.55438551,0.00034761,116.59490758,0.00005109,0.00408193,414.89366080,-0.00112055,-0.00296138,0.00000000,0.00000000,0.00000000,0.00000000
11.14000000,0.01354100,2.09300000,0.00043611,136.89580744,0.00043602,136.95550923,-0.00008152,0.00498679,422.72759313,-0.00165339,-0.00333340,0.00000000,0.00000000,0.00000000,0.00000000
12.64000000,0.01653300,2.45100000,0.00052100,160.31133495,0.00052086,160.39485715,-0.00007285,0.00586027,431.68546920,-0.00207496,-0.00378531,0.00000000,0.00000000,0.00000000,0.00000000
14.14000000,0.01995200,2.78100000,0.00064222,181.89548041,0.00064202,182.01229773,0.00001688,0.00670310,438.46385462,-0.00238706,-0.00431604,0.00000000,0.00000000,0.00000000,0.00000000
15.64000000,0.02319900,3.13700000,0.00077978,205.18019491,0.00077947,205.34018987,0.00021429,0.00756812,446.52120198,-0.00272155,-0.00484657,0.00000000,0.00000000,0.00000000,0.00000000
17.14000000,0.02597700,3.46100000,0.00087744,226.37190137,0.00087706,226.57053013,0.00030353,0.00852466,452.77942063,-0.00316002,-0.00536465,0.00000000,0.00000000,0.00000000,0.00000000
18.64000000,0.02914700,3.78000000,0.00092733,247.23657532,0.00092690,247.46584603,0.00022469,0.00952415,459.73255921,-0.00373708,-0.00578707,0.00000000,0.00000000,0.00000000,0.00000000
20.14000000,0.03337500,4.09500000,0.00101222,267.83962326,0.00101171,268.11073648,0.00006527,0.01044818,465.53572925,-0.00424413,-0.00620404,0.00000000,0.00000000,0.00000000,0.00000000
21.64000000,0.03946700,4.42700000,0.00116611,289.55458173,0.00116543,289.89223454,-0.00012452,0.01135495,472.47108146,-0.00470078,-0.00665417,0.00000000,0.00000000,0.00000000,0.00000000
23.14000000,0.04716400,4.72000000,0.00145244,308.71868664,0.00145139,309.16708338,-0.00016930,0.01234780,477.93045530,-0.00518218,-0.00716563,0.00000000,0.00000000,0.00000000,0.00000000
24.64000000,0.05612600,5.01400000,0.00188500,327.94819805,0.00188323,328.56638040,0.00011667,0.01335283,484.40527391,-0.00562292,-0.00772991,0.00000000,0.00000000,0.00000000,0.00000000
26.14000000,0.06905000,5.26600000,0.00232044,344.43063641,0.00231776,345.22986856,0.00039512,0.01432064,489.40818224,-0.00607580,-0.00824484,0.00000000,0.00000000,0.00000000,0.00000000
27.64000000,0.08528900,5.51100000,0.00282356,360.45522925,0.00281958,361.47299461,0.00058643,0.01525887,495.07316825,-0.00650708,-0.00875179,0.00000000,0.00000000,0.00000000,0.00000000
29.14000000,0.10224800,5.70100000,0.00336333,372.88246452,0.00335769,374.13659254,0.00055621,0.01625802,499.91089193,-0.00703980,-0.00921823,0.00000000,0.00000000,0.00000000,0.00000000
30.64000000,0.12318300,5.89600000,0.00403867,385.63673229,0.00403053,387.19419051,0.00046064,0.01731314,505.58877183,-0.00760083,-0.00971232,0.00000000,0.00000000,0.00000000,0.00000000
32.14000000,0.14555100,6.05800000,0.00485333,396.23258552,0.00484159,398.15563433,0.00062130,0.01832609,510.11877538,-0.00816924,-0.01015685,0.00000000,0.00000000,0.00000000,0.00000000
33.64000000,0.17090600,6.21300000,0.00569044,406.37059324,0.00567432,408.68302252,0.00081840,0.01930157,515.44242011,-0.00860312,-0.01069845,0.00000000,0.00000000,0.00000000,0.00000000
35.14000000,0.19679200,6.34300000,0.00649511,414.87343842,0.00647411,417.56808750,0.00083299,0.02033537,519.66629700,-0.00908457,-0.01125081,0.00000000,0.00000000,0.00000000,0.00000000
36.64000000,0.22311200,6.47200000,0.00732222,423.31087710,0.00729554,426.41045341,0.00059153,0.02136180,524.43188135,-0.00955392,-0.01180788,0.00000000,0.00000000,0.00000000,0.00000000
38.14000000,0.25116200,6.57200000,0.00827444,429.85152724,0.00824040,433.40830982,0.00064896,0.02242681,528.42065595,-0.01010433,-0.01232247,0.00000000,0.00000000,0.00000000,0.00000000
39.64000000,0.27990900,6.68400000,0.00927822,437.17705540,0.00923544,441.23328127,0.00088884,0.02343656,533.19557234,-0.01057061,-0.01286595,0.00000000,0.00000000,0.00000000,0.00000000
41.14000000,0.30740400,6.78300000,0.01019022,443.65229904,0.01013865,448.17321456,0.00088848,0.02452152,537.00976489,-0.01115121,-0.01337031,0.00000000,0.00000000,0.00000000,0.00000000
42.64000000,0.33758100,6.88500000,0.01110200,450.32376218,0.01104083,455.32325659,0.00072014,0.02556970,541.55372999,-0.01168962,-0.01388008,0.00000000,0.00000000,0.00000000,0.00000000
44.14000000,0.36640200,6.97500000,0.01208000,456.21034731,0.01200762,461.72136830,0.00058853,0.02663906,545.17310921,-0.01224773,-0.01439134,0.00000000,0.00000000,0.00000000,0.00000000
45.64000000,0.39621400,7.06800000,0.01312422,462.29315194,0.01303885,468.36039000,0.00074766,0.02771958,549.14386618,-0.01281385,-0.01490574,0.00000000,0.00000000,0.00000000,0.00000000
47.14000000,0.42619300,7.14500000,0.01409867,467.32945255,0.01400020,473.91817472,0.00079079,0.02879746,552.71521626,-0.01332408,-0.01547338,0.00000000,0.00000000,0.00000000,0.00000000
48.64000000,0.45713200,7.23100000,0.01503267,472.95441167,0.01492080,480.06417769,0.00059427,0.02986864,556.69650215,-0.01383691,-0.01603172,0.00000000,0.00000000,0.00000000,0.00000000
50.14000000,0.48714700,7.30800000,0.01601456,477.99071228,0.01588768,485.64552109,0.00045630,0.03098403,560.10026032,-0.01440469,-0.01657934,0.00000000,0.00000000,0.00000000,0.00000000
51.64000000,0.51855500,7.38800000,0.01708844,483.22323239,0.01694408,491.48076575,0.00058585,0.03207477,563.90451746,-0.01494378,-0.01713099,0.00000000,0.00000000,0.00000000,0.00000000
53.14000000,0.54956400,7.45900000,0.01811456,487.86709399,0.01795244,496.70458957,0.00067216,0.03320618,567.12786277,-0.01552817,-0.01767801,0.00000000,0.00000000,0.00000000,0.00000000
54.64000000,0.58113900,7.53400000,0.01912967,492.77258159,0.01894900,502.19915682,0.00062089,0.03426297,570.85965141,-0.01606317,-0.01819980,0.00000000,0.00000000,0.00000000,0.00000000
56.14000000,0.61357200,7.59400000,0.02017400,496.69697168,0.01997320,506.71733639,0.00050499,0.03536042,574.00906377,-0.01663420,-0.01872622,0.00000000,0.00000000,0.00000000,0.00000000
57.64000000,0.64464900,7.66300000,0.02125889,501.21002028,0.02103607,511.86518841,0.00056170,0.03648922,576.97830902,-0.01723389,-0.01925533,0.00000000,0.00000000,0.00000000,0.00000000
59.14000000,0.67738100,7.72500000,0.02236222,505.26522336,0.02211585,516.56407657,0.00071960,0.03757644,580.27086692,-0.01773864,-0.01983780,0.00000000,0.00000000,0.00000000,0.00000000
60.64000000,0.70988100,7.78900000,0.02339578,509.45123945,0.02312629,521.37024744,0.00063263,0.03867851,583.10014254,-0.01826143,-0.02041708,0.00000000,0.00000000,0.00000000,0.00000000
62.14000000,0.74251600,7.84600000,0.02450278,513.17941003,0.02420740,525.75373108,0.00069661,0.03982259,586.50726809,-0.01880525,-0.02101734,0.00000000,0.00000000,0.00000000,0.00000000
63.64000000,0.77577800,7.90500000,0.02559867,517.03839362,0.02527651,530.27388711,0.00066682,0.04095421,589.29745359,-0.01933753,-0.02161668,0.00000000,0.00000000,0.00000000,0.00000000
65.14000000,0.80887600,7.95500000,0.02669844,520.30871869,0.02634826,534.20015211,0.00074535,0.04206497,592.49250108,-0.01985984,-0.02220513,0.00000000,0.00000000,0.00000000,0.00000000
66.64000000,0.84267100,8.01100000,0.02783856,523.97148277,0.02745811,538.55809200,0.00075880,0.04322244,595.17244838,-0.02042015,-0.02280228,0.00000000,0.00000000,0.00000000,0.00000000
68.14000000,0.87623300,8.06100000,0.02892000,527.24180784,0.02850971,542.48964092,0.00072235,0.04437382,598.12929077,-0.02099252,-0.02338130,0.00000000,0.00000000,0.00000000,0.00000000
69.64000000,0.91016000,8.11300000,0.03004911,530.64294591,0.02960648,546.58829475,0.00074271,0.04550848,600.66908126,-0.02153287,-0.02397561,0.00000000,0.00000000,0.00000000,0.00000000
71.14000000,0.94395500,8.15900000,0.03117089,533.65164497,0.03069494,550.28604110,0.00072078,0.04663962,603.62535206,-0.02213388,-0.02450574,0.00000000,0.00000000,0.00000000,0.00000000
72.64000000,0.97854400,8.20900000,0.03232211,536.92197004,0.03181074,554.27642162,0.00076261,0.04784807,606.22059396,-0.02277410,-0.02507397,0.00000000,0.00000000,0.00000000,0.00000000
74.14000000,1.01273600,8.24900000,0.03345867,539.53823010,0.03291111,557.59045989,0.00078307,0.04899783,609.13091328,-0.02335587,-0.02564195,0.00000000,0.00000000,0.00000000,0.00000000
75.64000000,1.04726000,8.29600000,0.03459144,542.61233567,0.03400661,561.38208013,0.00071087,0.05016964,611.50735173,-0.02394514,-0.02622450,0.00000000,0.00000000,0.00000000,0.00000000
77.14000000,1.08211400,8.33700000,0.03573533,545.29400222,0.03511164,564.78026516,0.00070322,0.05127964,614.12752960,-0.02445855,-0.02682109,0.00000000,0.00000000,0.00000000,0.00000000
78.64000000,1.11693400,8.38400000,0.03689389,548.36810779,0.03622960,568.59953983,0.00064562,0.05246285,616.45144816,-0.02505513,-0.02740772,0.00000000,0.00000000,0.00000000,0.00000000
80.14000000,1.15208800,8.41900000,0.03805622,550.65733534,0.03734995,571.61327326,0.00073720,0.05363607,619.12094527,-0.02564105,-0.02799501,0.00000000,0.00000000,0.00000000,0.00000000
81.64000000,1.18681100,8.45700000,0.03918533,553.14278239,0.03843707,574.81786670,0.00068655,0.05480649,621.37717361,-0.02620597,-0.02860052,0.00000000,0.00000000,0.00000000,0.00000000
83.14000000,1.22216300,8.49600000,0.04037711,555.69363595,0.03958325,578.13093963,0.00069303,0.05595641,623.97297460,-0.02676847,-0.02918794,0.00000000,0.00000000,0.00000000,0.00000000
84.64000000,1.25768000,8.53300000,0.04158344,558.11367650,0.04074210,581.32196556,0.00080492,0.05715190,626.18462151,-0.02738115,-0.02977075,0.00000000,0.00000000,0.00000000,0.00000000
86.14000000,1.29346200,8.57000000,0.04273844,560.53371705,0.04185037,584.49005618,0.00079038,0.05833461,628.60191345,-0.02798111,-0.03035350,0.00000000,0.00000000,0.00000000,0.00000000
87.64000000,1.32970800,8.60100000,0.04394856,562.56131860,0.04301021,587.28507596,0.00078947,0.05950027,630.66413045,-0.02853197,-0.03096830,0.00000000,0.00000000,0.00000000,0.00000000
89.14000000,1.36575300,8.63600000,0.04515489,564.85054614,0.04416509,590.35630979,0.00080940,0.06070081,633.10208099,-0.02913198,-0.03156883,0.00000000,0.00000000,0.00000000,0.00000000
90.64000000,1.40220000,8.66900000,0.04637611,567.00896069,0.04533287,593.30463125,0.00089302,0.06188429,635.18413570,-0.02969120,-0.03219309,0.00000000,0.00000000,0.00000000,0.00000000
92.14000000,1.43841200,8.70200000,0.04754200,569.16737524,0.04644647,596.22673059,0.00077975,0.06310948,637.57730365,-0.03031011,-0.03279937,0.00000000,0.00000000,0.00000000,0.00000000
93.64000000,1.47495400,8.73200000,0.04875211,571.12957028,0.04760099,598.97334255,0.00075787,0.06429378,639.59830695,-0.03089816,-0.03339562,0.00000000,0.00000000,0.00000000,0.00000000
95.14000000,1.51126800,8.76300000,0.05000267,573.15717182,0.04879270,601.81655883,0.00084780,0.06546574,641.75581595,-0.03148451,-0.03398123,0.00000000,0.00000000,0.00000000,0.00000000
96.64000000,1.54844000,8.79000000,0.05120167,574.92314736,0.04993395,604.36017071,0.00083985,0.06668149,643.80513310,-0.03210816,-0.03457333,0.00000000,0.00000000,0.00000000,0.00000000
98.14000000,1.58554700,8.82100000,0.05240822,576.95074890,0.05108108,607.18771196,0.00069250,0.06791570,645.94092957,-0.03271826,-0.03519745,0.00000000,0.00000000,0.00000000,0.00000000
99.64000000,1.62275400,8.84700000,0.05365500,578.65131794,0.05226507,609.69885441,0.00073324,0.06908805,647.82928006,-0.03324395,-0.03584410,0.00000000,0.00000000,0.00000000,0.00000000
101.14000000,1.65982700,8.87500000,0.05490556,580.48269998,0.05345124,612.35442511,0.00073933,0.07029205,649.95365282,-0.03386777,-0.03642428,0.00000000,0.00000000,0.00000000,0.00000000
102.64000000,1.69723100,8.90100000,0.05612667,582.18326902,0.05460813,614.85927530,0.00080815,0.07152621,651.88988634,-0.03447139,-0.03705482,0.00000000,0.00000000,0.00000000,0.00000000
104.14000000,1.73463700,8.92800000,0.05736989,583.94924455,0.05578459,617.45034783,0.00077251,0.07275170,653.89503942,-0.03507921,-0.03767249,0.00000000,0.00000000,0.00000000,0.00000000
105.64000000,1.77250600,8.95100000,0.05864989,585.45359409,0.05699441,619.79038233,0.00082029,0.07395219,655.81685342,-0.03567944,-0.03827276,0.00000000,0.00000000,0.00000000,0.00000000
107.14000000,1.81014300,8.97600000,0.05989311,587.08875662,0.05816806,622.25132875,0.00080527,0.07520178,657.84572350,-0.03634277,-0.03885901,0.00000000,0.00000000,0.00000000,0.00000000
108.64000000,1.84787900,8.99900000,0.06114000,588.59310615,0.05934380,624.57968867,0.00083219,0.07646462,659.60325366,-0.03698113,-0.03948349,0.00000000,0.00000000,0.00000000,0.00000000
110.14000000,1.88607900,9.02300000,0.06239778,590.16286219,0.06052841,626.98771332,0.00078936,0.07764697,661.52420972,-0.03755992,-0.04008705,0.00000000,0.00000000,0.00000000,0.00000000
111.64000000,1.92408000,9.04500000,0.06366311,591.60180522,0.06171872,629.26501668,0.00078152,0.07889959,663.35313580,-0.03819307,-0.04070652,0.00000000,0.00000000,0.00000000,0.00000000
113.14000000,1.96208200,9.06800000,0.06495422,593.10615475,0.06293181,631.63090373,0.00085677,0.08017089,665.19810001,-0.03885972,-0.04131117,0.00000000,0.00000000,0.00000000,0.00000000
114.64000000,2.00048000,9.08700000,0.06621578,594.34887828,0.06411572,633.70415153,0.00080029,0.08138314,667.00720073,-0.03942990,-0.04195324,0.00000000,0.00000000,0.00000000,0.00000000
116.14000000,2.03878000,9.11000000,0.06747378,595.85322781,0.06529490,636.05769609,0.00077186,0.08261076,668.83005505,-0.04004360,-0.04256716,0.00000000,0.00000000,0.00000000,0.00000000
117.64000000,2.07751000,9.12800000,0.06877589,597.03054484,0.06651396,638.09185125,0.00073680,0.08388497,670.47299706,-0.04067864,-0.04320633,0.00000000,0.00000000,0.00000000,0.00000000
119.14000000,2.11640500,9.14900000,0.07008533,598.40408137,0.06773840,640.34343088,0.00079781,0.08512954,672.31410578,-0.04129274,-0.04383680,0.00000000,0.00000000,0.00000000,0.00000000
120.64000000,2.15520200,9.16600000,0.07136900,599.51599189,0.06893727,642.30284871,0.00083109,0.08636696,673.93866117,-0.04193399,-0.04443298,0.00000000,0.00000000,0.00000000,0.00000000
122.14000000,2.19393100,9.18700000,0.07267111,600.88952842,0.07015190,644.55683810,0.00080936,0.08758237,675.62315767,-0.04250570,-0.04507667,0.00000000,0.00000000,0.00000000,0.00000000
123.64000000,2.23332400,9.20300000,0.07400267,601.93603244,0.07139248,646.48090401,0.00080173,0.08887980,677.36652157,-0.04317226,-0.04570754,0.00000000,0.00000000,0.00000000,0.00000000
125.14000000,2.27238500,9.22300000,0.07532678,603.24416247,0.07262459,648.68460144,0.00090329,0.09013890,679.08718330,-0.04381730,-0.04632160,0.00000000,0.00000000,0.00000000,0.00000000
126.64000000,2.31181100,9.23900000,0.07662522,604.29066649,0.07383135,650.59457310,0.00088857,0.09134059,680.55553188,-0.04433751,-0.04700307,0.00000000,0.00000000,0.00000000,0.00000000
128.14000000,2.35136800,9.25500000,0.07792733,605.33717051,0.07504006,652.50948198,0.00081923,0.09261314,682.29160215,-0.04497948,-0.04763366,0.00000000,0.00000000,0.00000000,0.00000000
129.64000000,2.39086000,9.27100000,0.07928467,606.38367454,0.07629848,654.46060205,0.00086599,0.09390166,683.82502286,-0.04564407,-0.04825759,0.00000000,0.00000000,0.00000000,0.00000000
131.14000000,2.43094800,9.28900000,0.08060511,607.56099156,0.07752117,656.53351279,0.00089209,0.09514099,685.54468215,-0.04623844,-0.04890254,0.00000000,0.00000000,0.00000000,0.00000000
132.64000000,2.47083600,9.30200000,0.08191822,608.41127608,0.07873560,658.25124620,0.00080244,0.09643656,687.01635849,-0.04691225,-0.04952432,0.00000000,0.00000000,0.00000000,0.00000000
134.14000000,2.51102400,9.31900000,0.08326822,609.52318660,0.07998260,660.27709876,0.00075403,0.09772314,688.62969180,-0.04758611,-0.05013704,0.00000000,0.00000000,0.00000000,0.00000000
135.64000000,2.55117700,9.33300000,0.08465856,610.43887762,0.08126524,662.11775126,0.00093630,0.09898519,690.15638428,-0.04820650,-0.05077870,0.00000000,0.00000000,0.00000000,0.00000000
137.14000000,2.59139700,9.34800000,0.08597167,611.41997515,0.08247513,663.98476944,0.00083343,0.10028856,691.71452769,-0.04887439,-0.05141417,0.00000000,0.00000000,0.00000000,0.00000000
138.64000000,2.63224600,9.36000000,0.08731778,612.20485316,0.08371391,665.66122049,0.00075082,0.10155390,693.24913458,-0.04946891,-0.05208499,0.00000000,0.00000000,0.00000000,0.00000000
140.14000000,2.67276500,9.37500000,0.08870456,613.18595068,0.08498851,667.57833791,0.00085829,0.10282160,694.64223583,-0.05007603,-0.05274557,0.00000000,0.00000000,0.00000000,0.00000000
141.64000000,2.71368100,9.38700000,0.09006911,613.97082870,0.08624110,669.27063549,0.00089087,0.10411333,696.20068982,-0.05072869,-0.05338465,0.00000000,0.00000000,0.00000000,0.00000000
143.14000000,2.75479500,9.40200000,0.09140433,614.95192622,0.08746525,671.16119707,0.00077509,0.10539061,697.67874826,-0.05135239,-0.05403822,0.00000000,0.00000000,0.00000000,0.00000000
144.64000000,2.79594300,9.41300000,0.09279844,615.67139774,0.08874179,672.80474574,0.00082151,0.10668622,699.09907050,-0.05200261,-0.05468361,0.00000000,0.00000000,0.00000000,0.00000000
146.14000000,2.83665900,9.42500000,0.09418511,616.45627575,0.09000990,674.51727858,0.00086740,0.10800312,700.53687871,-0.05264985,-0.05535326,0.00000000,0.00000000,0.00000000,0.00000000
147.64000000,2.87803800,9.43600000,0.09552033,617.17574727,0.09122944,676.12858037,0.00085964,0.10930475,702.03997798,-0.05328230,-0.05602245,0.00000000,0.00000000,0.00000000,0.00000000
149.14000000,2.91931900,9.44900000,0.09689233,618.02603179,0.09248103,677.90801607,0.00075135,0.11061781,703.55388628,-0.05393574,-0.05668206,0.00000000,0.00000000,0.00000000,0.00000000
150.64000000,2.96132700,9.45900000,0.09830478,618.68009680,0.09376788,679.49930623,0.00079047,0.11191353,704.91102797,-0.05455658,-0.05735695,0.00000000,0.00000000,0.00000000,0.00000000
152.14000000,3.00283800,9.47100000,0.09970611,619.46497482,0.09504297,681.22941843,0.00092329,0.11322707,706.28314409,-0.05523464,-0.05799243,0.00000000,0.00000000,0.00000000,0.00000000
153.64000000,3.04464800,9.48100000,0.10110022,620.11903983,0.09630988,682.81321256,0.00089547,0.11455845,707.67033042,-0.05593299,-0.05862547,0.00000000,0.00000000,0.00000000,0.00000000
155.14000000,3.08652300,9.49200000,0.10253100,620.83851135,0.09760845,684.49370476,0.00090096,0.11587496,709.04939729,-0.05660165,-0.05927331,0.00000000,0.00000000,0.00000000,0.00000000
156.64000000,3.12899600,9.50100000,0.10392144,621.42716986,0.09886879,686.00677897,0.00092661,0.11720926,710.44355747,-0.05727045,-0.05993881,0.00000000,0.00000000,0.00000000,0.00000000
158.14000000,3.17064000,9.51100000,0.10528600,622.08123487,0.10010413,687.57767977,0.00079211,0.11851577,711.82035051,-0.05790982,-0.06060595,0.00000000,0.00000000,0.00000000,0.00000000
159.64000000,3.21288100,9.51900000,0.10668011,622.60448689,0.10136464,689.02400273,0.00072462,0.11985008,713.14519877,-0.05856275,-0.06128733,0.00000000,0.00000000,0.00000000,0.00000000
161.14000000,3.25551800,9.52900000,0.10815878,623.25855190,0.10269988,690.66943511,0.00085646,0.12115634,714.52654784,-0.05919540,-0.06196094,0.00000000,0.00000000,0.00000000,0.00000000
162.64000000,3.29792300,9.53800000,0.10959700,623.84721041,0.10399689,692.21899313,0.00082890,0.12251286,715.87198240,-0.05983400,-0.06267886,0.00000000,0.00000000,0.00000000,0.00000000
164.14000000,3.34072600,9.54600000,0.11100578,624.37046242,0.10526571,693.67919123,0.00082125,0.12387773,717.15122877,-0.06052500,-0.06335273,0.00000000,0.00000000,0.00000000,0.00000000
165.64000000,3.38323100,9.55500000,0.11246233,624.95912094,0.10657588,695.24348192,0.00089291,0.12518545,718.46608611,-0.06115703,-0.06402842,0.00000000,0.00000000,0.00000000,0.00000000
167.14000000,3.42626600,9.56200000,0.11387478,625.41696645,0.10784473,696.63618452,0.00083230,0.12652693,719.80755489,-0.06184280,-0.06468413,0.00000000,0.00000000,0.00000000,0.00000000
168.64000000,3.46883600,9.57000000,0.11535344,625.94021846,0.10917135,698.14457867,0.00091691,0.12791191,721.10797410,-0.06252266,-0.06538925,0.00000000,0.00000000,0.00000000,0.00000000
170.14000000,3.51226900,9.57700000,0.11682844,626.39806397,0.11049292,699.57917538,0.00095531,0.12928525,722.40219382,-0.06322876,-0.06605649,0.00000000,0.00000000,0.00000000,0.00000000
171.64000000,3.55520500,9.58500000,0.11825189,626.92131598,0.11176665,701.05594578,0.00085529,0.13064756,723.61555367,-0.06389674,-0.06675082,0.00000000,0.00000000,0.00000000,0.00000000
173.14000000,3.59890200,9.59200000,0.11974533,627.37916149,0.11310128,702.50488831,0.00090696,0.13201995,724.98853177,-0.06461726,-0.06740268,0.00000000,0.00000000,0.00000000,0.00000000
174.64000000,3.64306200,9.60000000,0.12119089,627.90241350,0.11439141,703.99846513,0.00084670,0.13337849,726.20332600,-0.06529733,-0.06808116,0.00000000,0.00000000,0.00000000,0.00000000
176.14000000,3.68682600,9.60600000,0.12268800,628.29485251,0.11572581,705.37909137,0.00091112,0.13481457,727.55205389,-0.06601308,-0.06880149,0.00000000,0.00000000,0.00000000,0.00000000
177.64000000,3.73055600,9.61300000,0.12417400,628.75269802,0.11704854,706.82743554,0.00091644,0.13615684,728.68362213,-0.06666149,-0.06949535,0.00000000,0.00000000,0.00000000,0.00000000
179.14000000,3.77448500,9.61800000,0.12564889,629.07973053,0.11835966,708.12289969,0.00086270,0.13755108,729.93055931,-0.06735153,-0.07019955,0.00000000,0.00000000,0.00000000,0.00000000
180.64000000,3.81874400,9.62500000,0.12714600,629.53757604,0.11968877,709.58076068,0.00087477,0.13893375,731.17108302,-0.06800037,-0.07093339,0.00000000,0.00000000,0.00000000,0.00000000
182.14000000,3.86333500,9.63100000,0.12862467,629.93001504,0.12099978,710.95455325,0.00081492,0.14033991,732.43091161,-0.06867121,-0.07166870,0.00000000,0.00000000,0.00000000,0.00000000
183.64000000,3.90772600,9.63600000,0.13016956,630.25704755,0.12236767,712.29732732,0.00092456,0.14176629,733.70773587,-0.06940851,-0.07235777,0.00000000,0.00000000,0.00000000,0.00000000
185.14000000,3.95231600,9.64100000,0.13165922,630.58408006,0.12368489,713.60628958,0.00087776,0.14319107,734.90953978,-0.07012066,-0.07307041,0.00000000,0.00000000,0.00000000,0.00000000
186.64000000,3.99740400,9.64700000,0.13318189,630.97651907,0.12502951,715.01116372,0.00094133,0.14458201,736.08829027,-0.07079914,-0.07378287,0.00000000,0.00000000,0.00000000,0.00000000
188.14000000,4.04202700,9.65100000,0.13471211,631.23814507,0.12637897,716.27356821,0.00091439,0.14606550,737.41361537,-0.07157191,-0.07449359,0.00000000,0.00000000,0.00000000,0.00000000
189.64000000,4.08744600,9.65600000,0.13623133,631.56517758,0.12771694,717.60414381,0.00084840,0.14748439,738.54069336,-0.07229043,-0.07519396,0.00000000,0.00000000,0.00000000,0.00000000
191.14000000,4.13263200,9.66000000,0.13778344,631.82680358,0.12908202,718.88207687,0.00095061,0.14893189,739.84363137,-0.07300877,-0.07592312,0.00000000,0.00000000,0.00000000,0.00000000
192.64000000,4.17805100,9.66500000,0.13931733,632.15383609,0.13042925,720.22382279,0.00094933,0.15040926,741.09445266,-0.07376813,-0.07664113,0.00000000,0.00000000,0.00000000,0.00000000
194.14000000,4.22389900,9.67000000,0.14091000,632.48086860,0.13182619,721.60374779,0.00096087,0.15188432,742.34565566,-0.07448622,-0.07739811,0.00000000,0.00000000,0.00000000,0.00000000
195.64000000,4.26945100,9.67300000,0.14246222,632.67708810,0.13318578,722.80967202,0.00092103,0.15332624,743.49741912,-0.07518114,-0.07814510,0.00000000,0.00000000,0.00000000,0.00000000
197.14000000,4.31566300,9.67700000,0.14402189,632.93871411,0.13455003,724.09574326,0.00091336,0.15479771,744.59615244,-0.07589871,-0.07889899,0.00000000,0.00000000,0.00000000,0.00000000
198.64000000,4.36164400,9.68000000,0.14561078,633.13493361,0.13593793,725.32620373,0.00093131,0.15626636,745.84843892,-0.07660301,-0.07966335,0.00000000,0.00000000,0.00000000,0.00000000
200.14000000,4.40732800,9.68400000,0.14716311,633.39655962,0.13729203,726.60916790,0.00091086,0.15779549,747.07101576,-0.07738185,-0.08041364,0.00000000,0.00000000,0.00000000,0.00000000
201.64000000,4.45400400,9.68800000,0.14876311,633.65818562,0.13868581,727.92314870,0.00081341,0.15932226,748.29382837,-0.07813196,-0.08119030,0.00000000,0.00000000,0.00000000,0.00000000
203.14000000,4.50064800,9.69000000,0.15038522,633.78899863,0.14009686,729.10149803,0.00094020,0.16081596,749.41639790,-0.07888096,-0.08193500,0.00000000,0.00000000,0.00000000,0.00000000
204.64000000,4.54719200,9.69300000,0.15198900,633.98521813,0.14149001,730.34399745,0.00092615,0.16233810,750.63956176,-0.07964289,-0.08269521,0.00000000,0.00000000,0.00000000,0.00000000
206.14000000,4.59410000,9.69600000,0.15360000,634.18143763,0.14288749,731.59170646,0.00094394,0.16388936,751.80909008,-0.08044525,-0.08344411,0.00000000,0.00000000,0.00000000,0.00000000
207.64000000,4.64133900,9.69900000,0.15527367,634.37765714,0.14433726,732.87980201,0.00101916,0.16543820,752.97861840,-0.08121050,-0.08422770,0.00000000,0.00000000,0.00000000,0.00000000
209.14000000,4.68821500,9.70100000,0.15689211,634.50847014,0.14573720,734.05784354,0.00095412,0.16695363,754.12468973,-0.08193201,-0.08502162,0.00000000,0.00000000,0.00000000,0.00000000
210.64000000,4.73548800,9.70400000,0.15854733,634.70468965,0.14716692,735.33542564,0.00095257,0.00000000,0.00000000,0.00000000,0.00000000,0.00000000,0.00000000,0.00000000,0.00000000
212.14000000,4.78319100,9.70700000,0.16023933,634.90090915,0.14862631,736.63700757,0.00107823,0.00000000,0.00000000,0.00000000,0.00000000,0.00000000,0.00000000,0.00000000,0.00000000
213.64000000,4.83099300,9.70900000,0.16189456,635.03172215,0.15005191,737.83990057,0.00094982,0.00000000,0.00000000,0.00000000,0.00000000,0.00000000,0.00000000,0.00000000,0.00000000
215.14000000,4.87879500,9.71000000,0.16354978,635.09712865,0.15147549,738.96712291,0.00094847,0.00000000,0.00000000,0.00000000,0.00000000,0.00000000,0.00000000,0.00000000,0.00000000
216.64000000,4.92732600,9.71300000,0.16527867,635.29334816,0.15296026,740.29378568,0.00101060,0.00000000,0.00000000,0.00000000,0.00000000,0.00000000,0.00000000,0.00000000,0.00000000
218.14000000,4.97608800,9.71400000,0.16697067,635.35875466,0.15441122,741.44502950,0.00094588,0.00000000,0.00000000,0.00000000,0.00000000,0.00000000,0.00000000,0.00000000,0.00000000
219.64000000,5.02485100,9.71600000,0.16866267,635.48956766,0.15586008,742.67293278,0.00088154,0.00000000,0.00000000,0.00000000,0.00000000,0.00000000,0.00000000,0.00000000,0.00000000
221.14000000,5.07348100,9.71600000,0.17039144,635.48956766,0.15733826,743.77155303,0.00094312,0.00000000,0.00000000,0.00000000,0.00000000,0.00000000,0.00000000,0.00000000,0.00000000
222.64000000,5.12220900,9.71700000,0.17215700,635.55497416,0.15884564,744.97021185,0.00100448,0.00000000,0.00000000,0.00000000,0.00000000,0.00000000,0.00000000,0.00000000,0.00000000
224.14000000,5.17173300,9.71900000,0.17388578,635.68578717,0.16031942,746.22250469,0.00100281,0.00000000,0.00000000,0.00000000,0.00000000,0.00000000,0.00000000,0.00000000,0.00000000
225.64000000,5.22165400,9.72100000,0.17565133,635.81660017,0.16182232,747.49863375,0.00093871,0.00000000,0.00000000,0.00000000,0.00000000,0.00000000,0.00000000,0.00000000,0.00000000
227.14000000,5.27164200,9.72100000,0.17752733,635.81660017,0.16341676,748.69142569,0.00106239,0.00000000,0.00000000,0.00000000,0.00000000,0.00000000,0.00000000,0.00000000,0.00000000
228.64000000,5.32136500,9.72100000,0.17929289,635.81660017,0.16491501,749.81399522,0.00106080,0.00000000,0.00000000,0.00000000,0.00000000,0.00000000,0.00000000,0.00000000,0.00000000
230.14000000,5.37151700,9.72100000,0.18109522,635.81660017,0.16644216,750.95994867,0.00105918,0.00000000,0.00000000,0.00000000,0.00000000,0.00000000,0.00000000,0.00000000,0.00000000
231.64000000,5.42190200,9.72200000,0.18289756,635.88200667,0.16796698,752.18327131,0.00099517,0.00000000,0.00000000,0.00000000,0.00000000,0.00000000,0.00000000,0.00000000,0.00000000
233.14000000,5.47225300,9.72200000,0.18473678,635.88200667,0.16952062,753.35279963,0.00099362,0.00000000,0.00000000,0.00000000,0.00000000,0.00000000,0.00000000,0.00000000,0.00000000
234.64000000,5.52336600,9.72300000,0.18661267,635.94741317,0.17110275,754.62325580,0.00111609,0.00000000,0.00000000,0.00000000,0.00000000,0.00000000,0.00000000,0.00000000,0.00000000
236.14000000,5.57421400,9.72300000,0.18841511,635.94741317,0.00000000,0.00000000,0.00000000,0.00000000,0.00000000,0.00000000,0.00000000,0.00000000,0.00000000,0.00000000,0.00000000
237.64000000,5.62565800,9.72300000,0.19036456,635.94741317,0.00000000,0.00000000,0.00000000,0.00000000,0.00000000,0.00000000,0.00000000,0.00000000,0.00000000,0.00000000,0.00000000
239.14000000,5.67756600,9.72200000,0.19224056,635.88200667,0.00000000,0.00000000,0.00000000,0.00000000,0.00000000,0.00000000,0.00000000,0.00000000,0.00000000,0.00000000,0.00000000
240.64000000,5.72927400,9.72100000,0.19419000,635.81660017,0.00000000,0.00000000,0.00000000,0.00000000,0.00000000,0.00000000,0.00000000,0.00000000,0.00000000,0.00000000,0.00000000
242.14000000,5.78088400,9.72100000,0.19610278,635.81660017,0.00000000,0.00000000,0.00000000,0.00000000,0.00000000,0.00000000,0.00000000,0.00000000,0.00000000,0.00000000,0.00000000
243.64000000,5.83295700,9.71900000,0.19805222,635.68578717,0.00000000,0.00000000,0.00000000,0.00000000,0.00000000,0.00000000,0.00000000,0.00000000,0.00000000,0.00000000,0.00000000
245.14000000,5.88589000,9.71900000,0.20000178,635.68578717,0.00000000,0.00000000,0.00000000,0.00000000,0.00000000,0.00000000,0.00000000,0.00000000,0.00000000,0.00000000,0.00000000
246.64000000,5.93809600,9.71700000,0.20202478,635.55497416,0.00000000,0.00000000,0.00000000,0.00000000,0.00000000,0.00000000,0.00000000,0.00000000,0.00000000,0.00000000,0.00000000
248.14000000,5.99119500,9.71600000,0.20397433,635.48956766,0.00000000,0.00000000,0.00000000,0.00000000,0.00000000,0.00000000,0.00000000,0.00000000,0.00000000,0.00000000,0.00000000
249.64000000,6.04502300,9.71500000,0.20603411,635.42416116,0.00000000,0.00000000,0.00000000,0.00000000,0.00000000,0.00000000,0.00000000,0.00000000,0.00000000,0.00000000,0.00000000
251.14000000,6.09852000,9.71300000,0.20809400,635.29334816,0.00000000,0.00000000,0.00000000,0.00000000,0.00000000,0.00000000,0.00000000,0.00000000,0.00000000,0.00000000,0.00000000
252.64000000,6.15224800,9.71000000,0.21019067,635.09712865,0.00000000,0.00000000,0.00000000,0.00000000,0.00000000,0.00000000,0.00000000,0.00000000,0.00000000,0.00000000,0.00000000
254.14000000,6.20591000,9.70800000,0.21225056,634.96631565,0.00000000,0.00000000,0.00000000,0.00000000,0.00000000,0.00000000,0.00000000,0.00000000,0.00000000,0.00000000,0.00000000
255.64000000,6.26043300,9.70600000,0.21434711,634.83550265,0.00000000,0.00000000,0.00000000,0.00000000,0.00000000,0.00000000,0.00000000,0.00000000,0.00000000,0.00000000,0.00000000
257.14000000,6.31492300,9.70400000,0.21648056,634.70468965,0.00000000,0.00000000,0.00000000,0.00000000,0.00000000,0.00000000,0.00000000,0.00000000,0.00000000,0.00000000,0.00000000
258.64000000,6.37110000,9.70100000,0.21868756,634.50847014,0.00000000,0.00000000,0.00000000,0.00000000,0.00000000,0.00000000,0.00000000,0.00000000,0.00000000,0.00000000,0.00000000
260.14000000,6.42655000,9.69800000,0.22082100,634.31225064,0.00000000,0.00000000,0.00000000,0.00000000,0.00000000,0.00000000,0.00000000,0.00000000,0.00000000,0.00000000,0.00000000
261.64000000,6.48200000,9.69400000,0.22299111,634.05062463,0.00000000,0.00000000,0.00000000,0.00000000,0.00000000,0.00000000,0.00000000,0.00000000,0.00000000,0.00000000,0.00000000
263.14000000,6.53801300,9.69000000,0.22519811,633.78899863,0.00000000,0.00000000,0.00000000,0.00000000,0.00000000,0.00000000,0.00000000,0.00000000,0.00000000,0.00000000,0.00000000
264.64000000,6.59452200,9.68700000,0.22740511,633.59277912,0.00000000,0.00000000,0.00000000,0.00000000,0.00000000,0.00000000,0.00000000,0.00000000,0.00000000,0.00000000,0.00000000
266.14000000,6.65126300,9.68000000,0.22957544,633.13493361,0.00000000,0.00000000,0.00000000,0.00000000,0.00000000,0.00000000,0.00000000,0.00000000,0.00000000,0.00000000,0.00000000
267.64000000,6.70836800,9.67600000,0.23178244,632.87330761,0.00000000,0.00000000,0.00000000,0.00000000,0.00000000,0.00000000,0.00000000,0.00000000,0.00000000,0.00000000,0.00000000
269.14000000,6.76613500,9.67100000,0.23402622,632.54627510,0.00000000,0.00000000,0.00000000,0.00000000,0.00000000,0.00000000,0.00000000,0.00000000,0.00000000,0.00000000,0.00000000
270.64000000,6.82423400,9.66500000,0.23623322,632.15383609,0.00000000,0.00000000,0.00000000,0.00000000,0.00000000,0.00000000,0.00000000,0.00000000,0.00000000,0.00000000,0.00000000
272.14000000,6.88306100,9.65600000,0.23840344,631.56517758,0.00000000,0.00000000,0.00000000,0.00000000,0.00000000,0.00000000,0.00000000,0.00000000,0.00000000,0.00000000,0.00000000
273.64000000,6.94066300,9.64900000,0.24057378,631.10733207,0.00000000,0.00000000,0.00000000,0.00000000,0.00000000,0.00000000,0.00000000,0.00000000,0.00000000,0.00000000,0.00000000
275.14000000,6.99919200,9.64100000,0.24270711,630.58408006,0.00000000,0.00000000,0.00000000,0.00000000,0.00000000,0.00000000,0.00000000,0.00000000,0.00000000,0.00000000,0.00000000
276.64000000,7.05858100,9.63100000,0.24480378,629.93001504,0.00000000,0.00000000,0.00000000,0.00000000,0.00000000,0.00000000,0.00000000,0.00000000,0.00000000,0.00000000,0.00000000
278.14000000,7.11777200,9.62000000,0.24686378,629.21054353,0.00000000,0.00000000,0.00000000,0.00000000,0.00000000,0.00000000,0.00000000,0.00000000,0.00000000,0.00000000,0.00000000
279.64000000,7.17752700,9.61000000,0.24877656,628.55647851,0.00000000,0.00000000,0.00000000,0.00000000,0.00000000,0.00000000,0.00000000,0.00000000,0.00000000,0.00000000,0.00000000
281.14000000,7.23718100,9.59600000,0.25068933,627.64078749,0.00000000,0.00000000,0.00000000,0.00000000,0.00000000,0.00000000,0.00000000,0.00000000,0.00000000,0.00000000,0.00000000
282.64000000,7.29792800,9.58400000,0.25245500,626.85590948,0.00000000,0.00000000,0.00000000,0.00000000,0.00000000,0.00000000,0.00000000,0.00000000,0.00000000,0.00000000,0.00000000
284.14000000,7.35784700,9.56600000,0.25411044,625.67859245,0.00000000,0.00000000,0.00000000,0.00000000,0.00000000,0.00000000,0.00000000,0.00000000,0.00000000,0.00000000,0.00000000
285.64000000,7.41816400,9.55000000,0.25572889,624.63208843,0.00000000,0.00000000,0.00000000,0.00000000,0.00000000,0.00000000,0.00000000,0.00000000,0.00000000,0.00000000,0.00000000
287.14000000,7.47924200,9.53100000,0.25720044,623.38936490,0.00000000,0.00000000,0.00000000,0.00000000,0.00000000,0.00000000,0.00000000,0.00000000,0.00000000,0.00000000,0.00000000
288.64000000,7.54028600,9.51300000,0.25863511,622.21204788,0.00000000,0.00000000,0.00000000,0.00000000,0.00000000,0.00000000,0.00000000,0.00000000,0.00000000,0.00000000,0.00000000
290.14000000,7.60136500,9.48900000,0.25995956,620.64229184,0.00000000,0.00000000,0.00000000,0.00000000,0.00000000,0.00000000,0.00000000,0.00000000,0.00000000,0.00000000,0.00000000
291.64000000,7.66237600,9.46700000,0.26113678,619.20334881,0.00000000,0.00000000,0.00000000,0.00000000,0.00000000,0.00000000,0.00000000,0.00000000,0.00000000,0.00000000,0.00000000
293.14000000,7.72375000,9.44000000,0.26220378,617.43737327,0.00000000,0.00000000,0.00000000,0.00000000,0.00000000,0.00000000,0.00000000,0.00000000,0.00000000,0.00000000,0.00000000
294.64000000,7.78605200,9.41400000,0.26316044,615.73680424,0.00000000,0.00000000,0.00000000,0.00000000,0.00000000,0.00000000,0.00000000,0.00000000,0.00000000,0.00000000,0.00000000
296.14000000,7.84765700,9.38200000,0.26396989,613.64379619,0.00000000,0.00000000,0.00000000,0.00000000,0.00000000,0.00000000,0.00000000,0.00000000,0.00000000,0.00000000,0.00000000
297.64000000,7.90942800,9.35200000,0.26463233,611.68160115,0.00000000,0.00000000,0.00000000,0.00000000,0.00000000,0.00000000,0.00000000,0.00000000,0.00000000,0.00000000,0.00000000
299.14000000,7.97090000,9.31300000,0.26518444,609.13074760,0.00000000,0.00000000,0.00000000,0.00000000,0.00000000,0.00000000,0.00000000,0.00000000,0.00000000,0.00000000,0.00000000
300.64000000,8.03362900,9.28000000,0.26569978,606.97233305,0.00000000,0.00000000,0.00000000,0.00000000,0.00000000,0.00000000,0.00000000,0.00000000,0.00000000,0.00000000,0.00000000
302.14000000,8.09655500,9.23700000,0.26603122,604.15985349,0.00000000,0.00000000,0.00000000,0.00000000,0.00000000,0.00000000,0.00000000,0.00000000,0.00000000,0.00000000,0.00000000
303.64000000,8.15984500,9.19200000,0.26636278,601.21656093,0.00000000,0.00000000,0.00000000,0.00000000,0.00000000,0.00000000,0.00000000,0.00000000,0.00000000,0.00000000,0.00000000
305.14000000,8.22273700,9.14000000,0.26658389,597.81542285,0.00000000,0.00000000,0.00000000,0.00000000,0.00000000,0.00000000,0.00000000,0.00000000,0.00000000,0.00000000,0.00000000
306.64000000,8.28642200,9.09100000,0.26665789,594.61050428,0.00000000,0.00000000,0.00000000,0.00000000,0.00000000,0.00000000,0.00000000,0.00000000,0.00000000,0.00000000,0.00000000
308.14000000,8.35053900,9.02200000,0.26673200,590.09745569,0.00000000,0.00000000,0.00000000,0.00000000,0.00000000,0.00000000,0.00000000,0.00000000,0.00000000,0.00000000,0.00000000
309.64000000,8.41478900,8.95900000,0.26676933,585.97684610,0.00000000,0.00000000,0.00000000,0.00000000,0.00000000,0.00000000,0.00000000,0.00000000,0.00000000,0.00000000,0.00000000
311.14000000,8.47983700,8.87600000,0.26677011,580.54810648,0.00000000,0.00000000,0.00000000,0.00000000,0.00000000,0.00000000,0.00000000,0.00000000,0.00000000,0.00000000,0.00000000
312.64000000,8.54648000,8.78600000,0.26669756,574.66152136,0.00000000,0.00000000,0.00000000,0.00000000,0.00000000,0.00000000,0.00000000,0.00000000,0.00000000,0.00000000,0.00000000
314.14000000,8.61479100,8.66800000,0.26666189,566.94355419,0.00000000,0.00000000,0.00000000,0.00000000,0.00000000,0.00000000,0.00000000,0.00000000,0.00000000,0.00000000,0.00000000
315.64000000,8.68537200,8.54700000,0.26658944,559.02936752,0.00000000,0.00000000,0.00000000,0.00000000,0.00000000,0.00000000,0.00000000,0.00000000,0.00000000,0.00000000,0.00000000
317.14000000,8.75965500,8.35300000,0.26651722,546.34050625,0.00000000,0.00000000,0.00000000,0.00000000,0.00000000,0.00000000,0.00000000,0.00000000,0.00000000,0.00000000,0.00000000
318.64000000,8.84737100,8.14300000,0.26633433,532.60514095,0.00000000,0.00000000,0.00000000,0.00000000,0.00000000,0.00000000,0.00000000,0.00000000,0.00000000,0.00000000,0.00000000
319.64000000,8.93849600,7.90600000,0.26603733,517.10380012,0.00000000,0.00000000,0.00000000,0.00000000,0.00000000,0.00000000,0.00000000,0.00000000,0.00000000,0.00000000,0.00000000