File: polyN_optimization/DP600_results/DATA/UT_00_3.csv
Time[s],Displacement[mm],Force[kN],EngStrain_longi,EngStress[MPa],TrueStrain,TrueStress[MPa],TrueStrainRate[1/s],PlasticStrain_longi,PlasticStress[MPa],PlasticStrain_thick,PlasticStrain_width,R-Value,Thickness[mm],Width[mm], Young's Modulus [MPa]
0.64000000,0.00000000,-0.01300000,0.00000000,-0.84939562,0.00000000,-0.84939562,0.00000000,0.00064108,319.67153118,0.00000374,-0.00064482,0.90861213,1.53050000,10.00000000,205861.29027191
2.14000000,0.00172500,0.06800000,0.00005633,4.44299249,0.00005633,4.44324277,0.00004889,0.00095394,335.18885375,-0.00012882,-0.00082512,0.00000000,0.00000000,0.00000000,0.00000000
3.64000000,0.00381100,0.46200000,0.00012467,30.18621366,0.00012466,30.18997687,0.00000844,0.00140804,350.37387873,-0.00032220,-0.00108583,0.00000000,0.00000000,0.00000000,0.00000000
5.14000000,0.00653300,0.74800000,0.00021100,48.87291735,0.00021098,48.88322953,0.00011198,0.00205063,362.95016915,-0.00055978,-0.00149085,0.00000000,0.00000000,0.00000000,0.00000000
6.64000000,0.00849400,1.10500000,0.00025444,72.19862790,0.00025441,72.21699844,0.00010109,0.00276189,374.84654009,-0.00086910,-0.00189278,0.00000000,0.00000000,0.00000000,0.00000000
8.14000000,0.01016000,1.41500000,0.00032022,92.45344659,0.00032017,92.48305223,0.00007198,0.00345304,384.71324685,-0.00121263,-0.00224041,0.00000000,0.00000000,0.00000000,0.00000000
9.64000000,0.01232400,1.82900000,0.00036967,119.50343025,0.00036960,119.54760669,-0.00002177,0.00418047,393.62080723,-0.00157867,-0.00260180,0.00000000,0.00000000,0.00000000,0.00000000
11.14000000,0.01496500,2.16000000,0.00047311,141.13034956,0.00047300,141.19711990,-0.00012283,0.00505511,402.00797009,-0.00210219,-0.00295292,0.00000000,0.00000000,0.00000000,0.00000000
12.64000000,0.01842100,2.46400000,0.00058633,160.99313950,0.00058616,161.08753514,-0.00010904,0.00598353,410.43229469,-0.00266279,-0.00332074,0.00000000,0.00000000,0.00000000,0.00000000
14.14000000,0.02229400,2.84400000,0.00076211,185.82162692,0.00076182,185.96324365,0.00016211,0.00685034,417.78994459,-0.00316648,-0.00368386,0.00000000,0.00000000,0.00000000,0.00000000
15.64000000,0.02584600,3.14700000,0.00091900,205.61907873,0.00091858,205.80804267,0.00037991,0.00767078,425.47135289,-0.00357823,-0.00409255,0.00000000,0.00000000,0.00000000,0.00000000
17.14000000,0.02942200,3.51800000,0.00100967,229.85952303,0.00100916,230.09160453,0.00036855,0.00855870,432.33470617,-0.00400106,-0.00455764,0.00000000,0.00000000,0.00000000,0.00000000
18.64000000,0.03374200,3.80600000,0.00104678,248.67690297,0.00104623,248.93721243,0.00017582,0.00954574,439.05527083,-0.00452593,-0.00501980,0.00000000,0.00000000,0.00000000,0.00000000
20.14000000,0.03959200,4.13500000,0.00117789,270.17314603,0.00117720,270.49137998,-0.00001376,0.01048181,445.50111983,-0.00499598,-0.00548583,0.00000000,0.00000000,0.00000000,0.00000000
21.64000000,0.04755900,4.40700000,0.00139222,287.94511598,0.00139125,288.34599956,-0.00016066,0.01135787,452.13097986,-0.00540997,-0.00594790,0.00000000,0.00000000,0.00000000,0.00000000
23.14000000,0.05667900,4.72500000,0.00175678,308.72263966,0.00175524,309.26499673,-0.00013908,0.01227841,458.26151282,-0.00589872,-0.00637969,0.00000000,0.00000000,0.00000000,0.00000000
24.64000000,0.06822200,4.95700000,0.00226900,323.88108461,0.00226643,324.61597079,0.00020621,0.01324189,464.48980362,-0.00643338,-0.00680851,0.00000000,0.00000000,0.00000000,0.00000000
26.14000000,0.08421200,5.21900000,0.00278167,340.99967331,0.00277780,341.94822073,0.00045545,0.01421363,470.20136935,-0.00699866,-0.00721497,0.00000000,0.00000000,0.00000000,0.00000000
27.64000000,0.10107700,5.40700000,0.00335422,353.28324077,0.00334861,354.46823127,0.00054425,0.01516478,475.64754018,-0.00753552,-0.00762926,0.00000000,0.00000000,0.00000000,0.00000000
29.14000000,0.12161400,5.60000000,0.00397811,365.89349886,0.00397022,367.34906385,0.00038252,0.01609717,480.96148017,-0.00800483,-0.00809234,0.00000000,0.00000000,0.00000000,0.00000000
30.64000000,0.14512100,5.74700000,0.00476433,375.49820320,0.00475302,377.28720181,0.00041230,0.01707441,486.57413847,-0.00848836,-0.00858605,0.00000000,0.00000000,0.00000000,0.00000000
32.14000000,0.17017700,5.90900000,0.00565644,386.08297942,0.00564051,388.26683634,0.00071099,0.01811492,491.56037524,-0.00901818,-0.00909674,0.00000000,0.00000000,0.00000000,0.00000000
33.64000000,0.19651900,6.02600000,0.00652233,393.72754002,0.00650115,396.29556228,0.00089260,0.01907356,496.78360675,-0.00946812,-0.00960544,0.00000000,0.00000000,0.00000000,0.00000000
35.14000000,0.22275900,6.16300000,0.00731411,402.67886312,0.00728749,405.62410106,0.00063612,0.02004544,501.48748350,-0.00994040,-0.01010504,0.00000000,0.00000000,0.00000000,0.00000000
36.64000000,0.25078500,6.26500000,0.00822011,409.34335185,0.00818651,412.70819968,0.00049709,0.02106588,506.15783582,-0.01045969,-0.01060619,0.00000000,0.00000000,0.00000000,0.00000000
38.14000000,0.27877500,6.37800000,0.00923589,416.72655995,0.00919350,420.57540015,0.00070737,0.02209761,510.57469418,-0.01102001,-0.01107759,0.00000000,0.00000000,0.00000000,0.00000000
39.64000000,0.30600100,6.47100000,0.01012611,422.80300555,0.01007519,427.08435577,0.00075670,0.02313393,515.20427821,-0.01157882,-0.01155511,0.00000000,0.00000000,0.00000000,0.00000000
41.14000000,0.33518300,6.58300000,0.01101644,430.12087553,0.01095621,434.85927826,0.00067754,0.02415299,519.49778300,-0.01210558,-0.01204741,0.00000000,0.00000000,0.00000000,0.00000000
42.64000000,0.36383400,6.67000000,0.01195478,435.80529239,0.01188388,441.01524781,0.00049481,0.02518161,523.93938364,-0.01266674,-0.01251486,0.00000000,0.00000000,0.00000000,0.00000000
44.14000000,0.39271700,6.77400000,0.01295900,442.60045737,0.01287575,448.33611669,0.00054501,0.02621779,527.92188418,-0.01320542,-0.01301237,0.00000000,0.00000000,0.00000000,0.00000000
45.64000000,0.42153300,6.85400000,0.01395522,447.82750735,0.01385874,454.07703973,0.00069575,0.02731716,531.87843333,-0.01381871,-0.01349845,0.00000000,0.00000000,0.00000000,0.00000000
47.14000000,0.45226800,6.94500000,0.01487433,453.77327671,0.01476480,460.52285168,0.00060838,0.02836946,535.68278972,-0.01433790,-0.01403156,0.00000000,0.00000000,0.00000000,0.00000000
48.64000000,0.48064700,7.01900000,0.01580167,458.60829794,0.01567812,465.85507340,0.00044874,0.02941619,539.69459509,-0.01486484,-0.01455135,0.00000000,0.00000000,0.00000000,0.00000000
50.14000000,0.51167800,7.10800000,0.01685022,464.42339105,0.01670983,472.24902839,0.00051429,0.03049552,543.32587480,-0.01541656,-0.01507896,0.00000000,0.00000000,0.00000000,0.00000000
51.64000000,0.54190900,7.17700000,0.01790244,468.93172166,0.01774408,477.32674575,0.00062862,0.03160147,547.11466263,-0.01600478,-0.01559669,0.00000000,0.00000000,0.00000000,0.00000000
53.14000000,0.57243700,7.26100000,0.01887411,474.42012414,0.01869821,483.37438228,0.00062148,0.03265477,550.54292088,-0.01653606,-0.01611871,0.00000000,0.00000000,0.00000000,0.00000000
54.64000000,0.60419200,7.32500000,0.01985289,478.60176413,0.01965839,488.10339177,0.00053392,0.03375585,554.07238022,-0.01712776,-0.01662809,0.00000000,0.00000000,0.00000000,0.00000000
56.14000000,0.63502000,7.39700000,0.02090944,483.30610911,0.02069384,493.41177135,0.00047632,0.03483537,557.39297243,-0.01769609,-0.01713928,0.00000000,0.00000000,0.00000000,0.00000000
57.64000000,0.66654200,7.45700000,0.02198767,487.22639660,0.02174942,497.93936820,0.00062046,0.03595514,560.81091478,-0.01830387,-0.01765127,0.00000000,0.00000000,0.00000000,0.00000000
59.14000000,0.69842900,7.52900000,0.02305111,491.93074159,0.02278945,503.27029177,0.00071194,0.03701896,563.99977622,-0.01885217,-0.01816680,0.00000000,0.00000000,0.00000000,0.00000000
60.64000000,0.73038000,7.58500000,0.02408178,495.58967658,0.02379638,507.52435704,0.00064046,0.03812470,567.08222896,-0.01940592,-0.01871878,0.00000000,0.00000000,0.00000000,0.00000000
62.14000000,0.76240000,7.65200000,0.02519611,499.96733094,0.02488392,512.56456336,0.00071002,0.03924583,570.24802717,-0.01997056,-0.01927526,0.00000000,0.00000000,0.00000000,0.00000000
63.64000000,0.79527900,7.70300000,0.02627789,503.29957530,0.02593856,516.52522562,0.00070255,0.04034844,573.47806238,-0.02059292,-0.01975552,0.00000000,0.00000000,0.00000000,0.00000000
65.14000000,0.82805900,7.76300000,0.02738567,507.21986279,0.02701739,521.11041688,0.00078121,0.04147557,576.38640764,-0.02117181,-0.02030376,0.00000000,0.00000000,0.00000000,0.00000000
66.64000000,0.86107100,7.81200000,0.02845978,510.42143090,0.02806232,524.94791140,0.00077153,0.04256950,579.28137752,-0.02173307,-0.02083643,0.00000000,0.00000000,0.00000000,0.00000000
68.14000000,0.89411400,7.87100000,0.02954900,514.27638027,0.02912084,529.47273303,0.00077827,0.04371770,582.35102812,-0.02230539,-0.02141232,0.00000000,0.00000000,0.00000000,0.00000000
69.64000000,0.92695900,7.91500000,0.03064556,517.15125776,0.03018536,532.99964536,0.00067089,0.04484819,585.14178630,-0.02293019,-0.02191800,0.00000000,0.00000000,0.00000000,0.00000000
71.14000000,0.96072800,7.97100000,0.03181178,520.81019275,0.03131626,537.37809086,0.00079186,0.04597819,587.86910805,-0.02352015,-0.02245804,0.00000000,0.00000000,0.00000000,0.00000000
72.64000000,0.99397000,8.01400000,0.03290456,523.61973211,0.03237479,540.84920668,0.00077725,0.04709189,590.73000501,-0.02407367,-0.02301822,0.00000000,0.00000000,0.00000000,0.00000000
74.14000000,1.02807500,8.06200000,0.03402278,526.75596210,0.03345680,544.67766315,0.00074803,0.04826172,593.28525763,-0.02467950,-0.02358222,0.00000000,0.00000000,0.00000000,0.00000000
75.64000000,1.06214500,8.10300000,0.03517022,529.43482522,0.03456588,548.05516568,0.00071821,0.04940789,596.17679422,-0.02527094,-0.02413695,0.00000000,0.00000000,0.00000000,0.00000000
77.14000000,1.09595300,8.15100000,0.03631456,532.57105521,0.03567072,551.91113638,0.00078863,0.05053388,598.57830840,-0.02582329,-0.02471059,0.00000000,0.00000000,0.00000000,0.00000000
78.64000000,1.13094200,8.19000000,0.03746922,535.11924208,0.03678431,555.16974387,0.00078004,0.05167163,601.19921391,-0.02641099,-0.02526064,0.00000000,0.00000000,0.00000000,0.00000000
80.14000000,1.16550900,8.23200000,0.03857289,537.86344332,0.03784755,558.61039016,0.00071585,0.05286444,603.72015407,-0.02705980,-0.02580464,0.00000000,0.00000000,0.00000000,0.00000000
81.64000000,1.19987500,8.27000000,0.03972033,540.34629206,0.03895177,561.80902690,0.00065220,0.05401317,606.28887605,-0.02766613,-0.02634704,0.00000000,0.00000000,0.00000000,0.00000000
83.14000000,1.23440200,8.31000000,0.04090444,542.95981705,0.04008999,565.16928673,0.00077063,0.05517984,608.52649388,-0.02827616,-0.02690369,0.00000000,0.00000000,0.00000000,0.00000000
84.64000000,1.26989900,8.34400000,0.04207467,545.18131330,0.04121360,568.11963533,0.00077702,0.05634378,611.11452187,-0.02888237,-0.02746141,0.00000000,0.00000000,0.00000000,0.00000000
86.14000000,1.30565600,8.38600000,0.04322244,547.92551454,0.04231443,571.60819465,0.00070627,0.05754553,613.31340248,-0.02947829,-0.02806724,0.00000000,0.00000000,0.00000000,0.00000000
87.64000000,1.34108300,8.41800000,0.04441800,550.01633453,0.04345979,574.44696008,0.00076102,0.05868958,615.75989285,-0.03005117,-0.02863841,0.00000000,0.00000000,0.00000000,0.00000000
89.14000000,1.37620700,8.45300000,0.04557667,552.30316890,0.04456857,577.47530633,0.00069660,0.05984047,617.93636708,-0.03067860,-0.02916187,0.00000000,0.00000000,0.00000000,0.00000000
90.64000000,1.41226400,8.48600000,0.04677222,554.45932702,0.04571136,580.39262187,0.00076674,0.06102726,620.27913423,-0.03127981,-0.02974745,0.00000000,0.00000000,0.00000000,0.00000000
92.14000000,1.44845400,8.51800000,0.04796744,556.55014701,0.04685252,583.24643527,0.00072344,0.06219680,622.33609354,-0.03190646,-0.03029035,0.00000000,0.00000000,0.00000000,0.00000000
93.64000000,1.48433500,8.54600000,0.04916656,558.37961451,0.04799609,585.83321684,0.00072303,0.06337045,624.67974136,-0.03250062,-0.03086983,0.00000000,0.00000000,0.00000000,0.00000000
95.14000000,1.52048800,8.58000000,0.05040589,560.60111075,0.04917665,588.85870805,0.00079816,0.06455085,626.75187744,-0.03313374,-0.03141711,0.00000000,0.00000000,0.00000000,0.00000000
96.64000000,1.55674200,8.60800000,0.05159422,562.43057824,0.05030732,591.44874648,0.00080487,0.06574665,628.90798895,-0.03376807,-0.03197858,0.00000000,0.00000000,0.00000000,0.00000000
98.14000000,1.59395800,8.64100000,0.05280467,564.58673636,0.05145771,594.39955078,0.00074165,0.06693183,630.92112114,-0.03438173,-0.03255011,0.00000000,0.00000000,0.00000000,0.00000000
99.64000000,1.63050700,8.66600000,0.05404422,566.22018948,0.05263441,596.82111923,0.00077515,0.06816206,633.10751432,-0.03506080,-0.03310126,0.00000000,0.00000000,0.00000000,0.00000000
101.14000000,1.66719100,8.69500000,0.05524300,568.11499510,0.05377107,599.49937177,0.00077364,0.06934436,634.98602025,-0.03566464,-0.03367972,0.00000000,0.00000000,0.00000000,0.00000000
102.64000000,1.70407100,8.71900000,0.05650500,569.68311009,0.05496629,601.87305423,0.00086362,0.07053092,637.08245335,-0.03627846,-0.03425246,0.00000000,0.00000000,0.00000000,0.00000000
104.14000000,1.74088800,8.74800000,0.05772278,571.57791571,0.05611827,604.57098073,0.00075796,0.07172084,638.97328977,-0.03688730,-0.03483354,0.00000000,0.00000000,0.00000000,0.00000000
105.64000000,1.77823200,8.77200000,0.05899144,573.14603071,0.05731699,606.95674294,0.00083346,0.07293574,641.02524271,-0.03752251,-0.03541323,0.00000000,0.00000000,0.00000000,0.00000000
107.14000000,1.81551400,8.79900000,0.06020922,574.91016008,0.05846627,609.52505366,0.00077736,0.07414263,642.93450707,-0.03818502,-0.03595761,0.00000000,0.00000000,0.00000000,0.00000000
108.64000000,1.85278700,8.82100000,0.06145989,576.34759882,0.05964521,611.76985821,0.00078272,0.07533830,644.84022288,-0.03877198,-0.03656631,0.00000000,0.00000000,0.00000000,0.00000000
110.14000000,1.89046400,8.84500000,0.06273267,577.91571382,0.06084358,614.16990766,0.00075501,0.07654627,646.61564883,-0.03940462,-0.03714164,0.00000000,0.00000000,0.00000000,0.00000000
111.64000000,1.92837000,8.86600000,0.06397556,579.28781444,0.06201242,616.34807420,0.00078129,0.07779979,648.56620048,-0.04010455,-0.03769523,0.00000000,0.00000000,0.00000000,0.00000000
113.14000000,1.96571800,8.89100000,0.06522633,580.92126756,0.06318730,618.81263180,0.00080855,0.07899819,650.34240255,-0.04071034,-0.03828786,0.00000000,0.00000000,0.00000000,0.00000000
114.64000000,2.00355400,8.90900000,0.06645867,582.09735381,0.06434350,620.78276781,0.00072506,0.08021844,652.20748229,-0.04135091,-0.03886753,0.00000000,0.00000000,0.00000000,0.00000000
116.14000000,2.04146200,8.93300000,0.06776067,583.66546880,0.06556362,623.21503008,0.00080663,0.08143794,653.93304010,-0.04201184,-0.03942611,0.00000000,0.00000000,0.00000000,0.00000000
117.64000000,2.07956600,8.95200000,0.06901489,584.90689317,0.06673756,625.27417741,0.00078488,0.08267874,655.81869501,-0.04265044,-0.04002829,0.00000000,0.00000000,0.00000000,0.00000000
119.14000000,2.11787100,8.97300000,0.07029500,586.27899379,0.06793431,627.49147566,0.00079786,0.08388906,657.40194146,-0.04325778,-0.04063128,0.00000000,0.00000000,0.00000000,0.00000000
120.64000000,2.15627100,8.99000000,0.07160456,587.38974191,0.06915711,629.44952332,0.00083133,0.08513753,659.22808291,-0.04391449,-0.04122304,0.00000000,0.00000000,0.00000000,0.00000000
122.14000000,2.19484300,9.01100000,0.07290667,588.76184254,0.07037148,631.68650593,0.00087051,0.08635475,660.82201843,-0.04453741,-0.04181734,0.00000000,0.00000000,0.00000000,0.00000000
123.64000000,2.23360900,9.02800000,0.07417189,589.87259066,0.07155003,633.62455491,0.00074635,0.08760337,662.58328579,-0.04518348,-0.04241989,0.00000000,0.00000000,0.00000000,0.00000000
125.14000000,2.27184400,9.04800000,0.07548489,591.17935315,0.07277162,635.80446094,0.00080703,0.08883073,664.26192514,-0.04584416,-0.04298657,0.00000000,0.00000000,0.00000000,0.00000000
126.64000000,2.31070900,9.06400000,0.07679433,592.22476315,0.07398842,637.70426902,0.00084755,0.09006630,666.02115089,-0.04648693,-0.04357937,0.00000000,0.00000000,0.00000000,0.00000000
128.14000000,2.34983700,9.08100000,0.07805933,593.33551127,0.07516251,639.65088572,0.00079789,0.09131777,667.57825838,-0.04715658,-0.04416119,0.00000000,0.00000000,0.00000000,0.00000000
129.64000000,2.38946700,9.09700000,0.07935800,594.38092127,0.07636642,641.54980242,0.00075635,0.09254471,669.12176923,-0.04784646,-0.04469825,0.00000000,0.00000000,0.00000000,0.00000000
131.13000000,2.42866600,9.11500000,0.08070056,595.55700751,0.07760949,643.61878889,0.00081054,0.09381611,670.77022661,-0.04850584,-0.04531027,0.00000000,0.00000000,0.00000000,0.00000000
132.64000000,2.46806000,9.12800000,0.08200256,596.40640314,0.07881354,645.31325234,0.00080916,0.09511286,672.43892538,-0.04923843,-0.04587443,0.00000000,0.00000000,0.00000000,0.00000000
134.14000000,2.50768500,9.14600000,0.08331156,597.58248938,0.08002260,647.36801615,0.00077885,0.09631857,673.90445691,-0.04982856,-0.04649000,0.00000000,0.00000000,0.00000000,0.00000000
135.63000000,2.54731100,9.15900000,0.08469456,598.43188500,0.08129843,649.11580754,0.00083722,0.09758534,675.48644050,-0.05049738,-0.04708796,0.00000000,0.00000000,0.00000000,0.00000000
137.13000000,2.58710800,9.17400000,0.08602644,599.41195688,0.08252557,650.97723628,0.00087859,0.09879107,677.02991439,-0.05110090,-0.04769017,0.00000000,0.00000000,0.00000000,0.00000000
138.64000000,2.62716400,9.18700000,0.08736900,600.26135250,0.08376102,652.70558661,0.00085652,0.10005860,678.54553649,-0.05174679,-0.04831182,0.00000000,0.00000000,0.00000000,0.00000000
140.14000000,2.66702400,9.20200000,0.08868211,601.24142437,0.08496789,654.56078317,0.00081565,0.10134735,680.07840575,-0.05239249,-0.04895485,0.00000000,0.00000000,0.00000000,0.00000000
141.63000000,2.70774200,9.21500000,0.09004633,602.09081999,0.08622020,656.30689067,0.00085412,0.10260536,681.52023557,-0.05306828,-0.04953708,0.00000000,0.00000000,0.00000000,0.00000000
143.13000000,2.74806300,9.22900000,0.09137422,603.00555374,0.08743766,658.10471721,0.00083623,0.10386495,682.96571608,-0.05372111,-0.05014384,0.00000000,0.00000000,0.00000000,0.00000000
144.63000000,2.78855300,9.24100000,0.09271300,603.78961124,0.08866359,659.76875746,0.00078955,0.10515573,684.43518682,-0.05442608,-0.05072965,0.00000000,0.00000000,0.00000000,0.00000000
146.13000000,2.82847600,9.25300000,0.09409956,604.57366874,0.08993170,661.46378226,0.00086035,0.10644174,685.90405157,-0.05512477,-0.05131698,0.00000000,0.00000000,0.00000000,0.00000000
147.63000000,2.86886400,9.26500000,0.09544944,605.35772623,0.09116473,663.13878489,0.00081241,0.10773569,687.38105383,-0.05579825,-0.05193744,0.00000000,0.00000000,0.00000000,0.00000000
149.13000000,2.91001800,9.27800000,0.09682922,606.20712186,0.09242349,664.90568597,0.00085923,0.10901171,688.84835577,-0.05647380,-0.05253791,0.00000000,0.00000000,0.00000000,0.00000000
150.63000000,2.95096400,9.28800000,0.09818267,606.86050310,0.09365669,666.44368559,0.00083772,0.11031568,690.26422491,-0.05719799,-0.05311770,0.00000000,0.00000000,0.00000000,0.00000000
152.13000000,2.99125500,9.30000000,0.09959511,607.64456060,0.09494203,668.16298813,0.00089063,0.11161162,691.67705169,-0.05785992,-0.05375170,0.00000000,0.00000000,0.00000000,0.00000000
153.63000000,3.03286600,9.31000000,0.10097433,608.29794185,0.09619555,669.72042100,0.00092909,0.11289009,692.93298778,-0.05852078,-0.05436931,0.00000000,0.00000000,0.00000000,0.00000000
155.13000000,3.07431500,9.32100000,0.10230944,609.01666122,0.09740747,671.32481749,0.00079445,0.11420854,694.36632809,-0.05919694,-0.05501160,0.00000000,0.00000000,0.00000000,0.00000000
156.63000000,3.11559800,9.33000000,0.10373711,609.60470434,0.09870180,672.84333529,0.00077368,0.11547691,695.69347047,-0.05986725,-0.05560966,0.00000000,0.00000000,0.00000000,0.00000000
158.13000000,3.15681100,9.34100000,0.10509044,610.32342372,0.09992718,674.46258357,0.00081540,0.11677277,697.11601843,-0.06053188,-0.05624089,0.00000000,0.00000000,0.00000000,0.00000000
159.63000000,3.19828900,9.35000000,0.10648067,610.91146684,0.10118441,675.96172710,0.00076493,0.11812220,698.50462986,-0.06126929,-0.05685291,0.00000000,0.00000000,0.00000000,0.00000000
161.13000000,3.24013400,9.36000000,0.10790778,611.56484809,0.10247335,677.55745181,0.00091665,0.11943443,699.86961167,-0.06195201,-0.05748242,0.00000000,0.00000000,0.00000000,0.00000000
162.63000000,3.28184700,9.36900000,0.10932389,612.15289121,0.10375072,679.07582587,0.00092189,0.12071547,701.21504606,-0.06261926,-0.05809620,0.00000000,0.00000000,0.00000000,0.00000000
164.13000000,3.32378800,9.37800000,0.11072167,612.74093434,0.10500995,680.58463182,0.00084828,0.12207267,702.54216476,-0.06334151,-0.05873116,0.00000000,0.00000000,0.00000000,0.00000000
165.63000000,3.36579800,9.38500000,0.11213744,613.19830121,0.10628379,681.96079164,0.00086619,0.12338008,703.76202339,-0.06402521,-0.05935487,0.00000000,0.00000000,0.00000000,0.00000000
167.13000000,3.40724700,9.39500000,0.11356144,613.85168246,0.10756339,683.56156619,0.00089243,0.12470187,705.06857233,-0.06472527,-0.05997660,0.00000000,0.00000000,0.00000000,0.00000000
168.63000000,3.45014900,9.40200000,0.11499189,614.30904933,0.10884713,684.94960727,0.00086437,0.12605335,706.47302261,-0.06548467,-0.06056868,0.00000000,0.00000000,0.00000000,0.00000000
170.13000000,3.49179300,9.41000000,0.11641922,614.83175433,0.11012644,686.40998897,0.00083698,0.12741316,707.81118701,-0.06623811,-0.06117505,0.00000000,0.00000000,0.00000000,0.00000000
171.63000000,3.53489500,9.41800000,0.11788311,615.35445933,0.11143682,687.89435743,0.00085577,0.12870703,709.02996101,-0.06688283,-0.06182420,0.00000000,0.00000000,0.00000000,0.00000000
173.13000000,3.57737100,9.42500000,0.11932478,615.81182620,0.11272563,689.29343551,0.00088508,0.13006965,710.29971813,-0.06758708,-0.06248257,0.00000000,0.00000000,0.00000000,0.00000000
174.63000000,3.62047300,9.43300000,0.12079611,616.33453120,0.11403925,690.78534571,0.00087318,0.13143707,711.57505955,-0.06832851,-0.06310856,0.00000000,0.00000000,0.00000000,0.00000000
176.13000000,3.66367100,9.43800000,0.12225289,616.66122182,0.11533817,692.04983766,0.00086571,0.13281228,712.85813402,-0.06903894,-0.06377334,0.00000000,0.00000000,0.00000000,0.00000000
177.63000000,3.70654200,9.44500000,0.12369800,617.11858870,0.11662503,693.45492388,0.00087053,0.13414996,714.11651911,-0.06970993,-0.06444002,0.00000000,0.00000000,0.00000000,0.00000000
179.13000000,3.74990900,9.45100000,0.12519489,617.51061745,0.11795626,694.81979058,0.00088241,0.13554375,715.41728589,-0.07045482,-0.06508893,0.00000000,0.00000000,0.00000000,0.00000000
180.63000000,3.79350900,9.45800000,0.12667011,617.96798432,0.11926648,696.24605756,0.00095348,0.13685309,716.58412853,-0.07111534,-0.06573774,0.00000000,0.00000000,0.00000000,0.00000000
182.13000000,3.83701300,9.46400000,0.12814567,618.36001307,0.12057528,697.60016918,0.00096583,0.13822049,717.87017692,-0.07182977,-0.06639073,0.00000000,0.00000000,0.00000000,0.00000000
183.63000000,3.88077800,9.47000000,0.12962056,618.75204182,0.12188178,698.95502523,0.00086675,0.13961879,719.02941273,-0.07260313,-0.06701566,0.00000000,0.00000000,0.00000000,0.00000000
185.13000000,3.92451000,9.47600000,0.13111722,619.14407057,0.12320584,700.32452125,0.00087740,0.14101437,720.26428600,-0.07336861,-0.06764576,0.00000000,0.00000000,0.00000000,0.00000000
186.63000000,3.96864000,9.48100000,0.13258900,619.47076119,0.12450616,701.60576994,0.00090315,0.14243986,721.52286634,-0.07413029,-0.06830957,0.00000000,0.00000000,0.00000000,0.00000000
188.13000000,4.01270100,9.48600000,0.13407878,619.79745181,0.12582067,702.89913662,0.00080512,0.14379993,722.73614351,-0.07484881,-0.06895112,0.00000000,0.00000000,0.00000000,0.00000000
189.63000000,4.05670100,9.49200000,0.13560144,620.18948056,0.12716242,704.28806996,0.00086219,0.14525329,724.01916367,-0.07564027,-0.06961302,0.00000000,0.00000000,0.00000000,0.00000000
191.13000000,4.10099500,9.49600000,0.13713556,620.45083306,0.12851243,705.53670275,0.00090619,0.14660960,725.23377185,-0.07631839,-0.07029121,0.00000000,0.00000000,0.00000000,0.00000000
192.63000000,4.14591900,9.50100000,0.13864344,620.77752369,0.12983759,706.84425780,0.00084016,0.14802752,726.41897038,-0.07701570,-0.07101182,0.00000000,0.00000000,0.00000000,0.00000000
194.13000000,4.19060800,9.50600000,0.14023233,621.10421431,0.13123204,708.20310752,0.00089670,0.14947496,727.62763627,-0.07779462,-0.07168034,0.00000000,0.00000000,0.00000000,0.00000000
195.63000000,4.23530000,9.51000000,0.14179144,621.36556681,0.13259847,709.46988805,0.00103023,0.15085709,728.79052643,-0.07850903,-0.07234806,0.00000000,0.00000000,0.00000000,0.00000000
197.13000000,4.28029300,9.51400000,0.14328144,621.62691931,0.13390259,710.69452221,0.00090112,0.15233158,730.02290330,-0.07928626,-0.07304532,0.00000000,0.00000000,0.00000000,0.00000000
198.63000000,4.32528100,9.51800000,0.14481544,621.88827181,0.13524344,711.94729828,0.00083583,0.15383574,731.20238101,-0.08014073,-0.07369502,0.00000000,0.00000000,0.00000000,0.00000000
200.13000000,4.37040400,9.52200000,0.14641167,622.14962431,0.13663677,713.23958772,0.00085987,0.15527435,732.41243228,-0.08092147,-0.07435288,0.00000000,0.00000000,0.00000000,0.00000000
201.63000000,4.41582500,9.52500000,0.14795667,622.34563868,0.13798355,714.42582489,0.00086607,0.15674248,733.64619047,-0.08169213,-0.07505035,0.00000000,0.00000000,0.00000000,0.00000000
203.13000000,4.46151100,9.52900000,0.14951222,622.60699118,0.13933770,715.69434600,0.00077439,0.15820889,734.80366390,-0.08245352,-0.07575537,0.00000000,0.00000000,0.00000000,0.00000000
204.63000000,4.50722800,9.53300000,0.15113078,622.86834368,0.14074474,717.00292091,0.00095871,0.15967305,735.96129381,-0.08326413,-0.07640891,0.00000000,0.00000000,0.00000000,0.00000000
206.13000000,4.55324500,9.53700000,0.15274878,623.12969618,0.14214933,718.31199567,0.00102082,0.16116566,737.14179652,-0.08401102,-0.07715464,0.00000000,0.00000000,0.00000000,0.00000000
207.63000000,4.59886200,9.54000000,0.15429367,623.32571055,0.14348861,719.50091996,0.00089175,0.16268735,738.34573495,-0.08480690,-0.07788045,0.00000000,0.00000000,0.00000000,0.00000000
209.13000000,4.64480800,9.54200000,0.15598567,623.45638680,0.14495337,720.70664693,0.00101834,0.16420680,739.54997836,-0.08562419,-0.07858260,0.00000000,0.00000000,0.00000000,0.00000000
210.63000000,4.69102300,9.54500000,0.15756722,623.65240118,0.14632058,721.91957766,0.00088980,0.16572429,740.67706966,-0.08641316,-0.07931113,0.00000000,0.00000000,0.00000000,0.00000000
212.13000000,4.73789800,9.54800000,0.15914878,623.84841555,0.14768592,723.13312840,0.00088878,0.16727000,741.90466778,-0.08722923,-0.08004077,0.00000000,0.00000000,0.00000000,0.00000000
213.63000000,4.78418100,9.55100000,0.16080433,624.04442992,0.14911316,724.39347845,0.00082431,0.16875142,743.08635958,-0.08799403,-0.08075739,0.00000000,0.00000000,0.00000000,0.00000000
215.13000000,4.83102300,9.55400000,0.16242278,624.24044430,0.15050643,725.63131126,0.00088666,0.00000000,0.00000000,0.00000000,0.00000000,0.00000000,0.00000000,0.00000000,0.00000000
216.63000000,4.87803000,9.55600000,0.16411456,624.37112055,0.15196076,726.83950950,0.00094820,0.00000000,0.00000000,0.00000000,0.00000000,0.00000000,0.00000000,0.00000000,0.00000000
218.13000000,4.92590000,9.55800000,0.16580611,624.50179680,0.15341279,728.04801111,0.00094587,0.00000000,0.00000000,0.00000000,0.00000000,0.00000000,0.00000000,0.00000000,0.00000000
219.63000000,4.97334300,9.56000000,0.16753511,624.63247305,0.15489478,729.28034382,0.00113453,0.00000000,0.00000000,0.00000000,0.00000000,0.00000000,0.00000000,0.00000000,0.00000000
221.13000000,5.02061300,9.56100000,0.16919000,624.69781117,0.15631120,730.39043385,0.00100665,0.00000000,0.00000000,0.00000000,0.00000000,0.00000000,0.00000000,0.00000000,0.00000000
222.63000000,5.06848400,9.56300000,0.17091878,624.82848742,0.15778872,731.62340881,0.00094212,0.00000000,0.00000000,0.00000000,0.00000000,0.00000000,0.00000000,0.00000000,0.00000000
224.13000000,5.11615300,9.56500000,0.17261100,624.95916367,0.15923289,732.83398987,0.00094171,0.00000000,0.00000000,0.00000000,0.00000000,0.00000000,0.00000000,0.00000000,0.00000000
225.63000000,5.16528300,9.56700000,0.17433967,625.08983992,0.16070600,734.06779425,0.00093995,0.00000000,0.00000000,0.00000000,0.00000000,0.00000000,0.00000000,0.00000000,0.00000000
227.13000000,5.21338200,9.56800000,0.17606822,625.15517805,0.16217686,735.22513886,0.00093781,0.00000000,0.00000000,0.00000000,0.00000000,0.00000000,0.00000000,0.00000000,0.00000000
228.63000000,5.26211200,9.56800000,0.17783400,625.15517805,0.16367716,736.32902398,0.00099907,0.00000000,0.00000000,0.00000000,0.00000000,0.00000000,0.00000000,0.00000000,0.00000000
230.13000000,5.31067700,9.57000000,0.17963600,625.28585430,0.16520592,737.60970402,0.00106012,0.00000000,0.00000000,0.00000000,0.00000000,0.00000000,0.00000000,0.00000000,0.00000000
231.63000000,5.35997200,9.57100000,0.18136467,625.35119242,0.16667027,738.76780298,0.00093398,0.00000000,0.00000000,0.00000000,0.00000000,0.00000000,0.00000000,0.00000000,0.00000000
233.13000000,5.40823500,9.57200000,0.18320389,625.41653055,0.16822592,739.99527112,0.00099491,0.00000000,0.00000000,0.00000000,0.00000000,0.00000000,0.00000000,0.00000000,0.00000000
234.63000000,5.45766400,9.57200000,0.18496978,625.41653055,0.16971727,741.09968722,0.00093189,0.00000000,0.00000000,0.00000000,0.00000000,0.00000000,0.00000000,0.00000000,0.00000000
236.13000000,5.50775200,9.57300000,0.18677189,625.48186867,0.17123692,742.30429875,0.00086809,0.00000000,0.00000000,0.00000000,0.00000000,0.00000000,0.00000000,0.00000000,0.00000000
237.63000000,5.55754100,9.57400000,0.18864789,625.54720680,0.17281643,743.55536676,0.00105301,0.00000000,0.00000000,0.00000000,0.00000000,0.00000000,0.00000000,0.00000000,0.00000000
239.13000000,5.60743000,9.57400000,0.19056033,625.54720680,0.00000000,0.00000000,0.00000000,0.00000000,0.00000000,0.00000000,0.00000000,0.00000000,0.00000000,0.00000000,0.00000000
240.63000000,5.65731900,9.57300000,0.19243611,625.48186867,0.00000000,0.00000000,0.00000000,0.00000000,0.00000000,0.00000000,0.00000000,0.00000000,0.00000000,0.00000000,0.00000000
242.13000000,5.70724100,9.57300000,0.19431189,625.48186867,0.00000000,0.00000000,0.00000000,0.00000000,0.00000000,0.00000000,0.00000000,0.00000000,0.00000000,0.00000000,0.00000000
243.63000000,5.75756500,9.57400000,0.19615111,625.54720680,0.00000000,0.00000000,0.00000000,0.00000000,0.00000000,0.00000000,0.00000000,0.00000000,0.00000000,0.00000000,0.00000000
245.13000000,5.80887800,9.57400000,0.19813744,625.54720680,0.00000000,0.00000000,0.00000000,0.00000000,0.00000000,0.00000000,0.00000000,0.00000000,0.00000000,0.00000000,0.00000000
246.63000000,5.85956100,9.57400000,0.20012356,625.54720680,0.00000000,0.00000000,0.00000000,0.00000000,0.00000000,0.00000000,0.00000000,0.00000000,0.00000000,0.00000000,0.00000000
248.13000000,5.91054200,9.57300000,0.20203633,625.48186867,0.00000000,0.00000000,0.00000000,0.00000000,0.00000000,0.00000000,0.00000000,0.00000000,0.00000000,0.00000000,0.00000000
249.63000000,5.96231900,9.57300000,0.20405922,625.48186867,0.00000000,0.00000000,0.00000000,0.00000000,0.00000000,0.00000000,0.00000000,0.00000000,0.00000000,0.00000000,0.00000000
251.13000000,6.01423000,9.57300000,0.20608233,625.48186867,0.00000000,0.00000000,0.00000000,0.00000000,0.00000000,0.00000000,0.00000000,0.00000000,0.00000000,0.00000000,0.00000000
252.63000000,6.06570700,9.57200000,0.20814222,625.41653055,0.00000000,0.00000000,0.00000000,0.00000000,0.00000000,0.00000000,0.00000000,0.00000000,0.00000000,0.00000000,0.00000000
254.13000000,6.11755100,9.57000000,0.21023878,625.28585430,0.00000000,0.00000000,0.00000000,0.00000000,0.00000000,0.00000000,0.00000000,0.00000000,0.00000000,0.00000000,0.00000000
255.63000000,6.16932800,9.56900000,0.21229889,625.22051617,0.00000000,0.00000000,0.00000000,0.00000000,0.00000000,0.00000000,0.00000000,0.00000000,0.00000000,0.00000000,0.00000000
257.13000000,6.22196500,9.56900000,0.21446878,625.22051617,0.00000000,0.00000000,0.00000000,0.00000000,0.00000000,0.00000000,0.00000000,0.00000000,0.00000000,0.00000000,0.00000000
258.63000000,6.27536500,9.56800000,0.21663911,625.15517805,0.00000000,0.00000000,0.00000000,0.00000000,0.00000000,0.00000000,0.00000000,0.00000000,0.00000000,0.00000000,0.00000000
260.13000000,6.32826600,9.56600000,0.21888267,625.02450180,0.00000000,0.00000000,0.00000000,0.00000000,0.00000000,0.00000000,0.00000000,0.00000000,0.00000000,0.00000000,0.00000000
261.63000000,6.38186500,9.56500000,0.22116311,624.95916367,0.00000000,0.00000000,0.00000000,0.00000000,0.00000000,0.00000000,0.00000000,0.00000000,0.00000000,0.00000000,0.00000000
263.13000000,6.43612200,9.56400000,0.22344344,624.89382555,0.00000000,0.00000000,0.00000000,0.00000000,0.00000000,0.00000000,0.00000000,0.00000000,0.00000000,0.00000000,0.00000000
264.63000000,6.48912400,9.56200000,0.22576111,624.76314930,0.00000000,0.00000000,0.00000000,0.00000000,0.00000000,0.00000000,0.00000000,0.00000000,0.00000000,0.00000000,0.00000000
266.13000000,6.54341600,9.56000000,0.22815189,624.63247305,0.00000000,0.00000000,0.00000000,0.00000000,0.00000000,0.00000000,0.00000000,0.00000000,0.00000000,0.00000000,0.00000000
267.63000000,6.59770700,9.55800000,0.23054267,624.50179680,0.00000000,0.00000000,0.00000000,0.00000000,0.00000000,0.00000000,0.00000000,0.00000000,0.00000000,0.00000000,0.00000000
269.13000000,6.65289200,9.55700000,0.23304411,624.43645867,0.00000000,0.00000000,0.00000000,0.00000000,0.00000000,0.00000000,0.00000000,0.00000000,0.00000000,0.00000000,0.00000000
270.63000000,6.70801200,9.55400000,0.23561844,624.24044430,0.00000000,0.00000000,0.00000000,0.00000000,0.00000000,0.00000000,0.00000000,0.00000000,0.00000000,0.00000000,0.00000000
272.13000000,6.76319800,9.55100000,0.23819322,624.04442992,0.00000000,0.00000000,0.00000000,0.00000000,0.00000000,0.00000000,0.00000000,0.00000000,0.00000000,0.00000000,0.00000000
273.63000000,6.81841800,9.54900000,0.24076811,623.91375368,0.00000000,0.00000000,0.00000000,0.00000000,0.00000000,0.00000000,0.00000000,0.00000000,0.00000000,0.00000000,0.00000000
275.13000000,6.87413100,9.54600000,0.24345300,623.71773930,0.00000000,0.00000000,0.00000000,0.00000000,0.00000000,0.00000000,0.00000000,0.00000000,0.00000000,0.00000000,0.00000000
276.63000000,6.93031200,9.54400000,0.24624811,623.58706305,0.00000000,0.00000000,0.00000000,0.00000000,0.00000000,0.00000000,0.00000000,0.00000000,0.00000000,0.00000000,0.00000000
278.13000000,6.98629300,9.54000000,0.24908056,623.32571055,0.00000000,0.00000000,0.00000000,0.00000000,0.00000000,0.00000000,0.00000000,0.00000000,0.00000000,0.00000000,0.00000000
279.63000000,7.04240700,9.53700000,0.25198611,623.12969618,0.00000000,0.00000000,0.00000000,0.00000000,0.00000000,0.00000000,0.00000000,0.00000000,0.00000000,0.00000000,0.00000000
281.13000000,7.09914700,9.53300000,0.25500200,622.86834368,0.00000000,0.00000000,0.00000000,0.00000000,0.00000000,0.00000000,0.00000000,0.00000000,0.00000000,0.00000000,0.00000000
282.63000000,7.15615200,9.53000000,0.25816522,622.67232930,0.00000000,0.00000000,0.00000000,0.00000000,0.00000000,0.00000000,0.00000000,0.00000000,0.00000000,0.00000000,0.00000000
284.13000000,7.21365600,9.52500000,0.26132844,622.34563868,0.00000000,0.00000000,0.00000000,0.00000000,0.00000000,0.00000000,0.00000000,0.00000000,0.00000000,0.00000000,0.00000000
285.63000000,7.27053200,9.52100000,0.26456489,622.08428618,0.00000000,0.00000000,0.00000000,0.00000000,0.00000000,0.00000000,0.00000000,0.00000000,0.00000000,0.00000000,0.00000000
287.13000000,7.32786900,9.51700000,0.26794889,621.82293368,0.00000000,0.00000000,0.00000000,0.00000000,0.00000000,0.00000000,0.00000000,0.00000000,0.00000000,0.00000000,0.00000000
288.63000000,7.38590100,9.51300000,0.27144278,621.56158118,0.00000000,0.00000000,0.00000000,0.00000000,0.00000000,0.00000000,0.00000000,0.00000000,0.00000000,0.00000000,0.00000000
290.13000000,7.44429900,9.50800000,0.27508422,621.23489056,0.00000000,0.00000000,0.00000000,0.00000000,0.00000000,0.00000000,0.00000000,0.00000000,0.00000000,0.00000000,0.00000000
291.63000000,7.50246100,9.50200000,0.27876200,620.84286181,0.00000000,0.00000000,0.00000000,0.00000000,0.00000000,0.00000000,0.00000000,0.00000000,0.00000000,0.00000000,0.00000000
293.13000000,7.56079200,9.49600000,0.28266089,620.45083306,0.00000000,0.00000000,0.00000000,0.00000000,0.00000000,0.00000000,0.00000000,0.00000000,0.00000000,0.00000000,0.00000000
294.63000000,7.61935500,9.49000000,0.28667000,620.05880431,0.00000000,0.00000000,0.00000000,0.00000000,0.00000000,0.00000000,0.00000000,0.00000000,0.00000000,0.00000000,0.00000000
296.13000000,7.67817800,9.48300000,0.29089944,619.60143744,0.00000000,0.00000000,0.00000000,0.00000000,0.00000000,0.00000000,0.00000000,0.00000000,0.00000000,0.00000000,0.00000000
297.63000000,7.73690700,9.47600000,0.29516611,619.14407057,0.00000000,0.00000000,0.00000000,0.00000000,0.00000000,0.00000000,0.00000000,0.00000000,0.00000000,0.00000000,0.00000000
299.13000000,7.79599600,9.46800000,0.29961611,618.62136557,0.00000000,0.00000000,0.00000000,0.00000000,0.00000000,0.00000000,0.00000000,0.00000000,0.00000000,0.00000000,0.00000000
300.63000000,7.85565200,9.46100000,0.30432378,618.16399869,0.00000000,0.00000000,0.00000000,0.00000000,0.00000000,0.00000000,0.00000000,0.00000000,0.00000000,0.00000000,0.00000000
302.13000000,7.91589900,9.45100000,0.30914211,617.51061745,0.00000000,0.00000000,0.00000000,0.00000000,0.00000000,0.00000000,0.00000000,0.00000000,0.00000000,0.00000000,0.00000000
303.63000000,7.97575300,9.44100000,0.31418067,616.85723620,0.00000000,0.00000000,0.00000000,0.00000000,0.00000000,0.00000000,0.00000000,0.00000000,0.00000000,0.00000000,0.00000000
305.13000000,8.03593500,9.42900000,0.31940344,616.07317870,0.00000000,0.00000000,0.00000000,0.00000000,0.00000000,0.00000000,0.00000000,0.00000000,0.00000000,0.00000000,0.00000000
306.63000000,8.09605600,9.41900000,0.32481056,615.41979745,0.00000000,0.00000000,0.00000000,0.00000000,0.00000000,0.00000000,0.00000000,0.00000000,0.00000000,0.00000000,0.00000000
308.13000000,8.15670000,9.40500000,0.33032722,614.50506370,0.00000000,0.00000000,0.00000000,0.00000000,0.00000000,0.00000000,0.00000000,0.00000000,0.00000000,0.00000000,0.00000000
309.63000000,8.21701900,9.39100000,0.33602833,613.59032996,0.00000000,0.00000000,0.00000000,0.00000000,0.00000000,0.00000000,0.00000000,0.00000000,0.00000000,0.00000000,0.00000000
311.13000000,8.27803100,9.37700000,0.34191344,612.67559621,0.00000000,0.00000000,0.00000000,0.00000000,0.00000000,0.00000000,0.00000000,0.00000000,0.00000000,0.00000000,0.00000000
312.63000000,8.33901000,9.36200000,0.34805567,611.69552434,0.00000000,0.00000000,0.00000000,0.00000000,0.00000000,0.00000000,0.00000000,0.00000000,0.00000000,0.00000000,0.00000000
314.13000000,8.40035200,9.34300000,0.35423511,610.45409997,0.00000000,0.00000000,0.00000000,0.00000000,0.00000000,0.00000000,0.00000000,0.00000000,0.00000000,0.00000000,0.00000000
315.63000000,8.46179500,9.32400000,0.36063456,609.21267560,0.00000000,0.00000000,0.00000000,0.00000000,0.00000000,0.00000000,0.00000000,0.00000000,0.00000000,0.00000000,0.00000000
317.13000000,8.52254000,9.30200000,0.36703444,607.77523685,0.00000000,0.00000000,0.00000000,0.00000000,0.00000000,0.00000000,0.00000000,0.00000000,0.00000000,0.00000000,0.00000000
318.63000000,8.58401400,9.28000000,0.37358133,606.33779811,0.00000000,0.00000000,0.00000000,0.00000000,0.00000000,0.00000000,0.00000000,0.00000000,0.00000000,0.00000000,0.00000000
320.13000000,8.64529000,9.25700000,0.38016467,604.83502123,0.00000000,0.00000000,0.00000000,0.00000000,0.00000000,0.00000000,0.00000000,0.00000000,0.00000000,0.00000000,0.00000000
321.63000000,8.70755500,9.23300000,0.38693244,603.26690624,0.00000000,0.00000000,0.00000000,0.00000000,0.00000000,0.00000000,0.00000000,0.00000000,0.00000000,0.00000000,0.00000000
323.13000000,8.76922700,9.20200000,0.39370011,601.24142437,0.00000000,0.00000000,0.00000000,0.00000000,0.00000000,0.00000000,0.00000000,0.00000000,0.00000000,0.00000000,0.00000000
324.63000000,8.83079900,9.17300000,0.40046756,599.34661875,0.00000000,0.00000000,0.00000000,0.00000000,0.00000000,0.00000000,0.00000000,0.00000000,0.00000000,0.00000000,0.00000000
326.13000000,8.89280100,9.14000000,0.40738211,597.19046063,0.00000000,0.00000000,0.00000000,0.00000000,0.00000000,0.00000000,0.00000000,0.00000000,0.00000000,0.00000000,0.00000000
327.63000000,8.95490100,9.10600000,0.41429656,594.96896439,0.00000000,0.00000000,0.00000000,0.00000000,0.00000000,0.00000000,0.00000000,0.00000000,0.00000000,0.00000000,0.00000000
329.13000000,9.01713300,9.07000000,0.42121111,592.61679190,0.00000000,0.00000000,0.00000000,0.00000000,0.00000000,0.00000000,0.00000000,0.00000000,0.00000000,0.00000000,0.00000000
330.63000000,9.07939500,9.03200000,0.42812556,590.13394316,0.00000000,0.00000000,0.00000000,0.00000000,0.00000000,0.00000000,0.00000000,0.00000000,0.00000000,0.00000000,0.00000000
332.13000000,9.14162500,8.98600000,0.43511289,587.12838942,0.00000000,0.00000000,0.00000000,0.00000000,0.00000000,0.00000000,0.00000000,0.00000000,0.00000000,0.00000000,0.00000000
333.63000000,9.20504200,8.94100000,0.44221078,584.18817380,0.00000000,0.00000000,0.00000000,0.00000000,0.00000000,0.00000000,0.00000000,0.00000000,0.00000000,0.00000000,0.00000000
335.13000000,9.26859200,8.88500000,0.44934522,580.52923881,0.00000000,0.00000000,0.00000000,0.00000000,0.00000000,0.00000000,0.00000000,0.00000000,0.00000000,0.00000000,0.00000000
336.63000000,9.33193800,8.83000000,0.45640544,576.93564195,0.00000000,0.00000000,0.00000000,0.00000000,0.00000000,0.00000000,0.00000000,0.00000000,0.00000000,0.00000000,0.00000000
338.13000000,9.39544600,8.76800000,0.46357556,572.88467821,0.00000000,0.00000000,0.00000000,0.00000000,0.00000000,0.00000000,0.00000000,0.00000000,0.00000000,0.00000000,0.00000000
339.63000000,9.46010600,8.70000000,0.47081878,568.44168572,0.00000000,0.00000000,0.00000000,0.00000000,0.00000000,0.00000000,0.00000000,0.00000000,0.00000000,0.00000000,0.00000000
341.13000000,9.52542500,8.61600000,0.47817156,562.95328324,0.00000000,0.00000000,0.00000000,0.00000000,0.00000000,0.00000000,0.00000000,0.00000000,0.00000000,0.00000000,0.00000000
342.63000000,9.59123200,8.52600000,0.48563422,557.07285201,0.00000000,0.00000000,0.00000000,0.00000000,0.00000000,0.00000000,0.00000000,0.00000000,0.00000000,0.00000000,0.00000000
344.13000000,9.65885000,8.41400000,0.49324300,549.75498203,0.00000000,0.00000000,0.00000000,0.00000000,0.00000000,0.00000000,0.00000000,0.00000000,0.00000000,0.00000000,0.00000000
345.63000000,9.72777700,8.29000000,0.50118189,541.65305456,0.00000000,0.00000000,0.00000000,0.00000000,0.00000000,0.00000000,0.00000000,0.00000000,0.00000000,0.00000000,0.00000000
347.13000000,9.79987200,8.14200000,0.50941444,531.98301209,0.00000000,0.00000000,0.00000000,0.00000000,0.00000000,0.00000000,0.00000000,0.00000000,0.00000000,0.00000000,0.00000000
348.63000000,9.87830600,7.95500000,0.51834533,519.76478275,0.00000000,0.00000000,0.00000000,0.00000000,0.00000000,0.00000000,0.00000000,0.00000000,0.00000000,0.00000000,0.00000000
349.13000000,9.90730300,7.84900000,0.52169011,512.83894152,0.00000000,0.00000000,0.00000000,0.00000000,0.00000000,0.00000000,0.00000000,0.00000000,0.00000000,0.00000000,0.00000000