File: polyN_optimization/DP600_results/DATA/UT_00_1.csv
Time[s],Displacement[mm],Force[kN],EngStrain_longi,EngStress[MPa],TrueStrain,TrueStress[MPa],TrueStrainRate[1/s],PlasticStrain_longi,PlasticStress[MPa],PlasticStrain_thick,PlasticStrain_width,R-Value,Thickness[mm],Width[mm], Young's Modulus [MPa]
0.64000000,0.00000000,-0.01200000,0.00000000,-0.78879905,0.00000000,-0.78879905,0.00000000,0.00057222,319.67232783,0.00006670,-0.00063893,0.89174163,1.52130000,10.00000000,205631.51307600
2.14000000,0.00173000,0.02900000,0.00004056,1.90626438,0.00004055,1.90634169,0.00003178,0.00083305,334.27437827,-0.00001208,-0.00082097,0.00000000,0.00000000,0.00000000,0.00000000
3.64000000,0.00344300,0.43600000,0.00009233,28.65969894,0.00009233,28.66234519,-0.00002689,0.00126341,350.99242934,-0.00020305,-0.00106036,0.00000000,0.00000000,0.00000000,0.00000000
5.14000000,0.00619700,0.76300000,0.00018022,50.15447315,0.00018021,50.16351210,0.00010154,0.00194357,362.92879341,-0.00058306,-0.00136052,0.00000000,0.00000000,0.00000000,0.00000000
6.64000000,0.00825600,1.06700000,0.00024944,70.13738250,0.00024941,70.15487788,0.00009931,0.00259955,375.99790322,-0.00087992,-0.00171963,0.00000000,0.00000000,0.00000000,0.00000000
8.14000000,0.00990800,1.45100000,0.00030056,95.37895221,0.00030051,95.40761889,0.00007509,0.00328315,385.45578068,-0.00118597,-0.00209718,0.00000000,0.00000000,0.00000000,0.00000000
9.64000000,0.01211300,1.75800000,0.00035722,115.55906133,0.00035716,115.60034159,0.00000533,0.00399744,395.27064129,-0.00151559,-0.00248185,0.00000000,0.00000000,0.00000000,0.00000000
11.14000000,0.01487400,2.11400000,0.00047011,138.96009991,0.00047000,139.02542660,-0.00004398,0.00487456,403.77384681,-0.00197155,-0.00290301,0.00000000,0.00000000,0.00000000,0.00000000
12.64000000,0.01832100,2.44300000,0.00056900,160.58634063,0.00056884,160.67771426,-0.00016257,0.00579829,412.24524093,-0.00255342,-0.00324486,0.00000000,0.00000000,0.00000000,0.00000000
14.14000000,0.02238900,2.79700000,0.00073533,183.85591271,0.00073506,183.99110809,0.00012436,0.00667012,419.18267176,-0.00302585,-0.00364427,0.00000000,0.00000000,0.00000000,0.00000000
15.64000000,0.02604100,3.09600000,0.00092733,203.51015579,0.00092690,203.69887754,0.00032417,0.00747623,427.50071264,-0.00343704,-0.00403919,0.00000000,0.00000000,0.00000000,0.00000000
17.14000000,0.02947400,3.46300000,0.00097178,227.63426017,0.00097131,227.85547009,0.00034680,0.00836680,434.00573970,-0.00391921,-0.00444759,0.00000000,0.00000000,0.00000000,0.00000000
18.64000000,0.03355000,3.75400000,0.00102778,246.76263722,0.00102725,247.01625437,0.00018160,0.00936172,441.30143367,-0.00454077,-0.00482096,0.00000000,0.00000000,0.00000000,0.00000000
20.14000000,0.03910100,4.08700000,0.00113667,268.65181095,0.00113602,268.95717851,-0.00005127,0.01027556,447.84161938,-0.00500826,-0.00526731,0.00000000,0.00000000,0.00000000,0.00000000
21.64000000,0.04654700,4.37900000,0.00136833,287.84592125,0.00136740,288.23979042,-0.00028648,0.01114355,454.70671341,-0.00540242,-0.00574113,0.00000000,0.00000000,0.00000000,0.00000000
23.14000000,0.05508900,4.67400000,0.00176567,307.23723132,0.00176411,307.77970985,-0.00007342,0.01204885,460.39828977,-0.00580860,-0.00624025,0.00000000,0.00000000,0.00000000,0.00000000
24.64000000,0.06644500,4.91000000,0.00226222,322.75027937,0.00225967,323.48041222,0.00033039,0.01309631,467.23687343,-0.00637613,-0.00672018,0.00000000,0.00000000,0.00000000,0.00000000
26.14000000,0.08243600,5.17700000,0.00276622,340.30105831,0.00276240,341.24240666,0.00067514,0.01404855,472.57126665,-0.00686273,-0.00718583,0.00000000,0.00000000,0.00000000,0.00000000
27.64000000,0.09875800,5.37000000,0.00323711,352.98757641,0.00323188,354.13023642,0.00059417,0.01495324,478.56317731,-0.00734540,-0.00760784,0.00000000,0.00000000,0.00000000,0.00000000
29.14000000,0.11839200,5.58100000,0.00386989,366.85729310,0.00386242,368.27699007,0.00038123,0.01587066,483.96822739,-0.00779719,-0.00807347,0.00000000,0.00000000,0.00000000,0.00000000
30.64000000,0.14107200,5.73100000,0.00467556,376.71728127,0.00466466,378.47864385,0.00054929,0.01692330,489.58374874,-0.00843093,-0.00849238,0.00000000,0.00000000,0.00000000,0.00000000
32.14000000,0.16570500,5.88700000,0.00558789,386.97166897,0.00557233,389.13402366,0.00090736,0.01794631,494.38926970,-0.00898040,-0.00896591,0.00000000,0.00000000,0.00000000,0.00000000
33.64000000,0.19212500,6.00700000,0.00638989,394.85965950,0.00636956,397.38276885,0.00097976,0.01889619,499.97543088,-0.00948884,-0.00940736,0.00000000,0.00000000,0.00000000,0.00000000
35.14000000,0.21765100,6.14500000,0.00715511,403.93084862,0.00712963,406.82101872,0.00066469,0.01982884,504.41798016,-0.00991442,-0.00991442,0.00000000,0.00000000,0.00000000,0.00000000
36.64000000,0.24496400,6.24800000,0.00808589,410.70137383,0.00805337,414.02225950,0.00058403,0.02085144,509.38657012,-0.01043392,-0.01041752,0.00000000,0.00000000,0.00000000,0.00000000
38.14000000,0.27323800,6.37200000,0.00911967,418.85229738,0.00907833,422.67209071,0.00082421,0.02192869,513.98809309,-0.01097862,-0.01095006,0.00000000,0.00000000,0.00000000,0.00000000
39.64000000,0.30012100,6.46600000,0.01001344,425.03122330,0.00996364,429.28724984,0.00090338,0.02289664,518.67750365,-0.01141555,-0.01148108,0.00000000,0.00000000,0.00000000,0.00000000
41.14000000,0.32829500,6.57200000,0.01085956,431.99894827,0.01080101,436.69026485,0.00073504,0.02391007,522.65532385,-0.01193222,-0.01197785,0.00000000,0.00000000,0.00000000,0.00000000
42.64000000,0.35739500,6.65900000,0.01180500,437.71774141,0.01173586,442.88499934,0.00054541,0.02495801,527.40411718,-0.01250214,-0.01245587,0.00000000,0.00000000,0.00000000,0.00000000
44.14000000,0.38606600,6.76500000,0.01283489,444.68546638,0.01275322,450.39295493,0.00069015,0.02602403,531.15501692,-0.01304781,-0.01297621,0.00000000,0.00000000,0.00000000,0.00000000
45.64000000,0.41443800,6.84600000,0.01381344,450.00985999,0.01371891,456.22604619,0.00082017,0.02703977,535.42953667,-0.01360534,-0.01343444,0.00000000,0.00000000,0.00000000,0.00000000
47.14000000,0.44502900,6.94400000,0.01471467,456.45171892,0.01460746,463.16825382,0.00073247,0.02807430,539.31480975,-0.01419305,-0.01388125,0.00000000,0.00000000,0.00000000,0.00000000
48.64000000,0.47320200,7.01800000,0.01567467,461.31597975,0.01555309,468.54695396,0.00046368,0.02914633,543.29615217,-0.01479947,-0.01434686,0.00000000,0.00000000,0.00000000,0.00000000
50.14000000,0.50352900,7.10300000,0.01669722,466.90330638,0.01655936,474.69929465,0.00052093,0.03024826,546.75711762,-0.01546112,-0.01478714,0.00000000,0.00000000,0.00000000,0.00000000
51.64000000,0.53375600,7.17300000,0.01773456,471.50463419,0.01757913,479.86655932,0.00069404,0.03127861,550.79929008,-0.01596555,-0.01531305,0.00000000,0.00000000,0.00000000,0.00000000
53.14000000,0.56457800,7.25800000,0.01868722,477.09196082,0.01851476,486.00748432,0.00067898,0.03234638,554.18764785,-0.01650134,-0.01584504,0.00000000,0.00000000,0.00000000,0.00000000
54.64000000,0.59493600,7.32300000,0.01966200,481.36462236,0.01947120,490.82921357,0.00043309,0.03342961,557.79635878,-0.01709884,-0.01633077,0.00000000,0.00000000,0.00000000,0.00000000
56.14000000,0.62615600,7.40100000,0.02071778,486.49181621,0.02050608,496.57084555,0.00041108,0.03454493,561.15679298,-0.01767977,-0.01686516,0.00000000,0.00000000,0.00000000,0.00000000
57.64000000,0.65717700,7.46100000,0.02182122,490.43581148,0.02158655,501.13772031,0.00061903,0.03556603,564.67625364,-0.01815296,-0.01741307,0.00000000,0.00000000,0.00000000,0.00000000
59.14000000,0.68842900,7.52900000,0.02285122,494.90567278,0.02259404,506.21487229,0.00072642,0.03668037,567.70708077,-0.01873400,-0.01794637,0.00000000,0.00000000,0.00000000,0.00000000
60.64000000,0.72031100,7.58500000,0.02385178,498.58673503,0.02357177,510.47891504,0.00058936,0.03779047,571.35936508,-0.01928886,-0.01850161,0.00000000,0.00000000,0.00000000,0.00000000
62.14000000,0.75199400,7.65300000,0.02494422,503.05659633,0.02463819,515.60495186,0.00052389,0.03890987,574.26866876,-0.01986173,-0.01904814,0.00000000,0.00000000,0.00000000,0.00000000
63.64000000,0.78463600,7.70600000,0.02605144,506.54045882,0.02571789,519.73656944,0.00070271,0.04000553,577.44528593,-0.02045369,-0.01955184,0.00000000,0.00000000,0.00000000,0.00000000
65.14000000,0.81694800,7.76900000,0.02711089,510.68165385,0.02674990,524.52668742,0.00070198,0.04111469,580.49838775,-0.02101913,-0.02009557,0.00000000,0.00000000,0.00000000,0.00000000
66.64000000,0.84975700,7.81900000,0.02816656,513.96831657,0.02777717,528.44503371,0.00061543,0.04227871,583.58974180,-0.02166652,-0.02061218,0.00000000,0.00000000,0.00000000,0.00000000
68.14000000,0.88236500,7.87300000,0.02930322,517.51791231,0.02888209,532.68285470,0.00065751,0.04335185,586.28898828,-0.02223130,-0.02112055,0.00000000,0.00000000,0.00000000,0.00000000
69.64000000,0.91540500,7.91900000,0.03041778,520.54164202,0.02996433,536.37536201,0.00074978,0.04448830,589.44548375,-0.02286717,-0.02162113,0.00000000,0.00000000,0.00000000,0.00000000
71.14000000,0.94871000,7.97600000,0.03151400,524.28843752,0.03102763,540.81086334,0.00077032,0.04562603,592.05572063,-0.02347758,-0.02214845,0.00000000,0.00000000,0.00000000,0.00000000
72.64000000,0.98185000,8.01800000,0.03259922,527.04923421,0.03207914,544.23062932,0.00069136,0.04675381,595.01162376,-0.02409646,-0.02265735,0.00000000,0.00000000,0.00000000,0.00000000
74.14000000,1.01535300,8.07100000,0.03374689,530.53309669,0.03318996,548.43693816,0.00067619,0.04789929,597.63737524,-0.02471216,-0.02318714,0.00000000,0.00000000,0.00000000,0.00000000
75.64000000,1.04879000,8.11100000,0.03487256,533.16242687,0.03427828,551.75516322,0.00075364,0.04903570,600.40183504,-0.02526631,-0.02376939,0.00000000,0.00000000,0.00000000,0.00000000
77.14000000,1.08365100,8.15700000,0.03599078,536.18615658,0.03535824,555.48391339,0.00074575,0.05018650,602.83300885,-0.02588793,-0.02429857,0.00000000,0.00000000,0.00000000,0.00000000
78.64000000,1.11692300,8.19500000,0.03711278,538.68402025,0.03644068,558.67608058,0.00070979,0.05132724,605.61091617,-0.02645240,-0.02487485,0.00000000,0.00000000,0.00000000,0.00000000
80.14000000,1.15138600,8.24100000,0.03830089,541.70774995,0.03758562,562.45563829,0.00073702,0.05247877,608.05264211,-0.02704862,-0.02543016,0.00000000,0.00000000,0.00000000,0.00000000
81.64000000,1.18594900,8.27700000,0.03943389,544.07414711,0.03867623,565.52910658,0.00084252,0.05363853,610.64380317,-0.02769577,-0.02594276,0.00000000,0.00000000,0.00000000,0.00000000
83.14000000,1.22047800,8.32100000,0.04057789,546.96641031,0.03977622,569.16115253,0.00078497,0.05480845,613.03694146,-0.02831987,-0.02648858,0.00000000,0.00000000,0.00000000,0.00000000
84.64000000,1.25570200,8.35600000,0.04173656,549.26707421,0.04088909,572.19158997,0.00075572,0.05596585,615.56702130,-0.02893420,-0.02703164,0.00000000,0.00000000,0.00000000,0.00000000
86.14000000,1.29069600,8.39300000,0.04292467,551.69920463,0.04202895,575.38070909,0.00076893,0.05711653,617.74799514,-0.02954422,-0.02757231,0.00000000,0.00000000,0.00000000,0.00000000
87.64000000,1.32585400,8.42500000,0.04409822,553.80266877,0.04315357,578.22438192,0.00079659,0.05827117,620.28612949,-0.03011918,-0.02815199,0.00000000,0.00000000,0.00000000,0.00000000
89.14000000,1.36134400,8.46400000,0.04527167,556.36626569,0.04427682,581.55389382,0.00079570,0.05944370,622.41949678,-0.03074969,-0.02869402,0.00000000,0.00000000,0.00000000,0.00000000
90.64000000,1.39690000,8.49400000,0.04647456,558.33826333,0.04542695,584.28678597,0.00073849,0.06062744,624.77485236,-0.03137023,-0.02925721,0.00000000,0.00000000,0.00000000,0.00000000
92.14000000,1.43225700,8.53100000,0.04763678,560.77039374,0.04653694,587.48368837,0.00078647,0.06178642,626.97870593,-0.03199492,-0.02979150,0.00000000,0.00000000,0.00000000,0.00000000
93.64000000,1.46787800,8.56000000,0.04881033,562.67665812,0.04765651,590.14109336,0.00072264,0.06297459,629.27572183,-0.03260864,-0.03036595,0.00000000,0.00000000,0.00000000,0.00000000
95.14000000,1.50386600,8.59300000,0.04999122,564.84585552,0.04878180,593.08319020,0.00067292,0.06414545,631.28435213,-0.03319535,-0.03095009,0.00000000,0.00000000,0.00000000,0.00000000
96.64000000,1.54058000,8.62000000,0.05123811,566.62065339,0.04996862,595.65322538,0.00076284,0.06532390,633.58407025,-0.03381005,-0.03151385,0.00000000,0.00000000,0.00000000,0.00000000
98.14000000,1.57703000,8.65200000,0.05246678,568.72411753,0.05113672,598.56323942,0.00078308,0.06652648,635.55035475,-0.03448183,-0.03204465,0.00000000,0.00000000,0.00000000,0.00000000
99.64000000,1.61288300,8.67800000,0.05365856,570.43318215,0.05226845,601.04180274,0.00074738,0.06771975,637.72684386,-0.03514053,-0.03257922,0.00000000,0.00000000,0.00000000,0.00000000
101.14000000,1.64956500,8.70900000,0.05487611,572.47091303,0.05342333,603.88589047,0.00073239,0.06894295,639.78516495,-0.03579985,-0.03314310,0.00000000,0.00000000,0.00000000,0.00000000
102.64000000,1.68641200,8.73400000,0.05612678,574.11424440,0.05460823,606.33742701,0.00079425,0.07009307,641.80055435,-0.03640652,-0.03368655,0.00000000,0.00000000,0.00000000,0.00000000
104.14000000,1.72292800,8.76200000,0.05735178,575.95477552,0.05576746,608.98680582,0.00078640,0.07130708,643.71898494,-0.03701346,-0.03429362,0.00000000,0.00000000,0.00000000,0.00000000
105.64000000,1.75994000,8.78500000,0.05856578,577.46664037,0.05691495,611.28642331,0.00073719,0.07252216,645.85519892,-0.03766138,-0.03486079,0.00000000,0.00000000,0.00000000,0.00000000
107.14000000,1.79682000,8.81200000,0.05982744,579.24143824,0.05810611,613.89597321,0.00075687,0.07374037,647.71291640,-0.03827436,-0.03546601,0.00000000,0.00000000,0.00000000,0.00000000
108.64000000,1.83429600,8.83400000,0.06110011,580.68756984,0.05930621,616.16764488,0.00081819,0.07496686,649.65092408,-0.03892973,-0.03603713,0.00000000,0.00000000,0.00000000,0.00000000
110.14000000,1.87124200,8.86100000,0.06232144,582.46236771,0.06045656,618.76226380,0.00079674,0.07614444,651.56077494,-0.03953201,-0.03661243,0.00000000,0.00000000,0.00000000,0.00000000
111.64000000,1.90881800,8.88100000,0.06356467,583.77703280,0.06162616,620.88462530,0.00080249,0.07736792,653.50434569,-0.04016570,-0.03720221,0.00000000,0.00000000,0.00000000,0.00000000
113.14000000,1.94626100,8.90500000,0.06482644,585.35463091,0.06281182,623.30109037,0.00080843,0.07858415,655.23230719,-0.04079346,-0.03779069,0.00000000,0.00000000,0.00000000,0.00000000
114.64000000,1.98423300,8.92400000,0.06610289,586.60356274,0.06400984,625.37975287,0.00081455,0.07981131,657.18565988,-0.04148145,-0.03832985,0.00000000,0.00000000,0.00000000,0.00000000
116.14000000,2.02170900,8.94800000,0.06734989,588.18116085,0.06517884,627.79509668,0.00081360,0.08105831,658.94077945,-0.04213854,-0.03891977,0.00000000,0.00000000,0.00000000,0.00000000
117.64000000,2.06007800,8.96600000,0.06862267,589.36435943,0.06637059,629.80811341,0.00079890,0.08227634,660.75189869,-0.04278720,-0.03948913,0.00000000,0.00000000,0.00000000,0.00000000
119.14000000,2.09758800,8.98900000,0.06988789,590.87622428,0.06755387,632.17131619,0.00080461,0.08354702,662.52956790,-0.04346349,-0.04008353,0.00000000,0.00000000,0.00000000,0.00000000
120.64000000,2.13625500,9.00700000,0.07117900,592.05942286,0.06875991,634.20162052,0.00083788,0.08476909,664.27832293,-0.04412146,-0.04064763,0.00000000,0.00000000,0.00000000,0.00000000
122.14000000,2.17482300,9.02600000,0.07245911,593.30835470,0.06995425,636.29895069,0.00080268,0.08599357,665.88781162,-0.04476173,-0.04123184,0.00000000,0.00000000,0.00000000,0.00000000
123.64000000,2.21276200,9.04200000,0.07375389,594.36008677,0.07116082,638.19645457,0.00080854,0.08721825,667.86131239,-0.04540899,-0.04180926,0.00000000,0.00000000,0.00000000,0.00000000
125.14000000,2.25152800,9.06300000,0.07504878,595.74048511,0.07236604,640.45008039,0.00075298,0.08847347,669.42556273,-0.04608691,-0.04238656,0.00000000,0.00000000,0.00000000,0.00000000
126.64000000,2.29039500,9.07900000,0.07632522,596.79221718,0.07355267,642.34251578,0.00080682,0.08969676,671.04358533,-0.04672998,-0.04296678,0.00000000,0.00000000,0.00000000,0.00000000
128.14000000,2.32969100,9.09900000,0.07765311,598.10688227,0.07478563,644.55174246,0.00082645,0.09091521,672.66131534,-0.04734974,-0.04356547,0.00000000,0.00000000,0.00000000,0.00000000
129.63000000,2.36898800,9.11400000,0.07896256,599.09288109,0.07599998,646.39878599,0.00080464,0.09221838,674.41187953,-0.04809380,-0.04412458,0.00000000,0.00000000,0.00000000,0.00000000
131.13000000,2.40838400,9.13100000,0.08027200,600.21034641,0.07721286,648.39043134,0.00079214,0.09348724,675.99732843,-0.04875683,-0.04473041,0.00000000,0.00000000,0.00000000,0.00000000
132.64000000,2.44778000,9.14500000,0.08160000,601.13061198,0.07844143,650.18286991,0.00074704,0.09469758,677.61868985,-0.04939209,-0.04530549,0.00000000,0.00000000,0.00000000,0.00000000
134.13000000,2.48724200,9.16300000,0.08293156,602.31381056,0.07967177,652.26463180,0.00084932,0.09595035,679.12627627,-0.05004506,-0.04590528,0.00000000,0.00000000,0.00000000,0.00000000
135.63000000,2.52696900,9.17600000,0.08427044,603.16834286,0.08090736,653.99760719,0.00085503,0.09722772,680.72631420,-0.05072241,-0.04650531,0.00000000,0.00000000,0.00000000,0.00000000
137.14000000,2.56672800,9.19300000,0.08559100,604.28580819,0.08212454,656.00723480,0.00082400,0.09853654,682.35088551,-0.05140815,-0.04712840,0.00000000,0.00000000,0.00000000,0.00000000
138.63000000,2.60688600,9.20600000,0.08696311,605.14034050,0.08338767,657.76522717,0.00089382,0.09975126,683.84088985,-0.05204353,-0.04770774,0.00000000,0.00000000,0.00000000,0.00000000
140.13000000,2.64707500,9.22000000,0.08829100,606.06060606,0.08460858,659.57030303,0.00082491,0.10100101,685.35760729,-0.05272985,-0.04827115,0.00000000,0.00000000,0.00000000,0.00000000
141.63000000,2.68753100,9.23300000,0.08965567,606.91513837,0.08586174,661.32851971,0.00087794,0.10232829,686.93050364,-0.05344139,-0.04888690,0.00000000,0.00000000,0.00000000,0.00000000
143.13000000,2.72782000,9.24700000,0.09094678,607.83540393,0.08704592,663.11607534,0.00068800,0.10357501,688.37735779,-0.05407555,-0.04949947,0.00000000,0.00000000,0.00000000,0.00000000
144.63000000,2.76748000,9.25800000,0.09235189,608.55846973,0.08833307,664.75999391,0.00080149,0.10486618,689.85752955,-0.05480387,-0.05006232,0.00000000,0.00000000,0.00000000,0.00000000
146.13000000,2.80810100,9.27300000,0.09371289,609.54446855,0.08957823,666.66664160,0.00082753,0.10614911,691.33467743,-0.05548641,-0.05066270,0.00000000,0.00000000,0.00000000,0.00000000
147.63000000,2.84935000,9.28400000,0.09505911,610.26753435,0.09080834,668.27902370,0.00081961,0.10742709,692.81106389,-0.05616166,-0.05126543,0.00000000,0.00000000,0.00000000,0.00000000
149.13000000,2.89033500,9.29600000,0.09641644,611.05633340,0.09204708,669.97221242,0.00077175,0.10870051,694.21315920,-0.05685553,-0.05184497,0.00000000,0.00000000,0.00000000,0.00000000
150.63000000,2.93035900,9.30600000,0.09781789,611.71366594,0.09332447,671.55020535,0.00086453,0.10999496,695.70627095,-0.05750812,-0.05248685,0.00000000,0.00000000,0.00000000,0.00000000
152.13000000,2.97220500,9.31900000,0.09922667,612.56819825,0.09460690,673.35129867,0.00097709,0.11130427,697.13852703,-0.05820742,-0.05309685,0.00000000,0.00000000,0.00000000,0.00000000
153.63000000,3.01332200,9.32900000,0.10058044,613.22553080,0.09583772,674.90402723,0.00081570,0.11261264,698.42458235,-0.05891517,-0.05369747,0.00000000,0.00000000,0.00000000,0.00000000
155.13000000,3.05443900,9.34000000,0.10198556,613.94859660,0.09711360,676.56248530,0.00081466,0.11390838,699.92642250,-0.05959392,-0.05431446,0.00000000,0.00000000,0.00000000,0.00000000
156.63000000,3.09582200,9.34900000,0.10338344,614.54019589,0.09838132,678.07347809,0.00091396,0.11523242,701.30241472,-0.06028573,-0.05494670,0.00000000,0.00000000,0.00000000,0.00000000
158.13000000,3.13740100,9.36000000,0.10475900,615.26326168,0.09962721,679.71762571,0.00088586,0.11652507,702.73305478,-0.06096051,-0.05556457,0.00000000,0.00000000,0.00000000,0.00000000
159.63000000,3.17921400,9.36900000,0.10615311,615.85486097,0.10088833,681.22977046,0.00083811,0.11785604,703.96994807,-0.06165894,-0.05619710,0.00000000,0.00000000,0.00000000,0.00000000
161.13000000,3.22092700,9.37900000,0.10758400,616.51219352,0.10218107,682.83904135,0.00079046,0.11915147,705.48196049,-0.06233278,-0.05681869,0.00000000,0.00000000,0.00000000,0.00000000
162.63000000,3.26264000,9.38700000,0.10900756,617.03805955,0.10346552,684.29987011,0.00091574,0.12044939,706.77454954,-0.06302254,-0.05742685,0.00000000,0.00000000,0.00000000,0.00000000
164.13000000,3.30428800,9.39700000,0.11038700,617.69539210,0.10470860,685.88093335,0.00088798,0.12176505,708.08192306,-0.06373688,-0.05802817,0.00000000,0.00000000,0.00000000,0.00000000
165.63000000,3.34659600,9.40500000,0.11183256,618.22125813,0.10600960,687.35852133,0.00082044,0.12312424,709.42250926,-0.06445752,-0.05866672,0.00000000,0.00000000,0.00000000,0.00000000
167.13000000,3.38834200,9.41400000,0.11327822,618.81285742,0.10730902,688.91087780,0.00091203,0.12443625,710.73179843,-0.06515071,-0.05928554,0.00000000,0.00000000,0.00000000,0.00000000
168.63000000,3.43078400,9.42200000,0.11468700,619.33872346,0.10857365,690.36882364,0.00084486,0.12578499,712.14461181,-0.06585582,-0.05992917,0.00000000,0.00000000,0.00000000,0.00000000
170.13000000,3.47352300,9.43000000,0.11612167,619.86458950,0.10985988,691.84429874,0.00083740,0.12714900,713.34542276,-0.06659734,-0.06055166,0.00000000,0.00000000,0.00000000,0.00000000
171.63000000,3.51622900,9.43800000,0.11759311,620.39045553,0.11117736,693.34409930,0.00090234,0.12846219,714.66226377,-0.06727375,-0.06118844,0.00000000,0.00000000,0.00000000,0.00000000
173.13000000,3.55906700,9.44500000,0.11904233,620.85058831,0.11247326,694.75809100,0.00093395,0.12980287,715.92574472,-0.06798509,-0.06181778,0.00000000,0.00000000,0.00000000,0.00000000
174.63000000,3.60223700,9.45200000,0.12046589,621.31072109,0.11374457,696.15746939,0.00087344,0.13116738,717.20849289,-0.06870533,-0.06246205,0.00000000,0.00000000,0.00000000,0.00000000
176.13000000,3.64507500,9.45800000,0.12197033,621.70512062,0.11508637,697.53470142,0.00092478,0.13255234,718.50816222,-0.06946388,-0.06308847,0.00000000,0.00000000,0.00000000,0.00000000
177.63000000,3.68788000,9.46600000,0.12341233,622.23098666,0.11637078,699.02196459,0.00086462,0.13384963,719.67107880,-0.07013332,-0.06371631,0.00000000,0.00000000,0.00000000,0.00000000
179.13000000,3.73161400,9.47200000,0.12488367,622.62538618,0.11767962,700.38112737,0.00087653,0.13521494,720.96078605,-0.07086263,-0.06435231,0.00000000,0.00000000,0.00000000,0.00000000
180.63000000,3.77514800,9.47900000,0.12636978,623.08551896,0.11899988,701.82469753,0.00085583,0.13661649,722.27894809,-0.07161309,-0.06500340,0.00000000,0.00000000,0.00000000,0.00000000
182.13000000,3.81851700,9.48400000,0.12781544,623.41418524,0.12028253,703.09614640,0.00082221,0.13795306,723.47624981,-0.07231544,-0.06563763,0.00000000,0.00000000,0.00000000,0.00000000
183.63000000,3.86185100,9.49000000,0.12929778,623.80858476,0.12159600,704.46564853,0.00077546,0.13935119,724.72023467,-0.07307152,-0.06627968,0.00000000,0.00000000,0.00000000,0.00000000
185.13000000,3.90621300,9.49600000,0.13085733,624.20298429,0.12297605,705.88452227,0.00093029,0.14071599,725.86581652,-0.07378621,-0.06692978,0.00000000,0.00000000,0.00000000,0.00000000
186.63000000,3.95007900,9.50100000,0.13235089,624.53165056,0.12429590,707.18896965,0.00096185,0.14210987,727.18699814,-0.07454469,-0.06756518,0.00000000,0.00000000,0.00000000,0.00000000
188.13000000,3.99401000,9.50600000,0.13384067,624.86031683,0.12561069,708.49203821,0.00094764,0.14347060,728.40983212,-0.07523756,-0.06823304,0.00000000,0.00000000,0.00000000,0.00000000
189.63000000,4.03814000,9.51200000,0.13531944,625.25471636,0.12691406,709.86383722,0.00082324,0.14492452,729.62637817,-0.07604461,-0.06887991,0.00000000,0.00000000,0.00000000,0.00000000
191.13000000,4.08306400,9.51700000,0.13689733,625.58338263,0.12830291,711.22407949,0.00096446,0.14634404,730.97294654,-0.07681249,-0.06953154,0.00000000,0.00000000,0.00000000,0.00000000
192.63000000,4.12762500,9.52100000,0.13838722,625.84631565,0.12961254,712.45544881,0.00087277,0.14773120,732.06791016,-0.07750858,-0.07022262,0.00000000,0.00000000,0.00000000,0.00000000
194.13000000,4.17192100,9.52500000,0.13989533,626.10924867,0.13093645,713.69901071,0.00078112,0.14917862,733.36253293,-0.07828848,-0.07089014,0.00000000,0.00000000,0.00000000,0.00000000
195.63000000,4.21674500,9.53000000,0.14146956,626.43791494,0.13231652,715.05980835,0.00090235,0.15059315,734.48122483,-0.07903288,-0.07156026,0.00000000,0.00000000,0.00000000,0.00000000
197.13000000,4.26160300,9.53400000,0.14300722,626.70084796,0.13366270,716.32359539,0.00090133,0.15206813,735.72331705,-0.07982396,-0.07224418,0.00000000,0.00000000,0.00000000,0.00000000
198.63000000,4.30709000,9.53900000,0.14452644,627.02951423,0.13499097,717.65186048,0.00081661,0.15350950,736.94262915,-0.08057697,-0.07293254,0.00000000,0.00000000,0.00000000,0.00000000
200.13000000,4.35214700,9.54300000,0.14611911,627.29244725,0.13638155,718.95186205,0.00081548,0.15494888,738.16245614,-0.08133145,-0.07361743,0.00000000,0.00000000,0.00000000,0.00000000
201.63000000,4.39723800,9.54600000,0.14770078,627.48964701,0.13776062,720.17035592,0.00096797,0.15638644,739.30552652,-0.08209744,-0.07428900,0.00000000,0.00000000,0.00000000,0.00000000
203.13000000,4.44318800,9.55000000,0.14923478,627.75258003,0.13909631,721.43509681,0.00089645,0.15791557,740.51841248,-0.08294026,-0.07497531,0.00000000,0.00000000,0.00000000,0.00000000
204.63000000,4.48870900,9.55300000,0.15081644,627.94977979,0.14047164,722.65493287,0.00083147,0.15934893,741.66200502,-0.08369118,-0.07565775,0.00000000,0.00000000,0.00000000,0.00000000
206.13000000,4.53502300,9.55600000,0.15243489,628.14697956,0.14187700,723.89849459,0.00095762,0.16084195,742.92958569,-0.08451298,-0.07632897,0.00000000,0.00000000,0.00000000,0.00000000
207.63000000,4.58021200,9.55900000,0.15401667,628.34417932,0.14324861,725.11965534,0.00089273,0.16236432,744.14336138,-0.08533935,-0.07702497,0.00000000,0.00000000,0.00000000,0.00000000
209.13000000,4.62662600,9.56200000,0.15563511,628.54137908,0.14465007,726.36448646,0.00095516,0.16388418,745.35723394,-0.08616632,-0.07771786,0.00000000,0.00000000,0.00000000,0.00000000
210.63000000,4.67290700,9.56500000,0.15725356,628.73857885,0.14604957,727.60995589,0.00095383,0.16534018,746.44713782,-0.08689123,-0.07844895,0.00000000,0.00000000,0.00000000,0.00000000
212.13000000,4.71918900,9.56700000,0.15887200,628.87004536,0.14744712,728.77988720,0.00101580,0.16688648,747.68461991,-0.08771106,-0.07917542,0.00000000,0.00000000,0.00000000,0.00000000
213.63000000,4.76583400,9.57000000,0.16049056,629.06724512,0.14884281,730.02659677,0.00088775,0.16839962,748.89922256,-0.08850776,-0.07989186,0.00000000,0.00000000,0.00000000,0.00000000
215.13000000,4.81238100,9.57200000,0.16214578,629.19871163,0.15026810,731.22062610,0.00088649,0.16994191,749.98080951,-0.08932001,-0.08062190,0.00000000,0.00000000,0.00000000,0.00000000
216.63000000,4.86021800,9.57500000,0.16383789,629.39591139,0.15172307,732.51480879,0.00101166,0.17151173,751.24189402,-0.09014166,-0.08137008,0.00000000,0.00000000,0.00000000,0.00000000
218.13000000,4.90765900,9.57700000,0.16553000,629.52737790,0.15317592,733.73304476,0.00101019,0.17307964,752.42493049,-0.09100683,-0.08207281,0.00000000,0.00000000,0.00000000,0.00000000
219.63000000,4.95456900,9.57900000,0.16722211,629.65884441,0.15462666,734.95172565,0.00107197,0.17464441,753.68631486,-0.09182608,-0.08281833,0.00000000,0.00000000,0.00000000,0.00000000
221.13000000,5.00214200,9.58000000,0.16887733,629.72457766,0.15604374,736.07078507,0.00094434,0.00000000,0.00000000,0.00000000,0.00000000,0.00000000,0.00000000,0.00000000,0.00000000
222.63000000,5.04998000,9.58200000,0.17056933,629.85604417,0.15749024,737.29016972,0.00094297,0.00000000,0.00000000,0.00000000,0.00000000,0.00000000,0.00000000,0.00000000,0.00000000
224.13000000,5.09844700,9.58400000,0.17226144,629.98751068,0.15893474,738.51006925,0.00094161,0.00000000,0.00000000,0.00000000,0.00000000,0.00000000,0.00000000,0.00000000,0.00000000
225.63000000,5.14628300,9.58600000,0.17399033,630.11897719,0.16040849,739.75358807,0.00100310,0.00000000,0.00000000,0.00000000,0.00000000,0.00000000,0.00000000,0.00000000,0.00000000
227.13000000,5.19438500,9.58700000,0.17575589,630.18471045,0.16191125,740.94338439,0.00093881,0.00000000,0.00000000,0.00000000,0.00000000,0.00000000,0.00000000,0.00000000,0.00000000
228.63000000,5.24301700,9.58900000,0.17748478,630.31617695,0.16338062,742.18770355,0.00099993,0.00000000,0.00000000,0.00000000,0.00000000,0.00000000,0.00000000,0.00000000,0.00000000
230.13000000,5.29181500,9.58900000,0.17928722,630.31617695,0.16491021,743.32381344,0.00106100,0.00000000,0.00000000,0.00000000,0.00000000,0.00000000,0.00000000,0.00000000,0.00000000
231.63000000,5.34031500,9.59000000,0.18097922,630.38191021,0.16634394,744.46793802,0.00087216,0.00000000,0.00000000,0.00000000,0.00000000,0.00000000,0.00000000,0.00000000,0.00000000
233.13000000,5.38954300,9.59100000,0.18281844,630.44764346,0.16790010,745.70510094,0.00093321,0.00000000,0.00000000,0.00000000,0.00000000,0.00000000,0.00000000,0.00000000,0.00000000
234.63000000,5.43857300,9.59100000,0.18458411,630.44764346,0.16939175,746.81826133,0.00099413,0.00000000,0.00000000,0.00000000,0.00000000,0.00000000,0.00000000,0.00000000,0.00000000
236.13000000,5.48813100,9.59300000,0.18642322,630.57910997,0.17094309,748.13369952,0.00099240,0.00000000,0.00000000,0.00000000,0.00000000,0.00000000,0.00000000,0.00000000,0.00000000
237.63000000,5.53805500,9.59200000,0.18826256,630.51337672,0.17249220,749.21543633,0.00105279,0.00000000,0.00000000,0.00000000,0.00000000,0.00000000,0.00000000,0.00000000,0.00000000
239.13000000,5.58774700,9.59300000,0.19010167,630.57910997,0.17403874,750.45324974,0.00105098,0.00000000,0.00000000,0.00000000,0.00000000,0.00000000,0.00000000,0.00000000,0.00000000
240.63000000,5.63720700,9.59300000,0.19190411,630.57910997,0.17555212,751.58983356,0.00092609,0.00000000,0.00000000,0.00000000,0.00000000,0.00000000,0.00000000,0.00000000,0.00000000
242.13000000,5.68769300,9.59300000,0.19381689,630.57910997,0.17715564,752.79599126,0.00098606,0.00000000,0.00000000,0.00000000,0.00000000,0.00000000,0.00000000,0.00000000,0.00000000
243.63000000,5.73814600,9.59400000,0.19576644,630.64484323,0.00000000,0.00000000,0.00000000,0.00000000,0.00000000,0.00000000,0.00000000,0.00000000,0.00000000,0.00000000,0.00000000
245.13000000,5.78859800,9.59300000,0.19760567,630.57910997,0.00000000,0.00000000,0.00000000,0.00000000,0.00000000,0.00000000,0.00000000,0.00000000,0.00000000,0.00000000,0.00000000
246.63000000,5.83951400,9.59300000,0.19955522,630.57910997,0.00000000,0.00000000,0.00000000,0.00000000,0.00000000,0.00000000,0.00000000,0.00000000,0.00000000,0.00000000,0.00000000
248.13000000,5.89086100,9.59300000,0.20154156,630.57910997,0.00000000,0.00000000,0.00000000,0.00000000,0.00000000,0.00000000,0.00000000,0.00000000,0.00000000,0.00000000,0.00000000
249.63000000,5.94224200,9.59200000,0.20352800,630.51337672,0.00000000,0.00000000,0.00000000,0.00000000,0.00000000,0.00000000,0.00000000,0.00000000,0.00000000,0.00000000,0.00000000
251.13000000,5.99378700,9.59100000,0.20551433,630.44764346,0.00000000,0.00000000,0.00000000,0.00000000,0.00000000,0.00000000,0.00000000,0.00000000,0.00000000,0.00000000,0.00000000
252.63000000,6.04500100,9.59000000,0.20757411,630.38191021,0.00000000,0.00000000,0.00000000,0.00000000,0.00000000,0.00000000,0.00000000,0.00000000,0.00000000,0.00000000,0.00000000
254.13000000,6.09674500,9.59000000,0.20963411,630.38191021,0.00000000,0.00000000,0.00000000,0.00000000,0.00000000,0.00000000,0.00000000,0.00000000,0.00000000,0.00000000,0.00000000
255.63000000,6.14925100,9.59000000,0.21173067,630.38191021,0.00000000,0.00000000,0.00000000,0.00000000,0.00000000,0.00000000,0.00000000,0.00000000,0.00000000,0.00000000,0.00000000
257.13000000,6.20215400,9.58900000,0.21386422,630.31617695,0.00000000,0.00000000,0.00000000,0.00000000,0.00000000,0.00000000,0.00000000,0.00000000,0.00000000,0.00000000,0.00000000
258.63000000,6.25479200,9.58800000,0.21596100,630.25044370,0.00000000,0.00000000,0.00000000,0.00000000,0.00000000,0.00000000,0.00000000,0.00000000,0.00000000,0.00000000,0.00000000
260.13000000,6.30789300,9.58600000,0.21820467,630.11897719,0.00000000,0.00000000,0.00000000,0.00000000,0.00000000,0.00000000,0.00000000,0.00000000,0.00000000,0.00000000,0.00000000
261.63000000,6.36145800,9.58600000,0.22044856,630.11897719,0.00000000,0.00000000,0.00000000,0.00000000,0.00000000,0.00000000,0.00000000,0.00000000,0.00000000,0.00000000,0.00000000
263.13000000,6.41465800,9.58300000,0.22269244,629.92177743,0.00000000,0.00000000,0.00000000,0.00000000,0.00000000,0.00000000,0.00000000,0.00000000,0.00000000,0.00000000,0.00000000
264.63000000,6.46805800,9.58100000,0.22500978,629.79031092,0.00000000,0.00000000,0.00000000,0.00000000,0.00000000,0.00000000,0.00000000,0.00000000,0.00000000,0.00000000,0.00000000
266.13000000,6.52228500,9.58000000,0.22725367,629.72457766,0.00000000,0.00000000,0.00000000,0.00000000,0.00000000,0.00000000,0.00000000,0.00000000,0.00000000,0.00000000,0.00000000
267.63000000,6.57690900,9.57800000,0.22975489,629.59311115,0.00000000,0.00000000,0.00000000,0.00000000,0.00000000,0.00000000,0.00000000,0.00000000,0.00000000,0.00000000,0.00000000
269.13000000,6.63146700,9.57700000,0.23221944,629.52737790,0.00000000,0.00000000,0.00000000,0.00000000,0.00000000,0.00000000,0.00000000,0.00000000,0.00000000,0.00000000,0.00000000
270.63000000,6.68625600,9.57400000,0.23464722,629.33017814,0.00000000,0.00000000,0.00000000,0.00000000,0.00000000,0.00000000,0.00000000,0.00000000,0.00000000,0.00000000,0.00000000
272.13000000,6.74107900,9.57100000,0.23725889,629.13297837,0.00000000,0.00000000,0.00000000,0.00000000,0.00000000,0.00000000,0.00000000,0.00000000,0.00000000,0.00000000,0.00000000
273.63000000,6.79633200,9.56900000,0.23979700,629.00151186,0.00000000,0.00000000,0.00000000,0.00000000,0.00000000,0.00000000,0.00000000,0.00000000,0.00000000,0.00000000,0.00000000
275.13000000,6.85168400,9.56700000,0.24244533,628.87004536,0.00000000,0.00000000,0.00000000,0.00000000,0.00000000,0.00000000,0.00000000,0.00000000,0.00000000,0.00000000,0.00000000
276.63000000,6.90759900,9.56300000,0.24520422,628.60711234,0.00000000,0.00000000,0.00000000,0.00000000,0.00000000,0.00000000,0.00000000,0.00000000,0.00000000,0.00000000,0.00000000
278.13000000,6.96351500,9.56000000,0.24796300,628.40991257,0.00000000,0.00000000,0.00000000,0.00000000,0.00000000,0.00000000,0.00000000,0.00000000,0.00000000,0.00000000,0.00000000
279.63000000,7.01986000,9.55700000,0.25086878,628.21271281,0.00000000,0.00000000,0.00000000,0.00000000,0.00000000,0.00000000,0.00000000,0.00000000,0.00000000,0.00000000,0.00000000
281.13000000,7.07709900,9.55400000,0.25377478,628.01551305,0.00000000,0.00000000,0.00000000,0.00000000,0.00000000,0.00000000,0.00000000,0.00000000,0.00000000,0.00000000,0.00000000
282.63000000,7.13334400,9.55000000,0.25686444,627.75258003,0.00000000,0.00000000,0.00000000,0.00000000,0.00000000,0.00000000,0.00000000,0.00000000,0.00000000,0.00000000,0.00000000
284.13000000,7.19012100,9.54600000,0.25995444,627.48964701,0.00000000,0.00000000,0.00000000,0.00000000,0.00000000,0.00000000,0.00000000,0.00000000,0.00000000,0.00000000,0.00000000
285.63000000,7.24742600,9.54200000,0.26319133,627.22671399,0.00000000,0.00000000,0.00000000,0.00000000,0.00000000,0.00000000,0.00000000,0.00000000,0.00000000,0.00000000,0.00000000
287.13000000,7.30506200,9.53900000,0.26653867,627.02951423,0.00000000,0.00000000,0.00000000,0.00000000,0.00000000,0.00000000,0.00000000,0.00000000,0.00000000,0.00000000,0.00000000
288.63000000,7.36312800,9.53300000,0.26995956,626.63511470,0.00000000,0.00000000,0.00000000,0.00000000,0.00000000,0.00000000,0.00000000,0.00000000,0.00000000,0.00000000,0.00000000
290.13000000,7.42112900,9.52800000,0.27349089,626.30644843,0.00000000,0.00000000,0.00000000,0.00000000,0.00000000,0.00000000,0.00000000,0.00000000,0.00000000,0.00000000,0.00000000
291.63000000,7.47886500,9.52300000,0.27720600,625.97778216,0.00000000,0.00000000,0.00000000,0.00000000,0.00000000,0.00000000,0.00000000,0.00000000,0.00000000,0.00000000,0.00000000
293.13000000,7.53676600,9.51700000,0.28099467,625.58338263,0.00000000,0.00000000,0.00000000,0.00000000,0.00000000,0.00000000,0.00000000,0.00000000,0.00000000,0.00000000,0.00000000
294.63000000,7.59579200,9.51200000,0.28500400,625.25471636,0.00000000,0.00000000,0.00000000,0.00000000,0.00000000,0.00000000,0.00000000,0.00000000,0.00000000,0.00000000,0.00000000
296.13000000,7.65438800,9.50400000,0.28908700,624.72885033,0.00000000,0.00000000,0.00000000,0.00000000,0.00000000,0.00000000,0.00000000,0.00000000,0.00000000,0.00000000,0.00000000
297.63000000,7.71324900,9.49800000,0.29335389,624.33445080,0.00000000,0.00000000,0.00000000,0.00000000,0.00000000,0.00000000,0.00000000,0.00000000,0.00000000,0.00000000,0.00000000
299.13000000,7.77273900,9.49000000,0.29791500,623.80858476,0.00000000,0.00000000,0.00000000,0.00000000,0.00000000,0.00000000,0.00000000,0.00000000,0.00000000,0.00000000,0.00000000
300.63000000,7.83216300,9.48200000,0.30251289,623.28271873,0.00000000,0.00000000,0.00000000,0.00000000,0.00000000,0.00000000,0.00000000,0.00000000,0.00000000,0.00000000,0.00000000
302.13000000,7.89211500,9.47400000,0.30736833,622.75685269,0.00000000,0.00000000,0.00000000,0.00000000,0.00000000,0.00000000,0.00000000,0.00000000,0.00000000,0.00000000,0.00000000
303.63000000,7.95220100,9.46300000,0.31237089,622.03378689,0.00000000,0.00000000,0.00000000,0.00000000,0.00000000,0.00000000,0.00000000,0.00000000,0.00000000,0.00000000,0.00000000
305.13000000,8.01215400,9.45300000,0.31759400,621.37645435,0.00000000,0.00000000,0.00000000,0.00000000,0.00000000,0.00000000,0.00000000,0.00000000,0.00000000,0.00000000,0.00000000
306.63000000,8.07237300,9.44000000,0.32300133,620.52192204,0.00000000,0.00000000,0.00000000,0.00000000,0.00000000,0.00000000,0.00000000,0.00000000,0.00000000,0.00000000,0.00000000
308.13000000,8.13279000,9.42900000,0.32851878,619.79885624,0.00000000,0.00000000,0.00000000,0.00000000,0.00000000,0.00000000,0.00000000,0.00000000,0.00000000,0.00000000,0.00000000
309.63000000,8.19334000,9.41300000,0.33433056,618.74712417,0.00000000,0.00000000,0.00000000,0.00000000,0.00000000,0.00000000,0.00000000,0.00000000,0.00000000,0.00000000,0.00000000
311.13000000,8.25438600,9.40000000,0.34032633,617.89259186,0.00000000,0.00000000,0.00000000,0.00000000,0.00000000,0.00000000,0.00000000,0.00000000,0.00000000,0.00000000,0.00000000
312.63000000,8.31529900,9.38100000,0.34643233,616.64366003,0.00000000,0.00000000,0.00000000,0.00000000,0.00000000,0.00000000,0.00000000,0.00000000,0.00000000,0.00000000,0.00000000
314.13000000,8.37670900,9.36400000,0.35268556,615.52619470,0.00000000,0.00000000,0.00000000,0.00000000,0.00000000,0.00000000,0.00000000,0.00000000,0.00000000,0.00000000,0.00000000
315.63000000,8.43768900,9.34300000,0.35897544,614.14579636,0.00000000,0.00000000,0.00000000,0.00000000,0.00000000,0.00000000,0.00000000,0.00000000,0.00000000,0.00000000,0.00000000
317.13000000,8.49876800,9.32400000,0.36548611,612.89686452,0.00000000,0.00000000,0.00000000,0.00000000,0.00000000,0.00000000,0.00000000,0.00000000,0.00000000,0.00000000,0.00000000
318.63000000,8.56021200,9.29800000,0.37210711,611.18779991,0.00000000,0.00000000,0.00000000,0.00000000,0.00000000,0.00000000,0.00000000,0.00000000,0.00000000,0.00000000,0.00000000
320.13000000,8.62178800,9.27600000,0.37883844,609.74166831,0.00000000,0.00000000,0.00000000,0.00000000,0.00000000,0.00000000,0.00000000,0.00000000,0.00000000,0.00000000,0.00000000
321.63000000,8.68333000,9.24800000,0.38553289,607.90113719,0.00000000,0.00000000,0.00000000,0.00000000,0.00000000,0.00000000,0.00000000,0.00000000,0.00000000,0.00000000,0.00000000
323.13000000,8.74507100,9.21900000,0.39226433,605.99487281,0.00000000,0.00000000,0.00000000,0.00000000,0.00000000,0.00000000,0.00000000,0.00000000,0.00000000,0.00000000,0.00000000
324.63000000,8.80730900,9.19000000,0.39914278,604.08860843,0.00000000,0.00000000,0.00000000,0.00000000,0.00000000,0.00000000,0.00000000,0.00000000,0.00000000,0.00000000,0.00000000
326.13000000,8.86885000,9.15100000,0.40605800,601.52501150,0.00000000,0.00000000,0.00000000,0.00000000,0.00000000,0.00000000,0.00000000,0.00000000,0.00000000,0.00000000,0.00000000
327.63000000,8.93089000,9.11900000,0.41297322,599.42154736,0.00000000,0.00000000,0.00000000,0.00000000,0.00000000,0.00000000,0.00000000,0.00000000,0.00000000,0.00000000,0.00000000
329.13000000,8.99282800,9.07800000,0.41988844,596.72648393,0.00000000,0.00000000,0.00000000,0.00000000,0.00000000,0.00000000,0.00000000,0.00000000,0.00000000,0.00000000,0.00000000
330.63000000,9.05585900,9.03600000,0.42691400,593.96568724,0.00000000,0.00000000,0.00000000,0.00000000,0.00000000,0.00000000,0.00000000,0.00000000,0.00000000,0.00000000,0.00000000
332.13000000,9.11892400,8.98800000,0.43397622,590.81049103,0.00000000,0.00000000,0.00000000,0.00000000,0.00000000,0.00000000,0.00000000,0.00000000,0.00000000,0.00000000,0.00000000
333.63000000,9.18215300,8.94200000,0.44103833,587.78676132,0.00000000,0.00000000,0.00000000,0.00000000,0.00000000,0.00000000,0.00000000,0.00000000,0.00000000,0.00000000,0.00000000
335.13000000,9.24548100,8.87800000,0.44817411,583.57983304,0.00000000,0.00000000,0.00000000,0.00000000,0.00000000,0.00000000,0.00000000,0.00000000,0.00000000,0.00000000,0.00000000
336.63000000,9.30913900,8.82200000,0.45527289,579.89877079,0.00000000,0.00000000,0.00000000,0.00000000,0.00000000,0.00000000,0.00000000,0.00000000,0.00000000,0.00000000,0.00000000
338.13000000,9.37355800,8.74900000,0.46255556,575.10024321,0.00000000,0.00000000,0.00000000,0.00000000,0.00000000,0.00000000,0.00000000,0.00000000,0.00000000,0.00000000,0.00000000
339.63000000,9.43903500,8.67100000,0.46991178,569.97304937,0.00000000,0.00000000,0.00000000,0.00000000,0.00000000,0.00000000,0.00000000,0.00000000,0.00000000,0.00000000,0.00000000
341.13000000,9.50477600,8.57600000,0.47737811,563.72839019,0.00000000,0.00000000,0.00000000,0.00000000,0.00000000,0.00000000,0.00000000,0.00000000,0.00000000,0.00000000,0.00000000
342.63000000,9.57236800,8.48200000,0.48502822,557.54946427,0.00000000,0.00000000,0.00000000,0.00000000,0.00000000,0.00000000,0.00000000,0.00000000,0.00000000,0.00000000,0.00000000
344.13000000,9.64177900,8.34100000,0.49293578,548.28107540,0.00000000,0.00000000,0.00000000,0.00000000,0.00000000,0.00000000,0.00000000,0.00000000,0.00000000,0.00000000,0.00000000
345.63000000,9.71466500,8.20300000,0.50124789,539.20988628,0.00000000,0.00000000,0.00000000,0.00000000,0.00000000,0.00000000,0.00000000,0.00000000,0.00000000,0.00000000,0.00000000