File: polyN_optimization/DP600_results/DATA/UT_15_1.csv
Time[s],Displacement[mm],Force[kN],EngStrain_longi,EngStress[MPa],TrueStrain,TrueStress[MPa],TrueStrainRate[1/s],PlasticStrain_longi,PlasticStress[MPa],PlasticStrain_thick,PlasticStrain_width,R-Value,Thickness[mm],Width[mm], Young's Modulus [MPa]
0.56000000,0.00000000,-0.01400000,0.00000000,-0.91330159,0.00000000,-0.91330159,0.00000000,0.00079428,339.39103660,0.00019352,-0.00098780,0.87787392,1.53290000,10.00000000,216637.81638544
2.06000000,0.00123300,-0.01200000,0.00003889,-0.78282993,0.00003889,-0.78286037,0.00005089,0.00118897,352.82766570,-0.00009551,-0.00109346,0.00000000,0.00000000,0.00000000,0.00000000
3.56000000,0.00318800,0.45300000,0.00007100,29.55182986,0.00007100,29.55392804,-0.00004755,0.00172027,366.78573922,-0.00040913,-0.00131115,0.00000000,0.00000000,0.00000000,0.00000000
5.06000000,0.00570700,0.74000000,0.00015667,48.27451236,0.00015665,48.28207537,0.00004710,0.00251568,378.30131713,-0.00085168,-0.00166400,0.00000000,0.00000000,0.00000000,0.00000000
6.56000000,0.00776300,1.12700000,0.00024356,73.52077761,0.00024353,73.53868400,0.00008331,0.00325835,389.22443346,-0.00115207,-0.00210628,0.00000000,0.00000000,0.00000000,0.00000000
8.06000000,0.00918000,1.44000000,0.00029756,93.93959162,0.00029751,93.96754387,0.00011841,0.00398610,397.79187523,-0.00148009,-0.00250600,0.00000000,0.00000000,0.00000000,0.00000000
9.56000000,0.01098400,1.80700000,0.00033178,117.88114032,0.00033172,117.92025067,0.00009641,0.00473332,407.49881724,-0.00186295,-0.00287037,0.00000000,0.00000000,0.00000000,0.00000000
11.06000000,0.01367300,2.11700000,0.00038878,138.10424685,0.00038870,138.15793871,-0.00006775,0.00565893,414.85846437,-0.00242260,-0.00323633,0.00000000,0.00000000,0.00000000,0.00000000
12.56000000,0.01690100,2.50300000,0.00050611,163.28527627,0.00050598,163.36791677,-0.00010750,0.00658737,422.95835574,-0.00299592,-0.00359145,0.00000000,0.00000000,0.00000000,0.00000000
14.06000000,0.02082000,2.81000000,0.00068644,183.31267532,0.00068621,183.43850929,0.00006995,0.00743870,430.18234727,-0.00343448,-0.00400421,0.00000000,0.00000000,0.00000000,0.00000000
15.56000000,0.02415700,3.19100000,0.00084567,208.16752561,0.00084531,208.34356594,0.00029466,0.00826983,437.67418908,-0.00381676,-0.00445307,0.00000000,0.00000000,0.00000000,0.00000000
17.06000000,0.02778600,3.49200000,0.00094944,227.80350969,0.00094899,228.01979646,0.00037190,0.00921199,443.83976662,-0.00424517,-0.00496682,0.00000000,0.00000000,0.00000000,0.00000000
18.56000000,0.03142500,3.83600000,0.00101533,250.24463435,0.00101482,250.49871607,0.00027063,0.01018013,451.22002212,-0.00476105,-0.00541908,0.00000000,0.00000000,0.00000000,0.00000000
20.06000000,0.03668300,4.12300000,0.00110356,268.96731685,0.00110295,269.26413723,0.00013963,0.01110431,456.93815591,-0.00524000,-0.00586431,0.00000000,0.00000000,0.00000000,0.00000000
21.56000000,0.04426400,4.46800000,0.00128378,291.47367734,0.00128295,291.84786477,-0.00008833,0.01197325,463.43694319,-0.00568935,-0.00628390,0.00000000,0.00000000,0.00000000,0.00000000
23.06000000,0.05287300,4.72700000,0.00157444,308.36975667,0.00157321,308.85526772,-0.00023495,0.01293162,469.25901204,-0.00628451,-0.00664712,0.00000000,0.00000000,0.00000000,0.00000000
24.56000000,0.06297300,5.02500000,0.00206011,327.81003327,0.00205799,328.48535836,0.00002195,0.01394509,475.45064287,-0.00687693,-0.00706816,0.00000000,0.00000000,0.00000000,0.00000000
26.06000000,0.07741000,5.24300000,0.00260833,342.03144367,0.00260494,342.92357568,0.00038902,0.01491562,480.56965676,-0.00737865,-0.00753697,0.00000000,0.00000000,0.00000000,0.00000000
27.56000000,0.09495900,5.47000000,0.00314911,356.83997652,0.00314416,357.96370525,0.00055012,0.01580514,486.59113644,-0.00775929,-0.00804585,0.00000000,0.00000000,0.00000000,0.00000000
29.06000000,0.11350300,5.64400000,0.00374511,368.19101050,0.00373812,369.56992675,0.00054249,0.01679679,491.40733323,-0.00824041,-0.00855638,0.00000000,0.00000000,0.00000000,0.00000000
30.56000000,0.13671500,5.83400000,0.00445156,380.58581773,0.00444168,382.28001664,0.00024913,0.01780319,496.70722058,-0.00876262,-0.00904057,0.00000000,0.00000000,0.00000000,0.00000000
32.06000000,0.16098600,5.96900000,0.00537878,389.39265445,0.00536436,391.48711100,0.00050512,0.01881028,501.61713568,-0.00932198,-0.00948830,0.00000000,0.00000000,0.00000000,0.00000000
33.56000000,0.18727500,6.12100000,0.00626922,399.30850023,0.00624965,401.81185395,0.00073862,0.01977942,506.71798920,-0.00985829,-0.00992113,0.00000000,0.00000000,0.00000000,0.00000000
35.06000000,0.21247100,6.23200000,0.00708978,406.54967708,0.00706476,409.43202395,0.00078194,0.02074502,511.62590694,-0.01038250,-0.01036252,0.00000000,0.00000000,0.00000000,0.00000000
36.56000000,0.24077900,6.35400000,0.00789911,414.50844804,0.00786808,417.78269633,0.00046725,0.02179922,515.78491269,-0.01096751,-0.01083171,0.00000000,0.00000000,0.00000000,0.00000000
38.06000000,0.26806100,6.45200000,0.00887033,420.90155914,0.00883122,424.63509627,0.00045953,0.02286782,520.42933394,-0.01155333,-0.01131449,0.00000000,0.00000000,0.00000000,0.00000000
39.56000000,0.29636900,6.57200000,0.00988556,428.72985844,0.00983701,432.96809127,0.00069965,0.02386209,524.64129380,-0.01203448,-0.01182761,0.00000000,0.00000000,0.00000000,0.00000000
41.06000000,0.32391600,6.66200000,0.01078656,434.60108291,0.01072880,439.28893164,0.00074961,0.02489014,529.08085124,-0.01260418,-0.01228596,0.00000000,0.00000000,0.00000000,0.00000000
42.56000000,0.35321800,6.76900000,0.01163267,441.58131646,0.01156553,446.71808472,0.00048003,0.02597637,533.08924244,-0.01317244,-0.01280393,0.00000000,0.00000000,0.00000000,0.00000000
44.06000000,0.38122900,6.85200000,0.01264789,446.99589014,0.01256857,452.64944450,0.00047955,0.02701757,537.28372047,-0.01369115,-0.01332642,0.00000000,0.00000000,0.00000000,0.00000000
45.56000000,0.41056200,6.94600000,0.01364100,453.12805793,0.01354880,459.30917777,0.00053719,0.02808531,540.89397107,-0.01428118,-0.01380413,0.00000000,0.00000000,0.00000000,0.00000000
47.06000000,0.44052400,7.02400000,0.01465267,458.21645248,0.01454635,464.93054542,0.00073251,0.02913232,544.90520672,-0.01487021,-0.01426211,0.00000000,0.00000000,0.00000000,0.00000000
48.56000000,0.46959300,7.11600000,0.01556500,464.21814861,0.01544511,471.44370409,0.00055784,0.03022631,548.54471861,-0.01549431,-0.01473200,0.00000000,0.00000000,0.00000000,0.00000000
50.06000000,0.50008400,7.18800000,0.01655467,468.91512819,0.01641913,476.67786183,0.00041998,0.03127221,552.30037898,-0.01606202,-0.01521020,0.00000000,0.00000000,0.00000000,0.00000000
51.56000000,0.53041000,7.27400000,0.01762522,474.52540935,0.01747170,482.88902514,0.00053530,0.03235709,555.81420221,-0.01667230,-0.01568479,0.00000000,0.00000000,0.00000000,0.00000000
53.06000000,0.56126500,7.34200000,0.01863322,478.96144563,0.01846175,487.88604068,0.00067902,0.03344018,559.46975067,-0.01721703,-0.01622315,0.00000000,0.00000000,0.00000000,0.00000000
54.56000000,0.59205400,7.41700000,0.01961556,483.85413269,0.01942565,493.34520031,0.00057764,0.03454586,562.60231110,-0.01779619,-0.01674967,0.00000000,0.00000000,0.00000000,0.00000000
56.06000000,0.62360500,7.47800000,0.02064911,487.83351817,0.02043881,497.90684669,0.00054069,0.03559212,566.04733055,-0.01831452,-0.01727760,0.00000000,0.00000000,0.00000000,0.00000000
57.56000000,0.65429600,7.55300000,0.02173422,492.72620523,0.02150140,503.43522607,0.00060495,0.03671586,569.33916897,-0.01890223,-0.01781362,0.00000000,0.00000000,0.00000000,0.00000000
59.06000000,0.68677400,7.61600000,0.02280467,496.83606237,0.02254853,508.16624316,0.00071233,0.03785901,572.71707004,-0.01949662,-0.01836239,0.00000000,0.00000000,0.00000000,0.00000000
60.56000000,0.71835700,7.67600000,0.02384556,500.75021202,0.02356569,512.69087902,0.00076871,0.03893227,575.65249240,-0.02004262,-0.01888965,0.00000000,0.00000000,0.00000000,0.00000000
62.06000000,0.75057000,7.74400000,0.02489756,505.18624829,0.02459266,517.76415097,0.00067465,0.04002776,578.87964229,-0.02060566,-0.01942211,0.00000000,0.00000000,0.00000000,0.00000000
63.56000000,0.78298000,7.79600000,0.02601200,508.57851132,0.02567944,521.80765555,0.00066677,0.04114877,581.64968343,-0.02124408,-0.01990469,0.00000000,0.00000000,0.00000000,0.00000000
65.06000000,0.81545800,7.85400000,0.02710811,512.36218931,0.02674719,526.25136047,0.00077363,0.04228781,584.77802333,-0.02183465,-0.02045316,0.00000000,0.00000000,0.00000000,0.00000000
66.56000000,0.84836500,7.90300000,0.02817489,515.55874486,0.02778528,530.08455521,0.00075142,0.04339538,587.62022524,-0.02244595,-0.02094943,0.00000000,0.00000000,0.00000000,0.00000000
68.06000000,0.88140500,7.96200000,0.02925633,519.40765869,0.02883653,534.60362228,0.00064329,0.04450493,590.53785074,-0.02301035,-0.02149458,0.00000000,0.00000000,0.00000000,0.00000000
69.56000000,0.91487500,8.00800000,0.03040767,522.40850675,0.02995452,538.29373049,0.00075691,0.04566959,593.35676010,-0.02365601,-0.02201357,0.00000000,0.00000000,0.00000000,0.00000000
71.06000000,0.94851000,8.06300000,0.03150011,525.99647727,0.03101416,542.56542474,0.00070632,0.04681891,596.17234790,-0.02422772,-0.02259120,0.00000000,0.00000000,0.00000000,0.00000000
72.56000000,0.98211300,8.10600000,0.03261844,528.80161785,0.03209776,546.05030404,0.00074130,0.04791594,598.68696700,-0.02483160,-0.02308435,0.00000000,0.00000000,0.00000000,0.00000000
74.06000000,1.01594800,8.15400000,0.03374033,531.93293757,0.03318362,549.88053219,0.00069038,0.04903537,601.35776667,-0.02540240,-0.02363297,0.00000000,0.00000000,0.00000000,0.00000000
75.56000000,1.04971600,8.19800000,0.03488067,534.80331398,0.03428612,553.45761011,0.00076782,0.05022001,604.00438095,-0.02606667,-0.02415334,0.00000000,0.00000000,0.00000000,0.00000000
77.06000000,1.08424500,8.24400000,0.03599900,537.80416205,0.03536618,557.16457408,0.00072471,0.05136771,606.77215474,-0.02666221,-0.02470550,0.00000000,0.00000000,0.00000000,0.00000000
78.56000000,1.11837700,8.28100000,0.03713189,540.21788766,0.03645910,560.27719824,0.00070956,0.05251222,609.19784450,-0.02726254,-0.02524967,0.00000000,0.00000000,0.00000000,0.00000000
80.06000000,1.15264300,8.32800000,0.03834211,543.28397156,0.03762532,564.11462596,0.00080080,0.05365827,611.76776654,-0.02790085,-0.02575742,0.00000000,0.00000000,0.00000000,0.00000000
81.56000000,1.18707300,8.36200000,0.03948611,545.50198969,0.03872647,567.04174187,0.00087776,0.05484613,614.02200570,-0.02852818,-0.02631795,0.00000000,0.00000000,0.00000000,0.00000000
83.06000000,1.22216600,8.40400000,0.04059344,548.24189445,0.03979117,570.49692133,0.00072835,0.05599988,616.53730576,-0.02914716,-0.02685272,0.00000000,0.00000000,0.00000000,0.00000000
84.56000000,1.25739100,8.44100000,0.04177789,550.65562007,0.04092876,573.66084938,0.00068506,0.05715001,618.84696048,-0.02977177,-0.02737824,0.00000000,0.00000000,0.00000000,0.00000000
86.06000000,1.29218600,8.47800000,0.04296233,553.06934568,0.04206506,576.83049527,0.00078318,0.05829834,621.22960521,-0.03031606,-0.02798228,0.00000000,0.00000000,0.00000000,0.00000000
87.56000000,1.32717900,8.51000000,0.04412467,555.15689217,0.04317889,579.65300498,0.00078912,0.05946679,623.49025061,-0.03099310,-0.02847369,0.00000000,0.00000000,0.00000000,0.00000000
89.06000000,1.36273500,8.54800000,0.04528344,557.63585361,0.04428809,582.88752581,0.00073912,0.06064015,625.82819332,-0.03160302,-0.02903713,0.00000000,0.00000000,0.00000000,0.00000000
90.56000000,1.39845700,8.57900000,0.04649000,559.65816426,0.04544171,585.67667232,0.00073848,0.06182048,627.89595488,-0.03224155,-0.02957894,0.00000000,0.00000000,0.00000000,0.00000000
92.06000000,1.43437700,8.61400000,0.04770022,561.94141823,0.04659750,588.74614875,0.00080786,0.06297775,630.16287836,-0.03285241,-0.03012534,0.00000000,0.00000000,0.00000000,0.00000000
93.56000000,1.47039700,8.64400000,0.04885889,563.89849305,0.04770280,591.44994687,0.00077157,0.06417223,632.24792543,-0.03347825,-0.03069399,0.00000000,0.00000000,0.00000000,0.00000000
95.06000000,1.50648200,8.67600000,0.05005433,565.98603953,0.04884191,594.31609342,0.00069363,0.06535830,634.40180373,-0.03413124,-0.03122706,0.00000000,0.00000000,0.00000000,0.00000000
96.56000000,1.54276700,8.70400000,0.05129400,567.81264270,0.05002179,596.93802440,0.00072791,0.06651236,636.46936210,-0.03471221,-0.03180015,0.00000000,0.00000000,0.00000000,0.00000000
98.06000000,1.57898500,8.73600000,0.05251156,569.90018918,0.05117927,599.82653463,0.00082486,0.06771250,638.64063736,-0.03536883,-0.03234367,0.00000000,0.00000000,0.00000000,0.00000000
99.56000000,1.61523700,8.76200000,0.05370344,571.59632070,0.05231105,602.29301195,0.00082414,0.06890503,640.67072194,-0.03597849,-0.03292654,0.00000000,0.00000000,0.00000000,0.00000000
101.06000000,1.65188500,8.79000000,0.05492111,573.42292387,0.05346599,604.91594799,0.00073953,0.07010662,642.64022180,-0.03661127,-0.03349535,0.00000000,0.00000000,0.00000000,0.00000000
102.56000000,1.68893100,8.81800000,0.05618633,575.24952704,0.05466462,607.57068872,0.00081505,0.07130345,644.61048210,-0.03726106,-0.03404239,0.00000000,0.00000000,0.00000000,0.00000000
104.06000000,1.72624200,8.84500000,0.05740389,577.01089438,0.05581674,610.13356365,0.00080717,0.07251576,646.59461377,-0.03788333,-0.03463243,0.00000000,0.00000000,0.00000000,0.00000000
105.56000000,1.76312200,8.86700000,0.05862522,578.44608259,0.05697111,612.35761272,0.00079931,0.07370638,648.49787611,-0.03851581,-0.03519057,0.00000000,0.00000000,0.00000000,0.00000000
107.06000000,1.80016800,8.89400000,0.05987222,580.20744993,0.05814836,614.94575931,0.00075663,0.07489575,650.40397482,-0.03919192,-0.03570383,0.00000000,0.00000000,0.00000000,0.00000000
108.56000000,1.83741100,8.91700000,0.06110444,581.70787396,0.05931029,617.25281043,0.00074905,0.07611060,652.33038740,-0.03981565,-0.03629494,0.00000000,0.00000000,0.00000000,0.00000000
110.06000000,1.87495300,8.94200000,0.06238822,583.33876965,0.06051941,619.73223844,0.00084503,0.07730379,654.24634997,-0.04044979,-0.03685400,0.00000000,0.00000000,0.00000000,0.00000000
111.56000000,1.91282600,8.96400000,0.06359478,584.77395786,0.06165447,621.96252776,0.00079578,0.07855402,655.99049721,-0.04113509,-0.03741893,0.00000000,0.00000000,0.00000000,0.00000000
113.06000000,1.95017000,8.98700000,0.06485289,586.27438189,0.06283666,624.29596924,0.00080173,0.07976812,657.85637602,-0.04180746,-0.03796067,0.00000000,0.00000000,0.00000000,0.00000000
114.56000000,1.98804200,9.00700000,0.06612544,587.57909844,0.06403100,626.43302747,0.00082142,0.08094064,659.62714216,-0.04240567,-0.03853497,0.00000000,0.00000000,0.00000000,0.00000000
116.06000000,2.02601500,9.03100000,0.06737978,589.14475830,0.06520684,628.84120119,0.00079275,0.08218636,661.30721891,-0.04307396,-0.03911240,0.00000000,0.00000000,0.00000000,0.00000000
117.56000000,2.06402100,9.04900000,0.06863422,590.31900320,0.06638141,630.83508884,0.00080576,0.08342299,663.19851577,-0.04373313,-0.03968986,0.00000000,0.00000000,0.00000000,0.00000000
119.06000000,2.10222400,9.06900000,0.06989589,591.62371975,0.06756134,632.97578553,0.00075681,0.08461224,664.77611165,-0.04432989,-0.04028235,0.00000000,0.00000000,0.00000000,0.00000000
120.56000000,2.14019700,9.08800000,0.07118700,592.86320047,0.06876738,635.06735312,0.00077624,0.08586277,666.61211986,-0.04501030,-0.04085247,0.00000000,0.00000000,0.00000000,0.00000000
122.06000000,2.17860000,9.10800000,0.07247078,594.16791702,0.06996512,637.22772810,0.00084392,0.08711258,668.30797573,-0.04565864,-0.04145394,0.00000000,0.00000000,0.00000000,0.00000000
123.56000000,2.21763100,9.12600000,0.07375089,595.34216192,0.07115802,639.24917555,0.00080875,0.08840749,670.03737047,-0.04637333,-0.04203416,0.00000000,0.00000000,0.00000000,0.00000000
125.06000000,2.25616700,9.14500000,0.07504556,596.58164264,0.07236304,641.35244344,0.00081439,0.08959772,671.55598563,-0.04699163,-0.04260609,0.00000000,0.00000000,0.00000000,0.00000000
126.56000000,2.29499900,9.16100000,0.07633678,597.62541588,0.07356340,643.24621444,0.00079318,0.09080256,673.23094696,-0.04763118,-0.04317138,0.00000000,0.00000000,0.00000000,0.00000000
128.06000000,2.33386500,9.18000000,0.07762411,598.86489660,0.07475872,645.35125188,0.00077139,0.09207967,674.88593711,-0.04833160,-0.04374807,0.00000000,0.00000000,0.00000000,0.00000000
129.56000000,2.37269900,9.19500000,0.07893367,599.84343401,0.07597321,647.19127569,0.00075686,0.09331178,676.51353829,-0.04897235,-0.04433943,0.00000000,0.00000000,0.00000000,0.00000000
131.06000000,2.41206100,9.21200000,0.08023956,600.95244308,0.07718283,649.17260002,0.00077673,0.09454975,678.00380271,-0.04961807,-0.04493168,0.00000000,0.00000000,0.00000000,0.00000000
132.56000000,2.45109300,9.22600000,0.08155633,601.86574467,0.07840105,650.95170796,0.00081627,0.09577877,679.63514828,-0.05026701,-0.04551175,0.00000000,0.00000000,0.00000000,0.00000000
134.06000000,2.49019000,9.24400000,0.08286589,603.03998956,0.07961113,653.01143433,0.00078839,0.09703348,681.14236509,-0.05091808,-0.04611540,0.00000000,0.00000000,0.00000000,0.00000000
135.56000000,2.53054700,9.25800000,0.08416811,603.95329115,0.08081298,654.78689886,0.00078745,0.09826600,682.78199456,-0.05157346,-0.04669254,0.00000000,0.00000000,0.00000000,0.00000000
137.06000000,2.57017500,9.27300000,0.08551800,604.93182856,0.08205729,656.66438868,0.00075902,0.09955471,684.17309603,-0.05228585,-0.04726886,0.00000000,0.00000000,0.00000000,0.00000000
138.56000000,2.61000000,9.28700000,0.08688278,605.84513015,0.08331376,658.48263796,0.00082598,0.10081086,685.76215736,-0.05293448,-0.04787637,0.00000000,0.00000000,0.00000000,0.00000000
140.06000000,2.64962700,9.29900000,0.08820700,606.62796008,0.08453139,660.13679255,0.00089934,0.10206281,687.20581401,-0.05363904,-0.04842376,0.00000000,0.00000000,0.00000000,0.00000000
141.56000000,2.69001500,9.31400000,0.08951644,607.60649749,0.08573397,661.99727076,0.00079705,0.10334214,688.81657769,-0.05434522,-0.04899692,0.00000000,0.00000000,0.00000000,0.00000000
143.06000000,2.73020600,9.32500000,0.09088489,608.32409159,0.08698919,663.61155906,0.00081622,0.10462050,690.28387006,-0.05504639,-0.04957411,0.00000000,0.00000000,0.00000000,0.00000000
144.56000000,2.77062800,9.33800000,0.09226422,609.17215735,0.08825281,665.37695265,0.00094993,0.10583838,691.63882699,-0.05566085,-0.05017753,0.00000000,0.00000000,0.00000000,0.00000000
146.06000000,2.81131400,9.35100000,0.09362167,610.02022311,0.08949482,667.13133309,0.00091542,0.10713031,693.04757342,-0.05636698,-0.05076333,0.00000000,0.00000000,0.00000000,0.00000000
147.56000000,2.85282900,9.36400000,0.09497156,610.86828886,0.09072839,668.88340050,0.00086678,0.10839759,694.44163437,-0.05705417,-0.05134342,0.00000000,0.00000000,0.00000000,0.00000000
149.06000000,2.89305100,9.37400000,0.09630678,611.52064714,0.09194706,670.41423021,0.00069782,0.10967930,695.92149834,-0.05774938,-0.05192992,0.00000000,0.00000000,0.00000000,0.00000000
150.56000000,2.93360600,9.38700000,0.09771933,612.36871290,0.09323469,672.20897528,0.00087817,0.11093367,697.23814861,-0.05840177,-0.05253190,0.00000000,0.00000000,0.00000000,0.00000000
152.06000000,2.97399500,9.39600000,0.09901778,612.95583534,0.09441685,673.64936004,0.00081686,0.11218930,698.70484219,-0.05908472,-0.05310458,0.00000000,0.00000000,0.00000000,0.00000000
153.56000000,3.01570800,9.41000000,0.10040456,613.86913693,0.09567789,675.50439479,0.00076896,0.11354158,700.09489691,-0.05982268,-0.05371890,0.00000000,0.00000000,0.00000000,0.00000000
155.06000000,3.05718900,9.41800000,0.10181711,614.39102355,0.09696074,676.94654266,0.00085493,0.11479749,701.49328919,-0.06047024,-0.05432725,0.00000000,0.00000000,0.00000000,0.00000000
156.56000000,3.09840500,9.42900000,0.10319278,615.10861765,0.09820850,678.58338454,0.00086031,0.11607152,702.83312190,-0.06113406,-0.05493746,0.00000000,0.00000000,0.00000000,0.00000000
158.06000000,3.13925700,9.43800000,0.10455378,615.69574010,0.09944143,680.06905569,0.00085261,0.11736991,704.19245998,-0.06181918,-0.05555072,0.00000000,0.00000000,0.00000000,0.00000000
159.56000000,3.18110200,9.44900000,0.10593689,616.41333420,0.10069284,681.71424510,0.00083164,0.11866694,705.47924747,-0.06252424,-0.05614270,0.00000000,0.00000000,0.00000000,0.00000000
161.06000000,3.22284800,9.45800000,0.10740833,617.00045665,0.10202245,683.27144737,0.00101022,0.11994254,706.82704693,-0.06321195,-0.05673059,0.00000000,0.00000000,0.00000000,0.00000000
162.56000000,3.26422900,9.46700000,0.10877667,617.58757910,0.10325731,684.76669733,0.00088927,0.12124275,708.12049684,-0.06386848,-0.05737427,0.00000000,0.00000000,0.00000000,0.00000000
164.06000000,3.30663700,9.47500000,0.11018544,618.10946572,0.10452707,686.21613191,0.00090135,0.12258646,709.44708896,-0.06457710,-0.05800936,0.00000000,0.00000000,0.00000000,0.00000000
165.56000000,3.34805200,9.48500000,0.11159433,618.76182399,0.10579532,687.81213723,0.00092021,0.12386702,710.73094236,-0.06527576,-0.05859125,0.00000000,0.00000000,0.00000000,0.00000000
167.06000000,3.39042700,9.49300000,0.11298100,619.28371061,0.10704200,689.25100352,0.00083956,0.12517850,711.96459006,-0.06597532,-0.05920318,0.00000000,0.00000000,0.00000000,0.00000000
168.56000000,3.43280100,9.50100000,0.11439356,619.80559723,0.10831036,690.70736325,0.00080558,0.12649075,713.34988375,-0.06669839,-0.05979236,0.00000000,0.00000000,0.00000000,0.00000000
170.06000000,3.47550800,9.50800000,0.11580600,620.26224803,0.10957701,692.09233792,0.00089024,0.12779911,714.51090865,-0.06736527,-0.06043384,0.00000000,0.00000000,0.00000000,0.00000000
171.56000000,3.51735400,9.51500000,0.11719644,620.71889882,0.11082237,693.46494676,0.00078366,0.12906288,715.86592915,-0.06803187,-0.06103100,0.00000000,0.00000000,0.00000000,0.00000000
173.06000000,3.56015900,9.52300000,0.11862378,621.24078544,0.11209916,694.93471432,0.00078942,0.13045728,717.16759629,-0.06875923,-0.06169805,0.00000000,0.00000000,0.00000000,0.00000000
174.56000000,3.60286500,9.53000000,0.12009511,621.69743623,0.11341360,696.36025891,0.00084078,0.13180210,718.36083105,-0.06950412,-0.06229798,0.00000000,0.00000000,0.00000000,0.00000000
176.06000000,3.64596700,9.53700000,0.12153700,622.15408702,0.11470007,697.76882830,0.00089243,0.13313508,719.62247763,-0.07020753,-0.06292755,0.00000000,0.00000000,0.00000000,0.00000000
177.56000000,3.68883900,9.54300000,0.12293478,622.54550199,0.11594560,699.07799493,0.00085825,0.13447617,720.81695070,-0.07095791,-0.06351826,0.00000000,0.00000000,0.00000000,0.00000000
179.06000000,3.73233900,9.55100000,0.12445022,623.06738861,0.11729422,700.60826358,0.00083772,0.13581827,722.08931502,-0.07166825,-0.06415002,0.00000000,0.00000000,0.00000000,0.00000000
180.56000000,3.77590600,9.55600000,0.12591800,623.39356775,0.11859870,701.89003901,0.00092153,0.13712363,723.33713874,-0.07234130,-0.06478232,0.00000000,0.00000000,0.00000000,0.00000000
182.06000000,3.81953900,9.56300000,0.12733411,623.85021854,0.11985565,703.28763158,0.00087462,0.13849149,724.48155748,-0.07310065,-0.06539084,0.00000000,0.00000000,0.00000000,0.00000000
183.56000000,3.86280800,9.56800000,0.12882022,624.17639768,0.12117304,704.58293993,0.00089967,0.13985720,725.70174688,-0.07386020,-0.06599700,0.00000000,0.00000000,0.00000000,0.00000000
185.06000000,3.90657400,9.57400000,0.13030267,624.56781264,0.12248544,705.95066414,0.00091816,0.14115751,726.87621880,-0.07453001,-0.06662750,0.00000000,0.00000000,0.00000000,0.00000000
186.56000000,3.95063800,9.58000000,0.13176289,624.95922761,0.12377650,707.30566088,0.00093622,0.14251955,728.09763205,-0.07526812,-0.06725143,0.00000000,0.00000000,0.00000000,0.00000000
188.06000000,3.99463500,9.58500000,0.13320844,625.28540675,0.12505294,708.57870311,0.00087637,0.14391171,729.26721695,-0.07601827,-0.06789344,0.00000000,0.00000000,0.00000000,0.00000000
189.56000000,4.03843500,9.59000000,0.13470200,625.61158588,0.12637006,709.88271772,0.00081056,0.14527024,730.41400411,-0.07672063,-0.06854960,0.00000000,0.00000000,0.00000000,0.00000000
191.06000000,4.08289400,9.59600000,0.13621744,626.00300085,0.12770471,711.27552984,0.00090653,0.14659500,731.61384823,-0.07739174,-0.06920326,0.00000000,0.00000000,0.00000000,0.00000000
192.56000000,4.12735500,9.60000000,0.13767044,626.26394416,0.12898270,712.48197969,0.00082779,0.14801295,732.80795351,-0.07816860,-0.06984435,0.00000000,0.00000000,0.00000000,0.00000000
194.06000000,4.17198100,9.60400000,0.13920067,626.52488747,0.13032685,713.73756949,0.00087839,0.14936596,733.95615683,-0.07891071,-0.07045525,0.00000000,0.00000000,0.00000000,0.00000000
195.56000000,4.21617900,9.60800000,0.14070889,626.78583078,0.13164990,714.98016860,0.00089672,0.15077986,735.15104640,-0.07967459,-0.07110527,0.00000000,0.00000000,0.00000000,0.00000000
197.06000000,4.26103700,9.61300000,0.14220967,627.11200992,0.13296469,716.29339981,0.00098586,0.15219210,736.27014155,-0.08044679,-0.07174531,0.00000000,0.00000000,0.00000000,0.00000000
198.56000000,4.30629200,9.61700000,0.14378400,627.37295323,0.13434206,717.57914593,0.00093940,0.15360170,737.54219133,-0.08122944,-0.07237227,0.00000000,0.00000000,0.00000000,0.00000000
200.06000000,4.35194400,9.62100000,0.14528100,627.63389654,0.13565002,718.81717666,0.00085432,0.15497893,738.56224069,-0.08195574,-0.07302319,0.00000000,0.00000000,0.00000000,0.00000000
201.56000000,4.39703300,9.62400000,0.14682589,627.82960402,0.13699803,720.01124370,0.00087236,0.15638530,739.68215935,-0.08272407,-0.07366123,0.00000000,0.00000000,0.00000000,0.00000000
203.06000000,4.44225700,9.62700000,0.14835256,628.02531150,0.13832835,721.19447142,0.00083945,0.15782051,740.90213839,-0.08351163,-0.07430888,0.00000000,0.00000000,0.00000000,0.00000000
204.56000000,4.48764400,9.63100000,0.14993422,628.28625481,0.13970474,722.48786576,0.00089590,0.15922287,742.02259939,-0.08418964,-0.07503323,0.00000000,0.00000000,0.00000000,0.00000000
206.06000000,4.53326400,9.63400000,0.15147922,628.48196229,0.14104740,723.68392112,0.00095861,0.16065388,743.24327626,-0.08492016,-0.07573372,0.00000000,0.00000000,0.00000000,0.00000000
207.56000000,4.57918100,9.63700000,0.15302422,628.67766978,0.14238825,724.88058122,0.00089370,0.16211461,744.33361637,-0.08574011,-0.07637450,0.00000000,0.00000000,0.00000000,0.00000000
209.06000000,4.62483300,9.64000000,0.15460589,628.87337726,0.14375906,726.10090475,0.00089228,0.16357293,745.50112875,-0.08651854,-0.07705439,0.00000000,0.00000000,0.00000000,0.00000000
210.56000000,4.67098200,9.64300000,0.15618767,629.06908474,0.14512810,727.32191726,0.00101855,0.16499815,746.64566617,-0.08729703,-0.07770112,0.00000000,0.00000000,0.00000000,0.00000000
212.06000000,4.71746300,9.64600000,0.15776933,629.26479222,0.14649517,728.54347898,0.00101696,0.16648352,747.75950247,-0.08809467,-0.07838885,0.00000000,0.00000000,0.00000000,0.00000000
213.56000000,4.76427400,9.64800000,0.15924067,629.39526388,0.14776519,729.62058530,0.00076156,0.16796658,748.87326868,-0.08889422,-0.07907236,0.00000000,0.00000000,0.00000000,0.00000000
215.06000000,4.81035600,9.65000000,0.16089589,629.52573553,0.14919203,730.81383833,0.00088725,0.00000000,0.00000000,0.00000000,0.00000000,0.00000000,0.00000000,0.00000000,0.00000000
216.56000000,4.85743200,9.65300000,0.16251444,629.72144302,0.15058528,732.06027348,0.00101281,0.00000000,0.00000000,0.00000000,0.00000000,0.00000000,0.00000000,0.00000000,0.00000000
218.06000000,4.90417700,9.65500000,0.16409611,629.85191467,0.15194492,733.20816445,0.00088481,0.00000000,0.00000000,0.00000000,0.00000000,0.00000000,0.00000000,0.00000000,0.00000000
219.56000000,4.95108700,9.65600000,0.16571467,629.91715050,0.15333435,734.30366112,0.00094671,0.00000000,0.00000000,0.00000000,0.00000000,0.00000000,0.00000000,0.00000000,0.00000000
221.06000000,4.99862600,9.65900000,0.16733322,630.11285798,0.15472185,735.55167287,0.00088255,0.00000000,0.00000000,0.00000000,0.00000000,0.00000000,0.00000000,0.00000000,0.00000000
222.56000000,5.04613300,9.66000000,0.16898856,630.17809381,0.15613889,736.67097962,0.00088149,0.00000000,0.00000000,0.00000000,0.00000000,0.00000000,0.00000000,0.00000000,0.00000000
224.06000000,5.09410200,9.66200000,0.17064367,630.30856546,0.15755374,737.86673021,0.00087986,0.00000000,0.00000000,0.00000000,0.00000000,0.00000000,0.00000000,0.00000000,0.00000000
225.56000000,5.14180700,9.66300000,0.17229889,630.37380129,0.15896668,738.98650684,0.00094158,0.00000000,0.00000000,0.00000000,0.00000000,0.00000000,0.00000000,0.00000000,0.00000000
227.06000000,5.18931400,9.66400000,0.17395422,630.43903712,0.16037773,740.10656948,0.00094025,0.00000000,0.00000000,0.00000000,0.00000000,0.00000000,0.00000000,0.00000000,0.00000000
228.56000000,5.23821100,9.66600000,0.17564633,630.56950877,0.16181807,741.32673090,0.00093890,0.00000000,0.00000000,0.00000000,0.00000000,0.00000000,0.00000000,0.00000000,0.00000000
230.06000000,5.28671000,9.66700000,0.17737522,630.63474460,0.16328757,742.49372257,0.00106253,0.00000000,0.00000000,0.00000000,0.00000000,0.00000000,0.00000000,0.00000000,0.00000000
231.56000000,5.33564000,9.66800000,0.17903044,630.69998043,0.16469244,743.61447824,0.00099862,0.00000000,0.00000000,0.00000000,0.00000000,0.00000000,0.00000000,0.00000000,0.00000000
233.06000000,5.38460300,9.66800000,0.18075933,630.69998043,0.16615773,744.70488842,0.00099735,0.00000000,0.00000000,0.00000000,0.00000000,0.00000000,0.00000000,0.00000000,0.00000000
234.56000000,5.43340100,9.66900000,0.18245133,630.76521626,0.16758968,745.84917098,0.00093350,0.00000000,0.00000000,0.00000000,0.00000000,0.00000000,0.00000000,0.00000000,0.00000000
236.06000000,5.48322300,9.67000000,0.18414344,630.83045208,0.16901968,746.99374439,0.00093216,0.00000000,0.00000000,0.00000000,0.00000000,0.00000000,0.00000000,0.00000000,0.00000000
237.56000000,5.53225200,9.67000000,0.18587233,630.83045208,0.17047865,748.08438015,0.00086875,0.00000000,0.00000000,0.00000000,0.00000000,0.00000000,0.00000000,0.00000000,0.00000000
239.06000000,5.58141400,9.67100000,0.18763800,630.89568791,0.17196646,749.27569300,0.00086764,0.00000000,0.00000000,0.00000000,0.00000000,0.00000000,0.00000000,0.00000000,0.00000000
240.56000000,5.63163500,9.67100000,0.18944033,630.89568791,0.00000000,0.00000000,0.00000000,0.00000000,0.00000000,0.00000000,0.00000000,0.00000000,0.00000000,0.00000000,0.00000000
242.06000000,5.68155800,9.67100000,0.19120611,630.89568791,0.00000000,0.00000000,0.00000000,0.00000000,0.00000000,0.00000000,0.00000000,0.00000000,0.00000000,0.00000000,0.00000000
243.56000000,5.73224300,9.67100000,0.19304511,630.89568791,0.00000000,0.00000000,0.00000000,0.00000000,0.00000000,0.00000000,0.00000000,0.00000000,0.00000000,0.00000000,0.00000000
245.06000000,5.78272900,9.67100000,0.19481078,630.89568791,0.00000000,0.00000000,0.00000000,0.00000000,0.00000000,0.00000000,0.00000000,0.00000000,0.00000000,0.00000000,0.00000000
246.56000000,5.83304900,9.67000000,0.19657644,630.83045208,0.00000000,0.00000000,0.00000000,0.00000000,0.00000000,0.00000000,0.00000000,0.00000000,0.00000000,0.00000000,0.00000000
248.06000000,5.88343600,9.67000000,0.19841567,630.83045208,0.00000000,0.00000000,0.00000000,0.00000000,0.00000000,0.00000000,0.00000000,0.00000000,0.00000000,0.00000000,0.00000000
249.56000000,5.93438600,9.67000000,0.20029167,630.83045208,0.00000000,0.00000000,0.00000000,0.00000000,0.00000000,0.00000000,0.00000000,0.00000000,0.00000000,0.00000000,0.00000000
251.06000000,5.98576600,9.66900000,0.20220444,630.76521626,0.00000000,0.00000000,0.00000000,0.00000000,0.00000000,0.00000000,0.00000000,0.00000000,0.00000000,0.00000000,0.00000000
252.56000000,6.03724500,9.66900000,0.20408044,630.76521626,0.00000000,0.00000000,0.00000000,0.00000000,0.00000000,0.00000000,0.00000000,0.00000000,0.00000000,0.00000000,0.00000000
254.06000000,6.08885600,9.66800000,0.20595644,630.69998043,0.00000000,0.00000000,0.00000000,0.00000000,0.00000000,0.00000000,0.00000000,0.00000000,0.00000000,0.00000000,0.00000000
255.56000000,6.14066600,9.66700000,0.20786922,630.63474460,0.00000000,0.00000000,0.00000000,0.00000000,0.00000000,0.00000000,0.00000000,0.00000000,0.00000000,0.00000000,0.00000000
257.06000000,6.19244400,9.66600000,0.20981878,630.56950877,0.00000000,0.00000000,0.00000000,0.00000000,0.00000000,0.00000000,0.00000000,0.00000000,0.00000000,0.00000000,0.00000000
258.56000000,6.24465100,9.66500000,0.21180522,630.50427295,0.00000000,0.00000000,0.00000000,0.00000000,0.00000000,0.00000000,0.00000000,0.00000000,0.00000000,0.00000000,0.00000000
260.06000000,6.29652800,9.66400000,0.21375467,630.43903712,0.00000000,0.00000000,0.00000000,0.00000000,0.00000000,0.00000000,0.00000000,0.00000000,0.00000000,0.00000000,0.00000000
261.56000000,6.34949700,9.66300000,0.21577778,630.37380129,0.00000000,0.00000000,0.00000000,0.00000000,0.00000000,0.00000000,0.00000000,0.00000000,0.00000000,0.00000000,0.00000000
263.06000000,6.40289600,9.66200000,0.21783767,630.30856546,0.00000000,0.00000000,0.00000000,0.00000000,0.00000000,0.00000000,0.00000000,0.00000000,0.00000000,0.00000000,0.00000000
264.56000000,6.45649400,9.66000000,0.21986089,630.17809381,0.00000000,0.00000000,0.00000000,0.00000000,0.00000000,0.00000000,0.00000000,0.00000000,0.00000000,0.00000000,0.00000000
266.06000000,6.50976100,9.65700000,0.22199433,629.98238633,0.00000000,0.00000000,0.00000000,0.00000000,0.00000000,0.00000000,0.00000000,0.00000000,0.00000000,0.00000000,0.00000000
267.56000000,6.56398800,9.65700000,0.22416467,629.98238633,0.00000000,0.00000000,0.00000000,0.00000000,0.00000000,0.00000000,0.00000000,0.00000000,0.00000000,0.00000000,0.00000000
269.06000000,6.61788400,9.65400000,0.22629822,629.78667884,0.00000000,0.00000000,0.00000000,0.00000000,0.00000000,0.00000000,0.00000000,0.00000000,0.00000000,0.00000000,0.00000000
270.56000000,6.67178000,9.65200000,0.22843167,629.65620719,0.00000000,0.00000000,0.00000000,0.00000000,0.00000000,0.00000000,0.00000000,0.00000000,0.00000000,0.00000000,0.00000000
272.06000000,6.72627200,9.65000000,0.23067544,629.52573553,0.00000000,0.00000000,0.00000000,0.00000000,0.00000000,0.00000000,0.00000000,0.00000000,0.00000000,0.00000000,0.00000000
273.56000000,6.78119400,9.64800000,0.23295611,629.39526388,0.00000000,0.00000000,0.00000000,0.00000000,0.00000000,0.00000000,0.00000000,0.00000000,0.00000000,0.00000000,0.00000000
275.06000000,6.83671100,9.64600000,0.23527333,629.26479222,0.00000000,0.00000000,0.00000000,0.00000000,0.00000000,0.00000000,0.00000000,0.00000000,0.00000000,0.00000000,0.00000000
276.56000000,6.89156700,9.64300000,0.23762767,629.06908474,0.00000000,0.00000000,0.00000000,0.00000000,0.00000000,0.00000000,0.00000000,0.00000000,0.00000000,0.00000000,0.00000000
278.06000000,6.94688700,9.64000000,0.23998178,628.87337726,0.00000000,0.00000000,0.00000000,0.00000000,0.00000000,0.00000000,0.00000000,0.00000000,0.00000000,0.00000000,0.00000000
279.56000000,7.00194100,9.63700000,0.24237278,628.67766978,0.00000000,0.00000000,0.00000000,0.00000000,0.00000000,0.00000000,0.00000000,0.00000000,0.00000000,0.00000000,0.00000000
281.06000000,7.05815400,9.63500000,0.24483733,628.54719812,0.00000000,0.00000000,0.00000000,0.00000000,0.00000000,0.00000000,0.00000000,0.00000000,0.00000000,0.00000000,0.00000000
282.56000000,7.11492900,9.63200000,0.24737544,628.35149064,0.00000000,0.00000000,0.00000000,0.00000000,0.00000000,0.00000000,0.00000000,0.00000000,0.00000000,0.00000000,0.00000000
284.06000000,7.17101000,9.62900000,0.24998711,628.15578316,0.00000000,0.00000000,0.00000000,0.00000000,0.00000000,0.00000000,0.00000000,0.00000000,0.00000000,0.00000000,0.00000000
285.56000000,7.22768700,9.62500000,0.25259867,627.89483985,0.00000000,0.00000000,0.00000000,0.00000000,0.00000000,0.00000000,0.00000000,0.00000000,0.00000000,0.00000000,0.00000000
287.06000000,7.28486000,9.62200000,0.25532078,627.69913236,0.00000000,0.00000000,0.00000000,0.00000000,0.00000000,0.00000000,0.00000000,0.00000000,0.00000000,0.00000000,0.00000000
288.56000000,7.34190000,9.61800000,0.25807967,627.43818905,0.00000000,0.00000000,0.00000000,0.00000000,0.00000000,0.00000000,0.00000000,0.00000000,0.00000000,0.00000000,0.00000000
290.06000000,7.39930500,9.61300000,0.26087511,627.11200992,0.00000000,0.00000000,0.00000000,0.00000000,0.00000000,0.00000000,0.00000000,0.00000000,0.00000000,0.00000000,0.00000000
291.56000000,7.45621200,9.60900000,0.26381789,626.85106661,0.00000000,0.00000000,0.00000000,0.00000000,0.00000000,0.00000000,0.00000000,0.00000000,0.00000000,0.00000000,0.00000000
293.06000000,7.51404800,9.60600000,0.26676056,626.65535912,0.00000000,0.00000000,0.00000000,0.00000000,0.00000000,0.00000000,0.00000000,0.00000000,0.00000000,0.00000000,0.00000000
294.56000000,7.57195000,9.60100000,0.26985056,626.32917999,0.00000000,0.00000000,0.00000000,0.00000000,0.00000000,0.00000000,0.00000000,0.00000000,0.00000000,0.00000000,0.00000000
296.06000000,7.63041300,9.59600000,0.27301400,626.00300085,0.00000000,0.00000000,0.00000000,0.00000000,0.00000000,0.00000000,0.00000000,0.00000000,0.00000000,0.00000000,0.00000000
297.56000000,7.68851200,9.59000000,0.27621411,625.61158588,0.00000000,0.00000000,0.00000000,0.00000000,0.00000000,0.00000000,0.00000000,0.00000000,0.00000000,0.00000000,0.00000000
299.06000000,7.74694200,9.58500000,0.27956144,625.28540675,0.00000000,0.00000000,0.00000000,0.00000000,0.00000000,0.00000000,0.00000000,0.00000000,0.00000000,0.00000000,0.00000000
300.56000000,7.80557200,9.57900000,0.28305600,624.89399178,0.00000000,0.00000000,0.00000000,0.00000000,0.00000000,0.00000000,0.00000000,0.00000000,0.00000000,0.00000000,0.00000000
302.06000000,7.86416800,9.57200000,0.28655044,624.43734099,0.00000000,0.00000000,0.00000000,0.00000000,0.00000000,0.00000000,0.00000000,0.00000000,0.00000000,0.00000000,0.00000000
303.56000000,7.92302900,9.56600000,0.29022878,624.04592602,0.00000000,0.00000000,0.00000000,0.00000000,0.00000000,0.00000000,0.00000000,0.00000000,0.00000000,0.00000000,0.00000000
305.06000000,7.98228700,9.55900000,0.29405422,623.58927523,0.00000000,0.00000000,0.00000000,0.00000000,0.00000000,0.00000000,0.00000000,0.00000000,0.00000000,0.00000000,0.00000000
306.56000000,8.04240500,9.55200000,0.29806378,623.13262444,0.00000000,0.00000000,0.00000000,0.00000000,0.00000000,0.00000000,0.00000000,0.00000000,0.00000000,0.00000000,0.00000000
308.06000000,8.10183000,9.54200000,0.30214678,622.48026616,0.00000000,0.00000000,0.00000000,0.00000000,0.00000000,0.00000000,0.00000000,0.00000000,0.00000000,0.00000000,0.00000000
309.56000000,8.16211500,9.53400000,0.30634011,621.95837954,0.00000000,0.00000000,0.00000000,0.00000000,0.00000000,0.00000000,0.00000000,0.00000000,0.00000000,0.00000000,0.00000000
311.06000000,8.22213400,9.52300000,0.31075433,621.24078544,0.00000000,0.00000000,0.00000000,0.00000000,0.00000000,0.00000000,0.00000000,0.00000000,0.00000000,0.00000000,0.00000000
312.56000000,8.28261700,9.51300000,0.31531544,620.58842716,0.00000000,0.00000000,0.00000000,0.00000000,0.00000000,0.00000000,0.00000000,0.00000000,0.00000000,0.00000000,0.00000000
314.06000000,8.34197500,9.50000000,0.31991333,619.74036141,0.00000000,0.00000000,0.00000000,0.00000000,0.00000000,0.00000000,0.00000000,0.00000000,0.00000000,0.00000000,0.00000000
315.56000000,8.40265700,9.48900000,0.32476878,619.02276730,0.00000000,0.00000000,0.00000000,0.00000000,0.00000000,0.00000000,0.00000000,0.00000000,0.00000000,0.00000000,0.00000000
317.06000000,8.46330700,9.47500000,0.32977144,618.10946572,0.00000000,0.00000000,0.00000000,0.00000000,0.00000000,0.00000000,0.00000000,0.00000000,0.00000000,0.00000000,0.00000000
318.56000000,8.52455100,9.46000000,0.33492111,617.13092831,0.00000000,0.00000000,0.00000000,0.00000000,0.00000000,0.00000000,0.00000000,0.00000000,0.00000000,0.00000000,0.00000000
320.06000000,8.58606100,9.44300000,0.34025478,616.02191924,0.00000000,0.00000000,0.00000000,0.00000000,0.00000000,0.00000000,0.00000000,0.00000000,0.00000000,0.00000000,0.00000000
321.56000000,8.64661000,9.42600000,0.34569878,614.91291017,0.00000000,0.00000000,0.00000000,0.00000000,0.00000000,0.00000000,0.00000000,0.00000000,0.00000000,0.00000000,0.00000000
323.06000000,8.70778700,9.40500000,0.35132656,613.54295779,0.00000000,0.00000000,0.00000000,0.00000000,0.00000000,0.00000000,0.00000000,0.00000000,0.00000000,0.00000000,0.00000000
324.56000000,8.76853600,9.38600000,0.35706489,612.30347707,0.00000000,0.00000000,0.00000000,0.00000000,0.00000000,0.00000000,0.00000000,0.00000000,0.00000000,0.00000000,0.00000000
326.06000000,8.83034400,9.36300000,0.36298722,610.80305304,0.00000000,0.00000000,0.00000000,0.00000000,0.00000000,0.00000000,0.00000000,0.00000000,0.00000000,0.00000000,0.00000000
327.56000000,8.89211800,9.33900000,0.36905656,609.23739318,0.00000000,0.00000000,0.00000000,0.00000000,0.00000000,0.00000000,0.00000000,0.00000000,0.00000000,0.00000000,0.00000000
329.06000000,8.95425600,9.31100000,0.37519944,607.41079001,0.00000000,0.00000000,0.00000000,0.00000000,0.00000000,0.00000000,0.00000000,0.00000000,0.00000000,0.00000000,0.00000000
330.56000000,9.01553400,9.28600000,0.38148956,605.77989432,0.00000000,0.00000000,0.00000000,0.00000000,0.00000000,0.00000000,0.00000000,0.00000000,0.00000000,0.00000000,0.00000000
332.06000000,9.07701000,9.25200000,0.38789011,603.56187618,0.00000000,0.00000000,0.00000000,0.00000000,0.00000000,0.00000000,0.00000000,0.00000000,0.00000000,0.00000000,0.00000000
333.56000000,9.13895100,9.22200000,0.39440089,601.60480136,0.00000000,0.00000000,0.00000000,0.00000000,0.00000000,0.00000000,0.00000000,0.00000000,0.00000000,0.00000000,0.00000000
335.06000000,9.20079200,9.18600000,0.40105889,599.25631157,0.00000000,0.00000000,0.00000000,0.00000000,0.00000000,0.00000000,0.00000000,0.00000000,0.00000000,0.00000000,0.00000000
336.56000000,9.26319600,9.14900000,0.40771689,596.84258595,0.00000000,0.00000000,0.00000000,0.00000000,0.00000000,0.00000000,0.00000000,0.00000000,0.00000000,0.00000000,0.00000000
338.06000000,9.32586500,9.10700000,0.41463244,594.10268119,0.00000000,0.00000000,0.00000000,0.00000000,0.00000000,0.00000000,0.00000000,0.00000000,0.00000000,0.00000000,0.00000000
339.56000000,9.38913100,9.06600000,0.42154800,591.42801226,0.00000000,0.00000000,0.00000000,0.00000000,0.00000000,0.00000000,0.00000000,0.00000000,0.00000000,0.00000000,0.00000000
341.06000000,9.45170300,9.01100000,0.42846367,587.84004175,0.00000000,0.00000000,0.00000000,0.00000000,0.00000000,0.00000000,0.00000000,0.00000000,0.00000000,0.00000000,0.00000000
342.56000000,9.51463700,8.96300000,0.43545300,584.70872203,0.00000000,0.00000000,0.00000000,0.00000000,0.00000000,0.00000000,0.00000000,0.00000000,0.00000000,0.00000000,0.00000000
344.06000000,9.57757400,8.90200000,0.44255289,580.72933655,0.00000000,0.00000000,0.00000000,0.00000000,0.00000000,0.00000000,0.00000000,0.00000000,0.00000000,0.00000000,0.00000000
345.56000000,9.64223300,8.83900000,0.44980000,576.61947942,0.00000000,0.00000000,0.00000000,0.00000000,0.00000000,0.00000000,0.00000000,0.00000000,0.00000000,0.00000000,0.00000000
347.06000000,9.70692700,8.76200000,0.45708411,571.59632070,0.00000000,0.00000000,0.00000000,0.00000000,0.00000000,0.00000000,0.00000000,0.00000000,0.00000000,0.00000000,0.00000000
348.56000000,9.77202000,8.68200000,0.46444244,566.37745450,0.00000000,0.00000000,0.00000000,0.00000000,0.00000000,0.00000000,0.00000000,0.00000000,0.00000000,0.00000000,0.00000000
350.06000000,9.83936600,8.58400000,0.47202178,559.98434340,0.00000000,0.00000000,0.00000000,0.00000000,0.00000000,0.00000000,0.00000000,0.00000000,0.00000000,0.00000000,0.00000000
351.56000000,9.90652000,8.48500000,0.47963922,553.52599648,0.00000000,0.00000000,0.00000000,0.00000000,0.00000000,0.00000000,0.00000000,0.00000000,0.00000000,0.00000000,0.00000000
353.06000000,9.97606200,8.35200000,0.48747867,544.84963142,0.00000000,0.00000000,0.00000000,0.00000000,0.00000000,0.00000000,0.00000000,0.00000000,0.00000000,0.00000000,0.00000000
354.56000000,10.04597700,8.20300000,0.49554067,535.12949312,0.00000000,0.00000000,0.00000000,0.00000000,0.00000000,0.00000000,0.00000000,0.00000000,0.00000000,0.00000000,0.00000000
356.06000000,10.12060100,8.00500000,0.50412011,522.21279927,0.00000000,0.00000000,0.00000000,0.00000000,0.00000000,0.00000000,0.00000000,0.00000000,0.00000000,0.00000000,0.00000000