File: polyN_optimization/DP600_results/DATA/UT_30_1.csv
Time[s],Displacement[mm],Force[kN],EngStrain_longi,EngStress[MPa],TrueStrain,TrueStress[MPa],TrueStrainRate[1/s],PlasticStrain_longi,PlasticStress[MPa],PlasticStrain_thick,PlasticStrain_width,R-Value,Thickness[mm],Width[mm], Young's Modulus [MPa]
0.65000000,0.00000000,-0.01500000,0.00000000,-0.98000784,0.00000000,-0.98000784,0.00000000,0.00062242,343.12273473,0.00029083,-0.00091325,0.80962664,1.53060000,10.00000000,236521.49224068
2.15000000,0.00137500,0.01900000,0.00005411,1.24134326,0.00005411,1.24141043,0.00004355,0.00101961,356.84239907,0.00009716,-0.00111677,0.00000000,0.00000000,0.00000000,0.00000000
3.65000000,0.00295000,0.45200000,0.00011000,29.53090291,0.00010999,29.53415131,-0.00002066,0.00148618,372.11071306,-0.00019521,-0.00129096,0.00000000,0.00000000,0.00000000,0.00000000
5.15000000,0.00533000,0.74100000,0.00018322,48.41238730,0.00018321,48.42125752,0.00017598,0.00214936,382.93739584,-0.00067749,-0.00147187,0.00000000,0.00000000,0.00000000,0.00000000
6.65000000,0.00729600,1.10200000,0.00021478,71.99790932,0.00021475,72.01337287,0.00008221,0.00285371,394.25600771,-0.00110014,-0.00175357,0.00000000,0.00000000,0.00000000,0.00000000
8.15000000,0.00880900,1.44200000,0.00025233,94.21142036,0.00025230,94.23519304,-0.00000666,0.00362130,403.70839787,-0.00145281,-0.00216848,0.00000000,0.00000000,0.00000000,0.00000000
9.65000000,0.01062700,1.80600000,0.00031489,117.99294394,0.00031484,118.03009861,-0.00004332,0.00434233,412.82727098,-0.00180408,-0.00253824,0.00000000,0.00000000,0.00000000,0.00000000
11.15000000,0.01311000,2.14300000,0.00041233,140.01045342,0.00041225,140.06818439,-0.00005731,0.00518757,420.29802008,-0.00224740,-0.00294017,0.00000000,0.00000000,0.00000000,0.00000000
12.65000000,0.01592100,2.50600000,0.00051311,163.72664315,0.00051298,163.81065311,-0.00010972,0.00610234,429.06550101,-0.00281146,-0.00329088,0.00000000,0.00000000,0.00000000,0.00000000
14.15000000,0.01943300,2.84100000,0.00065078,185.61348491,0.00065057,185.73427804,0.00004353,0.00698981,435.72329934,-0.00335678,-0.00363302,0.00000000,0.00000000,0.00000000,0.00000000
15.65000000,0.02289000,3.17400000,0.00077611,207.36965896,0.00077581,207.53060085,0.00018231,0.00780024,443.08621909,-0.00381000,-0.00399025,0.00000000,0.00000000,0.00000000,0.00000000
17.15000000,0.02606100,3.50100000,0.00091556,228.73382987,0.00091514,228.94324840,0.00035948,0.00868618,449.70114989,-0.00429284,-0.00439334,0.00000000,0.00000000,0.00000000,0.00000000
18.65000000,0.02993100,3.84900000,0.00098700,251.47001176,0.00098651,251.71821266,0.00030594,0.00966399,456.70117206,-0.00485364,-0.00481035,0.00000000,0.00000000,0.00000000,0.00000000
20.15000000,0.03439800,4.16400000,0.00107411,272.05017640,0.00107353,272.34238852,0.00016161,0.01062842,462.44855592,-0.00529022,-0.00533821,0.00000000,0.00000000,0.00000000,0.00000000
21.65000000,0.04045800,4.49300000,0.00123233,293.54501503,0.00123157,293.90676033,0.00007347,0.01148850,469.35287700,-0.00571484,-0.00577366,0.00000000,0.00000000,0.00000000,0.00000000
23.15000000,0.04880100,4.78100000,0.00144944,312.36116556,0.00144840,312.81391571,-0.00009541,0.01242731,474.77839634,-0.00622707,-0.00620024,0.00000000,0.00000000,0.00000000,0.00000000
24.65000000,0.05883400,5.04900000,0.00181733,329.87063897,0.00181568,330.47012387,-0.00006610,0.01339471,480.82640533,-0.00678191,-0.00661279,0.00000000,0.00000000,0.00000000,0.00000000
26.15000000,0.07145200,5.29400000,0.00235456,345.87743369,0.00235179,346.69182132,0.00019089,0.01437809,486.36112249,-0.00739404,-0.00698405,0.00000000,0.00000000,0.00000000,0.00000000
27.65000000,0.08781000,5.54300000,0.00289922,362.14556383,0.00289503,363.19550430,0.00035234,0.01530227,492.01067253,-0.00794632,-0.00735596,0.00000000,0.00000000,0.00000000,0.00000000
29.15000000,0.10572500,5.71900000,0.00350622,373.64432249,0.00350009,374.95440251,0.00048392,0.01622983,496.73818799,-0.00845703,-0.00777280,0.00000000,0.00000000,0.00000000,0.00000000
30.65000000,0.12711700,5.90000000,0.00416844,385.46975042,0.00415978,387.07655966,0.00037381,0.01723157,502.37979921,-0.00895728,-0.00827429,0.00000000,0.00000000,0.00000000,0.00000000
32.15000000,0.15129000,6.05000000,0.00497044,395.26982883,0.00495813,397.23449555,0.00045402,0.01824771,507.03696581,-0.00947846,-0.00876925,0.00000000,0.00000000,0.00000000,0.00000000
33.65000000,0.17658800,6.19400000,0.00584233,404.67790409,0.00582533,407.04216730,0.00056323,0.01923240,512.02179767,-0.00998479,-0.00924761,0.00000000,0.00000000,0.00000000,0.00000000
35.15000000,0.20185200,6.30700000,0.00668867,412.06062982,0.00666640,414.81676602,0.00071645,0.02018608,516.53115607,-0.01046930,-0.00971678,0.00000000,0.00000000,0.00000000,0.00000000
36.65000000,0.22887000,6.43900000,0.00752022,420.68469881,0.00749209,423.84834123,0.00060620,0.02117711,521.26955018,-0.01103619,-0.01014092,0.00000000,0.00000000,0.00000000,0.00000000
38.15000000,0.25727700,6.53800000,0.00841800,427.15275056,0.00838277,430.74852241,0.00047451,0.02224184,525.38452600,-0.01169425,-0.01054759,0.00000000,0.00000000,0.00000000,0.00000000
39.65000000,0.28495600,6.64800000,0.00938556,434.33947472,0.00934178,438.41599199,0.00055421,0.02324104,530.21234631,-0.01225165,-0.01098939,0.00000000,0.00000000,0.00000000,0.00000000
41.15000000,0.31180600,6.74400000,0.01033089,440.61152489,0.01027789,445.16343360,0.00073543,0.02429433,534.00201363,-0.01287664,-0.01141769,0.00000000,0.00000000,0.00000000,0.00000000
42.65000000,0.34153800,6.84500000,0.01122844,447.21024435,0.01116587,452.23171973,0.00067652,0.02531436,538.52217013,-0.01345505,-0.01185931,0.00000000,0.00000000,0.00000000,0.00000000
44.15000000,0.36941600,6.92800000,0.01213711,452.63295440,0.01206405,458.12661086,0.00045058,0.02636585,542.19176862,-0.01402669,-0.01233916,0.00000000,0.00000000,0.00000000,0.00000000
45.65000000,0.39894900,7.02800000,0.01313022,459.16634000,0.01304477,465.19529608,0.00042842,0.02745308,546.36069287,-0.01462328,-0.01282980,0.00000000,0.00000000,0.00000000,0.00000000
47.15000000,0.42828400,7.10500000,0.01413078,464.19704691,0.01403187,470.75651222,0.00061672,0.02849617,549.83809004,-0.01514508,-0.01335108,0.00000000,0.00000000,0.00000000,0.00000000
48.65000000,0.45837800,7.19100000,0.01509444,469.81575853,0.01498166,476.90736639,0.00058700,0.02952834,553.85739348,-0.01565118,-0.01387717,0.00000000,0.00000000,0.00000000,0.00000000
50.15000000,0.48777800,7.26900000,0.01604711,474.91179929,0.01591972,482.53276171,0.00047072,0.03061223,557.23625267,-0.01624850,-0.01436372,0.00000000,0.00000000,0.00000000,0.00000000
51.65000000,0.51893100,7.34900000,0.01707333,480.13850777,0.01692922,488.33607256,0.00047025,0.03166039,561.14419213,-0.01682337,-0.01483701,0.00000000,0.00000000,0.00000000,0.00000000
53.15000000,0.54886000,7.41500000,0.01808122,484.45054227,0.01791970,493.21000018,0.00054904,0.03274644,564.33472187,-0.01739716,-0.01534927,0.00000000,0.00000000,0.00000000,0.00000000
54.65000000,0.57948400,7.49400000,0.01907456,489.61191690,0.01889492,498.95104660,0.00059933,0.03381863,567.93141908,-0.01803061,-0.01578801,0.00000000,0.00000000,0.00000000,0.00000000
56.15000000,0.61133200,7.55600000,0.02009356,493.66261597,0.01989434,503.58205317,0.00054098,0.03489966,570.92816052,-0.01865162,-0.01624804,0.00000000,0.00000000,0.00000000,0.00000000
57.65000000,0.64218800,7.62600000,0.02115300,498.23598589,0.02093238,508.77517170,0.00054042,0.03599766,574.55347445,-0.01925930,-0.01673836,0.00000000,0.00000000,0.00000000,0.00000000
59.15000000,0.67440100,7.68800000,0.02223456,502.28668496,0.02199097,513.45480616,0.00064075,0.03710827,577.51171784,-0.01987318,-0.01723509,0.00000000,0.00000000,0.00000000,0.00000000
60.65000000,0.70585200,7.75200000,0.02326444,506.46805174,0.02299795,518.25074960,0.00070441,0.03815567,580.84861968,-0.02041656,-0.01773911,0.00000000,0.00000000,0.00000000,0.00000000
62.15000000,0.73790100,7.80600000,0.02430189,509.99607997,0.02401130,522.38994804,0.00070391,0.03923244,583.73090428,-0.02098546,-0.01824699,0.00000000,0.00000000,0.00000000,0.00000000
63.65000000,0.77044400,7.87100000,0.02538711,514.24278061,0.02507021,527.29791922,0.00065308,0.04037028,586.85994577,-0.02160757,-0.01876270,0.00000000,0.00000000,0.00000000,0.00000000
65.15000000,0.80259200,7.92100000,0.02651267,517.50947341,0.02616730,531.23002957,0.00080288,0.04147319,589.63236535,-0.02218016,-0.01929303,0.00000000,0.00000000,0.00000000,0.00000000
66.65000000,0.83516900,7.97700000,0.02757944,521.16816935,0.02720598,535.54169792,0.00073758,0.04258380,592.75764232,-0.02278811,-0.01979569,0.00000000,0.00000000,0.00000000,0.00000000
68.15000000,0.86820900,8.02800000,0.02864989,524.50019600,0.02824715,539.52706834,0.00073681,0.04371645,595.42190302,-0.02343364,-0.02028281,0.00000000,0.00000000,0.00000000,0.00000000
69.65000000,0.90148100,8.08100000,0.02975700,527.96289037,0.02932285,543.67348210,0.00075026,0.04486323,598.51232259,-0.02407187,-0.02079136,0.00000000,0.00000000,0.00000000,0.00000000
71.15000000,0.93498400,8.12600000,0.03088256,530.90291389,0.03041529,547.29855262,0.00072098,0.04597633,601.03840916,-0.02471601,-0.02126031,0.00000000,0.00000000,0.00000000,0.00000000
72.65000000,0.96848700,8.17900000,0.03198244,534.36560826,0.03148166,551.45592664,0.00073443,0.04706934,603.83279080,-0.02532330,-0.02174604,0.00000000,0.00000000,0.00000000,0.00000000
74.15000000,1.00175900,8.21900000,0.03306744,536.97896250,0.03253248,554.73548451,0.00073344,0.04819075,606.30512938,-0.02596124,-0.02222951,0.00000000,0.00000000,0.00000000,0.00000000
75.65000000,1.03549400,8.26700000,0.03419311,540.11498759,0.03362152,558.58319937,0.00071158,0.04935085,609.15113306,-0.02662008,-0.02273078,0.00000000,0.00000000,0.00000000,0.00000000
77.15000000,1.06979300,8.30900000,0.03530022,542.85900954,0.03469145,562.02205321,0.00071790,0.05045944,611.55667607,-0.02719191,-0.02326753,0.00000000,0.00000000,0.00000000,0.00000000
78.65000000,1.10362700,8.35300000,0.03644422,545.73369920,0.03579584,565.62253941,0.00072419,0.05160362,614.26557236,-0.02781235,-0.02379127,0.00000000,0.00000000,0.00000000,0.00000000
80.15000000,1.13828900,8.38900000,0.03760656,548.08571802,0.03691667,568.69733402,0.00078722,0.05275198,616.56684859,-0.02844204,-0.02430994,0.00000000,0.00000000,0.00000000,0.00000000
81.65000000,1.17272000,8.43400000,0.03875056,551.02574154,0.03801860,572.37829515,0.00080048,0.05388051,619.06842005,-0.02905351,-0.02482701,0.00000000,0.00000000,0.00000000,0.00000000
83.15000000,1.20708400,8.46800000,0.03991300,553.24709264,0.03913706,575.32884385,0.00080685,0.05501917,621.37290641,-0.02968584,-0.02533333,0.00000000,0.00000000,0.00000000,0.00000000
84.65000000,1.24187900,8.50800000,0.04104944,555.86044688,0.04022929,578.67820942,0.00074191,0.05615895,623.89114811,-0.03031546,-0.02584349,0.00000000,0.00000000,0.00000000,0.00000000
86.15000000,1.27624300,8.54200000,0.04216411,558.08179799,0.04129943,581.61282093,0.00075562,0.05732978,626.15548469,-0.03095746,-0.02637232,0.00000000,0.00000000,0.00000000,0.00000000
87.65000000,1.31183100,8.58000000,0.04331178,560.56448452,0.04240006,584.84352890,0.00077589,0.05848578,628.34528342,-0.03160812,-0.02687766,0.00000000,0.00000000,0.00000000,0.00000000
89.15000000,1.34685800,8.61100000,0.04449244,562.58983405,0.04353107,587.62083099,0.00073244,0.05961617,630.52315109,-0.03224763,-0.02736853,0.00000000,0.00000000,0.00000000,0.00000000
90.65000000,1.38241200,8.64800000,0.04568789,565.00718672,0.04467494,590.82117229,0.00078794,0.06082464,632.75474142,-0.03292035,-0.02790429,0.00000000,0.00000000,0.00000000,0.00000000
92.15000000,1.41803500,8.67800000,0.04689822,566.96720240,0.04583172,593.55695626,0.00085052,0.06195164,635.07882668,-0.03356144,-0.02839020,0.00000000,0.00000000,0.00000000,0.00000000
93.65000000,1.45359100,8.71100000,0.04804956,569.12321965,0.04693087,596.46933741,0.00075817,0.06307567,637.05544345,-0.03414502,-0.02893065,0.00000000,0.00000000,0.00000000,0.00000000
95.15000000,1.48984200,8.74100000,0.04922667,571.08323533,0.04805338,599.19575940,0.00068019,0.06425153,639.41943464,-0.03479214,-0.02945939,0.00000000,0.00000000,0.00000000,0.00000000
96.65000000,1.52562900,8.77300000,0.05044056,573.17391872,0.04920965,602.08512962,0.00074247,0.06544513,641.37849742,-0.03545225,-0.02999288,0.00000000,0.00000000,0.00000000,0.00000000
98.15000000,1.56161500,8.79800000,0.05160289,574.80726512,0.05031556,604.46898056,0.00074165,0.06659208,643.45177948,-0.03605308,-0.03053900,0.00000000,0.00000000,0.00000000,0.00000000
99.65000000,1.59733700,8.83000000,0.05279844,576.89794852,0.05145180,607.35726280,0.00074778,0.06776612,645.33552386,-0.03671267,-0.03105345,0.00000000,0.00000000,0.00000000,0.00000000
101.15000000,1.63461400,8.85600000,0.05401600,578.59662877,0.05260763,609.85010427,0.00071211,0.06891658,647.55966215,-0.03731813,-0.03159845,0.00000000,0.00000000,0.00000000,0.00000000
102.65000000,1.67080000,8.88400000,0.05524456,580.42597674,0.05377255,612.49135186,0.00080187,0.07009486,649.38316932,-0.03799062,-0.03210424,0.00000000,0.00000000,0.00000000,0.00000000
104.15000000,1.70777900,8.90900000,0.05644744,582.05932314,0.05491181,614.91508445,0.00076624,0.07126732,651.41809527,-0.03866940,-0.03259792,0.00000000,0.00000000,0.00000000,0.00000000
105.65000000,1.74432800,8.93600000,0.05765756,583.82333725,0.05605661,617.48516376,0.00073719,0.07241576,653.22915208,-0.03928094,-0.03313482,0.00000000,0.00000000,0.00000000,0.00000000
107.15000000,1.78081000,8.95800000,0.05890467,585.26068209,0.05723504,619.73526748,0.00081316,0.07363326,655.23046021,-0.03997867,-0.03365460,0.00000000,0.00000000,0.00000000,0.00000000
108.65000000,1.81841800,8.98600000,0.06011100,587.09003005,0.05837362,622.38059885,0.00079106,0.07479921,657.06001577,-0.04059922,-0.03419998,0.00000000,0.00000000,0.00000000,0.00000000
110.15000000,1.85543100,9.00600000,0.06134333,588.39670717,0.05953540,624.49092251,0.00081109,0.07599392,658.98293012,-0.04124493,-0.03474899,0.00000000,0.00000000,0.00000000,0.00000000
111.65000000,1.89257600,9.02900000,0.06255722,589.89938586,0.06067848,626.80185283,0.00073400,0.07719146,660.69833785,-0.04193664,-0.03525482,0.00000000,0.00000000,0.00000000,0.00000000
113.15000000,1.92968700,9.05000000,0.06383000,591.27139684,0.06187560,629.01225010,0.00079540,0.07836597,662.68606407,-0.04255520,-0.03581077,0.00000000,0.00000000,0.00000000,0.00000000
114.65000000,1.96772600,9.07500000,0.06504389,592.90474324,0.06301601,631.46957348,0.00079470,0.07953055,664.31501172,-0.04321421,-0.03631634,0.00000000,0.00000000,0.00000000,0.00000000
116.15000000,2.00497000,9.09300000,0.06627989,594.08075265,0.06417585,633.45635892,0.00067619,0.08076699,666.20872129,-0.04390493,-0.03686207,0.00000000,0.00000000,0.00000000,0.00000000
117.65000000,2.04261100,9.11300000,0.06753789,595.38742977,0.06535496,635.59863984,0.00075827,0.08195233,667.85778390,-0.04458303,-0.03736930,0.00000000,0.00000000,0.00000000,0.00000000
119.15000000,2.08008700,9.13400000,0.06878122,596.75944074,0.06651895,637.80528445,0.00081938,0.08312215,669.64232192,-0.04520454,-0.03791761,0.00000000,0.00000000,0.00000000,0.00000000
120.65000000,2.11845600,9.15400000,0.07002811,598.06611786,0.06768492,639.94755842,0.00077708,0.08434827,671.32500052,-0.04590225,-0.03844602,0.00000000,0.00000000,0.00000000,0.00000000
122.15000000,2.15652800,9.17400000,0.07130456,599.37279498,0.06887712,642.11080574,0.00075561,0.08556594,673.07674113,-0.04656784,-0.03899810,0.00000000,0.00000000,0.00000000,0.00000000
123.65000000,2.19479900,9.19200000,0.07258467,600.54880439,0.07007131,644.13943917,0.00083036,0.08676587,674.67634191,-0.04721032,-0.03955555,0.00000000,0.00000000,0.00000000,0.00000000
125.15000000,2.23247300,9.21000000,0.07380956,601.72481380,0.07121266,646.13785487,0.00074701,0.08795777,676.27338207,-0.04782453,-0.04013324,0.00000000,0.00000000,0.00000000,0.00000000
126.65000000,2.27123900,9.22600000,0.07508956,602.77015549,0.07240397,648.03189857,0.00080754,0.08915822,677.87910841,-0.04851380,-0.04064442,0.00000000,0.00000000,0.00000000,0.00000000
128.15000000,2.30960800,9.24400000,0.07637700,603.94616490,0.07360077,650.07376114,0.00082723,0.09039655,679.65752668,-0.04919586,-0.04120069,0.00000000,0.00000000,0.00000000,0.00000000
129.65000000,2.34797800,9.26000000,0.07764233,604.99150660,0.07477563,651.96445882,0.00081264,0.09156136,681.10081416,-0.04982633,-0.04173503,0.00000000,0.00000000,0.00000000,0.00000000
131.15000000,2.38657800,9.27800000,0.07890400,606.16751601,0.07594571,653.99655769,0.00083868,0.09278739,682.73279185,-0.05052648,-0.04226092,0.00000000,0.00000000,0.00000000,0.00000000
132.65000000,2.42561100,9.29300000,0.08018789,607.14752385,0.07713500,655.83340203,0.00076318,0.09403579,684.23863786,-0.05124574,-0.04279005,0.00000000,0.00000000,0.00000000,0.00000000
134.15000000,2.46477400,9.31000000,0.08149000,608.25819940,0.07833972,657.82516007,0.00082331,0.09521261,685.77028947,-0.05187821,-0.04333441,0.00000000,0.00000000,0.00000000,0.00000000
135.65000000,2.50417000,9.32300000,0.08276644,609.10753953,0.07951929,659.52120486,0.00077471,0.09641484,687.24971347,-0.05255092,-0.04386392,0.00000000,0.00000000,0.00000000,0.00000000
137.15000000,2.54336700,9.33800000,0.08405378,610.08754737,0.08070751,661.36771050,0.00073975,0.09766500,688.83736417,-0.05326633,-0.04439867,0.00000000,0.00000000,0.00000000,0.00000000
138.65000000,2.58279600,9.35200000,0.08537433,611.00222135,0.08192494,663.16612866,0.00080664,0.09887083,690.32461910,-0.05392336,-0.04494747,0.00000000,0.00000000,0.00000000,0.00000000
140.15000000,2.62209300,9.36700000,0.08666544,611.98222919,0.08311378,665.01994108,0.00083965,0.10010505,691.83417934,-0.05465437,-0.04545068,0.00000000,0.00000000,0.00000000,0.00000000
141.65000000,2.66138900,9.38000000,0.08796022,612.83156932,0.08430459,666.73637034,0.00073035,0.10132150,693.26130003,-0.05533184,-0.04598966,0.00000000,0.00000000,0.00000000,0.00000000
143.15000000,2.70141300,9.39400000,0.08926611,613.74624330,0.08550418,668.53298365,0.00074315,0.10255289,694.70129644,-0.05605240,-0.04650049,0.00000000,0.00000000,0.00000000,0.00000000
144.65000000,2.74140400,9.40500000,0.09062333,614.46491572,0.08674940,670.14977460,0.00087696,0.10376339,696.05625323,-0.05670971,-0.04705367,0.00000000,0.00000000,0.00000000,0.00000000
146.15000000,2.78172700,9.41900000,0.09191444,615.37958970,0.08793253,671.94186281,0.00077494,0.10498154,697.56494658,-0.05736189,-0.04761966,0.00000000,0.00000000,0.00000000,0.00000000
147.65000000,2.82185200,9.43000000,0.09325711,616.09826212,0.08916142,673.55380621,0.00078069,0.10622881,698.87729530,-0.05805319,-0.04817563,0.00000000,0.00000000,0.00000000,0.00000000
149.15000000,2.86197500,9.44200000,0.09459233,616.88226839,0.09038200,675.23460155,0.00080675,0.10745745,700.32522664,-0.05873369,-0.04872377,0.00000000,0.00000000,0.00000000,0.00000000
150.65000000,2.90176800,9.45200000,0.09587600,617.53560695,0.09155404,676.74245080,0.00075185,0.10866848,701.68995042,-0.05935303,-0.04931545,0.00000000,0.00000000,0.00000000,0.00000000
152.15000000,2.94225700,9.46500000,0.09724433,618.38494708,0.09280189,678.51937900,0.00083135,0.10993324,703.16829174,-0.06009314,-0.04984010,0.00000000,0.00000000,0.00000000,0.00000000
153.65000000,2.98291000,9.47500000,0.09857233,619.03828564,0.09401146,680.05833388,0.00075688,0.11117727,704.56110443,-0.06080090,-0.05037637,0.00000000,0.00000000,0.00000000,0.00000000
155.15000000,3.02366300,9.48600000,0.09992967,619.75695806,0.09524624,681.68906429,0.00088308,0.11239095,705.78760697,-0.06150398,-0.05088696,0.00000000,0.00000000,0.00000000,0.00000000
156.65000000,3.06435000,9.49500000,0.10124278,620.34496276,0.09643934,683.15040997,0.00080168,0.11367134,707.13708965,-0.06223518,-0.05143616,0.00000000,0.00000000,0.00000000,0.00000000
158.15000000,3.10510300,9.50600000,0.10259644,621.06363518,0.09766780,684.78255592,0.00074747,0.11487186,708.43210642,-0.06293146,-0.05194040,0.00000000,0.00000000,0.00000000,0.00000000
159.65000000,3.14631900,9.51500000,0.10397222,621.65163988,0.09891479,686.28614233,0.00087320,0.11614904,709.78382130,-0.06367692,-0.05247213,0.00000000,0.00000000,0.00000000,0.00000000
161.15000000,3.18667500,9.52500000,0.10529278,622.30497844,0.10011026,687.82919824,0.00084561,0.11735951,711.09024410,-0.06431132,-0.05304819,0.00000000,0.00000000,0.00000000,0.00000000
162.65000000,3.22789100,9.53300000,0.10665367,622.82764929,0.10134075,689.25450179,0.00079113,0.11864030,712.37500775,-0.06502966,-0.05361064,0.00000000,0.00000000,0.00000000,0.00000000
164.15000000,3.26960400,9.54300000,0.10800733,623.48098785,0.10256321,690.82150673,0.00081023,0.11989672,713.64445844,-0.06567314,-0.05422358,0.00000000,0.00000000,0.00000000,0.00000000
165.65000000,3.31108400,9.55200000,0.10935733,624.06899255,0.10378087,692.31551339,0.00076275,0.12114222,714.83389912,-0.06636795,-0.05477427,0.00000000,0.00000000,0.00000000,0.00000000
167.15000000,3.35223600,9.56000000,0.11073678,624.59166340,0.10502356,693.75693163,0.00080163,0.12244032,716.21169855,-0.06707006,-0.05537025,0.00000000,0.00000000,0.00000000,0.00000000
168.65000000,3.39388300,9.56700000,0.11207933,625.04900039,0.10623154,695.10407566,0.00074109,0.12370845,717.42142341,-0.06778444,-0.05592402,0.00000000,0.00000000,0.00000000,0.00000000
170.15000000,3.43539700,9.57500000,0.11348822,625.57167124,0.10749763,696.56668808,0.00083938,0.12492014,718.59236628,-0.06840044,-0.05651969,0.00000000,0.00000000,0.00000000,0.00000000
171.65000000,3.47767200,9.58300000,0.11481967,626.09434209,0.10869266,697.98228575,0.00077875,0.12619107,719.88252833,-0.06914864,-0.05704243,0.00000000,0.00000000,0.00000000,0.00000000
173.15000000,3.51915400,9.59100000,0.11624700,626.61701294,0.10997217,699.45936084,0.00083073,0.12748656,721.11786665,-0.06985071,-0.05763585,0.00000000,0.00000000,0.00000000,0.00000000
174.65000000,3.56116400,9.59700000,0.11763744,627.00901607,0.11121703,700.76875437,0.00084939,0.12871649,722.23286267,-0.07053880,-0.05817770,0.00000000,0.00000000,0.00000000,0.00000000
176.15000000,3.60300900,9.60500000,0.11899111,627.53168692,0.11242749,702.20237960,0.00083525,0.12999250,723.45788732,-0.07124593,-0.05874657,0.00000000,0.00000000,0.00000000,0.00000000
177.65000000,3.64627800,9.61100000,0.12036300,627.92369006,0.11365274,703.50246916,0.00074216,0.13126423,724.60673991,-0.07193135,-0.05933288,0.00000000,0.00000000,0.00000000,0.00000000
179.15000000,3.68855300,9.61800000,0.12184544,628.38102705,0.11497505,704.94639257,0.00088544,0.13253032,725.90347354,-0.07262304,-0.05990727,0.00000000,0.00000000,0.00000000,0.00000000
180.65000000,3.73106100,9.62300000,0.12321756,628.70769633,0.11619738,706.17552183,0.00089109,0.13380834,727.06063306,-0.07333453,-0.06047381,0.00000000,0.00000000,0.00000000,0.00000000
182.15000000,3.77343600,9.62900000,0.12460422,629.09969946,0.11743117,707.48817822,0.00078502,0.13508462,728.21829894,-0.07405612,-0.06102849,0.00000000,0.00000000,0.00000000,0.00000000
183.65000000,3.81617600,9.63600000,0.12603522,629.55703646,0.11870281,708.90339745,0.00091492,0.13635915,729.37647112,-0.07474929,-0.06160986,0.00000000,0.00000000,0.00000000,0.00000000
185.15000000,3.85937900,9.64100000,0.12745511,629.88370574,0.11996298,710.16560344,0.00086802,0.13763224,730.53536101,-0.07544292,-0.06218932,0.00000000,0.00000000,0.00000000,0.00000000
186.65000000,3.90264900,9.64700000,0.12884189,630.27570887,0.12119223,711.48162172,0.00089315,0.13890360,731.69475719,-0.07614230,-0.06276130,0.00000000,0.00000000,0.00000000,0.00000000
188.15000000,3.94578500,9.65100000,0.13028378,630.53704430,0.12246873,712.68579246,0.00087234,0.14020579,732.72721604,-0.07686086,-0.06334493,0.00000000,0.00000000,0.00000000,0.00000000
189.65000000,3.98905400,9.65800000,0.13171467,630.99438129,0.12373389,714.10559589,0.00087772,0.14150556,733.91092905,-0.07760520,-0.06390035,0.00000000,0.00000000,0.00000000,0.00000000
191.15000000,4.03272200,9.66200000,0.13310889,631.25571671,0.12496508,715.28146377,0.00083779,0.14277205,735.07194826,-0.07827240,-0.06449966,0.00000000,0.00000000,0.00000000,0.00000000
192.65000000,4.07602400,9.66700000,0.13454344,631.58238599,0.12623032,716.55765565,0.00075894,0.14403719,736.15775288,-0.07896186,-0.06507533,0.00000000,0.00000000,0.00000000,0.00000000
194.15000000,4.11985600,9.67100000,0.13601122,631.84372142,0.12752320,717.78155822,0.00079690,0.14536388,737.29067233,-0.07968803,-0.06567585,0.00000000,0.00000000,0.00000000,0.00000000
195.65000000,4.16365500,9.67600000,0.13743100,632.17039070,0.12877221,719.05019966,0.00086041,0.14665735,738.40069615,-0.08041623,-0.06624112,0.00000000,0.00000000,0.00000000,0.00000000
197.15000000,4.20814900,9.68100000,0.13883622,632.49705998,0.13000688,720.31056235,0.00077560,0.14794940,739.43502470,-0.08112808,-0.06682132,0.00000000,0.00000000,0.00000000,0.00000000
198.65000000,4.25155200,9.68400000,0.14032589,632.69306154,0.13131409,721.47627780,0.00078726,0.14923950,740.54573827,-0.08184120,-0.06739831,0.00000000,0.00000000,0.00000000,0.00000000
200.15000000,4.29611100,9.68800000,0.14180467,632.95439697,0.13261005,722.71028425,0.00090871,0.15059066,741.70353932,-0.08260951,-0.06798115,0.00000000,0.00000000,0.00000000,0.00000000
201.65000000,4.34020800,9.69200000,0.14321711,633.21573239,0.13384632,723.90306030,0.00081755,0.15184623,742.71527654,-0.08333254,-0.06851369,0.00000000,0.00000000,0.00000000,0.00000000
203.15000000,4.38493400,9.69500000,0.14468856,633.41173396,0.13513260,725.05916282,0.00083572,0.15319420,743.79736636,-0.08406485,-0.06912936,0.00000000,0.00000000,0.00000000,0.00000000
204.65000000,4.42916400,9.69900000,0.14614522,633.67306938,0.13640433,726.28136093,0.00083466,0.15450879,744.93286543,-0.08480938,-0.06969942,0.00000000,0.00000000,0.00000000,0.00000000
206.15000000,4.47346000,9.70200000,0.14765333,633.86907095,0.13771928,727.46195218,0.00089749,0.15585316,746.01546955,-0.08554509,-0.07030806,0.00000000,0.00000000,0.00000000,0.00000000
207.65000000,4.51871400,9.70500000,0.14912467,634.06507252,0.13900049,728.61981511,0.00089634,0.15716486,746.99815857,-0.08624274,-0.07092212,0.00000000,0.00000000,0.00000000,0.00000000
209.15000000,4.56347300,9.70800000,0.15059600,634.26107409,0.14028007,729.77825480,0.00089539,0.15850573,748.08114098,-0.08693586,-0.07156987,0.00000000,0.00000000,0.00000000,0.00000000
210.65000000,4.60899300,9.71100000,0.15206744,634.45707566,0.14155811,730.93734176,0.00089424,0.15981356,749.14086058,-0.08765766,-0.07215590,0.00000000,0.00000000,0.00000000,0.00000000
212.15000000,4.65375200,9.71300000,0.15353867,634.58774337,0.14283432,732.02149937,0.00089291,0.16115122,750.14722096,-0.08842334,-0.07272789,0.00000000,0.00000000,0.00000000,0.00000000
213.65000000,4.69874400,9.71500000,0.15497333,634.71841108,0.14407726,733.08283897,0.00076457,0.16248672,751.23071767,-0.08916999,-0.07331672,0.00000000,0.00000000,0.00000000,0.00000000
215.15000000,4.74442800,9.71800000,0.15648144,634.91441265,0.14538216,734.26673704,0.00076357,0.16378969,752.21370950,-0.08992064,-0.07386905,0.00000000,0.00000000,0.00000000,0.00000000
216.65000000,4.79008100,9.72000000,0.15795289,635.04508036,0.14665370,735.35228538,0.00076260,0.00000000,0.00000000,0.00000000,0.00000000,0.00000000,0.00000000,0.00000000,0.00000000
218.15000000,4.83636300,9.72300000,0.15949778,635.24108193,0.14798696,736.56062285,0.00088851,0.00000000,0.00000000,0.00000000,0.00000000,0.00000000,0.00000000,0.00000000,0.00000000
219.65000000,4.88198200,9.72500000,0.16100589,635.37174964,0.14928677,737.67034297,0.00082398,0.00000000,0.00000000,0.00000000,0.00000000,0.00000000,0.00000000,0.00000000,0.00000000
221.15000000,4.92826500,9.72600000,0.16251411,635.43708350,0.15058500,738.70457629,0.00082291,0.00000000,0.00000000,0.00000000,0.00000000,0.00000000,0.00000000,0.00000000,0.00000000
222.65000000,4.97504300,9.72900000,0.16405900,635.63308506,0.15191304,739.91441337,0.00088503,0.00000000,0.00000000,0.00000000,0.00000000,0.00000000,0.00000000,0.00000000,0.00000000
224.15000000,5.02155600,9.73000000,0.16560389,635.69841892,0.15323931,740.97254925,0.00094680,0.00000000,0.00000000,0.00000000,0.00000000,0.00000000,0.00000000,0.00000000,0.00000000
225.65000000,5.06783800,9.73000000,0.16711200,635.69841892,0.15453232,741.93125310,0.00081947,0.00000000,0.00000000,0.00000000,0.00000000,0.00000000,0.00000000,0.00000000,0.00000000
227.15000000,5.11455000,9.73300000,0.16865700,635.89442049,0.15585523,743.14246577,0.00094452,0.00000000,0.00000000,0.00000000,0.00000000,0.00000000,0.00000000,0.00000000,0.00000000
228.65000000,5.16179200,9.73400000,0.17016511,635.95975434,0.15714486,744.17791660,0.00081753,0.00000000,0.00000000,0.00000000,0.00000000,0.00000000,0.00000000,0.00000000,0.00000000
230.15000000,5.20920000,9.73500000,0.17174689,636.02508820,0.15849570,745.26041835,0.00087922,0.00000000,0.00000000,0.00000000,0.00000000,0.00000000,0.00000000,0.00000000,0.00000000
231.65000000,5.25644200,9.73600000,0.17332856,636.09042206,0.15984463,746.34305611,0.00087804,0.00000000,0.00000000,0.00000000,0.00000000,0.00000000,0.00000000,0.00000000,0.00000000
233.15000000,5.30378200,9.73700000,0.17487344,636.15575591,0.16116043,747.40250415,0.00087688,0.00000000,0.00000000,0.00000000,0.00000000,0.00000000,0.00000000,0.00000000,0.00000000
234.65000000,5.35099000,9.73700000,0.17641844,636.15575591,0.16247461,748.38536480,0.00081318,0.00000000,0.00000000,0.00000000,0.00000000,0.00000000,0.00000000,0.00000000,0.00000000
236.15000000,5.39945800,9.73800000,0.17800011,636.22108977,0.16381818,749.46851444,0.00087455,0.00000000,0.00000000,0.00000000,0.00000000,0.00000000,0.00000000,0.00000000,0.00000000
237.65000000,5.44769300,9.73800000,0.17958178,636.22108977,0.16515995,750.47480413,0.00087319,0.00000000,0.00000000,0.00000000,0.00000000,0.00000000,0.00000000,0.00000000,0.00000000
239.15000000,5.49556400,9.73800000,0.18120033,636.22108977,0.16653115,751.50456331,0.00093430,0.00000000,0.00000000,0.00000000,0.00000000,0.00000000,0.00000000,0.00000000,0.00000000
240.65000000,5.54422900,9.73900000,0.18278200,636.28642362,0.16786929,752.58812871,0.00099527,0.00000000,0.00000000,0.00000000,0.00000000,0.00000000,0.00000000,0.00000000,0.00000000
242.15000000,5.59259600,9.74000000,0.18436367,636.35175748,0.00000000,0.00000000,0.00000000,0.00000000,0.00000000,0.00000000,0.00000000,0.00000000,0.00000000,0.00000000,0.00000000
243.65000000,5.64169200,9.73900000,0.18598222,636.28642362,0.00000000,0.00000000,0.00000000,0.00000000,0.00000000,0.00000000,0.00000000,0.00000000,0.00000000,0.00000000,0.00000000
245.15000000,5.69065700,9.73800000,0.18752722,636.22108977,0.00000000,0.00000000,0.00000000,0.00000000,0.00000000,0.00000000,0.00000000,0.00000000,0.00000000,0.00000000,0.00000000
246.65000000,5.73988500,9.73900000,0.18918244,636.28642362,0.00000000,0.00000000,0.00000000,0.00000000,0.00000000,0.00000000,0.00000000,0.00000000,0.00000000,0.00000000,0.00000000
248.15000000,5.78891500,9.73900000,0.19083778,636.28642362,0.00000000,0.00000000,0.00000000,0.00000000,0.00000000,0.00000000,0.00000000,0.00000000,0.00000000,0.00000000,0.00000000
249.65000000,5.83834200,9.73900000,0.19245622,636.28642362,0.00000000,0.00000000,0.00000000,0.00000000,0.00000000,0.00000000,0.00000000,0.00000000,0.00000000,0.00000000,0.00000000
251.15000000,5.88813300,9.73800000,0.19411156,636.22108977,0.00000000,0.00000000,0.00000000,0.00000000,0.00000000,0.00000000,0.00000000,0.00000000,0.00000000,0.00000000,0.00000000
252.65000000,5.93775800,9.73800000,0.19569333,636.22108977,0.00000000,0.00000000,0.00000000,0.00000000,0.00000000,0.00000000,0.00000000,0.00000000,0.00000000,0.00000000,0.00000000
254.15000000,5.98851000,9.73700000,0.19738533,636.15575591,0.00000000,0.00000000,0.00000000,0.00000000,0.00000000,0.00000000,0.00000000,0.00000000,0.00000000,0.00000000,0.00000000
255.65000000,6.03896200,9.73600000,0.19911422,636.09042206,0.00000000,0.00000000,0.00000000,0.00000000,0.00000000,0.00000000,0.00000000,0.00000000,0.00000000,0.00000000,0.00000000
257.15000000,6.08908500,9.73500000,0.20073267,636.02508820,0.00000000,0.00000000,0.00000000,0.00000000,0.00000000,0.00000000,0.00000000,0.00000000,0.00000000,0.00000000,0.00000000
258.65000000,6.14006900,9.73400000,0.20246156,635.95975434,0.00000000,0.00000000,0.00000000,0.00000000,0.00000000,0.00000000,0.00000000,0.00000000,0.00000000,0.00000000,0.00000000
260.15000000,6.19078800,9.73300000,0.20411678,635.89442049,0.00000000,0.00000000,0.00000000,0.00000000,0.00000000,0.00000000,0.00000000,0.00000000,0.00000000,0.00000000,0.00000000
261.65000000,6.24236600,9.73200000,0.20584556,635.82908663,0.00000000,0.00000000,0.00000000,0.00000000,0.00000000,0.00000000,0.00000000,0.00000000,0.00000000,0.00000000,0.00000000
263.15000000,6.29391300,9.73100000,0.20757444,635.76375278,0.00000000,0.00000000,0.00000000,0.00000000,0.00000000,0.00000000,0.00000000,0.00000000,0.00000000,0.00000000,0.00000000
264.65000000,6.34595500,9.72900000,0.20922967,635.63308506,0.00000000,0.00000000,0.00000000,0.00000000,0.00000000,0.00000000,0.00000000,0.00000000,0.00000000,0.00000000,0.00000000
266.15000000,6.39786500,9.72800000,0.21095856,635.56775121,0.00000000,0.00000000,0.00000000,0.00000000,0.00000000,0.00000000,0.00000000,0.00000000,0.00000000,0.00000000,0.00000000
267.65000000,6.45037100,9.72700000,0.21272422,635.50241735,0.00000000,0.00000000,0.00000000,0.00000000,0.00000000,0.00000000,0.00000000,0.00000000,0.00000000,0.00000000,0.00000000
269.15000000,6.50300800,9.72500000,0.21445311,635.37174964,0.00000000,0.00000000,0.00000000,0.00000000,0.00000000,0.00000000,0.00000000,0.00000000,0.00000000,0.00000000,0.00000000
270.65000000,6.55538100,9.72300000,0.21629233,635.24108193,0.00000000,0.00000000,0.00000000,0.00000000,0.00000000,0.00000000,0.00000000,0.00000000,0.00000000,0.00000000,0.00000000
272.15000000,6.60848200,9.72100000,0.21794756,635.11041422,0.00000000,0.00000000,0.00000000,0.00000000,0.00000000,0.00000000,0.00000000,0.00000000,0.00000000,0.00000000,0.00000000
273.65000000,6.66234600,9.71900000,0.21982356,634.97974650,0.00000000,0.00000000,0.00000000,0.00000000,0.00000000,0.00000000,0.00000000,0.00000000,0.00000000,0.00000000,0.00000000
275.15000000,6.71591000,9.71700000,0.22155244,634.84907879,0.00000000,0.00000000,0.00000000,0.00000000,0.00000000,0.00000000,0.00000000,0.00000000,0.00000000,0.00000000,0.00000000
276.65000000,6.76960700,9.71400000,0.22342833,634.65307722,0.00000000,0.00000000,0.00000000,0.00000000,0.00000000,0.00000000,0.00000000,0.00000000,0.00000000,0.00000000,0.00000000
278.15000000,6.82304000,9.71100000,0.22523089,634.45707566,0.00000000,0.00000000,0.00000000,0.00000000,0.00000000,0.00000000,0.00000000,0.00000000,0.00000000,0.00000000,0.00000000
279.65000000,6.87753200,9.71000000,0.22703322,634.39174180,0.00000000,0.00000000,0.00000000,0.00000000,0.00000000,0.00000000,0.00000000,0.00000000,0.00000000,0.00000000,0.00000000
281.15000000,6.93215700,9.70700000,0.22883567,634.19574023,0.00000000,0.00000000,0.00000000,0.00000000,0.00000000,0.00000000,0.00000000,0.00000000,0.00000000,0.00000000,0.00000000
282.65000000,6.98655000,9.70400000,0.23067467,633.99973866,0.00000000,0.00000000,0.00000000,0.00000000,0.00000000,0.00000000,0.00000000,0.00000000,0.00000000,0.00000000,0.00000000
284.15000000,7.04163700,9.70100000,0.23251400,633.80373710,0.00000000,0.00000000,0.00000000,0.00000000,0.00000000,0.00000000,0.00000000,0.00000000,0.00000000,0.00000000,0.00000000
285.65000000,7.09708900,9.69800000,0.23438989,633.60773553,0.00000000,0.00000000,0.00000000,0.00000000,0.00000000,0.00000000,0.00000000,0.00000000,0.00000000,0.00000000,0.00000000
287.15000000,7.15290400,9.69400000,0.23622900,633.34640010,0.00000000,0.00000000,0.00000000,0.00000000,0.00000000,0.00000000,0.00000000,0.00000000,0.00000000,0.00000000,0.00000000
288.65000000,7.20862100,9.69100000,0.23810489,633.15039854,0.00000000,0.00000000,0.00000000,0.00000000,0.00000000,0.00000000,0.00000000,0.00000000,0.00000000,0.00000000,0.00000000
290.15000000,7.26404000,9.68700000,0.23990733,632.88906311,0.00000000,0.00000000,0.00000000,0.00000000,0.00000000,0.00000000,0.00000000,0.00000000,0.00000000,0.00000000,0.00000000
291.65000000,7.32035200,9.68400000,0.24182011,632.69306154,0.00000000,0.00000000,0.00000000,0.00000000,0.00000000,0.00000000,0.00000000,0.00000000,0.00000000,0.00000000,0.00000000
293.15000000,7.37725900,9.67900000,0.24358556,632.36639226,0.00000000,0.00000000,0.00000000,0.00000000,0.00000000,0.00000000,0.00000000,0.00000000,0.00000000,0.00000000,0.00000000
294.65000000,7.43423400,9.67500000,0.24546156,632.10505684,0.00000000,0.00000000,0.00000000,0.00000000,0.00000000,0.00000000,0.00000000,0.00000000,0.00000000,0.00000000,0.00000000
296.15000000,7.49130800,9.66900000,0.24733756,631.71305370,0.00000000,0.00000000,0.00000000,0.00000000,0.00000000,0.00000000,0.00000000,0.00000000,0.00000000,0.00000000,0.00000000
297.65000000,7.54825000,9.66400000,0.24910311,631.38638442,0.00000000,0.00000000,0.00000000,0.00000000,0.00000000,0.00000000,0.00000000,0.00000000,0.00000000,0.00000000,0.00000000
299.15000000,7.60621700,9.65800000,0.25086867,630.99438129,0.00000000,0.00000000,0.00000000,0.00000000,0.00000000,0.00000000,0.00000000,0.00000000,0.00000000,0.00000000,0.00000000
300.65000000,7.66451400,9.65100000,0.25259744,630.53704430,0.00000000,0.00000000,0.00000000,0.00000000,0.00000000,0.00000000,0.00000000,0.00000000,0.00000000,0.00000000,0.00000000
302.15000000,7.72224900,9.64500000,0.25432611,630.14504116,0.00000000,0.00000000,0.00000000,0.00000000,0.00000000,0.00000000,0.00000000,0.00000000,0.00000000,0.00000000,0.00000000
303.65000000,7.78081200,9.63800000,0.25594456,629.68770417,0.00000000,0.00000000,0.00000000,0.00000000,0.00000000,0.00000000,0.00000000,0.00000000,0.00000000,0.00000000,0.00000000
305.15000000,7.83990500,9.63000000,0.25748933,629.16503332,0.00000000,0.00000000,0.00000000,0.00000000,0.00000000,0.00000000,0.00000000,0.00000000,0.00000000,0.00000000,0.00000000
306.65000000,7.89989000,9.62100000,0.25903411,628.57702862,0.00000000,0.00000000,0.00000000,0.00000000,0.00000000,0.00000000,0.00000000,0.00000000,0.00000000,0.00000000,0.00000000
308.15000000,7.95898300,9.61000000,0.26054211,627.85835620,0.00000000,0.00000000,0.00000000,0.00000000,0.00000000,0.00000000,0.00000000,0.00000000,0.00000000,0.00000000,0.00000000
309.65000000,8.01903500,9.59700000,0.26186622,627.00901607,0.00000000,0.00000000,0.00000000,0.00000000,0.00000000,0.00000000,0.00000000,0.00000000,0.00000000,0.00000000,0.00000000
311.15000000,8.07888900,9.58600000,0.26308000,626.29034366,0.00000000,0.00000000,0.00000000,0.00000000,0.00000000,0.00000000,0.00000000,0.00000000,0.00000000,0.00000000,0.00000000
312.65000000,8.13877600,9.57100000,0.26407300,625.31033582,0.00000000,0.00000000,0.00000000,0.00000000,0.00000000,0.00000000,0.00000000,0.00000000,0.00000000,0.00000000,0.00000000
314.15000000,8.19972300,9.55600000,0.26502922,624.33032798,0.00000000,0.00000000,0.00000000,0.00000000,0.00000000,0.00000000,0.00000000,0.00000000,0.00000000,0.00000000,0.00000000
315.65000000,8.26030400,9.53800000,0.26587511,623.15431857,0.00000000,0.00000000,0.00000000,0.00000000,0.00000000,0.00000000,0.00000000,0.00000000,0.00000000,0.00000000,0.00000000
317.15000000,8.32158000,9.52000000,0.26657389,621.97830916,0.00000000,0.00000000,0.00000000,0.00000000,0.00000000,0.00000000,0.00000000,0.00000000,0.00000000,0.00000000,0.00000000
318.65000000,8.38255900,9.49700000,0.26716222,620.47563047,0.00000000,0.00000000,0.00000000,0.00000000,0.00000000,0.00000000,0.00000000,0.00000000,0.00000000,0.00000000,0.00000000
320.15000000,8.44410200,9.47600000,0.26764044,619.10361950,0.00000000,0.00000000,0.00000000,0.00000000,0.00000000,0.00000000,0.00000000,0.00000000,0.00000000,0.00000000,0.00000000
321.65000000,8.50557700,9.44900000,0.26804489,617.33960538,0.00000000,0.00000000,0.00000000,0.00000000,0.00000000,0.00000000,0.00000000,0.00000000,0.00000000,0.00000000,0.00000000
323.15000000,8.56718400,9.42500000,0.26833900,615.77159284,0.00000000,0.00000000,0.00000000,0.00000000,0.00000000,0.00000000,0.00000000,0.00000000,0.00000000,0.00000000,0.00000000
324.65000000,8.62942100,9.39100000,0.26855967,613.55024174,0.00000000,0.00000000,0.00000000,0.00000000,0.00000000,0.00000000,0.00000000,0.00000000,0.00000000,0.00000000,0.00000000
326.15000000,8.69135800,9.36100000,0.26874344,611.59022606,0.00000000,0.00000000,0.00000000,0.00000000,0.00000000,0.00000000,0.00000000,0.00000000,0.00000000,0.00000000,0.00000000
327.65000000,8.75359400,9.32100000,0.26885389,608.97687181,0.00000000,0.00000000,0.00000000,0.00000000,0.00000000,0.00000000,0.00000000,0.00000000,0.00000000,0.00000000,0.00000000
329.15000000,8.81586200,9.28600000,0.26885378,606.69018685,0.00000000,0.00000000,0.00000000,0.00000000,0.00000000,0.00000000,0.00000000,0.00000000,0.00000000,0.00000000,0.00000000
330.65000000,8.87869200,9.24200000,0.26892733,603.81549719,0.00000000,0.00000000,0.00000000,0.00000000,0.00000000,0.00000000,0.00000000,0.00000000,0.00000000,0.00000000,0.00000000
332.15000000,8.94165300,9.20000000,0.26892733,601.07147524,0.00000000,0.00000000,0.00000000,0.00000000,0.00000000,0.00000000,0.00000000,0.00000000,0.00000000,0.00000000,0.00000000
333.65000000,9.00434700,9.14100000,0.26889067,597.21677773,0.00000000,0.00000000,0.00000000,0.00000000,0.00000000,0.00000000,0.00000000,0.00000000,0.00000000,0.00000000,0.00000000
335.15000000,9.06786800,9.09000000,0.26885400,593.88475108,0.00000000,0.00000000,0.00000000,0.00000000,0.00000000,0.00000000,0.00000000,0.00000000,0.00000000,0.00000000,0.00000000
336.65000000,9.13234700,9.01900000,0.26885422,589.24604730,0.00000000,0.00000000,0.00000000,0.00000000,0.00000000,0.00000000,0.00000000,0.00000000,0.00000000,0.00000000,0.00000000
338.15000000,9.19745100,8.95400000,0.26881767,584.99934666,0.00000000,0.00000000,0.00000000,0.00000000,0.00000000,0.00000000,0.00000000,0.00000000,0.00000000,0.00000000,0.00000000
339.65000000,9.26258500,8.86800000,0.26874467,579.38063505,0.00000000,0.00000000,0.00000000,0.00000000,0.00000000,0.00000000,0.00000000,0.00000000,0.00000000,0.00000000,0.00000000
341.15000000,9.32844500,8.78400000,0.26874533,573.89259114,0.00000000,0.00000000,0.00000000,0.00000000,0.00000000,0.00000000,0.00000000,0.00000000,0.00000000,0.00000000,0.00000000
342.65000000,9.39552700,8.66300000,0.26870944,565.98719456,0.00000000,0.00000000,0.00000000,0.00000000,0.00000000,0.00000000,0.00000000,0.00000000,0.00000000,0.00000000,0.00000000
344.15000000,9.46432800,8.54700000,0.26863733,558.40846727,0.00000000,0.00000000,0.00000000,0.00000000,0.00000000,0.00000000,0.00000000,0.00000000,0.00000000,0.00000000,0.00000000
345.65000000,9.53590900,8.37000000,0.26852878,546.84437475,0.00000000,0.00000000,0.00000000,0.00000000,0.00000000,0.00000000,0.00000000,0.00000000,0.00000000,0.00000000,0.00000000
347.15000000,9.61053700,8.19200000,0.26838489,535.21494839,0.00000000,0.00000000,0.00000000,0.00000000,0.00000000,0.00000000,0.00000000,0.00000000,0.00000000,0.00000000,0.00000000