File: polyN_optimization/DP600_results/DATA/UT_45_2.csv
Time[s],Displacement[mm],Force[kN],EngStrain_longi,EngStress[MPa],TrueStrain,TrueStress[MPa],TrueStrainRate[1/s],PlasticStrain_longi,PlasticStress[MPa],PlasticStrain_thick,PlasticStrain_width,R-Value,Thickness[mm],Width[mm], Young's Modulus [MPa]
0.58000000,0.00000000,-0.01300000,0.00000000,-0.85234723,0.00000000,-0.85234723,0.00000000,0.00066132,357.25530763,0.00014740,-0.00080873,0.81500747,1.52520000,10.00000000,245987.64074562
2.08000000,0.00114000,0.06000000,0.00003122,3.93391031,0.00003122,3.93403313,0.00002400,0.00113485,370.33485398,0.00008630,-0.00122115,0.00000000,0.00000000,0.00000000,0.00000000
3.58000000,0.00247600,0.43900000,0.00009044,28.78311041,0.00009044,28.78571368,0.00004400,0.00177060,383.88619317,-0.00031712,-0.00145348,0.00000000,0.00000000,0.00000000,0.00000000
5.08000000,0.00465500,0.77600000,0.00011656,50.87857330,0.00011655,50.88450348,0.00003289,0.00247633,394.18543489,-0.00084593,-0.00163039,0.00000000,0.00000000,0.00000000,0.00000000
6.58000000,0.00666700,1.10300000,0.00016256,72.31838447,0.00016254,72.33014023,0.00003377,0.00316911,405.55123612,-0.00128365,-0.00188545,0.00000000,0.00000000,0.00000000,0.00000000
8.08000000,0.00875600,1.43500000,0.00024978,94.08602151,0.00024975,94.10952210,0.00004777,0.00392342,413.85359370,-0.00162380,-0.00229962,0.00000000,0.00000000,0.00000000,0.00000000
9.58000000,0.01049100,1.76900000,0.00030822,115.98478888,0.00030817,116.02053797,-0.00002133,0.00481057,423.28346120,-0.00205986,-0.00275071,0.00000000,0.00000000,0.00000000,0.00000000
11.08000000,0.01268900,2.12500000,0.00037967,139.32599003,0.00037959,139.37888747,-0.00012573,0.00573373,430.36250745,-0.00258078,-0.00315295,0.00000000,0.00000000,0.00000000,0.00000000
12.58000000,0.01551300,2.45500000,0.00048778,160.96249672,0.00048766,161.04101065,-0.00005220,0.00660508,438.16106540,-0.00306670,-0.00353838,0.00000000,0.00000000,0.00000000,0.00000000
14.08000000,0.01956900,2.80900000,0.00065000,184.17256753,0.00064979,184.29227970,0.00013170,0.00745668,444.57157627,-0.00355830,-0.00389838,0.00000000,0.00000000,0.00000000,0.00000000
15.58000000,0.02216100,3.13700000,0.00075744,205.67794388,0.00075716,205.83373349,0.00030513,0.00835982,452.21158864,-0.00409357,-0.00426625,0.00000000,0.00000000,0.00000000,0.00000000
17.08000000,0.02526000,3.46000000,0.00081222,226.85549436,0.00081189,227.03975144,0.00029045,0.00936427,458.25049305,-0.00462082,-0.00474346,0.00000000,0.00000000,0.00000000,0.00000000
18.58000000,0.02824000,3.77700000,0.00089089,247.63965382,0.00089049,247.86027323,0.00022714,0.01028964,465.39576296,-0.00508183,-0.00520780,0.00000000,0.00000000,0.00000000,0.00000000
20.08000000,0.03174900,4.11100000,0.00093433,269.53842119,0.00093390,269.79025992,0.00000733,0.01120326,471.01693260,-0.00549683,-0.00570642,0.00000000,0.00000000,0.00000000,0.00000000
21.58000000,0.03744300,4.41800000,0.00108144,289.66692893,0.00108086,289.98018762,-0.00015449,0.01212041,477.24998507,-0.00598927,-0.00613115,0.00000000,0.00000000,0.00000000,0.00000000
23.08000000,0.04423100,4.73400000,0.00132800,310.38552321,0.00132712,310.79771518,-0.00024233,0.01312477,482.46890387,-0.00662691,-0.00649786,0.00000000,0.00000000,0.00000000,0.00000000
24.58000000,0.05260800,5.00700000,0.00173633,328.28481511,0.00173483,328.85482697,0.00002950,0.01410495,488.75517695,-0.00720807,-0.00689688,0.00000000,0.00000000,0.00000000,0.00000000
26.08000000,0.06422800,5.25900000,0.00217033,344.80723839,0.00216798,345.55558504,0.00035970,0.01506154,493.70449777,-0.00769132,-0.00737023,0.00000000,0.00000000,0.00000000,0.00000000
27.58000000,0.08025300,5.48600000,0.00268178,359.69053239,0.00267819,360.65514247,0.00063130,0.01601987,499.60112454,-0.00813169,-0.00788817,0.00000000,0.00000000,0.00000000,0.00000000
29.08000000,0.09677500,5.70800000,0.00320422,374.24600052,0.00319910,375.44516788,0.00060150,0.01700126,504.24741791,-0.00859464,-0.00840662,0.00000000,0.00000000,0.00000000,0.00000000
30.58000000,0.11644200,5.88700000,0.00384422,385.98216627,0.00383685,387.46596749,0.00047645,0.01800805,509.38508276,-0.00915948,-0.00884857,0.00000000,0.00000000,0.00000000,0.00000000
32.08000000,0.13928600,6.05600000,0.00464244,397.06268030,0.00463170,398.90602174,0.00055660,0.01903525,513.80467720,-0.00978177,-0.00925348,0.00000000,0.00000000,0.00000000,0.00000000
33.58000000,0.16415000,6.19500000,0.00552533,406.17623918,0.00551012,408.42049830,0.00081964,0.01998920,519.00159848,-0.01027348,-0.00971572,0.00000000,0.00000000,0.00000000,0.00000000
35.08000000,0.19066900,6.32200000,0.00636400,414.50301600,0.00634384,417.14091319,0.00089937,0.02102619,523.17517414,-0.01090035,-0.01012584,0.00000000,0.00000000,0.00000000,0.00000000
36.58000000,0.21626100,6.43800000,0.00718433,422.10857592,0.00715865,425.14114464,0.00066489,0.02207636,528.10501338,-0.01152692,-0.01054944,0.00000000,0.00000000,0.00000000,0.00000000
38.08000000,0.24420300,6.55400000,0.00809667,429.71413585,0.00806406,433.19338797,0.00056197,0.02311199,532.09294424,-0.01209347,-0.01101852,0.00000000,0.00000000,0.00000000,0.00000000
39.58000000,0.27204600,6.65500000,0.00911200,436.33621820,0.00907074,440.31211382,0.00075835,0.02415879,536.49980443,-0.01266706,-0.01149173,0.00000000,0.00000000,0.00000000,0.00000000
41.08000000,0.29992200,6.76000000,0.01003167,443.22056124,0.00998168,447.66680217,0.00081598,0.02518941,540.29845569,-0.01317757,-0.01201184,0.00000000,0.00000000,0.00000000,0.00000000
42.58000000,0.32855900,6.85300000,0.01093656,449.31812221,0.01087718,454.23211482,0.00072795,0.02625886,544.73462843,-0.01371774,-0.01254112,0.00000000,0.00000000,0.00000000,0.00000000
44.08000000,0.35842100,6.94400000,0.01184500,455.28455285,0.01177540,460.67739837,0.00045796,0.02733525,548.23538432,-0.01430807,-0.01302718,0.00000000,0.00000000,0.00000000,0.00000000
45.58000000,0.38715700,7.03000000,0.01287489,460.92315762,0.01279271,466.85749206,0.00057381,0.02837796,552.53824038,-0.01488468,-0.01349328,0.00000000,0.00000000,0.00000000,0.00000000
47.08000000,0.41672200,7.11900000,0.01389378,466.75845791,0.01379814,473.24349620,0.00070390,0.02944860,555.98275499,-0.01549306,-0.01395554,0.00000000,0.00000000,0.00000000,0.00000000
48.58000000,0.44714700,7.19900000,0.01482444,472.00367165,0.01471564,479.00086386,0.00064521,0.03051064,559.49725653,-0.01611461,-0.01439603,0.00000000,0.00000000,0.00000000,0.00000000
50.08000000,0.47594900,7.28200000,0.01578456,477.44558091,0.01566128,484.98184720,0.00047807,0.03161399,563.04204170,-0.01678826,-0.01482573,0.00000000,0.00000000,0.00000000,0.00000000
51.58000000,0.50723400,7.35600000,0.01680344,482.29740362,0.01666383,490.40166125,0.00046294,0.03270611,566.45148848,-0.01736348,-0.01534264,0.00000000,0.00000000,0.00000000,0.00000000
53.08000000,0.53732700,7.42700000,0.01787400,486.95253082,0.01771614,495.65632035,0.00060724,0.03376097,569.98290012,-0.01795375,-0.01580722,0.00000000,0.00000000,0.00000000,0.00000000
54.58000000,0.56857800,7.49700000,0.01888933,491.54209284,0.01871315,500.82699528,0.00062845,0.03484423,573.26453798,-0.01850413,-0.01634010,0.00000000,0.00000000,0.00000000,0.00000000
56.08000000,0.59959800,7.56800000,0.01990089,496.19722004,0.01970545,506.07198578,0.00060603,0.03595407,576.63643054,-0.01911057,-0.01684350,0.00000000,0.00000000,0.00000000,0.00000000
57.58000000,0.63101500,7.63200000,0.02095289,500.39339103,0.02073640,510.87807815,0.00060541,0.03704251,579.79751354,-0.01966495,-0.01737755,0.00000000,0.00000000,0.00000000,0.00000000
59.08000000,0.66283000,7.69900000,0.02202333,504.78625754,0.02178432,515.90333355,0.00060477,0.03815471,582.91028556,-0.02027092,-0.01788378,0.00000000,0.00000000,0.00000000,0.00000000
60.58000000,0.69461100,7.75900000,0.02310467,508.72016785,0.02284180,520.47397775,0.00076231,0.03927963,586.03683816,-0.02086876,-0.01841087,0.00000000,0.00000000,0.00000000,0.00000000
62.08000000,0.72689000,7.81600000,0.02413467,512.45738264,0.02384803,524.82537075,0.00066105,0.04040323,589.16899946,-0.02146308,-0.01894015,0.00000000,0.00000000,0.00000000,0.00000000
63.58000000,0.75910200,7.87200000,0.02523078,516.12903226,0.02491774,529.15136918,0.00065318,0.04153709,592.10744852,-0.02212004,-0.01941705,0.00000000,0.00000000,0.00000000,0.00000000
65.08000000,0.79184400,7.93000000,0.02633800,519.93181222,0.02599713,533.62577629,0.00070273,0.04266568,595.11755628,-0.02276299,-0.01990269,0.00000000,0.00000000,0.00000000,0.00000000
66.58000000,0.82514800,7.98300000,0.02744867,523.40676633,0.02707871,537.77358419,0.00073031,0.04376939,597.91219605,-0.02333170,-0.02043769,0.00000000,0.00000000,0.00000000,0.00000000
68.08000000,0.85792300,8.03800000,0.02854856,527.01285077,0.02814864,542.05830642,0.00077276,0.04489676,600.65764510,-0.02397243,-0.02092433,0.00000000,0.00000000,0.00000000,0.00000000
69.58000000,0.89139400,8.08600000,0.02963356,530.15997902,0.02920297,545.87050421,0.00070026,0.04605067,603.42465268,-0.02460166,-0.02144902,0.00000000,0.00000000,0.00000000,0.00000000
71.08000000,0.92456600,8.13300000,0.03076289,533.24154209,0.03029920,549.64559240,0.00070661,0.04716071,606.30890541,-0.02518951,-0.02197120,0.00000000,0.00000000,0.00000000,0.00000000
72.58000000,0.95806900,8.18000000,0.03187744,536.32310517,0.03137990,553.41971516,0.00074161,0.04829161,608.93481097,-0.02578473,-0.02250688,0.00000000,0.00000000,0.00000000,0.00000000
74.08000000,0.99206900,8.22500000,0.03302144,539.27353790,0.03248795,557.08112907,0.00078362,0.04945262,611.58441431,-0.02641652,-0.02303610,0.00000000,0.00000000,0.00000000,0.00000000
75.58000000,1.02600100,8.27200000,0.03413956,542.35510097,0.03356973,560.87086307,0.00078965,0.05059167,614.15651276,-0.02702868,-0.02356299,0.00000000,0.00000000,0.00000000,0.00000000
77.08000000,1.05986900,8.31000000,0.03526889,544.84657750,0.03466119,564.06271090,0.00073210,0.05177157,616.62009756,-0.02769937,-0.02407220,0.00000000,0.00000000,0.00000000,0.00000000
78.58000000,1.09443100,8.35700000,0.03643500,547.92814057,0.03578694,567.89190237,0.00076688,0.05291869,619.13788421,-0.02827862,-0.02464007,0.00000000,0.00000000,0.00000000,0.00000000
80.08000000,1.12912600,8.39400000,0.03757522,550.35405193,0.03688647,571.03372773,0.00082260,0.05405767,621.58599856,-0.02891420,-0.02514347,0.00000000,0.00000000,0.00000000,0.00000000
81.58000000,1.16335700,8.43600000,0.03870822,553.10778914,0.03797785,574.51760836,0.00080758,0.05524423,623.99902867,-0.02958838,-0.02565585,0.00000000,0.00000000,0.00000000,0.00000000
83.08000000,1.19854800,8.47300000,0.03987056,555.53370050,0.03909624,577.68313777,0.00079256,0.05639747,626.53559515,-0.03024387,-0.02615360,0.00000000,0.00000000,0.00000000,0.00000000
84.58000000,1.23327500,8.51200000,0.04101822,558.09074220,0.04019929,580.98263228,0.00079169,0.05756108,628.80432166,-0.03087507,-0.02668601,0.00000000,0.00000000,0.00000000,0.00000000
86.08000000,1.26823400,8.54500000,0.04218056,560.25439287,0.04131521,583.88623441,0.00076948,0.05873041,631.01119014,-0.03148029,-0.02725012,0.00000000,0.00000000,0.00000000,0.00000000
87.58000000,1.30445200,8.58500000,0.04336878,562.87699974,0.04245469,587.28828726,0.00076881,0.05989842,633.22157848,-0.03216713,-0.02773130,0.00000000,0.00000000,0.00000000,0.00000000
89.08000000,1.33921300,8.61600000,0.04452744,564.90952006,0.04356458,590.06349733,0.00071156,0.06107123,635.57960224,-0.03281503,-0.02825620,0.00000000,0.00000000,0.00000000,0.00000000
90.58000000,1.37562900,8.65100000,0.04572656,567.20430108,0.04471191,593.14060006,0.00071053,0.06226393,637.81466629,-0.03346509,-0.02879884,0.00000000,0.00000000,0.00000000,0.00000000
92.08000000,1.41121800,8.68300000,0.04691100,569.30238657,0.04584392,596.00893083,0.00068871,0.06342087,640.03124033,-0.03413060,-0.02929027,0.00000000,0.00000000,0.00000000,0.00000000
93.58000000,1.44703800,8.71600000,0.04809178,571.46603724,0.04697116,598.94885491,0.00070914,0.06462161,642.13961448,-0.03476366,-0.02985795,0.00000000,0.00000000,0.00000000,0.00000000
95.08000000,1.48355400,8.74400000,0.04930200,573.30186205,0.04812518,601.56679045,0.00073629,0.06581438,644.17656393,-0.03543017,-0.03038422,0.00000000,0.00000000,0.00000000,0.00000000
96.58000000,1.51930800,8.77700000,0.05050844,575.46551272,0.04927428,604.53138060,0.00070031,0.06700195,646.28466788,-0.03608475,-0.03091719,0.00000000,0.00000000,0.00000000,0.00000000
98.08000000,1.55625400,8.80400000,0.05170767,577.23577236,0.05041519,607.08328726,0.00073460,0.06817435,648.38704766,-0.03671045,-0.03146390,0.00000000,0.00000000,0.00000000,0.00000000
99.58000000,1.59303400,8.83300000,0.05294000,579.13716234,0.05158625,609.79668371,0.00078990,0.06938022,650.37392102,-0.03737271,-0.03200751,0.00000000,0.00000000,0.00000000,0.00000000
101.08000000,1.62918600,8.86000000,0.05417222,580.90742198,0.05275584,612.37646793,0.00078181,0.07058076,652.43199505,-0.03804346,-0.03253730,0.00000000,0.00000000,0.00000000,0.00000000
102.58000000,1.66596600,8.88800000,0.05538600,582.74324679,0.05390658,615.01906425,0.00078070,0.07175982,654.40911979,-0.03864749,-0.03311232,0.00000000,0.00000000,0.00000000,0.00000000
104.08000000,1.70327600,8.91200000,0.05663667,584.31681091,0.05509091,617.41056736,0.00076610,0.07296149,656.33396304,-0.03934494,-0.03361656,0.00000000,0.00000000,0.00000000,0.00000000
105.58000000,1.73972500,8.94100000,0.05786522,586.21820089,0.05625294,620.13984736,0.00077193,0.07419935,658.21535184,-0.04003428,-0.03416507,0.00000000,0.00000000,0.00000000,0.00000000
107.08000000,1.77730000,8.96300000,0.05909744,587.66063467,0.05741708,622.38987638,0.00079895,0.07539813,660.14569898,-0.04071920,-0.03467893,0.00000000,0.00000000,0.00000000,0.00000000
108.58000000,1.81477600,8.98800000,0.06034444,589.29976397,0.05859380,624.86073083,0.00075629,0.07659231,662.00546875,-0.04135099,-0.03524131,0.00000000,0.00000000,0.00000000,0.00000000
110.08000000,1.85175500,9.01100000,0.06159144,590.80776292,0.05976914,627.19646642,0.00077634,0.07778142,663.93671575,-0.04199848,-0.03578293,0.00000000,0.00000000,0.00000000,0.00000000
111.58000000,1.88966100,9.03500000,0.06286044,592.38132704,0.06096381,629.61868054,0.00081683,0.07906759,665.79367430,-0.04275037,-0.03631723,0.00000000,0.00000000,0.00000000,0.00000000
113.08000000,1.92730200,9.05500000,0.06410378,593.69263047,0.06213292,631.75057093,0.00079540,0.08026470,667.52318791,-0.04337716,-0.03688754,0.00000000,0.00000000,0.00000000,0.00000000
114.58000000,1.96471200,9.07900000,0.06535800,595.26619460,0.06331089,634.17160254,0.00079426,0.08148371,669.34221217,-0.04405615,-0.03742756,0.00000000,0.00000000,0.00000000,0.00000000
116.08000000,2.00271600,9.09800000,0.06661611,596.51193286,0.06449112,636.24923806,0.00078665,0.08271151,671.09894783,-0.04470461,-0.03800690,0.00000000,0.00000000,0.00000000,0.00000000
117.58000000,2.04062300,9.12000000,0.06791456,597.95436664,0.06570773,638.56417169,0.00081317,0.08393118,672.85352440,-0.04537823,-0.03855295,0.00000000,0.00000000,0.00000000,0.00000000
119.08000000,2.07843000,9.14000000,0.06917256,599.26567008,0.06688504,640.71840793,0.00083280,0.08517264,674.62616561,-0.04607453,-0.03909812,0.00000000,0.00000000,0.00000000,0.00000000
120.58000000,2.11689800,9.16000000,0.07044522,600.57697351,0.06807466,642.88475187,0.00079048,0.08639627,676.31815191,-0.04674146,-0.03965480,0.00000000,0.00000000,0.00000000,0.00000000
122.08000000,2.15516800,9.17700000,0.07173633,601.69158143,0.06928007,644.85472928,0.00079637,0.08763805,678.09767960,-0.04744745,-0.04019061,0.00000000,0.00000000,0.00000000,0.00000000
123.58000000,2.19416700,9.19800000,0.07302744,603.06845004,0.07048404,647.10899777,0.00080909,0.08889606,679.67529772,-0.04816756,-0.04072850,0.00000000,0.00000000,0.00000000,0.00000000
125.08000000,2.23253600,9.21400000,0.07429644,604.11749279,0.07166598,649.00127453,0.00080813,0.09010830,681.36898018,-0.04881686,-0.04129143,0.00000000,0.00000000,0.00000000,0.00000000
126.58000000,2.27083900,9.23200000,0.07556556,605.29766588,0.07284662,651.03732028,0.00073877,0.09131982,682.92070161,-0.04948685,-0.04183297,0.00000000,0.00000000,0.00000000,0.00000000
128.08000000,2.30993600,9.24900000,0.07689344,606.41227380,0.07408046,653.04140229,0.00078575,0.09256902,684.64586298,-0.05015976,-0.04240925,0.00000000,0.00000000,0.00000000,0.00000000
129.58000000,2.34910000,9.26700000,0.07819922,607.59244689,0.07529226,655.10570367,0.00083243,0.09385102,686.17942086,-0.05089495,-0.04295607,0.00000000,0.00000000,0.00000000,0.00000000
131.08000000,2.38866100,9.28200000,0.07951978,608.57592447,0.07651629,656.96974674,0.00085880,0.09507085,687.81806259,-0.05155549,-0.04351536,0.00000000,0.00000000,0.00000000,0.00000000
132.58000000,2.42815600,9.29900000,0.08081833,609.69053239,0.07771847,658.96470507,0.00076952,0.09632293,689.33667683,-0.05221537,-0.04410756,0.00000000,0.00000000,0.00000000,0.00000000
134.08000000,2.46728800,9.31300000,0.08217200,610.60844479,0.07897013,660.78336192,0.00085690,0.09758319,690.93646504,-0.05290994,-0.04467325,0.00000000,0.00000000,0.00000000,0.00000000
135.58000000,2.50711300,9.32900000,0.08349611,611.65748754,0.08019295,662.72850908,0.00089648,0.09884493,692.54024491,-0.05362872,-0.04521621,0.00000000,0.00000000,0.00000000,0.00000000
137.08000000,2.54670800,9.34300000,0.08479833,612.57539995,0.08139410,664.52077290,0.00090216,0.10010915,694.00281482,-0.05433014,-0.04577901,0.00000000,0.00000000,0.00000000,0.00000000
138.58000000,2.58650000,9.35800000,0.08612978,613.55887752,0.08262072,666.40456730,0.00076535,0.10136820,695.53743626,-0.05503935,-0.04632885,0.00000000,0.00000000,0.00000000,0.00000000
140.08000000,2.62678900,9.37000000,0.08750922,614.34565959,0.08388996,668.10657043,0.00089317,0.10261603,696.99385737,-0.05571594,-0.04690009,0.00000000,0.00000000,0.00000000,0.00000000
141.58000000,2.66697900,9.38500000,0.08882978,615.32913716,0.08510352,669.98868768,0.00086493,0.10382901,698.50164549,-0.05635193,-0.04747707,0.00000000,0.00000000,0.00000000,0.00000000
143.08000000,2.70736800,9.39700000,0.09015033,616.11591922,0.08631561,671.65897471,0.00081677,0.10509712,699.90417924,-0.05709137,-0.04800576,0.00000000,0.00000000,0.00000000,0.00000000
144.58000000,2.74755900,9.41100000,0.09150022,617.03383163,0.08755310,673.49256434,0.00083572,0.10638619,701.39731527,-0.05779263,-0.04859356,0.00000000,0.00000000,0.00000000,0.00000000
146.08000000,2.78834400,9.42300000,0.09287600,617.82061369,0.08881275,675.20132101,0.00085522,0.10764775,702.80025435,-0.05851685,-0.04913090,0.00000000,0.00000000,0.00000000,0.00000000
147.58000000,2.82870000,9.43500000,0.09418178,618.60739575,0.09000685,676.86894003,0.00078003,0.10892986,704.36736129,-0.05918044,-0.04974942,0.00000000,0.00000000,0.00000000,0.00000000
149.08000000,2.86935300,9.44800000,0.09552444,619.45974298,0.09123319,678.63329079,0.00073220,0.11022777,705.72743643,-0.05992558,-0.05030219,0.00000000,0.00000000,0.00000000,0.00000000
150.58000000,2.91027200,9.45900000,0.09691856,620.18095987,0.09250494,680.28800269,0.00074465,0.11151735,707.08396798,-0.06065015,-0.05086720,0.00000000,0.00000000,0.00000000,0.00000000
152.08000000,2.95135600,9.47000000,0.09830900,620.90217676,0.09377172,681.94244886,0.00083762,0.11278248,708.42545371,-0.06135659,-0.05142589,0.00000000,0.00000000,0.00000000,0.00000000
153.58000000,2.99210900,9.48000000,0.09965900,621.55782848,0.09500013,683.50166011,0.00085661,0.11403589,709.83485368,-0.06203973,-0.05199616,0.00000000,0.00000000,0.00000000,0.00000000
155.08000000,3.03358900,9.49100000,0.10106767,622.27904537,0.09628032,685.17133650,0.00090216,0.11536903,711.30359568,-0.06279650,-0.05257253,0.00000000,0.00000000,0.00000000,0.00000000
156.58000000,3.07467400,9.50100000,0.10247289,622.93469709,0.09755574,686.76861509,0.00087439,0.11664265,712.58407789,-0.06349948,-0.05314317,0.00000000,0.00000000,0.00000000,0.00000000
158.08000000,3.11589000,9.51100000,0.10383011,623.59034881,0.09878605,688.33780401,0.00087976,0.11796939,713.97901565,-0.06425342,-0.05371597,0.00000000,0.00000000,0.00000000,0.00000000
159.58000000,3.15710600,9.52100000,0.10519111,624.24600052,0.10001827,689.91113093,0.00082557,0.11924244,715.33787398,-0.06491359,-0.05432884,0.00000000,0.00000000,0.00000000,0.00000000
161.08000000,3.19901700,9.53000000,0.10657789,624.83608707,0.10127227,691.42979813,0.00079781,0.12053699,716.64004447,-0.06559987,-0.05493712,0.00000000,0.00000000,0.00000000,0.00000000
162.58000000,3.24102800,9.53900000,0.10800878,625.42617362,0.10256451,692.97769022,0.00084353,0.12186209,717.96640529,-0.06634374,-0.05551835,0.00000000,0.00000000,0.00000000,0.00000000
164.08000000,3.28280700,9.54800000,0.10937344,626.01626016,0.10379539,694.48581481,0.00076294,0.12314060,719.18674039,-0.06703936,-0.05610124,0.00000000,0.00000000,0.00000000,0.00000000
165.58000000,3.32438800,9.55500000,0.11076022,626.47521637,0.10504467,695.86375055,0.00072876,0.12444282,720.50094428,-0.06780510,-0.05663773,0.00000000,0.00000000,0.00000000,0.00000000
167.08000000,3.36639900,9.56500000,0.11215433,627.13086808,0.10629898,697.46631251,0.00072785,0.12577243,721.83719676,-0.06855685,-0.05721557,0.00000000,0.00000000,0.00000000,0.00000000
168.58000000,3.40860900,9.57200000,0.11358522,627.58982429,0.10758474,698.87475394,0.00085907,0.12712305,723.11602542,-0.06932131,-0.05780174,0.00000000,0.00000000,0.00000000,0.00000000
170.08000000,3.45085100,9.58100000,0.11501611,628.17991083,0.10886885,700.43072125,0.00087771,0.12843981,724.37238592,-0.07004952,-0.05839028,0.00000000,0.00000000,0.00000000,0.00000000
171.58000000,3.49329100,9.58800000,0.11645800,628.63886703,0.11016117,701.84889221,0.00087000,0.12979639,725.65981205,-0.07080841,-0.05898798,0.00000000,0.00000000,0.00000000,0.00000000
173.08000000,3.53563400,9.59600000,0.11785578,629.16338841,0.11141237,703.31392890,0.00083590,0.13111269,726.92002642,-0.07153169,-0.05958100,0.00000000,0.00000000,0.00000000,0.00000000
174.58000000,3.57959700,9.60300000,0.11934544,629.62234461,0.11274409,704.76490316,0.00092019,0.13243371,728.18576584,-0.07224659,-0.06018712,0.00000000,0.00000000,0.00000000,0.00000000
176.08000000,3.62170700,9.61000000,0.12074322,630.08130081,0.11399206,706.15934734,0.00080737,0.13376289,729.38408746,-0.07299613,-0.06076676,0.00000000,0.00000000,0.00000000,0.00000000
177.58000000,3.66520800,9.61700000,0.12223300,630.54025702,0.11532045,707.61308425,0.00087206,0.13507110,730.56894734,-0.07369726,-0.06137384,0.00000000,0.00000000,0.00000000,0.00000000
179.08000000,3.70788100,9.62300000,0.12363089,630.93364805,0.11656531,708.93653578,0.00081874,0.13644096,731.87661214,-0.07446907,-0.06197189,0.00000000,0.00000000,0.00000000,0.00000000
180.58000000,3.75148200,9.62900000,0.12509122,631.32703908,0.11786412,710.30051002,0.00089613,0.13777746,733.08618122,-0.07521519,-0.06256226,0.00000000,0.00000000,0.00000000,0.00000000
182.08000000,3.79484900,9.63600000,0.12657356,631.78599528,0.11918077,711.75339505,0.00084917,0.13917617,734.26764213,-0.07604209,-0.06313408,0.00000000,0.00000000,0.00000000,0.00000000
183.58000000,3.83845000,9.64100000,0.12799711,632.11382114,0.12044359,713.02256414,0.00081538,0.14054071,735.50176126,-0.07679368,-0.06374704,0.00000000,0.00000000,0.00000000,0.00000000
185.08000000,3.88248100,9.64600000,0.12948689,632.44164700,0.12176345,714.33454827,0.00078832,0.14187179,736.71314480,-0.07751173,-0.06436006,0.00000000,0.00000000,0.00000000,0.00000000
186.58000000,3.92618000,9.65300000,0.13099133,632.90060320,0.12309453,715.80509708,0.00089145,0.14326428,737.97193697,-0.07828686,-0.06497742,0.00000000,0.00000000,0.00000000,0.00000000
188.08000000,3.97034300,9.65700000,0.13246633,633.16286389,0.12439785,717.03562687,0.00089657,0.14462357,739.13188821,-0.07904263,-0.06558094,0.00000000,0.00000000,0.00000000,0.00000000
189.58000000,4.01410800,9.66200000,0.13392667,633.49068975,0.12568654,718.33198619,0.00081111,0.14601265,740.31577057,-0.07980623,-0.06620642,0.00000000,0.00000000,0.00000000,0.00000000
191.08000000,4.05890100,9.66700000,0.13546056,633.81851560,0.12703834,719.67592385,0.00094610,0.14739969,741.50000656,-0.08059178,-0.06680791,0.00000000,0.00000000,0.00000000,0.00000000
192.58000000,4.10289800,9.67200000,0.13697244,634.14634146,0.12836898,721.00691599,0.00099040,0.14881600,742.78454830,-0.08137650,-0.06743949,0.00000000,0.00000000,0.00000000,0.00000000
194.08000000,4.14755800,9.67700000,0.13847322,634.47416732,0.12968809,722.33184969,0.00095668,0.15023091,743.91674266,-0.08217017,-0.06806074,0.00000000,0.00000000,0.00000000,0.00000000
195.58000000,4.19248300,9.68000000,0.14000711,634.67086284,0.13103450,723.52929685,0.00093608,0.15164381,745.04915406,-0.08296108,-0.06868273,0.00000000,0.00000000,0.00000000,0.00000000
197.08000000,4.23750600,9.68400000,0.14147478,634.93312352,0.13232109,724.76014608,0.00086379,0.15305452,746.25860521,-0.08374177,-0.06931275,0.00000000,0.00000000,0.00000000,0.00000000
198.58000000,4.28246400,9.68800000,0.14300489,635.19538421,0.13366066,726.03142955,0.00081751,0.15446304,747.46834869,-0.08451904,-0.06994400,0.00000000,0.00000000,0.00000000,0.00000000
200.08000000,4.32752000,9.69200000,0.14450567,635.45764490,0.13497281,727.28487551,0.00079720,0.15586965,748.67859720,-0.08526356,-0.07060609,0.00000000,0.00000000,0.00000000,0.00000000
201.58000000,4.37264300,9.69500000,0.14603222,635.65434041,0.13630574,728.48035631,0.00080894,0.15730611,749.75867273,-0.08607481,-0.07123131,0.00000000,0.00000000,0.00000000,0.00000000
203.08000000,4.41780000,9.69900000,0.14757711,635.91660110,0.13765286,729.76333600,0.00083343,0.15874022,750.91593903,-0.08685546,-0.07188477,0.00000000,0.00000000,0.00000000,0.00000000
204.58000000,4.46375000,9.70300000,0.14915889,636.17886179,0.13903027,731.07059395,0.00096055,0.16020328,752.09683792,-0.08767578,-0.07252751,0.00000000,0.00000000,0.00000000,0.00000000
206.08000000,4.50976600,9.70700000,0.15074056,636.44112248,0.14040570,732.37861086,0.00095923,0.16166428,753.27803446,-0.08851121,-0.07315306,0.00000000,0.00000000,0.00000000,0.00000000
207.58000000,4.55558400,9.70900000,0.15228544,636.57225282,0.14174731,733.51294126,0.00095794,0.16312312,754.45945770,-0.08934459,-0.07377854,0.00000000,0.00000000,0.00000000,0.00000000
209.08000000,4.60150200,9.71100000,0.15386711,636.70338316,0.14311901,734.67109336,0.00089266,0.16458020,755.56353440,-0.09015339,-0.07442680,0.00000000,0.00000000,0.00000000,0.00000000
210.58000000,4.64738600,9.71300000,0.15541211,636.83451351,0.14445709,735.80630968,0.00082797,0.16609690,756.71451307,-0.09102879,-0.07506811,0.00000000,0.00000000,0.00000000,0.00000000
212.08000000,4.69376700,9.71700000,0.15699378,637.09677419,0.14582507,737.11700358,0.00089024,0.00000000,0.00000000,0.00000000,0.00000000,0.00000000,0.00000000,0.00000000,0.00000000
213.58000000,4.74044500,9.72000000,0.15857544,637.29346971,0.14719119,738.35256491,0.00082551,0.00000000,0.00000000,0.00000000,0.00000000,0.00000000,0.00000000,0.00000000,0.00000000
215.08000000,4.78758700,9.72100000,0.16023078,637.35903488,0.14861893,739.48356876,0.00095138,0.00000000,0.00000000,0.00000000,0.00000000,0.00000000,0.00000000,0.00000000,0.00000000
216.58000000,4.83453200,9.72400000,0.16184922,637.55573040,0.15001289,740.74362948,0.00094986,0.00000000,0.00000000,0.00000000,0.00000000,0.00000000,0.00000000,0.00000000,0.00000000
218.08000000,4.88190600,9.72600000,0.16350456,637.68686074,0.15143662,741.95156749,0.00101195,0.00000000,0.00000000,0.00000000,0.00000000,0.00000000,0.00000000,0.00000000,0.00000000
219.58000000,4.92947700,9.72900000,0.16515978,637.88355625,0.15285823,743.23626265,0.00101032,0.00000000,0.00000000,0.00000000,0.00000000,0.00000000,0.00000000,0.00000000,0.00000000
221.08000000,4.97665300,9.73000000,0.16677833,637.94912143,0.15424639,744.34521265,0.00094604,0.00000000,0.00000000,0.00000000,0.00000000,0.00000000,0.00000000,0.00000000,0.00000000
222.58000000,5.02396100,9.73100000,0.16839678,638.01468660,0.15563253,745.45430400,0.00088174,0.00000000,0.00000000,0.00000000,0.00000000,0.00000000,0.00000000,0.00000000,0.00000000
224.08000000,5.07203000,9.73300000,0.17005211,638.14581694,0.15704829,746.66386031,0.00088031,0.00000000,0.00000000,0.00000000,0.00000000,0.00000000,0.00000000,0.00000000,0.00000000
225.58000000,5.12029900,9.73500000,0.17174422,638.27694729,0.15849343,747.89732516,0.00094203,0.00000000,0.00000000,0.00000000,0.00000000,0.00000000,0.00000000,0.00000000,0.00000000
227.08000000,5.16909600,9.73600000,0.17343633,638.34251246,0.15993648,749.05429723,0.00100338,0.00000000,0.00000000,0.00000000,0.00000000,0.00000000,0.00000000,0.00000000,0.00000000
228.58000000,5.21739700,9.73600000,0.17509156,638.34251246,0.16134606,750.11089594,0.00093934,0.00000000,0.00000000,0.00000000,0.00000000,0.00000000,0.00000000,0.00000000,0.00000000
230.08000000,5.26609500,9.73700000,0.17682044,638.40807763,0.16281626,751.29167765,0.00100050,0.00000000,0.00000000,0.00000000,0.00000000,0.00000000,0.00000000,0.00000000,0.00000000
231.58000000,5.31472700,9.73800000,0.17854922,638.47364280,0.16428421,752.47261513,0.00099903,0.00000000,0.00000000,0.00000000,0.00000000,0.00000000,0.00000000,0.00000000,0.00000000
233.08000000,5.36359200,9.73900000,0.18027811,638.53920797,0.16575010,753.65385026,0.00099757,0.00000000,0.00000000,0.00000000,0.00000000,0.00000000,0.00000000,0.00000000,0.00000000
234.58000000,5.41328300,9.74000000,0.18200700,638.60477314,0.16721384,754.83531209,0.00099611,0.00000000,0.00000000,0.00000000,0.00000000,0.00000000,0.00000000,0.00000000,0.00000000
236.08000000,5.46261000,9.74000000,0.18377256,638.60477314,0.16870642,755.96280430,0.00105660,0.00000000,0.00000000,0.00000000,0.00000000,0.00000000,0.00000000,0.00000000,0.00000000
237.58000000,5.51216800,9.74000000,0.18553822,638.60477314,0.17019687,757.09036746,0.00099314,0.00000000,0.00000000,0.00000000,0.00000000,0.00000000,0.00000000,0.00000000,0.00000000
239.08000000,5.56232300,9.74000000,0.18734056,638.60477314,0.00000000,0.00000000,0.00000000,0.00000000,0.00000000,0.00000000,0.00000000,0.00000000,0.00000000,0.00000000,0.00000000
240.58000000,5.61195000,9.74000000,0.18910633,638.60477314,0.00000000,0.00000000,0.00000000,0.00000000,0.00000000,0.00000000,0.00000000,0.00000000,0.00000000,0.00000000,0.00000000
242.08000000,5.66223700,9.74000000,0.19094556,638.60477314,0.00000000,0.00000000,0.00000000,0.00000000,0.00000000,0.00000000,0.00000000,0.00000000,0.00000000,0.00000000,0.00000000
243.58000000,5.71249200,9.74000000,0.19278467,638.60477314,0.00000000,0.00000000,0.00000000,0.00000000,0.00000000,0.00000000,0.00000000,0.00000000,0.00000000,0.00000000,0.00000000
245.08000000,5.76314300,9.74000000,0.19462389,638.60477314,0.00000000,0.00000000,0.00000000,0.00000000,0.00000000,0.00000000,0.00000000,0.00000000,0.00000000,0.00000000,0.00000000
246.58000000,5.81435800,9.74000000,0.19649978,638.60477314,0.00000000,0.00000000,0.00000000,0.00000000,0.00000000,0.00000000,0.00000000,0.00000000,0.00000000,0.00000000,0.00000000
248.08000000,5.86500900,9.73900000,0.19833911,638.53920797,0.00000000,0.00000000,0.00000000,0.00000000,0.00000000,0.00000000,0.00000000,0.00000000,0.00000000,0.00000000,0.00000000
249.58000000,5.91705000,9.73900000,0.20025189,638.53920797,0.00000000,0.00000000,0.00000000,0.00000000,0.00000000,0.00000000,0.00000000,0.00000000,0.00000000,0.00000000,0.00000000
251.08000000,5.96862900,9.73800000,0.20216467,638.47364280,0.00000000,0.00000000,0.00000000,0.00000000,0.00000000,0.00000000,0.00000000,0.00000000,0.00000000,0.00000000,0.00000000
252.58000000,6.02024100,9.73700000,0.20411422,638.40807763,0.00000000,0.00000000,0.00000000,0.00000000,0.00000000,0.00000000,0.00000000,0.00000000,0.00000000,0.00000000,0.00000000
254.08000000,6.07195200,9.73500000,0.20606378,638.27694729,0.00000000,0.00000000,0.00000000,0.00000000,0.00000000,0.00000000,0.00000000,0.00000000,0.00000000,0.00000000,0.00000000
255.58000000,6.12373000,9.73400000,0.20801344,638.21138211,0.00000000,0.00000000,0.00000000,0.00000000,0.00000000,0.00000000,0.00000000,0.00000000,0.00000000,0.00000000,0.00000000
257.08000000,6.17699700,9.73400000,0.21003656,638.21138211,0.00000000,0.00000000,0.00000000,0.00000000,0.00000000,0.00000000,0.00000000,0.00000000,0.00000000,0.00000000,0.00000000
258.58000000,6.22989900,9.73300000,0.21205978,638.14581694,0.00000000,0.00000000,0.00000000,0.00000000,0.00000000,0.00000000,0.00000000,0.00000000,0.00000000,0.00000000,0.00000000
260.08000000,6.28306700,9.73100000,0.21415644,638.01468660,0.00000000,0.00000000,0.00000000,0.00000000,0.00000000,0.00000000,0.00000000,0.00000000,0.00000000,0.00000000,0.00000000
261.58000000,6.33636700,9.72900000,0.21621644,637.88355625,0.00000000,0.00000000,0.00000000,0.00000000,0.00000000,0.00000000,0.00000000,0.00000000,0.00000000,0.00000000,0.00000000
263.08000000,6.38996600,9.72700000,0.21834989,637.75242591,0.00000000,0.00000000,0.00000000,0.00000000,0.00000000,0.00000000,0.00000000,0.00000000,0.00000000,0.00000000,0.00000000
264.58000000,6.44419200,9.72600000,0.22048344,637.68686074,0.00000000,0.00000000,0.00000000,0.00000000,0.00000000,0.00000000,0.00000000,0.00000000,0.00000000,0.00000000,0.00000000
266.08000000,6.49841900,9.72300000,0.22265378,637.49016522,0.00000000,0.00000000,0.00000000,0.00000000,0.00000000,0.00000000,0.00000000,0.00000000,0.00000000,0.00000000,0.00000000
267.58000000,6.55297700,9.72100000,0.22493433,637.35903488,0.00000000,0.00000000,0.00000000,0.00000000,0.00000000,0.00000000,0.00000000,0.00000000,0.00000000,0.00000000,0.00000000
269.08000000,6.60753400,9.71900000,0.22714144,637.22790454,0.00000000,0.00000000,0.00000000,0.00000000,0.00000000,0.00000000,0.00000000,0.00000000,0.00000000,0.00000000,0.00000000
270.58000000,6.66248900,9.71700000,0.22942211,637.09677419,0.00000000,0.00000000,0.00000000,0.00000000,0.00000000,0.00000000,0.00000000,0.00000000,0.00000000,0.00000000,0.00000000
272.08000000,6.71820600,9.71500000,0.23177633,636.96564385,0.00000000,0.00000000,0.00000000,0.00000000,0.00000000,0.00000000,0.00000000,0.00000000,0.00000000,0.00000000,0.00000000
273.58000000,6.77355900,9.71100000,0.23416733,636.70338316,0.00000000,0.00000000,0.00000000,0.00000000,0.00000000,0.00000000,0.00000000,0.00000000,0.00000000,0.00000000,0.00000000
275.08000000,6.82894400,9.70800000,0.23655833,636.50668765,0.00000000,0.00000000,0.00000000,0.00000000,0.00000000,0.00000000,0.00000000,0.00000000,0.00000000,0.00000000,0.00000000
276.58000000,6.88485900,9.70500000,0.23902300,636.30999213,0.00000000,0.00000000,0.00000000,0.00000000,0.00000000,0.00000000,0.00000000,0.00000000,0.00000000,0.00000000,0.00000000
278.08000000,6.94080800,9.70200000,0.24159789,636.11329662,0.00000000,0.00000000,0.00000000,0.00000000,0.00000000,0.00000000,0.00000000,0.00000000,0.00000000,0.00000000,0.00000000
279.58000000,6.99764900,9.69900000,0.24413600,635.91660110,0.00000000,0.00000000,0.00000000,0.00000000,0.00000000,0.00000000,0.00000000,0.00000000,0.00000000,0.00000000,0.00000000
281.08000000,7.05409400,9.69500000,0.24674778,635.65434041,0.00000000,0.00000000,0.00000000,0.00000000,0.00000000,0.00000000,0.00000000,0.00000000,0.00000000,0.00000000,0.00000000
282.58000000,7.11126700,9.69200000,0.24946978,635.45764490,0.00000000,0.00000000,0.00000000,0.00000000,0.00000000,0.00000000,0.00000000,0.00000000,0.00000000,0.00000000,0.00000000
284.08000000,7.16844000,9.68700000,0.25226556,635.12981904,0.00000000,0.00000000,0.00000000,0.00000000,0.00000000,0.00000000,0.00000000,0.00000000,0.00000000,0.00000000,0.00000000
285.58000000,7.22528300,9.68300000,0.25502456,634.86755835,0.00000000,0.00000000,0.00000000,0.00000000,0.00000000,0.00000000,0.00000000,0.00000000,0.00000000,0.00000000,0.00000000
287.08000000,7.28288600,9.67900000,0.25796722,634.60529767,0.00000000,0.00000000,0.00000000,0.00000000,0.00000000,0.00000000,0.00000000,0.00000000,0.00000000,0.00000000,0.00000000
288.58000000,7.34085300,9.67400000,0.26094700,634.27747181,0.00000000,0.00000000,0.00000000,0.00000000,0.00000000,0.00000000,0.00000000,0.00000000,0.00000000,0.00000000,0.00000000
290.08000000,7.39938300,9.66900000,0.26403689,633.94964595,0.00000000,0.00000000,0.00000000,0.00000000,0.00000000,0.00000000,0.00000000,0.00000000,0.00000000,0.00000000,0.00000000
291.58000000,7.45718500,9.66400000,0.26716378,633.62182009,0.00000000,0.00000000,0.00000000,0.00000000,0.00000000,0.00000000,0.00000000,0.00000000,0.00000000,0.00000000,0.00000000
293.08000000,7.51502200,9.65800000,0.27036411,633.22842906,0.00000000,0.00000000,0.00000000,0.00000000,0.00000000,0.00000000,0.00000000,0.00000000,0.00000000,0.00000000,0.00000000
294.58000000,7.57398100,9.65300000,0.27378511,632.90060320,0.00000000,0.00000000,0.00000000,0.00000000,0.00000000,0.00000000,0.00000000,0.00000000,0.00000000,0.00000000,0.00000000
296.08000000,7.63287500,9.64600000,0.27716944,632.44164700,0.00000000,0.00000000,0.00000000,0.00000000,0.00000000,0.00000000,0.00000000,0.00000000,0.00000000,0.00000000,0.00000000
297.58000000,7.69150400,9.63900000,0.28073778,631.98269079,0.00000000,0.00000000,0.00000000,0.00000000,0.00000000,0.00000000,0.00000000,0.00000000,0.00000000,0.00000000,0.00000000
299.08000000,7.75056300,9.63100000,0.28434278,631.45816942,0.00000000,0.00000000,0.00000000,0.00000000,0.00000000,0.00000000,0.00000000,0.00000000,0.00000000,0.00000000,0.00000000
300.58000000,7.80972200,9.62400000,0.28816878,630.99921322,0.00000000,0.00000000,0.00000000,0.00000000,0.00000000,0.00000000,0.00000000,0.00000000,0.00000000,0.00000000,0.00000000
302.08000000,7.87007200,9.61700000,0.29210489,630.54025702,0.00000000,0.00000000,0.00000000,0.00000000,0.00000000,0.00000000,0.00000000,0.00000000,0.00000000,0.00000000,0.00000000
303.58000000,7.93025700,9.60700000,0.29622511,629.88460530,0.00000000,0.00000000,0.00000000,0.00000000,0.00000000,0.00000000,0.00000000,0.00000000,0.00000000,0.00000000,0.00000000
305.08000000,7.98991300,9.59600000,0.30034544,629.16338841,0.00000000,0.00000000,0.00000000,0.00000000,0.00000000,0.00000000,0.00000000,0.00000000,0.00000000,0.00000000,0.00000000
306.58000000,8.04993200,9.58500000,0.30464967,628.44217152,0.00000000,0.00000000,0.00000000,0.00000000,0.00000000,0.00000000,0.00000000,0.00000000,0.00000000,0.00000000,0.00000000
308.08000000,8.11002000,9.57200000,0.30910122,627.58982429,0.00000000,0.00000000,0.00000000,0.00000000,0.00000000,0.00000000,0.00000000,0.00000000,0.00000000,0.00000000,0.00000000
309.58000000,8.17066800,9.55900000,0.31366333,626.73747705,0.00000000,0.00000000,0.00000000,0.00000000,0.00000000,0.00000000,0.00000000,0.00000000,0.00000000,0.00000000,0.00000000
311.08000000,8.23151600,9.54400000,0.31833589,625.75399948,0.00000000,0.00000000,0.00000000,0.00000000,0.00000000,0.00000000,0.00000000,0.00000000,0.00000000,0.00000000,0.00000000
312.58000000,8.29213100,9.52900000,0.32311900,624.77052190,0.00000000,0.00000000,0.00000000,0.00000000,0.00000000,0.00000000,0.00000000,0.00000000,0.00000000,0.00000000,0.00000000
314.08000000,8.35347600,9.51000000,0.32812289,623.52478363,0.00000000,0.00000000,0.00000000,0.00000000,0.00000000,0.00000000,0.00000000,0.00000000,0.00000000,0.00000000,0.00000000
315.58000000,8.41482100,9.49100000,0.33323778,622.27904537,0.00000000,0.00000000,0.00000000,0.00000000,0.00000000,0.00000000,0.00000000,0.00000000,0.00000000,0.00000000,0.00000000
317.08000000,8.47636500,9.47000000,0.33842633,620.90217676,0.00000000,0.00000000,0.00000000,0.00000000,0.00000000,0.00000000,0.00000000,0.00000000,0.00000000,0.00000000,0.00000000
318.58000000,8.53747900,9.44500000,0.34372600,619.26304747,0.00000000,0.00000000,0.00000000,0.00000000,0.00000000,0.00000000,0.00000000,0.00000000,0.00000000,0.00000000,0.00000000
320.08000000,8.59919100,9.42100000,0.34924667,617.68948335,0.00000000,0.00000000,0.00000000,0.00000000,0.00000000,0.00000000,0.00000000,0.00000000,0.00000000,0.00000000,0.00000000
321.58000000,8.66100200,9.39400000,0.35484144,615.91922371,0.00000000,0.00000000,0.00000000,0.00000000,0.00000000,0.00000000,0.00000000,0.00000000,0.00000000,0.00000000,0.00000000
323.08000000,8.72255000,9.36200000,0.36054733,613.82113821,0.00000000,0.00000000,0.00000000,0.00000000,0.00000000,0.00000000,0.00000000,0.00000000,0.00000000,0.00000000,0.00000000
324.58000000,8.78506200,9.33300000,0.36636500,611.91974823,0.00000000,0.00000000,0.00000000,0.00000000,0.00000000,0.00000000,0.00000000,0.00000000,0.00000000,0.00000000,0.00000000
326.08000000,8.84707700,9.29700000,0.37229400,609.55940205,0.00000000,0.00000000,0.00000000,0.00000000,0.00000000,0.00000000,0.00000000,0.00000000,0.00000000,0.00000000,0.00000000
327.58000000,8.90959400,9.25900000,0.37840856,607.06792552,0.00000000,0.00000000,0.00000000,0.00000000,0.00000000,0.00000000,0.00000000,0.00000000,0.00000000,0.00000000,0.00000000
329.08000000,8.97185000,9.21500000,0.38456167,604.18305796,0.00000000,0.00000000,0.00000000,0.00000000,0.00000000,0.00000000,0.00000000,0.00000000,0.00000000,0.00000000,0.00000000
330.58000000,9.03417800,9.17000000,0.39086467,601.23262523,0.00000000,0.00000000,0.00000000,0.00000000,0.00000000,0.00000000,0.00000000,0.00000000,0.00000000,0.00000000,0.00000000
332.08000000,9.09793600,9.11700000,0.39742811,597.75767113,0.00000000,0.00000000,0.00000000,0.00000000,0.00000000,0.00000000,0.00000000,0.00000000,0.00000000,0.00000000,0.00000000
333.58000000,9.16177000,9.06700000,0.40414322,594.47941254,0.00000000,0.00000000,0.00000000,0.00000000,0.00000000,0.00000000,0.00000000,0.00000000,0.00000000,0.00000000,0.00000000
335.08000000,9.22601300,8.99900000,0.41104833,590.02098085,0.00000000,0.00000000,0.00000000,0.00000000,0.00000000,0.00000000,0.00000000,0.00000000,0.00000000,0.00000000,0.00000000
336.57000000,9.29027200,8.92700000,0.41799722,585.30028849,0.00000000,0.00000000,0.00000000,0.00000000,0.00000000,0.00000000,0.00000000,0.00000000,0.00000000,0.00000000,0.00000000
338.08000000,9.35564900,8.83800000,0.42521233,579.46498820,0.00000000,0.00000000,0.00000000,0.00000000,0.00000000,0.00000000,0.00000000,0.00000000,0.00000000,0.00000000,0.00000000
339.58000000,9.42274200,8.74000000,0.43277244,573.03960136,0.00000000,0.00000000,0.00000000,0.00000000,0.00000000,0.00000000,0.00000000,0.00000000,0.00000000,0.00000000,0.00000000
341.08000000,9.49145900,8.61100000,0.44056867,564.58169420,0.00000000,0.00000000,0.00000000,0.00000000,0.00000000,0.00000000,0.00000000,0.00000000,0.00000000,0.00000000,0.00000000
342.57000000,9.56316100,8.47600000,0.44878900,555.73039601,0.00000000,0.00000000,0.00000000,0.00000000,0.00000000,0.00000000,0.00000000,0.00000000,0.00000000,0.00000000,0.00000000
344.07000000,9.64261200,8.27600000,0.45795900,542.61736166,0.00000000,0.00000000,0.00000000,0.00000000,0.00000000,0.00000000,0.00000000,0.00000000,0.00000000,0.00000000,0.00000000
345.57000000,9.73601900,8.01700000,0.46906089,525.63598217,0.00000000,0.00000000,0.00000000,0.00000000,0.00000000,0.00000000,0.00000000,0.00000000,0.00000000,0.00000000,0.00000000
346.07000000,9.77614100,7.88300000,0.47378656,516.85024915,0.00000000,0.00000000,0.00000000,0.00000000,0.00000000,0.00000000,0.00000000,0.00000000,0.00000000,0.00000000,0.00000000