File: polyN_optimization/DP600_results/DATA/UT_45_1.csv
Time[s],Displacement[mm],Force[kN],EngStrain_longi,EngStress[MPa],TrueStrain,TrueStress[MPa],TrueStrainRate[1/s],PlasticStrain_longi,PlasticStress[MPa],PlasticStrain_thick,PlasticStrain_width,R-Value,Thickness[mm],Width[mm], Young's Modulus [MPa]
0.65000000,0.00000000,-0.01300000,0.00000000,-0.84989540,0.00000000,-0.84989540,0.00000000,0.00063979,353.72388508,0.00029337,-0.00093316,0.79942286,1.52960000,10.00000000,253417.60487363
2.15000000,0.00119400,0.07600000,0.00006778,4.96861925,0.00006778,4.96895601,0.00003089,0.00109207,366.75609674,-0.00007259,-0.00101948,0.00000000,0.00000000,0.00000000,0.00000000
3.65000000,0.00290000,0.40900000,0.00009711,26.73901674,0.00009711,26.74161339,-0.00002422,0.00168724,381.30197135,-0.00047965,-0.00120760,0.00000000,0.00000000,0.00000000,0.00000000
5.14000000,0.00535000,0.74000000,0.00018167,48.37866109,0.00018165,48.38744988,0.00009043,0.00239088,391.56863293,-0.00088101,-0.00150987,0.00000000,0.00000000,0.00000000,0.00000000
6.64000000,0.00821400,1.07000000,0.00023544,69.95292887,0.00023542,69.96939890,0.00010153,0.00302236,402.21647619,-0.00109037,-0.00193199,0.00000000,0.00000000,0.00000000,0.00000000
8.14000000,0.00957400,1.43000000,0.00028511,93.48849372,0.00028507,93.51514833,0.00009198,0.00375265,411.20667841,-0.00143375,-0.00231889,0.00000000,0.00000000,0.00000000,0.00000000
9.64000000,0.01078600,1.73800000,0.00033656,113.62447699,0.00033650,113.66271794,0.00002710,0.00458469,420.12154079,-0.00192757,-0.00265713,0.00000000,0.00000000,0.00000000,0.00000000
11.14000000,0.01289500,2.12100000,0.00038844,138.66370293,0.00038837,138.71756607,-0.00006109,0.00552554,427.44830982,-0.00252935,-0.00299619,0.00000000,0.00000000,0.00000000,0.00000000
12.64000000,0.01549800,2.42400000,0.00049844,158.47280335,0.00049832,158.55179324,-0.00009351,0.00639100,435.87934066,-0.00301659,-0.00337440,0.00000000,0.00000000,0.00000000,0.00000000
14.14000000,0.01882200,2.77600000,0.00061000,181.48535565,0.00060981,181.59606172,-0.00004775,0.00722118,442.39187785,-0.00342973,-0.00379145,0.00000000,0.00000000,0.00000000,0.00000000
15.64000000,0.02245100,3.10400000,0.00076411,202.92887029,0.00076382,203.08393050,0.00020363,0.00810605,448.74137058,-0.00381530,-0.00429075,0.00000000,0.00000000,0.00000000,0.00000000
17.14000000,0.02540100,3.45100000,0.00087367,225.61453975,0.00087329,225.81165165,0.00032552,0.00909345,456.27533755,-0.00436705,-0.00472639,0.00000000,0.00000000,0.00000000,0.00000000
18.64000000,0.02847200,3.74200000,0.00091356,244.63912134,0.00091314,244.86261277,0.00025223,0.01003635,462.14541369,-0.00491912,-0.00511723,0.00000000,0.00000000,0.00000000,0.00000000
20.14000000,0.03208600,4.09900000,0.00094200,267.97855649,0.00094156,268.23099229,0.00003685,0.01094962,468.67650475,-0.00547823,-0.00547139,0.00000000,0.00000000,0.00000000,0.00000000
21.64000000,0.03751800,4.37800000,0.00108911,286.21861925,0.00108852,286.53034313,-0.00011765,0.01186117,474.62062626,-0.00602816,-0.00583301,0.00000000,0.00000000,0.00000000,0.00000000
23.14000000,0.04424300,4.69300000,0.00131367,306.81223849,0.00131280,307.21528750,-0.00026430,0.01285437,480.74791659,-0.00659542,-0.00625895,0.00000000,0.00000000,0.00000000,0.00000000
24.64000000,0.05292600,4.96700000,0.00168200,324.72541841,0.00168059,325.27160656,-0.00005080,0.01387652,485.90243191,-0.00717035,-0.00670617,0.00000000,0.00000000,0.00000000,0.00000000
26.14000000,0.06356500,5.23700000,0.00213511,342.37709205,0.00213284,343.10810518,0.00032356,0.01480965,492.09004164,-0.00762550,-0.00718415,0.00000000,0.00000000,0.00000000,0.00000000
27.64000000,0.07934200,5.44900000,0.00262500,356.23692469,0.00262156,357.17204661,0.00059475,0.01569816,496.86560408,-0.00808566,-0.00761250,0.00000000,0.00000000,0.00000000,0.00000000
29.14000000,0.09585400,5.68400000,0.00316278,371.60041841,0.00315779,372.77570796,0.00063853,0.01671259,502.31397876,-0.00870602,-0.00800658,0.00000000,0.00000000,0.00000000,0.00000000
30.64000000,0.11468300,5.85100000,0.00374867,382.51830544,0.00374166,383.95223906,0.00047738,0.01773549,507.24254411,-0.00929368,-0.00844181,0.00000000,0.00000000,0.00000000,0.00000000
32.15000000,0.13702500,6.02200000,0.00453722,393.69769874,0.00452696,395.48399269,0.00053230,0.01869911,512.35127611,-0.00985041,-0.00884871,0.00000000,0.00000000,0.00000000,0.00000000
33.65000000,0.16086000,6.16400000,0.00538800,402.98117155,0.00537354,405.15243410,0.00087172,0.01966521,516.66686839,-0.01038248,-0.00928272,0.00000000,0.00000000,0.00000000,0.00000000
35.15000000,0.18750300,6.30100000,0.00621656,411.93776151,0.00619731,414.49859549,0.00097308,0.02068397,521.75583957,-0.01090021,-0.00978376,0.00000000,0.00000000,0.00000000,0.00000000
36.65000000,0.21245200,6.41100000,0.00701911,419.12918410,0.00699459,422.07109841,0.00081864,0.02173138,525.86279045,-0.01147312,-0.01025826,0.00000000,0.00000000,0.00000000,0.00000000
38.15000000,0.24057700,6.53900000,0.00788044,427.49738494,0.00784956,430.86625433,0.00057709,0.02273498,530.69406907,-0.01196504,-0.01076995,0.00000000,0.00000000,0.00000000,0.00000000
39.65000000,0.26850600,6.63500000,0.00890744,433.77353556,0.00886801,437.63734923,0.00080279,0.02372739,534.58669162,-0.01249509,-0.01123230,0.00000000,0.00000000,0.00000000,0.00000000
41.15000000,0.29666500,6.74200000,0.00984244,440.76882845,0.00979432,445.10707116,0.00093304,0.02479188,538.92975711,-0.01310463,-0.01168726,0.00000000,0.00000000,0.00000000,0.00000000
42.65000000,0.32462200,6.83700000,0.01070778,446.97960251,0.01065086,451.76576077,0.00081588,0.02585104,542.60437245,-0.01375414,-0.01209690,0.00000000,0.00000000,0.00000000,0.00000000
44.15000000,0.35432900,6.92800000,0.01161689,452.92887029,0.01154993,458.19049465,0.00056749,0.02687728,546.94335613,-0.01434112,-0.01253616,0.00000000,0.00000000,0.00000000,0.00000000
45.65000000,0.38294400,7.01600000,0.01265067,458.68200837,0.01257132,464.48464156,0.00066854,0.02793860,550.49925007,-0.01491691,-0.01302169,0.00000000,0.00000000,0.00000000,0.00000000
47.15000000,0.41238700,7.10100000,0.01364756,464.23901674,0.01355527,470.57474451,0.00074771,0.02903116,554.68848283,-0.01552787,-0.01350329,0.00000000,0.00000000,0.00000000,0.00000000
48.65000000,0.44302600,7.18900000,0.01458556,469.99215481,0.01448021,476.84725150,0.00071788,0.03010893,557.99754867,-0.01612740,-0.01398153,0.00000000,0.00000000,0.00000000,0.00000000
50.15000000,0.47181100,7.26700000,0.01552378,475.09152720,0.01540452,482.46674249,0.00052175,0.03116576,561.70827349,-0.01667496,-0.01449080,0.00000000,0.00000000,0.00000000,0.00000000
51.65000000,0.50284300,7.34800000,0.01654289,480.38702929,0.01640755,488.33401854,0.00043442,0.03224132,564.96178594,-0.01722758,-0.01501374,0.00000000,0.00000000,0.00000000,0.00000000
53.15000000,0.53311200,7.42200000,0.01761367,485.22489540,0.01746034,493.77148496,0.00061482,0.03332388,568.76940934,-0.01783108,-0.01549280,0.00000000,0.00000000,0.00000000,0.00000000
54.65000000,0.56400900,7.49100000,0.01859989,489.73587866,0.01842903,498.84491159,0.00072967,0.03443287,571.91956512,-0.01844945,-0.01598342,0.00000000,0.00000000,0.00000000,0.00000000
56.15000000,0.59477200,7.55800000,0.01955700,494.11610879,0.01936822,503.77953753,0.00052731,0.03552061,575.60874882,-0.01906833,-0.01645227,0.00000000,0.00000000,0.00000000,0.00000000
57.65000000,0.62646300,7.62900000,0.02060944,498.75784519,0.02039994,509.03696729,0.00049802,0.03660394,578.48458956,-0.01967035,-0.01693359,0.00000000,0.00000000,0.00000000,0.00000000
59.15000000,0.65795300,7.69200000,0.02167667,502.87656904,0.02144507,513.77725680,0.00061238,0.03769783,581.85007547,-0.02029243,-0.01740540,0.00000000,0.00000000,0.00000000,0.00000000
60.65000000,0.69007400,7.75800000,0.02271056,507.19142259,0.02245651,518.71002157,0.00066197,0.03879295,584.67632408,-0.02092969,-0.01786326,0.00000000,0.00000000,0.00000000,0.00000000
62.15000000,0.72216100,7.81600000,0.02372233,510.98326360,0.02344533,523.10497891,0.00055361,0.03990227,587.99545264,-0.02156851,-0.01833376,0.00000000,0.00000000,0.00000000,0.00000000
63.65000000,0.75408400,7.87200000,0.02483711,514.64435146,0.02453368,527.42663040,0.00059639,0.04101301,590.77418456,-0.02217862,-0.01883439,0.00000000,0.00000000,0.00000000,0.00000000
65.14000000,0.78650400,7.92700000,0.02593711,518.24006276,0.02560645,531.68171285,0.00068870,0.04211977,594.03609689,-0.02279437,-0.01932540,0.00000000,0.00000000,0.00000000,0.00000000
66.64000000,0.81921800,7.98500000,0.02701478,522.03190377,0.02665632,536.13447964,0.00076655,0.04327758,596.71727592,-0.02342844,-0.01984913,0.00000000,0.00000000,0.00000000,0.00000000
68.14000000,0.85206800,8.03600000,0.02806700,525.36610879,0.02768034,540.11155936,0.00064425,0.04437319,599.64148939,-0.02403195,-0.02034124,0.00000000,0.00000000,0.00000000,0.00000000
69.64000000,0.88514600,8.08900000,0.02917767,528.83106695,0.02876010,544.26112354,0.00065046,0.04550435,602.18007066,-0.02465180,-0.02085255,0.00000000,0.00000000,0.00000000,0.00000000
71.14000000,0.91848700,8.13800000,0.03031422,532.03451883,0.02986383,548.16273146,0.00076410,0.04663918,605.13927943,-0.02527067,-0.02136851,0.00000000,0.00000000,0.00000000,0.00000000
72.64000000,0.95170100,8.18500000,0.03138844,535.10721757,0.03090590,551.90340074,0.00069174,0.04779234,607.63286251,-0.02590215,-0.02189019,0.00000000,0.00000000,0.00000000,0.00000000
74.14000000,0.98583600,8.23000000,0.03252156,538.04916318,0.03200392,555.54735893,0.00066278,0.04893890,610.47269864,-0.02653499,-0.02240392,0.00000000,0.00000000,0.00000000,0.00000000
75.64000000,1.01944400,8.27700000,0.03364356,541.12186192,0.03308999,559.32712535,0.00064787,0.05006526,612.89108469,-0.02715779,-0.02290747,0.00000000,0.00000000,0.00000000,0.00000000
77.14000000,1.05348000,8.32000000,0.03479100,543.93305439,0.03419947,562.85702929,0.00071783,0.05121032,615.53338487,-0.02780402,-0.02340630,0.00000000,0.00000000,0.00000000,0.00000000
78.64000000,1.08748300,8.36500000,0.03587611,546.87500000,0.03524755,566.49474826,0.00063188,0.05237608,617.91664477,-0.02846942,-0.02390666,0.00000000,0.00000000,0.00000000,0.00000000
80.14000000,1.12234800,8.40500000,0.03706078,549.49006276,0.03639054,569.85459187,0.00071647,0.05349433,620.48325183,-0.02904128,-0.02445306,0.00000000,0.00000000,0.00000000,0.00000000
81.64000000,1.15734400,8.44400000,0.03821211,552.03974895,0.03750011,573.13435318,0.00068762,0.05463374,622.72082101,-0.02965667,-0.02497708,0.00000000,0.00000000,0.00000000,0.00000000
83.14000000,1.19204400,8.48200000,0.03935244,554.52405858,0.03859787,576.34593579,0.00067254,0.05580474,625.33023971,-0.03027629,-0.02552845,0.00000000,0.00000000,0.00000000,0.00000000
84.64000000,1.22730600,8.52200000,0.04051500,557.13912134,0.03971578,579.71161284,0.00071430,0.05696200,627.58820241,-0.03093102,-0.02603098,0.00000000,0.00000000,0.00000000,0.00000000
86.14000000,1.26233500,8.55800000,0.04168111,559.49267782,0.04083586,582.81295429,0.00073463,0.05810055,629.90849512,-0.03153455,-0.02656600,0.00000000,0.00000000,0.00000000,0.00000000
87.64000000,1.29743300,8.59500000,0.04283978,561.91161088,0.04194755,585.98377942,0.00074085,0.05927678,631.97804340,-0.03218837,-0.02708841,0.00000000,0.00000000,0.00000000,0.00000000
89.14000000,1.33315900,8.62900000,0.04406133,564.13441423,0.04311824,588.99092870,0.00083197,0.06045689,634.40346104,-0.03283909,-0.02761779,0.00000000,0.00000000,0.00000000,0.00000000
90.64000000,1.36858700,8.66200000,0.04522756,566.29184100,0.04423462,591.90383670,0.00081679,0.06162650,636.54725482,-0.03348082,-0.02814569,0.00000000,0.00000000,0.00000000,0.00000000
92.14000000,1.40474300,8.69400000,0.04640089,568.38389121,0.04535655,594.75740900,0.00081608,0.06280067,638.90826796,-0.03413776,-0.02866291,0.00000000,0.00000000,0.00000000,0.00000000
93.64000000,1.44020200,8.72700000,0.04758900,570.54131799,0.04649133,597.69280877,0.00074449,0.06397199,640.85143632,-0.03479374,-0.02917825,0.00000000,0.00000000,0.00000000,0.00000000
95.14000000,1.47668800,8.75700000,0.04880667,572.50261506,0.04765301,600.44455936,0.00084876,0.06517504,643.02940467,-0.03546594,-0.02970911,0.00000000,0.00000000,0.00000000,0.00000000
96.64000000,1.51267700,8.78900000,0.04998767,574.59466527,0.04877842,603.31731187,0.00081308,0.06635385,644.98515594,-0.03609953,-0.03025432,0.00000000,0.00000000,0.00000000,0.00000000
98.14000000,1.54893000,8.81800000,0.05114978,576.49058577,0.04988459,605.97795113,0.00072759,0.06754989,647.30773807,-0.03681171,-0.03073818,0.00000000,0.00000000,0.00000000,0.00000000
99.64000000,1.58561400,8.84600000,0.05237844,578.32112971,0.05105279,608.61269087,0.00073392,0.06873330,649.13352946,-0.03745294,-0.03128037,0.00000000,0.00000000,0.00000000,0.00000000
101.14000000,1.62206700,8.87300000,0.05359233,580.08629707,0.05220559,611.17447527,0.00071936,0.06991077,651.17053066,-0.03811234,-0.03179843,0.00000000,0.00000000,0.00000000,0.00000000
102.64000000,1.65911300,8.90100000,0.05481722,581.91684100,0.05336750,613.81590579,0.00076742,0.07109065,653.14241492,-0.03876644,-0.03232422,0.00000000,0.00000000,0.00000000,0.00000000
104.14000000,1.69596200,8.92700000,0.05599800,583.61663180,0.05448629,616.29799595,0.00068972,0.07230616,655.21221483,-0.03943442,-0.03287175,0.00000000,0.00000000,0.00000000,0.00000000
105.64000000,1.73287800,8.95400000,0.05726333,585.38179916,0.05568381,618.90271226,0.00073053,0.07351463,656.99825363,-0.04006751,-0.03344712,0.00000000,0.00000000,0.00000000,0.00000000
107.14000000,1.76995800,8.97800000,0.05849556,586.95083682,0.05684861,621.28485210,0.00079920,0.07472049,658.99863871,-0.04075895,-0.03396155,0.00000000,0.00000000,0.00000000,0.00000000
108.64000000,1.80693900,9.00100000,0.05968744,588.45449791,0.05797400,623.57784306,0.00074984,0.07588873,660.76504895,-0.04139846,-0.03449027,0.00000000,0.00000000,0.00000000,0.00000000
110.14000000,1.84438300,9.02400000,0.06093800,589.95815900,0.05915342,625.90902929,0.00074183,0.07713288,662.72731175,-0.04206862,-0.03506426,0.00000000,0.00000000,0.00000000,0.00000000
111.64000000,1.88192600,9.04900000,0.06220344,591.59257322,0.06034547,628.39166898,0.00078992,0.07833540,664.52339808,-0.04273495,-0.03560045,0.00000000,0.00000000,0.00000000,0.00000000
113.14000000,1.91953500,9.07100000,0.06344300,593.03085774,0.06151176,630.65451445,0.00082328,0.07952971,666.31738964,-0.04339463,-0.03613508,0.00000000,0.00000000,0.00000000,0.00000000
114.64000000,1.95701400,9.09400000,0.06469733,594.53451883,0.06269056,632.99931677,0.00080874,0.08073353,667.97846706,-0.04407095,-0.03666258,0.00000000,0.00000000,0.00000000,0.00000000
116.14000000,1.99515200,9.11400000,0.06596622,595.84205021,0.06388164,635.14749930,0.00080757,0.08196453,669.94651957,-0.04477022,-0.03719431,0.00000000,0.00000000,0.00000000,0.00000000
117.64000000,2.03299100,9.13400000,0.06722789,597.14958159,0.06506453,637.29468731,0.00081370,0.08319208,671.63010212,-0.04545842,-0.03773366,0.00000000,0.00000000,0.00000000,0.00000000
119.14000000,2.07109800,9.15400000,0.06846733,598.45711297,0.06622522,639.43187561,0.00076427,0.08440101,673.37585085,-0.04613392,-0.03826709,0.00000000,0.00000000,0.00000000,0.00000000
120.64000000,2.10916900,9.17500000,0.06974378,599.83002092,0.06741916,641.66443260,0.00079100,0.08562541,675.06366295,-0.04681956,-0.03880586,0.00000000,0.00000000,0.00000000,0.00000000
122.14000000,2.14730900,9.19300000,0.07104222,601.00679916,0.06863221,643.70365775,0.00079025,0.08687163,676.84120729,-0.04749109,-0.03938054,0.00000000,0.00000000,0.00000000,0.00000000
123.64000000,2.18647200,9.21300000,0.07230378,602.31433054,0.06980940,645.86393205,0.00076838,0.08812386,678.41066630,-0.04818074,-0.03994312,0.00000000,0.00000000,0.00000000,0.00000000
125.14000000,2.22520700,9.23100000,0.07360600,603.49110879,0.07102308,647.91167534,0.00078153,0.08935039,680.10938845,-0.04888034,-0.04047005,0.00000000,0.00000000,0.00000000,0.00000000
126.64000000,2.26420800,9.24800000,0.07488600,604.60251046,0.07221461,649.87877406,0.00078039,0.09056609,681.65979297,-0.04954012,-0.04102597,0.00000000,0.00000000,0.00000000,0.00000000
128.14000000,2.30284300,9.26400000,0.07617711,605.64853556,0.07341505,651.78509135,0.00080693,0.09179290,683.36485555,-0.05020047,-0.04159242,0.00000000,0.00000000,0.00000000,0.00000000
129.64000000,2.34207500,9.28200000,0.07748289,606.82531381,0.07462766,653.84389217,0.00085361,0.09305215,684.95095751,-0.05090020,-0.04215194,0.00000000,0.00000000,0.00000000,0.00000000
131.15000000,2.38137000,9.29900000,0.07878867,607.93671548,0.07583881,655.83523871,0.00080899,0.09429287,686.59954216,-0.05158304,-0.04270983,0.00000000,0.00000000,0.00000000,0.00000000
132.64000000,2.42086400,9.31500000,0.08009078,608.98274059,0.07704509,657.75664193,0.00080380,0.09552599,688.10113218,-0.05225902,-0.04326697,0.00000000,0.00000000,0.00000000,0.00000000
134.14000000,2.46036000,9.33000000,0.08139656,609.96338912,0.07825331,659.61230801,0.00078946,0.09676142,689.53450325,-0.05297827,-0.04378315,0.00000000,0.00000000,0.00000000,0.00000000
135.64000000,2.49992200,9.34500000,0.08268767,610.94403766,0.07944653,661.46157459,0.00082261,0.09801398,691.20001724,-0.05366739,-0.04434658,0.00000000,0.00000000,0.00000000,0.00000000
137.14000000,2.53941800,9.35900000,0.08404122,611.85930962,0.08069593,663.28071383,0.00081440,0.09926268,692.64793067,-0.05436785,-0.04489483,0.00000000,0.00000000,0.00000000,0.00000000
138.64000000,2.57993800,9.37500000,0.08535433,612.90533473,0.08190651,665.21946097,0.00081342,0.10054579,694.19513374,-0.05511117,-0.04543462,0.00000000,0.00000000,0.00000000,0.00000000
140.14000000,2.61959800,9.38800000,0.08666022,613.75523013,0.08310898,666.94339476,0.00081264,0.10176835,695.63006389,-0.05576495,-0.04600340,0.00000000,0.00000000,0.00000000,0.00000000
141.64000000,2.65962200,9.40200000,0.08799156,614.67050209,0.08433339,668.75631573,0.00083801,0.10307424,697.27167447,-0.05651182,-0.04656242,0.00000000,0.00000000,0.00000000,0.00000000
143.14000000,2.70024300,9.41500000,0.08935267,615.52039749,0.08558364,670.51878639,0.00085778,0.10432345,698.65751613,-0.05721240,-0.04711105,0.00000000,0.00000000,0.00000000,0.00000000
144.64000000,2.74059800,9.42800000,0.09067678,616.37029289,0.08679840,672.26076496,0.00081617,0.10558757,700.05621666,-0.05791116,-0.04767641,0.00000000,0.00000000,0.00000000,0.00000000
146.14000000,2.78065700,9.43900000,0.09203411,617.08943515,0.08804211,673.88271279,0.00086911,0.10684352,701.45160601,-0.05857913,-0.04826439,0.00000000,0.00000000,0.00000000,0.00000000
147.64000000,2.82160700,9.45300000,0.09335456,618.00470711,0.08925054,675.69826188,0.00082109,0.10812041,702.93750771,-0.05930624,-0.04881416,0.00000000,0.00000000,0.00000000,0.00000000
149.14000000,2.86236000,9.46400000,0.09472667,618.72384937,0.09050471,677.33349721,0.00082006,0.10938293,704.34250149,-0.05998597,-0.04939696,0.00000000,0.00000000,0.00000000,0.00000000
150.64000000,2.90301400,9.47600000,0.09609489,619.50836820,0.09175376,679.03995601,0.00079875,0.11069630,705.78594747,-0.06072479,-0.04997151,0.00000000,0.00000000,0.00000000,0.00000000
152.14000000,2.94370000,9.48700000,0.09743022,620.22751046,0.09297129,680.65641463,0.00076456,0.11198889,707.07000258,-0.06145971,-0.05052919,0.00000000,0.00000000,0.00000000,0.00000000
153.64000000,2.98501300,9.49700000,0.09877278,620.88127615,0.09419390,682.20744447,0.00076362,0.11329826,708.58927890,-0.06218472,-0.05111353,0.00000000,0.00000000,0.00000000,0.00000000
155.14000000,3.02599700,9.50800000,0.10018878,621.60041841,0.09548178,683.87780460,0.00086953,0.11456761,709.93521271,-0.06288062,-0.05168699,0.00000000,0.00000000,0.00000000,0.00000000
156.64000000,3.06757700,9.51800000,0.10156800,622.25418410,0.09673462,685.45529707,0.00084160,0.11588399,711.31699575,-0.06365232,-0.05223167,0.00000000,0.00000000,0.00000000,0.00000000
158.14000000,3.10892700,9.52800000,0.10294000,622.90794979,0.09797934,687.03009414,0.00083391,0.11720240,712.62864830,-0.06442132,-0.05278108,0.00000000,0.00000000,0.00000000,0.00000000
159.64000000,3.15060600,9.53700000,0.10431578,623.49633891,0.09922594,688.53684445,0.00084656,0.11849272,713.99651999,-0.06513197,-0.05336075,0.00000000,0.00000000,0.00000000,0.00000000
161.14000000,3.19218700,9.54700000,0.10569122,624.15010460,0.10047068,690.11729201,0.00085153,0.11975864,715.34923698,-0.06582432,-0.05393432,0.00000000,0.00000000,0.00000000,0.00000000
162.64000000,3.23403100,9.55600000,0.10707789,624.73849372,0.10172401,691.63417274,0.00083721,0.12109135,716.67797768,-0.06661527,-0.05447608,0.00000000,0.00000000,0.00000000,0.00000000
164.14000000,3.27630700,9.56500000,0.10843522,625.32688285,0.10294931,693.13434235,0.00077662,0.12239977,717.91710642,-0.06732909,-0.05507068,0.00000000,0.00000000,0.00000000,0.00000000
165.64000000,3.31772200,9.57300000,0.10985867,625.84989540,0.10423268,694.60493044,0.00076240,0.12369644,719.22428655,-0.06804091,-0.05565553,0.00000000,0.00000000,0.00000000,0.00000000
167.14000000,3.36029500,9.58300000,0.11127856,626.50366109,0.10551120,696.22008354,0.00086066,0.12504018,720.49308842,-0.06879303,-0.05624714,0.00000000,0.00000000,0.00000000,0.00000000
168.64000000,3.40316600,9.59100000,0.11269089,627.02667364,0.10678131,697.68686685,0.00077345,0.12638183,721.83720213,-0.06951681,-0.05686502,0.00000000,0.00000000,0.00000000,0.00000000
170.14000000,3.44586900,9.59900000,0.11412178,627.54968619,0.10806645,699.16677202,0.00083212,0.12770269,723.09375587,-0.07025852,-0.05744417,0.00000000,0.00000000,0.00000000,0.00000000
171.64000000,3.48844400,9.60500000,0.11556356,627.94194561,0.10935971,700.50914952,0.00087708,0.12900569,724.33939766,-0.07096774,-0.05803794,0.00000000,0.00000000,0.00000000,0.00000000
173.14000000,3.53075300,9.61300000,0.11697600,628.46495816,0.11062503,701.98027510,0.00088254,0.13035476,725.69560924,-0.07173287,-0.05862189,0.00000000,0.00000000,0.00000000,0.00000000
174.64000000,3.57412100,9.62000000,0.11839956,628.92259414,0.11189870,703.38674977,0.00086193,0.13171876,726.91486913,-0.07254779,-0.05917097,0.00000000,0.00000000,0.00000000,0.00000000
176.14000000,3.61748800,9.62700000,0.11988178,629.38023013,0.11322312,704.83145101,0.00097236,0.13302649,728.09500848,-0.07327031,-0.05975618,0.00000000,0.00000000,0.00000000,0.00000000
177.64000000,3.66079100,9.63400000,0.12131633,629.83786611,0.11450329,706.24748662,0.00089221,0.13437071,729.30369535,-0.07408205,-0.06028865,0.00000000,0.00000000,0.00000000,0.00000000
179.14000000,3.70425900,9.64000000,0.12278778,630.23012552,0.11581468,707.61468212,0.00091757,0.13572237,730.59519264,-0.07482862,-0.06089375,0.00000000,0.00000000,0.00000000,0.00000000
180.64000000,3.74795900,9.64600000,0.12422956,630.62238494,0.11709796,708.96432354,0.00085094,0.13705976,731.80286624,-0.07552931,-0.06153045,0.00000000,0.00000000,0.00000000,0.00000000
182.14000000,3.79162300,9.65200000,0.12569356,631.01464435,0.11839934,710.32911861,0.00090217,0.13845894,733.05793070,-0.07632305,-0.06213589,0.00000000,0.00000000,0.00000000,0.00000000
183.64000000,3.83515900,9.65900000,0.12712800,631.47228033,0.11967280,711.75008839,0.00080319,0.13982475,734.21477919,-0.07709109,-0.06273366,0.00000000,0.00000000,0.00000000,0.00000000
185.14000000,3.87922200,9.66400000,0.12861756,631.79916318,0.12099348,713.05962715,0.00079523,0.14115671,735.42426200,-0.07782202,-0.06333468,0.00000000,0.00000000,0.00000000,0.00000000
186.64000000,3.92361600,9.67000000,0.13011833,632.19142259,0.12232235,714.45111685,0.00085929,0.14258188,736.70458588,-0.07867615,-0.06390573,0.00000000,0.00000000,0.00000000,0.00000000
188.14000000,3.96811100,9.67500000,0.13163389,632.51830544,0.12366251,715.77914978,0.00099488,0.14394202,737.86288676,-0.07943686,-0.06450516,0.00000000,0.00000000,0.00000000,0.00000000
189.64000000,4.01220700,9.68000000,0.13310867,632.84518828,0.12496489,717.08236750,0.00092157,0.14533233,738.96922376,-0.08021662,-0.06511571,0.00000000,0.00000000,0.00000000,0.00000000
191.14000000,4.05762700,9.68500000,0.13459467,633.17207113,0.12627547,718.39365499,0.00091409,0.14668844,740.20429694,-0.08096829,-0.06572015,0.00000000,0.00000000,0.00000000,0.00000000
192.64000000,4.10211900,9.68900000,0.13611022,633.43357741,0.12761034,719.65036239,0.00097804,0.14813717,741.51029053,-0.08180969,-0.06632748,0.00000000,0.00000000,0.00000000,0.00000000
194.14000000,4.14711100,9.69400000,0.13758522,633.76046025,0.12890779,720.95653401,0.00087339,0.14955251,742.71717390,-0.08259103,-0.06696148,0.00000000,0.00000000,0.00000000,0.00000000
195.64000000,4.19206800,9.69800000,0.13910433,634.02196653,0.13024228,722.21716950,0.00084626,0.15096665,743.77196098,-0.08336102,-0.06760563,0.00000000,0.00000000,0.00000000,0.00000000
197.14000000,4.23696100,9.70200000,0.14061611,634.28347280,0.13156856,723.47394809,0.00084514,0.15237852,744.90322703,-0.08418893,-0.06818959,0.00000000,0.00000000,0.00000000,0.00000000
198.64000000,4.28234600,9.70700000,0.14212800,634.61035565,0.13289319,724.80625628,0.00087653,0.15381968,746.05815246,-0.08497159,-0.06884809,0.00000000,0.00000000,0.00000000,0.00000000
200.14000000,4.32819800,9.71000000,0.14365444,634.80648536,0.13422879,725.99925834,0.00083667,0.15522704,747.26640993,-0.08574452,-0.06948251,0.00000000,0.00000000,0.00000000,0.00000000
201.64000000,4.37447700,9.71500000,0.14526544,635.13336820,0.13563644,727.39629921,0.00091237,0.15666407,748.42188603,-0.08657231,-0.07009176,0.00000000,0.00000000,0.00000000,0.00000000
203.14000000,4.41983200,9.71700000,0.14677711,635.26412134,0.13695550,728.50635386,0.00092377,0.15809939,749.50073514,-0.08737976,-0.07071964,0.00000000,0.00000000,0.00000000,0.00000000
204.64000000,4.46555100,9.72000000,0.14828889,635.46025105,0.13827291,729.69194561,0.00085866,0.15953191,750.73350193,-0.08815460,-0.07137732,0.00000000,0.00000000,0.00000000,0.00000000
206.14000000,4.51206100,9.72400000,0.14987033,635.72175732,0.13964918,730.99758900,0.00089557,0.16102490,751.93655649,-0.08904047,-0.07198443,0.00000000,0.00000000,0.00000000,0.00000000
207.64000000,4.55867200,9.72800000,0.15145211,635.98326360,0.14102385,732.30427150,0.00095863,0.16248507,753.03926569,-0.08982890,-0.07265617,0.00000000,0.00000000,0.00000000,0.00000000
209.14000000,4.60518500,9.72900000,0.15303356,636.04864017,0.14239634,733.38542508,0.00089330,0.16394281,754.14176229,-0.09066747,-0.07327534,0.00000000,0.00000000,0.00000000,0.00000000
210.64000000,4.65196300,9.73200000,0.15461522,636.24476987,0.14376715,734.61789636,0.00089227,0.16542955,755.26785800,-0.09148403,-0.07394552,0.00000000,0.00000000,0.00000000,0.00000000
212.14000000,4.69920300,9.73500000,0.15616011,636.44089958,0.14510427,735.82758118,0.00089108,0.00000000,0.00000000,0.00000000,0.00000000,0.00000000,0.00000000,0.00000000,0.00000000
213.64000000,4.74674100,9.73800000,0.15781522,636.63702929,0.14653480,737.10804354,0.00088961,0.00000000,0.00000000,0.00000000,0.00000000,0.00000000,0.00000000,0.00000000,0.00000000
215.14000000,4.79381800,9.74000000,0.15943367,636.76778243,0.14793167,738.29000479,0.00095203,0.00000000,0.00000000,0.00000000,0.00000000,0.00000000,0.00000000,0.00000000,0.00000000
216.64000000,4.84148900,9.74100000,0.16105211,636.83315900,0.14932659,739.39648368,0.00095070,0.00000000,0.00000000,0.00000000,0.00000000,0.00000000,0.00000000,0.00000000,0.00000000
218.14000000,4.88902800,9.74300000,0.16267033,636.96391213,0.15071937,740.57904404,0.00101229,0.00000000,0.00000000,0.00000000,0.00000000,0.00000000,0.00000000,0.00000000,0.00000000
219.64000000,4.93706300,9.74600000,0.16436244,637.16004184,0.15217368,741.88522382,0.00101101,0.00000000,0.00000000,0.00000000,0.00000000,0.00000000,0.00000000,0.00000000,0.00000000
221.14000000,4.98599300,9.74800000,0.16594400,637.29079498,0.15353106,743.04537866,0.00088360,0.00000000,0.00000000,0.00000000,0.00000000,0.00000000,0.00000000,0.00000000,0.00000000
222.64000000,5.03405900,9.74800000,0.16759911,637.29079498,0.15494960,744.10016574,0.00088235,0.00000000,0.00000000,0.00000000,0.00000000,0.00000000,0.00000000,0.00000000,0.00000000
224.14000000,5.08272500,9.74900000,0.16929122,637.35617155,0.15639777,745.25497682,0.00094419,0.00000000,0.00000000,0.00000000,0.00000000,0.00000000,0.00000000,0.00000000,0.00000000
225.64000000,5.13096100,9.75100000,0.17094633,637.48692469,0.15781225,746.46297701,0.00087982,0.00000000,0.00000000,0.00000000,0.00000000,0.00000000,0.00000000,0.00000000,0.00000000
227.14000000,5.18038500,9.75200000,0.17263833,637.55230126,0.15925620,747.61826796,0.00094150,0.00000000,0.00000000,0.00000000,0.00000000,0.00000000,0.00000000,0.00000000,0.00000000
228.64000000,5.22941200,9.75300000,0.17436700,637.61767782,0.16072928,748.79715945,0.00100259,0.00000000,0.00000000,0.00000000,0.00000000,0.00000000,0.00000000,0.00000000,0.00000000
230.14000000,5.27883900,9.75400000,0.17605900,637.68305439,0.16216902,749.95289527,0.00100115,0.00000000,0.00000000,0.00000000,0.00000000,0.00000000,0.00000000,0.00000000,0.00000000
231.64000000,5.32813100,9.75500000,0.17775078,637.74843096,0.16360650,751.10871059,0.00099933,0.00000000,0.00000000,0.00000000,0.00000000,0.00000000,0.00000000,0.00000000,0.00000000
233.14000000,5.37852000,9.75500000,0.17951633,637.74843096,0.16510447,752.23469088,0.00099783,0.00000000,0.00000000,0.00000000,0.00000000,0.00000000,0.00000000,0.00000000,0.00000000
234.64000000,5.42807800,9.75600000,0.18124511,637.81380753,0.16656906,753.41444195,0.00099618,0.00000000,0.00000000,0.00000000,0.00000000,0.00000000,0.00000000,0.00000000,0.00000000
236.14000000,5.47820000,9.75600000,0.18301067,637.81380753,0.16806260,754.54053766,0.00105728,0.00000000,0.00000000,0.00000000,0.00000000,0.00000000,0.00000000,0.00000000,0.00000000
237.64000000,5.52848700,9.75600000,0.18473933,637.81380753,0.16952278,755.64310513,0.00099343,0.00000000,0.00000000,0.00000000,0.00000000,0.00000000,0.00000000,0.00000000,0.00000000
239.14000000,5.57890600,9.75700000,0.18654167,637.87918410,0.00000000,0.00000000,0.00000000,0.00000000,0.00000000,0.00000000,0.00000000,0.00000000,0.00000000,0.00000000,0.00000000
240.64000000,5.62985600,9.75700000,0.18830722,637.87918410,0.00000000,0.00000000,0.00000000,0.00000000,0.00000000,0.00000000,0.00000000,0.00000000,0.00000000,0.00000000,0.00000000
242.14000000,5.68034200,9.75700000,0.19007289,637.87918410,0.00000000,0.00000000,0.00000000,0.00000000,0.00000000,0.00000000,0.00000000,0.00000000,0.00000000,0.00000000,0.00000000
243.64000000,5.73215100,9.75700000,0.19191189,637.87918410,0.00000000,0.00000000,0.00000000,0.00000000,0.00000000,0.00000000,0.00000000,0.00000000,0.00000000,0.00000000,0.00000000
245.14000000,5.78409100,9.75600000,0.19375089,637.81380753,0.00000000,0.00000000,0.00000000,0.00000000,0.00000000,0.00000000,0.00000000,0.00000000,0.00000000,0.00000000,0.00000000
246.64000000,5.83540400,9.75500000,0.19562667,637.74843096,0.00000000,0.00000000,0.00000000,0.00000000,0.00000000,0.00000000,0.00000000,0.00000000,0.00000000,0.00000000,0.00000000
248.14000000,5.88705000,9.75400000,0.19739244,637.68305439,0.00000000,0.00000000,0.00000000,0.00000000,0.00000000,0.00000000,0.00000000,0.00000000,0.00000000,0.00000000,0.00000000
249.64000000,5.93929100,9.75300000,0.19930500,637.61767782,0.00000000,0.00000000,0.00000000,0.00000000,0.00000000,0.00000000,0.00000000,0.00000000,0.00000000,0.00000000,0.00000000
251.14000000,5.99199400,9.75300000,0.20121767,637.61767782,0.00000000,0.00000000,0.00000000,0.00000000,0.00000000,0.00000000,0.00000000,0.00000000,0.00000000,0.00000000,0.00000000
252.64000000,6.04502700,9.75200000,0.20316700,637.55230126,0.00000000,0.00000000,0.00000000,0.00000000,0.00000000,0.00000000,0.00000000,0.00000000,0.00000000,0.00000000,0.00000000
254.14000000,6.09796300,9.75000000,0.20504300,637.42154812,0.00000000,0.00000000,0.00000000,0.00000000,0.00000000,0.00000000,0.00000000,0.00000000,0.00000000,0.00000000,0.00000000
255.64000000,6.15113100,9.74800000,0.20699222,637.29079498,0.00000000,0.00000000,0.00000000,0.00000000,0.00000000,0.00000000,0.00000000,0.00000000,0.00000000,0.00000000,0.00000000
257.14000000,6.20479500,9.74800000,0.20894178,637.29079498,0.00000000,0.00000000,0.00000000,0.00000000,0.00000000,0.00000000,0.00000000,0.00000000,0.00000000,0.00000000,0.00000000
258.64000000,6.25888900,9.74600000,0.21092778,637.16004184,0.00000000,0.00000000,0.00000000,0.00000000,0.00000000,0.00000000,0.00000000,0.00000000,0.00000000,0.00000000,0.00000000
260.14000000,6.31261700,9.74300000,0.21291422,636.96391213,0.00000000,0.00000000,0.00000000,0.00000000,0.00000000,0.00000000,0.00000000,0.00000000,0.00000000,0.00000000,0.00000000
261.64000000,6.36694200,9.74200000,0.21490022,636.89853556,0.00000000,0.00000000,0.00000000,0.00000000,0.00000000,0.00000000,0.00000000,0.00000000,0.00000000,0.00000000,0.00000000
263.14000000,6.42206200,9.74000000,0.21688656,636.76778243,0.00000000,0.00000000,0.00000000,0.00000000,0.00000000,0.00000000,0.00000000,0.00000000,0.00000000,0.00000000,0.00000000
264.64000000,6.47748100,9.73800000,0.21894611,636.63702929,0.00000000,0.00000000,0.00000000,0.00000000,0.00000000,0.00000000,0.00000000,0.00000000,0.00000000,0.00000000,0.00000000
266.14000000,6.53276500,9.73400000,0.22096922,636.37552301,0.00000000,0.00000000,0.00000000,0.00000000,0.00000000,0.00000000,0.00000000,0.00000000,0.00000000,0.00000000,0.00000000
267.64000000,6.58768500,9.73200000,0.22306556,636.24476987,0.00000000,0.00000000,0.00000000,0.00000000,0.00000000,0.00000000,0.00000000,0.00000000,0.00000000,0.00000000,0.00000000
269.14000000,6.64293900,9.72900000,0.22512544,636.04864017,0.00000000,0.00000000,0.00000000,0.00000000,0.00000000,0.00000000,0.00000000,0.00000000,0.00000000,0.00000000,0.00000000
270.64000000,6.69888700,9.72600000,0.22722211,635.85251046,0.00000000,0.00000000,0.00000000,0.00000000,0.00000000,0.00000000,0.00000000,0.00000000,0.00000000,0.00000000,0.00000000
272.14000000,6.75566100,9.72300000,0.22928178,635.65638075,0.00000000,0.00000000,0.00000000,0.00000000,0.00000000,0.00000000,0.00000000,0.00000000,0.00000000,0.00000000,0.00000000
273.64000000,6.81180800,9.71900000,0.23141511,635.39487448,0.00000000,0.00000000,0.00000000,0.00000000,0.00000000,0.00000000,0.00000000,0.00000000,0.00000000,0.00000000,0.00000000
275.14000000,6.86848400,9.71500000,0.23351167,635.13336820,0.00000000,0.00000000,0.00000000,0.00000000,0.00000000,0.00000000,0.00000000,0.00000000,0.00000000,0.00000000,0.00000000
276.64000000,6.92582000,9.71200000,0.23560811,634.93723849,0.00000000,0.00000000,0.00000000,0.00000000,0.00000000,0.00000000,0.00000000,0.00000000,0.00000000,0.00000000,0.00000000
278.14000000,6.98282800,9.70600000,0.23774144,634.54497908,0.00000000,0.00000000,0.00000000,0.00000000,0.00000000,0.00000000,0.00000000,0.00000000,0.00000000,0.00000000,0.00000000
279.64000000,7.04023200,9.70200000,0.23980111,634.28347280,0.00000000,0.00000000,0.00000000,0.00000000,0.00000000,0.00000000,0.00000000,0.00000000,0.00000000,0.00000000,0.00000000
281.14000000,7.09800000,9.69700000,0.24186078,633.95658996,0.00000000,0.00000000,0.00000000,0.00000000,0.00000000,0.00000000,0.00000000,0.00000000,0.00000000,0.00000000,0.00000000
282.64000000,7.15580100,9.69100000,0.24392044,633.56433054,0.00000000,0.00000000,0.00000000,0.00000000,0.00000000,0.00000000,0.00000000,0.00000000,0.00000000,0.00000000,0.00000000
284.14000000,7.21419700,9.68400000,0.24594333,633.10669456,0.00000000,0.00000000,0.00000000,0.00000000,0.00000000,0.00000000,0.00000000,0.00000000,0.00000000,0.00000000,0.00000000
285.64000000,7.27236300,9.67800000,0.24792956,632.71443515,0.00000000,0.00000000,0.00000000,0.00000000,0.00000000,0.00000000,0.00000000,0.00000000,0.00000000,0.00000000,0.00000000
287.14000000,7.33142200,9.67100000,0.24980522,632.25679916,0.00000000,0.00000000,0.00000000,0.00000000,0.00000000,0.00000000,0.00000000,0.00000000,0.00000000,0.00000000,0.00000000
288.64000000,7.39041400,9.66200000,0.25168078,631.66841004,0.00000000,0.00000000,0.00000000,0.00000000,0.00000000,0.00000000,0.00000000,0.00000000,0.00000000,0.00000000,0.00000000
290.14000000,7.44934100,9.65300000,0.25348289,631.08002092,0.00000000,0.00000000,0.00000000,0.00000000,0.00000000,0.00000000,0.00000000,0.00000000,0.00000000,0.00000000,0.00000000
291.64000000,7.50879700,9.64300000,0.25517467,630.42625523,0.00000000,0.00000000,0.00000000,0.00000000,0.00000000,0.00000000,0.00000000,0.00000000,0.00000000,0.00000000,0.00000000
293.14000000,7.56792200,9.63200000,0.25671933,629.70711297,0.00000000,0.00000000,0.00000000,0.00000000,0.00000000,0.00000000,0.00000000,0.00000000,0.00000000,0.00000000,0.00000000
294.64000000,7.62840500,9.62000000,0.25822711,628.92259414,0.00000000,0.00000000,0.00000000,0.00000000,0.00000000,0.00000000,0.00000000,0.00000000,0.00000000,0.00000000,0.00000000
296.14000000,7.68921800,9.60800000,0.25955089,628.13807531,0.00000000,0.00000000,0.00000000,0.00000000,0.00000000,0.00000000,0.00000000,0.00000000,0.00000000,0.00000000,0.00000000
297.64000000,7.75009900,9.58900000,0.26080122,626.89592050,0.00000000,0.00000000,0.00000000,0.00000000,0.00000000,0.00000000,0.00000000,0.00000000,0.00000000,0.00000000,0.00000000
299.14000000,7.81055000,9.57300000,0.26183078,625.84989540,0.00000000,0.00000000,0.00000000,0.00000000,0.00000000,0.00000000,0.00000000,0.00000000,0.00000000,0.00000000,0.00000000
300.64000000,7.87126600,9.55300000,0.26271322,624.54236402,0.00000000,0.00000000,0.00000000,0.00000000,0.00000000,0.00000000,0.00000000,0.00000000,0.00000000,0.00000000,0.00000000
302.14000000,7.93231500,9.53300000,0.26355889,623.23483264,0.00000000,0.00000000,0.00000000,0.00000000,0.00000000,0.00000000,0.00000000,0.00000000,0.00000000,0.00000000,0.00000000
303.64000000,7.99382800,9.50900000,0.26425744,621.66579498,0.00000000,0.00000000,0.00000000,0.00000000,0.00000000,0.00000000,0.00000000,0.00000000,0.00000000,0.00000000,0.00000000
305.14000000,8.05573800,9.48600000,0.26480878,620.16213389,0.00000000,0.00000000,0.00000000,0.00000000,0.00000000,0.00000000,0.00000000,0.00000000,0.00000000,0.00000000,0.00000000
306.64000000,8.11742100,9.45500000,0.26524989,618.13546025,0.00000000,0.00000000,0.00000000,0.00000000,0.00000000,0.00000000,0.00000000,0.00000000,0.00000000,0.00000000,0.00000000
308.14000000,8.17973400,9.42900000,0.26558056,616.43566946,0.00000000,0.00000000,0.00000000,0.00000000,0.00000000,0.00000000,0.00000000,0.00000000,0.00000000,0.00000000,0.00000000
309.64000000,8.24201600,9.39400000,0.26587444,614.14748954,0.00000000,0.00000000,0.00000000,0.00000000,0.00000000,0.00000000,0.00000000,0.00000000,0.00000000,0.00000000,0.00000000
311.14000000,8.30420200,9.35900000,0.26605811,611.85930962,0.00000000,0.00000000,0.00000000,0.00000000,0.00000000,0.00000000,0.00000000,0.00000000,0.00000000,0.00000000,0.00000000
312.64000000,8.36649200,9.31800000,0.26613133,609.17887029,0.00000000,0.00000000,0.00000000,0.00000000,0.00000000,0.00000000,0.00000000,0.00000000,0.00000000,0.00000000,0.00000000
314.14000000,8.42925200,9.28200000,0.26627822,606.82531381,0.00000000,0.00000000,0.00000000,0.00000000,0.00000000,0.00000000,0.00000000,0.00000000,0.00000000,0.00000000,0.00000000
315.64000000,8.49278100,9.23000000,0.26631478,603.42573222,0.00000000,0.00000000,0.00000000,0.00000000,0.00000000,0.00000000,0.00000000,0.00000000,0.00000000,0.00000000,0.00000000
317.14000000,8.55638500,9.18400000,0.26635122,600.41841004,0.00000000,0.00000000,0.00000000,0.00000000,0.00000000,0.00000000,0.00000000,0.00000000,0.00000000,0.00000000,0.00000000
318.64000000,8.62006900,9.12000000,0.26631422,596.23430962,0.00000000,0.00000000,0.00000000,0.00000000,0.00000000,0.00000000,0.00000000,0.00000000,0.00000000,0.00000000,0.00000000
320.14000000,8.68399900,9.06300000,0.26635056,592.50784519,0.00000000,0.00000000,0.00000000,0.00000000,0.00000000,0.00000000,0.00000000,0.00000000,0.00000000,0.00000000,0.00000000
321.64000000,8.74881300,8.98200000,0.26631344,587.21234310,0.00000000,0.00000000,0.00000000,0.00000000,0.00000000,0.00000000,0.00000000,0.00000000,0.00000000,0.00000000,0.00000000
323.14000000,8.81414800,8.90000000,0.26623956,581.85146444,0.00000000,0.00000000,0.00000000,0.00000000,0.00000000,0.00000000,0.00000000,0.00000000,0.00000000,0.00000000,0.00000000
324.64000000,8.88077500,8.81200000,0.26616556,576.09832636,0.00000000,0.00000000,0.00000000,0.00000000,0.00000000,0.00000000,0.00000000,0.00000000,0.00000000,0.00000000,0.00000000
326.14000000,8.94905900,8.67800000,0.26616500,567.33786611,0.00000000,0.00000000,0.00000000,0.00000000,0.00000000,0.00000000,0.00000000,0.00000000,0.00000000,0.00000000,0.00000000
327.64000000,9.01993300,8.54800000,0.26605433,558.83891213,0.00000000,0.00000000,0.00000000,0.00000000,0.00000000,0.00000000,0.00000000,0.00000000,0.00000000,0.00000000,0.00000000
329.14000000,9.09512400,8.33900000,0.26590689,545.17520921,0.00000000,0.00000000,0.00000000,0.00000000,0.00000000,0.00000000,0.00000000,0.00000000,0.00000000,0.00000000,0.00000000
330.64000000,9.17993000,8.12200000,0.26572278,530.98849372,0.00000000,0.00000000,0.00000000,0.00000000,0.00000000,0.00000000,0.00000000,0.00000000,0.00000000,0.00000000,0.00000000
332.14000000,9.28438300,7.75500000,0.26546544,506.99529289,0.00000000,0.00000000,0.00000000,0.00000000,0.00000000,0.00000000,0.00000000,0.00000000,0.00000000,0.00000000,0.00000000