File: polyN_optimization/DP600_results/DATA/UT_45_3.csv
Time[s],Displacement[mm],Force[kN],EngStrain_longi,EngStress[MPa],TrueStrain,TrueStress[MPa],TrueStrainRate[1/s],PlasticStrain_longi,PlasticStress[MPa],PlasticStrain_thick,PlasticStrain_width,R-Value,Thickness[mm],Width[mm], Young's Modulus [MPa]
0.60000000,0.00000000,-0.01400000,0.00000000,-0.91767174,0.00000000,-0.91767174,0.00000000,0.00073158,355.60695691,0.00015227,-0.00088385,0.81929783,1.52560000,10.00000000,257892.07489679
1.60000000,0.00025700,-0.02100000,0.00002333,-1.37650760,0.00002333,-1.37653972,0.00006267,0.00102215,366.64011512,0.00016833,-0.00119047,0.00000000,0.00000000,0.00000000,0.00000000
2.60000000,0.00160800,0.21200000,0.00005467,13.89617200,0.00005467,13.89693166,0.00008866,0.00147962,375.76753675,-0.00006742,-0.00141220,0.00000000,0.00000000,0.00000000,0.00000000
3.60000000,0.00219100,0.43900000,0.00009056,28.77556371,0.00009055,28.77816950,0.00004022,0.00182178,383.34368187,-0.00023225,-0.00158954,0.00000000,0.00000000,0.00000000,0.00000000
4.60000000,0.00379100,0.62500000,0.00008200,40.96748820,0.00008200,40.97084754,-0.00000111,0.00224281,391.15422402,-0.00050486,-0.00173795,0.00000000,0.00000000,0.00000000,0.00000000
5.60000000,0.00439200,0.84500000,0.00012867,55.38804405,0.00012866,55.39517064,0.00000222,0.00279112,398.29694599,-0.00091546,-0.00187566,0.00000000,0.00000000,0.00000000,0.00000000
6.60000000,0.00689300,1.09700000,0.00020867,71.90613529,0.00020864,71.92113970,0.00014109,0.00331577,404.97611877,-0.00123822,-0.00207754,0.00000000,0.00000000,0.00000000,0.00000000
7.61000000,0.00682700,1.27500000,0.00020822,83.57367593,0.00020820,83.59107783,-0.00002222,0.00373985,411.22483032,-0.00143436,-0.00230549,0.00000000,0.00000000,0.00000000,0.00000000
8.60000000,0.00959900,1.50500000,0.00034944,98.64971159,0.00034938,98.68418418,0.00020261,0.00446200,417.14111773,-0.00184822,-0.00261379,0.00000000,0.00000000,0.00000000,0.00000000
9.60000000,0.01005100,1.73700000,0.00031111,113.85684321,0.00031106,113.89226534,-0.00004065,0.00487448,422.07507673,-0.00198970,-0.00288478,0.00000000,0.00000000,0.00000000,0.00000000
10.60000000,0.01219200,1.96700000,0.00042956,128.93287887,0.00042946,128.98826270,0.00006975,0.00550112,427.89905826,-0.00232926,-0.00317186,0.00000000,0.00000000,0.00000000,0.00000000
11.60000000,0.01383800,2.19800000,0.00041533,144.07446251,0.00041525,144.13430143,0.00008241,0.00610152,433.05687396,-0.00267556,-0.00342596,0.00000000,0.00000000,0.00000000,0.00000000
12.60000000,0.01452700,2.42600000,0.00047978,159.01940220,0.00047966,159.09569618,-0.00012927,0.00677795,437.52540284,-0.00309616,-0.00368178,0.00000000,0.00000000,0.00000000,0.00000000
13.60000000,0.01796500,2.65500000,0.00058733,174.02988988,0.00058716,174.13210343,0.00022077,0.00718638,442.27908196,-0.00328829,-0.00389808,0.00000000,0.00000000,0.00000000,0.00000000
14.61000000,0.01768900,2.85800000,0.00053533,187.33613005,0.00053519,187.43641732,-0.00011214,0.00799855,447.01862734,-0.00387795,-0.00412060,0.00000000,0.00000000,0.00000000,0.00000000
15.60000000,0.02130100,3.11200000,0.00074667,203.98531725,0.00074639,204.13762629,0.00023562,0.00848653,451.55265303,-0.00408076,-0.00440577,0.00000000,0.00000000,0.00000000,0.00000000
16.61000000,0.02206200,3.33700000,0.00066233,218.73361300,0.00066211,218.87848757,-0.00001263,0.00908471,455.94226133,-0.00433985,-0.00474485,0.00000000,0.00000000,0.00000000,0.00000000
17.61000000,0.02485000,3.53500000,0.00082311,231.71211327,0.00082277,231.90283808,-0.00003619,0.00971030,460.34979520,-0.00466158,-0.00504872,0.00000000,0.00000000,0.00000000,0.00000000
18.61000000,0.02737500,3.75500000,0.00086411,246.13266911,0.00086374,246.34535509,0.00024795,0.01048982,464.30229115,-0.00508037,-0.00540945,0.00000000,0.00000000,0.00000000,0.00000000
19.60000000,0.02902800,3.97300000,0.00087856,260.42212900,0.00087817,260.65092431,-0.00025887,0.01092202,468.83005744,-0.00520006,-0.00572196,0.00000000,0.00000000,0.00000000,0.00000000
20.60000000,0.03241900,4.18900000,0.00113589,274.58049292,0.00113524,274.89238585,0.00047751,0.01167833,472.98269787,-0.00565530,-0.00602303,0.00000000,0.00000000,0.00000000,0.00000000
21.60000000,0.03632800,4.40100000,0.00104778,288.47666492,0.00104723,288.77892436,-0.00013896,0.01230304,476.54529595,-0.00599177,-0.00631128,0.00000000,0.00000000,0.00000000,0.00000000
22.60000000,0.04035000,4.60700000,0.00143122,301.97954903,0.00143020,302.41174887,0.00032423,0.01295817,480.46045457,-0.00640853,-0.00654963,0.00000000,0.00000000,0.00000000,0.00000000
23.60000000,0.04597300,4.78500000,0.00140700,313.64708967,0.00140601,314.08839112,0.00017754,0.01350925,484.19668244,-0.00668937,-0.00681988,0.00000000,0.00000000,0.00000000,0.00000000
24.60000000,0.05274300,4.99600000,0.00172344,327.47771369,0.00172196,328.04210333,-0.00000776,0.01429507,487.98503116,-0.00721491,-0.00708015,0.00000000,0.00000000,0.00000000,0.00000000
25.60000000,0.05950500,5.17400000,0.00204000,339.14525433,0.00203792,339.83711064,0.00066853,0.01487146,491.60910910,-0.00748256,-0.00738890,0.00000000,0.00000000,0.00000000,0.00000000
26.60000000,0.06895600,5.32400000,0.00214756,348.97745149,0.00214525,349.72689996,-0.00016763,0.01554483,495.28547007,-0.00780625,-0.00773857,0.00000000,0.00000000,0.00000000,0.00000000
27.60000000,0.08064200,5.48000000,0.00272333,359.20293655,0.00271963,360.18116588,0.00060140,0.01619902,498.42161405,-0.00812546,-0.00807356,0.00000000,0.00000000,0.00000000,0.00000000
28.60000000,0.09130200,5.62400000,0.00295000,368.64184583,0.00294566,369.72933928,0.00035521,0.01692807,502.26924637,-0.00850686,-0.00842122,0.00000000,0.00000000,0.00000000,0.00000000
29.60000000,0.10460100,5.75700000,0.00343678,377.35972732,0.00343089,378.65662885,0.00032380,0.01750438,505.57568376,-0.00876164,-0.00874273,0.00000000,0.00000000,0.00000000,0.00000000
30.60000000,0.11815800,5.88000000,0.00388200,385.42212900,0.00387448,386.91833770,0.00045451,0.01820406,508.54635262,-0.00919431,-0.00900975,0.00000000,0.00000000,0.00000000,0.00000000
31.60000000,0.13357100,5.99100000,0.00446333,392.69795490,0.00445340,394.45069678,0.00069590,0.01890552,511.79042973,-0.00957329,-0.00933223,0.00000000,0.00000000,0.00000000,0.00000000
32.60000000,0.15097200,6.08200000,0.00483489,398.66282119,0.00482324,400.59031163,0.00027093,0.01954215,515.00543891,-0.00995522,-0.00958693,0.00000000,0.00000000,0.00000000,0.00000000
33.60000000,0.16672100,6.18700000,0.00564067,405.54535920,0.00562482,407.83290539,0.00076119,0.02020304,518.16981821,-0.01032017,-0.00988287,0.00000000,0.00000000,0.00000000,0.00000000
34.60000000,0.18395400,6.27600000,0.00603111,411.37912952,0.00601300,413.86020276,0.00062986,0.02092873,521.23758626,-0.01076789,-0.01016085,0.00000000,0.00000000,0.00000000,0.00000000
35.60000000,0.20185100,6.35000000,0.00664944,416.22968013,0.00662743,418.99737626,0.00035810,0.02158991,524.20840215,-0.01114469,-0.01044522,0.00000000,0.00000000,0.00000000,0.00000000
36.60000000,0.21900900,6.42800000,0.00729100,421.34242265,0.00726455,424.41443026,0.00076038,0.02229071,526.93449266,-0.01153540,-0.01075531,0.00000000,0.00000000,0.00000000,0.00000000
37.60000000,0.23785400,6.50400000,0.00796556,426.32406922,0.00793400,429.71997728,0.00079053,0.02298950,530.06761996,-0.01193458,-0.01105492,0.00000000,0.00000000,0.00000000,0.00000000
38.60000000,0.25755900,6.57700000,0.00841867,431.10907184,0.00838343,434.73843541,0.00043946,0.02370642,533.01227268,-0.01234895,-0.01135747,0.00000000,0.00000000,0.00000000,0.00000000
39.60000000,0.27610400,6.64600000,0.00921733,435.63188254,0.00917511,439.64724681,0.00062743,0.02440714,535.54717960,-0.01271831,-0.01168883,0.00000000,0.00000000,0.00000000,0.00000000
40.60000000,0.29487800,6.71500000,0.00978122,440.15469324,0.00973370,444.45994410,0.00088245,0.02507327,538.33701713,-0.01304040,-0.01203288,0.00000000,0.00000000,0.00000000,0.00000000
41.60000000,0.31444900,6.77300000,0.01036278,443.95647614,0.01030945,448.55709845,0.00036448,0.02580766,541.03221806,-0.01341584,-0.01239182,0.00000000,0.00000000,0.00000000,0.00000000
42.60000000,0.33378600,6.84400000,0.01106533,448.61038280,0.01100456,453.57440622,0.00073555,0.02650229,543.70948462,-0.01377435,-0.01272794,0.00000000,0.00000000,0.00000000,0.00000000
43.60000000,0.35180800,6.90600000,0.01175311,452.67435763,0.01168458,457.99468965,0.00085744,0.02721468,546.33230518,-0.01417014,-0.01304454,0.00000000,0.00000000,0.00000000,0.00000000
44.60000000,0.37220700,6.96000000,0.01227833,456.21394861,0.01220357,461.81549554,0.00060225,0.02789128,548.87119494,-0.01454570,-0.01334559,0.00000000,0.00000000,0.00000000,0.00000000
45.60000000,0.39224500,7.02000000,0.01300233,460.14682748,0.01291853,466.12980991,0.00043550,0.02864677,551.25352388,-0.01501955,-0.01362722,0.00000000,0.00000000,0.00000000,0.00000000
46.60000000,0.41148800,7.07800000,0.01371944,463.94861038,0.01362618,470.31372757,0.00094328,0.02931451,553.92975871,-0.01534859,-0.01396592,0.00000000,0.00000000,0.00000000,0.00000000
47.60000000,0.43212000,7.13400000,0.01430378,467.61929733,0.01420244,474.30801984,0.00054363,0.03005760,556.37981741,-0.01582688,-0.01423071,0.00000000,0.00000000,0.00000000,0.00000000
48.60000000,0.45265600,7.18900000,0.01497678,471.22443629,0.01486573,478.28185995,0.00058685,0.03076249,558.60799694,-0.01620667,-0.01455581,0.00000000,0.00000000,0.00000000,0.00000000
49.60000000,0.47225600,7.24200000,0.01570133,474.69847929,0.01557934,482.15187834,0.00066654,0.03153271,561.07986040,-0.01668872,-0.01484399,0.00000000,0.00000000,0.00000000,0.00000000
50.60000000,0.49258500,7.28800000,0.01636767,477.71368642,0.01623516,485.53274480,0.00084042,0.03221489,563.43744848,-0.01704013,-0.01517475,0.00000000,0.00000000,0.00000000,0.00000000
51.60000000,0.51328000,7.34400000,0.01697122,481.38437336,0.01682882,489.55405454,0.00042003,0.03296020,565.76575382,-0.01748694,-0.01547326,0.00000000,0.00000000,0.00000000,0.00000000
52.60000000,0.53366800,7.39400000,0.01777767,484.66177242,0.01762149,493.27792785,0.00081807,0.03368045,568.01483779,-0.01785754,-0.01582292,0.00000000,0.00000000,0.00000000,0.00000000
53.60000000,0.55393000,7.43800000,0.01841056,487.54588359,0.01824313,496.52187416,0.00067961,0.03444928,570.29468897,-0.01828793,-0.01616135,0.00000000,0.00000000,0.00000000,0.00000000
54.60000000,0.57561300,7.48500000,0.01909944,490.62663870,0.01891934,499.99733493,0.00069376,0.03511359,572.24470687,-0.01860563,-0.01650795,0.00000000,0.00000000,0.00000000,0.00000000
55.60000000,0.59630300,7.53100000,0.01979100,493.64184583,0.01959770,503.41151160,0.00055575,0.03589159,574.67246348,-0.01906904,-0.01682255,0.00000000,0.00000000,0.00000000,0.00000000
56.60000000,0.61679700,7.57600000,0.02053433,496.59150498,0.02032635,506.78868048,0.00082893,0.03660292,576.86002847,-0.01942075,-0.01718217,0.00000000,0.00000000,0.00000000,0.00000000
57.60000000,0.63795100,7.62000000,0.02115267,499.47561615,0.02093205,510.04085737,0.00061269,0.03735728,578.80176746,-0.01979622,-0.01756106,0.00000000,0.00000000,0.00000000,0.00000000
58.60000000,0.65947400,7.66300000,0.02191067,502.29417934,0.02167408,513.29977967,0.00066292,0.03805412,580.84958831,-0.02014928,-0.01790484,0.00000000,0.00000000,0.00000000,0.00000000
59.60000000,0.68106000,7.70000000,0.02262811,504.71945464,0.02237589,516.14030254,0.00076267,0.03886270,583.03385711,-0.02062106,-0.01824164,0.00000000,0.00000000,0.00000000,0.00000000
60.60000000,0.70248300,7.74600000,0.02333744,507.73466177,0.02306929,519.58389123,0.00079755,0.03954432,585.07825345,-0.02091911,-0.01862521,0.00000000,0.00000000,0.00000000,0.00000000
61.60000000,0.72443500,7.78600000,0.02399622,510.35658102,0.02371284,522.60321095,0.00060404,0.04031354,587.10816125,-0.02134982,-0.01896372,0.00000000,0.00000000,0.00000000,0.00000000
62.60000000,0.74598900,7.82000000,0.02478633,512.58521238,0.02448414,525.29032031,0.00079599,0.04106169,589.12842876,-0.02178959,-0.01927210,0.00000000,0.00000000,0.00000000,0.00000000
63.60000000,0.76757500,7.85800000,0.02548133,515.07603566,0.02516210,528.20085981,0.00072434,0.04183714,590.96141479,-0.02221684,-0.01962030,0.00000000,0.00000000,0.00000000,0.00000000
64.60000000,0.78946200,7.89600000,0.02620578,517.56685894,0.02586829,531.13010103,0.00070932,0.04254861,593.03402897,-0.02262230,-0.01992631,0.00000000,0.00000000,0.00000000,0.00000000
65.60000000,0.81178000,7.93300000,0.02691922,519.99213424,0.02656327,533.98991806,0.00063739,0.04331565,595.00481728,-0.02304303,-0.02027262,0.00000000,0.00000000,0.00000000,0.00000000
66.60000000,0.83376300,7.96900000,0.02769511,522.35186156,0.02731854,536.81845441,0.00072235,0.04406234,596.75945778,-0.02346011,-0.02060222,0.00000000,0.00000000,0.00000000,0.00000000
67.60000000,0.85588100,8.00400000,0.02838656,524.64604090,0.02799112,539.53893489,0.00070868,0.04481466,598.58874773,-0.02386206,-0.02095261,0.00000000,0.00000000,0.00000000,0.00000000
68.60000000,0.87822600,8.03400000,0.02915100,526.61248034,0.02873419,541.96376075,0.00070038,0.04551457,600.38892187,-0.02420346,-0.02131111,0.00000000,0.00000000,0.00000000,0.00000000
69.60000000,0.90041000,8.07100000,0.02990133,529.03775564,0.02946300,544.85668991,0.00074325,0.04634613,602.33991348,-0.02469671,-0.02164942,0.00000000,0.00000000,0.00000000,0.00000000
70.60000000,0.92256000,8.10400000,0.03064367,531.20083901,0.03018353,547.47878046,0.00073452,0.04707591,604.16299155,-0.02501991,-0.02205600,0.00000000,0.00000000,0.00000000,0.00000000
71.60000000,0.94536900,8.13300000,0.03138689,533.10173047,0.03090439,549.83413525,0.00079887,0.04784326,606.01127367,-0.02548414,-0.02235911,0.00000000,0.00000000,0.00000000,0.00000000
72.60000000,0.96745100,8.16400000,0.03211133,535.13371788,0.03160654,552.31757507,0.00066951,0.04860857,607.58397891,-0.02588306,-0.02272551,0.00000000,0.00000000,0.00000000,0.00000000
73.60000000,0.98993600,8.19600000,0.03289122,537.23125328,0.03236188,554.90144581,0.00081923,0.04940234,609.52248587,-0.02630149,-0.02310085,0.00000000,0.00000000,0.00000000,0.00000000
74.60000000,1.01290800,8.22600000,0.03362289,539.19769271,0.03307000,557.32707682,0.00072595,0.05011691,611.20719761,-0.02668473,-0.02343218,0.00000000,0.00000000,0.00000000,0.00000000
75.60000000,1.03604900,8.25600000,0.03439200,541.16413214,0.03381381,559.77584898,0.00078258,0.05088683,612.78930965,-0.02708514,-0.02380169,0.00000000,0.00000000,0.00000000,0.00000000
76.60000000,1.05889300,8.28400000,0.03513867,542.99947562,0.03453540,562.07975319,0.00066175,0.05168369,614.52898361,-0.02752636,-0.02415733,0.00000000,0.00000000,0.00000000,0.00000000
77.60000000,1.08157200,8.31000000,0.03592233,544.70372313,0.03529217,564.27075184,0.00078850,0.05246577,616.19244144,-0.02796943,-0.02449634,0.00000000,0.00000000,0.00000000,0.00000000
78.60000000,1.10477800,8.34100000,0.03667989,546.73571054,0.03602319,566.78991565,0.00073775,0.05320907,617.90366451,-0.02835783,-0.02485124,0.00000000,0.00000000,0.00000000,0.00000000
79.60000000,1.12782100,8.36800000,0.03743011,548.50550603,0.03674661,569.03612807,0.00072264,0.05398689,619.49938332,-0.02880315,-0.02518375,0.00000000,0.00000000,0.00000000,0.00000000
80.60000000,1.15083100,8.39200000,0.03820644,550.07865758,0.03749465,571.09520725,0.00065937,0.05477422,621.17280301,-0.02926550,-0.02550872,0.00000000,0.00000000,0.00000000,0.00000000
81.60000000,1.17377800,8.41800000,0.03897933,551.78290509,0.03823882,573.29103487,0.00080052,0.05553453,622.55281542,-0.02967897,-0.02585556,0.00000000,0.00000000,0.00000000,0.00000000
82.60000000,1.19687900,8.44400000,0.03974411,553.48715260,0.03897464,575.48500749,0.00069303,0.05629613,624.35393285,-0.03012629,-0.02616984,0.00000000,0.00000000,0.00000000,0.00000000
83.60000000,1.22055200,8.46900000,0.04053156,555.12585212,0.03973169,577.62596644,0.00076364,0.05711333,625.91311682,-0.03057371,-0.02653962,0.00000000,0.00000000,0.00000000,0.00000000
84.60000000,1.24365900,8.49400000,0.04128567,556.76455165,0.04045617,579.75094734,0.00068538,0.05787847,627.37182346,-0.03100170,-0.02687677,0.00000000,0.00000000,0.00000000,0.00000000
85.60000000,1.26686600,8.51800000,0.04208744,558.33770320,0.04122586,581.83671026,0.00081157,0.05864600,628.90385322,-0.03143676,-0.02720924,0.00000000,0.00000000,0.00000000,0.00000000
86.60000000,1.29079800,8.54000000,0.04286389,559.77975878,0.04197067,583.77409617,0.00066324,0.05942001,630.44197798,-0.03185281,-0.02756720,0.00000000,0.00000000,0.00000000,0.00000000
87.60000000,1.31480300,8.56600000,0.04368022,561.48400629,0.04275314,586.00975246,0.00084548,0.06023857,631.87029574,-0.03231896,-0.02791962,0.00000000,0.00000000,0.00000000,0.00000000
88.60000000,1.33834400,8.58900000,0.04444211,562.99160986,0.04348288,588.01214554,0.00074716,0.06097671,633.38964511,-0.03271773,-0.02825898,0.00000000,0.00000000,0.00000000,0.00000000
89.60000000,1.36191400,8.60900000,0.04523289,564.30256948,0.04423972,589.82760491,0.00074532,0.06178024,634.88241007,-0.03313584,-0.02864440,0.00000000,0.00000000,0.00000000,0.00000000
90.60000000,1.38588300,8.63200000,0.04604611,565.81017305,0.04501745,591.86353114,0.00073242,0.06255221,636.28683931,-0.03355830,-0.02899391,0.00000000,0.00000000,0.00000000,0.00000000
91.60000000,1.41024700,8.65400000,0.04684044,567.25222863,0.04577653,593.82257513,0.00080788,0.06338568,637.66215332,-0.03400166,-0.02938401,0.00000000,0.00000000,0.00000000,0.00000000
92.60000000,1.43391900,8.67500000,0.04761278,568.62873623,0.04651403,595.70272989,0.00073005,0.06411184,639.04086844,-0.03440952,-0.02970232,0.00000000,0.00000000,0.00000000,0.00000000
93.60000000,1.45768800,8.69600000,0.04841867,570.00524384,0.04728300,597.60413774,0.00075790,0.06495068,640.49365587,-0.03487585,-0.03007483,0.00000000,0.00000000,0.00000000,0.00000000
94.60000000,1.48152400,8.71600000,0.04920578,571.31620346,0.04803348,599.42826161,0.00073678,0.06569976,641.89065820,-0.03527319,-0.03042658,0.00000000,0.00000000,0.00000000,0.00000000
95.60000000,1.50586000,8.73400000,0.05002244,572.49606712,0.04881154,601.13371983,0.00087594,0.06652688,643.41025275,-0.03573071,-0.03079617,0.00000000,0.00000000,0.00000000,0.00000000
96.60000000,1.53065700,8.75700000,0.05081333,574.00367069,0.04956447,603.17071054,0.00070011,0.06725720,644.79878629,-0.03611223,-0.03114497,0.00000000,0.00000000,0.00000000,0.00000000
97.60000000,1.55459300,8.77700000,0.05162644,575.31463031,0.05033796,605.01607911,0.00077017,0.06814507,646.14994232,-0.03664079,-0.03150428,0.00000000,0.00000000,0.00000000,0.00000000
98.60000000,1.57909400,8.79400000,0.05245356,576.42894599,0.05112416,606.66469373,0.00079027,0.06888469,647.54803985,-0.03701426,-0.03187043,0.00000000,0.00000000,0.00000000,0.00000000
99.60000000,1.60375400,8.81300000,0.05326289,577.67435763,0.05189286,608.44296275,0.00078206,0.06970323,648.78710237,-0.03746733,-0.03223591,0.00000000,0.00000000,0.00000000,0.00000000
100.60000000,1.62805600,8.83100000,0.05405000,578.85422129,0.05263989,610.14129195,0.00067012,0.07045271,650.12427682,-0.03787983,-0.03257288,0.00000000,0.00000000,0.00000000,0.00000000
101.60000000,1.65219100,8.84900000,0.05488511,580.03408495,0.05343186,611.86932015,0.00080889,0.07130341,651.52925983,-0.03837997,-0.03292344,0.00000000,0.00000000,0.00000000,0.00000000
102.60000000,1.67665800,8.86600000,0.05569411,581.14840063,0.05419848,613.51494423,0.00078721,0.07205137,652.79801129,-0.03873129,-0.03332008,0.00000000,0.00000000,0.00000000,0.00000000
103.60000000,1.70151800,8.88500000,0.05649256,582.39381227,0.05495451,615.29472707,0.00068898,0.07289106,654.12849246,-0.03924248,-0.03364858,0.00000000,0.00000000,0.00000000,0.00000000
104.60000000,1.72658100,8.90000000,0.05734578,583.37703199,0.05576178,616.83124162,0.00072354,0.07367197,655.42211749,-0.03966182,-0.03401015,0.00000000,0.00000000,0.00000000,0.00000000
105.60000000,1.75098300,8.91900000,0.05819167,584.62244363,0.05656148,618.64259799,0.00082002,0.07452382,656.69305454,-0.04014077,-0.03438305,0.00000000,0.00000000,0.00000000,0.00000000
106.60000000,1.77544700,8.93500000,0.05896078,585.67121133,0.05728803,620.20284147,0.00070228,0.07530027,657.91593544,-0.04059421,-0.03470607,0.00000000,0.00000000,0.00000000,0.00000000
107.60000000,1.80060500,8.95000000,0.05982122,586.65443104,0.05810024,621.74881613,0.00073611,0.07611050,659.16265892,-0.04099080,-0.03511969,0.00000000,0.00000000,0.00000000,0.00000000
108.60000000,1.82553600,8.96600000,0.06065256,587.70319874,0.05888434,623.34889965,0.00077053,0.07690942,660.40349589,-0.04145358,-0.03545583,0.00000000,0.00000000,0.00000000,0.00000000
109.60000000,1.85020000,8.98200000,0.06152044,588.75196644,0.05970226,624.97224908,0.00086603,0.07773768,661.73668417,-0.04192775,-0.03580994,0.00000000,0.00000000,0.00000000,0.00000000
110.60000000,1.87546000,8.99800000,0.06229656,589.80073414,0.06043313,626.54328834,0.00067852,0.07851561,662.89545330,-0.04234485,-0.03617076,0.00000000,0.00000000,0.00000000,0.00000000
111.60000000,1.90032100,9.01300000,0.06318311,590.78395385,0.06126734,628.11152205,0.00080278,0.07933993,664.08654730,-0.04282926,-0.03651067,0.00000000,0.00000000,0.00000000,0.00000000
112.60000000,1.92558100,9.02700000,0.06399189,591.70162559,0.06202777,629.56573027,0.00077397,0.08015367,665.27210741,-0.04323072,-0.03692295,0.00000000,0.00000000,0.00000000,0.00000000
113.60000000,1.95047700,9.04000000,0.06483778,592.55374934,0.06282247,630.97361767,0.00080070,0.08096956,666.53213031,-0.04368691,-0.03728265,0.00000000,0.00000000,0.00000000,0.00000000
114.60000000,1.97560300,9.05600000,0.06566567,593.60251704,0.06359964,632.58182206,0.00070433,0.08177157,667.71290039,-0.04414203,-0.03762954,0.00000000,0.00000000,0.00000000,0.00000000
115.60000000,2.00053300,9.07000000,0.06655589,594.52018878,0.06443466,634.08900840,0.00088362,0.08260007,668.91292047,-0.04457387,-0.03802620,0.00000000,0.00000000,0.00000000,0.00000000
116.60000000,2.02585700,9.08300000,0.06735756,595.37231253,0.06518602,635.47513615,0.00076507,0.08342126,670.10957438,-0.04507012,-0.03835114,0.00000000,0.00000000,0.00000000,0.00000000
117.60000000,2.05161100,9.09700000,0.06818511,596.28998427,0.06596105,636.94808310,0.00075781,0.08425240,671.17091321,-0.04550780,-0.03874459,0.00000000,0.00000000,0.00000000,0.00000000
118.60000000,2.07727300,9.11000000,0.06906056,597.14210802,0.06678028,638.38107375,0.00071623,0.08507201,672.36944549,-0.04596477,-0.03910724,0.00000000,0.00000000,0.00000000,0.00000000
119.60000000,2.10243100,9.12300000,0.06994689,597.99423178,0.06760901,639.82206786,0.00090825,0.08589786,673.50183419,-0.04646257,-0.03943529,0.00000000,0.00000000,0.00000000,0.00000000
120.60000000,2.12789000,9.13800000,0.07073767,598.97745149,0.06834782,641.34771880,0.00069435,0.08672710,674.56599390,-0.04687606,-0.03985104,0.00000000,0.00000000,0.00000000,0.00000000
121.60000000,2.15377700,9.14700000,0.07162378,599.56738332,0.06917505,642.51066435,0.00083733,0.08751454,675.67513634,-0.04731352,-0.04020102,0.00000000,0.00000000,0.00000000,0.00000000
122.60000000,2.17940000,9.16000000,0.07248467,600.41950708,0.06997807,643.94071491,0.00077468,0.08841231,676.86053512,-0.04782980,-0.04058251,0.00000000,0.00000000,0.00000000,0.00000000
123.60000000,2.20479000,9.17300000,0.07333778,601.27163083,0.07077321,645.36755608,0.00089109,0.08919884,677.89973499,-0.04825081,-0.04094803,0.00000000,0.00000000,0.00000000,0.00000000
124.60000000,2.23080800,9.18600000,0.07419100,602.12375459,0.07156782,646.79591807,0.00069170,0.09005194,678.98550099,-0.04877089,-0.04128105,0.00000000,0.00000000,0.00000000,0.00000000
125.60000000,2.25613200,9.19600000,0.07506644,602.77923440,0.07238247,648.02772831,0.00082844,0.09083393,680.02412670,-0.04912450,-0.04170943,0.00000000,0.00000000,0.00000000,0.00000000
126.60000000,2.28209000,9.20900000,0.07593433,603.63135815,0.07318943,649.46770291,0.00079347,0.09169236,681.11619691,-0.04964479,-0.04204757,0.00000000,0.00000000,0.00000000,0.00000000
127.60000000,2.30810800,9.22000000,0.07675822,604.35238595,0.07395488,650.74140069,0.00081269,0.09252594,682.26501965,-0.05013661,-0.04238933,0.00000000,0.00000000,0.00000000,0.00000000
128.60000000,2.33400000,9.23100000,0.07761556,605.07341374,0.07475078,652.03652290,0.00068971,0.09335614,683.34054558,-0.05054624,-0.04280990,0.00000000,0.00000000,0.00000000,0.00000000
129.60000000,2.36002000,9.24300000,0.07849067,605.85998951,0.07556253,653.41434400,0.00080520,0.09418544,684.41677749,-0.05101958,-0.04316585,0.00000000,0.00000000,0.00000000,0.00000000
130.60000000,2.38647000,9.25400000,0.07938456,606.58101730,0.07639102,654.73418177,0.00077013,0.09504153,685.36764781,-0.05147829,-0.04356324,0.00000000,0.00000000,0.00000000,0.00000000
131.60000000,2.41262400,9.26300000,0.08027100,607.17094913,0.07721194,655.90916839,0.00083783,0.09586279,686.44090147,-0.05192427,-0.04393852,0.00000000,0.00000000,0.00000000,0.00000000
132.60000000,2.43894200,9.27500000,0.08119411,607.95752491,0.07806609,657.32009574,0.00083032,0.09669669,687.52418565,-0.05239543,-0.04430126,0.00000000,0.00000000,0.00000000,0.00000000
133.60000000,2.46512700,9.28500000,0.08202867,608.61300472,0.07883767,658.53671801,0.00080893,0.09751331,688.52413071,-0.05279533,-0.04471798,0.00000000,0.00000000,0.00000000,0.00000000
134.60000000,2.49131400,9.29400000,0.08289333,609.20293655,0.07963647,659.70179864,0.00077421,0.09837637,689.55738863,-0.05331426,-0.04506211,0.00000000,0.00000000,0.00000000,0.00000000
135.60000000,2.51763500,9.30400000,0.08376489,609.85841636,0.08044099,660.94313885,0.00077359,0.09922783,690.65675450,-0.05377024,-0.04545760,0.00000000,0.00000000,0.00000000,0.00000000
136.60000000,2.54388400,9.31400000,0.08468422,610.51389617,0.08128891,662.21479063,0.00080019,0.10003311,691.57960209,-0.05419231,-0.04584080,0.00000000,0.00000000,0.00000000,0.00000000
137.60000000,2.57089800,9.32400000,0.08553056,611.16937598,0.08206886,663.44303225,0.00079322,0.10089357,692.61481966,-0.05467598,-0.04621758,0.00000000,0.00000000,0.00000000,0.00000000
138.60000000,2.59734900,9.33300000,0.08646067,611.75930781,0.08292532,664.65242541,0.00084615,0.10170426,693.54364086,-0.05511892,-0.04658534,0.00000000,0.00000000,0.00000000,0.00000000
139.60000000,2.62386300,9.34200000,0.08731800,612.34923964,0.08371411,665.81835055,0.00078496,0.10259967,694.53254418,-0.05562495,-0.04697471,0.00000000,0.00000000,0.00000000,0.00000000
140.60000000,2.65011600,9.35100000,0.08824833,612.93917147,0.08456937,667.03003179,0.00085170,0.10339846,695.52842840,-0.05609161,-0.04730686,0.00000000,0.00000000,0.00000000,0.00000000
141.60000000,2.67719500,9.36100000,0.08913122,613.59465128,0.08538033,668.28509250,0.00085836,0.10426613,696.57359795,-0.05656515,-0.04770098,0.00000000,0.00000000,0.00000000,0.00000000
142.60000000,2.70440700,9.37000000,0.09004322,614.18458311,0.08621735,669.48774202,0.00086396,0.10509681,697.52088432,-0.05702288,-0.04807393,0.00000000,0.00000000,0.00000000,0.00000000
143.60000000,2.73155700,9.37800000,0.09091867,614.70896696,0.08702015,670.59748663,0.00081579,0.10593672,698.47573812,-0.05749753,-0.04843918,0.00000000,0.00000000,0.00000000,0.00000000
144.60000000,2.75800700,9.38700000,0.09187878,615.29889879,0.08789986,671.83180958,0.00090283,0.10674308,699.40816754,-0.05793613,-0.04880694,0.00000000,0.00000000,0.00000000,0.00000000
145.60000000,2.78515200,9.39400000,0.09270267,615.75773466,0.08865414,672.84011869,0.00076075,0.10764368,700.48136357,-0.05846729,-0.04917639,0.00000000,0.00000000,0.00000000,0.00000000
146.60000000,2.81196600,9.40200000,0.09363667,616.28211851,0.08950853,673.98872181,0.00080705,0.10844864,701.41507342,-0.05887255,-0.04957609,0.00000000,0.00000000,0.00000000,0.00000000
147.60000000,2.83897900,9.41000000,0.09452689,616.80650236,0.09032220,675.11130207,0.00076577,0.10933512,702.33367569,-0.05939071,-0.04994441,0.00000000,0.00000000,0.00000000,0.00000000
148.60000000,2.86589300,9.41800000,0.09550911,617.33088621,0.09121920,676.29161041,0.00097432,0.11020696,703.39038472,-0.05987687,-0.05033009,0.00000000,0.00000000,0.00000000,0.00000000
149.60000000,2.89284100,9.42600000,0.09637722,617.85527006,0.09201131,677.40244472,0.00075171,0.11104623,704.27791420,-0.06030620,-0.05074003,0.00000000,0.00000000,0.00000000,0.00000000
150.60000000,2.92018600,9.43400000,0.09728911,618.37965391,0.09284269,678.54126076,0.00083151,0.11186831,705.15427894,-0.06077539,-0.05109292,0.00000000,0.00000000,0.00000000,0.00000000
151.60000000,2.94736500,9.44100000,0.09819789,618.83848977,0.09367055,679.60712303,0.00077070,0.11274522,706.07045650,-0.06123353,-0.05151169,0.00000000,0.00000000,0.00000000,0.00000000
152.60000000,2.97487500,9.44800000,0.09915411,619.29732564,0.09454089,680.70320148,0.00093751,0.11357584,706.95486763,-0.06168932,-0.05188651,0.00000000,0.00000000,0.00000000,0.00000000
153.60000000,3.00195600,9.45500000,0.10004033,619.75616151,0.09534685,681.75677449,0.00082216,0.11444123,707.93896172,-0.06217122,-0.05227001,0.00000000,0.00000000,0.00000000,0.00000000
154.60000000,3.02956300,9.46200000,0.10093422,620.21499738,0.09615911,682.81591575,0.00076859,0.11530622,708.84988938,-0.06263136,-0.05267486,0.00000000,0.00000000,0.00000000,0.00000000
155.60000000,3.05651000,9.46900000,0.10192744,620.67383325,0.09706087,683.93753090,0.00090145,0.11617025,709.76119018,-0.06311735,-0.05305290,0.00000000,0.00000000,0.00000000,0.00000000
156.60000000,3.08425100,9.47500000,0.10278811,621.06712113,0.09784162,684.90543739,0.00079410,0.11704380,710.60613771,-0.06357859,-0.05346520,0.00000000,0.00000000,0.00000000,0.00000000
157.60000000,3.11199700,9.48200000,0.10374456,621.52595700,0.09870854,686.00589118,0.00080671,0.11788350,711.57636625,-0.06401985,-0.05386365,0.00000000,0.00000000,0.00000000,0.00000000
158.60000000,3.13910800,9.48800000,0.10465678,621.91924489,0.09953468,687.00730910,0.00080624,0.11878120,712.44056929,-0.06454134,-0.05423986,0.00000000,0.00000000,0.00000000,0.00000000
159.60000000,3.16671700,9.49400000,0.10561678,622.31253277,0.10040335,688.03917726,0.00086547,0.11964876,713.35856038,-0.06503427,-0.05461449,0.00000000,0.00000000,0.00000000,0.00000000
160.60000000,3.19435600,9.50100000,0.10650278,622.77136864,0.10120439,689.09824932,0.00082479,0.12052876,714.28653380,-0.06550296,-0.05502580,0.00000000,0.00000000,0.00000000,0.00000000
161.60000000,3.22199900,9.50800000,0.10745200,623.23020451,0.10206188,690.19753644,0.00080381,0.12136576,715.18472991,-0.06594396,-0.05542180,0.00000000,0.00000000,0.00000000,0.00000000
162.60000000,3.25016900,9.51300000,0.10838222,623.55794442,0.10290149,691.14054012,0.00076964,0.12224787,715.96719653,-0.06643292,-0.05581495,0.00000000,0.00000000,0.00000000,0.00000000
163.60000000,3.27804200,9.51900000,0.10936100,623.95123230,0.10378417,692.18716302,0.00091565,0.12312865,716.82417628,-0.06696674,-0.05616191,0.00000000,0.00000000,0.00000000,0.00000000
164.60000000,3.30572300,9.52400000,0.11024722,624.27897221,0.10458271,693.10399479,0.00078196,0.12397695,717.65873519,-0.06740332,-0.05657364,0.00000000,0.00000000,0.00000000,0.00000000
165.60000000,3.33349700,9.52900000,0.11120000,624.60671211,0.10544051,694.06297850,0.00086732,0.12483665,718.57718131,-0.06786218,-0.05697447,0.00000000,0.00000000,0.00000000,0.00000000
166.60000000,3.36150400,9.53500000,0.11215611,625.00000000,0.10630057,695.09756944,0.00078721,0.12576041,719.54293559,-0.06838573,-0.05737468,0.00000000,0.00000000,0.00000000,0.00000000
167.60000000,3.38953800,9.54100000,0.11311989,625.39328789,0.10716678,696.13770712,0.00091256,0.12665144,720.33638866,-0.06890701,-0.05774443,0.00000000,0.00000000,0.00000000,0.00000000
168.60000000,3.41711800,9.54600000,0.11401722,625.72102779,0.10797260,697.06400127,0.00077891,0.12752539,721.19330094,-0.06935140,-0.05817399,0.00000000,0.00000000,0.00000000,0.00000000
169.60000000,3.44532500,9.55100000,0.11497011,626.04876770,0.10882760,698.02566408,0.00081853,0.12838576,722.04132465,-0.06984215,-0.05854361,0.00000000,0.00000000,0.00000000,0.00000000
170.60000000,3.47342700,9.55600000,0.11593333,626.37650760,0.10969113,698.99442405,0.00085667,0.12927417,722.91062712,-0.07034019,-0.05893398,0.00000000,0.00000000,0.00000000,0.00000000
171.60000000,3.50206400,9.56200000,0.11689000,626.76979549,0.11054804,700.03291689,0.00094889,0.13018452,723.72166448,-0.07084106,-0.05934347,0.00000000,0.00000000,0.00000000,0.00000000
172.60000000,3.53026700,9.56700000,0.11781300,627.09753540,0.11137410,700.97777733,0.00078959,0.13105206,724.57770160,-0.07133159,-0.05972047,0.00000000,0.00000000,0.00000000,0.00000000
173.60000000,3.55857400,9.57200000,0.11873644,627.42527530,0.11219987,701.92352165,0.00082233,0.13191292,725.35450519,-0.07175329,-0.06015963,0.00000000,0.00000000,0.00000000,0.00000000
174.60000000,3.58730600,9.57700000,0.11974044,627.75301521,0.11309691,702.92044025,0.00083469,0.13281447,726.16177229,-0.07229826,-0.06051621,0.00000000,0.00000000,0.00000000,0.00000000
175.60000000,3.61610500,9.58100000,0.12072967,628.01520713,0.11397996,703.83527375,0.00084705,0.13375018,727.07027341,-0.07282751,-0.06092267,0.00000000,0.00000000,0.00000000,0.00000000
176.60000000,3.64437700,9.58500000,0.12167844,628.27739906,0.11482617,704.72521565,0.00085248,0.13457975,727.82680528,-0.07323156,-0.06134819,0.00000000,0.00000000,0.00000000,0.00000000
177.60000000,3.67281400,9.58900000,0.12261633,628.53959098,0.11566197,705.60881098,0.00087157,0.13547271,728.63044160,-0.07374762,-0.06172509,0.00000000,0.00000000,0.00000000,0.00000000
178.60000000,3.70151600,9.59300000,0.12360244,628.80178291,0.11653999,706.52322034,0.00086506,0.13642788,729.63178155,-0.07427704,-0.06215084,0.00000000,0.00000000,0.00000000,0.00000000
179.60000000,3.73018500,9.59800000,0.12454711,629.12952281,0.11738039,707.48578739,0.00087620,0.13731927,730.43617316,-0.07475618,-0.06256309,0.00000000,0.00000000,0.00000000,0.00000000
180.60000000,3.75895100,9.60300000,0.12553322,629.45726272,0.11825690,708.47506116,0.00088906,0.13824155,731.18829459,-0.07530221,-0.06293934,0.00000000,0.00000000,0.00000000,0.00000000
181.60000000,3.78778900,9.60600000,0.12651533,629.65390666,0.11912909,709.31478055,0.00089480,0.13909915,731.96953862,-0.07574590,-0.06335325,0.00000000,0.00000000,0.00000000,0.00000000
182.60000000,3.81652200,9.61000000,0.12749000,629.91609858,0.11999392,710.22410199,0.00088771,0.14002015,732.72228684,-0.07625397,-0.06376618,0.00000000,0.00000000,0.00000000,0.00000000
183.60000000,3.84558900,9.61400000,0.12844611,630.17829051,0.12084156,711.12224123,0.00082786,0.14093985,733.55083747,-0.07676624,-0.06417361,0.00000000,0.00000000,0.00000000,0.00000000
184.60000000,3.87452500,9.61800000,0.12942089,630.44048243,0.12170501,712.03265006,0.00086612,0.14185879,734.37973833,-0.07728541,-0.06457337,0.00000000,0.00000000,0.00000000,0.00000000
185.60000000,3.90382100,9.62100000,0.13041767,630.63712638,0.12258718,712.88334891,0.00082681,0.14277668,735.20877775,-0.07779496,-0.06498172,0.00000000,0.00000000,0.00000000,0.00000000
186.60000000,3.93288800,9.62500000,0.13140711,630.89931830,0.12346209,713.80397512,0.00083276,0.14369363,736.03802622,-0.07824983,-0.06544380,0.00000000,0.00000000,0.00000000,0.00000000
187.60000000,3.96202300,9.62900000,0.13241489,631.16151023,0.12435242,714.73669147,0.00084459,0.14464198,736.81512035,-0.07881815,-0.06582383,0.00000000,0.00000000,0.00000000,0.00000000
188.60000000,3.99132200,9.63100000,0.13342989,631.29260619,0.12524834,715.52590849,0.00095387,0.14555701,737.64472179,-0.07931219,-0.06624482,0.00000000,0.00000000,0.00000000,0.00000000
189.60000000,4.02051800,9.63500000,0.13437867,631.55479811,0.12608507,716.42228981,0.00085567,0.14647213,738.39887153,-0.07979784,-0.06667429,0.00000000,0.00000000,0.00000000,0.00000000
190.60000000,4.04978200,9.63800000,0.13533900,631.75144206,0.12693128,717.25205047,0.00077838,0.14744915,739.19970255,-0.08039736,-0.06705179,0.00000000,0.00000000,0.00000000,0.00000000
191.60000000,4.07917900,9.64100000,0.13638689,631.94808600,0.12785383,718.13751939,0.00091891,0.14836216,740.03043648,-0.08087233,-0.06748983,0.00000000,0.00000000,0.00000000,0.00000000
192.60000000,4.10857400,9.64500000,0.13737989,632.21027792,0.12872727,719.06325566,0.00093766,0.14930531,740.88448317,-0.08145573,-0.06784959,0.00000000,0.00000000,0.00000000,0.00000000
193.60000000,4.13856900,9.64800000,0.13837711,632.40692187,0.12960366,719.91756476,0.00083372,0.15021689,741.63926875,-0.08189152,-0.06832537,0.00000000,0.00000000,0.00000000,0.00000000
194.60000000,4.16796500,9.65000000,0.13937378,632.53801783,0.13047879,720.69723096,0.00079436,0.15115874,742.41737328,-0.08244473,-0.06871401,0.00000000,0.00000000,0.00000000,0.00000000
195.60000000,4.19776200,9.65300000,0.14041100,632.73466177,0.13138872,721.57756837,0.00085816,0.15209874,743.19491569,-0.08296686,-0.06913189,0.00000000,0.00000000,0.00000000,0.00000000
196.60000000,4.22759000,9.65600000,0.14146633,632.93130572,0.13231369,722.46977679,0.00097929,0.00000000,0.00000000,0.00000000,0.00000000,0.00000000,0.00000000,0.00000000,0.00000000
197.60000000,4.25718600,9.65900000,0.14244144,633.12794966,0.13316759,723.31160933,0.00090198,0.00000000,0.00000000,0.00000000,0.00000000,0.00000000,0.00000000,0.00000000,0.00000000
198.60000000,4.28691200,9.66100000,0.14346722,633.25904562,0.13406507,724.11096184,0.00086850,0.00000000,0.00000000,0.00000000,0.00000000,0.00000000,0.00000000,0.00000000,0.00000000
199.60000000,4.31670700,9.66400000,0.14444200,633.45568956,0.13491718,724.95329628,0.00082949,0.00000000,0.00000000,0.00000000,0.00000000,0.00000000,0.00000000,0.00000000,0.00000000
200.60000000,4.34686500,9.66600000,0.14553433,633.58678553,0.13587119,725.79541597,0.00100842,0.00000000,0.00000000,0.00000000,0.00000000,0.00000000,0.00000000,0.00000000,0.00000000
201.60000000,4.37675800,9.66900000,0.14648344,633.78342947,0.13669938,726.62220925,0.00085400,0.00000000,0.00000000,0.00000000,0.00000000,0.00000000,0.00000000,0.00000000,0.00000000
202.60000000,4.40665300,9.67100000,0.14751322,633.91452543,0.13759719,727.42529969,0.00076954,0.00000000,0.00000000,0.00000000,0.00000000,0.00000000,0.00000000,0.00000000,0.00000000
203.60000000,4.43701000,9.67300000,0.14857989,634.04562139,0.13852630,728.25204937,0.00096142,0.00000000,0.00000000,0.00000000,0.00000000,0.00000000,0.00000000,0.00000000,0.00000000
204.60000000,4.46713400,9.67600000,0.14964644,634.24226534,0.13945446,729.15436526,0.00102415,0.00000000,0.00000000,0.00000000,0.00000000,0.00000000,0.00000000,0.00000000,0.00000000
205.60000000,4.49798800,9.67800000,0.15063956,634.37336130,0.14031792,729.93508250,0.00083121,0.00000000,0.00000000,0.00000000,0.00000000,0.00000000,0.00000000,0.00000000,0.00000000
206.60000000,4.52814600,9.68100000,0.15166956,634.57000524,0.14121268,730.81495591,0.00083027,0.00000000,0.00000000,0.00000000,0.00000000,0.00000000,0.00000000,0.00000000,0.00000000
207.60000000,4.55869900,9.68200000,0.15277278,634.63555322,0.14217015,731.59058957,0.00089350,0.00000000,0.00000000,0.00000000,0.00000000,0.00000000,0.00000000,0.00000000,0.00000000
208.60000000,4.58885900,9.68300000,0.15383956,634.70110121,0.14309513,732.34323653,0.00102081,0.00000000,0.00000000,0.00000000,0.00000000,0.00000000,0.00000000,0.00000000,0.00000000
209.60000000,4.61918200,9.68500000,0.15483233,634.83219717,0.14395517,733.12474753,0.00089172,0.00000000,0.00000000,0.00000000,0.00000000,0.00000000,0.00000000,0.00000000,0.00000000
210.60000000,4.64970900,9.68700000,0.15586244,634.96329313,0.14484677,733.93022413,0.00082764,0.00000000,0.00000000,0.00000000,0.00000000,0.00000000,0.00000000,0.00000000,0.00000000
211.60000000,4.68072600,9.68900000,0.15700256,635.09438909,0.14583266,734.80583120,0.00095365,0.00000000,0.00000000,0.00000000,0.00000000,0.00000000,0.00000000,0.00000000,0.00000000
212.60000000,4.71157900,9.69100000,0.15806933,635.22548506,0.14675425,735.63515399,0.00095315,0.00000000,0.00000000,0.00000000,0.00000000,0.00000000,0.00000000,0.00000000,0.00000000
213.60000000,4.74256400,9.69300000,0.15913556,635.35658102,0.14767452,736.46440351,0.00095189,0.00000000,0.00000000,0.00000000,0.00000000,0.00000000,0.00000000,0.00000000,0.00000000
214.60000000,4.77401300,9.69500000,0.16016567,635.48767698,0.14856281,737.27098442,0.00082438,0.00000000,0.00000000,0.00000000,0.00000000,0.00000000,0.00000000,0.00000000,0.00000000
215.60000000,4.80486600,9.69600000,0.16130544,635.55322496,0.14954476,738.07142038,0.00095031,0.00000000,0.00000000,0.00000000,0.00000000,0.00000000,0.00000000,0.00000000,0.00000000
216.60000000,4.83624800,9.69700000,0.16240922,635.61877294,0.15049477,738.84912349,0.00101290,0.00000000,0.00000000,0.00000000,0.00000000,0.00000000,0.00000000,0.00000000,0.00000000
217.60000000,4.86736600,9.69800000,0.16347567,635.68432092,0.15141179,739.60323908,0.00088528,0.00000000,0.00000000,0.00000000,0.00000000,0.00000000,0.00000000,0.00000000,0.00000000
218.60000000,4.89868500,9.70000000,0.16450567,635.81541689,0.15229668,740.41065592,0.00082112,0.00000000,0.00000000,0.00000000,0.00000000,0.00000000,0.00000000,0.00000000,0.00000000
219.60000000,4.93033300,9.70100000,0.16560889,635.88096487,0.15324360,741.18850492,0.00082053,0.00000000,0.00000000,0.00000000,0.00000000,0.00000000,0.00000000,0.00000000,0.00000000
220.60000000,4.96201400,9.70200000,0.16674933,635.94651285,0.15422153,741.99016990,0.00094606,0.00000000,0.00000000,0.00000000,0.00000000,0.00000000,0.00000000,0.00000000,0.00000000
221.60000000,4.99380400,9.70300000,0.16785156,636.01206083,0.15516578,742.76767459,0.00094346,0.00000000,0.00000000,0.00000000,0.00000000,0.00000000,0.00000000,0.00000000,0.00000000
222.60000000,5.02465500,9.70400000,0.16899067,636.07760881,0.00000000,0.00000000,0.00000000,0.00000000,0.00000000,0.00000000,0.00000000,0.00000000,0.00000000,0.00000000,0.00000000