File: polyN_optimization/DP600_results/DATA/UT_60_1.csv
Time[s],Displacement[mm],Force[kN],EngStrain_longi,EngStress[MPa],TrueStrain,TrueStress[MPa],TrueStrainRate[1/s],PlasticStrain_longi,PlasticStress[MPa],PlasticStrain_thick,PlasticStrain_width,R-Value,Thickness[mm],Width[mm], Young's Modulus [MPa]
0.62000000,0.00000000,-0.01300000,0.00000000,-0.84922916,0.00000000,-0.84922916,0.00000000,0.00053838,337.60641201,0.00020330,-0.00074168,0.91909334,1.53080000,10.00000000,238749.92324770
2.12000000,0.00177000,0.02000000,0.00005944,1.30650640,0.00005944,1.30658407,0.00002978,0.00086027,355.55788760,0.00000529,-0.00086556,0.00000000,0.00000000,0.00000000,0.00000000
3.62000000,0.00332400,0.42400000,0.00012100,27.69793572,0.00012099,27.70128717,0.00003511,0.00136718,368.53842749,-0.00012153,-0.00124564,0.00000000,0.00000000,0.00000000,0.00000000
5.12000000,0.00607500,0.75600000,0.00019933,49.38594199,0.00019931,49.39578626,0.00008532,0.00200228,383.02794604,-0.00034882,-0.00165346,0.00000000,0.00000000,0.00000000,0.00000000
6.62000000,0.00835200,1.08300000,0.00023244,70.74732166,0.00023242,70.76376648,0.00009331,0.00270020,393.42054783,-0.00078706,-0.00191314,0.00000000,0.00000000,0.00000000,0.00000000
8.12000000,0.00983200,1.44400000,0.00030756,94.32976222,0.00030751,94.35877386,0.00005021,0.00341735,404.23109482,-0.00122031,-0.00219704,0.00000000,0.00000000,0.00000000,0.00000000
9.62000000,0.01157400,1.77800000,0.00037378,116.14841913,0.00037371,116.19183283,-0.00002488,0.00414521,412.69170948,-0.00157021,-0.00257500,0.00000000,0.00000000,0.00000000,0.00000000
11.12000000,0.01417600,2.11100000,0.00042667,137.90175072,0.00042658,137.96058880,-0.00008463,0.00501652,422.34626949,-0.00197936,-0.00303716,0.00000000,0.00000000,0.00000000,0.00000000
12.62000000,0.01713200,2.44200000,0.00056356,159.52443167,0.00056340,159.61433255,-0.00010216,0.00594987,429.53764668,-0.00245707,-0.00349279,0.00000000,0.00000000,0.00000000,0.00000000
14.12000000,0.02069100,2.79800000,0.00070622,182.78024562,0.00070597,182.90932909,0.00010793,0.00684330,438.04608381,-0.00297444,-0.00386886,0.00000000,0.00000000,0.00000000,0.00000000
15.62000000,0.02404800,3.12800000,0.00084011,204.33760125,0.00083976,204.50926754,0.00033797,0.00766509,444.62088102,-0.00343612,-0.00422897,0.00000000,0.00000000,0.00000000,0.00000000
17.12000000,0.02663700,3.47700000,0.00088644,227.13613797,0.00088605,227.33748153,0.00031974,0.00855535,451.89927744,-0.00391486,-0.00464049,0.00000000,0.00000000,0.00000000,0.00000000
18.62000000,0.02950400,3.79500000,0.00093433,247.90958976,0.00093390,248.14121995,0.00016097,0.00955917,458.05070682,-0.00447152,-0.00508765,0.00000000,0.00000000,0.00000000,0.00000000
20.12000000,0.03370200,4.10600000,0.00099689,268.22576431,0.00099639,268.49315559,-0.00005150,0.01051688,465.25388590,-0.00501377,-0.00550311,0.00000000,0.00000000,0.00000000,0.00000000
21.62000000,0.03959500,4.41100000,0.00116611,288.14998693,0.00116543,288.48600184,-0.00019820,0.01141138,471.04718542,-0.00541646,-0.00599492,0.00000000,0.00000000,0.00000000,0.00000000
23.12000000,0.04701100,4.72500000,0.00147511,308.66213744,0.00147402,309.11744839,-0.00016885,0.01235115,477.80257846,-0.00583152,-0.00651963,0.00000000,0.00000000,0.00000000,0.00000000
24.62000000,0.05614900,4.99800000,0.00187611,326.49594983,0.00187435,327.10849251,0.00007342,0.01335121,483.07026217,-0.00643389,-0.00691732,0.00000000,0.00000000,0.00000000,0.00000000
26.12000000,0.06866400,5.26900000,0.00234333,344.19911158,0.00234059,345.00568483,0.00038913,0.01432923,489.00326418,-0.00697939,-0.00734984,0.00000000,0.00000000,0.00000000,0.00000000
27.62000000,0.08462200,5.49600000,0.00285833,359.02795924,0.00285426,360.05418082,0.00060170,0.01528504,494.07034657,-0.00748882,-0.00779623,0.00000000,0.00000000,0.00000000,0.00000000
29.12000000,0.10121200,5.70000000,0.00339556,372.35432454,0.00338980,373.61867433,0.00053537,0.01622507,500.00625879,-0.00792418,-0.00830089,0.00000000,0.00000000,0.00000000,0.00000000
30.62000000,0.12141000,5.88100000,0.00403222,384.17820747,0.00402411,385.72729938,0.00039578,0.01720210,504.76997039,-0.00840449,-0.00879762,0.00000000,0.00000000,0.00000000,0.00000000
32.12000000,0.14385900,6.05400000,0.00483789,395.47948785,0.00482622,397.39277367,0.00050518,0.01826103,510.31995122,-0.00888932,-0.00937170,0.00000000,0.00000000,0.00000000,0.00000000
33.62000000,0.16872500,6.19700000,0.00574644,404.82100862,0.00573000,407.14729006,0.00077547,0.01924464,514.77171172,-0.00942193,-0.00982271,0.00000000,0.00000000,0.00000000,0.00000000
35.12000000,0.19415400,6.33700000,0.00656678,413.96655344,0.00654531,416.68497980,0.00086981,0.02027167,519.72348884,-0.00997599,-0.01029568,0.00000000,0.00000000,0.00000000,0.00000000
36.62000000,0.21994800,6.45500000,0.00735778,421.67494121,0.00733084,424.77753172,0.00060630,0.02129739,523.94671318,-0.01056512,-0.01073227,0.00000000,0.00000000,0.00000000,0.00000000
38.12000000,0.24766000,6.56500000,0.00829967,428.86072642,0.00826541,432.42012749,0.00054026,0.02234322,528.99454849,-0.01114971,-0.01119351,0.00000000,0.00000000,0.00000000,0.00000000
39.62000000,0.27576800,6.67000000,0.00931144,435.71988503,0.00926836,439.77706653,0.00067825,0.02338575,532.97545074,-0.01169909,-0.01168665,0.00000000,0.00000000,0.00000000,0.00000000
41.12000000,0.30308200,6.77700000,0.01022400,442.70969428,0.01017209,447.23595819,0.00077952,0.02445218,537.71725123,-0.01228696,-0.01216522,0.00000000,0.00000000,0.00000000,0.00000000
42.62000000,0.33221600,6.87300000,0.01109578,448.98092501,0.01103467,453.96271758,0.00065484,0.02552542,541.52942180,-0.01277421,-0.01275121,0.00000000,0.00000000,0.00000000,0.00000000
44.12000000,0.36105300,6.97100000,0.01203389,455.38280638,0.01196206,460.86283247,0.00044338,0.02657733,545.80967424,-0.01330366,-0.01327367,0.00000000,0.00000000,0.00000000,0.00000000
45.62000000,0.39015400,7.05900000,0.01307500,461.13143454,0.01299026,467.16072805,0.00051577,0.02767791,549.38273424,-0.01387802,-0.01379990,0.00000000,0.00000000,0.00000000,0.00000000
47.12000000,0.41942200,7.14500000,0.01409756,466.74941207,0.01399911,473.32943784,0.00068929,0.02874555,553.62071317,-0.01445901,-0.01428654,0.00000000,0.00000000,0.00000000,0.00000000
48.62000000,0.44978300,7.22600000,0.01502067,472.04076300,0.01490897,479.13112995,0.00056515,0.02983332,557.13426217,-0.01504305,-0.01479026,0.00000000,0.00000000,0.00000000,0.00000000
50.12000000,0.47832200,7.31000000,0.01596967,477.52808989,0.01584349,485.15405431,0.00038391,0.03091725,561.19467226,-0.01561781,-0.01529945,0.00000000,0.00000000,0.00000000,0.00000000
51.62000000,0.50967500,7.38500000,0.01701811,482.42748889,0.01687493,490.63749350,0.00043421,0.03199631,564.51467670,-0.01619020,-0.01580611,0.00000000,0.00000000,0.00000000,0.00000000
53.12000000,0.54036500,7.46400000,0.01811789,487.58818918,0.01795572,496.42225782,0.00063591,0.03307970,568.18320704,-0.01676377,-0.01631593,0.00000000,0.00000000,0.00000000,0.00000000
54.62000000,0.57112100,7.53500000,0.01912600,492.22628691,0.01894540,501.64060687,0.00067869,0.03422455,571.35064784,-0.01731808,-0.01690646,0.00000000,0.00000000,0.00000000,0.00000000
56.12000000,0.60263800,7.60200000,0.02012300,496.60308336,0.01992321,506.59622720,0.00063488,0.03532650,575.04435326,-0.01787212,-0.01745439,0.00000000,0.00000000,0.00000000,0.00000000
57.62000000,0.63346000,7.66700000,0.02121567,500.84922916,0.02099375,511.47507946,0.00060525,0.03640228,578.04922957,-0.01841329,-0.01798900,0.00000000,0.00000000,0.00000000,0.00000000
59.12000000,0.66537500,7.73500000,0.02231189,505.29135093,0.02206662,516.56535541,0.00074138,0.03756590,581.65679517,-0.01902983,-0.01853606,0.00000000,0.00000000,0.00000000,0.00000000
60.62000000,0.69735600,7.79600000,0.02339344,509.27619545,0.02312401,521.18991984,0.00075493,0.03871686,584.65012529,-0.01964672,-0.01907014,0.00000000,0.00000000,0.00000000,0.00000000
62.12000000,0.72976700,7.85900000,0.02445289,513.39169062,0.02415870,525.94560059,0.00073267,0.03983011,587.90088180,-0.02020589,-0.01962422,0.00000000,0.00000000,0.00000000,0.00000000
63.62000000,0.76178200,7.91600000,0.02553433,517.11523386,0.02521378,530.31942662,0.00070306,0.04097223,590.69627428,-0.02080602,-0.02016621,0.00000000,0.00000000,0.00000000,0.00000000
65.12000000,0.79462400,7.97100000,0.02666367,520.70812647,0.02631439,534.59211438,0.00078132,0.04211409,594.04538529,-0.02141581,-0.02069828,0.00000000,0.00000000,0.00000000,0.00000000
66.62000000,0.82773000,8.02400000,0.02777811,524.17036843,0.02739930,538.73083117,0.00077312,0.04325043,596.78075542,-0.02201618,-0.02123425,0.00000000,0.00000000,0.00000000,0.00000000
68.12000000,0.86110200,8.08000000,0.02887422,527.82858636,0.02846522,543.06922626,0.00072217,0.04437682,599.85907108,-0.02260692,-0.02176990,0.00000000,0.00000000,0.00000000,0.00000000
69.62000000,0.89437400,8.12900000,0.02999244,531.02952704,0.02955147,546.95640063,0.00075009,0.04552159,602.47343646,-0.02321985,-0.02230174,0.00000000,0.00000000,0.00000000,0.00000000
71.12000000,0.92791000,8.18100000,0.03112533,534.42644369,0.03065076,551.06064489,0.00071348,0.04669859,605.38800424,-0.02385879,-0.02283980,0.00000000,0.00000000,0.00000000,0.00000000
72.62000000,0.96148000,8.22700000,0.03226200,537.43140841,0.03175251,554.77002051,0.00074134,0.04784407,608.01375451,-0.02447108,-0.02337299,0.00000000,0.00000000,0.00000000,0.00000000
74.12000000,0.99551400,8.27300000,0.03340600,540.43637314,0.03286014,558.49019062,0.00074761,0.04901139,610.93419484,-0.02504589,-0.02396550,0.00000000,0.00000000,0.00000000,0.00000000
75.62000000,1.02974600,8.31700000,0.03454622,543.31068722,0.03396290,562.08001896,0.00074658,0.05017245,613.37322394,-0.02569066,-0.02448179,0.00000000,0.00000000,0.00000000,0.00000000
77.12000000,1.06410900,8.36300000,0.03570500,546.31565195,0.03508235,565.82185230,0.00079575,0.05135492,616.17623953,-0.02629677,-0.02505815,0.00000000,0.00000000,0.00000000,0.00000000
78.62000000,1.09867100,8.40400000,0.03686000,548.99399007,0.03619692,569.22990854,0.00082317,0.05252397,618.56123957,-0.02691146,-0.02561251,0.00000000,0.00000000,0.00000000,0.00000000
80.12000000,1.13306900,8.44800000,0.03804078,551.86830415,0.03733507,572.86180368,0.00077961,0.05372850,621.25048728,-0.02752569,-0.02620282,0.00000000,0.00000000,0.00000000,0.00000000
81.62000000,1.16769800,8.48600000,0.03921056,554.35066632,0.03846134,576.08706392,0.00079307,0.05492306,623.52258990,-0.02815994,-0.02676312,0.00000000,0.00000000,0.00000000,0.00000000
83.12000000,1.20292300,8.52400000,0.04040244,556.83302848,0.03960760,579.33044398,0.00090541,0.05611094,626.14264245,-0.02878312,-0.02732782,0.00000000,0.00000000,0.00000000,0.00000000
84.62000000,1.23788300,8.56100000,0.04155744,559.25006533,0.04071714,582.49106885,0.00076289,0.05729601,628.34877078,-0.02940018,-0.02789583,0.00000000,0.00000000,0.00000000,0.00000000
86.12000000,1.27357100,8.60000000,0.04276767,561.79775281,0.04187840,585.82453184,0.00075497,0.05849150,630.98395577,-0.03004923,-0.02844227,0.00000000,0.00000000,0.00000000,0.00000000
87.62000000,1.30935900,8.63400000,0.04394489,564.01881369,0.04300670,588.80455779,0.00075412,0.05968120,633.06282301,-0.03067581,-0.02900538,0.00000000,0.00000000,0.00000000,0.00000000
89.12000000,1.34451900,8.67000000,0.04511467,566.37052522,0.04412661,591.92214267,0.00068308,0.06087144,635.42552006,-0.03130761,-0.02956383,0.00000000,0.00000000,0.00000000,0.00000000
90.62000000,1.38113400,8.70400000,0.04634700,568.59158610,0.04530505,594.94410034,0.00072434,0.06206485,637.58522882,-0.03191836,-0.03014649,0.00000000,0.00000000,0.00000000,0.00000000
92.12000000,1.41692200,8.73600000,0.04754989,570.68199634,0.04645400,597.81786186,0.00072351,0.06327632,639.97087849,-0.03256023,-0.03071610,0.00000000,0.00000000,0.00000000,0.00000000
93.62000000,1.45314000,8.76700000,0.04876378,572.70708126,0.04761212,600.63444211,0.00075765,0.06447726,642.07422342,-0.03316409,-0.03131317,0.00000000,0.00000000,0.00000000,0.00000000
95.12000000,1.48902700,8.79800000,0.04996667,574.73216619,0.04875842,603.44961676,0.00073582,0.06570346,644.33844177,-0.03378906,-0.03191440,0.00000000,0.00000000,0.00000000,0.00000000
96.62000000,1.52587300,8.82800000,0.05123944,576.69192579,0.04996989,606.24129968,0.00077701,0.06694625,646.40722232,-0.03440632,-0.03253993,0.00000000,0.00000000,0.00000000,0.00000000
98.12000000,1.56272200,8.85900000,0.05249022,578.71701071,0.05115900,609.09399521,0.00083924,0.06814234,648.59053837,-0.03503148,-0.03311087,0.00000000,0.00000000,0.00000000,0.00000000
99.62000000,1.59930300,8.88700000,0.05374089,580.54611968,0.05234658,611.74518419,0.00085196,0.06935200,650.50524763,-0.03564269,-0.03370931,0.00000000,0.00000000,0.00000000,0.00000000
101.12000000,1.63638200,8.91400000,0.05496589,582.30990332,0.05350843,614.31708476,0.00083032,0.07058643,652.65150407,-0.03630615,-0.03428028,0.00000000,0.00000000,0.00000000,0.00000000
102.62000000,1.67319600,8.94000000,0.05623489,584.00836164,0.05471059,616.85000697,0.00084300,0.07181002,654.58311014,-0.03692554,-0.03488448,0.00000000,0.00000000,0.00000000,0.00000000
104.12000000,1.71057200,8.96800000,0.05749289,585.83747060,0.05590091,619.51895921,0.00086281,0.07303117,656.72904387,-0.03756502,-0.03546615,0.00000000,0.00000000,0.00000000,0.00000000
105.62000000,1.74765200,8.99300000,0.05872889,587.47060361,0.05706903,621.97209941,0.00076437,0.07427539,658.68210876,-0.03819616,-0.03607923,0.00000000,0.00000000,0.00000000,0.00000000
107.12000000,1.78535900,9.01900000,0.05999067,589.16906193,0.05826010,624.51370673,0.00073578,0.07551146,660.63366066,-0.03882489,-0.03668657,0.00000000,0.00000000,0.00000000,0.00000000
108.62000000,1.82250400,9.04200000,0.06125978,590.67154429,0.05945667,626.85595183,0.00072820,0.07673980,662.44195617,-0.03945235,-0.03728745,0.00000000,0.00000000,0.00000000,0.00000000
110.12000000,1.86044300,9.06500000,0.06255456,592.17402665,0.06067597,629.21720970,0.00077564,0.07798918,664.48096467,-0.04008557,-0.03790361,0.00000000,0.00000000,0.00000000,0.00000000
111.62000000,1.89828300,9.08700000,0.06382367,593.61118369,0.06186965,631.49762601,0.00074692,0.07924514,666.24382406,-0.04073673,-0.03850841,0.00000000,0.00000000,0.00000000,0.00000000
113.12000000,1.93569300,9.11100000,0.06510744,595.17899138,0.06307568,633.92957449,0.00075980,0.08049166,668.21751973,-0.04141434,-0.03907732,0.00000000,0.00000000,0.00000000,0.00000000
114.62000000,1.97403000,9.13200000,0.06641700,596.55082310,0.06430443,636.17193912,0.00081431,0.08173760,669.98072110,-0.04204192,-0.03969568,0.00000000,0.00000000,0.00000000,0.00000000
116.12000000,2.01223300,9.15400000,0.06770800,597.98798014,0.06551429,638.47655030,0.00082666,0.08301492,671.91132012,-0.04271115,-0.04030377,0.00000000,0.00000000,0.00000000,0.00000000
117.62000000,2.05027200,9.17500000,0.06902867,599.35981186,0.06675045,640.73282053,0.00085329,0.08431489,673.71804825,-0.04339449,-0.04092040,0.00000000,0.00000000,0.00000000,0.00000000
119.12000000,2.08907300,9.19400000,0.07033456,600.60099294,0.06797127,642.84399685,0.00087302,0.08556011,675.34802122,-0.04405084,-0.04150927,0.00000000,0.00000000,0.00000000,0.00000000
120.62000000,2.12750800,9.21300000,0.07161467,601.84217403,0.06916655,644.94290071,0.00078962,0.08683023,677.06965921,-0.04472445,-0.04210578,0.00000000,0.00000000,0.00000000,0.00000000
122.12000000,2.16581200,9.23300000,0.07295000,603.14868043,0.07041186,647.14837667,0.00077496,0.08806437,678.91370577,-0.04531291,-0.04275146,0.00000000,0.00000000,0.00000000,0.00000000
123.62000000,2.20471100,9.25100000,0.07425211,604.32453619,0.07162471,649.19690880,0.00078768,0.08937511,680.59792925,-0.04602216,-0.04335295,0.00000000,0.00000000,0.00000000,0.00000000
125.12000000,2.24387400,9.27000000,0.07555811,605.56571727,0.07283970,651.32111902,0.00078011,0.09062988,682.39109507,-0.04662061,-0.04400927,0.00000000,0.00000000,0.00000000,0.00000000
126.62000000,2.28247500,9.28700000,0.07689700,606.67624771,0.07408376,653.32783113,0.00077893,0.09192473,683.85481458,-0.04731498,-0.04460975,0.00000000,0.00000000,0.00000000,0.00000000
128.12000000,2.32170600,9.30300000,0.07821756,607.72145284,0.07530927,655.25593933,0.00076437,0.09320621,685.67289117,-0.04798112,-0.04522509,0.00000000,0.00000000,0.00000000,0.00000000
129.62000000,2.36156400,9.32000000,0.07958233,608.83198328,0.07657424,657.28425311,0.00083156,0.09450373,687.28877295,-0.04861360,-0.04589013,0.00000000,0.00000000,0.00000000,0.00000000
131.12000000,2.40056400,9.33700000,0.08092122,609.94251372,0.07781366,659.29980741,0.00080339,0.09582201,689.06680979,-0.04930788,-0.04651413,0.00000000,0.00000000,0.00000000,0.00000000
132.62000000,2.44035700,9.35200000,0.08228589,610.92239352,0.07907537,661.19268571,0.00083606,0.09711997,690.54442557,-0.04999546,-0.04712450,0.00000000,0.00000000,0.00000000,0.00000000
134.12000000,2.48024900,9.36800000,0.08362856,611.96759864,0.08031518,663.14556496,0.00084179,0.09840562,692.16130954,-0.05064153,-0.04776410,0.00000000,0.00000000,0.00000000,0.00000000
135.62000000,2.52004200,9.38300000,0.08498967,612.94747844,0.08157046,665.04168032,0.00083418,0.09971322,693.72385260,-0.05135294,-0.04836029,0.00000000,0.00000000,0.00000000,0.00000000
137.12000000,2.55960500,9.39700000,0.08635078,613.86203292,0.08282417,666.86949692,0.00081288,0.10103815,695.44691024,-0.05201812,-0.04902003,0.00000000,0.00000000,0.00000000,0.00000000
138.62000000,2.59992600,9.41100000,0.08773378,614.77658741,0.08409643,668.71325991,0.00084557,0.10232607,696.92891122,-0.05266327,-0.04966280,0.00000000,0.00000000,0.00000000,0.00000000
140.12000000,2.64041400,9.42600000,0.08911322,615.75646721,0.08536381,670.62851010,0.00087164,0.10362249,698.34661994,-0.05336169,-0.05026080,0.00000000,0.00000000,0.00000000,0.00000000
141.62000000,2.68080300,9.43900000,0.09049267,616.60569637,0.08662958,672.40399011,0.00083017,0.10494276,699.92966586,-0.05402637,-0.05091640,0.00000000,0.00000000,0.00000000,0.00000000
143.12000000,2.72152300,9.45200000,0.09192733,617.45492553,0.08794433,674.21591029,0.00084252,0.10629793,701.46712240,-0.05472451,-0.05157342,0.00000000,0.00000000,0.00000000,0.00000000
144.62000000,2.76187800,9.46600000,0.09329567,618.36948001,0.08919668,676.06067289,0.00084126,0.10763142,702.99218588,-0.05543227,-0.05219915,0.00000000,0.00000000,0.00000000,0.00000000
146.12000000,2.80253200,9.47700000,0.09465678,619.08805853,0.09044087,677.68893931,0.00077299,0.10894059,704.42956383,-0.05608964,-0.05285095,0.00000000,0.00000000,0.00000000,0.00000000
147.62000000,2.84335100,9.48900000,0.09608022,619.87196237,0.09174038,679.42939827,0.00088618,0.11032606,705.99699367,-0.05683772,-0.05348833,0.00000000,0.00000000,0.00000000,0.00000000
149.12000000,2.88440200,9.50200000,0.09748544,620.72119153,0.09302160,681.23247277,0.00081111,0.11167084,707.46501529,-0.05751863,-0.05415221,0.00000000,0.00000000,0.00000000,0.00000000
150.62000000,2.92578400,9.51200000,0.09890544,621.37444473,0.09431463,682.83176036,0.00087055,0.11299718,708.99624130,-0.05821116,-0.05478602,0.00000000,0.00000000,0.00000000,0.00000000
152.12000000,2.96703400,9.52400000,0.10033633,622.15834858,0.09561589,684.58343602,0.00086942,0.11434173,710.39581436,-0.05887746,-0.05546426,0.00000000,0.00000000,0.00000000,0.00000000
153.62000000,3.00798500,9.53400000,0.10180400,622.81160178,0.09694884,686.21631408,0.00095503,0.11568185,711.72088616,-0.05963370,-0.05604814,0.00000000,0.00000000,0.00000000,0.00000000
155.12000000,3.04956400,9.54600000,0.10321656,623.59550562,0.09823005,687.96088577,0.00090705,0.11702583,713.19888399,-0.06030128,-0.05672455,0.00000000,0.00000000,0.00000000,0.00000000
156.62000000,3.09144300,9.55400000,0.10462911,624.11810818,0.09950963,689.41903107,0.00081271,0.11844961,714.66276638,-0.06108009,-0.05736952,0.00000000,0.00000000,0.00000000,0.00000000
158.12000000,3.13285800,9.56500000,0.10608578,624.83668670,0.10082746,691.12297259,0.00083837,0.11981603,716.08817220,-0.06180767,-0.05800836,0.00000000,0.00000000,0.00000000,0.00000000
159.62000000,3.17424000,9.57400000,0.10751667,625.42461458,0.10212027,692.66818439,0.00083728,0.12117743,717.51254251,-0.06249561,-0.05868182,0.00000000,0.00000000,0.00000000,0.00000000
161.12000000,3.21668100,9.58400000,0.10896233,626.07786778,0.10342474,694.29677310,0.00081614,0.12258251,718.89663718,-0.06326473,-0.05931778,0.00000000,0.00000000,0.00000000,0.00000000
162.62000000,3.25892300,9.59300000,0.11045578,626.66579566,0.10477054,695.88465353,0.00084147,0.12395021,720.25620125,-0.06391925,-0.06003096,0.00000000,0.00000000,0.00000000,0.00000000
164.12000000,3.30106700,9.60100000,0.11190889,627.18839822,0.10607826,697.37635499,0.00086697,0.12534483,721.63765026,-0.06463130,-0.06071353,0.00000000,0.00000000,0.00000000,0.00000000
165.62000000,3.34284700,9.60900000,0.11339867,627.71100078,0.10741720,698.89259132,0.00093849,0.12674775,722.95292521,-0.06537438,-0.06137337,0.00000000,0.00000000,0.00000000,0.00000000
167.12000000,3.38535400,9.61800000,0.11491422,628.29892866,0.10877747,700.49941138,0.00100342,0.12815109,724.42032307,-0.06610973,-0.06204136,0.00000000,0.00000000,0.00000000,0.00000000
168.62000000,3.42756400,9.62600000,0.11637444,628.82153123,0.11008633,702.00028758,0.00089616,0.12954940,725.81189150,-0.06686223,-0.06268716,0.00000000,0.00000000,0.00000000,0.00000000
170.12000000,3.47043500,9.63300000,0.11788644,629.27880847,0.11143980,703.46224976,0.00092159,0.13096589,727.06925689,-0.06770673,-0.06325917,0.00000000,0.00000000,0.00000000,0.00000000
171.62000000,3.51307500,9.64100000,0.11935033,629.80141103,0.11274846,704.96841937,0.00090688,0.13238639,728.40675339,-0.06851624,-0.06387016,0.00000000,0.00000000,0.00000000,0.00000000
173.12000000,3.55604700,9.64800000,0.12084389,630.25868827,0.11408187,706.42159916,0.00078786,0.13382705,729.76136033,-0.06933500,-0.06449206,0.00000000,0.00000000,0.00000000,0.00000000
174.62000000,3.59991100,9.65700000,0.12241456,630.84661615,0.11548222,708.07142429,0.00088499,0.13526935,731.04426093,-0.07012487,-0.06514448,0.00000000,0.00000000,0.00000000,0.00000000
176.12000000,3.64321300,9.66300000,0.12386767,631.23856807,0.11677601,709.42861661,0.00080532,0.13670909,732.40289932,-0.07084570,-0.06586340,0.00000000,0.00000000,0.00000000,0.00000000
177.62000000,3.68625000,9.66800000,0.12545678,631.56519467,0.11818898,710.79932895,0.00092883,0.13816315,733.69895723,-0.07164146,-0.06652170,0.00000000,0.00000000,0.00000000,0.00000000
179.12000000,3.72961800,9.67500000,0.12699433,632.02247191,0.11955421,712.28574438,0.00096642,0.13962403,735.07791656,-0.07238650,-0.06723753,0.00000000,0.00000000,0.00000000,0.00000000
180.62000000,3.77355000,9.68100000,0.12852456,632.41442383,0.12091108,713.69520658,0.00097811,0.14111492,736.40577984,-0.07320334,-0.06791158,0.00000000,0.00000000,0.00000000,0.00000000
182.12000000,3.81744800,9.68800000,0.13006600,632.87170107,0.12227604,715.18679174,0.00084654,0.14257200,737.71094780,-0.07392084,-0.06865116,0.00000000,0.00000000,0.00000000,0.00000000
183.62000000,3.86134600,9.69400000,0.13167700,633.26365299,0.12370060,716.64991103,0.00094926,0.14405882,738.96444561,-0.07472146,-0.06933735,0.00000000,0.00000000,0.00000000,0.00000000
185.12000000,3.90584000,9.69800000,0.13318889,633.52495427,0.12503568,717.90343902,0.00088305,0.14551194,740.19501263,-0.07542954,-0.07008240,0.00000000,0.00000000,0.00000000,0.00000000
186.62000000,3.95003600,9.70400000,0.13477433,633.91690619,0.12643381,719.35263461,0.00085596,0.14705695,741.57219656,-0.07625627,-0.07080068,0.00000000,0.00000000,0.00000000,0.00000000
188.12000000,3.99413400,9.70900000,0.13639667,634.24353279,0.12786244,720.75223652,0.00096488,0.14860002,742.87409823,-0.07707624,-0.07152378,0.00000000,0.00000000,0.00000000,0.00000000
189.62000000,4.03879300,9.71400000,0.13794167,634.57015939,0.12922107,722.10382480,0.00087975,0.15010899,744.22924651,-0.07778550,-0.07232349,0.00000000,0.00000000,0.00000000,0.00000000
191.12000000,4.08318800,9.71800000,0.13958589,634.83146067,0.13066494,723.44497441,0.00094911,0.15167905,745.47938542,-0.07856918,-0.07310988,0.00000000,0.00000000,0.00000000,0.00000000
192.62000000,4.12850900,9.72200000,0.14117511,635.09276195,0.13205853,724.75205319,0.00091564,0.15324591,746.88259511,-0.07941380,-0.07383211,0.00000000,0.00000000,0.00000000,0.00000000
194.12000000,4.17350000,9.72800000,0.14278622,635.48471388,0.13346934,726.22317545,0.00092738,0.15481084,748.21013222,-0.08017964,-0.07463120,0.00000000,0.00000000,0.00000000,0.00000000
195.62000000,4.21908700,9.73100000,0.14443789,635.68068984,0.13491359,727.49706668,0.00097092,0.15640481,749.48491288,-0.08095425,-0.07545057,0.00000000,0.00000000,0.00000000,0.00000000
197.12000000,4.26374600,9.73500000,0.14608589,635.94199112,0.13635256,728.84414217,0.00099513,0.15799603,750.75979671,-0.08178329,-0.07621274,0.00000000,0.00000000,0.00000000,0.00000000
198.62000000,4.30946400,9.73900000,0.14776333,636.20329240,0.13781512,730.21081156,0.00102603,0.15955340,752.08847400,-0.08255683,-0.07699656,0.00000000,0.00000000,0.00000000,0.00000000
200.12000000,4.35465300,9.74300000,0.14936344,636.46459368,0.13920826,731.52913765,0.00091550,0.16123301,753.43460729,-0.08346621,-0.07776680,0.00000000,0.00000000,0.00000000,0.00000000
201.62000000,4.40047300,9.74600000,0.15106656,636.66056964,0.14068895,732.83868895,0.00098445,0.16294080,754.80450157,-0.08437192,-0.07856887,0.00000000,0.00000000,0.00000000,0.00000000
203.12000000,4.44645600,9.74900000,0.15273322,636.85654560,0.14213584,734.12569790,0.00095776,0.16458362,756.12758146,-0.08518739,-0.07939623,0.00000000,0.00000000,0.00000000,0.00000000
204.62000000,4.49217400,9.75300000,0.15446200,637.11784688,0.14363443,735.52834374,0.00102007,0.16625510,757.39707362,-0.08601496,-0.08024014,0.00000000,0.00000000,0.00000000,0.00000000
206.12000000,4.53881900,9.75600000,0.15619078,637.31382284,0.14513079,736.85636452,0.00101835,0.16795418,758.76755050,-0.08692396,-0.08103022,0.00000000,0.00000000,0.00000000,0.00000000
207.62000000,4.58490300,9.75900000,0.15788300,637.50979880,0.14659334,738.16175836,0.00101686,0.16968155,760.08411393,-0.08787937,-0.08180218,0.00000000,0.00000000,0.00000000,0.00000000
209.12000000,4.63128300,9.76100000,0.15964867,637.64044944,0.14811709,739.43889700,0.00107878,0.17143685,761.42432564,-0.08879595,-0.08264090,0.00000000,0.00000000,0.00000000,0.00000000
210.62000000,4.67779600,9.76300000,0.16134067,637.77110008,0.14957508,740.66951455,0.00107682,0.17321967,762.78797259,-0.08966452,-0.08355515,0.00000000,0.00000000,0.00000000,0.00000000
212.12000000,4.72480700,9.76700000,0.16310656,638.03240136,0.15109449,742.09966868,0.00101249,0.00000000,0.00000000,0.00000000,0.00000000,0.00000000,0.00000000,0.00000000,0.00000000
213.62000000,4.77201500,9.76900000,0.16494589,638.16305200,0.15267464,743.42542387,0.00107425,0.00000000,0.00000000,0.00000000,0.00000000,0.00000000,0.00000000,0.00000000,0.00000000
215.12000000,4.81942200,9.77100000,0.16671144,638.29370264,0.15418906,744.70456779,0.00107225,0.00000000,0.00000000,0.00000000,0.00000000,0.00000000,0.00000000,0.00000000,0.00000000
216.62000000,4.86666300,9.77200000,0.16855078,638.35902796,0.15576433,745.95493862,0.00107075,0.00000000,0.00000000,0.00000000,0.00000000,0.00000000,0.00000000,0.00000000,0.00000000
218.12000000,4.91466600,9.77400000,0.17042678,638.48967860,0.15736845,747.30541717,0.00113191,0.00000000,0.00000000,0.00000000,0.00000000,0.00000000,0.00000000,0.00000000,0.00000000
219.62000000,4.96286800,9.77600000,0.17222922,638.62032924,0.15890725,748.60941184,0.00106701,0.00000000,0.00000000,0.00000000,0.00000000,0.00000000,0.00000000,0.00000000,0.00000000
221.12000000,5.01080500,9.77700000,0.17406856,638.68565456,0.16047511,749.86074390,0.00100265,0.00000000,0.00000000,0.00000000,0.00000000,0.00000000,0.00000000,0.00000000,0.00000000
222.62000000,5.05913900,9.77800000,0.17601822,638.75097988,0.16213434,751.18279180,0.00112653,0.00000000,0.00000000,0.00000000,0.00000000,0.00000000,0.00000000,0.00000000,0.00000000
224.12000000,5.10744000,9.78000000,0.17793111,638.88163052,0.16375960,752.55854891,0.00124966,0.00000000,0.00000000,0.00000000,0.00000000,0.00000000,0.00000000,0.00000000,0.00000000
225.62000000,5.15617100,9.78100000,0.17984389,638.94695584,0.16538213,753.85766117,0.00112269,0.00000000,0.00000000,0.00000000,0.00000000,0.00000000,0.00000000,0.00000000,0.00000000
227.12000000,5.20559800,9.78200000,0.18183033,639.01228116,0.16706437,755.20409725,0.00105853,0.00000000,0.00000000,0.00000000,0.00000000,0.00000000,0.00000000,0.00000000,0.00000000
228.62000000,5.25469400,9.78300000,0.18377989,639.07760648,0.16871261,756.52721799,0.00105678,0.00000000,0.00000000,0.00000000,0.00000000,0.00000000,0.00000000,0.00000000,0.00000000
230.12000000,5.30375500,9.78300000,0.18580300,639.07760648,0.17042018,757.82014300,0.00111685,0.00000000,0.00000000,0.00000000,0.00000000,0.00000000,0.00000000,0.00000000,0.00000000
231.62000000,5.35361300,9.78400000,0.18789989,639.14293180,0.17218695,759.23781767,0.00123917,0.00000000,0.00000000,0.00000000,0.00000000,0.00000000,0.00000000,0.00000000,0.00000000
233.12000000,5.40340400,9.78400000,0.18995978,639.14293180,0.17391951,760.55438109,0.00123703,0.00000000,0.00000000,0.00000000,0.00000000,0.00000000,0.00000000,0.00000000,0.00000000
234.62000000,5.45283200,9.78400000,0.19201978,639.14293180,0.17564916,761.87101553,0.00117296,0.00000000,0.00000000,0.00000000,0.00000000,0.00000000,0.00000000,0.00000000,0.00000000
236.12000000,5.50331700,9.78500000,0.19411656,639.20825712,0.17740663,763.28916228,0.00110926,0.00000000,0.00000000,0.00000000,0.00000000,0.00000000,0.00000000,0.00000000,0.00000000
237.62000000,5.55419900,9.78500000,0.19636033,639.20825712,0.00000000,0.00000000,0.00000000,0.00000000,0.00000000,0.00000000,0.00000000,0.00000000,0.00000000,0.00000000,0.00000000
239.12000000,5.60488500,9.78500000,0.19856756,639.20825712,0.00000000,0.00000000,0.00000000,0.00000000,0.00000000,0.00000000,0.00000000,0.00000000,0.00000000,0.00000000,0.00000000
240.62000000,5.65540400,9.78400000,0.20073789,639.14293180,0.00000000,0.00000000,0.00000000,0.00000000,0.00000000,0.00000000,0.00000000,0.00000000,0.00000000,0.00000000,0.00000000
242.12000000,5.70599100,9.78300000,0.20301856,639.07760648,0.00000000,0.00000000,0.00000000,0.00000000,0.00000000,0.00000000,0.00000000,0.00000000,0.00000000,0.00000000,0.00000000
243.62000000,5.75756900,9.78300000,0.20529922,639.07760648,0.00000000,0.00000000,0.00000000,0.00000000,0.00000000,0.00000000,0.00000000,0.00000000,0.00000000,0.00000000,0.00000000
245.12000000,5.80964300,9.78300000,0.20769022,639.07760648,0.00000000,0.00000000,0.00000000,0.00000000,0.00000000,0.00000000,0.00000000,0.00000000,0.00000000,0.00000000,0.00000000
246.62000000,5.86115500,9.78100000,0.21015478,638.94695584,0.00000000,0.00000000,0.00000000,0.00000000,0.00000000,0.00000000,0.00000000,0.00000000,0.00000000,0.00000000,0.00000000
248.12000000,5.91316400,9.78000000,0.21258267,638.88163052,0.00000000,0.00000000,0.00000000,0.00000000,0.00000000,0.00000000,0.00000000,0.00000000,0.00000000,0.00000000,0.00000000
249.62000000,5.96557100,9.77900000,0.21515756,638.81630520,0.00000000,0.00000000,0.00000000,0.00000000,0.00000000,0.00000000,0.00000000,0.00000000,0.00000000,0.00000000,0.00000000
251.12000000,6.01867200,9.77800000,0.21773256,638.75097988,0.00000000,0.00000000,0.00000000,0.00000000,0.00000000,0.00000000,0.00000000,0.00000000,0.00000000,0.00000000,0.00000000
252.62000000,6.07157500,9.77600000,0.22034411,638.62032924,0.00000000,0.00000000,0.00000000,0.00000000,0.00000000,0.00000000,0.00000000,0.00000000,0.00000000,0.00000000,0.00000000
254.12000000,6.12411400,9.77400000,0.22306633,638.48967860,0.00000000,0.00000000,0.00000000,0.00000000,0.00000000,0.00000000,0.00000000,0.00000000,0.00000000,0.00000000,0.00000000
255.62000000,6.17754500,9.77200000,0.22578844,638.35902796,0.00000000,0.00000000,0.00000000,0.00000000,0.00000000,0.00000000,0.00000000,0.00000000,0.00000000,0.00000000,0.00000000
257.12000000,6.23144200,9.77100000,0.22865767,638.29370264,0.00000000,0.00000000,0.00000000,0.00000000,0.00000000,0.00000000,0.00000000,0.00000000,0.00000000,0.00000000,0.00000000
258.62000000,6.28606700,9.76900000,0.23163733,638.16305200,0.00000000,0.00000000,0.00000000,0.00000000,0.00000000,0.00000000,0.00000000,0.00000000,0.00000000,0.00000000,0.00000000
260.12000000,6.34085600,9.76500000,0.23469044,637.90175072,0.00000000,0.00000000,0.00000000,0.00000000,0.00000000,0.00000000,0.00000000,0.00000000,0.00000000,0.00000000,0.00000000
261.62000000,6.39528200,9.76200000,0.23781722,637.70577476,0.00000000,0.00000000,0.00000000,0.00000000,0.00000000,0.00000000,0.00000000,0.00000000,0.00000000,0.00000000,0.00000000
263.12000000,6.45086600,9.75900000,0.24105433,637.50979880,0.00000000,0.00000000,0.00000000,0.00000000,0.00000000,0.00000000,0.00000000,0.00000000,0.00000000,0.00000000,0.00000000
264.62000000,6.50641700,9.75600000,0.24443844,637.31382284,0.00000000,0.00000000,0.00000000,0.00000000,0.00000000,0.00000000,0.00000000,0.00000000,0.00000000,0.00000000,0.00000000
266.12000000,6.56216700,9.75200000,0.24789633,637.05252156,0.00000000,0.00000000,0.00000000,0.00000000,0.00000000,0.00000000,0.00000000,0.00000000,0.00000000,0.00000000,0.00000000
267.62000000,6.61804900,9.74800000,0.25153789,636.79122028,0.00000000,0.00000000,0.00000000,0.00000000,0.00000000,0.00000000,0.00000000,0.00000000,0.00000000,0.00000000,0.00000000
269.12000000,6.67522200,9.74400000,0.25529011,636.52991900,0.00000000,0.00000000,0.00000000,0.00000000,0.00000000,0.00000000,0.00000000,0.00000000,0.00000000,0.00000000,0.00000000
270.62000000,6.73256000,9.73900000,0.25922589,636.20329240,0.00000000,0.00000000,0.00000000,0.00000000,0.00000000,0.00000000,0.00000000,0.00000000,0.00000000,0.00000000,0.00000000
272.12000000,6.78936900,9.73200000,0.26327233,635.74601516,0.00000000,0.00000000,0.00000000,0.00000000,0.00000000,0.00000000,0.00000000,0.00000000,0.00000000,0.00000000,0.00000000
273.62000000,6.84677400,9.72800000,0.26757611,635.48471388,0.00000000,0.00000000,0.00000000,0.00000000,0.00000000,0.00000000,0.00000000,0.00000000,0.00000000,0.00000000,0.00000000
275.12000000,6.90490700,9.72000000,0.27199033,634.96211131,0.00000000,0.00000000,0.00000000,0.00000000,0.00000000,0.00000000,0.00000000,0.00000000,0.00000000,0.00000000,0.00000000
276.62000000,6.96327200,9.71200000,0.27666200,634.43950875,0.00000000,0.00000000,0.00000000,0.00000000,0.00000000,0.00000000,0.00000000,0.00000000,0.00000000,0.00000000,0.00000000
278.12000000,7.02180200,9.70300000,0.28151744,633.85158087,0.00000000,0.00000000,0.00000000,0.00000000,0.00000000,0.00000000,0.00000000,0.00000000,0.00000000,0.00000000,0.00000000
279.62000000,7.08033300,9.69400000,0.28648356,633.26365299,0.00000000,0.00000000,0.00000000,0.00000000,0.00000000,0.00000000,0.00000000,0.00000000,0.00000000,0.00000000,0.00000000
281.12000000,7.13942600,9.68400000,0.29174367,632.61039979,0.00000000,0.00000000,0.00000000,0.00000000,0.00000000,0.00000000,0.00000000,0.00000000,0.00000000,0.00000000,0.00000000
282.62000000,7.19957800,9.67300000,0.29726144,631.89182127,0.00000000,0.00000000,0.00000000,0.00000000,0.00000000,0.00000000,0.00000000,0.00000000,0.00000000,0.00000000,0.00000000
284.12000000,7.25979700,9.65800000,0.30288944,630.91194147,0.00000000,0.00000000,0.00000000,0.00000000,0.00000000,0.00000000,0.00000000,0.00000000,0.00000000,0.00000000,0.00000000
285.62000000,7.31932000,9.64500000,0.30870122,630.06271231,0.00000000,0.00000000,0.00000000,0.00000000,0.00000000,0.00000000,0.00000000,0.00000000,0.00000000,0.00000000,0.00000000
287.12000000,7.37900900,9.62700000,0.31466044,628.88685655,0.00000000,0.00000000,0.00000000,0.00000000,0.00000000,0.00000000,0.00000000,0.00000000,0.00000000,0.00000000,0.00000000
288.62000000,7.44005500,9.61300000,0.32095056,627.97230206,0.00000000,0.00000000,0.00000000,0.00000000,0.00000000,0.00000000,0.00000000,0.00000000,0.00000000,0.00000000,0.00000000
290.12000000,7.50159800,9.59000000,0.32735111,626.46981970,0.00000000,0.00000000,0.00000000,0.00000000,0.00000000,0.00000000,0.00000000,0.00000000,0.00000000,0.00000000,0.00000000
291.62000000,7.56208200,9.57100000,0.33378844,625.22863862,0.00000000,0.00000000,0.00000000,0.00000000,0.00000000,0.00000000,0.00000000,0.00000000,0.00000000,0.00000000,0.00000000
293.12000000,7.62326100,9.54700000,0.34029944,623.66083094,0.00000000,0.00000000,0.00000000,0.00000000,0.00000000,0.00000000,0.00000000,0.00000000,0.00000000,0.00000000,0.00000000
294.62000000,7.68437500,9.52400000,0.34695756,622.15834858,0.00000000,0.00000000,0.00000000,0.00000000,0.00000000,0.00000000,0.00000000,0.00000000,0.00000000,0.00000000,0.00000000
296.12000000,7.74591800,9.49400000,0.35372622,620.19858897,0.00000000,0.00000000,0.00000000,0.00000000,0.00000000,0.00000000,0.00000000,0.00000000,0.00000000,0.00000000,0.00000000
297.62000000,7.80746200,9.46700000,0.36053144,618.43480533,0.00000000,0.00000000,0.00000000,0.00000000,0.00000000,0.00000000,0.00000000,0.00000000,0.00000000,0.00000000,0.00000000
299.12000000,7.86943700,9.43100000,0.36733689,616.08309381,0.00000000,0.00000000,0.00000000,0.00000000,0.00000000,0.00000000,0.00000000,0.00000000,0.00000000,0.00000000,0.00000000
300.62000000,7.93157800,9.40000000,0.37425289,614.05800888,0.00000000,0.00000000,0.00000000,0.00000000,0.00000000,0.00000000,0.00000000,0.00000000,0.00000000,0.00000000,0.00000000
302.12000000,7.99448300,9.36100000,0.38120578,611.51032140,0.00000000,0.00000000,0.00000000,0.00000000,0.00000000,0.00000000,0.00000000,0.00000000,0.00000000,0.00000000,0.00000000
303.62000000,8.05768500,9.32300000,0.38823267,609.02795924,0.00000000,0.00000000,0.00000000,0.00000000,0.00000000,0.00000000,0.00000000,0.00000000,0.00000000,0.00000000,0.00000000
305.12000000,8.12042600,9.27100000,0.39529644,605.63104259,0.00000000,0.00000000,0.00000000,0.00000000,0.00000000,0.00000000,0.00000000,0.00000000,0.00000000,0.00000000,0.00000000
306.62000000,8.18323600,9.22700000,0.40232400,602.75672851,0.00000000,0.00000000,0.00000000,0.00000000,0.00000000,0.00000000,0.00000000,0.00000000,0.00000000,0.00000000,0.00000000
308.12000000,8.24677500,9.16600000,0.40946233,598.77188398,0.00000000,0.00000000,0.00000000,0.00000000,0.00000000,0.00000000,0.00000000,0.00000000,0.00000000,0.00000000,0.00000000
309.62000000,8.31051700,9.11100000,0.41663867,595.17899138,0.00000000,0.00000000,0.00000000,0.00000000,0.00000000,0.00000000,0.00000000,0.00000000,0.00000000,0.00000000,0.00000000
311.12000000,8.37558700,9.04000000,0.42388956,590.54089365,0.00000000,0.00000000,0.00000000,0.00000000,0.00000000,0.00000000,0.00000000,0.00000000,0.00000000,0.00000000,0.00000000
312.62000000,8.44115800,8.97100000,0.43121567,586.03344656,0.00000000,0.00000000,0.00000000,0.00000000,0.00000000,0.00000000,0.00000000,0.00000000,0.00000000,0.00000000,0.00000000
314.12000000,8.50756700,8.87200000,0.43869111,579.56623987,0.00000000,0.00000000,0.00000000,0.00000000,0.00000000,0.00000000,0.00000000,0.00000000,0.00000000,0.00000000,0.00000000
315.62000000,8.57435100,8.78100000,0.44627978,573.62163575,0.00000000,0.00000000,0.00000000,0.00000000,0.00000000,0.00000000,0.00000000,0.00000000,0.00000000,0.00000000,0.00000000
317.12000000,8.64280200,8.64700000,0.45402011,564.86804285,0.00000000,0.00000000,0.00000000,0.00000000,0.00000000,0.00000000,0.00000000,0.00000000,0.00000000,0.00000000,0.00000000
318.62000000,8.71464600,8.52000000,0.46217078,556.57172720,0.00000000,0.00000000,0.00000000,0.00000000,0.00000000,0.00000000,0.00000000,0.00000000,0.00000000,0.00000000,0.00000000
320.12000000,8.79297700,8.33400000,0.47117711,544.42121766,0.00000000,0.00000000,0.00000000,0.00000000,0.00000000,0.00000000,0.00000000,0.00000000,0.00000000,0.00000000,0.00000000
321.12000000,8.85089900,8.17700000,0.47778967,534.16514241,0.00000000,0.00000000,0.00000000,0.00000000,0.00000000,0.00000000,0.00000000,0.00000000,0.00000000,0.00000000,0.00000000