File: polyN_optimization/DP600_results/DATA/UT_75_3.csv
Time[s],Displacement[mm],Force[kN],EngStrain_longi,EngStress[MPa],TrueStrain,TrueStress[MPa],TrueStrainRate[1/s],PlasticStrain_longi,PlasticStress[MPa],PlasticStrain_thick,PlasticStrain_width,R-Value,Thickness[mm],Width[mm], Young's Modulus [MPa]
0.58000000,0.00000000,-0.01400000,0.00000000,-0.91575092,0.00000000,-0.91575092,0.00000000,0.00055219,340.87679516,0.00024845,-0.00080064,0.99921414,1.52880000,10.00000000,234541.40769076
2.08000000,0.00132400,-0.00400000,0.00002056,-0.26164312,0.00002056,-0.26164850,-0.00000511,0.00089802,355.38036889,0.00027081,-0.00116883,0.00000000,0.00000000,0.00000000,0.00000000
3.58000000,0.00314200,0.43800000,0.00009233,28.64992151,0.00009233,28.65256685,-0.00003133,0.00141496,371.66846747,0.00011075,-0.00152571,0.00000000,0.00000000,0.00000000,0.00000000
5.08000000,0.00570400,0.74400000,0.00018211,48.66562009,0.00018209,48.67448264,0.00008687,0.00209242,383.36721886,-0.00032363,-0.00176879,0.00000000,0.00000000,0.00000000,0.00000000
6.58000000,0.00763700,1.09700000,0.00024022,71.75562533,0.00024019,71.77286262,0.00012731,0.00275615,395.53839777,-0.00071448,-0.00204167,0.00000000,0.00000000,0.00000000,0.00000000
8.08000000,0.00941800,1.43000000,0.00030167,93.53741497,0.00030162,93.56563209,0.00006709,0.00345105,404.90638446,-0.00096769,-0.00248336,0.00000000,0.00000000,0.00000000,0.00000000
9.58000000,0.01112000,1.79000000,0.00034689,117.08529566,0.00034683,117.12591124,-0.00000733,0.00422358,415.57328002,-0.00126830,-0.00295528,0.00000000,0.00000000,0.00000000,0.00000000
11.08000000,0.01338800,2.09900000,0.00041711,137.29722658,0.00041702,137.35449478,-0.00008818,0.00519169,423.37024176,-0.00180176,-0.00338993,0.00000000,0.00000000,0.00000000,0.00000000
12.58000000,0.01641700,2.46000000,0.00052633,160.91051805,0.00052619,160.99521062,-0.00014125,0.00608046,432.27159788,-0.00227969,-0.00380077,0.00000000,0.00000000,0.00000000,0.00000000
14.08000000,0.02042600,2.79100000,0.00069922,182.56148613,0.00069898,182.68913718,0.00011681,0.00695244,439.13131529,-0.00273315,-0.00421928,0.00000000,0.00000000,0.00000000,0.00000000
15.58000000,0.02341900,3.14600000,0.00085044,205.78231293,0.00085008,205.95731935,0.00034840,0.00783861,446.67153453,-0.00315581,-0.00468281,0.00000000,0.00000000,0.00000000,0.00000000
17.08000000,0.02631600,3.47100000,0.00091000,227.04081633,0.00090959,227.24742347,0.00033661,0.00886068,452.96160564,-0.00363433,-0.00522635,0.00000000,0.00000000,0.00000000,0.00000000
18.58000000,0.02941500,3.79000000,0.00094611,247.90685505,0.00094566,248.14140248,0.00021092,0.00983220,460.43543651,-0.00405821,-0.00577399,0.00000000,0.00000000,0.00000000,0.00000000
20.08000000,0.03363600,4.10400000,0.00101156,268.44583987,0.00101104,268.71738776,0.00000000,0.01077122,466.18189942,-0.00451339,-0.00625783,0.00000000,0.00000000,0.00000000,0.00000000
21.58000000,0.03966100,4.43500000,0.00116978,290.09680795,0.00116909,290.43615675,-0.00023504,0.01167101,473.11709646,-0.00496762,-0.00670339,0.00000000,0.00000000,0.00000000,0.00000000
23.08000000,0.04724400,4.72800000,0.00148622,309.26216641,0.00148512,309.72179871,-0.00013202,0.01268209,478.58779359,-0.00551449,-0.00716760,0.00000000,0.00000000,0.00000000,0.00000000
24.58000000,0.05671400,5.02400000,0.00192389,328.62375720,0.00192204,329.25599279,0.00013951,0.01370752,484.60928271,-0.00609039,-0.00761713,0.00000000,0.00000000,0.00000000,0.00000000
26.08000000,0.06919700,5.27500000,0.00242433,345.04186290,0.00242140,345.87835939,0.00049198,0.01469666,489.69146346,-0.00650066,-0.00819600,0.00000000,0.00000000,0.00000000,0.00000000
27.58000000,0.08595300,5.50400000,0.00287700,360.02093145,0.00287287,361.05671167,0.00056512,0.01563305,495.75864905,-0.00687663,-0.00875642,0.00000000,0.00000000,0.00000000,0.00000000
29.08000000,0.10330500,5.70900000,0.00344000,373.43014129,0.00343410,374.71474097,0.00049857,0.01668248,500.62423103,-0.00740232,-0.00928017,0.00000000,0.00000000,0.00000000,0.00000000
30.58000000,0.12446400,5.90500000,0.00417589,386.25065411,0.00416719,387.86359392,0.00049843,0.01771963,506.29630681,-0.00796858,-0.00975105,0.00000000,0.00000000,0.00000000,0.00000000
32.08000000,0.14668500,6.06600000,0.00501100,396.78178964,0.00499849,398.77006319,0.00071764,0.01875417,510.77303361,-0.00852265,-0.01023151,0.00000000,0.00000000,0.00000000,0.00000000
33.58000000,0.17258200,6.22200000,0.00584622,406.98587127,0.00582920,409.36520112,0.00090005,0.01974185,515.77082737,-0.00902623,-0.01071563,0.00000000,0.00000000,0.00000000,0.00000000
35.08000000,0.19801200,6.35200000,0.00663756,415.48927263,0.00661562,418.24710576,0.00082624,0.02077023,520.32967234,-0.00954759,-0.01122265,0.00000000,0.00000000,0.00000000,0.00000000
36.58000000,0.22466700,6.47000000,0.00751344,423.20774464,0.00748536,426.38749251,0.00055524,0.02186833,525.06862323,-0.01013731,-0.01173102,0.00000000,0.00000000,0.00000000,0.00000000
38.08000000,0.25251200,6.58000000,0.00851800,430.40293040,0.00848193,434.06910256,0.00068605,0.02290037,529.10983801,-0.01059970,-0.01230066,0.00000000,0.00000000,0.00000000,0.00000000
39.58000000,0.28184800,6.69200000,0.00954078,437.72893773,0.00949555,441.90521225,0.00090403,0.02393141,533.89916750,-0.01106207,-0.01286934,0.00000000,0.00000000,0.00000000,0.00000000
41.08000000,0.30909700,6.79000000,0.01044578,444.13919414,0.01039160,448.77857346,0.00085195,0.02502994,537.79068878,-0.01161973,-0.01341021,0.00000000,0.00000000,0.00000000,0.00000000
42.58000000,0.33972500,6.89200000,0.01134700,450.81109367,0.01128311,455.92644715,0.00053094,0.02611719,542.29154404,-0.01219103,-0.01392616,0.00000000,0.00000000,0.00000000,0.00000000
44.08000000,0.36836400,6.98200000,0.01238800,456.69806384,0.01231190,462.35563946,0.00057430,0.02718637,545.84593799,-0.01275426,-0.01443211,0.00000000,0.00000000,0.00000000,0.00000000
45.58000000,0.39856000,7.06900000,0.01341422,462.38880167,0.01332505,468.59138781,0.00066782,0.02826305,549.81740254,-0.01335670,-0.01490635,0.00000000,0.00000000,0.00000000,0.00000000
47.08000000,0.42901900,7.15200000,0.01437811,467.81789639,0.01427573,474.54423408,0.00070357,0.02937273,553.34124584,-0.01391391,-0.01545882,0.00000000,0.00000000,0.00000000,0.00000000
48.58000000,0.45951200,7.23800000,0.01533844,473.44322344,0.01522200,480.70510602,0.00052184,0.03049247,557.48812707,-0.01448798,-0.01600449,0.00000000,0.00000000,0.00000000,0.00000000
50.08000000,0.48964100,7.31500000,0.01639811,478.47985348,0.01626511,486.32601928,0.00049987,0.03160436,560.75699602,-0.01503693,-0.01656744,0.00000000,0.00000000,0.00000000,0.00000000
51.58000000,0.52092800,7.39500000,0.01750178,483.71271586,0.01735039,492.17854832,0.00064373,0.03269537,564.42843349,-0.01552893,-0.01716644,0.00000000,0.00000000,0.00000000,0.00000000
53.08000000,0.55241500,7.46600000,0.01851356,488.35688121,0.01834427,497.39810347,0.00070093,0.03382263,567.65180318,-0.01605256,-0.01777008,0.00000000,0.00000000,0.00000000,0.00000000
54.58000000,0.58370300,7.53500000,0.01954000,492.87022501,0.01935155,502.50090921,0.00057027,0.03493200,571.41642388,-0.01657319,-0.01835881,0.00000000,0.00000000,0.00000000,0.00000000
56.08000000,0.61624900,7.60100000,0.02061778,497.18733647,0.02040811,507.43823449,0.00055508,0.03608968,574.39845567,-0.01716560,-0.01892408,0.00000000,0.00000000,0.00000000,0.00000000
57.58000000,0.64766900,7.66900000,0.02173244,501.63526949,0.02149966,512.53703012,0.00062649,0.03721493,577.98233255,-0.01769936,-0.01951558,0.00000000,0.00000000,0.00000000,0.00000000
59.08000000,0.68041200,7.73100000,0.02283600,505.69073783,0.02257916,517.23869152,0.00076251,0.03836315,580.90360113,-0.01833476,-0.02002839,0.00000000,0.00000000,0.00000000,0.00000000
60.58000000,0.71289000,7.79500000,0.02389178,509.87702773,0.02361084,522.05889637,0.00072569,0.03949688,584.36982310,-0.01887310,-0.02062378,0.00000000,0.00000000,0.00000000,0.00000000
62.08000000,0.74566600,7.85200000,0.02501744,513.60544218,0.02470963,526.45453779,0.00068195,0.04067442,587.25251567,-0.01952174,-0.02115268,0.00000000,0.00000000,0.00000000,0.00000000
63.58000000,0.77883900,7.91100000,0.02613933,517.46467818,0.02580354,530.99085989,0.00076721,0.04184593,590.34347573,-0.02009630,-0.02174963,0.00000000,0.00000000,0.00000000,0.00000000
65.08000000,0.81211200,7.96500000,0.02723556,520.99686028,0.02687127,535.18649922,0.00079496,0.04298609,593.07895809,-0.02063455,-0.02235155,0.00000000,0.00000000,0.00000000,0.00000000
66.58000000,0.84591300,8.01700000,0.02837233,524.39822083,0.02797729,539.27662195,0.00077289,0.04413342,596.23676871,-0.02121490,-0.02291852,0.00000000,0.00000000,0.00000000,0.00000000
68.08000000,0.87998000,8.06700000,0.02949789,527.66875981,0.02907120,543.23387426,0.00074333,0.04529951,598.86174996,-0.02180484,-0.02349467,0.00000000,0.00000000,0.00000000,0.00000000
69.58000000,0.91378200,8.11800000,0.03064567,531.00470958,0.03018547,547.27770290,0.00079966,0.04645885,601.90153137,-0.02236129,-0.02409756,0.00000000,0.00000000,0.00000000,0.00000000
71.08000000,0.94778100,8.16500000,0.03177867,534.07901622,0.03128417,551.05133525,0.00080589,0.04764342,604.47995446,-0.02296668,-0.02467674,0.00000000,0.00000000,0.00000000,0.00000000
72.58000000,0.98218100,8.21100000,0.03291178,537.08791209,0.03238178,554.76443010,0.00074819,0.04881122,607.32982930,-0.02352068,-0.02529055,0.00000000,0.00000000,0.00000000,0.00000000
74.08000000,1.01641300,8.25500000,0.03408900,539.96598639,0.03352085,558.37288690,0.00074734,0.05001784,609.79435989,-0.02415455,-0.02586329,0.00000000,0.00000000,0.00000000,0.00000000
75.58000000,1.05097600,8.30000000,0.03524033,542.90947148,0.03463361,562.04178223,0.00071794,0.05122130,612.60833729,-0.02477413,-0.02644717,0.00000000,0.00000000,0.00000000,0.00000000
77.08000000,1.08603700,8.34200000,0.03640644,545.65672423,0.03575939,565.52214544,0.00075253,0.05240448,614.99974975,-0.02536586,-0.02703862,0.00000000,0.00000000,0.00000000,0.00000000
78.58000000,1.12066700,8.38600000,0.03760200,548.53479853,0.03691228,569.16080403,0.00077309,0.05359839,617.74975962,-0.02597853,-0.02761986,0.00000000,0.00000000,0.00000000,0.00000000
80.08000000,1.15648900,8.42500000,0.03879756,551.08581894,0.03806385,572.46660162,0.00082163,0.05482396,620.10819696,-0.02657346,-0.02825050,0.00000000,0.00000000,0.00000000,0.00000000
81.58000000,1.19138300,8.46500000,0.03996744,553.70225013,0.03918941,575.83231405,0.00072900,0.05601965,622.59206672,-0.02715797,-0.02886168,0.00000000,0.00000000,0.00000000,0.00000000
83.08000000,1.22690700,8.49800000,0.04119233,555.86080586,0.04036653,578.75800946,0.00079860,0.05722562,624.80878471,-0.02776781,-0.02945781,0.00000000,0.00000000,0.00000000,0.00000000
84.58000000,1.26259500,8.53700000,0.04241733,558.41182627,0.04154237,582.09816684,0.00082603,0.05841425,627.43765391,-0.02835653,-0.03005772,0.00000000,0.00000000,0.00000000,0.00000000
86.08000000,1.29835000,8.57200000,0.04359811,560.70120356,0.04267446,585.14671693,0.00078973,0.05964504,629.60966264,-0.02897252,-0.03067253,0.00000000,0.00000000,0.00000000,0.00000000
87.58000000,1.33430500,8.60900000,0.04482689,563.12140241,0.04385122,588.36438294,0.00076072,0.06084872,632.11860051,-0.02957182,-0.03127690,0.00000000,0.00000000,0.00000000,0.00000000
89.08000000,1.37092100,8.64100000,0.04604444,565.21454736,0.04501585,591.23953718,0.00071754,0.06207378,634.15618437,-0.03018434,-0.03188944,0.00000000,0.00000000,0.00000000,0.00000000
90.58000000,1.40690800,8.67600000,0.04726933,567.50392465,0.04618614,594.32945683,0.00075173,0.06327833,636.53529792,-0.03078909,-0.03248924,0.00000000,0.00000000,0.00000000,0.00000000
92.08000000,1.44359000,8.70500000,0.04850544,569.40083726,0.04736576,597.01987794,0.00078625,0.06451743,638.59043585,-0.03141573,-0.03310170,0.00000000,0.00000000,0.00000000,0.00000000
93.58000000,1.48020600,8.73600000,0.04974878,571.42857143,0.04855088,599.85644444,0.00079929,0.06576010,641.00345561,-0.03201778,-0.03374233,0.00000000,0.00000000,0.00000000,0.00000000
95.08000000,1.51655700,8.76600000,0.05096633,573.39089482,0.04971006,602.61452630,0.00077002,0.06700022,642.92727688,-0.03263699,-0.03436323,0.00000000,0.00000000,0.00000000,0.00000000
96.58000000,1.55413300,8.79700000,0.05225022,575.41862899,0.05093094,605.48438023,0.00081810,0.06826082,645.22048244,-0.03325609,-0.03500473,0.00000000,0.00000000,0.00000000,0.00000000
98.08000000,1.59177600,8.82500000,0.05351567,577.25013082,0.05213283,608.14205641,0.00085911,0.06949383,647.21836835,-0.03389309,-0.03560074,0.00000000,0.00000000,0.00000000,0.00000000
99.58000000,1.62888700,8.85400000,0.05478844,579.14704343,0.05334022,610.87760905,0.00083720,0.07071803,649.35577840,-0.03449114,-0.03622689,0.00000000,0.00000000,0.00000000,0.00000000
101.08000000,1.66616500,8.87800000,0.05605744,580.71690215,0.05454258,613.27040763,0.00080820,0.07194182,651.21432226,-0.03510646,-0.03683537,0.00000000,0.00000000,0.00000000,0.00000000
102.58000000,1.70367500,8.90500000,0.05734867,582.48299320,0.05576452,615.88761621,0.00086293,0.07316962,653.36235904,-0.03573482,-0.03743480,0.00000000,0.00000000,0.00000000,0.00000000
104.08000000,1.74128400,8.93100000,0.05859200,584.18367347,0.05693972,618.41216327,0.00079933,0.07445155,655.26669087,-0.03639464,-0.03805690,0.00000000,0.00000000,0.00000000,0.00000000
105.58000000,1.77932200,8.95700000,0.05987222,585.88435374,0.05814836,620.96255197,0.00074299,0.07567284,657.34788540,-0.03695289,-0.03871995,0.00000000,0.00000000,0.00000000,0.00000000
107.08000000,1.81719600,8.98100000,0.06116700,587.45421245,0.05936925,623.38702427,0.00076974,0.07694508,659.18257389,-0.03760386,-0.03934121,0.00000000,0.00000000,0.00000000,0.00000000
108.58000000,1.85523400,9.00500000,0.06246556,589.02407117,0.06059220,625.81778701,0.00078261,0.07823217,661.10193071,-0.03823215,-0.04000002,0.00000000,0.00000000,0.00000000,0.00000000
110.08000000,1.89343900,9.02600000,0.06375300,590.39769754,0.06180322,628.03732195,0.00080235,0.07950782,662.94628276,-0.03889407,-0.04061374,0.00000000,0.00000000,0.00000000,0.00000000
111.58000000,1.93184200,9.05000000,0.06509200,591.96755625,0.06306118,630.49990842,0.00083599,0.08078774,664.93988180,-0.03950518,-0.04128257,0.00000000,0.00000000,0.00000000,0.00000000
113.08000000,1.96971700,9.07000000,0.06639067,593.27577185,0.06427974,632.66374586,0.00084185,0.08208390,666.73401361,-0.04016100,-0.04192290,0.00000000,0.00000000,0.00000000,0.00000000
114.58000000,2.00825200,9.09200000,0.06772600,594.71480900,0.06553115,634.99246415,0.00087516,0.08334784,668.58165103,-0.04081479,-0.04253304,0.00000000,0.00000000,0.00000000,0.00000000
116.08000000,2.04682000,9.11300000,0.06903544,596.08843537,0.06675679,637.23966544,0.00089467,0.08460024,670.35352427,-0.04141708,-0.04318316,0.00000000,0.00000000,0.00000000,0.00000000
117.58000000,2.08615000,9.13400000,0.07040022,597.46206175,0.06803262,639.52352366,0.00094857,0.08592790,672.25130383,-0.04207498,-0.04385292,0.00000000,0.00000000,0.00000000,0.00000000
119.08000000,2.12448700,9.15200000,0.07169144,598.63945578,0.06923819,641.55678307,0.00085138,0.08722508,673.84502778,-0.04274057,-0.04448451,0.00000000,0.00000000,0.00000000,0.00000000
120.58000000,2.16385000,9.17100000,0.07300856,599.88226060,0.07046644,643.67879795,0.00080931,0.08854253,675.74322326,-0.04339110,-0.04515143,0.00000000,0.00000000,0.00000000,0.00000000
122.08000000,2.20321300,9.19000000,0.07434000,601.12506541,0.07170652,645.81270277,0.00074644,0.08983273,677.33867194,-0.04402281,-0.04580991,0.00000000,0.00000000,0.00000000,0.00000000
123.58000000,2.24251000,9.20800000,0.07567156,602.30245945,0.07294517,647.87962347,0.00073869,0.09115000,679.24404878,-0.04468417,-0.04646583,0.00000000,0.00000000,0.00000000,0.00000000
125.08000000,2.28154100,9.22500000,0.07698500,603.41444270,0.07416547,649.86830357,0.00071055,0.09247694,680.87104592,-0.04537068,-0.04710626,0.00000000,0.00000000,0.00000000,0.00000000
126.58000000,2.32133400,9.24300000,0.07831656,604.59183673,0.07540108,651.94138690,0.00071647,0.09379834,682.56970042,-0.04606207,-0.04773627,0.00000000,0.00000000,0.00000000,0.00000000
128.08000000,2.36099500,9.25800000,0.07972544,605.57299843,0.07670679,653.85257487,0.00085184,0.09512205,684.12845837,-0.04676230,-0.04835975,0.00000000,0.00000000,0.00000000,0.00000000
129.58000000,2.40128500,9.27600000,0.08112333,606.75039246,0.07800062,655.97200680,0.00085752,0.09642301,685.89202481,-0.04742449,-0.04899852,0.00000000,0.00000000,0.00000000,0.00000000
131.08000000,2.44137800,9.29200000,0.08249533,607.79696494,0.07926887,657.93737816,0.00093160,0.09776939,687.54517648,-0.04809435,-0.04967503,0.00000000,0.00000000,0.00000000,0.00000000
132.58000000,2.48216400,9.30700000,0.08388944,608.77812664,0.08055591,659.84818547,0.00094374,0.09910417,689.12084249,-0.04876925,-0.05033492,0.00000000,0.00000000,0.00000000,0.00000000
134.08000000,2.52205700,9.32100000,0.08526533,609.69387755,0.08182450,661.67962925,0.00088846,0.10040714,690.75026862,-0.04939126,-0.05101588,0.00000000,0.00000000,0.00000000,0.00000000
135.58000000,2.56248000,9.33700000,0.08663378,610.74045003,0.08308464,663.65120245,0.00083987,0.10174504,692.33415174,-0.05005293,-0.05169211,0.00000000,0.00000000,0.00000000,0.00000000
137.08000000,2.60336400,9.35000000,0.08805722,611.59079016,0.08439374,665.44577628,0.00087923,0.10308778,693.92443773,-0.05071759,-0.05237019,0.00000000,0.00000000,0.00000000,0.00000000
138.58000000,2.64441600,9.36500000,0.08942922,612.57195186,0.08565391,667.35378507,0.00079017,0.10449149,695.48720905,-0.05142558,-0.05306590,0.00000000,0.00000000,0.00000000,0.00000000
140.08000000,2.68493700,9.37800000,0.09084189,613.42229199,0.08694977,669.14673168,0.00083643,0.10584722,697.01947478,-0.05210820,-0.05373902,0.00000000,0.00000000,0.00000000,0.00000000
141.58000000,2.72628700,9.39200000,0.09226533,614.33804291,0.08825383,671.02014722,0.00092286,0.10719455,698.54874379,-0.05277819,-0.05441636,0.00000000,0.00000000,0.00000000,0.00000000
143.08000000,2.76767000,9.40400000,0.09372211,615.12297227,0.08958666,672.77359582,0.00091513,0.10852722,699.99719190,-0.05345128,-0.05507595,0.00000000,0.00000000,0.00000000,0.00000000
144.58000000,2.80898600,9.41700000,0.09518244,615.97331240,0.09092097,674.60315799,0.00097420,0.10994279,701.58012124,-0.05420866,-0.05573413,0.00000000,0.00000000,0.00000000,0.00000000
146.08000000,2.84977100,9.42700000,0.09658756,616.62742020,0.09220314,676.18595540,0.00088557,0.11129150,703.04538403,-0.05485540,-0.05643610,0.00000000,0.00000000,0.00000000,0.00000000
147.58000000,2.89135200,9.44000000,0.09801844,617.47776033,0.09350714,678.00196988,0.00089798,0.11269344,704.62467260,-0.05558034,-0.05711309,0.00000000,0.00000000,0.00000000,0.00000000
149.08000000,2.93333000,9.45200000,0.09948256,618.26268969,0.09483967,679.76904207,0.00091033,0.11413912,706.16421483,-0.05633438,-0.05780474,0.00000000,0.00000000,0.00000000,0.00000000
150.58000000,2.97504400,9.46300000,0.10093200,618.98220827,0.09615709,681.45732051,0.00087581,0.11545291,707.61309655,-0.05694695,-0.05850596,0.00000000,0.00000000,0.00000000,0.00000000
152.08000000,3.01685600,9.47300000,0.10236644,619.63631606,0.09745918,683.06628259,0.00082103,0.11686296,708.98504039,-0.05763983,-0.05922313,0.00000000,0.00000000,0.00000000,0.00000000
153.58000000,3.05893400,9.48400000,0.10381944,620.35583464,0.09877639,684.76083275,0.00079316,0.11828324,710.51500061,-0.05837371,-0.05990953,0.00000000,0.00000000,0.00000000,0.00000000
155.08000000,3.10127600,9.49300000,0.10532767,620.94453166,0.10014182,686.34717031,0.00090532,0.11968936,711.88931654,-0.05907512,-0.06061424,0.00000000,0.00000000,0.00000000,0.00000000
156.58000000,3.14338600,9.50300000,0.10679533,621.59863946,0.10146875,687.98247336,0.00085068,0.12110558,713.42201007,-0.05978991,-0.06131567,0.00000000,0.00000000,0.00000000,0.00000000
158.08000000,3.18596100,9.51300000,0.10829989,622.25274725,0.10282721,689.64265064,0.00088303,0.12254947,714.82859934,-0.06052222,-0.06202725,0.00000000,0.00000000,0.00000000,0.00000000
159.58000000,3.22866600,9.52200000,0.10978589,622.84144427,0.10416710,691.22064587,0.00094134,0.12400452,716.24579249,-0.06123003,-0.06277449,0.00000000,0.00000000,0.00000000,0.00000000
161.08000000,3.27160300,9.53200000,0.11128678,623.49555207,0.10551860,692.88236302,0.00095348,0.12545688,717.73833862,-0.06193587,-0.06352100,0.00000000,0.00000000,0.00000000,0.00000000
162.58000000,3.31450900,9.54000000,0.11279133,624.01883830,0.10687157,694.40275510,0.00095878,0.12689177,719.07158192,-0.06264090,-0.06425087,0.00000000,0.00000000,0.00000000,0.00000000
164.08000000,3.35777800,9.54900000,0.11429578,624.60753532,0.10822262,695.99753938,0.00083857,0.12838163,720.59668498,-0.06340431,-0.06497732,0.00000000,0.00000000,0.00000000,0.00000000
165.58000000,3.40058400,9.55500000,0.11580033,625.00000000,0.10957194,697.37520833,0.00081114,0.12980625,721.85250992,-0.06413578,-0.06567047,0.00000000,0.00000000,0.00000000,0.00000000
167.08000000,3.44329000,9.56400000,0.11734889,625.58869702,0.11095882,699.00083551,0.00087568,0.13122163,723.25395104,-0.06483716,-0.06638446,0.00000000,0.00000000,0.00000000,0.00000000
168.58000000,3.48722100,9.57200000,0.11887922,626.11198325,0.11232749,700.54368885,0.00093389,0.13272785,724.72398801,-0.06558520,-0.06714265,0.00000000,0.00000000,0.00000000,0.00000000
170.08000000,3.53055800,9.57900000,0.12041678,626.56985871,0.11370074,702.01938215,0.00083419,0.13420055,726.02175737,-0.06634830,-0.06785225,0.00000000,0.00000000,0.00000000,0.00000000
171.58000000,3.57448900,9.58700000,0.12202789,627.09314495,0.11513766,703.61599757,0.00099666,0.13567697,727.39993857,-0.06708376,-0.06859322,0.00000000,0.00000000,0.00000000,0.00000000
173.08000000,3.61808800,9.59300000,0.12362067,627.48560963,0.11655621,705.05579901,0.00101483,0.13723121,728.76197011,-0.06785102,-0.06938018,0.00000000,0.00000000,0.00000000,0.00000000
174.58000000,3.66281300,9.60100000,0.12514356,628.00889587,0.11791063,706.60016202,0.00081764,0.13879839,730.21165814,-0.06863707,-0.07016132,0.00000000,0.00000000,0.00000000,0.00000000
176.08000000,3.70704200,9.60700000,0.12673267,628.40136054,0.11932200,708.04034070,0.00099901,0.14027486,731.52171834,-0.06936394,-0.07091092,0.00000000,0.00000000,0.00000000,0.00000000
177.58000000,3.75130500,9.61300000,0.12831078,628.79382522,0.12072163,709.47485000,0.00096510,0.14182505,732.88829166,-0.07013347,-0.07169159,0.00000000,0.00000000,0.00000000,0.00000000
179.08000000,3.79563300,9.61900000,0.12992189,629.18628990,0.12214851,710.93136115,0.00096372,0.14339491,734.27184261,-0.07091705,-0.07247787,0.00000000,0.00000000,0.00000000,0.00000000
180.58000000,3.84019500,9.62500000,0.13153689,629.57875458,0.12357679,712.39158527,0.00099496,0.14491809,735.62348570,-0.07167817,-0.07323992,0.00000000,0.00000000,0.00000000,0.00000000
182.08000000,3.88541800,9.63200000,0.13316644,630.03663004,0.12501588,713.93636793,0.00102610,0.14651191,736.95353516,-0.07247818,-0.07403373,0.00000000,0.00000000,0.00000000,0.00000000
183.58000000,3.93047400,9.63700000,0.13477033,630.36368394,0.12643028,715.31800774,0.00095372,0.14805588,738.24903663,-0.07324504,-0.07481084,0.00000000,0.00000000,0.00000000,0.00000000
185.08000000,3.97539900,9.64200000,0.13645878,630.69073783,0.12791709,716.75402507,0.00100376,0.14966035,739.59168437,-0.07404570,-0.07561464,0.00000000,0.00000000,0.00000000,0.00000000
186.58000000,4.02085300,9.64700000,0.13809944,631.01779173,0.12935972,718.16099820,0.00097008,0.15129288,741.11089275,-0.07485014,-0.07644274,0.00000000,0.00000000,0.00000000,0.00000000
188.08000000,4.06650700,9.65200000,0.13968867,631.34484563,0.13075513,719.53656532,0.00087841,0.15292336,742.47805363,-0.07566712,-0.07725624,0.00000000,0.00000000,0.00000000,0.00000000
189.58000000,4.11182800,9.65600000,0.14135111,631.60648875,0.13221275,720.88476772,0.00079941,0.15455180,743.76931258,-0.07651641,-0.07803540,0.00000000,0.00000000,0.00000000,0.00000000
191.08000000,4.15764600,9.66000000,0.14303956,631.86813187,0.13369099,722.25026862,0.00089470,0.15623941,745.18406724,-0.07733139,-0.07890802,0.00000000,0.00000000,0.00000000,0.00000000
192.58000000,4.20376300,9.66600000,0.14476489,632.26059655,0.13519928,723.78973155,0.00106717,0.15792433,746.59948276,-0.07821544,-0.07970890,0.00000000,0.00000000,0.00000000,0.00000000
194.08000000,4.25024400,9.66900000,0.14647911,632.45682889,0.13669560,725.09854300,0.00103338,0.15957517,747.99197881,-0.07900336,-0.08057181,0.00000000,0.00000000,0.00000000,0.00000000
195.58000000,4.29662600,9.67300000,0.14817500,632.71847200,0.13817373,726.47153159,0.00103185,0.16128635,749.27760544,-0.07984854,-0.08143780,0.00000000,0.00000000,0.00000000,0.00000000
197.08000000,4.34303900,9.67700000,0.14992600,632.98011512,0.13969759,727.88029186,0.00111362,0.16299393,750.64028639,-0.08064770,-0.08234622,0.00000000,0.00000000,0.00000000,0.00000000
198.58000000,4.38981800,9.68000000,0.15165844,633.17634746,0.14120303,729.20288738,0.00100306,0.16476070,752.05012007,-0.08152693,-0.08323377,0.00000000,0.00000000,0.00000000,0.00000000
200.08000000,4.43672800,9.68400000,0.15344633,633.43799058,0.14275427,730.63672763,0.00095736,0.16655524,753.48360387,-0.08241018,-0.08414506,0.00000000,0.00000000,0.00000000,0.00000000
201.58000000,4.48377300,9.68700000,0.15519722,633.63422292,0.14427108,731.97249422,0.00102558,0.16837777,754.86306024,-0.08335405,-0.08502372,0.00000000,0.00000000,0.00000000,0.00000000
203.08000000,4.53081500,9.68900000,0.15693711,633.76504448,0.14577609,733.22629968,0.00092219,0.17019687,756.24244599,-0.08425299,-0.08594388,0.00000000,0.00000000,0.00000000,0.00000000
204.58000000,4.57838800,9.69300000,0.15875789,634.02668760,0.14734865,734.68342602,0.00091441,0.00000000,0.00000000,0.00000000,0.00000000,0.00000000,0.00000000,0.00000000,0.00000000
206.08000000,4.62599400,9.69600000,0.16061567,634.22291994,0.14895061,736.08905704,0.00105911,0.00000000,0.00000000,0.00000000,0.00000000,0.00000000,0.00000000,0.00000000,0.00000000
207.58000000,4.67369800,9.69800000,0.16248422,634.35374150,0.15055929,737.42621580,0.00107615,0.00000000,0.00000000,0.00000000,0.00000000,0.00000000,0.00000000,0.00000000,0.00000000
209.08000000,4.72170200,9.70000000,0.16432356,634.48456306,0.15214028,738.74532240,0.00113785,0.00000000,0.00000000,0.00000000,0.00000000,0.00000000,0.00000000,0.00000000,0.00000000
210.58000000,4.77000200,9.70300000,0.16616267,634.68079540,0.15371859,740.14104884,0.00107275,0.00000000,0.00000000,0.00000000,0.00000000,0.00000000,0.00000000,0.00000000,0.00000000
212.08000000,4.81790600,9.70500000,0.16811211,634.81161695,0.15538887,741.53113804,0.00113377,0.00000000,0.00000000,0.00000000,0.00000000,0.00000000,0.00000000,0.00000000,0.00000000
213.58000000,4.86643900,9.70700000,0.16998833,634.94243851,0.15699378,742.87524540,0.00106962,0.00000000,0.00000000,0.00000000,0.00000000,0.00000000,0.00000000,0.00000000,0.00000000
215.08000000,4.91530200,9.70900000,0.17193767,635.07326007,0.15865850,744.26627457,0.00112988,0.00000000,0.00000000,0.00000000,0.00000000,0.00000000,0.00000000,0.00000000,0.00000000
216.58000000,4.96476300,9.71000000,0.17388744,635.13867085,0.16032084,745.58131120,0.00106588,0.00000000,0.00000000,0.00000000,0.00000000,0.00000000,0.00000000,0.00000000,0.00000000
218.08000000,5.01422300,9.71200000,0.17583700,635.26949241,0.16198023,746.97337415,0.00100133,0.00000000,0.00000000,0.00000000,0.00000000,0.00000000,0.00000000,0.00000000,0.00000000
219.58000000,5.06391400,9.71300000,0.17786011,635.33490319,0.16369933,748.33563967,0.00112458,0.00000000,0.00000000,0.00000000,0.00000000,0.00000000,0.00000000,0.00000000,0.00000000
221.08000000,5.11314300,9.71400000,0.17992011,635.40031397,0.16544673,749.72160906,0.00118480,0.00000000,0.00000000,0.00000000,0.00000000,0.00000000,0.00000000,0.00000000,0.00000000
222.58000000,5.16313200,9.71400000,0.18194333,635.40031397,0.16715998,751.00716510,0.00118315,0.00000000,0.00000000,0.00000000,0.00000000,0.00000000,0.00000000,0.00000000,0.00000000
224.08000000,5.21338700,9.71600000,0.18404000,635.53113553,0.16893232,752.49428571,0.00118086,0.00000000,0.00000000,0.00000000,0.00000000,0.00000000,0.00000000,0.00000000,0.00000000
225.58000000,5.26413900,9.71700000,0.18621044,635.59654631,0.17076373,753.95126169,0.00124094,0.00000000,0.00000000,0.00000000,0.00000000,0.00000000,0.00000000,0.00000000,0.00000000
227.08000000,5.31535300,9.71700000,0.18834389,635.59654631,0.17256065,755.30727161,0.00117659,0.00000000,0.00000000,0.00000000,0.00000000,0.00000000,0.00000000,0.00000000,0.00000000
228.58000000,5.36593700,9.71700000,0.19051411,635.59654631,0.17438524,756.68665736,0.00117444,0.00000000,0.00000000,0.00000000,0.00000000,0.00000000,0.00000000,0.00000000,0.00000000
230.08000000,5.41688700,9.71800000,0.19272133,635.66195709,0.00000000,0.00000000,0.00000000,0.00000000,0.00000000,0.00000000,0.00000000,0.00000000,0.00000000,0.00000000,0.00000000
231.58000000,5.46873000,9.71800000,0.19503878,635.66195709,0.00000000,0.00000000,0.00000000,0.00000000,0.00000000,0.00000000,0.00000000,0.00000000,0.00000000,0.00000000,0.00000000
233.08000000,5.51994600,9.71800000,0.19724600,635.66195709,0.00000000,0.00000000,0.00000000,0.00000000,0.00000000,0.00000000,0.00000000,0.00000000,0.00000000,0.00000000,0.00000000
234.58000000,5.57192200,9.71700000,0.19956322,635.59654631,0.00000000,0.00000000,0.00000000,0.00000000,0.00000000,0.00000000,0.00000000,0.00000000,0.00000000,0.00000000,0.00000000
236.08000000,5.62409700,9.71700000,0.20191756,635.59654631,0.00000000,0.00000000,0.00000000,0.00000000,0.00000000,0.00000000,0.00000000,0.00000000,0.00000000,0.00000000,0.00000000
237.58000000,5.67686500,9.71700000,0.20438211,635.59654631,0.00000000,0.00000000,0.00000000,0.00000000,0.00000000,0.00000000,0.00000000,0.00000000,0.00000000,0.00000000,0.00000000
239.07000000,5.72920600,9.71500000,0.20677311,635.46572475,0.00000000,0.00000000,0.00000000,0.00000000,0.00000000,0.00000000,0.00000000,0.00000000,0.00000000,0.00000000,0.00000000
240.58000000,5.78227500,9.71400000,0.20931133,635.40031397,0.00000000,0.00000000,0.00000000,0.00000000,0.00000000,0.00000000,0.00000000,0.00000000,0.00000000,0.00000000,0.00000000
242.08000000,5.83504600,9.71300000,0.21181267,635.33490319,0.00000000,0.00000000,0.00000000,0.00000000,0.00000000,0.00000000,0.00000000,0.00000000,0.00000000,0.00000000,0.00000000
243.58000000,5.88890800,9.71200000,0.21449800,635.26949241,0.00000000,0.00000000,0.00000000,0.00000000,0.00000000,0.00000000,0.00000000,0.00000000,0.00000000,0.00000000,0.00000000
245.08000000,5.94287000,9.71000000,0.21714678,635.13867085,0.00000000,0.00000000,0.00000000,0.00000000,0.00000000,0.00000000,0.00000000,0.00000000,0.00000000,0.00000000,0.00000000
246.57000000,5.99670000,9.70800000,0.21994233,635.00784929,0.00000000,0.00000000,0.00000000,0.00000000,0.00000000,0.00000000,0.00000000,0.00000000,0.00000000,0.00000000,0.00000000
248.08000000,6.05069700,9.70500000,0.22266456,634.81161695,0.00000000,0.00000000,0.00000000,0.00000000,0.00000000,0.00000000,0.00000000,0.00000000,0.00000000,0.00000000,0.00000000
249.58000000,6.10548700,9.70400000,0.22564411,634.74620617,0.00000000,0.00000000,0.00000000,0.00000000,0.00000000,0.00000000,0.00000000,0.00000000,0.00000000,0.00000000,0.00000000
251.08000000,6.16047500,9.70100000,0.22862378,634.54997384,0.00000000,0.00000000,0.00000000,0.00000000,0.00000000,0.00000000,0.00000000,0.00000000,0.00000000,0.00000000,0.00000000
252.57000000,6.21559600,9.69800000,0.23164022,634.35374150,0.00000000,0.00000000,0.00000000,0.00000000,0.00000000,0.00000000,0.00000000,0.00000000,0.00000000,0.00000000,0.00000000
254.08000000,6.27121300,9.69400000,0.23476700,634.09209838,0.00000000,0.00000000,0.00000000,0.00000000,0.00000000,0.00000000,0.00000000,0.00000000,0.00000000,0.00000000,0.00000000
255.57000000,6.32686400,9.69100000,0.23796733,633.89586604,0.00000000,0.00000000,0.00000000,0.00000000,0.00000000,0.00000000,0.00000000,0.00000000,0.00000000,0.00000000,0.00000000
257.07000000,6.38340900,9.68700000,0.24127800,633.63422292,0.00000000,0.00000000,0.00000000,0.00000000,0.00000000,0.00000000,0.00000000,0.00000000,0.00000000,0.00000000,0.00000000
258.57000000,6.44018500,9.68300000,0.24480944,633.37257980,0.00000000,0.00000000,0.00000000,0.00000000,0.00000000,0.00000000,0.00000000,0.00000000,0.00000000,0.00000000,0.00000000
260.08000000,6.49722600,9.67900000,0.24837778,633.11093668,0.00000000,0.00000000,0.00000000,0.00000000,0.00000000,0.00000000,0.00000000,0.00000000,0.00000000,0.00000000,0.00000000
261.57000000,6.55446600,9.67300000,0.25205644,632.71847200,0.00000000,0.00000000,0.00000000,0.00000000,0.00000000,0.00000000,0.00000000,0.00000000,0.00000000,0.00000000,0.00000000
263.07000000,6.61220200,9.66700000,0.25584533,632.32600733,0.00000000,0.00000000,0.00000000,0.00000000,0.00000000,0.00000000,0.00000000,0.00000000,0.00000000,0.00000000,0.00000000
264.57000000,6.66997100,9.66100000,0.25985511,631.93354265,0.00000000,0.00000000,0.00000000,0.00000000,0.00000000,0.00000000,0.00000000,0.00000000,0.00000000,0.00000000,0.00000000
266.07000000,6.72836900,9.65300000,0.26397522,631.41025641,0.00000000,0.00000000,0.00000000,0.00000000,0.00000000,0.00000000,0.00000000,0.00000000,0.00000000,0.00000000,0.00000000
267.57000000,6.78683300,9.64600000,0.26809511,630.95238095,0.00000000,0.00000000,0.00000000,0.00000000,0.00000000,0.00000000,0.00000000,0.00000000,0.00000000,0.00000000,0.00000000
269.07000000,6.84602700,9.63700000,0.27254622,630.36368394,0.00000000,0.00000000,0.00000000,0.00000000,0.00000000,0.00000000,0.00000000,0.00000000,0.00000000,0.00000000,0.00000000
270.57000000,6.90551600,9.62800000,0.27707089,629.77498692,0.00000000,0.00000000,0.00000000,0.00000000,0.00000000,0.00000000,0.00000000,0.00000000,0.00000000,0.00000000,0.00000000
272.07000000,6.96480800,9.61600000,0.28181611,628.99005756,0.00000000,0.00000000,0.00000000,0.00000000,0.00000000,0.00000000,0.00000000,0.00000000,0.00000000,0.00000000,0.00000000
273.57000000,7.02419800,9.60500000,0.28670889,628.27053898,0.00000000,0.00000000,0.00000000,0.00000000,0.00000000,0.00000000,0.00000000,0.00000000,0.00000000,0.00000000,0.00000000
275.07000000,7.08441800,9.59100000,0.29167500,627.35478807,0.00000000,0.00000000,0.00000000,0.00000000,0.00000000,0.00000000,0.00000000,0.00000000,0.00000000,0.00000000,0.00000000
276.57000000,7.14414000,9.57900000,0.29686211,626.56985871,0.00000000,0.00000000,0.00000000,0.00000000,0.00000000,0.00000000,0.00000000,0.00000000,0.00000000,0.00000000,0.00000000
278.07000000,7.20505400,9.56000000,0.30215956,625.32705390,0.00000000,0.00000000,0.00000000,0.00000000,0.00000000,0.00000000,0.00000000,0.00000000,0.00000000,0.00000000,0.00000000
279.57000000,7.26577000,9.54500000,0.30760411,624.34589220,0.00000000,0.00000000,0.00000000,0.00000000,0.00000000,0.00000000,0.00000000,0.00000000,0.00000000,0.00000000,0.00000000
281.07000000,7.32671600,9.52700000,0.31326933,623.16849817,0.00000000,0.00000000,0.00000000,0.00000000,0.00000000,0.00000000,0.00000000,0.00000000,0.00000000,0.00000000,0.00000000
282.57000000,7.38779700,9.50400000,0.31904489,621.66405024,0.00000000,0.00000000,0.00000000,0.00000000,0.00000000,0.00000000,0.00000000,0.00000000,0.00000000,0.00000000,0.00000000
284.07000000,7.44900900,9.48300000,0.32493111,620.29042386,0.00000000,0.00000000,0.00000000,0.00000000,0.00000000,0.00000000,0.00000000,0.00000000,0.00000000,0.00000000,0.00000000
285.57000000,7.50965900,9.45700000,0.33092744,618.58974359,0.00000000,0.00000000,0.00000000,0.00000000,0.00000000,0.00000000,0.00000000,0.00000000,0.00000000,0.00000000,0.00000000
287.07000000,7.57133500,9.43200000,0.33707122,616.95447410,0.00000000,0.00000000,0.00000000,0.00000000,0.00000000,0.00000000,0.00000000,0.00000000,0.00000000,0.00000000,0.00000000
288.57000000,7.63334400,9.40300000,0.34332544,615.05756149,0.00000000,0.00000000,0.00000000,0.00000000,0.00000000,0.00000000,0.00000000,0.00000000,0.00000000,0.00000000,0.00000000
290.07000000,7.69485600,9.37600000,0.34972678,613.29147043,0.00000000,0.00000000,0.00000000,0.00000000,0.00000000,0.00000000,0.00000000,0.00000000,0.00000000,0.00000000,0.00000000
291.57000000,7.75683300,9.33800000,0.35623856,610.80586081,0.00000000,0.00000000,0.00000000,0.00000000,0.00000000,0.00000000,0.00000000,0.00000000,0.00000000,0.00000000,0.00000000
293.07000000,7.81867800,9.30700000,0.36278744,608.77812664,0.00000000,0.00000000,0.00000000,0.00000000,0.00000000,0.00000000,0.00000000,0.00000000,0.00000000,0.00000000,0.00000000
294.57000000,7.88141800,9.26800000,0.36948356,606.22710623,0.00000000,0.00000000,0.00000000,0.00000000,0.00000000,0.00000000,0.00000000,0.00000000,0.00000000,0.00000000,0.00000000
296.07000000,7.94386200,9.22800000,0.37629022,603.61067504,0.00000000,0.00000000,0.00000000,0.00000000,0.00000000,0.00000000,0.00000000,0.00000000,0.00000000,0.00000000,0.00000000
297.57000000,8.00657000,9.18100000,0.38317089,600.53636839,0.00000000,0.00000000,0.00000000,0.00000000,0.00000000,0.00000000,0.00000000,0.00000000,0.00000000,0.00000000,0.00000000
299.07000000,8.06947900,9.13700000,0.39005178,597.65829409,0.00000000,0.00000000,0.00000000,0.00000000,0.00000000,0.00000000,0.00000000,0.00000000,0.00000000,0.00000000,0.00000000
300.57000000,8.13275500,9.07800000,0.39715411,593.79905808,0.00000000,0.00000000,0.00000000,0.00000000,0.00000000,0.00000000,0.00000000,0.00000000,0.00000000,0.00000000,0.00000000
302.07000000,8.19745600,9.02500000,0.40436756,590.33228676,0.00000000,0.00000000,0.00000000,0.00000000,0.00000000,0.00000000,0.00000000,0.00000000,0.00000000,0.00000000,0.00000000
303.57000000,8.26229600,8.95500000,0.41154544,585.75353218,0.00000000,0.00000000,0.00000000,0.00000000,0.00000000,0.00000000,0.00000000,0.00000000,0.00000000,0.00000000,0.00000000
305.07000000,8.32700800,8.88900000,0.41879811,581.43642072,0.00000000,0.00000000,0.00000000,0.00000000,0.00000000,0.00000000,0.00000000,0.00000000,0.00000000,0.00000000,0.00000000
306.57000000,8.39258800,8.79500000,0.42623689,575.28780743,0.00000000,0.00000000,0.00000000,0.00000000,0.00000000,0.00000000,0.00000000,0.00000000,0.00000000,0.00000000,0.00000000
308.07000000,8.45917400,8.71000000,0.43375300,569.72789116,0.00000000,0.00000000,0.00000000,0.00000000,0.00000000,0.00000000,0.00000000,0.00000000,0.00000000,0.00000000,0.00000000
309.57000000,8.52726100,8.58400000,0.44141933,561.48613291,0.00000000,0.00000000,0.00000000,0.00000000,0.00000000,0.00000000,0.00000000,0.00000000,0.00000000,0.00000000,0.00000000
311.07000000,8.59744900,8.46500000,0.44942278,553.70225013,0.00000000,0.00000000,0.00000000,0.00000000,0.00000000,0.00000000,0.00000000,0.00000000,0.00000000,0.00000000,0.00000000
312.57000000,8.67137000,8.29500000,0.45783856,542.58241758,0.00000000,0.00000000,0.00000000,0.00000000,0.00000000,0.00000000,0.00000000,0.00000000,0.00000000,0.00000000,0.00000000
313.57000000,8.72634000,8.16000000,0.46419133,533.75196232,0.00000000,0.00000000,0.00000000,0.00000000,0.00000000,0.00000000,0.00000000,0.00000000,0.00000000,0.00000000,0.00000000