File: polyN_optimization/DP600_results/DATA/UT_90_1.csv
Time[s],Displacement[mm],Force[kN],EngStrain_longi,EngStress[MPa],TrueStrain,TrueStress[MPa],TrueStrainRate[1/s],PlasticStrain_longi,PlasticStress[MPa],PlasticStrain_thick,PlasticStrain_width,R-Value,Thickness[mm],Width[mm], Young's Modulus [MPa]
0.61000000,0.00000000,-0.01500000,0.00000000,-0.98593401,0.00000000,-0.98593401,0.00000000,0.00060884,329.09707857,0.00019884,-0.00080768,1.04261096,1.52140000,10.00000000,220713.68159379
2.11000000,0.00196000,-0.00700000,0.00004733,-0.46010254,0.00004733,-0.46012432,0.00001289,0.00102845,343.55910898,0.00009361,-0.00112206,0.00000000,0.00000000,0.00000000,0.00000000
3.61000000,0.00378100,0.46200000,0.00013311,30.36676745,0.00013310,30.37080961,0.00008799,0.00145840,358.96362575,0.00010004,-0.00155845,0.00000000,0.00000000,0.00000000,0.00000000
5.11000000,0.00655500,0.74600000,0.00019389,49.03378467,0.00019387,49.04329178,0.00011554,0.00201344,371.85276421,-0.00013086,-0.00188258,0.00000000,0.00000000,0.00000000,0.00000000
6.61000000,0.00829600,1.12400000,0.00025489,73.87932168,0.00025486,73.89815270,0.00014641,0.00271255,384.41633716,-0.00053456,-0.00217799,0.00000000,0.00000000,0.00000000,0.00000000
8.11000000,0.01006800,1.43000000,0.00030056,93.99237544,0.00030051,94.02062537,0.00004421,0.00352314,394.12990728,-0.00100656,-0.00251658,0.00000000,0.00000000,0.00000000,0.00000000
9.61000000,0.01191800,1.79100000,0.00037300,117.72052057,0.00037293,117.76443033,-0.00002799,0.00427592,405.16180014,-0.00129629,-0.00297963,0.00000000,0.00000000,0.00000000,0.00000000
11.11000000,0.01462700,2.12500000,0.00045211,139.67398449,0.00045201,139.73713265,-0.00009929,0.00504216,413.23233406,-0.00159635,-0.00344580,0.00000000,0.00000000,0.00000000,0.00000000
12.61000000,0.01759300,2.48300000,0.00058233,163.20494282,0.00058216,163.29998249,-0.00007129,0.00584821,421.99624074,-0.00194436,-0.00390384,0.00000000,0.00000000,0.00000000,0.00000000
14.11000000,0.02161600,2.78700000,0.00075744,183.18653871,0.00075716,183.32529234,0.00020141,0.00682602,429.71922703,-0.00252016,-0.00430586,0.00000000,0.00000000,0.00000000,0.00000000
15.61000000,0.02492300,3.16600000,0.00088944,208.09780465,0.00088905,208.28289609,0.00033662,0.00772238,437.48829904,-0.00302511,-0.00469727,0.00000000,0.00000000,0.00000000,0.00000000
17.11000000,0.02804300,3.46500000,0.00092700,227.75075588,0.00092657,227.96188083,0.00030130,0.00856929,443.98452858,-0.00341361,-0.00515569,0.00000000,0.00000000,0.00000000,0.00000000
18.61000000,0.03140000,3.80600000,0.00095422,250.16432233,0.00095377,250.40303469,0.00010501,0.00945340,451.64151177,-0.00378416,-0.00566925,0.00000000,0.00000000,0.00000000,0.00000000
20.11000000,0.03655300,4.11600000,0.00108156,270.54029184,0.00108097,270.83289619,-0.00008080,0.01045676,457.76608918,-0.00422249,-0.00623427,0.00000000,0.00000000,0.00000000,0.00000000
21.61000000,0.04417100,4.43700000,0.00131356,291.63927961,0.00131269,292.02236401,-0.00019085,0.01142344,464.48682367,-0.00468970,-0.00673374,0.00000000,0.00000000,0.00000000,0.00000000
23.11000000,0.05265000,4.69700000,0.00167411,308.72880242,0.00167271,309.24564874,-0.00011003,0.01230157,470.57716524,-0.00508165,-0.00721992,0.00000000,0.00000000,0.00000000,0.00000000
24.61000000,0.06374800,4.99600000,0.00217833,328.38175365,0.00217596,329.09707857,0.00030137,0.01323604,476.83893975,-0.00557947,-0.00765658,0.00000000,0.00000000,0.00000000,0.00000000
26.11000000,0.07912000,5.21300000,0.00266800,342.64493230,0.00266445,343.55910898,0.00048477,0.01422119,482.13226064,-0.00607347,-0.00814772,0.00000000,0.00000000,0.00000000,0.00000000
27.61000000,0.09548500,5.44400000,0.00317278,357.82831602,0.00316776,358.96362575,0.00057271,0.01521530,488.31181368,-0.00654806,-0.00866724,0.00000000,0.00000000,0.00000000,0.00000000
29.11000000,0.11354300,5.63600000,0.00379133,370.44827133,0.00378416,371.85276421,0.00052807,0.01617771,493.34686105,-0.00693989,-0.00923782,0.00000000,0.00000000,0.00000000,0.00000000
30.61000000,0.13577500,5.82200000,0.00455344,382.67385303,0.00454311,384.41633716,0.00054979,0.01714774,498.86549047,-0.00737035,-0.00977739,0.00000000,0.00000000,0.00000000,0.00000000
32.11000000,0.15856800,5.96400000,0.00541456,392.00736164,0.00539995,394.12990728,0.00081243,0.01815891,503.81015974,-0.00788060,-0.01027831,0.00000000,0.00000000,0.00000000,0.00000000
33.61000000,0.18486900,6.12600000,0.00622456,402.65544893,0.00620526,405.16180014,0.00095849,0.01920013,509.04919243,-0.00841376,-0.01078637,0.00000000,0.00000000,0.00000000,0.00000000
35.11000000,0.20935000,6.24300000,0.00703456,410.34573419,0.00700993,413.23233406,0.00082592,0.02022623,513.48225027,-0.00897682,-0.01124941,0.00000000,0.00000000,0.00000000,0.00000000
36.61000000,0.23714200,6.37000000,0.00788867,418.69330879,0.00785771,421.99624074,0.00056253,0.02123653,518.72552081,-0.00948418,-0.01175235,0.00000000,0.00000000,0.00000000,0.00000000
38.11000000,0.26427000,6.48000000,0.00891178,425.92349152,0.00887230,429.71922703,0.00080984,0.02229399,522.85560200,-0.01002581,-0.01226817,0.00000000,0.00000000,0.00000000,0.00000000
39.61000000,0.29275200,6.59100000,0.00985389,433.21940318,0.00980566,437.48829904,0.00092554,0.02337316,527.47883470,-0.01052281,-0.01285035,0.00000000,0.00000000,0.00000000,0.00000000
41.11000000,0.32004000,6.68300000,0.01074078,439.26646510,0.01068351,443.98452858,0.00085940,0.02441687,531.75424773,-0.01096028,-0.01345659,0.00000000,0.00000000,0.00000000,0.00000000
42.60000000,0.34971200,6.79200000,0.01167167,446.43091889,0.01160408,451.64151177,0.00061626,0.02549099,536.19007327,-0.01142125,-0.01406974,0.00000000,0.00000000,0.00000000,0.00000000
44.11000000,0.37852300,6.87700000,0.01271678,452.01787827,0.01263660,457.76608918,0.00069133,0.02657065,539.95953394,-0.01196744,-0.01460321,0.00000000,0.00000000,0.00000000,0.00000000
45.61000000,0.40750000,6.97100000,0.01372867,458.19639805,0.01363528,464.48682367,0.00086845,0.02766025,544.35338153,-0.01251356,-0.01514670,0.00000000,0.00000000,0.00000000,0.00000000
47.11000000,0.43846400,7.05600000,0.01464867,463.78335743,0.01454241,470.57716524,0.00078335,0.02875268,547.94189321,-0.01310543,-0.01564724,0.00000000,0.00000000,0.00000000,0.00000000
48.61000000,0.46793700,7.14300000,0.01562756,469.50177468,0.01550670,476.83893975,0.00061811,0.02983825,551.94239389,-0.01363237,-0.01620588,0.00000000,0.00000000,0.00000000,0.00000000
50.11000000,0.49823700,7.21500000,0.01665422,474.23425792,0.01651706,482.13226064,0.00052139,0.03095655,555.56040022,-0.01419976,-0.01675679,0.00000000,0.00000000,0.00000000,0.00000000
51.61000000,0.52856700,7.30000000,0.01769533,479.82121730,0.01754059,488.31181368,0.00067339,0.03204740,559.37524429,-0.01469487,-0.01735253,0.00000000,0.00000000,0.00000000,0.00000000
53.11000000,0.55979100,7.36800000,0.01869967,484.29078480,0.01852698,493.34686105,0.00070058,0.03316151,562.59622767,-0.01525041,-0.01791110,0.00000000,0.00000000,0.00000000,0.00000000
54.61000000,0.59111600,7.44300000,0.01971511,489.22045484,0.01952329,498.86549047,0.00052373,0.03428506,566.51304541,-0.01574821,-0.01853685,0.00000000,0.00000000,0.00000000,0.00000000
56.11000000,0.62247100,7.50900000,0.02077078,493.55856448,0.02055801,503.81015974,0.00045231,0.03541789,569.69024458,-0.01629214,-0.01912575,0.00000000,0.00000000,0.00000000,0.00000000
57.60000000,0.65399300,7.57900000,0.02185967,498.15958985,0.02162417,509.04919243,0.00061722,0.03650355,572.84692462,-0.01683208,-0.01967147,0.00000000,0.00000000,0.00000000,0.00000000
59.10000000,0.68588000,7.63700000,0.02293033,501.97186802,0.02267138,513.48225027,0.00066801,0.03765638,576.46043508,-0.01739845,-0.02025792,0.00000000,0.00000000,0.00000000,0.00000000
60.60000000,0.71886000,7.70700000,0.02398989,506.57289339,0.02370665,518.72552081,0.00060884,0.03878553,579.58692516,-0.01799892,-0.02078661,0.00000000,0.00000000,0.00000000,0.00000000
62.11000000,0.75068000,7.76000000,0.02509344,510.05652688,0.02478377,522.85560200,0.00054905,0.03990020,582.50502073,-0.01852560,-0.02137460,0.00000000,0.00000000,0.00000000,0.00000000
63.60000000,0.78375800,7.82000000,0.02622289,514.00026292,0.02588496,527.47883470,0.00067400,0.04107188,585.73791694,-0.01916257,-0.02190931,0.00000000,0.00000000,0.00000000,0.00000000
65.11000000,0.81683500,7.87500000,0.02731544,517.61535428,0.02694904,531.75424773,0.00069470,0.04221207,588.68330332,-0.01973699,-0.02247508,0.00000000,0.00000000,0.00000000,0.00000000
66.61000000,0.85044400,7.93200000,0.02844122,521.36190351,0.02804428,536.19007327,0.00068703,0.04333978,591.76537788,-0.02025715,-0.02308263,0.00000000,0.00000000,0.00000000,0.00000000
68.11000000,0.88428100,7.97900000,0.02957067,524.45116340,0.02914189,539.95953394,0.00060768,0.04453797,594.48111993,-0.02086341,-0.02367456,0.00000000,0.00000000,0.00000000,0.00000000
69.61000000,0.91762300,8.03500000,0.03071467,528.13198370,0.03025241,544.35338153,0.00072778,0.04569103,597.52153221,-0.02139684,-0.02429419,0.00000000,0.00000000,0.00000000,0.00000000
71.11000000,0.95155800,8.07900000,0.03185889,531.02405679,0.03136192,547.94189321,0.00074874,0.04682033,600.13829192,-0.02194393,-0.02487639,0.00000000,0.00000000,0.00000000,0.00000000
72.61000000,0.98595900,8.12900000,0.03299933,534.31050348,0.03246654,551.94239389,0.00070530,0.04803808,603.02182164,-0.02255522,-0.02548286,0.00000000,0.00000000,0.00000000,0.00000000
74.11000000,1.02029500,8.17300000,0.03417300,537.20257657,0.03360207,555.56040022,0.00077586,0.04921635,605.74868779,-0.02312689,-0.02608946,0.00000000,0.00000000,0.00000000,0.00000000
75.61000000,1.05476000,8.22000000,0.03532056,540.29183647,0.03471109,559.37524429,0.00073184,0.05038636,608.47616886,-0.02370625,-0.02668010,0.00000000,0.00000000,0.00000000,0.00000000
77.11000000,1.08952500,8.25800000,0.03649056,542.78953595,0.03584054,562.59622767,0.00080223,0.05154621,610.85499967,-0.02425278,-0.02729343,0.00000000,0.00000000,0.00000000,0.00000000
78.61000000,1.12458600,8.30600000,0.03767511,545.94452478,0.03698274,566.51304541,0.00076596,0.05273760,613.60645436,-0.02484449,-0.02789310,0.00000000,0.00000000,0.00000000,0.00000000
80.11000000,1.15961600,8.34300000,0.03886700,548.37649533,0.03813070,569.69024458,0.00078605,0.05391180,616.00415303,-0.02538668,-0.02852512,0.00000000,0.00000000,0.00000000,0.00000000
81.61000000,1.19461400,8.38000000,0.04001111,550.80846589,0.03923140,572.84692462,0.00076424,0.05510482,618.55809123,-0.02598391,-0.02912090,0.00000000,0.00000000,0.00000000,0.00000000
83.11000000,1.22997300,8.42300000,0.04122867,553.63481004,0.04040143,576.46043508,0.00079836,0.05628325,620.96832584,-0.02652945,-0.02975380,0.00000000,0.00000000,0.00000000,0.00000000
84.61000000,1.26556400,8.45900000,0.04242056,556.00105166,0.04154547,579.58692516,0.00081856,0.05749433,623.47388409,-0.02715803,-0.03033629,0.00000000,0.00000000,0.00000000,0.00000000
86.11000000,1.30161800,8.49200000,0.04359767,558.17010648,0.04267404,582.50502073,0.00074734,0.05867075,625.68242993,-0.02772573,-0.03094502,0.00000000,0.00000000,0.00000000,0.00000000
87.61000000,1.33773900,8.52900000,0.04483722,560.60207703,0.04386111,585.73791694,0.00083795,0.05987208,628.19186038,-0.02831346,-0.03155863,0.00000000,0.00000000,0.00000000,0.00000000
89.11000000,1.37349700,8.56200000,0.04604389,562.77113185,0.04501532,588.68330332,0.00082295,0.06110788,630.37682091,-0.02894192,-0.03216596,0.00000000,0.00000000,0.00000000,0.00000000
90.61000000,1.41034700,8.59700000,0.04723956,565.07164454,0.04615771,591.76537788,0.00075196,0.06229374,632.60495415,-0.02951910,-0.03277464,0.00000000,0.00000000,0.00000000,0.00000000
92.11000000,1.44660100,8.62600000,0.04850867,566.97778362,0.04736884,594.48111993,0.00084243,0.06350914,634.85634491,-0.03009110,-0.03341804,0.00000000,0.00000000,0.00000000,0.00000000
93.61000000,1.48321900,8.66000000,0.04973356,569.21256737,0.04853638,597.52153221,0.00081328,0.06473647,637.11995098,-0.03066969,-0.03406679,0.00000000,0.00000000,0.00000000,0.00000000
95.11000000,1.51980300,8.68800000,0.05093278,571.05297752,0.04967813,600.13829192,0.00076328,0.06595313,639.16944203,-0.03125828,-0.03469485,0.00000000,0.00000000,0.00000000,0.00000000
96.61000000,1.55665400,8.71900000,0.05222778,573.09057447,0.05090961,603.02182164,0.00082572,0.06718408,641.51511210,-0.03185623,-0.03532784,0.00000000,0.00000000,0.00000000,0.00000000
98.11000000,1.59376600,8.74800000,0.05348200,574.99671355,0.05210087,605.74868779,0.00081039,0.06840166,643.43211906,-0.03244580,-0.03595586,0.00000000,0.00000000,0.00000000,0.00000000
99.61000000,1.63104700,8.77700000,0.05472900,576.90285264,0.05328386,608.47616886,0.00080922,0.06964411,645.58169218,-0.03308981,-0.03655430,0.00000000,0.00000000,0.00000000,0.00000000
101.11000000,1.66815900,8.80100000,0.05596500,578.48034705,0.05445504,610.85499967,0.00078743,0.07084821,647.56875356,-0.03369511,-0.03715309,0.00000000,0.00000000,0.00000000,0.00000000
102.61000000,1.70547000,8.83000000,0.05723767,580.38648613,0.05565953,613.60645436,0.00076566,0.07204360,649.62510565,-0.03429064,-0.03775297,0.00000000,0.00000000,0.00000000,0.00000000
104.11000000,1.74301500,8.85400000,0.05849189,581.96398054,0.05684515,616.00415303,0.00079185,0.07330614,651.58704585,-0.03493351,-0.03837263,0.00000000,0.00000000,0.00000000,0.00000000
105.61000000,1.78085800,8.88000000,0.05976833,583.67293283,0.05805033,618.55809123,0.00075628,0.07453921,653.67613920,-0.03550704,-0.03903217,0.00000000,0.00000000,0.00000000,0.00000000
107.11000000,1.81850000,8.90400000,0.06103011,585.25042724,0.05924024,620.96832584,0.00070719,0.07579549,655.57065248,-0.03614958,-0.03964591,0.00000000,0.00000000,0.00000000,0.00000000
108.61000000,1.85650600,8.92900000,0.06232856,586.89365058,0.06046325,623.47388409,0.00081012,0.07704644,657.53685491,-0.03673835,-0.04030809,0.00000000,0.00000000,0.00000000,0.00000000
110.11000000,1.89464500,8.95000000,0.06359022,588.27395820,0.06165019,625.68242993,0.00076088,0.07827245,659.41895272,-0.03731713,-0.04095531,0.00000000,0.00000000,0.00000000,0.00000000
111.61000000,1.93281800,8.97500000,0.06488144,589.91718154,0.06286347,628.19186038,0.00069086,0.07954097,661.33291530,-0.03792948,-0.04161149,0.00000000,0.00000000,0.00000000,0.00000000
113.11000000,1.97125500,8.99500000,0.06620933,591.23176022,0.06410968,630.37682091,0.00080738,0.08077485,663.01252958,-0.03851547,-0.04225939,0.00000000,0.00000000,0.00000000,0.00000000
114.61000000,2.00966000,9.01600000,0.06748578,592.61206783,0.06530614,632.60495415,0.00081350,0.08205668,665.01449040,-0.03916824,-0.04288844,0.00000000,0.00000000,0.00000000,0.00000000
116.11000000,2.04813000,9.03700000,0.06879544,593.99237544,0.06653226,634.85634491,0.00083330,0.08334446,666.80881808,-0.03981326,-0.04353120,0.00000000,0.00000000,0.00000000,0.00000000
117.61000000,2.08666700,9.05800000,0.07011956,595.37268306,0.06777038,637.11995098,0.00081835,0.08464373,668.61440547,-0.04049646,-0.04414728,0.00000000,0.00000000,0.00000000,0.00000000
119.11000000,2.12573500,9.07600000,0.07143278,596.55580386,0.06899680,639.16944203,0.00085179,0.08587431,670.37739166,-0.04108900,-0.04478531,0.00000000,0.00000000,0.00000000,0.00000000
120.61000000,2.16466600,9.09800000,0.07276444,598.00184041,0.07023891,641.51511210,0.00087167,0.08718390,672.19700522,-0.04177465,-0.04540925,0.00000000,0.00000000,0.00000000,0.00000000
122.11000000,2.20370100,9.11400000,0.07408122,599.05350335,0.07146562,643.43211906,0.00086998,0.08845221,673.84781127,-0.04240034,-0.04605187,0.00000000,0.00000000,0.00000000,0.00000000
123.61000000,2.24273100,9.13300000,0.07542756,600.30235310,0.07271831,645.58169218,0.00086889,0.08971187,675.56825437,-0.04297255,-0.04673932,0.00000000,0.00000000,0.00000000,0.00000000
125.11000000,2.28232600,9.15000000,0.07673344,601.41974497,0.07393187,647.56875356,0.00085441,0.09100294,677.38578460,-0.04360918,-0.04739376,0.00000000,0.00000000,0.00000000,0.00000000
126.61000000,2.32139300,9.16800000,0.07803189,602.60286578,0.07513705,649.62510565,0.00079193,0.09227663,678.97741885,-0.04418461,-0.04809202,0.00000000,0.00000000,0.00000000,0.00000000
128.10000000,2.36085400,9.18400000,0.07940389,603.65452872,0.07640893,651.58704585,0.00083480,0.09355794,680.72251986,-0.04482076,-0.04873718,0.00000000,0.00000000,0.00000000,0.00000000
129.60000000,2.40058200,9.20200000,0.08074644,604.83764953,0.07765195,653.67613920,0.00083046,0.09485172,682.33406466,-0.04546609,-0.04938563,0.00000000,0.00000000,0.00000000,0.00000000
131.10000000,2.44126900,9.21700000,0.08211478,605.82358354,0.07891725,655.57065248,0.00082941,0.09615683,683.95643989,-0.04610620,-0.05005063,0.00000000,0.00000000,0.00000000,0.00000000
132.60000000,2.48096400,9.23300000,0.08347944,606.87524648,0.08017757,657.53685491,0.00079451,0.09746407,685.51043615,-0.04675655,-0.05070752,0.00000000,0.00000000,0.00000000,0.00000000
134.10000000,2.52102300,9.24800000,0.08481833,607.86118049,0.08141254,659.41895272,0.00078677,0.09875922,687.13204738,-0.04740162,-0.05135760,0.00000000,0.00000000,0.00000000,0.00000000
135.60000000,2.56170900,9.26300000,0.08620522,608.84711450,0.08269017,661.33291530,0.00081319,0.10009971,688.64180208,-0.04807562,-0.05202409,0.00000000,0.00000000,0.00000000,0.00000000
137.10000000,2.60200100,9.27500000,0.08755500,609.63586171,0.08393206,663.01252958,0.00083855,0.10141738,690.35826837,-0.04870895,-0.05270843,0.00000000,0.00000000,0.00000000,0.00000000
138.60000000,2.64265500,9.29100000,0.08896033,610.68752465,0.08522342,665.01449040,0.00085809,0.10271142,691.84171707,-0.04933392,-0.05337750,0.00000000,0.00000000,0.00000000,0.00000000
140.10000000,2.68377200,9.30400000,0.09037289,611.54200079,0.08651974,666.80881808,0.00087757,0.10403704,693.27641392,-0.04994557,-0.05409147,0.00000000,0.00000000,0.00000000,0.00000000
141.60000000,2.72439300,9.31700000,0.09179989,612.39647693,0.08782761,668.61440547,0.00098394,0.10533386,694.84067033,-0.05061197,-0.05472189,0.00000000,0.00000000,0.00000000,0.00000000
143.10000000,2.76561100,9.33000000,0.09315344,613.25095307,0.08906659,670.37739166,0.00084808,0.10667878,696.29421753,-0.05127948,-0.05539929,0.00000000,0.00000000,0.00000000,0.00000000
144.60000000,2.80662900,9.34300000,0.09459544,614.10542921,0.09038484,672.19700522,0.00089409,0.10800536,697.81131624,-0.05193346,-0.05607190,0.00000000,0.00000000,0.00000000,0.00000000
146.10000000,2.84774700,9.35400000,0.09599322,614.82844748,0.09166100,673.84781127,0.00083250,0.10928416,699.29769949,-0.05252091,-0.05676325,0.00000000,0.00000000,0.00000000,0.00000000
147.60000000,2.88912900,9.36600000,0.09738367,615.61719469,0.09292886,675.56825437,0.00081139,0.11064266,700.91672192,-0.05321769,-0.05742497,0.00000000,0.00000000,0.00000000,0.00000000
149.10000000,2.93081000,9.37900000,0.09881089,616.47167083,0.09422858,677.38578460,0.00083724,0.11199393,702.31174004,-0.05385662,-0.05813731,0.00000000,0.00000000,0.00000000,0.00000000
150.60000000,2.97248900,9.38900000,0.10021967,617.12896017,0.09550986,678.97741885,0.00084284,0.11335556,703.86480512,-0.05451494,-0.05884062,0.00000000,0.00000000,0.00000000,0.00000000
152.10000000,3.01410400,9.40100000,0.10163944,617.91770737,0.09679947,680.72251986,0.00082157,0.11472271,705.27628913,-0.05517572,-0.05954699,0.00000000,0.00000000,0.00000000,0.00000000
153.60000000,3.05591700,9.41100000,0.10307411,618.57499671,0.09810093,682.33406466,0.00077415,0.11608822,706.61485342,-0.05586402,-0.06022420,0.00000000,0.00000000,0.00000000,0.00000000
155.10000000,3.09829200,9.42100000,0.10452322,619.23228605,0.09941377,683.95643989,0.00087941,0.11743504,708.09133883,-0.05651729,-0.06091775,0.00000000,0.00000000,0.00000000,0.00000000
156.60000000,3.13983900,9.43000000,0.10597622,619.82384646,0.10072840,685.51043615,0.00092489,0.11884506,709.54100638,-0.05725028,-0.06159478,0.00000000,0.00000000,0.00000000,0.00000000
158.10000000,3.18241300,9.44000000,0.10741811,620.48113580,0.10203128,687.13204738,0.00086386,0.12019807,710.95270189,-0.05785175,-0.06234632,0.00000000,0.00000000,0.00000000,0.00000000
159.60000000,3.22445700,9.44800000,0.10891156,621.00696727,0.10337895,688.64180208,0.00095572,0.12158848,712.31893335,-0.05855349,-0.06303500,0.00000000,0.00000000,0.00000000,0.00000000
161.10000000,3.26709600,9.45900000,0.11038278,621.72998554,0.10470480,690.35826837,0.00096747,0.12298615,713.76763704,-0.05928049,-0.06370566,0.00000000,0.00000000,0.00000000,0.00000000
162.60000000,3.30980200,9.46700000,0.11182844,622.25581701,0.10600591,691.84171707,0.00097281,0.12436300,715.12913252,-0.05993759,-0.06442541,0.00000000,0.00000000,0.00000000,0.00000000
164.10000000,3.35277300,9.47400000,0.11331089,622.71591955,0.10733836,693.27641392,0.00092518,0.12574792,716.42379589,-0.06059027,-0.06515765,0.00000000,0.00000000,0.00000000,0.00000000
165.60000000,3.39505100,9.48300000,0.11476389,623.30747995,0.10864262,694.84067033,0.00084500,0.12716573,717.81952389,-0.06129314,-0.06587259,0.00000000,0.00000000,0.00000000,0.00000000
167.10000000,3.43825300,9.49000000,0.11627189,623.76758249,0.10999446,696.29421753,0.00089624,0.12853382,719.10665221,-0.06196453,-0.06656929,0.00000000,0.00000000,0.00000000,0.00000000
168.60000000,3.48129000,9.49800000,0.11776178,624.29341396,0.11132827,697.81131624,0.00082304,0.12997042,720.52085180,-0.06268925,-0.06728117,0.00000000,0.00000000,0.00000000,0.00000000
170.10000000,3.52439500,9.50600000,0.11920000,624.81924543,0.11261414,699.29769949,0.00072327,0.13141457,721.86764587,-0.06340972,-0.06800485,0.00000000,0.00000000,0.00000000,0.00000000
171.60000000,3.56766300,9.51500000,0.12073011,625.41080584,0.11398036,700.91672192,0.00082721,0.13283121,723.19687111,-0.06408819,-0.06874302,0.00000000,0.00000000,0.00000000,0.00000000
173.10000000,3.61159400,9.52100000,0.12225300,625.80517944,0.11533827,702.31174004,0.00087878,0.13425537,724.53389780,-0.06475970,-0.06949567,0.00000000,0.00000000,0.00000000,0.00000000
174.60000000,3.65539200,9.52900000,0.12379044,626.33101091,0.11670730,703.86480512,0.00090369,0.13573536,725.83813739,-0.06551636,-0.07021899,0.00000000,0.00000000,0.00000000,0.00000000
176.10000000,3.69945500,9.53500000,0.12533544,626.72538451,0.11808116,705.27628913,0.00092853,0.13715218,727.17448245,-0.06621224,-0.07093993,0.00000000,0.00000000,0.00000000,0.00000000
177.60000000,3.74335500,9.54000000,0.12688033,627.05402918,0.11945305,706.61485342,0.00102512,0.13860546,728.46380538,-0.06696145,-0.07164402,0.00000000,0.00000000,0.00000000,0.00000000
179.10000000,3.78731900,9.54700000,0.12840700,627.51413172,0.12080690,708.09133883,0.00095221,0.14006024,729.68030548,-0.06765690,-0.07240335,0.00000000,0.00000000,0.00000000,0.00000000
180.60000000,3.83151500,9.55300000,0.13000700,627.90850532,0.12222383,709.54100638,0.00105494,0.14151487,731.12745146,-0.06837683,-0.07313804,0.00000000,0.00000000,0.00000000,0.00000000
182.10000000,3.87617500,9.55900000,0.13154456,628.30287893,0.12358356,710.95270189,0.00100144,0.14300625,732.45156234,-0.06913591,-0.07387033,0.00000000,0.00000000,0.00000000,0.00000000
183.60000000,3.92090200,9.56400000,0.13312633,628.63152360,0.12498048,712.31893335,0.00089625,0.14448879,733.77150478,-0.06983624,-0.07465255,0.00000000,0.00000000,0.00000000,0.00000000
185.10000000,3.96566100,9.57000000,0.13471900,629.02589720,0.12638504,713.76763704,0.00091458,0.14598576,734.95122015,-0.07055438,-0.07543139,0.00000000,0.00000000,0.00000000,0.00000000
186.60000000,4.01095000,9.57500000,0.13628978,629.35454187,0.12776837,715.12913252,0.00100371,0.14743577,736.25154843,-0.07126232,-0.07617345,0.00000000,0.00000000,0.00000000,0.00000000
188.10000000,4.05567600,9.57900000,0.13787156,629.61745760,0.12915946,716.42379589,0.00084073,0.14894686,737.52250218,-0.07199868,-0.07694818,0.00000000,0.00000000,0.00000000,0.00000000
189.60000000,4.10096300,9.58400000,0.13949356,629.94610227,0.13058391,717.81952389,0.00094918,0.15051793,738.91704186,-0.07280733,-0.07771059,0.00000000,0.00000000,0.00000000,0.00000000
191.10000000,4.14635200,9.58800000,0.14106056,630.20901801,0.13195814,719.10665221,0.00092197,0.15205615,740.13562764,-0.07361058,-0.07844557,0.00000000,0.00000000,0.00000000,0.00000000
192.60000000,4.19194000,9.59300000,0.14270867,630.53766268,0.13340147,720.52085180,0.00096636,0.15359135,741.43115113,-0.07433680,-0.07925455,0.00000000,0.00000000,0.00000000,0.00000000
194.10000000,4.23782400,9.59700000,0.14436744,630.80057841,0.13485203,721.86764587,0.00099682,0.15515573,742.75066794,-0.07509580,-0.08005993,0.00000000,0.00000000,0.00000000,0.00000000
195.60000000,4.28357800,9.60100000,0.14599700,631.06349415,0.13627500,723.19687111,0.00096941,0.15674876,744.09391096,-0.07588247,-0.08086629,0.00000000,0.00000000,0.00000000,0.00000000
197.10000000,4.32952800,9.60500000,0.14763756,631.32640989,0.13770553,724.53389780,0.00088472,0.15827773,745.23653261,-0.07660981,-0.08166792,0.00000000,0.00000000,0.00000000,0.00000000
198.60000000,4.37534700,9.60800000,0.14934444,631.52359669,0.13919173,725.83813739,0.00101784,0.15989716,746.52635292,-0.07741884,-0.08247832,0.00000000,0.00000000,0.00000000,0.00000000
200.10000000,4.42149600,9.61200000,0.15098133,631.78651242,0.14061491,727.17448245,0.00093353,0.16148270,747.87077133,-0.07813621,-0.08334649,0.00000000,0.00000000,0.00000000,0.00000000
201.60000000,4.46721500,9.61500000,0.15266233,631.98369922,0.14207434,728.46380538,0.00095126,0.16312802,749.18461102,-0.07895347,-0.08417455,0.00000000,0.00000000,0.00000000,0.00000000
203.10000000,4.51386100,9.61700000,0.15434711,632.11515709,0.14353491,729.68030548,0.00094332,0.16477062,750.49870699,-0.07972892,-0.08504170,0.00000000,0.00000000,0.00000000,0.00000000
204.60000000,4.56050800,9.62200000,0.15603544,632.44380176,0.14499643,731.12745146,0.00089714,0.16641097,751.73522162,-0.08053543,-0.08587553,0.00000000,0.00000000,0.00000000,0.00000000
206.10000000,4.60788100,9.62500000,0.15776811,632.64098856,0.14649411,732.45156234,0.00092172,0.16811015,753.01824561,-0.08140889,-0.08670126,0.00000000,0.00000000,0.00000000,0.00000000
207.60000000,4.65469200,9.62800000,0.15949311,632.83817536,0.14798294,733.77150478,0.00099647,0.16974453,754.33285899,-0.08216432,-0.08758020,0.00000000,0.00000000,0.00000000,0.00000000
209.10000000,4.70143700,9.62900000,0.16123667,632.90390430,0.14948553,734.95122015,0.00098214,0.00000000,0.00000000,0.00000000,0.00000000,0.00000000,0.00000000,0.00000000,0.00000000
210.60000000,4.74848000,9.63200000,0.16292889,633.10109110,0.15094173,736.25154843,0.00101245,0.00000000,0.00000000,0.00000000,0.00000000,0.00000000,0.00000000,0.00000000,0.00000000
212.10000000,4.79635000,9.63400000,0.16469456,633.23254897,0.15245887,737.52250218,0.00094773,0.00000000,0.00000000,0.00000000,0.00000000,0.00000000,0.00000000,0.00000000,0.00000000
213.60000000,4.84421900,9.63700000,0.16653356,633.42973577,0.15403658,738.91704186,0.00113531,0.00000000,0.00000000,0.00000000,0.00000000,0.00000000,0.00000000,0.00000000,0.00000000
215.10000000,4.89222300,9.63800000,0.16833611,633.49546470,0.15558061,740.13562764,0.00100757,0.00000000,0.00000000,0.00000000,0.00000000,0.00000000,0.00000000,0.00000000,0.00000000
216.60000000,4.94029100,9.64000000,0.17013833,633.62692257,0.15712198,741.43115113,0.00106892,0.00000000,0.00000000,0.00000000,0.00000000,0.00000000,0.00000000,0.00000000,0.00000000
218.10000000,4.98899000,9.64200000,0.17197767,633.75838044,0.15869264,742.75066794,0.00100425,0.00000000,0.00000000,0.00000000,0.00000000,0.00000000,0.00000000,0.00000000,0.00000000
219.60000000,5.03792000,9.64400000,0.17385367,633.88983831,0.16029207,744.09391096,0.00106553,0.00000000,0.00000000,0.00000000,0.00000000,0.00000000,0.00000000,0.00000000,0.00000000
221.10000000,5.08641900,9.64400000,0.17565622,633.88983831,0.16182648,745.23653261,0.00100168,0.00000000,0.00000000,0.00000000,0.00000000,0.00000000,0.00000000,0.00000000,0.00000000
222.60000000,5.13528300,9.64500000,0.17756889,633.95556724,0.16345205,746.52635292,0.00099986,0.00000000,0.00000000,0.00000000,0.00000000,0.00000000,0.00000000,0.00000000,0.00000000
224.10000000,5.18447800,9.64700000,0.17944500,634.08702511,0.16504399,747.87077133,0.00106086,0.00000000,0.00000000,0.00000000,0.00000000,0.00000000,0.00000000,0.00000000,0.00000000
225.60000000,5.23430100,9.64800000,0.18139456,634.15275404,0.16669557,749.18461102,0.00112159,0.00000000,0.00000000,0.00000000,0.00000000,0.00000000,0.00000000,0.00000000,0.00000000
227.10000000,5.28409300,9.64900000,0.18334411,634.21848298,0.16834442,750.49870699,0.00118156,0.00000000,0.00000000,0.00000000,0.00000000,0.00000000,0.00000000,0.00000000,0.00000000
228.60000000,5.33375000,9.64900000,0.18529378,634.21848298,0.16999066,751.73522162,0.00111771,0.00000000,0.00000000,0.00000000,0.00000000,0.00000000,0.00000000,0.00000000,0.00000000
230.10000000,5.38370500,9.64900000,0.18731678,634.21848298,0.17169595,753.01824561,0.00117742,0.00000000,0.00000000,0.00000000,0.00000000,0.00000000,0.00000000,0.00000000,0.00000000
231.60000000,5.43425800,9.65000000,0.18926633,634.28421191,0.17333659,754.33285899,0.00117567,0.00000000,0.00000000,0.00000000,0.00000000,0.00000000,0.00000000,0.00000000,0.00000000
233.10000000,5.48477800,9.65100000,0.19132622,634.34994084,0.00000000,0.00000000,0.00000000,0.00000000,0.00000000,0.00000000,0.00000000,0.00000000,0.00000000,0.00000000,0.00000000
234.60000000,5.53546200,9.65000000,0.19331256,634.28421191,0.00000000,0.00000000,0.00000000,0.00000000,0.00000000,0.00000000,0.00000000,0.00000000,0.00000000,0.00000000,0.00000000
236.10000000,5.58651100,9.65100000,0.19537233,634.34994084,0.00000000,0.00000000,0.00000000,0.00000000,0.00000000,0.00000000,0.00000000,0.00000000,0.00000000,0.00000000,0.00000000
237.60000000,5.63815600,9.65100000,0.19750578,634.34994084,0.00000000,0.00000000,0.00000000,0.00000000,0.00000000,0.00000000,0.00000000,0.00000000,0.00000000,0.00000000,0.00000000
239.10000000,5.68956700,9.65000000,0.19967600,634.28421191,0.00000000,0.00000000,0.00000000,0.00000000,0.00000000,0.00000000,0.00000000,0.00000000,0.00000000,0.00000000,0.00000000
240.60000000,5.74088300,9.65000000,0.20180967,634.28421191,0.00000000,0.00000000,0.00000000,0.00000000,0.00000000,0.00000000,0.00000000,0.00000000,0.00000000,0.00000000,0.00000000
242.10000000,5.79292500,9.64900000,0.20397989,634.21848298,0.00000000,0.00000000,0.00000000,0.00000000,0.00000000,0.00000000,0.00000000,0.00000000,0.00000000,0.00000000,0.00000000
243.60000000,5.84453600,9.64900000,0.20622367,634.21848298,0.00000000,0.00000000,0.00000000,0.00000000,0.00000000,0.00000000,0.00000000,0.00000000,0.00000000,0.00000000,0.00000000
245.10000000,5.89700900,9.64800000,0.20846733,634.15275404,0.00000000,0.00000000,0.00000000,0.00000000,0.00000000,0.00000000,0.00000000,0.00000000,0.00000000,0.00000000,0.00000000
246.60000000,5.95007800,9.64700000,0.21078467,634.08702511,0.00000000,0.00000000,0.00000000,0.00000000,0.00000000,0.00000000,0.00000000,0.00000000,0.00000000,0.00000000,0.00000000
248.10000000,6.00235100,9.64500000,0.21306533,633.95556724,0.00000000,0.00000000,0.00000000,0.00000000,0.00000000,0.00000000,0.00000000,0.00000000,0.00000000,0.00000000,0.00000000
249.60000000,6.05558700,9.64400000,0.21549322,633.88983831,0.00000000,0.00000000,0.00000000,0.00000000,0.00000000,0.00000000,0.00000000,0.00000000,0.00000000,0.00000000,0.00000000
251.10000000,6.10978000,9.64300000,0.21792100,633.82410937,0.00000000,0.00000000,0.00000000,0.00000000,0.00000000,0.00000000,0.00000000,0.00000000,0.00000000,0.00000000,0.00000000
252.60000000,6.16258300,9.64100000,0.22038544,633.69265151,0.00000000,0.00000000,0.00000000,0.00000000,0.00000000,0.00000000,0.00000000,0.00000000,0.00000000,0.00000000,0.00000000
254.10000000,6.21614800,9.63800000,0.22292367,633.49546470,0.00000000,0.00000000,0.00000000,0.00000000,0.00000000,0.00000000,0.00000000,0.00000000,0.00000000,0.00000000,0.00000000
255.60000000,6.27041000,9.63700000,0.22546178,633.42973577,0.00000000,0.00000000,0.00000000,0.00000000,0.00000000,0.00000000,0.00000000,0.00000000,0.00000000,0.00000000,0.00000000
257.10000000,6.32493500,9.63500000,0.22811033,633.29827790,0.00000000,0.00000000,0.00000000,0.00000000,0.00000000,0.00000000,0.00000000,0.00000000,0.00000000,0.00000000,0.00000000
258.60000000,6.37985700,9.63400000,0.23083222,633.23254897,0.00000000,0.00000000,0.00000000,0.00000000,0.00000000,0.00000000,0.00000000,0.00000000,0.00000000,0.00000000,0.00000000
260.10000000,6.43517600,9.63000000,0.23355422,632.96963323,0.00000000,0.00000000,0.00000000,0.00000000,0.00000000,0.00000000,0.00000000,0.00000000,0.00000000,0.00000000,0.00000000
261.60000000,6.49006600,9.62700000,0.23642344,632.77244643,0.00000000,0.00000000,0.00000000,0.00000000,0.00000000,0.00000000,0.00000000,0.00000000,0.00000000,0.00000000,0.00000000
263.10000000,6.54597900,9.62500000,0.23940289,632.64098856,0.00000000,0.00000000,0.00000000,0.00000000,0.00000000,0.00000000,0.00000000,0.00000000,0.00000000,0.00000000,0.00000000
264.60000000,6.60156500,9.62000000,0.24238244,632.31234389,0.00000000,0.00000000,0.00000000,0.00000000,0.00000000,0.00000000,0.00000000,0.00000000,0.00000000,0.00000000,0.00000000
266.10000000,6.65807600,9.61700000,0.24547222,632.11515709,0.00000000,0.00000000,0.00000000,0.00000000,0.00000000,0.00000000,0.00000000,0.00000000,0.00000000,0.00000000,0.00000000
267.60000000,6.71438800,9.61400000,0.24859889,631.91797029,0.00000000,0.00000000,0.00000000,0.00000000,0.00000000,0.00000000,0.00000000,0.00000000,0.00000000,0.00000000,0.00000000
269.10000000,6.77156000,9.61000000,0.25183589,631.65505456,0.00000000,0.00000000,0.00000000,0.00000000,0.00000000,0.00000000,0.00000000,0.00000000,0.00000000,0.00000000,0.00000000
270.60000000,6.82873200,9.60600000,0.25518322,631.39213882,0.00000000,0.00000000,0.00000000,0.00000000,0.00000000,0.00000000,0.00000000,0.00000000,0.00000000,0.00000000,0.00000000
272.10000000,6.88603900,9.60000000,0.25871444,630.99776522,0.00000000,0.00000000,0.00000000,0.00000000,0.00000000,0.00000000,0.00000000,0.00000000,0.00000000,0.00000000,0.00000000
273.60000000,6.94410500,9.59600000,0.26228233,630.73484948,0.00000000,0.00000000,0.00000000,0.00000000,0.00000000,0.00000000,0.00000000,0.00000000,0.00000000,0.00000000,0.00000000
275.10000000,7.00141200,9.59000000,0.26588722,630.34047588,0.00000000,0.00000000,0.00000000,0.00000000,0.00000000,0.00000000,0.00000000,0.00000000,0.00000000,0.00000000,0.00000000
276.60000000,7.05964400,9.58400000,0.26974967,629.94610227,0.00000000,0.00000000,0.00000000,0.00000000,0.00000000,0.00000000,0.00000000,0.00000000,0.00000000,0.00000000,0.00000000
278.10000000,7.11767700,9.57800000,0.27368556,629.55172867,0.00000000,0.00000000,0.00000000,0.00000000,0.00000000,0.00000000,0.00000000,0.00000000,0.00000000,0.00000000,0.00000000
279.60000000,7.17630700,9.57000000,0.27773189,629.02589720,0.00000000,0.00000000,0.00000000,0.00000000,0.00000000,0.00000000,0.00000000,0.00000000,0.00000000,0.00000000,0.00000000
281.10000000,7.23583000,9.56400000,0.28196200,628.63152360,0.00000000,0.00000000,0.00000000,0.00000000,0.00000000,0.00000000,0.00000000,0.00000000,0.00000000,0.00000000,0.00000000
282.60000000,7.29489000,9.55400000,0.28630256,627.97423426,0.00000000,0.00000000,0.00000000,0.00000000,0.00000000,0.00000000,0.00000000,0.00000000,0.00000000,0.00000000,0.00000000
284.10000000,7.35418000,9.54600000,0.29075333,627.44840279,0.00000000,0.00000000,0.00000000,0.00000000,0.00000000,0.00000000,0.00000000,0.00000000,0.00000000,0.00000000,0.00000000
285.60000000,7.41353900,9.53500000,0.29542500,626.72538451,0.00000000,0.00000000,0.00000000,0.00000000,0.00000000,0.00000000,0.00000000,0.00000000,0.00000000,0.00000000,0.00000000
287.10000000,7.47289700,9.52500000,0.30020722,626.06809518,0.00000000,0.00000000,0.00000000,0.00000000,0.00000000,0.00000000,0.00000000,0.00000000,0.00000000,0.00000000,0.00000000
288.60000000,7.53314800,9.51400000,0.30520967,625.34507690,0.00000000,0.00000000,0.00000000,0.00000000,0.00000000,0.00000000,0.00000000,0.00000000,0.00000000,0.00000000,0.00000000
290.10000000,7.59353100,9.50200000,0.31032278,624.55632970,0.00000000,0.00000000,0.00000000,0.00000000,0.00000000,0.00000000,0.00000000,0.00000000,0.00000000,0.00000000,0.00000000
291.60000000,7.65398000,9.48700000,0.31558300,623.57039569,0.00000000,0.00000000,0.00000000,0.00000000,0.00000000,0.00000000,0.00000000,0.00000000,0.00000000,0.00000000,0.00000000
293.10000000,7.71370200,9.47200000,0.32102689,622.58446168,0.00000000,0.00000000,0.00000000,0.00000000,0.00000000,0.00000000,0.00000000,0.00000000,0.00000000,0.00000000,0.00000000
294.60000000,7.77478100,9.45800000,0.32654444,621.66425661,0.00000000,0.00000000,0.00000000,0.00000000,0.00000000,0.00000000,0.00000000,0.00000000,0.00000000,0.00000000,0.00000000
296.10000000,7.83612400,9.43900000,0.33228278,620.41540686,0.00000000,0.00000000,0.00000000,0.00000000,0.00000000,0.00000000,0.00000000,0.00000000,0.00000000,0.00000000,0.00000000
297.60000000,7.89614400,9.42000000,0.33805800,619.16655712,0.00000000,0.00000000,0.00000000,0.00000000,0.00000000,0.00000000,0.00000000,0.00000000,0.00000000,0.00000000,0.00000000
299.10000000,7.95715500,9.40000000,0.34405367,617.85197844,0.00000000,0.00000000,0.00000000,0.00000000,0.00000000,0.00000000,0.00000000,0.00000000,0.00000000,0.00000000,0.00000000
300.60000000,8.01843300,9.38100000,0.35012300,616.60312870,0.00000000,0.00000000,0.00000000,0.00000000,0.00000000,0.00000000,0.00000000,0.00000000,0.00000000,0.00000000,0.00000000
302.10000000,8.07994100,9.35500000,0.35633956,614.89417642,0.00000000,0.00000000,0.00000000,0.00000000,0.00000000,0.00000000,0.00000000,0.00000000,0.00000000,0.00000000,0.00000000
303.60000000,8.14267500,9.33200000,0.36274000,613.38241094,0.00000000,0.00000000,0.00000000,0.00000000,0.00000000,0.00000000,0.00000000,0.00000000,0.00000000,0.00000000,0.00000000
305.10000000,8.20391800,9.30400000,0.36914056,611.54200079,0.00000000,0.00000000,0.00000000,0.00000000,0.00000000,0.00000000,0.00000000,0.00000000,0.00000000,0.00000000,0.00000000
306.60000000,8.26542800,9.27600000,0.37565122,609.70159064,0.00000000,0.00000000,0.00000000,0.00000000,0.00000000,0.00000000,0.00000000,0.00000000,0.00000000,0.00000000,0.00000000
308.10000000,8.32693900,9.24500000,0.38223567,607.66399369,0.00000000,0.00000000,0.00000000,0.00000000,0.00000000,0.00000000,0.00000000,0.00000000,0.00000000,0.00000000,0.00000000
309.60000000,8.38901300,9.21600000,0.38893056,605.75785461,0.00000000,0.00000000,0.00000000,0.00000000,0.00000000,0.00000000,0.00000000,0.00000000,0.00000000,0.00000000,0.00000000
311.10000000,8.45138200,9.17700000,0.39577256,603.19442619,0.00000000,0.00000000,0.00000000,0.00000000,0.00000000,0.00000000,0.00000000,0.00000000,0.00000000,0.00000000,0.00000000
312.60000000,8.51425100,9.14400000,0.40257778,601.02537137,0.00000000,0.00000000,0.00000000,0.00000000,0.00000000,0.00000000,0.00000000,0.00000000,0.00000000,0.00000000,0.00000000
314.10000000,8.57724900,9.10100000,0.40941978,598.19902721,0.00000000,0.00000000,0.00000000,0.00000000,0.00000000,0.00000000,0.00000000,0.00000000,0.00000000,0.00000000,0.00000000
315.60000000,8.64018500,9.05900000,0.41644589,595.43841199,0.00000000,0.00000000,0.00000000,0.00000000,0.00000000,0.00000000,0.00000000,0.00000000,0.00000000,0.00000000,0.00000000
317.10000000,8.70312300,9.01000000,0.42339833,592.21769423,0.00000000,0.00000000,0.00000000,0.00000000,0.00000000,0.00000000,0.00000000,0.00000000,0.00000000,0.00000000,0.00000000
318.60000000,8.76642200,8.96400000,0.43053500,589.19416327,0.00000000,0.00000000,0.00000000,0.00000000,0.00000000,0.00000000,0.00000000,0.00000000,0.00000000,0.00000000,0.00000000
320.10000000,8.82999000,8.90200000,0.43763511,585.11896937,0.00000000,0.00000000,0.00000000,0.00000000,0.00000000,0.00000000,0.00000000,0.00000000,0.00000000,0.00000000,0.00000000
321.60000000,8.89442100,8.84700000,0.44484589,581.50387801,0.00000000,0.00000000,0.00000000,0.00000000,0.00000000,0.00000000,0.00000000,0.00000000,0.00000000,0.00000000,0.00000000
323.10000000,8.95911900,8.76800000,0.45205700,576.31129223,0.00000000,0.00000000,0.00000000,0.00000000,0.00000000,0.00000000,0.00000000,0.00000000,0.00000000,0.00000000,0.00000000
324.60000000,9.02395300,8.69900000,0.45937911,571.77599579,0.00000000,0.00000000,0.00000000,0.00000000,0.00000000,0.00000000,0.00000000,0.00000000,0.00000000,0.00000000,0.00000000
326.10000000,9.09057700,8.60800000,0.46684878,565.79466281,0.00000000,0.00000000,0.00000000,0.00000000,0.00000000,0.00000000,0.00000000,0.00000000,0.00000000,0.00000000,0.00000000
327.60000000,9.15710500,8.51700000,0.47435633,559.81332983,0.00000000,0.00000000,0.00000000,0.00000000,0.00000000,0.00000000,0.00000000,0.00000000,0.00000000,0.00000000,0.00000000
329.10000000,9.22579300,8.38400000,0.48215933,551.07138162,0.00000000,0.00000000,0.00000000,0.00000000,0.00000000,0.00000000,0.00000000,0.00000000,0.00000000,0.00000000,0.00000000
330.60000000,9.29740100,8.25600000,0.49033178,542.65807809,0.00000000,0.00000000,0.00000000,0.00000000,0.00000000,0.00000000,0.00000000,0.00000000,0.00000000,0.00000000,0.00000000
331.10000000,9.32423300,8.19400000,0.49346111,538.58288419,0.00000000,0.00000000,0.00000000,0.00000000,0.00000000,0.00000000,0.00000000,0.00000000,0.00000000,0.00000000,0.00000000