File: polyN_optimization/DP600_results/DATA/UT_90_3.csv
Time[s],Displacement[mm],Force[kN],EngStrain_longi,EngStress[MPa],TrueStrain,TrueStress[MPa],TrueStrainRate[1/s],PlasticStrain_longi,PlasticStress[MPa],PlasticStrain_thick,PlasticStrain_width,R-Value,Thickness[mm],Width[mm], Young's Modulus [MPa]
0.59000000,0.00000000,-0.01500000,0.00000000,-0.98173964,0.00000000,-0.98173964,0.00000000,0.00071729,337.91460510,0.00022933,-0.00094662,1.04013887,1.52790000,10.00000000,232067.32924230
2.10000000,0.00189800,-0.00200000,0.00006567,-0.13089862,0.00006566,-0.13090721,0.00002135,0.00112749,352.77903768,0.00003192,-0.00115941,0.00000000,0.00000000,0.00000000,0.00000000
3.60000000,0.00374400,0.45900000,0.00013789,30.04123306,0.00013788,30.04537542,0.00006177,0.00160871,367.35495460,-0.00006470,-0.00154401,0.00000000,0.00000000,0.00000000,0.00000000
5.09000000,0.00639900,0.74000000,0.00022589,48.43248904,0.00022586,48.44342940,0.00010587,0.00228523,378.59805069,-0.00028575,-0.00199948,0.00000000,0.00000000,0.00000000,0.00000000
6.59000000,0.00816400,1.09400000,0.00024678,71.60154460,0.00024675,71.61921427,0.00006021,0.00294344,390.50911911,-0.00058027,-0.00236317,0.00000000,0.00000000,0.00000000,0.00000000
8.10000000,0.01008100,1.45400000,0.00031378,95.16329603,0.00031373,95.19315615,0.00005401,0.00364642,400.54285532,-0.00092276,-0.00272367,0.00000000,0.00000000,0.00000000,0.00000000
9.60000000,0.01195800,1.78900000,0.00038922,117.08881471,0.00038915,117.13438828,-0.00002488,0.00440469,410.35023038,-0.00128627,-0.00311842,0.00000000,0.00000000,0.00000000,0.00000000
11.10000000,0.01464300,2.14900000,0.00048444,140.65056614,0.00048433,140.71870352,-0.00008907,0.00530138,419.30660296,-0.00171498,-0.00358640,0.00000000,0.00000000,0.00000000,0.00000000
12.60000000,0.01792100,2.48300000,0.00058156,162.51063551,0.00058139,162.60514448,-0.00015524,0.00620640,427.09279182,-0.00209865,-0.00410776,0.00000000,0.00000000,0.00000000,0.00000000
14.10000000,0.02122800,2.81300000,0.00072978,184.10890765,0.00072951,184.24326624,0.00015056,0.00702832,434.52617848,-0.00241618,-0.00461214,0.00000000,0.00000000,0.00000000,0.00000000
15.60000000,0.02445300,3.14100000,0.00086778,205.57628117,0.00086740,205.75467570,0.00031908,0.00786967,441.58316556,-0.00279246,-0.00507720,0.00000000,0.00000000,0.00000000,0.00000000
17.09000000,0.02752600,3.48800000,0.00092044,228.28719157,0.00092002,228.49731725,0.00031396,0.00881038,448.96212419,-0.00330635,-0.00550403,0.00000000,0.00000000,0.00000000,0.00000000
18.59000000,0.03077800,3.80500000,0.00096900,249.03462268,0.00096853,249.27593723,0.00016130,0.00979033,455.51009328,-0.00386325,-0.00592708,0.00000000,0.00000000,0.00000000,0.00000000
20.09000000,0.03552600,4.13900000,0.00105944,270.89469206,0.00105888,271.18168994,-0.00006750,0.01071193,461.91097017,-0.00432727,-0.00638466,0.00000000,0.00000000,0.00000000,0.00000000
21.59000000,0.04247900,4.43900000,0.00126556,290.52948491,0.00126476,290.89716612,-0.00014692,0.01160859,468.04590401,-0.00472578,-0.00688280,0.00000000,0.00000000,0.00000000,0.00000000
23.09000000,0.05059500,4.74100000,0.00158211,310.29517639,0.00158086,310.78609783,-0.00013933,0.01256498,474.35337921,-0.00512454,-0.00744044,0.00000000,0.00000000,0.00000000,0.00000000
24.59000000,0.06102800,4.98200000,0.00203844,326.06845998,0.00203637,326.73313242,0.00009559,0.01358114,480.10183113,-0.00563092,-0.00795021,0.00000000,0.00000000,0.00000000,0.00000000
26.09000000,0.07547000,5.20400000,0.00254622,340.59820669,0.00254299,341.46544541,0.00043317,0.01453404,485.96442698,-0.00610097,-0.00843307,0.00000000,0.00000000,0.00000000,0.00000000
27.59000000,0.09200100,5.45600000,0.00308000,357.09143269,0.00307527,358.19127430,0.00053576,0.01545942,491.42383431,-0.00655793,-0.00890149,0.00000000,0.00000000,0.00000000,0.00000000
29.09000000,0.10965800,5.63700000,0.00363244,368.93775771,0.00362586,370.27790361,0.00053568,0.01646040,496.66346836,-0.00710331,-0.00935709,0.00000000,0.00000000,0.00000000,0.00000000
30.59000000,0.13099000,5.84000000,0.00431389,382.22396754,0.00430461,383.87283926,0.00043307,0.01746872,501.64937391,-0.00761458,-0.00985414,0.00000000,0.00000000,0.00000000,0.00000000
32.09000000,0.15394800,5.98500000,0.00516422,391.71411742,0.00515093,393.73701617,0.00069586,0.01843515,506.89175302,-0.00805261,-0.01038254,0.00000000,0.00000000,0.00000000,0.00000000
33.59000000,0.18011900,6.14000000,0.00599233,401.85876039,0.00597445,404.26683204,0.00084136,0.01940690,511.61032680,-0.00848559,-0.01092131,0.00000000,0.00000000,0.00000000,0.00000000
35.09000000,0.20459800,6.27800000,0.00679111,410.89076510,0.00676816,413.68116994,0.00081883,0.02044101,516.57148158,-0.00892981,-0.01151120,0.00000000,0.00000000,0.00000000,0.00000000
36.59000000,0.23145700,6.39500000,0.00761178,418.54833432,0.00758295,421.73423123,0.00056974,0.02148312,521.07634520,-0.00947015,-0.01201297,0.00000000,0.00000000,0.00000000,0.00000000
38.09000000,0.25911000,6.51400000,0.00857600,426.33680215,0.00853944,429.99306656,0.00059851,0.02249659,525.37332002,-0.00992049,-0.01257610,0.00000000,0.00000000,0.00000000,0.00000000
39.59000000,0.28775600,6.61100000,0.00954367,432.68538517,0.00949841,436.81479026,0.00080184,0.02353390,529.69130746,-0.01047043,-0.01306347,0.00000000,0.00000000,0.00000000,0.00000000
41.09000000,0.31478200,6.71900000,0.01042333,439.75391060,0.01036938,444.33761219,0.00079388,0.02458763,534.09408543,-0.01101886,-0.01356877,0.00000000,0.00000000,0.00000000,0.00000000
42.59000000,0.34511700,6.81400000,0.01131378,445.97159500,0.01125026,451.01721852,0.00060393,0.02568078,538.18953468,-0.01161175,-0.01406903,0.00000000,0.00000000,0.00000000,0.00000000
44.09000000,0.37319900,6.90500000,0.01227778,451.92748217,0.01220302,457.47614736,0.00048719,0.02674038,542.34278900,-0.01213899,-0.01460139,0.00000000,0.00000000,0.00000000,0.00000000
45.59000000,0.40293400,6.99300000,0.01332633,457.68702140,0.01323832,463.78631121,0.00065362,0.02774372,546.06773646,-0.01258468,-0.01515904,0.00000000,0.00000000,0.00000000,0.00000000
47.09000000,0.43316600,7.08500000,0.01429767,463.70835788,0.01419642,470.33830541,0.00071809,0.02887743,549.93934110,-0.01316245,-0.01571498,0.00000000,0.00000000,0.00000000,0.00000000
48.59000000,0.46310000,7.16600000,0.01520289,469.00975195,0.01508848,476.14005509,0.00052936,0.02993974,553.50833971,-0.01370977,-0.01622997,0.00000000,0.00000000,0.00000000,0.00000000
50.09000000,0.49290100,7.24900000,0.01620000,474.44204464,0.01607018,482.12800576,0.00040569,0.03100332,557.35661037,-0.01421427,-0.01678905,0.00000000,0.00000000,0.00000000,0.00000000
51.59000000,0.52445800,7.31900000,0.01725967,479.02349630,0.01711241,487.29128217,0.00052850,0.03209247,560.81929332,-0.01476848,-0.01732399,0.00000000,0.00000000,0.00000000,0.00000000
53.09000000,0.55545300,7.40300000,0.01828256,484.52123830,0.01811744,493.37952476,0.00063581,0.03323947,564.52579203,-0.01535694,-0.01788254,0.00000000,0.00000000,0.00000000,0.00000000
54.59000000,0.58677800,7.46800000,0.01929078,488.77544342,0.01910707,498.20430188,0.00056322,0.03427726,567.76936565,-0.01585740,-0.01841986,0.00000000,0.00000000,0.00000000,0.00000000
56.09000000,0.61896500,7.54500000,0.02031000,493.81504025,0.02010650,503.84442372,0.00049795,0.03533578,570.96286563,-0.01635761,-0.01897817,0.00000000,0.00000000,0.00000000,0.00000000
57.59000000,0.65005700,7.60400000,0.02138067,497.67654951,0.02115531,508.31720593,0.00061277,0.03646707,574.20448607,-0.01693566,-0.01953141,0.00000000,0.00000000,0.00000000,0.00000000
59.09000000,0.68224200,7.67200000,0.02246233,502.12710256,0.02221377,513.40604891,0.00074127,0.03755401,577.56379088,-0.01743553,-0.02011848,0.00000000,0.00000000,0.00000000,0.00000000
60.59000000,0.71495600,7.72800000,0.02351456,505.79226389,0.02324235,517.68574418,0.00068295,0.03866556,580.67053906,-0.01797587,-0.02068969,0.00000000,0.00000000,0.00000000,0.00000000
62.09000000,0.74736900,7.79500000,0.02458511,510.17736763,0.02428776,522.72013490,0.00064665,0.03982137,583.87796831,-0.01856676,-0.02125461,0.00000000,0.00000000,0.00000000,0.00000000
63.59000000,0.78041300,7.84700000,0.02571444,513.58073172,0.02538939,526.78717492,0.00078205,0.04094558,586.79926617,-0.01908622,-0.02185937,0.00000000,0.00000000,0.00000000,0.00000000
65.09000000,0.81342300,7.91000000,0.02679589,517.70403822,0.02644317,531.57637811,0.00077386,0.04206816,589.72550927,-0.01961334,-0.02245482,0.00000000,0.00000000,0.00000000,0.00000000
66.59000000,0.84729500,7.95800000,0.02789589,520.84560508,0.02751389,535.37505621,0.00076590,0.04320087,592.52623518,-0.02014585,-0.02305502,0.00000000,0.00000000,0.00000000,0.00000000
68.09000000,0.88076900,8.01300000,0.02902167,524.44531710,0.02860851,539.66559428,0.00072984,0.04435590,595.48356491,-0.02073161,-0.02362428,0.00000000,0.00000000,0.00000000,0.00000000
69.59000000,0.91447400,8.05800000,0.03012122,527.39053603,0.02967649,543.27618356,0.00070705,0.04551019,598.30880140,-0.02132092,-0.02418927,0.00000000,0.00000000,0.00000000,0.00000000
71.09000000,0.94831100,8.11300000,0.03120633,530.99024805,0.03072931,547.56050673,0.00077055,0.04662123,601.11377269,-0.02185704,-0.02476419,0.00000000,0.00000000,0.00000000,0.00000000
72.59000000,0.98224800,8.15600000,0.03232478,533.80456836,0.03181332,551.05968241,0.00063427,0.04778757,603.81970737,-0.02245129,-0.02533628,0.00000000,0.00000000,0.00000000,0.00000000
74.09000000,1.01681600,8.20700000,0.03348367,537.14248315,0.03293530,555.12798300,0.00071959,0.04895295,606.39235690,-0.02302979,-0.02592316,0.00000000,0.00000000,0.00000000,0.00000000
75.59000000,1.05108400,8.24700000,0.03457967,539.76045553,0.03399523,558.42519216,0.00067564,0.05007921,608.87714781,-0.02357476,-0.02650446,0.00000000,0.00000000,0.00000000,0.00000000
77.09000000,1.08591500,8.29300000,0.03574200,542.77112376,0.03511808,562.17084927,0.00071008,0.05121346,611.57959517,-0.02415818,-0.02705528,0.00000000,0.00000000,0.00000000,0.00000000
78.59000000,1.12067800,8.33000000,0.03688967,545.19274822,0.03622553,565.30472697,0.00059567,0.05236509,614.02067819,-0.02471590,-0.02764920,0.00000000,0.00000000,0.00000000,0.00000000
80.09000000,1.15584300,8.37500000,0.03806711,548.13796714,0.03736044,569.00399604,0.00075903,0.05354234,616.62137679,-0.02525974,-0.02828260,0.00000000,0.00000000,0.00000000,0.00000000
81.59000000,1.19100400,8.41000000,0.03919633,550.42869298,0.03844766,572.00347950,0.00078602,0.05471234,619.01429779,-0.02585653,-0.02885580,0.00000000,0.00000000,0.00000000,0.00000000
83.09000000,1.22586800,8.45300000,0.04036967,553.24301329,0.03957610,575.57724932,0.00074945,0.05583968,621.31582529,-0.02639555,-0.02944413,0.00000000,0.00000000,0.00000000,0.00000000
84.59000000,1.26149100,8.48700000,0.04158000,555.46828981,0.04073879,578.56466130,0.00086895,0.05703478,623.66418761,-0.02700468,-0.03003011,0.00000000,0.00000000,0.00000000,0.00000000
86.09000000,1.29797800,8.52500000,0.04277178,557.95536357,0.04188234,581.82010639,0.00090335,0.05822454,626.08375970,-0.02758986,-0.03063468,0.00000000,0.00000000,0.00000000,0.00000000
87.59000000,1.33386800,8.55600000,0.04391944,559.98429217,0.04298233,584.57849118,0.00076117,0.05936939,628.27034405,-0.02812508,-0.03124431,0.00000000,0.00000000,0.00000000,0.00000000
89.09000000,1.36982300,8.59500000,0.04511144,562.53681524,0.04412353,587.91366353,0.00076732,0.06054975,630.62352628,-0.02870693,-0.03184283,0.00000000,0.00000000,0.00000000,0.00000000
90.59000000,1.40640800,8.62500000,0.04634367,564.50029452,0.04530186,590.66130800,0.00085097,0.06176758,632.79510202,-0.02933710,-0.03243048,0.00000000,0.00000000,0.00000000,0.00000000
92.09000000,1.44285900,8.66100000,0.04754289,566.85646966,0.04644732,593.80646382,0.00084979,0.06292858,635.00501334,-0.02987131,-0.03305728,0.00000000,0.00000000,0.00000000,0.00000000
93.59000000,1.47934300,8.68800000,0.04869811,568.62360102,0.04754950,596.31449632,0.00071594,0.06410959,637.09161433,-0.03042540,-0.03368419,0.00000000,0.00000000,0.00000000,0.00000000
95.09000000,1.51569600,8.72100000,0.04990089,570.78342823,0.04869577,599.26602867,0.00067298,0.06530227,639.26008283,-0.03103647,-0.03426581,0.00000000,0.00000000,0.00000000,0.00000000
96.59000000,1.55337400,8.74800000,0.05114789,572.55055959,0.04988279,601.83531200,0.00079823,0.06651493,641.30495509,-0.03164223,-0.03487270,0.00000000,0.00000000,0.00000000,0.00000000
98.09000000,1.59009000,8.78000000,0.05232144,574.64493750,0.05099862,604.71119067,0.00067143,0.06766754,643.38559799,-0.03220826,-0.03545929,0.00000000,0.00000000,0.00000000,0.00000000
99.59000000,1.62746900,8.80600000,0.05356111,576.34661954,0.05217596,607.21638487,0.00067085,0.06887036,645.43218241,-0.03278731,-0.03608305,0.00000000,0.00000000,0.00000000,0.00000000
101.09000000,1.66441600,8.83600000,0.05480444,578.31009883,0.05335539,610.00406251,0.00075352,0.07010940,647.43568858,-0.03344470,-0.03666470,0.00000000,0.00000000,0.00000000,0.00000000
102.59000000,1.70192600,8.85900000,0.05603300,579.81543295,0.05451943,612.30423110,0.00078738,0.07129892,649.48167271,-0.03402794,-0.03727099,0.00000000,0.00000000,0.00000000,0.00000000
104.09000000,1.73953700,8.88800000,0.05723967,581.71346292,0.05566142,615.01054764,0.00074485,0.07249465,651.39408548,-0.03457304,-0.03792161,0.00000000,0.00000000,0.00000000,0.00000000
105.59000000,1.77724600,8.91000000,0.05851233,583.15334773,0.05686446,617.27501080,0.00077167,0.07370202,653.38869927,-0.03514750,-0.03855452,0.00000000,0.00000000,0.00000000,0.00000000
107.09000000,1.81478900,8.93700000,0.05978511,584.92047909,0.05806616,619.89001492,0.00081228,0.07491567,655.17839700,-0.03572524,-0.03919043,0.00000000,0.00000000,0.00000000,0.00000000
108.59000000,1.85272900,8.95900000,0.06101389,586.36036390,0.05922495,622.13648999,0.00085324,0.07610992,657.17192748,-0.03627894,-0.03983098,0.00000000,0.00000000,0.00000000,0.00000000
110.09000000,1.89119900,8.98500000,0.06225711,588.06204595,0.06039599,624.67309008,0.00078276,0.07733788,658.90698831,-0.03690530,-0.04043259,0.00000000,0.00000000,0.00000000,0.00000000
111.59000000,1.92923800,9.00400000,0.06354089,589.30558283,0.06160380,626.75058339,0.00079582,0.07856993,660.86179131,-0.03753824,-0.04103170,0.00000000,0.00000000,0.00000000,0.00000000
113.09000000,1.96724600,9.02700000,0.06479167,590.81091694,0.06277916,629.09054094,0.00083602,0.07978452,662.59483435,-0.03812927,-0.04165525,0.00000000,0.00000000,0.00000000,0.00000000
114.59000000,2.00558400,9.04700000,0.06603500,592.11990314,0.06394616,631.22054094,0.00078687,0.08102748,664.49289018,-0.03873447,-0.04229301,0.00000000,0.00000000,0.00000000,0.00000000
116.09000000,2.04421800,9.07100000,0.06731878,593.69068656,0.06514969,633.65721796,0.00073760,0.08225624,666.17065024,-0.03936319,-0.04289306,0.00000000,0.00000000,0.00000000,0.00000000
117.59000000,2.08325300,9.08800000,0.06861367,594.80332482,0.06636217,635.61496189,0.00081951,0.08348615,667.99551976,-0.03994816,-0.04353798,0.00000000,0.00000000,0.00000000,0.00000000
119.09000000,2.12208600,9.11000000,0.06988633,596.24320963,0.06755241,637.91246133,0.00081812,0.08472218,669.68463919,-0.04052820,-0.04419399,0.00000000,0.00000000,0.00000000,0.00000000
120.59000000,2.16088900,9.12700000,0.07114833,597.35584790,0.06873128,639.85672088,0.00076983,0.08593964,671.36442765,-0.04107851,-0.04486114,0.00000000,0.00000000,0.00000000,0.00000000
122.09000000,2.20005300,9.14700000,0.07245778,598.66483409,0.06995300,642.04275760,0.00076848,0.08719920,673.07576590,-0.04170427,-0.04549494,0.00000000,0.00000000,0.00000000,0.00000000
123.59000000,2.23951600,9.16400000,0.07378200,599.77747235,0.07118700,644.03025381,0.00091142,0.08844371,674.78018408,-0.04227461,-0.04616910,0.00000000,0.00000000,0.00000000,0.00000000
125.09000000,2.27844900,9.18400000,0.07501800,601.08645854,0.07233741,646.17876248,0.00078712,0.08968375,676.41274422,-0.04291137,-0.04677238,0.00000000,0.00000000,0.00000000,0.00000000
126.59000000,2.31778000,9.20000000,0.07635700,602.13364749,0.07358219,648.11076641,0.00077953,0.09093553,678.05632587,-0.04351486,-0.04742068,0.00000000,0.00000000,0.00000000,0.00000000
128.09000000,2.35757400,9.21700000,0.07767022,603.24628575,0.07480151,650.10055882,0.00081963,0.09220257,679.64115398,-0.04417884,-0.04802374,0.00000000,0.00000000,0.00000000,0.00000000
129.59000000,2.39776600,9.23500000,0.07894289,604.42437332,0.07598176,652.13937947,0.00077045,0.09345447,681.29090909,-0.04482436,-0.04863011,0.00000000,0.00000000,0.00000000,0.00000000
131.09000000,2.43789100,9.25000000,0.08026356,605.40611297,0.07720504,653.99816015,0.00078330,0.09469186,682.86139509,-0.04543188,-0.04925998,0.00000000,0.00000000,0.00000000,0.00000000
132.59000000,2.47798300,9.26600000,0.08160244,606.45330192,0.07844369,655.94137380,0.00081624,0.09596113,684.38412706,-0.04607047,-0.04989066,0.00000000,0.00000000,0.00000000,0.00000000
134.09000000,2.51827200,9.28000000,0.08292667,607.36959225,0.07966725,657.73672797,0.00085589,0.09718249,685.87667516,-0.04664233,-0.05054016,0.00000000,0.00000000,0.00000000,0.00000000
135.59000000,2.55846300,9.29500000,0.08425089,608.35133189,0.08088932,659.60547236,0.00082757,0.09849078,687.57721419,-0.04731410,-0.05117668,0.00000000,0.00000000,0.00000000,0.00000000
137.09000000,2.59859000,9.30900000,0.08559367,609.26762223,0.08212700,661.41707199,0.00082020,0.09970606,688.99836828,-0.04788116,-0.05182490,0.00000000,0.00000000,0.00000000,0.00000000
138.59000000,2.63944100,9.32400000,0.08695089,610.24936187,0.08337643,663.31108633,0.00087338,0.10099247,690.47126066,-0.04849252,-0.05249995,0.00000000,0.00000000,0.00000000,0.00000000
140.09000000,2.68082400,9.33700000,0.08827500,611.10020289,0.08459387,665.04507330,0.00080429,0.10221114,691.89978912,-0.04905239,-0.05315876,0.00000000,0.00000000,0.00000000,0.00000000
141.59000000,2.72170900,9.35100000,0.08962867,612.01649323,0.08583697,666.87071549,0.00081696,0.10348753,693.37093947,-0.04968590,-0.05380163,0.00000000,0.00000000,0.00000000,0.00000000
143.09000000,2.76302700,9.36200000,0.09100100,612.73643563,0.08709562,668.49606401,0.00085709,0.10476529,694.91885944,-0.05032989,-0.05443541,0.00000000,0.00000000,0.00000000,0.00000000
144.59000000,2.80368000,9.37500000,0.09232156,613.58727665,0.08830530,670.23460850,0.00078828,0.10604229,696.32257835,-0.05096086,-0.05508143,0.00000000,0.00000000,0.00000000,0.00000000
146.09000000,2.84466500,9.38600000,0.09367133,614.30721906,0.08954023,671.85019534,0.00080723,0.10731372,697.79821614,-0.05159724,-0.05571648,0.00000000,0.00000000,0.00000000,0.00000000
147.59000000,2.88651100,9.40000000,0.09509122,615.22350939,0.09083767,673.72586484,0.00086668,0.10857406,699.19527194,-0.05221824,-0.05635582,0.00000000,0.00000000,0.00000000,0.00000000
149.09000000,2.92832300,9.41100000,0.09644856,615.94345180,0.09207637,675.35030803,0.00083884,0.10988214,700.62831301,-0.05287261,-0.05700953,0.00000000,0.00000000,0.00000000,0.00000000
150.59000000,2.97010300,9.42200000,0.09781333,616.66339420,0.09332032,676.98129633,0.00083112,0.11117840,702.05560680,-0.05352239,-0.05765601,0.00000000,0.00000000,0.00000000,0.00000000
152.09000000,3.01155300,9.43200000,0.09918167,617.31788730,0.09456596,678.54450422,0.00080318,0.11242124,703.37399873,-0.05414162,-0.05827962,0.00000000,0.00000000,0.00000000,0.00000000
153.59000000,3.05346500,9.44300000,0.10059433,618.03782970,0.09585034,680.20893315,0.00082276,0.11372068,704.80844359,-0.05478691,-0.05893376,0.00000000,0.00000000,0.00000000,0.00000000
155.09000000,3.09597300,9.45300000,0.10195900,618.69232280,0.09708950,681.77357334,0.00078159,0.11501246,706.16609758,-0.05542224,-0.05959022,0.00000000,0.00000000,0.00000000,0.00000000
156.59000000,3.13758500,9.46300000,0.10337878,619.34681589,0.09837709,683.37413274,0.00086702,0.11627956,707.50857776,-0.05603999,-0.06023958,0.00000000,0.00000000,0.00000000,0.00000000
158.09000000,3.17976200,9.47200000,0.10472889,619.93585968,0.09959996,684.86105344,0.00075971,0.11758131,708.80386346,-0.05664531,-0.06093600,0.00000000,0.00000000,0.00000000,0.00000000
159.59000000,3.22220400,9.48200000,0.10615956,620.59035277,0.10089416,686.47194880,0.00089117,0.11893641,710.13935337,-0.05732804,-0.06160836,0.00000000,0.00000000,0.00000000,0.00000000
161.09000000,3.26570500,9.49100000,0.10759789,621.17939656,0.10219361,688.01698825,0.00085729,0.12022129,711.50136024,-0.05795494,-0.06226635,0.00000000,0.00000000,0.00000000,0.00000000
162.59000000,3.30818000,9.50000000,0.10898822,621.76844034,0.10344809,689.53387729,0.00092217,0.12152762,712.80664441,-0.05859626,-0.06293136,0.00000000,0.00000000,0.00000000,0.00000000
164.09000000,3.35042300,9.50800000,0.11038244,622.29203482,0.10470450,690.98215078,0.00084814,0.12283867,714.11751710,-0.05922609,-0.06361258,0.00000000,0.00000000,0.00000000,0.00000000
165.59000000,3.39293100,9.51600000,0.11176189,622.81562930,0.10594604,692.42268045,0.00088028,0.12414502,715.35263499,-0.05988529,-0.06425974,0.00000000,0.00000000,0.00000000,0.00000000
167.09000000,3.43636700,9.52500000,0.11319267,623.40467308,0.10723216,693.96951044,0.00088574,0.12542019,716.64205317,-0.06048720,-0.06493300,0.00000000,0.00000000,0.00000000,0.00000000
168.59000000,3.47966900,9.53200000,0.11459433,623.86281825,0.10849051,695.35396200,0.00083216,0.12674550,717.89492702,-0.06113898,-0.06560652,0.00000000,0.00000000,0.00000000,0.00000000
170.09000000,3.52260600,9.54000000,0.11603989,624.38641272,0.10978661,696.84014268,0.00085698,0.12810832,719.10203844,-0.06183963,-0.06626869,0.00000000,0.00000000,0.00000000,0.00000000
171.59000000,3.56617500,9.54700000,0.11747067,624.84455789,0.11106780,698.24546467,0.00086245,0.12939429,720.40557819,-0.06245778,-0.06693651,0.00000000,0.00000000,0.00000000,0.00000000
173.09000000,3.61043600,9.55500000,0.11887967,625.36815237,0.11232789,699.71170986,0.00084865,0.13074343,721.68193887,-0.06314207,-0.06760137,0.00000000,0.00000000,0.00000000,0.00000000
174.59000000,3.65440100,9.56100000,0.12035467,625.76084822,0.11364530,701.07408652,0.00085368,0.13206547,722.86557432,-0.06375997,-0.06830550,0.00000000,0.00000000,0.00000000,0.00000000
176.09000000,3.69836400,9.56800000,0.12180400,626.21899339,0.11493810,702.49497166,0.00083316,0.13340760,724.14099188,-0.06445241,-0.06895519,0.00000000,0.00000000,0.00000000,0.00000000
177.59000000,3.74216300,9.57400000,0.12320911,626.61168925,0.11618987,703.81595849,0.00083845,0.13475518,725.27169200,-0.06511258,-0.06964259,0.00000000,0.00000000,0.00000000,0.00000000
179.09000000,3.78632600,9.58100000,0.12469867,627.06983441,0.11751515,705.26460667,0.00087648,0.13609357,726.54845689,-0.06576330,-0.07033026,0.00000000,0.00000000,0.00000000,0.00000000
180.59000000,3.83102100,9.58700000,0.12615189,627.46253027,0.11880641,706.61811367,0.00086251,0.13743034,727.82617110,-0.06641707,-0.07101327,0.00000000,0.00000000,0.00000000,0.00000000
182.09000000,3.87611200,9.59200000,0.12766011,627.78977682,0.12014479,707.93348948,0.00099227,0.13876593,728.95371752,-0.06706633,-0.07169960,0.00000000,0.00000000,0.00000000,0.00000000
183.59000000,3.92040700,9.59800000,0.12907622,628.18247267,0.12139980,709.26589311,0.00088647,0.14013147,730.10492801,-0.06771749,-0.07241398,0.00000000,0.00000000,0.00000000,0.00000000
185.09000000,3.96533200,9.60300000,0.13059911,628.50971922,0.12274768,710.59252988,0.00085932,0.14146352,731.23335842,-0.06836728,-0.07309624,0.00000000,0.00000000,0.00000000,0.00000000
186.59000000,4.01048800,9.60900000,0.13208156,628.90241508,0.12405802,711.96882436,0.00089727,0.14285629,732.56018910,-0.06907892,-0.07377737,0.00000000,0.00000000,0.00000000,0.00000000
188.09000000,4.05574500,9.61300000,0.13355667,629.16421232,0.12536018,713.19328730,0.00087649,0.14418469,733.68964033,-0.06969680,-0.07448789,0.00000000,0.00000000,0.00000000,0.00000000
189.59000000,4.10063800,9.61800000,0.13502067,629.49145887,0.12665086,714.48581530,0.00082326,0.14560593,734.88927674,-0.07042271,-0.07518322,0.00000000,0.00000000,0.00000000,0.00000000
191.09000000,4.14586000,9.62200000,0.13652867,629.75325610,0.12797859,715.73262849,0.00085425,0.14699370,736.06612835,-0.07112819,-0.07586552,0.00000000,0.00000000,0.00000000,0.00000000
192.59000000,4.19204100,9.62800000,0.13804789,630.14595196,0.12931442,717.13627032,0.00096328,0.14838000,737.16728893,-0.07179534,-0.07658465,0.00000000,0.00000000,0.00000000,0.00000000
194.09000000,4.23825800,9.63200000,0.13953033,630.40774920,0.13061619,718.36875258,0.00090428,0.14973236,738.32151598,-0.07248629,-0.07724607,0.00000000,0.00000000,0.00000000,0.00000000
195.59000000,4.28430900,9.63500000,0.14110844,630.60409713,0.13200011,719.58766033,0.00093498,0.15111455,739.42299268,-0.07311672,-0.07799783,0.00000000,0.00000000,0.00000000,0.00000000
197.09000000,4.32999400,9.63900000,0.14261667,630.86589436,0.13332095,720.83788533,0.00099232,0.15249500,740.52482201,-0.07381404,-0.07868096,0.00000000,0.00000000,0.00000000,0.00000000
198.59000000,4.37614400,9.64300000,0.14409911,631.12769160,0.13461752,722.07263096,0.00087502,0.15393579,741.75008034,-0.07453985,-0.07939594,0.00000000,0.00000000,0.00000000,0.00000000
200.09000000,4.42255900,9.64800000,0.14559989,631.45493815,0.13592842,723.39470698,0.00084146,0.15537485,742.89905967,-0.07525392,-0.08012093,0.00000000,0.00000000,0.00000000,0.00000000
201.59000000,4.46933700,9.65000000,0.14716300,631.58583677,0.13729194,724.53190327,0.00087210,0.15678061,744.02495032,-0.07595450,-0.08082611,0.00000000,0.00000000,0.00000000,0.00000000
203.09000000,4.51538700,9.65300000,0.14873022,631.78218470,0.13865718,725.74728942,0.00089665,0.15818475,745.07411899,-0.07662751,-0.08155724,0.00000000,0.00000000,0.00000000,0.00000000
204.59000000,4.56269600,9.65700000,0.15027511,632.04398194,0.14000114,727.02446155,0.00089564,0.15961720,746.30062622,-0.07732082,-0.08229638,0.00000000,0.00000000,0.00000000,0.00000000
206.09000000,4.60973900,9.65900000,0.15182011,632.17488056,0.14134340,728.15174116,0.00089444,0.16101715,747.34987069,-0.07800137,-0.08301578,0.00000000,0.00000000,0.00000000,0.00000000
207.59000000,4.65684900,9.66200000,0.15340178,632.37122848,0.14271564,729.37809915,0.00095701,0.16241531,748.39925603,-0.07866533,-0.08374997,0.00000000,0.00000000,0.00000000,0.00000000
209.09000000,4.70408800,9.66400000,0.15494667,632.50212710,0.14405417,730.50622336,0.00089201,0.16390459,749.51865675,-0.07942579,-0.08447880,0.00000000,0.00000000,0.00000000,0.00000000
210.59000000,4.75152800,9.66700000,0.15649167,632.69847503,0.14539100,731.71051389,0.00089082,0.00000000,0.00000000,0.00000000,0.00000000,0.00000000,0.00000000,0.00000000,0.00000000
212.09000000,4.79936600,9.67000000,0.15814689,632.89482296,0.14682122,732.98517020,0.00095309,0.00000000,0.00000000,0.00000000,0.00000000,0.00000000,0.00000000,0.00000000,0.00000000
213.59000000,4.84687400,9.67100000,0.15972867,632.96027227,0.14818607,734.06217261,0.00101525,0.00000000,0.00000000,0.00000000,0.00000000,0.00000000,0.00000000,0.00000000,0.00000000
215.09000000,4.89547100,9.67300000,0.16134722,633.09117089,0.14958073,735.23867272,0.00095065,0.00000000,0.00000000,0.00000000,0.00000000,0.00000000,0.00000000,0.00000000,0.00000000
216.59000000,4.94416900,9.67500000,0.16292878,633.22206951,0.15094163,736.39216735,0.00088570,0.00000000,0.00000000,0.00000000,0.00000000,0.00000000,0.00000000,0.00000000,0.00000000
218.09000000,4.99280200,9.67700000,0.16451067,633.35296813,0.15230097,737.54628715,0.00082131,0.00000000,0.00000000,0.00000000,0.00000000,0.00000000,0.00000000,0.00000000,0.00000000
219.59000000,5.04159900,9.67900000,0.16616600,633.48386675,0.15372144,738.74734695,0.00094653,0.00000000,0.00000000,0.00000000,0.00000000,0.00000000,0.00000000,0.00000000,0.00000000
221.09000000,5.09003300,9.67900000,0.16778433,633.48386675,0.15510822,739.77253500,0.00094522,0.00000000,0.00000000,0.00000000,0.00000000,0.00000000,0.00000000,0.00000000,0.00000000
222.59000000,5.13969000,9.68100000,0.16947656,633.61476536,0.15655626,740.99761335,0.00106990,0.00000000,0.00000000,0.00000000,0.00000000,0.00000000,0.00000000,0.00000000,0.00000000
224.09000000,5.18918300,9.68200000,0.17109489,633.68021467,0.15793911,742.09966059,0.00094236,0.00000000,0.00000000,0.00000000,0.00000000,0.00000000,0.00000000,0.00000000,0.00000000
225.59000000,5.23887600,9.68400000,0.17278722,633.81111329,0.15938316,743.32557497,0.00094138,0.00000000,0.00000000,0.00000000,0.00000000,0.00000000,0.00000000,0.00000000,0.00000000
227.09000000,5.28886400,9.68400000,0.17440544,633.81111329,0.16076201,744.35122220,0.00087685,0.00000000,0.00000000,0.00000000,0.00000000,0.00000000,0.00000000,0.00000000,0.00000000
228.59000000,5.33855700,9.68500000,0.17606078,633.87656260,0.16217053,745.47736323,0.00087562,0.00000000,0.00000000,0.00000000,0.00000000,0.00000000,0.00000000,0.00000000,0.00000000
230.09000000,5.38884400,9.68600000,0.17778967,633.94201191,0.16363952,746.65035090,0.00093700,0.00000000,0.00000000,0.00000000,0.00000000,0.00000000,0.00000000,0.00000000,0.00000000
231.59000000,5.43929600,9.68600000,0.17955533,633.94201191,0.16513753,747.76968117,0.00112315,0.00000000,0.00000000,0.00000000,0.00000000,0.00000000,0.00000000,0.00000000,0.00000000
233.09000000,5.48938600,9.68600000,0.18117400,633.94201191,0.16650886,748.79582198,0.00105949,0.00000000,0.00000000,0.00000000,0.00000000,0.00000000,0.00000000,0.00000000,0.00000000
234.59000000,5.54053400,9.68700000,0.18286600,634.00746122,0.16794031,749.94586962,0.00093317,0.00000000,0.00000000,0.00000000,0.00000000,0.00000000,0.00000000,0.00000000,0.00000000
236.09000000,5.59141700,9.68700000,0.18455789,634.00746122,0.00000000,0.00000000,0.00000000,0.00000000,0.00000000,0.00000000,0.00000000,0.00000000,0.00000000,0.00000000,0.00000000
237.59000000,5.64306100,9.68700000,0.18632367,634.00746122,0.00000000,0.00000000,0.00000000,0.00000000,0.00000000,0.00000000,0.00000000,0.00000000,0.00000000,0.00000000,0.00000000
239.09000000,5.69437500,9.68700000,0.18805244,634.00746122,0.00000000,0.00000000,0.00000000,0.00000000,0.00000000,0.00000000,0.00000000,0.00000000,0.00000000,0.00000000,0.00000000
240.59000000,5.74519300,9.68600000,0.18985500,633.94201191,0.00000000,0.00000000,0.00000000,0.00000000,0.00000000,0.00000000,0.00000000,0.00000000,0.00000000,0.00000000,0.00000000
242.09000000,5.79700300,9.68600000,0.19158378,633.94201191,0.00000000,0.00000000,0.00000000,0.00000000,0.00000000,0.00000000,0.00000000,0.00000000,0.00000000,0.00000000,0.00000000
243.59000000,5.84904500,9.68500000,0.19331267,633.87656260,0.00000000,0.00000000,0.00000000,0.00000000,0.00000000,0.00000000,0.00000000,0.00000000,0.00000000,0.00000000,0.00000000
245.09000000,5.90175000,9.68500000,0.19511489,633.87656260,0.00000000,0.00000000,0.00000000,0.00000000,0.00000000,0.00000000,0.00000000,0.00000000,0.00000000,0.00000000,0.00000000
246.59000000,5.95369200,9.68300000,0.19695422,633.74566398,0.00000000,0.00000000,0.00000000,0.00000000,0.00000000,0.00000000,0.00000000,0.00000000,0.00000000,0.00000000,0.00000000
248.09000000,6.00633000,9.68300000,0.19875667,633.74566398,0.00000000,0.00000000,0.00000000,0.00000000,0.00000000,0.00000000,0.00000000,0.00000000,0.00000000,0.00000000,0.00000000
249.59000000,6.05939800,9.68200000,0.20055900,633.68021467,0.00000000,0.00000000,0.00000000,0.00000000,0.00000000,0.00000000,0.00000000,0.00000000,0.00000000,0.00000000,0.00000000
251.09000000,6.11233400,9.68100000,0.20236144,633.61476536,0.00000000,0.00000000,0.00000000,0.00000000,0.00000000,0.00000000,0.00000000,0.00000000,0.00000000,0.00000000,0.00000000
252.59000000,6.16583400,9.67900000,0.20427433,633.48386675,0.00000000,0.00000000,0.00000000,0.00000000,0.00000000,0.00000000,0.00000000,0.00000000,0.00000000,0.00000000,0.00000000
254.09000000,6.21886800,9.67800000,0.20615022,633.41841744,0.00000000,0.00000000,0.00000000,0.00000000,0.00000000,0.00000000,0.00000000,0.00000000,0.00000000,0.00000000,0.00000000
255.59000000,6.27309600,9.67700000,0.20798933,633.35296813,0.00000000,0.00000000,0.00000000,0.00000000,0.00000000,0.00000000,0.00000000,0.00000000,0.00000000,0.00000000,0.00000000
257.09000000,6.32715800,9.67500000,0.20982889,633.22206951,0.00000000,0.00000000,0.00000000,0.00000000,0.00000000,0.00000000,0.00000000,0.00000000,0.00000000,0.00000000,0.00000000
258.59000000,6.38148400,9.67400000,0.21177844,633.15662020,0.00000000,0.00000000,0.00000000,0.00000000,0.00000000,0.00000000,0.00000000,0.00000000,0.00000000,0.00000000,0.00000000
260.09000000,6.43601000,9.67200000,0.21372789,633.02572158,0.00000000,0.00000000,0.00000000,0.00000000,0.00000000,0.00000000,0.00000000,0.00000000,0.00000000,0.00000000,0.00000000
261.59000000,6.49119800,9.66900000,0.21564056,632.82937365,0.00000000,0.00000000,0.00000000,0.00000000,0.00000000,0.00000000,0.00000000,0.00000000,0.00000000,0.00000000,0.00000000
263.09000000,6.54655000,9.66700000,0.21762700,632.69847503,0.00000000,0.00000000,0.00000000,0.00000000,0.00000000,0.00000000,0.00000000,0.00000000,0.00000000,0.00000000,0.00000000
264.59000000,6.60133900,9.66400000,0.21957667,632.50212710,0.00000000,0.00000000,0.00000000,0.00000000,0.00000000,0.00000000,0.00000000,0.00000000,0.00000000,0.00000000,0.00000000
266.09000000,6.65712200,9.66200000,0.22148944,632.37122848,0.00000000,0.00000000,0.00000000,0.00000000,0.00000000,0.00000000,0.00000000,0.00000000,0.00000000,0.00000000,0.00000000
267.59000000,6.71326900,9.66000000,0.22351256,632.24032986,0.00000000,0.00000000,0.00000000,0.00000000,0.00000000,0.00000000,0.00000000,0.00000000,0.00000000,0.00000000,0.00000000
269.09000000,6.76918400,9.65700000,0.22553556,632.04398194,0.00000000,0.00000000,0.00000000,0.00000000,0.00000000,0.00000000,0.00000000,0.00000000,0.00000000,0.00000000,0.00000000
270.59000000,6.82579300,9.65300000,0.22759556,631.78218470,0.00000000,0.00000000,0.00000000,0.00000000,0.00000000,0.00000000,0.00000000,0.00000000,0.00000000,0.00000000,0.00000000
272.09000000,6.88180800,9.64900000,0.22958200,631.52038746,0.00000000,0.00000000,0.00000000,0.00000000,0.00000000,0.00000000,0.00000000,0.00000000,0.00000000,0.00000000,0.00000000
273.59000000,6.93884800,9.64600000,0.23164189,631.32403953,0.00000000,0.00000000,0.00000000,0.00000000,0.00000000,0.00000000,0.00000000,0.00000000,0.00000000,0.00000000,0.00000000
275.09000000,6.99585700,9.64200000,0.23370178,631.06224229,0.00000000,0.00000000,0.00000000,0.00000000,0.00000000,0.00000000,0.00000000,0.00000000,0.00000000,0.00000000,0.00000000
276.59000000,7.05312900,9.63800000,0.23579833,630.80044506,0.00000000,0.00000000,0.00000000,0.00000000,0.00000000,0.00000000,0.00000000,0.00000000,0.00000000,0.00000000,0.00000000
278.09000000,7.11073200,9.63400000,0.23782156,630.53864782,0.00000000,0.00000000,0.00000000,0.00000000,0.00000000,0.00000000,0.00000000,0.00000000,0.00000000,0.00000000,0.00000000
279.59000000,7.16803800,9.62800000,0.23995511,630.14595196,0.00000000,0.00000000,0.00000000,0.00000000,0.00000000,0.00000000,0.00000000,0.00000000,0.00000000,0.00000000,0.00000000
281.09000000,7.22676600,9.62500000,0.24201500,629.94960403,0.00000000,0.00000000,0.00000000,0.00000000,0.00000000,0.00000000,0.00000000,0.00000000,0.00000000,0.00000000,0.00000000
282.59000000,7.28516400,9.61900000,0.24414856,629.55690817,0.00000000,0.00000000,0.00000000,0.00000000,0.00000000,0.00000000,0.00000000,0.00000000,0.00000000,0.00000000,0.00000000
284.09000000,7.34319700,9.61300000,0.24617156,629.16421232,0.00000000,0.00000000,0.00000000,0.00000000,0.00000000,0.00000000,0.00000000,0.00000000,0.00000000,0.00000000,0.00000000
285.59000000,7.40096600,9.60600000,0.24819489,628.70606715,0.00000000,0.00000000,0.00000000,0.00000000,0.00000000,0.00000000,0.00000000,0.00000000,0.00000000,0.00000000,0.00000000
287.09000000,7.45949600,9.60000000,0.25021800,628.31337129,0.00000000,0.00000000,0.00000000,0.00000000,0.00000000,0.00000000,0.00000000,0.00000000,0.00000000,0.00000000,0.00000000
288.59000000,7.51911900,9.59300000,0.25220422,627.85522613,0.00000000,0.00000000,0.00000000,0.00000000,0.00000000,0.00000000,0.00000000,0.00000000,0.00000000,0.00000000,0.00000000
290.09000000,7.57837600,9.58500000,0.25419044,627.33163165,0.00000000,0.00000000,0.00000000,0.00000000,0.00000000,0.00000000,0.00000000,0.00000000,0.00000000,0.00000000,0.00000000
291.59000000,7.63783300,9.57500000,0.25606633,626.67713856,0.00000000,0.00000000,0.00000000,0.00000000,0.00000000,0.00000000,0.00000000,0.00000000,0.00000000,0.00000000,0.00000000
293.09000000,7.69715600,9.56500000,0.25790556,626.02264546,0.00000000,0.00000000,0.00000000,0.00000000,0.00000000,0.00000000,0.00000000,0.00000000,0.00000000,0.00000000,0.00000000
294.59000000,7.75658100,9.55500000,0.25970800,625.36815237,0.00000000,0.00000000,0.00000000,0.00000000,0.00000000,0.00000000,0.00000000,0.00000000,0.00000000,0.00000000,0.00000000
296.09000000,7.81719600,9.54300000,0.26140000,624.58276065,0.00000000,0.00000000,0.00000000,0.00000000,0.00000000,0.00000000,0.00000000,0.00000000,0.00000000,0.00000000,0.00000000
297.59000000,7.87711400,9.53100000,0.26301833,623.79736894,0.00000000,0.00000000,0.00000000,0.00000000,0.00000000,0.00000000,0.00000000,0.00000000,0.00000000,0.00000000,0.00000000
299.09000000,7.93736400,9.51700000,0.26456333,622.88107860,0.00000000,0.00000000,0.00000000,0.00000000,0.00000000,0.00000000,0.00000000,0.00000000,0.00000000,0.00000000,0.00000000
300.59000000,7.99804500,9.50200000,0.26607133,621.89933896,0.00000000,0.00000000,0.00000000,0.00000000,0.00000000,0.00000000,0.00000000,0.00000000,0.00000000,0.00000000,0.00000000
302.09000000,8.05892600,9.48400000,0.26739567,620.72125139,0.00000000,0.00000000,0.00000000,0.00000000,0.00000000,0.00000000,0.00000000,0.00000000,0.00000000,0.00000000,0.00000000
303.59000000,8.12046700,9.46700000,0.26860944,619.60861313,0.00000000,0.00000000,0.00000000,0.00000000,0.00000000,0.00000000,0.00000000,0.00000000,0.00000000,0.00000000,0.00000000
305.09000000,8.18174400,9.44700000,0.26971300,618.29962694,0.00000000,0.00000000,0.00000000,0.00000000,0.00000000,0.00000000,0.00000000,0.00000000,0.00000000,0.00000000,0.00000000
306.59000000,8.24275600,9.42600000,0.27070611,616.92519144,0.00000000,0.00000000,0.00000000,0.00000000,0.00000000,0.00000000,0.00000000,0.00000000,0.00000000,0.00000000,0.00000000
308.09000000,8.30400000,9.40200000,0.27162578,615.35440801,0.00000000,0.00000000,0.00000000,0.00000000,0.00000000,0.00000000,0.00000000,0.00000000,0.00000000,0.00000000,0.00000000
309.59000000,8.36517600,9.37900000,0.27243522,613.84907389,0.00000000,0.00000000,0.00000000,0.00000000,0.00000000,0.00000000,0.00000000,0.00000000,0.00000000,0.00000000,0.00000000
311.09000000,8.42734900,9.35500000,0.27313411,612.27829046,0.00000000,0.00000000,0.00000000,0.00000000,0.00000000,0.00000000,0.00000000,0.00000000,0.00000000,0.00000000,0.00000000
312.59000000,8.48889100,9.32800000,0.27375933,610.51115911,0.00000000,0.00000000,0.00000000,0.00000000,0.00000000,0.00000000,0.00000000,0.00000000,0.00000000,0.00000000,0.00000000
314.09000000,8.55152400,9.29800000,0.27431122,608.54767982,0.00000000,0.00000000,0.00000000,0.00000000,0.00000000,0.00000000,0.00000000,0.00000000,0.00000000,0.00000000,0.00000000
315.59000000,8.61359500,9.26700000,0.27464222,606.51875123,0.00000000,0.00000000,0.00000000,0.00000000,0.00000000,0.00000000,0.00000000,0.00000000,0.00000000,0.00000000,0.00000000
317.09000000,8.67520300,9.23200000,0.27501033,604.22802539,0.00000000,0.00000000,0.00000000,0.00000000,0.00000000,0.00000000,0.00000000,0.00000000,0.00000000,0.00000000,0.00000000
318.59000000,8.73743900,9.19800000,0.27530444,602.00274887,0.00000000,0.00000000,0.00000000,0.00000000,0.00000000,0.00000000,0.00000000,0.00000000,0.00000000,0.00000000,0.00000000
320.09000000,8.80027000,9.16000000,0.27548833,599.51567511,0.00000000,0.00000000,0.00000000,0.00000000,0.00000000,0.00000000,0.00000000,0.00000000,0.00000000,0.00000000,0.00000000
321.59000000,8.86310100,9.12000000,0.27563544,596.89770273,0.00000000,0.00000000,0.00000000,0.00000000,0.00000000,0.00000000,0.00000000,0.00000000,0.00000000,0.00000000,0.00000000
323.09000000,8.92550200,9.07300000,0.27574600,593.82158518,0.00000000,0.00000000,0.00000000,0.00000000,0.00000000,0.00000000,0.00000000,0.00000000,0.00000000,0.00000000,0.00000000
324.59000000,8.98859800,9.02600000,0.27581967,590.74546764,0.00000000,0.00000000,0.00000000,0.00000000,0.00000000,0.00000000,0.00000000,0.00000000,0.00000000,0.00000000,0.00000000
326.09000000,9.05208900,8.97100000,0.27585633,587.14575561,0.00000000,0.00000000,0.00000000,0.00000000,0.00000000,0.00000000,0.00000000,0.00000000,0.00000000,0.00000000,0.00000000
327.59000000,9.11554500,8.91500000,0.27585633,583.48059428,0.00000000,0.00000000,0.00000000,0.00000000,0.00000000,0.00000000,0.00000000,0.00000000,0.00000000,0.00000000,0.00000000
329.09000000,9.17906600,8.85300000,0.27581956,579.42273709,0.00000000,0.00000000,0.00000000,0.00000000,0.00000000,0.00000000,0.00000000,0.00000000,0.00000000,0.00000000,0.00000000
330.59000000,9.24351200,8.78500000,0.27581956,574.97218404,0.00000000,0.00000000,0.00000000,0.00000000,0.00000000,0.00000000,0.00000000,0.00000000,0.00000000,0.00000000,0.00000000
332.09000000,9.30858500,8.70300000,0.27578278,569.60534066,0.00000000,0.00000000,0.00000000,0.00000000,0.00000000,0.00000000,0.00000000,0.00000000,0.00000000,0.00000000,0.00000000
333.59000000,9.37458200,8.61600000,0.27570933,563.91125074,0.00000000,0.00000000,0.00000000,0.00000000,0.00000000,0.00000000,0.00000000,0.00000000,0.00000000,0.00000000,0.00000000
335.09000000,9.44130300,8.51100000,0.27563589,557.03907324,0.00000000,0.00000000,0.00000000,0.00000000,0.00000000,0.00000000,0.00000000,0.00000000,0.00000000,0.00000000,0.00000000
336.59000000,9.50957600,8.39700000,0.27559922,549.57785195,0.00000000,0.00000000,0.00000000,0.00000000,0.00000000,0.00000000,0.00000000,0.00000000,0.00000000,0.00000000,0.00000000
338.09000000,9.57989600,8.26400000,0.27548889,540.87309379,0.00000000,0.00000000,0.00000000,0.00000000,0.00000000,0.00000000,0.00000000,0.00000000,0.00000000,0.00000000,0.00000000
338.59000000,9.60382000,8.21800000,0.27545222,537.86242555,0.00000000,0.00000000,0.00000000,0.00000000,0.00000000,0.00000000,0.00000000,0.00000000,0.00000000,0.00000000,0.00000000