File: Template_Auto_Cali_large_DP600/_data/DP600Large_UT_00_003_Front_DIC_File.txt
Date of Test;Material;Sample Geometry;Orientation [°];Test Number;Nominal Speed [mm/min];Thickness [mm];Central Width [mm];Gauge Width / Diameter [mm];Pixel to mm ratio [mm/px];Extensometer 1-4 [mm];Extensometer 2-3 [mm];Extensometer 5-6 [mm];;;;;
09/07/21;DP600Large;UT;00;3;0.48;0.29301;2;0;0;6;1.8;1.8;;;;;
;;;;;;;;;;;;;;;;;
Time [s];U1 [mm];U2 [mm];U3 [mm];Force [kN];Ambient Temperature [°C];DIC Zone X 1 [px];DIC Zone Y 1 [px];DIC Zone X 2 [px];DIC Zone Y 2 [px];DIC Zone X 3 [px];DIC Zone Y 3 [px];DIC Zone X 4 [px];DIC Zone Y 4 [px];DIC Zone X 5 [px];DIC Zone Y 5 [px];DIC Zone X 6 [px];DIC Zone Y 6 [px];exx;exy;eyy;e1;e2
0;0;0;0;0.0002058;0;0;0;0;0;0;0;0;0;0;0;0;0;-3.1572e-18;-1.3379e-17;-1.4139e-23;7.5972e-18;-2.4133e-17
1;2.3716e-05;0.00013272;3.1917e-05;0.0002156;0;0;0;0;0;0;0;0;0;0;0;0;0;3.4769e-06;1.3464e-05;3.7239e-06;0.00011636;-9.9417e-05
1.999;-9.8959e-05;8.9563e-05;-4.9676e-05;0.0002646;0;0;0;0;0;0;0;0;0;0;0;0;0;-2.6105e-05;2.0623e-06;1.075e-06;0.00011113;-0.00013518
3;0.00032955;9.4694e-05;-4.3628e-05;0.0008036;0;0;0;0;0;0;0;0;0;0;0;0;0;4.658e-05;-9.227e-06;6.0057e-06;0.00016528;-0.00012793
4;0.0007256;0.00015618;1.0264e-05;0.003381;0;0;0;0;0;0;0;0;0;0;0;0;0;0.00012965;-2.3438e-05;-1.1271e-05;0.00022212;-0.00011591
5;0.0013524;0.00037421;-0.00021472;0.0094276;0;0;0;0;0;0;0;0;0;0;0;0;0;0.00022857;-6.2611e-05;-1.9649e-05;0.00030517;-0.00013921
5.999;0.0018855;0.00052601;-0.0001809;0.01862;0;0;0;0;0;0;0;0;0;0;0;0;0;0.00031923;-0.00010494;-3.3501e-05;0.00039165;-0.00017736
7;0.0030102;0.00081904;-9.7468e-05;0.03282;0;0;0;0;0;0;0;0;0;0;0;0;0;0.00049944;-0.00010754;-5.648e-05;0.00057225;-0.00018035
7.999;0.0039736;0.0012147;-0.00029434;0.049892;0;0;0;0;0;0;0;0;0;0;0;0;0;0.00065941;-0.00019542;-3.577e-05;0.00072016;-0.00025618
8.999;0.0052233;0.0015005;-0.00045812;0.069943;0;0;0;0;0;0;0;0;0;0;0;0;0;0.00085732;-0.00027957;-2.4319e-05;0.00091638;-0.00033862
10;0.006575;0.0018669;-0.00061537;0.092659;0;0;0;0;0;0;0;0;0;0;0;0;0;0.0010954;-0.00035044;-1.9147e-05;0.0011466;-0.00040157
11;0.0083774;0.0023802;-0.0007047;0.11744;0;0;0;0;0;0;0;0;0;0;0;0;0;0.001408;-0.00043605;-2.6405e-05;0.0014545;-0.00048256
11.999;0.010864;0.0031155;-0.00095402;0.14299;0;0;0;0;0;0;0;0;0;0;0;0;0;0.0018154;-0.00060995;-3.4695e-05;0.0018574;-0.00065199
13;0.014263;0.0041711;-0.0014298;0.16787;0;0;0;0;0;0;0;0;0;0;0;0;0;0.0023908;-0.00087346;-2.1579e-05;0.0024261;-0.00090869
13.999;0.018617;0.0054867;-0.0019801;0.18957;0;0;0;0;0;0;0;0;0;0;0;0;0;0.0030913;-0.0011862;-2.6691e-05;0.0031212;-0.0012161
15;0.023204;0.0069266;-0.0026596;0.20934;0;0;0;0;0;0;0;0;0;0;0;0;0;0.0038586;-0.0015526;-2.2769e-05;0.003887;-0.0015809
16;0.027902;0.0083119;-0.0034563;0.22422;0;0;0;0;0;0;0;0;0;0;0;0;0;0.0046394;-0.0019623;-2.9918e-05;0.0046664;-0.0019893
16.999;0.032874;0.0098236;-0.003953;0.23583;0;0;0;0;0;0;0;0;0;0;0;0;0;0.0054542;-0.00231;-2.5612e-05;0.0054788;-0.0023345
18;0.03786;0.011329;-0.0046611;0.24396;0;0;0;0;0;0;0;0;0;0;0;0;0;0.0062828;-0.0026777;-2.4947e-05;0.0063067;-0.0027016
19;0.042413;0.012513;-0.0054181;0.25041;0;0;0;0;0;0;0;0;0;0;0;0;0;0.0070092;-0.0031325;-2.1565e-05;0.0070374;-0.0031606
20;0.04788;0.014226;-0.0060326;0.25609;0;0;0;0;0;0;0;0;0;0;0;0;0;0.0079119;-0.0035422;-3.2886e-05;0.0079408;-0.0035711
21;0.052825;0.01578;-0.00674;0.26051;0;0;0;0;0;0;0;0;0;0;0;0;0;0.0087345;-0.0039139;-4.3977e-05;0.0087636;-0.003943
22;0.058043;0.017172;-0.0074129;0.26469;0;0;0;0;0;0;0;0;0;0;0;0;0;0.0095829;-0.0042943;-4.5742e-05;0.0096126;-0.004324
23;0.062971;0.018646;-0.0080618;0.26827;0;0;0;0;0;0;0;0;0;0;0;0;0;0.010403;-0.0046619;-4.6226e-05;0.010434;-0.0046929
23.999;0.068232;0.020185;-0.0088065;0.27144;0;0;0;0;0;0;0;0;0;0;0;0;0;0.011234;-0.0050371;-5.1857e-05;0.011267;-0.0050696
24.999;0.072996;0.021646;-0.0094787;0.27465;0;0;0;0;0;0;0;0;0;0;0;0;0;0.012029;-0.0054057;-3.9064e-05;0.012063;-0.0054394
25.999;0.077933;0.023015;-0.01021;0.27759;0;0;0;0;0;0;0;0;0;0;0;0;0;0.012842;-0.0057845;-4.5564e-05;0.012877;-0.0058189
26.999;0.082826;0.024505;-0.010803;0.28042;0;0;0;0;0;0;0;0;0;0;0;0;0;0.01364;-0.006142;-4.3887e-05;0.013675;-0.0061773
27.999;0.087797;0.02603;-0.0114;0.28312;0;0;0;0;0;0;0;0;0;0;0;0;0;0.01445;-0.0064878;-4.1334e-05;0.014486;-0.0065243
29;0.092791;0.027452;-0.012068;0.28561;0;0;0;0;0;0;0;0;0;0;0;0;0;0.015245;-0.0068617;-4.0696e-05;0.015283;-0.0068997
30;0.097765;0.028795;-0.012713;0.28822;0;0;0;0;0;0;0;0;0;0;0;0;0;0.016058;-0.0072042;-3.261e-05;0.016098;-0.0072437
30.999;0.10257;0.030291;-0.013355;0.29052;0;0;0;0;0;0;0;0;0;0;0;0;0;0.016857;-0.007577;-3.8689e-05;0.016897;-0.0076172
32;0.10742;0.03164;-0.013974;0.29293;0;0;0;0;0;0;0;0;0;0;0;0;0;0.017653;-0.0079387;-5.1526e-05;0.017694;-0.0079801
32.999;0.11233;0.033164;-0.01471;0.29518;0;0;0;0;0;0;0;0;0;0;0;0;0;0.018452;-0.0083099;-3.7339e-05;0.018494;-0.0083525
33.999;0.1174;0.034748;-0.015335;0.29723;0;0;0;0;0;0;0;0;0;0;0;0;0;0.019281;-0.0086377;-2.7782e-05;0.019324;-0.0086807
35;0.12231;0.036176;-0.015972;0.2994;0;0;0;0;0;0;0;0;0;0;0;0;0;0.020077;-0.0089955;-2.4713e-05;0.020121;-0.00904
35.999;0.12738;0.037609;-0.01675;0.30134;0;0;0;0;0;0;0;0;0;0;0;0;0;0.0209;-0.0093897;-3.7537e-05;0.020945;-0.0094353
36.999;0.1324;0.039112;-0.017367;0.30337;0;0;0;0;0;0;0;0;0;0;0;0;0;0.021698;-0.0097478;-3.7108e-05;0.021745;-0.0097944
38;0.13737;0.040603;-0.017968;0.30526;0;0;0;0;0;0;0;0;0;0;0;0;0;0.022488;-0.010117;-3.9645e-05;0.022536;-0.010164
39;0.14241;0.042143;-0.018587;0.30709;0;0;0;0;0;0;0;0;0;0;0;0;0;0.023311;-0.010458;-4.7131e-05;0.023362;-0.010508
39.999;0.14758;0.043676;-0.019412;0.30886;0;0;0;0;0;0;0;0;0;0;0;0;0;0.02413;-0.010871;-3.5091e-05;0.024181;-0.010922
40.999;0.15234;0.045092;-0.020005;0.31049;0;0;0;0;0;0;0;0;0;0;0;0;0;0.024936;-0.011196;-2.3442e-05;0.024987;-0.011247
41.999;0.15729;0.046525;-0.020528;0.31223;0;0;0;0;0;0;0;0;0;0;0;0;0;0.025726;-0.011501;-9.1864e-05;0.025779;-0.011554
43;0.16242;0.047989;-0.021347;0.31383;0;0;0;0;0;0;0;0;0;0;0;0;0;0.026553;-0.011939;-2.1286e-05;0.026607;-0.011993
44;0.16764;0.049629;-0.02196;0.31533;0;0;0;0;0;0;0;0;0;0;0;0;0;0.027382;-0.012326;-2.0261e-05;0.027437;-0.012382
44.999;0.17264;0.051197;-0.022679;0.31694;0;0;0;0;0;0;0;0;0;0;0;0;0;0.028191;-0.012693;-1.8695e-05;0.028247;-0.012749
46;0.17761;0.052537;-0.02334;0.31838;0;0;0;0;0;0;0;0;0;0;0;0;0;0.028983;-0.013056;-2.3029e-05;0.02904;-0.013113
47;0.18298;0.054177;-0.023982;0.31991;0;0;0;0;0;0;0;0;0;0;0;0;0;0.029842;-0.013405;-4.1968e-06;0.0299;-0.013463
47.999;0.18816;0.055737;-0.024765;0.32133;0;0;0;0;0;0;0;0;0;0;0;0;0;0.030668;-0.013802;5.0998e-06;0.030727;-0.013862
48.999;0.19333;0.057212;-0.025369;0.32271;0;0;0;0;0;0;0;0;0;0;0;0;0;0.031476;-0.014129;-6.2711e-06;0.031537;-0.014189
49.999;0.19835;0.05874;-0.025946;0.32401;0;0;0;0;0;0;0;0;0;0;0;0;0;0.032292;-0.014505;8.7327e-06;0.032352;-0.014566
51;0.20372;0.060495;-0.026619;0.32542;0;0;0;0;0;0;0;0;0;0;0;0;0;0.033166;-0.014875;8.5027e-06;0.033227;-0.014936
52;0.20855;0.061892;-0.027275;0.32659;0;0;0;0;0;0;0;0;0;0;0;0;0;0.033931;-0.015234;2.7825e-06;0.033993;-0.015296
53;0.21365;0.063315;-0.027957;0.32783;0;0;0;0;0;0;0;0;0;0;0;0;0;0.034737;-0.01561;1.7208e-05;0.0348;-0.015673
54;0.21891;0.064896;-0.028521;0.32908;0;0;0;0;0;0;0;0;0;0;0;0;0;0.035562;-0.015943;1.1255e-05;0.035626;-0.016007
54.999;0.22423;0.066451;-0.029148;0.33019;0;0;0;0;0;0;0;0;0;0;0;0;0;0.036394;-0.016331;1.3787e-05;0.036458;-0.016395
56;0.22948;0.068029;-0.029751;0.33138;0;0;0;0;0;0;0;0;0;0;0;0;0;0.037225;-0.016692;2.2465e-05;0.037289;-0.016757
57;0.23447;0.069494;-0.03043;0.33244;0;0;0;0;0;0;0;0;0;0;0;0;0;0.038015;-0.017057;1.3734e-05;0.03808;-0.017122
58;0.23961;0.071247;-0.031156;0.33356;0;0;0;0;0;0;0;0;0;0;0;0;0;0.038844;-0.01743;2.0511e-05;0.038909;-0.017496
58.999;0.24492;0.072745;-0.031801;0.3346;0;0;0;0;0;0;0;0;0;0;0;0;0;0.039667;-0.017806;2.6657e-05;0.039733;-0.017872
59.999;0.25019;0.07438;-0.032338;0.33557;0;0;0;0;0;0;0;0;0;0;0;0;0;0.040501;-0.018146;3.2971e-05;0.040567;-0.018213
61;0.2552;0.075915;-0.033035;0.33662;0;0;0;0;0;0;0;0;0;0;0;0;0;0.041302;-0.018508;2.033e-05;0.041369;-0.018575
62;0.26052;0.077463;-0.033679;0.33756;0;0;0;0;0;0;0;0;0;0;0;0;0;0.042142;-0.018876;2.7423e-05;0.04221;-0.018944
63;0.26568;0.079031;-0.034257;0.33858;0;0;0;0;0;0;0;0;0;0;0;0;0;0.042964;-0.019232;3.9243e-05;0.043032;-0.0193
64;0.27095;0.080629;-0.034916;0.33951;0;0;0;0;0;0;0;0;0;0;0;0;0;0.043769;-0.019613;2.198e-05;0.043837;-0.019682
64.999;0.27629;0.082141;-0.035525;0.34045;0;0;0;0;0;0;0;0;0;0;0;0;0;0.044598;-0.019973;3.7132e-05;0.044668;-0.020042
65.999;0.28175;0.083855;-0.036212;0.3414;0;0;0;0;0;0;0;0;0;0;0;0;0;0.04545;-0.020346;3.7927e-05;0.04552;-0.020416
66.999;0.28687;0.085362;-0.036854;0.34226;0;0;0;0;0;0;0;0;0;0;0;0;0;0.046257;-0.020711;4.0611e-05;0.046327;-0.020782
68;0.29235;0.08706;-0.037483;0.34317;0;0;0;0;0;0;0;0;0;0;0;0;0;0.047105;-0.021087;5.3374e-05;0.047175;-0.021158
68.999;0.29753;0.088618;-0.038115;0.34401;0;0;0;0;0;0;0;0;0;0;0;0;0;0.047912;-0.021441;5.1336e-05;0.047983;-0.021512
69.999;0.30271;0.090252;-0.038764;0.34482;0;0;0;0;0;0;0;0;0;0;0;0;0;0.048724;-0.021818;4.4245e-05;0.048795;-0.021889
70.999;0.30811;0.09184;-0.039348;0.34563;0;0;0;0;0;0;0;0;0;0;0;0;0;0.049551;-0.022135;5.3149e-05;0.049623;-0.022206
72;0.31304;0.093314;-0.040044;0.34637;0;0;0;0;0;0;0;0;0;0;0;0;0;0.050331;-0.022517;3.3206e-05;0.050403;-0.022589
72.999;0.3185;0.094998;-0.040639;0.34718;0;0;0;0;0;0;0;0;0;0;0;0;0;0.051167;-0.022889;5.296e-05;0.051239;-0.022962
74;0.32388;0.096605;-0.041271;0.34793;0;0;0;0;0;0;0;0;0;0;0;0;0;0.052009;-0.023259;6.0046e-05;0.052082;-0.023332
75;0.32924;0.098219;-0.042019;0.34864;0;0;0;0;0;0;0;0;0;0;0;0;0;0.052848;-0.023647;5.0264e-05;0.052922;-0.023721
75.999;0.33445;0.099766;-0.042587;0.34939;0;0;0;0;0;0;0;0;0;0;0;0;0;0.053651;-0.023994;5.5411e-05;0.053725;-0.024068
76.999;0.33981;0.10149;-0.043305;0.3501;0;0;0;0;0;0;0;0;0;0;0;0;0;0.054488;-0.024378;6.7125e-05;0.054563;-0.024453
78;0.34527;0.10308;-0.04393;0.35079;0;0;0;0;0;0;0;0;0;0;0;0;0;0.055327;-0.02473;7.4293e-05;0.055403;-0.024806
79;0.35051;0.10459;-0.044456;0.35145;0;0;0;0;0;0;0;0;0;0;0;0;0;0.056129;-0.025105;7.4011e-05;0.056205;-0.025181
79.999;0.35584;0.10629;-0.045156;0.35213;0;0;0;0;0;0;0;0;0;0;0;0;0;0.05697;-0.025465;7.1412e-05;0.057046;-0.025542
81;0.36116;0.10789;-0.045779;0.35277;0;0;0;0;0;0;0;0;0;0;0;0;0;0.057777;-0.025817;8.7186e-05;0.057854;-0.025894
82;0.36646;0.10943;-0.046376;0.35341;0;0;0;0;0;0;0;0;0;0;0;0;0;0.058592;-0.026168;6.0877e-05;0.058669;-0.026245
83;0.37175;0.11107;-0.046944;0.35403;0;0;0;0;0;0;0;0;0;0;0;0;0;0.059425;-0.026562;8.7185e-05;0.059503;-0.026639
83.999;0.3771;0.11277;-0.047598;0.35465;0;0;0;0;0;0;0;0;0;0;0;0;0;0.060247;-0.026925;9.3951e-05;0.060325;-0.027003
84.999;0.38187;0.11421;-0.048365;0.35527;0;0;0;0;0;0;0;0;0;0;0;0;0;0.060983;-0.027325;0.00010459;0.061062;-0.027404
85.999;0.388;0.11594;-0.048852;0.35584;0;0;0;0;0;0;0;0;0;0;0;0;0;0.061922;-0.027637;0.00010857;0.062001;-0.027716
87;0.39305;0.11746;-0.049463;0.35644;0;0;0;0;0;0;0;0;0;0;0;0;0;0.062708;-0.028003;0.00011461;0.062787;-0.028083
88;0.39813;0.11907;-0.050064;0.35697;0;0;0;0;0;0;0;0;0;0;0;0;0;0.063507;-0.028397;0.00012391;0.063586;-0.028476
88.999;0.40346;0.12069;-0.050863;0.3575;0;0;0;0;0;0;0;0;0;0;0;0;0;0.064336;-0.028793;0.00010368;0.064416;-0.028873
90;0.40896;0.1224;-0.051417;0.35805;0;0;0;0;0;0;0;0;0;0;0;0;0;0.065195;-0.029122;0.00011338;0.065276;-0.029203
90.999;0.41418;0.12395;-0.05206;0.35857;0;0;0;0;0;0;0;0;0;0;0;0;0;0.066008;-0.029499;0.00010122;0.066089;-0.029581
91.999;0.41937;0.12562;-0.052639;0.35909;0;0;0;0;0;0;0;0;0;0;0;0;0;0.066811;-0.029905;0.00013419;0.066893;-0.029987
92.999;0.42508;0.12732;-0.053254;0.35961;0;0;0;0;0;0;0;0;0;0;0;0;0;0.06769;-0.030217;0.0001009;0.067772;-0.030299
93.999;0.43035;0.12894;-0.053822;0.36014;0;0;0;0;0;0;0;0;0;0;0;0;0;0.068503;-0.030588;0.00012021;0.068585;-0.030671
94.999;0.43581;0.13065;-0.054535;0.36067;0;0;0;0;0;0;0;0;0;0;0;0;0;0.069345;-0.030968;0.00014387;0.069428;-0.031051
95.999;0.44095;0.13224;-0.055298;0.36114;0;0;0;0;0;0;0;0;0;0;0;0;0;0.070138;-0.031357;0.00013195;0.070221;-0.03144
96.999;0.4465;0.13387;-0.055851;0.36164;0;0;0;0;0;0;0;0;0;0;0;0;0;0.07098;-0.031694;0.00014171;0.071065;-0.031779
97.999;0.45182;0.13558;-0.056538;0.3621;0;0;0;0;0;0;0;0;0;0;0;0;0;0.071791;-0.03205;0.00012322;0.071876;-0.032135
98.999;0.45801;0.13754;-0.057136;0.3626;0;0;0;0;0;0;0;0;0;0;0;0;0;0.072731;-0.032382;0.00015384;0.072817;-0.032467
99.999;0.46252;0.13889;-0.057827;0.36304;0;0;0;0;0;0;0;0;0;0;0;0;0;0.073428;-0.032795;0.00011771;0.073514;-0.032881
101;0.46822;0.14057;-0.058452;0.36349;0;0;0;0;0;0;0;0;0;0;0;0;0;0.074277;-0.033135;0.00013186;0.074363;-0.033222
102;0.47361;0.14231;-0.059131;0.3639;0;0;0;0;0;0;0;0;0;0;0;0;0;0.075104;-0.033509;0.00013834;0.07519;-0.033596
103;0.4791;0.14401;-0.059762;0.36431;0;0;0;0;0;0;0;0;0;0;0;0;0;0.075944;-0.033868;0.00014195;0.076031;-0.033955
104;0.48478;0.14577;-0.060438;0.3647;0;0;0;0;0;0;0;0;0;0;0;0;0;0.076792;-0.034229;0.00016489;0.07688;-0.034316
105;0.48999;0.14732;-0.061124;0.36509;0;0;0;0;0;0;0;0;0;0;0;0;0;0.077584;-0.034611;0.00014649;0.077672;-0.034699
106;0.49548;0.14912;-0.061765;0.36546;0;0;0;0;0;0;0;0;0;0;0;0;0;0.078421;-0.03497;0.00015568;0.07851;-0.035058
107;0.50094;0.15064;-0.062443;0.36579;0;0;0;0;0;0;0;0;0;0;0;0;0;0.079242;-0.035332;0.00015952;0.079331;-0.035421
108;0.50634;0.1524;-0.063138;0.3662;0;0;0;0;0;0;0;0;0;0;0;0;0;0.080087;-0.035683;0.00016807;0.080176;-0.035772
109;0.51205;0.15405;-0.063788;0.36656;0;0;0;0;0;0;0;0;0;0;0;0;0;0.080923;-0.03604;0.00017179;0.081012;-0.03613
110;0.51748;0.15578;-0.064484;0.36695;0;0;0;0;0;0;0;0;0;0;0;0;0;0.08175;-0.036414;0.00017521;0.081839;-0.036503
111;0.52287;0.15738;-0.065249;0.3673;0;0;0;0;0;0;0;0;0;0;0;0;0;0.082552;-0.036806;0.00017528;0.082642;-0.036895
112;0.52855;0.15916;-0.065959;0.36764;0;0;0;0;0;0;0;0;0;0;0;0;0;0.083402;-0.03718;0.00019134;0.083493;-0.03727
113;0.53423;0.16084;-0.066492;0.36798;0;0;0;0;0;0;0;0;0;0;0;0;0;0.084247;-0.037518;0.00018691;0.084338;-0.037609
114;0.5398;0.16255;-0.06714;0.3683;0;0;0;0;0;0;0;0;0;0;0;0;0;0.0851;-0.037901;0.0001922;0.085192;-0.037992
115;0.54555;0.1643;-0.067809;0.36867;0;0;0;0;0;0;0;0;0;0;0;0;0;0.085931;-0.038252;0.00019537;0.086022;-0.038343
116;0.55054;0.16582;-0.0685;0.369;0;0;0;0;0;0;0;0;0;0;0;0;0;0.086707;-0.038668;0.00018227;0.086799;-0.038759
117;0.5566;0.16767;-0.069057;0.36934;0;0;0;0;0;0;0;0;0;0;0;0;0;0.087602;-0.038973;0.00020707;0.087694;-0.039065
118;0.56208;0.16936;-0.069626;0.36964;0;0;0;0;0;0;0;0;0;0;0;0;0;0.088423;-0.039333;0.00019929;0.088515;-0.039425
119;0.56757;0.1711;-0.070406;0.36991;0;0;0;0;0;0;0;0;0;0;0;0;0;0.089247;-0.039708;0.00020291;0.08934;-0.0398
120;0.57354;0.17281;-0.07101;0.37022;0;0;0;0;0;0;0;0;0;0;0;0;0;0.090127;-0.040082;0.00020994;0.090219;-0.040174
121;0.57892;0.1744;-0.071692;0.37051;0;0;0;0;0;0;0;0;0;0;0;0;0;0.090949;-0.040445;0.000222;0.091041;-0.040537
122;0.58434;0.17609;-0.072306;0.3708;0;0;0;0;0;0;0;0;0;0;0;0;0;0.091731;-0.040817;0.00020785;0.091824;-0.04091
123;0.58998;0.17784;-0.073086;0.37106;0;0;0;0;0;0;0;0;0;0;0;0;0;0.092585;-0.041164;0.00021846;0.092678;-0.041257
124;0.59582;0.17957;-0.07375;0.37132;0;0;0;0;0;0;0;0;0;0;0;0;0;0.093453;-0.041535;0.00022027;0.093546;-0.041628
125;0.60141;0.18122;-0.07447;0.37162;0;0;0;0;0;0;0;0;0;0;0;0;0;0.094288;-0.041914;0.00022777;0.094381;-0.042008
126;0.6068;0.18295;-0.075061;0.37187;0;0;0;0;0;0;0;0;0;0;0;0;0;0.095095;-0.042265;0.00022327;0.095189;-0.042359
127;0.61231;0.18463;-0.075657;0.37215;0;0;0;0;0;0;0;0;0;0;0;0;0;0.095918;-0.042625;0.00022152;0.096012;-0.042719
128;0.61808;0.18633;-0.076303;0.37239;0;0;0;0;0;0;0;0;0;0;0;0;0;0.096763;-0.042995;0.00023612;0.096857;-0.04309
129;0.62384;0.18809;-0.076985;0.37265;0;0;0;0;0;0;0;0;0;0;0;0;0;0.097593;-0.043348;0.00024363;0.097687;-0.043443
130;0.62953;0.18972;-0.077534;0.37288;0;0;0;0;0;0;0;0;0;0;0;0;0;0.09844;-0.043706;0.00024927;0.098535;-0.043801
131;0.6351;0.1914;-0.078252;0.3731;0;0;0;0;0;0;0;0;0;0;0;0;0;0.099268;-0.044121;0.00024236;0.099363;-0.044216
132;0.64086;0.19311;-0.078919;0.37335;0;0;0;0;0;0;0;0;0;0;0;0;0;0.10011;-0.044464;0.00025719;0.10021;-0.044559
133;0.64661;0.19493;-0.079576;0.37358;0;0;0;0;0;0;0;0;0;0;0;0;0;0.10095;-0.044828;0.00025745;0.10105;-0.044924
134;0.65224;0.19661;-0.080149;0.3738;0;0;0;0;0;0;0;0;0;0;0;0;0;0.10179;-0.045173;0.00025966;0.10189;-0.045269
135;0.65814;0.19821;-0.080865;0.37403;0;0;0;0;0;0;0;0;0;0;0;0;0;0.10263;-0.045556;0.00026734;0.10272;-0.045653
136;0.66368;0.19982;-0.081424;0.37424;0;0;0;0;0;0;0;0;0;0;0;0;0;0.10346;-0.045925;0.00026931;0.10356;-0.046022
137;0.6695;0.20173;-0.082128;0.37445;0;0;0;0;0;0;0;0;0;0;0;0;0;0.10431;-0.046283;0.00027973;0.10441;-0.046381
138;0.67529;0.20346;-0.082711;0.37465;0;0;0;0;0;0;0;0;0;0;0;0;0;0.10516;-0.04664;0.00029397;0.10526;-0.046738
139;0.68101;0.20521;-0.083395;0.37486;0;0;0;0;0;0;0;0;0;0;0;0;0;0.10598;-0.047024;0.00028825;0.10608;-0.047122
140;0.68666;0.20678;-0.08397;0.37505;0;0;0;0;0;0;0;0;0;0;0;0;0;0.10681;-0.047399;0.00028553;0.10691;-0.047498
141;0.69238;0.20844;-0.084643;0.37523;0;0;0;0;0;0;0;0;0;0;0;0;0;0.10765;-0.047764;0.00029157;0.10775;-0.047863
142;0.69828;0.21013;-0.085265;0.37543;0;0;0;0;0;0;0;0;0;0;0;0;0;0.1085;-0.048122;0.0002898;0.1086;-0.048222
143;0.70404;0.21179;-0.085989;0.3756;0;0;0;0;0;0;0;0;0;0;0;0;0;0.10934;-0.048487;0.00029944;0.10945;-0.048587
144;0.71;0.21361;-0.08663;0.37578;0;0;0;0;0;0;0;0;0;0;0;0;0;0.1102;-0.048856;0.00030575;0.1103;-0.048957
145;0.71554;0.21532;-0.087395;0.37597;0;0;0;0;0;0;0;0;0;0;0;0;0;0.11104;-0.049257;0.0003079;0.11114;-0.049358
146;0.72156;0.217;-0.087991;0.37613;0;0;0;0;0;0;0;0;0;0;0;0;0;0.11188;-0.049607;0.00031406;0.11199;-0.049709
147;0.72724;0.21876;-0.088546;0.37632;0;0;0;0;0;0;0;0;0;0;0;0;0;0.11274;-0.049951;0.00031845;0.11284;-0.050053
148;0.73292;0.22032;-0.089283;0.37648;0;0;0;0;0;0;0;0;0;0;0;0;0;0.11355;-0.050355;0.00033075;0.11365;-0.050457
149;0.73932;0.22228;-0.089899;0.37663;0;0;0;0;0;0;0;0;0;0;0;0;0;0.11447;-0.050677;0.00035426;0.11457;-0.05078
150;0.74471;0.22381;-0.09057;0.3768;0;0;0;0;0;0;0;0;0;0;0;0;0;0.11525;-0.051086;0.00031462;0.11535;-0.051189
151;0.75062;0.22558;-0.091175;0.37696;0;0;0;0;0;0;0;0;0;0;0;0;0;0.11611;-0.051452;0.00033725;0.11621;-0.051556
152;0.75648;0.22726;-0.091775;0.37708;0;0;0;0;0;0;0;0;0;0;0;0;0;0.11695;-0.05181;0.00033755;0.11706;-0.051914
153;0.76258;0.22914;-0.092383;0.37721;0;0;0;0;0;0;0;0;0;0;0;0;0;0.11784;-0.052158;0.00036914;0.11795;-0.052262
154;0.76826;0.23082;-0.093001;0.37736;0;0;0;0;0;0;0;0;0;0;0;0;0;0.11866;-0.052551;0.00033916;0.11876;-0.052656
155;0.7742;0.23252;-0.093698;0.37748;0;0;0;0;0;0;0;0;0;0;0;0;0;0.1195;-0.052931;0.00034868;0.11961;-0.053036
156;0.78003;0.23425;-0.094366;0.3776;0;0;0;0;0;0;0;0;0;0;0;0;0;0.12035;-0.053318;0.00034841;0.12045;-0.053423
157;0.78591;0.23597;-0.094921;0.37775;0;0;0;0;0;0;0;0;0;0;0;0;0;0.12121;-0.053669;0.00035418;0.12131;-0.053774
158;0.7918;0.23778;-0.095678;0.37788;0;0;0;0;0;0;0;0;0;0;0;0;0;0.12205;-0.054048;0.00036082;0.12215;-0.054154
159;0.79769;0.23951;-0.096236;0.37801;0;0;0;0;0;0;0;0;0;0;0;0;0;0.1229;-0.054427;0.00035595;0.123;-0.054532
160;0.8037;0.24135;-0.096765;0.37814;0;0;0;0;0;0;0;0;0;0;0;0;0;0.12377;-0.054785;0.00036737;0.12387;-0.054891
161;0.80926;0.24289;-0.09743;0.37826;0;0;0;0;0;0;0;0;0;0;0;0;0;0.12454;-0.055158;0.00036847;0.12465;-0.055265
162;0.81566;0.24491;-0.098004;0.37838;0;0;0;0;0;0;0;0;0;0;0;0;0;0.12548;-0.055522;0.00037808;0.12559;-0.055628
163;0.82127;0.24661;-0.098762;0.37846;0;0;0;0;0;0;0;0;0;0;0;0;0;0.12631;-0.055891;0.00038633;0.12641;-0.055998
164;0.82731;0.24843;-0.099343;0.37855;0;0;0;0;0;0;0;0;0;0;0;0;0;0.12717;-0.056254;0.00037918;0.12728;-0.056362
165;0.83329;0.2503;-0.099923;0.37867;0;0;0;0;0;0;0;0;0;0;0;0;0;0.12804;-0.056621;0.00038062;0.12814;-0.05673
166;0.83907;0.25199;-0.10059;0.37879;0;0;0;0;0;0;0;0;0;0;0;0;0;0.12885;-0.057019;0.00038637;0.12896;-0.057128
167;0.84518;0.2538;-0.10121;0.37895;0;0;0;0;0;0;0;0;0;0;0;0;0;0.12972;-0.057373;0.00039341;0.12983;-0.057482
168;0.85113;0.25555;-0.10186;0.37907;0;0;0;0;0;0;0;0;0;0;0;0;0;0.13058;-0.057747;0.0003884;0.13069;-0.057857
169;0.85708;0.25739;-0.10255;0.37915;0;0;0;0;0;0;0;0;0;0;0;0;0;0.13144;-0.058111;0.0004042;0.13155;-0.058221
170;0.86309;0.25922;-0.10313;0.37923;0;0;0;0;0;0;0;0;0;0;0;0;0;0.1323;-0.058479;0.00040664;0.13241;-0.058589
171;0.86926;0.26106;-0.10373;0.3793;0;0;0;0;0;0;0;0;0;0;0;0;0;0.13318;-0.058863;0.00043156;0.13329;-0.058973
172;0.87511;0.26295;-0.10452;0.37937;0;0;0;0;0;0;0;0;0;0;0;0;0;0.13402;-0.059233;0.00041437;0.13413;-0.059344
173;0.88101;0.26469;-0.10508;0.37946;0;0;0;0;0;0;0;0;0;0;0;0;0;0.13486;-0.059612;0.00041407;0.13497;-0.059723
174;0.88715;0.26664;-0.10585;0.37953;0;0;0;0;0;0;0;0;0;0;0;0;0;0.13573;-0.059988;0.00041803;0.13584;-0.0601
175;0.89311;0.26839;-0.1065;0.3796;0;0;0;0;0;0;0;0;0;0;0;0;0;0.13658;-0.060362;0.00041882;0.13669;-0.060475
176;0.89919;0.27015;-0.10717;0.37967;0;0;0;0;0;0;0;0;0;0;0;0;0;0.13744;-0.06076;0.00042243;0.13756;-0.060873
177;0.90534;0.27199;-0.10776;0.37975;0;0;0;0;0;0;0;0;0;0;0;0;0;0.1383;-0.061115;0.00044438;0.13841;-0.061228
178;0.91133;0.27381;-0.10841;0.37981;0;0;0;0;0;0;0;0;0;0;0;0;0;0.13915;-0.061477;0.00042647;0.13926;-0.061591
179;0.91792;0.27587;-0.10917;0.37988;0;0;0;0;0;0;0;0;0;0;0;0;0;0.14006;-0.06185;0.00044374;0.14017;-0.061964
180;0.92371;0.2776;-0.10981;0.37993;0;0;0;0;0;0;0;0;0;0;0;0;0;0.14089;-0.062233;0.00044802;0.141;-0.062348
181;0.92983;0.2795;-0.11053;0.37998;0;0;0;0;0;0;0;0;0;0;0;0;0;0.14174;-0.062616;0.00044278;0.14185;-0.062731
182;0.93599;0.28133;-0.11111;0.38003;0;0;0;0;0;0;0;0;0;0;0;0;0;0.14261;-0.062973;0.00045068;0.14273;-0.063089
183;0.94184;0.28314;-0.1118;0.38008;0;0;0;0;0;0;0;0;0;0;0;0;0;0.14343;-0.063361;0.00048033;0.14355;-0.063477
184;0.94825;0.28505;-0.11256;0.38014;0;0;0;0;0;0;0;0;0;0;0;0;0;0.14434;-0.063748;0.00046954;0.14446;-0.063865
185;0.95418;0.2868;-0.11319;0.38019;0;0;0;0;0;0;0;0;0;0;0;0;0;0.14517;-0.064114;0.00046678;0.14529;-0.064231
186;0.96052;0.28867;-0.11377;0.38022;0;0;0;0;0;0;0;0;0;0;0;0;0;0.14605;-0.064464;0.00046991;0.14617;-0.064582
187;0.96663;0.2906;-0.11449;0.38025;0;0;0;0;0;0;0;0;0;0;0;0;0;0.1469;-0.064851;0.00047812;0.14702;-0.064968
188;0.97304;0.29248;-0.11515;0.38028;0;0;0;0;0;0;0;0;0;0;0;0;0;0.14778;-0.065224;0.00048565;0.1479;-0.065342
189;0.9791;0.29429;-0.11578;0.38031;0;0;0;0;0;0;0;0;0;0;0;0;0;0.14863;-0.065597;0.00048485;0.14874;-0.065715
190;0.98545;0.2963;-0.11642;0.38036;0;0;0;0;0;0;0;0;0;0;0;0;0;0.14951;-0.065972;0.00049444;0.14963;-0.06609
191;0.99163;0.29819;-0.11707;0.3804;0;0;0;0;0;0;0;0;0;0;0;0;0;0.15037;-0.066356;0.00049599;0.15049;-0.066474
192;0.99806;0.30013;-0.11783;0.38044;0;0;0;0;0;0;0;0;0;0;0;0;0;0.15126;-0.066737;0.00051654;0.15137;-0.066855
193;1.0043;0.30202;-0.11837;0.38047;0;0;0;0;0;0;0;0;0;0;0;0;0;0.15213;-0.067101;0.00051449;0.15225;-0.06722
194;1.0105;0.30384;-0.1191;0.38048;0;0;0;0;0;0;0;0;0;0;0;0;0;0.153;-0.067478;0.00051432;0.15312;-0.067598
195;1.0169;0.30574;-0.1198;0.3805;0;0;0;0;0;0;0;0;0;0;0;0;0;0.15387;-0.067875;0.0005226;0.15399;-0.067995
196;1.0232;0.30775;-0.12048;0.38052;0;0;0;0;0;0;0;0;0;0;0;0;0;0.15476;-0.068232;0.00052628;0.15488;-0.068352
197;1.0295;0.30957;-0.12112;0.38055;0;0;0;0;0;0;0;0;0;0;0;0;0;0.15563;-0.06861;0.00053753;0.15575;-0.068731
198;1.0358;0.31149;-0.12173;0.38057;0;0;0;0;0;0;0;0;0;0;0;0;0;0.1565;-0.06899;0.0005469;0.15662;-0.06911
199;1.0421;0.3134;-0.1225;0.38058;0;0;0;0;0;0;0;0;0;0;0;0;0;0.15736;-0.069356;0.0005578;0.15749;-0.069477
200;1.0485;0.31531;-0.12311;0.38061;0;0;0;0;0;0;0;0;0;0;0;0;0;0.15825;-0.069745;0.00055441;0.15837;-0.069867
201;1.0551;0.31735;-0.12371;0.38063;0;0;0;0;0;0;0;0;0;0;0;0;0;0.15915;-0.07012;0.00056686;0.15927;-0.070241
202;1.0612;0.31911;-0.1244;0.38065;0;0;0;0;0;0;0;0;0;0;0;0;0;0.16;-0.070504;0.00056201;0.16012;-0.070626
203;1.0677;0.32101;-0.12508;0.38065;0;0;0;0;0;0;0;0;0;0;0;0;0;0.16089;-0.070879;0.00056153;0.16102;-0.071002
204;1.0739;0.32292;-0.12576;0.38063;0;0;0;0;0;0;0;0;0;0;0;0;0;0.16175;-0.071254;0.00057725;0.16188;-0.071377
205;1.0803;0.32489;-0.12643;0.38058;0;0;0;0;0;0;0;0;0;0;0;0;0;0.16267;-0.071625;0.0006032;0.16279;-0.071749
206;1.0869;0.32681;-0.12717;0.38057;0;0;0;0;0;0;0;0;0;0;0;0;0;0.16356;-0.072027;0.00061092;0.16369;-0.072151
207;1.0932;0.32872;-0.12783;0.38057;0;0;0;0;0;0;0;0;0;0;0;0;0;0.16443;-0.0724;0.00060681;0.16456;-0.072524
208;1.0999;0.33077;-0.12855;0.38057;0;0;0;0;0;0;0;0;0;0;0;0;0;0.16534;-0.072773;0.00061578;0.16547;-0.072897
209;1.1061;0.33257;-0.12921;0.38058;0;0;0;0;0;0;0;0;0;0;0;0;0;0.1662;-0.07315;0.00062476;0.16632;-0.073275
210;1.1127;0.3346;-0.12986;0.38058;0;0;0;0;0;0;0;0;0;0;0;0;0;0.1671;-0.073535;0.00060595;0.16723;-0.07366
211;1.1191;0.33656;-0.13049;0.38058;0;0;0;0;0;0;0;0;0;0;0;0;0;0.16797;-0.073911;0.00062824;0.16809;-0.074036
212;1.1255;0.33837;-0.13125;0.38058;0;0;0;0;0;0;0;0;0;0;0;0;0;0.16883;-0.074316;0.00063745;0.16895;-0.074441
213;1.1321;0.34037;-0.13193;0.38059;0;0;0;0;0;0;0;0;0;0;0;0;0;0.16973;-0.074684;0.00064671;0.16985;-0.07481
214;1.1388;0.34238;-0.1326;0.38058;0;0;0;0;0;0;0;0;0;0;0;0;0;0.17062;-0.075051;0.00065452;0.17074;-0.075178
215;1.1452;0.34432;-0.1333;0.38058;0;0;0;0;0;0;0;0;0;0;0;0;0;0.17152;-0.075446;0.00065789;0.17164;-0.075574
216;1.1517;0.34621;-0.13397;0.38057;0;0;0;0;0;0;0;0;0;0;0;0;0;0.1724;-0.075815;0.00066267;0.17253;-0.075942
217;1.1585;0.34817;-0.13479;0.38056;0;0;0;0;0;0;0;0;0;0;0;0;0;0.1733;-0.07622;0.00067502;0.17343;-0.076348
218;1.1651;0.35008;-0.13533;0.38054;0;0;0;0;0;0;0;0;0;0;0;0;0;0.17418;-0.076598;0.00068072;0.17431;-0.076726
219;1.1718;0.35209;-0.13599;0.38053;0;0;0;0;0;0;0;0;0;0;0;0;0;0.17509;-0.076967;0.00068595;0.17522;-0.077096
220;1.1784;0.35406;-0.13668;0.38052;0;0;0;0;0;0;0;0;0;0;0;0;0;0.17598;-0.077378;0.0006944;0.17611;-0.077507
221;1.185;0.35595;-0.13729;0.3805;0;0;0;0;0;0;0;0;0;0;0;0;0;0.17687;-0.077745;0.00070036;0.177;-0.077874
222;1.1917;0.35785;-0.1379;0.38048;0;0;0;0;0;0;0;0;0;0;0;0;0;0.17776;-0.078142;0.00070851;0.17789;-0.078272
223;1.1981;0.35969;-0.13849;0.38047;0;0;0;0;0;0;0;0;0;0;0;0;0;0.17863;-0.078539;0.00071082;0.17876;-0.078669
224;1.2051;0.3617;-0.13913;0.38044;0;0;0;0;0;0;0;0;0;0;0;0;0;0.17955;-0.078904;0.00072644;0.17968;-0.079035
225;1.2117;0.36366;-0.13982;0.38042;0;0;0;0;0;0;0;0;0;0;0;0;0;0.18044;-0.079302;0.00072778;0.18057;-0.079434
226;1.2184;0.36548;-0.14044;0.3804;0;0;0;0;0;0;0;0;0;0;0;0;0;0.18133;-0.079696;0.00073073;0.18146;-0.079828
227;1.2253;0.36751;-0.14101;0.38039;0;0;0;0;0;0;0;0;0;0;0;0;0;0.18226;-0.080059;0.00072332;0.1824;-0.080191
228;1.2321;0.36941;-0.14169;0.38037;0;0;0;0;0;0;0;0;0;0;0;0;0;0.18317;-0.08045;0.00074992;0.1833;-0.080583
229;1.2388;0.37121;-0.14226;0.38036;0;0;0;0;0;0;0;0;0;0;0;0;0;0.18404;-0.080835;0.00075308;0.18418;-0.080968
230;1.2455;0.37304;-0.14287;0.38033;0;0;0;0;0;0;0;0;0;0;0;0;0;0.18494;-0.081228;0.00076925;0.18507;-0.081362
231;1.2524;0.37475;-0.14356;0.38031;0;0;0;0;0;0;0;0;0;0;0;0;0;0.18582;-0.0816;0.00076041;0.18596;-0.081734
232;1.2591;0.3766;-0.14423;0.38028;0;0;0;0;0;0;0;0;0;0;0;0;0;0.18673;-0.081982;0.00076448;0.18686;-0.082116
233.01;1.266;0.3785;-0.14494;0.38026;0;0;0;0;0;0;0;0;0;0;0;0;0;0.18763;-0.082368;0.00078688;0.18777;-0.082503
234;1.2729;0.38031;-0.14549;0.38024;0;0;0;0;0;0;0;0;0;0;0;0;0;0.18854;-0.082748;0.00078389;0.18867;-0.082883
235;1.2798;0.38206;-0.14623;0.38022;0;0;0;0;0;0;0;0;0;0;0;0;0;0.18944;-0.083137;0.00079251;0.18957;-0.083273
236;1.2866;0.38377;-0.14687;0.3802;0;0;0;0;0;0;0;0;0;0;0;0;0;0.19035;-0.083515;0.00080727;0.19049;-0.083652
237;1.2936;0.38562;-0.14743;0.38018;0;0;0;0;0;0;0;0;0;0;0;0;0;0.19125;-0.083893;0.00081797;0.19139;-0.084031
238;1.3005;0.38722;-0.14793;0.38015;0;0;0;0;0;0;0;0;0;0;0;0;0;0.19216;-0.084276;0.00081898;0.1923;-0.084413
239;1.3075;0.38872;-0.14842;0.38013;0;0;0;0;0;0;0;0;0;0;0;0;0;0.19307;-0.084649;0.00083309;0.19321;-0.084787
240;1.3145;0.39041;-0.14903;0.38012;0;0;0;0;0;0;0;0;0;0;0;0;0;0.19396;-0.085037;0.00083606;0.1941;-0.085175
241;1.3215;0.392;-0.14957;0.3801;0;0;0;0;0;0;0;0;0;0;0;0;0;0.19487;-0.085436;0.00083909;0.19501;-0.085575
242;1.3285;0.39342;-0.15002;0.38008;0;0;0;0;0;0;0;0;0;0;0;0;0;0.19576;-0.085808;0.00084586;0.1959;-0.085948
243;1.3356;0.3948;-0.15059;0.38004;0;0;0;0;0;0;0;0;0;0;0;0;0;0.19667;-0.086226;0.00085261;0.19681;-0.086366
244;1.3428;0.39627;-0.15088;0.38;0;0;0;0;0;0;0;0;0;0;0;0;0;0.19759;-0.086575;0.00086456;0.19773;-0.086715
245;1.35;0.39756;-0.15145;0.37999;0;0;0;0;0;0;0;0;0;0;0;0;0;0.19849;-0.086965;0.00087017;0.19864;-0.087106
246;1.357;0.39882;-0.15184;0.37995;0;0;0;0;0;0;0;0;0;0;0;0;0;0.1994;-0.087336;0.00087797;0.19954;-0.087478
247;1.3642;0.39999;-0.15219;0.37992;0;0;0;0;0;0;0;0;0;0;0;0;0;0.20028;-0.08772;0.00088566;0.20042;-0.087862
248;1.3714;0.40116;-0.1527;0.3799;0;0;0;0;0;0;0;0;0;0;0;0;0;0.20119;-0.088106;0.00089219;0.20133;-0.088248
249;1.3784;0.40211;-0.15287;0.37986;0;0;0;0;0;0;0;0;0;0;0;0;0;0.20208;-0.088483;0.00089923;0.20222;-0.088625
250;1.3857;0.40313;-0.15323;0.37983;0;0;0;0;0;0;0;0;0;0;0;0;0;0.20299;-0.088881;0.0009114;0.20313;-0.089024
251;1.3931;0.40397;-0.15354;0.37978;0;0;0;0;0;0;0;0;0;0;0;0;0;0.2039;-0.089248;0.00091118;0.20404;-0.089391
252;1.4008;0.40482;-0.15388;0.37972;0;0;0;0;0;0;0;0;0;0;0;0;0;0.20483;-0.089619;0.00091879;0.20497;-0.089762
253;1.4081;0.4055;-0.154;0.37967;0;0;0;0;0;0;0;0;0;0;0;0;0;0.20573;-0.089972;0.00091019;0.20587;-0.090117
254;1.4157;0.40611;-0.15429;0.37959;0;0;0;0;0;0;0;0;0;0;0;0;0;0.20664;-0.090378;0.00092238;0.20678;-0.090523
255;1.4234;0.40663;-0.15447;0.37953;0;0;0;0;0;0;0;0;0;0;0;0;0;0.20755;-0.090779;0.00092716;0.2077;-0.090925
256;1.4308;0.40705;-0.15458;0.37947;0;0;0;0;0;0;0;0;0;0;0;0;0;0.20844;-0.091111;0.00093369;0.20859;-0.091257
257;1.4384;0.40748;-0.15474;0.37938;0;0;0;0;0;0;0;0;0;0;0;0;0;0.20936;-0.091504;0.00093786;0.20951;-0.091651
258;1.446;0.40777;-0.15491;0.37929;0;0;0;0;0;0;0;0;0;0;0;0;0;0.21026;-0.091876;0.00093405;0.21041;-0.092023
259;1.4538;0.40806;-0.15499;0.37915;0;0;0;0;0;0;0;0;0;0;0;0;0;0.21119;-0.092239;0.00092737;0.21133;-0.092386
260;1.4617;0.40821;-0.15502;0.37901;0;0;0;0;0;0;0;0;0;0;0;0;0;0.21211;-0.09262;0.00093068;0.21226;-0.092767
261;1.4697;0.40829;-0.1551;0.37882;0;0;0;0;0;0;0;0;0;0;0;0;0;0.21304;-0.092982;0.00093968;0.21319;-0.09313
262;1.4777;0.40844;-0.15514;0.37856;0;0;0;0;0;0;0;0;0;0;0;0;0;0.21394;-0.093357;0.0009498;0.21409;-0.093506
263;1.4857;0.40845;-0.15525;0.37826;0;0;0;0;0;0;0;0;0;0;0;0;0;0.21487;-0.093745;0.00096226;0.21502;-0.093894
264;1.4939;0.40838;-0.15533;0.37784;0;0;0;0;0;0;0;0;0;0;0;0;0;0.21578;-0.094107;0.00096166;0.21593;-0.094256
265;1.5022;0.40859;-0.1552;0.37738;0;0;0;0;0;0;0;0;0;0;0;0;0;0.21673;-0.094472;0.00095786;0.21688;-0.094621
266;1.5105;0.40852;-0.15513;0.3768;0;0;0;0;0;0;0;0;0;0;0;0;0;0.21764;-0.09482;0.00095642;0.21779;-0.09497
267;1.5188;0.40853;-0.15535;0.37609;0;0;0;0;0;0;0;0;0;0;0;0;0;0.21856;-0.095215;0.00095095;0.21871;-0.095366
268;1.5271;0.40852;-0.15528;0.37533;0;0;0;0;0;0;0;0;0;0;0;0;0;0.21949;-0.095556;0.0009504;0.21965;-0.095707
269;1.5359;0.4086;-0.15529;0.37451;0;0;0;0;0;0;0;0;0;0;0;0;0;0.22042;-0.095906;0.00094963;0.22057;-0.096058
270;1.5441;0.40848;-0.15521;0.37352;0;0;0;0;0;0;0;0;0;0;0;0;0;0.22133;-0.09624;0.00094465;0.22148;-0.096392
271;1.5527;0.40844;-0.15523;0.37248;0;0;0;0;0;0;0;0;0;0;0;0;0;0.22223;-0.096579;0.00093285;0.22239;-0.096732
272;1.5612;0.40846;-0.15521;0.37124;0;0;0;0;0;0;0;0;0;0;0;0;0;0.22317;-0.096903;0.0009211;0.22332;-0.097057
273;1.5696;0.40835;-0.15516;0.36978;0;0;0;0;0;0;0;0;0;0;0;0;0;0.22402;-0.097251;0.00093693;0.22418;-0.097406
274;1.5782;0.40842;-0.15526;0.36828;0;0;0;0;0;0;0;0;0;0;0;0;0;0.22493;-0.097521;0.00092711;0.22509;-0.097678
275;1.5867;0.40823;-0.15524;0.36649;0;0;0;0;0;0;0;0;0;0;0;0;0;0.22582;-0.097846;0.0009283;0.22598;-0.098003
276;1.5952;0.40823;-0.15518;0.36467;0;0;0;0;0;0;0;0;0;0;0;0;0;0.22671;-0.098137;0.00091677;0.22687;-0.098295
277;1.6039;0.40813;-0.15515;0.36256;0;0;0;0;0;0;0;0;0;0;0;0;0;0.22758;-0.098421;0.00092107;0.22773;-0.09858
278;1.6124;0.40807;-0.15519;0.36021;0;0;0;0;0;0;0;0;0;0;0;0;0;0.22844;-0.098701;0.00091652;0.2286;-0.098861
279;1.6215;0.40809;-0.15513;0.3576;0;0;0;0;0;0;0;0;0;0;0;0;0;0.22934;-0.098956;0.00090927;0.2295;-0.099116
280;1.63;0.40787;-0.1551;0.35466;0;0;0;0;0;0;0;0;0;0;0;0;0;0.23015;-0.09921;0.00089896;0.23032;-0.099372
281;1.6391;0.40777;-0.15513;0.35137;0;0;0;0;0;0;0;0;0;0;0;0;0;0.23098;-0.09945;0.00090413;0.23114;-0.099613
282;1.6485;0.40762;-0.15509;0.34742;0;0;0;0;0;0;0;0;0;0;0;0;0;0.2318;-0.099662;0.00089809;0.23196;-0.099824
283;1.6581;0.40741;-0.15503;0.34297;0;0;0;0;0;0;0;0;0;0;0;0;0;0.23225;-0.099739;0.00086315;0.23242;-0.099902
284;NaN;NaN;NaN;0.28201;0;0;0;0;0;0;0;0;0;0;0;0;0;0;0;0;0;0
285;NaN;NaN;NaN;0.19216;0;0;0;0;0;0;0;0;0;0;0;0;0;0;0;0;0;0
286;NaN;NaN;NaN;0.11036;0;0;0;0;0;0;0;0;0;0;0;0;0;0;0;0;0;0
287;NaN;NaN;NaN;0.029861;0;0;0;0;0;0;0;0;0;0;0;0;0;0;0;0;0;0
287.5;NaN;NaN;NaN;6.86e-05;0;0;0;0;0;0;0;0;0;0;0;0;0;0;0;0;0;0