File: Template_Auto_Cali_large_DP600/_data/DP600Large_CH_00_001_Front_DIC_File.txt
Date of Test;Material;Sample Geometry;Orientation [°];Test Number;Nominal Speed [mm/min];Thickness [mm];Central Width [mm];Gauge Width / Diameter [mm];Pixel to mm ratio [mm/px];Extensometer 1-4 [mm];Extensometer 2-3 [mm];Extensometer 5-6 [mm];;;;;
07/27/21;DP600Large;CH;00;1;0.0798;0.28735;4;1;0;6;0.20001;0.20001;;;;;
;;;;;;;;;;;;;;;;;
Time [s];U1 [mm];U2 [mm];U3 [mm];Force [kN];Ambient Temperature [°C];DIC Zone X 1 [px];DIC Zone Y 1 [px];DIC Zone X 2 [px];DIC Zone Y 2 [px];DIC Zone X 3 [px];DIC Zone Y 3 [px];DIC Zone X 4 [px];DIC Zone Y 4 [px];DIC Zone X 5 [px];DIC Zone Y 5 [px];DIC Zone X 6 [px];DIC Zone Y 6 [px]
0;0;0;0;0.0018228;0;0;0;0;0;0;0;0;0;0;0;0;0
0.999;-8.5522e-05;-2.2258e-06;4.856e-05;0.0018326;0;0;0;0;0;0;0;0;0;0;0;0;0
1.999;-4.0817e-05;-1.3573e-05;0.00010305;0.0018424;0;0;0;0;0;0;0;0;0;0;0;0;0
3;-4.7251e-06;1.6142e-05;6.7762e-05;0.0018718;0;0;0;0;0;0;0;0;0;0;0;0;0
4;-1.288e-05;6.2971e-05;6.9415e-05;0.0019306;0;0;0;0;0;0;0;0;0;0;0;0;0
4.999;4.0192e-05;2.3422e-05;4.476e-05;0.0021168;0;0;0;0;0;0;0;0;0;0;0;0;0
5.999;0.00018332;-1.1632e-05;0.0001108;0.0030576;0;0;0;0;0;0;0;0;0;0;0;0;0
6.999;0.00024737;1.4674e-05;1.7513e-05;0.0046158;0;0;0;0;0;0;0;0;0;0;0;0;0
7.999;0.00023582;1.6128e-05;9.0932e-05;0.0066248;0;0;0;0;0;0;0;0;0;0;0;0;0
9;0.00032394;9.4159e-05;0.00010966;0.0086828;0;0;0;0;0;0;0;0;0;0;0;0;0
10;0.00035324;0.00011067;0.00015375;0.010584;0;0;0;0;0;0;0;0;0;0;0;0;0
10.999;0.00044155;0.00014143;0.0001394;0.012309;0;0;0;0;0;0;0;0;0;0;0;0;0
11.999;0.00045103;0.00015968;0.00016989;0.014181;0;0;0;0;0;0;0;0;0;0;0;0;0
13;0.00050894;0.0001858;7.3064e-05;0.016268;0;0;0;0;0;0;0;0;0;0;0;0;0
13.999;0.00056372;0.00027561;0.00021002;0.018581;0;0;0;0;0;0;0;0;0;0;0;0;0
15;0.00059529;0.00031045;-3.2337e-06;0.021109;0;0;0;0;0;0;0;0;0;0;0;0;0
15.999;0.00072505;0.0003967;7.1613e-05;0.023834;0;0;0;0;0;0;0;0;0;0;0;0;0
17;0.00082881;0.00040144;2.1717e-05;0.026676;0;0;0;0;0;0;0;0;0;0;0;0;0
17.999;0.00095813;0.00043004;3.253e-05;0.029586;0;0;0;0;0;0;0;0;0;0;0;0;0
19;0.00096413;0.00034208;0.00015521;0.032516;0;0;0;0;0;0;0;0;0;0;0;0;0
20;0.0010881;0.0004745;0.00013075;0.035466;0;0;0;0;0;0;0;0;0;0;0;0;0
20.999;0.0011177;0.00047178;0.00022831;0.038583;0;0;0;0;0;0;0;0;0;0;0;0;0
22;0.0012698;0.00049905;2.89e-07;0.041503;0;0;0;0;0;0;0;0;0;0;0;0;0
23;0.001371;0.00055475;0.00012772;0.04458;0;0;0;0;0;0;0;0;0;0;0;0;0
23.999;0.0014217;0.00056616;9.6635e-05;0.047746;0;0;0;0;0;0;0;0;0;0;0;0;0
24.999;0.0015941;0.00055227;0.00014954;0.051078;0;0;0;0;0;0;0;0;0;0;0;0;0
26;0.001631;0.00061144;7.9023e-05;0.054214;0;0;0;0;0;0;0;0;0;0;0;0;0
27;0.0017666;0.00060366;6.5773e-05;0.057555;0;0;0;0;0;0;0;0;0;0;0;0;0
28;0.0018384;0.00069016;0.00021087;0.060956;0;0;0;0;0;0;0;0;0;0;0;0;0
28.999;0.0017788;0.00064468;0.00011687;0.064464;0;0;0;0;0;0;0;0;0;0;0;0;0
29.999;0.0018442;0.00065846;0.0001754;0.068041;0;0;0;0;0;0;0;0;0;0;0;0;0
30.999;0.0022289;0.00068378;0.00012298;0.071687;0;0;0;0;0;0;0;0;0;0;0;0;0
31.999;0.0022254;0.00062767;0.00012409;0.075391;0;0;0;0;0;0;0;0;0;0;0;0;0
32.999;0.0023571;0.00081129;0.00027415;0.079155;0;0;0;0;0;0;0;0;0;0;0;0;0
33.999;0.002425;0.00069699;0.00012078;0.083045;0;0;0;0;0;0;0;0;0;0;0;0;0
34.999;0.0025946;0.00074427;0.00024703;0.087083;0;0;0;0;0;0;0;0;0;0;0;0;0
35.999;0.0026233;0.00077812;0.00026073;0.091267;0;0;0;0;0;0;0;0;0;0;0;0;0
36.999;0.0028181;0.00069991;0.00022368;0.095599;0;0;0;0;0;0;0;0;0;0;0;0;0
37.999;0.0029575;0.00075762;0.00012944;0.10008;0;0;0;0;0;0;0;0;0;0;0;0;0
38.999;0.0032679;0.00073814;0.00014958;0.10476;0;0;0;0;0;0;0;0;0;0;0;0;0
40;0.003315;0.00069307;0.00034383;0.1096;0;0;0;0;0;0;0;0;0;0;0;0;0
41;0.0031288;0.00072537;0.00023965;0.11465;0;0;0;0;0;0;0;0;0;0;0;0;0
42;0.0033707;0.00080422;0.00022028;0.11988;0;0;0;0;0;0;0;0;0;0;0;0;0
42.999;0.0036451;0.00072373;0.00035592;0.12527;0;0;0;0;0;0;0;0;0;0;0;0;0
43.999;0.0038584;0.00083688;0.00028804;0.13094;0;0;0;0;0;0;0;0;0;0;0;0;0
45;0.004267;0.00070682;0.00020549;0.13687;0;0;0;0;0;0;0;0;0;0;0;0;0
46;0.0042351;0.0006966;0.0003549;0.14307;0;0;0;0;0;0;0;0;0;0;0;0;0
46.999;0.0043033;0.00072881;0.00029026;0.14969;0;0;0;0;0;0;0;0;0;0;0;0;0
47.999;0.0046834;0.0007435;0.00037107;0.15582;0;0;0;0;0;0;0;0;0;0;0;0;0
48.999;0.0049583;0.00066906;0.00023367;0.16226;0;0;0;0;0;0;0;0;0;0;0;0;0
50;0.0050784;0.0006041;0.00040227;0.16894;0;0;0;0;0;0;0;0;0;0;0;0;0
50.999;0.0053518;0.00066461;0.00033559;0.1752;0;0;0;0;0;0;0;0;0;0;0;0;0
51.999;0.0055282;0.00067576;0.00047929;0.18213;0;0;0;0;0;0;0;0;0;0;0;0;0
53;0.0058271;0.00061644;0.00037548;0.18864;0;0;0;0;0;0;0;0;0;0;0;0;0
53.999;0.0061737;0.00066448;0.00041354;0.19549;0;0;0;0;0;0;0;0;0;0;0;0;0
55;0.0063778;0.00066114;0.00040429;0.2023;0;0;0;0;0;0;0;0;0;0;0;0;0
56;0.0066283;0.00072852;0.00043486;0.20882;0;0;0;0;0;0;0;0;0;0;0;0;0
56.999;0.006926;0.00068453;0.00046129;0.21579;0;0;0;0;0;0;0;0;0;0;0;0;0
57.999;0.0071808;0.00068752;0.00057593;0.22228;0;0;0;0;0;0;0;0;0;0;0;0;0
59;0.0074375;0.00073223;0.00065603;0.22856;0;0;0;0;0;0;0;0;0;0;0;0;0
59.999;0.0075983;0.00078401;0.00060652;0.23453;0;0;0;0;0;0;0;0;0;0;0;0;0
60.999;0.0078862;0.00078189;0.00073314;0.24005;0;0;0;0;0;0;0;0;0;0;0;0;0
62;0.0082386;0.00079511;0.00069821;0.24608;0;0;0;0;0;0;0;0;0;0;0;0;0
62.999;0.0084984;0.00075871;0.00080763;0.25112;0;0;0;0;0;0;0;0;0;0;0;0;0
63.999;0.0086597;0.00091568;0.00080919;0.25669;0;0;0;0;0;0;0;0;0;0;0;0;0
64.999;0.009063;0.0010041;0.00083513;0.26189;0;0;0;0;0;0;0;0;0;0;0;0;0
65.999;0.0092033;0.0010353;0.00088503;0.26695;0;0;0;0;0;0;0;0;0;0;0;0;0
66.999;0.0096204;0.0011487;0.00088296;0.27189;0;0;0;0;0;0;0;0;0;0;0;0;0
67.999;0.0098659;0.0011249;0.0010273;0.27676;0;0;0;0;0;0;0;0;0;0;0;0;0
68.999;0.010222;0.0013159;0.0010972;0.28155;0;0;0;0;0;0;0;0;0;0;0;0;0
70;0.010574;0.0013537;0.0010957;0.28647;0;0;0;0;0;0;0;0;0;0;0;0;0
71;0.010866;0.0014344;0.0011844;0.29093;0;0;0;0;0;0;0;0;0;0;0;0;0
72;0.011149;0.0014795;0.0012912;0.29549;0;0;0;0;0;0;0;0;0;0;0;0;0
72.999;0.011628;0.0016557;0.0012642;0.29994;0;0;0;0;0;0;0;0;0;0;0;0;0
73.999;0.011985;0.0017846;0.0014374;0.30411;0;0;0;0;0;0;0;0;0;0;0;0;0
74.999;0.012354;0.0018707;0.0014841;0.30878;0;0;0;0;0;0;0;0;0;0;0;0;0
76;0.012971;0.0019067;0.0016001;0.31286;0;0;0;0;0;0;0;0;0;0;0;0;0
76.999;0.013327;0.0020781;0.001682;0.31701;0;0;0;0;0;0;0;0;0;0;0;0;0
77.999;0.013668;0.0022505;0.0017792;0.32098;0;0;0;0;0;0;0;0;0;0;0;0;0
78.999;0.01409;0.002375;0.0018376;0.32482;0;0;0;0;0;0;0;0;0;0;0;0;0
79.999;0.014702;0.002516;0.0020265;0.32854;0;0;0;0;0;0;0;0;0;0;0;0;0
80.999;0.015139;0.0025954;0.0021865;0.33215;0;0;0;0;0;0;0;0;0;0;0;0;0
82;0.015582;0.0026923;0.0022508;0.33571;0;0;0;0;0;0;0;0;0;0;0;0;0
83;0.016095;0.0029508;0.0023686;0.33919;0;0;0;0;0;0;0;0;0;0;0;0;0
83.999;0.016608;0.002998;0.0026604;0.34272;0;0;0;0;0;0;0;0;0;0;0;0;0
84.999;0.017205;0.0032248;0.0027718;0.34587;0;0;0;0;0;0;0;0;0;0;0;0;0
85.999;0.017755;0.003329;0.0027406;0.34909;0;0;0;0;0;0;0;0;0;0;0;0;0
86.999;0.018308;0.0034673;0.0029299;0.35222;0;0;0;0;0;0;0;0;0;0;0;0;0
87.999;0.018861;0.0036673;0.0029257;0.35525;0;0;0;0;0;0;0;0;0;0;0;0;0
88.999;0.019524;0.0038365;0.0030209;0.35822;0;0;0;0;0;0;0;0;0;0;0;0;0
89.999;0.020079;0.0040795;0.0033134;0.36124;0;0;0;0;0;0;0;0;0;0;0;0;0
90.999;0.020714;0.0042024;0.0034083;0.36396;0;0;0;0;0;0;0;0;0;0;0;0;0
91.999;0.02144;0.0044524;0.0035357;0.36674;0;0;0;0;0;0;0;0;0;0;0;0;0
92.999;0.021953;0.0046141;0.0036114;0.36944;0;0;0;0;0;0;0;0;0;0;0;0;0
93.999;0.022723;0.0047329;0.0038496;0.37206;0;0;0;0;0;0;0;0;0;0;0;0;0
94.998;0.023474;0.0050314;0.0038958;0.37459;0;0;0;0;0;0;0;0;0;0;0;0;0
95.999;0.024192;0.0051523;0.0041257;0.37705;0;0;0;0;0;0;0;0;0;0;0;0;0
96.999;0.024923;0.0054833;0.0043732;0.37931;0;0;0;0;0;0;0;0;0;0;0;0;0
98;0.025502;0.0056059;0.0043417;0.38169;0;0;0;0;0;0;0;0;0;0;0;0;0
98.999;0.025873;0.0057889;0.0046522;0.38385;0;0;0;0;0;0;0;0;0;0;0;0;0
99.999;0.026897;0.0059917;0.0047514;0.38613;0;0;0;0;0;0;0;0;0;0;0;0;0
101;0.027583;0.0062099;0.0049557;0.38829;0;0;0;0;0;0;0;0;0;0;0;0;0
102;0.028313;0.0064103;0.0049632;0.39036;0;0;0;0;0;0;0;0;0;0;0;0;0
103;0.029089;0.0066315;0.005293;0.39229;0;0;0;0;0;0;0;0;0;0;0;0;0
104;0.029785;0.0068151;0.0054564;0.39431;0;0;0;0;0;0;0;0;0;0;0;0;0
105;0.030481;0.006984;0.0057207;0.39617;0;0;0;0;0;0;0;0;0;0;0;0;0
106;0.031279;0.0071976;0.0059561;0.3981;0;0;0;0;0;0;0;0;0;0;0;0;0
107;0.031949;0.0073803;0.0061058;0.39975;0;0;0;0;0;0;0;0;0;0;0;0;0
108;0.032744;0.0075471;0.0063493;0.40158;0;0;0;0;0;0;0;0;0;0;0;0;0
109;0.033431;0.0077333;0.0065431;0.4033;0;0;0;0;0;0;0;0;0;0;0;0;0
110;0.034165;0.0080084;0.006757;0.40499;0;0;0;0;0;0;0;0;0;0;0;0;0
111;0.034954;0.0080798;0.0069081;0.40665;0;0;0;0;0;0;0;0;0;0;0;0;0
112;0.035706;0.0083793;0.0071198;0.40836;0;0;0;0;0;0;0;0;0;0;0;0;0
113;0.036449;0.0085218;0.007235;0.40991;0;0;0;0;0;0;0;0;0;0;0;0;0
114;0.03717;0.0087321;0.0074782;0.41149;0;0;0;0;0;0;0;0;0;0;0;0;0
115;0.037913;0.0090035;0.0077255;0.41304;0;0;0;0;0;0;0;0;0;0;0;0;0
116;0.03878;0.0091101;0.0079247;0.41462;0;0;0;0;0;0;0;0;0;0;0;0;0
117;0.039387;0.0093629;0.0081082;0.41606;0;0;0;0;0;0;0;0;0;0;0;0;0
118;0.040185;0.0096075;0.0082445;0.41747;0;0;0;0;0;0;0;0;0;0;0;0;0
119;0.040972;0.009731;0.0084561;0.41899;0;0;0;0;0;0;0;0;0;0;0;0;0
120;0.041768;0.010056;0.0085507;0.42036;0;0;0;0;0;0;0;0;0;0;0;0;0
121;0.042606;0.010154;0.0087107;0.42182;0;0;0;0;0;0;0;0;0;0;0;0;0
122;0.043286;0.010406;0.0088859;0.42314;0;0;0;0;0;0;0;0;0;0;0;0;0
123;0.044098;0.010537;0.0091042;0.42454;0;0;0;0;0;0;0;0;0;0;0;0;0
124;0.044835;0.010693;0.0092678;0.42581;0;0;0;0;0;0;0;0;0;0;0;0;0
125;0.045644;0.010938;0.0094976;0.42717;0;0;0;0;0;0;0;0;0;0;0;0;0
126;0.046497;0.011056;0.0096652;0.42845;0;0;0;0;0;0;0;0;0;0;0;0;0
127;0.04733;0.011285;0.009839;0.42974;0;0;0;0;0;0;0;0;0;0;0;0;0
128;0.047996;0.011526;0.0099581;0.43103;0;0;0;0;0;0;0;0;0;0;0;0;0
129;0.048933;0.011673;0.010202;0.43237;0;0;0;0;0;0;0;0;0;0;0;0;0
130;0.049662;0.01187;0.010328;0.43359;0;0;0;0;0;0;0;0;0;0;0;0;0
131;0.05055;0.012071;0.01056;0.43478;0;0;0;0;0;0;0;0;0;0;0;0;0
132;0.051379;0.012265;0.010739;0.43603;0;0;0;0;0;0;0;0;0;0;0;0;0
133;0.052168;0.012427;0.010908;0.43723;0;0;0;0;0;0;0;0;0;0;0;0;0
134;0.052952;0.012678;0.011063;0.43842;0;0;0;0;0;0;0;0;0;0;0;0;0
135;0.053729;0.012857;0.011241;0.43954;0;0;0;0;0;0;0;0;0;0;0;0;0
136;0.054581;0.01311;0.01149;0.44074;0;0;0;0;0;0;0;0;0;0;0;0;0
137;0.055422;0.013244;0.011627;0.44186;0;0;0;0;0;0;0;0;0;0;0;0;0
138;0.056155;0.013443;0.011774;0.44296;0;0;0;0;0;0;0;0;0;0;0;0;0
139;0.057037;0.013637;0.012018;0.44405;0;0;0;0;0;0;0;0;0;0;0;0;0
140;0.057808;0.013802;0.012282;0.44514;0;0;0;0;0;0;0;0;0;0;0;0;0
141;0.058653;0.013961;0.012518;0.4462;0;0;0;0;0;0;0;0;0;0;0;0;0
142;0.059499;0.014219;0.01268;0.44724;0;0;0;0;0;0;0;0;0;0;0;0;0
143;0.060392;0.014357;0.012949;0.44835;0;0;0;0;0;0;0;0;0;0;0;0;0
144;0.061083;0.014569;0.013141;0.44933;0;0;0;0;0;0;0;0;0;0;0;0;0
145;0.061934;0.014767;0.013255;0.4504;0;0;0;0;0;0;0;0;0;0;0;0;0
146;0.062792;0.014933;0.013534;0.45141;0;0;0;0;0;0;0;0;0;0;0;0;0
147;0.063635;0.015242;0.013604;0.45242;0;0;0;0;0;0;0;0;0;0;0;0;0
148;0.064419;0.015369;0.013823;0.45343;0;0;0;0;0;0;0;0;0;0;0;0;0
149;0.065218;0.015617;0.014154;0.45441;0;0;0;0;0;0;0;0;0;0;0;0;0
150;0.0661;0.015857;0.01434;0.45541;0;0;0;0;0;0;0;0;0;0;0;0;0
151;0.067013;0.016037;0.014463;0.45633;0;0;0;0;0;0;0;0;0;0;0;0;0
152;0.06773;0.016216;0.014782;0.45733;0;0;0;0;0;0;0;0;0;0;0;0;0
153;0.068602;0.016443;0.014932;0.45823;0;0;0;0;0;0;0;0;0;0;0;0;0
154;0.069396;0.016639;0.015112;0.45917;0;0;0;0;0;0;0;0;0;0;0;0;0
155;0.070277;0.016898;0.01527;0.4601;0;0;0;0;0;0;0;0;0;0;0;0;0
156;0.071063;0.017074;0.01543;0.46096;0;0;0;0;0;0;0;0;0;0;0;0;0
157;0.071867;0.017316;0.015641;0.4619;0;0;0;0;0;0;0;0;0;0;0;0;0
158;0.072718;0.017558;0.015874;0.46279;0;0;0;0;0;0;0;0;0;0;0;0;0
159;0.073592;0.017756;0.016036;0.46365;0;0;0;0;0;0;0;0;0;0;0;0;0
160;0.074335;0.018036;0.016261;0.46448;0;0;0;0;0;0;0;0;0;0;0;0;0
161;0.075093;0.018206;0.016458;0.46543;0;0;0;0;0;0;0;0;0;0;0;0;0
162;0.07596;0.018379;0.016659;0.46625;0;0;0;0;0;0;0;0;0;0;0;0;0
163;0.076789;0.01869;0.016843;0.46711;0;0;0;0;0;0;0;0;0;0;0;0;0
164;0.077648;0.018913;0.016993;0.46795;0;0;0;0;0;0;0;0;0;0;0;0;0
165;0.07848;0.019066;0.017231;0.46882;0;0;0;0;0;0;0;0;0;0;0;0;0
166;0.079358;0.019201;0.017375;0.46965;0;0;0;0;0;0;0;0;0;0;0;0;0
167;0.08017;0.019535;0.017691;0.47046;0;0;0;0;0;0;0;0;0;0;0;0;0
168;0.080981;0.019824;0.017986;0.47125;0;0;0;0;0;0;0;0;0;0;0;0;0
169;0.081739;0.02005;0.018252;0.47205;0;0;0;0;0;0;0;0;0;0;0;0;0
170;0.082598;0.02022;0.018502;0.47277;0;0;0;0;0;0;0;0;0;0;0;0;0
171;0.083483;0.020565;0.01877;0.47354;0;0;0;0;0;0;0;0;0;0;0;0;0
172;0.084286;0.020767;0.018881;0.4743;0;0;0;0;0;0;0;0;0;0;0;0;0
173;0.085174;0.020879;0.019282;0.47511;0;0;0;0;0;0;0;0;0;0;0;0;0
174;0.085946;0.021167;0.01937;0.47582;0;0;0;0;0;0;0;0;0;0;0;0;0
175;0.08676;0.021427;0.019588;0.47656;0;0;0;0;0;0;0;0;0;0;0;0;0
176;0.087602;0.021646;0.019846;0.47731;0;0;0;0;0;0;0;0;0;0;0;0;0
177;0.088413;0.021857;0.019973;0.47808;0;0;0;0;0;0;0;0;0;0;0;0;0
178;0.089313;0.02216;0.020241;0.47882;0;0;0;0;0;0;0;0;0;0;0;0;0
179;0.090166;0.022472;0.020513;0.47958;0;0;0;0;0;0;0;0;0;0;0;0;0
180;0.090986;0.02265;0.020805;0.48035;0;0;0;0;0;0;0;0;0;0;0;0;0
181;0.091839;0.022837;0.020907;0.48103;0;0;0;0;0;0;0;0;0;0;0;0;0
182;0.092682;0.023142;0.021184;0.48172;0;0;0;0;0;0;0;0;0;0;0;0;0
183;0.093524;0.023412;0.021405;0.48234;0;0;0;0;0;0;0;0;0;0;0;0;0
184;0.094302;0.023654;0.021643;0.483;0;0;0;0;0;0;0;0;0;0;0;0;0
185;0.095196;0.023894;0.021852;0.48365;0;0;0;0;0;0;0;0;0;0;0;0;0
186;0.096066;0.024209;0.022091;0.48436;0;0;0;0;0;0;0;0;0;0;0;0;0
187;0.096765;0.024424;0.022294;0.48504;0;0;0;0;0;0;0;0;0;0;0;0;0
188;0.097665;0.024692;0.022488;0.48572;0;0;0;0;0;0;0;0;0;0;0;0;0
189;0.098445;0.024881;0.022678;0.48637;0;0;0;0;0;0;0;0;0;0;0;0;0
190;0.099268;0.025232;0.022717;0.48703;0;0;0;0;0;0;0;0;0;0;0;0;0
191;0.10004;0.025457;0.022975;0.48765;0;0;0;0;0;0;0;0;0;0;0;0;0
192;0.101;0.02568;0.023214;0.48832;0;0;0;0;0;0;0;0;0;0;0;0;0
193;0.10169;0.025874;0.02331;0.48896;0;0;0;0;0;0;0;0;0;0;0;0;0
194;0.10264;0.026248;0.023381;0.48959;0;0;0;0;0;0;0;0;0;0;0;0;0
195;0.10349;0.026484;0.023697;0.49022;0;0;0;0;0;0;0;0;0;0;0;0;0
196;0.10435;0.026661;0.023936;0.49083;0;0;0;0;0;0;0;0;0;0;0;0;0
197;0.10525;0.026913;0.023984;0.49146;0;0;0;0;0;0;0;0;0;0;0;0;0
198;0.10605;0.02722;0.02422;0.49207;0;0;0;0;0;0;0;0;0;0;0;0;0
199;0.1069;0.027485;0.0245;0.49269;0;0;0;0;0;0;0;0;0;0;0;0;0
200;0.10768;0.027644;0.024615;0.49334;0;0;0;0;0;0;0;0;0;0;0;0;0
201;0.10863;0.027942;0.024768;0.49392;0;0;0;0;0;0;0;0;0;0;0;0;0
202;0.10944;0.028186;0.024933;0.49453;0;0;0;0;0;0;0;0;0;0;0;0;0
203;0.11022;0.028501;0.025115;0.49511;0;0;0;0;0;0;0;0;0;0;0;0;0
204;0.11105;0.028701;0.025246;0.49565;0;0;0;0;0;0;0;0;0;0;0;0;0
205;0.11189;0.028913;0.025606;0.49622;0;0;0;0;0;0;0;0;0;0;0;0;0
206;0.11275;0.029175;0.025811;0.49678;0;0;0;0;0;0;0;0;0;0;0;0;0
207;0.11355;0.029511;0.025998;0.49736;0;0;0;0;0;0;0;0;0;0;0;0;0
208;0.11445;0.029729;0.026215;0.49792;0;0;0;0;0;0;0;0;0;0;0;0;0
209;0.11541;0.029975;0.026436;0.49854;0;0;0;0;0;0;0;0;0;0;0;0;0
210;0.11616;0.030177;0.026593;0.49909;0;0;0;0;0;0;0;0;0;0;0;0;0
211;0.11695;0.03051;0.026689;0.49966;0;0;0;0;0;0;0;0;0;0;0;0;0
212;0.1178;0.030689;0.026966;0.5002;0;0;0;0;0;0;0;0;0;0;0;0;0
213;0.11871;0.03096;0.027241;0.50076;0;0;0;0;0;0;0;0;0;0;0;0;0
214;0.11947;0.031247;0.027374;0.50128;0;0;0;0;0;0;0;0;0;0;0;0;0
215;0.12031;0.031606;0.027641;0.5018;0;0;0;0;0;0;0;0;0;0;0;0;0
216;0.12129;0.031867;0.027776;0.50237;0;0;0;0;0;0;0;0;0;0;0;0;0
217;0.12192;0.03203;0.027888;0.50288;0;0;0;0;0;0;0;0;0;0;0;0;0
218;0.12284;0.032285;0.02807;0.5034;0;0;0;0;0;0;0;0;0;0;0;0;0
219;0.12382;0.03266;0.028304;0.50392;0;0;0;0;0;0;0;0;0;0;0;0;0
220;0.12458;0.032972;0.028526;0.50445;0;0;0;0;0;0;0;0;0;0;0;0;0
221;0.12543;0.033112;0.028677;0.50497;0;0;0;0;0;0;0;0;0;0;0;0;0
222;0.12639;0.033336;0.028986;0.50548;0;0;0;0;0;0;0;0;0;0;0;0;0
223;0.12718;0.033695;0.029212;0.50599;0;0;0;0;0;0;0;0;0;0;0;0;0
224;0.12809;0.033964;0.029412;0.5065;0;0;0;0;0;0;0;0;0;0;0;0;0
225;0.12893;0.034225;0.029693;0.507;0;0;0;0;0;0;0;0;0;0;0;0;0
226;0.12981;0.034484;0.030041;0.50752;0;0;0;0;0;0;0;0;0;0;0;0;0
227;0.13059;0.034748;0.030191;0.50799;0;0;0;0;0;0;0;0;0;0;0;0;0
228;0.13139;0.034971;0.030503;0.50848;0;0;0;0;0;0;0;0;0;0;0;0;0
229;0.13229;0.03536;0.030747;0.50894;0;0;0;0;0;0;0;0;0;0;0;0;0
230;0.13315;0.035625;0.031022;0.50939;0;0;0;0;0;0;0;0;0;0;0;0;0
231;0.13411;0.035872;0.031256;0.50987;0;0;0;0;0;0;0;0;0;0;0;0;0
232;0.13487;0.036213;0.031409;0.51032;0;0;0;0;0;0;0;0;0;0;0;0;0
233;0.13587;0.036462;0.03166;0.5108;0;0;0;0;0;0;0;0;0;0;0;0;0
234;0.13648;0.036754;0.03185;0.51126;0;0;0;0;0;0;0;0;0;0;0;0;0
235;0.13728;0.037002;0.031995;0.51174;0;0;0;0;0;0;0;0;0;0;0;0;0
236;0.13835;0.037305;0.032169;0.51225;0;0;0;0;0;0;0;0;0;0;0;0;0
237;0.13927;0.037572;0.032353;0.51271;0;0;0;0;0;0;0;0;0;0;0;0;0
238;0.14012;0.037888;0.032553;0.51318;0;0;0;0;0;0;0;0;0;0;0;0;0
239;0.14071;0.038045;0.03265;0.51364;0;0;0;0;0;0;0;0;0;0;0;0;0
240;0.14179;0.038294;0.032844;0.51406;0;0;0;0;0;0;0;0;0;0;0;0;0
241;0.14268;0.03866;0.033156;0.5145;0;0;0;0;0;0;0;0;0;0;0;0;0
242;0.14362;0.038992;0.033363;0.51494;0;0;0;0;0;0;0;0;0;0;0;0;0
243;0.14435;0.03926;0.033635;0.51538;0;0;0;0;0;0;0;0;0;0;0;0;0
244;0.14527;0.039555;0.033879;0.51584;0;0;0;0;0;0;0;0;0;0;0;0;0
245;0.14614;0.039808;0.034027;0.51629;0;0;0;0;0;0;0;0;0;0;0;0;0
246;0.14699;0.040107;0.034262;0.51671;0;0;0;0;0;0;0;0;0;0;0;0;0
247;0.14782;0.040354;0.034538;0.51718;0;0;0;0;0;0;0;0;0;0;0;0;0
248;0.14872;0.040735;0.034638;0.51759;0;0;0;0;0;0;0;0;0;0;0;0;0
249;0.1496;0.040975;0.034846;0.51801;0;0;0;0;0;0;0;0;0;0;0;0;0
250;0.15051;0.041162;0.035035;0.51841;0;0;0;0;0;0;0;0;0;0;0;0;0
251;0.15137;0.041535;0.03528;0.51888;0;0;0;0;0;0;0;0;0;0;0;0;0
252;0.15228;0.041734;0.035411;0.51927;0;0;0;0;0;0;0;0;0;0;0;0;0
253;0.15308;0.041991;0.035624;0.51969;0;0;0;0;0;0;0;0;0;0;0;0;0
254;0.15407;0.04232;0.035825;0.52011;0;0;0;0;0;0;0;0;0;0;0;0;0
255;0.15495;0.042612;0.035984;0.52052;0;0;0;0;0;0;0;0;0;0;0;0;0
256;0.15586;0.042923;0.036176;0.52094;0;0;0;0;0;0;0;0;0;0;0;0;0
257;0.15667;0.043093;0.036425;0.52133;0;0;0;0;0;0;0;0;0;0;0;0;0
258;0.1576;0.04334;0.036699;0.52177;0;0;0;0;0;0;0;0;0;0;0;0;0
259;0.15846;0.043605;0.036836;0.52218;0;0;0;0;0;0;0;0;0;0;0;0;0
260;0.1594;0.043885;0.037072;0.52258;0;0;0;0;0;0;0;0;0;0;0;0;0
261;0.16031;0.044206;0.037366;0.52298;0;0;0;0;0;0;0;0;0;0;0;0;0
262;0.16152;0.044543;0.037594;0.52337;0;0;0;0;0;0;0;0;0;0;0;0;0
263;0.16199;0.0448;0.037731;0.52378;0;0;0;0;0;0;0;0;0;0;0;0;0
264;0.16289;0.045044;0.037995;0.52418;0;0;0;0;0;0;0;0;0;0;0;0;0
265;0.16385;0.045417;0.038243;0.5246;0;0;0;0;0;0;0;0;0;0;0;0;0
266;0.16462;0.045712;0.038448;0.52499;0;0;0;0;0;0;0;0;0;0;0;0;0
267;0.1655;0.046007;0.038744;0.52538;0;0;0;0;0;0;0;0;0;0;0;0;0
268;0.16645;0.046261;0.038916;0.52577;0;0;0;0;0;0;0;0;0;0;0;0;0
269;0.16747;0.046526;0.039117;0.52615;0;0;0;0;0;0;0;0;0;0;0;0;0
270;0.16852;0.046869;0.039404;0.52652;0;0;0;0;0;0;0;0;0;0;0;0;0
271;0.16914;0.047217;0.039698;0.52691;0;0;0;0;0;0;0;0;0;0;0;0;0
272;0.17029;0.047505;0.039935;0.52728;0;0;0;0;0;0;0;0;0;0;0;0;0
273;0.17109;0.047772;0.040155;0.52763;0;0;0;0;0;0;0;0;0;0;0;0;0
274;0.17192;0.048135;0.040327;0.52801;0;0;0;0;0;0;0;0;0;0;0;0;0
275;0.17295;0.048428;0.040693;0.52837;0;0;0;0;0;0;0;0;0;0;0;0;0
276;0.17382;0.048703;0.040841;0.52872;0;0;0;0;0;0;0;0;0;0;0;0;0
277;0.17456;0.04901;0.041052;0.52907;0;0;0;0;0;0;0;0;0;0;0;0;0
278;0.17538;0.049502;0.041234;0.52945;0;0;0;0;0;0;0;0;0;0;0;0;0
279;0.17639;0.049756;0.041523;0.52982;0;0;0;0;0;0;0;0;0;0;0;0;0
280;0.1773;0.050049;0.041808;0.5302;0;0;0;0;0;0;0;0;0;0;0;0;0
281;0.17824;0.050366;0.042095;0.53054;0;0;0;0;0;0;0;0;0;0;0;0;0
282;0.17914;0.050709;0.042344;0.53091;0;0;0;0;0;0;0;0;0;0;0;0;0
283;0.18007;0.051011;0.042647;0.53127;0;0;0;0;0;0;0;0;0;0;0;0;0
284;0.18097;0.051351;0.042828;0.53163;0;0;0;0;0;0;0;0;0;0;0;0;0
285;0.1819;0.051708;0.043134;0.53196;0;0;0;0;0;0;0;0;0;0;0;0;0
286;0.1828;0.051981;0.043504;0.53233;0;0;0;0;0;0;0;0;0;0;0;0;0
287;0.18372;0.05231;0.043849;0.53266;0;0;0;0;0;0;0;0;0;0;0;0;0
288;0.18458;0.052674;0.043964;0.53302;0;0;0;0;0;0;0;0;0;0;0;0;0
289;0.18563;0.053012;0.044304;0.53336;0;0;0;0;0;0;0;0;0;0;0;0;0
290;0.18664;0.0534;0.044586;0.5337;0;0;0;0;0;0;0;0;0;0;0;0;0
291;0.18745;0.053666;0.044928;0.53401;0;0;0;0;0;0;0;0;0;0;0;0;0
292;0.18847;0.054091;0.045167;0.53434;0;0;0;0;0;0;0;0;0;0;0;0;0
293;0.18929;0.054381;0.04545;0.53466;0;0;0;0;0;0;0;0;0;0;0;0;0
294;0.19037;0.054756;0.045796;0.53497;0;0;0;0;0;0;0;0;0;0;0;0;0
295;0.19122;0.055176;0.046092;0.53532;0;0;0;0;0;0;0;0;0;0;0;0;0
296;0.19217;0.055508;0.046435;0.53562;0;0;0;0;0;0;0;0;0;0;0;0;0
297;0.1931;0.055845;0.046839;0.53592;0;0;0;0;0;0;0;0;0;0;0;0;0
298;0.19407;0.056224;0.047;0.5362;0;0;0;0;0;0;0;0;0;0;0;0;0
299;0.19504;0.05646;0.047443;0.53654;0;0;0;0;0;0;0;0;0;0;0;0;0
300;0.19597;0.056851;0.047793;0.53684;0;0;0;0;0;0;0;0;0;0;0;0;0
301;0.19712;0.057243;0.04819;0.53718;0;0;0;0;0;0;0;0;0;0;0;0;0
302;0.19781;0.057521;0.048553;0.53749;0;0;0;0;0;0;0;0;0;0;0;0;0
303;0.19873;0.057786;0.048755;0.53778;0;0;0;0;0;0;0;0;0;0;0;0;0
304;0.19973;0.058123;0.04914;0.5381;0;0;0;0;0;0;0;0;0;0;0;0;0
305;0.20048;0.058459;0.049483;0.53841;0;0;0;0;0;0;0;0;0;0;0;0;0
306;0.20156;0.058823;0.049829;0.53872;0;0;0;0;0;0;0;0;0;0;0;0;0
307;0.20247;0.0591;0.050202;0.53901;0;0;0;0;0;0;0;0;0;0;0;0;0
308;0.20341;0.059484;0.050539;0.53929;0;0;0;0;0;0;0;0;0;0;0;0;0
309;0.20434;0.059831;0.050863;0.53958;0;0;0;0;0;0;0;0;0;0;0;0;0
310;0.20533;0.06016;0.051224;0.53987;0;0;0;0;0;0;0;0;0;0;0;0;0
311;0.20623;0.060546;0.051534;0.54018;0;0;0;0;0;0;0;0;0;0;0;0;0
312;0.20724;0.061025;0.051909;0.54047;0;0;0;0;0;0;0;0;0;0;0;0;0
313;0.20821;0.061385;0.052113;0.54076;0;0;0;0;0;0;0;0;0;0;0;0;0
314;0.20907;0.061725;0.052465;0.54106;0;0;0;0;0;0;0;0;0;0;0;0;0
315;0.20994;0.062103;0.052805;0.54137;0;0;0;0;0;0;0;0;0;0;0;0;0
316;0.21103;0.062445;0.053166;0.54167;0;0;0;0;0;0;0;0;0;0;0;0;0
317;0.21192;0.062789;0.053491;0.54194;0;0;0;0;0;0;0;0;0;0;0;0;0
318;0.21292;0.063168;0.053847;0.5422;0;0;0;0;0;0;0;0;0;0;0;0;0
319;0.21389;0.063577;0.054155;0.54247;0;0;0;0;0;0;0;0;0;0;0;0;0
320;0.21479;0.063907;0.054489;0.54275;0;0;0;0;0;0;0;0;0;0;0;0;0
321;0.2158;0.064225;0.054797;0.54304;0;0;0;0;0;0;0;0;0;0;0;0;0
322;0.21714;0.064608;0.055273;0.54332;0;0;0;0;0;0;0;0;0;0;0;0;0
323;0.21773;0.064907;0.055648;0.54358;0;0;0;0;0;0;0;0;0;0;0;0;0
324;0.2187;0.065401;0.055809;0.54384;0;0;0;0;0;0;0;0;0;0;0;0;0
325;0.21973;0.065807;0.056084;0.54411;0;0;0;0;0;0;0;0;0;0;0;0;0
326;0.22069;0.066155;0.056462;0.54438;0;0;0;0;0;0;0;0;0;0;0;0;0
327;0.22157;0.066529;0.056872;0.54467;0;0;0;0;0;0;0;0;0;0;0;0;0
328;0.22253;0.066941;0.057119;0.54495;0;0;0;0;0;0;0;0;0;0;0;0;0
329;0.22349;0.067219;0.057411;0.54521;0;0;0;0;0;0;0;0;0;0;0;0;0
330;0.22443;0.067614;0.057805;0.54545;0;0;0;0;0;0;0;0;0;0;0;0;0
331;0.22549;0.068106;0.058184;0.54572;0;0;0;0;0;0;0;0;0;0;0;0;0
332;0.22637;0.068474;0.058542;0.54598;0;0;0;0;0;0;0;0;0;0;0;0;0
333;0.22728;0.068789;0.058833;0.54623;0;0;0;0;0;0;0;0;0;0;0;0;0
334;0.22832;0.06925;0.059231;0.54649;0;0;0;0;0;0;0;0;0;0;0;0;0
335;0.22932;0.069632;0.059603;0.54674;0;0;0;0;0;0;0;0;0;0;0;0;0
336;0.23028;0.069995;0.059879;0.54699;0;0;0;0;0;0;0;0;0;0;0;0;0
337;0.23118;0.070312;0.060268;0.54725;0;0;0;0;0;0;0;0;0;0;0;0;0
338;0.23228;0.070814;0.060723;0.54751;0;0;0;0;0;0;0;0;0;0;0;0;0
339;0.23324;0.071181;0.061119;0.54774;0;0;0;0;0;0;0;0;0;0;0;0;0
340;0.23422;0.071521;0.061467;0.54798;0;0;0;0;0;0;0;0;0;0;0;0;0
341;0.23509;0.071991;0.061781;0.54821;0;0;0;0;0;0;0;0;0;0;0;0;0
342;0.23614;0.072374;0.062196;0.54848;0;0;0;0;0;0;0;0;0;0;0;0;0
343;0.23713;0.07276;0.062761;0.54871;0;0;0;0;0;0;0;0;0;0;0;0;0
344;0.23819;0.073151;0.063136;0.54896;0;0;0;0;0;0;0;0;0;0;0;0;0
345;0.23916;0.073497;0.063455;0.54919;0;0;0;0;0;0;0;0;0;0;0;0;0
346;0.2401;0.073977;0.063891;0.54944;0;0;0;0;0;0;0;0;0;0;0;0;0
347;0.24112;0.074393;0.064296;0.54964;0;0;0;0;0;0;0;0;0;0;0;0;0
348;0.24215;0.074804;0.064722;0.54986;0;0;0;0;0;0;0;0;0;0;0;0;0
349;0.24315;0.075209;0.06513;0.55007;0;0;0;0;0;0;0;0;0;0;0;0;0
350;0.2441;0.075555;0.06565;0.55028;0;0;0;0;0;0;0;0;0;0;0;0;0
351;0.24513;0.076033;0.066108;0.55049;0;0;0;0;0;0;0;0;0;0;0;0;0
352;0.24611;0.07642;0.066575;0.55071;0;0;0;0;0;0;0;0;0;0;0;0;0
353;0.2471;0.076856;0.067049;0.55093;0;0;0;0;0;0;0;0;0;0;0;0;0
354;0.2481;0.077352;0.067543;0.55116;0;0;0;0;0;0;0;0;0;0;0;0;0
355;0.24912;0.077791;0.067945;0.55139;0;0;0;0;0;0;0;0;0;0;0;0;0
356;0.25002;0.078174;0.068385;0.5516;0;0;0;0;0;0;0;0;0;0;0;0;0
357;0.2511;0.07866;0.068937;0.55182;0;0;0;0;0;0;0;0;0;0;0;0;0
358;0.2521;0.079093;0.069501;0.55199;0;0;0;0;0;0;0;0;0;0;0;0;0
359;0.25316;0.079673;0.069847;0.55218;0;0;0;0;0;0;0;0;0;0;0;0;0
360;0.25425;0.080214;0.070414;0.55237;0;0;0;0;0;0;0;0;0;0;0;0;0
361;0.25522;0.080705;0.070875;0.55258;0;0;0;0;0;0;0;0;0;0;0;0;0
362;0.2563;0.081186;0.071394;0.55278;0;0;0;0;0;0;0;0;0;0;0;0;0
363;0.25732;0.081673;0.07176;0.55297;0;0;0;0;0;0;0;0;0;0;0;0;0
364;0.25837;0.082169;0.072216;0.55315;0;0;0;0;0;0;0;0;0;0;0;0;0
365;0.25942;0.082727;0.072735;0.55332;0;0;0;0;0;0;0;0;0;0;0;0;0
366;0.2604;0.083301;0.073233;0.55352;0;0;0;0;0;0;0;0;0;0;0;0;0
367;0.26146;0.083868;0.07362;0.55371;0;0;0;0;0;0;0;0;0;0;0;0;0
368;0.26246;0.084355;0.074043;0.55391;0;0;0;0;0;0;0;0;0;0;0;0;0
369;0.26356;0.08495;0.074575;0.5541;0;0;0;0;0;0;0;0;0;0;0;0;0
370;0.26463;0.085489;0.075038;0.55429;0;0;0;0;0;0;0;0;0;0;0;0;0
371;0.26561;0.08604;0.075431;0.55446;0;0;0;0;0;0;0;0;0;0;0;0;0
372;0.26668;0.086605;0.075923;0.55464;0;0;0;0;0;0;0;0;0;0;0;0;0
373;0.26793;0.087198;0.076514;0.55482;0;0;0;0;0;0;0;0;0;0;0;0;0
374;0.26881;0.08777;0.076983;0.55501;0;0;0;0;0;0;0;0;0;0;0;0;0
375;0.26968;0.088272;0.077465;0.55519;0;0;0;0;0;0;0;0;0;0;0;0;0
376;0.27087;0.088807;0.07791;0.55537;0;0;0;0;0;0;0;0;0;0;0;0;0
377;0.2719;0.089353;0.078415;0.55553;0;0;0;0;0;0;0;0;0;0;0;0;0
378;0.27301;0.089934;0.07897;0.55569;0;0;0;0;0;0;0;0;0;0;0;0;0
379;0.2741;0.090533;0.079455;0.55587;0;0;0;0;0;0;0;0;0;0;0;0;0
380;0.27518;0.091105;0.079991;0.55602;0;0;0;0;0;0;0;0;0;0;0;0;0
381;0.27617;0.091653;0.080392;0.55621;0;0;0;0;0;0;0;0;0;0;0;0;0
382;0.27726;0.092325;0.080931;0.55637;0;0;0;0;0;0;0;0;0;0;0;0;0
383;0.27833;0.092964;0.081385;0.55654;0;0;0;0;0;0;0;0;0;0;0;0;0
384;0.27936;0.093585;0.081912;0.55671;0;0;0;0;0;0;0;0;0;0;0;0;0
385;0.28052;0.094143;0.082564;0.55686;0;0;0;0;0;0;0;0;0;0;0;0;0
386;0.28159;0.094705;0.083043;0.55699;0;0;0;0;0;0;0;0;0;0;0;0;0
387;0.28261;0.095343;0.083557;0.55715;0;0;0;0;0;0;0;0;0;0;0;0;0
388;0.28359;0.095992;0.0841;0.55729;0;0;0;0;0;0;0;0;0;0;0;0;0
389;0.28473;0.096621;0.084637;0.55744;0;0;0;0;0;0;0;0;0;0;0;0;0
390;0.28586;0.097281;0.085249;0.5576;0;0;0;0;0;0;0;0;0;0;0;0;0
391;0.28694;0.097943;0.085905;0.55774;0;0;0;0;0;0;0;0;0;0;0;0;0
392;0.28801;0.098608;0.086368;0.55788;0;0;0;0;0;0;0;0;0;0;0;0;0
393;0.28914;0.099287;0.08712;0.55801;0;0;0;0;0;0;0;0;0;0;0;0;0
394;0.2902;0.10001;0.08771;0.55812;0;0;0;0;0;0;0;0;0;0;0;0;0
395;0.29131;0.10072;0.088298;0.55824;0;0;0;0;0;0;0;0;0;0;0;0;0
396;0.29245;0.10147;0.088898;0.55835;0;0;0;0;0;0;0;0;0;0;0;0;0
397;0.29341;0.10223;0.089577;0.55846;0;0;0;0;0;0;0;0;0;0;0;0;0
398;0.29465;0.10292;0.090253;0.55858;0;0;0;0;0;0;0;0;0;0;0;0;0
399;0.29568;0.1036;0.090846;0.5587;0;0;0;0;0;0;0;0;0;0;0;0;0
400;0.29682;0.10433;0.091492;0.55882;0;0;0;0;0;0;0;0;0;0;0;0;0
401;0.29775;0.10505;0.092283;0.55892;0;0;0;0;0;0;0;0;0;0;0;0;0
402;0.29902;0.10579;0.092896;0.55902;0;0;0;0;0;0;0;0;0;0;0;0;0
403;0.30013;0.10666;0.093581;0.55912;0;0;0;0;0;0;0;0;0;0;0;0;0
404;0.30131;0.1073;0.094115;0.55921;0;0;0;0;0;0;0;0;0;0;0;0;0
405;0.30232;0.10802;0.09497;0.55931;0;0;0;0;0;0;0;0;0;0;0;0;0
406;0.30362;0.10877;0.09574;0.55939;0;0;0;0;0;0;0;0;0;0;0;0;0
407;0.30458;0.10949;0.096324;0.55948;0;0;0;0;0;0;0;0;0;0;0;0;0
408;0.30573;0.11024;0.097044;0.55958;0;0;0;0;0;0;0;0;0;0;0;0;0
409;0.30688;0.11095;0.097834;0.55966;0;0;0;0;0;0;0;0;0;0;0;0;0
410;0.308;0.11168;0.098555;0.55972;0;0;0;0;0;0;0;0;0;0;0;0;0
411;0.30904;0.1124;0.099101;0.55978;0;0;0;0;0;0;0;0;0;0;0;0;0
412;0.31036;0.11317;0.099931;0.55983;0;0;0;0;0;0;0;0;0;0;0;0;0
413;0.31125;0.11389;0.10061;0.55987;0;0;0;0;0;0;0;0;0;0;0;0;0
414;0.31253;0.11465;0.10138;0.55991;0;0;0;0;0;0;0;0;0;0;0;0;0
415;0.31368;0.11545;0.10206;0.55997;0;0;0;0;0;0;0;0;0;0;0;0;0
416;0.31485;0.11619;0.10276;0.56003;0;0;0;0;0;0;0;0;0;0;0;0;0
417;0.31595;0.117;0.10362;0.56009;0;0;0;0;0;0;0;0;0;0;0;0;0
418;0.31708;0.11781;0.10449;0.56016;0;0;0;0;0;0;0;0;0;0;0;0;0
419;0.31825;0.11856;0.10527;0.56022;0;0;0;0;0;0;0;0;0;0;0;0;0
420;0.31938;0.1194;0.10594;0.56027;0;0;0;0;0;0;0;0;0;0;0;0;0
421;0.32058;0.12031;0.10685;0.56031;0;0;0;0;0;0;0;0;0;0;0;0;0
422;0.32174;0.12113;0.10767;0.56033;0;0;0;0;0;0;0;0;0;0;0;0;0
423;0.32277;0.1219;0.10849;0.56035;0;0;0;0;0;0;0;0;0;0;0;0;0
424;0.3241;0.12277;0.10931;0.56038;0;0;0;0;0;0;0;0;0;0;0;0;0
425;0.32527;0.12358;0.11024;0.56041;0;0;0;0;0;0;0;0;0;0;0;0;0
426;0.32646;0.12448;0.11111;0.56044;0;0;0;0;0;0;0;0;0;0;0;0;0
427;0.32759;0.12532;0.11194;0.56047;0;0;0;0;0;0;0;0;0;0;0;0;0
428;0.32879;0.12623;0.11278;0.56049;0;0;0;0;0;0;0;0;0;0;0;0;0
429;0.32999;0.12714;0.11366;0.56051;0;0;0;0;0;0;0;0;0;0;0;0;0
430;0.33126;0.12807;0.11458;0.56052;0;0;0;0;0;0;0;0;0;0;0;0;0
431;0.33251;0.12885;0.11551;0.56052;0;0;0;0;0;0;0;0;0;0;0;0;0
432;0.33375;0.12982;0.11637;0.56054;0;0;0;0;0;0;0;0;0;0;0;0;0
433;0.33476;0.1307;0.11731;0.56054;0;0;0;0;0;0;0;0;0;0;0;0;0
434;0.33603;0.13162;0.11818;0.56054;0;0;0;0;0;0;0;0;0;0;0;0;0
435;0.33716;0.13257;0.11915;0.56054;0;0;0;0;0;0;0;0;0;0;0;0;0
436;0.33844;0.13354;0.12004;0.56051;0;0;0;0;0;0;0;0;0;0;0;0;0
437;0.33971;0.1345;0.12088;0.56049;0;0;0;0;0;0;0;0;0;0;0;0;0
438;0.3408;0.13552;0.12197;0.56047;0;0;0;0;0;0;0;0;0;0;0;0;0
439;0.34209;0.1365;0.12282;0.56046;0;0;0;0;0;0;0;0;0;0;0;0;0
440;0.34336;0.13755;0.12387;0.56046;0;0;0;0;0;0;0;0;0;0;0;0;0
441;0.34455;0.13862;0.12492;0.56044;0;0;0;0;0;0;0;0;0;0;0;0;0
442;0.34582;0.1396;0.12592;0.56042;0;0;0;0;0;0;0;0;0;0;0;0;0
443;0.34713;0.14069;0.1269;0.5604;0;0;0;0;0;0;0;0;0;0;0;0;0
444;0.34826;0.1417;0.12806;0.56038;0;0;0;0;0;0;0;0;0;0;0;0;0
445;0.3496;0.14272;0.1291;0.56036;0;0;0;0;0;0;0;0;0;0;0;0;0
446;0.35075;0.14376;0.13016;0.56035;0;0;0;0;0;0;0;0;0;0;0;0;0
447;0.35205;0.14483;0.13114;0.56032;0;0;0;0;0;0;0;0;0;0;0;0;0
448;0.35346;0.14592;0.13242;0.56032;0;0;0;0;0;0;0;0;0;0;0;0;0
449;0.35458;0.14694;0.13346;0.56032;0;0;0;0;0;0;0;0;0;0;0;0;0
450;0.35585;0.14809;0.1344;0.5603;0;0;0;0;0;0;0;0;0;0;0;0;0
451;0.35702;0.14919;0.13575;0.56028;0;0;0;0;0;0;0;0;0;0;0;0;0
452;0.35839;0.15033;0.13687;0.56025;0;0;0;0;0;0;0;0;0;0;0;0;0
453;0.35961;0.1515;0.13802;0.5602;0;0;0;0;0;0;0;0;0;0;0;0;0
454;0.361;0.15258;0.13928;0.56016;0;0;0;0;0;0;0;0;0;0;0;0;0
455;0.36226;0.15371;0.14048;0.56013;0;0;0;0;0;0;0;0;0;0;0;0;0
456;0.36359;0.15482;0.14168;0.5601;0;0;0;0;0;0;0;0;0;0;0;0;0
457;0.36493;0.15605;0.1428;0.56008;0;0;0;0;0;0;0;0;0;0;0;0;0
458;0.3662;0.15717;0.14408;0.56006;0;0;0;0;0;0;0;0;0;0;0;0;0
459;0.36756;0.15833;0.14533;0.56004;0;0;0;0;0;0;0;0;0;0;0;0;0
460;0.36886;0.15946;0.14646;0.55999;0;0;0;0;0;0;0;0;0;0;0;0;0
461;0.37015;0.16066;0.14775;0.55995;0;0;0;0;0;0;0;0;0;0;0;0;0
462;0.37146;0.16184;0.14901;0.55991;0;0;0;0;0;0;0;0;0;0;0;0;0
463;0.37269;0.16306;0.15019;0.55988;0;0;0;0;0;0;0;0;0;0;0;0;0
464;0.37408;0.16427;0.15146;0.55985;0;0;0;0;0;0;0;0;0;0;0;0;0
465;0.37545;0.16549;0.15272;0.55983;0;0;0;0;0;0;0;0;0;0;0;0;0
466;0.37705;0.16674;0.15397;0.5598;0;0;0;0;0;0;0;0;0;0;0;0;0
467;0.37804;0.16794;0.15524;0.55977;0;0;0;0;0;0;0;0;0;0;0;0;0
468;0.37942;0.16921;0.15651;0.55972;0;0;0;0;0;0;0;0;0;0;0;0;0
469;0.38064;0.1704;0.15785;0.55968;0;0;0;0;0;0;0;0;0;0;0;0;0
470;0.38168;0.17172;0.15914;0.55961;0;0;0;0;0;0;0;0;0;0;0;0;0
471;0.38356;0.17296;0.16049;0.55955;0;0;0;0;0;0;0;0;0;0;0;0;0
472;0.38479;0.17429;0.16181;0.55948;0;0;0;0;0;0;0;0;0;0;0;0;0
473;0.38621;0.1756;0.16309;0.55941;0;0;0;0;0;0;0;0;0;0;0;0;0
474;0.38755;0.17693;0.16445;0.55936;0;0;0;0;0;0;0;0;0;0;0;0;0
475;0.38878;0.17831;0.16574;0.5593;0;0;0;0;0;0;0;0;0;0;0;0;0
476;0.39023;0.17963;0.16715;0.55923;0;0;0;0;0;0;0;0;0;0;0;0;0
477;0.39163;0.18097;0.16849;0.55916;0;0;0;0;0;0;0;0;0;0;0;0;0
478;0.39285;0.18229;0.17002;0.55907;0;0;0;0;0;0;0;0;0;0;0;0;0
479;0.39438;0.18364;0.17136;0.55897;0;0;0;0;0;0;0;0;0;0;0;0;0
480;0.39589;0.18509;0.1727;0.55887;0;0;0;0;0;0;0;0;0;0;0;0;0
481;0.39711;0.18639;0.17415;0.55874;0;0;0;0;0;0;0;0;0;0;0;0;0
482;0.39849;0.18779;0.17553;0.55859;0;0;0;0;0;0;0;0;0;0;0;0;0
483;0.39989;0.18908;0.17685;0.55842;0;0;0;0;0;0;0;0;0;0;0;0;0
484;0.4012;0.19049;0.17835;0.55823;0;0;0;0;0;0;0;0;0;0;0;0;0
485;0.40259;0.19171;0.17967;0.558;0;0;0;0;0;0;0;0;0;0;0;0;0
486;0.4039;0.19311;0.18105;0.55768;0;0;0;0;0;0;0;0;0;0;0;0;0
487;0.40515;0.19439;0.18241;0.55727;0;0;0;0;0;0;0;0;0;0;0;0;0
488;0.40639;0.19569;0.18372;0.55671;0;0;0;0;0;0;0;0;0;0;0;0;0
489;0.40759;0.19694;0.1851;0.55609;0;0;0;0;0;0;0;0;0;0;0;0;0
490;0.4089;0.19818;0.18653;0.55533;0;0;0;0;0;0;0;0;0;0;0;0;0
491;0.41013;0.19947;0.18789;0.55446;0;0;0;0;0;0;0;0;0;0;0;0;0
492;0.41156;0.20089;0.18954;0.55352;0;0;0;0;0;0;0;0;0;0;0;0;0
493;0.41293;0.20232;0.19121;0.55233;0;0;0;0;0;0;0;0;0;0;0;0;0
494;0.41427;0.20357;0.19263;0.55083;0;0;0;0;0;0;0;0;0;0;0;0;0
495;0.41561;0.20501;0.19426;0.54915;0;0;0;0;0;0;0;0;0;0;0;0;0
495.5;0.41638;0.20579;0.19519;0.54826;0;0;0;0;0;0;0;0;0;0;0;0;0