File: Template_Auto_Cali_large_DP600/_data/DP600medium_NT6_00_004_Front_DIC_File.txt
Date of Test;Material;Sample Geometry;Orientation [°];Test Number;Nominal Speed [mm/min];Thickness [mm];Central Width [mm];Gauge Width / Diameter [mm];Pixel to mm ratio [mm/px];Extensometer 1-4 [mm];Extensometer 2-3 [mm];Extensometer 5-6 [mm];;;;;
09/07/21;DP600medium;NT6;00;4;0.0402;0.14143;1;2;0;3;0.09999;0.2;;;;;
;;;;;;;;;;;;;;;;;
Time [s];U1 [mm];U2 [mm];U3 [mm];Force [kN];Ambient Temperature [°C];DIC Zone X 1 [px];DIC Zone Y 1 [px];DIC Zone X 2 [px];DIC Zone Y 2 [px];DIC Zone X 3 [px];DIC Zone Y 3 [px];DIC Zone X 4 [px];DIC Zone Y 4 [px];DIC Zone X 5 [px];DIC Zone Y 5 [px];DIC Zone X 6 [px];DIC Zone Y 6 [px]
0;0;0;0;0.00178;0;0;0;0;0;0;0;0;0;0;0;0;0
1;0.0001205;-1.8464e-05;-7.3581e-05;0.00183;0;0;0;0;0;0;0;0;0;0;0;0;0
2.001;6.2231e-05;6.3136e-05;-4.5079e-05;0.00193;0;0;0;0;0;0;0;0;0;0;0;0;0
3.001;3.0984e-05;3.585e-05;-1.9566e-05;0.00201;0;0;0;0;0;0;0;0;0;0;0;0;0
4;0.0001472;-3.339e-06;-5.433e-05;0.00212;0;0;0;0;0;0;0;0;0;0;0;0;0
5.001;0.00025281;3.3766e-05;-3.2098e-05;0.00219;0;0;0;0;0;0;0;0;0;0;0;0;0
6.001;0.00023001;9.1196e-06;-4.0358e-05;0.00221;0;0;0;0;0;0;0;0;0;0;0;0;0
7;0.00023468;-3.2109e-05;-5.9429e-05;0.00223;0;0;0;0;0;0;0;0;0;0;0;0;0
8;0.00021612;-4.6568e-05;-6.3529e-05;0.00224;0;0;0;0;0;0;0;0;0;0;0;0;0
9;0.00021664;5.2837e-06;-5.5072e-05;0.00227;0;0;0;0;0;0;0;0;0;0;0;0;0
10.001;0.00030685;5.9674e-05;-5.9003e-05;0.0023;0;0;0;0;0;0;0;0;0;0;0;0;0
11;0.00023348;5.7066e-05;-5.2501e-05;0.00234;0;0;0;0;0;0;0;0;0;0;0;0;0
12;0.00020252;6.0446e-06;-9.2496e-05;0.00237;0;0;0;0;0;0;0;0;0;0;0;0;0
13;0.00025985;2.5991e-05;-0.00015483;0.00242;0;0;0;0;0;0;0;0;0;0;0;0;0
14;0.00021786;4.2636e-05;-7.2309e-05;0.00247;0;0;0;0;0;0;0;0;0;0;0;0;0
15;0.00014341;6.6077e-05;-0.00012803;0.00253;0;0;0;0;0;0;0;0;0;0;0;0;0
16;0.00015352;7.5578e-05;-0.00013687;0.00259;0;0;0;0;0;0;0;0;0;0;0;0;0
17.001;0.00018044;0.00010513;-0.00019512;0.00265;0;0;0;0;0;0;0;0;0;0;0;0;0
18;9.4655e-05;7.4777e-05;-0.00018317;0.00273;0;0;0;0;0;0;0;0;0;0;0;0;0
19;0.00019817;8.1562e-05;-0.00013881;0.00284;0;0;0;0;0;0;0;0;0;0;0;0;0
20;0.0002131;9.2216e-05;-0.00019579;0.00297;0;0;0;0;0;0;0;0;0;0;0;0;0
21.001;0.00022695;6.1938e-05;-0.00016017;0.00312;0;0;0;0;0;0;0;0;0;0;0;0;0
22.001;0.00018956;4.7024e-05;-0.00021618;0.00328;0;0;0;0;0;0;0;0;0;0;0;0;0
23;0.0002487;4.6936e-05;-6.5512e-05;0.00347;0;0;0;0;0;0;0;0;0;0;0;0;0
24;0.00022583;-2.2813e-06;-0.00022338;0.00379;0;0;0;0;0;0;0;0;0;0;0;0;0
25.001;0.00028388;5.4084e-05;-0.0001619;0.00417;0;0;0;0;0;0;0;0;0;0;0;0;0
26;0.00026029;6.1326e-05;-0.00018697;0.00466;0;0;0;0;0;0;0;0;0;0;0;0;0
27.001;0.0002571;8.0263e-06;-0.00016235;0.00522;0;0;0;0;0;0;0;0;0;0;0;0;0
28.001;0.000269;2.0432e-05;-0.00020227;0.00573;0;0;0;0;0;0;0;0;0;0;0;0;0
29;0.00023216;2.5192e-05;-0.00020375;0.00622;0;0;0;0;0;0;0;0;0;0;0;0;0
30;0.00037052;2.3321e-06;-0.00018982;0.00671;0;0;0;0;0;0;0;0;0;0;0;0;0
31;0.00034137;4.437e-05;-0.00022226;0.00717;0;0;0;0;0;0;0;0;0;0;0;0;0
32.001;0.00050548;0.00010194;-0.0002034;0.00761;0;0;0;0;0;0;0;0;0;0;0;0;0
33;0.00043148;0.00010441;-0.0001516;0.00808;0;0;0;0;0;0;0;0;0;0;0;0;0
34;0.00047845;0.00015632;-0.00018806;0.00853;0;0;0;0;0;0;0;0;0;0;0;0;0
35.001;0.00055699;0.00012259;-0.00022862;0.00902;0;0;0;0;0;0;0;0;0;0;0;0;0
36;0.00060424;0.00012785;-0.00023223;0.00954;0;0;0;0;0;0;0;0;0;0;0;0;0
37.001;0.00073689;9.5868e-05;-0.00025223;0.01001;0;0;0;0;0;0;0;0;0;0;0;0;0
38.001;0.00058269;4.7606e-05;-0.00029944;0.01051;0;0;0;0;0;0;0;0;0;0;0;0;0
39.001;0.00072694;6.7697e-05;-0.00028953;0.01105;0;0;0;0;0;0;0;0;0;0;0;0;0
40.001;0.00077178;0.00010674;-0.00029805;0.01157;0;0;0;0;0;0;0;0;0;0;0;0;0
41.001;0.00074171;9.854e-05;-0.00027928;0.01213;0;0;0;0;0;0;0;0;0;0;0;0;0
42;0.00078138;0.00010852;-0.00030651;0.01271;0;0;0;0;0;0;0;0;0;0;0;0;0
43;0.00079069;8.7067e-05;-0.00027671;0.01331;0;0;0;0;0;0;0;0;0;0;0;0;0
44;0.00079025;0.00011296;-0.00029905;0.01394;0;0;0;0;0;0;0;0;0;0;0;0;0
45;0.00084616;0.00012112;-0.00032371;0.01462;0;0;0;0;0;0;0;0;0;0;0;0;0
46;0.00092045;4.1418e-05;-0.00036653;0.01531;0;0;0;0;0;0;0;0;0;0;0;0;0
47.001;0.0010026;4.5721e-05;-0.00031412;0.01605;0;0;0;0;0;0;0;0;0;0;0;0;0
48;0.0012071;0.00011816;-0.00034326;0.01682;0;0;0;0;0;0;0;0;0;0;0;0;0
49;0.0011248;0.00010851;-0.00034743;0.01758;0;0;0;0;0;0;0;0;0;0;0;0;0
50;0.0012549;8.9198e-05;-0.00038316;0.0184;0;0;0;0;0;0;0;0;0;0;0;0;0
51;0.0011623;0.00013028;-0.00035672;0.01924;0;0;0;0;0;0;0;0;0;0;0;0;0
52.001;0.0012115;0.00013445;-0.00034883;0.02012;0;0;0;0;0;0;0;0;0;0;0;0;0
53;0.0012312;0.00012036;-0.00035505;0.02102;0;0;0;0;0;0;0;0;0;0;0;0;0
54;0.0012685;9.4131e-05;-0.00038385;0.02198;0;0;0;0;0;0;0;0;0;0;0;0;0
55;0.001401;4.5039e-05;-0.00040723;0.0229;0;0;0;0;0;0;0;0;0;0;0;0;0
56;0.0014746;8.7465e-05;-0.00040331;0.02392;0;0;0;0;0;0;0;0;0;0;0;0;0
57;0.0015952;0.00010516;-0.00040306;0.02495;0;0;0;0;0;0;0;0;0;0;0;0;0
58;0.0015863;6.2734e-05;-0.00037881;0.02602;0;0;0;0;0;0;0;0;0;0;0;0;0
59;0.0017801;0.00013675;-0.00039507;0.02718;0;0;0;0;0;0;0;0;0;0;0;0;0
60;0.0018481;0.00021533;-0.00040085;0.02826;0;0;0;0;0;0;0;0;0;0;0;0;0
61;0.0019181;0.00011768;-0.00043672;0.02948;0;0;0;0;0;0;0;0;0;0;0;0;0
62.001;0.0020198;0.00015449;-0.00044517;0.03063;0;0;0;0;0;0;0;0;0;0;0;0;0
63;0.0020755;0.00011893;-0.00045362;0.03183;0;0;0;0;0;0;0;0;0;0;0;0;0
64;0.0021592;7.2986e-05;-0.00051272;0.03304;0;0;0;0;0;0;0;0;0;0;0;0;0
65;0.002267;2.357e-05;-0.00057542;0.03425;0;0;0;0;0;0;0;0;0;0;0;0;0
66.001;0.0024072;7.2665e-05;-0.00049363;0.03545;0;0;0;0;0;0;0;0;0;0;0;0;0
67;0.0024748;4.7307e-05;-0.00052467;0.03668;0;0;0;0;0;0;0;0;0;0;0;0;0
68;0.002504;3.3264e-05;-0.00057689;0.03793;0;0;0;0;0;0;0;0;0;0;0;0;0
69;0.0026971;0.00012157;-0.00058768;0.03923;0;0;0;0;0;0;0;0;0;0;0;0;0
70;0.0028012;8.5963e-05;-0.00053534;0.04044;0;0;0;0;0;0;0;0;0;0;0;0;0
71.001;0.0028749;4.7692e-05;-0.00062062;0.04174;0;0;0;0;0;0;0;0;0;0;0;0;0
72;0.0029836;0.00011232;-0.0005799;0.04297;0;0;0;0;0;0;0;0;0;0;0;0;0
73;0.0031936;9.0937e-05;-0.00066408;0.04416;0;0;0;0;0;0;0;0;0;0;0;0;0
74;0.0033411;0.00011169;-0.00068484;0.04538;0;0;0;0;0;0;0;0;0;0;0;0;0
75;0.0034366;0.00016512;-0.0006579;0.04661;0;0;0;0;0;0;0;0;0;0;0;0;0
76;0.0036418;0.00010785;-0.00062731;0.04783;0;0;0;0;0;0;0;0;0;0;0;0;0
77;0.0038024;0.00015423;-0.00065145;0.04902;0;0;0;0;0;0;0;0;0;0;0;0;0
78;0.0039683;0.00011493;-0.00066862;0.0502;0;0;0;0;0;0;0;0;0;0;0;0;0
79;0.0041661;0.00020469;-0.00070744;0.05135;0;0;0;0;0;0;0;0;0;0;0;0;0
80;0.0043671;0.00014063;-0.00067903;0.05255;0;0;0;0;0;0;0;0;0;0;0;0;0
81;0.0046405;0.00021073;-0.00071408;0.05369;0;0;0;0;0;0;0;0;0;0;0;0;0
82;0.0048418;0.00021989;-0.00077783;0.05472;0;0;0;0;0;0;0;0;0;0;0;0;0
83;0.0050426;0.00024056;-0.0007888;0.05578;0;0;0;0;0;0;0;0;0;0;0;0;0
84;0.0052672;0.00030209;-0.00077061;0.0568;0;0;0;0;0;0;0;0;0;0;0;0;0
85;0.0055013;0.0003365;-0.00076783;0.05772;0;0;0;0;0;0;0;0;0;0;0;0;0
86;0.005856;0.0002898;-0.00087331;0.05866;0;0;0;0;0;0;0;0;0;0;0;0;0
87;0.0061137;0.00025927;-0.00089808;0.0596;0;0;0;0;0;0;0;0;0;0;0;0;0
88;0.0064225;0.00030689;-0.00088448;0.06048;0;0;0;0;0;0;0;0;0;0;0;0;0
89;0.0067421;0.00033764;-0.00095273;0.06129;0;0;0;0;0;0;0;0;0;0;0;0;0
90;0.0070452;0.00034185;-0.00095273;0.06212;0;0;0;0;0;0;0;0;0;0;0;0;0
91;0.0073882;0.00033278;-0.0010037;0.06289;0;0;0;0;0;0;0;0;0;0;0;0;0
92.001;0.0077693;0.00044609;-0.00096527;0.06359;0;0;0;0;0;0;0;0;0;0;0;0;0
93;0.0081522;0.00041571;-0.0010739;0.06429;0;0;0;0;0;0;0;0;0;0;0;0;0
94.001;0.0084346;0.00039082;-0.00098473;0.06497;0;0;0;0;0;0;0;0;0;0;0;0;0
95;0.0089162;0.00049247;-0.001059;0.06562;0;0;0;0;0;0;0;0;0;0;0;0;0
96;0.0092933;0.0004546;-0.0011244;0.06628;0;0;0;0;0;0;0;0;0;0;0;0;0
97;0.0096331;0.00046137;-0.0011895;0.06686;0;0;0;0;0;0;0;0;0;0;0;0;0
98;0.010098;0.00048858;-0.0010674;0.06742;0;0;0;0;0;0;0;0;0;0;0;0;0
99;0.010519;0.00047699;-0.0011314;0.06796;0;0;0;0;0;0;0;0;0;0;0;0;0
100;0.010997;0.00053488;-0.0012175;0.06852;0;0;0;0;0;0;0;0;0;0;0;0;0
101;0.011437;0.00061684;-0.0012052;0.06905;0;0;0;0;0;0;0;0;0;0;0;0;0
102;0.011786;0.00066957;-0.0012735;0.06953;0;0;0;0;0;0;0;0;0;0;0;0;0
103;0.012248;0.00061672;-0.0012777;0.07006;0;0;0;0;0;0;0;0;0;0;0;0;0
104;0.012709;0.00073257;-0.0013098;0.07054;0;0;0;0;0;0;0;0;0;0;0;0;0
105;0.013175;0.00065127;-0.001299;0.07098;0;0;0;0;0;0;0;0;0;0;0;0;0
106;0.013565;0.00075182;-0.0013084;0.07143;0;0;0;0;0;0;0;0;0;0;0;0;0
107;0.014109;0.00075834;-0.0013915;0.07189;0;0;0;0;0;0;0;0;0;0;0;0;0
108;0.014512;0.00077588;-0.0014826;0.0723;0;0;0;0;0;0;0;0;0;0;0;0;0
109;0.014968;0.00081514;-0.0014258;0.07274;0;0;0;0;0;0;0;0;0;0;0;0;0
110;0.015506;0.00084091;-0.0014742;0.07317;0;0;0;0;0;0;0;0;0;0;0;0;0
111;0.015922;0.00087777;-0.0015058;0.0736;0;0;0;0;0;0;0;0;0;0;0;0;0
112;0.016431;0.00091453;-0.0015752;0.07401;0;0;0;0;0;0;0;0;0;0;0;0;0
113;0.01688;0.00097563;-0.0015171;0.07438;0;0;0;0;0;0;0;0;0;0;0;0;0
114;0.017384;0.0010655;-0.0015817;0.07474;0;0;0;0;0;0;0;0;0;0;0;0;0
115;0.017877;0.0011156;-0.0015725;0.07511;0;0;0;0;0;0;0;0;0;0;0;0;0
116;0.018344;0.0010667;-0.0015686;0.0755;0;0;0;0;0;0;0;0;0;0;0;0;0
117;0.01884;0.0011868;-0.0015935;0.07586;0;0;0;0;0;0;0;0;0;0;0;0;0
118;0.019344;0.001193;-0.0016368;0.07622;0;0;0;0;0;0;0;0;0;0;0;0;0
119;0.019808;0.0012547;-0.0016187;0.07657;0;0;0;0;0;0;0;0;0;0;0;0;0
120;0.020298;0.0013133;-0.0016718;0.07691;0;0;0;0;0;0;0;0;0;0;0;0;0
121;0.020791;0.0013032;-0.0016744;0.07726;0;0;0;0;0;0;0;0;0;0;0;0;0
122;0.021285;0.0014284;-0.0017047;0.07759;0;0;0;0;0;0;0;0;0;0;0;0;0
123;0.021779;0.0014664;-0.0017407;0.07792;0;0;0;0;0;0;0;0;0;0;0;0;0
124;0.022365;0.0013978;-0.0017586;0.07826;0;0;0;0;0;0;0;0;0;0;0;0;0
125;0.022768;0.0014738;-0.0017907;0.0786;0;0;0;0;0;0;0;0;0;0;0;0;0
126;0.023366;0.0014764;-0.0018084;0.07891;0;0;0;0;0;0;0;0;0;0;0;0;0
127;0.023803;0.0015479;-0.001849;0.07921;0;0;0;0;0;0;0;0;0;0;0;0;0
128;0.02433;0.0014967;-0.0018522;0.07954;0;0;0;0;0;0;0;0;0;0;0;0;0
129;0.024898;0.001584;-0.0019027;0.07981;0;0;0;0;0;0;0;0;0;0;0;0;0
130;0.025359;0.0016051;-0.001956;0.08011;0;0;0;0;0;0;0;0;0;0;0;0;0
131;0.025892;0.0016392;-0.0020007;0.08043;0;0;0;0;0;0;0;0;0;0;0;0;0
132;0.02633;0.0017009;-0.0020062;0.08072;0;0;0;0;0;0;0;0;0;0;0;0;0
133;0.026895;0.0017268;-0.0020535;0.08103;0;0;0;0;0;0;0;0;0;0;0;0;0
134;0.027349;0.0018705;-0.0020369;0.08131;0;0;0;0;0;0;0;0;0;0;0;0;0
135;0.027868;0.0019112;-0.0021225;0.08156;0;0;0;0;0;0;0;0;0;0;0;0;0
136;0.028445;0.0019191;-0.0020998;0.08183;0;0;0;0;0;0;0;0;0;0;0;0;0
137;0.028921;0.0020162;-0.0021298;0.08209;0;0;0;0;0;0;0;0;0;0;0;0;0
138;0.029497;0.0020101;-0.0021952;0.08234;0;0;0;0;0;0;0;0;0;0;0;0;0
139;0.029993;0.0020444;-0.0022244;0.08263;0;0;0;0;0;0;0;0;0;0;0;0;0
140;0.030568;0.0021096;-0.0022624;0.08291;0;0;0;0;0;0;0;0;0;0;0;0;0
141;0.031005;0.0022552;-0.0023168;0.08314;0;0;0;0;0;0;0;0;0;0;0;0;0
142;0.031577;0.0023111;-0.0022838;0.08341;0;0;0;0;0;0;0;0;0;0;0;0;0
143;0.032138;0.0024147;-0.0023519;0.08366;0;0;0;0;0;0;0;0;0;0;0;0;0
144;0.032665;0.0023885;-0.0023614;0.08388;0;0;0;0;0;0;0;0;0;0;0;0;0
145;0.033146;0.002377;-0.0024097;0.08414;0;0;0;0;0;0;0;0;0;0;0;0;0
146;0.033727;0.0025758;-0.0024133;0.08437;0;0;0;0;0;0;0;0;0;0;0;0;0
147;0.034297;0.0026112;-0.0024649;0.08458;0;0;0;0;0;0;0;0;0;0;0;0;0
148;0.034814;0.0026261;-0.0025253;0.08481;0;0;0;0;0;0;0;0;0;0;0;0;0
149;0.035364;0.002667;-0.0024881;0.08503;0;0;0;0;0;0;0;0;0;0;0;0;0
150;0.035916;0.0027377;-0.0025704;0.08525;0;0;0;0;0;0;0;0;0;0;0;0;0
151;0.03644;0.0027092;-0.002521;0.08547;0;0;0;0;0;0;0;0;0;0;0;0;0
152;0.036952;0.0028796;-0.0026;0.08569;0;0;0;0;0;0;0;0;0;0;0;0;0
153;0.037482;0.0029062;-0.0025864;0.08589;0;0;0;0;0;0;0;0;0;0;0;0;0
154;0.037966;0.0028586;-0.0025944;0.08609;0;0;0;0;0;0;0;0;0;0;0;0;0
155;0.038596;0.0029349;-0.002498;0.0863;0;0;0;0;0;0;0;0;0;0;0;0;0
156;0.039156;0.0029552;-0.0025805;0.08651;0;0;0;0;0;0;0;0;0;0;0;0;0
157;0.039609;0.0030253;-0.002563;0.08671;0;0;0;0;0;0;0;0;0;0;0;0;0
158;0.040182;0.0029468;-0.0025315;0.08691;0;0;0;0;0;0;0;0;0;0;0;0;0
159;0.040787;0.002962;-0.0025694;0.08708;0;0;0;0;0;0;0;0;0;0;0;0;0
160;0.041263;0.0029793;-0.0025758;0.08726;0;0;0;0;0;0;0;0;0;0;0;0;0
161;0.041761;0.0030416;-0.0026331;0.08745;0;0;0;0;0;0;0;0;0;0;0;0;0
162;0.042371;0.0029938;-0.0025746;0.08763;0;0;0;0;0;0;0;0;0;0;0;0;0
163;0.042851;0.0031126;-0.0025815;0.08782;0;0;0;0;0;0;0;0;0;0;0;0;0
164;0.043457;0.0031869;-0.0026271;0.08802;0;0;0;0;0;0;0;0;0;0;0;0;0
165;0.044018;0.0031447;-0.0026429;0.08818;0;0;0;0;0;0;0;0;0;0;0;0;0
166;0.044515;0.0032106;-0.0026467;0.08837;0;0;0;0;0;0;0;0;0;0;0;0;0
167;0.045034;0.0033048;-0.0026711;0.08854;0;0;0;0;0;0;0;0;0;0;0;0;0
168;0.04568;0.0033051;-0.0026655;0.08871;0;0;0;0;0;0;0;0;0;0;0;0;0
169;0.046204;0.0033962;-0.0027937;0.08889;0;0;0;0;0;0;0;0;0;0;0;0;0
170;0.046796;0.0034091;-0.0028183;0.08907;0;0;0;0;0;0;0;0;0;0;0;0;0
171;0.047367;0.003481;-0.0028929;0.08924;0;0;0;0;0;0;0;0;0;0;0;0;0
172;0.047998;0.0035621;-0.0028997;0.08941;0;0;0;0;0;0;0;0;0;0;0;0;0
173;0.048587;0.0035715;-0.0028326;0.08958;0;0;0;0;0;0;0;0;0;0;0;0;0
174;0.04903;0.0036968;-0.0027313;0.08972;0;0;0;0;0;0;0;0;0;0;0;0;0
175;0.049601;0.003645;-0.0027144;0.08987;0;0;0;0;0;0;0;0;0;0;0;0;0
176;0.0502;0.0038193;-0.002691;0.09003;0;0;0;0;0;0;0;0;0;0;0;0;0
177;0.050724;0.0037793;-0.0027043;0.09015;0;0;0;0;0;0;0;0;0;0;0;0;0
178;0.051332;0.0038878;-0.002723;0.0903;0;0;0;0;0;0;0;0;0;0;0;0;0
179;0.05195;NaN;-0.0027741;0.09046;0;0;0;0;0;0;0;0;0;0;0;0;0
180;0.052487;NaN;-0.0028177;0.09062;0;0;0;0;0;0;0;0;0;0;0;0;0
181;0.053112;NaN;-0.0027629;0.09079;0;0;0;0;0;0;0;0;0;0;0;0;0
182;0.053626;NaN;-0.0028332;0.09094;0;0;0;0;0;0;0;0;0;0;0;0;0
183;0.054231;NaN;-0.0028887;0.09108;0;0;0;0;0;0;0;0;0;0;0;0;0
184;0.054842;NaN;-0.002845;0.09122;0;0;0;0;0;0;0;0;0;0;0;0;0
185;0.055424;NaN;-0.0029618;0.09137;0;0;0;0;0;0;0;0;0;0;0;0;0
186;0.055986;NaN;-0.0030002;0.0915;0;0;0;0;0;0;0;0;0;0;0;0;0
187;0.056509;NaN;-0.0029992;0.09164;0;0;0;0;0;0;0;0;0;0;0;0;0
188;0.057167;NaN;-0.0030606;0.09177;0;0;0;0;0;0;0;0;0;0;0;0;0
189;0.05775;NaN;-0.003132;0.0919;0;0;0;0;0;0;0;0;0;0;0;0;0
190;0.058336;NaN;-0.0031431;0.09205;0;0;0;0;0;0;0;0;0;0;0;0;0
191;0.058911;NaN;-0.0031826;0.09218;0;0;0;0;0;0;0;0;0;0;0;0;0
192;0.05943;NaN;-0.0031702;0.09231;0;0;0;0;0;0;0;0;0;0;0;0;0
193;0.060019;NaN;-0.0032376;0.09244;0;0;0;0;0;0;0;0;0;0;0;0;0
194;0.060593;NaN;-0.0032259;0.09257;0;0;0;0;0;0;0;0;0;0;0;0;0
195;0.061198;NaN;-0.0032407;0.09269;0;0;0;0;0;0;0;0;0;0;0;0;0
196;0.06176;NaN;-0.0033283;0.0928;0;0;0;0;0;0;0;0;0;0;0;0;0
197;0.062372;NaN;-0.0033504;0.09292;0;0;0;0;0;0;0;0;0;0;0;0;0
198;0.062944;NaN;-0.0033987;0.09304;0;0;0;0;0;0;0;0;0;0;0;0;0
199;0.063525;NaN;-0.0033845;0.09316;0;0;0;0;0;0;0;0;0;0;0;0;0
200;0.064076;NaN;-0.0033731;0.09329;0;0;0;0;0;0;0;0;0;0;0;0;0
201;0.064633;NaN;-0.003459;0.0934;0;0;0;0;0;0;0;0;0;0;0;0;0
202;0.065236;NaN;-0.003409;0.09352;0;0;0;0;0;0;0;0;0;0;0;0;0
203;0.065814;NaN;-0.0033978;0.09365;0;0;0;0;0;0;0;0;0;0;0;0;0
204;0.066369;NaN;-0.0034479;0.09375;0;0;0;0;0;0;0;0;0;0;0;0;0
205;0.066942;NaN;-0.0034681;0.09385;0;0;0;0;0;0;0;0;0;0;0;0;0
206;0.067623;NaN;-0.0035355;0.09396;0;0;0;0;0;0;0;0;0;0;0;0;0
207;0.068139;NaN;-0.0035439;0.09405;0;0;0;0;0;0;0;0;0;0;0;0;0
208;0.068769;NaN;-0.0035446;0.09417;0;0;0;0;0;0;0;0;0;0;0;0;0
209;0.069342;NaN;-0.0035615;0.09433;0;0;0;0;0;0;0;0;0;0;0;0;0
210;0.06997;NaN;-0.0035473;0.09445;0;0;0;0;0;0;0;0;0;0;0;0;0
211;0.070634;NaN;-0.0035981;0.09456;0;0;0;0;0;0;0;0;0;0;0;0;0
212;0.071127;NaN;-0.0035422;0.09467;0;0;0;0;0;0;0;0;0;0;0;0;0
213;0.071592;NaN;-0.0035924;0.09475;0;0;0;0;0;0;0;0;0;0;0;0;0
214;0.07229;NaN;-0.0035792;0.09485;0;0;0;0;0;0;0;0;0;0;0;0;0
215;0.072913;NaN;-0.0036321;0.09496;0;0;0;0;0;0;0;0;0;0;0;0;0
216;0.073493;NaN;-0.0036433;0.09505;0;0;0;0;0;0;0;0;0;0;0;0;0
217;0.074052;NaN;-0.0035981;0.09514;0;0;0;0;0;0;0;0;0;0;0;0;0
218;0.074689;NaN;-0.0036495;0.09525;0;0;0;0;0;0;0;0;0;0;0;0;0
219;0.075274;NaN;-0.0036841;0.09534;0;0;0;0;0;0;0;0;0;0;0;0;0
220;0.075906;NaN;-0.0036719;0.09543;0;0;0;0;0;0;0;0;0;0;0;0;0
221;0.076564;NaN;-0.0037327;0.09554;0;0;0;0;0;0;0;0;0;0;0;0;0
222;0.077039;NaN;-0.0038625;0.09563;0;0;0;0;0;0;0;0;0;0;0;0;0
223;0.0775;NaN;-0.0040015;0.09571;0;0;0;0;0;0;0;0;0;0;0;0;0
224;0.078081;NaN;-0.0040226;0.0958;0;0;0;0;0;0;0;0;0;0;0;0;0
225;0.078747;NaN;-0.004121;0.09587;0;0;0;0;0;0;0;0;0;0;0;0;0
226;0.079426;NaN;-0.0041113;0.09594;0;0;0;0;0;0;0;0;0;0;0;0;0
227;0.079971;NaN;-0.004135;0.09601;0;0;0;0;0;0;0;0;0;0;0;0;0
228;0.080644;NaN;-0.0041308;0.09609;0;0;0;0;0;0;0;0;0;0;0;0;0
229;0.081183;NaN;-0.0041604;0.09617;0;0;0;0;0;0;0;0;0;0;0;0;0
230;0.081601;NaN;-0.0041644;0.09626;0;0;0;0;0;0;0;0;0;0;0;0;0
231;0.082262;NaN;-0.0041804;0.09634;0;0;0;0;0;0;0;0;0;0;0;0;0
232;0.082977;NaN;-0.0042058;0.09641;0;0;0;0;0;0;0;0;0;0;0;0;0
233;0.083609;NaN;-0.0042639;0.09649;0;0;0;0;0;0;0;0;0;0;0;0;0
234;0.084211;NaN;-0.0043294;0.09656;0;0;0;0;0;0;0;0;0;0;0;0;0
235;0.08486;NaN;-0.0043642;0.09662;0;0;0;0;0;0;0;0;0;0;0;0;0
236;0.085456;NaN;-0.004412;0.0967;0;0;0;0;0;0;0;0;0;0;0;0;0
237;0.085929;NaN;-0.0043426;0.09676;0;0;0;0;0;0;0;0;0;0;0;0;0
238;0.086548;NaN;-0.0044548;0.09686;0;0;0;0;0;0;0;0;0;0;0;0;0
239;0.087126;NaN;-0.0044106;0.09695;0;0;0;0;0;0;0;0;0;0;0;0;0
240;0.087798;NaN;NaN;0.09702;0;0;0;0;0;0;0;0;0;0;0;0;0
241;0.088408;NaN;NaN;0.09709;0;0;0;0;0;0;0;0;0;0;0;0;0
242;0.089012;NaN;NaN;0.09712;0;0;0;0;0;0;0;0;0;0;0;0;0
243;0.0897;NaN;NaN;0.09717;0;0;0;0;0;0;0;0;0;0;0;0;0
244;0.090266;NaN;NaN;0.09721;0;0;0;0;0;0;0;0;0;0;0;0;0
245;0.090845;NaN;NaN;0.09727;0;0;0;0;0;0;0;0;0;0;0;0;0
246;0.091473;NaN;NaN;0.0973;0;0;0;0;0;0;0;0;0;0;0;0;0
247;0.091949;NaN;NaN;0.09735;0;0;0;0;0;0;0;0;0;0;0;0;0
248;0.092712;NaN;NaN;0.09741;0;0;0;0;0;0;0;0;0;0;0;0;0
249;0.093234;NaN;NaN;0.09746;0;0;0;0;0;0;0;0;0;0;0;0;0
250;0.093857;NaN;NaN;0.09754;0;0;0;0;0;0;0;0;0;0;0;0;0
251;0.094543;NaN;NaN;0.09761;0;0;0;0;0;0;0;0;0;0;0;0;0
252;0.095174;NaN;NaN;0.09766;0;0;0;0;0;0;0;0;0;0;0;0;0
253;0.095741;NaN;NaN;0.09772;0;0;0;0;0;0;0;0;0;0;0;0;0
254;0.096361;NaN;NaN;0.09777;0;0;0;0;0;0;0;0;0;0;0;0;0
255;0.096992;NaN;NaN;0.09783;0;0;0;0;0;0;0;0;0;0;0;0;0
256;0.097621;NaN;NaN;0.09789;0;0;0;0;0;0;0;0;0;0;0;0;0
257;0.098251;NaN;NaN;0.09793;0;0;0;0;0;0;0;0;0;0;0;0;0
258;0.098969;NaN;NaN;0.09798;0;0;0;0;0;0;0;0;0;0;0;0;0
259;0.099493;NaN;NaN;0.09803;0;0;0;0;0;0;0;0;0;0;0;0;0
260;0.10012;NaN;NaN;0.09807;0;0;0;0;0;0;0;0;0;0;0;0;0
261;0.10077;NaN;NaN;0.09813;0;0;0;0;0;0;0;0;0;0;0;0;0
262;0.10135;NaN;NaN;0.09817;0;0;0;0;0;0;0;0;0;0;0;0;0
263;0.10197;NaN;NaN;0.09821;0;0;0;0;0;0;0;0;0;0;0;0;0
264;0.10263;NaN;NaN;0.09825;0;0;0;0;0;0;0;0;0;0;0;0;0
265;0.10316;NaN;NaN;0.09829;0;0;0;0;0;0;0;0;0;0;0;0;0
266;0.10382;NaN;NaN;0.09832;0;0;0;0;0;0;0;0;0;0;0;0;0
267;0.1044;NaN;NaN;0.09835;0;0;0;0;0;0;0;0;0;0;0;0;0
268;0.10514;NaN;NaN;0.09839;0;0;0;0;0;0;0;0;0;0;0;0;0
269;0.10567;NaN;NaN;0.09843;0;0;0;0;0;0;0;0;0;0;0;0;0
270;0.10633;NaN;NaN;0.09848;0;0;0;0;0;0;0;0;0;0;0;0;0
271;0.10697;NaN;NaN;0.09855;0;0;0;0;0;0;0;0;0;0;0;0;0
272;0.10757;NaN;NaN;0.09861;0;0;0;0;0;0;0;0;0;0;0;0;0
273;0.10822;NaN;NaN;0.09867;0;0;0;0;0;0;0;0;0;0;0;0;0
274;0.10886;NaN;NaN;0.09873;0;0;0;0;0;0;0;0;0;0;0;0;0
275;0.10947;NaN;NaN;0.09876;0;0;0;0;0;0;0;0;0;0;0;0;0
276;0.11009;NaN;NaN;0.09878;0;0;0;0;0;0;0;0;0;0;0;0;0
277;0.11071;NaN;NaN;0.09879;0;0;0;0;0;0;0;0;0;0;0;0;0
278;0.1114;NaN;NaN;0.09882;0;0;0;0;0;0;0;0;0;0;0;0;0
279;0.11197;NaN;NaN;0.09885;0;0;0;0;0;0;0;0;0;0;0;0;0
280;0.11265;NaN;NaN;0.09888;0;0;0;0;0;0;0;0;0;0;0;0;0
281;0.11322;NaN;NaN;0.09892;0;0;0;0;0;0;0;0;0;0;0;0;0
282;0.11391;NaN;NaN;0.09893;0;0;0;0;0;0;0;0;0;0;0;0;0
283;0.11452;NaN;NaN;0.09895;0;0;0;0;0;0;0;0;0;0;0;0;0
284;0.11511;NaN;NaN;0.09898;0;0;0;0;0;0;0;0;0;0;0;0;0
285;0.11579;NaN;NaN;0.099;0;0;0;0;0;0;0;0;0;0;0;0;0
286;0.11638;NaN;NaN;0.09903;0;0;0;0;0;0;0;0;0;0;0;0;0
287;0.117;NaN;NaN;0.09905;0;0;0;0;0;0;0;0;0;0;0;0;0
288;0.11762;NaN;NaN;0.09906;0;0;0;0;0;0;0;0;0;0;0;0;0
289;0.11833;NaN;NaN;0.09907;0;0;0;0;0;0;0;0;0;0;0;0;0
290;0.11888;NaN;NaN;0.09908;0;0;0;0;0;0;0;0;0;0;0;0;0
291;0.11949;NaN;NaN;0.0991;0;0;0;0;0;0;0;0;0;0;0;0;0
292;0.12017;NaN;NaN;0.09914;0;0;0;0;0;0;0;0;0;0;0;0;0
293;0.12071;NaN;NaN;0.09916;0;0;0;0;0;0;0;0;0;0;0;0;0
294;0.12141;NaN;NaN;0.09917;0;0;0;0;0;0;0;0;0;0;0;0;0
295;0.12203;NaN;NaN;0.09919;0;0;0;0;0;0;0;0;0;0;0;0;0
296;0.12262;NaN;NaN;0.09919;0;0;0;0;0;0;0;0;0;0;0;0;0
297;0.12334;NaN;NaN;0.0992;0;0;0;0;0;0;0;0;0;0;0;0;0
298;0.12402;NaN;NaN;0.09921;0;0;0;0;0;0;0;0;0;0;0;0;0
299;0.1246;NaN;NaN;0.09922;0;0;0;0;0;0;0;0;0;0;0;0;0
300;0.12519;NaN;NaN;0.09924;0;0;0;0;0;0;0;0;0;0;0;0;0
301;0.12583;NaN;NaN;0.09925;0;0;0;0;0;0;0;0;0;0;0;0;0
302;0.12652;NaN;NaN;0.09926;0;0;0;0;0;0;0;0;0;0;0;0;0
303;0.12716;NaN;NaN;0.09927;0;0;0;0;0;0;0;0;0;0;0;0;0
304;0.12778;NaN;NaN;0.09926;0;0;0;0;0;0;0;0;0;0;0;0;0
305;0.1284;NaN;NaN;0.09926;0;0;0;0;0;0;0;0;0;0;0;0;0
306;0.129;NaN;NaN;0.09925;0;0;0;0;0;0;0;0;0;0;0;0;0
307;0.12969;NaN;NaN;0.09925;0;0;0;0;0;0;0;0;0;0;0;0;0
308;0.1303;NaN;NaN;0.09925;0;0;0;0;0;0;0;0;0;0;0;0;0
309;0.13098;NaN;NaN;0.09925;0;0;0;0;0;0;0;0;0;0;0;0;0
310;0.13166;NaN;NaN;0.09926;0;0;0;0;0;0;0;0;0;0;0;0;0
311;0.13222;NaN;NaN;0.09926;0;0;0;0;0;0;0;0;0;0;0;0;0
312;0.13282;NaN;NaN;0.09926;0;0;0;0;0;0;0;0;0;0;0;0;0
313;0.13356;NaN;NaN;0.09926;0;0;0;0;0;0;0;0;0;0;0;0;0
314;0.13414;NaN;NaN;0.09925;0;0;0;0;0;0;0;0;0;0;0;0;0
315;0.13481;NaN;NaN;0.09925;0;0;0;0;0;0;0;0;0;0;0;0;0
316;0.13552;NaN;NaN;0.09927;0;0;0;0;0;0;0;0;0;0;0;0;0
317;0.13614;NaN;NaN;0.09927;0;0;0;0;0;0;0;0;0;0;0;0;0
318;0.13681;NaN;NaN;0.09926;0;0;0;0;0;0;0;0;0;0;0;0;0
319;0.13745;NaN;NaN;0.09924;0;0;0;0;0;0;0;0;0;0;0;0;0
320;0.13803;NaN;NaN;0.09919;0;0;0;0;0;0;0;0;0;0;0;0;0
321;0.13865;NaN;NaN;0.09915;0;0;0;0;0;0;0;0;0;0;0;0;0
322;0.13934;NaN;NaN;0.09916;0;0;0;0;0;0;0;0;0;0;0;0;0
323;0.13998;NaN;NaN;0.09916;0;0;0;0;0;0;0;0;0;0;0;0;0
324;0.14061;NaN;NaN;0.09917;0;0;0;0;0;0;0;0;0;0;0;0;0
325;0.14134;NaN;NaN;0.09917;0;0;0;0;0;0;0;0;0;0;0;0;0
326;0.14188;NaN;NaN;0.09915;0;0;0;0;0;0;0;0;0;0;0;0;0
327;0.14257;NaN;NaN;0.09913;0;0;0;0;0;0;0;0;0;0;0;0;0
328;0.1433;NaN;NaN;0.09911;0;0;0;0;0;0;0;0;0;0;0;0;0
329;0.14387;NaN;NaN;0.0991;0;0;0;0;0;0;0;0;0;0;0;0;0
330;0.14449;NaN;NaN;0.09909;0;0;0;0;0;0;0;0;0;0;0;0;0
331;0.14519;NaN;NaN;0.09908;0;0;0;0;0;0;0;0;0;0;0;0;0
332;0.14582;NaN;NaN;0.09907;0;0;0;0;0;0;0;0;0;0;0;0;0
333;0.14644;NaN;NaN;0.09906;0;0;0;0;0;0;0;0;0;0;0;0;0
334;0.14707;NaN;NaN;0.09906;0;0;0;0;0;0;0;0;0;0;0;0;0
335;0.14784;NaN;NaN;0.09905;0;0;0;0;0;0;0;0;0;0;0;0;0
336;0.14844;NaN;NaN;0.09904;0;0;0;0;0;0;0;0;0;0;0;0;0
337;0.14908;NaN;NaN;0.09902;0;0;0;0;0;0;0;0;0;0;0;0;0
338;0.14969;NaN;NaN;0.09901;0;0;0;0;0;0;0;0;0;0;0;0;0
339;0.15036;NaN;NaN;0.099;0;0;0;0;0;0;0;0;0;0;0;0;0
340;0.15103;NaN;NaN;0.09899;0;0;0;0;0;0;0;0;0;0;0;0;0
341;0.15178;NaN;NaN;0.09898;0;0;0;0;0;0;0;0;0;0;0;0;0
342;0.15237;NaN;NaN;0.09897;0;0;0;0;0;0;0;0;0;0;0;0;0
343;0.15304;NaN;NaN;0.09897;0;0;0;0;0;0;0;0;0;0;0;0;0
344;0.15368;NaN;NaN;0.09896;0;0;0;0;0;0;0;0;0;0;0;0;0
345;0.15437;NaN;NaN;0.09895;0;0;0;0;0;0;0;0;0;0;0;0;0
346;0.15505;NaN;NaN;0.09894;0;0;0;0;0;0;0;0;0;0;0;0;0
347;0.15567;NaN;NaN;0.09893;0;0;0;0;0;0;0;0;0;0;0;0;0
348;0.15642;NaN;NaN;0.09891;0;0;0;0;0;0;0;0;0;0;0;0;0
349;0.1569;NaN;NaN;0.09889;0;0;0;0;0;0;0;0;0;0;0;0;0
350;0.15762;NaN;NaN;0.09888;0;0;0;0;0;0;0;0;0;0;0;0;0
351;0.15822;NaN;NaN;0.09886;0;0;0;0;0;0;0;0;0;0;0;0;0
352;0.15899;NaN;NaN;0.09885;0;0;0;0;0;0;0;0;0;0;0;0;0
353;0.15968;NaN;NaN;0.09884;0;0;0;0;0;0;0;0;0;0;0;0;0
354;0.16026;NaN;NaN;0.09883;0;0;0;0;0;0;0;0;0;0;0;0;0
355;0.16092;NaN;NaN;0.09882;0;0;0;0;0;0;0;0;0;0;0;0;0
356;0.16166;NaN;NaN;0.0988;0;0;0;0;0;0;0;0;0;0;0;0;0
357;0.16235;NaN;NaN;0.09879;0;0;0;0;0;0;0;0;0;0;0;0;0
358;0.16296;NaN;NaN;0.09878;0;0;0;0;0;0;0;0;0;0;0;0;0
359;0.1636;NaN;NaN;0.09877;0;0;0;0;0;0;0;0;0;0;0;0;0
360;0.16433;NaN;NaN;0.09875;0;0;0;0;0;0;0;0;0;0;0;0;0
361;0.16501;NaN;NaN;0.09874;0;0;0;0;0;0;0;0;0;0;0;0;0
362;0.16565;NaN;NaN;0.09872;0;0;0;0;0;0;0;0;0;0;0;0;0
363;0.16622;NaN;NaN;0.0987;0;0;0;0;0;0;0;0;0;0;0;0;0
364;0.16707;NaN;NaN;0.09869;0;0;0;0;0;0;0;0;0;0;0;0;0
365;0.16763;NaN;NaN;0.09867;0;0;0;0;0;0;0;0;0;0;0;0;0
366;0.16831;NaN;NaN;0.09864;0;0;0;0;0;0;0;0;0;0;0;0;0
367;0.16898;NaN;NaN;0.09862;0;0;0;0;0;0;0;0;0;0;0;0;0
368;0.1697;NaN;NaN;0.0986;0;0;0;0;0;0;0;0;0;0;0;0;0
369;0.17031;NaN;NaN;0.09859;0;0;0;0;0;0;0;0;0;0;0;0;0
370;0.17104;NaN;NaN;0.09858;0;0;0;0;0;0;0;0;0;0;0;0;0
371;0.17171;NaN;NaN;0.09855;0;0;0;0;0;0;0;0;0;0;0;0;0
372;0.1724;NaN;NaN;0.09853;0;0;0;0;0;0;0;0;0;0;0;0;0
373;0.17308;NaN;NaN;0.09851;0;0;0;0;0;0;0;0;0;0;0;0;0
374;0.17373;NaN;NaN;0.09849;0;0;0;0;0;0;0;0;0;0;0;0;0
375;0.17442;NaN;NaN;0.09847;0;0;0;0;0;0;0;0;0;0;0;0;0
376;0.17504;NaN;NaN;0.09847;0;0;0;0;0;0;0;0;0;0;0;0;0
377;0.17575;NaN;NaN;0.09844;0;0;0;0;0;0;0;0;0;0;0;0;0
378;0.17646;NaN;NaN;0.09841;0;0;0;0;0;0;0;0;0;0;0;0;0
379;0.17716;NaN;NaN;0.09839;0;0;0;0;0;0;0;0;0;0;0;0;0
380;0.17781;NaN;NaN;0.09835;0;0;0;0;0;0;0;0;0;0;0;0;0
381;0.17858;NaN;NaN;0.09833;0;0;0;0;0;0;0;0;0;0;0;0;0
382;0.1792;NaN;NaN;0.09829;0;0;0;0;0;0;0;0;0;0;0;0;0
383;0.17994;NaN;NaN;0.09825;0;0;0;0;0;0;0;0;0;0;0;0;0
384;0.18055;NaN;NaN;0.09822;0;0;0;0;0;0;0;0;0;0;0;0;0
385;0.18135;NaN;NaN;0.09817;0;0;0;0;0;0;0;0;0;0;0;0;0
386;0.18199;NaN;NaN;0.09814;0;0;0;0;0;0;0;0;0;0;0;0;0
387;0.18273;NaN;NaN;0.0981;0;0;0;0;0;0;0;0;0;0;0;0;0
388;0.18337;NaN;NaN;0.09806;0;0;0;0;0;0;0;0;0;0;0;0;0
389;0.18405;NaN;NaN;0.09801;0;0;0;0;0;0;0;0;0;0;0;0;0
390;0.18478;NaN;NaN;0.09795;0;0;0;0;0;0;0;0;0;0;0;0;0
391;0.18551;NaN;NaN;0.0979;0;0;0;0;0;0;0;0;0;0;0;0;0
392;0.18619;NaN;NaN;0.09784;0;0;0;0;0;0;0;0;0;0;0;0;0
393;0.18693;NaN;NaN;0.09777;0;0;0;0;0;0;0;0;0;0;0;0;0
394;0.18762;NaN;NaN;0.09771;0;0;0;0;0;0;0;0;0;0;0;0;0
395;0.18826;NaN;NaN;0.09764;0;0;0;0;0;0;0;0;0;0;0;0;0
396;0.18904;NaN;NaN;0.09757;0;0;0;0;0;0;0;0;0;0;0;0;0
397;0.18984;NaN;NaN;0.0975;0;0;0;0;0;0;0;0;0;0;0;0;0
398;0.19055;NaN;NaN;0.09741;0;0;0;0;0;0;0;0;0;0;0;0;0
399;0.19133;NaN;NaN;0.09733;0;0;0;0;0;0;0;0;0;0;0;0;0
400;0.19209;NaN;NaN;0.09722;0;0;0;0;0;0;0;0;0;0;0;0;0
401;0.19281;NaN;NaN;0.09711;0;0;0;0;0;0;0;0;0;0;0;0;0
402;0.19377;NaN;NaN;0.09699;0;0;0;0;0;0;0;0;0;0;0;0;0
403;0.19429;NaN;NaN;0.09688;0;0;0;0;0;0;0;0;0;0;0;0;0
404;0.19498;NaN;NaN;0.09674;0;0;0;0;0;0;0;0;0;0;0;0;0
405;0.19582;NaN;NaN;0.09662;0;0;0;0;0;0;0;0;0;0;0;0;0
406;0.19664;NaN;NaN;0.09648;0;0;0;0;0;0;0;0;0;0;0;0;0
407;0.19744;NaN;NaN;0.09631;0;0;0;0;0;0;0;0;0;0;0;0;0
408;0.19821;NaN;NaN;0.09614;0;0;0;0;0;0;0;0;0;0;0;0;0
409;0.19905;NaN;NaN;0.09595;0;0;0;0;0;0;0;0;0;0;0;0;0
410;0.19979;NaN;NaN;0.09574;0;0;0;0;0;0;0;0;0;0;0;0;0
411;0.20065;NaN;NaN;0.09553;0;0;0;0;0;0;0;0;0;0;0;0;0
412;0.20157;NaN;NaN;0.0953;0;0;0;0;0;0;0;0;0;0;0;0;0
413;0.20244;NaN;NaN;0.09504;0;0;0;0;0;0;0;0;0;0;0;0;0
414;0.2033;NaN;NaN;0.09473;0;0;0;0;0;0;0;0;0;0;0;0;0
415;0.20422;NaN;NaN;0.09444;0;0;0;0;0;0;0;0;0;0;0;0;0
416;0.20509;NaN;NaN;0.09412;0;0;0;0;0;0;0;0;0;0;0;0;0
417;0.20604;NaN;NaN;0.09377;0;0;0;0;0;0;0;0;0;0;0;0;0
418;0.20704;NaN;NaN;0.09339;0;0;0;0;0;0;0;0;0;0;0;0;0
419;0.20801;NaN;NaN;0.09295;0;0;0;0;0;0;0;0;0;0;0;0;0
420;0.20906;NaN;NaN;0.09249;0;0;0;0;0;0;0;0;0;0;0;0;0
421;0.21015;NaN;NaN;0.09199;0;0;0;0;0;0;0;0;0;0;0;0;0
422;0.21122;NaN;NaN;0.0914;0;0;0;0;0;0;0;0;0;0;0;0;0
423;0.21249;NaN;NaN;0.09068;0;0;0;0;0;0;0;0;0;0;0;0;0
424;0.21424;NaN;NaN;0.08979;0;0;0;0;0;0;0;0;0;0;0;0;0