File: Template_Auto_Cali_large_DP600/_data/DP600Large_UT_00_001_Front_DIC_File.txt
Date of Test;Material;Sample Geometry;Orientation [°];Test Number;Nominal Speed [mm/min];Thickness [mm];Central Width [mm];Gauge Width / Diameter [mm];Pixel to mm ratio [mm/px];Extensometer 1-4 [mm];Extensometer 2-3 [mm];Extensometer 5-6 [mm];;;;;
07/27/21;DP600Large;UT;00;1;0.24;0.29122;2;0;0;6;1.8;1.8;;;;;
;;;;;;;;;;;;;;;;;
Time [s];U1 [mm];Uarfdgasdfg2 [mm];U3 [mm];Force [kN];Ambient Temperature [°C];DIC Zone X 1 [px];DIC Zone Y 1 [px];DIC Zone X 2 [px];DIC Zone Y 2 [px];DIC Zone X 3 [px];DIC Zone Y 3 [px];DIC Zone X 4 [px];DIC Zone Y 4 [px];DIC Zone X 5 [px];DIC Zone Y 5 [px];DIC Zone X 6 [px];DIC Zone Y 6 [px];exx;exy;eyy;e1;e2
0;0;0;0;-0.000637;0;0;0;0;0;0;0;0;0;0;0;0;0;-2.1549e-17;-3.3233e-17;2.2428e-21;1.8386e-18;-5.6621e-17
1.499;-3.8431e-05;-2.6816e-05;-4.4254e-05;-0.000637;0;0;0;0;0;0;0;0;0;0;0;0;0;-5.0324e-08;-1.7551e-06;2.2954e-06;9.4994e-05;-9.6799e-05
2.999;-0.00010469;4.166e-06;3.6028e-05;-0.0006174;0;0;0;0;0;0;0;0;0;0;0;0;0;4.1104e-07;-1.0167e-05;2.7813e-06;9.4897e-05;-0.00010465
4.5;0.00010672;8.8857e-05;2.1759e-05;-0.000196;0;0;0;0;0;0;0;0;0;0;0;0;0;4.0266e-05;-2.4121e-05;-9.0687e-07;0.00013784;-0.0001217
6;0.00037285;8.998e-05;7.5898e-05;0.0015092;0;0;0;0;0;0;0;0;0;0;0;0;0;7.3966e-05;-2.3062e-05;5.2651e-06;0.00017375;-0.00012284
7.5;0.00068563;0.00017866;0.00010609;0.0045178;0;0;0;0;0;0;0;0;0;0;0;0;0;0.00013446;-3.0436e-05;4.8771e-07;0.00021768;-0.00011366
9;0.0011267;0.00044343;1.2989e-05;0.0096432;0;0;0;0;0;0;0;0;0;0;0;0;0;0.00020692;-4.7916e-05;1.3569e-06;0.00029483;-0.00013583
10.5;0.0019254;0.00044801;-4.6753e-05;0.018042;0;0;0;0;0;0;0;0;0;0;0;0;0;0.00031205;-9.9373e-05;-9.1929e-06;0.00039556;-0.00018289
11.999;0.0026605;0.00083742;-0.00010841;0.030821;0;0;0;0;0;0;0;0;0;0;0;0;0;0.00044835;-0.00012769;-6.1106e-06;0.00052317;-0.00020251
13.5;0.0034004;0.0010568;-0.00010477;0.04607;0;0;0;0;0;0;0;0;0;0;0;0;0;0.00057317;-0.00017474;3.578e-06;0.00064766;-0.00024924
15;0.0042194;0.0012329;-0.00026377;0.063671;0;0;0;0;0;0;0;0;0;0;0;0;0;0.0007077;-0.0002188;-9.0696e-07;0.00077524;-0.00028634
16.499;0.0051431;0.0016044;-0.00018959;0.081203;0;0;0;0;0;0;0;0;0;0;0;0;0;0.00085946;-0.00024574;2.8279e-06;0.0009249;-0.00031117
18;0.006023;0.0019185;-0.00029095;0.097912;0;0;0;0;0;0;0;0;0;0;0;0;0;0.0010007;-0.00028862;3.1043e-06;0.001064;-0.00035185
19.5;0.006838;0.0020536;-0.00039113;0.11326;0;0;0;0;0;0;0;0;0;0;0;0;0;0.0011358;-0.00033453;3.3154e-06;0.0011918;-0.00039053
21;0.0078488;0.0024333;-0.00049453;0.12834;0;0;0;0;0;0;0;0;0;0;0;0;0;0.0013171;-0.0003841;-5.8936e-07;0.0013634;-0.00043047
22.5;0.0090254;0.0027557;-0.00057414;0.14267;0;0;0;0;0;0;0;0;0;0;0;0;0;0.0015085;-0.0004461;5.0666e-06;0.0015493;-0.00048684
23.999;0.010395;0.003116;-0.00079186;0.15656;0;0;0;0;0;0;0;0;0;0;0;0;0;0.001737;-0.00053625;2.7827e-06;0.0017715;-0.00057074
25.5;0.012135;0.0037224;-0.00096613;0.17103;0;0;0;0;0;0;0;0;0;0;0;0;0;0.0020294;-0.0006704;-4.292e-06;0.0020603;-0.0007013
26.999;0.014158;0.0042195;-0.001329;0.18473;0;0;0;0;0;0;0;0;0;0;0;0;0;0.0023703;-0.00082999;-4.5468e-06;0.0023978;-0.00085754
28.499;0.016676;0.0050862;-0.0016626;0.1967;0;0;0;0;0;0;0;0;0;0;0;0;0;0.0027893;-0.0010171;-9.8666e-06;0.0028145;-0.0010423
30;0.019458;0.0058087;-0.0020351;0.20758;0;0;0;0;0;0;0;0;0;0;0;0;0;0.003252;-0.0012309;-1.5136e-05;0.0032768;-0.0012558
31.5;0.022366;0.0067703;-0.0025685;0.21639;0;0;0;0;0;0;0;0;0;0;0;0;0;0.0037427;-0.0014958;-1.2956e-05;0.003766;-0.001519
32.999;0.025517;0.0077588;-0.0029526;0.22411;0;0;0;0;0;0;0;0;0;0;0;0;0;0.0042676;-0.001725;-8.2841e-06;0.0042888;-0.0017462
34.499;0.028868;0.0087932;-0.0034174;0.23052;0;0;0;0;0;0;0;0;0;0;0;0;0;0.0048251;-0.0019979;-1.2023e-06;0.0048466;-0.0020194
36;0.032243;0.0097361;-0.0039059;0.23604;0;0;0;0;0;0;0;0;0;0;0;0;0;0.0053877;-0.0022644;4.4708e-06;0.0054076;-0.0022843
37.5;0.03582;0.010934;-0.0044472;0.24088;0;0;0;0;0;0;0;0;0;0;0;0;0;0.0059835;-0.0025563;7.1832e-06;0.0060029;-0.0025757
39;0.039379;0.011917;-0.0049905;0.24524;0;0;0;0;0;0;0;0;0;0;0;0;0;0.0065705;-0.0028381;1.3476e-05;0.0065895;-0.0028571
40.5;0.043068;0.013075;-0.005528;0.24909;0;0;0;0;0;0;0;0;0;0;0;0;0;0.0071763;-0.0031295;2.3005e-05;0.0071952;-0.0031485
41.999;0.046882;0.014131;-0.0059852;0.25247;0;0;0;0;0;0;0;0;0;0;0;0;0;0.007818;-0.0034139;2.09e-05;0.0078364;-0.0034324
43.499;0.050629;0.015294;-0.006516;0.25561;0;0;0;0;0;0;0;0;0;0;0;0;0;0.0084446;-0.0036875;2.227e-05;0.008463;-0.003706
44.999;0.054346;0.01642;-0.0071769;0.25842;0;0;0;0;0;0;0;0;0;0;0;0;0;0.0090586;-0.0040088;4.1809e-05;0.0090772;-0.0040274
46.499;0.058239;0.017541;-0.0076081;0.26109;0;0;0;0;0;0;0;0;0;0;0;0;0;0.0096939;-0.0042846;3.5748e-05;0.0097123;-0.0043029
47.999;0.062058;0.018729;-0.0082315;0.26356;0;0;0;0;0;0;0;0;0;0;0;0;0;0.01031;-0.0045839;5.6117e-05;0.01033;-0.004603
49.5;0.065823;0.01981;-0.008726;0.26591;0;0;0;0;0;0;0;0;0;0;0;0;0;0.010938;-0.004851;6.7644e-05;0.010957;-0.0048702
51;0.069397;0.020922;-0.0093039;0.26822;0;0;0;0;0;0;0;0;0;0;0;0;0;0.011543;-0.0051327;7.237e-05;0.011563;-0.0051524
52.499;0.073262;0.021878;-0.0097792;0.27041;0;0;0;0;0;0;0;0;0;0;0;0;0;0.012161;-0.0054173;7.4228e-05;0.012181;-0.0054378
53.999;0.076991;0.022995;-0.010353;0.27251;0;0;0;0;0;0;0;0;0;0;0;0;0;0.012779;-0.0057124;8.6116e-05;0.0128;-0.0057335
55.499;0.080701;0.024217;-0.010918;0.27459;0;0;0;0;0;0;0;0;0;0;0;0;0;0.013392;-0.0060106;0.00010087;0.013414;-0.0060332
57;0.08448;0.025352;-0.011415;0.27658;0;0;0;0;0;0;0;0;0;0;0;0;0;0.014015;-0.0062794;0.00010162;0.014038;-0.0063021
58.499;0.088271;0.026428;-0.011903;0.27856;0;0;0;0;0;0;0;0;0;0;0;0;0;0.014626;-0.0065583;0.00010865;0.014651;-0.0065824
59.999;0.091916;0.027702;-0.012355;0.28044;0;0;0;0;0;0;0;0;0;0;0;0;0;0.015248;-0.0068289;0.00011142;0.015273;-0.0068538
61.499;0.095728;0.028752;-0.012893;0.28225;0;0;0;0;0;0;0;0;0;0;0;0;0;0.015854;-0.0071107;0.00011858;0.01588;-0.0071367
62.999;0.099418;0.029806;-0.013378;0.2841;0;0;0;0;0;0;0;0;0;0;0;0;0;0.01647;-0.0074001;0.00013161;0.016497;-0.0074271
64.499;0.10344;0.031027;-0.013831;0.2858;0;0;0;0;0;0;0;0;0;0;0;0;0;0.017118;-0.0076698;0.00015299;0.017146;-0.0076977
65.999;0.10698;0.032091;-0.014414;0.28746;0;0;0;0;0;0;0;0;0;0;0;0;0;0.017701;-0.0079486;0.00014454;0.017729;-0.007977
67.499;0.1108;0.033132;-0.014819;0.28913;0;0;0;0;0;0;0;0;0;0;0;0;0;0.018317;-0.0082309;0.00016394;0.018347;-0.0082603
69;0.11399;0.03402;-0.015454;0.29071;0;0;0;0;0;0;0;0;0;0;0;0;0;0.018834;-0.0085199;0.00018115;0.018864;-0.0085505
70.5;0.11826;0.035406;-0.015916;0.29225;0;0;0;0;0;0;0;0;0;0;0;0;0;0.019544;-0.0087947;0.00017359;0.019576;-0.0088262
71.999;0.12195;0.036553;-0.016385;0.29376;0;0;0;0;0;0;0;0;0;0;0;0;0;0.020139;-0.0090875;0.00017523;0.020172;-0.0091204
73.499;0.12583;0.037718;-0.016959;0.29525;0;0;0;0;0;0;0;0;0;0;0;0;0;0.020747;-0.0093568;0.00018444;0.020782;-0.0093913
75;0.12956;0.038786;-0.017404;0.29667;0;0;0;0;0;0;0;0;0;0;0;0;0;0.021358;-0.0096363;0.00019697;0.021394;-0.009672
76.499;0.13336;0.039928;-0.017853;0.29808;0;0;0;0;0;0;0;0;0;0;0;0;0;0.021972;-0.0099144;0.00020349;0.022009;-0.0099512
77.999;0.13683;0.040958;-0.018374;0.29946;0;0;0;0;0;0;0;0;0;0;0;0;0;0.022541;-0.010181;0.00021645;0.022579;-0.01022
79.499;0.14104;0.042222;-0.018872;0.30078;0;0;0;0;0;0;0;0;0;0;0;0;0;0.023209;-0.010465;0.00022843;0.023248;-0.010504
80.999;0.14469;0.043322;-0.019361;0.30209;0;0;0;0;0;0;0;0;0;0;0;0;0;0.023812;-0.010746;0.00022679;0.023853;-0.010787
82.499;0.14848;0.044475;-0.019882;0.30335;0;0;0;0;0;0;0;0;0;0;0;0;0;0.024425;-0.011031;0.000234;0.024467;-0.011073
84;0.15228;0.045596;-0.020403;0.30458;0;0;0;0;0;0;0;0;0;0;0;0;0;0.02505;-0.011302;0.00024697;0.025094;-0.011346
85.499;0.15597;0.046777;-0.020888;0.30579;0;0;0;0;0;0;0;0;0;0;0;0;0;0.025647;-0.011588;0.00025196;0.025691;-0.011632
86.999;0.15989;0.047967;-0.021377;0.30699;0;0;0;0;0;0;0;0;0;0;0;0;0;0.026263;-0.01186;0.00026174;0.02631;-0.011906
88.499;0.16369;0.049202;-0.021812;0.3082;0;0;0;0;0;0;0;0;0;0;0;0;0;0.026882;-0.012138;0.00026899;0.026929;-0.012185
89.999;0.1675;0.050261;-0.022373;0.30932;0;0;0;0;0;0;0;0;0;0;0;0;0;0.027491;-0.012407;0.00027988;0.02754;-0.012455
91.499;0.17126;0.051434;-0.022929;0.31041;0;0;0;0;0;0;0;0;0;0;0;0;0;0.0281;-0.012704;0.00029355;0.02815;-0.012755
92.999;0.1751;0.052563;-0.023308;0.31149;0;0;0;0;0;0;0;0;0;0;0;0;0;0.028722;-0.012971;0.00029431;0.028773;-0.013022
94.499;0.179;0.053724;-0.023901;0.31255;0;0;0;0;0;0;0;0;0;0;0;0;0;0.029336;-0.01326;0.00030602;0.029388;-0.013312
95.999;0.18274;0.054841;-0.024392;0.31364;0;0;0;0;0;0;0;0;0;0;0;0;0;0.02996;-0.013541;0.00031799;0.030014;-0.013595
97.499;0.18676;0.056089;-0.024873;0.31469;0;0;0;0;0;0;0;0;0;0;0;0;0;0.030593;-0.013813;0.00032068;0.030648;-0.013868
98.999;0.19067;0.05728;-0.025424;0.31572;0;0;0;0;0;0;0;0;0;0;0;0;0;0.031206;-0.014112;0.00033543;0.031262;-0.014168
100.5;0.19445;0.058344;-0.025885;0.31674;0;0;0;0;0;0;0;0;0;0;0;0;0;0.031828;-0.014382;0.00034795;0.031885;-0.014439
102;0.19835;0.059583;-0.026535;0.31772;0;0;0;0;0;0;0;0;0;0;0;0;0;0.03245;-0.014669;0.00035535;0.032509;-0.014727
103.5;0.20221;0.060786;-0.026989;0.31868;0;0;0;0;0;0;0;0;0;0;0;0;0;0.033065;-0.014956;0.00036643;0.033125;-0.015015
105;0.20615;0.061951;-0.027479;0.31962;0;0;0;0;0;0;0;0;0;0;0;0;0;0.03369;-0.015242;0.00037088;0.033751;-0.015303
106.5;0.21007;0.063121;-0.027942;0.32052;0;0;0;0;0;0;0;0;0;0;0;0;0;0.034318;-0.015512;0.00038115;0.03438;-0.015574
108;0.21396;0.064249;-0.028407;0.32143;0;0;0;0;0;0;0;0;0;0;0;0;0;0.034931;-0.015799;0.00038302;0.034994;-0.015863
109.5;0.21786;0.065391;-0.028873;0.32231;0;0;0;0;0;0;0;0;0;0;0;0;0;0.035557;-0.016076;0.00039352;0.035622;-0.01614
111;0.22163;0.066522;-0.02938;0.32316;0;0;0;0;0;0;0;0;0;0;0;0;0;0.036172;-0.016355;0.00040179;0.036237;-0.016421
112.5;0.22559;0.067737;-0.029864;0.32401;0;0;0;0;0;0;0;0;0;0;0;0;0;0.03679;-0.016623;0.00041066;0.036856;-0.01669
114;0.22936;0.068809;-0.030421;0.32484;0;0;0;0;0;0;0;0;0;0;0;0;0;0.037387;-0.016928;0.00040819;0.037455;-0.016996
115.5;0.23354;0.070046;-0.030676;0.32562;0;0;0;0;0;0;0;0;0;0;0;0;0;0.038036;-0.017145;0.00044422;0.038105;-0.017214
117;0.23709;0.071263;-0.031239;0.32639;0;0;0;0;0;0;0;0;0;0;0;0;0;0.038621;-0.017463;0.00043345;0.038691;-0.017533
118.5;0.24098;0.072393;-0.031685;0.32713;0;0;0;0;0;0;0;0;0;0;0;0;0;0.039243;-0.017735;0.00044499;0.039314;-0.017805
120;0.24494;0.073448;-0.032239;0.32791;0;0;0;0;0;0;0;0;0;0;0;0;0;0.039872;-0.018011;0.00045657;0.039944;-0.018083
121.5;0.2487;0.074634;-0.032614;0.32863;0;0;0;0;0;0;0;0;0;0;0;0;0;0.040479;-0.018299;0.0004603;0.040552;-0.018373
123;0.25269;0.075913;-0.033169;0.32939;0;0;0;0;0;0;0;0;0;0;0;0;0;0.041106;-0.018566;0.00047131;0.041181;-0.018641
124.5;0.25663;0.076941;-0.033647;0.33013;0;0;0;0;0;0;0;0;0;0;0;0;0;0.041731;-0.018872;0.00048591;0.041808;-0.018949
126;0.26064;0.07812;-0.034112;0.33088;0;0;0;0;0;0;0;0;0;0;0;0;0;0.042357;-0.019107;0.0004948;0.042435;-0.019185
127.5;0.26454;0.079262;-0.034617;0.33156;0;0;0;0;0;0;0;0;0;0;0;0;0;0.042972;-0.019411;0.00050007;0.043051;-0.019491
129;0.26854;0.080425;-0.035104;0.33223;0;0;0;0;0;0;0;0;0;0;0;0;0;0.043601;-0.01969;0.00051844;0.043683;-0.019771
130.5;0.27241;0.081468;-0.035628;0.33291;0;0;0;0;0;0;0;0;0;0;0;0;0;0.044209;-0.019975;0.00052179;0.044292;-0.020058
132;0.27637;0.082706;-0.036041;0.33362;0;0;0;0;0;0;0;0;0;0;0;0;0;0.044839;-0.020247;0.00052498;0.044923;-0.020331
133.5;0.28033;0.083801;-0.036583;0.33432;0;0;0;0;0;0;0;0;0;0;0;0;0;0.045458;-0.020533;0.00054104;0.045543;-0.020618
135;0.2843;0.084974;-0.037051;0.33498;0;0;0;0;0;0;0;0;0;0;0;0;0;0.04609;-0.020805;0.00054229;0.046176;-0.020891
136.5;0.28825;0.086025;-0.037633;0.33561;0;0;0;0;0;0;0;0;0;0;0;0;0;0.046707;-0.021084;0.00055248;0.046795;-0.021171
138;0.29214;0.087285;-0.038072;0.33624;0;0;0;0;0;0;0;0;0;0;0;0;0;0.047324;-0.021375;0.00056143;0.047412;-0.021463
139.5;0.2962;0.08853;-0.038513;0.33687;0;0;0;0;0;0;0;0;0;0;0;0;0;0.047954;-0.021658;0.00057027;0.048044;-0.021747
141;0.30011;0.089719;-0.03898;0.33745;0;0;0;0;0;0;0;0;0;0;0;0;0;0.048564;-0.021922;0.00058032;0.048654;-0.022013
142.5;0.30401;0.090703;-0.0395;0.33806;0;0;0;0;0;0;0;0;0;0;0;0;0;0.049177;-0.022211;0.00058989;0.049269;-0.022304
144;0.30803;0.091864;-0.039898;0.33862;0;0;0;0;0;0;0;0;0;0;0;0;0;0.049801;-0.022476;0.00059483;0.049894;-0.022569
145.5;0.31201;0.09316;-0.040421;0.3392;0;0;0;0;0;0;0;0;0;0;0;0;0;0.050428;-0.022749;0.00060059;0.050523;-0.022844
147;0.31589;0.094329;-0.040928;0.33975;0;0;0;0;0;0;0;0;0;0;0;0;0;0.051041;-0.023039;0.00061593;0.051138;-0.023136
148.5;0.32;0.095521;-0.041417;0.34034;0;0;0;0;0;0;0;0;0;0;0;0;0;0.051672;-0.023325;0.00062603;0.05177;-0.023422
150;0.32397;0.096659;-0.041921;0.34089;0;0;0;0;0;0;0;0;0;0;0;0;0;0.052291;-0.023594;0.00063109;0.05239;-0.023693
151.5;0.32792;0.097714;-0.0424;0.34145;0;0;0;0;0;0;0;0;0;0;0;0;0;0.052906;-0.02387;0.00064583;0.053008;-0.023972
153;0.33189;0.098968;-0.042934;0.34197;0;0;0;0;0;0;0;0;0;0;0;0;0;0.053537;-0.024153;0.00065143;0.053639;-0.024255
154.5;0.33598;0.10016;-0.043394;0.34251;0;0;0;0;0;0;0;0;0;0;0;0;0;0.054167;-0.024434;0.00065615;0.054271;-0.024538
156;0.33973;0.10116;-0.044003;0.34303;0;0;0;0;0;0;0;0;0;0;0;0;0;0.054781;-0.024705;0.00067268;0.054887;-0.02481
157.5;0.34382;0.10244;-0.044515;0.34355;0;0;0;0;0;0;0;0;0;0;0;0;0;0.055392;-0.024987;0.00067719;0.055499;-0.025094
159;0.34779;0.10363;-0.044975;0.34407;0;0;0;0;0;0;0;0;0;0;0;0;0;0.056024;-0.025265;0.0006891;0.056133;-0.025373
160.5;0.35177;0.1047;-0.045386;0.34458;0;0;0;0;0;0;0;0;0;0;0;0;0;0.056647;-0.025546;0.00068715;0.056756;-0.025655
162;0.35579;0.10593;-0.04593;0.34507;0;0;0;0;0;0;0;0;0;0;0;0;0;0.057265;-0.025814;0.00069883;0.057375;-0.025924
163.5;0.35975;0.1071;-0.046449;0.34553;0;0;0;0;0;0;0;0;0;0;0;0;0;0.057882;-0.026104;0.00071239;0.057994;-0.026216
165;0.36372;0.1083;-0.046938;0.34599;0;0;0;0;0;0;0;0;0;0;0;0;0;0.058509;-0.026375;0.00071501;0.058622;-0.026488
166.5;0.36779;0.10946;-0.04747;0.34646;0;0;0;0;0;0;0;0;0;0;0;0;0;0.059137;-0.026661;0.00072337;0.05925;-0.026774
168;0.37183;0.11063;-0.047979;0.34691;0;0;0;0;0;0;0;0;0;0;0;0;0;0.059762;-0.026951;0.00073284;0.059877;-0.027066
169.5;0.37585;0.1118;-0.04851;0.34738;0;0;0;0;0;0;0;0;0;0;0;0;0;0.060386;-0.027215;0.00074322;0.060502;-0.027331
171;0.37992;0.11298;-0.048958;0.34782;0;0;0;0;0;0;0;0;0;0;0;0;0;0.061009;-0.027504;0.00075755;0.061127;-0.027622
172.5;0.38386;0.11414;-0.049547;0.34823;0;0;0;0;0;0;0;0;0;0;0;0;0;0.061628;-0.027786;0.00076181;0.061748;-0.027905
174;0.38802;0.11535;-0.050043;0.34866;0;0;0;0;0;0;0;0;0;0;0;0;0;0.062264;-0.028064;0.00076355;0.062385;-0.028185
175.5;0.3922;0.11654;-0.050491;0.34913;0;0;0;0;0;0;0;0;0;0;0;0;0;0.0629;-0.02834;0.00078902;0.063023;-0.028463
177;0.39615;0.11765;-0.05104;0.34953;0;0;0;0;0;0;0;0;0;0;0;0;0;0.06351;-0.028618;0.00078524;0.063634;-0.028742
178.5;0.40028;0.11881;-0.051495;0.34992;0;0;0;0;0;0;0;0;0;0;0;0;0;0.064138;-0.028897;0.00079732;0.064263;-0.029022
180;0.40428;0.12006;-0.051948;0.3503;0;0;0;0;0;0;0;0;0;0;0;0;0;0.064755;-0.029173;0.00080607;0.064881;-0.0293
181.5;0.40836;0.12136;-0.052479;0.35069;0;0;0;0;0;0;0;0;0;0;0;0;0;0.065393;-0.029464;0.00081677;0.06552;-0.029592
183;0.41246;0.12253;-0.052978;0.35108;0;0;0;0;0;0;0;0;0;0;0;0;0;0.066005;-0.02973;0.00081721;0.066134;-0.02986
184.5;0.41645;0.12375;-0.053444;0.35147;0;0;0;0;0;0;0;0;0;0;0;0;0;0.066631;-0.030011;0.00083638;0.066762;-0.030142
186;0.42061;0.12503;-0.054009;0.35182;0;0;0;0;0;0;0;0;0;0;0;0;0;0.067255;-0.030284;0.00084428;0.067387;-0.030416
187.5;0.42478;0.12618;-0.054469;0.3522;0;0;0;0;0;0;0;0;0;0;0;0;0;0.067886;-0.030566;0.0008611;0.068019;-0.0307
189;0.42889;0.12741;-0.054937;0.35256;0;0;0;0;0;0;0;0;0;0;0;0;0;0.068502;-0.030841;0.00085988;0.068637;-0.030976
190.5;0.43296;0.12863;-0.055466;0.35294;0;0;0;0;0;0;0;0;0;0;0;0;0;0.069129;-0.03112;0.00086952;0.069265;-0.031256
192;0.43706;0.12982;-0.055948;0.35331;0;0;0;0;0;0;0;0;0;0;0;0;0;0.069758;-0.031399;0.00088006;0.069894;-0.031536
193.5;0.44107;0.13104;-0.056375;0.35364;0;0;0;0;0;0;0;0;0;0;0;0;0;0.070369;-0.031676;0.00088367;0.070507;-0.031814
195;0.44539;0.13218;-0.05691;0.35398;0;0;0;0;0;0;0;0;0;0;0;0;0;0.071016;-0.031956;0.00089736;0.071155;-0.032095
196.5;0.44957;0.13348;-0.057424;0.35432;0;0;0;0;0;0;0;0;0;0;0;0;0;0.071659;-0.032236;0.00090224;0.0718;-0.032376
198;0.45355;0.13448;-0.057827;0.35468;0;0;0;0;0;0;0;0;0;0;0;0;0;0.072262;-0.032506;0.00091486;0.072405;-0.032649
199.5;0.45779;0.13574;-0.05834;0.35501;0;0;0;0;0;0;0;0;0;0;0;0;0;0.072891;-0.032786;0.0009277;0.073034;-0.032929
201;0.46179;0.13706;-0.058885;0.35533;0;0;0;0;0;0;0;0;0;0;0;0;0;0.073516;-0.033075;0.00093316;0.07366;-0.033219
202.5;0.46589;0.13823;-0.059327;0.35564;0;0;0;0;0;0;0;0;0;0;0;0;0;0.074134;-0.033358;0.00093964;0.07428;-0.033504
204;0.47003;0.13936;-0.059751;0.35598;0;0;0;0;0;0;0;0;0;0;0;0;0;0.074764;-0.033636;0.00095414;0.074911;-0.033783
205.5;0.47416;0.14067;-0.060251;0.35632;0;0;0;0;0;0;0;0;0;0;0;0;0;0.075397;-0.033907;0.00096349;0.075546;-0.034055
207;0.47838;0.14194;-0.060726;0.35664;0;0;0;0;0;0;0;0;0;0;0;0;0;0.076027;-0.034195;0.0009705;0.076176;-0.034344
208.5;0.48252;0.14293;-0.061331;0.35694;0;0;0;0;0;0;0;0;0;0;0;0;0;0.076651;-0.034486;0.00097997;0.076802;-0.034637
210;0.48674;0.1442;-0.061878;0.35724;0;0;0;0;0;0;0;0;0;0;0;0;0;0.077283;-0.03476;0.00098827;0.077435;-0.034912
211.5;0.49084;0.14539;-0.062322;0.35754;0;0;0;0;0;0;0;0;0;0;0;0;0;0.077909;-0.03504;0.00099812;0.078062;-0.035193
213;0.49489;0.14666;-0.062841;0.35783;0;0;0;0;0;0;0;0;0;0;0;0;0;0.078529;-0.035339;0.0010028;0.078684;-0.035493
214.5;0.49917;0.14789;-0.063286;0.35811;0;0;0;0;0;0;0;0;0;0;0;0;0;0.079176;-0.035601;0.0010106;0.079331;-0.035756
216;0.50317;0.14903;-0.063772;0.3584;0;0;0;0;0;0;0;0;0;0;0;0;0;0.079795;-0.035874;0.0010216;0.079952;-0.036032
217.5;0.5074;0.15039;-0.06433;0.35866;0;0;0;0;0;0;0;0;0;0;0;0;0;0.080435;-0.036177;0.0010218;0.080593;-0.036335
219;0.51152;0.15153;-0.06477;0.35893;0;0;0;0;0;0;0;0;0;0;0;0;0;0.081044;-0.036443;0.0010449;0.081204;-0.036603
220.5;0.51555;0.15271;-0.065244;0.35921;0;0;0;0;0;0;0;0;0;0;0;0;0;0.081661;-0.03673;0.0010557;0.081822;-0.03689
222;0.51987;0.15383;-0.065645;0.35947;0;0;0;0;0;0;0;0;0;0;0;0;0;0.082312;-0.036997;0.0010581;0.082473;-0.037159
223.5;0.52414;0.15515;-0.066161;0.35976;0;0;0;0;0;0;0;0;0;0;0;0;0;0.08294;-0.037274;0.0010752;0.083103;-0.037437
225;0.52832;0.15655;-0.066585;0.36001;0;0;0;0;0;0;0;0;0;0;0;0;0;0.083578;-0.037561;0.0010738;0.083742;-0.037726
226.5;0.53243;0.15749;-0.067062;0.36028;0;0;0;0;0;0;0;0;0;0;0;0;0;0.084199;-0.037831;0.0010853;0.084364;-0.037996
228;0.53652;0.15869;-0.067536;0.36053;0;0;0;0;0;0;0;0;0;0;0;0;0;0.084815;-0.038121;0.0010871;0.084982;-0.038288
229.5;0.54079;0.15992;-0.068065;0.36079;0;0;0;0;0;0;0;0;0;0;0;0;0;0.08545;-0.038397;0.0010991;0.085619;-0.038566
231;0.54495;0.1611;-0.068496;0.36102;0;0;0;0;0;0;0;0;0;0;0;0;0;0.086078;-0.038679;0.0011034;0.086249;-0.03885
232.5;0.54914;0.16245;-0.068897;0.36129;0;0;0;0;0;0;0;0;0;0;0;0;0;0.086722;-0.038961;0.0011192;0.086893;-0.039132
234;0.55342;0.16371;-0.069403;0.36154;0;0;0;0;0;0;0;0;0;0;0;0;0;0.087345;-0.039243;0.0011222;0.087517;-0.039415
235.5;0.55753;0.16491;-0.069872;0.36177;0;0;0;0;0;0;0;0;0;0;0;0;0;0.087969;-0.039521;0.0011312;0.088143;-0.039695
237;0.56182;0.16611;-0.07038;0.36199;0;0;0;0;0;0;0;0;0;0;0;0;0;0.088602;-0.039808;0.0011407;0.088777;-0.039983
238.5;0.56599;0.16737;-0.070861;0.36223;0;0;0;0;0;0;0;0;0;0;0;0;0;0.089233;-0.040085;0.0011495;0.08941;-0.040262
240;0.57032;0.16856;-0.071324;0.36245;0;0;0;0;0;0;0;0;0;0;0;0;0;0.089868;-0.040375;0.0011593;0.090046;-0.040553
241.5;0.57452;0.16971;-0.071807;0.36267;0;0;0;0;0;0;0;0;0;0;0;0;0;0.090494;-0.040647;0.0011621;0.090674;-0.040826
243;0.57863;0.17103;-0.072278;0.36286;0;0;0;0;0;0;0;0;0;0;0;0;0;0.091122;-0.04093;0.0011755;0.091303;-0.041111
244.5;0.58298;0.17222;-0.07272;0.36306;0;0;0;0;0;0;0;0;0;0;0;0;0;0.091758;-0.041202;0.0011896;0.091939;-0.041384
246;0.58711;0.17356;-0.073215;0.36329;0;0;0;0;0;0;0;0;0;0;0;0;0;0.092376;-0.041494;0.0011855;0.09256;-0.041677
247.5;0.59142;0.17485;-0.073657;0.36351;0;0;0;0;0;0;0;0;0;0;0;0;0;0.093024;-0.041779;0.0012071;0.093209;-0.041964
249;0.59563;0.17609;-0.074089;0.36371;0;0;0;0;0;0;0;0;0;0;0;0;0;0.093654;-0.042053;0.0012098;0.093839;-0.042239
250.5;0.59994;0.17725;-0.07475;0.36389;0;0;0;0;0;0;0;0;0;0;0;0;0;0.094292;-0.042342;0.0012173;0.094479;-0.042529
252;0.60422;0.17862;-0.075142;0.3641;0;0;0;0;0;0;0;0;0;0;0;0;0;0.094928;-0.04262;0.0012283;0.095115;-0.042808
253.5;0.60843;0.17979;-0.075626;0.36431;0;0;0;0;0;0;0;0;0;0;0;0;0;0.095558;-0.04291;0.0012335;0.095746;-0.043099
255;0.61252;0.18099;-0.076053;0.36452;0;0;0;0;0;0;0;0;0;0;0;0;0;0.096164;-0.043191;0.0012505;0.096354;-0.043381
256.5;0.61694;0.18228;-0.076536;0.36471;0;0;0;0;0;0;0;0;0;0;0;0;0;0.096828;-0.043467;0.001251;0.097019;-0.043658
258;0.62129;0.18355;-0.076954;0.36489;0;0;0;0;0;0;0;0;0;0;0;0;0;0.097466;-0.043746;0.0012671;0.097659;-0.043939
259.5;0.62544;0.18478;-0.07756;0.36507;0;0;0;0;0;0;0;0;0;0;0;0;0;0.098085;-0.044025;0.0012705;0.098279;-0.044219
261;0.62975;0.18595;-0.078084;0.36524;0;0;0;0;0;0;0;0;0;0;0;0;0;0.09871;-0.044313;0.0012729;0.098905;-0.044508
262.5;0.63407;0.18735;-0.078503;0.36541;0;0;0;0;0;0;0;0;0;0;0;0;0;0.099365;-0.044589;0.0012783;0.09956;-0.044785
264;0.63844;0.18853;-0.078968;0.36559;0;0;0;0;0;0;0;0;0;0;0;0;0;0.099999;-0.044874;0.0012943;0.1002;-0.045072
265.5;0.64269;0.18974;-0.079436;0.36577;0;0;0;0;0;0;0;0;0;0;0;0;0;0.10063;-0.045146;0.0012993;0.10083;-0.045345
267;0.64703;0.19099;-0.079913;0.36595;0;0;0;0;0;0;0;0;0;0;0;0;0;0.10127;-0.045448;0.0013074;0.10147;-0.045647
268.5;0.65135;0.19224;-0.080352;0.36612;0;0;0;0;0;0;0;0;0;0;0;0;0;0.10191;-0.045724;0.0013157;0.10211;-0.045925
270;0.65562;0.1935;-0.080835;0.36628;0;0;0;0;0;0;0;0;0;0;0;0;0;0.10254;-0.046;0.0013219;0.10274;-0.046203
271.5;0.6599;0.19488;-0.081326;0.36645;0;0;0;0;0;0;0;0;0;0;0;0;0;0.10318;-0.046288;0.0013295;0.10339;-0.046491
273;0.66429;0.19609;-0.081784;0.36661;0;0;0;0;0;0;0;0;0;0;0;0;0;0.10382;-0.046578;0.0013337;0.10403;-0.046783
274.5;0.66858;0.19736;-0.08225;0.36676;0;0;0;0;0;0;0;0;0;0;0;0;0;0.10445;-0.046862;0.0013421;0.10466;-0.047068
276;0.67292;0.19853;-0.082723;0.36689;0;0;0;0;0;0;0;0;0;0;0;0;0;0.10509;-0.047147;0.0013499;0.1053;-0.047354
277.5;0.6772;0.19991;-0.083143;0.36703;0;0;0;0;0;0;0;0;0;0;0;0;0;0.10573;-0.047424;0.0013563;0.10593;-0.047633
279;0.68158;0.2011;-0.083598;0.36719;0;0;0;0;0;0;0;0;0;0;0;0;0;0.10637;-0.047723;0.0013628;0.10658;-0.047933
280.5;0.6859;0.20238;-0.084028;0.36734;0;0;0;0;0;0;0;0;0;0;0;0;0;0.107;-0.047993;0.0013724;0.10721;-0.048205
282;0.69023;0.20353;-0.084547;0.36749;0;0;0;0;0;0;0;0;0;0;0;0;0;0.10764;-0.048268;0.0013815;0.10786;-0.048481
283.5;0.6945;0.20481;-0.084998;0.36765;0;0;0;0;0;0;0;0;0;0;0;0;0;0.10827;-0.048539;0.0013838;0.10848;-0.048752
285;0.69895;0.20613;-0.085484;0.36779;0;0;0;0;0;0;0;0;0;0;0;0;0;0.10893;-0.048828;0.0013879;0.10915;-0.049042
286.5;0.70333;0.20728;-0.086068;0.36793;0;0;0;0;0;0;0;0;0;0;0;0;0;0.10957;-0.04913;0.0014006;0.10978;-0.049345
288;0.70766;0.20854;-0.086388;0.36807;0;0;0;0;0;0;0;0;0;0;0;0;0;0.11021;-0.049378;0.0013967;0.11042;-0.049594
289.5;0.71205;0.20989;-0.086939;0.3682;0;0;0;0;0;0;0;0;0;0;0;0;0;0.11085;-0.04968;0.0014116;0.11106;-0.049897
291;0.71642;0.21122;-0.087515;0.36833;0;0;0;0;0;0;0;0;0;0;0;0;0;0.11149;-0.049973;0.0014226;0.1117;-0.050192
292.5;0.72088;0.21242;-0.087944;0.36845;0;0;0;0;0;0;0;0;0;0;0;0;0;0.11213;-0.050251;0.0014201;0.11235;-0.050471
294;0.72515;0.21377;-0.088396;0.36858;0;0;0;0;0;0;0;0;0;0;0;0;0;0.11276;-0.050536;0.0014325;0.11298;-0.050757
295.5;0.72963;0.21507;-0.088908;0.36868;0;0;0;0;0;0;0;0;0;0;0;0;0;0.11341;-0.050824;0.0014454;0.11363;-0.051046
297;0.73402;0.21629;-0.089321;0.36881;0;0;0;0;0;0;0;0;0;0;0;0;0;0.11405;-0.051101;0.0014471;0.11427;-0.051324
298.5;0.73848;0.21751;-0.089837;0.36892;0;0;0;0;0;0;0;0;0;0;0;0;0;0.1147;-0.051382;0.0014579;0.11492;-0.051607
300;0.7427;0.21869;-0.090414;0.36904;0;0;0;0;0;0;0;0;0;0;0;0;0;0.11532;-0.051678;0.0014643;0.11555;-0.051903
301.5;0.74715;0.21998;-0.090919;0.36916;0;0;0;0;0;0;0;0;0;0;0;0;0;0.11596;-0.05197;0.0014732;0.11619;-0.052196
303;0.75161;0.22127;-0.091234;0.36927;0;0;0;0;0;0;0;0;0;0;0;0;0;0.11661;-0.052244;0.0014816;0.11684;-0.052472
304.5;0.75606;0.22257;-0.091786;0.36939;0;0;0;0;0;0;0;0;0;0;0;0;0;0.11726;-0.052535;0.0014912;0.11749;-0.052763
306;0.76051;0.22381;-0.092229;0.36951;0;0;0;0;0;0;0;0;0;0;0;0;0;0.1179;-0.052827;0.0014973;0.11813;-0.053057
307.5;0.7649;0.22501;-0.092695;0.36962;0;0;0;0;0;0;0;0;0;0;0;0;0;0.11854;-0.053104;0.001501;0.11877;-0.053335
309;0.76939;0.22639;-0.093217;0.3697;0;0;0;0;0;0;0;0;0;0;0;0;0;0.11919;-0.053383;0.0015094;0.11942;-0.053615
310.5;0.77389;0.22771;-0.09367;0.3698;0;0;0;0;0;0;0;0;0;0;0;0;0;0.11983;-0.053669;0.0015092;0.12007;-0.053901
312;0.77825;0.22894;-0.094188;0.3699;0;0;0;0;0;0;0;0;0;0;0;0;0;0.12047;-0.053948;0.0015202;0.12071;-0.054182
313.5;0.78245;0.23012;-0.094669;0.37001;0;0;0;0;0;0;0;0;0;0;0;0;0;0.12109;-0.054245;0.0015291;0.12132;-0.054479
315;0.78718;0.23149;-0.095143;0.37012;0;0;0;0;0;0;0;0;0;0;0;0;0;0.12177;-0.054517;0.0015225;0.122;-0.054752
316.5;0.79157;0.23276;-0.095654;0.37021;0;0;0;0;0;0;0;0;0;0;0;0;0;0.1224;-0.054804;0.0015401;0.12264;-0.055039
318;0.79608;0.23402;-0.09605;0.37031;0;0;0;0;0;0;0;0;0;0;0;0;0;0.12305;-0.0551;0.0015436;0.12328;-0.055336
319.5;0.80071;0.23528;-0.096545;0.37044;0;0;0;0;0;0;0;0;0;0;0;0;0;0.12372;-0.055377;0.001549;0.12396;-0.055613
321;0.80507;0.23655;-0.097041;0.37055;0;0;0;0;0;0;0;0;0;0;0;0;0;0.12436;-0.055669;0.0015577;0.1246;-0.055907
322.5;0.8096;0.23792;-0.097567;0.37065;0;0;0;0;0;0;0;0;0;0;0;0;0;0.12501;-0.055958;0.0015655;0.12525;-0.056197
324;0.81406;0.23923;-0.097994;0.37071;0;0;0;0;0;0;0;0;0;0;0;0;0;0.12566;-0.056233;0.0015746;0.1259;-0.056473
325.5;0.81852;0.24044;-0.098494;0.3708;0;0;0;0;0;0;0;0;0;0;0;0;0;0.12631;-0.056522;0.0015743;0.12655;-0.056763
327;0.82321;0.24174;-0.098938;0.37088;0;0;0;0;0;0;0;0;0;0;0;0;0;0.12697;-0.056813;0.0015877;0.12721;-0.057055
328.5;0.82767;0.24308;-0.099462;0.37096;0;0;0;0;0;0;0;0;0;0;0;0;0;0.12762;-0.05709;0.0015929;0.12787;-0.057332
330;0.83213;0.24445;-0.099925;0.37103;0;0;0;0;0;0;0;0;0;0;0;0;0;0.12827;-0.057388;0.0016033;0.12851;-0.057632
331.5;0.83657;0.24564;-0.10046;0.37112;0;0;0;0;0;0;0;0;0;0;0;0;0;0.1289;-0.057669;0.0016032;0.12915;-0.057914
333;0.84109;0.24686;-0.10093;0.37118;0;0;0;0;0;0;0;0;0;0;0;0;0;0.12957;-0.057951;0.0016153;0.12981;-0.058196
334.5;0.84543;0.24814;-0.10134;0.37125;0;0;0;0;0;0;0;0;0;0;0;0;0;0.1302;-0.058239;0.0016149;0.13045;-0.058486
336;0.85007;0.24955;-0.10183;0.37131;0;0;0;0;0;0;0;0;0;0;0;0;0;0.13087;-0.058516;0.0016431;0.13112;-0.058763
337.5;0.85462;0.25072;-0.10239;0.3714;0;0;0;0;0;0;0;0;0;0;0;0;0;0.13153;-0.058823;0.0016365;0.13177;-0.05907
339;0.85931;0.25213;-0.1028;0.37147;0;0;0;0;0;0;0;0;0;0;0;0;0;0.13219;-0.059113;0.0016435;0.13244;-0.059362
340.5;0.86384;0.25334;-0.10329;0.37155;0;0;0;0;0;0;0;0;0;0;0;0;0;0.13284;-0.059395;0.0016574;0.13309;-0.059646
342;0.8683;0.25462;-0.10374;0.3716;0;0;0;0;0;0;0;0;0;0;0;0;0;0.13349;-0.059685;0.0016615;0.13374;-0.059937
343.5;0.87281;0.25587;-0.10431;0.37166;0;0;0;0;0;0;0;0;0;0;0;0;0;0.13413;-0.059986;0.0016607;0.13439;-0.060239
345;0.8774;0.25733;-0.10481;0.37168;0;0;0;0;0;0;0;0;0;0;0;0;0;0.13479;-0.060259;0.0016801;0.13504;-0.060513
346.5;0.88192;0.2586;-0.10525;0.37174;0;0;0;0;0;0;0;0;0;0;0;0;0;0.13543;-0.060551;0.001689;0.13569;-0.060806
348;0.88657;0.25983;-0.10572;0.3718;0;0;0;0;0;0;0;0;0;0;0;0;0;0.1361;-0.06084;0.0016991;0.13636;-0.061096
349.5;0.89124;0.26118;-0.10617;0.37186;0;0;0;0;0;0;0;0;0;0;0;0;0;0.13676;-0.061142;0.0017043;0.13702;-0.061398
351;0.89588;0.26245;-0.1067;0.3719;0;0;0;0;0;0;0;0;0;0;0;0;0;0.13742;-0.061426;0.0017043;0.13768;-0.061684
352.5;0.90046;0.26376;-0.10715;0.37196;0;0;0;0;0;0;0;0;0;0;0;0;0;0.13807;-0.061714;0.0017216;0.13833;-0.061973
354;0.90495;0.26517;-0.1076;0.372;0;0;0;0;0;0;0;0;0;0;0;0;0;0.13872;-0.062005;0.0017273;0.13898;-0.062264
355.5;0.90945;0.26637;-0.108;0.37205;0;0;0;0;0;0;0;0;0;0;0;0;0;0.13937;-0.062299;0.0017341;0.13964;-0.062559
357;0.91425;0.26775;-0.10848;0.37211;0;0;0;0;0;0;0;0;0;0;0;0;0;0.14005;-0.062585;0.0017417;0.14031;-0.062846
358.5;0.91909;0.26912;-0.10893;0.37216;0;0;0;0;0;0;0;0;0;0;0;0;0;0.14072;-0.062873;0.0017598;0.14098;-0.063134
360;0.92356;0.27034;-0.10945;0.37219;0;0;0;0;0;0;0;0;0;0;0;0;0;0.14137;-0.063171;0.0017581;0.14163;-0.063432
361.5;0.92827;0.27174;-0.10982;0.37225;0;0;0;0;0;0;0;0;0;0;0;0;0;0.14203;-0.063432;0.0017813;0.14229;-0.063695
363;0.93282;0.273;-0.11033;0.37229;0;0;0;0;0;0;0;0;0;0;0;0;0;0.14269;-0.063746;0.0017729;0.14295;-0.06401
364.5;0.93739;0.27433;-0.11074;0.37233;0;0;0;0;0;0;0;0;0;0;0;0;0;0.14334;-0.064025;0.0017849;0.1436;-0.064289
366;0.94213;0.27563;-0.11124;0.37237;0;0;0;0;0;0;0;0;0;0;0;0;0;0.144;-0.064311;0.0017861;0.14427;-0.064576
367.5;0.94677;0.277;-0.11168;0.37241;0;0;0;0;0;0;0;0;0;0;0;0;0;0.14467;-0.064606;0.0017967;0.14493;-0.064872
369;0.95159;0.27838;-0.11207;0.37245;0;0;0;0;0;0;0;0;0;0;0;0;0;0.14533;-0.064889;0.0018064;0.14559;-0.065156
370.5;0.95616;0.27964;-0.11257;0.37248;0;0;0;0;0;0;0;0;0;0;0;0;0;0.14597;-0.065189;0.0018119;0.14624;-0.065457
372;0.96094;0.281;-0.11305;0.37251;0;0;0;0;0;0;0;0;0;0;0;0;0;0.14665;-0.065474;0.001819;0.14692;-0.065742
373.5;0.96562;0.2824;-0.11347;0.37255;0;0;0;0;0;0;0;0;0;0;0;0;0;0.1473;-0.065787;0.0018413;0.14757;-0.066057
375;0.97076;0.28386;-0.11397;0.37258;0;0;0;0;0;0;0;0;0;0;0;0;0;0.14804;-0.066061;0.0018472;0.14832;-0.066332
376.5;0.97503;0.28501;-0.11449;0.37263;0;0;0;0;0;0;0;0;0;0;0;0;0;0.14865;-0.066356;0.0018453;0.14892;-0.066628
378;0.97975;0.28649;-0.11492;0.37266;0;0;0;0;0;0;0;0;0;0;0;0;0;0.14931;-0.066645;0.0018595;0.14958;-0.066918
379.5;0.98455;0.28777;-0.1154;0.37271;0;0;0;0;0;0;0;0;0;0;0;0;0;0.14998;-0.066946;0.0018708;0.15025;-0.06722
381;0.98927;0.28916;-0.11596;0.37276;0;0;0;0;0;0;0;0;0;0;0;0;0;0.15065;-0.067238;0.0018685;0.15092;-0.067513
382.5;0.99387;0.29049;-0.11641;0.37278;0;0;0;0;0;0;0;0;0;0;0;0;0;0.15129;-0.067549;0.001878;0.15157;-0.067825
384;0.99879;0.29183;-0.11694;0.3728;0;0;0;0;0;0;0;0;0;0;0;0;0;0.15197;-0.067832;0.0018893;0.15225;-0.068108
385.5;1.0036;0.29307;-0.11743;0.37282;0;0;0;0;0;0;0;0;0;0;0;0;0;0.15265;-0.068124;0.0018869;0.15293;-0.068401
387;1.0084;0.29446;-0.11786;0.37282;0;0;0;0;0;0;0;0;0;0;0;0;0;0.15332;-0.068407;0.0018946;0.1536;-0.068685
388.5;1.013;0.29573;-0.11835;0.37283;0;0;0;0;0;0;0;0;0;0;0;0;0;0.15398;-0.0687;0.0019144;0.15426;-0.068979
390;1.0178;0.29707;-0.11883;0.37284;0;0;0;0;0;0;0;0;0;0;0;0;0;0.15465;-0.068974;0.0019094;0.15493;-0.069254
391.5;1.0227;0.29847;-0.11924;0.37286;0;0;0;0;0;0;0;0;0;0;0;0;0;0.15532;-0.069283;0.0019197;0.1556;-0.069564
393;1.0274;0.29977;-0.11974;0.37289;0;0;0;0;0;0;0;0;0;0;0;0;0;0.15598;-0.069569;0.0019246;0.15626;-0.06985
394.5;1.0323;0.30119;-0.12029;0.37293;0;0;0;0;0;0;0;0;0;0;0;0;0;0.15667;-0.069866;0.0019306;0.15695;-0.070148
396;1.0371;0.30248;-0.12077;0.37297;0;0;0;0;0;0;0;0;0;0;0;0;0;0.15734;-0.070161;0.0019378;0.15762;-0.070443
397.5;1.0419;0.30384;-0.12123;0.373;0;0;0;0;0;0;0;0;0;0;0;0;0;0.15801;-0.07045;0.0019453;0.1583;-0.070733
399;1.0467;0.30522;-0.12174;0.37301;0;0;0;0;0;0;0;0;0;0;0;0;0;0.15868;-0.070757;0.0019482;0.15896;-0.071042
400.5;1.0516;0.30657;-0.12222;0.37302;0;0;0;0;0;0;0;0;0;0;0;0;0;0.15937;-0.071047;0.0019602;0.15965;-0.071332
402;1.0565;0.30791;-0.12262;0.37303;0;0;0;0;0;0;0;0;0;0;0;0;0;0.16004;-0.071342;0.0019713;0.16032;-0.071628
403.5;1.0615;0.30924;-0.12308;0.37303;0;0;0;0;0;0;0;0;0;0;0;0;0;0.16071;-0.071635;0.0019801;0.161;-0.071922
405;1.0662;0.31061;-0.12355;0.37304;0;0;0;0;0;0;0;0;0;0;0;0;0;0.16139;-0.071935;0.0019935;0.16167;-0.072224
406.5;1.071;0.31198;-0.12405;0.37305;0;0;0;0;0;0;0;0;0;0;0;0;0;0.16206;-0.072223;0.0019965;0.16234;-0.072512
408;1.0761;0.31335;-0.12446;0.37306;0;0;0;0;0;0;0;0;0;0;0;0;0;0.16275;-0.072514;0.0020164;0.16304;-0.072804
409.5;1.0808;0.31463;-0.12502;0.37307;0;0;0;0;0;0;0;0;0;0;0;0;0;0.16341;-0.072811;0.0020128;0.1637;-0.073102
411;1.0859;0.31595;-0.12545;0.37307;0;0;0;0;0;0;0;0;0;0;0;0;0;0.1641;-0.073113;0.0020232;0.16439;-0.073405
412.5;1.0908;0.31737;-0.12594;0.37307;0;0;0;0;0;0;0;0;0;0;0;0;0;0.16478;-0.07342;0.002038;0.16507;-0.073712
414;1.0956;0.3187;-0.1264;0.37308;0;0;0;0;0;0;0;0;0;0;0;0;0;0.16546;-0.073712;0.0020378;0.16575;-0.074005
415.5;1.1006;0.32005;-0.12677;0.37309;0;0;0;0;0;0;0;0;0;0;0;0;0;0.16614;-0.074008;0.0020527;0.16644;-0.074302
417;1.1056;0.32128;-0.12734;0.37308;0;0;0;0;0;0;0;0;0;0;0;0;0;0.16682;-0.074311;0.0020558;0.16711;-0.074606
418.5;1.1105;0.32281;-0.12774;0.37308;0;0;0;0;0;0;0;0;0;0;0;0;0;0.1675;-0.074612;0.0020662;0.1678;-0.074908
420;1.1155;0.32406;-0.12825;0.3731;0;0;0;0;0;0;0;0;0;0;0;0;0;0.16819;-0.074914;0.0020722;0.16849;-0.075211
421.5;1.1206;0.32548;-0.12869;0.3731;0;0;0;0;0;0;0;0;0;0;0;0;0;0.16888;-0.075214;0.0020822;0.16918;-0.075511
423;1.1254;0.32685;-0.12913;0.37308;0;0;0;0;0;0;0;0;0;0;0;0;0;0.16955;-0.075514;0.0020901;0.16984;-0.075813
424.5;1.1305;0.32831;-0.12959;0.37305;0;0;0;0;0;0;0;0;0;0;0;0;0;0.17025;-0.075816;0.0020959;0.17055;-0.076115
426;1.1354;0.3297;-0.13005;0.37304;0;0;0;0;0;0;0;0;0;0;0;0;0;0.17092;-0.076104;0.0021056;0.17122;-0.076403
427.5;1.1404;0.33107;-0.13056;0.37304;0;0;0;0;0;0;0;0;0;0;0;0;0;0.17161;-0.076411;0.0021171;0.17191;-0.076711
429;1.1456;0.33253;-0.13093;0.37305;0;0;0;0;0;0;0;0;0;0;0;0;0;0.17231;-0.076698;0.0021261;0.17261;-0.077
430.5;1.1505;0.3338;-0.1314;0.37304;0;0;0;0;0;0;0;0;0;0;0;0;0;0.173;-0.077012;0.002132;0.1733;-0.077314
432;1.1555;0.33528;-0.13193;0.37304;0;0;0;0;0;0;0;0;0;0;0;0;0;0.17368;-0.077316;0.0021381;0.17398;-0.077619
433.5;1.1606;0.33662;-0.13234;0.37304;0;0;0;0;0;0;0;0;0;0;0;0;0;0.17437;-0.07761;0.0021597;0.17467;-0.077915
435;1.1657;0.33805;-0.13289;0.37302;0;0;0;0;0;0;0;0;0;0;0;0;0;0.17506;-0.077915;0.0021648;0.17537;-0.07822
436.5;1.1708;0.33938;-0.13323;0.37299;0;0;0;0;0;0;0;0;0;0;0;0;0;0.17576;-0.078206;0.0021641;0.17607;-0.078512
438;1.1758;0.34075;-0.13371;0.373;0;0;0;0;0;0;0;0;0;0;0;0;0;0.17643;-0.078513;0.0021856;0.17674;-0.07882
439.5;1.181;0.34213;-0.13418;0.37301;0;0;0;0;0;0;0;0;0;0;0;0;0;0.17714;-0.078817;0.0021885;0.17745;-0.079125
441;1.1862;0.34353;-0.13448;0.37302;0;0;0;0;0;0;0;0;0;0;0;0;0;0.17785;-0.07911;0.0022018;0.17816;-0.079418
442.5;1.1916;0.345;-0.13499;0.373;0;0;0;0;0;0;0;0;0;0;0;0;0;0.17859;-0.079412;0.0022082;0.1789;-0.079721
444;1.1963;0.34615;-0.13544;0.37298;0;0;0;0;0;0;0;0;0;0;0;0;0;0.17922;-0.079733;0.0022124;0.17953;-0.080043
445.5;1.2014;0.3475;-0.13582;0.37298;0;0;0;0;0;0;0;0;0;0;0;0;0;0.17993;-0.080037;0.0022233;0.18024;-0.080348
447;1.2068;0.34902;-0.1362;0.37298;0;0;0;0;0;0;0;0;0;0;0;0;0;0.18065;-0.080325;0.0022352;0.18096;-0.080637
448.5;1.2119;0.35043;-0.13669;0.37297;0;0;0;0;0;0;0;0;0;0;0;0;0;0.18133;-0.080636;0.0022404;0.18164;-0.080948
450;1.217;0.35171;-0.13717;0.37296;0;0;0;0;0;0;0;0;0;0;0;0;0;0.18202;-0.080952;0.002246;0.18234;-0.081264
451.5;1.2222;0.35306;-0.1376;0.37294;0;0;0;0;0;0;0;0;0;0;0;0;0;0.18273;-0.081243;0.0022532;0.18304;-0.081556
453;1.2274;0.35456;-0.13793;0.37294;0;0;0;0;0;0;0;0;0;0;0;0;0;0.18343;-0.081552;0.0022555;0.18374;-0.081866
454.5;1.2326;0.35586;-0.1384;0.37293;0;0;0;0;0;0;0;0;0;0;0;0;0;0.18412;-0.081863;0.0022687;0.18444;-0.082178
456;1.2379;0.35729;-0.13893;0.37292;0;0;0;0;0;0;0;0;0;0;0;0;0;0.18483;-0.082162;0.0022792;0.18515;-0.082477
457.5;1.2432;0.35876;-0.13931;0.3729;0;0;0;0;0;0;0;0;0;0;0;0;0;0.18554;-0.08248;0.0022784;0.18586;-0.082796
459;1.2485;0.36009;-0.13975;0.37291;0;0;0;0;0;0;0;0;0;0;0;0;0;0.18625;-0.082787;0.002292;0.18656;-0.083104
460.5;1.2537;0.36153;-0.14015;0.37292;0;0;0;0;0;0;0;0;0;0;0;0;0;0.18695;-0.083103;0.0022937;0.18727;-0.08342
462;1.2592;0.363;-0.14058;0.37293;0;0;0;0;0;0;0;0;0;0;0;0;0;0.18767;-0.083403;0.0023005;0.18799;-0.083721
463.5;1.2643;0.36443;-0.14101;0.37293;0;0;0;0;0;0;0;0;0;0;0;0;0;0.18837;-0.083723;0.0023126;0.18868;-0.084042
465;1.2696;0.3659;-0.14134;0.37292;0;0;0;0;0;0;0;0;0;0;0;0;0;0.18909;-0.084031;0.0023199;0.18941;-0.084351
466.5;1.2749;0.36728;-0.14181;0.37291;0;0;0;0;0;0;0;0;0;0;0;0;0;0.18979;-0.084332;0.0023305;0.19011;-0.084653
468;1.2803;0.36855;-0.14219;0.37289;0;0;0;0;0;0;0;0;0;0;0;0;0;0.19051;-0.084636;0.0023362;0.19083;-0.084957
469.5;1.2857;0.36991;-0.14252;0.37287;0;0;0;0;0;0;0;0;0;0;0;0;0;0.19122;-0.084958;0.0023435;0.19154;-0.08528
471;1.2911;0.37131;-0.14291;0.37286;0;0;0;0;0;0;0;0;0;0;0;0;0;0.19193;-0.085269;0.0023504;0.19226;-0.085591
472.5;1.2964;0.37264;-0.14334;0.37285;0;0;0;0;0;0;0;0;0;0;0;0;0;0.19265;-0.085588;0.0023617;0.19297;-0.08591
474;1.3019;0.374;-0.14369;0.37284;0;0;0;0;0;0;0;0;0;0;0;0;0;0.19337;-0.085891;0.0023644;0.19369;-0.086214
475.5;1.3074;0.37536;-0.14399;0.37285;0;0;0;0;0;0;0;0;0;0;0;0;0;0.1941;-0.086198;0.0023627;0.19442;-0.086521
477;1.3127;0.3766;-0.14445;0.37283;0;0;0;0;0;0;0;0;0;0;0;0;0;0.1948;-0.086527;0.0023821;0.19512;-0.086852
478.5;1.3182;0.37796;-0.14481;0.37282;0;0;0;0;0;0;0;0;0;0;0;0;0;0.19553;-0.086826;0.0023889;0.19586;-0.087151
480;1.3237;0.37928;-0.14524;0.37281;0;0;0;0;0;0;0;0;0;0;0;0;0;0.19626;-0.087148;0.0023859;0.19658;-0.087473
481.5;1.3291;0.38053;-0.14554;0.37279;0;0;0;0;0;0;0;0;0;0;0;0;0;0.19697;-0.087435;0.0024105;0.19729;-0.087762
483;1.3346;0.38187;-0.14594;0.37279;0;0;0;0;0;0;0;0;0;0;0;0;0;0.1977;-0.087788;0.0024242;0.19802;-0.088115
484.5;1.3401;0.38309;-0.14633;0.37279;0;0;0;0;0;0;0;0;0;0;0;0;0;0.19842;-0.088111;0.0024337;0.19875;-0.08844
486;1.3458;0.38453;-0.14665;0.37277;0;0;0;0;0;0;0;0;0;0;0;0;0;0.19917;-0.088429;0.0024336;0.19949;-0.088757
487.5;1.3512;0.38591;-0.14698;0.37274;0;0;0;0;0;0;0;0;0;0;0;0;0;0.19988;-0.088753;0.002445;0.20021;-0.089082
489;1.3567;0.38713;-0.1473;0.37271;0;0;0;0;0;0;0;0;0;0;0;0;0;0.2006;-0.089062;0.0024583;0.20093;-0.089391
490.5;1.3622;0.38834;-0.14768;0.37269;0;0;0;0;0;0;0;0;0;0;0;0;0;0.20132;-0.089378;0.0024635;0.20165;-0.089708
492;1.3677;0.38956;-0.14805;0.37266;0;0;0;0;0;0;0;0;0;0;0;0;0;0.20206;-0.089687;0.0024777;0.20239;-0.090018
493.5;1.3734;0.39088;-0.14837;0.37264;0;0;0;0;0;0;0;0;0;0;0;0;0;0.2028;-0.090013;0.0024824;0.20313;-0.090344
495;1.379;0.39212;-0.14869;0.37262;0;0;0;0;0;0;0;0;0;0;0;0;0;0.20353;-0.090339;0.0024858;0.20386;-0.09067
496.5;1.3846;0.39329;-0.14899;0.3726;0;0;0;0;0;0;0;0;0;0;0;0;0;0.20426;-0.090647;0.0024957;0.20459;-0.090979
498;1.3903;0.39443;-0.14925;0.37258;0;0;0;0;0;0;0;0;0;0;0;0;0;0.205;-0.09097;0.002508;0.20534;-0.091302
499.5;1.3959;0.39577;-0.14948;0.37256;0;0;0;0;0;0;0;0;0;0;0;0;0;0.20574;-0.09127;0.0025136;0.20608;-0.091603
501;1.4015;0.39683;-0.14984;0.37252;0;0;0;0;0;0;0;0;0;0;0;0;0;0.20647;-0.091608;0.0025199;0.2068;-0.091941
502.5;1.4072;0.39805;-0.15001;0.3725;0;0;0;0;0;0;0;0;0;0;0;0;0;0.20721;-0.09192;0.0025275;0.20754;-0.092254
504;1.4129;0.39924;-0.15027;0.37248;0;0;0;0;0;0;0;0;0;0;0;0;0;0.20794;-0.092232;0.0025373;0.20827;-0.092567
505.5;1.4186;0.40033;-0.15051;0.37245;0;0;0;0;0;0;0;0;0;0;0;0;0;0.20867;-0.092564;0.0025454;0.20901;-0.092899
507;1.4243;0.40141;-0.15072;0.37242;0;0;0;0;0;0;0;0;0;0;0;0;0;0.20943;-0.092878;0.0025548;0.20976;-0.093213
508.5;1.43;0.40256;-0.15091;0.3724;0;0;0;0;0;0;0;0;0;0;0;0;0;0.21016;-0.093193;0.0025686;0.2105;-0.09353
510;1.4358;0.40346;-0.15103;0.37238;0;0;0;0;0;0;0;0;0;0;0;0;0;0.21091;-0.093501;0.0025643;0.21125;-0.093838
511.5;1.4415;0.40442;-0.15133;0.37234;0;0;0;0;0;0;0;0;0;0;0;0;0;0.21164;-0.093856;0.0025753;0.21197;-0.094193
513;1.4473;0.40542;-0.15143;0.3723;0;0;0;0;0;0;0;0;0;0;0;0;0;0.21239;-0.094152;0.0025864;0.21273;-0.094491
514.5;1.4532;0.40637;-0.15151;0.37223;0;0;0;0;0;0;0;0;0;0;0;0;0;0.21314;-0.09446;0.0025834;0.21348;-0.094799
516;1.4591;0.40735;-0.15169;0.37218;0;0;0;0;0;0;0;0;0;0;0;0;0;0.21388;-0.094783;0.0026025;0.21422;-0.095122
517.5;1.4648;0.40824;-0.15171;0.37214;0;0;0;0;0;0;0;0;0;0;0;0;0;0.21463;-0.095097;0.0026096;0.21497;-0.095437
519;1.4707;0.4091;-0.15184;0.37209;0;0;0;0;0;0;0;0;0;0;0;0;0;0.21536;-0.095413;0.0026138;0.2157;-0.095754
520.5;1.4764;0.40985;-0.15197;0.37204;0;0;0;0;0;0;0;0;0;0;0;0;0;0.21609;-0.095734;0.0026207;0.21643;-0.096075
522;1.4824;0.41069;-0.15203;0.37197;0;0;0;0;0;0;0;0;0;0;0;0;0;0.21685;-0.096036;0.0026322;0.21719;-0.096377
523.5;1.4883;0.41133;-0.15205;0.37192;0;0;0;0;0;0;0;0;0;0;0;0;0;0.21758;-0.096355;0.0026336;0.21792;-0.096697
525;1.4943;0.41191;-0.15215;0.37187;0;0;0;0;0;0;0;0;0;0;0;0;0;0.21832;-0.096669;0.0026507;0.21866;-0.097011
526.5;1.5002;0.41242;-0.15222;0.3718;0;0;0;0;0;0;0;0;0;0;0;0;0;0.21906;-0.096977;0.0026596;0.21941;-0.097321
528;1.5061;0.413;-0.15221;0.3717;0;0;0;0;0;0;0;0;0;0;0;0;0;0.2198;-0.097291;0.0026659;0.22015;-0.097635
529.5;1.512;0.41355;-0.15233;0.37162;0;0;0;0;0;0;0;0;0;0;0;0;0;0.22054;-0.097601;0.002674;0.22088;-0.097945
531;1.518;0.41407;-0.15228;0.37154;0;0;0;0;0;0;0;0;0;0;0;0;0;0.22127;-0.097919;0.0026865;0.22162;-0.098264
532.5;1.5239;0.41454;-0.15238;0.37145;0;0;0;0;0;0;0;0;0;0;0;0;0;0.222;-0.098227;0.0026948;0.22234;-0.098571
534;1.5298;0.41496;-0.15235;0.37136;0;0;0;0;0;0;0;0;0;0;0;0;0;0.22271;-0.098511;0.0026998;0.22306;-0.098856
535.5;1.5359;0.41538;-0.15229;0.37122;0;0;0;0;0;0;0;0;0;0;0;0;0;0.22345;-0.098809;0.0027088;0.2238;-0.099155
537;1.542;0.41583;-0.15235;0.37112;0;0;0;0;0;0;0;0;0;0;0;0;0;0.22418;-0.099089;0.0027261;0.22453;-0.099435
538.5;1.5478;0.4162;-0.15238;0.37098;0;0;0;0;0;0;0;0;0;0;0;0;0;0.22489;-0.099397;0.002733;0.22524;-0.099744
540;1.5538;0.41657;-0.15237;0.37083;0;0;0;0;0;0;0;0;0;0;0;0;0;0.22562;-0.09969;0.0027458;0.22596;-0.10004
541.5;1.5601;0.41691;-0.15242;0.37067;0;0;0;0;0;0;0;0;0;0;0;0;0;0.22634;-0.099991;0.0027605;0.22669;-0.10034
543;1.5662;0.41734;-0.15239;0.37046;0;0;0;0;0;0;0;0;0;0;0;0;0;0.22706;-0.10027;0.0027767;0.22741;-0.10062
544.5;1.5722;0.41769;-0.15236;0.37022;0;0;0;0;0;0;0;0;0;0;0;0;0;0.22778;-0.10054;0.0027918;0.22813;-0.10089
546;1.5783;0.41804;-0.15233;0.36995;0;0;0;0;0;0;0;0;0;0;0;0;0;0.22849;-0.10083;0.0028039;0.22884;-0.10118
547.5;1.5845;0.41844;-0.15238;0.36963;0;0;0;0;0;0;0;0;0;0;0;0;0;0.22921;-0.10111;0.0028244;0.22956;-0.10146
549;1.5908;0.41874;-0.1524;0.36921;0;0;0;0;0;0;0;0;0;0;0;0;0;0.22994;-0.10138;0.0028504;0.23029;-0.10173
550.5;1.5971;0.41909;-0.15235;0.36874;0;0;0;0;0;0;0;0;0;0;0;0;0;0.23065;-0.10166;0.0028567;0.231;-0.10202
552;1.6034;0.41931;-0.1525;0.36818;0;0;0;0;0;0;0;0;0;0;0;0;0;0.23137;-0.10194;0.0028987;0.23172;-0.10229
553.5;1.6096;0.41956;-0.15243;0.36752;0;0;0;0;0;0;0;0;0;0;0;0;0;0.23207;-0.1022;0.0029113;0.23243;-0.10256
555;1.616;0.41982;-0.15245;0.36675;0;0;0;0;0;0;0;0;0;0;0;0;0;0.23277;-0.10245;0.0029326;0.23313;-0.10281
556.5;1.622;0.41991;-0.15241;0.36581;0;0;0;0;0;0;0;0;0;0;0;0;0;0.23345;-0.1027;0.0029692;0.23381;-0.10306
558;1.6285;0.42014;-0.15242;0.36475;0;0;0;0;0;0;0;0;0;0;0;0;0;0.23397;-0.10287;0.0029158;0.23433;-0.10323
559.5;1.6347;0.42025;-0.15248;0.36357;0;0;0;0;0;0;0;0;0;0;0;0;0;0.23463;-0.10313;0.0029397;0.235;-0.1035
561;1.6408;0.42029;-0.15243;0.36214;0;0;0;0;0;0;0;0;0;0;0;0;0;0.23529;-0.10337;0.0029691;0.23565;-0.10373
562.5;1.6472;0.4203;-0.15239;0.36065;0;0;0;0;0;0;0;0;0;0;0;0;0;0.23595;-0.10359;0.0029869;0.23632;-0.10396
564;1.6531;0.42029;-0.15243;0.35892;0;0;0;0;0;0;0;0;0;0;0;0;0;0.23657;-0.10386;0.0030028;0.23694;-0.10423
565.5;1.6593;0.42032;-0.15242;0.35702;0;0;0;0;0;0;0;0;0;0;0;0;0;0.23722;-0.10403;0.0030537;0.23759;-0.10441
567;1.6656;0.42037;-0.15235;0.35493;0;0;0;0;0;0;0;0;0;0;0;0;0;0.23785;-0.10424;0.0030949;0.23822;-0.10461
568.5;1.6717;0.42037;-0.15239;0.35268;0;0;0;0;0;0;0;0;0;0;0;0;0;0.23845;-0.10446;0.0031396;0.23883;-0.10484
570;1.6778;0.42031;-0.15236;0.35023;0;0;0;0;0;0;0;0;0;0;0;0;0;0.23906;-0.10462;0.0031829;0.23944;-0.10499
571.5;1.684;0.4202;-0.15234;0.34749;0;0;0;0;0;0;0;0;0;0;0;0;0;0.23966;-0.10477;0.0032446;0.24004;-0.10515
573;1.6901;0.42015;-0.15234;0.34457;0;0;0;0;0;0;0;0;0;0;0;0;0;0.24025;-0.10496;0.0032817;0.24064;-0.10534
574.5;1.6965;0.42016;-0.15232;0.34125;0;0;0;0;0;0;0;0;0;0;0;0;0;0.24084;-0.10512;0.0033316;0.24123;-0.10551
576;1.7028;0.41995;-0.15232;0.33766;0;0;0;0;0;0;0;0;0;0;0;0;0;0.24141;-0.10527;0.0033881;0.2418;-0.10566
577.5;1.7092;0.41984;-0.15231;0.33353;0;0;0;0;0;0;0;0;0;0;0;0;0;0.24198;-0.1054;0.0034661;0.24237;-0.1058
579;1.7159;0.41973;-0.15223;0.32893;0;0;0;0;0;0;0;0;0;0;0;0;0;0.24254;-0.10552;0.0035498;0.24294;-0.10592
580.5;1.7227;0.4195;-0.15219;0.32344;0;0;0;0;0;0;0;0;0;0;0;0;0;0.24308;-0.10566;0.0036157;0.24349;-0.10607
582;NaN;NaN;NaN;0.31384;0;0;0;0;0;0;0;0;0;0;0;0;0;0;0;0;0;0
583.5;NaN;NaN;NaN;0.19124;0;0;0;0;0;0;0;0;0;0;0;0;0;0;0;0;0;0
585;NaN;NaN;NaN;0.074304;0;0;0;0;0;0;0;0;0;0;0;0;0;0;0;0;0;0
586;NaN;NaN;NaN;0.0001274;0;0;0;0;0;0;0;0;0;0;0;0;0;0;0;0;0;0