File: Template_Auto_Cali_large_DP600/_data/DP600Large_NT20_00_003_Front_DIC_File.txt
Date of Test;Material;Sample Geometry;Orientation [°];Test Number;Nominal Speed [mm/min];Thickness [mm];Central Width [mm];Gauge Width / Diameter [mm];Pixel to mm ratio [mm/px];Extensometer 1-4 [mm];Extensometer 2-3 [mm];Extensometer 5-6 [mm];;;;;
09/08/21;DP600Large;NT20;00;3;0.0798;0.29036;2;4;0;6;0.20001;0.4;;;;;
;;;;;;;;;;;;;;;;;
Time [s];U1 [mm];U2 [mm];U3 [mm];Force [kN];Ambient Temperature [°C];DIC Zone X 1 [px];DIC Zone Y 1 [px];DIC Zone X 2 [px];DIC Zone Y 2 [px];DIC Zone X 3 [px];DIC Zone Y 3 [px];DIC Zone X 4 [px];DIC Zone Y 4 [px];DIC Zone X 5 [px];DIC Zone Y 5 [px];DIC Zone X 6 [px];DIC Zone Y 6 [px]
0;0;0;0;9.8e-06;0;0;0;0;0;0;0;0;0;0;0;0;0
1;-2.8602e-05;-6.0426e-05;-4.9942e-05;9.8e-06;0;0;0;0;0;0;0;0;0;0;0;0;0
2;7.6281e-05;-5.0475e-05;-1.5495e-05;9.8e-06;0;0;0;0;0;0;0;0;0;0;0;0;0
3;-2.4944e-05;-2.5435e-05;-2.1472e-05;1.96e-05;0;0;0;0;0;0;0;0;0;0;0;0;0
4;0.00019624;-0.00015154;5.0552e-06;3.92e-05;0;0;0;0;0;0;0;0;0;0;0;0;0
5;5.3178e-05;-8.343e-05;-3.6164e-05;0.0002352;0;0;0;0;0;0;0;0;0;0;0;0;0
6.001;0.00024332;-9.3451e-05;3.7409e-05;0.0007742;0;0;0;0;0;0;0;0;0;0;0;0;0
7.001;0.00035282;-8.1846e-05;9.7029e-06;0.0015288;0;0;0;0;0;0;0;0;0;0;0;0;0
8;0.00035318;-0.00018182;-2.6019e-06;0.002401;0;0;0;0;0;0;0;0;0;0;0;0;0
9;0.00027722;-0.00019064;-1.7995e-06;0.0032536;0;0;0;0;0;0;0;0;0;0;0;0;0
10;0.000374;-0.00016967;-1.8825e-05;0.0038318;0;0;0;0;0;0;0;0;0;0;0;0;0
11;0.00040295;-0.0002919;-2.083e-05;0.0043904;0;0;0;0;0;0;0;0;0;0;0;0;0
12;0.00044754;-0.00028286;-1.1001e-06;0.0050176;0;0;0;0;0;0;0;0;0;0;0;0;0
13;0.00050544;-0.00024604;-4.2106e-05;0.005684;0;0;0;0;0;0;0;0;0;0;0;0;0
14;0.00057168;-0.00033072;-6.7976e-05;0.0064288;0;0;0;0;0;0;0;0;0;0;0;0;0
15;0.0005489;-0.00038167;-4.9117e-05;0.0071344;0;0;0;0;0;0;0;0;0;0;0;0;0
15.999;0.0006757;-0.0003117;9.6923e-06;0.0078792;0;0;0;0;0;0;0;0;0;0;0;0;0
17;0.00072058;-0.00041144;-5.2386e-05;0.0087318;0;0;0;0;0;0;0;0;0;0;0;0;0
18;0.00070524;-0.00048298;-4.6226e-05;0.0095844;0;0;0;0;0;0;0;0;0;0;0;0;0
19.001;0.00092595;-0.00040383;-2.2053e-05;0.010555;0;0;0;0;0;0;0;0;0;0;0;0;0
20;0.00060376;-0.00054481;-6.7643e-05;0.01174;0;0;0;0;0;0;0;0;0;0;0;0;0
21.001;0.0010358;-0.000437;-4.8129e-05;0.013005;0;0;0;0;0;0;0;0;0;0;0;0;0
22;0.0011069;-0.00060404;-5.1631e-05;0.014416;0;0;0;0;0;0;0;0;0;0;0;0;0
23.001;0.0011887;-0.00055397;-6.3494e-05;0.015954;0;0;0;0;0;0;0;0;0;0;0;0;0
24;0.0011859;-0.00066478;-6.4033e-05;0.01763;0;0;0;0;0;0;0;0;0;0;0;0;0
25;0.0012431;-0.00071387;-2.2656e-05;0.019561;0;0;0;0;0;0;0;0;0;0;0;0;0
26.001;0.0012488;-0.00064041;-3.0308e-05;0.02157;0;0;0;0;0;0;0;0;0;0;0;0;0
27.001;0.0012273;-0.00075954;-1.5473e-06;0.023647;0;0;0;0;0;0;0;0;0;0;0;0;0
27.999;0.0015079;-0.00077351;-1.6381e-05;0.02595;0;0;0;0;0;0;0;0;0;0;0;0;0
28.999;0.001591;-0.00084967;1.0164e-05;0.028342;0;0;0;0;0;0;0;0;0;0;0;0;0
30;0.0016557;-0.00093666;-3.6557e-05;0.030919;0;0;0;0;0;0;0;0;0;0;0;0;0
30.999;0.0018087;-0.00091372;1.0233e-05;0.033398;0;0;0;0;0;0;0;0;0;0;0;0;0
32;0.001898;-0.00089128;1.8239e-05;0.036035;0;0;0;0;0;0;0;0;0;0;0;0;0
32.999;0.0019805;-0.0009127;3.0798e-06;0.038877;0;0;0;0;0;0;0;0;0;0;0;0;0
34;0.0019674;-0.0010801;3.2896e-06;0.041542;0;0;0;0;0;0;0;0;0;0;0;0;0
35;0.002106;-0.0009193;-2.2495e-05;0.044345;0;0;0;0;0;0;0;0;0;0;0;0;0
36;0.0022006;-0.00099246;-8.4382e-07;0.047275;0;0;0;0;0;0;0;0;0;0;0;0;0
36.999;0.0023484;-0.0011313;-2.181e-05;0.050039;0;0;0;0;0;0;0;0;0;0;0;0;0
38;0.0022897;-0.0011262;-5.2925e-05;0.053047;0;0;0;0;0;0;0;0;0;0;0;0;0
38.999;0.0025039;-0.00112;-6.6609e-05;0.05636;0;0;0;0;0;0;0;0;0;0;0;0;0
40;0.0025745;-0.0011493;-4.2219e-05;0.059613;0;0;0;0;0;0;0;0;0;0;0;0;0
41;0.002703;-0.0011413;-3.3263e-05;0.063308;0;0;0;0;0;0;0;0;0;0;0;0;0
42;0.0028957;-0.0011375;-3.8937e-05;0.066865;0;0;0;0;0;0;0;0;0;0;0;0;0
43;0.0030384;-0.001154;-7.2457e-05;0.070707;0;0;0;0;0;0;0;0;0;0;0;0;0
44;0.0031797;-0.0012367;-1.4673e-05;0.074617;0;0;0;0;0;0;0;0;0;0;0;0;0
45;0.0032993;-0.0013859;-3.767e-05;0.078782;0;0;0;0;0;0;0;0;0;0;0;0;0
46;0.0034956;-0.001313;-5.9914e-06;0.082692;0;0;0;0;0;0;0;0;0;0;0;0;0
47;0.0035604;-0.0012811;-3.4843e-05;0.086975;0;0;0;0;0;0;0;0;0;0;0;0;0
48;0.0037611;-0.0013321;8.5143e-06;0.090983;0;0;0;0;0;0;0;0;0;0;0;0;0
49;0.004041;-0.001356;-3.5344e-05;0.095207;0;0;0;0;0;0;0;0;0;0;0;0;0
50;0.0038217;-0.0013663;-3.8201e-06;0.09947;0;0;0;0;0;0;0;0;0;0;0;0;0
51.001;0.0043051;-0.0013325;-0.00011282;0.10374;0;0;0;0;0;0;0;0;0;0;0;0;0
52.001;0.0045322;-0.0013705;-4.2558e-05;0.10806;0;0;0;0;0;0;0;0;0;0;0;0;0
53;0.0047512;-0.0013492;-6.7357e-05;0.11243;0;0;0;0;0;0;0;0;0;0;0;0;0
54;0.0048661;-0.0013404;-7.6523e-05;0.11685;0;0;0;0;0;0;0;0;0;0;0;0;0
55;0.0050554;-0.0013953;-2.7768e-05;0.12133;0;0;0;0;0;0;0;0;0;0;0;0;0
56;0.005291;-0.0013244;-4.1405e-05;0.1259;0;0;0;0;0;0;0;0;0;0;0;0;0
57;0.0056465;-0.0013529;-3.0742e-05;0.1305;0;0;0;0;0;0;0;0;0;0;0;0;0
58;0.0057173;-0.0013567;-6.8458e-05;0.13498;0;0;0;0;0;0;0;0;0;0;0;0;0
59;0.0059844;-0.001317;-3.2109e-05;0.13988;0;0;0;0;0;0;0;0;0;0;0;0;0
60;0.0061768;-0.001331;-5.9387e-05;0.14462;0;0;0;0;0;0;0;0;0;0;0;0;0
61;0.006502;-0.0012976;-8.9295e-05;0.14959;0;0;0;0;0;0;0;0;0;0;0;0;0
62;0.0067462;-0.0013727;-0.00010316;0.15416;0;0;0;0;0;0;0;0;0;0;0;0;0
63;0.0069674;-0.0013539;-0.00010224;0.15891;0;0;0;0;0;0;0;0;0;0;0;0;0
63.999;0.0072514;-0.0013318;-5.4983e-05;0.16365;0;0;0;0;0;0;0;0;0;0;0;0;0
65;0.0075226;-0.0013091;-0.00014346;0.16838;0;0;0;0;0;0;0;0;0;0;0;0;0
66;0.0078185;-0.0012826;-0.00015457;0.17333;0;0;0;0;0;0;0;0;0;0;0;0;0
67;0.0081189;-0.0013142;-0.0001268;0.17788;0;0;0;0;0;0;0;0;0;0;0;0;0
68;0.0085074;-0.00131;-0.00021142;0.18258;0;0;0;0;0;0;0;0;0;0;0;0;0
69;0.008759;-0.0012407;-0.00013547;0.18722;0;0;0;0;0;0;0;0;0;0;0;0;0
70;0.0092764;-0.0012937;-0.00017082;0.1918;0;0;0;0;0;0;0;0;0;0;0;0;0
70.999;0.0095524;-0.0013087;-0.00010646;0.19629;0;0;0;0;0;0;0;0;0;0;0;0;0
72;0.0098323;-0.0013249;-0.00013486;0.20069;0;0;0;0;0;0;0;0;0;0;0;0;0
73;0.01036;-0.0012669;-0.0001759;0.20505;0;0;0;0;0;0;0;0;0;0;0;0;0
73.999;0.010847;-0.0011561;-0.0001898;0.2093;0;0;0;0;0;0;0;0;0;0;0;0;0
74.999;0.011308;-0.0011661;-0.00025842;0.21348;0;0;0;0;0;0;0;0;0;0;0;0;0
76;0.011766;-0.0012051;-0.00028988;0.21755;0;0;0;0;0;0;0;0;0;0;0;0;0
77;0.012348;-0.0011966;-0.00033423;0.22147;0;0;0;0;0;0;0;0;0;0;0;0;0
78;0.012863;-0.0011614;-0.00029637;0.22525;0;0;0;0;0;0;0;0;0;0;0;0;0
78.999;0.013365;-0.0010531;-0.0003474;0.22902;0;0;0;0;0;0;0;0;0;0;0;0;0
79.999;0.014081;-0.0010615;-0.00047477;0.2324;0;0;0;0;0;0;0;0;0;0;0;0;0
81;0.014785;-0.0010795;-0.00042899;0.23594;0;0;0;0;0;0;0;0;0;0;0;0;0
82;0.015213;-0.0010232;-0.00044617;0.23921;0;0;0;0;0;0;0;0;0;0;0;0;0
82.999;0.015896;-0.00098118;-0.00045441;0.24223;0;0;0;0;0;0;0;0;0;0;0;0;0
83.999;0.016382;-0.0010525;-0.00055824;0.24511;0;0;0;0;0;0;0;0;0;0;0;0;0
85;0.017394;-0.00091626;-0.0006076;0.24822;0;0;0;0;0;0;0;0;0;0;0;0;0
86;0.018151;-0.00085962;-0.00069906;0.25086;0;0;0;0;0;0;0;0;0;0;0;0;0
86.999;0.018763;-0.00085169;-0.0007518;0.25348;0;0;0;0;0;0;0;0;0;0;0;0;0
88;0.019478;-0.00072145;-0.00080694;0.256;0;0;0;0;0;0;0;0;0;0;0;0;0
89;0.020247;-0.00069495;-0.00080707;0.25831;0;0;0;0;0;0;0;0;0;0;0;0;0
89.999;0.020959;-0.0005853;-0.00092213;0.26072;0;0;0;0;0;0;0;0;0;0;0;0;0
90.999;0.021862;-0.0006306;-0.00094095;0.26298;0;0;0;0;0;0;0;0;0;0;0;0;0
92.001;0.022565;-0.00048085;-0.0010454;0.26524;0;0;0;0;0;0;0;0;0;0;0;0;0
93;0.023393;-0.00049936;-0.001068;0.26731;0;0;0;0;0;0;0;0;0;0;0;0;0
94;0.02431;-0.00032207;-0.0011741;0.26925;0;0;0;0;0;0;0;0;0;0;0;0;0
94.999;0.025207;-0.00034136;-0.0011597;0.27112;0;0;0;0;0;0;0;0;0;0;0;0;0
96;0.026213;-0.00015703;-0.0012283;0.27316;0;0;0;0;0;0;0;0;0;0;0;0;0
97;0.026595;-0.00018709;-0.0012899;0.27491;0;0;0;0;0;0;0;0;0;0;0;0;0
98;0.027747;-3.5357e-05;-0.001392;0.27668;0;0;0;0;0;0;0;0;0;0;0;0;0
98.999;0.028499;-4.9987e-06;-0.001475;0.2785;0;0;0;0;0;0;0;0;0;0;0;0;0
100;0.029705;5.8495e-05;-0.0015754;0.28013;0;0;0;0;0;0;0;0;0;0;0;0;0
101;0.030315;0.00011559;-0.0015947;0.2818;0;0;0;0;0;0;0;0;0;0;0;0;0
102;0.031252;0.00014247;-0.0016995;0.28347;0;0;0;0;0;0;0;0;0;0;0;0;0
103;0.032258;0.00027462;-0.0017696;0.28495;0;0;0;0;0;0;0;0;0;0;0;0;0
104;0.033276;0.00018911;-0.001802;0.28647;0;0;0;0;0;0;0;0;0;0;0;0;0
105;0.034181;0.00037252;-0.0019008;0.28795;0;0;0;0;0;0;0;0;0;0;0;0;0
106;0.035245;0.00046748;-0.0019092;0.28942;0;0;0;0;0;0;0;0;0;0;0;0;0
107;0.036208;0.00047817;-0.0020428;0.29089;0;0;0;0;0;0;0;0;0;0;0;0;0
108;0.036928;0.00056784;-0.0020858;0.29232;0;0;0;0;0;0;0;0;0;0;0;0;0
109;0.037861;0.00060542;-0.0021693;0.29373;0;0;0;0;0;0;0;0;0;0;0;0;0
110;0.038995;0.00073947;-0.0022477;0.29506;0;0;0;0;0;0;0;0;0;0;0;0;0
111;0.040002;0.00073337;-0.0023154;0.29636;0;0;0;0;0;0;0;0;0;0;0;0;0
112;0.041076;0.00078726;-0.0023692;0.29765;0;0;0;0;0;0;0;0;0;0;0;0;0
113;0.041409;0.00089171;-0.0024174;0.29898;0;0;0;0;0;0;0;0;0;0;0;0;0
114;0.043088;0.0008809;-0.0025433;0.3002;0;0;0;0;0;0;0;0;0;0;0;0;0
115;0.043967;0.0010874;-0.002617;0.30144;0;0;0;0;0;0;0;0;0;0;0;0;0
116;0.044957;0.0011077;-0.0026273;0.3027;0;0;0;0;0;0;0;0;0;0;0;0;0
117;0.046028;0.0010894;-0.0027705;0.30383;0;0;0;0;0;0;0;0;0;0;0;0;0
118;0.047001;0.0012987;-0.0028499;0.30504;0;0;0;0;0;0;0;0;0;0;0;0;0
119;0.04803;0.0013033;-0.0028774;0.30614;0;0;0;0;0;0;0;0;0;0;0;0;0
120;0.048985;0.0013839;-0.0029706;0.30727;0;0;0;0;0;0;0;0;0;0;0;0;0
121;0.050004;0.0014631;-0.003019;0.30844;0;0;0;0;0;0;0;0;0;0;0;0;0
122;0.051103;0.001484;-0.0030643;0.3095;0;0;0;0;0;0;0;0;0;0;0;0;0
123;0.052272;0.0016233;-0.003163;0.31062;0;0;0;0;0;0;0;0;0;0;0;0;0
124;0.053164;0.0017361;-0.0032121;0.31177;0;0;0;0;0;0;0;0;0;0;0;0;0
125;0.054245;0.001657;-0.0032555;0.3128;0;0;0;0;0;0;0;0;0;0;0;0;0
126;0.055219;0.0019075;-0.0033614;0.31384;0;0;0;0;0;0;0;0;0;0;0;0;0
127;0.056358;0.0019752;-0.0034261;0.31487;0;0;0;0;0;0;0;0;0;0;0;0;0
128;0.057476;0.0019661;-0.0034288;0.31588;0;0;0;0;0;0;0;0;0;0;0;0;0
129;0.058634;0.0020593;-0.0035509;0.31692;0;0;0;0;0;0;0;0;0;0;0;0;0
130;0.059434;0.002073;-0.0036298;0.31786;0;0;0;0;0;0;0;0;0;0;0;0;0
131;0.060482;0.0020831;-0.0036747;0.31886;0;0;0;0;0;0;0;0;0;0;0;0;0
132;0.061491;0.0022865;-0.0037517;0.31976;0;0;0;0;0;0;0;0;0;0;0;0;0
133;0.062657;0.0023552;-0.0038785;0.32069;0;0;0;0;0;0;0;0;0;0;0;0;0
134;0.063759;0.0023271;-0.0039356;0.3216;0;0;0;0;0;0;0;0;0;0;0;0;0
135;0.064866;0.0023907;-0.0040052;0.32249;0;0;0;0;0;0;0;0;0;0;0;0;0
136;0.06589;0.0025235;-0.0040457;0.32339;0;0;0;0;0;0;0;0;0;0;0;0;0
137;0.066975;0.0024932;-0.0041782;0.32422;0;0;0;0;0;0;0;0;0;0;0;0;0
138;0.068077;0.0026801;-0.0042434;0.32507;0;0;0;0;0;0;0;0;0;0;0;0;0
139;0.069287;0.002722;-0.0043646;0.32594;0;0;0;0;0;0;0;0;0;0;0;0;0
140;0.070172;0.0026709;-0.0044396;0.32678;0;0;0;0;0;0;0;0;0;0;0;0;0
141;0.071341;0.0027613;-0.0044845;0.3276;0;0;0;0;0;0;0;0;0;0;0;0;0
142;0.072363;0.0028469;-0.0045844;0.32844;0;0;0;0;0;0;0;0;0;0;0;0;0
143;0.073504;0.0028554;-0.0046772;0.32925;0;0;0;0;0;0;0;0;0;0;0;0;0
144;0.074414;0.0029591;-0.0047727;0.33002;0;0;0;0;0;0;0;0;0;0;0;0;0
145;0.075746;0.0030607;-0.0048045;0.33079;0;0;0;0;0;0;0;0;0;0;0;0;0
146;0.076698;0.0031699;-0.0049404;0.33161;0;0;0;0;0;0;0;0;0;0;0;0;0
147;0.077922;0.0031642;-0.0050495;0.33239;0;0;0;0;0;0;0;0;0;0;0;0;0
148;0.078874;0.0033265;-0.0050836;0.33316;0;0;0;0;0;0;0;0;0;0;0;0;0
149;0.080126;0.0032846;-0.0052339;0.33393;0;0;0;0;0;0;0;0;0;0;0;0;0
150;0.081163;0.0033284;-0.0052806;0.33466;0;0;0;0;0;0;0;0;0;0;0;0;0
151;0.08223;0.0033953;-0.0053587;0.33541;0;0;0;0;0;0;0;0;0;0;0;0;0
152;0.083412;0.003512;-0.0054397;0.33613;0;0;0;0;0;0;0;0;0;0;0;0;0
153;0.084527;0.0034054;-0.0055021;0.33684;0;0;0;0;0;0;0;0;0;0;0;0;0
154;0.08562;0.0035574;-0.0056206;0.33759;0;0;0;0;0;0;0;0;0;0;0;0;0
155;0.086758;0.0037083;-0.0056926;0.33831;0;0;0;0;0;0;0;0;0;0;0;0;0
156;0.087841;0.0037398;-0.0057796;0.339;0;0;0;0;0;0;0;0;0;0;0;0;0
157;0.088563;0.0037682;-0.0058152;0.33971;0;0;0;0;0;0;0;0;0;0;0;0;0
158;0.090177;0.0039344;-0.0058842;0.34035;0;0;0;0;0;0;0;0;0;0;0;0;0
159;0.09114;0.0040696;-0.0059705;0.34101;0;0;0;0;0;0;0;0;0;0;0;0;0
160;0.092313;0.0040792;-0.0060595;0.34168;0;0;0;0;0;0;0;0;0;0;0;0;0
161;0.093413;0.00418;-0.006096;0.34233;0;0;0;0;0;0;0;0;0;0;0;0;0
162;0.094592;0.0042913;-0.0061988;0.34299;0;0;0;0;0;0;0;0;0;0;0;0;0
163;0.095596;0.0044165;-0.0062639;0.34365;0;0;0;0;0;0;0;0;0;0;0;0;0
164;0.096961;0.0044426;-0.0063239;0.34428;0;0;0;0;0;0;0;0;0;0;0;0;0
165;0.09814;0.0045477;-0.006466;0.34493;0;0;0;0;0;0;0;0;0;0;0;0;0
166;0.099391;0.0046495;-0.0065576;0.34552;0;0;0;0;0;0;0;0;0;0;0;0;0
167;0.10022;0.0047117;-0.0066439;0.34612;0;0;0;0;0;0;0;0;0;0;0;0;0
168;0.10144;0.0047868;-0.0066313;0.34671;0;0;0;0;0;0;0;0;0;0;0;0;0
169;0.10256;0.0049381;-0.0067643;0.34729;0;0;0;0;0;0;0;0;0;0;0;0;0
170;0.10366;0.0050126;-0.0068174;0.34788;0;0;0;0;0;0;0;0;0;0;0;0;0
171;0.10476;0.005052;-0.0069154;0.34842;0;0;0;0;0;0;0;0;0;0;0;0;0
172;0.10592;0.0052;-0.0069446;0.34896;0;0;0;0;0;0;0;0;0;0;0;0;0
173;0.10705;0.0052612;-0.0070498;0.34954;0;0;0;0;0;0;0;0;0;0;0;0;0
174;0.10815;0.005348;-0.0070533;0.3501;0;0;0;0;0;0;0;0;0;0;0;0;0
175;0.10931;0.005428;-0.0071622;0.35065;0;0;0;0;0;0;0;0;0;0;0;0;0
176;0.11043;0.005609;-0.0072027;0.35119;0;0;0;0;0;0;0;0;0;0;0;0;0
177;0.11161;0.0056928;-0.007278;0.35173;0;0;0;0;0;0;0;0;0;0;0;0;0
178;0.1128;0.0057899;-0.007387;0.35229;0;0;0;0;0;0;0;0;0;0;0;0;0
179;0.11391;0.0058324;-0.0074469;0.35281;0;0;0;0;0;0;0;0;0;0;0;0;0
180;0.11494;0.0059129;-0.0074558;0.35331;0;0;0;0;0;0;0;0;0;0;0;0;0
181;0.11615;0.0060218;-0.0075581;0.35387;0;0;0;0;0;0;0;0;0;0;0;0;0
182;0.11726;0.0060823;-0.0075834;0.35436;0;0;0;0;0;0;0;0;0;0;0;0;0
183;0.11844;0.0061845;-0.007714;0.35485;0;0;0;0;0;0;0;0;0;0;0;0;0
184;0.11951;0.0062943;-0.0077356;0.35537;0;0;0;0;0;0;0;0;0;0;0;0;0
185;0.12052;0.006389;-0.0078271;0.35589;0;0;0;0;0;0;0;0;0;0;0;0;0
186;0.12193;0.0064549;-0.0079077;0.35638;0;0;0;0;0;0;0;0;0;0;0;0;0
187;0.12308;0.0065453;-0.0079713;0.35691;0;0;0;0;0;0;0;0;0;0;0;0;0
188;0.12409;0.006663;-0.0080047;0.35738;0;0;0;0;0;0;0;0;0;0;0;0;0
189;0.12521;0.0067596;-0.0080462;0.35784;0;0;0;0;0;0;0;0;0;0;0;0;0
190;0.12646;0.0068243;-0.0080909;0.35831;0;0;0;0;0;0;0;0;0;0;0;0;0
191;0.1278;0.0069756;-0.0081664;0.35877;0;0;0;0;0;0;0;0;0;0;0;0;0
192;0.1288;0.0070546;-0.008198;0.35923;0;0;0;0;0;0;0;0;0;0;0;0;0
193;0.13011;0.0071542;-0.0083419;0.35969;0;0;0;0;0;0;0;0;0;0;0;0;0
194;0.13103;0.0071395;-0.0083792;0.36017;0;0;0;0;0;0;0;0;0;0;0;0;0
195;0.13222;0.0073675;-0.008498;0.3606;0;0;0;0;0;0;0;0;0;0;0;0;0
196;0.13317;0.0074589;-0.0085826;0.36105;0;0;0;0;0;0;0;0;0;0;0;0;0
197;0.13448;0.0075311;-0.0086351;0.36151;0;0;0;0;0;0;0;0;0;0;0;0;0
198;0.13566;0.0076151;-0.0087409;0.36192;0;0;0;0;0;0;0;0;0;0;0;0;0
199;0.1368;0.0077826;-0.008798;0.36235;0;0;0;0;0;0;0;0;0;0;0;0;0
200;0.13791;0.0079081;-0.0089059;0.36276;0;0;0;0;0;0;0;0;0;0;0;0;0
201;0.13892;0.0079533;-0.0089568;0.36316;0;0;0;0;0;0;0;0;0;0;0;0;0
202.01;0.14039;0.0080804;-0.0089528;0.36357;0;0;0;0;0;0;0;0;0;0;0;0;0
203;0.14165;0.0081407;-0.0090464;0.36392;0;0;0;0;0;0;0;0;0;0;0;0;0
204;0.14264;0.0082975;-0.0091232;0.36434;0;0;0;0;0;0;0;0;0;0;0;0;0
205;0.1438;0.0083331;-0.0092449;0.36473;0;0;0;0;0;0;0;0;0;0;0;0;0
206;0.14501;0.0084804;-0.0092808;0.36512;0;0;0;0;0;0;0;0;0;0;0;0;0
207;0.14618;0.0085992;-0.0093505;0.36552;0;0;0;0;0;0;0;0;0;0;0;0;0
208;0.14734;0.0087231;-0.0095002;0.36589;0;0;0;0;0;0;0;0;0;0;0;0;0
209;0.14849;0.0087071;-0.0094902;0.36632;0;0;0;0;0;0;0;0;0;0;0;0;0
210;0.14977;0.0087993;-0.0096019;0.3667;0;0;0;0;0;0;0;0;0;0;0;0;0
211;0.15086;0.0088776;-0.0096012;0.36707;0;0;0;0;0;0;0;0;0;0;0;0;0
212;0.15207;0.0090716;-0.0096194;0.36744;0;0;0;0;0;0;0;0;0;0;0;0;0
213;0.15331;0.0091223;-0.0097105;0.36779;0;0;0;0;0;0;0;0;0;0;0;0;0
214;0.15439;0.0091944;-0.0097933;0.36817;0;0;0;0;0;0;0;0;0;0;0;0;0
215;0.15568;0.0093094;-0.0098401;0.36855;0;0;0;0;0;0;0;0;0;0;0;0;0
216;0.1568;0.009418;-0.0098528;0.36889;0;0;0;0;0;0;0;0;0;0;0;0;0
217;0.15797;0.0095268;-0.0099255;0.36925;0;0;0;0;0;0;0;0;0;0;0;0;0
218;0.15921;0.0096695;-0.0099962;0.36964;0;0;0;0;0;0;0;0;0;0;0;0;0
219;0.16032;0.0097467;-0.010039;0.37001;0;0;0;0;0;0;0;0;0;0;0;0;0
220;0.16179;0.0098794;-0.010059;0.37038;0;0;0;0;0;0;0;0;0;0;0;0;0
221;0.16259;0.0099624;-0.01014;0.37073;0;0;0;0;0;0;0;0;0;0;0;0;0
222;0.16384;0.010024;-0.01027;0.37105;0;0;0;0;0;0;0;0;0;0;0;0;0
223;0.16487;0.010152;-0.010344;0.37136;0;0;0;0;0;0;0;0;0;0;0;0;0
224;0.16623;0.010314;-0.010428;0.37168;0;0;0;0;0;0;0;0;0;0;0;0;0
225;0.16728;0.010406;-0.010477;0.37202;0;0;0;0;0;0;0;0;0;0;0;0;0
226;0.16844;0.010473;-0.010477;0.37236;0;0;0;0;0;0;0;0;0;0;0;0;0
227;0.16969;0.010635;-0.010548;0.37268;0;0;0;0;0;0;0;0;0;0;0;0;0
228;0.1709;0.010781;-0.010573;0.37302;0;0;0;0;0;0;0;0;0;0;0;0;0
229;0.172;0.010832;-0.010561;0.37334;0;0;0;0;0;0;0;0;0;0;0;0;0
230;0.17321;0.010985;-0.010666;0.37366;0;0;0;0;0;0;0;0;0;0;0;0;0
231;0.17448;0.011061;-0.010737;0.37396;0;0;0;0;0;0;0;0;0;0;0;0;0
232;0.17568;0.011235;-0.010753;0.37428;0;0;0;0;0;0;0;0;0;0;0;0;0
233;0.17679;0.011368;-0.010848;0.37457;0;0;0;0;0;0;0;0;0;0;0;0;0
234;0.17815;0.011399;-0.0109;0.37485;0;0;0;0;0;0;0;0;0;0;0;0;0
235;0.17941;0.011562;-0.010945;0.37516;0;0;0;0;0;0;0;0;0;0;0;0;0
236;0.1804;0.011679;-0.011079;0.37543;0;0;0;0;0;0;0;0;0;0;0;0;0
237;0.18129;0.011834;-0.011143;0.37572;0;0;0;0;0;0;0;0;0;0;0;0;0
238;0.18272;0.011975;-0.011186;0.37601;0;0;0;0;0;0;0;0;0;0;0;0;0
239;0.18353;0.011966;-0.011242;0.37628;0;0;0;0;0;0;0;0;0;0;0;0;0
240;0.18505;0.012156;-0.01131;0.37658;0;0;0;0;0;0;0;0;0;0;0;0;0
241;0.18648;0.012315;-0.011388;0.37687;0;0;0;0;0;0;0;0;0;0;0;0;0
242;0.18742;0.012369;-0.011456;0.37714;0;0;0;0;0;0;0;0;0;0;0;0;0
243;0.18848;0.012442;-0.01148;0.37742;0;0;0;0;0;0;0;0;0;0;0;0;0
244;0.1898;0.012597;-0.011561;0.37765;0;0;0;0;0;0;0;0;0;0;0;0;0
245;0.19097;0.012732;-0.011651;0.37789;0;0;0;0;0;0;0;0;0;0;0;0;0
246;0.19244;0.01293;-0.011697;0.37814;0;0;0;0;0;0;0;0;0;0;0;0;0
247;0.19338;0.013007;-0.011744;0.37837;0;0;0;0;0;0;0;0;0;0;0;0;0
248;0.19455;0.013133;-0.011807;0.37859;0;0;0;0;0;0;0;0;0;0;0;0;0
249;0.19574;0.013339;-0.011877;0.37884;0;0;0;0;0;0;0;0;0;0;0;0;0
250;0.19689;0.013516;-0.011941;0.37908;0;0;0;0;0;0;0;0;0;0;0;0;0
251;0.19822;0.013621;-0.012035;0.37937;0;0;0;0;0;0;0;0;0;0;0;0;0
252;0.19928;0.013796;-0.012052;0.37964;0;0;0;0;0;0;0;0;0;0;0;0;0
253;0.20012;0.013922;-0.012091;0.37988;0;0;0;0;0;0;0;0;0;0;0;0;0
254;0.2016;0.014141;-0.012116;0.38012;0;0;0;0;0;0;0;0;0;0;0;0;0
255;0.20287;0.014236;-0.012146;0.38034;0;0;0;0;0;0;0;0;0;0;0;0;0
256;0.20401;0.014376;-0.012261;0.38058;0;0;0;0;0;0;0;0;0;0;0;0;0
257;0.20537;0.01456;-0.012287;0.38084;0;0;0;0;0;0;0;0;0;0;0;0;0
258;0.20652;0.014702;-0.012357;0.38106;0;0;0;0;0;0;0;0;0;0;0;0;0
259;0.20766;0.014836;-0.012343;0.3813;0;0;0;0;0;0;0;0;0;0;0;0;0
260;0.20886;0.014956;-0.012434;0.3815;0;0;0;0;0;0;0;0;0;0;0;0;0
261;0.21005;0.015092;-0.012442;0.38173;0;0;0;0;0;0;0;0;0;0;0;0;0
262;0.21127;0.015173;-0.012541;0.38195;0;0;0;0;0;0;0;0;0;0;0;0;0
263;0.21254;0.015396;-0.012626;0.38218;0;0;0;0;0;0;0;0;0;0;0;0;0
264;0.2136;0.015534;-0.012658;0.38241;0;0;0;0;0;0;0;0;0;0;0;0;0
265;0.21498;0.015685;-0.012743;0.38262;0;0;0;0;0;0;0;0;0;0;0;0;0
266;0.21605;0.01576;-0.012791;0.38284;0;0;0;0;0;0;0;0;0;0;0;0;0
267;0.2173;0.015933;-0.012898;0.38304;0;0;0;0;0;0;0;0;0;0;0;0;0
268;0.21863;0.01611;-0.013006;0.38323;0;0;0;0;0;0;0;0;0;0;0;0;0
269;0.21982;0.016186;-0.01305;0.38341;0;0;0;0;0;0;0;0;0;0;0;0;0
270;0.22094;0.016334;-0.013152;0.38362;0;0;0;0;0;0;0;0;0;0;0;0;0
271;0.22217;0.016495;-0.01327;0.38384;0;0;0;0;0;0;0;0;0;0;0;0;0
272;0.22365;0.016719;-0.013318;0.38408;0;0;0;0;0;0;0;0;0;0;0;0;0
273;0.22459;0.016799;-0.01344;0.3843;0;0;0;0;0;0;0;0;0;0;0;0;0
274;0.22583;0.016906;-0.013586;0.38449;0;0;0;0;0;0;0;0;0;0;0;0;0
275;0.22697;0.017086;-0.01362;0.38466;0;0;0;0;0;0;0;0;0;0;0;0;0
276;0.22827;0.017255;-0.013722;0.38483;0;0;0;0;0;0;0;0;0;0;0;0;0
277;0.22956;0.017371;-0.013816;0.38502;0;0;0;0;0;0;0;0;0;0;0;0;0
278;0.23075;0.017516;-0.013894;0.38522;0;0;0;0;0;0;0;0;0;0;0;0;0
279;0.232;0.017728;-0.013985;0.3854;0;0;0;0;0;0;0;0;0;0;0;0;0
280;0.23316;0.017898;-0.01408;0.3856;0;0;0;0;0;0;0;0;0;0;0;0;0
281;0.2343;0.018008;-0.014183;0.38577;0;0;0;0;0;0;0;0;0;0;0;0;0
282;0.2356;0.018138;-0.014283;0.38594;0;0;0;0;0;0;0;0;0;0;0;0;0
283;0.23687;0.018275;-0.014398;0.38611;0;0;0;0;0;0;0;0;0;0;0;0;0
284;0.23777;0.018422;-0.014505;0.38629;0;0;0;0;0;0;0;0;0;0;0;0;0
285;0.23916;0.018587;-0.014535;0.38646;0;0;0;0;0;0;0;0;0;0;0;0;0
286;0.24022;0.018723;-0.014662;0.38662;0;0;0;0;0;0;0;0;0;0;0;0;0
287;0.24177;0.018896;-0.014754;0.38678;0;0;0;0;0;0;0;0;0;0;0;0;0
288;0.24297;0.019066;-0.014876;0.38693;0;0;0;0;0;0;0;0;0;0;0;0;0
289;0.244;0.019242;-0.014942;0.38709;0;0;0;0;0;0;0;0;0;0;0;0;0
290;0.24514;0.019443;-0.015039;0.38724;0;0;0;0;0;0;0;0;0;0;0;0;0
291;0.24625;0.019529;-0.015165;0.38738;0;0;0;0;0;0;0;0;0;0;0;0;0
292;0.24775;0.019739;-0.015181;0.38753;0;0;0;0;0;0;0;0;0;0;0;0;0
293;0.249;0.019866;-0.015405;0.38767;0;0;0;0;0;0;0;0;0;0;0;0;0
294;0.25026;0.020071;-0.015485;0.38783;0;0;0;0;0;0;0;0;0;0;0;0;0
295;0.25144;0.02025;-0.015562;0.38796;0;0;0;0;0;0;0;0;0;0;0;0;0
296;0.25278;0.020402;-0.015626;0.3881;0;0;0;0;0;0;0;0;0;0;0;0;0
297;0.25404;0.020553;-0.015754;0.38826;0;0;0;0;0;0;0;0;0;0;0;0;0
298;0.25535;0.020754;-0.015814;0.38841;0;0;0;0;0;0;0;0;0;0;0;0;0
299;0.25671;0.020926;-0.015964;0.38857;0;0;0;0;0;0;0;0;0;0;0;0;0
300;0.25766;0.021101;-0.016085;0.38874;0;0;0;0;0;0;0;0;0;0;0;0;0
301;0.259;0.021301;-0.016199;0.38887;0;0;0;0;0;0;0;0;0;0;0;0;0
302;0.25997;0.021494;-0.016287;0.389;0;0;0;0;0;0;0;0;0;0;0;0;0
303;0.26121;0.021679;-0.016317;0.38912;0;0;0;0;0;0;0;0;0;0;0;0;0
304;0.26278;0.021879;-0.016471;0.38923;0;0;0;0;0;0;0;0;0;0;0;0;0
305;0.26384;0.022066;-0.016593;0.38932;0;0;0;0;0;0;0;0;0;0;0;0;0
306;0.265;0.022279;-0.016704;0.38944;0;0;0;0;0;0;0;0;0;0;0;0;0
307;0.2662;0.022503;-0.016823;0.38955;0;0;0;0;0;0;0;0;0;0;0;0;0
308;0.26747;0.022709;-0.016877;0.38967;0;0;0;0;0;0;0;0;0;0;0;0;0
309;0.26877;0.022888;-0.017015;0.3898;0;0;0;0;0;0;0;0;0;0;0;0;0
310;0.2699;0.023158;-0.017133;0.3899;0;0;0;0;0;0;0;0;0;0;0;0;0
311;0.27125;0.023371;-0.017229;0.39;0;0;0;0;0;0;0;0;0;0;0;0;0
312;0.27252;0.023579;-0.017321;0.39011;0;0;0;0;0;0;0;0;0;0;0;0;0
313;0.27359;0.023793;-0.01746;0.39021;0;0;0;0;0;0;0;0;0;0;0;0;0
314;0.27486;0.02403;-0.017567;0.3903;0;0;0;0;0;0;0;0;0;0;0;0;0
315;0.27626;0.02425;-0.017685;0.3904;0;0;0;0;0;0;0;0;0;0;0;0;0
316;0.2774;0.024469;-0.017839;0.39049;0;0;0;0;0;0;0;0;0;0;0;0;0
317;0.27871;0.024736;-0.017958;0.39058;0;0;0;0;0;0;0;0;0;0;0;0;0
318;0.27994;0.024885;-0.018123;0.39069;0;0;0;0;0;0;0;0;0;0;0;0;0
319;0.28122;0.025163;-0.01822;0.39079;0;0;0;0;0;0;0;0;0;0;0;0;0
320;0.28251;0.025342;-0.018371;0.39091;0;0;0;0;0;0;0;0;0;0;0;0;0
321;0.28371;0.025553;-0.018465;0.39104;0;0;0;0;0;0;0;0;0;0;0;0;0
322;0.28502;0.0258;-0.018587;0.39114;0;0;0;0;0;0;0;0;0;0;0;0;0
323;0.28627;0.025992;-0.018725;0.39124;0;0;0;0;0;0;0;0;0;0;0;0;0
324;0.2874;0.026214;-0.018874;0.39132;0;0;0;0;0;0;0;0;0;0;0;0;0
325;0.28862;0.026446;-0.019003;0.3914;0;0;0;0;0;0;0;0;0;0;0;0;0
326;0.29002;0.026664;-0.019125;0.39149;0;0;0;0;0;0;0;0;0;0;0;0;0
327;0.29137;0.026887;-0.019196;0.39157;0;0;0;0;0;0;0;0;0;0;0;0;0
328;0.29313;0.027064;-0.019291;0.39166;0;0;0;0;0;0;0;0;0;0;0;0;0
329;0.29368;0.027295;-0.019451;0.39173;0;0;0;0;0;0;0;0;0;0;0;0;0
330;0.29486;0.027521;-0.019503;0.39179;0;0;0;0;0;0;0;0;0;0;0;0;0
331;0.29614;0.027691;-0.019631;0.39186;0;0;0;0;0;0;0;0;0;0;0;0;0
332;0.29746;0.02791;-0.019759;0.39193;0;0;0;0;0;0;0;0;0;0;0;0;0
333;0.29864;0.028128;-0.01984;0.392;0;0;0;0;0;0;0;0;0;0;0;0;0
334;0.29996;0.028384;-0.019935;0.39206;0;0;0;0;0;0;0;0;0;0;0;0;0
335;0.30123;0.028557;-0.020136;0.39212;0;0;0;0;0;0;0;0;0;0;0;0;0
336;0.30238;0.028755;-0.020139;0.39221;0;0;0;0;0;0;0;0;0;0;0;0;0
337;0.30363;0.028962;-0.020256;0.39227;0;0;0;0;0;0;0;0;0;0;0;0;0
338;0.30501;0.02925;-0.020392;0.39233;0;0;0;0;0;0;0;0;0;0;0;0;0
339;0.30599;0.029463;-0.020533;0.39239;0;0;0;0;0;0;0;0;0;0;0;0;0
340;0.30744;0.029709;-0.020671;0.39244;0;0;0;0;0;0;0;0;0;0;0;0;0
341;0.3087;0.029939;-0.02075;0.39248;0;0;0;0;0;0;0;0;0;0;0;0;0
342;0.30993;0.030164;-0.020885;0.39253;0;0;0;0;0;0;0;0;0;0;0;0;0
343;0.31123;0.030463;-0.020969;0.39257;0;0;0;0;0;0;0;0;0;0;0;0;0
344;0.31264;0.030651;-0.021071;0.39262;0;0;0;0;0;0;0;0;0;0;0;0;0
345;0.31367;0.030844;-0.02121;0.39267;0;0;0;0;0;0;0;0;0;0;0;0;0
346;0.31494;0.031131;-0.021338;0.39273;0;0;0;0;0;0;0;0;0;0;0;0;0
347;0.31625;0.031332;-0.021462;0.39277;0;0;0;0;0;0;0;0;0;0;0;0;0
348;0.31753;0.031557;-0.021582;0.39282;0;0;0;0;0;0;0;0;0;0;0;0;0
349;0.31878;0.031861;-0.021643;0.39286;0;0;0;0;0;0;0;0;0;0;0;0;0
350;0.32016;0.032033;-0.021779;0.39292;0;0;0;0;0;0;0;0;0;0;0;0;0
351;0.32138;0.032298;-0.02183;0.39297;0;0;0;0;0;0;0;0;0;0;0;0;0
352;0.32228;0.032538;-0.02194;0.393;0;0;0;0;0;0;0;0;0;0;0;0;0
353;0.32382;0.032861;-0.022046;0.39304;0;0;0;0;0;0;0;0;0;0;0;0;0
354;0.32499;0.033019;-0.022184;0.39305;0;0;0;0;0;0;0;0;0;0;0;0;0
355;0.32636;0.033364;-0.022361;0.39309;0;0;0;0;0;0;0;0;0;0;0;0;0
356;0.32757;0.033564;-0.022467;0.39312;0;0;0;0;0;0;0;0;0;0;0;0;0
357;0.32877;0.033785;-0.022638;0.39314;0;0;0;0;0;0;0;0;0;0;0;0;0
358;0.33004;0.034063;-0.022735;0.39316;0;0;0;0;0;0;0;0;0;0;0;0;0
359;0.33129;0.034373;-0.022881;0.39316;0;0;0;0;0;0;0;0;0;0;0;0;0
360;0.33251;0.034618;-0.023028;0.39317;0;0;0;0;0;0;0;0;0;0;0;0;0
361;0.33382;0.034861;-0.02317;0.39318;0;0;0;0;0;0;0;0;0;0;0;0;0
362;0.33504;0.035102;-0.023335;0.3932;0;0;0;0;0;0;0;0;0;0;0;0;0
363;0.3363;0.035307;-0.023505;0.39319;0;0;0;0;0;0;0;0;0;0;0;0;0
364;0.33749;0.035609;-0.023585;0.39321;0;0;0;0;0;0;0;0;0;0;0;0;0
365;0.33873;0.035911;-0.02378;0.39322;0;0;0;0;0;0;0;0;0;0;0;0;0
366;0.34005;0.036134;-0.023926;0.39323;0;0;0;0;0;0;0;0;0;0;0;0;0
367;0.34134;0.036409;-0.024014;0.39329;0;0;0;0;0;0;0;0;0;0;0;0;0
368;0.34263;0.036655;-0.024165;0.39332;0;0;0;0;0;0;0;0;0;0;0;0;0
369;0.34382;0.036932;-0.024252;0.39335;0;0;0;0;0;0;0;0;0;0;0;0;0
370;0.34515;0.037284;-0.024429;0.39337;0;0;0;0;0;0;0;0;0;0;0;0;0
371;0.3465;0.037507;-0.024606;0.39336;0;0;0;0;0;0;0;0;0;0;0;0;0
372;0.34764;0.037823;-0.024654;0.39335;0;0;0;0;0;0;0;0;0;0;0;0;0
373;0.3489;0.038023;-0.02477;0.39334;0;0;0;0;0;0;0;0;0;0;0;0;0
374;0.35015;0.03835;-0.024971;0.39333;0;0;0;0;0;0;0;0;0;0;0;0;0
375;0.35148;0.038644;-0.025125;0.39335;0;0;0;0;0;0;0;0;0;0;0;0;0
376;0.35262;0.038999;-0.025194;0.39336;0;0;0;0;0;0;0;0;0;0;0;0;0
377;0.35393;0.039249;-0.025381;0.39335;0;0;0;0;0;0;0;0;0;0;0;0;0
378;0.35524;0.039506;-0.0255;0.39333;0;0;0;0;0;0;0;0;0;0;0;0;0
379;0.35652;0.039843;-0.025564;0.39333;0;0;0;0;0;0;0;0;0;0;0;0;0
380;0.35778;0.040139;-0.025734;0.39331;0;0;0;0;0;0;0;0;0;0;0;0;0
381;0.35906;0.040464;-0.02587;0.39331;0;0;0;0;0;0;0;0;0;0;0;0;0
382;0.36032;0.040756;-0.025983;0.39332;0;0;0;0;0;0;0;0;0;0;0;0;0
383;0.36153;0.041058;-0.026153;0.39331;0;0;0;0;0;0;0;0;0;0;0;0;0
384;0.36283;0.041321;-0.026286;0.3933;0;0;0;0;0;0;0;0;0;0;0;0;0
385;0.36362;0.041653;-0.02641;0.39329;0;0;0;0;0;0;0;0;0;0;0;0;0
386;0.36521;0.041969;-0.026606;0.39328;0;0;0;0;0;0;0;0;0;0;0;0;0
387;0.36668;0.042251;-0.026745;0.39327;0;0;0;0;0;0;0;0;0;0;0;0;0
388;0.36807;0.042607;-0.026893;0.39326;0;0;0;0;0;0;0;0;0;0;0;0;0
389;0.36938;0.042926;-0.027064;0.39325;0;0;0;0;0;0;0;0;0;0;0;0;0
390;0.3705;0.04321;-0.027221;0.39323;0;0;0;0;0;0;0;0;0;0;0;0;0
391;0.37179;0.043561;-0.02732;0.39322;0;0;0;0;0;0;0;0;0;0;0;0;0
392;0.37305;0.043917;-0.027498;0.39321;0;0;0;0;0;0;0;0;0;0;0;0;0
393;0.37439;0.044255;-0.02759;0.39321;0;0;0;0;0;0;0;0;0;0;0;0;0
394;0.37561;0.044678;-0.027744;0.3932;0;0;0;0;0;0;0;0;0;0;0;0;0
395;0.37666;0.044998;-0.027937;0.39318;0;0;0;0;0;0;0;0;0;0;0;0;0
396;0.37817;0.045373;-0.028035;0.39317;0;0;0;0;0;0;0;0;0;0;0;0;0
397;0.3795;0.04572;-0.028195;0.39316;0;0;0;0;0;0;0;0;0;0;0;0;0
398;0.38077;0.046083;-0.028308;0.39315;0;0;0;0;0;0;0;0;0;0;0;0;0
399;0.38199;0.046452;-0.028564;0.39314;0;0;0;0;0;0;0;0;0;0;0;0;0
400;0.38358;0.046783;-0.028659;0.39313;0;0;0;0;0;0;0;0;0;0;0;0;0
401;0.38457;0.047155;-0.028893;0.39311;0;0;0;0;0;0;0;0;0;0;0;0;0
402;0.38581;0.047464;-0.029112;0.39309;0;0;0;0;0;0;0;0;0;0;0;0;0
403;0.38715;0.047812;-0.029229;0.39307;0;0;0;0;0;0;0;0;0;0;0;0;0
404;0.38839;0.048184;-0.029528;0.39305;0;0;0;0;0;0;0;0;0;0;0;0;0
405;0.38958;0.048507;-0.029581;0.39304;0;0;0;0;0;0;0;0;0;0;0;0;0
406;0.39081;0.048863;-0.02977;0.39302;0;0;0;0;0;0;0;0;0;0;0;0;0
407;0.39253;0.049306;-0.029936;0.393;0;0;0;0;0;0;0;0;0;0;0;0;0
408;0.3934;0.049639;-0.030108;0.39299;0;0;0;0;0;0;0;0;0;0;0;0;0
409;0.39484;0.05011;-0.030264;0.39297;0;0;0;0;0;0;0;0;0;0;0;0;0
410;0.39599;0.050449;-0.030382;0.39295;0;0;0;0;0;0;0;0;0;0;0;0;0
411;0.39745;0.050824;-0.030492;0.39294;0;0;0;0;0;0;0;0;0;0;0;0;0
412;0.39844;0.051298;-0.030707;0.39292;0;0;0;0;0;0;0;0;0;0;0;0;0
413;0.39999;0.051726;-0.030793;0.3929;0;0;0;0;0;0;0;0;0;0;0;0;0
414;0.40073;0.052153;-0.030977;0.39289;0;0;0;0;0;0;0;0;0;0;0;0;0
415;0.40242;0.052625;-0.031073;0.39287;0;0;0;0;0;0;0;0;0;0;0;0;0
416;0.40371;0.053091;-0.031207;0.39285;0;0;0;0;0;0;0;0;0;0;0;0;0
417;0.40514;0.053513;-0.031292;0.39284;0;0;0;0;0;0;0;0;0;0;0;0;0
418;0.40641;0.054062;-0.031453;0.39281;0;0;0;0;0;0;0;0;0;0;0;0;0
419;0.40783;0.054538;-0.031563;0.39279;0;0;0;0;0;0;0;0;0;0;0;0;0
420;0.40897;0.055031;-0.031682;0.39276;0;0;0;0;0;0;0;0;0;0;0;0;0
421;0.41021;0.055503;-0.03181;0.39274;0;0;0;0;0;0;0;0;0;0;0;0;0
422;0.41146;0.055976;-0.03187;0.39273;0;0;0;0;0;0;0;0;0;0;0;0;0
423;0.41293;0.056502;-0.031959;0.3927;0;0;0;0;0;0;0;0;0;0;0;0;0
424;0.41412;0.057;-0.032136;0.39268;0;0;0;0;0;0;0;0;0;0;0;0;0
425;0.41548;0.057413;-0.032323;0.39267;0;0;0;0;0;0;0;0;0;0;0;0;0
426;0.4168;0.057893;-0.0325;0.39264;0;0;0;0;0;0;0;0;0;0;0;0;0
427;0.41809;0.058362;-0.032671;0.39262;0;0;0;0;0;0;0;0;0;0;0;0;0
428;0.41942;0.058813;-0.032825;0.39258;0;0;0;0;0;0;0;0;0;0;0;0;0
429;0.42065;0.059221;-0.032986;0.39254;0;0;0;0;0;0;0;0;0;0;0;0;0
430;0.42182;0.05964;-0.033154;0.39251;0;0;0;0;0;0;0;0;0;0;0;0;0
431;0.42334;0.060155;-0.03338;0.39248;0;0;0;0;0;0;0;0;0;0;0;0;0
432;0.42463;0.060597;-0.033553;0.39246;0;0;0;0;0;0;0;0;0;0;0;0;0
433;0.42625;0.061123;-0.03376;0.39245;0;0;0;0;0;0;0;0;0;0;0;0;0
434;0.42716;0.061612;-0.033849;0.39243;0;0;0;0;0;0;0;0;0;0;0;0;0
435;0.42849;0.062079;-0.033986;0.39241;0;0;0;0;0;0;0;0;0;0;0;0;0
436;0.42984;0.062522;-0.034183;0.39237;0;0;0;0;0;0;0;0;0;0;0;0;0
437;0.43106;0.063084;-0.034362;0.39232;0;0;0;0;0;0;0;0;0;0;0;0;0
438;0.43238;0.06362;-0.034466;0.39226;0;0;0;0;0;0;0;0;0;0;0;0;0
439;0.43344;0.064119;-0.034703;0.39222;0;0;0;0;0;0;0;0;0;0;0;0;0
440;0.43536;0.064639;-0.034897;0.39216;0;0;0;0;0;0;0;0;0;0;0;0;0
441;0.4364;0.065088;-0.03505;0.39213;0;0;0;0;0;0;0;0;0;0;0;0;0
442;0.4373;0.065573;-0.035214;0.39207;0;0;0;0;0;0;0;0;0;0;0;0;0
443;0.43892;0.066137;-0.035429;0.39202;0;0;0;0;0;0;0;0;0;0;0;0;0
444;0.44031;0.066681;-0.035716;0.39196;0;0;0;0;0;0;0;0;0;0;0;0;0
445;0.44125;0.067099;-0.0359;0.39192;0;0;0;0;0;0;0;0;0;0;0;0;0
446;0.44296;0.067693;-0.036026;0.39187;0;0;0;0;0;0;0;0;0;0;0;0;0
447;0.44418;0.068199;-0.036234;0.39182;0;0;0;0;0;0;0;0;0;0;0;0;0
448;0.44603;0.068781;-0.036376;0.39177;0;0;0;0;0;0;0;0;0;0;0;0;0
449;0.44672;0.06935;-0.036597;0.3917;0;0;0;0;0;0;0;0;0;0;0;0;0
450;0.4481;0.069949;-0.036691;0.39162;0;0;0;0;0;0;0;0;0;0;0;0;0
451;0.4496;0.070586;-0.036836;0.39155;0;0;0;0;0;0;0;0;0;0;0;0;0
452;0.45076;0.071225;-0.036896;0.39147;0;0;0;0;0;0;0;0;0;0;0;0;0
453;0.45215;0.07183;-0.037148;0.39138;0;0;0;0;0;0;0;0;0;0;0;0;0
454;0.45344;0.072408;-0.037324;0.39128;0;0;0;0;0;0;0;0;0;0;0;0;0
455;0.45489;0.073023;-0.037496;0.39116;0;0;0;0;0;0;0;0;0;0;0;0;0
456;0.45715;0.073624;-0.03767;0.39102;0;0;0;0;0;0;0;0;0;0;0;0;0
457;0.45756;0.074206;-0.037805;0.39086;0;0;0;0;0;0;0;0;0;0;0;0;0
458;0.45885;0.07477;-0.037984;0.39071;0;0;0;0;0;0;0;0;0;0;0;0;0
459;0.46031;0.075335;-0.038148;0.39055;0;0;0;0;0;0;0;0;0;0;0;0;0
460;0.46154;0.075942;-0.038232;0.3904;0;0;0;0;0;0;0;0;0;0;0;0;0
461;0.46314;0.07654;-0.03843;0.39023;0;0;0;0;0;0;0;0;0;0;0;0;0
462;0.46436;0.077172;-0.038549;0.39007;0;0;0;0;0;0;0;0;0;0;0;0;0
463;0.46584;0.077781;-0.038671;0.38987;0;0;0;0;0;0;0;0;0;0;0;0;0
464;0.46722;0.078446;-0.038792;0.38968;0;0;0;0;0;0;0;0;0;0;0;0;0
465;0.46853;0.07905;-0.038908;0.38946;0;0;0;0;0;0;0;0;0;0;0;0;0
466;0.4701;0.079759;-0.039003;0.38925;0;0;0;0;0;0;0;0;0;0;0;0;0
467;0.47134;0.080425;-0.03904;0.38901;0;0;0;0;0;0;0;0;0;0;0;0;0
468;0.4727;0.081142;-0.039082;0.38877;0;0;0;0;0;0;0;0;0;0;0;0;0
469;0.4741;0.081748;-0.039225;0.38851;0;0;0;0;0;0;0;0;0;0;0;0;0
470;0.47552;0.082423;-0.039315;0.38824;0;0;0;0;0;0;0;0;0;0;0;0;0
471;0.47682;0.08314;-0.039499;0.38797;0;0;0;0;0;0;0;0;0;0;0;0;0
472;0.47816;0.083895;-0.039593;0.38767;0;0;0;0;0;0;0;0;0;0;0;0;0
473;0.47963;0.084686;-0.039811;0.38737;0;0;0;0;0;0;0;0;0;0;0;0;0
474;0.48074;0.085497;-0.039866;0.38701;0;0;0;0;0;0;0;0;0;0;0;0;0
475;0.48236;0.086322;-0.040082;0.38668;0;0;0;0;0;0;0;0;0;0;0;0;0
476;0.48359;0.087046;-0.040136;0.38632;0;0;0;0;0;0;0;0;0;0;0;0;0
477;0.48505;0.08785;-0.040311;0.38594;0;0;0;0;0;0;0;0;0;0;0;0;0
478;0.48638;0.088644;-0.04032;0.38556;0;0;0;0;0;0;0;0;0;0;0;0;0
479;0.48782;0.089432;-0.040593;0.38517;0;0;0;0;0;0;0;0;0;0;0;0;0
480;0.48909;0.090245;-0.04063;0.38479;0;0;0;0;0;0;0;0;0;0;0;0;0
481;0.49052;0.090972;-0.040643;0.38439;0;0;0;0;0;0;0;0;0;0;0;0;0
482;0.49173;0.09167;-0.040795;0.38397;0;0;0;0;0;0;0;0;0;0;0;0;0
483;0.4931;0.092305;-0.040823;0.38355;0;0;0;0;0;0;0;0;0;0;0;0;0
484;0.49443;0.093026;-0.040922;0.3831;0;0;0;0;0;0;0;0;0;0;0;0;0
485;0.49576;0.093716;-0.040934;0.38261;0;0;0;0;0;0;0;0;0;0;0;0;0
486;0.49715;0.094395;-0.041109;0.38217;0;0;0;0;0;0;0;0;0;0;0;0;0
487;0.49858;0.095159;-0.041119;0.38166;0;0;0;0;0;0;0;0;0;0;0;0;0
488;0.49973;0.095998;-0.041244;0.3812;0;0;0;0;0;0;0;0;0;0;0;0;0
489;0.50103;0.096699;-0.041413;0.38071;0;0;0;0;0;0;0;0;0;0;0;0;0
490;0.50251;0.097509;-0.041409;0.38021;0;0;0;0;0;0;0;0;0;0;0;0;0
491;0.50358;0.098282;-0.041487;0.3797;0;0;0;0;0;0;0;0;0;0;0;0;0
492;0.50515;0.099102;-0.041634;0.37918;0;0;0;0;0;0;0;0;0;0;0;0;0
493;0.50666;0.09992;-0.0417;0.37864;0;0;0;0;0;0;0;0;0;0;0;0;0
494;0.50784;0.10069;-0.041722;0.37808;0;0;0;0;0;0;0;0;0;0;0;0;0
495;0.50901;0.1014;-0.041794;0.37753;0;0;0;0;0;0;0;0;0;0;0;0;0
496;0.50989;0.10214;-0.041887;0.37695;0;0;0;0;0;0;0;0;0;0;0;0;0
497;0.51213;0.10288;-0.041919;0.37637;0;0;0;0;0;0;0;0;0;0;0;0;0
498;0.51307;0.10364;-0.041928;0.37578;0;0;0;0;0;0;0;0;0;0;0;0;0
499;0.51467;0.10445;-0.041983;0.37516;0;0;0;0;0;0;0;0;0;0;0;0;0
500;0.51598;0.10513;-0.042035;0.37453;0;0;0;0;0;0;0;0;0;0;0;0;0
501;0.51715;0.10602;-0.042081;0.37392;0;0;0;0;0;0;0;0;0;0;0;0;0
502;0.51864;0.10686;-0.042086;0.37327;0;0;0;0;0;0;0;0;0;0;0;0;0
503;0.51991;0.10777;-0.042136;0.37261;0;0;0;0;0;0;0;0;0;0;0;0;0
504;0.52121;0.10859;-0.042159;0.3719;0;0;0;0;0;0;0;0;0;0;0;0;0
505;0.52263;0.10937;-0.042176;0.37124;0;0;0;0;0;0;0;0;0;0;0;0;0
506;0.52389;0.1102;-0.042162;0.37053;0;0;0;0;0;0;0;0;0;0;0;0;0
507;0.52525;0.11091;-0.0422;0.36982;0;0;0;0;0;0;0;0;0;0;0;0;0
508;0.52674;0.11159;-0.042093;0.3691;0;0;0;0;0;0;0;0;0;0;0;0;0
509;0.52881;0.11233;-0.042075;0.36835;0;0;0;0;0;0;0;0;0;0;0;0;0
510;0.52941;0.11304;-0.042119;0.36757;0;0;0;0;0;0;0;0;0;0;0;0;0
511;0.53055;0.1138;-0.042074;0.36682;0;0;0;0;0;0;0;0;0;0;0;0;0
512;0.53212;0.11464;-0.042067;0.36602;0;0;0;0;0;0;0;0;0;0;0;0;0
513;0.53343;0.11557;-0.042074;0.36518;0;0;0;0;0;0;0;0;0;0;0;0;0
514;0.53567;0.1166;-0.04206;0.36437;0;0;0;0;0;0;0;0;0;0;0;0;0
515;0.53629;0.11724;-0.042001;0.36353;0;0;0;0;0;0;0;0;0;0;0;0;0
516;0.5376;0.11815;-0.041932;0.36266;0;0;0;0;0;0;0;0;0;0;0;0;0
517;0.53903;0.11901;-0.041979;0.36175;0;0;0;0;0;0;0;0;0;0;0;0;0
518;0.54049;0.11996;-0.041935;0.36081;0;0;0;0;0;0;0;0;0;0;0;0;0
519;0.54207;0.12089;-0.041959;0.35977;0;0;0;0;0;0;0;0;0;0;0;0;0
520;0.54341;0.12171;-0.041935;0.35879;0;0;0;0;0;0;0;0;0;0;0;0;0
521;0.54485;0.12257;-0.041861;0.35774;0;0;0;0;0;0;0;0;0;0;0;0;0
522;0.54629;0.12347;-0.041803;0.35669;0;0;0;0;0;0;0;0;0;0;0;0;0
523;0.54751;0.12428;-0.041773;0.35561;0;0;0;0;0;0;0;0;0;0;0;0;0
524;0.54914;0.12519;-0.041738;0.35451;0;0;0;0;0;0;0;0;0;0;0;0;0
525;0.55064;0.12602;-0.041624;0.35336;0;0;0;0;0;0;0;0;0;0;0;0;0
526;0.552;0.12681;-0.041666;0.35213;0;0;0;0;0;0;0;0;0;0;0;0;0
527;0.55343;0.12759;-0.041604;0.35095;0;0;0;0;0;0;0;0;0;0;0;0;0
528;0.555;0.12837;-0.041573;0.34973;0;0;0;0;0;0;0;0;0;0;0;0;0
529;0.55634;0.12914;-0.041529;0.34827;0;0;0;0;0;0;0;0;0;0;0;0;0
530;0.55783;0.12993;-0.041582;0.34694;0;0;0;0;0;0;0;0;0;0;0;0;0
531;0.55929;0.1308;-0.041593;0.34552;0;0;0;0;0;0;0;0;0;0;0;0;0
532;0.56094;0.13156;-0.041503;0.34403;0;0;0;0;0;0;0;0;0;0;0;0;0
533;0.56233;0.13226;-0.041521;0.34245;0;0;0;0;0;0;0;0;0;0;0;0;0
534;0.56388;0.1332;-0.041444;0.3408;0;0;0;0;0;0;0;0;0;0;0;0;0
535;0.56555;0.13404;-0.041599;0.33884;0;0;0;0;0;0;0;0;0;0;0;0;0
535.5;0.567;0.1351;-0.041552;0.33776;0;0;0;0;0;0;0;0;0;0;0;0;0