File: Template_Auto_Cali_large_DP600/_data/DP600Large_NT20_00_001_Front_DIC_File.txt
Date of Test;Material;Sample Geometry;Orientation [°];Test Number;Nominal Speed [mm/min];Thickness [mm];Central Width [mm];Gauge Width / Diameter [mm];Pixel to mm ratio [mm/px];Extensometer 1-4 [mm];Extensometer 2-3 [mm];Extensometer 5-6 [mm];;;;;
07/27/21;DP600Large;NT20;00;1;0.0798;0.29282;2;4;0;6;0.20002;0.4;;;;;
;;;;;;;;;;;;;;;;;
Time [s];U1 [mm];U2 [mm];U3 [mm];Force [kN];Ambient Temperature [°C];DIC Zone X 1 [px];DIC Zone Y 1 [px];DIC Zone X 2 [px];DIC Zone Y 2 [px];DIC Zone X 3 [px];DIC Zone Y 3 [px];DIC Zone X 4 [px];DIC Zone Y 4 [px];DIC Zone X 5 [px];DIC Zone Y 5 [px];DIC Zone X 6 [px];DIC Zone Y 6 [px]
0;0;0;0;-0.0001078;0;0;0;0;0;0;0;0;0;0;0;0;0
0.999;1.5923e-06;-2.9426e-05;-2.5425e-05;-8.82e-05;0;0;0;0;0;0;0;0;0;0;0;0;0
2;-4.5669e-05;-1.0287e-05;-2.0311e-06;-5.88e-05;0;0;0;0;0;0;0;0;0;0;0;0;0
3;-3.0497e-05;-5.8703e-05;-8.3772e-05;-9.8e-06;0;0;0;0;0;0;0;0;0;0;0;0;0
4;0.00011516;-6.3318e-05;-9.3626e-05;0.000392;0;0;0;0;0;0;0;0;0;0;0;0;0
5;0.00039494;-5.2895e-06;2.7339e-05;0.0024206;0;0;0;0;0;0;0;0;0;0;0;0;0
5.999;0.00047553;-2.0108e-05;-6.1427e-05;0.0068012;0;0;0;0;0;0;0;0;0;0;0;0;0
7;0.00055546;6.5167e-05;1.9752e-05;0.012328;0;0;0;0;0;0;0;0;0;0;0;0;0
8;0.00076311;9.2187e-05;3.2688e-05;0.018561;0;0;0;0;0;0;0;0;0;0;0;0;0
8.999;0.00096799;8.4325e-05;9.0204e-06;0.023961;0;0;0;0;0;0;0;0;0;0;0;0;0
10;0.0012967;7.0512e-05;-7.4736e-05;0.028224;0;0;0;0;0;0;0;0;0;0;0;0;0
11;0.0011704;0.00010749;-0.00013773;0.032075;0;0;0;0;0;0;0;0;0;0;0;0;0
11.999;0.0014593;9.5809e-05;-0.00012889;0.03575;0;0;0;0;0;0;0;0;0;0;0;0;0
13;0.0016109;0.00015673;-0.0001236;0.039367;0;0;0;0;0;0;0;0;0;0;0;0;0
14;0.0016234;0.00017884;-0.00011794;0.042816;0;0;0;0;0;0;0;0;0;0;0;0;0
15;0.001868;0.00017705;-0.00013498;0.04656;0;0;0;0;0;0;0;0;0;0;0;0;0
16;0.0019434;0.00019082;-0.00019124;0.050196;0;0;0;0;0;0;0;0;0;0;0;0;0
16.999;0.0019581;0.00015252;-0.00013675;0.053841;0;0;0;0;0;0;0;0;0;0;0;0;0
17.999;0.00232;0.00020908;-0.00017637;0.057497;0;0;0;0;0;0;0;0;0;0;0;0;0
19.002;0.0023574;0.00027122;-6.2868e-05;0.061142;0;0;0;0;0;0;0;0;0;0;0;0;0
19.999;0.0024496;0.00022001;-8.3084e-05;0.06467;0;0;0;0;0;0;0;0;0;0;0;0;0
20.999;0.0026028;0.0002666;-0.00012873;0.068502;0;0;0;0;0;0;0;0;0;0;0;0;0
22;0.0027495;0.00022994;-0.0001489;0.072206;0;0;0;0;0;0;0;0;0;0;0;0;0
23;0.0027415;0.0001922;-0.00015083;0.075901;0;0;0;0;0;0;0;0;0;0;0;0;0
24;0.0029911;0.0002784;-0.00012296;0.079576;0;0;0;0;0;0;0;0;0;0;0;0;0
24.999;0.0030418;0.00029925;-0.00016319;0.083075;0;0;0;0;0;0;0;0;0;0;0;0;0
25.999;0.0032752;0.00037047;-0.00019641;0.086838;0;0;0;0;0;0;0;0;0;0;0;0;0
27;0.0035056;0.00032368;-0.0001979;0.090297;0;0;0;0;0;0;0;0;0;0;0;0;0
27.999;0.0037166;0.00039019;-0.00016384;0.094041;0;0;0;0;0;0;0;0;0;0;0;0;0
29;0.0038187;0.00036781;-0.00019258;0.097608;0;0;0;0;0;0;0;0;0;0;0;0;0
29.999;0.0039793;0.00037897;-0.00021766;0.10115;0;0;0;0;0;0;0;0;0;0;0;0;0
31;0.0040849;0.00040298;-0.00031853;0.10464;0;0;0;0;0;0;0;0;0;0;0;0;0
32;0.0042777;0.00045924;-0.0003211;0.10811;0;0;0;0;0;0;0;0;0;0;0;0;0
33;0.0046098;0.0004718;-0.00029355;0.11157;0;0;0;0;0;0;0;0;0;0;0;0;0
34;0.0045479;0.00044913;-0.00036171;0.11505;0;0;0;0;0;0;0;0;0;0;0;0;0
34.999;0.0047644;0.00046733;-0.00040912;0.1184;0;0;0;0;0;0;0;0;0;0;0;0;0
36;0.004954;0.00053313;-0.00034092;0.12204;0;0;0;0;0;0;0;0;0;0;0;0;0
36.999;0.0049829;0.00053575;-0.00037965;0.12558;0;0;0;0;0;0;0;0;0;0;0;0;0
37.999;0.0054578;0.00053734;-0.00041726;0.12932;0;0;0;0;0;0;0;0;0;0;0;0;0
38.999;0.0055749;0.00054138;-0.00042833;0.13285;0;0;0;0;0;0;0;0;0;0;0;0;0
40;0.0057423;0.0005202;-0.00037985;0.13667;0;0;0;0;0;0;0;0;0;0;0;0;0
40.999;0.0055628;0.0005293;-0.00040859;0.14062;0;0;0;0;0;0;0;0;0;0;0;0;0
41.999;0.0060002;0.00054298;-0.00034356;0.14448;0;0;0;0;0;0;0;0;0;0;0;0;0
42.999;0.0062156;0.00060282;-0.00039614;0.14872;0;0;0;0;0;0;0;0;0;0;0;0;0
43.999;0.006771;0.0006297;-0.00039156;0.1527;0;0;0;0;0;0;0;0;0;0;0;0;0
44.999;0.0068086;0.00064262;-0.0003667;0.15701;0;0;0;0;0;0;0;0;0;0;0;0;0
45.999;0.0070029;0.00067685;-0.00041788;0.16118;0;0;0;0;0;0;0;0;0;0;0;0;0
46.999;0.0072062;0.00067465;-0.0004598;0.16535;0;0;0;0;0;0;0;0;0;0;0;0;0
48;0.0075121;0.00069809;-0.00048613;0.16944;0;0;0;0;0;0;0;0;0;0;0;0;0
48.999;0.0079252;0.00070411;-0.00046867;0.17337;0;0;0;0;0;0;0;0;0;0;0;0;0
49.999;0.008097;0.00081879;-0.00044366;0.17763;0;0;0;0;0;0;0;0;0;0;0;0;0
50.999;0.0084453;0.00080243;-0.00049338;0.18157;0;0;0;0;0;0;0;0;0;0;0;0;0
51.999;0.0088;0.00081954;-0.00051212;0.1859;0;0;0;0;0;0;0;0;0;0;0;0;0
52.999;0.0090262;0.00088491;-0.00059049;0.1899;0;0;0;0;0;0;0;0;0;0;0;0;0
53.999;0.009533;0.00088849;-0.00056548;0.19424;0;0;0;0;0;0;0;0;0;0;0;0;0
55;0.0098299;0.00091912;-0.00067346;0.19837;0;0;0;0;0;0;0;0;0;0;0;0;0
55.999;0.010341;0.0010698;-0.00064312;0.20242;0;0;0;0;0;0;0;0;0;0;0;0;0
56.999;0.010718;0.0011071;-0.00066926;0.20639;0;0;0;0;0;0;0;0;0;0;0;0;0
58;0.011136;0.0011084;-0.00081119;0.21029;0;0;0;0;0;0;0;0;0;0;0;0;0
58.999;0.0116;0.0011109;-0.00082563;0.21413;0;0;0;0;0;0;0;0;0;0;0;0;0
59.999;0.01218;0.0012224;-0.00092502;0.21792;0;0;0;0;0;0;0;0;0;0;0;0;0
60.999;0.012688;0.0012282;-0.00094432;0.22154;0;0;0;0;0;0;0;0;0;0;0;0;0
62;0.013235;0.0013372;-0.00094463;0.22539;0;0;0;0;0;0;0;0;0;0;0;0;0
62.999;0.013703;0.0014291;-0.0010017;0.22898;0;0;0;0;0;0;0;0;0;0;0;0;0
63.999;0.014428;0.0015855;-0.0010265;0.23249;0;0;0;0;0;0;0;0;0;0;0;0;0
65;0.015128;0.0016934;-0.0011159;0.23589;0;0;0;0;0;0;0;0;0;0;0;0;0
66;0.015774;0.0017599;-0.0011495;0.23904;0;0;0;0;0;0;0;0;0;0;0;0;0
66.999;0.016484;0.0018632;-0.0012278;0.24235;0;0;0;0;0;0;0;0;0;0;0;0;0
67.999;0.017118;0.0018757;-0.0013177;0.24539;0;0;0;0;0;0;0;0;0;0;0;0;0
68.999;0.017775;0.0019786;-0.0013497;0.24828;0;0;0;0;0;0;0;0;0;0;0;0;0
69.999;0.018525;0.0021617;-0.001462;0.25106;0;0;0;0;0;0;0;0;0;0;0;0;0
71;0.019347;0.0022056;-0.001554;0.25372;0;0;0;0;0;0;0;0;0;0;0;0;0
71.999;0.020028;0.0022213;-0.0016157;0.2562;0;0;0;0;0;0;0;0;0;0;0;0;0
73;0.020829;0.0023458;-0.0016816;0.25879;0;0;0;0;0;0;0;0;0;0;0;0;0
74;0.021751;0.0023691;-0.0017102;0.26109;0;0;0;0;0;0;0;0;0;0;0;0;0
74.999;0.022574;0.0025582;-0.0017315;0.26348;0;0;0;0;0;0;0;0;0;0;0;0;0
76;0.023442;0.0026535;-0.0018529;0.26562;0;0;0;0;0;0;0;0;0;0;0;0;0
76.999;0.024335;0.0026599;-0.0019365;0.26782;0;0;0;0;0;0;0;0;0;0;0;0;0
77.999;0.025113;0.0028239;-0.0020436;0.26978;0;0;0;0;0;0;0;0;0;0;0;0;0
78.999;0.026155;0.0028362;-0.0021061;0.27176;0;0;0;0;0;0;0;0;0;0;0;0;0
79.999;0.026913;0.002981;-0.0021467;0.27373;0;0;0;0;0;0;0;0;0;0;0;0;0
81;0.028061;0.0029868;-0.002245;0.2755;0;0;0;0;0;0;0;0;0;0;0;0;0
81.999;0.028871;0.0030261;-0.0022978;0.27737;0;0;0;0;0;0;0;0;0;0;0;0;0
83;0.029732;0.003135;-0.0024352;0.27904;0;0;0;0;0;0;0;0;0;0;0;0;0
83.999;0.030713;0.0032029;-0.0023885;0.28079;0;0;0;0;0;0;0;0;0;0;0;0;0
85;0.031706;0.0032479;-0.0025316;0.28244;0;0;0;0;0;0;0;0;0;0;0;0;0
85.999;0.032539;0.0032162;-0.0026828;0.28403;0;0;0;0;0;0;0;0;0;0;0;0;0
87;0.033508;0.0033661;-0.0026856;0.28559;0;0;0;0;0;0;0;0;0;0;0;0;0
88;0.034518;0.0033609;-0.0028239;0.28714;0;0;0;0;0;0;0;0;0;0;0;0;0
88.999;0.03548;0.0034562;-0.0029436;0.28858;0;0;0;0;0;0;0;0;0;0;0;0;0
89.999;0.036351;0.0035404;-0.0029785;0.29011;0;0;0;0;0;0;0;0;0;0;0;0;0
91;0.037354;0.0036222;-0.0031015;0.29151;0;0;0;0;0;0;0;0;0;0;0;0;0
91.999;0.038482;0.0035643;-0.0031351;0.293;0;0;0;0;0;0;0;0;0;0;0;0;0
92.999;0.039353;0.0036146;-0.003229;0.29439;0;0;0;0;0;0;0;0;0;0;0;0;0
93.999;0.040361;0.0037697;-0.0033222;0.29576;0;0;0;0;0;0;0;0;0;0;0;0;0
94.999;0.041315;0.003871;-0.0033258;0.29702;0;0;0;0;0;0;0;0;0;0;0;0;0
96;0.042332;0.0039195;-0.0034984;0.29834;0;0;0;0;0;0;0;0;0;0;0;0;0
96.999;0.043338;0.0039219;-0.0035199;0.29956;0;0;0;0;0;0;0;0;0;0;0;0;0
97.999;0.044353;0.0040421;-0.0035837;0.30086;0;0;0;0;0;0;0;0;0;0;0;0;0
99;0.045455;0.0041673;-0.0036886;0.30205;0;0;0;0;0;0;0;0;0;0;0;0;0
100;0.046425;0.004247;-0.0037734;0.30333;0;0;0;0;0;0;0;0;0;0;0;0;0
101;0.047437;0.0043043;-0.0038867;0.30453;0;0;0;0;0;0;0;0;0;0;0;0;0
102;0.048535;0.004483;-0.0039078;0.30569;0;0;0;0;0;0;0;0;0;0;0;0;0
103;0.049615;0.0044832;-0.0040075;0.30686;0;0;0;0;0;0;0;0;0;0;0;0;0
104;0.050568;0.0045459;-0.0041538;0.30795;0;0;0;0;0;0;0;0;0;0;0;0;0
105;0.051611;0.004662;-0.0041923;0.30912;0;0;0;0;0;0;0;0;0;0;0;0;0
106;0.052782;0.0047266;-0.0042434;0.31021;0;0;0;0;0;0;0;0;0;0;0;0;0
107;0.053744;0.0048255;-0.0043828;0.31134;0;0;0;0;0;0;0;0;0;0;0;0;0
108;0.054976;0.0050527;-0.0044849;0.31236;0;0;0;0;0;0;0;0;0;0;0;0;0
109;0.055998;0.0050819;-0.0045523;0.31343;0;0;0;0;0;0;0;0;0;0;0;0;0
110;0.057147;0.005255;-0.0046071;0.31441;0;0;0;0;0;0;0;0;0;0;0;0;0
111;0.058143;0.0052107;-0.0047148;0.31546;0;0;0;0;0;0;0;0;0;0;0;0;0
112;0.059269;0.0053716;-0.0047705;0.31647;0;0;0;0;0;0;0;0;0;0;0;0;0
113;0.060429;0.0054203;-0.0048275;0.31745;0;0;0;0;0;0;0;0;0;0;0;0;0
114;0.061484;0.0055152;-0.0049324;0.31844;0;0;0;0;0;0;0;0;0;0;0;0;0
115;0.062609;0.0055696;-0.0049816;0.31942;0;0;0;0;0;0;0;0;0;0;0;0;0
116;0.063855;0.0056516;-0.0050259;0.32037;0;0;0;0;0;0;0;0;0;0;0;0;0
117;0.064702;0.0058331;-0.005118;0.32128;0;0;0;0;0;0;0;0;0;0;0;0;0
118;0.06588;0.0059343;-0.0052172;0.32223;0;0;0;0;0;0;0;0;0;0;0;0;0
119;0.066902;0.0061391;-0.0053524;0.32313;0;0;0;0;0;0;0;0;0;0;0;0;0
120;0.067899;0.0062678;-0.0053807;0.32402;0;0;0;0;0;0;0;0;0;0;0;0;0
121;0.069051;0.0063087;-0.0054925;0.3249;0;0;0;0;0;0;0;0;0;0;0;0;0
122.01;0.070183;0.0064305;-0.0055811;0.32577;0;0;0;0;0;0;0;0;0;0;0;0;0
123;0.071262;0.0065484;-0.0056564;0.3266;0;0;0;0;0;0;0;0;0;0;0;0;0
124;0.07235;0.0066407;-0.0057259;0.32749;0;0;0;0;0;0;0;0;0;0;0;0;0
125;0.073479;0.006751;-0.005832;0.32832;0;0;0;0;0;0;0;0;0;0;0;0;0
126;0.074546;0.0068953;-0.0059035;0.32915;0;0;0;0;0;0;0;0;0;0;0;0;0
127;0.075666;0.0070095;-0.0059815;0.32998;0;0;0;0;0;0;0;0;0;0;0;0;0
128;0.076832;0.0071093;-0.0061555;0.33078;0;0;0;0;0;0;0;0;0;0;0;0;0
129;0.077845;0.0072038;-0.0061848;0.33158;0;0;0;0;0;0;0;0;0;0;0;0;0
130;0.078955;0.0072748;-0.0062706;0.33237;0;0;0;0;0;0;0;0;0;0;0;0;0
131;0.080138;0.0074195;-0.0063791;0.33312;0;0;0;0;0;0;0;0;0;0;0;0;0
132;0.08127;0.0074773;-0.0063934;0.33385;0;0;0;0;0;0;0;0;0;0;0;0;0
133;0.082387;0.0075861;-0.006543;0.33461;0;0;0;0;0;0;0;0;0;0;0;0;0
134;0.083593;0.00771;-0.0066066;0.33533;0;0;0;0;0;0;0;0;0;0;0;0;0
135;0.084652;0.0078377;-0.0067199;0.3361;0;0;0;0;0;0;0;0;0;0;0;0;0
136;0.085741;0.0079189;-0.0067732;0.33685;0;0;0;0;0;0;0;0;0;0;0;0;0
137;0.086901;0.0080239;-0.0069115;0.33757;0;0;0;0;0;0;0;0;0;0;0;0;0
138;0.087989;0.0081251;-0.0069578;0.33829;0;0;0;0;0;0;0;0;0;0;0;0;0
139;0.089155;0.008219;-0.0070414;0.33899;0;0;0;0;0;0;0;0;0;0;0;0;0
140;0.090299;0.0083568;-0.0071674;0.33973;0;0;0;0;0;0;0;0;0;0;0;0;0
141;0.091406;0.0084952;-0.0072434;0.34038;0;0;0;0;0;0;0;0;0;0;0;0;0
142;0.092559;0.0087017;-0.0073471;0.34104;0;0;0;0;0;0;0;0;0;0;0;0;0
143;0.093708;0.0087166;-0.0073838;0.34174;0;0;0;0;0;0;0;0;0;0;0;0;0
144;0.094833;0.008798;-0.0075058;0.34238;0;0;0;0;0;0;0;0;0;0;0;0;0
145;0.096026;0.0089724;-0.0076447;0.34309;0;0;0;0;0;0;0;0;0;0;0;0;0
146;0.097256;0.0090417;-0.0077338;0.34374;0;0;0;0;0;0;0;0;0;0;0;0;0
147;0.098349;0.0091672;-0.0077592;0.3444;0;0;0;0;0;0;0;0;0;0;0;0;0
148;0.099507;0.009226;-0.0078603;0.34501;0;0;0;0;0;0;0;0;0;0;0;0;0
149;0.10045;0.0094919;-0.0079172;0.34566;0;0;0;0;0;0;0;0;0;0;0;0;0
150;0.10155;0.0095714;-0.0080205;0.34626;0;0;0;0;0;0;0;0;0;0;0;0;0
151;0.10284;0.0097516;-0.0081593;0.34688;0;0;0;0;0;0;0;0;0;0;0;0;0
152;0.10391;0.009896;-0.0082339;0.34749;0;0;0;0;0;0;0;0;0;0;0;0;0
153;0.10508;0.0099992;-0.0082168;0.34807;0;0;0;0;0;0;0;0;0;0;0;0;0
154;0.10624;0.01008;-0.0083173;0.34866;0;0;0;0;0;0;0;0;0;0;0;0;0
155;0.10743;0.010141;-0.0085035;0.34924;0;0;0;0;0;0;0;0;0;0;0;0;0
156;0.10859;0.010354;-0.0085626;0.34981;0;0;0;0;0;0;0;0;0;0;0;0;0
157;0.10968;0.01046;-0.0086421;0.35038;0;0;0;0;0;0;0;0;0;0;0;0;0
158;0.11083;0.010645;-0.0087483;0.35098;0;0;0;0;0;0;0;0;0;0;0;0;0
159;0.11195;0.01076;-0.0088566;0.35151;0;0;0;0;0;0;0;0;0;0;0;0;0
160;0.11323;0.010851;-0.0089882;0.35207;0;0;0;0;0;0;0;0;0;0;0;0;0
161;0.1144;0.010951;-0.0090371;0.35259;0;0;0;0;0;0;0;0;0;0;0;0;0
162;0.11537;0.011065;-0.0091133;0.35312;0;0;0;0;0;0;0;0;0;0;0;0;0
163;0.11667;0.011236;-0.009265;0.35364;0;0;0;0;0;0;0;0;0;0;0;0;0
164;0.11786;0.011358;-0.0093378;0.35417;0;0;0;0;0;0;0;0;0;0;0;0;0
165;0.11908;0.011482;-0.0094315;0.35467;0;0;0;0;0;0;0;0;0;0;0;0;0
166;0.12027;0.011514;-0.0094756;0.35521;0;0;0;0;0;0;0;0;0;0;0;0;0
167;0.12138;0.011713;-0.0096186;0.3557;0;0;0;0;0;0;0;0;0;0;0;0;0
168;0.12255;0.011826;-0.0096723;0.35621;0;0;0;0;0;0;0;0;0;0;0;0;0
169;0.12369;0.012044;-0.0097872;0.35668;0;0;0;0;0;0;0;0;0;0;0;0;0
170;0.12481;0.012079;-0.0098399;0.3572;0;0;0;0;0;0;0;0;0;0;0;0;0
171;0.12636;0.012209;-0.0099377;0.35769;0;0;0;0;0;0;0;0;0;0;0;0;0
172;0.12711;0.012326;-0.010046;0.35819;0;0;0;0;0;0;0;0;0;0;0;0;0
173;0.12837;0.012482;-0.01006;0.35869;0;0;0;0;0;0;0;0;0;0;0;0;0
174;0.12955;0.012572;-0.010101;0.35918;0;0;0;0;0;0;0;0;0;0;0;0;0
175;0.13086;0.012847;-0.010196;0.35962;0;0;0;0;0;0;0;0;0;0;0;0;0
176;0.13194;0.013038;-0.010257;0.36009;0;0;0;0;0;0;0;0;0;0;0;0;0
177;0.13307;0.01305;-0.010371;0.36053;0;0;0;0;0;0;0;0;0;0;0;0;0
178;0.13432;0.01323;-0.010461;0.36097;0;0;0;0;0;0;0;0;0;0;0;0;0
179;0.13554;0.013304;-0.010556;0.36141;0;0;0;0;0;0;0;0;0;0;0;0;0
180;0.1366;0.013451;-0.010563;0.36186;0;0;0;0;0;0;0;0;0;0;0;0;0
181;0.13777;0.013573;-0.010721;0.36229;0;0;0;0;0;0;0;0;0;0;0;0;0
182;0.13891;0.01371;-0.010822;0.3627;0;0;0;0;0;0;0;0;0;0;0;0;0
183;0.14021;0.013756;-0.010868;0.36316;0;0;0;0;0;0;0;0;0;0;0;0;0
184;0.14131;0.013919;-0.010905;0.36356;0;0;0;0;0;0;0;0;0;0;0;0;0
185;0.14258;0.014078;-0.010991;0.36401;0;0;0;0;0;0;0;0;0;0;0;0;0
186;0.14379;0.014124;-0.011023;0.36443;0;0;0;0;0;0;0;0;0;0;0;0;0
187;0.14498;0.014273;-0.011121;0.36483;0;0;0;0;0;0;0;0;0;0;0;0;0
188;0.14613;0.01441;-0.011225;0.36523;0;0;0;0;0;0;0;0;0;0;0;0;0
189;0.14736;0.014505;-0.011314;0.36564;0;0;0;0;0;0;0;0;0;0;0;0;0
190;0.14838;0.01465;-0.011432;0.36602;0;0;0;0;0;0;0;0;0;0;0;0;0
191;0.14963;0.014744;-0.011443;0.3664;0;0;0;0;0;0;0;0;0;0;0;0;0
192;0.15094;0.014934;-0.011561;0.36682;0;0;0;0;0;0;0;0;0;0;0;0;0
193;0.15203;0.015032;-0.011611;0.36723;0;0;0;0;0;0;0;0;0;0;0;0;0
194;0.15328;0.015193;-0.011717;0.36762;0;0;0;0;0;0;0;0;0;0;0;0;0
195;0.15459;0.015318;-0.011754;0.36801;0;0;0;0;0;0;0;0;0;0;0;0;0
196;0.15565;0.01545;-0.011884;0.36836;0;0;0;0;0;0;0;0;0;0;0;0;0
197;0.15701;0.015532;-0.011959;0.36872;0;0;0;0;0;0;0;0;0;0;0;0;0
198;0.15807;0.015639;-0.012051;0.3691;0;0;0;0;0;0;0;0;0;0;0;0;0
199;0.15938;0.015814;-0.012131;0.36946;0;0;0;0;0;0;0;0;0;0;0;0;0
200;0.16046;0.015983;-0.012206;0.36982;0;0;0;0;0;0;0;0;0;0;0;0;0
201;0.16159;0.016081;-0.012312;0.37019;0;0;0;0;0;0;0;0;0;0;0;0;0
202;0.16294;0.016247;-0.012435;0.37054;0;0;0;0;0;0;0;0;0;0;0;0;0
203;0.16412;0.016377;-0.012476;0.37089;0;0;0;0;0;0;0;0;0;0;0;0;0
204;0.16522;0.016529;-0.012586;0.37123;0;0;0;0;0;0;0;0;0;0;0;0;0
205;0.16651;0.016662;-0.012627;0.37159;0;0;0;0;0;0;0;0;0;0;0;0;0
206;0.16767;0.016805;-0.012769;0.37192;0;0;0;0;0;0;0;0;0;0;0;0;0
207;0.16894;0.016922;-0.012863;0.37227;0;0;0;0;0;0;0;0;0;0;0;0;0
208;0.17014;0.01713;-0.012981;0.37263;0;0;0;0;0;0;0;0;0;0;0;0;0
209;0.17123;0.017272;-0.013049;0.37298;0;0;0;0;0;0;0;0;0;0;0;0;0
210;0.17248;0.017352;-0.013152;0.37333;0;0;0;0;0;0;0;0;0;0;0;0;0
211;0.17384;0.017469;-0.013234;0.37365;0;0;0;0;0;0;0;0;0;0;0;0;0
212;0.1749;0.017643;-0.013323;0.374;0;0;0;0;0;0;0;0;0;0;0;0;0
213;0.1761;0.017776;-0.013473;0.3743;0;0;0;0;0;0;0;0;0;0;0;0;0
214;0.17741;0.017903;-0.013588;0.37462;0;0;0;0;0;0;0;0;0;0;0;0;0
215;0.17862;0.017976;-0.013634;0.37493;0;0;0;0;0;0;0;0;0;0;0;0;0
216;0.17988;0.018161;-0.01371;0.37522;0;0;0;0;0;0;0;0;0;0;0;0;0
217;0.18101;0.018221;-0.013848;0.3755;0;0;0;0;0;0;0;0;0;0;0;0;0
218;0.18231;0.018318;-0.0139;0.37581;0;0;0;0;0;0;0;0;0;0;0;0;0
219;0.18342;0.01847;-0.014062;0.37607;0;0;0;0;0;0;0;0;0;0;0;0;0
220;0.18464;0.018497;-0.014129;0.37636;0;0;0;0;0;0;0;0;0;0;0;0;0
221;0.18583;0.018685;-0.014195;0.37666;0;0;0;0;0;0;0;0;0;0;0;0;0
222;0.18707;0.018777;-0.014293;0.37694;0;0;0;0;0;0;0;0;0;0;0;0;0
223;0.18825;0.018839;-0.01443;0.37724;0;0;0;0;0;0;0;0;0;0;0;0;0
224;0.18954;0.018941;-0.014488;0.37752;0;0;0;0;0;0;0;0;0;0;0;0;0
225;0.19072;0.019028;-0.014645;0.3778;0;0;0;0;0;0;0;0;0;0;0;0;0
226;0.19182;0.019221;-0.014756;0.37807;0;0;0;0;0;0;0;0;0;0;0;0;0
227;0.19304;0.019332;-0.014823;0.37835;0;0;0;0;0;0;0;0;0;0;0;0;0
228;0.19428;0.019363;-0.014859;0.37862;0;0;0;0;0;0;0;0;0;0;0;0;0
229;0.19566;0.019609;-0.01498;0.3789;0;0;0;0;0;0;0;0;0;0;0;0;0
230;0.19678;0.019753;-0.015174;0.37915;0;0;0;0;0;0;0;0;0;0;0;0;0
231;0.19797;0.019911;-0.015239;0.3794;0;0;0;0;0;0;0;0;0;0;0;0;0
232;0.19909;0.019996;-0.015305;0.37965;0;0;0;0;0;0;0;0;0;0;0;0;0
233;0.20035;0.0201;-0.015405;0.37989;0;0;0;0;0;0;0;0;0;0;0;0;0
234;0.20161;0.020345;-0.015502;0.38014;0;0;0;0;0;0;0;0;0;0;0;0;0
235;0.2028;0.020459;-0.015591;0.38037;0;0;0;0;0;0;0;0;0;0;0;0;0
236;0.20402;0.020637;-0.015795;0.38062;0;0;0;0;0;0;0;0;0;0;0;0;0
237;0.20526;0.0207;-0.01584;0.38084;0;0;0;0;0;0;0;0;0;0;0;0;0
238;0.2065;0.020913;-0.01601;0.38109;0;0;0;0;0;0;0;0;0;0;0;0;0
239;0.20773;0.021071;-0.016122;0.38132;0;0;0;0;0;0;0;0;0;0;0;0;0
240;0.20895;0.021268;-0.016168;0.38154;0;0;0;0;0;0;0;0;0;0;0;0;0
241;0.20991;0.021375;-0.016305;0.38177;0;0;0;0;0;0;0;0;0;0;0;0;0
242;0.21133;0.021497;-0.016443;0.38196;0;0;0;0;0;0;0;0;0;0;0;0;0
243;0.21253;0.021682;-0.01653;0.38219;0;0;0;0;0;0;0;0;0;0;0;0;0
244;0.2138;0.021865;-0.016631;0.38242;0;0;0;0;0;0;0;0;0;0;0;0;0
245;0.21502;0.022048;-0.016708;0.38263;0;0;0;0;0;0;0;0;0;0;0;0;0
246;0.21616;0.022148;-0.016781;0.38286;0;0;0;0;0;0;0;0;0;0;0;0;0
247;0.21738;0.022338;-0.016932;0.38308;0;0;0;0;0;0;0;0;0;0;0;0;0
248;0.21865;0.022582;-0.017049;0.38329;0;0;0;0;0;0;0;0;0;0;0;0;0
249;0.21982;0.022744;-0.017187;0.38351;0;0;0;0;0;0;0;0;0;0;0;0;0
250;0.22106;0.022898;-0.017174;0.38374;0;0;0;0;0;0;0;0;0;0;0;0;0
251;0.22236;0.023019;-0.017292;0.38393;0;0;0;0;0;0;0;0;0;0;0;0;0
252;0.22338;0.023266;-0.01747;0.38414;0;0;0;0;0;0;0;0;0;0;0;0;0
253;0.22467;0.023317;-0.01745;0.38433;0;0;0;0;0;0;0;0;0;0;0;0;0
254;0.22569;0.023494;-0.01763;0.3845;0;0;0;0;0;0;0;0;0;0;0;0;0
255;0.22705;0.023741;-0.017644;0.38472;0;0;0;0;0;0;0;0;0;0;0;0;0
256;0.22826;0.023853;-0.017874;0.38491;0;0;0;0;0;0;0;0;0;0;0;0;0
257;0.22953;0.024047;-0.017942;0.38511;0;0;0;0;0;0;0;0;0;0;0;0;0
258;0.23036;0.024124;-0.018082;0.38533;0;0;0;0;0;0;0;0;0;0;0;0;0
259;0.23197;0.024289;-0.018171;0.38552;0;0;0;0;0;0;0;0;0;0;0;0;0
260;0.23308;0.024487;-0.018255;0.38573;0;0;0;0;0;0;0;0;0;0;0;0;0
261;0.23438;0.024635;-0.018382;0.38592;0;0;0;0;0;0;0;0;0;0;0;0;0
262;0.23578;0.024773;-0.018531;0.38613;0;0;0;0;0;0;0;0;0;0;0;0;0
263;0.23677;0.024924;-0.018708;0.38631;0;0;0;0;0;0;0;0;0;0;0;0;0
264;0.23802;0.0251;-0.018769;0.38649;0;0;0;0;0;0;0;0;0;0;0;0;0
265;0.23933;0.025182;-0.018871;0.38667;0;0;0;0;0;0;0;0;0;0;0;0;0
266;0.24032;0.025289;-0.019003;0.38685;0;0;0;0;0;0;0;0;0;0;0;0;0
267;0.24148;0.025483;-0.019202;0.38703;0;0;0;0;0;0;0;0;0;0;0;0;0
268;0.24293;0.025588;-0.019284;0.38721;0;0;0;0;0;0;0;0;0;0;0;0;0
269;0.24418;0.025845;-0.019415;0.38737;0;0;0;0;0;0;0;0;0;0;0;0;0
270;0.24565;0.026004;-0.019555;0.38753;0;0;0;0;0;0;0;0;0;0;0;0;0
271;0.24635;0.026174;-0.019686;0.3877;0;0;0;0;0;0;0;0;0;0;0;0;0
272;0.24785;0.026475;-0.019845;0.38786;0;0;0;0;0;0;0;0;0;0;0;0;0
273;0.24923;0.026614;-0.019961;0.38802;0;0;0;0;0;0;0;0;0;0;0;0;0
274;0.2505;0.0269;-0.02005;0.38818;0;0;0;0;0;0;0;0;0;0;0;0;0
275;0.25164;0.027068;-0.020206;0.38832;0;0;0;0;0;0;0;0;0;0;0;0;0
276;0.25297;0.027235;-0.020262;0.38845;0;0;0;0;0;0;0;0;0;0;0;0;0
277;0.25418;0.027362;-0.020442;0.3886;0;0;0;0;0;0;0;0;0;0;0;0;0
278;0.25552;0.027508;-0.020491;0.38875;0;0;0;0;0;0;0;0;0;0;0;0;0
279;0.25676;0.027751;-0.020595;0.3889;0;0;0;0;0;0;0;0;0;0;0;0;0
280;0.25806;0.027876;-0.020669;0.38905;0;0;0;0;0;0;0;0;0;0;0;0;0
281;0.25923;0.028071;-0.020788;0.38921;0;0;0;0;0;0;0;0;0;0;0;0;0
282;0.26048;0.028125;-0.020984;0.38934;0;0;0;0;0;0;0;0;0;0;0;0;0
283;0.26179;0.028344;-0.021043;0.38947;0;0;0;0;0;0;0;0;0;0;0;0;0
284;0.26306;0.028511;-0.021166;0.38959;0;0;0;0;0;0;0;0;0;0;0;0;0
285;0.2642;0.028635;-0.021204;0.38972;0;0;0;0;0;0;0;0;0;0;0;0;0
286;0.26534;0.028735;-0.021309;0.38983;0;0;0;0;0;0;0;0;0;0;0;0;0
287;0.26668;0.028962;-0.021411;0.38995;0;0;0;0;0;0;0;0;0;0;0;0;0
288;0.2679;0.029029;-0.021528;0.39009;0;0;0;0;0;0;0;0;0;0;0;0;0
289;0.26916;0.029239;-0.021629;0.39021;0;0;0;0;0;0;0;0;0;0;0;0;0
290;0.2703;0.029404;-0.021685;0.39034;0;0;0;0;0;0;0;0;0;0;0;0;0
291;0.27155;0.029567;-0.021878;0.39046;0;0;0;0;0;0;0;0;0;0;0;0;0
292;0.27289;0.02979;-0.021921;0.39059;0;0;0;0;0;0;0;0;0;0;0;0;0
293;0.27405;0.02991;-0.022092;0.39072;0;0;0;0;0;0;0;0;0;0;0;0;0
294;0.27556;0.030209;-0.022199;0.39082;0;0;0;0;0;0;0;0;0;0;0;0;0
295;0.27655;0.030437;-0.022301;0.39094;0;0;0;0;0;0;0;0;0;0;0;0;0
296;0.27801;0.030579;-0.022425;0.39106;0;0;0;0;0;0;0;0;0;0;0;0;0
297;0.27926;0.03079;-0.022515;0.39118;0;0;0;0;0;0;0;0;0;0;0;0;0
298;0.28052;0.030992;-0.022605;0.39129;0;0;0;0;0;0;0;0;0;0;0;0;0
299;0.28189;0.031238;-0.022712;0.3914;0;0;0;0;0;0;0;0;0;0;0;0;0
300;0.28311;0.03143;-0.022911;0.39151;0;0;0;0;0;0;0;0;0;0;0;0;0
301;0.2843;0.031641;-0.022993;0.39162;0;0;0;0;0;0;0;0;0;0;0;0;0
302;0.28551;0.031775;-0.023136;0.39171;0;0;0;0;0;0;0;0;0;0;0;0;0
303;0.28685;0.031911;-0.023157;0.3918;0;0;0;0;0;0;0;0;0;0;0;0;0
304;0.28805;0.032125;-0.023278;0.39189;0;0;0;0;0;0;0;0;0;0;0;0;0
305;0.28939;0.032355;-0.023358;0.392;0;0;0;0;0;0;0;0;0;0;0;0;0
306;0.29072;0.032518;-0.023554;0.39212;0;0;0;0;0;0;0;0;0;0;0;0;0
307;0.29182;0.032742;-0.023658;0.39224;0;0;0;0;0;0;0;0;0;0;0;0;0
308;0.29304;0.032969;-0.02374;0.39233;0;0;0;0;0;0;0;0;0;0;0;0;0
309;0.29457;0.033237;-0.023769;0.39243;0;0;0;0;0;0;0;0;0;0;0;0;0
310;0.29561;0.033491;-0.023915;0.39251;0;0;0;0;0;0;0;0;0;0;0;0;0
311;0.29701;0.033695;-0.024018;0.39261;0;0;0;0;0;0;0;0;0;0;0;0;0
312;0.29833;0.034007;-0.02415;0.3927;0;0;0;0;0;0;0;0;0;0;0;0;0
313;0.29962;0.034243;-0.024211;0.39278;0;0;0;0;0;0;0;0;0;0;0;0;0
314;0.30084;0.034477;-0.024289;0.39286;0;0;0;0;0;0;0;0;0;0;0;0;0
315;0.30205;0.034803;-0.024412;0.39295;0;0;0;0;0;0;0;0;0;0;0;0;0
316;0.30341;0.034962;-0.024548;0.39304;0;0;0;0;0;0;0;0;0;0;0;0;0
317;0.3047;0.035217;-0.024661;0.39311;0;0;0;0;0;0;0;0;0;0;0;0;0
318;0.30597;0.03538;-0.024712;0.39318;0;0;0;0;0;0;0;0;0;0;0;0;0
319;0.30727;0.035681;-0.024841;0.39323;0;0;0;0;0;0;0;0;0;0;0;0;0
320;0.30855;0.035882;-0.024968;0.3933;0;0;0;0;0;0;0;0;0;0;0;0;0
321;0.30992;0.036188;-0.025053;0.39336;0;0;0;0;0;0;0;0;0;0;0;0;0
322;0.31126;0.036462;-0.02518;0.39342;0;0;0;0;0;0;0;0;0;0;0;0;0
323;0.31234;0.036625;-0.025256;0.39348;0;0;0;0;0;0;0;0;0;0;0;0;0
324;0.31366;0.036862;-0.02538;0.39354;0;0;0;0;0;0;0;0;0;0;0;0;0
325;0.31485;0.037036;-0.025491;0.39359;0;0;0;0;0;0;0;0;0;0;0;0;0
326;0.31607;0.037178;-0.025547;0.39364;0;0;0;0;0;0;0;0;0;0;0;0;0
327;0.31753;0.037426;-0.025679;0.39369;0;0;0;0;0;0;0;0;0;0;0;0;0
328;0.31882;0.037668;-0.025769;0.39373;0;0;0;0;0;0;0;0;0;0;0;0;0
329;0.31996;0.037842;-0.025826;0.39378;0;0;0;0;0;0;0;0;0;0;0;0;0
330;0.32121;0.038105;-0.025992;0.39381;0;0;0;0;0;0;0;0;0;0;0;0;0
331;0.32247;0.038352;-0.025972;0.39385;0;0;0;0;0;0;0;0;0;0;0;0;0
332;0.32373;0.038542;-0.026138;0.39388;0;0;0;0;0;0;0;0;0;0;0;0;0
333;0.32504;0.038777;-0.026281;0.39391;0;0;0;0;0;0;0;0;0;0;0;0;0
334;0.32626;0.038961;-0.026365;0.39395;0;0;0;0;0;0;0;0;0;0;0;0;0
335;0.32751;0.03926;-0.026471;0.39399;0;0;0;0;0;0;0;0;0;0;0;0;0
336;0.32877;0.039485;-0.02656;0.39402;0;0;0;0;0;0;0;0;0;0;0;0;0
337;0.32999;0.039771;-0.026725;0.39405;0;0;0;0;0;0;0;0;0;0;0;0;0
338;0.33138;0.040048;-0.026808;0.39408;0;0;0;0;0;0;0;0;0;0;0;0;0
339;0.33267;0.04034;-0.026924;0.39412;0;0;0;0;0;0;0;0;0;0;0;0;0
340;0.33395;0.040629;-0.027018;0.39414;0;0;0;0;0;0;0;0;0;0;0;0;0
341;0.33504;0.040877;-0.027194;0.39415;0;0;0;0;0;0;0;0;0;0;0;0;0
342;0.33634;0.041123;-0.02725;0.39418;0;0;0;0;0;0;0;0;0;0;0;0;0
343;0.33774;0.041349;-0.027349;0.3942;0;0;0;0;0;0;0;0;0;0;0;0;0
344;0.33894;0.041645;-0.027475;0.39422;0;0;0;0;0;0;0;0;0;0;0;0;0
345;0.3403;0.041869;-0.02756;0.39425;0;0;0;0;0;0;0;0;0;0;0;0;0
346;0.34164;0.042062;-0.027615;0.39427;0;0;0;0;0;0;0;0;0;0;0;0;0
347;0.34294;0.042261;-0.027791;0.39429;0;0;0;0;0;0;0;0;0;0;0;0;0
348;0.34425;0.042521;-0.027907;0.39433;0;0;0;0;0;0;0;0;0;0;0;0;0
349;0.3453;0.042727;-0.027985;0.39435;0;0;0;0;0;0;0;0;0;0;0;0;0
350;0.34651;0.043036;-0.028137;0.39437;0;0;0;0;0;0;0;0;0;0;0;0;0
351;0.34783;0.04324;-0.028234;0.39438;0;0;0;0;0;0;0;0;0;0;0;0;0
352;0.3493;0.043493;-0.028398;0.39439;0;0;0;0;0;0;0;0;0;0;0;0;0
353;0.35038;0.043685;-0.028469;0.39441;0;0;0;0;0;0;0;0;0;0;0;0;0
354;0.35182;0.043857;-0.028659;0.39442;0;0;0;0;0;0;0;0;0;0;0;0;0
355;0.35295;0.044243;-0.028814;0.39443;0;0;0;0;0;0;0;0;0;0;0;0;0
356;0.35453;0.0446;-0.028918;0.39444;0;0;0;0;0;0;0;0;0;0;0;0;0
357;0.35568;0.044963;-0.029074;0.39444;0;0;0;0;0;0;0;0;0;0;0;0;0
358;0.35704;0.045308;-0.029133;0.39444;0;0;0;0;0;0;0;0;0;0;0;0;0
359;0.35819;0.045718;-0.029256;0.39446;0;0;0;0;0;0;0;0;0;0;0;0;0
360;0.35949;0.046129;-0.029472;0.39447;0;0;0;0;0;0;0;0;0;0;0;0;0
361;0.36078;0.046424;-0.029579;0.39448;0;0;0;0;0;0;0;0;0;0;0;0;0
362;0.36183;0.046751;-0.029693;0.39448;0;0;0;0;0;0;0;0;0;0;0;0;0
363;0.3633;0.047131;-0.029819;0.39446;0;0;0;0;0;0;0;0;0;0;0;0;0
364;0.36456;0.047408;-0.029905;0.39447;0;0;0;0;0;0;0;0;0;0;0;0;0
365;0.36581;0.047713;-0.030106;0.39446;0;0;0;0;0;0;0;0;0;0;0;0;0
366;0.36713;0.048028;-0.030235;0.39447;0;0;0;0;0;0;0;0;0;0;0;0;0
367;0.36841;0.048325;-0.030345;0.39447;0;0;0;0;0;0;0;0;0;0;0;0;0
368;0.36978;0.04856;-0.030519;0.39446;0;0;0;0;0;0;0;0;0;0;0;0;0
369;0.37114;0.048905;-0.03065;0.39445;0;0;0;0;0;0;0;0;0;0;0;0;0
370;0.37197;0.049191;-0.030727;0.39444;0;0;0;0;0;0;0;0;0;0;0;0;0
371;0.37354;0.049427;-0.03093;0.39442;0;0;0;0;0;0;0;0;0;0;0;0;0
372;0.37509;0.049745;-0.031078;0.39441;0;0;0;0;0;0;0;0;0;0;0;0;0
373;0.37622;0.050067;-0.031283;0.3944;0;0;0;0;0;0;0;0;0;0;0;0;0
374;0.3774;0.050317;-0.031405;0.39439;0;0;0;0;0;0;0;0;0;0;0;0;0
375;0.37865;0.050621;-0.031518;0.39437;0;0;0;0;0;0;0;0;0;0;0;0;0
376;0.38;0.050945;-0.031688;0.39436;0;0;0;0;0;0;0;0;0;0;0;0;0
377;0.38132;0.051285;-0.031798;0.39434;0;0;0;0;0;0;0;0;0;0;0;0;0
378;0.38267;0.051737;-0.031984;0.39431;0;0;0;0;0;0;0;0;0;0;0;0;0
379;0.38396;0.052035;-0.032115;0.39431;0;0;0;0;0;0;0;0;0;0;0;0;0
380;0.38517;0.05234;-0.032203;0.3943;0;0;0;0;0;0;0;0;0;0;0;0;0
381;0.38651;0.052714;-0.032346;0.39429;0;0;0;0;0;0;0;0;0;0;0;0;0
382;0.3877;0.053051;-0.032562;0.39429;0;0;0;0;0;0;0;0;0;0;0;0;0
383;0.38907;0.053406;-0.032637;0.39426;0;0;0;0;0;0;0;0;0;0;0;0;0
384;0.39029;0.053745;-0.032834;0.39422;0;0;0;0;0;0;0;0;0;0;0;0;0
385;0.39175;0.054212;-0.03292;0.39421;0;0;0;0;0;0;0;0;0;0;0;0;0
386;0.3927;0.054633;-0.033088;0.39419;0;0;0;0;0;0;0;0;0;0;0;0;0
387;0.39442;0.055057;-0.033269;0.39417;0;0;0;0;0;0;0;0;0;0;0;0;0
388;0.39538;0.055602;-0.033401;0.39416;0;0;0;0;0;0;0;0;0;0;0;0;0
389;0.39683;0.055896;-0.033618;0.39414;0;0;0;0;0;0;0;0;0;0;0;0;0
390;0.39793;0.05632;-0.033754;0.39412;0;0;0;0;0;0;0;0;0;0;0;0;0
391;0.39951;0.056704;-0.03391;0.39411;0;0;0;0;0;0;0;0;0;0;0;0;0
392;0.40064;0.057102;-0.034081;0.3941;0;0;0;0;0;0;0;0;0;0;0;0;0
393;0.40196;0.057511;-0.034252;0.39409;0;0;0;0;0;0;0;0;0;0;0;0;0
394;0.40322;0.057922;-0.034379;0.39406;0;0;0;0;0;0;0;0;0;0;0;0;0
395;0.40451;0.058352;-0.034531;0.39404;0;0;0;0;0;0;0;0;0;0;0;0;0
396;0.40589;0.058839;-0.034744;0.39403;0;0;0;0;0;0;0;0;0;0;0;0;0
397;0.40716;0.059297;-0.034928;0.39401;0;0;0;0;0;0;0;0;0;0;0;0;0
398;0.40841;0.059735;-0.035017;0.394;0;0;0;0;0;0;0;0;0;0;0;0;0
399;0.40976;0.060047;-0.03521;0.39399;0;0;0;0;0;0;0;0;0;0;0;0;0
400;0.41098;0.060504;-0.035374;0.39398;0;0;0;0;0;0;0;0;0;0;0;0;0
401;0.41219;0.060979;-0.035525;0.39397;0;0;0;0;0;0;0;0;0;0;0;0;0
402;0.41357;0.061406;-0.035752;0.39395;0;0;0;0;0;0;0;0;0;0;0;0;0
403;0.41474;0.061867;-0.035875;0.39393;0;0;0;0;0;0;0;0;0;0;0;0;0
404;0.41622;0.062292;-0.036079;0.39392;0;0;0;0;0;0;0;0;0;0;0;0;0
405;0.41756;0.062652;-0.036296;0.39391;0;0;0;0;0;0;0;0;0;0;0;0;0
406;0.41884;0.063021;-0.03641;0.39391;0;0;0;0;0;0;0;0;0;0;0;0;0
407;0.42016;0.063393;-0.036598;0.39392;0;0;0;0;0;0;0;0;0;0;0;0;0
408;0.42143;0.063658;-0.036828;0.39391;0;0;0;0;0;0;0;0;0;0;0;0;0
409;0.42273;0.063964;-0.036955;0.39389;0;0;0;0;0;0;0;0;0;0;0;0;0
410;0.42419;0.064516;-0.037161;0.39386;0;0;0;0;0;0;0;0;0;0;0;0;0
411;0.42548;0.06486;-0.037412;0.39384;0;0;0;0;0;0;0;0;0;0;0;0;0
412;0.42658;0.065356;-0.037534;0.39381;0;0;0;0;0;0;0;0;0;0;0;0;0
413;0.42802;0.066262;-0.037778;0.39379;0;0;0;0;0;0;0;0;0;0;0;0;0
414;0.42917;0.066656;-0.037961;0.39378;0;0;0;0;0;0;0;0;0;0;0;0;0
415;0.43058;0.06722;-0.038192;0.39376;0;0;0;0;0;0;0;0;0;0;0;0;0
416;0.43181;0.067745;-0.038327;0.39374;0;0;0;0;0;0;0;0;0;0;0;0;0
417;0.43336;0.068239;-0.038518;0.39371;0;0;0;0;0;0;0;0;0;0;0;0;0
418;0.43436;0.068822;-0.038701;0.39369;0;0;0;0;0;0;0;0;0;0;0;0;0
419;0.43574;0.069366;-0.03883;0.39366;0;0;0;0;0;0;0;0;0;0;0;0;0
420;0.43715;0.06994;-0.039009;0.39364;0;0;0;0;0;0;0;0;0;0;0;0;0
421;0.43863;0.070518;-0.039125;0.39362;0;0;0;0;0;0;0;0;0;0;0;0;0
422;0.4398;0.071205;-0.039412;0.39358;0;0;0;0;0;0;0;0;0;0;0;0;0
423;0.4411;0.071787;-0.039596;0.39355;0;0;0;0;0;0;0;0;0;0;0;0;0
424;0.44244;0.072413;-0.039715;0.39352;0;0;0;0;0;0;0;0;0;0;0;0;0
425;0.44383;0.072986;-0.040009;0.39347;0;0;0;0;0;0;0;0;0;0;0;0;0
426;0.44501;0.073568;-0.04016;0.39343;0;0;0;0;0;0;0;0;0;0;0;0;0
427;0.4464;0.074246;-0.040372;0.39338;0;0;0;0;0;0;0;0;0;0;0;0;0
428;0.44773;0.074743;-0.04054;0.39333;0;0;0;0;0;0;0;0;0;0;0;0;0
429;0.44916;0.07538;-0.040656;0.3933;0;0;0;0;0;0;0;0;0;0;0;0;0
430;0.45046;0.075922;-0.040846;0.39328;0;0;0;0;0;0;0;0;0;0;0;0;0
431;0.45183;0.076445;-0.041036;0.39326;0;0;0;0;0;0;0;0;0;0;0;0;0
432;0.45315;0.077022;-0.041147;0.39322;0;0;0;0;0;0;0;0;0;0;0;0;0
433;0.45438;0.077619;-0.041364;0.39319;0;0;0;0;0;0;0;0;0;0;0;0;0
434;0.45566;0.078189;-0.041521;0.39314;0;0;0;0;0;0;0;0;0;0;0;0;0
435;0.45703;0.078709;-0.04177;0.39308;0;0;0;0;0;0;0;0;0;0;0;0;0
436;0.45834;0.079385;-0.041868;0.39302;0;0;0;0;0;0;0;0;0;0;0;0;0
437;0.45956;0.080018;-0.042113;0.39298;0;0;0;0;0;0;0;0;0;0;0;0;0
438;0.46103;0.080639;-0.04226;0.39295;0;0;0;0;0;0;0;0;0;0;0;0;0
439;0.46227;0.081298;-0.042432;0.39291;0;0;0;0;0;0;0;0;0;0;0;0;0
440;0.46366;0.081995;-0.042626;0.39287;0;0;0;0;0;0;0;0;0;0;0;0;0
441;0.46502;0.082655;-0.042755;0.39282;0;0;0;0;0;0;0;0;0;0;0;0;0
442;0.46631;0.083434;-0.042925;0.39276;0;0;0;0;0;0;0;0;0;0;0;0;0
443;0.46761;0.083975;-0.043042;0.39273;0;0;0;0;0;0;0;0;0;0;0;0;0
444;0.46915;0.08472;-0.043166;0.39267;0;0;0;0;0;0;0;0;0;0;0;0;0
445;0.47031;0.085364;-0.043388;0.39262;0;0;0;0;0;0;0;0;0;0;0;0;0
446;0.47163;0.086069;-0.043547;0.39257;0;0;0;0;0;0;0;0;0;0;0;0;0
447;0.47301;0.086772;-0.043659;0.39252;0;0;0;0;0;0;0;0;0;0;0;0;0
448;0.47427;0.087508;-0.043777;0.39247;0;0;0;0;0;0;0;0;0;0;0;0;0
449;0.47572;0.088262;-0.043981;0.3924;0;0;0;0;0;0;0;0;0;0;0;0;0
450;0.47707;0.089019;-0.044199;0.39232;0;0;0;0;0;0;0;0;0;0;0;0;0
451;0.4783;0.089605;-0.044336;0.39225;0;0;0;0;0;0;0;0;0;0;0;0;0
452;0.47967;0.090289;-0.044499;0.39218;0;0;0;0;0;0;0;0;0;0;0;0;0
453;0.48109;0.091034;-0.044703;0.39211;0;0;0;0;0;0;0;0;0;0;0;0;0
454;0.48241;0.091726;-0.044908;0.39204;0;0;0;0;0;0;0;0;0;0;0;0;0
455;0.48368;0.092395;-0.045135;0.39196;0;0;0;0;0;0;0;0;0;0;0;0;0
456;0.48513;0.093162;-0.045315;0.39187;0;0;0;0;0;0;0;0;0;0;0;0;0
457;0.48655;0.093851;-0.045481;0.39176;0;0;0;0;0;0;0;0;0;0;0;0;0
458;0.4878;0.094762;-0.045656;0.39168;0;0;0;0;0;0;0;0;0;0;0;0;0
459;0.48921;0.095569;-0.04593;0.39156;0;0;0;0;0;0;0;0;0;0;0;0;0
460;0.49068;0.096302;-0.046047;0.39145;0;0;0;0;0;0;0;0;0;0;0;0;0
461;0.49202;0.09715;-0.046245;0.39133;0;0;0;0;0;0;0;0;0;0;0;0;0
462;0.49333;0.097902;-0.046455;0.39121;0;0;0;0;0;0;0;0;0;0;0;0;0
463;0.49478;0.098684;-0.046674;0.39108;0;0;0;0;0;0;0;0;0;0;0;0;0
464;0.49623;0.099506;-0.046846;0.39093;0;0;0;0;0;0;0;0;0;0;0;0;0
465;0.49744;0.10031;-0.046977;0.39077;0;0;0;0;0;0;0;0;0;0;0;0;0
466;0.49875;0.10106;-0.047087;0.39057;0;0;0;0;0;0;0;0;0;0;0;0;0
467;0.50011;0.10195;-0.047263;0.39037;0;0;0;0;0;0;0;0;0;0;0;0;0
468;0.50168;0.10281;-0.047438;0.39016;0;0;0;0;0;0;0;0;0;0;0;0;0
469;0.50304;0.10371;-0.04764;0.38992;0;0;0;0;0;0;0;0;0;0;0;0;0
470;0.50429;0.10453;-0.047818;0.38973;0;0;0;0;0;0;0;0;0;0;0;0;0
471;0.50568;0.10547;-0.048075;0.38949;0;0;0;0;0;0;0;0;0;0;0;0;0
472;0.50711;0.10622;-0.048288;0.38923;0;0;0;0;0;0;0;0;0;0;0;0;0
473;0.50851;0.107;-0.048426;0.38895;0;0;0;0;0;0;0;0;0;0;0;0;0
474;0.50991;0.10781;-0.048588;0.38862;0;0;0;0;0;0;0;0;0;0;0;0;0
475;0.51127;0.10865;-0.048711;0.38827;0;0;0;0;0;0;0;0;0;0;0;0;0
476;0.51262;0.10949;-0.04886;0.38791;0;0;0;0;0;0;0;0;0;0;0;0;0
477;0.51392;0.11027;-0.048963;0.38753;0;0;0;0;0;0;0;0;0;0;0;0;0
478;0.51537;0.11111;-0.049078;0.38714;0;0;0;0;0;0;0;0;0;0;0;0;0
479;0.51686;0.11201;-0.049148;0.38671;0;0;0;0;0;0;0;0;0;0;0;0;0
480;0.51812;0.11279;-0.049329;0.38626;0;0;0;0;0;0;0;0;0;0;0;0;0
481;0.51944;0.11363;-0.049435;0.38583;0;0;0;0;0;0;0;0;0;0;0;0;0
482;0.52075;0.11452;-0.049509;0.38538;0;0;0;0;0;0;0;0;0;0;0;0;0
483;0.52227;0.1152;-0.049608;0.3849;0;0;0;0;0;0;0;0;0;0;0;0;0
484;0.52344;0.11603;-0.049757;0.38439;0;0;0;0;0;0;0;0;0;0;0;0;0
485;0.52475;0.11686;-0.049876;0.38391;0;0;0;0;0;0;0;0;0;0;0;0;0
486;0.52612;0.1177;-0.049933;0.38339;0;0;0;0;0;0;0;0;0;0;0;0;0
487;0.52747;0.1185;-0.050138;0.38284;0;0;0;0;0;0;0;0;0;0;0;0;0
488;0.52871;0.11931;-0.050257;0.38231;0;0;0;0;0;0;0;0;0;0;0;0;0
489;0.53011;0.12014;-0.050336;0.38175;0;0;0;0;0;0;0;0;0;0;0;0;0
490;0.53145;0.12093;-0.050524;0.38118;0;0;0;0;0;0;0;0;0;0;0;0;0
491;0.5328;0.12176;-0.050613;0.38061;0;0;0;0;0;0;0;0;0;0;0;0;0
492;0.53411;0.12262;-0.050804;0.38004;0;0;0;0;0;0;0;0;0;0;0;0;0
493;0.53551;0.12363;-0.050942;0.37943;0;0;0;0;0;0;0;0;0;0;0;0;0
494;0.53668;0.12444;-0.051138;0.3788;0;0;0;0;0;0;0;0;0;0;0;0;0
495;0.5381;0.12532;-0.05127;0.37816;0;0;0;0;0;0;0;0;0;0;0;0;0
496;0.53957;0.12614;-0.051427;0.37754;0;0;0;0;0;0;0;0;0;0;0;0;0
497;0.54078;0.12718;-0.051572;0.37685;0;0;0;0;0;0;0;0;0;0;0;0;0
498;0.54199;0.1283;-0.051704;0.37617;0;0;0;0;0;0;0;0;0;0;0;0;0
499;0.54341;0.12937;-0.051766;0.37549;0;0;0;0;0;0;0;0;0;0;0;0;0
500;0.54478;0.13034;-0.051904;0.37481;0;0;0;0;0;0;0;0;0;0;0;0;0
501;0.54604;0.1312;-0.052027;0.37406;0;0;0;0;0;0;0;0;0;0;0;0;0
502;0.54738;0.13208;-0.052227;0.37335;0;0;0;0;0;0;0;0;0;0;0;0;0
503;0.54875;0.13318;-0.052407;0.37258;0;0;0;0;0;0;0;0;0;0;0;0;0
504;0.55002;0.13398;-0.052528;0.37183;0;0;0;0;0;0;0;0;0;0;0;0;0
505;0.55141;0.13475;-0.052674;0.37101;0;0;0;0;0;0;0;0;0;0;0;0;0
506;0.55275;0.13574;-0.052854;0.37023;0;0;0;0;0;0;0;0;0;0;0;0;0
507;0.55416;0.13672;-0.053056;0.36938;0;0;0;0;0;0;0;0;0;0;0;0;0
508;0.55533;0.13776;-0.053211;0.36858;0;0;0;0;0;0;0;0;0;0;0;0;0
509;0.5569;0.1388;-0.053266;0.36771;0;0;0;0;0;0;0;0;0;0;0;0;0
510;0.55816;0.13991;-0.053369;0.36687;0;0;0;0;0;0;0;0;0;0;0;0;0
511;0.55945;0.14087;-0.053433;0.36593;0;0;0;0;0;0;0;0;0;0;0;0;0
512;0.56097;0.14178;-0.053503;0.36506;0;0;0;0;0;0;0;0;0;0;0;0;0
513;0.56209;0.14284;-0.053585;0.36408;0;0;0;0;0;0;0;0;0;0;0;0;0
514;0.56345;0.14379;-0.053647;0.36312;0;0;0;0;0;0;0;0;0;0;0;0;0
515;0.56466;0.14471;-0.053686;0.36214;0;0;0;0;0;0;0;0;0;0;0;0;0
516;0.56615;0.14566;-0.053672;0.36115;0;0;0;0;0;0;0;0;0;0;0;0;0
517;0.56757;0.14671;-0.053742;0.36013;0;0;0;0;0;0;0;0;0;0;0;0;0
518;0.5689;0.14762;-0.05384;0.35912;0;0;0;0;0;0;0;0;0;0;0;0;0
519;0.57016;0.14863;-0.053829;0.35795;0;0;0;0;0;0;0;0;0;0;0;0;0
520;0.57153;0.14969;-0.053888;0.35689;0;0;0;0;0;0;0;0;0;0;0;0;0
521;0.57299;0.151;-0.053932;0.35578;0;0;0;0;0;0;0;0;0;0;0;0;0
522;0.57442;0.15217;-0.053917;0.35455;0;0;0;0;0;0;0;0;0;0;0;0;0
523;0.57579;0.1534;-0.053896;0.3534;0;0;0;0;0;0;0;0;0;0;0;0;0
524;0.57717;0.1543;-0.053847;0.35209;0;0;0;0;0;0;0;0;0;0;0;0;0
525;0.57858;0.15552;-0.053714;0.35078;0;0;0;0;0;0;0;0;0;0;0;0;0
526;0.58002;0.1566;-0.053702;0.34943;0;0;0;0;0;0;0;0;0;0;0;0;0
527;0.58154;0.15781;-0.053732;0.34802;0;0;0;0;0;0;0;0;0;0;0;0;0
528;0.58301;0.15902;-0.053666;0.34644;0;0;0;0;0;0;0;0;0;0;0;0;0
529;0.58452;0.16028;-0.053642;0.34489;0;0;0;0;0;0;0;0;0;0;0;0;0
530;0.5862;0.16188;-0.053586;0.3431;0;0;0;0;0;0;0;0;0;0;0;0;0
530.5;0.58903;0.16523;-0.053393;0.34206;0;0;0;0;0;0;0;0;0;0;0;0;0