File: Template_Auto_Cali_large_DP600/_data/DP600Large_NT6_00_003_Front_DIC_File.txt
Date of Test;Material;Sample Geometry;Orientation [°];Test Number;Nominal Speed [mm/min];Thickness [mm];Central Width [mm];Gauge Width / Diameter [mm];Pixel to mm ratio [mm/px];Extensometer 1-4 [mm];Extensometer 2-3 [mm];Extensometer 5-6 [mm];;;;;
09/07/21;DP600Large;NT6;00;3;0.0798;0.28659;2;4;0;6;0.20003;0.4;;;;;
;;;;;;;;;;;;;;;;;
Time [s];U1 [mm];U2 [mm];U3 [mm];Force [kN];Ambient Temperature [°C];DIC Zone X 1 [px];DIC Zone Y 1 [px];DIC Zone X 2 [px];DIC Zone Y 2 [px];DIC Zone X 3 [px];DIC Zone Y 3 [px];DIC Zone X 4 [px];DIC Zone Y 4 [px];DIC Zone X 5 [px];DIC Zone Y 5 [px];DIC Zone X 6 [px];DIC Zone Y 6 [px]
0;0;0;0;0.0003136;0;0;0;0;0;0;0;0;0;0;0;0;0
1.001;1.6202e-05;-1.4534e-05;1.5278e-05;0.0003234;0;0;0;0;0;0;0;0;0;0;0;0;0
2;2.8387e-05;-4.3069e-05;3.5034e-05;0.0003234;0;0;0;0;0;0;0;0;0;0;0;0;0
3;2.9282e-05;-8.537e-06;-3.6881e-06;0.0003234;0;0;0;0;0;0;0;0;0;0;0;0;0
4;2.4642e-05;-1.9811e-05;3.7591e-05;0.000343;0;0;0;0;0;0;0;0;0;0;0;0;0
5;0.00033223;-6.7852e-05;9.2744e-06;0.0005782;0;0;0;0;0;0;0;0;0;0;0;0;0
6;0.00037443;-5.2961e-05;-2.2047e-05;0.0011074;0;0;0;0;0;0;0;0;0;0;0;0;0
7;0.00052122;-4.4019e-05;5.839e-05;0.0017934;0;0;0;0;0;0;0;0;0;0;0;0;0
8;0.00048262;-4.7768e-05;4.6292e-05;0.0028812;0;0;0;0;0;0;0;0;0;0;0;0;0
9;0.00050092;-5.3204e-06;3.9422e-05;0.0040474;0;0;0;0;0;0;0;0;0;0;0;0;0
10;0.00073415;6.1283e-05;9.5626e-05;0.0051646;0;0;0;0;0;0;0;0;0;0;0;0;0
11;0.00081844;9.911e-06;7.9886e-05;0.00637;0;0;0;0;0;0;0;0;0;0;0;0;0
12;0.00094786;7.6463e-05;8.9913e-05;0.0074872;0;0;0;0;0;0;0;0;0;0;0;0;0
13;0.00090757;5.0545e-05;9.3824e-05;0.0085554;0;0;0;0;0;0;0;0;0;0;0;0;0
14;0.00098341;3.7259e-05;8.2626e-05;0.0094962;0;0;0;0;0;0;0;0;0;0;0;0;0
15;0.0010656;3.7283e-05;0.00010382;0.010506;0;0;0;0;0;0;0;0;0;0;0;0;0
16;0.0011357;-2.4421e-05;0.00012237;0.011574;0;0;0;0;0;0;0;0;0;0;0;0;0
17;0.0012449;2.7547e-05;0.00011427;0.01276;0;0;0;0;0;0;0;0;0;0;0;0;0
18;0.0012557;7.4099e-05;0.00011607;0.014112;0;0;0;0;0;0;0;0;0;0;0;0;0
19;0.0013374;2.4755e-05;0.00015417;0.015631;0;0;0;0;0;0;0;0;0;0;0;0;0
20;0.0014676;4.187e-05;0.00016702;0.017395;0;0;0;0;0;0;0;0;0;0;0;0;0
21;0.0017545;2.0219e-05;0.00015118;0.019179;0;0;0;0;0;0;0;0;0;0;0;0;0
22;0.0015446;8.9357e-05;0.00018504;0.021227;0;0;0;0;0;0;0;0;0;0;0;0;0
23;0.0014894;-1.0468e-05;0.00017195;0.023579;0;0;0;0;0;0;0;0;0;0;0;0;0
24;0.0021743;4.5095e-05;0.00017148;0.026039;0;0;0;0;0;0;0;0;0;0;0;0;0
25;0.0019044;3.0487e-05;0.00012945;0.028626;0;0;0;0;0;0;0;0;0;0;0;0;0
26;0.0019705;6.4546e-05;0.00012021;0.031487;0;0;0;0;0;0;0;0;0;0;0;0;0
27;0.0022065;6.8188e-05;0.00013324;0.034467;0;0;0;0;0;0;0;0;0;0;0;0;0
28;0.0022827;-1.8583e-05;0.0001607;0.037554;0;0;0;0;0;0;0;0;0;0;0;0;0
29;0.0023958;8.5101e-05;0.00012096;0.040709;0;0;0;0;0;0;0;0;0;0;0;0;0
30;0.00232;4.5888e-05;0.00011198;0.043904;0;0;0;0;0;0;0;0;0;0;0;0;0
31;0.0023287;1.2664e-05;0.00012499;0.047207;0;0;0;0;0;0;0;0;0;0;0;0;0
32;0.0026546;2.6903e-05;0.00012586;0.050656;0;0;0;0;0;0;0;0;0;0;0;0;0
33;0.0027057;4.3119e-05;5.9807e-05;0.05437;0;0;0;0;0;0;0;0;0;0;0;0;0
34;0.0028565;4.9509e-05;6.9325e-05;0.058016;0;0;0;0;0;0;0;0;0;0;0;0;0
35;0.002753;2.1633e-05;0.0001053;0.062093;0;0;0;0;0;0;0;0;0;0;0;0;0
36;0.0031679;2.2525e-05;6.445e-05;0.06614;0;0;0;0;0;0;0;0;0;0;0;0;0
37;0.0033572;5.9139e-05;8.7995e-05;0.070139;0;0;0;0;0;0;0;0;0;0;0;0;0
38.001;0.0034361;3.5071e-05;0.00010014;0.074509;0;0;0;0;0;0;0;0;0;0;0;0;0
39;0.0036756;-4.6478e-05;0.00012702;0.078596;0;0;0;0;0;0;0;0;0;0;0;0;0
40.001;0.0037145;-1.2984e-06;9.1805e-05;0.083075;0;0;0;0;0;0;0;0;0;0;0;0;0
41;0.0039178;5.8731e-06;8.2315e-05;0.08724;0;0;0;0;0;0;0;0;0;0;0;0;0
42;0.004045;-1.3824e-05;7.4788e-05;0.091601;0;0;0;0;0;0;0;0;0;0;0;0;0
43;0.0042505;-7.1944e-06;3.4778e-05;0.096216;0;0;0;0;0;0;0;0;0;0;0;0;0
43.999;0.0044233;6.4487e-05;6.7814e-05;0.1007;0;0;0;0;0;0;0;0;0;0;0;0;0
45.001;0.0045438;6.6992e-05;4.5708e-05;0.10508;0;0;0;0;0;0;0;0;0;0;0;0;0
46;0.0045734;9.1271e-05;2.9604e-05;0.10966;0;0;0;0;0;0;0;0;0;0;0;0;0
47;0.0049455;2.4526e-05;2.3529e-05;0.11428;0;0;0;0;0;0;0;0;0;0;0;0;0
48;0.0051793;8.9755e-05;1.8635e-05;0.11893;0;0;0;0;0;0;0;0;0;0;0;0;0
49;0.0052725;8.0353e-05;3.3089e-05;0.12359;0;0;0;0;0;0;0;0;0;0;0;0;0
50;0.0053544;6.3876e-05;-1.029e-05;0.12829;0;0;0;0;0;0;0;0;0;0;0;0;0
51;0.0056779;0.00013792;-2.332e-05;0.13323;0;0;0;0;0;0;0;0;0;0;0;0;0
52;0.0060191;0.00016997;2.9532e-05;0.13784;0;0;0;0;0;0;0;0;0;0;0;0;0
53;0.0061338;0.0001193;9.2815e-06;0.14289;0;0;0;0;0;0;0;0;0;0;0;0;0
54;0.0064372;0.00014941;-2.0046e-05;0.14761;0;0;0;0;0;0;0;0;0;0;0;0;0
55;0.0066913;0.00016407;-8.0477e-06;0.15251;0;0;0;0;0;0;0;0;0;0;0;0;0
56;0.0075924;0.00017391;-2.7326e-05;0.15757;0;0;0;0;0;0;0;0;0;0;0;0;0
57;0.0071194;0.00021032;-5.3272e-05;0.16229;0;0;0;0;0;0;0;0;0;0;0;0;0
58;0.007227;0.00017637;-6.1684e-05;0.1674;0;0;0;0;0;0;0;0;0;0;0;0;0
59;0.0075519;0.00019623;-8.6028e-05;0.17215;0;0;0;0;0;0;0;0;0;0;0;0;0
60;0.0079502;0.00014727;-9.909e-05;0.17712;0;0;0;0;0;0;0;0;0;0;0;0;0
61;0.0082129;0.00019462;-7.921e-05;0.18205;0;0;0;0;0;0;0;0;0;0;0;0;0
62;0.0084853;0.00019743;-9.4108e-05;0.18698;0;0;0;0;0;0;0;0;0;0;0;0;0
63;0.0088106;0.00020764;-0.00012544;0.19208;0;0;0;0;0;0;0;0;0;0;0;0;0
63.999;0.009138;0.00029469;-0.00013519;0.19673;0;0;0;0;0;0;0;0;0;0;0;0;0
65;0.0095915;0.00031644;-0.00013741;0.20133;0;0;0;0;0;0;0;0;0;0;0;0;0
66;0.010007;0.00037297;-0.00019907;0.20647;0;0;0;0;0;0;0;0;0;0;0;0;0
67;0.010387;0.00037793;-0.00022839;0.21095;0;0;0;0;0;0;0;0;0;0;0;0;0
68;0.01091;0.00035286;-0.00027768;0.21573;0;0;0;0;0;0;0;0;0;0;0;0;0
69;0.01124;0.00040034;-0.0003327;0.22003;0;0;0;0;0;0;0;0;0;0;0;0;0
70;0.011747;0.00041967;-0.0003402;0.22435;0;0;0;0;0;0;0;0;0;0;0;0;0
71;0.012211;0.00053611;-0.00036161;0.22866;0;0;0;0;0;0;0;0;0;0;0;0;0
72;0.012917;0.0005476;-0.00041356;0.23261;0;0;0;0;0;0;0;0;0;0;0;0;0
72.999;0.01345;0.00067587;-0.00044382;0.23622;0;0;0;0;0;0;0;0;0;0;0;0;0
74;0.01416;0.00062889;-0.00047106;0.2399;0;0;0;0;0;0;0;0;0;0;0;0;0
75;0.014814;0.00067846;-0.00049884;0.24311;0;0;0;0;0;0;0;0;0;0;0;0;0
76;0.015659;0.00079466;-0.00054736;0.24626;0;0;0;0;0;0;0;0;0;0;0;0;0
77;0.016363;0.00076986;-0.00061405;0.24938;0;0;0;0;0;0;0;0;0;0;0;0;0
78;0.017234;0.00078248;-0.0005505;0.25214;0;0;0;0;0;0;0;0;0;0;0;0;0
79;0.017825;0.00088756;-0.00064154;0.25504;0;0;0;0;0;0;0;0;0;0;0;0;0
80;0.018481;0.00092319;-0.00066499;0.25763;0;0;0;0;0;0;0;0;0;0;0;0;0
81;0.019446;0.00093489;-0.00073281;0.26026;0;0;0;0;0;0;0;0;0;0;0;0;0
82;0.020107;0.00092461;-0.00072888;0.26278;0;0;0;0;0;0;0;0;0;0;0;0;0
83;0.021029;0.0010731;-0.00076914;0.26522;0;0;0;0;0;0;0;0;0;0;0;0;0
84;0.021835;0.0010851;-0.00075388;0.26769;0;0;0;0;0;0;0;0;0;0;0;0;0
84.999;0.022563;0.0011704;-0.00078672;0.26989;0;0;0;0;0;0;0;0;0;0;0;0;0
85.999;0.023426;0.0012056;-0.00085111;0.27224;0;0;0;0;0;0;0;0;0;0;0;0;0
87;0.024123;0.0012901;-0.0008436;0.27437;0;0;0;0;0;0;0;0;0;0;0;0;0
87.999;0.024971;0.0013428;-0.00088125;0.27661;0;0;0;0;0;0;0;0;0;0;0;0;0
88.999;0.025894;0.0014764;-0.00083879;0.27863;0;0;0;0;0;0;0;0;0;0;0;0;0
90;0.026826;0.001513;-0.00092591;0.28072;0;0;0;0;0;0;0;0;0;0;0;0;0
90.999;0.027774;0.0015893;-0.00090102;0.28279;0;0;0;0;0;0;0;0;0;0;0;0;0
92;0.028671;0.0016946;-0.00096155;0.28481;0;0;0;0;0;0;0;0;0;0;0;0;0
93;0.02955;0.00181;-0.00095156;0.28681;0;0;0;0;0;0;0;0;0;0;0;0;0
94.001;0.030418;0.0018561;-0.0010618;0.28876;0;0;0;0;0;0;0;0;0;0;0;0;0
95;0.031281;0.0020552;-0.0010356;0.29066;0;0;0;0;0;0;0;0;0;0;0;0;0
96;0.032269;0.0020075;-0.0010424;0.29261;0;0;0;0;0;0;0;0;0;0;0;0;0
97;0.033155;0.0021123;-0.0011016;0.2944;0;0;0;0;0;0;0;0;0;0;0;0;0
98;0.034086;0.0021856;-0.0011208;0.29631;0;0;0;0;0;0;0;0;0;0;0;0;0
98.999;0.03497;0.0023068;-0.0011118;0.29804;0;0;0;0;0;0;0;0;0;0;0;0;0
100;0.036036;0.0024412;-0.0011373;0.2998;0;0;0;0;0;0;0;0;0;0;0;0;0
101;0.036778;0.0024751;-0.0011504;0.30151;0;0;0;0;0;0;0;0;0;0;0;0;0
102;0.037884;0.0025919;-0.001138;0.30317;0;0;0;0;0;0;0;0;0;0;0;0;0
103;0.038902;0.0026505;-0.0011791;0.30482;0;0;0;0;0;0;0;0;0;0;0;0;0
104;0.040189;0.0027945;-0.0011673;0.30644;0;0;0;0;0;0;0;0;0;0;0;0;0
105;0.04094;0.0028489;-0.001191;0.3081;0;0;0;0;0;0;0;0;0;0;0;0;0
106;0.041803;0.002906;-0.0012112;0.30961;0;0;0;0;0;0;0;0;0;0;0;0;0
107;0.042741;0.0031681;-0.0012229;0.31122;0;0;0;0;0;0;0;0;0;0;0;0;0
108;0.043793;0.0031447;-0.0012771;0.31275;0;0;0;0;0;0;0;0;0;0;0;0;0
109;0.044765;0.0032716;-0.0012621;0.31418;0;0;0;0;0;0;0;0;0;0;0;0;0
110;0.045956;0.003435;-0.0012616;0.31571;0;0;0;0;0;0;0;0;0;0;0;0;0
111;0.046524;0.0033947;-0.0012723;0.31709;0;0;0;0;0;0;0;0;0;0;0;0;0
112;0.04771;0.0035337;-0.0012828;0.31854;0;0;0;0;0;0;0;0;0;0;0;0;0
113;0.048671;0.0036482;-0.0013433;0.31985;0;0;0;0;0;0;0;0;0;0;0;0;0
114;0.049562;0.0036328;-0.001346;0.32127;0;0;0;0;0;0;0;0;0;0;0;0;0
115;0.050537;0.0038098;-0.001367;0.32262;0;0;0;0;0;0;0;0;0;0;0;0;0
116;0.051718;0.0038735;-0.0013993;0.32389;0;0;0;0;0;0;0;0;0;0;0;0;0
117;0.0528;0.0039759;-0.0013294;0.32525;0;0;0;0;0;0;0;0;0;0;0;0;0
118;0.053839;0.0041056;-0.0014064;0.32649;0;0;0;0;0;0;0;0;0;0;0;0;0
119;0.054831;0.0041431;-0.0014228;0.32782;0;0;0;0;0;0;0;0;0;0;0;0;0
120;0.05591;0.0043406;-0.0014624;0.32908;0;0;0;0;0;0;0;0;0;0;0;0;0
121;0.056996;0.0043711;-0.0014473;0.33028;0;0;0;0;0;0;0;0;0;0;0;0;0
122;0.057883;0.0044046;-0.0014669;0.33153;0;0;0;0;0;0;0;0;0;0;0;0;0
123;0.058968;0.0045882;-0.0014853;0.33269;0;0;0;0;0;0;0;0;0;0;0;0;0
124;0.060078;0.0046816;-0.0015212;0.33387;0;0;0;0;0;0;0;0;0;0;0;0;0
125;0.061214;0.0047391;-0.0015179;0.33508;0;0;0;0;0;0;0;0;0;0;0;0;0
126;0.062313;0.0048191;-0.0015205;0.3362;0;0;0;0;0;0;0;0;0;0;0;0;0
127;0.063405;0.0049361;-0.0015494;0.33738;0;0;0;0;0;0;0;0;0;0;0;0;0
128;0.064445;0.0049609;-0.0015496;0.33845;0;0;0;0;0;0;0;0;0;0;0;0;0
129;0.065857;0.0051637;-0.0015937;0.33949;0;0;0;0;0;0;0;0;0;0;0;0;0
130;0.06644;0.0051942;-0.0016837;0.3406;0;0;0;0;0;0;0;0;0;0;0;0;0
131;0.067486;0.00524;-0.0016839;0.34166;0;0;0;0;0;0;0;0;0;0;0;0;0
132;0.068603;0.005396;-0.001729;0.34276;0;0;0;0;0;0;0;0;0;0;0;0;0
133;0.069835;0.0054792;-0.0017647;0.34376;0;0;0;0;0;0;0;0;0;0;0;0;0
134;0.070681;0.0055337;-0.001776;0.34484;0;0;0;0;0;0;0;0;0;0;0;0;0
135;0.071779;0.0056082;-0.0018014;0.34581;0;0;0;0;0;0;0;0;0;0;0;0;0
136;0.07285;0.0057794;-0.0018394;0.34684;0;0;0;0;0;0;0;0;0;0;0;0;0
137;0.073916;0.0059203;-0.0018828;0.34778;0;0;0;0;0;0;0;0;0;0;0;0;0
138;0.075044;0.0059534;-0.0019026;0.34868;0;0;0;0;0;0;0;0;0;0;0;0;0
139;0.075946;0.006061;-0.0019682;0.34967;0;0;0;0;0;0;0;0;0;0;0;0;0
140;0.076852;0.0061859;-0.0020081;0.35059;0;0;0;0;0;0;0;0;0;0;0;0;0
141;0.078071;0.0061937;-0.0021017;0.35153;0;0;0;0;0;0;0;0;0;0;0;0;0
142;0.079319;0.0063191;-0.0021002;0.35246;0;0;0;0;0;0;0;0;0;0;0;0;0
143;0.080389;0.0064467;-0.0021588;0.35341;0;0;0;0;0;0;0;0;0;0;0;0;0
144;0.081531;0.0064937;-0.0021782;0.35428;0;0;0;0;0;0;0;0;0;0;0;0;0
145;0.082574;0.0066374;-0.0022513;0.35519;0;0;0;0;0;0;0;0;0;0;0;0;0
146;0.083627;0.0067354;-0.0022684;0.35607;0;0;0;0;0;0;0;0;0;0;0;0;0
147;0.084845;0.0068773;-0.0023448;0.35692;0;0;0;0;0;0;0;0;0;0;0;0;0
148;0.085905;0.0070017;-0.002365;0.35781;0;0;0;0;0;0;0;0;0;0;0;0;0
149;0.086784;0.0071339;-0.0023966;0.35866;0;0;0;0;0;0;0;0;0;0;0;0;0
150;0.08804;0.0072393;-0.0024172;0.35944;0;0;0;0;0;0;0;0;0;0;0;0;0
151;0.089277;0.0072948;-0.0024931;0.36028;0;0;0;0;0;0;0;0;0;0;0;0;0
152;0.090117;0.0074375;-0.0025393;0.36103;0;0;0;0;0;0;0;0;0;0;0;0;0
153;0.091359;0.0075706;-0.0025768;0.36182;0;0;0;0;0;0;0;0;0;0;0;0;0
154;0.092535;0.0076771;-0.0026016;0.3626;0;0;0;0;0;0;0;0;0;0;0;0;0
155;0.093645;0.007745;-0.0026751;0.36338;0;0;0;0;0;0;0;0;0;0;0;0;0
156;0.09504;0.0078718;-0.0027033;0.36418;0;0;0;0;0;0;0;0;0;0;0;0;0
157;0.095735;0.0080391;-0.002725;0.36489;0;0;0;0;0;0;0;0;0;0;0;0;0
158;0.096882;0.0080936;-0.0027494;0.36564;0;0;0;0;0;0;0;0;0;0;0;0;0
159;0.098032;0.0082725;-0.0028106;0.36637;0;0;0;0;0;0;0;0;0;0;0;0;0
160;0.099095;0.0083659;-0.0028355;0.3671;0;0;0;0;0;0;0;0;0;0;0;0;0
161;0.10017;0.0085322;-0.002886;0.36785;0;0;0;0;0;0;0;0;0;0;0;0;0
162;0.10149;0.0085743;-0.0029282;0.36854;0;0;0;0;0;0;0;0;0;0;0;0;0
163;0.10227;0.0087008;-0.0029467;0.36921;0;0;0;0;0;0;0;0;0;0;0;0;0
164;0.10359;0.0088305;-0.0030022;0.36992;0;0;0;0;0;0;0;0;0;0;0;0;0
165;0.1049;0.0090154;-0.0030344;0.37058;0;0;0;0;0;0;0;0;0;0;0;0;0
166;0.10577;0.0090766;-0.0030753;0.37127;0;0;0;0;0;0;0;0;0;0;0;0;0
167;0.1069;0.0092279;-0.003093;0.37197;0;0;0;0;0;0;0;0;0;0;0;0;0
168;0.10776;0.0093648;-0.0031826;0.3726;0;0;0;0;0;0;0;0;0;0;0;0;0
169;0.10922;0.0095377;-0.0031992;0.3733;0;0;0;0;0;0;0;0;0;0;0;0;0
170;0.11035;0.0096256;-0.0032158;0.37391;0;0;0;0;0;0;0;0;0;0;0;0;0
171;0.11152;0.0097875;-0.0032685;0.37453;0;0;0;0;0;0;0;0;0;0;0;0;0
172;0.11262;0.0099444;-0.0032994;0.37513;0;0;0;0;0;0;0;0;0;0;0;0;0
173;0.11381;0.010093;-0.003327;0.37578;0;0;0;0;0;0;0;0;0;0;0;0;0
174;0.11485;0.010206;-0.0033614;0.3764;0;0;0;0;0;0;0;0;0;0;0;0;0
175;0.1159;0.010364;-0.0033918;0.37697;0;0;0;0;0;0;0;0;0;0;0;0;0
176;0.11707;0.010517;-0.0034504;0.37757;0;0;0;0;0;0;0;0;0;0;0;0;0
177;0.11835;0.010623;-0.0034756;0.37815;0;0;0;0;0;0;0;0;0;0;0;0;0
178;0.11947;0.010707;-0.0035189;0.37873;0;0;0;0;0;0;0;0;0;0;0;0;0
179;0.12056;0.01087;-0.0036221;0.37933;0;0;0;0;0;0;0;0;0;0;0;0;0
180;0.12176;0.011069;-0.0036104;0.3799;0;0;0;0;0;0;0;0;0;0;0;0;0
181;0.12293;0.011147;-0.0036499;0.38046;0;0;0;0;0;0;0;0;0;0;0;0;0
182;0.12405;0.011353;-0.0036873;0.381;0;0;0;0;0;0;0;0;0;0;0;0;0
183;0.12525;0.011511;-0.003716;0.38153;0;0;0;0;0;0;0;0;0;0;0;0;0
184;0.12631;0.011649;-0.0038338;0.38205;0;0;0;0;0;0;0;0;0;0;0;0;0
185;0.1276;0.011695;-0.0038348;0.38258;0;0;0;0;0;0;0;0;0;0;0;0;0
186;0.12867;0.011748;-0.0039008;0.38314;0;0;0;0;0;0;0;0;0;0;0;0;0
187;0.12988;0.011952;-0.0039387;0.38364;0;0;0;0;0;0;0;0;0;0;0;0;0
188;0.1311;0.012141;-0.0039731;0.38419;0;0;0;0;0;0;0;0;0;0;0;0;0
189;0.13203;0.012234;-0.0040741;0.38471;0;0;0;0;0;0;0;0;0;0;0;0;0
190;0.13324;0.012315;-0.0041168;0.38517;0;0;0;0;0;0;0;0;0;0;0;0;0
191;0.13454;0.012441;-0.0042108;0.38567;0;0;0;0;0;0;0;0;0;0;0;0;0
192;0.13558;0.012615;-0.0042477;0.38615;0;0;0;0;0;0;0;0;0;0;0;0;0
193;0.13685;0.012776;-0.0042551;0.38661;0;0;0;0;0;0;0;0;0;0;0;0;0
194;0.13801;0.01286;-0.0043636;0.38714;0;0;0;0;0;0;0;0;0;0;0;0;0
195;0.13934;0.013004;-0.0043819;0.38761;0;0;0;0;0;0;0;0;0;0;0;0;0
196;0.14018;0.013071;-0.0044579;0.3881;0;0;0;0;0;0;0;0;0;0;0;0;0
197;0.14138;0.01322;-0.0045366;0.38855;0;0;0;0;0;0;0;0;0;0;0;0;0
198;0.14251;0.013327;-0.0045638;0.38901;0;0;0;0;0;0;0;0;0;0;0;0;0
199;0.14391;0.013456;-0.0046774;0.38942;0;0;0;0;0;0;0;0;0;0;0;0;0
200;0.14515;0.013648;-0.0046843;0.38984;0;0;0;0;0;0;0;0;0;0;0;0;0
201;0.14573;0.01376;-0.0047711;0.39028;0;0;0;0;0;0;0;0;0;0;0;0;0
202;0.1474;0.013899;-0.004851;0.3907;0;0;0;0;0;0;0;0;0;0;0;0;0
203;0.14868;0.014069;-0.0048935;0.39114;0;0;0;0;0;0;0;0;0;0;0;0;0
204;0.14975;0.01423;-0.0049324;0.39154;0;0;0;0;0;0;0;0;0;0;0;0;0
205;0.15096;0.014324;-0.0050112;0.39195;0;0;0;0;0;0;0;0;0;0;0;0;0
206;0.15225;0.014538;-0.0050273;0.39234;0;0;0;0;0;0;0;0;0;0;0;0;0
207;0.15333;0.014693;-0.0051039;0.39274;0;0;0;0;0;0;0;0;0;0;0;0;0
208;0.15456;0.01487;-0.0051052;0.39314;0;0;0;0;0;0;0;0;0;0;0;0;0
209;0.15571;0.015005;-0.0052109;0.39352;0;0;0;0;0;0;0;0;0;0;0;0;0
210;0.15689;0.015179;-0.0052507;0.39392;0;0;0;0;0;0;0;0;0;0;0;0;0
211;0.15799;0.015308;-0.0052843;0.39427;0;0;0;0;0;0;0;0;0;0;0;0;0
212;0.15936;0.015528;-0.0053676;0.39465;0;0;0;0;0;0;0;0;0;0;0;0;0
213;0.16054;0.015648;-0.0053978;0.39503;0;0;0;0;0;0;0;0;0;0;0;0;0
214;0.16155;0.015846;-0.0054653;0.3954;0;0;0;0;0;0;0;0;0;0;0;0;0
215;0.16277;0.015933;-0.005538;0.39581;0;0;0;0;0;0;0;0;0;0;0;0;0
216;0.164;0.016131;-0.0056026;0.39616;0;0;0;0;0;0;0;0;0;0;0;0;0
217;0.16516;0.01631;-0.0056735;0.39651;0;0;0;0;0;0;0;0;0;0;0;0;0
218;0.16636;0.016473;-0.0057291;0.39684;0;0;0;0;0;0;0;0;0;0;0;0;0
219;0.16752;0.016559;-0.0057832;0.39717;0;0;0;0;0;0;0;0;0;0;0;0;0
220;0.16871;0.016681;-0.0058738;0.39749;0;0;0;0;0;0;0;0;0;0;0;0;0
221;0.16987;0.016863;-0.0059206;0.39783;0;0;0;0;0;0;0;0;0;0;0;0;0
222;0.17112;0.017027;-0.0059808;0.39814;0;0;0;0;0;0;0;0;0;0;0;0;0
223;0.17238;0.017298;-0.0060438;0.39847;0;0;0;0;0;0;0;0;0;0;0;0;0
224;0.17335;0.017371;-0.0061558;0.39878;0;0;0;0;0;0;0;0;0;0;0;0;0
225;0.17462;0.017586;-0.0061803;0.3991;0;0;0;0;0;0;0;0;0;0;0;0;0
226;0.1759;0.017759;-0.006302;0.39941;0;0;0;0;0;0;0;0;0;0;0;0;0
227;0.17713;0.017953;-0.0063252;0.39972;0;0;0;0;0;0;0;0;0;0;0;0;0
228;0.17838;0.018175;-0.006377;0.40003;0;0;0;0;0;0;0;0;0;0;0;0;0
229;0.17937;0.01836;-0.0064974;0.4003;0;0;0;0;0;0;0;0;0;0;0;0;0
230;0.18079;0.018557;-0.0065468;0.4006;0;0;0;0;0;0;0;0;0;0;0;0;0
231;0.18188;0.018766;-0.0066276;0.40086;0;0;0;0;0;0;0;0;0;0;0;0;0
232;0.18308;0.018978;-0.0066622;0.40113;0;0;0;0;0;0;0;0;0;0;0;0;0
233;0.18417;0.019168;-0.0067161;0.40143;0;0;0;0;0;0;0;0;0;0;0;0;0
234;0.18556;0.019407;-0.0067894;0.40168;0;0;0;0;0;0;0;0;0;0;0;0;0
235;0.18673;0.019565;-0.0068764;0.40194;0;0;0;0;0;0;0;0;0;0;0;0;0
236;0.18788;0.019728;-0.0069113;0.4022;0;0;0;0;0;0;0;0;0;0;0;0;0
237;0.18974;0.020021;-0.0069917;0.40244;0;0;0;0;0;0;0;0;0;0;0;0;0
238;0.19047;0.020237;-0.0070698;0.40267;0;0;0;0;0;0;0;0;0;0;0;0;0
239;0.19168;0.02047;-0.0071497;0.40292;0;0;0;0;0;0;0;0;0;0;0;0;0
240;0.1929;0.020639;-0.0072663;0.40315;0;0;0;0;0;0;0;0;0;0;0;0;0
241;0.19415;0.020923;-0.0072952;0.40339;0;0;0;0;0;0;0;0;0;0;0;0;0
242;0.19557;0.021183;-0.0073535;0.40362;0;0;0;0;0;0;0;0;0;0;0;0;0
243;0.19653;0.021392;-0.0074811;0.40385;0;0;0;0;0;0;0;0;0;0;0;0;0
244;0.19783;0.021651;-0.0075443;0.40405;0;0;0;0;0;0;0;0;0;0;0;0;0
245;0.19897;0.021857;-0.0076058;0.40427;0;0;0;0;0;0;0;0;0;0;0;0;0
246;0.20022;0.022165;-0.0076714;0.40448;0;0;0;0;0;0;0;0;0;0;0;0;0
247;0.20134;0.022302;-0.0077852;0.40467;0;0;0;0;0;0;0;0;0;0;0;0;0
248;0.20257;0.022602;-0.0078602;0.40487;0;0;0;0;0;0;0;0;0;0;0;0;0
249;0.20394;0.02283;-0.0079651;0.40504;0;0;0;0;0;0;0;0;0;0;0;0;0
250;0.20576;0.023102;-0.0080476;0.40524;0;0;0;0;0;0;0;0;0;0;0;0;0
251;0.20627;0.023219;-0.0081465;0.40544;0;0;0;0;0;0;0;0;0;0;0;0;0
252;0.20755;0.023413;-0.0082448;0.40561;0;0;0;0;0;0;0;0;0;0;0;0;0
253;0.20884;0.023716;-0.0083533;0.4058;0;0;0;0;0;0;0;0;0;0;0;0;0
254;0.21047;0.023972;-0.0083855;0.40597;0;0;0;0;0;0;0;0;0;0;0;0;0
255;0.21126;0.024164;-0.0084945;0.40614;0;0;0;0;0;0;0;0;0;0;0;0;0
256;0.21232;0.024451;-0.008589;0.4063;0;0;0;0;0;0;0;0;0;0;0;0;0
257;0.21393;0.024693;-0.0087035;0.40646;0;0;0;0;0;0;0;0;0;0;0;0;0
258;0.215;0.024884;-0.0087943;0.4066;0;0;0;0;0;0;0;0;0;0;0;0;0
259;0.21617;0.02511;-0.0088606;0.40673;0;0;0;0;0;0;0;0;0;0;0;0;0
260;0.21739;0.025461;-0.0089541;0.40687;0;0;0;0;0;0;0;0;0;0;0;0;0
261;0.21888;0.025679;-0.0090425;0.407;0;0;0;0;0;0;0;0;0;0;0;0;0
262;0.22;0.025913;-0.00916;0.40715;0;0;0;0;0;0;0;0;0;0;0;0;0
263;0.22127;0.026172;-0.0092284;0.40729;0;0;0;0;0;0;0;0;0;0;0;0;0
264;0.2225;0.02646;-0.009302;0.40741;0;0;0;0;0;0;0;0;0;0;0;0;0
265;0.22381;0.026662;-0.0093716;0.40753;0;0;0;0;0;0;0;0;0;0;0;0;0
266;0.22497;0.026971;-0.0094086;0.40765;0;0;0;0;0;0;0;0;0;0;0;0;0
267;0.22637;0.027266;-0.0095353;0.40777;0;0;0;0;0;0;0;0;0;0;0;0;0
268;0.22753;0.027523;-0.009688;0.40788;0;0;0;0;0;0;0;0;0;0;0;0;0
269;0.22878;0.027747;-0.0097899;0.40797;0;0;0;0;0;0;0;0;0;0;0;0;0
270;0.23004;0.028055;-0.0098557;0.40806;0;0;0;0;0;0;0;0;0;0;0;0;0
271;0.23118;0.028356;-0.0099172;0.40816;0;0;0;0;0;0;0;0;0;0;0;0;0
272;0.23256;0.028713;-0.010009;0.40826;0;0;0;0;0;0;0;0;0;0;0;0;0
273;0.23384;0.02898;-0.010134;0.40836;0;0;0;0;0;0;0;0;0;0;0;0;0
274;0.23506;0.029334;-0.010258;0.40842;0;0;0;0;0;0;0;0;0;0;0;0;0
275;0.23622;0.029707;-0.010266;0.4085;0;0;0;0;0;0;0;0;0;0;0;0;0
276;0.23754;0.029998;-0.010365;0.40855;0;0;0;0;0;0;0;0;0;0;0;0;0
277;0.2388;0.030368;-0.010461;0.40861;0;0;0;0;0;0;0;0;0;0;0;0;0
278;0.24016;0.030703;-0.01057;0.40867;0;0;0;0;0;0;0;0;0;0;0;0;0
279;0.24138;0.031072;-0.010652;0.40871;0;0;0;0;0;0;0;0;0;0;0;0;0
280;0.24271;0.03144;-0.010768;0.40876;0;0;0;0;0;0;0;0;0;0;0;0;0
281;0.24396;0.031861;-0.01087;0.40881;0;0;0;0;0;0;0;0;0;0;0;0;0
282;0.24526;0.032242;-0.010924;0.40885;0;0;0;0;0;0;0;0;0;0;0;0;0
283;0.24649;0.032565;-0.011058;0.40888;0;0;0;0;0;0;0;0;0;0;0;0;0
284;0.24779;0.033017;-0.011112;0.40891;0;0;0;0;0;0;0;0;0;0;0;0;0
285;0.24906;0.033398;-0.011208;0.40893;0;0;0;0;0;0;0;0;0;0;0;0;0
286;0.25033;0.033775;-0.011299;0.40895;0;0;0;0;0;0;0;0;0;0;0;0;0
287;0.25163;0.034149;-0.011419;0.40896;0;0;0;0;0;0;0;0;0;0;0;0;0
288;0.25297;0.034496;-0.011499;0.40898;0;0;0;0;0;0;0;0;0;0;0;0;0
289;0.2542;0.034864;-0.011643;0.40898;0;0;0;0;0;0;0;0;0;0;0;0;0
290;0.25551;0.035313;-0.011718;0.40898;0;0;0;0;0;0;0;0;0;0;0;0;0
291;0.2568;0.035755;-0.011863;0.40898;0;0;0;0;0;0;0;0;0;0;0;0;0
292;0.25812;0.036104;-0.011957;0.40897;0;0;0;0;0;0;0;0;0;0;0;0;0
293;0.25938;0.036499;-0.012114;0.40897;0;0;0;0;0;0;0;0;0;0;0;0;0
294;0.26084;0.036912;-0.01222;0.40896;0;0;0;0;0;0;0;0;0;0;0;0;0
295;0.26267;0.037361;-0.012338;0.40894;0;0;0;0;0;0;0;0;0;0;0;0;0
296;0.26319;0.037735;-0.012572;0.40891;0;0;0;0;0;0;0;0;0;0;0;0;0
297;0.26452;0.038185;-0.012664;0.4089;0;0;0;0;0;0;0;0;0;0;0;0;0
298;0.26609;0.038612;-0.012744;0.40889;0;0;0;0;0;0;0;0;0;0;0;0;0
299;0.26703;0.039052;-0.012898;0.40888;0;0;0;0;0;0;0;0;0;0;0;0;0
300;0.2684;0.039548;-0.013068;0.40887;0;0;0;0;0;0;0;0;0;0;0;0;0
301;0.26947;0.03996;-0.013215;0.40885;0;0;0;0;0;0;0;0;0;0;0;0;0
302;0.27108;0.040415;-0.013357;0.40883;0;0;0;0;0;0;0;0;0;0;0;0;0
303;0.27221;0.040928;-0.013495;0.40881;0;0;0;0;0;0;0;0;0;0;0;0;0
304;0.27359;0.041341;-0.013635;0.40879;0;0;0;0;0;0;0;0;0;0;0;0;0
305;0.27491;0.041892;-0.013791;0.40877;0;0;0;0;0;0;0;0;0;0;0;0;0
306;0.2762;0.042311;-0.013905;0.40875;0;0;0;0;0;0;0;0;0;0;0;0;0
307;0.27742;0.042798;-0.014014;0.40873;0;0;0;0;0;0;0;0;0;0;0;0;0
308;0.27875;0.043394;-0.014145;0.4087;0;0;0;0;0;0;0;0;0;0;0;0;0
309;0.28007;0.043876;-0.014238;0.40867;0;0;0;0;0;0;0;0;0;0;0;0;0
310;0.28119;0.044422;-0.014388;0.40866;0;0;0;0;0;0;0;0;0;0;0;0;0
311;0.28263;0.044964;-0.014529;0.40863;0;0;0;0;0;0;0;0;0;0;0;0;0
312;0.28405;0.045628;-0.014595;0.40862;0;0;0;0;0;0;0;0;0;0;0;0;0
313;0.28542;0.046163;-0.014685;0.4086;0;0;0;0;0;0;0;0;0;0;0;0;0
314;0.28694;0.046754;-0.014816;0.40856;0;0;0;0;0;0;0;0;0;0;0;0;0
315;0.28796;0.047317;-0.014926;0.40854;0;0;0;0;0;0;0;0;0;0;0;0;0
316;0.28942;0.047931;-0.0151;0.40851;0;0;0;0;0;0;0;0;0;0;0;0;0
317;0.2903;0.048601;-0.015246;0.40847;0;0;0;0;0;0;0;0;0;0;0;0;0
318;0.29207;0.04922;-0.015346;0.40845;0;0;0;0;0;0;0;0;0;0;0;0;0
319;0.29369;0.049887;-0.015493;0.40842;0;0;0;0;0;0;0;0;0;0;0;0;0
320;0.29477;0.050525;-0.015606;0.40838;0;0;0;0;0;0;0;0;0;0;0;0;0
321;0.29615;0.051217;-0.015739;0.40835;0;0;0;0;0;0;0;0;0;0;0;0;0
322;0.29743;0.05186;-0.015901;0.40829;0;0;0;0;0;0;0;0;0;0;0;0;0
323;0.2988;0.05253;-0.016025;0.40826;0;0;0;0;0;0;0;0;0;0;0;0;0
324;0.29997;0.053178;-0.016143;0.40821;0;0;0;0;0;0;0;0;0;0;0;0;0
325;0.30126;0.053862;-0.016243;0.40816;0;0;0;0;0;0;0;0;0;0;0;0;0
326;0.3028;0.054644;-0.016368;0.40811;0;0;0;0;0;0;0;0;0;0;0;0;0
327;0.30406;0.055292;-0.016445;0.40805;0;0;0;0;0;0;0;0;0;0;0;0;0
328;0.3055;0.055999;-0.016597;0.40801;0;0;0;0;0;0;0;0;0;0;0;0;0
329;0.30693;0.056783;-0.016664;0.40798;0;0;0;0;0;0;0;0;0;0;0;0;0
330;0.30816;0.057507;-0.016867;0.40793;0;0;0;0;0;0;0;0;0;0;0;0;0
331;0.3095;0.058279;-0.016944;0.40788;0;0;0;0;0;0;0;0;0;0;0;0;0
332;0.31072;0.059011;-0.017112;0.40779;0;0;0;0;0;0;0;0;0;0;0;0;0
333;0.31202;0.05978;-0.01716;0.40769;0;0;0;0;0;0;0;0;0;0;0;0;0
334;0.31343;0.060531;-0.017284;0.40758;0;0;0;0;0;0;0;0;0;0;0;0;0
335;0.31478;0.061355;-0.017374;0.40748;0;0;0;0;0;0;0;0;0;0;0;0;0
336;0.3161;0.062164;-0.017529;0.4074;0;0;0;0;0;0;0;0;0;0;0;0;0
337;0.31766;0.062873;-0.017568;0.4073;0;0;0;0;0;0;0;0;0;0;0;0;0
338;0.31895;0.063715;-0.017714;0.40722;0;0;0;0;0;0;0;0;0;0;0;0;0
339;0.32039;0.064555;-0.017841;0.40709;0;0;0;0;0;0;0;0;0;0;0;0;0
340;0.32165;0.065356;-0.017994;0.40696;0;0;0;0;0;0;0;0;0;0;0;0;0
341;0.32312;0.066277;-0.018098;0.40682;0;0;0;0;0;0;0;0;0;0;0;0;0
342;0.32442;0.067132;-0.018265;0.40666;0;0;0;0;0;0;0;0;0;0;0;0;0
343;0.32599;0.067989;-0.018431;0.40647;0;0;0;0;0;0;0;0;0;0;0;0;0
344;0.32739;0.068855;-0.018598;0.40627;0;0;0;0;0;0;0;0;0;0;0;0;0
345;0.32867;0.069707;-0.018752;0.40603;0;0;0;0;0;0;0;0;0;0;0;0;0
346;0.33034;0.070625;-0.018909;0.40577;0;0;0;0;0;0;0;0;0;0;0;0;0
347;0.33156;0.071406;-0.019067;0.40548;0;0;0;0;0;0;0;0;0;0;0;0;0
348;0.33325;0.072285;-0.019287;0.40517;0;0;0;0;0;0;0;0;0;0;0;0;0
349;0.33468;0.073194;-0.019569;0.40483;0;0;0;0;0;0;0;0;0;0;0;0;0
350;0.33613;0.07407;-0.019763;0.40448;0;0;0;0;0;0;0;0;0;0;0;0;0
351;0.33768;0.074897;-0.019967;0.40406;0;0;0;0;0;0;0;0;0;0;0;0;0
352;0.33898;0.075804;-0.020207;0.40367;0;0;0;0;0;0;0;0;0;0;0;0;0
353;0.34041;0.076628;-0.02047;0.40324;0;0;0;0;0;0;0;0;0;0;0;0;0
354;0.34185;0.077606;-0.02058;0.40276;0;0;0;0;0;0;0;0;0;0;0;0;0
355;0.34317;0.078497;-0.02075;0.40228;0;0;0;0;0;0;0;0;0;0;0;0;0
356;0.34474;0.079505;-0.020884;0.40175;0;0;0;0;0;0;0;0;0;0;0;0;0
357;0.34618;0.080516;-0.020982;0.4012;0;0;0;0;0;0;0;0;0;0;0;0;0
358;0.34744;0.081528;-0.021111;0.40065;0;0;0;0;0;0;0;0;0;0;0;0;0
359;0.34891;0.082543;-0.021227;0.40006;0;0;0;0;0;0;0;0;0;0;0;0;0
360;0.35029;0.083542;-0.021399;0.39947;0;0;0;0;0;0;0;0;0;0;0;0;0
361;0.35171;0.084503;-0.02148;0.39888;0;0;0;0;0;0;0;0;0;0;0;0;0
362;0.35306;0.085447;-0.021587;0.39827;0;0;0;0;0;0;0;0;0;0;0;0;0
363;0.35436;0.08636;-0.021666;0.39761;0;0;0;0;0;0;0;0;0;0;0;0;0
364;0.35575;0.08728;-0.021811;0.39699;0;0;0;0;0;0;0;0;0;0;0;0;0
365;0.35698;0.08816;-0.021972;0.39632;0;0;0;0;0;0;0;0;0;0;0;0;0
366;0.35835;0.089162;-0.022131;0.39561;0;0;0;0;0;0;0;0;0;0;0;0;0
367;0.35989;0.090108;-0.022227;0.39491;0;0;0;0;0;0;0;0;0;0;0;0;0
368;0.36128;0.09114;-0.022368;0.39416;0;0;0;0;0;0;0;0;0;0;0;0;0
369;0.36246;0.09223;-0.022536;0.39338;0;0;0;0;0;0;0;0;0;0;0;0;0
370;0.36422;0.093388;-0.022645;0.39266;0;0;0;0;0;0;0;0;0;0;0;0;0
371;0.36553;0.094659;-0.0228;0.39184;0;0;0;0;0;0;0;0;0;0;0;0;0
372;0.36676;0.095869;-0.023013;0.39106;0;0;0;0;0;0;0;0;0;0;0;0;0
373;0.36829;0.097239;-0.023165;0.39021;0;0;0;0;0;0;0;0;0;0;0;0;0
374;0.36928;0.098652;-0.02328;0.38938;0;0;0;0;0;0;0;0;0;0;0;0;0
375;0.37103;0.099878;-0.023511;0.38851;0;0;0;0;0;0;0;0;0;0;0;0;0
376;0.37254;0.10119;-0.023641;0.38759;0;0;0;0;0;0;0;0;0;0;0;0;0
377;0.37399;0.10245;-0.023742;0.38673;0;0;0;0;0;0;0;0;0;0;0;0;0
378;0.37535;0.10366;-0.023865;0.38579;0;0;0;0;0;0;0;0;0;0;0;0;0
379;0.37644;0.10483;-0.023895;0.38483;0;0;0;0;0;0;0;0;0;0;0;0;0
380;0.37803;0.10602;-0.023981;0.38383;0;0;0;0;0;0;0;0;0;0;0;0;0
381;0.37948;0.10733;-0.024111;0.38287;0;0;0;0;0;0;0;0;0;0;0;0;0
382;0.38095;0.10851;-0.024198;0.3818;0;0;0;0;0;0;0;0;0;0;0;0;0
383;0.38243;0.10985;-0.024246;0.38079;0;0;0;0;0;0;0;0;0;0;0;0;0
384;0.38381;0.11115;-0.024316;0.37969;0;0;0;0;0;0;0;0;0;0;0;0;0
385;0.38513;0.11249;-0.024366;0.37856;0;0;0;0;0;0;0;0;0;0;0;0;0
386;0.38667;0.11378;-0.024423;0.37741;0;0;0;0;0;0;0;0;0;0;0;0;0
387;0.38823;0.11519;-0.024442;0.37621;0;0;0;0;0;0;0;0;0;0;0;0;0
388;0.38953;0.11645;-0.024431;0.37499;0;0;0;0;0;0;0;0;0;0;0;0;0
389;0.3911;0.11779;-0.024425;0.37368;0;0;0;0;0;0;0;0;0;0;0;0;0
390;0.39256;0.11926;-0.024367;0.37239;0;0;0;0;0;0;0;0;0;0;0;0;0
391;0.39394;0.12055;-0.02435;0.37111;0;0;0;0;0;0;0;0;0;0;0;0;0
392;0.3955;0.12183;-0.024257;0.36971;0;0;0;0;0;0;0;0;0;0;0;0;0
393;0.39706;0.12331;-0.024171;0.36827;0;0;0;0;0;0;0;0;0;0;0;0;0
394;0.39851;0.12494;-0.024082;0.36678;0;0;0;0;0;0;0;0;0;0;0;0;0
395;0.40009;0.12669;-0.024185;0.36524;0;0;0;0;0;0;0;0;0;0;0;0;0
396;0.40165;0.12831;-0.024116;0.36362;0;0;0;0;0;0;0;0;0;0;0;0;0
397;0.40308;0.12975;-0.024239;0.36195;0;0;0;0;0;0;0;0;0;0;0;0;0
398;0.40487;0.13143;-0.024474;0.36021;0;0;0;0;0;0;0;0;0;0;0;0;0
399;0.40627;0.13317;-0.024423;0.35826;0;0;0;0;0;0;0;0;0;0;0;0;0
400;0.40809;0.13489;-0.024494;0.35636;0;0;0;0;0;0;0;0;0;0;0;0;0
401;0.40978;0.1366;-0.024465;0.35417;0;0;0;0;0;0;0;0;0;0;0;0;0
402;0.41178;0.13861;-0.024829;0.35193;0;0;0;0;0;0;0;0;0;0;0;0;0
403;0.415;0.142;-0.024803;0.3495;0;0;0;0;0;0;0;0;0;0;0;0;0