File: Template_Auto_Cali_large_DP600/_data/DP600Large_NT6_00_002_Front_DIC_File.txt
Date of Test;Material;Sample Geometry;Orientation [°];Test Number;Nominal Speed [mm/min];Thickness [mm];Central Width [mm];Gauge Width / Diameter [mm];Pixel to mm ratio [mm/px];Extensometer 1-4 [mm];Extensometer 2-3 [mm];Extensometer 5-6 [mm];;;;;
09/07/21;DP600Large;NT6;00;2;0.0798;0.28843;2;4;0;6;0.2;0.4;;;;;
;;;;;;;;;;;;;;;;;
Time [s];U1 [mm];U2 [mm];U3 [mm];Force [kN];Ambient Temperature [°C];DIC Zone X 1 [px];DIC Zone Y 1 [px];DIC Zone X 2 [px];DIC Zone Y 2 [px];DIC Zone X 3 [px];DIC Zone Y 3 [px];DIC Zone X 4 [px];DIC Zone Y 4 [px];DIC Zone X 5 [px];DIC Zone Y 5 [px];DIC Zone X 6 [px];DIC Zone Y 6 [px]
0;0;0;0;0.0001862;0;0;0;0;0;0;0;0;0;0;0;0;0
1;-0.00016888;-9.1115e-05;-6.3835e-05;0.000196;0;0;0;0;0;0;0;0;0;0;0;0;0
2;-8.3649e-05;-3.9804e-05;-7.2451e-05;0.0003332;0;0;0;0;0;0;0;0;0;0;0;0;0
3.001;0.00025632;-0.00011111;3.1027e-05;0.0008624;0;0;0;0;0;0;0;0;0;0;0;0;0
4;0.00035341;-0.00014293;-3.4299e-05;0.0022246;0;0;0;0;0;0;0;0;0;0;0;0;0
5;0.00060535;-0.00014948;-1.4505e-05;0.0041944;0;0;0;0;0;0;0;0;0;0;0;0;0
6;0.00074571;-9.1465e-05;1.0426e-05;0.006762;0;0;0;0;0;0;0;0;0;0;0;0;0
7;0.00060776;-2.5814e-05;4.3287e-06;0.0096726;0;0;0;0;0;0;0;0;0;0;0;0;0
8;0.0007469;-6.459e-05;-3.3331e-05;0.012299;0;0;0;0;0;0;0;0;0;0;0;0;0
9;0.00080045;-4.8825e-05;-4.6406e-05;0.015102;0;0;0;0;0;0;0;0;0;0;0;0;0
10;0.00095636;-9.4865e-05;2.9743e-05;0.017846;0;0;0;0;0;0;0;0;0;0;0;0;0
11;0.0010311;-7.7987e-05;-3.0309e-05;0.020649;0;0;0;0;0;0;0;0;0;0;0;0;0
12;0.0010842;-5.7841e-05;-5.3046e-06;0.023481;0;0;0;0;0;0;0;0;0;0;0;0;0
13;0.0011041;-0.00013731;-5.318e-05;0.026235;0;0;0;0;0;0;0;0;0;0;0;0;0
14.001;0.0012427;-0.00013573;-7.6257e-05;0.029165;0;0;0;0;0;0;0;0;0;0;0;0;0
15;0.0014014;-6.2905e-05;-4.1843e-06;0.032144;0;0;0;0;0;0;0;0;0;0;0;0;0
16;0.0014431;-6.7664e-05;-1.5953e-05;0.035329;0;0;0;0;0;0;0;0;0;0;0;0;0
17;0.0014146;-0.00013146;3.5366e-06;0.038465;0;0;0;0;0;0;0;0;0;0;0;0;0
18;0.001803;-1.1626e-05;3.7047e-05;0.041738;0;0;0;0;0;0;0;0;0;0;0;0;0
19;0.0017939;-2.6855e-05;6.0299e-06;0.045217;0;0;0;0;0;0;0;0;0;0;0;0;0
20.001;0.0017567;-3.0647e-05;4.1612e-05;0.048775;0;0;0;0;0;0;0;0;0;0;0;0;0
21;0.0018273;-7.9236e-05;-1.4571e-05;0.052802;0;0;0;0;0;0;0;0;0;0;0;0;0
22;0.0021112;5.7607e-05;-4.8487e-05;0.056634;0;0;0;0;0;0;0;0;0;0;0;0;0
23;0.0022466;2.0246e-05;3.2059e-05;0.060868;0;0;0;0;0;0;0;0;0;0;0;0;0
24;0.0024785;-5.9317e-06;2.1795e-05;0.064807;0;0;0;0;0;0;0;0;0;0;0;0;0
25;0.0025488;6.6019e-05;-1.9548e-05;0.069149;0;0;0;0;0;0;0;0;0;0;0;0;0
26;0.0026821;9.9394e-05;-2.825e-05;0.073255;0;0;0;0;0;0;0;0;0;0;0;0;0
27;0.0029444;8.0843e-05;-2.4073e-05;0.077626;0;0;0;0;0;0;0;0;0;0;0;0;0
28;0.0030552;0.00011535;6.2592e-06;0.082212;0;0;0;0;0;0;0;0;0;0;0;0;0
29;0.0031847;8.0847e-05;-3.1467e-06;0.086671;0;0;0;0;0;0;0;0;0;0;0;0;0
30;0.0033453;0.00012964;-6.3429e-05;0.090964;0;0;0;0;0;0;0;0;0;0;0;0;0
31;0.0035394;0.00018911;-1.4424e-05;0.095472;0;0;0;0;0;0;0;0;0;0;0;0;0
32;0.0035847;0.00016978;-1.981e-05;0.099999;0;0;0;0;0;0;0;0;0;0;0;0;0
33;0.0038048;0.00012234;-5.0808e-05;0.10475;0;0;0;0;0;0;0;0;0;0;0;0;0
34;0.0039797;0.00022754;2.2857e-05;0.10919;0;0;0;0;0;0;0;0;0;0;0;0;0
35;0.0042004;0.0002016;-9.6622e-06;0.11402;0;0;0;0;0;0;0;0;0;0;0;0;0
36;0.0044133;0.00021601;5.2619e-05;0.11856;0;0;0;0;0;0;0;0;0;0;0;0;0
37;0.0045689;0.00024518;7.2147e-05;0.12332;0;0;0;0;0;0;0;0;0;0;0;0;0
38;0.004816;0.00021495;6.8277e-05;0.12831;0;0;0;0;0;0;0;0;0;0;0;0;0
39;0.0050539;0.0002295;7.725e-05;0.13297;0;0;0;0;0;0;0;0;0;0;0;0;0
40;0.0052542;0.00018444;6.5242e-05;0.13809;0;0;0;0;0;0;0;0;0;0;0;0;0
41;0.0054553;0.00023651;3.6748e-05;0.14305;0;0;0;0;0;0;0;0;0;0;0;0;0
42;0.0056667;0.00026991;5.7633e-05;0.14783;0;0;0;0;0;0;0;0;0;0;0;0;0
43;0.0058956;0.00021573;5.018e-05;0.15303;0;0;0;0;0;0;0;0;0;0;0;0;0
44;0.0061335;0.00026684;7.5633e-06;0.15777;0;0;0;0;0;0;0;0;0;0;0;0;0
45;0.006503;0.00021886;-2.1723e-06;0.16269;0;0;0;0;0;0;0;0;0;0;0;0;0
46;0.00676;0.00040638;3.9518e-05;0.16762;0;0;0;0;0;0;0;0;0;0;0;0;0
47;0.0070416;0.00036379;7.5524e-05;0.17259;0;0;0;0;0;0;0;0;0;0;0;0;0
48;0.0072587;0.0003883;3.8053e-05;0.1778;0;0;0;0;0;0;0;0;0;0;0;0;0
48.999;0.0075512;0.00037756;2.0784e-05;0.18257;0;0;0;0;0;0;0;0;0;0;0;0;0
50;0.0079246;0.0004004;3.5763e-05;0.18768;0;0;0;0;0;0;0;0;0;0;0;0;0
51;0.0082177;0.00043782;-2.7515e-05;0.19251;0;0;0;0;0;0;0;0;0;0;0;0;0
52;0.0085344;0.00041899;1.0233e-05;0.19729;0;0;0;0;0;0;0;0;0;0;0;0;0
52.999;0.0088924;0.00056921;3.2202e-05;0.20205;0;0;0;0;0;0;0;0;0;0;0;0;0
54;0.0092532;0.00057682;6.546e-05;0.2066;0;0;0;0;0;0;0;0;0;0;0;0;0
55;0.0096707;0.00057101;0.00010621;0.2115;0;0;0;0;0;0;0;0;0;0;0;0;0
56;0.010076;0.00066087;-1.4437e-05;0.21595;0;0;0;0;0;0;0;0;0;0;0;0;0
56.999;0.010579;0.00071675;-9.7785e-06;0.22048;0;0;0;0;0;0;0;0;0;0;0;0;0
58;0.011085;0.0007685;4.6599e-05;0.22488;0;0;0;0;0;0;0;0;0;0;0;0;0
59;0.01156;0.00078463;-2.628e-05;0.22917;0;0;0;0;0;0;0;0;0;0;0;0;0
60;0.012061;0.00081935;-4.3092e-05;0.2335;0;0;0;0;0;0;0;0;0;0;0;0;0
61;0.012636;0.00083461;-0.00010142;0.23756;0;0;0;0;0;0;0;0;0;0;0;0;0
62;0.01319;0.00090491;-7.1061e-05;0.24132;0;0;0;0;0;0;0;0;0;0;0;0;0
63;0.013801;0.00090178;-4.9464e-05;0.24524;0;0;0;0;0;0;0;0;0;0;0;0;0
64;0.014341;0.00097276;-9.1548e-05;0.24883;0;0;0;0;0;0;0;0;0;0;0;0;0
65.001;0.015059;0.0010818;-0.00020864;0.25227;0;0;0;0;0;0;0;0;0;0;0;0;0
65.999;0.015707;0.0010416;-0.00017015;0.25545;0;0;0;0;0;0;0;0;0;0;0;0;0
67;0.016371;0.0012381;-0.00021472;0.25865;0;0;0;0;0;0;0;0;0;0;0;0;0
68;0.017133;0.0013448;-0.00024872;0.26185;0;0;0;0;0;0;0;0;0;0;0;0;0
68.999;0.01785;0.0013963;-0.0002436;0.26464;0;0;0;0;0;0;0;0;0;0;0;0;0
70;0.018569;0.0014596;-0.00033716;0.26754;0;0;0;0;0;0;0;0;0;0;0;0;0
71;0.019428;0.0015632;-0.00035381;0.27007;0;0;0;0;0;0;0;0;0;0;0;0;0
72;0.020254;0.0017126;-0.00042591;0.27261;0;0;0;0;0;0;0;0;0;0;0;0;0
73;0.02112;0.0017562;-0.00040112;0.27514;0;0;0;0;0;0;0;0;0;0;0;0;0
74;0.021919;0.0019021;-0.00041019;0.2774;0;0;0;0;0;0;0;0;0;0;0;0;0
74.999;0.022716;0.0020169;-0.0004975;0.27974;0;0;0;0;0;0;0;0;0;0;0;0;0
76.001;0.023576;0.0020935;-0.00046713;0.28191;0;0;0;0;0;0;0;0;0;0;0;0;0
77;0.024462;0.0021441;-0.00055491;0.28403;0;0;0;0;0;0;0;0;0;0;0;0;0
77.999;0.025357;0.0023346;-0.00052909;0.28608;0;0;0;0;0;0;0;0;0;0;0;0;0
79;0.026336;0.0023236;-0.00060407;0.28801;0;0;0;0;0;0;0;0;0;0;0;0;0
79.999;0.027205;0.0024469;-0.00061371;0.29002;0;0;0;0;0;0;0;0;0;0;0;0;0
81;0.028191;0.0026037;-0.00063148;0.29182;0;0;0;0;0;0;0;0;0;0;0;0;0
81.999;0.029092;0.0025508;-0.00068513;0.29375;0;0;0;0;0;0;0;0;0;0;0;0;0
83;0.030003;0.0027939;-0.00069986;0.29554;0;0;0;0;0;0;0;0;0;0;0;0;0
84;0.030973;0.0029061;-0.00072238;0.29722;0;0;0;0;0;0;0;0;0;0;0;0;0
85;0.031911;0.0029493;-0.00070431;0.29902;0;0;0;0;0;0;0;0;0;0;0;0;0
86;0.032847;0.0030393;-0.00077384;0.30063;0;0;0;0;0;0;0;0;0;0;0;0;0
86.999;0.033862;0.0031462;-0.00074191;0.30234;0;0;0;0;0;0;0;0;0;0;0;0;0
88;0.034754;0.0032756;-0.00081803;0.30389;0;0;0;0;0;0;0;0;0;0;0;0;0
89;0.035833;0.0033324;-0.00088408;0.3055;0;0;0;0;0;0;0;0;0;0;0;0;0
90;0.03679;0.0034409;-0.00087894;0.3071;0;0;0;0;0;0;0;0;0;0;0;0;0
91;0.037844;0.0036574;-0.00088328;0.30855;0;0;0;0;0;0;0;0;0;0;0;0;0
92;0.038826;0.0037485;-0.00092395;0.31008;0;0;0;0;0;0;0;0;0;0;0;0;0
92.999;0.03983;0.0038977;-0.00096369;0.3115;0;0;0;0;0;0;0;0;0;0;0;0;0
94;0.040858;0.0039968;-0.001045;0.31288;0;0;0;0;0;0;0;0;0;0;0;0;0
95;0.041679;0.0041082;-0.0010843;0.31429;0;0;0;0;0;0;0;0;0;0;0;0;0
96;0.042851;0.0042369;-0.0010791;0.31568;0;0;0;0;0;0;0;0;0;0;0;0;0
97;0.043917;0.0043004;-0.0011154;0.31704;0;0;0;0;0;0;0;0;0;0;0;0;0
98;0.045003;0.0044668;-0.0012446;0.31842;0;0;0;0;0;0;0;0;0;0;0;0;0
99;0.046003;0.0045456;-0.0012556;0.31968;0;0;0;0;0;0;0;0;0;0;0;0;0
100;0.047067;0.0046279;-0.0012275;0.32097;0;0;0;0;0;0;0;0;0;0;0;0;0
101;0.048002;0.0047423;-0.0013136;0.3222;0;0;0;0;0;0;0;0;0;0;0;0;0
102;0.049222;0.0048904;-0.0013185;0.32346;0;0;0;0;0;0;0;0;0;0;0;0;0
103;0.050262;0.0050004;-0.0013482;0.32465;0;0;0;0;0;0;0;0;0;0;0;0;0
104;0.051313;0.00513;-0.0013993;0.3258;0;0;0;0;0;0;0;0;0;0;0;0;0
105;0.052406;0.0051963;-0.0013527;0.32704;0;0;0;0;0;0;0;0;0;0;0;0;0
106;0.053336;0.0052734;-0.0014196;0.32821;0;0;0;0;0;0;0;0;0;0;0;0;0
107;0.054514;0.0053846;-0.0014466;0.32936;0;0;0;0;0;0;0;0;0;0;0;0;0
108;0.055679;0.0055349;-0.001427;0.33043;0;0;0;0;0;0;0;0;0;0;0;0;0
109;0.056647;0.0056572;-0.0014391;0.33154;0;0;0;0;0;0;0;0;0;0;0;0;0
110;0.057876;0.0057716;-0.0014163;0.33267;0;0;0;0;0;0;0;0;0;0;0;0;0
111;0.058883;0.00593;-0.0014572;0.33369;0;0;0;0;0;0;0;0;0;0;0;0;0
112;0.059987;0.0059717;-0.0015224;0.33478;0;0;0;0;0;0;0;0;0;0;0;0;0
113;0.061034;0.0061153;-0.0015264;0.33581;0;0;0;0;0;0;0;0;0;0;0;0;0
114;0.06212;0.006204;-0.001568;0.33681;0;0;0;0;0;0;0;0;0;0;0;0;0
115;0.063163;0.0064222;-0.0016116;0.33779;0;0;0;0;0;0;0;0;0;0;0;0;0
116;0.064346;0.0065005;-0.0015997;0.33877;0;0;0;0;0;0;0;0;0;0;0;0;0
117;0.065416;0.0065427;-0.0016184;0.33974;0;0;0;0;0;0;0;0;0;0;0;0;0
118;0.066522;0.006631;-0.0016872;0.34069;0;0;0;0;0;0;0;0;0;0;0;0;0
119;0.067639;0.0067949;-0.0016907;0.34169;0;0;0;0;0;0;0;0;0;0;0;0;0
120;0.068824;0.0067913;-0.0017246;0.34263;0;0;0;0;0;0;0;0;0;0;0;0;0
121;0.06987;0.0070198;-0.00172;0.34349;0;0;0;0;0;0;0;0;0;0;0;0;0
122;0.070941;0.0071292;-0.0017495;0.3444;0;0;0;0;0;0;0;0;0;0;0;0;0
123;0.072087;0.0071747;-0.0017787;0.34523;0;0;0;0;0;0;0;0;0;0;0;0;0
124;0.073201;0.007392;-0.001848;0.34615;0;0;0;0;0;0;0;0;0;0;0;0;0
125;0.074317;0.0075007;-0.0018558;0.34697;0;0;0;0;0;0;0;0;0;0;0;0;0
126;0.075466;0.0075838;-0.0018933;0.34782;0;0;0;0;0;0;0;0;0;0;0;0;0
127;0.076608;0.0077392;-0.0019013;0.34869;0;0;0;0;0;0;0;0;0;0;0;0;0
128;0.077742;0.0077968;-0.0019692;0.34947;0;0;0;0;0;0;0;0;0;0;0;0;0
129;0.078789;0.0079023;-0.0019457;0.35028;0;0;0;0;0;0;0;0;0;0;0;0;0
130;0.079908;0.0080232;-0.0019789;0.3511;0;0;0;0;0;0;0;0;0;0;0;0;0
131;0.081126;0.0081643;-0.0020255;0.35184;0;0;0;0;0;0;0;0;0;0;0;0;0
132;0.082233;0.0083542;-0.0021138;0.35264;0;0;0;0;0;0;0;0;0;0;0;0;0
133;0.083379;0.0084415;-0.0020668;0.3534;0;0;0;0;0;0;0;0;0;0;0;0;0
134;0.084471;0.0086285;-0.002111;0.3541;0;0;0;0;0;0;0;0;0;0;0;0;0
135;0.085631;0.0087012;-0.0021545;0.35483;0;0;0;0;0;0;0;0;0;0;0;0;0
136;0.086825;0.008836;-0.0021721;0.35558;0;0;0;0;0;0;0;0;0;0;0;0;0
137;0.087892;0.008988;-0.0021916;0.35627;0;0;0;0;0;0;0;0;0;0;0;0;0
138;0.08906;0.0091406;-0.0021863;0.35699;0;0;0;0;0;0;0;0;0;0;0;0;0
139;0.090202;0.0091975;-0.0022351;0.35771;0;0;0;0;0;0;0;0;0;0;0;0;0
140;0.091397;0.0092883;-0.0022357;0.3584;0;0;0;0;0;0;0;0;0;0;0;0;0
141;0.092488;0.0094622;-0.0023084;0.35911;0;0;0;0;0;0;0;0;0;0;0;0;0
142;0.0937;0.0095445;-0.0022863;0.35975;0;0;0;0;0;0;0;0;0;0;0;0;0
143;0.094765;0.0096048;-0.0023672;0.36041;0;0;0;0;0;0;0;0;0;0;0;0;0
144;0.095869;0.0096678;-0.002354;0.36104;0;0;0;0;0;0;0;0;0;0;0;0;0
145;0.096915;0.0098217;-0.0023986;0.36171;0;0;0;0;0;0;0;0;0;0;0;0;0
146;0.098235;0.0099926;-0.0024642;0.36235;0;0;0;0;0;0;0;0;0;0;0;0;0
147;0.09937;0.010127;-0.0024882;0.36302;0;0;0;0;0;0;0;0;0;0;0;0;0
148;0.10055;0.010162;-0.0025158;0.36365;0;0;0;0;0;0;0;0;0;0;0;0;0
149;0.1017;0.010373;-0.0025408;0.36422;0;0;0;0;0;0;0;0;0;0;0;0;0
150;0.10275;0.010502;-0.002632;0.3648;0;0;0;0;0;0;0;0;0;0;0;0;0
151;0.10402;0.010577;-0.0026419;0.36535;0;0;0;0;0;0;0;0;0;0;0;0;0
152;0.10519;0.010653;-0.0026542;0.36595;0;0;0;0;0;0;0;0;0;0;0;0;0
153;0.10632;0.010753;-0.0026552;0.36651;0;0;0;0;0;0;0;0;0;0;0;0;0
154;0.10754;0.010901;-0.0027336;0.36709;0;0;0;0;0;0;0;0;0;0;0;0;0
155;0.10867;0.011014;-0.0027667;0.36765;0;0;0;0;0;0;0;0;0;0;0;0;0
156;0.10979;0.011228;-0.0027809;0.3682;0;0;0;0;0;0;0;0;0;0;0;0;0
157;0.11099;0.01139;-0.0028355;0.36877;0;0;0;0;0;0;0;0;0;0;0;0;0
158;0.11212;0.011353;-0.0028828;0.36931;0;0;0;0;0;0;0;0;0;0;0;0;0
159;0.11302;0.011544;-0.0029428;0.36984;0;0;0;0;0;0;0;0;0;0;0;0;0
160;0.11453;0.011717;-0.0029438;0.37034;0;0;0;0;0;0;0;0;0;0;0;0;0
161;0.11586;0.011816;-0.0030046;0.37086;0;0;0;0;0;0;0;0;0;0;0;0;0
162;0.11688;0.011979;-0.0030593;0.37141;0;0;0;0;0;0;0;0;0;0;0;0;0
163;0.11811;0.012139;-0.0030772;0.37193;0;0;0;0;0;0;0;0;0;0;0;0;0
164;0.1192;0.012218;-0.0031689;0.37241;0;0;0;0;0;0;0;0;0;0;0;0;0
165;0.12037;0.012346;-0.0031178;0.37292;0;0;0;0;0;0;0;0;0;0;0;0;0
166;0.12157;0.012458;-0.003175;0.37341;0;0;0;0;0;0;0;0;0;0;0;0;0
167;0.12277;0.012601;-0.0032128;0.3739;0;0;0;0;0;0;0;0;0;0;0;0;0
168;0.12389;0.012701;-0.0033278;0.37441;0;0;0;0;0;0;0;0;0;0;0;0;0
169;0.12514;0.012892;-0.0033594;0.37486;0;0;0;0;0;0;0;0;0;0;0;0;0
170;0.12635;0.01297;-0.0034183;0.37532;0;0;0;0;0;0;0;0;0;0;0;0;0
171;0.1273;0.013194;-0.0034595;0.37578;0;0;0;0;0;0;0;0;0;0;0;0;0
172;0.12872;0.013334;-0.0035202;0.37625;0;0;0;0;0;0;0;0;0;0;0;0;0
173;0.1299;0.013502;-0.0035913;0.37669;0;0;0;0;0;0;0;0;0;0;0;0;0
174;0.13154;0.01365;-0.0036335;0.37716;0;0;0;0;0;0;0;0;0;0;0;0;0
175;0.1322;0.013826;-0.0036694;0.3776;0;0;0;0;0;0;0;0;0;0;0;0;0
176;0.13344;0.0139;-0.0037484;0.37801;0;0;0;0;0;0;0;0;0;0;0;0;0
177;0.13465;0.014148;-0.0037921;0.37845;0;0;0;0;0;0;0;0;0;0;0;0;0
178;0.13576;0.014279;-0.0038453;0.37886;0;0;0;0;0;0;0;0;0;0;0;0;0
179;0.13701;0.014446;-0.0039126;0.37928;0;0;0;0;0;0;0;0;0;0;0;0;0
180;0.13818;0.014579;-0.0039428;0.3797;0;0;0;0;0;0;0;0;0;0;0;0;0
181;0.13938;0.014731;-0.004018;0.3801;0;0;0;0;0;0;0;0;0;0;0;0;0
182;0.14053;0.014894;-0.0041057;0.38052;0;0;0;0;0;0;0;0;0;0;0;0;0
183;0.14186;0.015081;-0.0041561;0.38092;0;0;0;0;0;0;0;0;0;0;0;0;0
184;0.14297;0.015292;-0.0042335;0.38132;0;0;0;0;0;0;0;0;0;0;0;0;0
185;0.14416;0.015464;-0.0042761;0.38169;0;0;0;0;0;0;0;0;0;0;0;0;0
186;0.14538;0.015614;-0.0043512;0.38208;0;0;0;0;0;0;0;0;0;0;0;0;0
187;0.14668;0.015729;-0.0043753;0.38243;0;0;0;0;0;0;0;0;0;0;0;0;0
188;0.14787;0.015916;-0.004461;0.38281;0;0;0;0;0;0;0;0;0;0;0;0;0
189;0.14908;0.016137;-0.0045009;0.38318;0;0;0;0;0;0;0;0;0;0;0;0;0
190;0.15026;0.016334;-0.0046215;0.38352;0;0;0;0;0;0;0;0;0;0;0;0;0
191;0.15137;0.016543;-0.0046252;0.38389;0;0;0;0;0;0;0;0;0;0;0;0;0
192;0.15261;0.016734;-0.004705;0.38421;0;0;0;0;0;0;0;0;0;0;0;0;0
193;0.15392;0.016885;-0.0047908;0.38454;0;0;0;0;0;0;0;0;0;0;0;0;0
194;0.15505;0.01708;-0.0048705;0.38486;0;0;0;0;0;0;0;0;0;0;0;0;0
195;0.15626;0.017284;-0.0049358;0.38518;0;0;0;0;0;0;0;0;0;0;0;0;0
196;0.15746;0.017392;-0.0050176;0.38549;0;0;0;0;0;0;0;0;0;0;0;0;0
197;0.15865;0.01752;-0.0051267;0.38582;0;0;0;0;0;0;0;0;0;0;0;0;0
198;0.15985;0.017798;-0.0051614;0.38615;0;0;0;0;0;0;0;0;0;0;0;0;0
199;0.16104;0.017956;-0.0052462;0.38645;0;0;0;0;0;0;0;0;0;0;0;0;0
200;0.16223;0.018187;-0.0052817;0.38679;0;0;0;0;0;0;0;0;0;0;0;0;0
201;0.1634;0.018324;-0.0053842;0.3871;0;0;0;0;0;0;0;0;0;0;0;0;0
202;0.16463;0.018573;-0.0054463;0.3874;0;0;0;0;0;0;0;0;0;0;0;0;0
203;0.16591;0.018809;-0.0055359;0.38772;0;0;0;0;0;0;0;0;0;0;0;0;0
204;0.16716;0.019012;-0.0055693;0.38801;0;0;0;0;0;0;0;0;0;0;0;0;0
205;0.16837;0.019301;-0.0056159;0.38831;0;0;0;0;0;0;0;0;0;0;0;0;0
206;0.16958;0.019458;-0.0057182;0.38857;0;0;0;0;0;0;0;0;0;0;0;0;0
207;0.17077;0.019701;-0.0057638;0.38884;0;0;0;0;0;0;0;0;0;0;0;0;0
208;0.17181;0.019945;-0.0058245;0.38913;0;0;0;0;0;0;0;0;0;0;0;0;0
209;0.17327;0.020195;-0.005939;0.3894;0;0;0;0;0;0;0;0;0;0;0;0;0
210;0.17445;0.020366;-0.0060125;0.38971;0;0;0;0;0;0;0;0;0;0;0;0;0
211;0.1757;0.020643;-0.0060894;0.38997;0;0;0;0;0;0;0;0;0;0;0;0;0
212;0.17697;0.020782;-0.0061501;0.39027;0;0;0;0;0;0;0;0;0;0;0;0;0
213;0.17819;0.020976;-0.006201;0.3905;0;0;0;0;0;0;0;0;0;0;0;0;0
214;0.17943;0.0213;-0.0063312;0.39075;0;0;0;0;0;0;0;0;0;0;0;0;0
215;0.18055;0.021398;-0.0063873;0.39098;0;0;0;0;0;0;0;0;0;0;0;0;0
216;0.18175;0.021723;-0.0064571;0.39121;0;0;0;0;0;0;0;0;0;0;0;0;0
217;0.183;0.021903;-0.0065479;0.39144;0;0;0;0;0;0;0;0;0;0;0;0;0
218;0.18425;0.022153;-0.0066237;0.39168;0;0;0;0;0;0;0;0;0;0;0;0;0
219;0.18548;0.022404;-0.0066924;0.39189;0;0;0;0;0;0;0;0;0;0;0;0;0
220;0.18673;0.02257;-0.0068281;0.39213;0;0;0;0;0;0;0;0;0;0;0;0;0
221;0.18795;0.022833;-0.0068596;0.39234;0;0;0;0;0;0;0;0;0;0;0;0;0
222;0.18917;0.023164;-0.007011;0.39258;0;0;0;0;0;0;0;0;0;0;0;0;0
223;0.19039;0.023287;-0.0070445;0.39277;0;0;0;0;0;0;0;0;0;0;0;0;0
224;0.19166;0.023595;-0.0071161;0.39299;0;0;0;0;0;0;0;0;0;0;0;0;0
225;0.19299;0.023851;-0.007136;0.39319;0;0;0;0;0;0;0;0;0;0;0;0;0
226;0.19421;0.024048;-0.0072235;0.3934;0;0;0;0;0;0;0;0;0;0;0;0;0
227;0.19518;0.024278;-0.0072817;0.39358;0;0;0;0;0;0;0;0;0;0;0;0;0
228;0.19662;0.024549;-0.0073395;0.39375;0;0;0;0;0;0;0;0;0;0;0;0;0
229;0.19768;0.024837;-0.0073999;0.39394;0;0;0;0;0;0;0;0;0;0;0;0;0
230;0.199;0.024941;-0.0074466;0.39411;0;0;0;0;0;0;0;0;0;0;0;0;0
231;0.20007;0.025365;-0.0075319;0.3943;0;0;0;0;0;0;0;0;0;0;0;0;0
232;0.20169;0.02562;-0.0076651;0.39448;0;0;0;0;0;0;0;0;0;0;0;0;0
233;0.20283;0.025795;-0.0077126;0.39465;0;0;0;0;0;0;0;0;0;0;0;0;0
234;0.20414;0.026088;-0.0078509;0.39482;0;0;0;0;0;0;0;0;0;0;0;0;0
235;0.20539;0.026421;-0.00792;0.39497;0;0;0;0;0;0;0;0;0;0;0;0;0
236;0.20668;0.026697;-0.0079502;0.39514;0;0;0;0;0;0;0;0;0;0;0;0;0
237;0.20786;0.026975;-0.0080549;0.39529;0;0;0;0;0;0;0;0;0;0;0;0;0
238;0.20909;0.027323;-0.0080674;0.39544;0;0;0;0;0;0;0;0;0;0;0;0;0
239;0.21042;0.027552;-0.00823;0.39559;0;0;0;0;0;0;0;0;0;0;0;0;0
240;0.21165;0.027869;-0.008289;0.39574;0;0;0;0;0;0;0;0;0;0;0;0;0
241;0.21294;0.028145;-0.0084268;0.39589;0;0;0;0;0;0;0;0;0;0;0;0;0
242;0.21419;0.028447;-0.0084971;0.39604;0;0;0;0;0;0;0;0;0;0;0;0;0
243;0.21543;0.028784;-0.0085692;0.39617;0;0;0;0;0;0;0;0;0;0;0;0;0
244;0.21663;0.029044;-0.0086604;0.39629;0;0;0;0;0;0;0;0;0;0;0;0;0
245;0.2179;0.029316;-0.0087264;0.39641;0;0;0;0;0;0;0;0;0;0;0;0;0
246;0.21924;0.029695;-0.0088364;0.39653;0;0;0;0;0;0;0;0;0;0;0;0;0
247;0.22049;0.02996;-0.008951;0.39664;0;0;0;0;0;0;0;0;0;0;0;0;0
248;0.22169;0.03023;-0.0090125;0.39674;0;0;0;0;0;0;0;0;0;0;0;0;0
249;0.22296;0.030481;-0.0090918;0.39685;0;0;0;0;0;0;0;0;0;0;0;0;0
250;0.22409;0.030825;-0.0091478;0.39695;0;0;0;0;0;0;0;0;0;0;0;0;0
251;0.22546;0.031136;-0.0091957;0.39705;0;0;0;0;0;0;0;0;0;0;0;0;0
252;0.22675;0.031443;-0.0093009;0.39716;0;0;0;0;0;0;0;0;0;0;0;0;0
253;0.22802;0.031763;-0.0094101;0.39724;0;0;0;0;0;0;0;0;0;0;0;0;0
254;0.2293;0.032057;-0.0094859;0.39734;0;0;0;0;0;0;0;0;0;0;0;0;0
255;0.23051;0.032442;-0.0095287;0.39744;0;0;0;0;0;0;0;0;0;0;0;0;0
256;0.2318;0.032736;-0.009567;0.39751;0;0;0;0;0;0;0;0;0;0;0;0;0
257;0.23305;0.033036;-0.0096516;0.39757;0;0;0;0;0;0;0;0;0;0;0;0;0
258;0.23437;0.03337;-0.0096994;0.39765;0;0;0;0;0;0;0;0;0;0;0;0;0
259;0.2356;0.033692;-0.0097759;0.3977;0;0;0;0;0;0;0;0;0;0;0;0;0
260;0.23693;0.034031;-0.0099203;0.39775;0;0;0;0;0;0;0;0;0;0;0;0;0
261;0.23765;0.034411;-0.01004;0.39782;0;0;0;0;0;0;0;0;0;0;0;0;0
262;0.23958;0.034752;-0.010047;0.39785;0;0;0;0;0;0;0;0;0;0;0;0;0
263;0.24087;0.035151;-0.01015;0.39792;0;0;0;0;0;0;0;0;0;0;0;0;0
264;0.24214;0.035513;-0.010255;0.39797;0;0;0;0;0;0;0;0;0;0;0;0;0
265;0.24343;0.035945;-0.010375;0.39802;0;0;0;0;0;0;0;0;0;0;0;0;0
266;0.24463;0.036339;-0.010453;0.39806;0;0;0;0;0;0;0;0;0;0;0;0;0
267;0.24597;0.036598;-0.010538;0.3981;0;0;0;0;0;0;0;0;0;0;0;0;0
268;0.24727;0.037047;-0.010664;0.39813;0;0;0;0;0;0;0;0;0;0;0;0;0
269;0.24857;0.037466;-0.010797;0.39814;0;0;0;0;0;0;0;0;0;0;0;0;0
270;0.24983;0.037779;-0.010879;0.39816;0;0;0;0;0;0;0;0;0;0;0;0;0
271;0.25109;0.038152;-0.011024;0.39816;0;0;0;0;0;0;0;0;0;0;0;0;0
272;0.25244;0.038593;-0.011198;0.39819;0;0;0;0;0;0;0;0;0;0;0;0;0
273;0.25374;0.038988;-0.011297;0.39823;0;0;0;0;0;0;0;0;0;0;0;0;0
274;0.25509;0.039443;-0.011477;0.39823;0;0;0;0;0;0;0;0;0;0;0;0;0
275;0.25634;0.03979;-0.011605;0.39825;0;0;0;0;0;0;0;0;0;0;0;0;0
276;0.25764;0.040212;-0.01174;0.39823;0;0;0;0;0;0;0;0;0;0;0;0;0
277;0.25893;0.040577;-0.011874;0.3982;0;0;0;0;0;0;0;0;0;0;0;0;0
278;0.26019;0.040975;-0.012034;0.39817;0;0;0;0;0;0;0;0;0;0;0;0;0
279;0.26156;0.041396;-0.012088;0.39814;0;0;0;0;0;0;0;0;0;0;0;0;0
280;0.26278;0.041836;-0.012233;0.39812;0;0;0;0;0;0;0;0;0;0;0;0;0
281;0.26414;0.042237;-0.012373;0.3981;0;0;0;0;0;0;0;0;0;0;0;0;0
282;0.26542;0.042663;-0.01248;0.39811;0;0;0;0;0;0;0;0;0;0;0;0;0
283;0.26669;0.043088;-0.012555;0.39812;0;0;0;0;0;0;0;0;0;0;0;0;0
284;0.26799;0.043575;-0.012667;0.3981;0;0;0;0;0;0;0;0;0;0;0;0;0
285;0.26936;0.044091;-0.012735;0.3981;0;0;0;0;0;0;0;0;0;0;0;0;0
286;0.2706;0.044425;-0.01284;0.39808;0;0;0;0;0;0;0;0;0;0;0;0;0
287;0.27196;0.044879;-0.012935;0.39806;0;0;0;0;0;0;0;0;0;0;0;0;0
288;0.27317;0.045381;-0.01308;0.39805;0;0;0;0;0;0;0;0;0;0;0;0;0
289;0.2745;0.045872;-0.013168;0.39803;0;0;0;0;0;0;0;0;0;0;0;0;0
290;0.27585;0.046366;-0.013314;0.39802;0;0;0;0;0;0;0;0;0;0;0;0;0
291;0.27717;0.046878;-0.013429;0.39799;0;0;0;0;0;0;0;0;0;0;0;0;0
292;0.27844;0.047461;-0.013568;0.39796;0;0;0;0;0;0;0;0;0;0;0;0;0
293;0.2797;0.048138;-0.013711;0.39794;0;0;0;0;0;0;0;0;0;0;0;0;0
294;0.28104;0.048747;-0.013896;0.39791;0;0;0;0;0;0;0;0;0;0;0;0;0
295;0.28237;0.049282;-0.014029;0.39789;0;0;0;0;0;0;0;0;0;0;0;0;0
296;0.28365;0.049793;-0.01417;0.39787;0;0;0;0;0;0;0;0;0;0;0;0;0
297;0.28495;0.050368;-0.01428;0.39784;0;0;0;0;0;0;0;0;0;0;0;0;0
298;0.28627;0.050835;-0.014477;0.39783;0;0;0;0;0;0;0;0;0;0;0;0;0
299;0.28762;0.051445;-0.014626;0.3978;0;0;0;0;0;0;0;0;0;0;0;0;0
300;0.28896;0.052059;-0.014752;0.39778;0;0;0;0;0;0;0;0;0;0;0;0;0
301;0.29022;0.052664;-0.014877;0.39776;0;0;0;0;0;0;0;0;0;0;0;0;0
302;0.29154;0.053291;-0.014992;0.39772;0;0;0;0;0;0;0;0;0;0;0;0;0
303;0.29286;0.053852;-0.015173;0.3977;0;0;0;0;0;0;0;0;0;0;0;0;0
304;0.29426;0.054491;-0.015254;0.39766;0;0;0;0;0;0;0;0;0;0;0;0;0
305;0.29552;0.055151;-0.015433;0.39764;0;0;0;0;0;0;0;0;0;0;0;0;0
306;0.29683;0.055782;-0.015508;0.3976;0;0;0;0;0;0;0;0;0;0;0;0;0
307;0.29812;0.056403;-0.015632;0.39757;0;0;0;0;0;0;0;0;0;0;0;0;0
308;0.29952;0.05707;-0.015805;0.39754;0;0;0;0;0;0;0;0;0;0;0;0;0
309;0.30085;0.057683;-0.015931;0.39751;0;0;0;0;0;0;0;0;0;0;0;0;0
310;0.3022;0.05843;-0.016091;0.39748;0;0;0;0;0;0;0;0;0;0;0;0;0
311;0.3035;0.059008;-0.016172;0.39744;0;0;0;0;0;0;0;0;0;0;0;0;0
312;0.30487;0.059604;-0.016323;0.3974;0;0;0;0;0;0;0;0;0;0;0;0;0
313;0.30615;0.060339;-0.016445;0.39736;0;0;0;0;0;0;0;0;0;0;0;0;0
314;0.30752;0.060973;-0.016538;0.39732;0;0;0;0;0;0;0;0;0;0;0;0;0
315;0.30879;0.061663;-0.016639;0.39729;0;0;0;0;0;0;0;0;0;0;0;0;0
316;0.31022;0.062396;-0.01682;0.39725;0;0;0;0;0;0;0;0;0;0;0;0;0
317;0.31141;0.063153;-0.016928;0.3972;0;0;0;0;0;0;0;0;0;0;0;0;0
318;0.31278;0.063845;-0.01709;0.39715;0;0;0;0;0;0;0;0;0;0;0;0;0
319;0.31414;0.064686;-0.017295;0.39711;0;0;0;0;0;0;0;0;0;0;0;0;0
320;0.31543;0.065409;-0.017434;0.39706;0;0;0;0;0;0;0;0;0;0;0;0;0
321;0.31683;0.066163;-0.017609;0.39701;0;0;0;0;0;0;0;0;0;0;0;0;0
322;0.31815;0.066819;-0.01777;0.39694;0;0;0;0;0;0;0;0;0;0;0;0;0
323;0.31955;0.067703;-0.017963;0.39687;0;0;0;0;0;0;0;0;0;0;0;0;0
324;0.32089;0.068479;-0.018106;0.3968;0;0;0;0;0;0;0;0;0;0;0;0;0
325;0.32225;0.069303;-0.018299;0.39675;0;0;0;0;0;0;0;0;0;0;0;0;0
326;0.32356;0.070185;-0.018469;0.3967;0;0;0;0;0;0;0;0;0;0;0;0;0
327;0.32494;0.070974;-0.018615;0.39664;0;0;0;0;0;0;0;0;0;0;0;0;0
328;0.32634;0.071763;-0.018784;0.39655;0;0;0;0;0;0;0;0;0;0;0;0;0
329;0.32772;0.072661;-0.018939;0.39642;0;0;0;0;0;0;0;0;0;0;0;0;0
330;0.32911;0.07358;-0.019089;0.39628;0;0;0;0;0;0;0;0;0;0;0;0;0
331;0.33043;0.074553;-0.01921;0.39616;0;0;0;0;0;0;0;0;0;0;0;0;0
332;0.33182;0.075439;-0.01931;0.39601;0;0;0;0;0;0;0;0;0;0;0;0;0
333;0.33326;0.076452;-0.019425;0.39586;0;0;0;0;0;0;0;0;0;0;0;0;0
334;0.33473;0.077375;-0.01964;0.39569;0;0;0;0;0;0;0;0;0;0;0;0;0
335;0.33609;0.078384;-0.019776;0.39549;0;0;0;0;0;0;0;0;0;0;0;0;0
336;0.33754;0.079431;-0.01991;0.39529;0;0;0;0;0;0;0;0;0;0;0;0;0
337;0.33896;0.080422;-0.020176;0.39506;0;0;0;0;0;0;0;0;0;0;0;0;0
338;0.34037;0.081379;-0.020469;0.39481;0;0;0;0;0;0;0;0;0;0;0;0;0
339;0.34191;0.082342;-0.020624;0.39453;0;0;0;0;0;0;0;0;0;0;0;0;0
340;0.34333;0.0834;-0.020889;0.39419;0;0;0;0;0;0;0;0;0;0;0;0;0
341;0.34447;0.084442;-0.021092;0.39385;0;0;0;0;0;0;0;0;0;0;0;0;0
342;0.34603;0.08549;-0.021255;0.39347;0;0;0;0;0;0;0;0;0;0;0;0;0
343;0.34751;0.086496;-0.021378;0.39305;0;0;0;0;0;0;0;0;0;0;0;0;0
344;0.34883;0.08757;-0.021508;0.39261;0;0;0;0;0;0;0;0;0;0;0;0;0
345;0.35022;0.088552;-0.021656;0.39211;0;0;0;0;0;0;0;0;0;0;0;0;0
346;0.35154;0.089562;-0.021781;0.39161;0;0;0;0;0;0;0;0;0;0;0;0;0
347;0.35296;0.09065;-0.021858;0.3911;0;0;0;0;0;0;0;0;0;0;0;0;0
348;0.35424;0.091758;-0.022053;0.39059;0;0;0;0;0;0;0;0;0;0;0;0;0
349;0.35571;0.092871;-0.022217;0.39002;0;0;0;0;0;0;0;0;0;0;0;0;0
350;0.35705;0.093922;-0.022479;0.3895;0;0;0;0;0;0;0;0;0;0;0;0;0
351;0.35846;0.09497;-0.022665;0.38889;0;0;0;0;0;0;0;0;0;0;0;0;0
352;0.35976;0.095903;-0.022656;0.38832;0;0;0;0;0;0;0;0;0;0;0;0;0
353;0.36101;0.097055;-0.022663;0.38774;0;0;0;0;0;0;0;0;0;0;0;0;0
354;0.36251;0.098078;-0.02269;0.38712;0;0;0;0;0;0;0;0;0;0;0;0;0
355;0.364;0.099199;-0.022757;0.38653;0;0;0;0;0;0;0;0;0;0;0;0;0
356;0.36532;0.10022;-0.022725;0.38587;0;0;0;0;0;0;0;0;0;0;0;0;0
357;0.36657;0.10143;-0.022904;0.38517;0;0;0;0;0;0;0;0;0;0;0;0;0
358;0.36805;0.10247;-0.02305;0.38447;0;0;0;0;0;0;0;0;0;0;0;0;0
359;0.36933;0.10351;-0.023117;0.3837;0;0;0;0;0;0;0;0;0;0;0;0;0
360;0.37069;0.10465;-0.023238;0.383;0;0;0;0;0;0;0;0;0;0;0;0;0
361;0.37209;0.10575;-0.023409;0.38224;0;0;0;0;0;0;0;0;0;0;0;0;0
362;0.37325;0.10689;-0.02358;0.38152;0;0;0;0;0;0;0;0;0;0;0;0;0
363;0.37466;0.10809;-0.023665;0.38075;0;0;0;0;0;0;0;0;0;0;0;0;0
364;0.37608;0.10924;-0.023867;0.37996;0;0;0;0;0;0;0;0;0;0;0;0;0
365;0.37752;0.11043;-0.024042;0.37919;0;0;0;0;0;0;0;0;0;0;0;0;0
366;0.37897;0.11161;-0.024169;0.37838;0;0;0;0;0;0;0;0;0;0;0;0;0
367;0.38028;0.11283;-0.024298;0.37752;0;0;0;0;0;0;0;0;0;0;0;0;0
368;0.38167;0.11407;-0.024404;0.37668;0;0;0;0;0;0;0;0;0;0;0;0;0
369;0.3831;0.11549;-0.024447;0.37576;0;0;0;0;0;0;0;0;0;0;0;0;0
370;0.38445;0.11664;-0.02447;0.37489;0;0;0;0;0;0;0;0;0;0;0;0;0
371;0.38586;0.11784;-0.024526;0.37393;0;0;0;0;0;0;0;0;0;0;0;0;0
372;0.38732;0.11927;-0.024587;0.37299;0;0;0;0;0;0;0;0;0;0;0;0;0
373;0.38883;0.1205;-0.024645;0.37207;0;0;0;0;0;0;0;0;0;0;0;0;0
374;0.39006;0.1219;-0.02466;0.37104;0;0;0;0;0;0;0;0;0;0;0;0;0
375;0.39156;0.12313;-0.02462;0.37005;0;0;0;0;0;0;0;0;0;0;0;0;0
376;0.39294;0.12446;-0.024712;0.36895;0;0;0;0;0;0;0;0;0;0;0;0;0
377;0.39449;0.12586;-0.024729;0.36785;0;0;0;0;0;0;0;0;0;0;0;0;0
378;0.39574;0.12726;-0.024773;0.3668;0;0;0;0;0;0;0;0;0;0;0;0;0
379;0.39714;0.12852;-0.024783;0.36562;0;0;0;0;0;0;0;0;0;0;0;0;0
380;0.39857;0.12993;-0.024864;0.36452;0;0;0;0;0;0;0;0;0;0;0;0;0
381;0.40014;0.13141;-0.025095;0.3633;0;0;0;0;0;0;0;0;0;0;0;0;0
382;0.40151;0.1328;-0.025333;0.36213;0;0;0;0;0;0;0;0;0;0;0;0;0
383;0.40273;0.13429;-0.025411;0.36088;0;0;0;0;0;0;0;0;0;0;0;0;0
384;0.40453;0.13583;-0.025745;0.35952;0;0;0;0;0;0;0;0;0;0;0;0;0
385;0.40614;0.13723;-0.025895;0.35823;0;0;0;0;0;0;0;0;0;0;0;0;0
386;0.40742;0.13894;-0.026018;0.35678;0;0;0;0;0;0;0;0;0;0;0;0;0
387;0.40888;0.14028;-0.025995;0.3554;0;0;0;0;0;0;0;0;0;0;0;0;0
388;0.41041;0.14193;-0.025976;0.35384;0;0;0;0;0;0;0;0;0;0;0;0;0
389;0.41197;0.14353;-0.025874;0.3523;0;0;0;0;0;0;0;0;0;0;0;0;0
390;0.41368;0.14509;-0.025496;0.3507;0;0;0;0;0;0;0;0;0;0;0;0;0
391;0.41509;0.1468;-0.025549;0.34906;0;0;0;0;0;0;0;0;0;0;0;0;0
392;0.41655;0.1484;-0.025936;0.34723;0;0;0;0;0;0;0;0;0;0;0;0;0
393;0.41838;0.15025;-0.025929;0.34519;0;0;0;0;0;0;0;0;0;0;0;0;0
394;0.42147;0.1537;-0.026655;0.34301;0;0;0;0;0;0;0;0;0;0;0;0;0