File: Template_Auto_Cali_large_DP600/_data/DP600Large_UT_00_002_Front_DIC_File.txt
Date of Test;Material;Sample Geometry;Orientation [°];Test Number;Nominal Speed [mm/min];Thickness [mm];Central Width [mm];Gauge Width / Diameter [mm];Pixel to mm ratio [mm/px];Extensometer 1-4 [mm];Extensometer 2-3 [mm];Extensometer 5-6 [mm];;;;;
09/07/21;DP600Large;UT;00;2;0.48;0.2885;2;0;0;6;1.8;1.8;;;;;
;;;;;;;;;;;;;;;;;
Time [s];U1 [mm];U2 [mm];U3 [mm];Force [kN];Ambient Temperature [°C];DIC Zone X 1 [px];DIC Zone Y 1 [px];DIC Zone X 2 [px];DIC Zone Y 2 [px];DIC Zone X 3 [px];DIC Zone Y 3 [px];DIC Zone X 4 [px];DIC Zone Y 4 [px];DIC Zone X 5 [px];DIC Zone Y 5 [px];DIC Zone X 6 [px];DIC Zone Y 6 [px];exx;exy;eyy;e1;e2
0;0;0;0;0.00049;0;0;0;0;0;0;0;0;0;0;0;0;0;-4.6453e-17;-1.8218e-17;-1.8186e-19;-1.4392e-17;-5.0279e-17
1.001;0.00078136;0.00035036;9.0203e-05;0.0004998;0;0;0;0;0;0;0;0;0;0;0;0;0;0.00012862;5.9271e-05;-3.7024e-05;0.00021544;-2.7545e-05
2.001;9.5792e-05;9.1131e-06;5.7135e-05;0.0004998;0;0;0;0;0;0;0;0;0;0;0;0;0;-4.8091e-06;1.1635e-05;5.6171e-06;0.00010406;-9.723e-05
3;0.00020794;-2.472e-05;-1.0138e-05;0.0005096;0;0;0;0;0;0;0;0;0;0;0;0;0;1.4064e-05;-8.0132e-06;8.6921e-06;0.00010107;-9.5019e-05
4.001;0.00034662;8.2277e-05;-1.0682e-05;0.0010192;0;0;0;0;0;0;0;0;0;0;0;0;0;4.3999e-05;-1.4803e-05;1.9094e-06;0.00014065;-0.00011146
5;0.0006397;0.00014545;-0.00018125;0.003577;0;0;0;0;0;0;0;0;0;0;0;0;0;0.00011487;-6.2917e-05;-1.4243e-05;0.00017293;-0.00012098
6.001;0.0013716;0.00044687;-6.7075e-05;0.0091238;0;0;0;0;0;0;0;0;0;0;0;0;0;0.00023911;-6.9713e-05;-9.4525e-06;0.00030051;-0.00013112
7;0.0021168;0.00054925;-0.0002197;0.0186;0;0;0;0;0;0;0;0;0;0;0;0;0;0.00036217;-0.00012554;-1.7157e-05;0.00040969;-0.00017306
8;0.0027525;0.00083439;-0.0001194;0.031419;0;0;0;0;0;0;0;0;0;0;0;0;0;0.00047413;-0.00014563;-3.3842e-05;0.00053373;-0.00020522
9.001;0.0034107;0.00092098;-0.00023407;0.045599;0;0;0;0;0;0;0;0;0;0;0;0;0;0.00057974;-0.00016119;-2.2964e-05;0.00065149;-0.00023294
10;0.0043673;0.001263;-0.00031048;0.060515;0;0;0;0;0;0;0;0;0;0;0;0;0;0.00076122;-0.00022372;-2.9252e-05;0.00082672;-0.00028922
11;0.0055911;0.001582;-0.00030806;0.078429;0;0;0;0;0;0;0;0;0;0;0;0;0;0.00095633;-0.00029615;-3.3611e-05;0.0010092;-0.00034902
12.001;0.00691;0.0020691;-0.00048614;0.096932;0;0;0;0;0;0;0;0;0;0;0;0;0;0.0011752;-0.0003867;-2.7502e-05;0.0012168;-0.00042826
13.001;0.0087975;0.002514;-0.00049081;0.1196;0;0;0;0;0;0;0;0;0;0;0;0;0;0.0014827;-0.00049383;-2.8757e-05;0.0015199;-0.00053111
14;0.011306;0.0031844;-0.00096025;0.14288;0;0;0;0;0;0;0;0;0;0;0;0;0;0.0019063;-0.00068998;-3.3749e-05;0.0019382;-0.0007219
15;0.015175;0.0043679;-0.0015002;0.16548;0;0;0;0;0;0;0;0;0;0;0;0;0;0.0025505;-0.00099383;-2.3951e-05;0.0025787;-0.001022
16;0.019632;0.0058005;-0.0022262;0.18573;0;0;0;0;0;0;0;0;0;0;0;0;0;0.0033146;-0.0013736;-7.711e-06;0.0033397;-0.0013987
17.001;0.024798;0.0073481;-0.0029104;0.20298;0;0;0;0;0;0;0;0;0;0;0;0;0;0.0041733;-0.0017687;-1.3525e-05;0.0041959;-0.0017913
18.001;0.02984;0.0089194;-0.0035992;0.21499;0;0;0;0;0;0;0;0;0;0;0;0;0;0.0050101;-0.0021374;-1.9986e-05;0.0050324;-0.0021597
19;0.034974;0.010525;-0.0042085;0.22381;0;0;0;0;0;0;0;0;0;0;0;0;0;0.0058388;-0.0025035;-2.1511e-05;0.0058609;-0.0025256
20;0.039827;0.012053;-0.0048544;0.23103;0;0;0;0;0;0;0;0;0;0;0;0;0;0.0066571;-0.0028356;-1.5488e-05;0.0066799;-0.0028585
21.001;0.044697;0.0135;-0.0054385;0.23679;0;0;0;0;0;0;0;0;0;0;0;0;0;0.007459;-0.0031886;-1.7675e-05;0.0074825;-0.0032121
22;0.049514;0.014962;-0.0060966;0.24174;0;0;0;0;0;0;0;0;0;0;0;0;0;0.0082672;-0.003531;-1.915e-05;0.0082912;-0.0035551
23;0.054185;0.016476;-0.0066545;0.24668;0;0;0;0;0;0;0;0;0;0;0;0;0;0.0090501;-0.0038836;-2.244e-05;0.0090742;-0.0039077
24;0.059137;0.017933;-0.0072587;0.25112;0;0;0;0;0;0;0;0;0;0;0;0;0;0.0098549;-0.0041929;-2.221e-05;0.0098803;-0.0042184
25;0.063975;0.019575;-0.0078862;0.25532;0;0;0;0;0;0;0;0;0;0;0;0;0;0.010656;-0.0045269;-2.3198e-05;0.010682;-0.0045525
26.001;0.068806;0.02096;-0.0085083;0.25911;0;0;0;0;0;0;0;0;0;0;0;0;0;0.01145;-0.0048566;-1.6561e-05;0.011476;-0.0048826
27;0.073614;0.022417;-0.009059;0.26319;0;0;0;0;0;0;0;0;0;0;0;0;0;0.012233;-0.0052016;-2.7664e-05;0.01226;-0.0052288
28;0.078586;0.024045;-0.0095232;0.26666;0;0;0;0;0;0;0;0;0;0;0;0;0;0.013033;-0.0055222;-1.8864e-05;0.01306;-0.0055495
29;0.083387;0.025475;-0.010014;0.27013;0;0;0;0;0;0;0;0;0;0;0;0;0;0.013827;-0.0058581;-1.9454e-05;0.013854;-0.0058855
30;0.088154;0.027055;-0.010542;0.27345;0;0;0;0;0;0;0;0;0;0;0;0;0;0.014617;-0.0061833;-1.3939e-05;0.014645;-0.006211
31;0.093057;0.028521;-0.011121;0.27661;0;0;0;0;0;0;0;0;0;0;0;0;0;0.015405;-0.0064947;-1.9879e-05;0.015434;-0.0065239
32.001;0.097785;0.030006;-0.011741;0.27964;0;0;0;0;0;0;0;0;0;0;0;0;0;0.016197;-0.0068376;-2.4568e-05;0.016227;-0.0068671
33;0.1028;0.03161;-0.01224;0.28253;0;0;0;0;0;0;0;0;0;0;0;0;0;0.017019;-0.007171;-2.694e-05;0.017049;-0.0072012
34;0.10762;0.033218;-0.0129;0.28521;0;0;0;0;0;0;0;0;0;0;0;0;0;0.017793;-0.0075058;-1.6931e-05;0.017824;-0.0075369
35;0.11244;0.034605;-0.013521;0.288;0;0;0;0;0;0;0;0;0;0;0;0;0;0.018591;-0.0078433;-1.9081e-05;0.018623;-0.0078751
36;0.11727;0.036159;-0.014198;0.29058;0;0;0;0;0;0;0;0;0;0;0;0;0;0.019381;-0.0081691;-1.5258e-05;0.019413;-0.0082015
37;0.12235;0.037717;-0.014792;0.29315;0;0;0;0;0;0;0;0;0;0;0;0;0;0.020196;-0.0084973;-1.1855e-05;0.020229;-0.0085305
38;0.12715;0.039172;-0.015472;0.29545;0;0;0;0;0;0;0;0;0;0;0;0;0;0.020995;-0.0088378;-5.7246e-06;0.021029;-0.0088717
39;0.13195;0.040809;-0.016053;0.29768;0;0;0;0;0;0;0;0;0;0;0;0;0;0.021802;-0.0091629;-1.0823e-05;0.021837;-0.0091976
40;0.13764;0.042472;-0.016632;0.30002;0;0;0;0;0;0;0;0;0;0;0;0;0;0.022702;-0.0094854;1.944e-05;0.022737;-0.0095205
41;0.14167;0.043899;-0.017256;0.3022;0;0;0;0;0;0;0;0;0;0;0;0;0;0.023367;-0.0098594;1.8587e-05;0.023403;-0.0098946
42.001;0.14696;0.045448;-0.018199;0.3043;0;0;0;0;0;0;0;0;0;0;0;0;0;0.024234;-0.010189;4.4489e-06;0.024269;-0.010225
43;0.15198;0.046938;-0.018723;0.3063;0;0;0;0;0;0;0;0;0;0;0;0;0;0.02503;-0.010513;7.0086e-06;0.025066;-0.010549
44;0.15706;0.048519;-0.019324;0.30823;0;0;0;0;0;0;0;0;0;0;0;0;0;0.025846;-0.010849;1.7339e-05;0.025883;-0.010886
45;0.16203;0.050176;-0.019889;0.31009;0;0;0;0;0;0;0;0;0;0;0;0;0;0.026651;-0.011203;1.9166e-05;0.026688;-0.01124
46;0.16709;0.051719;-0.02048;0.31191;0;0;0;0;0;0;0;0;0;0;0;0;0;0.027462;-0.011547;2.4539e-05;0.027501;-0.011585
47;0.17214;0.053285;-0.021072;0.31371;0;0;0;0;0;0;0;0;0;0;0;0;0;0.028283;-0.011857;2.8415e-05;0.028323;-0.011896
48.001;0.17731;0.054972;-0.021749;0.31553;0;0;0;0;0;0;0;0;0;0;0;0;0;0.029111;-0.012209;1.6602e-05;0.029151;-0.01225
49;0.18242;0.056506;-0.022361;0.31716;0;0;0;0;0;0;0;0;0;0;0;0;0;0.029929;-0.012539;2.4116e-05;0.02997;-0.01258
50.001;0.18754;0.058126;-0.022961;0.31875;0;0;0;0;0;0;0;0;0;0;0;0;0;0.030755;-0.012894;3.0466e-05;0.030796;-0.012935
51;0.19265;0.059733;-0.023644;0.3204;0;0;0;0;0;0;0;0;0;0;0;0;0;0.031583;-0.013251;3.7085e-05;0.031625;-0.013293
52;0.19774;0.061462;-0.024331;0.32195;0;0;0;0;0;0;0;0;0;0;0;0;0;0.032412;-0.013569;4.0165e-05;0.032455;-0.013612
53;0.20279;0.063103;-0.024979;0.32347;0;0;0;0;0;0;0;0;0;0;0;0;0;0.033227;-0.013931;2.7341e-05;0.03327;-0.013975
54;0.20795;0.064611;-0.025621;0.32494;0;0;0;0;0;0;0;0;0;0;0;0;0;0.034038;-0.014282;5.0339e-05;0.034082;-0.014326
55.001;0.21303;0.06622;-0.026149;0.32636;0;0;0;0;0;0;0;0;0;0;0;0;0;0.034855;-0.014616;5.8775e-05;0.034899;-0.01466
56;0.2184;0.06798;-0.026865;0.32774;0;0;0;0;0;0;0;0;0;0;0;0;0;0.035736;-0.014954;6.0699e-05;0.035781;-0.014999
57;0.22355;0.069624;-0.027555;0.32904;0;0;0;0;0;0;0;0;0;0;0;0;0;0.036543;-0.015306;5.3993e-05;0.036588;-0.015352
58;0.22863;0.071235;-0.028056;0.3304;0;0;0;0;0;0;0;0;0;0;0;0;0;0.03736;-0.015638;7.5372e-05;0.037406;-0.015684
59;0.23395;0.072817;-0.028784;0.33162;0;0;0;0;0;0;0;0;0;0;0;0;0;0.038186;-0.016055;6.8892e-05;0.038232;-0.016101
60;0.23915;0.074475;-0.029345;0.33292;0;0;0;0;0;0;0;0;0;0;0;0;0;0.039017;-0.016341;7.6833e-05;0.039064;-0.016388
61;0.24456;0.076176;-0.029946;0.33411;0;0;0;0;0;0;0;0;0;0;0;0;0;0.039856;-0.016666;8.3382e-05;0.039904;-0.016714
62;0.24957;0.077675;-0.030551;0.33531;0;0;0;0;0;0;0;0;0;0;0;0;0;0.040683;-0.016989;9.4962e-05;0.040732;-0.017037
63;0.25469;0.079333;-0.031305;0.33646;0;0;0;0;0;0;0;0;0;0;0;0;0;0.041501;-0.017374;9.4579e-05;0.04155;-0.017424
64.001;0.25988;0.081058;-0.032013;0.33758;0;0;0;0;0;0;0;0;0;0;0;0;0;0.042341;-0.017725;9.9302e-05;0.04239;-0.017774
65;0.26516;0.082797;-0.032645;0.33871;0;0;0;0;0;0;0;0;0;0;0;0;0;0.043171;-0.018079;9.7392e-05;0.043221;-0.018128
66;0.27036;0.084418;-0.033454;0.33974;0;0;0;0;0;0;0;0;0;0;0;0;0;0.044014;-0.018423;0.00011282;0.044064;-0.018473
67;0.27568;0.086054;-0.034186;0.34074;0;0;0;0;0;0;0;0;0;0;0;0;0;0.044851;-0.018784;0.00012098;0.044901;-0.018834
68;0.28089;0.087746;-0.034903;0.34179;0;0;0;0;0;0;0;0;0;0;0;0;0;0.045698;-0.019116;0.00012522;0.045748;-0.019167
68.999;0.28604;0.089452;-0.035559;0.3428;0;0;0;0;0;0;0;0;0;0;0;0;0;0.046527;-0.01947;0.00013353;0.04658;-0.019522
70;0.29138;0.091182;-0.036195;0.34382;0;0;0;0;0;0;0;0;0;0;0;0;0;0.047377;-0.019823;0.00014339;0.047429;-0.019876
71.001;0.29683;0.092924;-0.036831;0.34473;0;0;0;0;0;0;0;0;0;0;0;0;0;0.048231;-0.020167;0.00014698;0.048284;-0.020221
72.001;0.30192;0.094585;-0.037462;0.34562;0;0;0;0;0;0;0;0;0;0;0;0;0;0.049062;-0.020512;0.00013356;0.049116;-0.020566
73;0.30716;0.096224;-0.038157;0.34655;0;0;0;0;0;0;0;0;0;0;0;0;0;0.049874;-0.02088;0.00014325;0.049928;-0.020935
74;0.31255;0.097916;-0.038703;0.34737;0;0;0;0;0;0;0;0;0;0;0;0;0;0.050735;-0.021237;0.00016585;0.05079;-0.021292
75;0.31798;0.099615;-0.03929;0.34826;0;0;0;0;0;0;0;0;0;0;0;0;0;0.051602;-0.021571;0.00017754;0.051658;-0.021627
76;0.32344;0.1013;-0.039995;0.34911;0;0;0;0;0;0;0;0;0;0;0;0;0;0.052464;-0.021912;0.00018129;0.05252;-0.021968
77;0.3288;0.10307;-0.040595;0.3499;0;0;0;0;0;0;0;0;0;0;0;0;0;0.053313;-0.022271;0.00018683;0.05337;-0.022327
78;0.33387;0.10462;-0.041287;0.35075;0;0;0;0;0;0;0;0;0;0;0;0;0;0.054122;-0.022588;0.00018022;0.054179;-0.022645
79;0.33947;0.10641;-0.042093;0.35157;0;0;0;0;0;0;0;0;0;0;0;0;0;0.054992;-0.022971;0.00019454;0.05505;-0.023029
80;0.345;0.1082;-0.042836;0.35236;0;0;0;0;0;0;0;0;0;0;0;0;0;0.055851;-0.02334;0.0001947;0.055909;-0.023398
81;0.35023;0.10986;-0.043579;0.3531;0;0;0;0;0;0;0;0;0;0;0;0;0;0.056695;-0.023682;0.00021523;0.056754;-0.023741
82;0.35551;0.11161;-0.044363;0.35381;0;0;0;0;0;0;0;0;0;0;0;0;0;0.05753;-0.024052;0.0002147;0.057589;-0.024111
83;0.36095;0.11324;-0.04515;0.35452;0;0;0;0;0;0;0;0;0;0;0;0;0;0.058381;-0.024425;0.00022347;0.058442;-0.024485
84.001;0.36644;0.11497;-0.04582;0.35517;0;0;0;0;0;0;0;0;0;0;0;0;0;0.059246;-0.024763;0.00023057;0.059307;-0.024824
85;0.37173;0.11677;-0.04647;0.35582;0;0;0;0;0;0;0;0;0;0;0;0;0;0.060086;-0.025112;0.00025356;0.060148;-0.025174
86;0.37715;0.11854;-0.047098;0.35645;0;0;0;0;0;0;0;0;0;0;0;0;0;0.06094;-0.025454;0.00024015;0.061002;-0.025516
87;0.38259;0.12025;-0.047779;0.3571;0;0;0;0;0;0;0;0;0;0;0;0;0;0.061797;-0.025801;0.00025355;0.06186;-0.025864
88;0.38808;0.12207;-0.048482;0.35778;0;0;0;0;0;0;0;0;0;0;0;0;0;0.062659;-0.026181;0.00027202;0.062722;-0.026244
89;0.39355;0.12383;-0.049263;0.35843;0;0;0;0;0;0;0;0;0;0;0;0;0;0.063528;-0.026525;0.00027701;0.063591;-0.026589
90;0.39896;0.12559;-0.049939;0.35906;0;0;0;0;0;0;0;0;0;0;0;0;0;0.064363;-0.026874;0.00028672;0.064428;-0.026938
91.001;0.40427;0.12722;-0.050684;0.35962;0;0;0;0;0;0;0;0;0;0;0;0;0;0.065212;-0.027251;0.00027132;0.065277;-0.027316
92;0.4096;0.12903;-0.051347;0.36021;0;0;0;0;0;0;0;0;0;0;0;0;0;0.066045;-0.027601;0.00029318;0.066112;-0.027667
93;0.41536;0.13085;-0.052088;0.36076;0;0;0;0;0;0;0;0;0;0;0;0;0;0.066937;-0.027953;0.00029762;0.067003;-0.02802
94;0.42096;0.13266;-0.052715;0.36129;0;0;0;0;0;0;0;0;0;0;0;0;0;0.067798;-0.028316;0.00029666;0.067866;-0.028384
95;0.42643;0.13451;-0.053457;0.36186;0;0;0;0;0;0;0;0;0;0;0;0;0;0.068647;-0.028671;0.00030109;0.068715;-0.028739
96;0.43193;0.13636;-0.054166;0.36238;0;0;0;0;0;0;0;0;0;0;0;0;0;0.069514;-0.029038;0.00031253;0.069583;-0.029107
97;0.43744;0.13819;-0.054864;0.36289;0;0;0;0;0;0;0;0;0;0;0;0;0;0.070378;-0.029397;0.00031151;0.070447;-0.029466
97.999;0.44308;0.14002;-0.055615;0.36345;0;0;0;0;0;0;0;0;0;0;0;0;0;0.071244;-0.029757;0.00031981;0.071314;-0.029827
99;0.44861;0.14186;-0.05632;0.36394;0;0;0;0;0;0;0;0;0;0;0;0;0;0.072109;-0.030125;0.00032268;0.072179;-0.030196
100;0.45419;0.14365;-0.057078;0.36447;0;0;0;0;0;0;0;0;0;0;0;0;0;0.072971;-0.030473;0.00033036;0.073042;-0.030545
101;0.45979;0.14554;-0.057783;0.36495;0;0;0;0;0;0;0;0;0;0;0;0;0;0.073842;-0.030842;0.00034222;0.073914;-0.030915
102;0.46531;0.1473;-0.058501;0.36542;0;0;0;0;0;0;0;0;0;0;0;0;0;0.074703;-0.031207;0.0003408;0.074775;-0.03128
103;0.47105;0.14913;-0.059286;0.3659;0;0;0;0;0;0;0;0;0;0;0;0;0;0.07558;-0.031576;0.00034969;0.075653;-0.031649
104;0.47671;0.15094;-0.059965;0.36636;0;0;0;0;0;0;0;0;0;0;0;0;0;0.076446;-0.03192;0.00035218;0.07652;-0.031994
105;0.4822;0.15292;-0.060625;0.36682;0;0;0;0;0;0;0;0;0;0;0;0;0;0.077325;-0.032301;0.00036232;0.0774;-0.032376
106;0.48812;0.15474;-0.061413;0.36724;0;0;0;0;0;0;0;0;0;0;0;0;0;0.078226;-0.032653;0.00037189;0.078302;-0.03273
107;0.49343;0.15645;-0.062108;0.36768;0;0;0;0;0;0;0;0;0;0;0;0;0;0.079025;-0.033009;0.00038323;0.079102;-0.033086
108;0.49936;0.15839;-0.062795;0.36808;0;0;0;0;0;0;0;0;0;0;0;0;0;0.07994;-0.033377;0.00037946;0.080017;-0.033454
109;0.50498;0.16019;-0.063495;0.36847;0;0;0;0;0;0;0;0;0;0;0;0;0;0.080816;-0.033749;0.00038776;0.080894;-0.033827
110;0.51065;0.16194;-0.064296;0.36884;0;0;0;0;0;0;0;0;0;0;0;0;0;0.081677;-0.034111;0.00040126;0.081755;-0.03419
111;0.51644;0.16381;-0.065045;0.36925;0;0;0;0;0;0;0;0;0;0;0;0;0;0.082566;-0.03446;0.00039943;0.082645;-0.034539
112;0.52198;0.1657;-0.06578;0.36965;0;0;0;0;0;0;0;0;0;0;0;0;0;0.083435;-0.034823;0.00041176;0.083515;-0.034903
113;0.52771;0.16755;-0.066665;0.37001;0;0;0;0;0;0;0;0;0;0;0;0;0;0.084305;-0.035223;0.00041299;0.084386;-0.035304
114;0.53384;0.16956;-0.06725;0.37041;0;0;0;0;0;0;0;0;0;0;0;0;0;0.08524;-0.035537;0.00039935;0.085322;-0.035618
115;0.5391;0.17125;-0.068137;0.37077;0;0;0;0;0;0;0;0;0;0;0;0;0;0.086063;-0.03591;0.00043504;0.086145;-0.035992
116;0.54475;0.17318;-0.068918;0.37111;0;0;0;0;0;0;0;0;0;0;0;0;0;0.086939;-0.036272;0.00043598;0.087022;-0.036356
117;0.5507;0.17509;-0.069706;0.37145;0;0;0;0;0;0;0;0;0;0;0;0;0;0.087825;-0.036653;0.0004454;0.087909;-0.036737
118;0.55636;0.17706;-0.070479;0.37178;0;0;0;0;0;0;0;0;0;0;0;0;0;0.08871;-0.037009;0.0004462;0.088794;-0.037094
119;0.56232;0.179;-0.071264;0.37212;0;0;0;0;0;0;0;0;0;0;0;0;0;0.089603;-0.03738;0.00045247;0.089688;-0.037465
120;0.56804;0.18081;-0.072018;0.37243;0;0;0;0;0;0;0;0;0;0;0;0;0;0.090471;-0.037743;0.00045423;0.090558;-0.03783
121;0.57373;0.18272;-0.07281;0.37274;0;0;0;0;0;0;0;0;0;0;0;0;0;0.091351;-0.03811;0.000467;0.091439;-0.038198
122;0.57951;0.18473;-0.073516;0.37305;0;0;0;0;0;0;0;0;0;0;0;0;0;0.092241;-0.038476;0.00047376;0.092329;-0.038564
123;0.58538;0.18672;-0.074243;0.37334;0;0;0;0;0;0;0;0;0;0;0;0;0;0.093137;-0.038799;0.00049255;0.093227;-0.038889
124;0.59122;0.18873;-0.075196;0.37363;0;0;0;0;0;0;0;0;0;0;0;0;0;0.094009;-0.039276;0.00048847;0.094099;-0.039366
125;0.59724;0.19069;-0.075788;0.37393;0;0;0;0;0;0;0;0;0;0;0;0;0;0.094926;-0.039552;0.00050883;0.095017;-0.039643
126;0.60299;0.19269;-0.07652;0.37419;0;0;0;0;0;0;0;0;0;0;0;0;0;0.095788;-0.039924;0.00050909;0.09588;-0.040016
127;0.60875;0.19462;-0.077421;0.37445;0;0;0;0;0;0;0;0;0;0;0;0;0;0.096673;-0.040302;0.00049759;0.096766;-0.040394
128;0.61453;0.19661;-0.078157;0.37471;0;0;0;0;0;0;0;0;0;0;0;0;0;0.097527;-0.040658;0.00051681;0.09762;-0.040751
129;0.62057;0.19879;-0.078983;0.37494;0;0;0;0;0;0;0;0;0;0;0;0;0;0.098451;-0.041046;0.00052017;0.098546;-0.04114
130;0.62648;0.20083;-0.079721;0.37518;0;0;0;0;0;0;0;0;0;0;0;0;0;0.099343;-0.041412;0.00052577;0.099438;-0.041507
131;0.63248;0.20291;-0.080495;0.37543;0;0;0;0;0;0;0;0;0;0;0;0;0;0.10025;-0.041774;0.00051996;0.10034;-0.04187
132;0.63846;0.20488;-0.081309;0.37567;0;0;0;0;0;0;0;0;0;0;0;0;0;0.10114;-0.042158;0.00053814;0.10123;-0.042255
133;0.64443;0.2069;-0.082175;0.37592;0;0;0;0;0;0;0;0;0;0;0;0;0;0.10203;-0.042532;0.00054837;0.10212;-0.042629
134;0.65044;0.209;-0.082841;0.37616;0;0;0;0;0;0;0;0;0;0;0;0;0;0.10293;-0.0429;0.00055201;0.10302;-0.042998
135;0.65643;0.2111;-0.083639;0.37639;0;0;0;0;0;0;0;0;0;0;0;0;0;0.10383;-0.043273;0.00056368;0.10393;-0.043372
136;0.66262;0.21318;-0.084312;0.37659;0;0;0;0;0;0;0;0;0;0;0;0;0;0.10475;-0.043573;0.0005935;0.10485;-0.043674
137;0.66844;0.2153;-0.085186;0.3768;0;0;0;0;0;0;0;0;0;0;0;0;0;0.10563;-0.044022;0.0005747;0.10573;-0.044124
138;0.67454;0.21736;-0.085937;0.37701;0;0;0;0;0;0;0;0;0;0;0;0;0;0.10654;-0.044368;0.0006106;0.10664;-0.044471
139;0.68041;0.21951;-0.086711;0.37719;0;0;0;0;0;0;0;0;0;0;0;0;0;0.10743;-0.044762;0.00058841;0.10753;-0.044865
140;0.6863;0.22154;-0.087443;0.37737;0;0;0;0;0;0;0;0;0;0;0;0;0;0.1083;-0.045152;0.00059741;0.1084;-0.045256
141;0.69259;0.22377;-0.088206;0.37756;0;0;0;0;0;0;0;0;0;0;0;0;0;0.10923;-0.045509;0.00059988;0.10934;-0.045614
142;0.69877;0.22591;-0.089011;0.37775;0;0;0;0;0;0;0;0;0;0;0;0;0;0.11014;-0.045874;0.00060954;0.11025;-0.04598
143;0.70452;0.22801;-0.089783;0.37795;0;0;0;0;0;0;0;0;0;0;0;0;0;0.11101;-0.046285;0.0006203;0.11111;-0.046392
144;0.71109;0.23042;-0.090559;0.37815;0;0;0;0;0;0;0;0;0;0;0;0;0;0.11197;-0.046634;0.00062289;0.11208;-0.046741
145;0.71763;0.23277;-0.091318;0.37833;0;0;0;0;0;0;0;0;0;0;0;0;0;0.11295;-0.046986;0.00065853;0.11306;-0.047095
146;0.7236;0.23487;-0.092241;0.3785;0;0;0;0;0;0;0;0;0;0;0;0;0;0.11383;-0.047381;0.00063036;0.11394;-0.04749
147;0.72945;0.23706;-0.093057;0.37864;0;0;0;0;0;0;0;0;0;0;0;0;0;0.1147;-0.047746;0.00063886;0.11481;-0.047855
148;0.73529;0.23927;-0.093858;0.3788;0;0;0;0;0;0;0;0;0;0;0;0;0;0.11558;-0.048132;0.00064162;0.11569;-0.048243
149;0.74174;0.2417;-0.094599;0.37895;0;0;0;0;0;0;0;0;0;0;0;0;0;0.11653;-0.048488;0.00065501;0.11664;-0.048599
150;0.74793;0.2439;-0.095413;0.37909;0;0;0;0;0;0;0;0;0;0;0;0;0;0.11745;-0.048883;0.00065571;0.11756;-0.048996
151;0.75432;0.24628;-0.096294;0.37924;0;0;0;0;0;0;0;0;0;0;0;0;0;0.11838;-0.049272;0.00067204;0.11849;-0.049385
152;0.76044;0.24861;-0.097132;0.37937;0;0;0;0;0;0;0;0;0;0;0;0;0;0.11929;-0.049656;0.00068072;0.1194;-0.049771
153;0.76687;0.251;-0.097914;0.3795;0;0;0;0;0;0;0;0;0;0;0;0;0;0.12022;-0.050039;0.00067992;0.12033;-0.050154
154;0.77302;0.25339;-0.098776;0.37963;0;0;0;0;0;0;0;0;0;0;0;0;0;0.12113;-0.050417;0.00068351;0.12124;-0.050532
155;0.77936;0.25572;-0.099654;0.37975;0;0;0;0;0;0;0;0;0;0;0;0;0;0.12205;-0.050799;0.00068921;0.12217;-0.050916
156;0.78556;0.25809;-0.10046;0.37987;0;0;0;0;0;0;0;0;0;0;0;0;0;0.12298;-0.051181;0.00070039;0.12309;-0.051298
157;0.7919;0.26054;-0.10139;0.37998;0;0;0;0;0;0;0;0;0;0;0;0;0;0.1239;-0.051559;0.00070691;0.12402;-0.051677
158;0.79827;0.26295;-0.10228;0.38009;0;0;0;0;0;0;0;0;0;0;0;0;0;0.12483;-0.051939;0.00071277;0.12495;-0.052058
159;0.80466;0.2655;-0.10315;0.38021;0;0;0;0;0;0;0;0;0;0;0;0;0;0.12577;-0.052328;0.00072693;0.12589;-0.052448
160;0.81097;0.26786;-0.10413;0.38032;0;0;0;0;0;0;0;0;0;0;0;0;0;0.12668;-0.052721;0.0007227;0.1268;-0.052841
161;0.81725;0.27033;-0.10502;0.38042;0;0;0;0;0;0;0;0;0;0;0;0;0;0.1276;-0.053101;0.0007246;0.12773;-0.053223
162;0.824;0.27279;-0.1058;0.38049;0;0;0;0;0;0;0;0;0;0;0;0;0;0.12858;-0.053478;0.00074162;0.1287;-0.0536
163;0.83032;0.27543;-0.10661;0.38058;0;0;0;0;0;0;0;0;0;0;0;0;0;0.12951;-0.053862;0.00075244;0.12963;-0.053985
164;0.83673;0.27785;-0.10745;0.38068;0;0;0;0;0;0;0;0;0;0;0;0;0;0.13044;-0.054244;0.00075663;0.13056;-0.054368
165;0.84342;0.28052;-0.10834;0.3808;0;0;0;0;0;0;0;0;0;0;0;0;0;0.13141;-0.054622;0.00076104;0.13153;-0.054746
166;0.84969;0.283;-0.10921;0.38092;0;0;0;0;0;0;0;0;0;0;0;0;0;0.13231;-0.055002;0.00079477;0.13244;-0.055127
167;0.85634;0.28573;-0.11037;0.38102;0;0;0;0;0;0;0;0;0;0;0;0;0;0.13328;-0.055428;0.00077671;0.1334;-0.055553
168;0.86259;0.28829;-0.11139;0.3811;0;0;0;0;0;0;0;0;0;0;0;0;0;0.13418;-0.055825;0.00077774;0.13431;-0.055952
169;0.86919;0.29112;-0.11234;0.38117;0;0;0;0;0;0;0;0;0;0;0;0;0;0.13517;-0.056199;0.00078865;0.1353;-0.056326
170;0.87576;0.29377;-0.11339;0.38122;0;0;0;0;0;0;0;0;0;0;0;0;0;0.1361;-0.056594;0.00079457;0.13623;-0.056722
171;0.8823;0.29651;-0.11428;0.38127;0;0;0;0;0;0;0;0;0;0;0;0;0;0.13705;-0.056962;0.00080312;0.13718;-0.057091
172;0.88889;0.29931;-0.11528;0.38133;0;0;0;0;0;0;0;0;0;0;0;0;0;0.13801;-0.057356;0.00081294;0.13814;-0.057485
173;0.89546;0.30205;-0.11628;0.38138;0;0;0;0;0;0;0;0;0;0;0;0;0;0.13897;-0.057747;0.0008178;0.1391;-0.057877
174;0.90191;0.30491;-0.11722;0.38143;0;0;0;0;0;0;0;0;0;0;0;0;0;0.1399;-0.058149;0.0008097;0.14003;-0.058281
175;0.90879;0.30797;-0.11814;0.38147;0;0;0;0;0;0;0;0;0;0;0;0;0;0.14088;-0.058513;0.00082638;0.14101;-0.058645
176;0.91548;0.31082;-0.11915;0.3815;0;0;0;0;0;0;0;0;0;0;0;0;0;0.14185;-0.058912;0.00083516;0.14198;-0.059045
177;0.92212;0.31372;-0.12029;0.38154;0;0;0;0;0;0;0;0;0;0;0;0;0;0.1428;-0.059306;0.00084052;0.14294;-0.059439
178;0.92874;0.31665;-0.12141;0.38158;0;0;0;0;0;0;0;0;0;0;0;0;0;0.14375;-0.059726;0.00085007;0.14389;-0.05986
179;0.93567;0.31963;-0.12249;0.38161;0;0;0;0;0;0;0;0;0;0;0;0;0;0.14474;-0.060099;0.00085476;0.14487;-0.060235
180;0.94237;0.32268;-0.12364;0.38164;0;0;0;0;0;0;0;0;0;0;0;0;0;0.1457;-0.060498;0.00085859;0.14584;-0.060634
181;0.94909;0.32575;-0.12482;0.38165;0;0;0;0;0;0;0;0;0;0;0;0;0;0.14666;-0.060903;0.00086205;0.14679;-0.06104
182;0.95593;0.32894;-0.12588;0.38166;0;0;0;0;0;0;0;0;0;0;0;0;0;0.14764;-0.061265;0.00086445;0.14777;-0.061403
183;0.96267;0.33206;-0.12717;0.38168;0;0;0;0;0;0;0;0;0;0;0;0;0;0.14861;-0.061707;0.00087654;0.14875;-0.061846
184;0.96962;0.3354;-0.12826;0.3817;0;0;0;0;0;0;0;0;0;0;0;0;0;0.14959;-0.062086;0.00087504;0.14973;-0.062226
185;0.97661;0.33859;-0.1295;0.3817;0;0;0;0;0;0;0;0;0;0;0;0;0;0.15057;-0.062477;0.0008832;0.15071;-0.062618
186;0.9833;0.34187;-0.13076;0.3817;0;0;0;0;0;0;0;0;0;0;0;0;0;0.15153;-0.062874;0.00089096;0.15167;-0.063015
187;0.99031;0.3454;-0.13204;0.38169;0;0;0;0;0;0;0;0;0;0;0;0;0;0.15253;-0.063276;0.00090109;0.15267;-0.063419
188;0.99735;0.3488;-0.13343;0.38168;0;0;0;0;0;0;0;0;0;0;0;0;0;0.15351;-0.06368;0.00090881;0.15365;-0.063824
189;1.0043;0.35228;-0.13482;0.38167;0;0;0;0;0;0;0;0;0;0;0;0;0;0.15449;-0.064085;0.00091831;0.15463;-0.06423
190;1.0112;0.35591;-0.13613;0.38166;0;0;0;0;0;0;0;0;0;0;0;0;0;0.15546;-0.064495;0.00092844;0.15561;-0.06464
191;1.0185;0.35971;-0.13753;0.38165;0;0;0;0;0;0;0;0;0;0;0;0;0;0.15648;-0.064899;0.00094347;0.15663;-0.065046
192;1.0254;0.36347;-0.13895;0.38165;0;0;0;0;0;0;0;0;0;0;0;0;0;0.15746;-0.065313;0.00094847;0.15761;-0.065461
193;1.0324;0.36724;-0.14048;0.38164;0;0;0;0;0;0;0;0;0;0;0;0;0;0.15845;-0.065708;0.00095682;0.1586;-0.065856
194;1.0397;0.37131;-0.142;0.38162;0;0;0;0;0;0;0;0;0;0;0;0;0;0.15947;-0.066101;0.00096369;0.15962;-0.066251
195;1.0468;0.37537;-0.14348;0.38158;0;0;0;0;0;0;0;0;0;0;0;0;0;0.16046;-0.066523;0.0009693;0.16061;-0.066672
196;1.0539;0.37939;-0.14504;0.38152;0;0;0;0;0;0;0;0;0;0;0;0;0;0.16143;-0.066924;0.00098826;0.16159;-0.067075
197;1.0613;0.38365;-0.14652;0.38146;0;0;0;0;0;0;0;0;0;0;0;0;0;0.16245;-0.067331;0.00099778;0.16261;-0.067484
198;1.0687;0.38811;-0.14823;0.38143;0;0;0;0;0;0;0;0;0;0;0;0;0;0.16348;-0.067751;0.00098822;0.16363;-0.067904
199;1.076;0.39262;-0.14987;0.3814;0;0;0;0;0;0;0;0;0;0;0;0;0;0.16448;-0.068163;0.00099037;0.16464;-0.068318
200;1.0835;0.39735;-0.1517;0.38137;0;0;0;0;0;0;0;0;0;0;0;0;0;0.16551;-0.068568;0.001008;0.16566;-0.068724
201;1.0906;0.40195;-0.15345;0.38136;0;0;0;0;0;0;0;0;0;0;0;0;0;0.16649;-0.068975;0.0010116;0.16665;-0.069132
202;1.0979;0.40691;-0.15516;0.38133;0;0;0;0;0;0;0;0;0;0;0;0;0;0.1675;-0.069387;0.0010118;0.16766;-0.069544
203;1.1055;0.41205;-0.1572;0.3813;0;0;0;0;0;0;0;0;0;0;0;0;0;0.16855;-0.069807;0.0010061;0.16871;-0.069966
204;1.1131;0.41727;-0.1592;0.38127;0;0;0;0;0;0;0;0;0;0;0;0;0;0.16956;-0.070203;0.0010312;0.16972;-0.070363
205;1.1204;0.42254;-0.1616;0.38124;0;0;0;0;0;0;0;0;0;0;0;0;0;0.17055;-0.070609;0.0010261;0.17071;-0.07077
206;1.1282;0.42815;-0.16387;0.38119;0;0;0;0;0;0;0;0;0;0;0;0;0;0.17162;-0.071;0.0010408;0.17178;-0.071162
207;1.1357;0.43387;-0.1662;0.38115;0;0;0;0;0;0;0;0;0;0;0;0;0;0.17261;-0.071426;0.0010548;0.17277;-0.071589
208;1.1433;0.4397;-0.16875;0.38111;0;0;0;0;0;0;0;0;0;0;0;0;0;0.17364;-0.071822;0.0010626;0.1738;-0.071987
209;1.1508;0.44582;-0.17152;0.38106;0;0;0;0;0;0;0;0;0;0;0;0;0;0.17465;-0.072276;0.0010611;0.17482;-0.072442
210;1.1588;0.45216;-0.17405;0.38101;0;0;0;0;0;0;0;0;0;0;0;0;0;0.1757;-0.072645;0.0010744;0.17587;-0.072813
211;1.1664;0.4586;-0.17674;0.38097;0;0;0;0;0;0;0;0;0;0;0;0;0;0.17671;-0.073017;0.0010512;0.17688;-0.073185
212;1.1741;0.46527;-0.1796;0.3809;0;0;0;0;0;0;0;0;0;0;0;0;0;0.17773;-0.073502;0.001077;0.1779;-0.073671
213;1.182;0.47197;-0.18247;0.38083;0;0;0;0;0;0;0;0;0;0;0;0;0;0.17875;-0.073845;0.0010976;0.17892;-0.074015
214;1.1898;0.47902;-0.18571;0.38076;0;0;0;0;0;0;0;0;0;0;0;0;0;0.17978;-0.074278;0.0010941;0.17995;-0.074448
215;1.1977;0.48614;-0.18902;0.38066;0;0;0;0;0;0;0;0;0;0;0;0;0;0.1808;-0.074672;0.0010995;0.18098;-0.074843
216;1.2055;0.49342;-0.19238;0.38057;0;0;0;0;0;0;0;0;0;0;0;0;0;0.18182;-0.075053;0.0011098;0.182;-0.075226
217;1.2136;0.50099;-0.19609;0.38046;0;0;0;0;0;0;0;0;0;0;0;0;0;0.18285;-0.075453;0.0011179;0.18302;-0.075627
218;1.2215;0.50856;-0.19988;0.38032;0;0;0;0;0;0;0;0;0;0;0;0;0;0.18385;-0.075861;0.0011174;0.18403;-0.076036
219;1.2297;0.51639;-0.2037;0.38015;0;0;0;0;0;0;0;0;0;0;0;0;0;0.18489;-0.076223;0.0011279;0.18507;-0.076399
220;1.2387;0.52465;-0.20788;0.37991;0;0;0;0;0;0;0;0;0;0;0;0;0;0.18601;-0.076571;0.0011381;0.18619;-0.076747
221;1.246;0.53248;-0.21206;0.37961;0;0;0;0;0;0;0;0;0;0;0;0;0;0.18693;-0.076991;0.0011348;0.1871;-0.077168
222;1.2541;0.54043;-0.21654;0.37924;0;0;0;0;0;0;0;0;0;0;0;0;0;0.18793;-0.077371;0.0011299;0.18811;-0.077549
223;1.2624;0.54879;-0.22116;0.37875;0;0;0;0;0;0;0;0;0;0;0;0;0;0.18893;-0.077762;0.0011263;0.18911;-0.077941
224;1.2707;0.55718;-0.22589;0.37817;0;0;0;0;0;0;0;0;0;0;0;0;0;0.18993;-0.078113;0.0011112;0.19011;-0.078292
225;1.2791;0.56552;-0.23053;0.37744;0;0;0;0;0;0;0;0;0;0;0;0;0;0.19095;-0.078469;0.001124;0.19113;-0.078649
226;1.2876;0.57415;-0.23528;0.37664;0;0;0;0;0;0;0;0;0;0;0;0;0;0.19196;-0.078837;0.0011297;0.19214;-0.079018
227;1.296;0.58248;-0.24009;0.37567;0;0;0;0;0;0;0;0;0;0;0;0;0;0.19293;-0.079197;0.0011156;0.19312;-0.079379
228;1.3045;0.59107;-0.24537;0.37461;0;0;0;0;0;0;0;0;0;0;0;0;0;0.19394;-0.079524;0.0011192;0.19412;-0.079707
229;1.313;0.59968;-0.25052;0.3734;0;0;0;0;0;0;0;0;0;0;0;0;0;0.19491;-0.079826;0.0011059;0.19509;-0.08001
230;1.3215;0.60826;-0.25579;0.37205;0;0;0;0;0;0;0;0;0;0;0;0;0;0.19588;-0.080161;0.0010991;0.19606;-0.080345
231;1.3302;0.61708;-0.26087;0.3705;0;0;0;0;0;0;0;0;0;0;0;0;0;0.19686;-0.080458;0.0010981;0.19704;-0.080643
232;1.3389;0.62596;-0.26597;0.36876;0;0;0;0;0;0;0;0;0;0;0;0;0;0.1978;-0.080759;0.0010723;0.19799;-0.080944
233;1.3476;0.63479;-0.27141;0.36689;0;0;0;0;0;0;0;0;0;0;0;0;0;0.19875;-0.081055;0.0010528;0.19894;-0.081242
234;1.3564;0.64365;-0.27666;0.36458;0;0;0;0;0;0;0;0;0;0;0;0;0;0.19969;-0.081352;0.0010318;0.19987;-0.081539
235;1.3653;0.65281;-0.28175;0.36208;0;0;0;0;0;0;0;0;0;0;0;0;0;0.20061;-0.081642;0.00099889;0.2008;-0.081829
236;1.375;0.66242;-0.28672;0.35925;0;0;0;0;0;0;0;0;0;0;0;0;0;0.20162;-0.081859;0.00097302;0.20181;-0.082047
237;1.3838;0.67177;-0.29222;0.35597;0;0;0;0;0;0;0;0;0;0;0;0;0;0.20246;-0.082149;0.0009269;0.20265;-0.082338
238;1.3935;0.68167;-0.29769;0.35233;0;0;0;0;0;0;0;0;0;0;0;0;0;0.20339;-0.082367;0.00088596;0.20358;-0.082557
239;1.4036;0.69236;-0.3032;0.34768;0;0;0;0;0;0;0;0;0;0;0;0;0;0.20433;-0.082636;0.00081722;0.20452;-0.082827
240;1.4142;0.70352;-0.30863;0.34224;0;0;0;0;0;0;0;0;0;0;0;0;0;0.20527;-0.082819;0.00075691;0.20546;-0.083011
241;1.4269;0.71695;-0.31525;0.33503;0;0;0;0;0;0;0;0;0;0;0;0;0;0.20634;-0.08303;0.00065336;0.20653;-0.083223
242;NaN;NaN;NaN;0.2649;0;0;0;0;0;0;0;0;0;0;0;0;0;0;0;0;0;0
243;NaN;NaN;NaN;0.17648;0;0;0;0;0;0;0;0;0;0;0;0;0;0;0;0;0;0
244;NaN;NaN;NaN;0.093316;0;0;0;0;0;0;0;0;0;0;0;0;0;0;0;0;0;0
245;NaN;NaN;NaN;0.012613;0;0;0;0;0;0;0;0;0;0;0;0;0;0;0;0;0;0
245.5;NaN;NaN;NaN;4.9e-05;0;0;0;0;0;0;0;0;0;0;0;0;0;0;0;0;0;0