File: Template_Auto_Cali_large_DP600/_data/DP600Large_CH_00_002_Front_DIC_File.txt
Date of Test;Material;Sample Geometry;Orientation [°];Test Number;Nominal Speed [mm/min];Thickness [mm];Central Width [mm];Gauge Width / Diameter [mm];Pixel to mm ratio [mm/px];Extensometer 1-4 [mm];Extensometer 2-3 [mm];Extensometer 5-6 [mm];;;;;
09/08/21;DP600Large;CH;00;2;0.0798;0.29503;4;1;0;6;0.20001;0.20001;;;;;
;;;;;;;;;;;;;;;;;
Time [s];U1 [mm];U2 [mm];U3 [mm];Force [kN];Ambient Temperature [°C];DIC Zone X 1 [px];DIC Zone Y 1 [px];DIC Zone X 2 [px];DIC Zone Y 2 [px];DIC Zone X 3 [px];DIC Zone Y 3 [px];DIC Zone X 4 [px];DIC Zone Y 4 [px];DIC Zone X 5 [px];DIC Zone Y 5 [px];DIC Zone X 6 [px];DIC Zone Y 6 [px]
0;0;0;0;0.0001568;0;0;0;0;0;0;0;0;0;0;0;0;0
1;0.00015164;0.00010054;8.2148e-05;0.0001764;0;0;0;0;0;0;0;0;0;0;0;0;0
2;8.8186e-05;-1.6815e-05;0.00013579;0.0001764;0;0;0;0;0;0;0;0;0;0;0;0;0
2.999;-0.00010712;5.4365e-05;7.8045e-06;0.0001764;0;0;0;0;0;0;0;0;0;0;0;0;0
4;-6.1516e-05;-2.6003e-05;0.00016188;0.0001862;0;0;0;0;0;0;0;0;0;0;0;0;0
5;-4.0517e-05;-0.00011528;-5.83e-05;0.0002156;0;0;0;0;0;0;0;0;0;0;0;0;0
5.999;-0.00012033;-0.00015052;-0.00012246;0.0006958;0;0;0;0;0;0;0;0;0;0;0;0;0
7;-0.00011822;-3.7858e-05;-0.00019446;0.0017542;0;0;0;0;0;0;0;0;0;0;0;0;0
8;-6.0958e-05;4.4188e-05;-8.2286e-05;0.0034202;0;0;0;0;0;0;0;0;0;0;0;0;0
9;6.6881e-05;-4.8862e-05;-0.00020587;0.0053704;0;0;0;0;0;0;0;0;0;0;0;0;0
10;-0.00017975;-8.5976e-05;-0.00021331;0.0074382;0;0;0;0;0;0;0;0;0;0;0;0;0
11;-5.4614e-05;-1.5401e-05;-0.00020233;0.0093884;0;0;0;0;0;0;0;0;0;0;0;0;0
11.999;0.0001275;-0.00021891;-0.00015471;0.011182;0;0;0;0;0;0;0;0;0;0;0;0;0
13;8.3765e-05;-0.00017224;1.1654e-05;0.013054;0;0;0;0;0;0;0;0;0;0;0;0;0
14;4.572e-05;-0.00014376;-0.00016731;0.014837;0;0;0;0;0;0;0;0;0;0;0;0;0
15;1.185e-05;-8.8285e-05;-9.3727e-05;0.016807;0;0;0;0;0;0;0;0;0;0;0;0;0
16;3.1356e-05;-0.00011825;-0.00016917;0.018973;0;0;0;0;0;0;0;0;0;0;0;0;0
17;0.00018518;-0.00011547;-0.00015427;0.021335;0;0;0;0;0;0;0;0;0;0;0;0;0
18;0.00056945;-8.5396e-05;-5.282e-05;0.023873;0;0;0;0;0;0;0;0;0;0;0;0;0
18.999;0.00030187;-0.00016798;-0.00018279;0.026568;0;0;0;0;0;0;0;0;0;0;0;0;0
19.999;0.00032559;-0.00017604;-0.00017341;0.02938;0;0;0;0;0;0;0;0;0;0;0;0;0
21;0.00029025;-0.00015802;-0.00032068;0.032301;0;0;0;0;0;0;0;0;0;0;0;0;0
22;0.00033722;-0.00012329;-0.00019667;0.0353;0;0;0;0;0;0;0;0;0;0;0;0;0
23;0.00034616;-9.2435e-05;-0.00034654;0.038465;0;0;0;0;0;0;0;0;0;0;0;0;0
24;0.00032017;-5.2003e-06;-0.00019958;0.041405;0;0;0;0;0;0;0;0;0;0;0;0;0
24.999;0.00046955;-0.00012752;-0.00036213;0.044404;0;0;0;0;0;0;0;0;0;0;0;0;0
26;0.00040653;-0.00015511;-0.00033544;0.047373;0;0;0;0;0;0;0;0;0;0;0;0;0
27;0.00055358;-0.00011451;-0.00041292;0.050411;0;0;0;0;0;0;0;0;0;0;0;0;0
28;0.00051197;-0.00018938;-0.00042636;0.053694;0;0;0;0;0;0;0;0;0;0;0;0;0
29;0.00059379;-0.00033216;-0.00025211;0.057399;0;0;0;0;0;0;0;0;0;0;0;0;0
30;0.00075137;-0.00028851;-0.00025029;0.061534;0;0;0;0;0;0;0;0;0;0;0;0;0
31;0.00068364;-0.00022796;-0.00029238;0.066023;0;0;0;0;0;0;0;0;0;0;0;0;0
31.999;0.00097179;-0.00022574;-0.00035266;0.070521;0;0;0;0;0;0;0;0;0;0;0;0;0
33;0.0010153;-9.9407e-05;-0.00019837;0.075519;0;0;0;0;0;0;0;0;0;0;0;0;0
34.002;0.00089896;-0.00011418;-0.00027331;0.080468;0;0;0;0;0;0;0;0;0;0;0;0;0
35;0.0013103;-0.00019291;-0.00026084;0.085544;0;0;0;0;0;0;0;0;0;0;0;0;0
35.999;0.0014326;-0.00021854;-0.00024021;0.090581;0;0;0;0;0;0;0;0;0;0;0;0;0
37;0.0015871;-0.00011503;-0.00026353;0.096158;0;0;0;0;0;0;0;0;0;0;0;0;0
37.999;0.0016245;-0.00010085;-0.00029331;0.1016;0;0;0;0;0;0;0;0;0;0;0;0;0
39.001;0.0016789;-0.00017591;-0.0002557;0.10691;0;0;0;0;0;0;0;0;0;0;0;0;0
40;0.0017251;-0.00011408;-0.00034234;0.11249;0;0;0;0;0;0;0;0;0;0;0;0;0
41;0.0018196;-0.00013365;-0.00037869;0.11836;0;0;0;0;0;0;0;0;0;0;0;0;0
42;0.0019559;-9.3207e-05;-0.00032079;0.12387;0;0;0;0;0;0;0;0;0;0;0;0;0
43.001;0.0020559;-3.19e-05;-0.0002097;0.12969;0;0;0;0;0;0;0;0;0;0;0;0;0
43.999;0.0023331;-8.0319e-05;-7.1981e-05;0.13581;0;0;0;0;0;0;0;0;0;0;0;0;0
44.999;0.0025045;-0.00016785;-5.0749e-05;0.14154;0;0;0;0;0;0;0;0;0;0;0;0;0
46;0.0025204;-0.00015057;-0.00010996;0.1478;0;0;0;0;0;0;0;0;0;0;0;0;0
47;0.0026927;-8.4695e-05;-0.00018903;0.15384;0;0;0;0;0;0;0;0;0;0;0;0;0
48;0.0029941;-1.0026e-07;-0.00018107;0.15993;0;0;0;0;0;0;0;0;0;0;0;0;0
49;0.0031455;1.6819e-05;-3.5681e-05;0.16606;0;0;0;0;0;0;0;0;0;0;0;0;0
50;0.0034095;2.5597e-05;5.785e-05;0.17223;0;0;0;0;0;0;0;0;0;0;0;0;0
51;0.0035955;-3.2242e-05;4.7642e-05;0.17822;0;0;0;0;0;0;0;0;0;0;0;0;0
52;0.0036912;6.9111e-05;1.8446e-05;0.18473;0;0;0;0;0;0;0;0;0;0;0;0;0
53;0.0039085;3.2694e-05;-5.7458e-06;0.19096;0;0;0;0;0;0;0;0;0;0;0;0;0
54;0.0039138;-9.0409e-05;-3.6901e-05;0.19692;0;0;0;0;0;0;0;0;0;0;0;0;0
55;0.0042822;-2.2059e-06;-4.6387e-05;0.20338;0;0;0;0;0;0;0;0;0;0;0;0;0
56.001;0.0044303;-2.2206e-05;-3.727e-05;0.20959;0;0;0;0;0;0;0;0;0;0;0;0;0
57;0.004589;-3.8842e-05;1.9753e-05;0.21583;0;0;0;0;0;0;0;0;0;0;0;0;0
57.999;0.0048109;-4.1e-05;-3.4305e-05;0.22204;0;0;0;0;0;0;0;0;0;0;0;0;0
59.002;0.0048909;-3.4176e-05;-1.8726e-05;0.22813;0;0;0;0;0;0;0;0;0;0;0;0;0
59.999;0.0051289;1.3413e-06;6.967e-05;0.23392;0;0;0;0;0;0;0;0;0;0;0;0;0
61;0.005381;-1.2952e-05;0.00013673;0.23991;0;0;0;0;0;0;0;0;0;0;0;0;0
62;0.0055472;0.00015658;0.00025484;0.24532;0;0;0;0;0;0;0;0;0;0;0;0;0
63;0.0058143;0.00012389;0.00024738;0.25016;0;0;0;0;0;0;0;0;0;0;0;0;0
64;0.0058435;0.00020303;0.00034224;0.25495;0;0;0;0;0;0;0;0;0;0;0;0;0
65;0.0061564;0.00024003;0.00032414;0.25925;0;0;0;0;0;0;0;0;0;0;0;0;0
66;0.0065296;0.00035618;0.00039804;0.26339;0;0;0;0;0;0;0;0;0;0;0;0;0
66.999;0.0065791;0.00022215;0.00045647;0.26743;0;0;0;0;0;0;0;0;0;0;0;0;0
68;0.0067259;0.00032211;0.00040383;0.27138;0;0;0;0;0;0;0;0;0;0;0;0;0
69;0.0067354;0.00023685;0.00054967;0.27527;0;0;0;0;0;0;0;0;0;0;0;0;0
70;0.0072937;0.00024727;0.0004079;0.2791;0;0;0;0;0;0;0;0;0;0;0;0;0
71;0.0073469;0.00028576;0.00053821;0.28291;0;0;0;0;0;0;0;0;0;0;0;0;0
72.001;0.0075739;0.00029836;0.00045864;0.2867;0;0;0;0;0;0;0;0;0;0;0;0;0
73;0.0075831;0.00046952;0.00047749;0.29061;0;0;0;0;0;0;0;0;0;0;0;0;0
73.999;0.0079257;0.00034138;0.00049012;0.29417;0;0;0;0;0;0;0;0;0;0;0;0;0
75;0.0082149;0.00032672;0.00055433;0.29784;0;0;0;0;0;0;0;0;0;0;0;0;0
76;0.0085578;0.00039742;0.00049975;0.30164;0;0;0;0;0;0;0;0;0;0;0;0;0
76.999;0.0087125;0.00033013;0.00045329;0.30515;0;0;0;0;0;0;0;0;0;0;0;0;0
78;0.0087704;0.00036357;0.00058318;0.30872;0;0;0;0;0;0;0;0;0;0;0;0;0
79;0.0093565;0.00025659;0.00057918;0.31256;0;0;0;0;0;0;0;0;0;0;0;0;0
80;0.0096742;0.00033399;0.00058643;0.31627;0;0;0;0;0;0;0;0;0;0;0;0;0
81;0.010011;0.0004844;0.00059289;0.31984;0;0;0;0;0;0;0;0;0;0;0;0;0
82;0.010146;0.00048368;0.00052212;0.32369;0;0;0;0;0;0;0;0;0;0;0;0;0
83;0.010609;0.00066867;0.00069154;0.32742;0;0;0;0;0;0;0;0;0;0;0;0;0
84;0.011008;0.00068849;0.0008611;0.3311;0;0;0;0;0;0;0;0;0;0;0;0;0
85;0.011406;0.00076951;0.00075247;0.33476;0;0;0;0;0;0;0;0;0;0;0;0;0
85.999;0.012001;0.00085449;0.00090551;0.33833;0;0;0;0;0;0;0;0;0;0;0;0;0
87;0.011623;0.0010399;0.00082283;0.34182;0;0;0;0;0;0;0;0;0;0;0;0;0
88;0.012554;0.0010358;0.0008682;0.34524;0;0;0;0;0;0;0;0;0;0;0;0;0
88.999;0.0129;0.0011045;0.00097992;0.34859;0;0;0;0;0;0;0;0;0;0;0;0;0
90;0.013577;0.0013084;0.0010673;0.35173;0;0;0;0;0;0;0;0;0;0;0;0;0
91;0.014153;0.0011801;0.0012449;0.35507;0;0;0;0;0;0;0;0;0;0;0;0;0
92;0.014565;0.0014283;0.0013114;0.35807;0;0;0;0;0;0;0;0;0;0;0;0;0
93;0.014224;0.0012947;0.0013033;0.36121;0;0;0;0;0;0;0;0;0;0;0;0;0
93.999;0.015314;0.0013394;0.0014467;0.36418;0;0;0;0;0;0;0;0;0;0;0;0;0
95.001;0.016175;0.0014413;0.0016801;0.36707;0;0;0;0;0;0;0;0;0;0;0;0;0
96.001;0.016779;0.0016271;0.0016818;0.36989;0;0;0;0;0;0;0;0;0;0;0;0;0
97;0.017388;0.0016932;0.0018431;0.37264;0;0;0;0;0;0;0;0;0;0;0;0;0
98;0.01788;0.0017134;0.0017767;0.37521;0;0;0;0;0;0;0;0;0;0;0;0;0
98.999;0.018712;0.0020594;0.0018542;0.37793;0;0;0;0;0;0;0;0;0;0;0;0;0
100;0.019229;0.0022114;0.0019826;0.38048;0;0;0;0;0;0;0;0;0;0;0;0;0
101;0.019858;0.0022084;0.0021638;0.38296;0;0;0;0;0;0;0;0;0;0;0;0;0
102;0.020469;0.0021653;0.0020965;0.3854;0;0;0;0;0;0;0;0;0;0;0;0;0
103;0.021137;0.0023653;0.0023875;0.38769;0;0;0;0;0;0;0;0;0;0;0;0;0
104;0.021819;0.002473;0.0024082;0.39021;0;0;0;0;0;0;0;0;0;0;0;0;0
105;0.022543;0.0025015;0.0024671;0.39241;0;0;0;0;0;0;0;0;0;0;0;0;0
106;0.023183;0.0026978;0.0024335;0.39464;0;0;0;0;0;0;0;0;0;0;0;0;0
107;0.023796;0.0028621;0.002563;0.39677;0;0;0;0;0;0;0;0;0;0;0;0;0
108;0.024369;0.0030001;0.0026452;0.39886;0;0;0;0;0;0;0;0;0;0;0;0;0
109;0.025091;0.0032371;0.0028344;0.4009;0;0;0;0;0;0;0;0;0;0;0;0;0
110;0.025614;0.0033689;0.0029321;0.40289;0;0;0;0;0;0;0;0;0;0;0;0;0
111;0.026402;0.0035136;0.0030455;0.4049;0;0;0;0;0;0;0;0;0;0;0;0;0
112;0.027096;0.0036746;0.0031543;0.40686;0;0;0;0;0;0;0;0;0;0;0;0;0
113;0.028052;0.0038058;0.0033366;0.40878;0;0;0;0;0;0;0;0;0;0;0;0;0
114;0.028766;0.0040326;0.0033876;0.41074;0;0;0;0;0;0;0;0;0;0;0;0;0
115;0.029564;0.0040686;0.0034222;0.41247;0;0;0;0;0;0;0;0;0;0;0;0;0
116;0.030177;0.0042248;0.0034767;0.41417;0;0;0;0;0;0;0;0;0;0;0;0;0
117;0.031414;0.0042908;0.0036201;0.41603;0;0;0;0;0;0;0;0;0;0;0;0;0
118;0.031655;0.0045274;0.0037188;0.41764;0;0;0;0;0;0;0;0;0;0;0;0;0
119;0.032369;0.0045668;0.0037713;0.4193;0;0;0;0;0;0;0;0;0;0;0;0;0
120;0.033275;0.004797;0.0041251;0.42096;0;0;0;0;0;0;0;0;0;0;0;0;0
121;0.03416;0.0049399;0.0041584;0.42257;0;0;0;0;0;0;0;0;0;0;0;0;0
122;0.034771;0.0051082;0.0042227;0.42412;0;0;0;0;0;0;0;0;0;0;0;0;0
123;0.035396;0.0053098;0.0042817;0.42568;0;0;0;0;0;0;0;0;0;0;0;0;0
124;0.036168;0.0055734;0.0044501;0.4272;0;0;0;0;0;0;0;0;0;0;0;0;0
125;0.036988;0.0057378;0.0045952;0.4287;0;0;0;0;0;0;0;0;0;0;0;0;0
126;0.037803;0.0057873;0.0047386;0.4302;0;0;0;0;0;0;0;0;0;0;0;0;0
127;0.038557;0.0060007;0.0048828;0.43169;0;0;0;0;0;0;0;0;0;0;0;0;0
128;0.039492;0.0061701;0.0049719;0.43313;0;0;0;0;0;0;0;0;0;0;0;0;0
129;0.040134;0.0062373;0.0050787;0.43456;0;0;0;0;0;0;0;0;0;0;0;0;0
130;0.040936;0.0063081;0.0051645;0.43594;0;0;0;0;0;0;0;0;0;0;0;0;0
131;0.041749;0.0063642;0.0052747;0.43731;0;0;0;0;0;0;0;0;0;0;0;0;0
132;0.04255;0.0067197;0.0054917;0.43867;0;0;0;0;0;0;0;0;0;0;0;0;0
133;0.043363;0.0069611;0.0057593;0.44003;0;0;0;0;0;0;0;0;0;0;0;0;0
134;0.044064;0.0070361;0.0058195;0.44131;0;0;0;0;0;0;0;0;0;0;0;0;0
135;0.044906;0.0072173;0.0060724;0.44262;0;0;0;0;0;0;0;0;0;0;0;0;0
136;0.045624;0.007353;0.0061275;0.44395;0;0;0;0;0;0;0;0;0;0;0;0;0
137;0.046465;0.0076804;0.0063303;0.44515;0;0;0;0;0;0;0;0;0;0;0;0;0
138;0.047211;0.0076721;0.0064723;0.44643;0;0;0;0;0;0;0;0;0;0;0;0;0
139;0.047988;0.0077849;0.0066193;0.44765;0;0;0;0;0;0;0;0;0;0;0;0;0
140;0.048809;0.0080255;0.0069427;0.44882;0;0;0;0;0;0;0;0;0;0;0;0;0
141;0.049632;0.0081194;0.0070316;0.45008;0;0;0;0;0;0;0;0;0;0;0;0;0
142;0.050449;0.0082972;0.0073615;0.45128;0;0;0;0;0;0;0;0;0;0;0;0;0
143;0.051182;0.0084727;0.0073128;0.45252;0;0;0;0;0;0;0;0;0;0;0;0;0
144;0.052155;0.0085864;0.0076467;0.45364;0;0;0;0;0;0;0;0;0;0;0;0;0
145;0.053082;0.0088139;0.0077344;0.45475;0;0;0;0;0;0;0;0;0;0;0;0;0
146;0.053883;0.0090121;0.0078456;0.45598;0;0;0;0;0;0;0;0;0;0;0;0;0
147;0.054711;0.0090026;0.0081981;0.45706;0;0;0;0;0;0;0;0;0;0;0;0;0
148;0.055456;0.0091553;0.0083196;0.45815;0;0;0;0;0;0;0;0;0;0;0;0;0
149;0.056238;0.0093639;0.0085094;0.45927;0;0;0;0;0;0;0;0;0;0;0;0;0
150;0.05715;0.0094231;0.0087702;0.46031;0;0;0;0;0;0;0;0;0;0;0;0;0
151;0.058173;0.0094767;0.0090421;0.46135;0;0;0;0;0;0;0;0;0;0;0;0;0
152;0.058991;0.0098604;0.0093416;0.46235;0;0;0;0;0;0;0;0;0;0;0;0;0
153;0.059789;0.0099802;0.0095319;0.46342;0;0;0;0;0;0;0;0;0;0;0;0;0
154;0.060345;0.010061;0.0097797;0.46445;0;0;0;0;0;0;0;0;0;0;0;0;0
155;0.061457;0.010179;0.009843;0.46549;0;0;0;0;0;0;0;0;0;0;0;0;0
156;0.06216;0.01029;0.010122;0.46645;0;0;0;0;0;0;0;0;0;0;0;0;0
157;0.062964;0.010598;0.010456;0.46742;0;0;0;0;0;0;0;0;0;0;0;0;0
158;0.063585;0.010727;0.010558;0.46836;0;0;0;0;0;0;0;0;0;0;0;0;0
159;0.064755;0.010897;0.010714;0.46932;0;0;0;0;0;0;0;0;0;0;0;0;0
160;0.065252;0.01116;0.010897;0.47027;0;0;0;0;0;0;0;0;0;0;0;0;0
161;0.066349;0.011206;0.010978;0.47123;0;0;0;0;0;0;0;0;0;0;0;0;0
162;0.067089;0.011373;0.011171;0.47219;0;0;0;0;0;0;0;0;0;0;0;0;0
163;0.067814;0.011517;0.01123;0.47311;0;0;0;0;0;0;0;0;0;0;0;0;0
164;0.068575;0.011574;0.011303;0.47403;0;0;0;0;0;0;0;0;0;0;0;0;0
165;0.069397;0.011828;0.011601;0.47489;0;0;0;0;0;0;0;0;0;0;0;0;0
166;0.07034;0.011929;0.011557;0.47582;0;0;0;0;0;0;0;0;0;0;0;0;0
167;0.071276;0.012121;0.011746;0.47672;0;0;0;0;0;0;0;0;0;0;0;0;0
168;0.071938;0.012292;0.011926;0.47757;0;0;0;0;0;0;0;0;0;0;0;0;0
169;0.073041;0.012532;0.012073;0.47843;0;0;0;0;0;0;0;0;0;0;0;0;0
170;0.073728;0.012834;0.012204;0.4793;0;0;0;0;0;0;0;0;0;0;0;0;0
171;0.074697;0.012914;0.012375;0.48015;0;0;0;0;0;0;0;0;0;0;0;0;0
172;0.075475;0.013032;0.012643;0.48099;0;0;0;0;0;0;0;0;0;0;0;0;0
173;0.07621;0.013121;0.012753;0.48188;0;0;0;0;0;0;0;0;0;0;0;0;0
174;0.076914;0.013397;0.012921;0.48267;0;0;0;0;0;0;0;0;0;0;0;0;0
175;0.077837;0.013448;0.013125;0.48345;0;0;0;0;0;0;0;0;0;0;0;0;0
176;0.078646;0.013628;0.013194;0.48424;0;0;0;0;0;0;0;0;0;0;0;0;0
177;0.079518;0.013736;0.013393;0.48502;0;0;0;0;0;0;0;0;0;0;0;0;0
178;0.080253;0.013861;0.013536;0.48583;0;0;0;0;0;0;0;0;0;0;0;0;0
179;0.081307;0.014137;0.01368;0.4866;0;0;0;0;0;0;0;0;0;0;0;0;0
180;0.082125;0.014306;0.013931;0.48743;0;0;0;0;0;0;0;0;0;0;0;0;0
181;0.082814;0.014507;0.013996;0.48823;0;0;0;0;0;0;0;0;0;0;0;0;0
182;0.083496;0.014665;0.014262;0.48894;0;0;0;0;0;0;0;0;0;0;0;0;0
183;0.08466;0.014833;0.014561;0.48973;0;0;0;0;0;0;0;0;0;0;0;0;0
184;0.085478;0.015058;0.014847;0.49046;0;0;0;0;0;0;0;0;0;0;0;0;0
185;0.086336;0.015312;0.014987;0.49118;0;0;0;0;0;0;0;0;0;0;0;0;0
186;0.087065;0.015216;0.015291;0.49195;0;0;0;0;0;0;0;0;0;0;0;0;0
187;0.08797;0.015465;0.015426;0.49266;0;0;0;0;0;0;0;0;0;0;0;0;0
188;0.088885;0.015651;0.015492;0.49344;0;0;0;0;0;0;0;0;0;0;0;0;0
189;0.089723;0.015915;0.015685;0.49414;0;0;0;0;0;0;0;0;0;0;0;0;0
190;0.090657;0.015926;0.0159;0.4948;0;0;0;0;0;0;0;0;0;0;0;0;0
191;0.091407;0.016176;0.016086;0.49555;0;0;0;0;0;0;0;0;0;0;0;0;0
192;0.092274;0.016467;0.016367;0.49623;0;0;0;0;0;0;0;0;0;0;0;0;0
193;0.093158;0.016454;0.01661;0.49691;0;0;0;0;0;0;0;0;0;0;0;0;0
194;0.094146;0.016681;0.016829;0.4976;0;0;0;0;0;0;0;0;0;0;0;0;0
195;0.09501;0.016762;0.016948;0.49827;0;0;0;0;0;0;0;0;0;0;0;0;0
196;0.095727;0.016964;0.017102;0.49895;0;0;0;0;0;0;0;0;0;0;0;0;0
197;0.096564;0.017133;0.017373;0.49964;0;0;0;0;0;0;0;0;0;0;0;0;0
198;0.097327;0.017182;0.017436;0.5003;0;0;0;0;0;0;0;0;0;0;0;0;0
199;0.098073;0.017512;0.017629;0.50102;0;0;0;0;0;0;0;0;0;0;0;0;0
200;0.099019;0.017573;0.017803;0.50167;0;0;0;0;0;0;0;0;0;0;0;0;0
201;0.099936;0.017816;0.018095;0.50235;0;0;0;0;0;0;0;0;0;0;0;0;0
202;0.10079;0.017911;0.018109;0.50298;0;0;0;0;0;0;0;0;0;0;0;0;0
203;0.10149;0.018199;0.01842;0.50359;0;0;0;0;0;0;0;0;0;0;0;0;0
204;0.10229;0.018309;0.018643;0.5042;0;0;0;0;0;0;0;0;0;0;0;0;0
205;0.10325;0.018722;0.018948;0.50482;0;0;0;0;0;0;0;0;0;0;0;0;0
206;0.1037;0.018813;0.019183;0.50543;0;0;0;0;0;0;0;0;0;0;0;0;0
207;0.105;0.01907;0.019357;0.50611;0;0;0;0;0;0;0;0;0;0;0;0;0
208;0.10568;0.019204;0.019695;0.50671;0;0;0;0;0;0;0;0;0;0;0;0;0
209;0.10622;0.019331;0.019951;0.5073;0;0;0;0;0;0;0;0;0;0;0;0;0
210;0.1072;0.019574;0.020139;0.50792;0;0;0;0;0;0;0;0;0;0;0;0;0
211;0.10829;0.019756;0.020272;0.50851;0;0;0;0;0;0;0;0;0;0;0;0;0
212;0.10907;0.019941;0.020625;0.50911;0;0;0;0;0;0;0;0;0;0;0;0;0
213;0.11006;0.020067;0.020899;0.50968;0;0;0;0;0;0;0;0;0;0;0;0;0
214;0.11072;0.020239;0.02111;0.51024;0;0;0;0;0;0;0;0;0;0;0;0;0
215;0.11162;0.020399;0.021335;0.51082;0;0;0;0;0;0;0;0;0;0;0;0;0
216;0.11273;0.020616;0.021559;0.51137;0;0;0;0;0;0;0;0;0;0;0;0;0
217;0.1135;0.020895;0.021792;0.51197;0;0;0;0;0;0;0;0;0;0;0;0;0
218;0.11429;0.021158;0.021999;0.51255;0;0;0;0;0;0;0;0;0;0;0;0;0
219;0.11513;0.021428;0.022287;0.51311;0;0;0;0;0;0;0;0;0;0;0;0;0
220;0.11575;0.021556;0.022501;0.51366;0;0;0;0;0;0;0;0;0;0;0;0;0
221;0.11666;0.021772;0.022819;0.51419;0;0;0;0;0;0;0;0;0;0;0;0;0
222;0.11755;0.021928;0.023116;0.51475;0;0;0;0;0;0;0;0;0;0;0;0;0
223;0.11853;0.022147;0.023372;0.51529;0;0;0;0;0;0;0;0;0;0;0;0;0
224;0.11936;0.022252;0.023443;0.51582;0;0;0;0;0;0;0;0;0;0;0;0;0
225;0.12031;0.022456;0.023829;0.51637;0;0;0;0;0;0;0;0;0;0;0;0;0
226;0.12113;0.02277;0.024073;0.51689;0;0;0;0;0;0;0;0;0;0;0;0;0
227;0.12189;0.022949;0.024337;0.51743;0;0;0;0;0;0;0;0;0;0;0;0;0
228;0.12285;0.023237;0.024403;0.51795;0;0;0;0;0;0;0;0;0;0;0;0;0
229;0.12377;0.02351;0.024666;0.51846;0;0;0;0;0;0;0;0;0;0;0;0;0
230;0.1246;0.023669;0.024905;0.51901;0;0;0;0;0;0;0;0;0;0;0;0;0
231;0.1255;0.023934;0.025078;0.51952;0;0;0;0;0;0;0;0;0;0;0;0;0
232;0.12637;0.024199;0.025382;0.52002;0;0;0;0;0;0;0;0;0;0;0;0;0
233;0.12704;0.024366;0.025559;0.52058;0;0;0;0;0;0;0;0;0;0;0;0;0
234;0.12859;0.024616;0.025841;0.52108;0;0;0;0;0;0;0;0;0;0;0;0;0
235;0.12884;0.024906;0.026;0.52159;0;0;0;0;0;0;0;0;0;0;0;0;0
236;0.12969;0.025038;0.026246;0.52209;0;0;0;0;0;0;0;0;0;0;0;0;0
237;0.13071;0.025424;0.026471;0.52256;0;0;0;0;0;0;0;0;0;0;0;0;0
238;0.13141;0.025498;0.02676;0.52301;0;0;0;0;0;0;0;0;0;0;0;0;0
239;0.13197;0.025767;0.027004;0.52348;0;0;0;0;0;0;0;0;0;0;0;0;0
240;0.13309;0.026079;0.027214;0.52398;0;0;0;0;0;0;0;0;0;0;0;0;0
241;0.13397;0.026254;0.027372;0.52445;0;0;0;0;0;0;0;0;0;0;0;0;0
242;0.13483;0.026496;0.027643;0.52491;0;0;0;0;0;0;0;0;0;0;0;0;0
243;0.13569;0.026643;0.027896;0.52537;0;0;0;0;0;0;0;0;0;0;0;0;0
244;0.13649;0.026886;0.02808;0.52588;0;0;0;0;0;0;0;0;0;0;0;0;0
245;0.13725;0.027069;0.028331;0.52638;0;0;0;0;0;0;0;0;0;0;0;0;0
246;0.1382;0.027286;0.02851;0.52687;0;0;0;0;0;0;0;0;0;0;0;0;0
247;0.13916;0.027572;0.028732;0.52733;0;0;0;0;0;0;0;0;0;0;0;0;0
248;0.13999;0.0276;0.028928;0.52775;0;0;0;0;0;0;0;0;0;0;0;0;0
249;0.14082;0.027837;0.029101;0.5282;0;0;0;0;0;0;0;0;0;0;0;0;0
250;0.14169;0.028116;0.029268;0.52864;0;0;0;0;0;0;0;0;0;0;0;0;0
251;0.14255;0.02826;0.029482;0.52909;0;0;0;0;0;0;0;0;0;0;0;0;0
252;0.14336;0.028474;0.029689;0.52954;0;0;0;0;0;0;0;0;0;0;0;0;0
253;0.14419;0.028721;0.029837;0.52998;0;0;0;0;0;0;0;0;0;0;0;0;0
254;0.14511;0.028868;0.030123;0.53045;0;0;0;0;0;0;0;0;0;0;0;0;0
255;0.14617;0.029091;0.030301;0.53089;0;0;0;0;0;0;0;0;0;0;0;0;0
256;0.14702;0.029288;0.030481;0.53138;0;0;0;0;0;0;0;0;0;0;0;0;0
257;0.14782;0.029657;0.030553;0.5318;0;0;0;0;0;0;0;0;0;0;0;0;0
258;0.14872;0.029783;0.030917;0.53221;0;0;0;0;0;0;0;0;0;0;0;0;0
259;0.1495;0.029903;0.031096;0.53263;0;0;0;0;0;0;0;0;0;0;0;0;0
260;0.15043;0.030172;0.031366;0.53308;0;0;0;0;0;0;0;0;0;0;0;0;0
261;0.15133;0.03049;0.03149;0.53349;0;0;0;0;0;0;0;0;0;0;0;0;0
262;0.15212;0.030885;0.031599;0.5339;0;0;0;0;0;0;0;0;0;0;0;0;0
263;0.15301;0.030966;0.031786;0.53432;0;0;0;0;0;0;0;0;0;0;0;0;0
264;0.15399;0.031219;0.032068;0.53471;0;0;0;0;0;0;0;0;0;0;0;0;0
265;0.15485;0.031374;0.032197;0.53509;0;0;0;0;0;0;0;0;0;0;0;0;0
266;0.1558;0.031659;0.032538;0.5355;0;0;0;0;0;0;0;0;0;0;0;0;0
267;0.15688;0.031939;0.032754;0.53591;0;0;0;0;0;0;0;0;0;0;0;0;0
268;0.15734;0.032017;0.032889;0.53631;0;0;0;0;0;0;0;0;0;0;0;0;0
269;0.15821;0.032241;0.033112;0.53677;0;0;0;0;0;0;0;0;0;0;0;0;0
270;0.15914;0.032566;0.033298;0.53717;0;0;0;0;0;0;0;0;0;0;0;0;0
271;0.16011;0.032778;0.03366;0.53757;0;0;0;0;0;0;0;0;0;0;0;0;0
272;0.16103;0.033077;0.034022;0.53796;0;0;0;0;0;0;0;0;0;0;0;0;0
273;0.16186;0.033335;0.034213;0.53834;0;0;0;0;0;0;0;0;0;0;0;0;0
274;0.16278;0.033515;0.034482;0.53875;0;0;0;0;0;0;0;0;0;0;0;0;0
275;0.16361;0.033721;0.034599;0.53916;0;0;0;0;0;0;0;0;0;0;0;0;0
276;0.16443;0.034193;0.034883;0.53955;0;0;0;0;0;0;0;0;0;0;0;0;0
277;0.16549;0.034528;0.035081;0.5399;0;0;0;0;0;0;0;0;0;0;0;0;0
278;0.16659;0.034523;0.035377;0.54026;0;0;0;0;0;0;0;0;0;0;0;0;0
279;0.16729;0.034916;0.035676;0.54061;0;0;0;0;0;0;0;0;0;0;0;0;0
280;0.16831;0.035041;0.035861;0.54096;0;0;0;0;0;0;0;0;0;0;0;0;0
281;0.16915;0.035275;0.036139;0.54134;0;0;0;0;0;0;0;0;0;0;0;0;0
282;0.17037;0.035536;0.036256;0.54174;0;0;0;0;0;0;0;0;0;0;0;0;0
283;0.17083;0.035818;0.03642;0.54213;0;0;0;0;0;0;0;0;0;0;0;0;0
284;0.17198;0.036031;0.036614;0.5425;0;0;0;0;0;0;0;0;0;0;0;0;0
285;0.17305;0.036246;0.036869;0.54284;0;0;0;0;0;0;0;0;0;0;0;0;0
286;0.17374;0.036485;0.03706;0.54319;0;0;0;0;0;0;0;0;0;0;0;0;0
287;0.1745;0.03672;0.037327;0.54354;0;0;0;0;0;0;0;0;0;0;0;0;0
288;0.1752;0.037052;0.037531;0.54388;0;0;0;0;0;0;0;0;0;0;0;0;0
289;0.17647;0.03733;0.037864;0.54428;0;0;0;0;0;0;0;0;0;0;0;0;0
290;0.17744;0.037831;0.03822;0.54465;0;0;0;0;0;0;0;0;0;0;0;0;0
291;0.1783;0.037992;0.038519;0.54506;0;0;0;0;0;0;0;0;0;0;0;0;0
292;0.17917;0.038262;0.038679;0.54541;0;0;0;0;0;0;0;0;0;0;0;0;0
293;0.18023;0.038554;0.038929;0.54574;0;0;0;0;0;0;0;0;0;0;0;0;0
294;0.18121;0.038777;0.03919;0.5461;0;0;0;0;0;0;0;0;0;0;0;0;0
295;0.18211;0.039116;0.039487;0.54645;0;0;0;0;0;0;0;0;0;0;0;0;0
296;0.183;0.039413;0.03987;0.5468;0;0;0;0;0;0;0;0;0;0;0;0;0
297;0.18389;0.039762;0.039975;0.54714;0;0;0;0;0;0;0;0;0;0;0;0;0
298;0.18488;0.040141;0.040294;0.54746;0;0;0;0;0;0;0;0;0;0;0;0;0
299;0.18572;0.040328;0.040533;0.54779;0;0;0;0;0;0;0;0;0;0;0;0;0
300;0.18664;0.040759;0.040752;0.54813;0;0;0;0;0;0;0;0;0;0;0;0;0
301;0.18774;0.041202;0.041061;0.54845;0;0;0;0;0;0;0;0;0;0;0;0;0
302;0.18869;0.041444;0.04128;0.54881;0;0;0;0;0;0;0;0;0;0;0;0;0
303;0.18963;0.041734;0.041626;0.54914;0;0;0;0;0;0;0;0;0;0;0;0;0
304;0.19056;0.041963;0.04178;0.54946;0;0;0;0;0;0;0;0;0;0;0;0;0
305;0.19139;0.042307;0.042013;0.54976;0;0;0;0;0;0;0;0;0;0;0;0;0
306;0.19244;0.042798;0.042103;0.55008;0;0;0;0;0;0;0;0;0;0;0;0;0
307;0.19345;0.043019;0.042435;0.55038;0;0;0;0;0;0;0;0;0;0;0;0;0
308;0.19432;0.043358;0.042777;0.55073;0;0;0;0;0;0;0;0;0;0;0;0;0
309;0.19539;0.043608;0.042958;0.55104;0;0;0;0;0;0;0;0;0;0;0;0;0
310;0.19626;0.043864;0.043222;0.55136;0;0;0;0;0;0;0;0;0;0;0;0;0
311;0.19707;0.044097;0.043418;0.55168;0;0;0;0;0;0;0;0;0;0;0;0;0
312;0.19812;0.044375;0.043666;0.55199;0;0;0;0;0;0;0;0;0;0;0;0;0
313;0.19965;0.04455;0.043909;0.5523;0;0;0;0;0;0;0;0;0;0;0;0;0
314;0.19998;0.044901;0.044298;0.55262;0;0;0;0;0;0;0;0;0;0;0;0;0
315;0.20094;0.045131;0.044519;0.55291;0;0;0;0;0;0;0;0;0;0;0;0;0
316;0.20196;0.045431;0.044746;0.55321;0;0;0;0;0;0;0;0;0;0;0;0;0
317;0.20272;0.045723;0.044896;0.55349;0;0;0;0;0;0;0;0;0;0;0;0;0
318;0.20372;0.046073;0.045274;0.55377;0;0;0;0;0;0;0;0;0;0;0;0;0
319;0.20461;0.046378;0.04556;0.55407;0;0;0;0;0;0;0;0;0;0;0;0;0
320;0.20576;0.046763;0.045768;0.55437;0;0;0;0;0;0;0;0;0;0;0;0;0
321;0.20645;0.047008;0.04611;0.55465;0;0;0;0;0;0;0;0;0;0;0;0;0
322;0.20759;0.047467;0.046421;0.55496;0;0;0;0;0;0;0;0;0;0;0;0;0
323;0.20893;0.0479;0.046594;0.55525;0;0;0;0;0;0;0;0;0;0;0;0;0
324;0.20935;0.048157;0.046977;0.55556;0;0;0;0;0;0;0;0;0;0;0;0;0
325;0.21038;0.048336;0.047384;0.55587;0;0;0;0;0;0;0;0;0;0;0;0;0
326;0.2115;0.048672;0.047588;0.55615;0;0;0;0;0;0;0;0;0;0;0;0;0
327;0.21238;0.04902;0.047962;0.5564;0;0;0;0;0;0;0;0;0;0;0;0;0
328;0.21326;0.049271;0.048277;0.55668;0;0;0;0;0;0;0;0;0;0;0;0;0
329;0.21427;0.049653;0.04861;0.55693;0;0;0;0;0;0;0;0;0;0;0;0;0
330;0.21554;0.050102;0.049014;0.55723;0;0;0;0;0;0;0;0;0;0;0;0;0
331;0.21619;0.050417;0.049229;0.55748;0;0;0;0;0;0;0;0;0;0;0;0;0
332;0.21746;0.050694;0.049701;0.55777;0;0;0;0;0;0;0;0;0;0;0;0;0
333;0.21834;0.050959;0.050098;0.55802;0;0;0;0;0;0;0;0;0;0;0;0;0
334;0.21935;0.051348;0.050457;0.55829;0;0;0;0;0;0;0;0;0;0;0;0;0
335;0.22001;0.051522;0.050742;0.55854;0;0;0;0;0;0;0;0;0;0;0;0;0
336;0.22114;0.051791;0.05103;0.55879;0;0;0;0;0;0;0;0;0;0;0;0;0
337;0.2221;0.052145;0.051314;0.55903;0;0;0;0;0;0;0;0;0;0;0;0;0
338;0.22304;0.052439;0.051697;0.55929;0;0;0;0;0;0;0;0;0;0;0;0;0
339;0.22403;0.052692;0.052037;0.55955;0;0;0;0;0;0;0;0;0;0;0;0;0
340;0.22495;0.052961;0.052399;0.55979;0;0;0;0;0;0;0;0;0;0;0;0;0
341;0.2259;0.05336;0.052785;0.56001;0;0;0;0;0;0;0;0;0;0;0;0;0
342;0.22683;0.053654;0.053156;0.56027;0;0;0;0;0;0;0;0;0;0;0;0;0
343;0.22774;0.05401;0.05353;0.56051;0;0;0;0;0;0;0;0;0;0;0;0;0
344;0.22882;0.054377;0.053818;0.56076;0;0;0;0;0;0;0;0;0;0;0;0;0
345;0.22977;0.054557;0.054176;0.561;0;0;0;0;0;0;0;0;0;0;0;0;0
346;0.23075;0.054906;0.054466;0.56123;0;0;0;0;0;0;0;0;0;0;0;0;0
347;0.23178;0.055332;0.054948;0.56147;0;0;0;0;0;0;0;0;0;0;0;0;0
348;0.23276;0.055638;0.055252;0.56174;0;0;0;0;0;0;0;0;0;0;0;0;0
349;0.23368;0.056036;0.055494;0.56198;0;0;0;0;0;0;0;0;0;0;0;0;0
350;0.23473;0.056485;0.055937;0.5622;0;0;0;0;0;0;0;0;0;0;0;0;0
351;0.23573;0.056714;0.056275;0.56243;0;0;0;0;0;0;0;0;0;0;0;0;0
352;0.2367;0.057102;0.056545;0.56268;0;0;0;0;0;0;0;0;0;0;0;0;0
353;0.23771;0.057475;0.056926;0.56291;0;0;0;0;0;0;0;0;0;0;0;0;0
354;0.23914;0.058061;0.057126;0.56312;0;0;0;0;0;0;0;0;0;0;0;0;0
355;0.23986;0.058227;0.05753;0.56336;0;0;0;0;0;0;0;0;0;0;0;0;0
356;0.24084;0.05862;0.057768;0.56359;0;0;0;0;0;0;0;0;0;0;0;0;0
357;0.24191;0.05891;0.058012;0.56382;0;0;0;0;0;0;0;0;0;0;0;0;0
358;0.24275;0.059513;0.058422;0.56404;0;0;0;0;0;0;0;0;0;0;0;0;0
359.01;0.24379;0.059741;0.058663;0.56424;0;0;0;0;0;0;0;0;0;0;0;0;0
360;0.24485;0.060156;0.058928;0.56444;0;0;0;0;0;0;0;0;0;0;0;0;0
361;0.24587;0.060526;0.059446;0.56463;0;0;0;0;0;0;0;0;0;0;0;0;0
362;0.24677;0.06104;0.059707;0.56482;0;0;0;0;0;0;0;0;0;0;0;0;0
363;0.24807;0.061478;0.060077;0.56504;0;0;0;0;0;0;0;0;0;0;0;0;0
364;0.24906;0.061763;0.060472;0.56528;0;0;0;0;0;0;0;0;0;0;0;0;0
365;0.24968;0.062276;0.060776;0.56547;0;0;0;0;0;0;0;0;0;0;0;0;0
366;0.25115;0.062773;0.061077;0.56568;0;0;0;0;0;0;0;0;0;0;0;0;0
367;0.25197;0.063179;0.061542;0.5659;0;0;0;0;0;0;0;0;0;0;0;0;0
368;0.25305;0.063718;0.062001;0.56611;0;0;0;0;0;0;0;0;0;0;0;0;0
369;0.25406;0.064176;0.06236;0.5663;0;0;0;0;0;0;0;0;0;0;0;0;0
370.02;0.25505;0.064541;0.062744;0.56652;0;0;0;0;0;0;0;0;0;0;0;0;0
371;0.25629;0.065171;0.063193;0.56669;0;0;0;0;0;0;0;0;0;0;0;0;0
372;0.25756;0.065569;0.06356;0.56684;0;0;0;0;0;0;0;0;0;0;0;0;0
373;0.25825;0.066092;0.064031;0.56701;0;0;0;0;0;0;0;0;0;0;0;0;0
374;0.25929;0.066576;0.064493;0.56719;0;0;0;0;0;0;0;0;0;0;0;0;0
375;0.26025;0.066992;0.064915;0.56739;0;0;0;0;0;0;0;0;0;0;0;0;0
376;0.26141;0.067463;0.065399;0.56758;0;0;0;0;0;0;0;0;0;0;0;0;0
377;0.26251;0.0681;0.065846;0.56776;0;0;0;0;0;0;0;0;0;0;0;0;0
378;0.26344;0.068677;0.066333;0.56796;0;0;0;0;0;0;0;0;0;0;0;0;0
379;0.26456;0.069173;0.066878;0.56813;0;0;0;0;0;0;0;0;0;0;0;0;0
380;0.26574;0.069698;0.067343;0.5683;0;0;0;0;0;0;0;0;0;0;0;0;0
381;0.26675;0.070056;0.067919;0.56848;0;0;0;0;0;0;0;0;0;0;0;0;0
382;0.26758;0.070452;0.068402;0.56866;0;0;0;0;0;0;0;0;0;0;0;0;0
383;0.26878;0.070809;0.068995;0.56882;0;0;0;0;0;0;0;0;0;0;0;0;0
384;0.26988;0.071235;0.069458;0.56897;0;0;0;0;0;0;0;0;0;0;0;0;0
385;0.27086;0.071625;0.069926;0.56913;0;0;0;0;0;0;0;0;0;0;0;0;0
386;0.27195;0.072076;0.070466;0.5693;0;0;0;0;0;0;0;0;0;0;0;0;0
387;0.27304;0.07246;0.070943;0.56945;0;0;0;0;0;0;0;0;0;0;0;0;0
388;0.27404;0.072956;0.071552;0.56962;0;0;0;0;0;0;0;0;0;0;0;0;0
389;0.27498;0.073441;0.072035;0.56975;0;0;0;0;0;0;0;0;0;0;0;0;0
390;0.27591;0.073913;0.072589;0.56989;0;0;0;0;0;0;0;0;0;0;0;0;0
391;0.27713;0.074373;0.073203;0.57006;0;0;0;0;0;0;0;0;0;0;0;0;0
392;0.27821;0.074834;0.073655;0.57019;0;0;0;0;0;0;0;0;0;0;0;0;0
393;0.27934;0.07548;0.074241;0.57033;0;0;0;0;0;0;0;0;0;0;0;0;0
394;0.28025;0.076051;0.074692;0.57049;0;0;0;0;0;0;0;0;0;0;0;0;0
395;0.28143;0.076572;0.075236;0.57062;0;0;0;0;0;0;0;0;0;0;0;0;0
396;0.28271;0.077065;0.075731;0.5708;0;0;0;0;0;0;0;0;0;0;0;0;0
397;0.28385;0.077586;0.076186;0.57095;0;0;0;0;0;0;0;0;0;0;0;0;0
398;0.28481;0.078301;0.076724;0.57109;0;0;0;0;0;0;0;0;0;0;0;0;0
399;0.28585;0.078904;0.077139;0.57119;0;0;0;0;0;0;0;0;0;0;0;0;0
400;0.28712;0.079537;0.077623;0.57131;0;0;0;0;0;0;0;0;0;0;0;0;0
401;0.28828;0.080161;0.078161;0.57144;0;0;0;0;0;0;0;0;0;0;0;0;0
402;0.28929;0.080643;0.078761;0.57153;0;0;0;0;0;0;0;0;0;0;0;0;0
403;0.29047;0.081297;0.079246;0.57162;0;0;0;0;0;0;0;0;0;0;0;0;0
404;0.29157;0.081876;0.079773;0.57171;0;0;0;0;0;0;0;0;0;0;0;0;0
405;0.29284;0.082336;0.080349;0.57179;0;0;0;0;0;0;0;0;0;0;0;0;0
406;0.29361;0.083099;0.080862;0.5719;0;0;0;0;0;0;0;0;0;0;0;0;0
407;0.29464;0.08407;0.08144;0.57203;0;0;0;0;0;0;0;0;0;0;0;0;0
408;0.29581;0.084547;0.081992;0.57212;0;0;0;0;0;0;0;0;0;0;0;0;0
409;0.29676;0.084952;0.08258;0.57226;0;0;0;0;0;0;0;0;0;0;0;0;0
410;0.29797;0.085819;0.083227;0.57235;0;0;0;0;0;0;0;0;0;0;0;0;0
411;0.29909;0.086271;0.083843;0.57245;0;0;0;0;0;0;0;0;0;0;0;0;0
412;0.30017;0.087146;0.084403;0.57255;0;0;0;0;0;0;0;0;0;0;0;0;0
413;0.30126;0.087803;0.085133;0.57261;0;0;0;0;0;0;0;0;0;0;0;0;0
414;0.30257;0.088461;0.085844;0.57269;0;0;0;0;0;0;0;0;0;0;0;0;0
415;0.3035;0.089352;0.086407;0.57277;0;0;0;0;0;0;0;0;0;0;0;0;0
416;0.30467;0.090095;0.087121;0.57283;0;0;0;0;0;0;0;0;0;0;0;0;0
417;0.30579;0.09082;0.087797;0.57289;0;0;0;0;0;0;0;0;0;0;0;0;0
418;0.30697;0.091601;0.088407;0.57297;0;0;0;0;0;0;0;0;0;0;0;0;0
419;0.30822;0.092401;0.089014;0.57305;0;0;0;0;0;0;0;0;0;0;0;0;0
420;0.30925;0.093212;0.089758;0.57312;0;0;0;0;0;0;0;0;0;0;0;0;0
421;0.31058;0.094131;0.090368;0.5732;0;0;0;0;0;0;0;0;0;0;0;0;0
422;0.3116;0.094979;0.091214;0.57327;0;0;0;0;0;0;0;0;0;0;0;0;0
423;0.31272;0.095772;0.091901;0.57333;0;0;0;0;0;0;0;0;0;0;0;0;0
424;0.31387;0.096663;0.09273;0.57337;0;0;0;0;0;0;0;0;0;0;0;0;0
425;0.31502;0.097494;0.093564;0.57341;0;0;0;0;0;0;0;0;0;0;0;0;0
426;0.31612;0.098211;0.094479;0.57344;0;0;0;0;0;0;0;0;0;0;0;0;0
427;0.31739;0.099036;0.095474;0.57348;0;0;0;0;0;0;0;0;0;0;0;0;0
428;0.31849;0.099867;0.096374;0.57351;0;0;0;0;0;0;0;0;0;0;0;0;0
429;0.31955;0.10071;0.09733;0.57351;0;0;0;0;0;0;0;0;0;0;0;0;0
430;0.32068;0.10156;0.098251;0.57353;0;0;0;0;0;0;0;0;0;0;0;0;0
431;0.32199;0.10233;0.099227;0.57355;0;0;0;0;0;0;0;0;0;0;0;0;0
432;0.32299;0.10315;0.10014;0.57359;0;0;0;0;0;0;0;0;0;0;0;0;0
433;0.32438;0.10396;0.10113;0.57365;0;0;0;0;0;0;0;0;0;0;0;0;0
434;0.3256;0.10461;0.10205;0.57368;0;0;0;0;0;0;0;0;0;0;0;0;0
435;0.32678;0.10522;0.10292;0.57369;0;0;0;0;0;0;0;0;0;0;0;0;0
436;0.32803;0.10583;0.10382;0.57368;0;0;0;0;0;0;0;0;0;0;0;0;0
437;0.32902;0.10647;0.10476;0.57369;0;0;0;0;0;0;0;0;0;0;0;0;0
438;0.33047;0.10722;0.10559;0.57369;0;0;0;0;0;0;0;0;0;0;0;0;0
439;0.33171;0.10797;0.10655;0.57368;0;0;0;0;0;0;0;0;0;0;0;0;0
440;0.33289;0.10862;0.1075;0.57367;0;0;0;0;0;0;0;0;0;0;0;0;0
441;0.33404;0.1094;0.10839;0.57367;0;0;0;0;0;0;0;0;0;0;0;0;0
442;0.33542;0.11014;0.10928;0.57367;0;0;0;0;0;0;0;0;0;0;0;0;0
443;0.33661;0.11079;0.11021;0.57365;0;0;0;0;0;0;0;0;0;0;0;0;0
444;0.33793;0.11175;0.11121;0.57363;0;0;0;0;0;0;0;0;0;0;0;0;0
445;0.33908;0.11265;0.11206;0.57362;0;0;0;0;0;0;0;0;0;0;0;0;0
446;0.34046;0.11353;0.11293;0.5736;0;0;0;0;0;0;0;0;0;0;0;0;0
447;0.34164;0.11457;0.11375;0.57359;0;0;0;0;0;0;0;0;0;0;0;0;0
448;0.34274;0.11555;0.11455;0.57357;0;0;0;0;0;0;0;0;0;0;0;0;0
449;0.34418;0.11654;0.11555;0.57355;0;0;0;0;0;0;0;0;0;0;0;0;0
450;0.34541;0.11756;0.1165;0.57351;0;0;0;0;0;0;0;0;0;0;0;0;0
451;0.34659;0.1186;0.11737;0.57347;0;0;0;0;0;0;0;0;0;0;0;0;0
452;0.34807;0.11972;0.11829;0.57343;0;0;0;0;0;0;0;0;0;0;0;0;0
453;0.34912;0.12082;0.11948;0.5734;0;0;0;0;0;0;0;0;0;0;0;0;0
454;0.35035;0.12203;0.12057;0.57339;0;0;0;0;0;0;0;0;0;0;0;0;0
455;0.35181;0.12326;0.12166;0.57338;0;0;0;0;0;0;0;0;0;0;0;0;0
456;0.3529;0.12441;0.12284;0.57335;0;0;0;0;0;0;0;0;0;0;0;0;0
457;0.35419;0.12556;0.12408;0.5733;0;0;0;0;0;0;0;0;0;0;0;0;0
458;0.35547;0.12664;0.12522;0.57324;0;0;0;0;0;0;0;0;0;0;0;0;0
459;0.35675;0.1278;0.12635;0.5732;0;0;0;0;0;0;0;0;0;0;0;0;0
460;0.35803;0.1289;0.12745;0.57316;0;0;0;0;0;0;0;0;0;0;0;0;0
461;0.35923;0.13007;0.12868;0.57313;0;0;0;0;0;0;0;0;0;0;0;0;0
462;0.36052;0.13114;0.12977;0.5731;0;0;0;0;0;0;0;0;0;0;0;0;0
463;0.3619;0.13229;0.13097;0.57306;0;0;0;0;0;0;0;0;0;0;0;0;0
464;0.36319;0.13346;0.13214;0.57303;0;0;0;0;0;0;0;0;0;0;0;0;0
465;0.3644;0.13468;0.13327;0.573;0;0;0;0;0;0;0;0;0;0;0;0;0
466;0.36571;0.13581;0.1344;0.57295;0;0;0;0;0;0;0;0;0;0;0;0;0
467;0.36704;0.13712;0.13561;0.5729;0;0;0;0;0;0;0;0;0;0;0;0;0
468;0.36842;0.13844;0.1367;0.57285;0;0;0;0;0;0;0;0;0;0;0;0;0
469;0.36962;0.13967;0.13787;0.5728;0;0;0;0;0;0;0;0;0;0;0;0;0
470;0.37101;0.14086;0.13909;0.57275;0;0;0;0;0;0;0;0;0;0;0;0;0
471;0.37271;0.14215;0.14042;0.57271;0;0;0;0;0;0;0;0;0;0;0;0;0
472;0.37361;0.14329;0.14162;0.57267;0;0;0;0;0;0;0;0;0;0;0;0;0
473;0.37502;0.14446;0.14291;0.57262;0;0;0;0;0;0;0;0;0;0;0;0;0
474;0.37597;0.14561;0.1442;0.57257;0;0;0;0;0;0;0;0;0;0;0;0;0
475;0.37759;0.14684;0.14552;0.57252;0;0;0;0;0;0;0;0;0;0;0;0;0
476;0.37942;0.14801;0.1468;0.57245;0;0;0;0;0;0;0;0;0;0;0;0;0
477;0.38032;0.14911;0.14807;0.57239;0;0;0;0;0;0;0;0;0;0;0;0;0
478;0.3816;0.15039;0.1495;0.57231;0;0;0;0;0;0;0;0;0;0;0;0;0
479;0.38301;0.15169;0.15083;0.57223;0;0;0;0;0;0;0;0;0;0;0;0;0
480;0.38464;0.15288;0.15224;0.57214;0;0;0;0;0;0;0;0;0;0;0;0;0
481;0.3857;0.15413;0.15353;0.57205;0;0;0;0;0;0;0;0;0;0;0;0;0
482;0.38705;0.15552;0.15493;0.57196;0;0;0;0;0;0;0;0;0;0;0;0;0
483;0.38857;0.15677;0.15622;0.57184;0;0;0;0;0;0;0;0;0;0;0;0;0
484;0.3899;0.15814;0.15761;0.57173;0;0;0;0;0;0;0;0;0;0;0;0;0
485;0.39128;0.15944;0.15899;0.57158;0;0;0;0;0;0;0;0;0;0;0;0;0
486;0.39274;0.16081;0.16029;0.57143;0;0;0;0;0;0;0;0;0;0;0;0;0
487;0.39404;0.16207;0.16165;0.57125;0;0;0;0;0;0;0;0;0;0;0;0;0
488;0.39568;0.16351;0.16297;0.57102;0;0;0;0;0;0;0;0;0;0;0;0;0
489;0.39727;0.16503;0.16432;0.57078;0;0;0;0;0;0;0;0;0;0;0;0;0
490;0.3985;0.16643;0.16576;0.57058;0;0;0;0;0;0;0;0;0;0;0;0;0
491;0.39982;0.16769;0.16718;0.57029;0;0;0;0;0;0;0;0;0;0;0;0;0
492;0.40142;0.16923;0.16864;0.57002;0;0;0;0;0;0;0;0;0;0;0;0;0
493;0.40251;0.17066;0.17016;0.56963;0;0;0;0;0;0;0;0;0;0;0;0;0
494;0.40393;0.17194;0.17164;0.56923;0;0;0;0;0;0;0;0;0;0;0;0;0
495;0.40565;0.17337;0.17306;0.56871;0;0;0;0;0;0;0;0;0;0;0;0;0
496;0.40705;0.17464;0.17452;0.5682;0;0;0;0;0;0;0;0;0;0;0;0;0
497.01;0.40858;0.17597;0.17603;0.56752;0;0;0;0;0;0;0;0;0;0;0;0;0
498;0.41012;0.17732;0.17738;0.56688;0;0;0;0;0;0;0;0;0;0;0;0;0
499;0.41136;0.17876;0.1788;0.56619;0;0;0;0;0;0;0;0;0;0;0;0;0
500;0.41308;0.18014;0.18035;0.56545;0;0;0;0;0;0;0;0;0;0;0;0;0
501;0.4142;0.1815;0.1818;0.56468;0;0;0;0;0;0;0;0;0;0;0;0;0
502;0.41561;0.18291;0.18313;0.56395;0;0;0;0;0;0;0;0;0;0;0;0;0
503;0.4171;0.18438;0.18462;0.56305;0;0;0;0;0;0;0;0;0;0;0;0;0
504;0.41874;0.18569;0.18603;0.56223;0;0;0;0;0;0;0;0;0;0;0;0;0
505;0.41976;0.18706;0.18738;0.56127;0;0;0;0;0;0;0;0;0;0;0;0;0
506;0.42141;0.18863;0.18878;0.56019;0;0;0;0;0;0;0;0;0;0;0;0;0
507;0.42267;0.19011;0.19038;0.55928;0;0;0;0;0;0;0;0;0;0;0;0;0
508;0.42417;0.19151;0.19179;0.55819;0;0;0;0;0;0;0;0;0;0;0;0;0
509;0.42577;0.19304;0.19326;0.55694;0;0;0;0;0;0;0;0;0;0;0;0;0
510;0.42738;0.19453;0.19499;0.55569;0;0;0;0;0;0;0;0;0;0;0;0;0
510.5;0.4286;0.19568;0.19639;0.55499;0;0;0;0;0;0;0;0;0;0;0;0;0