File: Template_Auto_Cali_large_DP600/_data/DP600Large_CH_00_003_Front_DIC_File.txt
Date of Test;Material;Sample Geometry;Orientation [°];Test Number;Nominal Speed [mm/min];Thickness [mm];Central Width [mm];Gauge Width / Diameter [mm];Pixel to mm ratio [mm/px];Extensometer 1-4 [mm];Extensometer 2-3 [mm];Extensometer 5-6 [mm];;;;;
09/08/21;DP600Large;CH;00;3;0.0798;0.28305;4;1;0;6;0.20003;0.19999;;;;;
;;;;;;;;;;;;;;;;;
Time [s];U1 [mm];U2 [mm];U3 [mm];Force [kN];Ambient Temperature [°C];DIC Zone X 1 [px];DIC Zone Y 1 [px];DIC Zone X 2 [px];DIC Zone Y 2 [px];DIC Zone X 3 [px];DIC Zone Y 3 [px];DIC Zone X 4 [px];DIC Zone Y 4 [px];DIC Zone X 5 [px];DIC Zone Y 5 [px];DIC Zone X 6 [px];DIC Zone Y 6 [px]
0;0;0;0;0.000196;0;0;0;0;0;0;0;0;0;0;0;0;0
1.001;0.00022007;-5.7472e-05;2.4597e-07;0.000196;0;0;0;0;0;0;0;0;0;0;0;0;0
2;0.0004826;-2.43e-05;1.9996e-05;0.0002058;0;0;0;0;0;0;0;0;0;0;0;0;0
3.001;0.00030363;-2.4567e-05;6.7569e-05;0.000392;0;0;0;0;0;0;0;0;0;0;0;0;0
4.002;0.00015331;-2.8617e-05;1.4335e-06;0.0011858;0;0;0;0;0;0;0;0;0;0;0;0;0
5.001;0.00034802;9.4851e-06;0.00010253;0.0025578;0;0;0;0;0;0;0;0;0;0;0;0;0
6.001;0.00036758;4.0399e-05;0.00010627;0.0044296;0;0;0;0;0;0;0;0;0;0;0;0;0
7.001;0.00041495;1.4968e-05;9.769e-05;0.0067228;0;0;0;0;0;0;0;0;0;0;0;0;0
8.001;0.00056723;3.9248e-05;0.00011705;0.0092218;0;0;0;0;0;0;0;0;0;0;0;0;0
9.001;0.00052597;0.00010794;8.4491e-05;0.011378;0;0;0;0;0;0;0;0;0;0;0;0;0
10;0.00058011;6.1161e-05;4.8338e-05;0.013661;0;0;0;0;0;0;0;0;0;0;0;0;0
11;0.00069379;5.0312e-05;0.00010324;0.016356;0;0;0;0;0;0;0;0;0;0;0;0;0
12.001;0.00077044;6.7407e-05;2.0893e-05;0.019159;0;0;0;0;0;0;0;0;0;0;0;0;0
13.001;0.00091286;0.0001008;5.8429e-05;0.022119;0;0;0;0;0;0;0;0;0;0;0;0;0
14.001;0.0009244;0.00013287;3.6199e-05;0.025255;0;0;0;0;0;0;0;0;0;0;0;0;0
15.001;0.00097679;0.00013401;0.00011469;0.028508;0;0;0;0;0;0;0;0;0;0;0;0;0
16.001;0.0011221;0.00016089;9.2242e-05;0.031732;0;0;0;0;0;0;0;0;0;0;0;0;0
17.001;0.0011874;0.00019174;8.4121e-05;0.035349;0;0;0;0;0;0;0;0;0;0;0;0;0
18.001;0.0012318;0.00016733;7.8633e-05;0.038877;0;0;0;0;0;0;0;0;0;0;0;0;0
19.001;0.0013853;0.00016353;8.8401e-05;0.042454;0;0;0;0;0;0;0;0;0;0;0;0;0
20.001;0.0015376;0.00023284;0.00014872;0.046168;0;0;0;0;0;0;0;0;0;0;0;0;0
21.001;0.0015728;0.00023051;9.7392e-05;0.050019;0;0;0;0;0;0;0;0;0;0;0;0;0
22.001;0.0017885;0.00026798;0.00011061;0.054615;0;0;0;0;0;0;0;0;0;0;0;0;0
23;0.0018912;0.00027676;0.00010515;0.059261;0;0;0;0;0;0;0;0;0;0;0;0;0
24.001;0.001999;0.00028192;0.00016053;0.064602;0;0;0;0;0;0;0;0;0;0;0;0;0
25;0.0025882;0.00032376;0.00017344;0.069786;0;0;0;0;0;0;0;0;0;0;0;0;0
26.001;0.0024115;0.00026374;0.00011747;0.074921;0;0;0;0;0;0;0;0;0;0;0;0;0
27.001;0.0024662;0.00033336;0.00013486;0.080213;0;0;0;0;0;0;0;0;0;0;0;0;0
28.001;0.0025947;0.0003561;3.2094e-05;0.084848;0;0;0;0;0;0;0;0;0;0;0;0;0
29.001;0.0028305;0.00043581;0.00013214;0.089905;0;0;0;0;0;0;0;0;0;0;0;0;0
30.001;0.0030496;0.00037843;0.00015804;0.095364;0;0;0;0;0;0;0;0;0;0;0;0;0
31.001;0.0030908;0.00040294;4.1778e-05;0.1002;0;0;0;0;0;0;0;0;0;0;0;0;0
32.001;0.0033028;0.00044999;7.5719e-05;0.10523;0;0;0;0;0;0;0;0;0;0;0;0;0
33.001;0.0033521;0.00054373;0.00018645;0.11029;0;0;0;0;0;0;0;0;0;0;0;0;0
34.001;0.0036184;0.00055709;0.00012761;0.11557;0;0;0;0;0;0;0;0;0;0;0;0;0
35.001;0.0037431;0.00053208;9.1061e-05;0.12051;0;0;0;0;0;0;0;0;0;0;0;0;0
36.001;0.004041;0.00055335;0.00014376;0.12576;0;0;0;0;0;0;0;0;0;0;0;0;0
37.001;0.0040396;0.00062862;8.7821e-05;0.13131;0;0;0;0;0;0;0;0;0;0;0;0;0
38.001;0.004312;0.00059848;7.5025e-05;0.13651;0;0;0;0;0;0;0;0;0;0;0;0;0
39.001;0.004623;0.00068818;0.00010655;0.14175;0;0;0;0;0;0;0;0;0;0;0;0;0
40.001;0.0047249;0.00067496;0.0001008;0.14769;0;0;0;0;0;0;0;0;0;0;0;0;0
41;0.0048706;0.00069155;0.00011996;0.15298;0;0;0;0;0;0;0;0;0;0;0;0;0
42;0.0050207;0.00080287;0.00011711;0.15834;0;0;0;0;0;0;0;0;0;0;0;0;0
43.001;0.0053118;0.00075802;9.4176e-05;0.16421;0;0;0;0;0;0;0;0;0;0;0;0;0
44.001;0.0054895;0.00081601;0.00015421;0.16968;0;0;0;0;0;0;0;0;0;0;0;0;0
45.001;0.0058236;0.00088238;0.00012968;0.17565;0;0;0;0;0;0;0;0;0;0;0;0;0
46;0.0059869;0.00090851;0.0001977;0.18134;0;0;0;0;0;0;0;0;0;0;0;0;0
47.001;0.0061778;0.00097234;0.00031179;0.18724;0;0;0;0;0;0;0;0;0;0;0;0;0
48.001;0.0063828;0.00096644;0.00025832;0.19266;0;0;0;0;0;0;0;0;0;0;0;0;0
49.001;0.0066004;0.0010077;0.00025901;0.19826;0;0;0;0;0;0;0;0;0;0;0;0;0
50.002;0.0067555;0.001102;0.00027923;0.20393;0;0;0;0;0;0;0;0;0;0;0;0;0
51.001;0.0069973;0.0011541;0.00032137;0.20955;0;0;0;0;0;0;0;0;0;0;0;0;0
52.001;0.0072491;0.001147;0.00036752;0.21508;0;0;0;0;0;0;0;0;0;0;0;0;0
53.001;0.0073441;0.0011958;0.00038131;0.22029;0;0;0;0;0;0;0;0;0;0;0;0;0
54.001;0.0074711;0.0011791;0.00045793;0.22531;0;0;0;0;0;0;0;0;0;0;0;0;0
55.001;0.0074978;0.0012055;0.00053348;0.22958;0;0;0;0;0;0;0;0;0;0;0;0;0
56;0.0076647;0.0012029;0.00051244;0.2337;0;0;0;0;0;0;0;0;0;0;0;0;0
57.001;0.0079114;0.0012366;0.00049189;0.23754;0;0;0;0;0;0;0;0;0;0;0;0;0
58.001;0.0080319;0.0012537;0.0005132;0.24178;0;0;0;0;0;0;0;0;0;0;0;0;0
59;0.0081852;0.0012597;0.00058112;0.24549;0;0;0;0;0;0;0;0;0;0;0;0;0
60.001;0.0081004;0.0013368;0.00062822;0.24934;0;0;0;0;0;0;0;0;0;0;0;0;0
61;0.008226;0.0013639;0.00069649;0.25302;0;0;0;0;0;0;0;0;0;0;0;0;0
62.002;0.0083227;0.001403;0.00073853;0.25696;0;0;0;0;0;0;0;0;0;0;0;0;0
63.002;0.0086131;0.0013761;0.00073078;0.26073;0;0;0;0;0;0;0;0;0;0;0;0;0
64.001;0.0086948;0.0013727;0.00073402;0.26451;0;0;0;0;0;0;0;0;0;0;0;0;0
65;0.0090692;0.0014931;0.00079951;0.26828;0;0;0;0;0;0;0;0;0;0;0;0;0
66.001;0.0092435;0.0015385;0.00093666;0.27191;0;0;0;0;0;0;0;0;0;0;0;0;0
67;0.009587;0.001609;0.00093076;0.27597;0;0;0;0;0;0;0;0;0;0;0;0;0
68;0.0096971;0.001626;0.0010427;0.27957;0;0;0;0;0;0;0;0;0;0;0;0;0
69.001;0.010053;0.0016487;0.0010057;0.28318;0;0;0;0;0;0;0;0;0;0;0;0;0
70;0.010239;0.0016712;0.0011132;0.28708;0;0;0;0;0;0;0;0;0;0;0;0;0
71;0.010532;0.0017581;0.0012105;0.29081;0;0;0;0;0;0;0;0;0;0;0;0;0
72.001;0.010894;0.0018333;0.0013093;0.29464;0;0;0;0;0;0;0;0;0;0;0;0;0
73;0.011314;0.0019062;0.0013784;0.2981;0;0;0;0;0;0;0;0;0;0;0;0;0
74.001;0.01154;0.0019693;0.0013816;0.30178;0;0;0;0;0;0;0;0;0;0;0;0;0
75;0.011856;0.002089;0.001478;0.30512;0;0;0;0;0;0;0;0;0;0;0;0;0
76.002;0.012052;0.00209;0.0015579;0.30853;0;0;0;0;0;0;0;0;0;0;0;0;0
77.001;0.012562;0.0021522;0.0016528;0.31189;0;0;0;0;0;0;0;0;0;0;0;0;0
78.001;0.013098;0.0022062;0.0017899;0.31521;0;0;0;0;0;0;0;0;0;0;0;0;0
79;0.013448;0.002267;0.001876;0.31846;0;0;0;0;0;0;0;0;0;0;0;0;0
80.001;0.013766;0.0022981;0.0019596;0.32166;0;0;0;0;0;0;0;0;0;0;0;0;0
81;0.014834;0.0024193;0.0020945;0.32476;0;0;0;0;0;0;0;0;0;0;0;0;0
82;0.014773;0.0025205;0.0021751;0.32778;0;0;0;0;0;0;0;0;0;0;0;0;0
83.001;0.015166;0.0025418;0.0022891;0.33086;0;0;0;0;0;0;0;0;0;0;0;0;0
84;0.01589;0.0026296;0.0024373;0.33362;0;0;0;0;0;0;0;0;0;0;0;0;0
85.001;0.01614;0.0027792;0.0025353;0.33644;0;0;0;0;0;0;0;0;0;0;0;0;0
86;0.017007;0.002859;0.0026761;0.3392;0;0;0;0;0;0;0;0;0;0;0;0;0
87;0.017149;0.0029351;0.0028805;0.3419;0;0;0;0;0;0;0;0;0;0;0;0;0
88.001;0.017544;0.0029628;0.0029626;0.3444;0;0;0;0;0;0;0;0;0;0;0;0;0
89.001;0.018452;0.0030784;0.0030049;0.34708;0;0;0;0;0;0;0;0;0;0;0;0;0
90;0.018981;0.0031638;0.0031727;0.34967;0;0;0;0;0;0;0;0;0;0;0;0;0
91;0.01953;0.0032124;0.0033383;0.35201;0;0;0;0;0;0;0;0;0;0;0;0;0
92.001;0.0205;0.0033369;0.0035458;0.35449;0;0;0;0;0;0;0;0;0;0;0;0;0
93;0.020794;0.0033587;0.0036297;0.35675;0;0;0;0;0;0;0;0;0;0;0;0;0
94.001;0.021412;0.0034151;0.0038095;0.35904;0;0;0;0;0;0;0;0;0;0;0;0;0
95;0.021887;0.0035727;0.0039503;0.3614;0;0;0;0;0;0;0;0;0;0;0;0;0
96;0.022617;0.0036262;0.0041478;0.36354;0;0;0;0;0;0;0;0;0;0;0;0;0
97.001;0.023281;0.0038112;0.004227;0.3657;0;0;0;0;0;0;0;0;0;0;0;0;0
98.001;0.023836;0.003945;0.004458;0.36793;0;0;0;0;0;0;0;0;0;0;0;0;0
99;0.024516;0.0040637;0.004553;0.37005;0;0;0;0;0;0;0;0;0;0;0;0;0
100;0.025117;0.0042131;0.0047409;0.37205;0;0;0;0;0;0;0;0;0;0;0;0;0
101;0.025663;0.0042961;0.0049008;0.37412;0;0;0;0;0;0;0;0;0;0;0;0;0
102;0.026333;0.0044451;0.0051385;0.37614;0;0;0;0;0;0;0;0;0;0;0;0;0
103;0.026994;0.0045622;0.0052454;0.37807;0;0;0;0;0;0;0;0;0;0;0;0;0
104;0.027695;0.0047245;0.0053689;0.3802;0;0;0;0;0;0;0;0;0;0;0;0;0
105;0.028276;0.004789;0.0055305;0.38204;0;0;0;0;0;0;0;0;0;0;0;0;0
106;0.028984;0.0050615;0.0056884;0.38402;0;0;0;0;0;0;0;0;0;0;0;0;0
107;0.029465;0.0050868;0.0057838;0.38582;0;0;0;0;0;0;0;0;0;0;0;0;0
108;0.030106;0.0053379;0.0060587;0.38765;0;0;0;0;0;0;0;0;0;0;0;0;0
109;0.03083;0.0053854;0.0060867;0.38946;0;0;0;0;0;0;0;0;0;0;0;0;0
110;0.031558;0.0056089;0.0064044;0.39126;0;0;0;0;0;0;0;0;0;0;0;0;0
111;0.03212;0.0056706;0.0064076;0.39301;0;0;0;0;0;0;0;0;0;0;0;0;0
112;0.032809;0.0057964;0.0066068;0.39473;0;0;0;0;0;0;0;0;0;0;0;0;0
113;0.033376;0.0058644;0.0067502;0.39645;0;0;0;0;0;0;0;0;0;0;0;0;0
114;0.034125;0.0059559;0.0069468;0.39805;0;0;0;0;0;0;0;0;0;0;0;0;0
115;0.034827;0.006128;0.0071558;0.39974;0;0;0;0;0;0;0;0;0;0;0;0;0
116;0.035578;0.0062342;0.0072342;0.40136;0;0;0;0;0;0;0;0;0;0;0;0;0
117;0.036158;0.0064597;0.0074501;0.40295;0;0;0;0;0;0;0;0;0;0;0;0;0
118;0.036895;0.0064741;0.0076589;0.40457;0;0;0;0;0;0;0;0;0;0;0;0;0
119;0.037497;0.0066628;0.0078317;0.40607;0;0;0;0;0;0;0;0;0;0;0;0;0
120;0.03831;0.0067934;0.0080165;0.40759;0;0;0;0;0;0;0;0;0;0;0;0;0
121;0.039028;0.0068996;0.0080949;0.40907;0;0;0;0;0;0;0;0;0;0;0;0;0
122;0.039819;0.0070528;0.0083509;0.41056;0;0;0;0;0;0;0;0;0;0;0;0;0
123;0.040486;0.0071366;0.0084603;0.41206;0;0;0;0;0;0;0;0;0;0;0;0;0
124;0.04125;0.0073488;0.0086452;0.41343;0;0;0;0;0;0;0;0;0;0;0;0;0
125;0.041746;0.0074196;0.0088327;0.41479;0;0;0;0;0;0;0;0;0;0;0;0;0
126;0.042193;0.007624;0.0089981;0.41628;0;0;0;0;0;0;0;0;0;0;0;0;0
127;0.043031;0.0077769;0.0091821;0.41761;0;0;0;0;0;0;0;0;0;0;0;0;0
128;0.043715;0.0078828;0.0092686;0.41897;0;0;0;0;0;0;0;0;0;0;0;0;0
129;0.044402;0.007995;0.0094217;0.42026;0;0;0;0;0;0;0;0;0;0;0;0;0
130;0.045034;0.0081278;0.0095362;0.42163;0;0;0;0;0;0;0;0;0;0;0;0;0
131;0.04575;0.0083409;0.0097021;0.4229;0;0;0;0;0;0;0;0;0;0;0;0;0
132;0.046446;0.0084538;0.0097868;0.42415;0;0;0;0;0;0;0;0;0;0;0;0;0
133;0.047226;0.0085702;0.010009;0.4254;0;0;0;0;0;0;0;0;0;0;0;0;0
134;0.047975;0.0086698;0.010103;0.42659;0;0;0;0;0;0;0;0;0;0;0;0;0
135;0.048547;0.0088338;0.010189;0.42785;0;0;0;0;0;0;0;0;0;0;0;0;0
136;0.049128;0.0090167;0.01054;0.42904;0;0;0;0;0;0;0;0;0;0;0;0;0
137;0.050202;0.0091402;0.010634;0.43027;0;0;0;0;0;0;0;0;0;0;0;0;0
138;0.050657;0.0092472;0.010767;0.43138;0;0;0;0;0;0;0;0;0;0;0;0;0
139;0.051381;0.0094454;0.011016;0.43253;0;0;0;0;0;0;0;0;0;0;0;0;0
140;0.052179;0.0096155;0.011159;0.43373;0;0;0;0;0;0;0;0;0;0;0;0;0
141;0.053035;0.0097139;0.011298;0.43482;0;0;0;0;0;0;0;0;0;0;0;0;0
142;0.053735;0.009883;0.011551;0.43592;0;0;0;0;0;0;0;0;0;0;0;0;0
143;0.054492;0.010006;0.011634;0.43704;0;0;0;0;0;0;0;0;0;0;0;0;0
144;0.055201;0.010154;0.011843;0.43815;0;0;0;0;0;0;0;0;0;0;0;0;0
145;0.05606;0.010343;0.012039;0.43924;0;0;0;0;0;0;0;0;0;0;0;0;0
146;0.056818;0.010433;0.012198;0.44032;0;0;0;0;0;0;0;0;0;0;0;0;0
147;0.057591;0.010609;0.0124;0.44133;0;0;0;0;0;0;0;0;0;0;0;0;0
148;0.058333;0.010749;0.012599;0.44241;0;0;0;0;0;0;0;0;0;0;0;0;0
149;0.058922;0.010933;0.012698;0.44345;0;0;0;0;0;0;0;0;0;0;0;0;0
150;0.059921;0.011031;0.012847;0.44447;0;0;0;0;0;0;0;0;0;0;0;0;0
151;0.060667;0.011222;0.013013;0.44548;0;0;0;0;0;0;0;0;0;0;0;0;0
152;0.061477;0.0114;0.013192;0.44648;0;0;0;0;0;0;0;0;0;0;0;0;0
153;0.062207;0.011561;0.01327;0.44747;0;0;0;0;0;0;0;0;0;0;0;0;0
154;0.063027;0.01169;0.013495;0.44844;0;0;0;0;0;0;0;0;0;0;0;0;0
155;0.063782;0.011923;0.01361;0.44942;0;0;0;0;0;0;0;0;0;0;0;0;0
156;0.064523;0.012046;0.013762;0.45039;0;0;0;0;0;0;0;0;0;0;0;0;0
157;0.065371;0.01224;0.013931;0.45135;0;0;0;0;0;0;0;0;0;0;0;0;0
158;0.066073;0.012416;0.014113;0.45233;0;0;0;0;0;0;0;0;0;0;0;0;0
159;0.066887;0.012612;0.014335;0.45327;0;0;0;0;0;0;0;0;0;0;0;0;0
160;0.067693;0.01276;0.014445;0.45416;0;0;0;0;0;0;0;0;0;0;0;0;0
161;0.068432;0.012991;0.014644;0.45506;0;0;0;0;0;0;0;0;0;0;0;0;0
162;0.069191;0.013154;0.014848;0.456;0;0;0;0;0;0;0;0;0;0;0;0;0
163;0.070146;0.013295;0.014951;0.45695;0;0;0;0;0;0;0;0;0;0;0;0;0
164;0.070722;0.013551;0.015149;0.45787;0;0;0;0;0;0;0;0;0;0;0;0;0
165;0.071539;0.013689;0.015352;0.45875;0;0;0;0;0;0;0;0;0;0;0;0;0
166;0.072318;0.013886;0.015461;0.45963;0;0;0;0;0;0;0;0;0;0;0;0;0
167;0.073063;0.014127;0.01563;0.46048;0;0;0;0;0;0;0;0;0;0;0;0;0
168;0.073801;0.014278;0.015864;0.46133;0;0;0;0;0;0;0;0;0;0;0;0;0
169;0.074479;0.014479;0.015973;0.46218;0;0;0;0;0;0;0;0;0;0;0;0;0
170;0.075216;0.014651;0.016141;0.463;0;0;0;0;0;0;0;0;0;0;0;0;0
171;0.07584;0.014731;0.016263;0.46383;0;0;0;0;0;0;0;0;0;0;0;0;0
172;0.076756;0.014939;0.015928;0.46466;0;0;0;0;0;0;0;0;0;0;0;0;0
173;0.077638;0.015143;0.016067;0.46549;0;0;0;0;0;0;0;0;0;0;0;0;0
174;0.078261;0.015272;0.016226;0.46631;0;0;0;0;0;0;0;0;0;0;0;0;0
175;0.079034;0.015414;0.016429;0.46713;0;0;0;0;0;0;0;0;0;0;0;0;0
176;0.079859;0.015618;0.016522;0.46798;0;0;0;0;0;0;0;0;0;0;0;0;0
177;0.080539;0.01576;0.016648;0.46874;0;0;0;0;0;0;0;0;0;0;0;0;0
178;0.081319;0.015941;0.016779;0.46953;0;0;0;0;0;0;0;0;0;0;0;0;0
179;0.082123;0.016136;0.017005;0.47031;0;0;0;0;0;0;0;0;0;0;0;0;0
180;0.082903;0.016247;0.017109;0.47107;0;0;0;0;0;0;0;0;0;0;0;0;0
181;0.083638;0.016317;0.017318;0.47182;0;0;0;0;0;0;0;0;0;0;0;0;0
182;0.084149;0.016509;0.017522;0.4726;0;0;0;0;0;0;0;0;0;0;0;0;0
183;0.085214;0.016641;0.017677;0.47338;0;0;0;0;0;0;0;0;0;0;0;0;0
184;0.085939;0.016762;0.017868;0.47411;0;0;0;0;0;0;0;0;0;0;0;0;0
185;0.086781;0.01694;0.018091;0.4749;0;0;0;0;0;0;0;0;0;0;0;0;0
186;0.087473;0.017054;0.018226;0.47556;0;0;0;0;0;0;0;0;0;0;0;0;0
187;0.088232;0.01726;0.018461;0.47632;0;0;0;0;0;0;0;0;0;0;0;0;0
188;0.089073;0.017367;0.018665;0.47702;0;0;0;0;0;0;0;0;0;0;0;0;0
189;0.089869;0.017552;0.01886;0.47775;0;0;0;0;0;0;0;0;0;0;0;0;0
190;0.090696;0.017652;0.019016;0.4785;0;0;0;0;0;0;0;0;0;0;0;0;0
191;0.091359;0.017815;0.019235;0.47925;0;0;0;0;0;0;0;0;0;0;0;0;0
192;0.092384;0.018036;0.019393;0.48;0;0;0;0;0;0;0;0;0;0;0;0;0
193;0.092792;0.018121;0.019563;0.48071;0;0;0;0;0;0;0;0;0;0;0;0;0
194;0.093506;0.018329;0.019734;0.48148;0;0;0;0;0;0;0;0;0;0;0;0;0
195;0.094249;0.018433;0.019878;0.48221;0;0;0;0;0;0;0;0;0;0;0;0;0
196;0.095131;0.018594;0.020028;0.48291;0;0;0;0;0;0;0;0;0;0;0;0;0
197;0.095827;0.01876;0.020167;0.48362;0;0;0;0;0;0;0;0;0;0;0;0;0
198;0.096627;0.018909;0.020396;0.48426;0;0;0;0;0;0;0;0;0;0;0;0;0
199;0.097385;0.019135;0.02058;0.48488;0;0;0;0;0;0;0;0;0;0;0;0;0
200;0.098361;0.019319;0.020738;0.48561;0;0;0;0;0;0;0;0;0;0;0;0;0
201;0.099052;0.019605;0.021013;0.48625;0;0;0;0;0;0;0;0;0;0;0;0;0
202;0.099775;0.019681;0.021181;0.4869;0;0;0;0;0;0;0;0;0;0;0;0;0
203;0.10058;0.019918;0.021344;0.48757;0;0;0;0;0;0;0;0;0;0;0;0;0
204;0.10141;0.020148;0.021535;0.48818;0;0;0;0;0;0;0;0;0;0;0;0;0
205;0.10218;0.020358;0.02179;0.48885;0;0;0;0;0;0;0;0;0;0;0;0;0
206;0.10305;0.020526;0.021975;0.4895;0;0;0;0;0;0;0;0;0;0;0;0;0
207;0.1038;0.020751;0.022104;0.49014;0;0;0;0;0;0;0;0;0;0;0;0;0
208;0.10459;0.020893;0.02227;0.49078;0;0;0;0;0;0;0;0;0;0;0;0;0
209;0.10541;0.021073;0.022494;0.49142;0;0;0;0;0;0;0;0;0;0;0;0;0
210;0.10627;0.021261;0.022741;0.49204;0;0;0;0;0;0;0;0;0;0;0;0;0
211;0.107;0.021463;0.022925;0.49266;0;0;0;0;0;0;0;0;0;0;0;0;0
212;0.10778;0.021577;0.023065;0.49327;0;0;0;0;0;0;0;0;0;0;0;0;0
213;0.10868;0.021794;0.023285;0.49389;0;0;0;0;0;0;0;0;0;0;0;0;0
214;0.1095;0.021946;0.023491;0.49452;0;0;0;0;0;0;0;0;0;0;0;0;0
215;0.1104;0.022106;0.023651;0.49511;0;0;0;0;0;0;0;0;0;0;0;0;0
216;0.11105;0.022177;0.023857;0.49571;0;0;0;0;0;0;0;0;0;0;0;0;0
217;0.11192;0.022347;0.024117;0.49633;0;0;0;0;0;0;0;0;0;0;0;0;0
218;0.1127;0.022556;0.024339;0.49692;0;0;0;0;0;0;0;0;0;0;0;0;0
219;0.11369;0.022712;0.024526;0.49752;0;0;0;0;0;0;0;0;0;0;0;0;0
220;0.11438;0.022859;0.024685;0.49812;0;0;0;0;0;0;0;0;0;0;0;0;0
221;0.11526;0.023005;0.024962;0.4987;0;0;0;0;0;0;0;0;0;0;0;0;0
222;0.1161;0.023182;0.025258;0.49928;0;0;0;0;0;0;0;0;0;0;0;0;0
223;0.1169;0.023411;0.025466;0.49988;0;0;0;0;0;0;0;0;0;0;0;0;0
224;0.11772;0.02365;0.025624;0.50043;0;0;0;0;0;0;0;0;0;0;0;0;0
225;0.11848;0.023756;0.025958;0.50097;0;0;0;0;0;0;0;0;0;0;0;0;0
226;0.11949;0.024027;0.026226;0.50155;0;0;0;0;0;0;0;0;0;0;0;0;0
227;0.12022;0.024272;0.026412;0.50212;0;0;0;0;0;0;0;0;0;0;0;0;0
228;0.12109;0.02446;0.026651;0.50269;0;0;0;0;0;0;0;0;0;0;0;0;0
229;0.12183;0.024666;0.026879;0.50326;0;0;0;0;0;0;0;0;0;0;0;0;0
230;0.12267;0.024889;0.027083;0.50381;0;0;0;0;0;0;0;0;0;0;0;0;0
231;0.12356;0.025107;0.027359;0.50435;0;0;0;0;0;0;0;0;0;0;0;0;0
232;0.1251;0.02531;0.027663;0.50489;0;0;0;0;0;0;0;0;0;0;0;0;0
233;0.12524;0.025459;0.027771;0.50543;0;0;0;0;0;0;0;0;0;0;0;0;0
234;0.12605;0.025719;0.028024;0.50596;0;0;0;0;0;0;0;0;0;0;0;0;0
235;0.12675;0.025913;0.02829;0.5065;0;0;0;0;0;0;0;0;0;0;0;0;0
236;0.12778;0.026076;0.028451;0.50706;0;0;0;0;0;0;0;0;0;0;0;0;0
237;0.12848;0.026165;0.028707;0.50761;0;0;0;0;0;0;0;0;0;0;0;0;0
238;0.12903;0.026414;0.028898;0.50817;0;0;0;0;0;0;0;0;0;0;0;0;0
239;0.12987;0.026584;0.02913;0.5087;0;0;0;0;0;0;0;0;0;0;0;0;0
240;0.13077;0.026802;0.029218;0.50922;0;0;0;0;0;0;0;0;0;0;0;0;0
241;0.13155;0.026983;0.029458;0.50975;0;0;0;0;0;0;0;0;0;0;0;0;0
242;0.13239;0.027235;0.029646;0.51023;0;0;0;0;0;0;0;0;0;0;0;0;0
243;0.13323;0.02761;0.029916;0.51074;0;0;0;0;0;0;0;0;0;0;0;0;0
244;0.13405;0.02779;0.030092;0.51127;0;0;0;0;0;0;0;0;0;0;0;0;0
245;0.13481;0.028035;0.030293;0.51177;0;0;0;0;0;0;0;0;0;0;0;0;0
246;0.1357;0.028331;0.030519;0.51231;0;0;0;0;0;0;0;0;0;0;0;0;0
247;0.13639;0.028594;0.03079;0.51282;0;0;0;0;0;0;0;0;0;0;0;0;0
248;0.13749;0.028819;0.031108;0.51331;0;0;0;0;0;0;0;0;0;0;0;0;0
249;0.1383;0.029084;0.031308;0.51387;0;0;0;0;0;0;0;0;0;0;0;0;0
250;0.13955;0.029388;0.031567;0.51436;0;0;0;0;0;0;0;0;0;0;0;0;0
251;0.14012;0.029616;0.031853;0.51485;0;0;0;0;0;0;0;0;0;0;0;0;0
252;0.14082;0.02986;0.032235;0.51533;0;0;0;0;0;0;0;0;0;0;0;0;0
253;0.14186;0.030094;0.03251;0.5158;0;0;0;0;0;0;0;0;0;0;0;0;0
254;0.14258;0.030333;0.032816;0.51627;0;0;0;0;0;0;0;0;0;0;0;0;0
255;0.14356;0.03063;0.033135;0.51673;0;0;0;0;0;0;0;0;0;0;0;0;0
256;0.14434;0.030856;0.033421;0.5172;0;0;0;0;0;0;0;0;0;0;0;0;0
257;0.14525;0.031148;0.033765;0.51768;0;0;0;0;0;0;0;0;0;0;0;0;0
258;0.14621;0.031394;0.034092;0.51813;0;0;0;0;0;0;0;0;0;0;0;0;0
259;0.14694;0.031634;0.034359;0.51862;0;0;0;0;0;0;0;0;0;0;0;0;0
260;0.14778;0.031928;0.034603;0.5191;0;0;0;0;0;0;0;0;0;0;0;0;0
261;0.14864;0.032196;0.034786;0.51957;0;0;0;0;0;0;0;0;0;0;0;0;0
262;0.14954;0.032456;0.035031;0.52004;0;0;0;0;0;0;0;0;0;0;0;0;0
263;0.1505;0.032763;0.035289;0.52044;0;0;0;0;0;0;0;0;0;0;0;0;0
264;0.15055;0.032962;0.035588;0.52088;0;0;0;0;0;0;0;0;0;0;0;0;0
265;0.15216;0.033322;0.035816;0.52132;0;0;0;0;0;0;0;0;0;0;0;0;0
266;0.15363;0.033784;0.036;0.52176;0;0;0;0;0;0;0;0;0;0;0;0;0
267;0.15376;0.034027;0.036203;0.52221;0;0;0;0;0;0;0;0;0;0;0;0;0
268;0.15462;0.034367;0.036396;0.52264;0;0;0;0;0;0;0;0;0;0;0;0;0
269;0.15567;0.034634;0.036692;0.52309;0;0;0;0;0;0;0;0;0;0;0;0;0
270;0.15666;0.034969;0.036851;0.52353;0;0;0;0;0;0;0;0;0;0;0;0;0
271;0.15773;0.035264;0.037121;0.52398;0;0;0;0;0;0;0;0;0;0;0;0;0
272;0.15825;0.035559;0.037374;0.52441;0;0;0;0;0;0;0;0;0;0;0;0;0
273;0.15923;0.035793;0.037596;0.52482;0;0;0;0;0;0;0;0;0;0;0;0;0
274;0.16003;0.036139;0.037886;0.52527;0;0;0;0;0;0;0;0;0;0;0;0;0
275;0.16116;0.036397;0.038196;0.52569;0;0;0;0;0;0;0;0;0;0;0;0;0
276;0.16189;0.03665;0.038464;0.52611;0;0;0;0;0;0;0;0;0;0;0;0;0
277;0.16262;0.036886;0.038703;0.52656;0;0;0;0;0;0;0;0;0;0;0;0;0
278;0.16367;0.037324;0.039087;0.52694;0;0;0;0;0;0;0;0;0;0;0;0;0
279;0.16452;0.037554;0.039334;0.52735;0;0;0;0;0;0;0;0;0;0;0;0;0
280;0.16538;0.037781;0.039758;0.52778;0;0;0;0;0;0;0;0;0;0;0;0;0
281;0.16633;0.038123;0.039967;0.52818;0;0;0;0;0;0;0;0;0;0;0;0;0
282;0.16739;0.038426;0.040247;0.52858;0;0;0;0;0;0;0;0;0;0;0;0;0
283;0.16827;0.038788;0.040539;0.52901;0;0;0;0;0;0;0;0;0;0;0;0;0
284;0.16878;0.039067;0.040739;0.52939;0;0;0;0;0;0;0;0;0;0;0;0;0
285;0.17005;0.039393;0.041093;0.52978;0;0;0;0;0;0;0;0;0;0;0;0;0
286;0.17089;0.039735;0.041384;0.53018;0;0;0;0;0;0;0;0;0;0;0;0;0
287;0.17182;0.040013;0.041667;0.53057;0;0;0;0;0;0;0;0;0;0;0;0;0
288;0.17275;0.040316;0.042064;0.53097;0;0;0;0;0;0;0;0;0;0;0;0;0
289;0.17397;0.040642;0.042274;0.53138;0;0;0;0;0;0;0;0;0;0;0;0;0
290;0.17445;0.040795;0.042622;0.53175;0;0;0;0;0;0;0;0;0;0;0;0;0
291;0.17544;0.041188;0.042911;0.53213;0;0;0;0;0;0;0;0;0;0;0;0;0
292;0.17629;0.041518;0.043256;0.53252;0;0;0;0;0;0;0;0;0;0;0;0;0
293;0.17715;0.041947;0.043601;0.53291;0;0;0;0;0;0;0;0;0;0;0;0;0
294;0.17803;0.042222;0.044041;0.53329;0;0;0;0;0;0;0;0;0;0;0;0;0
295;0.17892;0.042658;0.044387;0.53368;0;0;0;0;0;0;0;0;0;0;0;0;0
296;0.17986;0.043024;0.044763;0.53406;0;0;0;0;0;0;0;0;0;0;0;0;0
297;0.18073;0.043315;0.045164;0.53443;0;0;0;0;0;0;0;0;0;0;0;0;0
298;0.18165;0.043674;0.045491;0.53486;0;0;0;0;0;0;0;0;0;0;0;0;0
299;0.18257;0.04394;0.045914;0.53524;0;0;0;0;0;0;0;0;0;0;0;0;0
300;0.18335;0.044304;0.046224;0.53558;0;0;0;0;0;0;0;0;0;0;0;0;0
301;0.18431;0.044571;0.04658;0.53594;0;0;0;0;0;0;0;0;0;0;0;0;0
302;0.18536;0.044866;0.046889;0.53629;0;0;0;0;0;0;0;0;0;0;0;0;0
303;0.18619;0.045262;0.047289;0.53662;0;0;0;0;0;0;0;0;0;0;0;0;0
304;0.18714;0.045531;0.047572;0.53698;0;0;0;0;0;0;0;0;0;0;0;0;0
305;0.18801;0.045896;0.047878;0.53733;0;0;0;0;0;0;0;0;0;0;0;0;0
306;0.1888;0.04619;0.048165;0.53768;0;0;0;0;0;0;0;0;0;0;0;0;0
307;0.18978;0.046493;0.048515;0.53803;0;0;0;0;0;0;0;0;0;0;0;0;0
308;0.19067;0.046866;0.048812;0.53838;0;0;0;0;0;0;0;0;0;0;0;0;0
309;0.19176;0.047116;0.049163;0.53873;0;0;0;0;0;0;0;0;0;0;0;0;0
310;0.19268;0.047482;0.049496;0.53907;0;0;0;0;0;0;0;0;0;0;0;0;0
311;0.19344;0.047794;0.049855;0.53941;0;0;0;0;0;0;0;0;0;0;0;0;0
312;0.19458;0.048052;0.050234;0.53977;0;0;0;0;0;0;0;0;0;0;0;0;0
313;0.19534;0.048474;0.050646;0.54012;0;0;0;0;0;0;0;0;0;0;0;0;0
314;0.19632;0.048672;0.050957;0.54047;0;0;0;0;0;0;0;0;0;0;0;0;0
315;0.19728;0.049031;0.051329;0.54081;0;0;0;0;0;0;0;0;0;0;0;0;0
316;0.19869;0.04932;0.051647;0.54114;0;0;0;0;0;0;0;0;0;0;0;0;0
317;0.19897;0.049582;0.051919;0.54148;0;0;0;0;0;0;0;0;0;0;0;0;0
318;0.20009;0.049872;0.052245;0.54175;0;0;0;0;0;0;0;0;0;0;0;0;0
319;0.20097;0.050136;0.05259;0.54205;0;0;0;0;0;0;0;0;0;0;0;0;0
320;0.2019;0.050494;0.052966;0.54234;0;0;0;0;0;0;0;0;0;0;0;0;0
321;0.20289;0.050781;0.053252;0.54261;0;0;0;0;0;0;0;0;0;0;0;0;0
322;0.20378;0.051108;0.05361;0.54292;0;0;0;0;0;0;0;0;0;0;0;0;0
323;0.20457;0.051364;0.053981;0.54325;0;0;0;0;0;0;0;0;0;0;0;0;0
324;0.20571;0.051761;0.054263;0.54359;0;0;0;0;0;0;0;0;0;0;0;0;0
325;0.20661;0.0521;0.054558;0.5439;0;0;0;0;0;0;0;0;0;0;0;0;0
326;0.20752;0.052413;0.054927;0.54423;0;0;0;0;0;0;0;0;0;0;0;0;0
327;0.20851;0.052809;0.055259;0.54452;0;0;0;0;0;0;0;0;0;0;0;0;0
328;0.20944;0.053226;0.055647;0.54482;0;0;0;0;0;0;0;0;0;0;0;0;0
329;0.21032;0.05359;0.055988;0.54512;0;0;0;0;0;0;0;0;0;0;0;0;0
330;0.21024;0.053946;0.056276;0.54541;0;0;0;0;0;0;0;0;0;0;0;0;0
331;0.21104;0.05438;0.056714;0.5457;0;0;0;0;0;0;0;0;0;0;0;0;0
332;0.21204;0.054776;0.057053;0.54599;0;0;0;0;0;0;0;0;0;0;0;0;0
333;0.21302;0.055202;0.05738;0.54628;0;0;0;0;0;0;0;0;0;0;0;0;0
334;0.21386;0.055454;0.057773;0.54659;0;0;0;0;0;0;0;0;0;0;0;0;0
335;0.21489;0.055796;0.058227;0.54687;0;0;0;0;0;0;0;0;0;0;0;0;0
336;0.21582;0.056182;0.058569;0.54716;0;0;0;0;0;0;0;0;0;0;0;0;0
337;0.21651;0.056512;0.059016;0.54746;0;0;0;0;0;0;0;0;0;0;0;0;0
338;0.21766;0.05685;0.059348;0.54772;0;0;0;0;0;0;0;0;0;0;0;0;0
339;0.2185;0.057175;0.059787;0.54802;0;0;0;0;0;0;0;0;0;0;0;0;0
340;0.21944;0.057586;0.060243;0.54828;0;0;0;0;0;0;0;0;0;0;0;0;0
341;0.22056;0.058123;0.060668;0.54854;0;0;0;0;0;0;0;0;0;0;0;0;0
342;0.22146;0.058528;0.061176;0.54883;0;0;0;0;0;0;0;0;0;0;0;0;0
343;0.22236;0.058981;0.061537;0.54911;0;0;0;0;0;0;0;0;0;0;0;0;0
344;0.22331;0.059505;0.061993;0.5494;0;0;0;0;0;0;0;0;0;0;0;0;0
345;0.22427;0.059973;0.062333;0.54967;0;0;0;0;0;0;0;0;0;0;0;0;0
346;0.22521;0.060299;0.062727;0.54995;0;0;0;0;0;0;0;0;0;0;0;0;0
347;0.22626;0.060891;0.063257;0.55019;0;0;0;0;0;0;0;0;0;0;0;0;0
348;0.22723;0.061439;0.063685;0.55044;0;0;0;0;0;0;0;0;0;0;0;0;0
349;0.22801;0.061925;0.064119;0.55073;0;0;0;0;0;0;0;0;0;0;0;0;0
350;0.22914;0.062405;0.064687;0.551;0;0;0;0;0;0;0;0;0;0;0;0;0
351;0.23014;0.062899;0.065117;0.55129;0;0;0;0;0;0;0;0;0;0;0;0;0
352;0.23062;0.063377;0.065509;0.55154;0;0;0;0;0;0;0;0;0;0;0;0;0
353;0.23206;0.063867;0.066074;0.5518;0;0;0;0;0;0;0;0;0;0;0;0;0
354;0.23299;0.064277;0.066587;0.55203;0;0;0;0;0;0;0;0;0;0;0;0;0
355;0.23389;0.064755;0.067097;0.55228;0;0;0;0;0;0;0;0;0;0;0;0;0
356;0.23502;0.065292;0.067574;0.55252;0;0;0;0;0;0;0;0;0;0;0;0;0
357;0.23598;0.065657;0.068056;0.55276;0;0;0;0;0;0;0;0;0;0;0;0;0
358;0.2369;0.066125;0.068676;0.55298;0;0;0;0;0;0;0;0;0;0;0;0;0
359;0.23814;0.066731;0.069204;0.55322;0;0;0;0;0;0;0;0;0;0;0;0;0
360;0.23893;0.067167;0.069648;0.55345;0;0;0;0;0;0;0;0;0;0;0;0;0
361;0.24003;0.067671;0.070125;0.5537;0;0;0;0;0;0;0;0;0;0;0;0;0
362;0.24093;0.068181;0.070651;0.55392;0;0;0;0;0;0;0;0;0;0;0;0;0
363;0.24187;0.068604;0.071142;0.55413;0;0;0;0;0;0;0;0;0;0;0;0;0
364;0.2429;0.069101;0.071684;0.55436;0;0;0;0;0;0;0;0;0;0;0;0;0
365;0.2439;0.069528;0.072226;0.55456;0;0;0;0;0;0;0;0;0;0;0;0;0
366;0.24492;0.069991;0.072741;0.55479;0;0;0;0;0;0;0;0;0;0;0;0;0
367;0.24597;0.070556;0.073321;0.55501;0;0;0;0;0;0;0;0;0;0;0;0;0
368;0.24705;0.071116;0.073845;0.55524;0;0;0;0;0;0;0;0;0;0;0;0;0
369;0.24794;0.071721;0.074364;0.55545;0;0;0;0;0;0;0;0;0;0;0;0;0
370;0.249;0.072253;0.074899;0.55565;0;0;0;0;0;0;0;0;0;0;0;0;0
371;0.24994;0.072742;0.075486;0.55581;0;0;0;0;0;0;0;0;0;0;0;0;0
372;0.25106;0.073254;0.075981;0.556;0;0;0;0;0;0;0;0;0;0;0;0;0
373;0.25201;0.073839;0.076448;0.55619;0;0;0;0;0;0;0;0;0;0;0;0;0
374;0.25328;0.074439;0.076928;0.55638;0;0;0;0;0;0;0;0;0;0;0;0;0
375;0.25408;0.074937;0.077428;0.55659;0;0;0;0;0;0;0;0;0;0;0;0;0
376;0.25513;0.075508;0.077992;0.55679;0;0;0;0;0;0;0;0;0;0;0;0;0
377;0.25623;0.076054;0.078532;0.55698;0;0;0;0;0;0;0;0;0;0;0;0;0
378;0.25715;0.076594;0.079048;0.55718;0;0;0;0;0;0;0;0;0;0;0;0;0
379;0.25821;0.077151;0.079671;0.55737;0;0;0;0;0;0;0;0;0;0;0;0;0
380;0.25932;0.077723;0.080195;0.55757;0;0;0;0;0;0;0;0;0;0;0;0;0
381;0.26028;0.078249;0.08072;0.55774;0;0;0;0;0;0;0;0;0;0;0;0;0
382;0.2615;0.078803;0.081359;0.55792;0;0;0;0;0;0;0;0;0;0;0;0;0
383;0.26242;0.079446;0.081946;0.55809;0;0;0;0;0;0;0;0;0;0;0;0;0
384;0.26339;0.080028;0.082624;0.55827;0;0;0;0;0;0;0;0;0;0;0;0;0
385;0.26455;0.080626;0.083231;0.55845;0;0;0;0;0;0;0;0;0;0;0;0;0
386;0.26554;0.081261;0.083811;0.55862;0;0;0;0;0;0;0;0;0;0;0;0;0
387;0.26652;0.081847;0.0844;0.55877;0;0;0;0;0;0;0;0;0;0;0;0;0
388;0.2677;0.082457;0.085127;0.55891;0;0;0;0;0;0;0;0;0;0;0;0;0
389;0.26871;0.083097;0.08565;0.55905;0;0;0;0;0;0;0;0;0;0;0;0;0
390;0.26981;0.083689;0.086209;0.55919;0;0;0;0;0;0;0;0;0;0;0;0;0
391;0.2709;0.084291;0.086754;0.55933;0;0;0;0;0;0;0;0;0;0;0;0;0
392;0.27187;0.084847;0.087379;0.55946;0;0;0;0;0;0;0;0;0;0;0;0;0
393;0.27296;0.085484;0.087978;0.55961;0;0;0;0;0;0;0;0;0;0;0;0;0
394;0.27401;0.086112;0.08857;0.55977;0;0;0;0;0;0;0;0;0;0;0;0;0
395;0.2751;0.086837;0.089246;0.55992;0;0;0;0;0;0;0;0;0;0;0;0;0
396;0.27618;0.087458;0.089882;0.56009;0;0;0;0;0;0;0;0;0;0;0;0;0
397;0.27719;0.088113;0.090438;0.56026;0;0;0;0;0;0;0;0;0;0;0;0;0
398;0.27826;0.088815;0.091194;0.5604;0;0;0;0;0;0;0;0;0;0;0;0;0
399;0.27935;0.089425;0.091771;0.56052;0;0;0;0;0;0;0;0;0;0;0;0;0
400;0.28051;0.090177;0.092417;0.56063;0;0;0;0;0;0;0;0;0;0;0;0;0
401;0.28155;0.090893;0.093229;0.56073;0;0;0;0;0;0;0;0;0;0;0;0;0
402;0.28247;0.091503;0.093946;0.56083;0;0;0;0;0;0;0;0;0;0;0;0;0
403;0.28371;0.092157;0.094639;0.56093;0;0;0;0;0;0;0;0;0;0;0;0;0
404;0.28494;0.092892;0.095403;0.56104;0;0;0;0;0;0;0;0;0;0;0;0;0
405;0.28599;0.093567;0.096117;0.56116;0;0;0;0;0;0;0;0;0;0;0;0;0
406;0.287;0.094291;0.096731;0.56126;0;0;0;0;0;0;0;0;0;0;0;0;0
407;0.28812;0.094941;0.09753;0.56134;0;0;0;0;0;0;0;0;0;0;0;0;0
408;0.28934;0.095633;0.09823;0.56143;0;0;0;0;0;0;0;0;0;0;0;0;0
409;0.29009;0.096277;0.098979;0.56152;0;0;0;0;0;0;0;0;0;0;0;0;0
410;0.29143;0.097013;0.099733;0.56161;0;0;0;0;0;0;0;0;0;0;0;0;0
411;0.2926;0.09784;0.10063;0.56174;0;0;0;0;0;0;0;0;0;0;0;0;0
412;0.29374;0.098556;0.10137;0.56183;0;0;0;0;0;0;0;0;0;0;0;0;0
413;0.29478;0.099354;0.10217;0.56191;0;0;0;0;0;0;0;0;0;0;0;0;0
414;0.29594;0.10024;0.10302;0.56198;0;0;0;0;0;0;0;0;0;0;0;0;0
415;0.29703;0.10105;0.10393;0.56202;0;0;0;0;0;0;0;0;0;0;0;0;0
416;0.29814;0.10184;0.10472;0.56205;0;0;0;0;0;0;0;0;0;0;0;0;0
417;0.29935;0.10267;0.10564;0.56211;0;0;0;0;0;0;0;0;0;0;0;0;0
418;0.30051;0.10352;0.10649;0.56216;0;0;0;0;0;0;0;0;0;0;0;0;0
419;0.30166;0.10442;0.10748;0.56221;0;0;0;0;0;0;0;0;0;0;0;0;0
420;0.30274;0.10526;0.10827;0.56227;0;0;0;0;0;0;0;0;0;0;0;0;0
421;0.30384;0.10612;0.10921;0.56231;0;0;0;0;0;0;0;0;0;0;0;0;0
422;0.30536;0.10706;0.11009;0.56236;0;0;0;0;0;0;0;0;0;0;0;0;0
423;0.30642;0.10791;0.11102;0.5624;0;0;0;0;0;0;0;0;0;0;0;0;0
424;0.30744;0.10883;0.112;0.56242;0;0;0;0;0;0;0;0;0;0;0;0;0
425;0.30867;0.10973;0.1129;0.56243;0;0;0;0;0;0;0;0;0;0;0;0;0
426;0.30986;0.11072;0.11391;0.56242;0;0;0;0;0;0;0;0;0;0;0;0;0
427;0.31102;0.1117;0.11481;0.56243;0;0;0;0;0;0;0;0;0;0;0;0;0
428;0.31218;0.11268;0.11579;0.56243;0;0;0;0;0;0;0;0;0;0;0;0;0
429;0.31332;0.11373;0.11667;0.56243;0;0;0;0;0;0;0;0;0;0;0;0;0
430;0.31459;0.11464;0.11767;0.56242;0;0;0;0;0;0;0;0;0;0;0;0;0
431;0.31563;0.11563;0.11858;0.56239;0;0;0;0;0;0;0;0;0;0;0;0;0
432;0.31694;0.11658;0.11956;0.56235;0;0;0;0;0;0;0;0;0;0;0;0;0
433;0.31812;0.11759;0.12055;0.56231;0;0;0;0;0;0;0;0;0;0;0;0;0
434;0.31935;0.11862;0.12141;0.56229;0;0;0;0;0;0;0;0;0;0;0;0;0
435;0.32056;0.1196;0.12244;0.56229;0;0;0;0;0;0;0;0;0;0;0;0;0
436;0.3215;0.12063;0.12348;0.56229;0;0;0;0;0;0;0;0;0;0;0;0;0
437;0.32297;0.12172;0.12458;0.56228;0;0;0;0;0;0;0;0;0;0;0;0;0
438;0.32376;0.12276;0.12565;0.56227;0;0;0;0;0;0;0;0;0;0;0;0;0
439;0.32535;0.12382;0.12671;0.56224;0;0;0;0;0;0;0;0;0;0;0;0;0
440;0.32659;0.12488;0.12777;0.56221;0;0;0;0;0;0;0;0;0;0;0;0;0
441;0.3278;0.12594;0.12884;0.56217;0;0;0;0;0;0;0;0;0;0;0;0;0
442;0.32911;0.12701;0.12989;0.56213;0;0;0;0;0;0;0;0;0;0;0;0;0
443;0.33012;0.12813;0.13099;0.5621;0;0;0;0;0;0;0;0;0;0;0;0;0
444;0.33172;0.12924;0.13204;0.56206;0;0;0;0;0;0;0;0;0;0;0;0;0
445;0.33291;0.13035;0.13321;0.56204;0;0;0;0;0;0;0;0;0;0;0;0;0
446;0.33377;0.13148;0.13429;0.56201;0;0;0;0;0;0;0;0;0;0;0;0;0
447;0.33535;0.13265;0.13537;0.56198;0;0;0;0;0;0;0;0;0;0;0;0;0
448;0.33663;0.13384;0.13655;0.56197;0;0;0;0;0;0;0;0;0;0;0;0;0
449;0.33789;0.13504;0.13771;0.56193;0;0;0;0;0;0;0;0;0;0;0;0;0
450;0.33913;0.13623;0.13882;0.5619;0;0;0;0;0;0;0;0;0;0;0;0;0
451;0.34043;0.13741;0.14;0.56188;0;0;0;0;0;0;0;0;0;0;0;0;0
452;0.34166;0.13867;0.14113;0.56181;0;0;0;0;0;0;0;0;0;0;0;0;0
453;0.34285;0.13988;0.14219;0.56178;0;0;0;0;0;0;0;0;0;0;0;0;0
454;0.34434;0.14112;0.14348;0.56175;0;0;0;0;0;0;0;0;0;0;0;0;0
455;0.34564;0.14238;0.14445;0.56174;0;0;0;0;0;0;0;0;0;0;0;0;0
456;0.34688;0.14367;0.14554;0.56172;0;0;0;0;0;0;0;0;0;0;0;0;0
457;0.34821;0.14492;0.14687;0.56169;0;0;0;0;0;0;0;0;0;0;0;0;0
458;0.34946;0.14624;0.14807;0.56164;0;0;0;0;0;0;0;0;0;0;0;0;0
459;0.3509;0.14753;0.14923;0.56158;0;0;0;0;0;0;0;0;0;0;0;0;0
460;0.35212;0.14881;0.15058;0.56151;0;0;0;0;0;0;0;0;0;0;0;0;0
461;0.35347;0.15018;0.15192;0.56144;0;0;0;0;0;0;0;0;0;0;0;0;0
462;0.35487;0.15147;0.15316;0.56138;0;0;0;0;0;0;0;0;0;0;0;0;0
463;0.35614;0.15278;0.15448;0.56129;0;0;0;0;0;0;0;0;0;0;0;0;0
464;0.35753;0.1542;0.15584;0.56122;0;0;0;0;0;0;0;0;0;0;0;0;0
465;0.35898;0.15555;0.15704;0.56114;0;0;0;0;0;0;0;0;0;0;0;0;0
466;0.36031;0.15691;0.15835;0.56104;0;0;0;0;0;0;0;0;0;0;0;0;0
467;0.36174;0.1583;0.15971;0.56092;0;0;0;0;0;0;0;0;0;0;0;0;0
468;0.36309;0.15963;0.16107;0.5608;0;0;0;0;0;0;0;0;0;0;0;0;0
469;0.36428;0.16111;0.16252;0.56064;0;0;0;0;0;0;0;0;0;0;0;0;0
470;0.36607;0.16255;0.16386;0.56046;0;0;0;0;0;0;0;0;0;0;0;0;0
471;0.36732;0.16397;0.16533;0.56028;0;0;0;0;0;0;0;0;0;0;0;0;0
472;0.36871;0.16542;0.1668;0.56004;0;0;0;0;0;0;0;0;0;0;0;0;0
473;0.37023;0.16695;0.16834;0.55978;0;0;0;0;0;0;0;0;0;0;0;0;0
474;0.37174;0.16844;0.16988;0.55949;0;0;0;0;0;0;0;0;0;0;0;0;0
475;0.37322;0.17003;0.17147;0.55914;0;0;0;0;0;0;0;0;0;0;0;0;0
476;0.37478;0.17158;0.17303;0.55874;0;0;0;0;0;0;0;0;0;0;0;0;0
477;0.37627;0.17312;0.17464;0.55821;0;0;0;0;0;0;0;0;0;0;0;0;0
478;0.37781;0.17479;0.17618;0.55766;0;0;0;0;0;0;0;0;0;0;0;0;0
479;0.37939;0.17641;0.17777;0.55697;0;0;0;0;0;0;0;0;0;0;0;0;0
480;0.38085;0.17796;0.17938;0.55621;0;0;0;0;0;0;0;0;0;0;0;0;0
481;0.38225;0.17955;0.18087;0.5554;0;0;0;0;0;0;0;0;0;0;0;0;0
482;0.38368;0.18107;0.18235;0.55448;0;0;0;0;0;0;0;0;0;0;0;0;0
483;0.38524;0.18255;0.18387;0.55349;0;0;0;0;0;0;0;0;0;0;0;0;0
484;0.38664;0.1841;0.18543;0.55251;0;0;0;0;0;0;0;0;0;0;0;0;0
485;0.38812;0.18582;0.187;0.55152;0;0;0;0;0;0;0;0;0;0;0;0;0
486;0.38985;0.18777;0.1887;0.5503;0;0;0;0;0;0;0;0;0;0;0;0;0
487;0.39194;0.19026;0.19088;0.5487;0;0;0;0;0;0;0;0;0;0;0;0;0
487.5;0.39299;0.19152;0.19194;0.54759;0;0;0;0;0;0;0;0;0;0;0;0;0