File: Template_Auto_Cali_large_DP600/_data/DP600Large_NT20_00_002_Front_DIC_File.txt
Date of Test;Material;Sample Geometry;Orientation [°];Test Number;Nominal Speed [mm/min];Thickness [mm];Central Width [mm];Gauge Width / Diameter [mm];Pixel to mm ratio [mm/px];Extensometer 1-4 [mm];Extensometer 2-3 [mm];Extensometer 5-6 [mm];;;;;
09/08/21;DP600Large;NT20;00;2;0.0798;0.28591;2;4;0;6;0.19997;0.4;;;;;
;;;;;;;;;;;;;;;;;
Time [s];U1 [mm];U2 [mm];U3 [mm];Force [kN];Ambient Temperature [°C];DIC Zone X 1 [px];DIC Zone Y 1 [px];DIC Zone X 2 [px];DIC Zone Y 2 [px];DIC Zone X 3 [px];DIC Zone Y 3 [px];DIC Zone X 4 [px];DIC Zone Y 4 [px];DIC Zone X 5 [px];DIC Zone Y 5 [px];DIC Zone X 6 [px];DIC Zone Y 6 [px]
0;0;0;0;0.011103;0;0;0;0;0;0;0;0;0;0;0;0;0
1;0.0001266;4.3801e-05;-6.1739e-05;0.011103;0;0;0;0;0;0;0;0;0;0;0;0;0
2;8.3185e-05;9.5587e-05;-2.4601e-05;0.011201;0;0;0;0;0;0;0;0;0;0;0;0;0
3.001;0.00035003;6.443e-05;-5.3558e-05;0.012338;0;0;0;0;0;0;0;0;0;0;0;0;0
4;0.00048846;1.5389e-05;-3.2191e-05;0.014435;0;0;0;0;0;0;0;0;0;0;0;0;0
5.001;0.00083731;-5.8327e-05;-8.1516e-05;0.017493;0;0;0;0;0;0;0;0;0;0;0;0;0
6;0.00067014;-8.1128e-06;-2.2686e-05;0.021168;0;0;0;0;0;0;0;0;0;0;0;0;0
7.001;0.00021248;-7.4651e-05;-0.00011729;0.024441;0;0;0;0;0;0;0;0;0;0;0;0;0
8;0.0011419;-3.657e-05;-2.3029e-05;0.027901;0;0;0;0;0;0;0;0;0;0;0;0;0
9;0.00099845;-0.00010061;-1.9897e-05;0.031291;0;0;0;0;0;0;0;0;0;0;0;0;0
10;0.0011612;-0.00014369;-0.00014259;0.034555;0;0;0;0;0;0;0;0;0;0;0;0;0
11;0.0010485;-0.00019083;-0.00015185;0.037955;0;0;0;0;0;0;0;0;0;0;0;0;0
12.001;0.0014553;-0.00016574;-0.00011108;0.041474;0;0;0;0;0;0;0;0;0;0;0;0;0
13.001;0.0015354;-0.00018598;-0.00015018;0.044708;0;0;0;0;0;0;0;0;0;0;0;0;0
14.001;0.0016216;-0.00016811;-9.883e-05;0.048157;0;0;0;0;0;0;0;0;0;0;0;0;0
15;0.0016645;-0.00026143;-0.0001295;0.051773;0;0;0;0;0;0;0;0;0;0;0;0;0
16;0.0018573;-0.00027998;-9.7767e-05;0.055576;0;0;0;0;0;0;0;0;0;0;0;0;0
17;0.0019878;-0.00022605;-0.00014685;0.059721;0;0;0;0;0;0;0;0;0;0;0;0;0
18;0.0021244;-0.00018682;-0.00014155;0.063749;0;0;0;0;0;0;0;0;0;0;0;0;0
19;0.0022784;-0.00021455;-0.00018136;0.068051;0;0;0;0;0;0;0;0;0;0;0;0;0
20;0.0026077;-0.00022568;-0.00014482;0.072687;0;0;0;0;0;0;0;0;0;0;0;0;0
21;0.0026344;-0.00025935;-0.0001839;0.077067;0;0;0;0;0;0;0;0;0;0;0;0;0
22;0.0028556;-0.00021696;-0.00017466;0.081663;0;0;0;0;0;0;0;0;0;0;0;0;0
23;0.0028462;-0.00025053;-0.00022607;0.086309;0;0;0;0;0;0;0;0;0;0;0;0;0
24.001;0.0030376;-0.00026916;-0.00022117;0.091169;0;0;0;0;0;0;0;0;0;0;0;0;0
25.002;0.0033491;-0.00028015;-0.00017611;0.095677;0;0;0;0;0;0;0;0;0;0;0;0;0
26;0.0033856;-0.00023031;-0.00018918;0.10061;0;0;0;0;0;0;0;0;0;0;0;0;0
27;0.0036527;-0.00025041;-0.00024178;0.10524;0;0;0;0;0;0;0;0;0;0;0;0;0
28;0.0036807;-0.00028174;-0.00024233;0.11011;0;0;0;0;0;0;0;0;0;0;0;0;0
29;0.0040025;-0.0002915;-0.00014618;0.11523;0;0;0;0;0;0;0;0;0;0;0;0;0
30.001;0.0042129;-0.00027645;-0.00025953;0.12003;0;0;0;0;0;0;0;0;0;0;0;0;0
31.001;0.0044652;-0.00042122;-0.00019741;0.1251;0;0;0;0;0;0;0;0;0;0;0;0;0
32.001;0.0046523;-0.00031273;-0.00023291;0.13043;0;0;0;0;0;0;0;0;0;0;0;0;0
33.001;0.0048843;-0.00040779;-0.00019317;0.13562;0;0;0;0;0;0;0;0;0;0;0;0;0
34.001;0.0051272;-0.00037632;-0.000189;0.14081;0;0;0;0;0;0;0;0;0;0;0;0;0
35.001;0.0054793;-0.00040311;-0.00019928;0.14575;0;0;0;0;0;0;0;0;0;0;0;0;0
36;0.0056176;-0.00039196;-0.00015447;0.15088;0;0;0;0;0;0;0;0;0;0;0;0;0
37.001;0.0058907;-0.0003796;-0.00018074;0.15596;0;0;0;0;0;0;0;0;0;0;0;0;0
38;0.0061374;-0.0004079;-0.00022887;0.16101;0;0;0;0;0;0;0;0;0;0;0;0;0
39.001;0.0064105;-0.00048182;-0.00020035;0.16607;0;0;0;0;0;0;0;0;0;0;0;0;0
40;0.006741;-0.00046704;-0.00023932;0.1711;0;0;0;0;0;0;0;0;0;0;0;0;0
41;0.006967;-0.00045586;-0.00022318;0.17632;0;0;0;0;0;0;0;0;0;0;0;0;0
42;0.0073968;-0.00041575;-0.00021251;0.18111;0;0;0;0;0;0;0;0;0;0;0;0;0
43.001;0.0076904;-0.00042739;-0.00020012;0.1862;0;0;0;0;0;0;0;0;0;0;0;0;0
44;0.0080567;-0.00040081;-0.00019027;0.19079;0;0;0;0;0;0;0;0;0;0;0;0;0
45;0.0084698;-0.00042466;-0.0003011;0.19546;0;0;0;0;0;0;0;0;0;0;0;0;0
46;0.0088916;-0.00035073;-0.00034791;0.19997;0;0;0;0;0;0;0;0;0;0;0;0;0
47.001;0.009473;-0.00033068;-0.00033525;0.20455;0;0;0;0;0;0;0;0;0;0;0;0;0
48;0.0098793;-0.00031627;-0.00039472;0.20868;0;0;0;0;0;0;0;0;0;0;0;0;0
49;0.010541;-0.00032375;-0.00042978;0.21281;0;0;0;0;0;0;0;0;0;0;0;0;0
50;0.011137;-0.00033817;-0.00044315;0.21675;0;0;0;0;0;0;0;0;0;0;0;0;0
51.001;0.011811;-0.00030028;-0.00050929;0.22048;0;0;0;0;0;0;0;0;0;0;0;0;0
52;0.012605;-0.00023204;-0.00058131;0.22398;0;0;0;0;0;0;0;0;0;0;0;0;0
53;0.012996;-0.00027349;-0.00067185;0.22739;0;0;0;0;0;0;0;0;0;0;0;0;0
54;0.013866;-0.000167;-0.00067079;0.23038;0;0;0;0;0;0;0;0;0;0;0;0;0
55.001;0.014494;-4.4383e-05;-0.00071899;0.23333;0;0;0;0;0;0;0;0;0;0;0;0;0
56;0.015195;-0.00018159;-0.00075171;0.23614;0;0;0;0;0;0;0;0;0;0;0;0;0
57;0.015612;-3.5807e-05;-0.00080023;0.23893;0;0;0;0;0;0;0;0;0;0;0;0;0
57.999;0.016816;4.8633e-05;-0.00088589;0.24141;0;0;0;0;0;0;0;0;0;0;0;0;0
59;0.017681;3.2824e-05;-0.00097203;0.24387;0;0;0;0;0;0;0;0;0;0;0;0;0
60.001;0.018633;0.00011069;-0.0010861;0.24623;0;0;0;0;0;0;0;0;0;0;0;0;0
61.001;0.019284;0.00013286;-0.0011202;0.2485;0;0;0;0;0;0;0;0;0;0;0;0;0
62;0.020073;0.00018247;-0.0012192;0.25068;0;0;0;0;0;0;0;0;0;0;0;0;0
63.001;0.02099;0.00021431;-0.0012482;0.25279;0;0;0;0;0;0;0;0;0;0;0;0;0
63.999;0.022128;0.00036862;-0.001268;0.25483;0;0;0;0;0;0;0;0;0;0;0;0;0
64.999;0.022804;0.00034686;-0.0013211;0.25682;0;0;0;0;0;0;0;0;0;0;0;0;0
66;0.023543;0.00050061;-0.0013978;0.25877;0;0;0;0;0;0;0;0;0;0;0;0;0
67.001;0.02451;0.00038518;-0.0014292;0.26069;0;0;0;0;0;0;0;0;0;0;0;0;0
68;0.02534;0.00052076;-0.0015098;0.26255;0;0;0;0;0;0;0;0;0;0;0;0;0
69;0.026242;0.00057501;-0.0015212;0.26436;0;0;0;0;0;0;0;0;0;0;0;0;0
70;0.027184;0.00052035;-0.0016375;0.26612;0;0;0;0;0;0;0;0;0;0;0;0;0
71.001;0.028031;0.00060713;-0.0016386;0.2679;0;0;0;0;0;0;0;0;0;0;0;0;0
72.001;0.02895;0.00057937;-0.0017256;0.26953;0;0;0;0;0;0;0;0;0;0;0;0;0
73;0.029953;0.00072255;-0.0017503;0.27121;0;0;0;0;0;0;0;0;0;0;0;0;0
74.002;0.031033;0.00066851;-0.0018387;0.27292;0;0;0;0;0;0;0;0;0;0;0;0;0
75.001;0.031795;0.0007784;-0.0018486;0.27449;0;0;0;0;0;0;0;0;0;0;0;0;0
76;0.032873;0.0008213;-0.0019419;0.2761;0;0;0;0;0;0;0;0;0;0;0;0;0
77;0.03375;0.00094309;-0.0018995;0.27774;0;0;0;0;0;0;0;0;0;0;0;0;0
78;0.034673;0.0010137;-0.001928;0.27922;0;0;0;0;0;0;0;0;0;0;0;0;0
79;0.035624;0.0010032;-0.0020226;0.28072;0;0;0;0;0;0;0;0;0;0;0;0;0
80;0.036639;0.0011665;-0.002023;0.28224;0;0;0;0;0;0;0;0;0;0;0;0;0
81;0.037682;0.001149;-0.0020774;0.28364;0;0;0;0;0;0;0;0;0;0;0;0;0
82;0.038605;0.0012472;-0.0022138;0.28508;0;0;0;0;0;0;0;0;0;0;0;0;0
83;0.039592;0.0013321;-0.002095;0.2865;0;0;0;0;0;0;0;0;0;0;0;0;0
84;0.040618;0.0013773;-0.00227;0.28791;0;0;0;0;0;0;0;0;0;0;0;0;0
85;0.041574;0.0014516;-0.0022765;0.28928;0;0;0;0;0;0;0;0;0;0;0;0;0
86;0.042484;0.0014383;-0.0023282;0.29067;0;0;0;0;0;0;0;0;0;0;0;0;0
87;0.043536;0.0015371;-0.0024282;0.29183;0;0;0;0;0;0;0;0;0;0;0;0;0
88;0.044562;0.0016441;-0.0024147;0.29326;0;0;0;0;0;0;0;0;0;0;0;0;0
89;0.045608;0.0017001;-0.0024892;0.29447;0;0;0;0;0;0;0;0;0;0;0;0;0
90;0.046558;0.0017735;-0.002515;0.29595;0;0;0;0;0;0;0;0;0;0;0;0;0
91.001;0.047603;0.0018396;-0.0025726;0.29717;0;0;0;0;0;0;0;0;0;0;0;0;0
92.031;0.048669;0.0019231;-0.0026167;0.29833;0;0;0;0;0;0;0;0;0;0;0;0;0
93;0.049764;0.0019776;-0.0026176;0.2995;0;0;0;0;0;0;0;0;0;0;0;0;0
94;0.050753;0.0020183;-0.0026915;0.30073;0;0;0;0;0;0;0;0;0;0;0;0;0
95;0.05177;0.0020438;-0.0027849;0.30204;0;0;0;0;0;0;0;0;0;0;0;0;0
96;0.052888;0.002125;-0.0028465;0.3031;0;0;0;0;0;0;0;0;0;0;0;0;0
97;0.053987;0.0022678;-0.0028441;0.30435;0;0;0;0;0;0;0;0;0;0;0;0;0
98;0.054982;0.0022958;-0.0029274;0.30551;0;0;0;0;0;0;0;0;0;0;0;0;0
98.999;0.056;0.0023665;-0.0029761;0.30652;0;0;0;0;0;0;0;0;0;0;0;0;0
100;0.056963;0.0024038;-0.0030414;0.30762;0;0;0;0;0;0;0;0;0;0;0;0;0
101;0.058126;0.0024744;-0.003074;0.30878;0;0;0;0;0;0;0;0;0;0;0;0;0
102;0.059229;0.0025796;-0.0031555;0.30974;0;0;0;0;0;0;0;0;0;0;0;0;0
103;0.06029;0.002638;-0.0031867;0.31086;0;0;0;0;0;0;0;0;0;0;0;0;0
104;0.061452;0.0026777;-0.0032242;0.3119;0;0;0;0;0;0;0;0;0;0;0;0;0
105;0.06253;0.0027435;-0.0033326;0.31293;0;0;0;0;0;0;0;0;0;0;0;0;0
106;0.063489;0.002862;-0.0034489;0.31387;0;0;0;0;0;0;0;0;0;0;0;0;0
107;0.064387;0.0028253;-0.0034467;0.31495;0;0;0;0;0;0;0;0;0;0;0;0;0
108;0.065549;0.0029215;-0.0035244;0.31592;0;0;0;0;0;0;0;0;0;0;0;0;0
109;0.066867;0.0029852;-0.003527;0.31679;0;0;0;0;0;0;0;0;0;0;0;0;0
110.01;0.067651;0.0030332;-0.0036357;0.31781;0;0;0;0;0;0;0;0;0;0;0;0;0
111;0.068843;0.0031342;-0.0036888;0.31876;0;0;0;0;0;0;0;0;0;0;0;0;0
112;0.069858;0.0031814;-0.003777;0.3196;0;0;0;0;0;0;0;0;0;0;0;0;0
113;0.070879;0.0032371;-0.0038623;0.32058;0;0;0;0;0;0;0;0;0;0;0;0;0
114;0.072131;0.0033124;-0.0038954;0.32147;0;0;0;0;0;0;0;0;0;0;0;0;0
115;0.072891;0.0034024;-0.0039882;0.32228;0;0;0;0;0;0;0;0;0;0;0;0;0
116;0.074108;0.0033869;-0.0040009;0.32326;0;0;0;0;0;0;0;0;0;0;0;0;0
117;0.075271;0.0034511;-0.0041497;0.32414;0;0;0;0;0;0;0;0;0;0;0;0;0
118;0.07631;0.0035073;-0.0041715;0.32488;0;0;0;0;0;0;0;0;0;0;0;0;0
119;0.077417;0.0035285;-0.004272;0.32577;0;0;0;0;0;0;0;0;0;0;0;0;0
120;0.0785;0.0036276;-0.0043884;0.32661;0;0;0;0;0;0;0;0;0;0;0;0;0
121.02;0.079672;0.0036362;-0.0044671;0.32753;0;0;0;0;0;0;0;0;0;0;0;0;0
122;0.08076;0.0038401;-0.0045158;0.32832;0;0;0;0;0;0;0;0;0;0;0;0;0
123;0.081493;0.0038315;-0.0046086;0.3292;0;0;0;0;0;0;0;0;0;0;0;0;0
124;0.082917;0.0039747;-0.0046734;0.33002;0;0;0;0;0;0;0;0;0;0;0;0;0
125;0.08402;0.004082;-0.004717;0.33075;0;0;0;0;0;0;0;0;0;0;0;0;0
126;0.085087;0.0040931;-0.0048551;0.33158;0;0;0;0;0;0;0;0;0;0;0;0;0
127;0.086142;0.0041894;-0.0049241;0.33235;0;0;0;0;0;0;0;0;0;0;0;0;0
128;0.087269;0.004255;-0.0049678;0.33316;0;0;0;0;0;0;0;0;0;0;0;0;0
129;0.088357;0.0042634;-0.0050799;0.33387;0;0;0;0;0;0;0;0;0;0;0;0;0
130;0.089809;0.0043216;-0.00513;0.3346;0;0;0;0;0;0;0;0;0;0;0;0;0
131;0.090849;0.0043534;-0.005209;0.33533;0;0;0;0;0;0;0;0;0;0;0;0;0
132;0.091648;0.0043247;-0.0052319;0.33597;0;0;0;0;0;0;0;0;0;0;0;0;0
133;0.09292;0.0043594;-0.005356;0.33674;0;0;0;0;0;0;0;0;0;0;0;0;0
134;0.093978;0.0044439;-0.0054093;0.33744;0;0;0;0;0;0;0;0;0;0;0;0;0
135;0.095039;0.0045559;-0.0054162;0.33815;0;0;0;0;0;0;0;0;0;0;0;0;0
136;0.096179;0.0045842;-0.0054521;0.33878;0;0;0;0;0;0;0;0;0;0;0;0;0
137;0.097286;0.0046777;-0.0055191;0.33948;0;0;0;0;0;0;0;0;0;0;0;0;0
138;0.098483;0.0047277;-0.0056326;0.34018;0;0;0;0;0;0;0;0;0;0;0;0;0
139;0.099605;0.0047354;-0.0056716;0.34092;0;0;0;0;0;0;0;0;0;0;0;0;0
140;0.10068;0.0048375;-0.0057612;0.34162;0;0;0;0;0;0;0;0;0;0;0;0;0
141;0.10176;0.0048756;-0.0058182;0.34223;0;0;0;0;0;0;0;0;0;0;0;0;0
142;0.10291;0.0048294;-0.0058244;0.34298;0;0;0;0;0;0;0;0;0;0;0;0;0
143;0.10422;0.0049325;-0.0059196;0.34362;0;0;0;0;0;0;0;0;0;0;0;0;0
144;0.10497;0.0049648;-0.0059966;0.34425;0;0;0;0;0;0;0;0;0;0;0;0;0
145;0.10619;0.005057;-0.006064;0.34482;0;0;0;0;0;0;0;0;0;0;0;0;0
146;0.10754;0.0050887;-0.0061616;0.34547;0;0;0;0;0;0;0;0;0;0;0;0;0
147;0.10843;0.0051985;-0.0061774;0.34601;0;0;0;0;0;0;0;0;0;0;0;0;0
148;0.1097;0.0052884;-0.0062655;0.34666;0;0;0;0;0;0;0;0;0;0;0;0;0
149;0.11081;0.0054277;-0.0062914;0.34726;0;0;0;0;0;0;0;0;0;0;0;0;0
150.01;0.11177;0.0055343;-0.0063295;0.34785;0;0;0;0;0;0;0;0;0;0;0;0;0
151;0.11296;0.0056612;-0.0063971;0.34843;0;0;0;0;0;0;0;0;0;0;0;0;0
152;0.11402;0.0057338;-0.0064006;0.34902;0;0;0;0;0;0;0;0;0;0;0;0;0
153;0.11518;0.0058204;-0.0064806;0.34954;0;0;0;0;0;0;0;0;0;0;0;0;0
154;0.11627;0.0059001;-0.0065849;0.35011;0;0;0;0;0;0;0;0;0;0;0;0;0
155;0.1175;0.006033;-0.0066103;0.35074;0;0;0;0;0;0;0;0;0;0;0;0;0
156;0.11857;0.0061156;-0.0066606;0.35129;0;0;0;0;0;0;0;0;0;0;0;0;0
157;0.11969;0.0062215;-0.0067313;0.35185;0;0;0;0;0;0;0;0;0;0;0;0;0
158;0.12086;0.0063144;-0.0068214;0.35242;0;0;0;0;0;0;0;0;0;0;0;0;0
159;0.1221;0.0063975;-0.0069558;0.35292;0;0;0;0;0;0;0;0;0;0;0;0;0
160;0.12313;0.0064897;-0.0069967;0.35347;0;0;0;0;0;0;0;0;0;0;0;0;0
161;0.12433;0.0065714;-0.0069928;0.35403;0;0;0;0;0;0;0;0;0;0;0;0;0
162;0.12555;0.0066644;-0.0070371;0.35455;0;0;0;0;0;0;0;0;0;0;0;0;0
163;0.12649;0.0066558;-0.0070423;0.35501;0;0;0;0;0;0;0;0;0;0;0;0;0
164;0.12769;0.0067275;-0.0070367;0.35551;0;0;0;0;0;0;0;0;0;0;0;0;0
165;0.12886;0.0067773;-0.006997;0.35602;0;0;0;0;0;0;0;0;0;0;0;0;0
166;0.13003;0.0068676;-0.0069117;0.3565;0;0;0;0;0;0;0;0;0;0;0;0;0
167;0.13118;0.0069802;-0.0069262;0.357;0;0;0;0;0;0;0;0;0;0;0;0;0
168;0.13239;0.0070411;-0.00699;0.3574;0;0;0;0;0;0;0;0;0;0;0;0;0
169;0.13341;0.0071231;-0.0071621;0.35796;0;0;0;0;0;0;0;0;0;0;0;0;0
170;0.13453;0.0072146;-0.007275;0.35847;0;0;0;0;0;0;0;0;0;0;0;0;0
171;0.13566;0.0073402;-0.0074834;0.35893;0;0;0;0;0;0;0;0;0;0;0;0;0
172;0.13677;0.0073992;-0.0076657;0.35937;0;0;0;0;0;0;0;0;0;0;0;0;0
173;0.13794;0.0074784;-0.0078273;0.35988;0;0;0;0;0;0;0;0;0;0;0;0;0
174;0.13908;0.0075242;-0.0079483;0.36031;0;0;0;0;0;0;0;0;0;0;0;0;0
175;0.14013;0.0075972;-0.0080437;0.3608;0;0;0;0;0;0;0;0;0;0;0;0;0
176;0.14119;0.0076499;-0.0081056;0.36123;0;0;0;0;0;0;0;0;0;0;0;0;0
177;0.14246;0.0077908;-0.008248;0.36171;0;0;0;0;0;0;0;0;0;0;0;0;0
178;0.14364;0.0078447;-0.0082503;0.36216;0;0;0;0;0;0;0;0;0;0;0;0;0
179;0.14472;0.0079891;-0.0082364;0.36258;0;0;0;0;0;0;0;0;0;0;0;0;0
180;0.1459;0.0081336;-0.0081299;0.36301;0;0;0;0;0;0;0;0;0;0;0;0;0
181;0.14712;0.0082686;-0.0080152;0.36337;0;0;0;0;0;0;0;0;0;0;0;0;0
182;0.14818;0.0083509;-0.0080437;0.36386;0;0;0;0;0;0;0;0;0;0;0;0;0
183;0.14933;0.0083957;-0.0081179;0.36429;0;0;0;0;0;0;0;0;0;0;0;0;0
184;0.15052;0.0085452;-0.0081662;0.36469;0;0;0;0;0;0;0;0;0;0;0;0;0
185;0.15155;0.008679;-0.0082007;0.3651;0;0;0;0;0;0;0;0;0;0;0;0;0
186;0.15266;0.0088004;-0.0082458;0.36544;0;0;0;0;0;0;0;0;0;0;0;0;0
187;0.15391;0.0088825;-0.0082595;0.36586;0;0;0;0;0;0;0;0;0;0;0;0;0
188;0.15508;0.0089796;-0.0083314;0.36628;0;0;0;0;0;0;0;0;0;0;0;0;0
189;0.15622;0.0091293;-0.008441;0.36669;0;0;0;0;0;0;0;0;0;0;0;0;0
190;0.15734;0.0092542;-0.0084785;0.3671;0;0;0;0;0;0;0;0;0;0;0;0;0
191;0.15852;0.0093478;-0.00858;0.36747;0;0;0;0;0;0;0;0;0;0;0;0;0
192;0.15988;0.0094908;-0.0085412;0.36781;0;0;0;0;0;0;0;0;0;0;0;0;0
193;0.16087;0.0095719;-0.0086901;0.36822;0;0;0;0;0;0;0;0;0;0;0;0;0
194;0.16201;0.0097355;-0.0088337;0.3686;0;0;0;0;0;0;0;0;0;0;0;0;0
195;0.16315;0.0098228;-0.0089016;0.36898;0;0;0;0;0;0;0;0;0;0;0;0;0
196;0.1643;0.009932;-0.0089643;0.36936;0;0;0;0;0;0;0;0;0;0;0;0;0
197;0.16551;0.010116;-0.009121;0.36973;0;0;0;0;0;0;0;0;0;0;0;0;0
198;0.16669;0.010192;-0.009118;0.37007;0;0;0;0;0;0;0;0;0;0;0;0;0
199;0.16781;0.010238;-0.0092657;0.37046;0;0;0;0;0;0;0;0;0;0;0;0;0
200;0.16892;0.010331;-0.009454;0.3708;0;0;0;0;0;0;0;0;0;0;0;0;0
201;0.17011;0.010499;-0.0095301;0.37114;0;0;0;0;0;0;0;0;0;0;0;0;0
202;0.17132;0.010599;-0.009628;0.37148;0;0;0;0;0;0;0;0;0;0;0;0;0
203;0.17248;0.01077;-0.0097405;0.37178;0;0;0;0;0;0;0;0;0;0;0;0;0
204;0.17367;0.010866;-0.0098223;0.37215;0;0;0;0;0;0;0;0;0;0;0;0;0
205;0.17481;0.010979;-0.0099485;0.37244;0;0;0;0;0;0;0;0;0;0;0;0;0
206;0.17599;0.011061;-0.010005;0.37277;0;0;0;0;0;0;0;0;0;0;0;0;0
207;0.1773;0.011202;-0.010128;0.37309;0;0;0;0;0;0;0;0;0;0;0;0;0
208;0.17831;0.011313;-0.010266;0.37341;0;0;0;0;0;0;0;0;0;0;0;0;0
209;0.17941;0.01147;-0.010406;0.37376;0;0;0;0;0;0;0;0;0;0;0;0;0
210;0.18063;0.011648;-0.010426;0.37408;0;0;0;0;0;0;0;0;0;0;0;0;0
211;0.18176;0.011731;-0.010569;0.37436;0;0;0;0;0;0;0;0;0;0;0;0;0
212.04;0.18294;0.011898;-0.010637;0.37469;0;0;0;0;0;0;0;0;0;0;0;0;0
213;0.18416;0.012073;-0.010715;0.375;0;0;0;0;0;0;0;0;0;0;0;0;0
214;0.18518;0.0122;-0.01085;0.3753;0;0;0;0;0;0;0;0;0;0;0;0;0
215;0.18626;0.012318;-0.010873;0.37563;0;0;0;0;0;0;0;0;0;0;0;0;0
216;0.18764;0.012531;-0.010956;0.37592;0;0;0;0;0;0;0;0;0;0;0;0;0
217;0.18879;0.012676;-0.011002;0.37623;0;0;0;0;0;0;0;0;0;0;0;0;0
218;0.18991;0.012775;-0.011145;0.3765;0;0;0;0;0;0;0;0;0;0;0;0;0
219;0.19122;0.012963;-0.011269;0.3768;0;0;0;0;0;0;0;0;0;0;0;0;0
220;0.19228;0.013023;-0.011359;0.37709;0;0;0;0;0;0;0;0;0;0;0;0;0
221;0.19339;0.013165;-0.011461;0.37739;0;0;0;0;0;0;0;0;0;0;0;0;0
222;0.19462;0.013344;-0.011587;0.37765;0;0;0;0;0;0;0;0;0;0;0;0;0
223;0.19584;0.013455;-0.011623;0.37792;0;0;0;0;0;0;0;0;0;0;0;0;0
224;0.19699;0.013577;-0.011714;0.3782;0;0;0;0;0;0;0;0;0;0;0;0;0
225;0.19816;0.013688;-0.011769;0.37846;0;0;0;0;0;0;0;0;0;0;0;0;0
226;0.19933;0.01389;-0.011834;0.3787;0;0;0;0;0;0;0;0;0;0;0;0;0
227;0.20047;0.01404;-0.011867;0.37898;0;0;0;0;0;0;0;0;0;0;0;0;0
228;0.20168;0.014129;-0.011918;0.37922;0;0;0;0;0;0;0;0;0;0;0;0;0
229;0.20285;0.01424;-0.011974;0.37943;0;0;0;0;0;0;0;0;0;0;0;0;0
230.04;0.20409;0.014415;-0.011958;0.3797;0;0;0;0;0;0;0;0;0;0;0;0;0
231;0.20523;0.014604;-0.012094;0.37994;0;0;0;0;0;0;0;0;0;0;0;0;0
232;0.20635;0.014706;-0.012193;0.38019;0;0;0;0;0;0;0;0;0;0;0;0;0
233;0.20739;0.014884;-0.012395;0.38041;0;0;0;0;0;0;0;0;0;0;0;0;0
234;0.20872;0.01504;-0.012545;0.38066;0;0;0;0;0;0;0;0;0;0;0;0;0
235;0.20977;0.015102;-0.012699;0.3809;0;0;0;0;0;0;0;0;0;0;0;0;0
236;0.21107;0.015326;-0.012796;0.38112;0;0;0;0;0;0;0;0;0;0;0;0;0
237;0.21224;0.015448;-0.013;0.38137;0;0;0;0;0;0;0;0;0;0;0;0;0
238;0.21353;0.015687;-0.013103;0.3816;0;0;0;0;0;0;0;0;0;0;0;0;0
239;0.21461;0.015878;-0.013195;0.38183;0;0;0;0;0;0;0;0;0;0;0;0;0
240;0.21578;0.01598;-0.013298;0.3821;0;0;0;0;0;0;0;0;0;0;0;0;0
241;0.21701;0.016102;-0.013246;0.38235;0;0;0;0;0;0;0;0;0;0;0;0;0
242;0.21826;0.016268;-0.013262;0.38259;0;0;0;0;0;0;0;0;0;0;0;0;0
243;0.21941;0.016406;-0.013289;0.38285;0;0;0;0;0;0;0;0;0;0;0;0;0
244;0.22055;0.016501;-0.013338;0.38306;0;0;0;0;0;0;0;0;0;0;0;0;0
245;0.22179;0.016602;-0.013493;0.38329;0;0;0;0;0;0;0;0;0;0;0;0;0
246;0.22318;0.016689;-0.013604;0.38348;0;0;0;0;0;0;0;0;0;0;0;0;0
247;0.22418;0.016845;-0.013676;0.3837;0;0;0;0;0;0;0;0;0;0;0;0;0
248;0.22543;0.017176;-0.01376;0.38389;0;0;0;0;0;0;0;0;0;0;0;0;0
249;0.22659;0.017306;-0.013927;0.38408;0;0;0;0;0;0;0;0;0;0;0;0;0
250;0.2278;0.017219;-0.014088;0.3843;0;0;0;0;0;0;0;0;0;0;0;0;0
251;0.22896;0.017246;-0.014187;0.38448;0;0;0;0;0;0;0;0;0;0;0;0;0
252;0.23015;0.017371;-0.014225;0.38465;0;0;0;0;0;0;0;0;0;0;0;0;0
253;0.23141;0.017473;-0.01436;0.38486;0;0;0;0;0;0;0;0;0;0;0;0;0
254;0.23261;0.017497;-0.014388;0.385;0;0;0;0;0;0;0;0;0;0;0;0;0
255;0.23384;0.017799;-0.014529;0.3852;0;0;0;0;0;0;0;0;0;0;0;0;0
256;0.23501;0.017973;-0.014618;0.38536;0;0;0;0;0;0;0;0;0;0;0;0;0
257;0.23616;0.018103;-0.014777;0.38557;0;0;0;0;0;0;0;0;0;0;0;0;0
258;0.23746;0.018261;-0.01487;0.38573;0;0;0;0;0;0;0;0;0;0;0;0;0
259;0.23872;0.018441;-0.015043;0.38592;0;0;0;0;0;0;0;0;0;0;0;0;0
260;0.23979;0.018619;-0.01518;0.38611;0;0;0;0;0;0;0;0;0;0;0;0;0
261;0.24106;0.018723;-0.015263;0.38626;0;0;0;0;0;0;0;0;0;0;0;0;0
262;0.24219;0.018824;-0.015356;0.38645;0;0;0;0;0;0;0;0;0;0;0;0;0
263;0.24346;0.01895;-0.015478;0.38663;0;0;0;0;0;0;0;0;0;0;0;0;0
264;0.24461;0.019142;-0.015609;0.38683;0;0;0;0;0;0;0;0;0;0;0;0;0
265;0.24579;0.019268;-0.015722;0.38699;0;0;0;0;0;0;0;0;0;0;0;0;0
266;0.24704;0.019461;-0.015857;0.38715;0;0;0;0;0;0;0;0;0;0;0;0;0
267;0.24833;0.019734;-0.015952;0.38732;0;0;0;0;0;0;0;0;0;0;0;0;0
268;0.24951;0.020058;-0.016104;0.38747;0;0;0;0;0;0;0;0;0;0;0;0;0
269;0.25066;0.020286;-0.01615;0.38762;0;0;0;0;0;0;0;0;0;0;0;0;0
270;0.25203;0.020445;-0.016285;0.38779;0;0;0;0;0;0;0;0;0;0;0;0;0
271;0.25281;0.020701;-0.016412;0.3879;0;0;0;0;0;0;0;0;0;0;0;0;0
272;0.25423;0.021018;-0.016434;0.38807;0;0;0;0;0;0;0;0;0;0;0;0;0
273;0.25538;0.021333;-0.016582;0.3882;0;0;0;0;0;0;0;0;0;0;0;0;0
274;0.25682;0.021444;-0.016743;0.38833;0;0;0;0;0;0;0;0;0;0;0;0;0
275;0.25827;0.021674;-0.016879;0.38848;0;0;0;0;0;0;0;0;0;0;0;0;0
276;0.2591;0.021969;-0.016923;0.3886;0;0;0;0;0;0;0;0;0;0;0;0;0
277;0.26043;0.022232;-0.017063;0.38873;0;0;0;0;0;0;0;0;0;0;0;0;0
278;0.26153;0.022451;-0.017157;0.38885;0;0;0;0;0;0;0;0;0;0;0;0;0
279;0.26359;0.022538;-0.017272;0.38899;0;0;0;0;0;0;0;0;0;0;0;0;0
280;0.26397;0.022605;-0.017371;0.38911;0;0;0;0;0;0;0;0;0;0;0;0;0
281;0.26527;0.022791;-0.017467;0.38927;0;0;0;0;0;0;0;0;0;0;0;0;0
282;0.26647;0.023041;-0.017588;0.38938;0;0;0;0;0;0;0;0;0;0;0;0;0
283;0.26777;0.023136;-0.017661;0.3895;0;0;0;0;0;0;0;0;0;0;0;0;0
284.01;0.26911;0.023176;-0.017778;0.38963;0;0;0;0;0;0;0;0;0;0;0;0;0
285;0.27025;0.023412;-0.017957;0.38977;0;0;0;0;0;0;0;0;0;0;0;0;0
286;0.27149;0.023572;-0.018035;0.3899;0;0;0;0;0;0;0;0;0;0;0;0;0
287;0.27258;0.023742;-0.01809;0.39005;0;0;0;0;0;0;0;0;0;0;0;0;0
288;0.27387;0.023814;-0.018246;0.39017;0;0;0;0;0;0;0;0;0;0;0;0;0
289;0.27515;0.023973;-0.018346;0.39028;0;0;0;0;0;0;0;0;0;0;0;0;0
290;0.27631;0.024121;-0.018566;0.3904;0;0;0;0;0;0;0;0;0;0;0;0;0
291;0.27764;0.02428;-0.018659;0.3905;0;0;0;0;0;0;0;0;0;0;0;0;0
292;0.27874;0.024542;-0.018865;0.39061;0;0;0;0;0;0;0;0;0;0;0;0;0
293;0.27997;0.024897;-0.01889;0.39071;0;0;0;0;0;0;0;0;0;0;0;0;0
294;0.2813;0.025133;-0.018979;0.39079;0;0;0;0;0;0;0;0;0;0;0;0;0
295;0.28259;0.025349;-0.019133;0.3909;0;0;0;0;0;0;0;0;0;0;0;0;0
296;0.28371;0.02554;-0.019239;0.39097;0;0;0;0;0;0;0;0;0;0;0;0;0
297;0.285;0.025629;-0.019288;0.39106;0;0;0;0;0;0;0;0;0;0;0;0;0
298;0.28616;0.025601;-0.01942;0.39114;0;0;0;0;0;0;0;0;0;0;0;0;0
299;0.28748;0.025582;-0.019571;0.39122;0;0;0;0;0;0;0;0;0;0;0;0;0
300;0.28871;0.025717;-0.019676;0.39129;0;0;0;0;0;0;0;0;0;0;0;0;0
301;0.28997;0.025864;-0.019735;0.39139;0;0;0;0;0;0;0;0;0;0;0;0;0
302;0.29116;0.026066;-0.019881;0.39146;0;0;0;0;0;0;0;0;0;0;0;0;0
303;0.29245;0.026162;-0.020018;0.39155;0;0;0;0;0;0;0;0;0;0;0;0;0
304;0.29391;0.026325;-0.020104;0.39163;0;0;0;0;0;0;0;0;0;0;0;0;0
305;0.29489;0.026552;-0.020287;0.3917;0;0;0;0;0;0;0;0;0;0;0;0;0
306;0.29598;0.026908;-0.020369;0.39177;0;0;0;0;0;0;0;0;0;0;0;0;0
307;0.29729;0.027322;-0.020505;0.39185;0;0;0;0;0;0;0;0;0;0;0;0;0
308;0.29857;0.027574;-0.020671;0.39193;0;0;0;0;0;0;0;0;0;0;0;0;0
309;0.29983;0.02787;-0.020794;0.39201;0;0;0;0;0;0;0;0;0;0;0;0;0
310;0.30102;0.027943;-0.020866;0.39209;0;0;0;0;0;0;0;0;0;0;0;0;0
311;0.30241;0.028033;-0.020971;0.39216;0;0;0;0;0;0;0;0;0;0;0;0;0
312;0.30364;0.028134;-0.021143;0.39223;0;0;0;0;0;0;0;0;0;0;0;0;0
313;0.30487;0.028427;-0.021243;0.39229;0;0;0;0;0;0;0;0;0;0;0;0;0
314;0.30619;0.02874;-0.021338;0.39236;0;0;0;0;0;0;0;0;0;0;0;0;0
315;0.30737;0.028981;-0.021507;0.3924;0;0;0;0;0;0;0;0;0;0;0;0;0
316;0.30851;0.029261;-0.021623;0.39243;0;0;0;0;0;0;0;0;0;0;0;0;0
317;0.30992;0.029503;-0.021821;0.39247;0;0;0;0;0;0;0;0;0;0;0;0;0
318;0.31109;0.029764;-0.021936;0.39248;0;0;0;0;0;0;0;0;0;0;0;0;0
319;0.31232;0.029954;-0.022117;0.39253;0;0;0;0;0;0;0;0;0;0;0;0;0
320;0.31367;0.030198;-0.022227;0.39257;0;0;0;0;0;0;0;0;0;0;0;0;0
321;0.31491;0.030342;-0.022408;0.39261;0;0;0;0;0;0;0;0;0;0;0;0;0
322;0.31613;0.030551;-0.022539;0.39265;0;0;0;0;0;0;0;0;0;0;0;0;0
323;0.31739;0.030745;-0.022681;0.39268;0;0;0;0;0;0;0;0;0;0;0;0;0
324;0.31862;0.031043;-0.022841;0.39272;0;0;0;0;0;0;0;0;0;0;0;0;0
325;0.31992;0.031202;-0.022967;0.39275;0;0;0;0;0;0;0;0;0;0;0;0;0
326;0.3212;0.031459;-0.02315;0.3928;0;0;0;0;0;0;0;0;0;0;0;0;0
327;0.32245;0.031648;-0.023262;0.39284;0;0;0;0;0;0;0;0;0;0;0;0;0
328;0.32367;0.031847;-0.023488;0.39289;0;0;0;0;0;0;0;0;0;0;0;0;0
329;0.3249;0.031868;-0.023586;0.39292;0;0;0;0;0;0;0;0;0;0;0;0;0
330;0.32619;0.032106;-0.023757;0.39294;0;0;0;0;0;0;0;0;0;0;0;0;0
331;0.32729;0.032377;-0.023899;0.39297;0;0;0;0;0;0;0;0;0;0;0;0;0
332;0.32865;0.032574;-0.024125;0.39299;0;0;0;0;0;0;0;0;0;0;0;0;0
333;0.32996;0.032804;-0.024232;0.393;0;0;0;0;0;0;0;0;0;0;0;0;0
334;0.33126;0.033038;-0.024345;0.393;0;0;0;0;0;0;0;0;0;0;0;0;0
335;0.33239;0.033246;-0.024489;0.39301;0;0;0;0;0;0;0;0;0;0;0;0;0
336;0.33365;0.033545;-0.024637;0.39302;0;0;0;0;0;0;0;0;0;0;0;0;0
337;0.33496;0.033732;-0.024754;0.39301;0;0;0;0;0;0;0;0;0;0;0;0;0
338;0.33618;0.034013;-0.024898;0.39301;0;0;0;0;0;0;0;0;0;0;0;0;0
339;0.33741;0.034286;-0.025034;0.393;0;0;0;0;0;0;0;0;0;0;0;0;0
340;0.33873;0.034574;-0.025183;0.39298;0;0;0;0;0;0;0;0;0;0;0;0;0
341;0.33994;0.034822;-0.025336;0.39298;0;0;0;0;0;0;0;0;0;0;0;0;0
342;0.34126;0.035045;-0.025484;0.39298;0;0;0;0;0;0;0;0;0;0;0;0;0
343;0.34251;0.035335;-0.025646;0.39299;0;0;0;0;0;0;0;0;0;0;0;0;0
344;0.34386;0.035545;-0.025727;0.39299;0;0;0;0;0;0;0;0;0;0;0;0;0
345;0.34497;0.035802;-0.025957;0.393;0;0;0;0;0;0;0;0;0;0;0;0;0
346;0.3463;0.036142;-0.026003;0.39301;0;0;0;0;0;0;0;0;0;0;0;0;0
347;0.34748;0.036431;-0.026112;0.393;0;0;0;0;0;0;0;0;0;0;0;0;0
348;0.3488;0.03673;-0.026246;0.39299;0;0;0;0;0;0;0;0;0;0;0;0;0
349;0.35006;0.037024;-0.026373;0.39297;0;0;0;0;0;0;0;0;0;0;0;0;0
350;0.35139;0.037287;-0.02657;0.39297;0;0;0;0;0;0;0;0;0;0;0;0;0
351;0.35257;0.037503;-0.026738;0.39298;0;0;0;0;0;0;0;0;0;0;0;0;0
352;0.35384;0.037822;-0.026946;0.39298;0;0;0;0;0;0;0;0;0;0;0;0;0
353;0.35504;0.038093;-0.027079;0.39299;0;0;0;0;0;0;0;0;0;0;0;0;0
354;0.35623;0.038473;-0.027232;0.39298;0;0;0;0;0;0;0;0;0;0;0;0;0
355;0.35778;0.038876;-0.027329;0.39297;0;0;0;0;0;0;0;0;0;0;0;0;0
356;0.3586;0.039159;-0.02752;0.39296;0;0;0;0;0;0;0;0;0;0;0;0;0
357;0.36029;0.039564;-0.027694;0.39296;0;0;0;0;0;0;0;0;0;0;0;0;0
358;0.3617;0.039814;-0.027861;0.39296;0;0;0;0;0;0;0;0;0;0;0;0;0
359;0.36191;0.040138;-0.028034;0.39296;0;0;0;0;0;0;0;0;0;0;0;0;0
360;0.36397;0.04046;-0.028163;0.39294;0;0;0;0;0;0;0;0;0;0;0;0;0
361;0.36531;0.040797;-0.028358;0.39293;0;0;0;0;0;0;0;0;0;0;0;0;0
362;0.36659;0.04109;-0.028435;0.39289;0;0;0;0;0;0;0;0;0;0;0;0;0
363;0.36786;0.041396;-0.028589;0.39287;0;0;0;0;0;0;0;0;0;0;0;0;0
364;0.36901;0.041704;-0.028744;0.39286;0;0;0;0;0;0;0;0;0;0;0;0;0
365;0.37029;0.041961;-0.028876;0.39284;0;0;0;0;0;0;0;0;0;0;0;0;0
366;0.37162;0.042356;-0.028965;0.39284;0;0;0;0;0;0;0;0;0;0;0;0;0
367;0.37284;0.042754;-0.029085;0.39285;0;0;0;0;0;0;0;0;0;0;0;0;0
368;0.37402;0.043293;-0.029203;0.39282;0;0;0;0;0;0;0;0;0;0;0;0;0
369;0.37544;0.043733;-0.029386;0.39279;0;0;0;0;0;0;0;0;0;0;0;0;0
370;0.37671;0.044171;-0.029505;0.39277;0;0;0;0;0;0;0;0;0;0;0;0;0
371;0.37801;0.044539;-0.029651;0.39272;0;0;0;0;0;0;0;0;0;0;0;0;0
372;0.37925;0.044951;-0.029824;0.3927;0;0;0;0;0;0;0;0;0;0;0;0;0
373;0.38052;0.045343;-0.030032;0.39268;0;0;0;0;0;0;0;0;0;0;0;0;0
374;0.38155;0.045724;-0.030272;0.39267;0;0;0;0;0;0;0;0;0;0;0;0;0
375;0.38317;0.046159;-0.030427;0.39265;0;0;0;0;0;0;0;0;0;0;0;0;0
376;0.38432;0.046606;-0.030671;0.39264;0;0;0;0;0;0;0;0;0;0;0;0;0
377;0.38565;0.047036;-0.030879;0.39262;0;0;0;0;0;0;0;0;0;0;0;0;0
378;0.38691;0.047497;-0.031092;0.3926;0;0;0;0;0;0;0;0;0;0;0;0;0
379;0.38833;0.047936;-0.031226;0.39259;0;0;0;0;0;0;0;0;0;0;0;0;0
380;0.3896;0.048395;-0.031424;0.39257;0;0;0;0;0;0;0;0;0;0;0;0;0
381;0.39106;0.048797;-0.031602;0.39255;0;0;0;0;0;0;0;0;0;0;0;0;0
382;0.39202;0.049288;-0.031849;0.39252;0;0;0;0;0;0;0;0;0;0;0;0;0
383;0.39331;0.049762;-0.032065;0.39251;0;0;0;0;0;0;0;0;0;0;0;0;0
384;0.39472;0.050232;-0.032294;0.39252;0;0;0;0;0;0;0;0;0;0;0;0;0
385;0.39624;0.050749;-0.032387;0.39251;0;0;0;0;0;0;0;0;0;0;0;0;0
386;0.39728;0.051229;-0.032578;0.39252;0;0;0;0;0;0;0;0;0;0;0;0;0
387;0.39857;0.051646;-0.032694;0.39251;0;0;0;0;0;0;0;0;0;0;0;0;0
388;0.39981;0.05212;-0.032929;0.39247;0;0;0;0;0;0;0;0;0;0;0;0;0
389;0.40113;0.052572;-0.033072;0.39245;0;0;0;0;0;0;0;0;0;0;0;0;0
390;0.40234;0.053053;-0.033306;0.39244;0;0;0;0;0;0;0;0;0;0;0;0;0
391;0.40372;0.053557;-0.033523;0.39241;0;0;0;0;0;0;0;0;0;0;0;0;0
392;0.40507;0.054037;-0.033741;0.39239;0;0;0;0;0;0;0;0;0;0;0;0;0
393;0.4064;0.054429;-0.033909;0.39236;0;0;0;0;0;0;0;0;0;0;0;0;0
394;0.40766;0.054862;-0.034041;0.39232;0;0;0;0;0;0;0;0;0;0;0;0;0
395;0.409;0.055257;-0.034191;0.3923;0;0;0;0;0;0;0;0;0;0;0;0;0
396;0.4103;0.055766;-0.034414;0.39227;0;0;0;0;0;0;0;0;0;0;0;0;0
397;0.41153;0.056367;-0.034538;0.39225;0;0;0;0;0;0;0;0;0;0;0;0;0
398;0.41294;0.056967;-0.034822;0.39221;0;0;0;0;0;0;0;0;0;0;0;0;0
399;0.4141;0.057609;-0.03506;0.39215;0;0;0;0;0;0;0;0;0;0;0;0;0
400;0.41525;0.05814;-0.035233;0.39211;0;0;0;0;0;0;0;0;0;0;0;0;0
401;0.41668;0.058603;-0.035455;0.39205;0;0;0;0;0;0;0;0;0;0;0;0;0
402;0.4181;0.059076;-0.035676;0.39201;0;0;0;0;0;0;0;0;0;0;0;0;0
403;0.41932;0.059576;-0.035825;0.39198;0;0;0;0;0;0;0;0;0;0;0;0;0
404;0.42067;0.060067;-0.036137;0.39194;0;0;0;0;0;0;0;0;0;0;0;0;0
405;0.42187;0.060592;-0.036345;0.39189;0;0;0;0;0;0;0;0;0;0;0;0;0
406;0.42315;0.061096;-0.036682;0.39184;0;0;0;0;0;0;0;0;0;0;0;0;0
407;0.42477;0.061619;-0.036882;0.3918;0;0;0;0;0;0;0;0;0;0;0;0;0
408;0.42552;0.062107;-0.037114;0.39174;0;0;0;0;0;0;0;0;0;0;0;0;0
409;0.42714;0.062653;-0.03727;0.3917;0;0;0;0;0;0;0;0;0;0;0;0;0
410;0.4285;0.063163;-0.037538;0.39164;0;0;0;0;0;0;0;0;0;0;0;0;0
411;0.42916;0.063717;-0.037752;0.39158;0;0;0;0;0;0;0;0;0;0;0;0;0
412;0.43117;0.064329;-0.037964;0.39152;0;0;0;0;0;0;0;0;0;0;0;0;0
413;0.43244;0.064965;-0.038141;0.39146;0;0;0;0;0;0;0;0;0;0;0;0;0
414;0.43386;0.065579;-0.038398;0.39139;0;0;0;0;0;0;0;0;0;0;0;0;0
415;0.43512;0.066306;-0.038725;0.3913;0;0;0;0;0;0;0;0;0;0;0;0;0
416;0.43662;0.066988;-0.038959;0.39123;0;0;0;0;0;0;0;0;0;0;0;0;0
417;0.4379;0.067732;-0.039278;0.39115;0;0;0;0;0;0;0;0;0;0;0;0;0
418;0.4392;0.06843;-0.039556;0.39108;0;0;0;0;0;0;0;0;0;0;0;0;0
419;0.44043;0.069223;-0.039701;0.391;0;0;0;0;0;0;0;0;0;0;0;0;0
420;0.44171;0.069825;-0.039942;0.39091;0;0;0;0;0;0;0;0;0;0;0;0;0
421;0.44321;0.070495;-0.040217;0.39078;0;0;0;0;0;0;0;0;0;0;0;0;0
422;0.44462;0.071223;-0.040477;0.39067;0;0;0;0;0;0;0;0;0;0;0;0;0
423;0.44668;0.07195;-0.040667;0.39054;0;0;0;0;0;0;0;0;0;0;0;0;0
424;0.44738;0.072589;-0.040891;0.39039;0;0;0;0;0;0;0;0;0;0;0;0;0
425;0.44854;0.073322;-0.041184;0.39026;0;0;0;0;0;0;0;0;0;0;0;0;0
426;0.44995;0.074172;-0.041425;0.3901;0;0;0;0;0;0;0;0;0;0;0;0;0
427;0.45122;0.074898;-0.041747;0.38992;0;0;0;0;0;0;0;0;0;0;0;0;0
428;0.45268;0.075646;-0.042069;0.38975;0;0;0;0;0;0;0;0;0;0;0;0;0
429;0.45408;0.076446;-0.042364;0.38955;0;0;0;0;0;0;0;0;0;0;0;0;0
430;0.45557;0.077302;-0.042672;0.38935;0;0;0;0;0;0;0;0;0;0;0;0;0
431;0.4569;0.077985;-0.042924;0.38915;0;0;0;0;0;0;0;0;0;0;0;0;0
432;0.4578;0.078792;-0.043174;0.38893;0;0;0;0;0;0;0;0;0;0;0;0;0
433;0.45977;0.079651;-0.043508;0.38872;0;0;0;0;0;0;0;0;0;0;0;0;0
434;0.46112;0.080392;-0.043758;0.38848;0;0;0;0;0;0;0;0;0;0;0;0;0
435;0.46281;0.081124;-0.04407;0.38825;0;0;0;0;0;0;0;0;0;0;0;0;0
436;0.46392;0.081929;-0.044421;0.388;0;0;0;0;0;0;0;0;0;0;0;0;0
437;0.46528;0.082763;-0.044667;0.38775;0;0;0;0;0;0;0;0;0;0;0;0;0
438;0.46681;0.083616;-0.044897;0.38747;0;0;0;0;0;0;0;0;0;0;0;0;0
439;0.46773;0.084546;-0.045024;0.38718;0;0;0;0;0;0;0;0;0;0;0;0;0
440;0.46928;0.085481;-0.04525;0.38687;0;0;0;0;0;0;0;0;0;0;0;0;0
441;0.47074;0.086398;-0.045369;0.38657;0;0;0;0;0;0;0;0;0;0;0;0;0
442;0.47214;0.087462;-0.045505;0.38625;0;0;0;0;0;0;0;0;0;0;0;0;0
443;0.47337;0.088438;-0.04564;0.38589;0;0;0;0;0;0;0;0;0;0;0;0;0
444;0.47496;0.089487;-0.045779;0.38556;0;0;0;0;0;0;0;0;0;0;0;0;0
445;0.47636;0.090515;-0.046119;0.38519;0;0;0;0;0;0;0;0;0;0;0;0;0
446;0.47778;0.091528;-0.046385;0.38481;0;0;0;0;0;0;0;0;0;0;0;0;0
447;0.4795;0.092511;-0.04656;0.38441;0;0;0;0;0;0;0;0;0;0;0;0;0
448;0.47991;0.093402;-0.04681;0.38404;0;0;0;0;0;0;0;0;0;0;0;0;0
449;0.48182;0.094431;-0.047049;0.38367;0;0;0;0;0;0;0;0;0;0;0;0;0
450;0.48338;0.095362;-0.04718;0.38327;0;0;0;0;0;0;0;0;0;0;0;0;0
451;0.4847;0.096297;-0.047282;0.38284;0;0;0;0;0;0;0;0;0;0;0;0;0
452;0.48464;0.097134;-0.047438;0.38242;0;0;0;0;0;0;0;0;0;0;0;0;0
453;0.4872;0.098123;-0.047564;0.38196;0;0;0;0;0;0;0;0;0;0;0;0;0
454;0.48855;0.099084;-0.047672;0.38147;0;0;0;0;0;0;0;0;0;0;0;0;0
455;0.48981;0.10009;-0.047989;0.38101;0;0;0;0;0;0;0;0;0;0;0;0;0
456;0.49144;0.10113;-0.04826;0.38059;0;0;0;0;0;0;0;0;0;0;0;0;0
457;0.49278;0.10212;-0.04859;0.38013;0;0;0;0;0;0;0;0;0;0;0;0;0
458;0.49406;0.10316;-0.048829;0.37964;0;0;0;0;0;0;0;0;0;0;0;0;0
459;0.4955;0.1042;-0.049078;0.37916;0;0;0;0;0;0;0;0;0;0;0;0;0
460;0.49694;0.1052;-0.049343;0.37862;0;0;0;0;0;0;0;0;0;0;0;0;0
461;0.49857;0.10624;-0.049689;0.37811;0;0;0;0;0;0;0;0;0;0;0;0;0
462;0.49956;0.10707;-0.049954;0.37756;0;0;0;0;0;0;0;0;0;0;0;0;0
463;0.50099;0.10811;-0.050235;0.37705;0;0;0;0;0;0;0;0;0;0;0;0;0
464;0.50225;0.10906;-0.050397;0.3765;0;0;0;0;0;0;0;0;0;0;0;0;0
465;0.50374;0.11018;-0.050534;0.37595;0;0;0;0;0;0;0;0;0;0;0;0;0
466;0.50503;0.11126;-0.050671;0.37537;0;0;0;0;0;0;0;0;0;0;0;0;0
467;0.50626;0.11216;-0.050754;0.37476;0;0;0;0;0;0;0;0;0;0;0;0;0
468;0.50783;0.11312;-0.05093;0.37414;0;0;0;0;0;0;0;0;0;0;0;0;0
469;0.50905;0.114;-0.051137;0.37352;0;0;0;0;0;0;0;0;0;0;0;0;0
470;0.51051;0.11503;-0.051184;0.37291;0;0;0;0;0;0;0;0;0;0;0;0;0
471;0.51188;0.11605;-0.051301;0.37225;0;0;0;0;0;0;0;0;0;0;0;0;0
472;0.51321;0.11707;-0.051533;0.37162;0;0;0;0;0;0;0;0;0;0;0;0;0
473;0.51492;0.11804;-0.051686;0.37094;0;0;0;0;0;0;0;0;0;0;0;0;0
474;0.51589;0.1189;-0.051909;0.37023;0;0;0;0;0;0;0;0;0;0;0;0;0
475;0.51733;0.1197;-0.052024;0.36952;0;0;0;0;0;0;0;0;0;0;0;0;0
476;0.51864;0.12068;-0.052243;0.36874;0;0;0;0;0;0;0;0;0;0;0;0;0
477;0.52013;0.12184;-0.052637;0.36805;0;0;0;0;0;0;0;0;0;0;0;0;0
478;0.52155;0.12295;-0.052915;0.3673;0;0;0;0;0;0;0;0;0;0;0;0;0
479;0.52279;0.1241;-0.053085;0.36655;0;0;0;0;0;0;0;0;0;0;0;0;0
480;0.52397;0.12516;-0.053356;0.36579;0;0;0;0;0;0;0;0;0;0;0;0;0
481;0.52546;0.1263;-0.053735;0.36498;0;0;0;0;0;0;0;0;0;0;0;0;0
482;0.52711;0.12769;-0.054088;0.36416;0;0;0;0;0;0;0;0;0;0;0;0;0
483;0.52865;0.12904;-0.054301;0.36331;0;0;0;0;0;0;0;0;0;0;0;0;0
484;0.52971;0.1302;-0.054478;0.36239;0;0;0;0;0;0;0;0;0;0;0;0;0
485;0.53119;0.13131;-0.054625;0.36144;0;0;0;0;0;0;0;0;0;0;0;0;0
486;0.53254;0.13219;-0.054749;0.36042;0;0;0;0;0;0;0;0;0;0;0;0;0
487;0.53402;0.13314;-0.054776;0.35944;0;0;0;0;0;0;0;0;0;0;0;0;0
488;0.53572;0.13418;-0.054734;0.35833;0;0;0;0;0;0;0;0;0;0;0;0;0
489;0.537;0.13564;-0.054776;0.35735;0;0;0;0;0;0;0;0;0;0;0;0;0
490;0.5383;0.13688;-0.054822;0.35632;0;0;0;0;0;0;0;0;0;0;0;0;0
491;0.53982;0.13789;-0.054867;0.3552;0;0;0;0;0;0;0;0;0;0;0;0;0
492;0.54125;0.13916;-0.055056;0.35412;0;0;0;0;0;0;0;0;0;0;0;0;0
493;0.54269;0.14032;-0.055183;0.35291;0;0;0;0;0;0;0;0;0;0;0;0;0
494;0.54409;0.1414;-0.055274;0.35168;0;0;0;0;0;0;0;0;0;0;0;0;0
495;0.54561;0.14271;-0.055473;0.35046;0;0;0;0;0;0;0;0;0;0;0;0;0
496;0.54712;0.14389;-0.055702;0.34914;0;0;0;0;0;0;0;0;0;0;0;0;0
497;0.54871;0.14512;-0.055982;0.34765;0;0;0;0;0;0;0;0;0;0;0;0;0
498;0.55051;0.14647;-0.056043;0.34607;0;0;0;0;0;0;0;0;0;0;0;0;0
499;0.55356;0.14882;-0.056072;0.34402;0;0;0;0;0;0;0;0;0;0;0;0;0