File: Template_Auto_Cali_large_DP600/_data/DP600Large_NT6_00_001_Front_DIC_File.txt
Date of Test;Material;Sample Geometry;Orientation [°];Test Number;Nominal Speed [mm/min];Thickness [mm];Central Width [mm];Gauge Width / Diameter [mm];Pixel to mm ratio [mm/px];Extensometer 1-4 [mm];Extensometer 2-3 [mm];Extensometer 5-6 [mm];;;;;
07/27/21;DP600Large;NT6;00;1;0.0798;0.28924;2;4;0;6;0.19999;0.4;;;;;
;;;;;;;;;;;;;;;;;
Time [s];U1 [mm];U2 [mm];U3 [mm];Force [kN];Ambient Temperature [°C];DIC Zone X 1 [px];DIC Zone Y 1 [px];DIC Zone X 2 [px];DIC Zone Y 2 [px];DIC Zone X 3 [px];DIC Zone Y 3 [px];DIC Zone X 4 [px];DIC Zone Y 4 [px];DIC Zone X 5 [px];DIC Zone Y 5 [px];DIC Zone X 6 [px];DIC Zone Y 6 [px]
0;0;0;0;-0.0017444;0;0;0;0;0;0;0;0;0;0;0;0;0
0.999;5.5858e-05;4.4785e-05;9.2623e-06;-0.001715;0;0;0;0;0;0;0;0;0;0;0;0;0
2;4.2682e-05;-4.5002e-05;2.9639e-05;-0.0016562;0;0;0;0;0;0;0;0;0;0;0;0;0
2.999;0.00018836;-7.3744e-06;5.0935e-05;-0.0014602;0;0;0;0;0;0;0;0;0;0;0;0;0
3.999;0.00039868;5.7336e-05;3.5294e-05;-0.000637;0;0;0;0;0;0;0;0;0;0;0;0;0
5;0.00049188;9.1594e-06;4.8319e-05;0.000392;0;0;0;0;0;0;0;0;0;0;0;0;0
6;0.00048007;-6.568e-05;6.8519e-05;0.001421;0;0;0;0;0;0;0;0;0;0;0;0;0
7;0.00059256;-1.4131e-05;0.00012718;0.0023324;0;0;0;0;0;0;0;0;0;0;0;0;0
7.999;0.00052035;2.6685e-05;8.3204e-05;0.0027636;0;0;0;0;0;0;0;0;0;0;0;0;0
9;0.00065578;2.6038e-05;0.000103;0.0031164;0;0;0;0;0;0;0;0;0;0;0;0;0
10;0.00095969;4.8283e-05;7.9159e-05;0.0043316;0;0;0;0;0;0;0;0;0;0;0;0;0
11;0.0010354;2.5926e-05;5.5903e-05;0.0060564;0;0;0;0;0;0;0;0;0;0;0;0;0
12;0.0011137;2.9882e-05;0.00010288;0.0079282;0;0;0;0;0;0;0;0;0;0;0;0;0
13;0.0012893;3.5903e-05;0.00011276;0.01031;0;0;0;0;0;0;0;0;0;0;0;0;0
14;0.0014942;3.7556e-05;0.0001073;0.012622;0;0;0;0;0;0;0;0;0;0;0;0;0
15;0.0016924;4.466e-05;0.00012204;0.015376;0;0;0;0;0;0;0;0;0;0;0;0;0
16;0.001828;7.3256e-05;0.00010502;0.018924;0;0;0;0;0;0;0;0;0;0;0;0;0
16.999;0.0020287;0.00010013;0.00013044;0.023148;0;0;0;0;0;0;0;0;0;0;0;0;0
18;0.0021469;0.00013611;0.00013791;0.027097;0;0;0;0;0;0;0;0;0;0;0;0;0
19;0.0022789;0.00015259;0.00010525;0.031115;0;0;0;0;0;0;0;0;0;0;0;0;0
20;0.0024845;0.00018641;8.5842e-05;0.034878;0;0;0;0;0;0;0;0;0;0;0;0;0
20.999;0.0025651;0.00016261;0.00011172;0.038416;0;0;0;0;0;0;0;0;0;0;0;0;0
22;0.0027404;0.0001748;0.00012412;0.041885;0;0;0;0;0;0;0;0;0;0;0;0;0
22.999;0.0028838;0.00012688;9.6056e-05;0.045247;0;0;0;0;0;0;0;0;0;0;0;0;0
23.999;0.0029474;0.00015362;0.00015516;0.048951;0;0;0;0;0;0;0;0;0;0;0;0;0
25;0.0031976;0.00017291;0.00015762;0.05245;0;0;0;0;0;0;0;0;0;0;0;0;0
26;0.0032843;0.00019823;0.00013439;0.056301;0;0;0;0;0;0;0;0;0;0;0;0;0
27;0.0035283;0.00023006;0.00013924;0.059878;0;0;0;0;0;0;0;0;0;0;0;0;0
27.999;0.0036508;0.00017793;0.00010703;0.063582;0;0;0;0;0;0;0;0;0;0;0;0;0
29;0.0036881;0.00022315;0.00013649;0.067395;0;0;0;0;0;0;0;0;0;0;0;0;0
29.999;0.003884;0.00021957;0.00016042;0.070893;0;0;0;0;0;0;0;0;0;0;0;0;0
31;0.004027;0.00023633;9.8632e-05;0.074676;0;0;0;0;0;0;0;0;0;0;0;0;0
31.999;0.0041932;0.00018145;0.00017299;0.078155;0;0;0;0;0;0;0;0;0;0;0;0;0
32.999;0.0043745;0.00020973;0.00016217;0.082055;0;0;0;0;0;0;0;0;0;0;0;0;0
33.999;0.0043852;0.00025482;0.00014609;0.085544;0;0;0;0;0;0;0;0;0;0;0;0;0
35;0.0045285;0.00023791;9.4627e-05;0.089131;0;0;0;0;0;0;0;0;0;0;0;0;0
35.999;0.0047544;0.00029874;0.00014388;0.092747;0;0;0;0;0;0;0;0;0;0;0;0;0
37;0.004876;0.00027769;0.00015181;0.096373;0;0;0;0;0;0;0;0;0;0;0;0;0
37.999;0.0050411;0.00023702;9.0252e-05;0.09995;0;0;0;0;0;0;0;0;0;0;0;0;0
38.999;0.0051791;0.0003297;7.9593e-05;0.10354;0;0;0;0;0;0;0;0;0;0;0;0;0
40;0.0053227;0.00027037;0.00010392;0.10711;0;0;0;0;0;0;0;0;0;0;0;0;0
40.999;0.0054506;0.00031164;5.8504e-05;0.11066;0;0;0;0;0;0;0;0;0;0;0;0;0
42;0.0056842;0.00029857;0.00016867;0.11424;0;0;0;0;0;0;0;0;0;0;0;0;0
43;0.0058926;0.00032382;0.00012487;0.11771;0;0;0;0;0;0;0;0;0;0;0;0;0
43.999;0.0060293;0.00029821;0.00011039;0.12149;0;0;0;0;0;0;0;0;0;0;0;0;0
45;0.0063057;0.00027637;0.00012724;0.12502;0;0;0;0;0;0;0;0;0;0;0;0;0
46;0.0065157;0.00025539;0.00012178;0.12899;0;0;0;0;0;0;0;0;0;0;0;0;0
46.999;0.006585;0.00030748;0.00010162;0.13251;0;0;0;0;0;0;0;0;0;0;0;0;0
48;0.0068294;0.0003634;0.00014374;0.13626;0;0;0;0;0;0;0;0;0;0;0;0;0
49;0.0069737;0.00031312;7.898e-05;0.14012;0;0;0;0;0;0;0;0;0;0;0;0;0
49.999;0.0071738;0.00030892;0.00012423;0.14427;0;0;0;0;0;0;0;0;0;0;0;0;0
50.999;0.0072699;0.00042352;0.00014601;0.14822;0;0;0;0;0;0;0;0;0;0;0;0;0
52;0.0075186;0.00034258;0.00013377;0.15245;0;0;0;0;0;0;0;0;0;0;0;0;0
52.999;0.0077145;0.00042075;0.00012617;0.15675;0;0;0;0;0;0;0;0;0;0;0;0;0
54;0.0079849;0.00042962;0.00010092;0.16109;0;0;0;0;0;0;0;0;0;0;0;0;0
55;0.0081081;0.00045971;0.00011617;0.16528;0;0;0;0;0;0;0;0;0;0;0;0;0
55.999;0.0083889;0.00042481;5.7121e-05;0.16981;0;0;0;0;0;0;0;0;0;0;0;0;0
57;0.0087189;0.00047865;6.4767e-05;0.17417;0;0;0;0;0;0;0;0;0;0;0;0;0
58;0.0089777;0.00055945;8.4259e-05;0.1786;0;0;0;0;0;0;0;0;0;0;0;0;0
58.999;0.0092424;0.0004599;0.00010631;0.18289;0;0;0;0;0;0;0;0;0;0;0;0;0
60;0.009595;0.00052516;8.4127e-05;0.18777;0;0;0;0;0;0;0;0;0;0;0;0;0
60.999;0.0099031;0.00048223;0.0001394;0.19216;0;0;0;0;0;0;0;0;0;0;0;0;0
62;0.010257;0.00054189;5.0463e-05;0.19653;0;0;0;0;0;0;0;0;0;0;0;0;0
62.999;0.010516;0.00054726;8.3353e-05;0.20126;0;0;0;0;0;0;0;0;0;0;0;0;0
64;0.010929;0.00063605;8.0367e-05;0.20578;0;0;0;0;0;0;0;0;0;0;0;0;0
65;0.011192;0.00067966;4.8769e-05;0.21024;0;0;0;0;0;0;0;0;0;0;0;0;0
66;0.011704;0.00069519;3.1263e-05;0.21449;0;0;0;0;0;0;0;0;0;0;0;0;0
66.999;0.012244;0.0007511;2.7136e-05;0.2191;0;0;0;0;0;0;0;0;0;0;0;0;0
68;0.012577;0.00075979;-3.6584e-05;0.22355;0;0;0;0;0;0;0;0;0;0;0;0;0
68.999;0.013004;0.00076602;3.3464e-05;0.22799;0;0;0;0;0;0;0;0;0;0;0;0;0
69.999;0.013462;0.0008077;-5.7422e-05;0.23236;0;0;0;0;0;0;0;0;0;0;0;0;0
70.999;0.014069;0.00081196;-3.435e-05;0.23658;0;0;0;0;0;0;0;0;0;0;0;0;0
72;0.014666;0.00097258;-7.3577e-05;0.24048;0;0;0;0;0;0;0;0;0;0;0;0;0
73;0.015184;0.0010546;-8.4601e-05;0.24457;0;0;0;0;0;0;0;0;0;0;0;0;0
73.999;0.015779;0.0010772;-0.00011504;0.24839;0;0;0;0;0;0;0;0;0;0;0;0;0
74.999;0.016438;0.0011628;-0.00016648;0.25211;0;0;0;0;0;0;0;0;0;0;0;0;0
76;0.017067;0.0012475;-0.00012508;0.25568;0;0;0;0;0;0;0;0;0;0;0;0;0
76.999;0.01787;0.0013304;-0.00022059;0.25908;0;0;0;0;0;0;0;0;0;0;0;0;0
78.008;0.018537;0.0013563;-0.00020163;0.26233;0;0;0;0;0;0;0;0;0;0;0;0;0
79;0.019395;0.0015699;-0.00026373;0.26556;0;0;0;0;0;0;0;0;0;0;0;0;0
79.999;0.020038;0.0015636;-0.00028023;0.26844;0;0;0;0;0;0;0;0;0;0;0;0;0
81;0.020929;0.001758;-0.00032336;0.27121;0;0;0;0;0;0;0;0;0;0;0;0;0
81.999;0.021663;0.0018514;-0.00034793;0.27407;0;0;0;0;0;0;0;0;0;0;0;0;0
82.999;0.022484;0.0018889;-0.00037303;0.27665;0;0;0;0;0;0;0;0;0;0;0;0;0
83.999;0.023362;0.0020321;-0.00044741;0.27915;0;0;0;0;0;0;0;0;0;0;0;0;0
84.999;0.024388;0.0021396;-0.00042906;0.28152;0;0;0;0;0;0;0;0;0;0;0;0;0
85.999;0.025302;0.0022489;-0.00049106;0.28384;0;0;0;0;0;0;0;0;0;0;0;0;0
87;0.025934;0.0023597;-0.00053583;0.28606;0;0;0;0;0;0;0;0;0;0;0;0;0
88;0.026961;0.0024419;-0.00060806;0.28818;0;0;0;0;0;0;0;0;0;0;0;0;0
88.999;0.027798;0.0025666;-0.00057663;0.29024;0;0;0;0;0;0;0;0;0;0;0;0;0
90;0.028762;0.0026373;-0.00061722;0.29223;0;0;0;0;0;0;0;0;0;0;0;0;0
90.999;0.029677;0.0027149;-0.0006989;0.29418;0;0;0;0;0;0;0;0;0;0;0;0;0
92;0.030741;0.002839;-0.00067844;0.29608;0;0;0;0;0;0;0;0;0;0;0;0;0
92.999;0.031653;0.0029162;-0.00072101;0.29794;0;0;0;0;0;0;0;0;0;0;0;0;0
94;0.032582;0.0030122;-0.00070399;0.29969;0;0;0;0;0;0;0;0;0;0;0;0;0
94.999;0.033543;0.0031174;-0.00083405;0.30162;0;0;0;0;0;0;0;0;0;0;0;0;0
95.999;0.03453;0.0032339;-0.00077909;0.30323;0;0;0;0;0;0;0;0;0;0;0;0;0
96.999;0.035532;0.0033911;-0.00089393;0.30508;0;0;0;0;0;0;0;0;0;0;0;0;0
97.999;0.036553;0.0034409;-0.00090415;0.30669;0;0;0;0;0;0;0;0;0;0;0;0;0
98.999;0.037605;0.0035365;-0.00095319;0.30832;0;0;0;0;0;0;0;0;0;0;0;0;0
99.999;0.038525;0.0036134;-0.00098534;0.30991;0;0;0;0;0;0;0;0;0;0;0;0;0
101;0.039773;0.003713;-0.0010006;0.31143;0;0;0;0;0;0;0;0;0;0;0;0;0
102;0.040668;0.0038354;-0.0010632;0.31295;0;0;0;0;0;0;0;0;0;0;0;0;0
103;0.041587;0.0039767;-0.0011046;0.31445;0;0;0;0;0;0;0;0;0;0;0;0;0
104;0.042525;0.004018;-0.0011245;0.31589;0;0;0;0;0;0;0;0;0;0;0;0;0
105;0.043692;0.0040809;-0.0011886;0.31727;0;0;0;0;0;0;0;0;0;0;0;0;0
106;0.044641;0.004182;-0.0012547;0.31872;0;0;0;0;0;0;0;0;0;0;0;0;0
107;0.045747;0.0043311;-0.0013005;0.32009;0;0;0;0;0;0;0;0;0;0;0;0;0
108;0.046789;0.0043941;-0.0013041;0.32152;0;0;0;0;0;0;0;0;0;0;0;0;0
109;0.047764;0.0044734;-0.0013419;0.32279;0;0;0;0;0;0;0;0;0;0;0;0;0
110;0.048862;0.0046148;-0.0014871;0.32403;0;0;0;0;0;0;0;0;0;0;0;0;0
111;0.050109;0.004713;-0.0015468;0.32535;0;0;0;0;0;0;0;0;0;0;0;0;0
112;0.050915;0.0048467;-0.0016006;0.32654;0;0;0;0;0;0;0;0;0;0;0;0;0
113;0.051971;0.0048962;-0.0015319;0.32779;0;0;0;0;0;0;0;0;0;0;0;0;0
114;0.052904;0.0050728;-0.0016179;0.329;0;0;0;0;0;0;0;0;0;0;0;0;0
115;0.054116;0.0051907;-0.001722;0.33018;0;0;0;0;0;0;0;0;0;0;0;0;0
116;0.055253;0.005315;-0.0017206;0.33131;0;0;0;0;0;0;0;0;0;0;0;0;0
117;0.056261;0.0054164;-0.0017813;0.33251;0;0;0;0;0;0;0;0;0;0;0;0;0
118;0.05728;0.0054399;-0.0018372;0.33368;0;0;0;0;0;0;0;0;0;0;0;0;0
119;0.05838;0.0055389;-0.0019432;0.33481;0;0;0;0;0;0;0;0;0;0;0;0;0
120;0.059546;0.0056616;-0.0019733;0.33588;0;0;0;0;0;0;0;0;0;0;0;0;0
121;0.060636;0.0058282;-0.0020543;0.33701;0;0;0;0;0;0;0;0;0;0;0;0;0
122;0.061635;0.0059224;-0.0020732;0.33803;0;0;0;0;0;0;0;0;0;0;0;0;0
123;0.062809;0.0060799;-0.0021482;0.33912;0;0;0;0;0;0;0;0;0;0;0;0;0
124;0.063836;0.0061308;-0.0022004;0.34011;0;0;0;0;0;0;0;0;0;0;0;0;0
125;0.064923;0.0062712;-0.0021894;0.34117;0;0;0;0;0;0;0;0;0;0;0;0;0
126;0.066044;0.0063934;-0.0023558;0.34218;0;0;0;0;0;0;0;0;0;0;0;0;0
127;0.067078;0.0065463;-0.0023611;0.34316;0;0;0;0;0;0;0;0;0;0;0;0;0
128;0.068266;0.0066147;-0.0023778;0.34411;0;0;0;0;0;0;0;0;0;0;0;0;0
129;0.069333;0.006725;-0.0024081;0.34504;0;0;0;0;0;0;0;0;0;0;0;0;0
130;0.070421;0.0068408;-0.0024967;0.34596;0;0;0;0;0;0;0;0;0;0;0;0;0
131;0.071499;0.0069406;-0.0025859;0.34688;0;0;0;0;0;0;0;0;0;0;0;0;0
132;0.072566;0.0070554;-0.0026334;0.3478;0;0;0;0;0;0;0;0;0;0;0;0;0
133;0.07387;0.0071516;-0.0026984;0.3487;0;0;0;0;0;0;0;0;0;0;0;0;0
134;0.074845;0.0073315;-0.002687;0.34959;0;0;0;0;0;0;0;0;0;0;0;0;0
135;0.076016;0.007465;-0.0028274;0.35041;0;0;0;0;0;0;0;0;0;0;0;0;0
136;0.077069;0.0075193;-0.0027987;0.35129;0;0;0;0;0;0;0;0;0;0;0;0;0
137;0.07811;0.007722;-0.0029361;0.3521;0;0;0;0;0;0;0;0;0;0;0;0;0
138;0.07932;0.007808;-0.002873;0.35293;0;0;0;0;0;0;0;0;0;0;0;0;0
139;0.080413;0.0079442;-0.0030226;0.35374;0;0;0;0;0;0;0;0;0;0;0;0;0
140;0.081489;0.0080379;-0.0031099;0.35454;0;0;0;0;0;0;0;0;0;0;0;0;0
141;0.082564;0.0081789;-0.0029803;0.35535;0;0;0;0;0;0;0;0;0;0;0;0;0
142;0.083801;0.0083001;-0.0030661;0.35613;0;0;0;0;0;0;0;0;0;0;0;0;0
143;0.085069;0.0084281;-0.0030878;0.35695;0;0;0;0;0;0;0;0;0;0;0;0;0
144;0.086042;0.0085327;-0.0031466;0.35768;0;0;0;0;0;0;0;0;0;0;0;0;0
145;0.087116;0.0086863;-0.0031714;0.35844;0;0;0;0;0;0;0;0;0;0;0;0;0
146;0.08825;0.0087639;-0.0032666;0.35915;0;0;0;0;0;0;0;0;0;0;0;0;0
147;0.089392;0.0088824;-0.0033077;0.35993;0;0;0;0;0;0;0;0;0;0;0;0;0
148;0.090459;0.0090152;-0.0032979;0.36061;0;0;0;0;0;0;0;0;0;0;0;0;0
149;0.091624;0.009092;-0.0033014;0.36132;0;0;0;0;0;0;0;0;0;0;0;0;0
150;0.09273;0.0092732;-0.003419;0.36202;0;0;0;0;0;0;0;0;0;0;0;0;0
151;0.093984;0.0093923;-0.0033839;0.36272;0;0;0;0;0;0;0;0;0;0;0;0;0
152;0.095072;0.0094144;-0.003397;0.36338;0;0;0;0;0;0;0;0;0;0;0;0;0
153;0.096104;0.0095454;-0.0034073;0.36412;0;0;0;0;0;0;0;0;0;0;0;0;0
154;0.097301;0.0096371;-0.0034482;0.36475;0;0;0;0;0;0;0;0;0;0;0;0;0
155;0.098524;0.0097669;-0.0035393;0.36543;0;0;0;0;0;0;0;0;0;0;0;0;0
156;0.099518;0.0098982;-0.0035192;0.36606;0;0;0;0;0;0;0;0;0;0;0;0;0
157;0.1008;0.010007;-0.003579;0.36674;0;0;0;0;0;0;0;0;0;0;0;0;0
158;0.10197;0.010095;-0.0035771;0.36736;0;0;0;0;0;0;0;0;0;0;0;0;0
159;0.1032;0.010271;-0.0036242;0.36801;0;0;0;0;0;0;0;0;0;0;0;0;0
160;0.10437;0.010347;-0.0037285;0.36861;0;0;0;0;0;0;0;0;0;0;0;0;0
161;0.10551;0.010469;-0.0037974;0.36923;0;0;0;0;0;0;0;0;0;0;0;0;0
162;0.10662;0.010572;-0.0038234;0.3698;0;0;0;0;0;0;0;0;0;0;0;0;0
163;0.10767;0.010661;-0.0038776;0.37043;0;0;0;0;0;0;0;0;0;0;0;0;0
164;0.10885;0.010801;-0.0039213;0.37097;0;0;0;0;0;0;0;0;0;0;0;0;0
165;0.11014;0.01092;-0.0038551;0.37155;0;0;0;0;0;0;0;0;0;0;0;0;0
166;0.1111;0.011009;-0.0039978;0.3721;0;0;0;0;0;0;0;0;0;0;0;0;0
167;0.11213;0.011128;-0.0039927;0.37265;0;0;0;0;0;0;0;0;0;0;0;0;0
168;0.11343;0.011186;-0.0039768;0.37322;0;0;0;0;0;0;0;0;0;0;0;0;0
169;0.11479;0.011334;-0.004086;0.37381;0;0;0;0;0;0;0;0;0;0;0;0;0
170;0.11591;0.011558;-0.0041019;0.37434;0;0;0;0;0;0;0;0;0;0;0;0;0
171;0.11705;0.011701;-0.0042026;0.37491;0;0;0;0;0;0;0;0;0;0;0;0;0
172;0.1182;0.011771;-0.0042581;0.37542;0;0;0;0;0;0;0;0;0;0;0;0;0
173;0.11929;0.011924;-0.0042945;0.37594;0;0;0;0;0;0;0;0;0;0;0;0;0
174;0.12052;0.01201;-0.0043485;0.37645;0;0;0;0;0;0;0;0;0;0;0;0;0
175;0.12175;0.012112;-0.0043893;0.37693;0;0;0;0;0;0;0;0;0;0;0;0;0
176;0.12283;0.012277;-0.0044436;0.37744;0;0;0;0;0;0;0;0;0;0;0;0;0
177;0.12403;0.012406;-0.0044296;0.37794;0;0;0;0;0;0;0;0;0;0;0;0;0
178;0.12522;0.012528;-0.00444;0.37842;0;0;0;0;0;0;0;0;0;0;0;0;0
179;0.1263;0.012709;-0.0045854;0.37891;0;0;0;0;0;0;0;0;0;0;0;0;0
180;0.12755;0.012782;-0.0045729;0.37941;0;0;0;0;0;0;0;0;0;0;0;0;0
181;0.12877;0.012953;-0.004615;0.37989;0;0;0;0;0;0;0;0;0;0;0;0;0
182;0.12994;0.013051;-0.0046096;0.38036;0;0;0;0;0;0;0;0;0;0;0;0;0
183;0.13104;0.013183;-0.0046343;0.38082;0;0;0;0;0;0;0;0;0;0;0;0;0
184;0.13226;0.013325;-0.0046153;0.38125;0;0;0;0;0;0;0;0;0;0;0;0;0
185;0.13343;0.013472;-0.0047035;0.3817;0;0;0;0;0;0;0;0;0;0;0;0;0
186;0.13472;0.013624;-0.0047395;0.38214;0;0;0;0;0;0;0;0;0;0;0;0;0
187;0.13601;0.013718;-0.0047711;0.38256;0;0;0;0;0;0;0;0;0;0;0;0;0
188;0.13712;0.013882;-0.0048495;0.383;0;0;0;0;0;0;0;0;0;0;0;0;0
189;0.13835;0.014056;-0.0048697;0.38342;0;0;0;0;0;0;0;0;0;0;0;0;0
190;0.13948;0.014142;-0.00487;0.38389;0;0;0;0;0;0;0;0;0;0;0;0;0
191;0.14067;0.01427;-0.0050267;0.3843;0;0;0;0;0;0;0;0;0;0;0;0;0
192;0.14189;0.014411;-0.00514;0.38472;0;0;0;0;0;0;0;0;0;0;0;0;0
193;0.14307;0.01458;-0.0052358;0.38513;0;0;0;0;0;0;0;0;0;0;0;0;0
194;0.14427;0.014823;-0.0052249;0.38553;0;0;0;0;0;0;0;0;0;0;0;0;0
195;0.14548;0.014857;-0.0053356;0.38593;0;0;0;0;0;0;0;0;0;0;0;0;0
196;0.14679;0.015011;-0.0054639;0.3863;0;0;0;0;0;0;0;0;0;0;0;0;0
197;0.14788;0.015151;-0.0055161;0.38672;0;0;0;0;0;0;0;0;0;0;0;0;0
198;0.14902;0.015387;-0.0056696;0.38707;0;0;0;0;0;0;0;0;0;0;0;0;0
199;0.1502;0.015521;-0.0057304;0.38743;0;0;0;0;0;0;0;0;0;0;0;0;0
200;0.15145;0.015786;-0.0057635;0.38782;0;0;0;0;0;0;0;0;0;0;0;0;0
201;0.1526;0.015915;-0.005883;0.38818;0;0;0;0;0;0;0;0;0;0;0;0;0
202;0.15385;0.016106;-0.0060173;0.38854;0;0;0;0;0;0;0;0;0;0;0;0;0
203;0.15508;0.016224;-0.0060254;0.38891;0;0;0;0;0;0;0;0;0;0;0;0;0
204;0.15627;0.016403;-0.0061154;0.38926;0;0;0;0;0;0;0;0;0;0;0;0;0
205;0.15757;0.016531;-0.0061532;0.3896;0;0;0;0;0;0;0;0;0;0;0;0;0
206;0.15868;0.016629;-0.0062076;0.38994;0;0;0;0;0;0;0;0;0;0;0;0;0
207;0.15978;0.016904;-0.0062776;0.39027;0;0;0;0;0;0;0;0;0;0;0;0;0
208;0.16119;0.017148;-0.006377;0.39058;0;0;0;0;0;0;0;0;0;0;0;0;0
209;0.16238;0.017247;-0.0064417;0.3909;0;0;0;0;0;0;0;0;0;0;0;0;0
210;0.16371;0.017398;-0.0063599;0.39121;0;0;0;0;0;0;0;0;0;0;0;0;0
211;0.16489;0.017541;-0.0064865;0.39154;0;0;0;0;0;0;0;0;0;0;0;0;0
212;0.16593;0.017732;-0.0065121;0.39184;0;0;0;0;0;0;0;0;0;0;0;0;0
213;0.1673;0.017961;-0.0065527;0.39213;0;0;0;0;0;0;0;0;0;0;0;0;0
214;0.16843;0.018129;-0.0065696;0.3924;0;0;0;0;0;0;0;0;0;0;0;0;0
215;0.16966;0.01839;-0.0066321;0.3927;0;0;0;0;0;0;0;0;0;0;0;0;0
216;0.17093;0.018525;-0.0066968;0.39298;0;0;0;0;0;0;0;0;0;0;0;0;0
217;0.17217;0.018845;-0.0067971;0.39325;0;0;0;0;0;0;0;0;0;0;0;0;0
218;0.17334;0.018888;-0.0068773;0.39351;0;0;0;0;0;0;0;0;0;0;0;0;0
219;0.17458;0.01908;-0.0068586;0.39377;0;0;0;0;0;0;0;0;0;0;0;0;0
220;0.1757;0.01925;-0.0069602;0.39403;0;0;0;0;0;0;0;0;0;0;0;0;0
221;0.17699;0.01948;-0.0070151;0.3943;0;0;0;0;0;0;0;0;0;0;0;0;0
222;0.17812;0.019608;-0.0071739;0.39458;0;0;0;0;0;0;0;0;0;0;0;0;0
223;0.17938;0.019811;-0.0071822;0.39484;0;0;0;0;0;0;0;0;0;0;0;0;0
224;0.18055;0.020022;-0.0072934;0.39508;0;0;0;0;0;0;0;0;0;0;0;0;0
225;0.18173;0.020199;-0.0073218;0.39534;0;0;0;0;0;0;0;0;0;0;0;0;0
226;0.18309;0.02035;-0.0074649;0.39557;0;0;0;0;0;0;0;0;0;0;0;0;0
227;0.18431;0.020606;-0.0075972;0.39583;0;0;0;0;0;0;0;0;0;0;0;0;0
228;0.18536;0.020814;-0.0077135;0.39608;0;0;0;0;0;0;0;0;0;0;0;0;0
229;0.18671;0.02097;-0.0078208;0.39632;0;0;0;0;0;0;0;0;0;0;0;0;0
230;0.18782;0.021232;-0.0078481;0.39655;0;0;0;0;0;0;0;0;0;0;0;0;0
231;0.18904;0.021397;-0.0080669;0.39677;0;0;0;0;0;0;0;0;0;0;0;0;0
232;0.19022;0.021705;-0.0081235;0.39699;0;0;0;0;0;0;0;0;0;0;0;0;0
233;0.19177;0.021917;-0.0082241;0.39719;0;0;0;0;0;0;0;0;0;0;0;0;0
234;0.19284;0.022098;-0.0082445;0.39742;0;0;0;0;0;0;0;0;0;0;0;0;0
235;0.19408;0.022345;-0.0083813;0.39764;0;0;0;0;0;0;0;0;0;0;0;0;0
236;0.19528;0.022529;-0.0084285;0.39785;0;0;0;0;0;0;0;0;0;0;0;0;0
237;0.19652;0.022733;-0.0085183;0.39807;0;0;0;0;0;0;0;0;0;0;0;0;0
238;0.19773;0.022934;-0.0086468;0.39826;0;0;0;0;0;0;0;0;0;0;0;0;0
239;0.19893;0.023202;-0.0086108;0.39847;0;0;0;0;0;0;0;0;0;0;0;0;0
240;0.2002;0.023328;-0.0086725;0.39865;0;0;0;0;0;0;0;0;0;0;0;0;0
241;0.20143;0.023545;-0.0087504;0.39885;0;0;0;0;0;0;0;0;0;0;0;0;0
242;0.20273;0.023823;-0.008837;0.39903;0;0;0;0;0;0;0;0;0;0;0;0;0
243;0.20397;0.024076;-0.0088713;0.3992;0;0;0;0;0;0;0;0;0;0;0;0;0
244;0.20516;0.024311;-0.0089405;0.39936;0;0;0;0;0;0;0;0;0;0;0;0;0
245;0.20639;0.024604;-0.0089663;0.39953;0;0;0;0;0;0;0;0;0;0;0;0;0
246;0.2077;0.024789;-0.0090335;0.39969;0;0;0;0;0;0;0;0;0;0;0;0;0
247;0.20896;0.025134;-0.0091579;0.39986;0;0;0;0;0;0;0;0;0;0;0;0;0
248;0.2102;0.025383;-0.0091435;0.40003;0;0;0;0;0;0;0;0;0;0;0;0;0
249;0.21164;0.025695;-0.0091766;0.40019;0;0;0;0;0;0;0;0;0;0;0;0;0
250;0.21284;0.026028;-0.0092648;0.40035;0;0;0;0;0;0;0;0;0;0;0;0;0
251;0.21405;0.026237;-0.0094388;0.4005;0;0;0;0;0;0;0;0;0;0;0;0;0
252;0.2154;0.02661;-0.0094998;0.40064;0;0;0;0;0;0;0;0;0;0;0;0;0
253;0.21642;0.026892;-0.0096092;0.40078;0;0;0;0;0;0;0;0;0;0;0;0;0
254;0.21768;0.027169;-0.0096669;0.40091;0;0;0;0;0;0;0;0;0;0;0;0;0
255;0.21907;0.027488;-0.00976;0.40106;0;0;0;0;0;0;0;0;0;0;0;0;0
256;0.22036;0.027803;-0.009856;0.40118;0;0;0;0;0;0;0;0;0;0;0;0;0
257;0.22167;0.028103;-0.0099728;0.4013;0;0;0;0;0;0;0;0;0;0;0;0;0
258;0.22294;0.02837;-0.0099175;0.40143;0;0;0;0;0;0;0;0;0;0;0;0;0
259;0.22416;0.028667;-0.010024;0.40154;0;0;0;0;0;0;0;0;0;0;0;0;0
260;0.2255;0.028956;-0.010147;0.40164;0;0;0;0;0;0;0;0;0;0;0;0;0
261;0.22677;0.029285;-0.010183;0.40172;0;0;0;0;0;0;0;0;0;0;0;0;0
262;0.22804;0.029694;-0.010263;0.40183;0;0;0;0;0;0;0;0;0;0;0;0;0
263;0.22919;0.029898;-0.010347;0.40194;0;0;0;0;0;0;0;0;0;0;0;0;0
264;0.23064;0.030333;-0.010371;0.40204;0;0;0;0;0;0;0;0;0;0;0;0;0
265;0.2318;0.030771;-0.010567;0.40216;0;0;0;0;0;0;0;0;0;0;0;0;0
266;0.23302;0.031197;-0.010514;0.40226;0;0;0;0;0;0;0;0;0;0;0;0;0
267;0.23427;0.031575;-0.010618;0.40236;0;0;0;0;0;0;0;0;0;0;0;0;0
268;0.23585;0.031959;-0.010701;0.40244;0;0;0;0;0;0;0;0;0;0;0;0;0
269;0.23699;0.032404;-0.010782;0.40251;0;0;0;0;0;0;0;0;0;0;0;0;0
270;0.23808;0.032818;-0.01097;0.40256;0;0;0;0;0;0;0;0;0;0;0;0;0
271;0.23957;0.033288;-0.011095;0.40263;0;0;0;0;0;0;0;0;0;0;0;0;0
272;0.24052;0.033705;-0.011334;0.4027;0;0;0;0;0;0;0;0;0;0;0;0;0
273;0.24202;0.034165;-0.011294;0.40276;0;0;0;0;0;0;0;0;0;0;0;0;0
274;0.24319;0.034566;-0.011444;0.40281;0;0;0;0;0;0;0;0;0;0;0;0;0
275;0.24453;0.034993;-0.011531;0.40286;0;0;0;0;0;0;0;0;0;0;0;0;0
276;0.2458;0.035436;-0.011638;0.40291;0;0;0;0;0;0;0;0;0;0;0;0;0
277;0.24711;0.035873;-0.011794;0.40297;0;0;0;0;0;0;0;0;0;0;0;0;0
278;0.24839;0.036331;-0.011828;0.403;0;0;0;0;0;0;0;0;0;0;0;0;0
279;0.2496;0.036682;-0.012017;0.40302;0;0;0;0;0;0;0;0;0;0;0;0;0
280;0.25097;0.037109;-0.01202;0.40304;0;0;0;0;0;0;0;0;0;0;0;0;0
281;0.25224;0.037517;-0.012092;0.40306;0;0;0;0;0;0;0;0;0;0;0;0;0
282;0.25352;0.037919;-0.012118;0.4031;0;0;0;0;0;0;0;0;0;0;0;0;0
283;0.25489;0.038323;-0.012244;0.40313;0;0;0;0;0;0;0;0;0;0;0;0;0
284;0.25615;0.038708;-0.012259;0.40316;0;0;0;0;0;0;0;0;0;0;0;0;0
285;0.25744;0.039099;-0.012346;0.40318;0;0;0;0;0;0;0;0;0;0;0;0;0
286;0.25876;0.039516;-0.012502;0.40319;0;0;0;0;0;0;0;0;0;0;0;0;0
287;0.26007;0.039963;-0.01264;0.40321;0;0;0;0;0;0;0;0;0;0;0;0;0
288;0.2613;0.040337;-0.012743;0.40321;0;0;0;0;0;0;0;0;0;0;0;0;0
289;0.26256;0.040659;-0.012832;0.40322;0;0;0;0;0;0;0;0;0;0;0;0;0
290;0.26382;0.041071;-0.012978;0.40322;0;0;0;0;0;0;0;0;0;0;0;0;0
291;0.26516;0.04142;-0.013182;0.40321;0;0;0;0;0;0;0;0;0;0;0;0;0
292;0.26657;0.041847;-0.013353;0.4032;0;0;0;0;0;0;0;0;0;0;0;0;0
293;0.26777;0.042123;-0.013565;0.40318;0;0;0;0;0;0;0;0;0;0;0;0;0
294;0.26904;0.042595;-0.013778;0.40315;0;0;0;0;0;0;0;0;0;0;0;0;0
295;0.27048;0.043006;-0.013915;0.40314;0;0;0;0;0;0;0;0;0;0;0;0;0
296;0.27174;0.043384;-0.014039;0.40313;0;0;0;0;0;0;0;0;0;0;0;0;0
297;0.273;0.043794;-0.01428;0.40311;0;0;0;0;0;0;0;0;0;0;0;0;0
298;0.27435;0.044237;-0.014422;0.4031;0;0;0;0;0;0;0;0;0;0;0;0;0
299;0.27558;0.044686;-0.014555;0.40308;0;0;0;0;0;0;0;0;0;0;0;0;0
300;0.27694;0.045092;-0.014742;0.40305;0;0;0;0;0;0;0;0;0;0;0;0;0
301;0.27815;0.045576;-0.014801;0.40303;0;0;0;0;0;0;0;0;0;0;0;0;0
302;0.27952;0.045982;-0.014951;0.40301;0;0;0;0;0;0;0;0;0;0;0;0;0
303;0.28071;0.046401;-0.015147;0.40299;0;0;0;0;0;0;0;0;0;0;0;0;0
304;0.28222;0.046966;-0.015291;0.40296;0;0;0;0;0;0;0;0;0;0;0;0;0
305;0.28339;0.047391;-0.015428;0.40294;0;0;0;0;0;0;0;0;0;0;0;0;0
306;0.28474;0.047903;-0.015644;0.40291;0;0;0;0;0;0;0;0;0;0;0;0;0
307;0.28608;0.048297;-0.015728;0.40289;0;0;0;0;0;0;0;0;0;0;0;0;0
308;0.28732;0.048833;-0.015907;0.40287;0;0;0;0;0;0;0;0;0;0;0;0;0
309;0.28868;0.049272;-0.0161;0.40285;0;0;0;0;0;0;0;0;0;0;0;0;0
310;0.29008;0.049892;-0.01633;0.40283;0;0;0;0;0;0;0;0;0;0;0;0;0
311;0.29128;0.050281;-0.016451;0.4028;0;0;0;0;0;0;0;0;0;0;0;0;0
312;0.29267;0.050767;-0.016577;0.40276;0;0;0;0;0;0;0;0;0;0;0;0;0
313;0.29391;0.051313;-0.01675;0.40273;0;0;0;0;0;0;0;0;0;0;0;0;0
314;0.29527;0.051802;-0.016936;0.40269;0;0;0;0;0;0;0;0;0;0;0;0;0
315;0.29645;0.052348;-0.01707;0.40267;0;0;0;0;0;0;0;0;0;0;0;0;0
316;0.29782;0.052801;-0.017275;0.40264;0;0;0;0;0;0;0;0;0;0;0;0;0
317;0.29918;0.053389;-0.017352;0.4026;0;0;0;0;0;0;0;0;0;0;0;0;0
318;0.30049;0.053917;-0.017467;0.40257;0;0;0;0;0;0;0;0;0;0;0;0;0
319;0.30184;0.054434;-0.017611;0.40254;0;0;0;0;0;0;0;0;0;0;0;0;0
320;0.30318;0.055011;-0.017783;0.40251;0;0;0;0;0;0;0;0;0;0;0;0;0
321;0.30438;0.055541;-0.017969;0.40247;0;0;0;0;0;0;0;0;0;0;0;0;0
322;0.30574;0.056139;-0.018126;0.40243;0;0;0;0;0;0;0;0;0;0;0;0;0
323;0.30719;0.056758;-0.018257;0.4024;0;0;0;0;0;0;0;0;0;0;0;0;0
324;0.30857;0.057331;-0.018405;0.40236;0;0;0;0;0;0;0;0;0;0;0;0;0
325;0.3099;0.057902;-0.018623;0.40232;0;0;0;0;0;0;0;0;0;0;0;0;0
326;0.31114;0.058496;-0.018853;0.40229;0;0;0;0;0;0;0;0;0;0;0;0;0
327;0.31255;0.059125;-0.018994;0.40225;0;0;0;0;0;0;0;0;0;0;0;0;0
328;0.31384;0.059664;-0.019196;0.40222;0;0;0;0;0;0;0;0;0;0;0;0;0
329;0.31519;0.060296;-0.019305;0.40219;0;0;0;0;0;0;0;0;0;0;0;0;0
330;0.31642;0.060964;-0.019476;0.40215;0;0;0;0;0;0;0;0;0;0;0;0;0
331;0.31778;0.061576;-0.019601;0.4021;0;0;0;0;0;0;0;0;0;0;0;0;0
332;0.31899;0.062276;-0.019745;0.40206;0;0;0;0;0;0;0;0;0;0;0;0;0
333;0.32056;0.062886;-0.019834;0.40201;0;0;0;0;0;0;0;0;0;0;0;0;0
334;0.32186;0.063575;-0.01994;0.40195;0;0;0;0;0;0;0;0;0;0;0;0;0
335;0.32309;0.064258;-0.020054;0.4019;0;0;0;0;0;0;0;0;0;0;0;0;0
336;0.32446;0.064992;-0.020235;0.40184;0;0;0;0;0;0;0;0;0;0;0;0;0
337;0.32605;0.065762;-0.020482;0.40179;0;0;0;0;0;0;0;0;0;0;0;0;0
338;0.32728;0.066495;-0.020589;0.40174;0;0;0;0;0;0;0;0;0;0;0;0;0
339;0.32859;0.06733;-0.020824;0.40168;0;0;0;0;0;0;0;0;0;0;0;0;0
340;0.32999;0.068107;-0.020982;0.40161;0;0;0;0;0;0;0;0;0;0;0;0;0
341;0.33105;0.068987;-0.021137;0.40155;0;0;0;0;0;0;0;0;0;0;0;0;0
342;0.33262;0.069866;-0.021357;0.4015;0;0;0;0;0;0;0;0;0;0;0;0;0
343;0.33414;0.070724;-0.021454;0.40143;0;0;0;0;0;0;0;0;0;0;0;0;0
344;0.3352;0.071593;-0.021666;0.40136;0;0;0;0;0;0;0;0;0;0;0;0;0
345;0.33679;0.072551;-0.021785;0.40127;0;0;0;0;0;0;0;0;0;0;0;0;0
346;0.33822;0.073546;-0.021968;0.40117;0;0;0;0;0;0;0;0;0;0;0;0;0
347;0.33949;0.074445;-0.022202;0.40109;0;0;0;0;0;0;0;0;0;0;0;0;0
348;0.34092;0.075386;-0.022418;0.40097;0;0;0;0;0;0;0;0;0;0;0;0;0
349;0.34236;0.076309;-0.022532;0.40087;0;0;0;0;0;0;0;0;0;0;0;0;0
350;0.34362;0.077349;-0.022632;0.40076;0;0;0;0;0;0;0;0;0;0;0;0;0
351;0.34498;0.078339;-0.022768;0.40062;0;0;0;0;0;0;0;0;0;0;0;0;0
352;0.34648;0.07922;-0.022775;0.40051;0;0;0;0;0;0;0;0;0;0;0;0;0
353;0.34788;0.080286;-0.022771;0.40039;0;0;0;0;0;0;0;0;0;0;0;0;0
354;0.34927;0.081305;-0.022953;0.40026;0;0;0;0;0;0;0;0;0;0;0;0;0
355;0.3506;0.082461;-0.023052;0.40009;0;0;0;0;0;0;0;0;0;0;0;0;0
356;0.35199;0.083467;-0.023107;0.39992;0;0;0;0;0;0;0;0;0;0;0;0;0
357;0.35349;0.084701;-0.02335;0.39973;0;0;0;0;0;0;0;0;0;0;0;0;0
358;0.35491;0.08575;-0.023566;0.39953;0;0;0;0;0;0;0;0;0;0;0;0;0
359;0.35638;0.086751;-0.023871;0.39929;0;0;0;0;0;0;0;0;0;0;0;0;0
360;0.35789;0.087766;-0.024071;0.39903;0;0;0;0;0;0;0;0;0;0;0;0;0
361;0.35928;0.088766;-0.024096;0.39873;0;0;0;0;0;0;0;0;0;0;0;0;0
362;0.36075;0.089692;-0.024263;0.39843;0;0;0;0;0;0;0;0;0;0;0;0;0
363;0.36238;0.090569;-0.024457;0.3981;0;0;0;0;0;0;0;0;0;0;0;0;0
364;0.36388;0.091518;-0.024512;0.39774;0;0;0;0;0;0;0;0;0;0;0;0;0
365;0.36539;0.092481;-0.024623;0.39734;0;0;0;0;0;0;0;0;0;0;0;0;0
366;0.36691;0.093501;-0.024647;0.39693;0;0;0;0;0;0;0;0;0;0;0;0;0
367;0.36844;0.094635;-0.024762;0.39649;0;0;0;0;0;0;0;0;0;0;0;0;0
368;0.36998;0.095675;-0.024772;0.39601;0;0;0;0;0;0;0;0;0;0;0;0;0
369;0.37147;0.096905;-0.024956;0.39554;0;0;0;0;0;0;0;0;0;0;0;0;0
370;0.37308;0.098208;-0.025028;0.39499;0;0;0;0;0;0;0;0;0;0;0;0;0
371;0.37451;0.099556;-0.025175;0.39445;0;0;0;0;0;0;0;0;0;0;0;0;0
372;0.37615;0.10095;-0.025301;0.39385;0;0;0;0;0;0;0;0;0;0;0;0;0
373;0.37772;0.10232;-0.025538;0.39322;0;0;0;0;0;0;0;0;0;0;0;0;0
374;0.37915;0.10362;-0.025754;0.39258;0;0;0;0;0;0;0;0;0;0;0;0;0
375;0.38046;0.1048;-0.02595;0.39188;0;0;0;0;0;0;0;0;0;0;0;0;0
376;0.38203;0.10599;-0.025872;0.39116;0;0;0;0;0;0;0;0;0;0;0;0;0
377;0.38377;0.10716;-0.026115;0.39041;0;0;0;0;0;0;0;0;0;0;0;0;0
378;0.38511;0.10832;-0.026267;0.38961;0;0;0;0;0;0;0;0;0;0;0;0;0
379;0.38668;0.10947;-0.026397;0.38885;0;0;0;0;0;0;0;0;0;0;0;0;0
380;0.38815;0.11061;-0.026677;0.38799;0;0;0;0;0;0;0;0;0;0;0;0;0
381;0.3897;0.11195;-0.026771;0.38716;0;0;0;0;0;0;0;0;0;0;0;0;0
382;0.39099;0.11322;-0.026877;0.38629;0;0;0;0;0;0;0;0;0;0;0;0;0
383;0.39259;0.11464;-0.027042;0.38538;0;0;0;0;0;0;0;0;0;0;0;0;0
384;0.39391;0.11599;-0.027393;0.38442;0;0;0;0;0;0;0;0;0;0;0;0;0
385;0.39538;0.11728;-0.027716;0.3835;0;0;0;0;0;0;0;0;0;0;0;0;0
386;0.39673;0.11858;-0.027931;0.38258;0;0;0;0;0;0;0;0;0;0;0;0;0
387;0.39845;0.11977;-0.027991;0.38154;0;0;0;0;0;0;0;0;0;0;0;0;0
388;0.40015;0.12094;-0.028104;0.38055;0;0;0;0;0;0;0;0;0;0;0;0;0
389;0.40145;0.12217;-0.028121;0.37945;0;0;0;0;0;0;0;0;0;0;0;0;0
390;0.40304;0.12341;-0.02811;0.37835;0;0;0;0;0;0;0;0;0;0;0;0;0
391;0.40446;0.12473;-0.028074;0.37721;0;0;0;0;0;0;0;0;0;0;0;0;0
392;0.40595;0.12604;-0.027997;0.37605;0;0;0;0;0;0;0;0;0;0;0;0;0
393;0.40753;0.1274;-0.027951;0.37484;0;0;0;0;0;0;0;0;0;0;0;0;0
394;0.40903;0.12868;-0.0278;0.37358;0;0;0;0;0;0;0;0;0;0;0;0;0
395;0.41051;0.13013;-0.027825;0.37228;0;0;0;0;0;0;0;0;0;0;0;0;0
396;0.41207;0.13148;-0.028098;0.37094;0;0;0;0;0;0;0;0;0;0;0;0;0
397;0.41347;0.13283;-0.028251;0.36956;0;0;0;0;0;0;0;0;0;0;0;0;0
398;0.41516;0.13422;-0.028381;0.36814;0;0;0;0;0;0;0;0;0;0;0;0;0
399;0.41665;0.13562;-0.028193;0.36667;0;0;0;0;0;0;0;0;0;0;0;0;0
400;0.41823;0.13703;-0.028052;0.36514;0;0;0;0;0;0;0;0;0;0;0;0;0
401;0.41981;0.13847;-0.027893;0.36355;0;0;0;0;0;0;0;0;0;0;0;0;0
402;0.42156;0.14002;-0.027714;0.36185;0;0;0;0;0;0;0;0;0;0;0;0;0
403;0.42355;0.14173;-0.027349;0.36;0;0;0;0;0;0;0;0;0;0;0;0;0
404;0.42506;0.1437;-0.027526;0.35793;0;0;0;0;0;0;0;0;0;0;0;0;0
404.5;0.42653;0.14531;-0.027778;0.35675;0;0;0;0;0;0;0;0;0;0;0;0;0