File: polyN_optimization/results_exp/AA7020-T6/UT_00_2.csv
Time[s],Displacement[mm],Force[kN],EngStrain_longi,EngStress[MPa],TrueStrain,TrueStress[MPa],TrueStrainRate[1/s],PlasticStrain_longi,PlasticStress[MPa],PlasticStrain_thick,PlasticStrain_width,R-Value,Thickness[mm],Width[mm], Young's Modulus [MPa]
0.61000000,0.00000000,-0.00900000,0.00000000,-0.88841507,0.00000000,-0.88841507,0.00000000,0.00093110,333.48339783,0.00056098,-0.00149208,0.67363731,1.00800000,10.05000000,81442.48493253
2.11000000,0.00279800,0.00400000,-0.00008678,0.39485114,-0.00008678,0.39481688,0.00000067,0.00325757,336.06253093,-0.00071771,-0.00253985,0.00000000,0.00000000,0.00000000,0.00000000
3.61000000,0.00856800,0.28300000,0.00006700,27.93571823,0.00006700,27.93758993,0.00014955,0.00392667,337.48859637,-0.00120909,-0.00271758,0.00000000,0.00000000,0.00000000,0.00000000
5.11000000,0.01546700,0.49900000,0.00023767,49.25767985,0.00023764,49.26938676,0.00006599,0.00463804,341.63327203,-0.00169290,-0.00294514,0.00000000,0.00000000,0.00000000,0.00000000
6.61000000,0.02405600,0.72800000,0.00047722,71.86290768,0.00047711,71.89720226,0.00014860,0.00600097,345.40912922,-0.00258470,-0.00341627,0.00000000,0.00000000,0.00000000,0.00000000
8.11000000,0.03173400,0.92900000,0.00075700,91.70417753,0.00075671,91.77359759,0.00032423,0.00740105,348.80651027,-0.00333168,-0.00406937,0.00000000,0.00000000,0.00000000,0.00000000
9.61000000,0.03932000,1.18100000,0.00098544,116.57979942,0.00098496,116.69468233,0.00034169,0.00851706,352.21303675,-0.00401686,-0.00450020,0.00000000,0.00000000,0.00000000,0.00000000
11.11000000,0.04808000,1.38200000,0.00117356,136.42106926,0.00117287,136.58116696,0.00025549,0.00958502,355.50925323,-0.00470869,-0.00487633,0.00000000,0.00000000,0.00000000,0.00000000
12.61000000,0.05679700,1.61500000,0.00141611,159.42114823,0.00141511,159.64690629,0.00009942,0.01063179,358.90550752,-0.00533440,-0.00529739,0.00000000,0.00000000,0.00000000,0.00000000
14.11000000,0.06484800,1.82900000,0.00163489,180.54568428,0.00163355,180.84085641,-0.00008586,0.01180641,362.05273973,-0.00604389,-0.00576252,0.00000000,0.00000000,0.00000000,0.00000000
15.61000000,0.07299800,2.05600000,0.00195722,202.95348654,0.00195531,203.35071161,0.00000377,0.01308696,365.44803759,-0.00686133,-0.00622563,0.00000000,0.00000000,0.00000000,0.00000000
17.11000000,0.08165300,2.26200000,0.00227144,223.28832030,0.00226887,223.79550732,0.00011818,0.01426947,368.61313917,-0.00759502,-0.00667445,0.00000000,0.00000000,0.00000000,0.00000000
18.61000000,0.09133500,2.46600000,0.00259156,243.42572850,0.00258820,244.05657980,0.00035201,0.01537485,371.65541275,-0.00826645,-0.00710840,0.00000000,0.00000000,0.00000000,0.00000000
20.11000000,0.09929100,2.67000000,0.00282589,263.56313670,0.00282190,264.30793684,0.00036655,0.01650173,374.61093316,-0.00897284,-0.00752889,0.00000000,0.00000000,0.00000000,0.00000000
21.61000000,0.10748000,2.88400000,0.00307222,284.68767275,0.00306751,285.56229654,0.00027584,0.01764659,377.78271049,-0.00970474,-0.00794185,0.00000000,0.00000000,0.00000000,0.00000000
23.11000000,0.11827900,3.06100000,0.00332067,302.15983574,0.00331517,303.16320784,0.00010920,0.01876491,380.64649833,-0.01033955,-0.00842536,0.00000000,0.00000000,0.00000000,0.00000000
24.61000000,0.13173400,3.25100000,0.00364322,320.91526495,0.00363660,322.08443057,0.00018157,0.01987175,383.71550682,-0.01101759,-0.00885417,0.00000000,0.00000000,0.00000000,0.00000000
26.11000000,0.16299900,3.35400000,0.00471189,331.08268183,0.00470082,332.64270664,0.00108297,0.02106507,386.51910035,-0.01172882,-0.00933626,0.00000000,0.00000000,0.00000000,0.00000000
27.61000000,0.20563500,3.37300000,0.00716700,332.95822475,0.00714144,335.34453635,0.00161376,0.02218766,389.30136954,-0.01239955,-0.00978810,0.00000000,0.00000000,0.00000000,0.00000000
29.11000000,0.25354700,3.38800000,0.00839100,334.43891653,0.00835599,337.24519348,0.00038106,0.02327982,392.07761940,-0.01300185,-0.01027797,0.00000000,0.00000000,0.00000000,0.00000000
30.61000000,0.29186600,3.42200000,0.00911356,337.79515123,0.00907228,340.87366611,0.00054379,0.02437657,394.96373064,-0.01367507,-0.01070150,0.00000000,0.00000000,0.00000000,0.00000000
32.11000000,0.32461100,3.44700000,0.01016578,340.26297086,0.01011445,343.72200861,0.00112378,0.02551218,397.56440017,-0.01439875,-0.01111343,0.00000000,0.00000000,0.00000000,0.00000000
33.61000000,0.36379800,3.48200000,0.01175967,343.71791834,0.01169106,347.75992649,0.00091413,0.02659663,400.35501601,-0.01503166,-0.01156496,0.00000000,0.00000000,0.00000000,0.00000000
35.11000000,0.40091500,3.50900000,0.01309822,346.38316355,0.01301318,350.92016720,0.00076458,0.02768602,402.94824405,-0.01568890,-0.01199713,0.00000000,0.00000000,0.00000000,0.00000000
36.61000000,0.43772900,3.54300000,0.01416600,349.73939825,0.01406660,354.69380656,0.00082318,0.02879726,405.45301617,-0.01634398,-0.01245328,0.00000000,0.00000000,0.00000000,0.00000000
38.11000000,0.47359400,3.56900000,0.01519600,352.30593066,0.01508170,357.65957159,0.00072533,0.02989987,407.95948952,-0.01698661,-0.01291325,0.00000000,0.00000000,0.00000000,0.00000000
39.61000000,0.50922100,3.59900000,0.01645556,355.26731422,0.01632163,361.11343525,0.00071765,0.03102722,410.68730606,-0.01766020,-0.01336702,0.00000000,0.00000000,0.00000000,0.00000000
41.11000000,0.54603700,3.62400000,0.01779778,357.73513385,0.01764125,364.10202427,0.00087922,0.03213571,413.10386351,-0.01831333,-0.01382238,0.00000000,0.00000000,0.00000000,0.00000000
42.61000000,0.58200200,3.65500000,0.01898211,360.79523020,0.01880420,367.64388535,0.00074533,0.03327248,415.74366331,-0.01904453,-0.01422795,0.00000000,0.00000000,0.00000000,0.00000000
44.11000000,0.61868300,3.67900000,0.02019656,363.16433704,0.01999531,370.49900575,0.00067101,0.03436388,418.16337679,-0.01966222,-0.01470166,0.00000000,0.00000000,0.00000000,0.00000000
45.61000000,0.65451300,3.70800000,0.02138467,366.02700782,0.02115922,373.85437337,0.00065543,0.03548419,420.49681408,-0.02036630,-0.01511788,0.00000000,0.00000000,0.00000000,0.00000000
47.11000000,0.69075200,3.73100000,0.02258389,368.29740188,0.02233265,376.61498948,0.00080162,0.03656710,422.81920229,-0.02102486,-0.01554224,0.00000000,0.00000000,0.00000000,0.00000000
48.61000000,0.72655100,3.75800000,0.02371933,370.96264708,0.02344240,379.76163376,0.00066870,0.03769597,425.37330561,-0.02169891,-0.01599706,0.00000000,0.00000000,0.00000000,0.00000000
50.11000000,0.76248000,3.78000000,0.02497867,373.13432836,0.02467180,382.45472637,0.00072622,0.03878702,427.70890977,-0.02235757,-0.01642945,0.00000000,0.00000000,0.00000000,0.00000000
51.61000000,0.79821500,3.80700000,0.02622700,375.79957356,0.02588897,385.65566898,0.00079140,0.03990904,430.06265143,-0.02299738,-0.01691166,0.00000000,0.00000000,0.00000000,0.00000000
53.11000000,0.83408300,3.82800000,0.02738500,377.87254205,0.02701674,388.22058162,0.00077623,0.04100240,432.30476552,-0.02365292,-0.01734948,0.00000000,0.00000000,0.00000000,0.00000000
54.61000000,0.86961000,3.85500000,0.02856556,380.53778725,0.02816517,391.40806056,0.00072390,0.04211561,434.56007998,-0.02428873,-0.01782688,0.00000000,0.00000000,0.00000000,0.00000000
56.11000000,0.90585000,3.87500000,0.02978744,382.51204296,0.02935242,393.90609919,0.00086207,0.04323633,436.71901564,-0.02498538,-0.01825095,0.00000000,0.00000000,0.00000000,0.00000000
57.61000000,0.94148100,3.89800000,0.03096056,384.78243702,0.03049095,396.69551504,0.00080998,0.04433490,439.08143805,-0.02563126,-0.01870364,0.00000000,0.00000000,0.00000000,0.00000000
59.11000000,0.97680800,3.91800000,0.03212611,386.75669273,0.03162086,399.18168121,0.00081639,0.04542220,441.13003995,-0.02626551,-0.01915668,0.00000000,0.00000000,0.00000000,0.00000000
60.61000000,1.01247300,3.94200000,0.03331422,389.12579957,0.03277133,402.08922293,0.00079394,0.04653022,443.40126140,-0.02692062,-0.01960960,0.00000000,0.00000000,0.00000000,0.00000000
62.11000000,1.04756200,3.96100000,0.03449089,391.00134249,0.03390941,404.48732635,0.00077820,0.04763119,445.56916344,-0.02758485,-0.02004635,0.00000000,0.00000000,0.00000000,0.00000000
63.61000000,1.08383400,3.98500000,0.03566011,393.37044934,0.03503901,407.39808327,0.00074062,0.04874291,447.64136194,-0.02827264,-0.02047027,0.00000000,0.00000000,0.00000000,0.00000000
65.11000000,1.11946500,4.00300000,0.03685200,395.14727948,0.03618920,409.70924702,0.00068188,0.04984273,449.71235134,-0.02892470,-0.02091803,0.00000000,0.00000000,0.00000000,0.00000000
66.61000000,1.15519700,4.02500000,0.03806644,397.31896075,0.03735979,412.44348090,0.00076075,0.05092340,451.77876273,-0.02957387,-0.02134953,0.00000000,0.00000000,0.00000000,0.00000000
68.11000000,1.19140400,4.04200000,0.03926578,398.99707810,0.03851448,414.66400870,0.00078147,0.05203467,453.86320718,-0.03023135,-0.02180333,0.00000000,0.00000000,0.00000000,0.00000000
69.61000000,1.22622400,4.06400000,0.04041644,401.16875938,0.03962106,417.38257425,0.00074450,0.05313399,455.94635612,-0.03086275,-0.02227123,0.00000000,0.00000000,0.00000000,0.00000000
71.11000000,1.26276900,4.08100000,0.04160456,402.84687673,0.04076237,419.60714199,0.00068581,0.05426147,457.94111720,-0.03154167,-0.02271980,0.00000000,0.00000000,0.00000000,0.00000000
72.61000000,1.29843300,4.10200000,0.04277011,404.91984522,0.04188074,422.23831199,0.00066351,0.05539283,459.83605846,-0.03224493,-0.02314790,0.00000000,0.00000000,0.00000000,0.00000000
74.11000000,1.33389600,4.11900000,0.04393567,406.59796257,0.04299787,424.46211512,0.00067001,0.05646830,461.81458758,-0.03286578,-0.02360252,0.00000000,0.00000000,0.00000000,0.00000000
75.61000000,1.37010300,4.13800000,0.04515011,408.47350549,0.04416052,426.91612965,0.00072666,0.05758840,463.81777637,-0.03353798,-0.02405042,0.00000000,0.00000000,0.00000000,0.00000000
77.11000000,1.40563300,4.15400000,0.04632700,410.05291005,0.04528594,429.04943122,0.00076175,0.05871891,465.72384957,-0.03423984,-0.02447906,0.00000000,0.00000000,0.00000000,0.00000000
78.61000000,1.44194200,4.17400000,0.04752644,412.02716576,0.04643162,431.60935196,0.00073223,0.05983409,467.62652248,-0.03490414,-0.02492994,0.00000000,0.00000000,0.00000000,0.00000000
80.11000000,1.47764000,4.19000000,0.04872956,413.60657032,0.04757948,433.76143467,0.00076700,0.06093729,469.52729817,-0.03556013,-0.02537716,0.00000000,0.00000000,0.00000000,0.00000000
81.61000000,1.51350800,4.20800000,0.04993289,415.38340046,0.04872625,436.12469364,0.00080953,0.06205681,471.43953601,-0.03621229,-0.02584452,0.00000000,0.00000000,0.00000000,0.00000000
83.11000000,1.54984700,4.22400000,0.05113589,416.96280502,0.04987138,438.28456869,0.00084413,0.06316941,473.24575956,-0.03684418,-0.02632523,0.00000000,0.00000000,0.00000000,0.00000000
84.61000000,1.58571400,4.24100000,0.05233533,418.64092237,0.05101182,440.55063459,0.00083599,0.06429466,475.06155782,-0.03754329,-0.02675137,0.00000000,0.00000000,0.00000000,0.00000000
86.11000000,1.62219100,4.25500000,0.05353478,420.02290137,0.05215097,442.50873405,0.00079241,0.06539893,476.76410348,-0.03814653,-0.02725239,0.00000000,0.00000000,0.00000000,0.00000000
87.61000000,1.65782200,4.27300000,0.05471533,421.79973150,0.05327090,444.87864441,0.00078415,0.06651657,478.69010288,-0.03886875,-0.02764782,0.00000000,0.00000000,0.00000000,0.00000000
89.11000000,1.69419800,4.28700000,0.05592244,423.18171050,0.05441474,446.84706619,0.00079062,0.06763419,480.51290023,-0.03953484,-0.02809935,0.00000000,0.00000000,0.00000000,0.00000000
90.61000000,1.73064100,4.30400000,0.05713311,424.85982784,0.05556063,449.13339160,0.00076111,0.06876235,482.23724976,-0.04026744,-0.02849491,0.00000000,0.00000000,0.00000000,0.00000000
92.11000000,1.76647400,4.31800000,0.05832489,426.24180684,0.05668736,451.10231286,0.00077433,0.06989263,483.96598765,-0.04094964,-0.02894299,0.00000000,0.00000000,0.00000000,0.00000000
93.61000000,1.80281600,4.33300000,0.05953956,427.72249862,0.05783443,453.18890609,0.00078813,0.07100081,485.68729097,-0.04161100,-0.02938981,0.00000000,0.00000000,0.00000000,0.00000000
95.11000000,1.83865000,4.34700000,0.06070133,429.10447761,0.05893032,455.15169154,0.00071622,0.07210410,487.40949604,-0.04222563,-0.02987847,0.00000000,0.00000000,0.00000000,0.00000000
96.61000000,1.87560200,4.36200000,0.06194578,430.58516939,0.06010286,457.25810261,0.00077169,0.07322698,489.14463315,-0.04289811,-0.03032888,0.00000000,0.00000000,0.00000000,0.00000000
98.11000000,1.91167400,4.37500000,0.06314533,431.86843560,0.06123181,459.13891192,0.00076392,0.07436706,490.78387422,-0.04358832,-0.03077874,0.00000000,0.00000000,0.00000000,0.00000000
99.61000000,1.94818300,4.39100000,0.06434478,433.44784016,0.06235938,461.33794512,0.00069935,0.07547129,492.40851694,-0.04423783,-0.03123346,0.00000000,0.00000000,0.00000000,0.00000000
101.11000000,1.98466000,4.40300000,0.06552911,434.63239359,0.06347149,463.11346800,0.00068460,0.07658323,494.14805786,-0.04490278,-0.03168046,0.00000000,0.00000000,0.00000000,0.00000000
102.61000000,2.02113700,4.41800000,0.06675867,436.11308537,0.06462477,465.22741346,0.00071236,0.07774818,495.70112977,-0.04562953,-0.03211864,0.00000000,0.00000000,0.00000000,0.00000000
104.11000000,2.05818900,4.42900000,0.06797311,437.19892600,0.06576256,466.91669718,0.00069739,0.07886566,497.34171131,-0.04627033,-0.03259532,0.00000000,0.00000000,0.00000000,0.00000000
105.61000000,2.09456400,4.44400000,0.06918000,438.67961778,0.06689200,469.02747374,0.00068226,0.07995928,498.86504085,-0.04692869,-0.03303059,0.00000000,0.00000000,0.00000000,0.00000000
107.11000000,2.13141200,4.45500000,0.07039822,439.76545842,0.06803075,470.72416489,0.00073091,0.08110142,500.52412580,-0.04763764,-0.03346378,0.00000000,0.00000000,0.00000000,0.00000000
108.61000000,2.16880300,4.46900000,0.07163144,441.14743742,0.06918220,472.74746557,0.00077903,0.08221294,502.06230100,-0.04827406,-0.03393889,0.00000000,0.00000000,0.00000000,0.00000000
110.11000000,2.20605800,4.48000000,0.07284222,442.23327805,0.07031141,474.44653277,0.00075701,0.08333344,503.60788972,-0.04897537,-0.03435807,0.00000000,0.00000000,0.00000000,0.00000000
111.61000000,2.24284200,4.49200000,0.07407167,443.41783148,0.07145672,476.26252928,0.00072820,0.08444369,505.04227353,-0.04962418,-0.03481951,0.00000000,0.00000000,0.00000000,0.00000000
113.11000000,2.27996000,4.50400000,0.07528989,444.60238490,0.07259029,478.07644906,0.00072738,0.08560239,506.61300080,-0.05033401,-0.03526839,0.00000000,0.00000000,0.00000000,0.00000000
114.61000000,2.31718100,4.51600000,0.07651933,445.78693832,0.07373300,479.89825765,0.00070569,0.08671545,508.16340221,-0.05101798,-0.03569748,0.00000000,0.00000000,0.00000000,0.00000000
116.11000000,2.35450500,4.52700000,0.07774889,446.87277896,0.07487450,481.61664100,0.00072592,0.08784748,509.72642144,-0.05167795,-0.03616953,0.00000000,0.00000000,0.00000000,0.00000000
117.61000000,2.39223100,4.53900000,0.07898967,448.05733239,0.07602511,483.44923172,0.00078772,0.08898449,511.07615257,-0.05236698,-0.03661750,0.00000000,0.00000000,0.00000000,0.00000000
119.11000000,2.42887800,4.54900000,0.08019656,449.04446024,0.07714302,485.05627924,0.00074506,0.09011887,512.53651583,-0.05304116,-0.03707771,0.00000000,0.00000000,0.00000000,0.00000000
120.61000000,2.46691500,4.56100000,0.08146367,450.22901366,0.07831537,486.90631995,0.00073042,0.09125022,514.10768103,-0.05370560,-0.03754462,0.00000000,0.00000000,0.00000000,0.00000000
122.11000000,2.50416700,4.57100000,0.08271933,451.21614151,0.07947578,488.54043993,0.00081930,0.09237637,515.45953092,-0.05436708,-0.03800929,0.00000000,0.00000000,0.00000000,0.00000000
123.61000000,2.54220100,4.58300000,0.08391500,452.40069494,0.08057949,490.36389925,0.00079091,0.09349111,516.80788123,-0.05503392,-0.03845719,0.00000000,0.00000000,0.00000000,0.00000000
125.11000000,2.57922000,4.59100000,0.08518978,453.19039722,0.08175488,491.79758645,0.00077646,0.09464682,518.29006920,-0.05569855,-0.03894827,0.00000000,0.00000000,0.00000000,0.00000000
126.61000000,2.61657500,4.60100000,0.08643044,454.17752507,0.08289750,493.43229042,0.00083082,0.09579784,519.77259201,-0.05637306,-0.03942478,0.00000000,0.00000000,0.00000000,0.00000000
128.11000000,2.65467700,4.61200000,0.08767511,455.26336571,0.08404249,495.17863188,0.00082313,0.09696575,521.15645213,-0.05708630,-0.03987944,0.00000000,0.00000000,0.00000000,0.00000000
129.61000000,2.69281200,4.62100000,0.08890456,456.15178078,0.08517220,496.70575211,0.00081505,0.09810203,522.52624285,-0.05773752,-0.04036451,0.00000000,0.00000000,0.00000000,0.00000000
131.11000000,2.73037200,4.63100000,0.09017922,457.13890863,0.08634211,498.36333986,0.00076597,0.09922505,523.78095524,-0.05840979,-0.04081526,0.00000000,0.00000000,0.00000000,0.00000000
132.61000000,2.76816900,4.64000000,0.09144622,458.02732370,0.08750363,499.91219213,0.00085450,0.10037519,525.16290446,-0.05911180,-0.04126339,0.00000000,0.00000000,0.00000000,0.00000000
134.11000000,2.80667500,4.65000000,0.09269456,459.01445155,0.08864672,501.56259213,0.00084661,0.10153433,526.55216181,-0.05980523,-0.04172910,0.00000000,0.00000000,0.00000000,0.00000000
135.61000000,2.84423400,4.65800000,0.09394278,459.80415383,0.08978840,502.99943328,0.00079748,0.10269858,527.94670168,-0.06051635,-0.04218223,0.00000000,0.00000000,0.00000000,0.00000000
137.11000000,2.88236900,4.66800000,0.09519856,460.79128169,0.09093568,504.65794612,0.00077606,0.10381275,529.20602907,-0.06114502,-0.04266774,0.00000000,0.00000000,0.00000000,0.00000000
138.61000000,2.92067100,4.67600000,0.09645811,461.58098397,0.09208509,506.10421381,0.00080254,0.10498382,530.38672175,-0.06183990,-0.04314392,0.00000000,0.00000000,0.00000000,0.00000000
140.11000000,2.95918000,4.68500000,0.09768756,462.46939904,0.09320574,507.64690415,0.00073987,0.10611058,531.76847651,-0.06248863,-0.04362195,0.00000000,0.00000000,0.00000000,0.00000000
141.61000000,2.99731500,4.69300000,0.09896589,463.25910132,0.09436964,509.10595007,0.00078696,0.10725907,532.94141396,-0.06317871,-0.04408036,0.00000000,0.00000000,0.00000000,0.00000000
143.11000000,3.03602200,4.70200000,0.10022167,464.14751639,0.09551167,510.66515406,0.00076565,0.10846284,534.36936723,-0.06390021,-0.04456263,0.00000000,0.00000000,0.00000000,0.00000000
144.61000000,3.07402300,4.70900000,0.10148144,464.83850588,0.09665604,512.01098889,0.00073087,0.10958191,535.53082399,-0.06459580,-0.04498611,0.00000000,0.00000000,0.00000000,0.00000000
146.11000000,3.11239600,4.71800000,0.10271833,465.72692095,0.09777834,513.56561406,0.00062764,0.11073456,536.82427594,-0.06524829,-0.04548627,0.00000000,0.00000000,0.00000000,0.00000000
147.61000000,3.15113800,4.72500000,0.10401911,466.41791045,0.09895726,514.93428690,0.00072214,0.11198669,538.06194155,-0.06605190,-0.04593479,0.00000000,0.00000000,0.00000000,0.00000000
149.11000000,3.18954500,4.73300000,0.10530122,467.20761273,0.10011790,516.40514538,0.00080316,0.11312152,539.23817831,-0.06672189,-0.04639963,0.00000000,0.00000000,0.00000000,0.00000000
150.61000000,3.22855800,4.74000000,0.10654200,467.89860223,0.10123984,517.74945511,0.00067308,0.11426015,540.53078401,-0.06735554,-0.04690460,0.00000000,0.00000000,0.00000000,0.00000000
152.11000000,3.26730200,4.74800000,0.10783511,468.68830451,0.10240776,519.22935990,0.00073972,0.11542668,541.61605080,-0.06805126,-0.04737541,0.00000000,0.00000000,0.00000000,0.00000000
153.61000000,3.30733100,4.75600000,0.10912478,469.47800679,0.10357122,520.70968995,0.00077975,0.11659209,542.92765582,-0.06872729,-0.04786480,0.00000000,0.00000000,0.00000000,0.00000000
155.11000000,3.34556900,4.76200000,0.11041811,470.07028350,0.10473662,521.97455630,0.00077203,0.11772621,543.99908089,-0.06935233,-0.04837388,0.00000000,0.00000000,0.00000000,0.00000000
156.61000000,3.38509000,4.76800000,0.11174156,470.66256021,0.10592775,523.25512683,0.00081850,0.11887722,545.19436530,-0.07004935,-0.04882787,0.00000000,0.00000000,0.00000000,0.00000000
158.11000000,3.42430800,4.77600000,0.11303111,471.45226250,0.10708702,524.74103556,0.00088507,0.12009249,546.42708662,-0.07079056,-0.04930193,0.00000000,0.00000000,0.00000000,0.00000000
159.61000000,3.46339000,4.78300000,0.11432444,472.14325199,0.10824834,526.12076698,0.00086389,0.12123275,547.73375330,-0.07145578,-0.04977698,0.00000000,0.00000000,0.00000000,0.00000000
161.11000000,3.50267700,4.78900000,0.11565167,472.73552871,0.10943869,527.40818049,0.00081583,0.12240556,548.72102315,-0.07218258,-0.05022298,0.00000000,0.00000000,0.00000000,0.00000000
162.61000000,3.54287700,4.79500000,0.11693756,473.32780542,0.11059061,528.67760196,0.00082843,0.12361781,549.84509490,-0.07291508,-0.05070273,0.00000000,0.00000000,0.00000000,0.00000000
164.11000000,3.58226400,4.80200000,0.11823478,474.01879491,0.11175135,530.06430179,0.00075331,0.12476845,551.05043504,-0.07361175,-0.05115671,0.00000000,0.00000000,0.00000000,0.00000000
165.61000000,3.62178900,4.80800000,0.11954700,474.61107163,0.11292414,531.34940141,0.00073257,0.12595363,552.27706547,-0.07431537,-0.05163825,0.00000000,0.00000000,0.00000000,0.00000000
167.11000000,3.66181800,4.81300000,0.12087400,475.10463555,0.11410874,532.53243327,0.00076483,0.12714675,553.28272270,-0.07503544,-0.05211131,0.00000000,0.00000000,0.00000000,0.00000000
168.61000000,3.70147500,4.81900000,0.12216733,475.69691226,0.11526193,533.81153551,0.00074394,0.12835970,554.41501627,-0.07573900,-0.05262070,0.00000000,0.00000000,0.00000000,0.00000000
170.11000000,3.74154000,4.82600000,0.12345711,476.38790176,0.11641064,535.20137588,0.00068313,0.12954679,555.42073001,-0.07646700,-0.05307979,0.00000000,0.00000000,0.00000000,0.00000000
171.61000000,3.78136700,4.83100000,0.12485944,476.88146569,0.11765809,536.42462056,0.00079571,0.13074867,556.66478237,-0.07724286,-0.05350582,0.00000000,0.00000000,0.00000000,0.00000000
173.11000000,3.82241100,4.83700000,0.12617900,477.47374240,0.11883049,537.72090174,0.00082795,0.13191318,557.66135572,-0.07790856,-0.05400461,0.00000000,0.00000000,0.00000000,0.00000000
174.61000000,3.86251200,4.84100000,0.12749511,477.86859354,0.11999846,538.79450297,0.00083408,0.13313156,558.68984834,-0.07866013,-0.05447143,0.00000000,0.00000000,0.00000000,0.00000000
176.11000000,3.90291400,4.84700000,0.12881478,478.46087025,0.12116821,540.09370093,0.00065310,0.13430622,559.69538287,-0.07932460,-0.05498162,0.00000000,0.00000000,0.00000000,0.00000000
177.61000000,3.94291100,4.85200000,0.13018711,478.95443418,0.12238320,541.30812832,0.00084527,0.13551987,560.83933130,-0.08003472,-0.05548516,0.00000000,0.00000000,0.00000000,0.00000000
179.11000000,3.98378700,4.85600000,0.13149189,479.34928532,0.12353702,542.37982828,0.00090422,0.13668695,561.95888705,-0.08070473,-0.05598222,0.00000000,0.00000000,0.00000000,0.00000000
180.61000000,4.02429000,4.86200000,0.13281533,479.94156203,0.12470598,543.68516057,0.00074381,0.13789117,562.87129849,-0.08138251,-0.05650866,0.00000000,0.00000000,0.00000000,0.00000000
182.11000000,4.06449100,4.86600000,0.13420267,480.33641317,0.12592991,544.79884072,0.00083581,0.13917596,563.94608137,-0.08218628,-0.05698968,0.00000000,0.00000000,0.00000000,0.00000000
183.61000000,4.10567100,4.87200000,0.13550744,480.92868988,0.12707964,546.09810761,0.00086794,0.14036281,564.96696675,-0.08287986,-0.05748295,0.00000000,0.00000000,0.00000000,0.00000000
185.11000000,4.14688400,4.87600000,0.13684589,481.32354103,0.12825766,547.19068884,0.00076092,0.14158013,566.00687778,-0.08362474,-0.05795539,0.00000000,0.00000000,0.00000000,0.00000000
186.61000000,4.18826900,4.88100000,0.13819556,481.81710495,0.12944416,548.40208745,0.00071354,0.14279583,567.04758077,-0.08434794,-0.05844788,0.00000000,0.00000000,0.00000000,0.00000000
188.11000000,4.22877100,4.88400000,0.13957156,482.11324331,0.13065236,549.40253863,0.00083109,0.14401029,568.08929257,-0.08508231,-0.05892798,0.00000000,0.00000000,0.00000000,0.00000000
189.61000000,4.27012000,4.88800000,0.14086889,482.50809445,0.13179016,550.47847359,0.00074499,0.14522478,569.01682806,-0.08581163,-0.05941315,0.00000000,0.00000000,0.00000000,0.00000000
191.11000000,4.31174000,4.89300000,0.14224478,483.00165837,0.13299543,551.70612194,0.00070439,0.14646787,570.07827924,-0.08651735,-0.05995052,0.00000000,0.00000000,0.00000000,0.00000000
192.61000000,4.35308900,4.89700000,0.14362078,483.39650952,0.13419935,552.82229219,0.00077566,0.14767931,571.00709153,-0.08730878,-0.06037053,0.00000000,0.00000000,0.00000000,0.00000000
194.11000000,4.39450700,4.90100000,0.14498567,483.79136066,0.13539212,553.93417361,0.00075493,0.14895287,571.97314475,-0.08808714,-0.06086572,0.00000000,0.00000000,0.00000000,0.00000000
195.61000000,4.43656600,4.90600000,0.14639189,484.28492458,0.13661952,555.18030945,0.00076118,0.15016103,572.90299152,-0.08876668,-0.06139435,0.00000000,0.00000000,0.00000000,0.00000000
197.11000000,4.47856000,4.90900000,0.14778667,484.58106294,0.13783545,556.19568296,0.00080577,0.15139801,573.96757976,-0.08955278,-0.06184523,0.00000000,0.00000000,0.00000000,0.00000000
198.61000000,4.52136400,4.91200000,0.14918167,484.87720130,0.13905009,557.21199031,0.00090965,0.15260158,575.01458685,-0.09019602,-0.06240556,0.00000000,0.00000000,0.00000000,0.00000000
200.11000000,4.56257900,4.91500000,0.15059167,485.17333965,0.14027630,558.23640149,0.00086332,0.15387029,575.86724303,-0.09101845,-0.06285184,0.00000000,0.00000000,0.00000000,0.00000000
201.61000000,4.60517900,4.91900000,0.15201656,485.56819079,0.14151393,559.38259464,0.00094041,0.15507238,576.79950956,-0.09168243,-0.06338995,0.00000000,0.00000000,0.00000000,0.00000000
203.11000000,4.64761300,4.92300000,0.15338889,485.96304193,0.14270447,560.50437298,0.00091943,0.15636812,577.78774483,-0.09249307,-0.06387506,0.00000000,0.00000000,0.00000000,0.00000000
204.61000000,4.69035000,4.92600000,0.15479522,486.25918029,0.14392303,561.52977816,0.00085998,0.15763039,578.75805868,-0.09320244,-0.06442795,0.00000000,0.00000000,0.00000000,0.00000000
206.11000000,4.73285000,4.93000000,0.15622011,486.65403143,0.14515616,562.67917829,0.00080047,0.15889269,579.61239865,-0.09400413,-0.06488856,0.00000000,0.00000000,0.00000000,0.00000000
207.61000000,4.77579200,4.93200000,0.15759244,486.85145700,0.14634237,563.57556819,0.00077955,0.16015336,580.46703556,-0.09476248,-0.06539088,0.00000000,0.00000000,0.00000000,0.00000000
209.11000000,4.81897000,4.93500000,0.15902122,487.14759536,0.14757587,564.61440137,0.00077878,0.16140916,581.55575311,-0.09548037,-0.06592880,0.00000000,0.00000000,0.00000000,0.00000000
210.61000000,4.86214500,4.93800000,0.16044989,487.44373371,0.14880777,565.65402663,0.00071288,0.16269643,582.54679548,-0.09624808,-0.06644835,0.00000000,0.00000000,0.00000000,0.00000000
212.11000000,4.90474800,4.94100000,0.16187856,487.73987207,0.15003814,566.69449805,0.00077667,0.16395203,583.40266307,-0.09698746,-0.06696457,0.00000000,0.00000000,0.00000000,0.00000000
213.61000000,4.94880400,4.94400000,0.16326967,488.03601042,0.15123472,567.71748717,0.00071077,0.16523921,584.16007394,-0.09778386,-0.06745536,0.00000000,0.00000000,0.00000000,0.00000000
215.11000000,4.99225100,4.94600000,0.16473600,488.23343599,0.15249445,568.66305931,0.00071025,0.16655275,585.17093662,-0.09861263,-0.06794012,0.00000000,0.00000000,0.00000000,0.00000000
216.61000000,5.03502400,4.94900000,0.16616478,488.52957435,0.15372040,569.70598251,0.00077401,0.16783466,586.04616797,-0.09938967,-0.06844499,0.00000000,0.00000000,0.00000000,0.00000000
218.11000000,5.08009500,4.95200000,0.16763111,488.82571271,0.15497700,570.76811007,0.00083720,0.16917779,586.95890804,-0.10021637,-0.06896142,0.00000000,0.00000000,0.00000000,0.00000000
219.61000000,5.12394700,4.95400000,0.16909733,489.02313828,0.15623194,571.71564690,0.00077206,0.17048754,587.85327944,-0.10098534,-0.06950220,0.00000000,0.00000000,0.00000000,0.00000000
221.11000000,5.16804200,4.95600000,0.17056389,489.22056385,0.15748559,572.66392574,0.00083567,0.17173328,588.71101648,-0.10173920,-0.06999408,0.00000000,0.00000000,0.00000000,0.00000000
222.61000000,5.21233500,4.95800000,0.17199267,489.41798942,0.15870543,573.59429453,0.00077035,0.17306938,589.74294818,-0.10252651,-0.07054287,0.00000000,0.00000000,0.00000000,0.00000000
224.11000000,5.25652800,4.96100000,0.17349667,489.71412777,0.15998790,574.67789656,0.00083377,0.17437554,590.51994761,-0.10330681,-0.07106873,0.00000000,0.00000000,0.00000000,0.00000000
225.61000000,5.30112800,4.96200000,0.17500044,489.81284056,0.16126853,575.53030535,0.00096042,0.17564735,591.39707810,-0.10406223,-0.07158513,0.00000000,0.00000000,0.00000000,0.00000000
227.11000000,5.34613100,4.96500000,0.17639144,490.10897891,0.16245166,576.56000964,0.00076690,0.17695009,592.17423340,-0.10480994,-0.07214015,0.00000000,0.00000000,0.00000000,0.00000000
228.61000000,5.39134000,4.96700000,0.17789544,490.30640449,0.16372932,577.52968023,0.00076630,0.17837355,593.14448224,-0.10572880,-0.07264475,0.00000000,0.00000000,0.00000000,0.00000000
230.11000000,5.43678100,4.96900000,0.17943678,490.50383006,0.16503702,578.51825681,0.00082882,0.17976379,594.09641686,-0.10660644,-0.07315736,0.00000000,0.00000000,0.00000000,0.00000000
231.61000000,5.48188800,4.96900000,0.18094078,490.50383006,0.16631139,579.25597457,0.00082776,0.18106108,594.87388389,-0.10738104,-0.07368005,0.00000000,0.00000000,0.00000000,0.00000000
233.11000000,5.52757000,4.97100000,0.18240711,490.70125563,0.16755229,580.20865408,0.00082673,0.18241844,595.68844350,-0.10821053,-0.07420791,0.00000000,0.00000000,0.00000000,0.00000000
234.61000000,5.57325200,4.97400000,0.18394867,490.99739398,0.16885518,581.31570994,0.00088950,0.18374317,596.48451153,-0.10899793,-0.07474524,0.00000000,0.00000000,0.00000000,0.00000000
236.11000000,5.61940700,4.97500000,0.18545267,491.09610677,0.17012470,582.17118936,0.00082480,0.00000000,0.00000000,0.00000000,0.00000000,0.00000000,0.00000000,0.00000000,0.00000000
237.61000000,5.66634000,4.97700000,0.18703178,491.29353234,0.17145589,583.18103510,0.00088719,0.00000000,0.00000000,0.00000000,0.00000000,0.00000000,0.00000000,0.00000000,0.00000000
239.11000000,5.71280000,4.97700000,0.18857333,491.29353234,0.17275371,583.93839138,0.00088604,0.00000000,0.00000000,0.00000000,0.00000000,0.00000000,0.00000000,0.00000000,0.00000000
240.61000000,5.75946200,4.97800000,0.19003978,491.39224512,0.17398673,584.77631819,0.00075885,0.00000000,0.00000000,0.00000000,0.00000000,0.00000000,0.00000000,0.00000000,0.00000000
242.11000000,5.80676800,4.98000000,0.19158133,491.58967069,0.17528128,585.76907526,0.00069444,0.00000000,0.00000000,0.00000000,0.00000000,0.00000000,0.00000000,0.00000000,0.00000000
243.61000000,5.85393800,4.98100000,0.19319789,491.68838348,0.17663700,586.68154116,0.00081926,0.00000000,0.00000000,0.00000000,0.00000000,0.00000000,0.00000000,0.00000000,0.00000000
245.11000000,5.90148200,4.98200000,0.19470178,491.78709626,0.17789660,587.53891820,0.00088112,0.00000000,0.00000000,0.00000000,0.00000000,0.00000000,0.00000000,0.00000000,0.00000000
246.61000000,5.94946200,4.98300000,0.19631856,491.88580905,0.17924897,588.45212058,0.00094312,0.00000000,0.00000000,0.00000000,0.00000000,0.00000000,0.00000000,0.00000000,0.00000000
248.11000000,5.99761200,4.98400000,0.19793533,491.98452184,0.18059952,589.36564216,0.00094184,0.00000000,0.00000000,0.00000000,0.00000000,0.00000000,0.00000000,0.00000000,0.00000000
249.61000000,6.04671200,4.98500000,0.19951433,492.08323462,0.18191675,590.26089312,0.00106609,0.00000000,0.00000000,0.00000000,0.00000000,0.00000000,0.00000000,0.00000000,0.00000000
251.11000000,6.09482800,4.98500000,0.20105589,492.08323462,0.18320108,591.01946676,0.00081408,0.00000000,0.00000000,0.00000000,0.00000000,0.00000000,0.00000000,0.00000000,0.00000000
252.61000000,6.14385800,4.98500000,0.20271022,492.08323462,0.18457753,591.83353646,0.00081333,0.00000000,0.00000000,0.00000000,0.00000000,0.00000000,0.00000000,0.00000000,0.00000000
254.11000000,6.19285700,4.98600000,0.20432689,492.18194741,0.18592081,592.74795349,0.00093703,0.00000000,0.00000000,0.00000000,0.00000000,0.00000000,0.00000000,0.00000000,0.00000000
255.61000000,6.24202200,4.98700000,0.20590578,492.28066019,0.18723097,593.64409241,0.00081044,0.00000000,0.00000000,0.00000000,0.00000000,0.00000000,0.00000000,0.00000000,0.00000000
257.11000000,6.29291400,4.98800000,0.20756022,492.37937298,0.18860198,594.57774505,0.00074728,0.00000000,0.00000000,0.00000000,0.00000000,0.00000000,0.00000000,0.00000000,0.00000000
258.61000000,6.34279200,4.98800000,0.20928967,492.37937298,0.19003313,595.42928782,0.00099514,0.00000000,0.00000000,0.00000000,0.00000000,0.00000000,0.00000000,0.00000000,0.00000000
260.11000000,6.39297200,4.98800000,0.21090633,492.37937298,0.19136912,596.22530114,0.00099381,0.00000000,0.00000000,0.00000000,0.00000000,0.00000000,0.00000000,0.00000000,0.00000000
261.61000000,6.44447500,4.98900000,0.21256067,492.47808576,0.00000000,0.00000000,0.00000000,0.00000000,0.00000000,0.00000000,0.00000000,0.00000000,0.00000000,0.00000000,0.00000000
263.11000000,6.49526300,4.98900000,0.21429022,492.47808576,0.00000000,0.00000000,0.00000000,0.00000000,0.00000000,0.00000000,0.00000000,0.00000000,0.00000000,0.00000000,0.00000000
264.61000000,6.54652900,4.98800000,0.21590689,492.37937298,0.00000000,0.00000000,0.00000000,0.00000000,0.00000000,0.00000000,0.00000000,0.00000000,0.00000000,0.00000000,0.00000000
266.11000000,6.59786000,4.98800000,0.21756122,492.37937298,0.00000000,0.00000000,0.00000000,0.00000000,0.00000000,0.00000000,0.00000000,0.00000000,0.00000000,0.00000000,0.00000000
267.61000000,6.65000500,4.98900000,0.21921556,492.47808576,0.00000000,0.00000000,0.00000000,0.00000000,0.00000000,0.00000000,0.00000000,0.00000000,0.00000000,0.00000000,0.00000000
269.11000000,6.70245200,4.98800000,0.22102022,492.37937298,0.00000000,0.00000000,0.00000000,0.00000000,0.00000000,0.00000000,0.00000000,0.00000000,0.00000000,0.00000000,0.00000000
270.61000000,6.75581400,4.98800000,0.22271211,492.37937298,0.00000000,0.00000000,0.00000000,0.00000000,0.00000000,0.00000000,0.00000000,0.00000000,0.00000000,0.00000000,0.00000000
272.11000000,6.80802400,4.98600000,0.22436633,492.18194741,0.00000000,0.00000000,0.00000000,0.00000000,0.00000000,0.00000000,0.00000000,0.00000000,0.00000000,0.00000000,0.00000000
273.61000000,6.86195900,4.98600000,0.22602056,492.18194741,0.00000000,0.00000000,0.00000000,0.00000000,0.00000000,0.00000000,0.00000000,0.00000000,0.00000000,0.00000000,0.00000000
275.11000000,6.91548900,4.98500000,0.22771233,492.08323462,0.00000000,0.00000000,0.00000000,0.00000000,0.00000000,0.00000000,0.00000000,0.00000000,0.00000000,0.00000000,0.00000000
276.61000000,6.96895300,4.98400000,0.22940411,491.98452184,0.00000000,0.00000000,0.00000000,0.00000000,0.00000000,0.00000000,0.00000000,0.00000000,0.00000000,0.00000000,0.00000000
278.11000000,7.02366600,4.98300000,0.23098311,491.88580905,0.00000000,0.00000000,0.00000000,0.00000000,0.00000000,0.00000000,0.00000000,0.00000000,0.00000000,0.00000000,0.00000000
279.61000000,7.07858300,4.98100000,0.23256222,491.68838348,0.00000000,0.00000000,0.00000000,0.00000000,0.00000000,0.00000000,0.00000000,0.00000000,0.00000000,0.00000000,0.00000000
281.11000000,7.13471900,4.98000000,0.23414111,491.58967069,0.00000000,0.00000000,0.00000000,0.00000000,0.00000000,0.00000000,0.00000000,0.00000000,0.00000000,0.00000000,0.00000000
282.61000000,7.19038100,4.97600000,0.23553200,491.19481955,0.00000000,0.00000000,0.00000000,0.00000000,0.00000000,0.00000000,0.00000000,0.00000000,0.00000000,0.00000000,0.00000000
284.11000000,7.24678700,4.97300000,0.23688544,490.89868120,0.00000000,0.00000000,0.00000000,0.00000000,0.00000000,0.00000000,0.00000000,0.00000000,0.00000000,0.00000000,0.00000000
285.61000000,7.30363200,4.96900000,0.23808844,490.50383006,0.00000000,0.00000000,0.00000000,0.00000000,0.00000000,0.00000000,0.00000000,0.00000000,0.00000000,0.00000000,0.00000000
287.11000000,7.36078500,4.96500000,0.23925378,490.10897891,0.00000000,0.00000000,0.00000000,0.00000000,0.00000000,0.00000000,0.00000000,0.00000000,0.00000000,0.00000000,0.00000000
288.61000000,7.41813700,4.95900000,0.24023122,489.51670220,0.00000000,0.00000000,0.00000000,0.00000000,0.00000000,0.00000000,0.00000000,0.00000000,0.00000000,0.00000000,0.00000000
290.11000000,7.47674100,4.95200000,0.24098322,488.82571271,0.00000000,0.00000000,0.00000000,0.00000000,0.00000000,0.00000000,0.00000000,0.00000000,0.00000000,0.00000000,0.00000000
291.61000000,7.53588500,4.94200000,0.24169744,487.83858485,0.00000000,0.00000000,0.00000000,0.00000000,0.00000000,0.00000000,0.00000000,0.00000000,0.00000000,0.00000000,0.00000000
293.11000000,7.59640600,4.93100000,0.24218689,486.75274422,0.00000000,0.00000000,0.00000000,0.00000000,0.00000000,0.00000000,0.00000000,0.00000000,0.00000000,0.00000000,0.00000000
294.61000000,7.65948500,4.90700000,0.24263933,484.38363737,0.00000000,0.00000000,0.00000000,0.00000000,0.00000000,0.00000000,0.00000000,0.00000000,0.00000000,0.00000000,0.00000000
296.11000000,7.73281900,4.87000000,0.24256789,480.73126431,0.00000000,0.00000000,0.00000000,0.00000000,0.00000000,0.00000000,0.00000000,0.00000000,0.00000000,0.00000000,0.00000000