File: polyN_optimization/results_exp/AA7020-T6/UT_60_2.csv
Time[s],Displacement[mm],Force[kN],EngStrain_longi,EngStress[MPa],TrueStrain,TrueStress[MPa],TrueStrainRate[1/s],PlasticStrain_longi,PlasticStress[MPa],PlasticStrain_thick,PlasticStrain_width,R-Value,Thickness[mm],Width[mm], Young's Modulus [MPa]
0.66000000,0.00000000,-0.01000000,0.00000000,-0.98517314,0.00000000,-0.98517314,0.00000000,0.00058829,191.83127718,-0.00054009,-0.00004820,0.71970624,1.01000000,10.05000000,66924.58207935
2.16000000,0.01023400,-0.00200000,0.00041722,-0.19703463,0.00041714,-0.19711684,0.00030012,0.00059785,213.14339029,-0.00056643,-0.00003142,0.00000000,0.00000000,0.00000000,0.00000000
3.66000000,0.02032300,0.30600000,0.00073467,30.14629821,0.00073440,30.16844569,-0.00001532,0.00070355,232.10976926,-0.00065238,-0.00005117,0.00000000,0.00000000,0.00000000,0.00000000
5.16000000,0.03055600,0.50100000,0.00116511,49.35717452,0.00116443,49.41468112,0.00015915,0.00089857,251.21168303,-0.00064374,-0.00025483,0.00000000,0.00000000,0.00000000,0.00000000
6.66000000,0.03917800,0.72500000,0.00151367,71.42505295,0.00151252,71.53316667,0.00037680,0.00126939,265.80804903,-0.00077776,-0.00049163,0.00000000,0.00000000,0.00000000,0.00000000
8.16000000,0.04769200,0.92000000,0.00179000,90.63592926,0.00178840,90.79816758,0.00045257,0.00182945,279.18144041,-0.00114205,-0.00068739,0.00000000,0.00000000,0.00000000,0.00000000
9.66000000,0.05725500,1.16800000,0.00199644,115.06822324,0.00199445,115.29795056,0.00025218,0.00260832,288.75623992,-0.00162140,-0.00098691,0.00000000,0.00000000,0.00000000,0.00000000
11.16000000,0.06646600,1.36500000,0.00227844,134.47613418,0.00227585,134.78253058,0.00003459,0.00354711,297.20018206,-0.00223458,-0.00131252,0.00000000,0.00000000,0.00000000,0.00000000
12.66000000,0.07493600,1.60700000,0.00259922,158.31732427,0.00259585,158.72882618,0.00000000,0.00442804,304.04752475,-0.00273439,-0.00169365,0.00000000,0.00000000,0.00000000,0.00000000
14.16000000,0.08392700,1.79900000,0.00296500,177.23264864,0.00296061,177.75814344,0.00005030,0.00534915,310.62087621,-0.00322091,-0.00212824,0.00000000,0.00000000,0.00000000,0.00000000
15.66000000,0.09383500,2.01900000,0.00334478,198.90645781,0.00333920,199.57175571,0.00031719,0.00641265,315.65256479,-0.00382731,-0.00258534,0.00000000,0.00000000,0.00000000,0.00000000
17.16000000,0.10371600,2.20100000,0.00363089,216.83660903,0.00362431,217.62391867,0.00029229,0.00749434,320.90140157,-0.00443179,-0.00306255,0.00000000,0.00000000,0.00000000,0.00000000
18.66000000,0.11472200,2.41800000,0.00395700,238.21486626,0.00394919,239.15748249,0.00021804,0.00855058,325.45193718,-0.00502482,-0.00352576,0.00000000,0.00000000,0.00000000,0.00000000
20.16000000,0.12992200,2.57800000,0.00448944,253.97763657,0.00447940,255.11785506,0.00037214,0.00960320,329.91073230,-0.00561530,-0.00398790,0.00000000,0.00000000,0.00000000,0.00000000
21.66000000,0.14974000,2.74700000,0.00520044,270.62706271,0.00518697,272.03444371,0.00065116,0.01077549,333.91685165,-0.00634115,-0.00443433,0.00000000,0.00000000,0.00000000,0.00000000
23.16000000,0.17584200,2.85000000,0.00606911,280.77434609,0.00605077,282.47839679,0.00089720,0.01191802,337.82163543,-0.00702556,-0.00489246,0.00000000,0.00000000,0.00000000,0.00000000
24.66000000,0.20362800,2.94200000,0.00690767,289.83793902,0.00688392,291.84004289,0.00074698,0.01299000,341.10670844,-0.00765065,-0.00533935,0.00000000,0.00000000,0.00000000,0.00000000
26.16000000,0.23354500,3.01000000,0.00792667,296.53711640,0.00789542,298.88766727,0.00066418,0.01411752,344.82136644,-0.00832790,-0.00578962,0.00000000,0.00000000,0.00000000,0.00000000
27.66000000,0.26501900,3.08300000,0.00902467,303.72888035,0.00898419,306.46993225,0.00089479,0.01527234,348.04900368,-0.00902163,-0.00625071,0.00000000,0.00000000,0.00000000,0.00000000
29.16000000,0.29808200,3.13500000,0.01007367,308.85178070,0.01002327,311.96305059,0.00095307,0.01637539,351.46784746,-0.00963154,-0.00674385,0.00000000,0.00000000,0.00000000,0.00000000
30.66000000,0.33040000,3.19100000,0.01113400,314.36875031,0.01107247,317.86893197,0.00078849,0.01751031,354.60182038,-0.01031786,-0.00719245,0.00000000,0.00000000,0.00000000,0.00000000
32.16000000,0.36545900,3.23200000,0.01230711,318.40796020,0.01223199,322.32664234,0.00080229,0.01867670,357.75403594,-0.01101533,-0.00766137,0.00000000,0.00000000,0.00000000,0.00000000
33.66000000,0.40000900,3.27600000,0.01349533,322.74272203,0.01340508,327.09824265,0.00091300,0.01982729,360.60323838,-0.01169364,-0.00813365,0.00000000,0.00000000,0.00000000,0.00000000
35.16000000,0.43516900,3.31000000,0.01462700,326.09231072,0.01452106,330.86206295,0.00091921,0.02095316,363.55131139,-0.01233976,-0.00861340,0.00000000,0.00000000,0.00000000,0.00000000
36.66000000,0.47073400,3.35000000,0.01576256,330.03300330,0.01563962,335.23516685,0.00070348,0.02206443,366.39870745,-0.01296636,-0.00909807,0.00000000,0.00000000,0.00000000,0.00000000
38.16000000,0.50619600,3.38000000,0.01700700,332.98852273,0.01686400,338.65165854,0.00076164,0.02320938,369.36654352,-0.01362283,-0.00958655,0.00000000,0.00000000,0.00000000,0.00000000
39.66000000,0.54220000,3.41600000,0.01818389,336.53514605,0.01802054,342.65466375,0.00084198,0.02434965,372.03328541,-0.01431846,-0.01003119,0.00000000,0.00000000,0.00000000,0.00000000
41.16000000,0.57786600,3.44300000,0.01933433,339.19511354,0.01914980,345.75322493,0.00074507,0.02547479,374.90430148,-0.01496100,-0.01051379,0.00000000,0.00000000,0.00000000,0.00000000
42.66000000,0.61393700,3.47400000,0.02054122,342.24915029,0.02033310,349.27936614,0.00071478,0.02660172,377.27115468,-0.01562330,-0.01097842,0.00000000,0.00000000,0.00000000,0.00000000
44.16000000,0.65024500,3.49900000,0.02176689,344.71208315,0.02153337,352.21539276,0.00081683,0.02775664,380.16538042,-0.01629456,-0.01146208,0.00000000,0.00000000,0.00000000,0.00000000
45.66000000,0.68662200,3.53000000,0.02293622,347.76611990,0.02267714,355.74256090,0.00074983,0.02886856,382.63962380,-0.01692955,-0.01193901,0.00000000,0.00000000,0.00000000,0.00000000
47.16000000,0.72343800,3.55300000,0.02416200,350.03201813,0.02387472,358.48949175,0.00072701,0.02995969,385.21359594,-0.01755405,-0.01240564,0.00000000,0.00000000,0.00000000,0.00000000
48.66000000,0.75866400,3.58200000,0.02538011,352.88902025,0.02506338,361.84538279,0.00072615,0.03108903,387.80780677,-0.01820456,-0.01288447,0.00000000,0.00000000,0.00000000,0.00000000
50.16000000,0.79503900,3.60400000,0.02658700,355.05640116,0.02623971,364.49628570,0.00074738,0.03222206,390.30619181,-0.01886625,-0.01335581,0.00000000,0.00000000,0.00000000,0.00000000
51.66000000,0.83107600,3.62900000,0.02774878,357.51933402,0.02737076,367.44005857,0.00070998,0.03332762,392.59317275,-0.01950062,-0.01382700,0.00000000,0.00000000,0.00000000,0.00000000
53.16000000,0.86741900,3.65000000,0.02896322,359.58819763,0.02855171,370.00303050,0.00070180,0.03445784,395.10080165,-0.02014226,-0.01431558,0.00000000,0.00000000,0.00000000,0.00000000
54.66000000,0.90389600,3.67600000,0.03020389,362.14964780,0.02975673,373.08797552,0.00075922,0.03560374,397.41365060,-0.02082056,-0.01478319,0.00000000,0.00000000,0.00000000,0.00000000
56.16000000,0.93935800,3.69600000,0.03139944,364.11999409,0.03091656,375.55315961,0.00075101,0.03674182,399.93491517,-0.02147187,-0.01526994,0.00000000,0.00000000,0.00000000,0.00000000
57.66000000,0.97603800,3.71900000,0.03258756,366.38589232,0.03206784,378.32551294,0.00073572,0.03783606,402.13353178,-0.02211150,-0.01572457,0.00000000,0.00000000,0.00000000,0.00000000
59.16000000,1.01227800,3.73900000,0.03380200,368.35623861,0.03324327,380.80741619,0.00069851,0.03898130,404.46090386,-0.02278545,-0.01619585,0.00000000,0.00000000,0.00000000,0.00000000
60.66000000,1.04818000,3.76100000,0.03502389,370.52361953,0.03442451,383.50079761,0.00077029,0.04011353,406.58053435,-0.02345053,-0.01666300,0.00000000,0.00000000,0.00000000,0.00000000
62.16000000,1.08408200,3.78000000,0.03622700,372.39544850,0.03558623,385.88621841,0.00084191,0.04121170,409.00198576,-0.02410473,-0.01710696,0.00000000,0.00000000,0.00000000,0.00000000
63.66000000,1.11991600,3.80300000,0.03739622,374.66134673,0.03671394,388.67226571,0.00076852,0.04231272,411.11782730,-0.02472150,-0.01759122,0.00000000,0.00000000,0.00000000,0.00000000
65.16000000,1.15629200,3.82100000,0.03859178,376.43465839,0.03786574,390.96194108,0.00073853,0.04345720,413.36006486,-0.02541417,-0.01804303,0.00000000,0.00000000,0.00000000,0.00000000
66.66000000,1.19300500,3.84200000,0.03981378,378.50352199,0.03904164,393.57317711,0.00081741,0.04458042,415.49397301,-0.02609957,-0.01848086,0.00000000,0.00000000,0.00000000,0.00000000
68.16000000,1.22914400,3.85900000,0.04099811,380.17831634,0.04017998,395.76490919,0.00076586,0.04567600,417.72495595,-0.02672994,-0.01894606,0.00000000,0.00000000,0.00000000,0.00000000
69.66000000,1.26511400,3.87900000,0.04220867,382.14866263,0.04134218,398.27864815,0.00073597,0.04678158,419.65144865,-0.02738498,-0.01939660,0.00000000,0.00000000,0.00000000,0.00000000
71.16000000,1.30176000,3.89600000,0.04342678,383.82345697,0.04251028,400.49167294,0.00072786,0.04794174,421.91855317,-0.02804467,-0.01989707,0.00000000,0.00000000,0.00000000,0.00000000
72.66000000,1.33776200,3.91600000,0.04462989,385.79380326,0.04366265,403.01173783,0.00078470,0.04903750,423.84902998,-0.02865436,-0.02038314,0.00000000,0.00000000,0.00000000,0.00000000
74.16000000,1.37403700,3.93200000,0.04581422,387.37008029,0.04479574,405.11713923,0.00069750,0.05015735,426.00321843,-0.02931539,-0.02084196,0.00000000,0.00000000,0.00000000,0.00000000
75.66000000,1.41027700,3.95100000,0.04702867,389.24190927,0.04595631,407.54743727,0.00069691,0.05127734,428.05697769,-0.02993432,-0.02134301,0.00000000,0.00000000,0.00000000,0.00000000
77.16000000,1.44648400,3.96700000,0.04826933,390.81818630,0.04714055,409.68271960,0.00080360,0.05239596,430.11432626,-0.03058680,-0.02180916,0.00000000,0.00000000,0.00000000,0.00000000
78.66000000,1.48306200,3.98500000,0.04945733,392.59149796,0.04827321,412.00802653,0.00080968,0.05349977,431.85395183,-0.03122795,-0.02227182,0.00000000,0.00000000,0.00000000,0.00000000
80.16000000,1.51943700,3.99900000,0.05066422,393.97074036,0.04942256,413.93096150,0.00075882,0.05463317,433.92571663,-0.03187853,-0.02275464,0.00000000,0.00000000,0.00000000,0.00000000
81.66000000,1.55557600,4.01700000,0.05187489,395.74405202,0.05057418,416.27323074,0.00075794,0.05577023,435.89793694,-0.03256196,-0.02320826,0.00000000,0.00000000,0.00000000,0.00000000
83.16000000,1.59218800,4.03100000,0.05308556,397.12329442,0.05172448,418.20480513,0.00080710,0.05687072,437.85808053,-0.03318840,-0.02368232,0.00000000,0.00000000,0.00000000,0.00000000
84.66000000,1.62849600,4.05000000,0.05426611,398.99512339,0.05284490,420.64703709,0.00078469,0.05799939,439.72893359,-0.03386044,-0.02413895,0.00000000,0.00000000,0.00000000,0.00000000
86.16000000,1.66521000,4.06300000,0.05549922,400.27584848,0.05401385,422.49084675,0.00074102,0.05911614,441.59824639,-0.03452467,-0.02459147,0.00000000,0.00000000,0.00000000,0.00000000
87.66000000,1.70151700,4.07900000,0.05673989,401.85212551,0.05518859,424.65317046,0.00084681,0.06025405,443.37482252,-0.03522659,-0.02502746,0.00000000,0.00000000,0.00000000,0.00000000
89.16000000,1.73829900,4.09200000,0.05790922,403.13285060,0.05629453,426.47796043,0.00076076,0.06137160,445.25185705,-0.03586063,-0.02551097,0.00000000,0.00000000,0.00000000,0.00000000
90.66000000,1.77484500,4.10900000,0.05911233,404.80764494,0.05743114,428.73676939,0.00073849,0.06250315,447.03277722,-0.03654346,-0.02595969,0.00000000,0.00000000,0.00000000,0.00000000
92.16000000,1.81149100,4.12200000,0.06036056,406.08837003,0.05860900,430.60008965,0.00080136,0.06363550,448.92387896,-0.03720218,-0.02643332,0.00000000,0.00000000,0.00000000,0.00000000
93.66000000,1.84827200,4.13800000,0.06155989,407.66464706,0.05973942,432.76043744,0.00080757,0.06474692,450.70289019,-0.03782362,-0.02692330,0.00000000,0.00000000,0.00000000,0.00000000
95.16000000,1.88430900,4.15000000,0.06277800,408.84685483,0.06088623,434.51344269,0.00077841,0.06588834,452.49905091,-0.03849674,-0.02739161,0.00000000,0.00000000,0.00000000,0.00000000
96.66000000,1.92143000,4.16500000,0.06398489,410.32461455,0.06202119,436.57918942,0.00072090,0.06702642,454.19062816,-0.03915166,-0.02787476,0.00000000,0.00000000,0.00000000,0.00000000
98.16000000,1.95824400,4.17700000,0.06522944,411.50682232,0.06319022,438.34918373,0.00080500,0.06815604,455.88166626,-0.03977785,-0.02837819,0.00000000,0.00000000,0.00000000,0.00000000
99.66000000,1.99495900,4.19200000,0.06642878,412.98458204,0.06431548,440.41864307,0.00074760,0.06926555,457.67366376,-0.04043014,-0.02883542,0.00000000,0.00000000,0.00000000,0.00000000
101.16000000,2.03197700,4.20300000,0.06765822,414.06827250,0.06546767,442.08339569,0.00076798,0.07042858,459.27984474,-0.04111250,-0.02931608,0.00000000,0.00000000,0.00000000,0.00000000
102.66000000,2.06869200,4.21800000,0.06891767,415.54603222,0.06664661,444.18449515,0.00080201,0.07154581,461.08228089,-0.04176993,-0.02977588,0.00000000,0.00000000,0.00000000,0.00000000
104.16000000,2.10581200,4.22900000,0.07012456,416.62972267,0.06777505,445.84569681,0.00077306,0.07266998,462.78420961,-0.04243035,-0.03023964,0.00000000,0.00000000,0.00000000,0.00000000
105.66000000,2.14252500,4.24100000,0.07134656,417.81193045,0.06891632,447.62137255,0.00074437,0.07380118,464.38533604,-0.04306903,-0.03073215,0.00000000,0.00000000,0.00000000,0.00000000
107.16000000,2.17957800,4.25300000,0.07259844,418.99413822,0.07008416,449.41246089,0.00076423,0.07496408,466.11196217,-0.04375047,-0.03121361,0.00000000,0.00000000,0.00000000,0.00000000
108.66000000,2.21683300,4.26600000,0.07383167,420.27486331,0.07123325,451.30445692,0.00079151,0.07609251,467.71816753,-0.04439178,-0.03170073,0.00000000,0.00000000,0.00000000,0.00000000
110.16000000,2.25408800,4.27700000,0.07506489,421.35855377,0.07238102,452.98778679,0.00075565,0.07723139,469.22462051,-0.04506565,-0.03216574,0.00000000,0.00000000,0.00000000,0.00000000
111.66000000,2.29158000,4.29000000,0.07633189,422.63927885,0.07355886,454.90013333,0.00078946,0.07832617,470.82097295,-0.04570672,-0.03261945,0.00000000,0.00000000,0.00000000,0.00000000
113.16000000,2.32863200,4.30000000,0.07755000,423.62445200,0.07468995,456.47652825,0.00074669,0.07945746,472.43768731,-0.04633769,-0.03311978,0.00000000,0.00000000,0.00000000,0.00000000
114.66000000,2.36629300,4.31200000,0.07878700,424.80665977,0.07583726,458.27590207,0.00077386,0.08063682,473.97228609,-0.04705929,-0.03357752,0.00000000,0.00000000,0.00000000,0.00000000
116.16000000,2.40348100,4.32300000,0.08003900,425.89035023,0.07699715,459.97818797,0.00072418,0.08179752,475.50098192,-0.04772481,-0.03407271,0.00000000,0.00000000,0.00000000,0.00000000
117.66000000,2.44114200,4.33400000,0.08130233,426.97404069,0.07816618,461.68802647,0.00077905,0.08292610,477.01722950,-0.04835802,-0.03456809,0.00000000,0.00000000,0.00000000,0.00000000
119.16000000,2.47873600,4.34500000,0.08252422,428.05773115,0.07929556,463.38286248,0.00074346,0.08408057,478.54881760,-0.04904666,-0.03503391,0.00000000,0.00000000,0.00000000,0.00000000
120.66000000,2.51670200,4.35400000,0.08377622,428.94438698,0.08045144,464.87972726,0.00074958,0.08520642,480.06954554,-0.04970990,-0.03549653,0.00000000,0.00000000,0.00000000,0.00000000
122.16000000,2.55453200,4.36600000,0.08504322,430.12659475,0.08161982,466.70594633,0.00071387,0.08633094,481.59250037,-0.05034826,-0.03598268,0.00000000,0.00000000,0.00000000,0.00000000
123.66000000,2.59222800,4.37500000,0.08630656,431.01325058,0.08278346,468.21251964,0.00074087,0.08754058,483.05078698,-0.05108280,-0.03645778,0.00000000,0.00000000,0.00000000,0.00000000
125.16000000,2.63002500,4.38500000,0.08755100,431.99842372,0.08392838,469.82031772,0.00071223,0.08862977,484.45320587,-0.05166281,-0.03696696,0.00000000,0.00000000,0.00000000,0.00000000
126.66000000,2.66755100,4.39400000,0.08880678,432.88507955,0.08508240,471.32820862,0.00078756,0.08976034,485.98759689,-0.05229337,-0.03746697,0.00000000,0.00000000,0.00000000,0.00000000
128.16000000,2.70609200,4.40500000,0.09006244,433.96877001,0.08623498,473.05305825,0.00078645,0.09093996,487.33030745,-0.05300606,-0.03793390,0.00000000,0.00000000,0.00000000,0.00000000
129.66000000,2.74422800,4.41400000,0.09138600,434.85542584,0.08744845,474.59512379,0.00081320,0.09210314,488.77693502,-0.05366237,-0.03844078,0.00000000,0.00000000,0.00000000,0.00000000
131.16000000,2.78216000,4.42200000,0.09263422,435.64356436,0.08859150,475.99906711,0.00073658,0.09325959,490.11340157,-0.05430925,-0.03895033,0.00000000,0.00000000,0.00000000,0.00000000
132.66000000,2.82039700,4.43000000,0.09392000,436.43170287,0.08976758,477.42136841,0.00079059,0.09439482,491.66129908,-0.05497895,-0.03941587,0.00000000,0.00000000,0.00000000,0.00000000
134.16000000,2.85903900,4.44000000,0.09518333,437.41687602,0.09092178,479.05167233,0.00074867,0.09554170,492.99822334,-0.05563698,-0.03990472,0.00000000,0.00000000,0.00000000,0.00000000
135.66000000,2.89751300,4.44800000,0.09648411,438.20501453,0.09210880,480.48483584,0.00082989,0.09669397,494.34029440,-0.05634398,-0.04034999,0.00000000,0.00000000,0.00000000,0.00000000
137.16000000,2.93561400,4.45700000,0.09773989,439.09167036,0.09325342,482.00844143,0.00082895,0.09784823,495.68584120,-0.05701104,-0.04083719,0.00000000,0.00000000,0.00000000,0.00000000
138.66000000,2.97425800,4.46400000,0.09901822,439.78129156,0.09441726,483.32765322,0.00069792,0.09901122,497.03825017,-0.05770146,-0.04130976,0.00000000,0.00000000,0.00000000,0.00000000
140.16000000,3.01303600,4.47400000,0.10030033,440.76646471,0.09558317,484.97548804,0.00081348,0.10018280,498.39749499,-0.05835106,-0.04183175,0.00000000,0.00000000,0.00000000,0.00000000
141.66000000,3.05150900,4.48200000,0.10160122,441.55460322,0.09676478,486.41709059,0.00087407,0.10133274,499.74839804,-0.05902643,-0.04230631,0.00000000,0.00000000,0.00000000,0.00000000
143.16000000,3.09052400,4.49100000,0.10286067,442.44125905,0.09790741,487.95106192,0.00076382,0.10247625,500.98791090,-0.05969737,-0.04277888,0.00000000,0.00000000,0.00000000,0.00000000
144.66000000,3.12903200,4.49700000,0.10417656,443.03236294,0.09909986,489.18594851,0.00078324,0.10364359,502.35246507,-0.06040857,-0.04323501,0.00000000,0.00000000,0.00000000,0.00000000
146.16000000,3.16743800,4.50500000,0.10545867,443.82050145,0.10026033,490.62521978,0.00075518,0.10478946,503.70868287,-0.06103258,-0.04375688,0.00000000,0.00000000,0.00000000,0.00000000
147.66000000,3.20716400,4.51300000,0.10673700,444.60863997,0.10141605,492.06483237,0.00075431,0.10599027,504.87325261,-0.06173537,-0.04425490,0.00000000,0.00000000,0.00000000,0.00000000
149.16000000,3.24516300,4.52000000,0.10801156,445.29826117,0.10256702,493.39561904,0.00072636,0.10713147,506.12072732,-0.06236281,-0.04476866,0.00000000,0.00000000,0.00000000,0.00000000
150.66000000,3.28455000,4.52700000,0.10932367,445.98788237,0.10375052,494.74491296,0.00075255,0.10831459,507.39184277,-0.06304316,-0.04527142,0.00000000,0.00000000,0.00000000,0.00000000
152.16000000,3.32353200,4.53500000,0.11062467,446.77602089,0.10492262,496.20046927,0.00073713,0.10951459,508.78538969,-0.06374018,-0.04577441,0.00000000,0.00000000,0.00000000,0.00000000
153.66000000,3.36349400,4.54100000,0.11191800,447.36712477,0.10608645,497.43555864,0.00070295,0.11065643,509.92857087,-0.06440155,-0.04625488,0.00000000,0.00000000,0.00000000,0.00000000
155.16000000,3.40298300,4.54900000,0.11326400,448.15526329,0.10729624,498.91512103,0.00074184,0.11187981,511.11569738,-0.06510637,-0.04677344,0.00000000,0.00000000,0.00000000,0.00000000
156.66000000,3.44254000,4.55500000,0.11458367,448.74636717,0.10848094,500.16537133,0.00078969,0.11301069,512.36912581,-0.06576572,-0.04724497,0.00000000,0.00000000,0.00000000,0.00000000
158.15000000,3.48202800,4.56100000,0.11590700,449.33747106,0.10966753,501.41882932,0.00085953,0.11418989,513.64976836,-0.06647036,-0.04771953,0.00000000,0.00000000,0.00000000,0.00000000
159.66000000,3.52165300,4.56800000,0.11718156,450.02709226,0.11080905,502.76196697,0.00073904,0.11541864,514.84633230,-0.06721978,-0.04819887,0.00000000,0.00000000,0.00000000,0.00000000
161.15000000,3.56131000,4.57500000,0.11855011,450.71671346,0.11203330,504.14922992,0.00087394,0.11660956,516.02543198,-0.06792427,-0.04868529,0.00000000,0.00000000,0.00000000,0.00000000
162.66000000,3.60117100,4.58000000,0.11989611,451.20930003,0.11323592,505.30754041,0.00084609,0.11778736,517.08741864,-0.06860428,-0.04918308,0.00000000,0.00000000,0.00000000,0.00000000
164.16000000,3.64066000,4.58700000,0.12115944,451.89892124,0.11436337,506.65074348,0.00078486,0.11894427,518.36537247,-0.06929106,-0.04965321,0.00000000,0.00000000,0.00000000,0.00000000
165.66000000,3.68106200,4.59200000,0.12253178,452.39150781,0.11558665,507.82384351,0.00081454,0.12011771,519.54161903,-0.06994656,-0.05017115,0.00000000,0.00000000,0.00000000,0.00000000
167.16000000,3.72136200,4.59800000,0.12389278,452.98261169,0.11679835,509.10388574,0.00080056,0.12134043,520.63298417,-0.07068351,-0.05065692,0.00000000,0.00000000,0.00000000,0.00000000
168.66000000,3.76156100,4.60300000,0.12521244,453.47519827,0.11797186,510.25593634,0.00083236,0.12248621,521.68583980,-0.07130949,-0.05117672,0.00000000,0.00000000,0.00000000,0.00000000
170.15000000,3.80172700,4.60900000,0.12654333,454.06630215,0.11915395,511.52536558,0.00074932,0.12372914,523.01776668,-0.07205599,-0.05167315,0.00000000,0.00000000,0.00000000,0.00000000
171.66000000,3.84175600,4.61500000,0.12789689,454.65740604,0.12035474,512.80667378,0.00082381,0.12488185,524.07816265,-0.07270540,-0.05217645,0.00000000,0.00000000,0.00000000,0.00000000
173.15000000,3.88300500,4.62100000,0.12924667,455.24850993,0.12155074,514.08786234,0.00085641,0.12608233,525.16560511,-0.07340455,-0.05267778,0.00000000,0.00000000,0.00000000,0.00000000
174.65000000,3.92377900,4.62600000,0.13060011,455.74109650,0.12274856,515.26093434,0.00074507,0.12731863,526.16041410,-0.07415556,-0.05316307,0.00000000,0.00000000,0.00000000,0.00000000
176.15000000,3.96482400,4.63000000,0.13197244,456.13516576,0.12396164,516.33243858,0.00077298,0.12846882,527.33844953,-0.07480017,-0.05366865,0.00000000,0.00000000,0.00000000,0.00000000
177.65000000,4.00498900,4.63500000,0.13334478,456.62775233,0.12517324,517.51667849,0.00081268,0.12967305,528.54730145,-0.07548011,-0.05419293,0.00000000,0.00000000,0.00000000,0.00000000
179.16000000,4.04552700,4.64000000,0.13468700,457.12033890,0.12635684,518.68850598,0.00079929,0.13091130,529.54865532,-0.07621237,-0.05469894,0.00000000,0.00000000,0.00000000,0.00000000
180.65000000,4.08674100,4.64600000,0.13604422,457.71144279,0.12755225,519.98044002,0.00082741,0.13206210,530.61901470,-0.07686706,-0.05519504,0.00000000,0.00000000,0.00000000,0.00000000
182.15000000,4.12809100,4.65000000,0.13740522,458.10551204,0.12874955,521.05160173,0.00074706,0.13332971,531.63952781,-0.07763800,-0.05569171,0.00000000,0.00000000,0.00000000,0.00000000
183.65000000,4.16893300,4.65400000,0.13877756,458.49958130,0.12995537,522.12903242,0.00083870,0.13456829,532.76056716,-0.07836970,-0.05619859,0.00000000,0.00000000,0.00000000,0.00000000
185.15000000,4.20991000,4.65900000,0.14016111,458.99216787,0.13116958,523.32502011,0.00076047,0.13578731,533.75859335,-0.07908816,-0.05669916,0.00000000,0.00000000,0.00000000,0.00000000
186.65000000,4.25170000,4.66400000,0.14155222,459.48475445,0.13238893,524.52584251,0.00086725,0.13698552,534.74706929,-0.07978704,-0.05719849,0.00000000,0.00000000,0.00000000,0.00000000
188.15000000,4.29362500,4.66700000,0.14293211,459.78030639,0.13359699,525.49767623,0.00083565,0.13822592,535.87471184,-0.08051049,-0.05771544,0.00000000,0.00000000,0.00000000,0.00000000
189.65000000,4.33453500,4.67100000,0.14431578,460.17437565,0.13480688,526.58479858,0.00075596,0.13944530,536.99298724,-0.08121060,-0.05823470,0.00000000,0.00000000,0.00000000,0.00000000
191.15000000,4.37649400,4.67500000,0.14570678,460.56844490,0.13602172,527.67638896,0.00085342,0.14068076,538.00687717,-0.08193672,-0.05874404,0.00000000,0.00000000,0.00000000,0.00000000
192.65000000,4.41814800,4.68000000,0.14709789,461.06103148,0.13723518,528.88213586,0.00083920,0.14194527,538.92303683,-0.08267292,-0.05927235,0.00000000,0.00000000,0.00000000,0.00000000
194.15000000,4.46068300,4.68300000,0.14853789,461.35658342,0.13848973,529.88551635,0.00084473,0.14315184,539.92451850,-0.08335775,-0.05979409,0.00000000,0.00000000,0.00000000,0.00000000
195.65000000,4.50298000,4.68700000,0.14996667,461.75065268,0.13973296,530.99785889,0.00100067,0.14436346,540.93040146,-0.08407610,-0.06028735,0.00000000,0.00000000,0.00000000,0.00000000
197.15000000,4.54514200,4.69000000,0.15131633,462.04620462,0.14090593,531.96134213,0.00078380,0.14563755,541.97206094,-0.08481766,-0.06081989,0.00000000,0.00000000,0.00000000,0.00000000
198.65000000,4.58767600,4.69400000,0.15275267,462.44027388,0.14215271,533.07925889,0.00076990,0.14688124,542.99888710,-0.08553048,-0.06135076,0.00000000,0.00000000,0.00000000,0.00000000
200.15000000,4.63051500,4.69800000,0.15422644,462.83434314,0.14343037,534.21563824,0.00086021,0.14809288,543.89395351,-0.08623922,-0.06185366,0.00000000,0.00000000,0.00000000,0.00000000
201.65000000,4.67311600,4.70100000,0.15564389,463.12989508,0.14465767,535.21323301,0.00090987,0.14936539,544.93990606,-0.08696735,-0.06239805,0.00000000,0.00000000,0.00000000,0.00000000
203.15000000,4.71551500,4.70400000,0.15704256,463.42544702,0.14586723,536.20296353,0.00079952,0.15063615,545.98669583,-0.08770563,-0.06293052,0.00000000,0.00000000,0.00000000,0.00000000
204.65000000,4.75865800,4.70700000,0.15851633,463.72099897,0.14714016,537.22835141,0.00087641,0.15187502,546.90132939,-0.08844087,-0.06343415,0.00000000,0.00000000,0.00000000,0.00000000
206.15000000,4.80227500,4.71100000,0.15994133,464.11506822,0.14836943,538.34625105,0.00083662,0.15314406,547.83406339,-0.08918615,-0.06395791,0.00000000,0.00000000,0.00000000,0.00000000
207.65000000,4.84528300,4.71400000,0.16136622,464.41062017,0.14959709,539.35080750,0.00073816,0.15437966,548.74980816,-0.08991973,-0.06445992,0.00000000,0.00000000,0.00000000,0.00000000
209.15000000,4.88869600,4.71700000,0.16284756,464.70617211,0.15087179,540.38243629,0.00084733,0.15564388,549.79968704,-0.09062650,-0.06501738,0.00000000,0.00000000,0.00000000,0.00000000
210.65000000,4.93265200,4.71900000,0.16426878,464.90320674,0.15209323,541.27228829,0.00083981,0.15693975,550.75194010,-0.09138833,-0.06555142,0.00000000,0.00000000,0.00000000,0.00000000
212.15000000,4.97630300,4.72200000,0.16573133,465.19875868,0.15334864,542.29676922,0.00077429,0.15820223,551.68719280,-0.09211499,-0.06608724,0.00000000,0.00000000,0.00000000,0.00000000
213.65000000,5.02039300,4.72500000,0.16727278,465.49431063,0.15467007,543.35883700,0.00090202,0.15949628,552.52423447,-0.09291205,-0.06658423,0.00000000,0.00000000,0.00000000,0.00000000
215.15000000,5.06363800,4.72800000,0.16870156,465.78986257,0.15589335,544.36933695,0.00090111,0.16078538,553.59466949,-0.09365889,-0.06712650,0.00000000,0.00000000,0.00000000,0.00000000
216.65000000,5.10789700,4.73000000,0.17013022,465.98689720,0.15711504,545.26535157,0.00077119,0.16204447,554.41499598,-0.09437749,-0.06766698,0.00000000,0.00000000,0.00000000,0.00000000
218.15000000,5.15256400,4.73300000,0.17170933,466.28244914,0.15846365,546.34749763,0.00089860,0.16336488,555.27082698,-0.09516060,-0.06820427,0.00000000,0.00000000,0.00000000,0.00000000
219.65000000,5.19729700,4.73500000,0.17317567,466.47948377,0.15971432,547.26237936,0.00089748,0.16465045,556.22636168,-0.09587071,-0.06877974,0.00000000,0.00000000,0.00000000,0.00000000
221.15000000,5.24128600,4.73700000,0.17464200,466.67651840,0.16096342,548.17783892,0.00083239,0.16596577,557.20014876,-0.09664287,-0.06932290,0.00000000,0.00000000,0.00000000,0.00000000
222.65000000,5.28602000,4.73900000,0.17614578,466.87355303,0.16224280,549.11135815,0.00089521,0.16724802,558.15695783,-0.09737145,-0.06987657,0.00000000,0.00000000,0.00000000,0.00000000
224.15000000,5.33095600,4.74100000,0.17764978,467.07058766,0.16352074,550.04557376,0.00089426,0.16856142,559.01449269,-0.09811004,-0.07045138,0.00000000,0.00000000,0.00000000,0.00000000
225.65000000,5.37589200,4.74400000,0.17919122,467.36613960,0.16482880,551.11404938,0.00089290,0.16987298,559.87228659,-0.09889200,-0.07098098,0.00000000,0.00000000,0.00000000,0.00000000
227.15000000,5.42130300,4.74500000,0.18065756,467.46465691,0.16607153,551.91567914,0.00082815,0.17121414,560.74810721,-0.09964749,-0.07156665,0.00000000,0.00000000,0.00000000,0.00000000
228.65000000,5.46668000,4.74700000,0.18219900,467.66169154,0.16737626,552.86918408,0.00082688,0.17258459,561.64186148,-0.10046718,-0.07211741,0.00000000,0.00000000,0.00000000,0.00000000
230.15000000,5.51337500,4.74900000,0.18374056,467.85872617,0.16867939,553.82334844,0.00082599,0.17392196,562.51827080,-0.10124838,-0.07267358,0.00000000,0.00000000,0.00000000,0.00000000
231.65000000,5.55898900,4.75100000,0.18531967,468.05576080,0.17001250,554.79569837,0.00095187,0.17528854,563.41262115,-0.10202416,-0.07326437,0.00000000,0.00000000,0.00000000,0.00000000
233.15000000,5.60467000,4.75200000,0.18686111,468.15427811,0.17131210,555.63410669,0.00088713,0.17668270,564.44343191,-0.10287066,-0.07381205,0.00000000,0.00000000,0.00000000,0.00000000
234.65000000,5.65099400,4.75400000,0.18840267,468.35131274,0.17261011,556.58994900,0.00088617,0.17804553,565.33865298,-0.10365845,-0.07438709,0.00000000,0.00000000,0.00000000,0.00000000
236.15000000,5.69721600,4.75500000,0.18994411,468.44983006,0.17390634,557.42911663,0.00082168,0.17943899,566.13305153,-0.10449784,-0.07494115,0.00000000,0.00000000,0.00000000,0.00000000
237.65000000,5.74442000,4.75800000,0.19152322,468.74538200,0.17523251,558.52100796,0.00088366,0.18079799,567.02876525,-0.10527203,-0.07552597,0.00000000,0.00000000,0.00000000,0.00000000
239.15000000,5.79165700,4.75900000,0.19317756,468.84389932,0.17661996,559.41401772,0.00100858,0.18224929,567.85865724,-0.10614041,-0.07610888,0.00000000,0.00000000,0.00000000,0.00000000
240.65000000,5.83930100,4.76000000,0.19475667,468.94241663,0.17794254,560.27207855,0.00100743,0.18366597,568.79015300,-0.10698699,-0.07667898,0.00000000,0.00000000,0.00000000,0.00000000
242.15000000,5.88657200,4.76100000,0.19633567,469.04093394,0.17926327,561.13039840,0.00094292,0.18508070,569.72204172,-0.10783417,-0.07724652,0.00000000,0.00000000,0.00000000,0.00000000
243.65000000,5.93394500,4.76200000,0.19799000,469.13945126,0.18064515,562.02437121,0.00094161,0.18652560,570.55222969,-0.10868792,-0.07783767,0.00000000,0.00000000,0.00000000,0.00000000
245.15000000,5.98229900,4.76300000,0.19960667,469.23796857,0.18199373,562.90099535,0.00094034,0.18793621,571.48463327,-0.10949612,-0.07844009,0.00000000,0.00000000,0.00000000,0.00000000
246.65000000,6.02980800,4.76400000,0.20129856,469.33648589,0.18340310,563.81324257,0.00100176,0.18940761,572.33269593,-0.11036826,-0.07903935,0.00000000,0.00000000,0.00000000,0.00000000
248.15000000,6.07880500,4.76500000,0.20295289,469.43500320,0.18477927,564.70819325,0.00093791,0.00000000,0.00000000,0.00000000,0.00000000,0.00000000,0.00000000,0.00000000,0.00000000
249.65000000,6.12807300,4.76600000,0.20460722,469.53352052,0.18615356,565.60346989,0.00093662,0.00000000,0.00000000,0.00000000,0.00000000,0.00000000,0.00000000,0.00000000,0.00000000
251.15000000,6.17737500,4.76600000,0.20633667,469.53352052,0.18758822,566.41550203,0.00099757,0.00000000,0.00000000,0.00000000,0.00000000,0.00000000,0.00000000,0.00000000,0.00000000
252.65000000,6.22620200,4.76700000,0.20799100,469.63203783,0.18895865,567.31127501,0.00099621,0.00000000,0.00000000,0.00000000,0.00000000,0.00000000,0.00000000,0.00000000,0.00000000
254.15000000,6.27513200,4.76700000,0.20972044,469.63203783,0.19038930,568.12347753,0.00093248,0.00000000,0.00000000,0.00000000,0.00000000,0.00000000,0.00000000,0.00000000,0.00000000
255.65000000,6.32497500,4.76900000,0.21145000,469.82907246,0.19181799,569.17442983,0.00093133,0.00000000,0.00000000,0.00000000,0.00000000,0.00000000,0.00000000,0.00000000,0.00000000
257.15000000,6.37563000,4.76900000,0.21321711,469.82907246,0.19327560,570.00467001,0.00099192,0.00000000,0.00000000,0.00000000,0.00000000,0.00000000,0.00000000,0.00000000,0.00000000
258.65000000,6.42608300,4.76900000,0.21498422,469.82907246,0.19473109,570.83491018,0.00099066,0.00000000,0.00000000,0.00000000,0.00000000,0.00000000,0.00000000,0.00000000,0.00000000
260.15000000,6.47612800,4.77000000,0.21671367,469.92758977,0.19615351,571.76732082,0.00098906,0.00000000,0.00000000,0.00000000,0.00000000,0.00000000,0.00000000,0.00000000,0.00000000
261.65000000,6.52763000,4.77000000,0.21855600,469.92758977,0.19766655,572.63308408,0.00104942,0.00000000,0.00000000,0.00000000,0.00000000,0.00000000,0.00000000,0.00000000,0.00000000
263.15000000,6.57970600,4.77000000,0.22032300,469.92758977,0.00000000,0.00000000,0.00000000,0.00000000,0.00000000,0.00000000,0.00000000,0.00000000,0.00000000,0.00000000,0.00000000
264.65000000,6.63107200,4.77000000,0.22212778,469.92758977,0.00000000,0.00000000,0.00000000,0.00000000,0.00000000,0.00000000,0.00000000,0.00000000,0.00000000,0.00000000,0.00000000
266.15000000,6.68250600,4.77000000,0.22397000,469.92758977,0.00000000,0.00000000,0.00000000,0.00000000,0.00000000,0.00000000,0.00000000,0.00000000,0.00000000,0.00000000,0.00000000
267.65000000,6.73434500,4.77000000,0.22581233,469.92758977,0.00000000,0.00000000,0.00000000,0.00000000,0.00000000,0.00000000,0.00000000,0.00000000,0.00000000,0.00000000,0.00000000
269.15000000,6.78740300,4.77000000,0.22765467,469.92758977,0.00000000,0.00000000,0.00000000,0.00000000,0.00000000,0.00000000,0.00000000,0.00000000,0.00000000,0.00000000,0.00000000
270.65000000,6.84110400,4.76900000,0.22949689,469.82907246,0.00000000,0.00000000,0.00000000,0.00000000,0.00000000,0.00000000,0.00000000,0.00000000,0.00000000,0.00000000,0.00000000
272.15000000,6.89429700,4.76900000,0.23133922,469.82907246,0.00000000,0.00000000,0.00000000,0.00000000,0.00000000,0.00000000,0.00000000,0.00000000,0.00000000,0.00000000,0.00000000
273.65000000,6.94786300,4.76800000,0.23318144,469.73055515,0.00000000,0.00000000,0.00000000,0.00000000,0.00000000,0.00000000,0.00000000,0.00000000,0.00000000,0.00000000,0.00000000
275.15000000,7.00098800,4.76700000,0.23498622,469.63203783,0.00000000,0.00000000,0.00000000,0.00000000,0.00000000,0.00000000,0.00000000,0.00000000,0.00000000,0.00000000,0.00000000
276.65000000,7.05611000,4.76600000,0.23675333,469.53352052,0.00000000,0.00000000,0.00000000,0.00000000,0.00000000,0.00000000,0.00000000,0.00000000,0.00000000,0.00000000,0.00000000
278.15000000,7.11062300,4.76400000,0.23852033,469.33648589,0.00000000,0.00000000,0.00000000,0.00000000,0.00000000,0.00000000,0.00000000,0.00000000,0.00000000,0.00000000,0.00000000
279.65000000,7.16523800,4.76300000,0.24021233,469.23796857,0.00000000,0.00000000,0.00000000,0.00000000,0.00000000,0.00000000,0.00000000,0.00000000,0.00000000,0.00000000,0.00000000
281.15000000,7.22181500,4.76100000,0.24179144,469.04093394,0.00000000,0.00000000,0.00000000,0.00000000,0.00000000,0.00000000,0.00000000,0.00000000,0.00000000,0.00000000,0.00000000
282.65000000,7.27829100,4.75800000,0.24333289,468.74538200,0.00000000,0.00000000,0.00000000,0.00000000,0.00000000,0.00000000,0.00000000,0.00000000,0.00000000,0.00000000,0.00000000
284.15000000,7.33466500,4.75500000,0.24472400,468.44983006,0.00000000,0.00000000,0.00000000,0.00000000,0.00000000,0.00000000,0.00000000,0.00000000,0.00000000,0.00000000,0.00000000
285.65000000,7.39114000,4.75100000,0.24600233,468.05576080,0.00000000,0.00000000,0.00000000,0.00000000,0.00000000,0.00000000,0.00000000,0.00000000,0.00000000,0.00000000,0.00000000
287.15000000,7.44883400,4.74800000,0.24716789,467.76020886,0.00000000,0.00000000,0.00000000,0.00000000,0.00000000,0.00000000,0.00000000,0.00000000,0.00000000,0.00000000,0.00000000
288.65000000,7.50656200,4.74300000,0.24818300,467.26762228,0.00000000,0.00000000,0.00000000,0.00000000,0.00000000,0.00000000,0.00000000,0.00000000,0.00000000,0.00000000,0.00000000
290.15000000,7.56459400,4.73700000,0.24908544,466.67651840,0.00000000,0.00000000,0.00000000,0.00000000,0.00000000,0.00000000,0.00000000,0.00000000,0.00000000,0.00000000,0.00000000
291.65000000,7.62333600,4.73200000,0.24983733,466.18393183,0.00000000,0.00000000,0.00000000,0.00000000,0.00000000,0.00000000,0.00000000,0.00000000,0.00000000,0.00000000,0.00000000
293.15000000,7.68268900,4.72400000,0.25047656,465.39579331,0.00000000,0.00000000,0.00000000,0.00000000,0.00000000,0.00000000,0.00000000,0.00000000,0.00000000,0.00000000,0.00000000
294.65000000,7.74251400,4.71500000,0.25100289,464.50913748,0.00000000,0.00000000,0.00000000,0.00000000,0.00000000,0.00000000,0.00000000,0.00000000,0.00000000,0.00000000,0.00000000
296.15000000,7.80288100,4.70400000,0.25137889,463.42544702,0.00000000,0.00000000,0.00000000,0.00000000,0.00000000,0.00000000,0.00000000,0.00000000,0.00000000,0.00000000,0.00000000
297.65000000,7.86321600,4.68800000,0.25167967,461.84916999,0.00000000,0.00000000,0.00000000,0.00000000,0.00000000,0.00000000,0.00000000,0.00000000,0.00000000,0.00000000,0.00000000
299.15000000,7.92564900,4.66900000,0.25179233,459.97734102,0.00000000,0.00000000,0.00000000,0.00000000,0.00000000,0.00000000,0.00000000,0.00000000,0.00000000,0.00000000,0.00000000
300.65000000,7.99191200,4.63400000,0.25186756,456.52923501,0.00000000,0.00000000,0.00000000,0.00000000,0.00000000,0.00000000,0.00000000,0.00000000,0.00000000,0.00000000,0.00000000
302.16000000,8.07050700,4.56500000,0.25160467,449.73154032,0.00000000,0.00000000,0.00000000,0.00000000,0.00000000,0.00000000,0.00000000,0.00000000,0.00000000,0.00000000,0.00000000