File: lab_data/DP780_results/DATA/UT_00_1.csv
Time[s],Displacement[mm],Force[kN],EngStrain_longi,EngStress[MPa],TrueStrain,TrueStress[MPa],TrueStrainRate[1/s],PlasticStrain_longi,PlasticStress[MPa],PlasticStrain_thick,PlasticStrain_width,R-Value,Thickness[mm],Width[mm], Young's Modulus [MPa]
0.00000000,0.00000000,-0.01420000,0.00000000,-0.95030690,0.00000000,-0.95030690,0.00000000,0.00060850,406.70780687,0.00010344,-0.00071194,0.82825310,1.49300000,10.00840000,212000.29476832
1.50000000,0.00262700,0.28810000,0.00006133,19.28052238,0.00006133,19.28170492,0.00002889,0.00070651,420.68552935,0.00010251,-0.00080901,0.00000000,0.00000000,0.00000000,0.00000000
3.00000000,0.00457000,0.66050000,0.00008000,44.20265544,0.00008000,44.20619165,-0.00009910,0.00091121,433.37582135,-0.00016683,-0.00074438,0.00000000,0.00000000,0.00000000,0.00000000
4.50000000,0.00708100,1.00020000,0.00021033,66.93640570,0.00021031,66.95048466,-0.00003821,0.00122241,445.85127479,-0.00007196,-0.00115044,0.00000000,0.00000000,0.00000000,0.00000000
6.00000000,0.00994500,1.31760000,0.00033722,88.17777260,0.00033717,88.20750810,0.00013440,0.00152353,458.76215054,-0.00037517,-0.00114836,0.00000000,0.00000000,0.00000000,0.00000000
7.50000000,0.01206100,1.63980000,0.00039400,109.74037000,0.00039392,109.78360770,0.00008863,0.00188046,470.15293386,-0.00065330,-0.00122715,0.00000000,0.00000000,0.00000000,0.00000000
9.00000000,0.01429700,1.91650000,0.00047289,128.25796994,0.00047278,128.31862171,0.00020636,0.00224683,481.12634697,-0.00067227,-0.00157457,0.00000000,0.00000000,0.00000000,0.00000000
10.50000000,0.01581400,2.18530000,0.00049744,146.24687801,0.00049732,146.31962770,0.00010595,0.00277932,492.51447146,-0.00089868,-0.00188063,0.00000000,0.00000000,0.00000000,0.00000000
12.00000000,0.01802100,2.46920000,0.00059633,165.24632370,0.00059616,165.34486559,0.00006019,0.00330241,502.66969058,-0.00123074,-0.00207168,0.00000000,0.00000000,0.00000000,0.00000000
13.50000000,0.02039000,2.71400000,0.00064222,181.62907926,0.00064202,181.74572549,-0.00022429,0.00381030,512.07923278,-0.00156831,-0.00224199,0.00000000,0.00000000,0.00000000,0.00000000
15.00000000,0.02373300,2.95320000,0.00084878,197.63706591,0.00084842,197.80481586,0.00022360,0.00437668,522.44158464,-0.00190363,-0.00247305,0.00000000,0.00000000,0.00000000,0.00000000
16.50000000,0.02554300,3.20520000,0.00086056,214.50166723,0.00086019,214.68625783,0.00020939,0.00493919,531.19891941,-0.00215332,-0.00278586,0.00000000,0.00000000,0.00000000,0.00000000
18.00000000,0.02666500,3.43810000,0.00080967,230.08803884,0.00080934,230.27433346,-0.00014699,0.00562422,539.97889058,-0.00244326,-0.00318096,0.00000000,0.00000000,0.00000000,0.00000000
19.50000000,0.02960600,3.66460000,0.00095122,245.24610312,0.00095077,245.47938666,-0.00014541,0.00621145,548.88003795,-0.00275871,-0.00345274,0.00000000,0.00000000,0.00000000,0.00000000
21.00000000,0.03205000,3.89980000,0.00116189,260.98639768,0.00116121,261.28963488,0.00025528,0.00687524,557.24565973,-0.00317610,-0.00369913,0.00000000,0.00000000,0.00000000,0.00000000
22.50000000,0.03415100,4.11200000,0.00110211,275.18746276,0.00110150,275.49074992,0.00014274,0.00756205,564.59860957,-0.00355784,-0.00400421,0.00000000,0.00000000,0.00000000,0.00000000
24.00000000,0.03625400,4.32010000,0.00113956,289.11414345,0.00113891,289.44360508,-0.00021019,0.00836235,572.95660976,-0.00402738,-0.00433497,0.00000000,0.00000000,0.00000000,0.00000000
25.50000000,0.03930800,4.55300000,0.00135756,304.70051506,0.00135663,305.11416294,-0.00011229,0.00906566,580.50441145,-0.00439140,-0.00467427,0.00000000,0.00000000,0.00000000,0.00000000
27.00000000,0.04225300,4.75390000,0.00152311,318.14535000,0.00152195,318.62992072,0.00038279,0.00973513,587.99556088,-0.00461238,-0.00512275,0.00000000,0.00000000,0.00000000,0.00000000
28.50000000,0.04709200,4.96210000,0.00152356,332.07872300,0.00152240,332.58466338,0.00018018,0.01052223,595.56727887,-0.00503657,-0.00548567,0.00000000,0.00000000,0.00000000,0.00000000
30.00000000,0.05132000,5.18380000,0.00156456,346.91555677,0.00156333,347.45832543,-0.00023318,0.01138747,602.16355759,-0.00552683,-0.00586063,0.00000000,0.00000000,0.00000000,0.00000000
31.50000000,0.05483800,5.39350000,0.00186144,360.94931430,0.00185971,361.62120139,-0.00014217,0.01214428,608.81404399,-0.00594184,-0.00620244,0.00000000,0.00000000,0.00000000,0.00000000
33.00000000,0.05896200,5.59610000,0.00213211,374.50791837,0.00212984,375.30641087,0.00032245,0.01294658,615.88464978,-0.00639588,-0.00655070,0.00000000,0.00000000,0.00000000,0.00000000
34.50000000,0.06558400,5.80980000,0.00226678,388.80936798,0.00226421,389.69071242,0.00048673,0.01379944,622.28840808,-0.00689233,-0.00690711,0.00000000,0.00000000,0.00000000,0.00000000
36.00000000,0.07240800,6.00680000,0.00231533,401.99320314,0.00231266,402.92395140,0.00002993,0.01474751,628.66059309,-0.00745997,-0.00728755,0.00000000,0.00000000,0.00000000,0.00000000
37.50000000,0.07892500,6.19420000,0.00256333,414.53457729,0.00256005,415.59716759,-0.00012745,0.01558092,634.91011209,-0.00792482,-0.00765610,0.00000000,0.00000000,0.00000000,0.00000000
39.00000000,0.08841300,6.39990000,0.00297956,428.30064273,0.00297513,429.57678829,0.00013449,0.01641536,640.78734254,-0.00840046,-0.00801490,0.00000000,0.00000000,0.00000000,0.00000000
40.50000000,0.09817300,6.58410000,0.00332489,440.62786322,0.00331937,442.09290190,0.00022460,0.01730983,647.04892350,-0.00892477,-0.00838507,0.00000000,0.00000000,0.00000000,0.00000000
42.00000000,0.10830500,6.76440000,0.00361011,452.69408392,0.00360361,454.32835986,0.00021678,0.01820008,652.44101371,-0.00941306,-0.00878702,0.00000000,0.00000000,0.00000000,0.00000000
43.50000000,0.12066300,6.94620000,0.00398889,464.86068916,0.00398095,466.71496680,0.00020165,0.01911407,658.12584829,-0.00992434,-0.00918973,0.00000000,0.00000000,0.00000000,0.00000000
45.00000000,0.13312700,7.10570000,0.00448444,475.53491102,0.00447442,477.66742091,0.00029913,0.02006082,663.62965086,-0.01032084,-0.00973998,0.00000000,0.00000000,0.00000000,0.00000000
46.50000000,0.14751800,7.26520000,0.00500256,486.20913289,0.00499008,488.64142109,0.00053805,0.02101300,669.36731913,-0.01084121,-0.01017178,0.00000000,0.00000000,0.00000000,0.00000000
48.00000000,0.16373600,7.42470000,0.00542322,496.88335475,0.00540857,499.57806360,0.00056789,0.02196283,673.84720162,-0.01134479,-0.01061805,0.00000000,0.00000000,0.00000000,0.00000000
49.50000000,0.18046500,7.56500000,0.00594156,506.27265461,0.00592397,509.28070172,0.00032123,0.02291998,678.89150534,-0.01182736,-0.01109261,0.00000000,0.00000000,0.00000000,0.00000000
51.00000000,0.19868200,7.70060000,0.00654633,515.34741627,0.00652500,518.72105224,0.00009714,0.02388595,684.17192154,-0.01229806,-0.01158789,0.00000000,0.00000000,0.00000000,0.00000000
52.50000000,0.21811800,7.83930000,0.00730511,524.62963930,0.00727856,528.46211711,0.00049246,0.02489421,688.82842816,-0.01289860,-0.01199561,0.00000000,0.00000000,0.00000000,0.00000000
54.00000000,0.23853600,7.96540000,0.00794744,533.06863226,0.00791603,537.30516560,0.00046216,0.02583524,693.55766552,-0.01334524,-0.01249000,0.00000000,0.00000000,0.00000000,0.00000000
55.50000000,0.25939400,8.08340000,0.00857867,540.96554875,0.00854208,545.60631187,0.00037262,0.02686229,698.41104596,-0.01389777,-0.01296451,0.00000000,0.00000000,0.00000000,0.00000000
57.00000000,0.28028600,8.20780000,0.00931889,549.29077258,0.00927574,554.40955225,0.00023097,0.02787840,703.04448900,-0.01450444,-0.01337397,0.00000000,0.00000000,0.00000000,0.00000000
58.50000000,0.30226100,8.32100000,0.01016433,556.86645856,0.01011302,562.52663487,0.00037225,0.02891650,707.37648668,-0.01508207,-0.01383444,0.00000000,0.00000000,0.00000000,0.00000000
60.00000000,0.32474200,8.43270000,0.01089322,564.34176002,0.01083432,570.48926022,0.00057977,0.02994641,711.70410898,-0.01567971,-0.01426670,0.00000000,0.00000000,0.00000000,0.00000000
61.50000000,0.34817200,8.54030000,0.01162589,571.54267709,0.01155883,578.18736875,0.00037896,0.03095164,715.64009601,-0.01628917,-0.01466247,0.00000000,0.00000000,0.00000000,0.00000000
63.00000000,0.37248000,8.64480000,0.01245233,578.53613280,0.01237544,585.74025757,0.00042300,0.03206367,719.76491296,-0.01692909,-0.01513457,0.00000000,0.00000000,0.00000000,0.00000000
64.50000000,0.39675500,8.74370000,0.01329378,585.15481958,0.01320619,592.93373772,0.00051895,0.03308706,723.94524801,-0.01748419,-0.01560287,0.00000000,0.00000000,0.00000000,0.00000000
66.00000000,0.42069000,8.84500000,0.01415411,591.93412162,0.01405488,600.31242295,0.00081508,0.03415307,728.11588361,-0.01806437,-0.01608870,0.00000000,0.00000000,0.00000000,0.00000000
67.50000000,0.44611400,8.93510000,0.01487911,597.96388582,0.01476950,606.86105692,0.00045878,0.03522967,731.29730140,-0.01873264,-0.01649703,0.00000000,0.00000000,0.00000000,0.00000000
69.00000000,0.47194300,9.02280000,0.01579967,603.83303477,0.01567615,613.37339544,0.00054786,0.03633047,735.22249686,-0.01932283,-0.01700764,0.00000000,0.00000000,0.00000000,0.00000000
70.50000000,0.49861700,9.11850000,0.01670856,610.23756789,0.01657050,620.43375620,0.00069474,0.03739525,738.85601876,-0.01987338,-0.01752188,0.00000000,0.00000000,0.00000000,0.00000000
72.00000000,0.52410800,9.20060000,0.01761389,615.73194792,0.01746056,626.57738204,0.00078281,0.03845985,742.32833254,-0.02035993,-0.01809992,0.00000000,0.00000000,0.00000000,0.00000000
73.50000000,0.55142600,9.28440000,0.01841778,621.34009709,0.01825022,632.78380092,0.00061215,0.03956336,746.39039707,-0.02098210,-0.01858126,0.00000000,0.00000000,0.00000000,0.00000000
75.00000000,0.57965400,9.36890000,0.01938700,626.99509237,0.01920147,639.15064623,0.00057494,0.04064072,749.71794101,-0.02153149,-0.01910923,0.00000000,0.00000000,0.00000000,0.00000000
76.50000000,0.60707300,9.44710000,0.02034111,632.22847262,0.02013699,645.08870223,0.00057462,0.04168614,752.63421807,-0.02209276,-0.01959338,0.00000000,0.00000000,0.00000000,0.00000000
78.00000000,0.63526800,9.51880000,0.02128378,637.02685324,0.02106044,650.58519122,0.00074299,0.04281637,756.35186256,-0.02271624,-0.02010012,0.00000000,0.00000000,0.00000000,0.00000000
79.50000000,0.66383500,9.59460000,0.02218933,642.09961824,0.02194673,656.34738070,0.00063947,0.04394883,760.07879179,-0.02339418,-0.02055465,0.00000000,0.00000000,0.00000000,0.00000000
81.00000000,0.69318000,9.66720000,0.02321100,646.95822957,0.02294572,661.97477703,0.00070488,0.04504966,762.66078246,-0.02394503,-0.02110463,0.00000000,0.00000000,0.00000000,0.00000000
82.50000000,0.72147600,9.73020000,0.02419889,651.17437990,0.02391074,666.93207636,0.00076280,0.04617054,766.05371248,-0.02456236,-0.02160818,0.00000000,0.00000000,0.00000000,0.00000000
84.00000000,0.75142700,9.80350000,0.02513044,656.07983734,0.02481987,672.56741525,0.00065216,0.04730331,768.89712950,-0.02518088,-0.02212244,0.00000000,0.00000000,0.00000000,0.00000000
85.50000000,0.78215800,9.86970000,0.02614089,660.51014134,0.02580506,677.77646356,0.00061513,0.04843853,771.74797867,-0.02577029,-0.02266825,0.00000000,0.00000000,0.00000000,0.00000000
87.00000000,0.81190700,9.92870000,0.02722256,664.45859959,0.02685861,682.54686073,0.00073112,0.04953050,774.40073786,-0.02634421,-0.02318629,0.00000000,0.00000000,0.00000000,0.00000000
88.50000000,0.84294100,9.99010000,0.02821456,668.56767308,0.02782386,687.43101284,0.00076025,0.05069724,777.51395058,-0.02703190,-0.02366534,0.00000000,0.00000000,0.00000000,0.00000000
90.00000000,0.87380500,10.05070000,0.02926233,672.62320816,0.02884236,692.30573268,0.00072255,0.05189887,780.49036675,-0.02767520,-0.02422368,0.00000000,0.00000000,0.00000000,0.00000000
91.50000000,0.90500500,10.10180000,0.03031411,676.04297454,0.02986372,696.53661638,0.00064910,0.05307374,783.50872895,-0.02834609,-0.02472765,0.00000000,0.00000000,0.00000000,0.00000000
93.00000000,0.93634200,10.16320000,0.03138078,680.15204803,0.03089847,701.49574831,0.00072839,0.05421636,786.28706417,-0.02893473,-0.02528163,0.00000000,0.00000000,0.00000000,0.00000000
94.50000000,0.96818500,10.21660000,0.03241367,683.72573736,0.03189943,705.88779550,0.00065510,0.05536560,788.95489412,-0.02957815,-0.02578745,0.00000000,0.00000000,0.00000000,0.00000000
96.00000000,1.00097600,10.26530000,0.03352567,686.98488849,0.03297593,710.01651486,0.00065482,0.05653769,791.70312461,-0.03014002,-0.02639768,0.00000000,0.00000000,0.00000000,0.00000000
97.50000000,1.03261700,10.31950000,0.03460356,690.61211623,0.03401832,714.50975096,0.00069024,0.05770880,794.34169833,-0.03080241,-0.02690640,0.00000000,0.00000000,0.00000000,0.00000000
99.00000000,1.06513500,10.36650000,0.03568900,693.75749822,0.03506691,718.51700958,0.00074725,0.05888988,796.82889972,-0.03140088,-0.02748900,0.00000000,0.00000000,0.00000000,0.00000000
100.50000000,1.09796000,10.40720000,0.03677444,696.48126518,0.03611440,722.09397677,0.00060882,0.06006721,799.82634880,-0.03200137,-0.02806583,0.00000000,0.00000000,0.00000000,0.00000000
102.00000000,1.13118900,10.45750000,0.03792367,699.84749314,0.03722224,726.38827619,0.00067304,0.06125402,801.97711823,-0.03267997,-0.02857405,0.00000000,0.00000000,0.00000000,0.00000000
103.50000000,1.16468600,10.50370000,0.03910689,702.93933672,0.03836158,730.42910725,0.00073774,0.06247674,804.45520986,-0.03331680,-0.02915994,0.00000000,0.00000000,0.00000000,0.00000000
105.00000000,1.19805100,10.54040000,0.04017344,705.39541159,0.03938747,733.73357497,0.00077288,0.06365276,806.77821736,-0.03394430,-0.02970847,0.00000000,0.00000000,0.00000000,0.00000000
106.50000000,1.23205500,10.58740000,0.04134911,708.54079358,0.04051709,737.83832558,0.00072889,0.06484121,809.92166166,-0.03463622,-0.03020499,0.00000000,0.00000000,0.00000000,0.00000000
108.00000000,1.26630000,10.62730000,0.04250967,711.21102213,0.04163095,741.44436561,0.00070611,0.06610514,811.64165402,-0.03539423,-0.03071091,0.00000000,0.00000000,0.00000000,0.00000000
109.50000000,1.30101400,10.66480000,0.04366656,713.72063542,0.04274005,744.88635719,0.00087148,0.06724698,813.60408576,-0.03595460,-0.03129238,0.00000000,0.00000000,0.00000000,0.00000000
111.00000000,1.33478400,10.70550000,0.04481556,716.44440238,0.04384037,748.55225629,0.00089137,0.06849090,815.94967969,-0.03660956,-0.03188133,0.00000000,0.00000000,0.00000000,0.00000000
112.50000000,1.36980400,10.74300000,0.04595744,718.95401567,0.04493268,751.99530490,0.00077562,0.06965343,818.16796631,-0.03720157,-0.03245186,0.00000000,0.00000000,0.00000000,0.00000000
114.00000000,1.40421400,10.77960000,0.04717811,721.40339824,0.04609903,755.43784792,0.00084669,0.07092073,820.76626765,-0.03789810,-0.03302263,0.00000000,0.00000000,0.00000000,0.00000000
115.50000000,1.43970700,10.80990000,0.04830478,723.43116578,0.04717436,758.37634748,0.00079552,0.07211921,822.85629917,-0.03855201,-0.03356720,0.00000000,0.00000000,0.00000000,0.00000000
117.00000000,1.47523500,10.84500000,0.04949167,725.78016382,0.04830592,761.70023376,0.00078021,0.07338639,824.83289766,-0.03920153,-0.03418486,0.00000000,0.00000000,0.00000000,0.00000000
118.50000000,1.51126700,10.87610000,0.05065956,727.86146977,0.04941812,764.73460834,0.00061473,0.07462718,826.90031973,-0.03986172,-0.03476546,0.00000000,0.00000000,0.00000000,0.00000000
120.00000000,1.54679300,10.90800000,0.05194767,729.99631415,0.05064337,767.91791934,0.00085658,0.07583497,831.21458469,-0.04056911,-0.03526586,0.00000000,0.00000000,0.00000000,0.00000000
121.50000000,1.58306300,10.93910000,0.05313833,732.07762010,0.05177460,770.97900471,0.00089150,0.07704651,830.76908623,-0.04125820,-0.03578831,0.00000000,0.00000000,0.00000000,0.00000000
123.00000000,1.61886100,10.96620000,0.05426133,733.89123398,0.05284036,773.71315085,0.00054833,0.07832217,833.29279873,-0.04188768,-0.03643449,0.00000000,0.00000000,0.00000000,0.00000000
124.50000000,1.65540200,10.99810000,0.05558356,736.02607835,0.05409375,776.93702476,0.00085427,0.07962344,835.13457012,-0.04263083,-0.03699261,0.00000000,0.00000000,0.00000000,0.00000000
126.00000000,1.69251700,11.02210000,0.05677033,737.63223086,0.05521740,779.50785848,0.00086719,0.08090168,837.14326306,-0.04332143,-0.03758025,0.00000000,0.00000000,0.00000000,0.00000000
127.50000000,1.72983200,11.05320000,0.05800589,739.71353681,0.05638590,782.62127804,0.00075292,0.08215347,839.24332803,-0.04400234,-0.03815113,0.00000000,0.00000000,0.00000000,0.00000000
129.00000000,1.76698100,11.08190000,0.05924144,741.63422752,0.05755303,785.56971040,0.00072350,0.08349004,841.25032211,-0.04476861,-0.03872142,0.00000000,0.00000000,0.00000000,0.00000000
130.50000000,1.80396200,11.10420000,0.06049578,743.12661089,0.05873651,788.08263320,0.00072264,0.08476165,842.85375486,-0.04542818,-0.03933347,0.00000000,0.00000000,0.00000000,0.00000000
132.00000000,1.84144800,11.12970000,0.06179122,744.83314793,0.05995731,790.85729849,0.00084885,0.08610122,844.98079336,-0.04616048,-0.03994074,0.00000000,0.00000000,0.00000000,0.00000000
133.50000000,1.87913600,11.15760000,0.06298567,746.70030021,0.06108162,793.73171642,0.00081987,0.08734800,847.45278768,-0.04684969,-0.04049831,0.00000000,0.00000000,0.00000000,0.00000000
135.00000000,1.91763700,11.17680000,0.06428900,747.98522222,0.06230697,796.07244417,0.00080466,0.08870440,848.90262014,-0.04766598,-0.04103842,0.00000000,0.00000000,0.00000000,0.00000000
136.50000000,1.95573200,11.19910000,0.06554689,749.47760559,0.06348818,798.60353093,0.00080371,0.09002049,850.54927261,-0.04837979,-0.04164070,0.00000000,0.00000000,0.00000000,0.00000000
138.00000000,1.99433500,11.21980000,0.06680144,750.86291213,0.06466487,801.02163924,0.00079610,0.09133116,852.20156987,-0.04910813,-0.04222304,0.00000000,0.00000000,0.00000000,0.00000000
139.50000000,2.03256400,11.24460000,0.06808178,752.52260305,0.06586431,803.75567968,0.00079431,0.09268689,854.13225641,-0.04990666,-0.04278023,0.00000000,0.00000000,0.00000000,0.00000000
141.00000000,2.07160500,11.26050000,0.06941156,753.58667909,0.06710855,805.89430273,0.00085008,0.09401639,856.10339597,-0.05064501,-0.04337137,0.00000000,0.00000000,0.00000000,0.00000000
142.50000000,2.11020600,11.28440000,0.07070722,755.18613929,0.06831939,808.58325346,0.00080005,0.09529199,857.60881945,-0.05130370,-0.04398830,0.00000000,0.00000000,0.00000000,0.00000000
144.00000000,2.14850300,11.30280000,0.07196900,756.41752288,0.06949714,810.85613558,0.00077795,0.09667606,859.51500314,-0.05205894,-0.04461713,0.00000000,0.00000000,0.00000000,0.00000000
145.50000000,2.18862500,11.31950000,0.07330233,757.53513733,0.07074019,813.06423048,0.00081220,0.09800452,861.31720552,-0.05278792,-0.04521659,0.00000000,0.00000000,0.00000000,0.00000000
147.00000000,2.22776700,11.34030000,0.07460167,758.92713617,0.07195005,815.54436541,0.00081080,0.09935652,862.78539925,-0.05350864,-0.04584788,0.00000000,0.00000000,0.00000000,0.00000000
148.50000000,2.26738100,11.35300000,0.07593489,759.77705854,0.07318995,817.47064506,0.00087984,0.10067452,864.57722699,-0.05423318,-0.04644134,0.00000000,0.00000000,0.00000000,0.00000000
150.00000000,2.30692800,11.36980000,0.07729444,760.90136529,0.07445275,819.71481360,0.00092764,0.10204230,866.18396216,-0.05501189,-0.04703041,0.00000000,0.00000000,0.00000000,0.00000000
151.50000000,2.34694800,11.38650000,0.07856367,762.01897974,0.07563022,821.88598486,0.00082885,0.10340040,868.02450764,-0.05577099,-0.04762942,0.00000000,0.00000000,0.00000000,0.00000000
153.00000000,2.38639400,11.40490000,0.07993822,763.25036333,0.07690384,824.26324049,0.00082100,0.10473866,869.37158781,-0.05655703,-0.04818162,0.00000000,0.00000000,0.00000000,0.00000000
154.50000000,2.42698800,11.41600000,0.08129400,763.99320887,0.07815847,826.10127279,0.00079900,0.10609119,870.91330043,-0.05729788,-0.04879331,0.00000000,0.00000000,0.00000000,0.00000000
156.00000000,2.46690700,11.43280000,0.08257856,765.11751562,0.07934575,828.29981489,0.00075616,0.10752795,872.70422366,-0.05814583,-0.04938212,0.00000000,0.00000000,0.00000000,0.00000000
157.50000000,2.50777300,11.44630000,0.08387044,766.02097641,0.08053838,830.26749615,0.00072777,0.10892264,874.40890992,-0.05894201,-0.04998063,0.00000000,0.00000000,0.00000000,0.00000000
159.00000000,2.54863800,11.46390000,0.08532389,767.19882158,0.08187846,832.65920858,0.00090664,0.11022910,875.97877625,-0.05963595,-0.05059316,0.00000000,0.00000000,0.00000000,0.00000000
160.50000000,2.59021200,11.47580000,0.08674744,767.99520553,0.08318924,834.61682695,0.00089216,0.11170938,877.88556011,-0.06046984,-0.05123954,0.00000000,0.00000000,0.00000000,0.00000000
162.00000000,2.63128100,11.48700000,0.08808056,768.74474336,0.08441519,836.45620744,0.00077991,0.11313402,879.14238161,-0.06129268,-0.05184134,0.00000000,0.00000000,0.00000000,0.00000000
163.50000000,2.67289000,11.50220000,0.08957911,769.76197328,0.08579149,838.71656662,0.00098594,0.11453780,880.80636387,-0.06201503,-0.05252277,0.00000000,0.00000000,0.00000000,0.00000000
165.00000000,2.71459900,11.51490000,0.09100622,770.61189565,0.08710041,840.74237308,0.00111590,0.11597656,882.38304580,-0.06289121,-0.05308535,0.00000000,0.00000000,0.00000000,0.00000000
166.50000000,2.75634400,11.52690000,0.09238433,771.41497191,0.08836277,842.68162981,0.00090750,0.11743268,884.09171151,-0.06371746,-0.05371522,0.00000000,0.00000000,0.00000000,0.00000000
168.00000000,2.79835600,11.53250000,0.09377767,771.78974082,0.08963745,844.16638188,0.00089984,0.11885509,885.47708546,-0.06445582,-0.05439927,0.00000000,0.00000000,0.00000000,0.00000000
169.50000000,2.84016800,11.54840000,0.09531000,772.85381686,0.09103743,846.51451414,0.00100819,0.12030760,887.07412872,-0.06525327,-0.05505434,0.00000000,0.00000000,0.00000000,0.00000000
171.00000000,2.88268900,11.55880000,0.09668078,773.54981628,0.09228814,848.33721417,0.00082873,0.12179192,888.45839025,-0.06611318,-0.05567874,0.00000000,0.00000000,0.00000000,0.00000000
172.50000000,2.92541400,11.56600000,0.09814911,774.03166203,0.09362614,850.00218163,0.00089585,0.12324158,889.75277149,-0.06689637,-0.05634521,0.00000000,0.00000000,0.00000000,0.00000000
174.00000000,2.96827200,11.57710000,0.09956511,774.77450757,0.09491475,851.91501750,0.00076550,0.12478610,891.50095931,-0.06777533,-0.05701077,0.00000000,0.00000000,0.00000000,0.00000000
175.50000000,3.01025300,11.58510000,0.10106722,775.30989173,0.09627991,853.66830885,0.00085975,0.12629644,892.97673614,-0.06868834,-0.05760810,0.00000000,0.00000000,0.00000000,0.00000000
177.00000000,3.05311200,11.59150000,0.10255833,775.73819907,0.09763324,855.29661587,0.00096728,0.12777104,894.54555002,-0.06945995,-0.05831109,0.00000000,0.00000000,0.00000000,0.00000000
178.50000000,3.09610700,11.60420000,0.10401933,776.58812144,0.09895746,857.36830010,0.00092572,0.12930898,896.17407076,-0.07031219,-0.05899679,0.00000000,0.00000000,0.00000000,0.00000000
180.00000000,3.13988000,11.60980000,0.10555544,776.96289035,0.10034787,858.97555356,0.00092423,0.13087778,897.71023147,-0.07119882,-0.05967896,0.00000000,0.00000000,0.00000000,0.00000000
181.50000000,3.18243500,11.61460000,0.10698244,777.28412086,0.10163779,860.43987613,0.00090236,0.13251070,898.99867023,-0.07214307,-0.06036762,0.00000000,0.00000000,0.00000000,0.00000000
183.00000000,3.22695200,11.62340000,0.10847744,777.87304344,0.10298740,862.25472330,0.00090836,0.13404207,900.44411036,-0.07302030,-0.06102177,0.00000000,0.00000000,0.00000000,0.00000000
184.50000000,3.27082300,11.63130000,0.10999467,778.40173531,0.10435521,864.02177472,0.00096120,0.13560262,902.16567410,-0.07386465,-0.06173797,0.00000000,0.00000000,0.00000000,0.00000000
186.00000000,3.31523900,11.63530000,0.11152678,778.66942739,0.10573455,865.51191958,0.00095307,0.13726024,903.48299175,-0.07480818,-0.06245206,0.00000000,0.00000000,0.00000000,0.00000000
187.50000000,3.35901100,11.64170000,0.11295022,779.09773473,0.10701435,867.09699700,0.00083719,0.13897903,905.04394613,-0.07580951,-0.06316952,0.00000000,0.00000000,0.00000000,0.00000000
189.00000000,3.40312000,11.65370000,0.11450122,779.90081098,0.10840697,869.20040705,0.00093038,0.00000000,0.00000000,0.00000000,0.00000000,0.00000000,0.00000000,0.00000000,0.00000000
190.50000000,3.44810800,11.65690000,0.11607856,780.11496465,0.10982125,870.66958291,0.00099620,0.00000000,0.00000000,0.00000000,0.00000000,0.00000000,0.00000000,0.00000000,0.00000000
192.00000000,3.49225100,11.66160000,0.11760322,780.42950285,0.11118641,872.21052710,0.00096102,0.00000000,0.00000000,0.00000000,0.00000000,0.00000000,0.00000000,0.00000000,0.00000000
193.50000000,3.53801800,11.66800000,0.11917689,780.85781018,0.11259349,873.91801467,0.00102721,0.00000000,0.00000000,0.00000000,0.00000000,0.00000000,0.00000000,0.00000000,0.00000000
195.00000000,3.58263600,11.66960000,0.12070533,780.96488702,0.11395825,875.23151403,0.00087166,0.00000000,0.00000000,0.00000000,0.00000000,0.00000000,0.00000000,0.00000000,0.00000000
196.50000000,3.62890900,11.68000000,0.12229756,781.66088644,0.11537797,877.25610212,0.00093025,0.00000000,0.00000000,0.00000000,0.00000000,0.00000000,0.00000000,0.00000000,0.00000000
198.00000000,3.67423500,11.68320000,0.12387489,781.87504010,0.11678244,878.72972382,0.00085536,0.00000000,0.00000000,0.00000000,0.00000000,0.00000000,0.00000000,0.00000000,0.00000000
199.50000000,3.72091400,11.68400000,0.12546000,781.92857852,0.11819184,880.02933798,0.00083460,0.00000000,0.00000000,0.00000000,0.00000000,0.00000000,0.00000000,0.00000000,0.00000000
201.00000000,3.76654500,11.68960000,0.12711600,782.30334744,0.11966216,881.74661975,0.00100656,0.00000000,0.00000000,0.00000000,0.00000000,0.00000000,0.00000000,0.00000000,0.00000000
202.50000000,3.81373100,11.69430000,0.12878356,782.61788564,0.12114055,883.40619959,0.00111833,0.00000000,0.00000000,0.00000000,0.00000000,0.00000000,0.00000000,0.00000000,0.00000000
204.00000000,3.86054500,11.69750000,0.13040222,782.83203931,0.12257352,884.91507686,0.00095721,0.00000000,0.00000000,0.00000000,0.00000000,0.00000000,0.00000000,0.00000000,0.00000000
205.50000000,3.90796700,11.70230000,0.13216711,783.15326981,0.12413359,886.66037503,0.00106157,0.00000000,0.00000000,0.00000000,0.00000000,0.00000000,0.00000000,0.00000000,0.00000000
207.00000000,3.95569300,11.70310000,0.13370689,783.20680822,0.12549270,887.92695391,0.00092736,0.00000000,0.00000000,0.00000000,0.00000000,0.00000000,0.00000000,0.00000000,0.00000000
208.50000000,4.00301600,11.70630000,0.13535967,783.42096189,0.12694949,889.46456215,0.00086041,0.00000000,0.00000000,0.00000000,0.00000000,0.00000000,0.00000000,0.00000000,0.00000000
210.00000000,4.05108200,11.70630000,0.13712489,783.42096189,0.12850305,890.84747424,0.00092555,0.00000000,0.00000000,0.00000000,0.00000000,0.00000000,0.00000000,0.00000000,0.00000000
211.50000000,4.09823300,11.71190000,0.13885244,783.79573081,0.13002113,892.62768398,0.00105553,0.00000000,0.00000000,0.00000000,0.00000000,0.00000000,0.00000000,0.00000000,0.00000000
213.00000000,4.14666800,11.71110000,0.14054244,783.74219239,0.13150398,893.89123593,0.00105377,0.00000000,0.00000000,0.00000000,0.00000000,0.00000000,0.00000000,0.00000000,0.00000000
214.50000000,4.19591600,11.71350000,0.14230778,783.90280764,0.13305058,895.45827419,0.00098675,0.00000000,0.00000000,0.00000000,0.00000000,0.00000000,0.00000000,0.00000000,0.00000000
216.00000000,4.24482700,11.71510000,0.14411056,784.00988448,0.13462753,896.99398449,0.00098538,0.00000000,0.00000000,0.00000000,0.00000000,0.00000000,0.00000000,0.00000000,0.00000000
217.50000000,4.29454700,11.71990000,0.14595078,784.33111498,0.13623467,898.80485124,0.00104899,0.00000000,0.00000000,0.00000000,0.00000000,0.00000000,0.00000000,0.00000000,0.00000000
219.00000000,4.34355700,11.71830000,0.14771589,784.22403814,0.13777378,900.06638903,0.00104738,0.00000000,0.00000000,0.00000000,0.00000000,0.00000000,0.00000000,0.00000000,0.00000000
220.50000000,4.39267000,11.71990000,0.14959378,784.33111498,0.13940864,901.66216950,0.00111085,0.00000000,0.00000000,0.00000000,0.00000000,0.00000000,0.00000000,0.00000000,0.00000000
222.00000000,4.44330300,11.71990000,0.15150900,784.33111498,0.14107326,903.16433788,0.00123953,0.00000000,0.00000000,0.00000000,0.00000000,0.00000000,0.00000000,0.00000000,0.00000000
223.50000000,4.49285600,11.71590000,0.15334944,784.06342289,0.14267027,904.29911320,0.00110742,0.00000000,0.00000000,0.00000000,0.00000000,0.00000000,0.00000000,0.00000000,0.00000000
225.00000000,4.54352300,11.72150000,0.15522722,784.43819181,0.14429705,906.20435333,0.00097513,0.00000000,0.00000000,0.00000000,0.00000000,0.00000000,0.00000000,0.00000000,0.00000000
226.50000000,4.59452800,11.71670000,0.15721767,784.11696131,0.00000000,0.00000000,0.00000000,0.00000000,0.00000000,0.00000000,0.00000000,0.00000000,0.00000000,0.00000000,0.00000000
228.00000000,4.64448700,11.71830000,0.15920822,784.22403814,0.00000000,0.00000000,0.00000000,0.00000000,0.00000000,0.00000000,0.00000000,0.00000000,0.00000000,0.00000000,0.00000000
229.50000000,4.69593300,11.71670000,0.16112367,784.11696131,0.00000000,0.00000000,0.00000000,0.00000000,0.00000000,0.00000000,0.00000000,0.00000000,0.00000000,0.00000000,0.00000000
231.00000000,4.74744500,11.71430000,0.16322667,783.95634606,0.00000000,0.00000000,0.00000000,0.00000000,0.00000000,0.00000000,0.00000000,0.00000000,0.00000000,0.00000000,0.00000000
232.50000000,4.79963300,11.71590000,0.16521722,784.06342289,0.00000000,0.00000000,0.00000000,0.00000000,0.00000000,0.00000000,0.00000000,0.00000000,0.00000000,0.00000000,0.00000000
234.00000000,4.85097600,11.71670000,0.16724544,784.11696131,0.00000000,0.00000000,0.00000000,0.00000000,0.00000000,0.00000000,0.00000000,0.00000000,0.00000000,0.00000000,0.00000000
235.50000000,4.90407900,11.71190000,0.16942378,783.79573081,0.00000000,0.00000000,0.00000000,0.00000000,0.00000000,0.00000000,0.00000000,0.00000000,0.00000000,0.00000000,0.00000000
237.00000000,4.95657000,11.71270000,0.17156444,783.84926923,0.00000000,0.00000000,0.00000000,0.00000000,0.00000000,0.00000000,0.00000000,0.00000000,0.00000000,0.00000000,0.00000000
238.50000000,5.00980800,11.70950000,0.17381778,783.63511556,0.00000000,0.00000000,0.00000000,0.00000000,0.00000000,0.00000000,0.00000000,0.00000000,0.00000000,0.00000000,0.00000000
240.00000000,5.06321400,11.71110000,0.17595844,783.74219239,0.00000000,0.00000000,0.00000000,0.00000000,0.00000000,0.00000000,0.00000000,0.00000000,0.00000000,0.00000000,0.00000000
241.50000000,5.11685400,11.70710000,0.17821144,783.47450031,0.00000000,0.00000000,0.00000000,0.00000000,0.00000000,0.00000000,0.00000000,0.00000000,0.00000000,0.00000000,0.00000000
243.00000000,5.17113900,11.70550000,0.18057767,783.36742347,0.00000000,0.00000000,0.00000000,0.00000000,0.00000000,0.00000000,0.00000000,0.00000000,0.00000000,0.00000000,0.00000000
244.50000000,5.22626900,11.69750000,0.18290622,782.83203931,0.00000000,0.00000000,0.00000000,0.00000000,0.00000000,0.00000000,0.00000000,0.00000000,0.00000000,0.00000000,0.00000000
246.00000000,5.28102800,11.69750000,0.18519711,782.83203931,0.00000000,0.00000000,0.00000000,0.00000000,0.00000000,0.00000000,0.00000000,0.00000000,0.00000000,0.00000000,0.00000000
247.50000000,5.33574900,11.68800000,0.18760067,782.19627060,0.00000000,0.00000000,0.00000000,0.00000000,0.00000000,0.00000000,0.00000000,0.00000000,0.00000000,0.00000000,0.00000000
249.00000000,5.39246800,11.69040000,0.19015444,782.35688586,0.00000000,0.00000000,0.00000000,0.00000000,0.00000000,0.00000000,0.00000000,0.00000000,0.00000000,0.00000000,0.00000000
250.50000000,5.44847600,11.68160000,0.19274589,781.76796327,0.00000000,0.00000000,0.00000000,0.00000000,0.00000000,0.00000000,0.00000000,0.00000000,0.00000000,0.00000000,0.00000000
252.00000000,5.50445200,11.68720000,0.19526189,782.14273219,0.00000000,0.00000000,0.00000000,0.00000000,0.00000000,0.00000000,0.00000000,0.00000000,0.00000000,0.00000000,0.00000000
253.50000000,5.56093400,11.67440000,0.19785322,781.28611752,0.00000000,0.00000000,0.00000000,0.00000000,0.00000000,0.00000000,0.00000000,0.00000000,0.00000000,0.00000000,0.00000000
255.00000000,5.61883300,11.66160000,0.20055711,780.42950285,0.00000000,0.00000000,0.00000000,0.00000000,0.00000000,0.00000000,0.00000000,0.00000000,0.00000000,0.00000000,0.00000000
256.50000000,5.67680200,11.65370000,0.20348633,779.90081098,0.00000000,0.00000000,0.00000000,0.00000000,0.00000000,0.00000000,0.00000000,0.00000000,0.00000000,0.00000000,0.00000000
258.00000000,5.73443100,11.64650000,0.20630267,779.41896523,0.00000000,0.00000000,0.00000000,0.00000000,0.00000000,0.00000000,0.00000000,0.00000000,0.00000000,0.00000000,0.00000000
259.50000000,5.79253600,11.64010000,0.20911911,778.99065789,0.00000000,0.00000000,0.00000000,0.00000000,0.00000000,0.00000000,0.00000000,0.00000000,0.00000000,0.00000000,0.00000000
261.00000000,5.85080800,11.62260000,0.21197300,777.81950503,0.00000000,0.00000000,0.00000000,0.00000000,0.00000000,0.00000000,0.00000000,0.00000000,0.00000000,0.00000000,0.00000000
262.50000000,5.91009600,11.61620000,0.21490211,777.39119769,0.00000000,0.00000000,0.00000000,0.00000000,0.00000000,0.00000000,0.00000000,0.00000000,0.00000000,0.00000000,0.00000000
264.00000000,5.96918000,11.59860000,0.21764389,776.21335252,0.00000000,0.00000000,0.00000000,0.00000000,0.00000000,0.00000000,0.00000000,0.00000000,0.00000000,0.00000000,0.00000000
265.50000000,6.02853500,11.58510000,0.22042311,775.30989173,0.00000000,0.00000000,0.00000000,0.00000000,0.00000000,0.00000000,0.00000000,0.00000000,0.00000000,0.00000000,0.00000000
267.00000000,6.08913900,11.56990000,0.22339000,774.29266181,0.00000000,0.00000000,0.00000000,0.00000000,0.00000000,0.00000000,0.00000000,0.00000000,0.00000000,0.00000000,0.00000000
268.50000000,6.14950900,11.54840000,0.22646944,772.85381686,0.00000000,0.00000000,0.00000000,0.00000000,0.00000000,0.00000000,0.00000000,0.00000000,0.00000000,0.00000000,0.00000000
270.00000000,6.21038400,11.53170000,0.22966156,771.73620241,0.00000000,0.00000000,0.00000000,0.00000000,0.00000000,0.00000000,0.00000000,0.00000000,0.00000000,0.00000000,0.00000000
271.50000000,6.27092400,11.50610000,0.23277856,770.02297307,0.00000000,0.00000000,0.00000000,0.00000000,0.00000000,0.00000000,0.00000000,0.00000000,0.00000000,0.00000000,0.00000000
273.00000000,6.33190200,11.47900000,0.23582056,768.20935920,0.00000000,0.00000000,0.00000000,0.00000000,0.00000000,0.00000000,0.00000000,0.00000000,0.00000000,0.00000000,0.00000000
274.50000000,6.39318300,11.44950000,0.23874956,766.23513007,0.00000000,0.00000000,0.00000000,0.00000000,0.00000000,0.00000000,0.00000000,0.00000000,0.00000000,0.00000000,0.00000000
276.00000000,6.45507600,11.41920000,0.24141578,764.20736253,0.00000000,0.00000000,0.00000000,0.00000000,0.00000000,0.00000000,0.00000000,0.00000000,0.00000000,0.00000000,0.00000000
277.50000000,6.51666400,11.38410000,0.24411944,761.85836449,0.00000000,0.00000000,0.00000000,0.00000000,0.00000000,0.00000000,0.00000000,0.00000000,0.00000000,0.00000000,0.00000000
279.00000000,6.57940500,11.34820000,0.24719878,759.45582804,0.00000000,0.00000000,0.00000000,0.00000000,0.00000000,0.00000000,0.00000000,0.00000000,0.00000000,0.00000000,0.00000000
280.50000000,6.64235000,11.30760000,0.25012800,756.73875338,0.00000000,0.00000000,0.00000000,0.00000000,0.00000000,0.00000000,0.00000000,0.00000000,0.00000000,0.00000000,0.00000000
282.00000000,6.70489100,11.25250000,0.25290711,753.05129492,0.00000000,0.00000000,0.00000000,0.00000000,0.00000000,0.00000000,0.00000000,0.00000000,0.00000000,0.00000000,0.00000000
283.50000000,6.76791100,11.20070000,0.25553589,749.58468242,0.00000000,0.00000000,0.00000000,0.00000000,0.00000000,0.00000000,0.00000000,0.00000000,0.00000000,0.00000000,0.00000000
285.00000000,6.83201900,11.14250000,0.25823967,745.68976260,0.00000000,0.00000000,0.00000000,0.00000000,0.00000000,0.00000000,0.00000000,0.00000000,0.00000000,0.00000000,0.00000000
286.50000000,6.89644000,11.06830000,0.26049300,740.72407443,0.00000000,0.00000000,0.00000000,0.00000000,0.00000000,0.00000000,0.00000000,0.00000000,0.00000000,0.00000000,0.00000000
288.00000000,6.96195200,10.99180000,0.26267133,735.60446332,0.00000000,0.00000000,0.00000000,0.00000000,0.00000000,0.00000000,0.00000000,0.00000000,0.00000000,0.00000000,0.00000000
289.50000000,7.02812600,10.90090000,0.26477456,729.52116070,0.00000000,0.00000000,0.00000000,0.00000000,0.00000000,0.00000000,0.00000000,0.00000000,0.00000000,0.00000000,0.00000000
291.00000000,7.09591000,10.76850000,0.26687767,720.66055270,0.00000000,0.00000000,0.00000000,0.00000000,0.00000000,0.00000000,0.00000000,0.00000000,0.00000000,0.00000000,0.00000000
292.00000000,7.14361300,10.66640000,0.26822978,713.82771225,0.00000000,0.00000000,0.00000000,0.00000000,0.00000000,0.00000000,0.00000000,0.00000000,0.00000000,0.00000000,0.00000000