File: LAB_DATA/DP780_results/DATA/UT_30_2.csv
Time[s],Displacement[mm],Force[kN],EngStrain_longi,EngStress[MPa],TrueStrain,TrueStress[MPa],TrueStrainRate[1/s],PlasticStrain_longi,PlasticStress[MPa],PlasticStrain_thick,PlasticStrain_width,R-Value,Thickness[mm],Width[mm], Young's Modulus [MPa]
0.00000000,0.00000000,-0.02770000,0.00000000,-1.84520215,0.00000000,-1.84520215,0.00000000,0.00067661,422.72749548,0.00016809,-0.00084471,0.82143756,1.50530000,9.97270000,220229.00414620
1.50000000,0.00198100,0.39170000,0.00003600,26.09262395,0.00003600,26.09356328,-0.00000444,0.00080563,434.95861984,0.00002617,-0.00083180,0.00000000,0.00000000,0.00000000,0.00000000
3.00000000,0.00338000,0.72830000,0.00008078,48.51482773,0.00008077,48.51874665,-0.00001955,0.00107789,447.73401261,-0.00002942,-0.00104847,0.00000000,0.00000000,0.00000000,0.00000000
4.50000000,0.00618700,1.08630000,0.00018933,72.36256675,0.00018932,72.37626739,0.00000911,0.00136654,459.34628926,-0.00007630,-0.00129024,0.00000000,0.00000000,0.00000000,0.00000000
6.00000000,0.00833800,1.39180000,0.00026256,92.71308147,0.00026252,92.73742380,0.00006754,0.00168682,470.61280711,-0.00031158,-0.00137524,0.00000000,0.00000000,0.00000000,0.00000000
7.50000000,0.01110300,1.67490000,0.00035178,111.57144716,0.00035172,111.61069551,0.00012707,0.00203850,482.27168892,-0.00057771,-0.00146079,0.00000000,0.00000000,0.00000000,0.00000000
9.00000000,0.01345400,1.96040000,0.00041800,130.58968595,0.00041791,130.64427244,0.00014350,0.00249617,492.07357897,-0.00078990,-0.00170627,0.00000000,0.00000000,0.00000000,0.00000000
10.50000000,0.01551900,2.21640000,0.00047456,147.64281777,0.00047444,147.71288249,0.00013905,0.00291468,501.43593485,-0.00089929,-0.00201539,0.00000000,0.00000000,0.00000000,0.00000000
12.00000000,0.01673600,2.47150000,0.00052633,164.63599716,0.00052619,164.72265057,0.00008662,0.00329152,511.63847401,-0.00104077,-0.00225075,0.00000000,0.00000000,0.00000000,0.00000000
13.50000000,0.01820700,2.73310000,0.00056389,182.06216623,0.00056373,182.16482906,0.00000555,0.00373471,520.43962226,-0.00129123,-0.00244348,0.00000000,0.00000000,0.00000000,0.00000000
15.00000000,0.02060600,2.96920000,0.00065922,197.78968350,0.00065901,197.92007085,-0.00009194,0.00430619,528.83316237,-0.00164082,-0.00266537,0.00000000,0.00000000,0.00000000,0.00000000
16.50000000,0.02350400,3.20600000,0.00074067,213.56383043,0.00074039,213.72201004,-0.00007794,0.00490178,537.57275798,-0.00199477,-0.00290701,0.00000000,0.00000000,0.00000000,0.00000000
18.00000000,0.02622700,3.45720000,0.00088111,230.29721602,0.00088072,230.50013345,0.00006306,0.00545707,545.33845222,-0.00223882,-0.00321826,0.00000000,0.00000000,0.00000000,0.00000000
19.50000000,0.02862400,3.69170000,0.00097944,245.91815121,0.00097897,246.15901438,0.00029329,0.00608192,553.25281573,-0.00251971,-0.00356221,0.00000000,0.00000000,0.00000000,0.00000000
21.00000000,0.03083900,3.92530000,0.00096500,261.47913399,0.00096453,261.73146135,0.00014298,0.00677445,561.00652528,-0.00293871,-0.00383574,0.00000000,0.00000000,0.00000000,0.00000000
22.50000000,0.03315600,4.17020000,0.00099967,277.79285266,0.00099917,278.07055292,0.00001554,0.00736413,568.32804560,-0.00321050,-0.00415363,0.00000000,0.00000000,0.00000000,0.00000000
24.00000000,0.03601700,4.39820000,0.00110933,292.98079818,0.00110872,293.30581155,-0.00013451,0.00796541,575.50992782,-0.00351513,-0.00445027,0.00000000,0.00000000,0.00000000,0.00000000
25.50000000,0.03921300,4.62470000,0.00121489,308.06882301,0.00121415,308.44309240,-0.00021728,0.00866600,582.81282532,-0.00393436,-0.00473164,0.00000000,0.00000000,0.00000000,0.00000000
27.00000000,0.04210200,4.86480000,0.00146322,324.06279546,0.00146215,324.53697135,0.00017287,0.00935777,589.52591857,-0.00431914,-0.00503863,0.00000000,0.00000000,0.00000000,0.00000000
28.50000000,0.04533200,5.08010000,0.00158389,338.40474577,0.00158264,338.94074129,0.00033772,0.00998391,595.88441313,-0.00464997,-0.00533394,0.00000000,0.00000000,0.00000000,0.00000000
30.00000000,0.05041900,5.29940000,0.00160322,353.01315127,0.00160194,353.57910980,0.00020280,0.01066294,602.71635416,-0.00502958,-0.00563335,0.00000000,0.00000000,0.00000000,0.00000000
31.50000000,0.05624000,5.52430000,0.00170867,367.99459402,0.00170721,368.62337411,-0.00006744,0.01145396,609.24668564,-0.00546361,-0.00599035,0.00000000,0.00000000,0.00000000,0.00000000
33.00000000,0.06155600,5.72920000,0.00190811,381.64376085,0.00190629,382.37197955,-0.00019451,0.01219942,615.11487346,-0.00589296,-0.00630646,0.00000000,0.00000000,0.00000000,0.00000000
34.50000000,0.06734800,5.93020000,0.00221256,395.03313387,0.00221011,395.90716663,-0.00002195,0.01293777,621.52364294,-0.00624780,-0.00668997,0.00000000,0.00000000,0.00000000,0.00000000
36.00000000,0.07458700,6.13430000,0.00247156,408.62900966,0.00246851,409.63895896,0.00028487,0.01376531,627.78069441,-0.00669482,-0.00707049,0.00000000,0.00000000,0.00000000,0.00000000
37.50000000,0.08202200,6.32890000,0.00269322,421.59205439,0.00268960,422.72749548,0.00044219,0.01455931,633.10872229,-0.00711668,-0.00744263,0.00000000,0.00000000,0.00000000,0.00000000
39.00000000,0.08969200,6.51080000,0.00288100,433.70910391,0.00287686,434.95861984,0.00017949,0.01537094,639.26627968,-0.00754723,-0.00782371,0.00000000,0.00000000,0.00000000,0.00000000
40.50000000,0.09953000,6.69980000,0.00321511,446.29911138,0.00320995,447.73401261,0.00013490,0.01618094,644.84009670,-0.00793996,-0.00824098,0.00000000,0.00000000,0.00000000,0.00000000
42.00000000,0.10922700,6.87120000,0.00356022,457.71671604,0.00355390,459.34628926,0.00014925,0.01704653,650.18637560,-0.00843545,-0.00861108,0.00000000,0.00000000,0.00000000,0.00000000
43.50000000,0.12013400,7.03710000,0.00393556,468.76794482,0.00392783,470.61280711,0.00021694,0.01790541,656.02180956,-0.00890784,-0.00899757,0.00000000,0.00000000,0.00000000,0.00000000
45.00000000,0.13371100,7.20850000,0.00434444,480.18554948,0.00433503,482.27168892,0.00020158,0.01875284,660.99205282,-0.00935100,-0.00940184,0.00000000,0.00000000,0.00000000,0.00000000
46.50000000,0.14634200,7.35130000,0.00485111,489.69799957,0.00483938,492.07357897,0.00038838,0.01960331,665.91782415,-0.00985503,-0.00974828,0.00000000,0.00000000,0.00000000,0.00000000
48.00000000,0.16019500,7.48770000,0.00531656,498.78412136,0.00530247,501.43593485,0.00058276,0.02047323,671.24801442,-0.01035413,-0.01011910,0.00000000,0.00000000,0.00000000,0.00000000
49.50000000,0.17637500,7.63680000,0.00574433,508.71623837,0.00572790,511.63847401,0.00049256,0.02137393,676.11499443,-0.01089715,-0.01047678,0.00000000,0.00000000,0.00000000,0.00000000
51.00000000,0.19241900,7.76440000,0.00623233,517.21615875,0.00621299,520.43962226,0.00020893,0.02230839,680.62954923,-0.01144023,-0.01086816,0.00000000,0.00000000,0.00000000,0.00000000
52.50000000,0.21093100,7.88480000,0.00684778,525.23645981,0.00682444,528.83316237,0.00024589,0.02317308,685.76297155,-0.01188795,-0.01128513,0.00000000,0.00000000,0.00000000,0.00000000
54.00000000,0.22826300,8.01000000,0.00748956,533.57650708,0.00746165,537.57275798,0.00037986,0.02413861,690.26052025,-0.01246479,-0.01167382,0.00000000,0.00000000,0.00000000,0.00000000
55.50000000,0.24826500,8.12090000,0.00808644,540.96397708,0.00805392,545.33845222,0.00035736,0.02504863,694.73449219,-0.01292998,-0.01211865,0.00000000,0.00000000,0.00000000,0.00000000
57.00000000,0.26623800,8.23330000,0.00875456,548.45136776,0.00871646,553.25281573,0.00026767,0.02600014,699.51375498,-0.01346662,-0.01253352,0.00000000,0.00000000,0.00000000,0.00000000
58.50000000,0.28698700,8.34260000,0.00949067,555.73225568,0.00944591,561.00652528,0.00063254,0.02695824,703.47962446,-0.01397956,-0.01297868,0.00000000,0.00000000,0.00000000,0.00000000
60.00000000,0.30699200,8.44620000,0.01012133,562.63344496,0.01007046,568.32804560,0.00069883,0.02792776,707.85380711,-0.01452595,-0.01340182,0.00000000,0.00000000,0.00000000,0.00000000
61.50000000,0.32791000,8.54750000,0.01076344,569.38142251,0.01070593,575.50992782,0.00054972,0.02885742,712.03492658,-0.01496378,-0.01389365,0.00000000,0.00000000,0.00000000,0.00000000
63.00000000,0.34848700,8.64960000,0.01150700,576.18269110,0.01144130,582.81282532,0.00054184,0.02983455,715.98800274,-0.01548980,-0.01434475,0.00000000,0.00000000,0.00000000,0.00000000
64.50000000,0.37082400,8.74290000,0.01223933,582.39775828,0.01216504,589.52591857,0.00058625,0.03085767,719.97457827,-0.01600329,-0.01485438,0.00000000,0.00000000,0.00000000,0.00000000
66.00000000,0.39285700,8.83140000,0.01290400,588.29307923,0.01282145,595.88441313,0.00045968,0.03182406,724.20447914,-0.01651808,-0.01530598,0.00000000,0.00000000,0.00000000,0.00000000
67.50000000,0.41681800,8.92630000,0.01362500,594.61472849,0.01353301,602.71635416,0.00028152,0.03284939,728.04843879,-0.01706437,-0.01578502,0.00000000,0.00000000,0.00000000,0.00000000
69.00000000,0.44010100,9.01560000,0.01445867,600.56334048,0.01435514,609.24668564,0.00035556,0.03391501,731.54065176,-0.01770144,-0.01621357,0.00000000,0.00000000,0.00000000,0.00000000
70.50000000,0.46412900,9.09540000,0.01524356,605.87912142,0.01512854,615.11487346,0.00045906,0.03490093,735.58514601,-0.01823598,-0.01666494,0.00000000,0.00000000,0.00000000,0.00000000
72.00000000,0.48738100,9.18310000,0.01602444,611.72115134,0.01589741,621.52364294,0.00037710,0.03592475,739.06021556,-0.01883876,-0.01708599,0.00000000,0.00000000,0.00000000,0.00000000
73.50000000,0.51269500,9.26760000,0.01689589,617.35001711,0.01675474,627.78069441,0.00043601,0.03694842,742.31886971,-0.01943647,-0.01751195,0.00000000,0.00000000,0.00000000,0.00000000
75.00000000,0.53753500,9.33860000,0.01772944,622.07959664,0.01757411,633.10872229,0.00050183,0.03801484,746.22180324,-0.01999681,-0.01801803,0.00000000,0.00000000,0.00000000,0.00000000
76.50000000,0.56406500,9.42150000,0.01858567,627.60188034,0.01841506,639.26627968,0.00057539,0.03906192,749.39923641,-0.02056077,-0.01850116,0.00000000,0.00000000,0.00000000,0.00000000
78.00000000,0.58927700,9.49570000,0.01943811,632.54462401,0.01925160,644.84009670,0.00053065,0.04010812,752.52606130,-0.02112919,-0.01897893,0.00000000,0.00000000,0.00000000,0.00000000
79.50000000,0.61557200,9.56590000,0.02034689,637.22091250,0.02014266,650.18637560,0.00055937,0.04121859,756.26679431,-0.02175096,-0.01946762,0.00000000,0.00000000,0.00000000,0.00000000
81.00000000,0.64223900,9.64320000,0.02125200,642.37015894,0.02102933,656.02180956,0.00066944,0.04230282,759.21105905,-0.02232333,-0.01997949,0.00000000,0.00000000,0.00000000,0.00000000
82.50000000,0.66991800,9.70780000,0.02214200,646.67341017,0.02190043,660.99205282,0.00066147,0.04328097,762.36003650,-0.02284675,-0.02043422,0.00000000,0.00000000,0.00000000,0.00000000
84.00000000,0.69739500,9.77160000,0.02303567,650.92337037,0.02277435,665.91782415,0.00058723,0.04451922,765.54602710,-0.02356934,-0.02094988,0.00000000,0.00000000,0.00000000,0.00000000
85.50000000,0.72480500,9.84100000,0.02395200,655.54636782,0.02366965,671.24801442,0.00059408,0.04557089,768.53870374,-0.02413651,-0.02143438,0.00000000,0.00000000,0.00000000,0.00000000
87.00000000,0.75350000,9.90320000,0.02489844,659.68974594,0.02459353,676.11499443,0.00065253,0.04667290,771.23840225,-0.02473256,-0.02194034,0.00000000,0.00000000,0.00000000,0.00000000
88.50000000,0.78236400,9.95980000,0.02587867,663.46008680,0.02554948,680.62954923,0.00071041,0.04776276,774.72211844,-0.02526658,-0.02249618,0.00000000,0.00000000,0.00000000,0.00000000
90.00000000,0.81126000,10.02600000,0.02679122,667.86992010,0.02643862,685.76297155,0.00059266,0.04886582,777.43367606,-0.02588478,-0.02298105,0.00000000,0.00000000,0.00000000,0.00000000
91.50000000,0.83978600,10.08180000,0.02780511,671.58696993,0.02742557,690.26052025,0.00068680,0.05002650,780.47767536,-0.02654375,-0.02348276,0.00000000,0.00000000,0.00000000,0.00000000
93.00000000,0.86983300,10.13770000,0.02876278,675.31068113,0.02835689,694.73449219,0.00062069,0.05112697,783.19789597,-0.02712709,-0.02399989,0.00000000,0.00000000,0.00000000,0.00000000
94.50000000,0.89974600,10.19750000,0.02976556,679.29418614,0.02933116,699.51375498,0.00064189,0.05228305,785.91759010,-0.02778480,-0.02449825,0.00000000,0.00000000,0.00000000,0.00000000
96.00000000,0.92989400,10.24530000,0.03077211,682.47832560,0.03030814,703.47962446,0.00072170,0.05341353,788.50197949,-0.02841499,-0.02499854,0.00000000,0.00000000,0.00000000,0.00000000
97.50000000,0.96075200,10.29880000,0.03179344,686.04216369,0.03129850,707.85380711,0.00070612,0.05456927,791.45156243,-0.02904583,-0.02552344,0.00000000,0.00000000,0.00000000,0.00000000
99.00000000,0.99157700,10.34980000,0.03277367,689.43946729,0.03224806,712.03492658,0.00063270,0.05570116,793.93380003,-0.02969138,-0.02600978,0.00000000,0.00000000,0.00000000,0.00000000
100.50000000,1.02301000,10.39690000,0.03380278,692.57697709,0.03324402,715.98800274,0.00060326,0.05686984,796.56378856,-0.03035780,-0.02651204,0.00000000,0.00000000,0.00000000,0.00000000
102.00000000,1.05400400,10.44390000,0.03488067,695.70782551,0.03428612,719.97457827,0.00073323,0.05805149,799.15951848,-0.03097907,-0.02707242,0.00000000,0.00000000,0.00000000,0.00000000
103.50000000,1.08618000,10.49490000,0.03590211,699.10512911,0.03527265,724.20447914,0.00065268,0.05921706,801.85421892,-0.03161941,-0.02759765,0.00000000,0.00000000,0.00000000,0.00000000
105.00000000,1.11818900,10.53960000,0.03698378,702.08276580,0.03631629,728.04843879,0.00067365,0.06036486,804.31166577,-0.03223565,-0.02812922,0.00000000,0.00000000,0.00000000,0.00000000
106.50000000,1.15060200,10.57870000,0.03810667,704.68736523,0.03739854,731.54065176,0.00071639,0.06154842,807.08826653,-0.03290795,-0.02864047,0.00000000,0.00000000,0.00000000,0.00000000
108.00000000,1.18338700,10.62650000,0.03915067,707.87150469,0.03840371,735.58514601,0.00070840,0.06271310,809.11885019,-0.03354104,-0.02917206,0.00000000,0.00000000,0.00000000,0.00000000
109.50000000,1.21647700,10.66560000,0.04023233,710.47610412,0.03944409,739.06021556,0.00067176,0.06391614,811.63518388,-0.03418172,-0.02973442,0.00000000,0.00000000,0.00000000,0.00000000
111.00000000,1.24872300,10.70150000,0.04131389,712.86753940,0.04048327,742.31886971,0.00061321,0.06511145,813.98534384,-0.03484657,-0.03026488,0.00000000,0.00000000,0.00000000,0.00000000
112.50000000,1.28198300,10.74610000,0.04244433,715.83851470,0.04156828,746.22180324,0.00074945,0.06631639,816.22595390,-0.03547758,-0.03083881,0.00000000,0.00000000,0.00000000,0.00000000
114.00000000,1.31574800,10.78040000,0.04355222,718.12336791,0.04263049,749.39923641,0.00077038,0.06754154,818.32223363,-0.03621309,-0.03132845,0.00000000,0.00000000,0.00000000,0.00000000
115.50000000,1.34978400,10.81390000,0.04466011,720.35493008,0.04369158,752.52606130,0.00074786,0.06870759,820.76930892,-0.03682672,-0.03188088,0.00000000,0.00000000,0.00000000,0.00000000
117.00000000,1.38503800,10.85540000,0.04583944,723.11940262,0.04481986,756.26679431,0.00083332,0.06990997,822.62464706,-0.03747206,-0.03243791,0.00000000,0.00000000,0.00000000,0.00000000
118.50000000,1.41849900,10.88570000,0.04698867,725.13780065,0.04591811,759.21105905,0.00081796,0.07110522,824.93154662,-0.03814740,-0.03295782,0.00000000,0.00000000,0.00000000,0.00000000
120.00000000,1.45331200,10.92000000,0.04802900,727.42265385,0.04691126,762.36003650,0.00060228,0.07230437,826.84910860,-0.03877474,-0.03352963,0.00000000,0.00000000,0.00000000,0.00000000
121.50000000,1.48816100,10.95190000,0.04934344,729.54763395,0.04816468,765.54602710,0.00098795,0.07357958,829.28869384,-0.03953472,-0.03404486,0.00000000,0.00000000,0.00000000,0.00000000
123.00000000,1.52304200,10.98300000,0.05046256,731.61932301,0.04923060,768.53870374,0.00062903,0.07479878,831.45489131,-0.04019254,-0.03460624,0.00000000,0.00000000,0.00000000,0.00000000
124.50000000,1.55924100,11.00930000,0.05163433,733.37126585,0.05034546,771.23840225,0.00082154,0.07605497,833.54746731,-0.04091367,-0.03514131,0.00000000,0.00000000,0.00000000,0.00000000
126.00000000,1.59517100,11.04680000,0.05279856,735.86928320,0.05145191,774.72211844,0.00081345,0.07727517,835.61382585,-0.04153736,-0.03573781,0.00000000,0.00000000,0.00000000,0.00000000
127.50000000,1.63093200,11.07310000,0.05397411,737.62122604,0.05256789,777.43367606,0.00073408,0.07854774,837.25595318,-0.04224270,-0.03630505,0.00000000,0.00000000,0.00000000,0.00000000
129.00000000,1.66730000,11.10340000,0.05521344,739.63962407,0.05374306,780.47767536,0.00075449,0.07977875,839.28044906,-0.04288949,-0.03688926,0.00000000,0.00000000,0.00000000,0.00000000
130.50000000,1.70346600,11.12970000,0.05638900,741.39156690,0.05485649,783.19789597,0.00076102,0.08103969,841.21019354,-0.04361135,-0.03742834,0.00000000,0.00000000,0.00000000,0.00000000
132.00000000,1.74030900,11.15530000,0.05762467,743.09688009,0.05602551,785.91759010,0.00076728,0.08229628,843.03045108,-0.04430357,-0.03799271,0.00000000,0.00000000,0.00000000,0.00000000
133.50000000,1.77647500,11.17920000,0.05883400,744.68894981,0.05716830,788.50197949,0.00073092,0.08355640,845.20739351,-0.04501014,-0.03854626,0.00000000,0.00000000,0.00000000,0.00000000
135.00000000,1.81389200,11.20790000,0.06007333,746.60076576,0.05833809,791.45156243,0.00072985,0.08483314,847.16144656,-0.04571269,-0.03912045,0.00000000,0.00000000,0.00000000,0.00000000
136.50000000,1.85070100,11.23020000,0.06128644,748.08625342,0.05948180,793.93380003,0.00072923,0.08612341,848.78665313,-0.04644579,-0.03967762,0.00000000,0.00000000,0.00000000,0.00000000
138.00000000,1.88815100,11.25410000,0.06254078,749.67832314,0.06066300,796.56378856,0.00070703,0.08741728,850.76954364,-0.04717251,-0.04024478,0.00000000,0.00000000,0.00000000,0.00000000
139.50000000,1.92604200,11.27730000,0.06381022,751.22376321,0.06185701,799.15951848,0.00084745,0.08872412,852.52508964,-0.04789728,-0.04082684,0.00000000,0.00000000,0.00000000,0.00000000
141.00000000,1.96318900,11.30200000,0.06506456,752.86912398,0.06303541,801.85421892,0.00080408,0.08997930,854.71713043,-0.04854575,-0.04143355,0.00000000,0.00000000,0.00000000,0.00000000
142.50000000,2.00134900,11.32350000,0.06630022,754.30132060,0.06419492,804.31166577,0.00071162,0.09128077,856.18797184,-0.04923794,-0.04204283,0.00000000,0.00000000,0.00000000,0.00000000
144.00000000,2.03934100,11.34900000,0.06757711,755.99997240,0.06539170,807.08826653,0.00076699,0.09254520,857.91664181,-0.04992537,-0.04261983,0.00000000,0.00000000,0.00000000,0.00000000
145.50000000,2.07767000,11.36420000,0.06883156,757.01250210,0.06656605,809.11885019,0.00075216,0.09381755,859.78057524,-0.05061929,-0.04319826,0.00000000,0.00000000,0.00000000,0.00000000
147.00000000,2.11603400,11.38570000,0.07013100,758.44469872,0.06778107,811.63518388,0.00082146,0.09516817,861.30194726,-0.05137101,-0.04379715,0.00000000,0.00000000,0.00000000,0.00000000
148.50000000,2.15456700,11.40490000,0.07142289,759.72368360,0.06898757,813.98534384,0.00084122,0.09647831,863.08668000,-0.05210716,-0.04437115,0.00000000,0.00000000,0.00000000,0.00000000
150.00000000,2.19367400,11.42240000,0.07272611,760.88942503,0.07020318,816.22595390,0.00086838,0.09778745,864.69601036,-0.05282904,-0.04495841,0.00000000,0.00000000,0.00000000,0.00000000
151.50000000,2.23366100,11.43760000,0.07405189,761.90195474,0.07143831,818.32223363,0.00082529,0.09913184,866.39066750,-0.05363030,-0.04550153,0.00000000,0.00000000,0.00000000,0.00000000
153.00000000,2.27188900,11.45830000,0.07531756,763.28086032,0.07261602,820.76930892,0.00079641,0.10047708,868.21534084,-0.05433899,-0.04613809,0.00000000,0.00000000,0.00000000,0.00000000
154.50000000,2.31096300,11.47030000,0.07662078,764.08022587,0.07382723,822.62464706,0.00082353,0.10180076,869.96505129,-0.05509006,-0.04671069,0.00000000,0.00000000,0.00000000,0.00000000
156.00000000,2.35051000,11.48860000,0.07792022,765.29925834,0.07503346,824.93154662,0.00079449,0.10311739,871.35429725,-0.05577435,-0.04734304,0.00000000,0.00000000,0.00000000,0.00000000
157.50000000,2.39036100,11.50140000,0.07922344,766.15191493,0.07624175,826.84910860,0.00076572,0.10442293,873.32503685,-0.05646944,-0.04795349,0.00000000,0.00000000,0.00000000,0.00000000
159.00000000,2.43027900,11.52050000,0.08061311,767.42423844,0.07752858,829.28869384,0.00091101,0.10579953,874.83178614,-0.05726982,-0.04852971,0.00000000,0.00000000,0.00000000,0.00000000
160.50000000,2.47073900,11.53640000,0.08194256,768.48339779,0.07875809,831.45489131,0.00081948,0.10717421,876.33935801,-0.05803488,-0.04913933,0.00000000,0.00000000,0.00000000,0.00000000
162.00000000,2.51170500,11.55080000,0.08331333,769.44263646,0.08002425,833.54746731,0.00087385,0.10851694,877.82126176,-0.05878511,-0.04973183,0.00000000,0.00000000,0.00000000,0.00000000
163.50000000,2.55152300,11.56520000,0.08464667,770.40187512,0.08125428,835.61382585,0.00081743,0.10990377,879.52448331,-0.05953168,-0.05037209,0.00000000,0.00000000,0.00000000,0.00000000
165.00000000,2.59194900,11.57310000,0.08603633,770.92812411,0.08253468,837.25595318,0.00079571,0.11130522,881.24369260,-0.06031624,-0.05098898,0.00000000,0.00000000,0.00000000,0.00000000
166.50000000,2.63294900,11.58670000,0.08738456,771.83407174,0.08377532,839.28044906,0.00082907,0.11273660,882.57147095,-0.06112147,-0.05161513,0.00000000,0.00000000,0.00000000,0.00000000
168.00000000,2.67405000,11.59860000,0.08876656,772.62677591,0.08504546,841.21019354,0.00088295,0.11413168,884.10246460,-0.06190366,-0.05222803,0.00000000,0.00000000,0.00000000,0.00000000
169.50000000,2.71572700,11.60900000,0.09014500,773.31955939,0.08631071,843.03045108,0.00073052,0.11552380,885.82190925,-0.06267914,-0.05284466,0.00000000,0.00000000,0.00000000,0.00000000
171.00000000,2.75733600,11.62420000,0.09153089,774.33208910,0.08758120,845.20739351,0.00083977,0.11691454,887.42239076,-0.06344552,-0.05346901,0.00000000,0.00000000,0.00000000,0.00000000
172.50000000,2.79958700,11.63610000,0.09293556,775.12479327,0.08886725,847.16144656,0.00088690,0.11833878,888.57158483,-0.06419576,-0.05414302,0.00000000,0.00000000,0.00000000,0.00000000
174.00000000,2.84092600,11.64330000,0.09435511,775.60441260,0.09016525,848.78665313,0.00085812,0.11975831,890.26328275,-0.06500071,-0.05475760,0.00000000,0.00000000,0.00000000,0.00000000
175.50000000,2.88307500,11.65530000,0.09578233,776.40377816,0.09146857,850.76954364,0.00093248,0.12124292,891.77361919,-0.06585846,-0.05538446,0.00000000,0.00000000,0.00000000,0.00000000
177.00000000,2.92532600,11.66400000,0.09722444,776.98331818,0.09278376,852.52508964,0.00095172,0.12262534,893.43785525,-0.06658878,-0.05603656,0.00000000,0.00000000,0.00000000,0.00000000
178.50000000,2.96767800,11.67920000,0.09861400,777.99584788,0.09404939,854.71713043,0.00086147,0.12407315,894.85955248,-0.06737041,-0.05670273,0.00000000,0.00000000,0.00000000,0.00000000
180.00000000,3.01020000,11.68400000,0.10005244,778.31559410,0.09535786,856.18797184,0.00087409,0.12555188,896.25039942,-0.06820875,-0.05734313,0.00000000,0.00000000,0.00000000,0.00000000
181.50000000,3.05272200,11.69270000,0.10145333,778.89513413,0.09663052,857.91664181,0.00087984,0.12702850,897.64151394,-0.06906531,-0.05796319,0.00000000,0.00000000,0.00000000,0.00000000
183.00000000,3.09595300,11.70310000,0.10286544,779.58791761,0.09791174,859.78057524,0.00085150,0.12850340,898.91100406,-0.06988126,-0.05862214,0.00000000,0.00000000,0.00000000,0.00000000
184.50000000,3.13904900,11.70790000,0.10436400,779.90766383,0.09926960,861.30194726,0.00083665,0.13000775,900.45376323,-0.07071681,-0.05929095,0.00000000,0.00000000,0.00000000,0.00000000
186.00000000,3.18184100,11.71670000,0.10582122,780.49386524,0.10058825,863.08668000,0.00091054,0.13157195,902.72010404,-0.07165200,-0.05991995,0.00000000,0.00000000,0.00000000,0.00000000
187.50000000,3.22564700,11.72310000,0.10727833,780.92019353,0.10190505,864.69601036,0.00087521,0.00000000,0.00000000,0.00000000,0.00000000,0.00000000,0.00000000,0.00000000,0.00000000
189.00000000,3.26887800,11.73020000,0.10877689,781.39315149,0.10325751,866.39066750,0.00092816,0.00000000,0.00000000,0.00000000,0.00000000,0.00000000,0.00000000,0.00000000,0.00000000
190.50000000,3.31322500,11.73900000,0.11027911,781.97935289,0.10461144,868.21534084,0.00099459,0.00000000,0.00000000,0.00000000,0.00000000,0.00000000,0.00000000,0.00000000,0.00000000
192.00000000,3.35720000,11.74700000,0.11175900,782.51226326,0.10594345,869.96505129,0.00093947,0.00000000,0.00000000,0.00000000,0.00000000,0.00000000,0.00000000,0.00000000,0.00000000
193.50000000,3.40174900,11.75020000,0.11323111,782.72542741,0.10726670,871.35429725,0.00082999,0.00000000,0.00000000,0.00000000,0.00000000,0.00000000,0.00000000,0.00000000,0.00000000
195.00000000,3.44616300,11.76130000,0.11469589,783.46484055,0.10858162,873.32503685,0.00083588,0.00000000,0.00000000,0.00000000,0.00000000,0.00000000,0.00000000,0.00000000,0.00000000
196.50000000,3.49078000,11.76530000,0.11623944,783.73129573,0.10996540,874.83178614,0.00087495,0.00000000,0.00000000,0.00000000,0.00000000,0.00000000,0.00000000,0.00000000,0.00000000
198.00000000,3.53583700,11.76930000,0.11778300,783.99775092,0.11134726,876.33935801,0.00090060,0.00000000,0.00000000,0.00000000,0.00000000,0.00000000,0.00000000,0.00000000,0.00000000
199.50000000,3.58079200,11.77330000,0.11929278,784.26420610,0.11269704,877.82126176,0.00089263,0.00000000,0.00000000,0.00000000,0.00000000,0.00000000,0.00000000,0.00000000,0.00000000
201.00000000,3.62584900,11.77970000,0.12085522,784.69053440,0.11409199,879.52448331,0.00089158,0.00000000,0.00000000,0.00000000,0.00000000,0.00000000,0.00000000,0.00000000,0.00000000
202.50000000,3.67202100,11.78610000,0.12243633,785.11686269,0.11550162,881.24369260,0.00093727,0.00000000,0.00000000,0.00000000,0.00000000,0.00000000,0.00000000,0.00000000,0.00000000
204.00000000,3.71795600,11.78690000,0.12405122,785.17015373,0.11693932,882.57147095,0.00100258,0.00000000,0.00000000,0.00000000,0.00000000,0.00000000,0.00000000,0.00000000,0.00000000
205.50000000,3.76419600,11.79080000,0.12562867,785.42994753,0.11834169,884.10246460,0.00100137,0.00000000,0.00000000,0.00000000,0.00000000,0.00000000,0.00000000,0.00000000,0.00000000
207.00000000,3.81077300,11.79720000,0.12720600,785.85627583,0.11974200,885.82190925,0.00093310,0.00000000,0.00000000,0.00000000,0.00000000,0.00000000,0.00000000,0.00000000,0.00000000
208.50000000,3.85718200,11.80200000,0.12878333,786.17602205,0.12114036,887.42239076,0.00093180,0.00000000,0.00000000,0.00000000,0.00000000,0.00000000,0.00000000,0.00000000,0.00000000
210.00000000,3.90386100,11.80040000,0.13039833,786.06943998,0.12257008,888.57158483,0.00086399,0.00000000,0.00000000,0.00000000,0.00000000,0.00000000,0.00000000,0.00000000,0.00000000
211.50000000,3.95087800,11.80600000,0.13201322,786.44247723,0.12399766,890.26328275,0.00092914,0.00000000,0.00000000,0.00000000,0.00000000,0.00000000,0.00000000,0.00000000,0.00000000
213.00000000,3.99863800,11.80840000,0.13370322,786.60235034,0.12548946,891.77361919,0.00112662,0.00000000,0.00000000,0.00000000,0.00000000,0.00000000,0.00000000,0.00000000,0.00000000
214.50000000,4.04639900,11.81400000,0.13528056,786.97538760,0.12687981,893.43785525,0.00105866,0.00000000,0.00000000,0.00000000,0.00000000,0.00000000,0.00000000,0.00000000,0.00000000
216.00000000,4.09426100,11.81560000,0.13693311,787.08196968,0.12833438,894.85955248,0.00092512,0.00000000,0.00000000,0.00000000,0.00000000,0.00000000,0.00000000,0.00000000,0.00000000
217.50000000,4.14232600,11.81640000,0.13862311,787.13526071,0.12981974,896.25039942,0.00085755,0.00000000,0.00000000,0.00000000,0.00000000,0.00000000,0.00000000,0.00000000,0.00000000
219.00000000,4.19015400,11.81720000,0.14031322,787.18855175,0.13130298,897.64151394,0.00092238,0.00000000,0.00000000,0.00000000,0.00000000,0.00000000,0.00000000,0.00000000,0.00000000
220.50000000,4.23886100,11.81640000,0.14200322,787.13526071,0.13278393,898.91100406,0.00098681,0.00000000,0.00000000,0.00000000,0.00000000,0.00000000,0.00000000,0.00000000,0.00000000
222.00000000,4.28767000,11.81880000,0.14373089,787.29513382,0.13429563,900.45376323,0.00098532,0.00000000,0.00000000,0.00000000,0.00000000,0.00000000,0.00000000,0.00000000,0.00000000
223.50000000,4.33708700,11.82990000,0.14553367,788.03454696,0.13587061,902.72010404,0.00118078,0.00000000,0.00000000,0.00000000,0.00000000,0.00000000,0.00000000,0.00000000,0.00000000
225.00000000,4.38626700,11.82110000,0.14722367,787.44834556,0.00000000,0.00000000,0.00000000,0.00000000,0.00000000,0.00000000,0.00000000,0.00000000,0.00000000,0.00000000,0.00000000
226.50000000,4.43527800,11.82190000,0.14895122,787.50163659,0.00000000,0.00000000,0.00000000,0.00000000,0.00000000,0.00000000,0.00000000,0.00000000,0.00000000,0.00000000,0.00000000
228.00000000,4.48601300,11.82350000,0.15079144,787.60821867,0.00000000,0.00000000,0.00000000,0.00000000,0.00000000,0.00000000,0.00000000,0.00000000,0.00000000,0.00000000,0.00000000
229.50000000,4.53600400,11.82190000,0.15255667,787.50163659,0.00000000,0.00000000,0.00000000,0.00000000,0.00000000,0.00000000,0.00000000,0.00000000,0.00000000,0.00000000,0.00000000
231.00000000,4.58646900,11.82270000,0.15435933,787.55492763,0.00000000,0.00000000,0.00000000,0.00000000,0.00000000,0.00000000,0.00000000,0.00000000,0.00000000,0.00000000,0.00000000
232.50000000,4.63615700,11.82190000,0.15616211,787.50163659,0.00000000,0.00000000,0.00000000,0.00000000,0.00000000,0.00000000,0.00000000,0.00000000,0.00000000,0.00000000,0.00000000
234.00000000,4.68770300,11.82190000,0.15807744,787.50163659,0.00000000,0.00000000,0.00000000,0.00000000,0.00000000,0.00000000,0.00000000,0.00000000,0.00000000,0.00000000,0.00000000
235.50000000,4.74002600,11.82030000,0.15999278,787.39505452,0.00000000,0.00000000,0.00000000,0.00000000,0.00000000,0.00000000,0.00000000,0.00000000,0.00000000,0.00000000,0.00000000
237.00000000,4.79143800,11.81880000,0.16183300,787.29513382,0.00000000,0.00000000,0.00000000,0.00000000,0.00000000,0.00000000,0.00000000,0.00000000,0.00000000,0.00000000,0.00000000
238.50000000,4.84271400,11.81640000,0.16371078,787.13526071,0.00000000,0.00000000,0.00000000,0.00000000,0.00000000,0.00000000,0.00000000,0.00000000,0.00000000,0.00000000,0.00000000
240.00000000,4.89517200,11.81400000,0.16566367,786.97538760,0.00000000,0.00000000,0.00000000,0.00000000,0.00000000,0.00000000,0.00000000,0.00000000,0.00000000,0.00000000,0.00000000
241.50000000,4.94820600,11.81640000,0.16765422,787.13526071,0.00000000,0.00000000,0.00000000,0.00000000,0.00000000,0.00000000,0.00000000,0.00000000,0.00000000,0.00000000,0.00000000
243.00000000,5.00123900,11.81240000,0.16956956,786.86880553,0.00000000,0.00000000,0.00000000,0.00000000,0.00000000,0.00000000,0.00000000,0.00000000,0.00000000,0.00000000,0.00000000
244.50000000,5.05427300,11.80600000,0.17163511,786.44247723,0.00000000,0.00000000,0.00000000,0.00000000,0.00000000,0.00000000,0.00000000,0.00000000,0.00000000,0.00000000,0.00000000
246.00000000,5.10876000,11.80680000,0.17358811,786.49576827,0.00000000,0.00000000,0.00000000,0.00000000,0.00000000,0.00000000,0.00000000,0.00000000,0.00000000,0.00000000,0.00000000
247.50000000,5.16317900,11.80120000,0.17572867,786.12273101,0.00000000,0.00000000,0.00000000,0.00000000,0.00000000,0.00000000,0.00000000,0.00000000,0.00000000,0.00000000,0.00000000
249.00000000,5.21786900,11.79640000,0.17775678,785.80298479,0.00000000,0.00000000,0.00000000,0.00000000,0.00000000,0.00000000,0.00000000,0.00000000,0.00000000,0.00000000,0.00000000
250.50000000,5.27323500,11.79240000,0.17982222,785.53652961,0.00000000,0.00000000,0.00000000,0.00000000,0.00000000,0.00000000,0.00000000,0.00000000,0.00000000,0.00000000,0.00000000
252.00000000,5.32816100,11.78610000,0.18196300,785.11686269,0.00000000,0.00000000,0.00000000,0.00000000,0.00000000,0.00000000,0.00000000,0.00000000,0.00000000,0.00000000,0.00000000
253.50000000,5.38430500,11.78210000,0.18406611,784.85040751,0.00000000,0.00000000,0.00000000,0.00000000,0.00000000,0.00000000,0.00000000,0.00000000,0.00000000,0.00000000,0.00000000
255.00000000,5.44085400,11.77570000,0.18616911,784.42407921,0.00000000,0.00000000,0.00000000,0.00000000,0.00000000,0.00000000,0.00000000,0.00000000,0.00000000,0.00000000,0.00000000
256.50000000,5.49780800,11.76610000,0.18834733,783.78458677,0.00000000,0.00000000,0.00000000,0.00000000,0.00000000,0.00000000,0.00000000,0.00000000,0.00000000,0.00000000,0.00000000
258.00000000,5.55520200,11.75890000,0.19045044,783.30496744,0.00000000,0.00000000,0.00000000,0.00000000,0.00000000,0.00000000,0.00000000,0.00000000,0.00000000,0.00000000,0.00000000
259.50000000,5.61306900,11.74540000,0.19262867,782.40568119,0.00000000,0.00000000,0.00000000,0.00000000,0.00000000,0.00000000,0.00000000,0.00000000,0.00000000,0.00000000,0.00000000
261.00000000,5.67127400,11.73900000,0.19465667,781.97935289,0.00000000,0.00000000,0.00000000,0.00000000,0.00000000,0.00000000,0.00000000,0.00000000,0.00000000,0.00000000,0.00000000
262.50000000,5.72985100,11.72390000,0.19672211,780.97348457,0.00000000,0.00000000,0.00000000,0.00000000,0.00000000,0.00000000,0.00000000,0.00000000,0.00000000,0.00000000,0.00000000
264.00000000,5.78869800,11.70950000,0.19871256,780.01424591,0.00000000,0.00000000,0.00000000,0.00000000,0.00000000,0.00000000,0.00000000,0.00000000,0.00000000,0.00000000,0.00000000
265.50000000,5.84849200,11.69040000,0.20059033,778.74192240,0.00000000,0.00000000,0.00000000,0.00000000,0.00000000,0.00000000,0.00000000,0.00000000,0.00000000,0.00000000,0.00000000
267.00000000,5.90930000,11.67920000,0.20243056,777.99584788,0.00000000,0.00000000,0.00000000,0.00000000,0.00000000,0.00000000,0.00000000,0.00000000,0.00000000,0.00000000,0.00000000
268.50000000,5.96929700,11.65130000,0.20423322,776.13732297,0.00000000,0.00000000,0.00000000,0.00000000,0.00000000,0.00000000,0.00000000,0.00000000,0.00000000,0.00000000,0.00000000
270.00000000,6.02959800,11.62500000,0.20584811,774.38538013,0.00000000,0.00000000,0.00000000,0.00000000,0.00000000,0.00000000,0.00000000,0.00000000,0.00000000,0.00000000,0.00000000
271.50000000,6.09118400,11.59550000,0.20735033,772.42027315,0.00000000,0.00000000,0.00000000,0.00000000,0.00000000,0.00000000,0.00000000,0.00000000,0.00000000,0.00000000,0.00000000
273.00000000,6.15236400,11.56670000,0.20866489,770.50179582,0.00000000,0.00000000,0.00000000,0.00000000,0.00000000,0.00000000,0.00000000,0.00000000,0.00000000,0.00000000,0.00000000
274.50000000,6.21435600,11.52850000,0.20994200,767.95714881,0.00000000,0.00000000,0.00000000,0.00000000,0.00000000,0.00000000,0.00000000,0.00000000,0.00000000,0.00000000,0.00000000
276.00000000,6.27641700,11.49020000,0.21099389,765.40584041,0.00000000,0.00000000,0.00000000,0.00000000,0.00000000,0.00000000,0.00000000,0.00000000,0.00000000,0.00000000,0.00000000
277.50000000,6.33925600,11.44550000,0.21189567,762.42820373,0.00000000,0.00000000,0.00000000,0.00000000,0.00000000,0.00000000,0.00000000,0.00000000,0.00000000,0.00000000,0.00000000
279.00000000,6.40280800,11.39370000,0.21264722,758.97760909,0.00000000,0.00000000,0.00000000,0.00000000,0.00000000,0.00000000,0.00000000,0.00000000,0.00000000,0.00000000,0.00000000
280.50000000,6.46666800,11.32990000,0.21321122,754.72764889,0.00000000,0.00000000,0.00000000,0.00000000,0.00000000,0.00000000,0.00000000,0.00000000,0.00000000,0.00000000,0.00000000
282.00000000,6.53084000,11.25250000,0.21362511,749.57174107,0.00000000,0.00000000,0.00000000,0.00000000,0.00000000,0.00000000,0.00000000,0.00000000,0.00000000,0.00000000,0.00000000
283.50000000,6.59641100,11.15290000,0.21392667,742.93700697,0.00000000,0.00000000,0.00000000,0.00000000,0.00000000,0.00000000,0.00000000,0.00000000,0.00000000,0.00000000,0.00000000
285.00000000,6.68175800,10.93910000,0.21419400,728.69497736,0.00000000,0.00000000,0.00000000,0.00000000,0.00000000,0.00000000,0.00000000,0.00000000,0.00000000,0.00000000,0.00000000