File: LAB_DATA/DP780_results/DATA/UT_45_1.csv
Time[s],Displacement[mm],Force[kN],EngStrain_longi,EngStress[MPa],TrueStrain,TrueStress[MPa],TrueStrainRate[1/s],PlasticStrain_longi,PlasticStress[MPa],PlasticStrain_thick,PlasticStrain_width,R-Value,Thickness[mm],Width[mm], Young's Modulus [MPa]
0.00000000,0.00000000,-0.00620000,0.00000000,-0.41353400,0.00000000,-0.41353400,0.00000000,0.00063363,417.53537695,0.00021627,-0.00084990,0.85852913,1.50720000,9.94740000,229865.62368737
1.50000000,0.00249800,0.38220000,0.00004033,25.49237012,0.00004033,25.49339831,0.00003689,0.00068039,429.68454261,0.00016228,-0.00084267,0.00000000,0.00000000,0.00000000,0.00000000
3.00000000,0.00422900,0.72590000,0.00008978,48.41682750,0.00008977,48.42117426,0.00002622,0.00093728,442.62655663,0.00024282,-0.00118010,0.00000000,0.00000000,0.00000000,0.00000000
4.50000000,0.00608100,1.05040000,0.00016222,70.06066346,0.00016221,70.07202886,0.00004355,0.00124469,454.26511541,-0.00004671,-0.00119798,0.00000000,0.00000000,0.00000000,0.00000000
6.00000000,0.00828300,1.37100000,0.00023622,91.44437320,0.00023619,91.46597439,-0.00002866,0.00151903,465.72890002,-0.00025739,-0.00126164,0.00000000,0.00000000,0.00000000,0.00000000
7.50000000,0.01089800,1.65810000,0.00031444,110.59366535,0.00031440,110.62844092,0.00005776,0.00185249,477.39629080,-0.00026970,-0.00158279,0.00000000,0.00000000,0.00000000,0.00000000
9.00000000,0.01313800,1.93330000,0.00037011,128.94923903,0.00037004,128.99696457,0.00008197,0.00229100,488.15704333,-0.00049192,-0.00179908,0.00000000,0.00000000,0.00000000,0.00000000
10.50000000,0.01514200,2.21080000,0.00048178,147.45822047,0.00048166,147.52926257,0.00021635,0.00254893,498.24670107,-0.00069609,-0.00185284,0.00000000,0.00000000,0.00000000,0.00000000
12.00000000,0.01629900,2.46520000,0.00049700,164.42645427,0.00049688,164.50817422,0.00002954,0.00301301,508.98536221,-0.00097453,-0.00203848,0.00000000,0.00000000,0.00000000,0.00000000
13.50000000,0.01757300,2.70920000,0.00052689,180.70101814,0.00052675,180.79622750,0.00003687,0.00359143,518.45587211,-0.00120809,-0.00238333,0.00000000,0.00000000,0.00000000,0.00000000
15.00000000,0.02034900,2.97160000,0.00060089,198.20284420,0.00060071,198.32194209,-0.00015834,0.00413413,527.48831917,-0.00147319,-0.00266093,0.00000000,0.00000000,0.00000000,0.00000000
16.50000000,0.02320000,3.21160000,0.00073744,214.21061194,0.00073717,214.36858036,0.00000910,0.00461835,536.98467271,-0.00169578,-0.00292257,0.00000000,0.00000000,0.00000000,0.00000000
18.00000000,0.02585200,3.44610000,0.00086667,229.85153500,0.00086629,230.05073966,0.00023514,0.00525849,545.76759491,-0.00209595,-0.00316254,0.00000000,0.00000000,0.00000000,0.00000000
19.50000000,0.02746300,3.68930000,0.00085800,246.07273964,0.00085763,246.28387005,0.00014988,0.00594016,554.31556374,-0.00250679,-0.00343337,0.00000000,0.00000000,0.00000000,0.00000000
21.00000000,0.02973800,3.91260000,0.00089933,260.96663354,0.00089893,261.20132953,-0.00007504,0.00651442,562.65302857,-0.00267389,-0.00384053,0.00000000,0.00000000,0.00000000,0.00000000
22.50000000,0.03275600,4.13350000,0.00100511,275.70044976,0.00100461,275.97755934,-0.00024729,0.00712725,570.64439810,-0.00289038,-0.00423687,0.00000000,0.00000000,0.00000000,0.00000000
24.00000000,0.03553600,4.36550000,0.00124567,291.17462524,0.00124489,291.53733176,0.00026990,0.00790555,578.15386137,-0.00341895,-0.00448660,0.00000000,0.00000000,0.00000000,0.00000000
25.50000000,0.03834900,4.57850000,0.00127200,305.38151910,0.00127119,305.76996440,0.00021019,0.00859829,586.32854230,-0.00375323,-0.00484506,0.00000000,0.00000000,0.00000000,0.00000000
27.00000000,0.04231100,4.78740000,0.00126889,319.31494694,0.00126808,319.72012213,-0.00001465,0.00924409,593.34279251,-0.00412563,-0.00511846,0.00000000,0.00000000,0.00000000,0.00000000
28.50000000,0.04560100,5.00110000,0.00149022,333.56853013,0.00148911,334.06562137,-0.00009031,0.01003261,600.67586221,-0.00461093,-0.00542168,0.00000000,0.00000000,0.00000000,0.00000000
30.00000000,0.04844300,5.20370000,0.00165978,347.08175406,0.00165840,347.65783264,0.00020278,0.01085759,607.98862428,-0.00507966,-0.00577793,0.00000000,0.00000000,0.00000000,0.00000000
31.50000000,0.05365900,5.40390000,0.00177633,360.43490031,0.00177476,361.07515284,0.00038979,0.01160801,614.45305711,-0.00542325,-0.00618476,0.00000000,0.00000000,0.00000000,0.00000000
33.00000000,0.05890200,5.61120000,0.00180656,374.26160970,0.00180493,374.93773409,-0.00014174,0.01234625,621.02834591,-0.00578498,-0.00656127,0.00000000,0.00000000,0.00000000,0.00000000
34.50000000,0.06333200,5.80260000,0.00214089,387.02780447,0.00213860,387.85638799,0.00004479,0.01322262,627.97236042,-0.00627392,-0.00694871,0.00000000,0.00000000,0.00000000,0.00000000
36.00000000,0.06969300,5.98760000,0.00234733,399.36712543,0.00234458,400.30457320,0.00035985,0.01406068,634.25761714,-0.00671201,-0.00734867,0.00000000,0.00000000,0.00000000,0.00000000
37.50000000,0.07553800,6.19580000,0.00241522,413.25386394,0.00241231,414.25196386,0.00017980,0.01481487,640.16573077,-0.00707314,-0.00774172,0.00000000,0.00000000,0.00000000,0.00000000
39.00000000,0.08250500,6.36800000,0.00271911,424.73943730,0.00271542,425.89435102,-0.00001507,0.01567247,646.69512319,-0.00753460,-0.00813786,0.00000000,0.00000000,0.00000000,0.00000000
40.50000000,0.09173000,6.54820000,0.00306467,436.75860291,0.00305998,438.09712244,0.00022488,0.01654405,652.43282268,-0.00804667,-0.00849738,0.00000000,0.00000000,0.00000000,0.00000000
42.00000000,0.10037800,6.73250000,0.00328611,449.05123455,0.00328072,450.52686680,0.00028420,0.01743785,657.97645841,-0.00850468,-0.00893317,0.00000000,0.00000000,0.00000000,0.00000000
43.50000000,0.11088900,6.90310000,0.00363111,460.43008945,0.00362453,462.10196226,0.00024645,0.01827110,663.70139570,-0.00896676,-0.00930434,0.00000000,0.00000000,0.00000000,0.00000000
45.00000000,0.12214200,7.06500000,0.00404422,471.22866277,0.00403607,473.13441620,0.00030678,0.01920476,669.01733444,-0.00949056,-0.00971421,0.00000000,0.00000000,0.00000000,0.00000000
46.50000000,0.13352200,7.23170000,0.00437089,482.34739144,0.00436136,484.45567829,0.00027637,0.02012643,674.33477712,-0.00998702,-0.01013941,0.00000000,0.00000000,0.00000000,0.00000000
48.00000000,0.14733800,7.38560000,0.00477611,492.61237250,0.00476474,494.96514393,0.00013403,0.02103241,679.70587964,-0.01043341,-0.01059900,0.00000000,0.00000000,0.00000000,0.00000000
49.50000000,0.16075300,7.53550000,0.00541400,502.61055743,0.00539940,505.33169099,0.00032095,0.02195352,684.76742997,-0.01092857,-0.01102496,0.00000000,0.00000000,0.00000000,0.00000000
51.00000000,0.17734200,7.68460000,0.00593211,512.55538314,0.00591459,515.59591862,0.00051523,0.02291550,689.53652752,-0.01137263,-0.01154287,0.00000000,0.00000000,0.00000000,0.00000000
52.50000000,0.19328700,7.81860000,0.00643167,521.49305346,0.00641107,524.84712295,0.00052249,0.02383864,694.56237133,-0.01184649,-0.01199215,0.00000000,0.00000000,0.00000000,0.00000000
54.00000000,0.21159900,7.94860000,0.00697611,530.16392765,0.00695189,533.86241012,0.00034319,0.02478097,699.22517858,-0.01235786,-0.01242311,0.00000000,0.00000000,0.00000000,0.00000000
55.50000000,0.23028600,8.08020000,0.00764800,538.94152029,0.00761890,543.06334504,0.00042458,0.02573320,703.90335695,-0.01285991,-0.01287329,0.00000000,0.00000000,0.00000000,0.00000000
57.00000000,0.25035900,8.19980000,0.00827511,546.91872455,0.00824106,551.44453776,0.00041726,0.02675108,708.36081689,-0.01344997,-0.01330111,0.00000000,0.00000000,0.00000000,0.00000000
58.50000000,0.26985700,8.31940000,0.00892822,554.89592881,0.00888860,559.85016297,0.00023062,0.02774551,712.92740551,-0.01398982,-0.01375569,0.00000000,0.00000000,0.00000000,0.00000000
60.00000000,0.29141500,8.43430000,0.00976178,562.55964761,0.00971444,568.05122988,0.00034929,0.02872350,716.93093099,-0.01451989,-0.01420361,0.00000000,0.00000000,0.00000000,0.00000000
61.50000000,0.31267200,8.54510000,0.01048656,569.94990038,0.01043195,575.92671168,0.00055009,0.02971299,721.33750601,-0.01505415,-0.01465884,0.00000000,0.00000000,0.00000000,0.00000000
63.00000000,0.33548400,8.65200000,0.01118122,577.08002693,0.01111917,583.53248695,0.00054949,0.03077076,724.92240918,-0.01569731,-0.01507345,0.00000000,0.00000000,0.00000000,0.00000000
64.50000000,0.35833000,8.76200000,0.01198122,584.41692048,0.01191002,591.41894947,0.00043791,0.03174425,729.22909674,-0.01624936,-0.01549489,0.00000000,0.00000000,0.00000000,0.00000000
66.00000000,0.38222600,8.85850000,0.01284500,590.85337709,0.01276320,598.44288871,0.00071956,0.03277804,733.58111295,-0.01675468,-0.01602336,0.00000000,0.00000000,0.00000000,0.00000000
67.50000000,0.40534400,8.95660000,0.01354733,597.39655215,0.01345639,605.48968237,0.00071906,0.03380683,737.22218831,-0.01732629,-0.01648054,0.00000000,0.00000000,0.00000000,0.00000000
69.00000000,0.43072700,9.05230000,0.01432089,603.77964953,0.01421931,612.42631081,0.00057759,0.03486544,741.21919019,-0.01788220,-0.01698323,0.00000000,0.00000000,0.00000000,0.00000000
70.50000000,0.45455400,9.14320000,0.01521478,609.84259156,0.01510019,619.12121107,0.00056241,0.03590774,744.60600444,-0.01840529,-0.01750246,0.00000000,0.00000000,0.00000000,0.00000000
72.00000000,0.48061300,9.23090000,0.01602967,615.69209669,0.01590255,625.56143577,0.00062103,0.03697734,748.07543948,-0.01896321,-0.01801413,0.00000000,0.00000000,0.00000000,0.00000000
73.50000000,0.50589400,9.32030000,0.01683333,621.65499017,0.01669322,632.11951584,0.00056873,0.03803723,751.81638366,-0.01953454,-0.01850269,0.00000000,0.00000000,0.00000000,0.00000000
75.00000000,0.53245900,9.40320000,0.01773089,627.18433995,0.01757553,638.30487579,0.00051668,0.03907859,755.44572402,-0.02007924,-0.01899936,0.00000000,0.00000000,0.00000000,0.00000000
76.50000000,0.55902600,9.48450000,0.01865100,632.60697127,0.01847920,644.40572389,0.00061965,0.04019994,758.63930337,-0.02073071,-0.01946922,0.00000000,0.00000000,0.00000000,0.00000000
78.00000000,0.58609900,9.56430000,0.01954478,637.92955404,0.01935623,650.39774541,0.00067776,0.04125508,761.90059935,-0.02129305,-0.01996203,0.00000000,0.00000000,0.00000000,0.00000000
79.50000000,0.61347600,9.64240000,0.02040856,643.13874846,0.02020309,656.26428134,0.00061096,0.04234801,765.25313172,-0.02190975,-0.02043826,0.00000000,0.00000000,0.00000000,0.00000000
81.00000000,0.64085400,9.71820000,0.02136244,648.19453510,0.02113747,662.04155485,0.00050745,0.04350201,768.32245212,-0.02255190,-0.02095012,0.00000000,0.00000000,0.00000000,0.00000000
82.50000000,0.66948200,9.78760000,0.02230889,652.82344794,0.02206369,667.38721370,0.00056590,0.04455709,771.60235100,-0.02310856,-0.02144852,0.00000000,0.00000000,0.00000000,0.00000000
84.00000000,0.69780700,9.85700000,0.02327411,657.45236078,0.02300740,672.75398007,0.00063879,0.04568624,774.83349541,-0.02372249,-0.02196374,0.00000000,0.00000000,0.00000000,0.00000000
85.50000000,0.72714500,9.92390000,0.02421300,661.91452603,0.02392451,677.94146245,0.00056485,0.04680700,778.06450343,-0.02429238,-0.02251461,0.00000000,0.00000000,0.00000000,0.00000000
87.00000000,0.75611200,9.98620000,0.02523456,666.06987574,0.02492142,682.87785303,0.00065231,0.04790768,780.72216804,-0.02490686,-0.02300082,0.00000000,0.00000000,0.00000000,0.00000000
88.50000000,0.78589000,10.05710000,0.02620344,670.79883713,0.02586602,688.37607719,0.00062224,0.04900863,783.83670015,-0.02549890,-0.02350973,0.00000000,0.00000000,0.00000000,0.00000000
90.00000000,0.81563400,10.10980000,0.02714989,674.31387613,0.02678787,692.62142294,0.00054852,0.05018332,786.90242993,-0.02615671,-0.02402661,0.00000000,0.00000000,0.00000000,0.00000000
91.50000000,0.84548000,10.17670000,0.02816389,678.77604138,0.02777458,697.89301439,0.00059922,0.05131884,789.66034262,-0.02674751,-0.02457133,0.00000000,0.00000000,0.00000000,0.00000000
93.00000000,0.87620500,10.23340000,0.02918544,682.55787651,0.02876766,702.47863150,0.00062778,0.05245998,792.48469982,-0.02737246,-0.02508752,0.00000000,0.00000000,0.00000000,0.00000000
94.50000000,0.90750400,10.28520000,0.03025200,686.01288638,0.02980343,706.76614822,0.00072919,0.05357251,795.06482042,-0.02794719,-0.02562532,0.00000000,0.00000000,0.00000000,0.00000000
96.00000000,0.93822900,10.33620000,0.03125856,689.41453703,0.03077995,710.96463963,0.00064829,0.05475129,797.59632236,-0.02861681,-0.02613448,0.00000000,0.00000000,0.00000000,0.00000000
97.50000000,0.97010200,10.39450000,0.03230267,693.30309060,0.03179191,715.69862924,0.00065495,0.05590836,800.67679094,-0.02918720,-0.02672116,0.00000000,0.00000000,0.00000000,0.00000000
99.00000000,1.00133400,10.44310000,0.03334289,696.54466357,0.03279907,719.76947490,0.00066161,0.05706018,803.07606316,-0.02983414,-0.02722605,0.00000000,0.00000000,0.00000000,0.00000000
100.50000000,1.03324200,10.49890000,0.03443956,700.26646957,0.03385979,724.38333555,0.00072624,0.05823394,805.78256324,-0.03044143,-0.02779251,0.00000000,0.00000000,0.00000000,0.00000000
102.00000000,1.06538600,10.54200000,0.03551000,703.14119786,0.03489406,728.10974180,0.00072570,0.05942526,808.23043926,-0.03111684,-0.02830841,0.00000000,0.00000000,0.00000000,0.00000000
103.50000000,1.09800400,10.58740000,0.03658778,706.16933392,0.03593434,732.00650059,0.00074639,0.06057616,810.70016555,-0.03172506,-0.02885111,0.00000000,0.00000000,0.00000000,0.00000000
105.00000000,1.13038500,10.63290000,0.03766944,709.20413989,0.03697728,735.91946584,0.00072398,0.06176101,813.14506765,-0.03242839,-0.02933262,0.00000000,0.00000000,0.00000000,0.00000000
106.50000000,1.16405000,10.67600000,0.03879611,712.07886818,0.03806246,739.70475907,0.00077369,0.06294018,815.76183882,-0.03298003,-0.02996015,0.00000000,0.00000000,0.00000000,0.00000000
108.00000000,1.19731000,10.72540000,0.03992289,715.37380037,0.03914657,743.93358912,0.00085260,0.06411616,817.98689782,-0.03365506,-0.03046110,0.00000000,0.00000000,0.00000000,0.00000000
109.50000000,1.23117900,10.76130000,0.04101944,717.76829563,0.04020047,747.21075236,0.00078656,0.06530184,820.10209770,-0.03427329,-0.03102855,0.00000000,0.00000000,0.00000000,0.00000000
111.00000000,1.26437100,10.79960000,0.04212744,720.32286856,0.04126424,750.66823019,0.00073538,0.06649360,822.11845721,-0.03491090,-0.03158269,0.00000000,0.00000000,0.00000000,0.00000000
112.50000000,1.29813800,10.83630000,0.04328411,722.77072305,0.04237354,754.05521133,0.00079210,0.06769172,824.71203024,-0.03558170,-0.03211002,0.00000000,0.00000000,0.00000000,0.00000000
114.00000000,1.33231100,10.87290000,0.04438078,725.21190763,0.04342415,757.39737614,0.00069059,0.06889040,826.85743535,-0.03623007,-0.03266033,0.00000000,0.00000000,0.00000000,0.00000000
115.50000000,1.36675400,10.91120000,0.04553378,727.76648056,0.04452755,760.90443776,0.00072576,0.07007951,829.97233305,-0.03685442,-0.03322509,0.00000000,0.00000000,0.00000000,0.00000000
117.00000000,1.40116300,10.94630000,0.04675067,730.10761659,0.04569076,764.24063441,0.00083981,0.07130047,831.22138081,-0.03751339,-0.03378708,0.00000000,0.00000000,0.00000000,0.00000000
118.50000000,1.43658600,10.97820000,0.04788489,732.23531572,0.04677374,767.29832246,0.00082448,0.07249531,833.25278864,-0.03817317,-0.03432214,0.00000000,0.00000000,0.00000000,0.00000000
120.00000000,1.47160400,11.01330000,0.04902278,734.57645175,0.04785904,770.58742991,0.00070173,0.07370056,835.70916291,-0.03882651,-0.03487405,0.00000000,0.00000000,0.00000000,0.00000000
121.50000000,1.50726300,11.04520000,0.05026222,736.70415088,0.04903987,773.73253863,0.00077985,0.07489731,837.46026667,-0.03941045,-0.03548686,0.00000000,0.00000000,0.00000000,0.00000000
123.00000000,1.54261900,11.07710000,0.05142267,738.83185001,0.05014417,776.82455396,0.00080035,0.07618501,839.47241068,-0.04014449,-0.03604051,0.00000000,0.00000000,0.00000000,0.00000000
124.50000000,1.57827900,11.12970000,0.05256067,742.34021911,0.05122593,781.35811592,0.00068522,0.07735262,841.61213613,-0.04075025,-0.03660237,0.00000000,0.00000000,0.00000000,0.00000000
126.00000000,1.61458100,11.13610000,0.05377744,742.76709291,0.05238127,782.71120899,0.00068443,0.07860712,843.37111605,-0.04140877,-0.03719835,0.00000000,0.00000000,0.00000000,0.00000000
127.50000000,1.65081600,11.16560000,0.05496800,744.73471436,0.05351043,785.67129214,0.00070494,0.07982779,845.39582069,-0.04206550,-0.03776230,0.00000000,0.00000000,0.00000000,0.00000000
129.00000000,1.68759100,11.19590000,0.05620367,746.75569504,0.05468103,788.72610321,0.00075400,0.08108860,847.33442527,-0.04274595,-0.03834265,0.00000000,0.00000000,0.00000000,0.00000000
130.50000000,1.72413000,11.22220000,0.05738667,748.50987959,0.05580046,791.46436655,0.00066780,0.08229900,849.41615533,-0.04339704,-0.03890196,0.00000000,0.00000000,0.00000000,0.00000000
132.00000000,1.76107400,11.24860000,0.05863356,750.27073404,0.05697898,794.26177481,0.00073105,0.08355300,851.41472137,-0.04411200,-0.03944100,0.00000000,0.00000000,0.00000000,0.00000000
133.50000000,1.79822100,11.27250000,0.05988422,751.86484091,0.05815968,796.88968212,0.00082940,0.08485464,853.17234484,-0.04482846,-0.04002618,0.00000000,0.00000000,0.00000000,0.00000000
135.00000000,1.83533500,11.29800000,0.06110100,753.56566623,0.05930705,799.60928200,0.00072223,0.08608565,854.98976024,-0.04544668,-0.04063897,0.00000000,0.00000000,0.00000000,0.00000000
136.50000000,1.87248200,11.32430000,0.06234789,755.31985078,0.06048145,802.41244891,0.00073540,0.08734539,856.94518352,-0.04614528,-0.04120011,0.00000000,0.00000000,0.00000000,0.00000000
138.00000000,1.91033900,11.34740000,0.06359856,756.86059842,0.06165802,804.99583924,0.00071343,0.08861302,858.33053697,-0.04684020,-0.04177283,0.00000000,0.00000000,0.00000000,0.00000000
139.50000000,1.94826300,11.36740000,0.06487922,758.19457907,0.06286139,807.38565365,0.00083971,0.08990232,860.56077046,-0.04755081,-0.04235152,0.00000000,0.00000000,0.00000000,0.00000000
141.00000000,1.98635700,11.38970000,0.06610733,759.68196749,0.06401401,809.90251654,0.00069778,0.09113043,862.38876413,-0.04816970,-0.04296073,0.00000000,0.00000000,0.00000000,0.00000000
142.50000000,2.02455200,11.41120000,0.06739178,761.11599668,0.06521808,812.40895679,0.00074609,0.09245746,863.88536288,-0.04886645,-0.04359101,0.00000000,0.00000000,0.00000000,0.00000000
144.00000000,2.06291600,11.43040000,0.06867244,762.39661810,0.06641717,814.75225750,0.00077328,0.09372872,865.99332474,-0.04959069,-0.04413804,0.00000000,0.00000000,0.00000000,0.00000000
145.50000000,2.10161800,11.44790000,0.06991933,763.56385116,0.06758326,816.95172660,0.00078651,0.09500595,867.22301679,-0.05027850,-0.04472745,0.00000000,0.00000000,0.00000000,0.00000000
147.00000000,2.14021900,11.46790000,0.07120000,764.89783181,0.06877952,819.35855743,0.00077851,0.09628468,869.22589464,-0.05097684,-0.04530784,0.00000000,0.00000000,0.00000000,0.00000000
148.50000000,2.17875200,11.48620000,0.07248067,766.11842410,0.06997435,821.64719822,0.00078463,0.09755892,870.39071850,-0.05168301,-0.04587591,0.00000000,0.00000000,0.00000000,0.00000000
150.00000000,2.21829900,11.50370000,0.07378011,767.28565716,0.07118524,823.89607820,0.00081163,0.09883650,872.63655149,-0.05236437,-0.04647213,0.00000000,0.00000000,0.00000000,0.00000000
151.50000000,2.25686600,11.51970000,0.07509089,768.35284168,0.07240521,826.04913954,0.00079678,0.10013405,873.89325615,-0.05306684,-0.04706721,0.00000000,0.00000000,0.00000000,0.00000000
153.00000000,2.29671800,11.53410000,0.07637533,769.31330774,0.07359922,828.06986806,0.00080286,0.10145463,875.64840978,-0.05378290,-0.04767173,0.00000000,0.00000000,0.00000000,0.00000000
154.50000000,2.33589300,11.55560000,0.07770478,770.74733694,0.07483357,830.63808748,0.00085055,0.10279080,877.30117627,-0.05456318,-0.04822762,0.00000000,0.00000000,0.00000000,0.00000000
156.00000000,2.37500100,11.56750000,0.07903433,771.54105542,0.07606651,832.51928838,0.00091914,0.10401861,878.67459368,-0.05510683,-0.04891178,0.00000000,0.00000000,0.00000000,0.00000000
157.50000000,2.41515600,11.58350000,0.08035633,772.60823994,0.07729092,834.69220520,0.00086924,0.10532781,880.30883520,-0.05580740,-0.04952040,0.00000000,0.00000000,0.00000000,0.00000000
159.00000000,2.45551500,11.60100000,0.08167456,773.77547300,0.07851035,836.97324086,0.00087517,0.10665931,881.84588858,-0.05652895,-0.05013036,0.00000000,0.00000000,0.00000000,0.00000000
160.50000000,2.49617800,11.61300000,0.08300022,774.57586139,0.07973517,838.86583001,0.00083920,0.10795108,883.59003085,-0.05726254,-0.05068855,0.00000000,0.00000000,0.00000000,0.00000000
162.00000000,2.53619800,11.62420000,0.08435978,775.32289055,0.08098975,840.72895730,0.00093533,0.10928019,884.89021544,-0.05795486,-0.05132533,0.00000000,0.00000000,0.00000000,0.00000000
163.50000000,2.57662400,11.64010000,0.08572689,776.38340516,0.08224971,842.94033907,0.00087191,0.11063050,886.27128948,-0.05868509,-0.05194541,0.00000000,0.00000000,0.00000000,0.00000000
165.00000000,2.61765900,11.65530000,0.08705267,777.39723045,0.08347006,845.07173242,0.00069108,0.11195013,888.10111418,-0.05938056,-0.05256957,0.00000000,0.00000000,0.00000000,0.00000000
166.50000000,2.65865900,11.66640000,0.08843467,778.13758971,0.08474058,846.95192808,0.00092489,0.11327558,889.04296979,-0.06010612,-0.05316946,0.00000000,0.00000000,0.00000000,0.00000000
168.00000000,2.69942300,11.67600000,0.08973044,778.77790042,0.08593037,848.65798755,0.00077221,0.11459002,890.51904484,-0.06081566,-0.05377436,0.00000000,0.00000000,0.00000000,0.00000000
169.50000000,2.74076200,11.69430000,0.09113133,779.99849271,0.08721508,851.08079535,0.00079872,0.11602487,892.22622157,-0.06163582,-0.05438904,0.00000000,0.00000000,0.00000000,0.00000000
171.00000000,2.78213500,11.70230000,0.09247956,780.53208497,0.08844993,852.71534528,0.00081137,0.11731547,893.74648643,-0.06230111,-0.05501436,0.00000000,0.00000000,0.00000000,0.00000000
172.50000000,2.82438600,11.71350000,0.09386922,781.27911413,0.08972116,854.61717691,0.00076928,0.11870399,895.29664064,-0.06305654,-0.05564745,0.00000000,0.00000000,0.00000000,0.00000000
174.00000000,2.86626600,11.72150000,0.09530378,781.81270639,0.09103175,856.32241082,0.00088478,0.12009218,896.48499671,-0.06378048,-0.05631170,0.00000000,0.00000000,0.00000000,0.00000000
175.50000000,2.90801000,11.73180000,0.09668967,782.49970642,0.09229625,858.15934220,0.00089055,0.12147680,898.03632930,-0.06455958,-0.05691722,0.00000000,0.00000000,0.00000000,0.00000000
177.00000000,2.94978800,11.74060000,0.09803044,783.08665790,0.09351807,859.85299101,0.00076637,0.12279381,899.46832408,-0.06527017,-0.05752364,0.00000000,0.00000000,0.00000000,0.00000000
178.50000000,2.99231000,11.75100000,0.09945011,783.78032784,0.09481016,861.72736853,0.00081997,0.12417610,900.71786680,-0.06599187,-0.05818423,0.00000000,0.00000000,0.00000000,0.00000000
180.00000000,3.03469600,11.75970000,0.10091100,784.36060942,0.09613802,863.51122287,0.00096226,0.12552324,901.99832855,-0.06669750,-0.05882574,0.00000000,0.00000000,0.00000000,0.00000000
181.50000000,3.07731900,11.76690000,0.10230067,784.84084245,0.09739951,865.13058386,0.00087251,0.12693413,903.33846049,-0.06749808,-0.05943605,0.00000000,0.00000000,0.00000000,0.00000000
183.00000000,3.12031500,11.77650000,0.10372022,785.48115316,0.09868649,866.95143292,0.00083714,0.12830867,905.00703994,-0.06821608,-0.06009259,0.00000000,0.00000000,0.00000000,0.00000000
184.50000000,3.16368100,11.78610000,0.10519622,786.12146387,0.10002290,868.81847207,0.00084286,0.12974743,906.56083296,-0.06900599,-0.06074144,0.00000000,0.00000000,0.00000000,0.00000000
186.00000000,3.20657500,11.78690000,0.10661211,786.17482309,0.10130320,869.99058069,0.00088257,0.13118595,907.74880350,-0.06979636,-0.06138959,0.00000000,0.00000000,0.00000000,0.00000000
187.50000000,3.24967100,11.79480000,0.10803556,786.70174545,0.10258868,871.69350557,0.00094263,0.13255707,908.87679984,-0.07049811,-0.06205896,0.00000000,0.00000000,0.00000000,0.00000000
189.00000000,3.29310500,11.80360000,0.10942889,787.28869693,0.10384537,873.44082427,0.00075849,0.13395779,910.27940229,-0.07124114,-0.06271666,0.00000000,0.00000000,0.00000000,0.00000000
190.50000000,3.33691200,11.80520000,0.11092367,787.39541538,0.10519180,874.73620197,0.00097400,0.13535586,911.80497970,-0.07204264,-0.06331322,0.00000000,0.00000000,0.00000000,0.00000000
192.00000000,3.38041300,11.81800000,0.11233200,788.24916300,0.10645871,876.79476797,0.00080368,0.13681864,913.02212386,-0.07285766,-0.06396099,0.00000000,0.00000000,0.00000000,0.00000000
193.50000000,3.42435500,11.81950000,0.11380800,788.34921154,0.10778477,878.06965861,0.00080940,0.13821482,914.11791843,-0.07358672,-0.06462810,0.00000000,0.00000000,0.00000000,0.00000000
195.00000000,3.46897200,11.82990000,0.11526144,789.04288148,0.10908886,879.98910373,0.00090283,0.13960425,916.19905500,-0.07432056,-0.06528368,0.00000000,0.00000000,0.00000000,0.00000000
196.50000000,3.51332000,11.83390000,0.11672989,789.30967761,0.11040467,881.44570858,0.00084769,0.14106352,916.86107677,-0.07520153,-0.06586199,0.00000000,0.00000000,0.00000000,0.00000000
198.00000000,3.55817300,11.83790000,0.11821333,789.57647374,0.11173217,882.91494062,0.00092709,0.14248678,917.80800107,-0.07592883,-0.06655794,0.00000000,0.00000000,0.00000000,0.00000000
199.50000000,3.60279000,11.84110000,0.11964800,789.78991064,0.11301435,884.28669387,0.00074482,0.14393890,919.08544142,-0.07672592,-0.06721298,0.00000000,0.00000000,0.00000000,0.00000000
201.00000000,3.64798300,11.84430000,0.12119167,790.00334754,0.11439211,885.74516991,0.00094485,0.14532531,920.11717028,-0.07750331,-0.06782200,0.00000000,0.00000000,0.00000000,0.00000000
202.50000000,3.69314100,11.85060000,0.12266011,790.42355145,0.11570097,887.37699209,0.00090342,0.14675888,924.41972942,-0.07823804,-0.06852085,0.00000000,0.00000000,0.00000000,0.00000000
204.00000000,3.73917800,11.84990000,0.12416611,790.37686212,0.11704153,888.51488341,0.00086878,0.00000000,0.00000000,0.00000000,0.00000000,0.00000000,0.00000000,0.00000000,0.00000000
205.50000000,3.78484300,11.85860000,0.12572467,790.95714371,0.11842698,890.39996695,0.00083420,0.00000000,0.00000000,0.00000000,0.00000000,0.00000000,0.00000000,0.00000000,0.00000000
207.00000000,3.83064400,11.86020000,0.12724200,791.06386216,0.11977394,891.72041011,0.00093307,0.00000000,0.00000000,0.00000000,0.00000000,0.00000000,0.00000000,0.00000000,0.00000000
208.50000000,3.87698500,11.86660000,0.12878178,791.49073596,0.12113898,893.42032004,0.00093180,0.00000000,0.00000000,0.00000000,0.00000000,0.00000000,0.00000000,0.00000000,0.00000000
210.00000000,3.92319100,11.86900000,0.13032167,791.65081364,0.12250225,894.82006709,0.00093053,0.00000000,0.00000000,0.00000000,0.00000000,0.00000000,0.00000000,0.00000000,0.00000000
211.50000000,3.97027500,11.86660000,0.13186144,791.49073596,0.12386357,895.85784767,0.00086288,0.00000000,0.00000000,0.00000000,0.00000000,0.00000000,0.00000000,0.00000000,0.00000000
213.00000000,4.01668400,11.87300000,0.13343889,791.91760977,0.12525628,897.59021571,0.00092817,0.00000000,0.00000000,0.00000000,0.00000000,0.00000000,0.00000000,0.00000000,0.00000000
214.50000000,4.06447900,11.87540000,0.13497867,792.07768745,0.12661385,898.99127760,0.00086050,0.00000000,0.00000000,0.00000000,0.00000000,0.00000000,0.00000000,0.00000000,0.00000000
216.00000000,4.11183400,11.88020000,0.13655600,792.39784280,0.12800264,900.60452262,0.00099154,0.00000000,0.00000000,0.00000000,0.00000000,0.00000000,0.00000000,0.00000000,0.00000000
217.50000000,4.15949300,11.87780000,0.13817100,792.23776512,0.12942259,901.70204937,0.00105616,0.00000000,0.00000000,0.00000000,0.00000000,0.00000000,0.00000000,0.00000000,0.00000000
219.00000000,4.20722100,11.88100000,0.13971078,792.45120203,0.13077453,903.16517581,0.00085693,0.00000000,0.00000000,0.00000000,0.00000000,0.00000000,0.00000000,0.00000000,0.00000000
220.50000000,4.25542100,11.88330000,0.14128822,792.60460980,0.13215764,904.59030605,0.00085575,0.00000000,0.00000000,0.00000000,0.00000000,0.00000000,0.00000000,0.00000000,0.00000000
222.00000000,4.30358700,11.88180000,0.14290311,792.50456125,0.13357161,905.75592863,0.00098604,0.00000000,0.00000000,0.00000000,0.00000000,0.00000000,0.00000000,0.00000000,0.00000000
223.50000000,4.35222600,11.88570000,0.14451811,792.76468748,0.13498368,907.33354267,0.00085353,0.00000000,0.00000000,0.00000000,0.00000000,0.00000000,0.00000000,0.00000000,0.00000000
225.00000000,4.40096800,11.88570000,0.14613300,792.76468748,0.13639367,908.61376955,0.00091769,0.00000000,0.00000000,0.00000000,0.00000000,0.00000000,0.00000000,0.00000000,0.00000000
226.50000000,4.45004700,11.88570000,0.14778544,792.76468748,0.13783439,909.92376916,0.00098184,0.00000000,0.00000000,0.00000000,0.00000000,0.00000000,0.00000000,0.00000000,0.00000000
228.00000000,4.49926100,11.88410000,0.14940044,792.65796903,0.13924045,911.08142189,0.00091508,0.00000000,0.00000000,0.00000000,0.00000000,0.00000000,0.00000000,0.00000000,0.00000000
229.50000000,4.54884700,11.88180000,0.15101533,792.50456125,0.14064445,912.18490174,0.00084851,0.00000000,0.00000000,0.00000000,0.00000000,0.00000000,0.00000000,0.00000000,0.00000000
231.00000000,4.59839900,11.88330000,0.15270544,792.60460980,0.14211174,913.63964901,0.00097765,0.00000000,0.00000000,0.00000000,0.00000000,0.00000000,0.00000000,0.00000000,0.00000000
232.50000000,4.64856000,11.88650000,0.15432033,792.81804670,0.14351171,915.16599195,0.00091118,0.00000000,0.00000000,0.00000000,0.00000000,0.00000000,0.00000000,0.00000000,0.00000000
234.00000000,4.69902400,11.88330000,0.15597289,792.60460980,0.14494232,916.22944054,0.00097489,0.00000000,0.00000000,0.00000000,0.00000000,0.00000000,0.00000000,0.00000000,0.00000000
235.50000000,4.75013100,11.88330000,0.15762533,792.60460980,0.14637078,917.53917562,0.00097349,0.00000000,0.00000000,0.00000000,0.00000000,0.00000000,0.00000000,0.00000000,0.00000000
237.00000000,4.80117100,11.87940000,0.15931544,792.34448358,0.14782970,918.57719713,0.00103690,0.00000000,0.00000000,0.00000000,0.00000000,0.00000000,0.00000000,0.00000000,0.00000000
238.50000000,4.85210900,11.88020000,0.16093033,792.39784280,0.14922170,919.91869178,0.00090599,0.00000000,0.00000000,0.00000000,0.00000000,0.00000000,0.00000000,0.00000000,0.00000000
240.00000000,4.90406100,11.87860000,0.16262044,792.29112435,0.15067646,921.13385912,0.00090467,0.00000000,0.00000000,0.00000000,0.00000000,0.00000000,0.00000000,0.00000000,0.00000000
241.50000000,4.95574300,11.86980000,0.16434800,791.70417287,0.00000000,0.00000000,0.00000000,0.00000000,0.00000000,0.00000000,0.00000000,0.00000000,0.00000000,0.00000000,0.00000000
243.00000000,5.00803300,11.87220000,0.16600056,791.86425054,0.00000000,0.00000000,0.00000000,0.00000000,0.00000000,0.00000000,0.00000000,0.00000000,0.00000000,0.00000000,0.00000000
244.50000000,5.06184400,11.87060000,0.16769056,791.75753209,0.00000000,0.00000000,0.00000000,0.00000000,0.00000000,0.00000000,0.00000000,0.00000000,0.00000000,0.00000000,0.00000000
246.00000000,5.11464100,11.87060000,0.16938067,791.75753209,0.00000000,0.00000000,0.00000000,0.00000000,0.00000000,0.00000000,0.00000000,0.00000000,0.00000000,0.00000000,0.00000000
247.50000000,5.16814800,11.86340000,0.17107078,791.27729906,0.00000000,0.00000000,0.00000000,0.00000000,0.00000000,0.00000000,0.00000000,0.00000000,0.00000000,0.00000000,0.00000000
249.00000000,5.22277000,11.85780000,0.17268567,790.90378448,0.00000000,0.00000000,0.00000000,0.00000000,0.00000000,0.00000000,0.00000000,0.00000000,0.00000000,0.00000000,0.00000000
250.50000000,5.27678400,11.85300000,0.17433822,790.58362912,0.00000000,0.00000000,0.00000000,0.00000000,0.00000000,0.00000000,0.00000000,0.00000000,0.00000000,0.00000000,0.00000000
252.00000000,5.33123700,11.84590000,0.17595322,790.11006600,0.00000000,0.00000000,0.00000000,0.00000000,0.00000000,0.00000000,0.00000000,0.00000000,0.00000000,0.00000000,0.00000000
253.50000000,5.38680600,11.84110000,0.17756822,789.78991064,0.00000000,0.00000000,0.00000000,0.00000000,0.00000000,0.00000000,0.00000000,0.00000000,0.00000000,0.00000000,0.00000000
255.00000000,5.44278000,11.83550000,0.17907044,789.41639606,0.00000000,0.00000000,0.00000000,0.00000000,0.00000000,0.00000000,0.00000000,0.00000000,0.00000000,0.00000000,0.00000000
256.50000000,5.49895800,11.82350000,0.18049767,788.61600767,0.00000000,0.00000000,0.00000000,0.00000000,0.00000000,0.00000000,0.00000000,0.00000000,0.00000000,0.00000000,0.00000000
258.00000000,5.55523600,11.81480000,0.18196244,788.03572609,0.00000000,0.00000000,0.00000000,0.00000000,0.00000000,0.00000000,0.00000000,0.00000000,0.00000000,0.00000000,0.00000000
259.50000000,5.61317100,11.81160000,0.18335200,787.82228919,0.00000000,0.00000000,0.00000000,0.00000000,0.00000000,0.00000000,0.00000000,0.00000000,0.00000000,0.00000000,0.00000000
261.00000000,5.67147800,11.79880000,0.18466667,786.96854158,0.00000000,0.00000000,0.00000000,0.00000000,0.00000000,0.00000000,0.00000000,0.00000000,0.00000000,0.00000000,0.00000000
262.50000000,5.72934500,11.78610000,0.18583100,786.12146387,0.00000000,0.00000000,0.00000000,0.00000000,0.00000000,0.00000000,0.00000000,0.00000000,0.00000000,0.00000000,0.00000000
264.00000000,5.78795600,11.77170000,0.18692022,785.16099780,0.00000000,0.00000000,0.00000000,0.00000000,0.00000000,0.00000000,0.00000000,0.00000000,0.00000000,0.00000000,0.00000000
265.50000000,5.84747900,11.75500000,0.18789689,784.04712397,0.00000000,0.00000000,0.00000000,0.00000000,0.00000000,0.00000000,0.00000000,0.00000000,0.00000000,0.00000000,0.00000000
267.00000000,5.90720600,11.73740000,0.18879833,782.87322100,0.00000000,0.00000000,0.00000000,0.00000000,0.00000000,0.00000000,0.00000000,0.00000000,0.00000000,0.00000000,0.00000000
268.50000000,5.96733800,11.71590000,0.18951211,781.43919180,0.00000000,0.00000000,0.00000000,0.00000000,0.00000000,0.00000000,0.00000000,0.00000000,0.00000000,0.00000000,0.00000000
270.00000000,6.02709900,11.69350000,0.19015067,779.94513348,0.00000000,0.00000000,0.00000000,0.00000000,0.00000000,0.00000000,0.00000000,0.00000000,0.00000000,0.00000000,0.00000000
271.50000000,6.08882000,11.67200000,0.19071422,778.51110429,0.00000000,0.00000000,0.00000000,0.00000000,0.00000000,0.00000000,0.00000000,0.00000000,0.00000000,0.00000000,0.00000000
273.00000000,6.15000000,11.63930000,0.19109000,776.33004594,0.00000000,0.00000000,0.00000000,0.00000000,0.00000000,0.00000000,0.00000000,0.00000000,0.00000000,0.00000000,0.00000000
274.50000000,6.21128200,11.60820000,0.19139067,774.25570603,0.00000000,0.00000000,0.00000000,0.00000000,0.00000000,0.00000000,0.00000000,0.00000000,0.00000000,0.00000000,0.00000000
276.00000000,6.27290300,11.57150000,0.19165378,771.80785155,0.00000000,0.00000000,0.00000000,0.00000000,0.00000000,0.00000000,0.00000000,0.00000000,0.00000000,0.00000000,0.00000000
277.50000000,6.33482900,11.53560000,0.19172922,769.41335629,0.00000000,0.00000000,0.00000000,0.00000000,0.00000000,0.00000000,0.00000000,0.00000000,0.00000000,0.00000000,0.00000000
279.00000000,6.39824400,11.49020000,0.19191722,766.38522023,0.00000000,0.00000000,0.00000000,0.00000000,0.00000000,0.00000000,0.00000000,0.00000000,0.00000000,0.00000000,0.00000000
280.50000000,6.46088300,11.44150000,0.19195500,763.13697736,0.00000000,0.00000000,0.00000000,0.00000000,0.00000000,0.00000000,0.00000000,0.00000000,0.00000000,0.00000000,0.00000000
282.00000000,6.52366000,11.38490000,0.19199289,759.36181213,0.00000000,0.00000000,0.00000000,0.00000000,0.00000000,0.00000000,0.00000000,0.00000000,0.00000000,0.00000000,0.00000000
283.50000000,6.58735400,11.32350000,0.19203089,755.26649155,0.00000000,0.00000000,0.00000000,0.00000000,0.00000000,0.00000000,0.00000000,0.00000000,0.00000000,0.00000000,0.00000000
285.00000000,6.65206900,11.24220000,0.19206889,749.84386023,0.00000000,0.00000000,0.00000000,0.00000000,0.00000000,0.00000000,0.00000000,0.00000000,0.00000000,0.00000000,0.00000000
286.50000000,6.71787800,11.15450000,0.19199456,743.99435511,0.00000000,0.00000000,0.00000000,0.00000000,0.00000000,0.00000000,0.00000000,0.00000000,0.00000000,0.00000000,0.00000000
288.00000000,6.78600500,11.03080000,0.19188311,735.74368482,0.00000000,0.00000000,0.00000000,0.00000000,0.00000000,0.00000000,0.00000000,0.00000000,0.00000000,0.00000000,0.00000000
289.50000000,6.86143500,10.81230000,0.19181033,721.16994627,0.00000000,0.00000000,0.00000000,0.00000000,0.00000000,0.00000000,0.00000000,0.00000000,0.00000000,0.00000000,0.00000000