File: LAB_DATA/DP780_results/DATA/UT_75_2.csv
Time[s],Displacement[mm],Force[kN],EngStrain_longi,EngStress[MPa],TrueStrain,TrueStress[MPa],TrueStrainRate[1/s],PlasticStrain_longi,PlasticStress[MPa],PlasticStrain_thick,PlasticStrain_width,R-Value,Thickness[mm],Width[mm], Young's Modulus [MPa]
0.00000000,0.00000000,-0.02690000,0.00000000,-1.79374258,0.00000000,-1.79374258,0.00000000,0.00058083,421.57235248,0.00043256,-0.00101339,0.90479530,1.50680000,9.95260000,251387.01677622
1.00000000,0.00197500,0.24660000,0.00008911,16.44375172,0.00008911,16.44521704,0.00015021,0.00073892,430.02785038,0.00028944,-0.00102836,0.00000000,0.00000000,0.00000000,0.00000000
2.00000000,0.00355400,0.46910000,0.00010556,31.28047012,0.00010555,31.28377195,0.00002333,0.00076241,438.42755274,0.00035980,-0.00112220,0.00000000,0.00000000,0.00000000,0.00000000
3.00000000,0.00405600,0.70190000,0.00013789,46.80401189,0.00013788,46.81046564,0.00010221,0.00098466,446.70283222,0.00010858,-0.00109324,0.00000000,0.00000000,0.00000000,0.00000000
4.00000000,0.00544900,0.93960000,0.00014278,62.65429487,0.00014277,62.66324051,0.00003999,0.00113323,454.78790846,0.00007669,-0.00120992,0.00000000,0.00000000,0.00000000,0.00000000
5.00000000,0.00636600,1.16050000,0.00018033,77.38432226,0.00018032,77.39827723,0.00003022,0.00121990,462.58576236,0.00023917,-0.00145908,0.00000000,0.00000000,0.00000000,0.00000000
6.00000000,0.00819800,1.37740000,0.00026489,91.84762213,0.00026485,91.87195154,0.00000022,0.00153394,470.43236895,-0.00001637,-0.00151757,0.00000000,0.00000000,0.00000000,0.00000000
7.00000000,0.00950400,1.58240000,0.00029300,105.51740762,0.00029296,105.54832422,0.00006754,0.00172614,477.15912868,-0.00012987,-0.00159627,0.00000000,0.00000000,0.00000000,0.00000000
8.00000000,0.01064500,1.75620000,0.00033444,117.10671844,0.00033439,117.14588414,-0.00002621,0.00187897,484.24563885,-0.00026565,-0.00161332,0.00000000,0.00000000,0.00000000,0.00000000
9.00000000,0.01318600,1.94200000,0.00044644,129.49621183,0.00044634,129.55402470,0.00017282,0.00206504,491.45185673,-0.00030274,-0.00176229,0.00000000,0.00000000,0.00000000,0.00000000
10.00000000,0.01286800,2.12460000,0.00042211,141.67232320,0.00042202,141.73212466,-0.00002554,0.00223699,498.49973615,-0.00025462,-0.00198237,0.00000000,0.00000000,0.00000000,0.00000000
11.00000000,0.01539600,2.30730000,0.00049289,153.85510276,0.00049277,153.93093623,0.00003154,0.00253767,505.18582361,-0.00037967,-0.00215800,0.00000000,0.00000000,0.00000000,0.00000000
12.00000000,0.01559000,2.48430000,0.00051411,165.65779560,0.00051398,165.74296211,0.00006841,0.00274993,511.61592861,-0.00045780,-0.00229213,0.00000000,0.00000000,0.00000000,0.00000000
13.00000000,0.01860600,2.66050000,0.00058022,177.40714293,0.00058005,177.51007850,-0.00000911,0.00314664,518.46760947,-0.00071261,-0.00243403,0.00000000,0.00000000,0.00000000,0.00000000
14.00000000,0.01898600,2.83120000,0.00061978,188.78973993,0.00061959,188.90674761,0.00004064,0.00331866,524.61506958,-0.00078974,-0.00252892,0.00000000,0.00000000,0.00000000,0.00000000
15.00000000,0.02099000,2.99950000,0.00065556,200.01230041,0.00065534,200.14341958,-0.00007195,0.00374525,530.63138266,-0.00104410,-0.00270115,0.00000000,0.00000000,0.00000000,0.00000000
16.00000000,0.02248400,3.16380000,0.00071622,210.96813336,0.00071597,211.11923343,0.00006928,0.00395347,536.21934349,-0.00110241,-0.00285106,0.00000000,0.00000000,0.00000000,0.00000000
17.00000000,0.02364500,3.32090000,0.00073800,221.44385678,0.00073773,221.60728235,-0.00010237,0.00439759,541.66204642,-0.00136940,-0.00302819,0.00000000,0.00000000,0.00000000,0.00000000
18.00000000,0.02589800,3.48270000,0.00089344,232.23298504,0.00089305,232.44047231,0.00025645,0.00472426,547.42921565,-0.00155907,-0.00316518,0.00000000,0.00000000,0.00000000,0.00000000
19.00000000,0.02672600,3.65260000,0.00084711,243.56223653,0.00084675,243.76856080,-0.00006728,0.00503893,553.34872207,-0.00166332,-0.00337561,0.00000000,0.00000000,0.00000000,0.00000000
20.00000000,0.02957200,3.81850000,0.00100111,254.62476049,0.00100061,254.87966817,0.00026242,0.00546823,558.64223753,-0.00192365,-0.00354458,0.00000000,0.00000000,0.00000000,0.00000000
21.00000000,0.03052600,3.97720000,0.00094867,265.20717492,0.00094822,265.45876813,-0.00009746,0.00577032,564.02362478,-0.00205497,-0.00371535,0.00000000,0.00000000,0.00000000,0.00000000
22.00000000,0.03269700,4.13910000,0.00113278,276.00297137,0.00113214,276.31562140,0.00018025,0.00629974,569.32915058,-0.00240925,-0.00389050,0.00000000,0.00000000,0.00000000,0.00000000
23.00000000,0.03473100,4.29460000,0.00108811,286.37200378,0.00108752,286.68360833,-0.00002220,0.00650951,574.50348251,-0.00239652,-0.00411299,0.00000000,0.00000000,0.00000000,0.00000000
24.00000000,0.03619100,4.45410000,0.00129878,297.00776371,0.00129794,297.39351079,0.00027033,0.00706486,579.72582196,-0.00274906,-0.00431581,0.00000000,0.00000000,0.00000000,0.00000000
25.00000000,0.03883500,4.60960000,0.00121267,307.37679612,0.00121193,307.74954171,0.00000755,0.00738495,584.32968842,-0.00282272,-0.00456223,0.00000000,0.00000000,0.00000000,0.00000000
26.00000000,0.04016000,4.75550000,0.00142667,317.10568247,0.00142565,317.55808658,0.00018752,0.00788309,588.98774373,-0.00305747,-0.00482562,0.00000000,0.00000000,0.00000000,0.00000000
27.00000000,0.04381500,4.90150000,0.00134011,326.84123702,0.00133921,327.27924059,0.00004461,0.00832385,593.94092171,-0.00320792,-0.00511593,0.00000000,0.00000000,0.00000000,0.00000000
28.00000000,0.04540800,5.04740000,0.00153978,336.57012338,0.00153859,337.08836657,0.00014290,0.00873842,598.88285574,-0.00344409,-0.00529432,0.00000000,0.00000000,0.00000000,0.00000000
29.00000000,0.04909900,5.19970000,0.00155878,346.72577377,0.00155756,347.26624220,0.00018017,0.00913504,603.65571790,-0.00361240,-0.00552264,0.00000000,0.00000000,0.00000000,0.00000000
30.00000000,0.05160400,5.36080000,0.00173111,357.46822471,0.00172961,358.08704193,0.00011957,0.00966580,608.29086373,-0.00397063,-0.00569518,0.00000000,0.00000000,0.00000000,0.00000000
31.00000000,0.05546100,5.49480000,0.00174633,366.40359669,0.00174481,367.04345950,0.00012002,0.01006350,612.75432050,-0.00414517,-0.00591833,0.00000000,0.00000000,0.00000000,0.00000000
32.00000000,0.05823300,5.63910000,0.00196067,376.02579204,0.00195875,376.76305328,0.00009759,0.01064114,617.53620873,-0.00448686,-0.00615428,0.00000000,0.00000000,0.00000000,0.00000000
33.00000000,0.06192000,5.78350000,0.00197211,385.65465558,0.00197017,386.41520941,0.00015725,0.01096481,621.90064099,-0.00463705,-0.00632777,0.00000000,0.00000000,0.00000000,0.00000000
34.00000000,0.06564000,5.91820000,0.00217478,394.63670487,0.00217242,395.49495201,0.00002240,0.01152514,626.31489738,-0.00493885,-0.00658629,0.00000000,0.00000000,0.00000000,0.00000000
35.00000000,0.07027100,6.04820000,0.00226089,403.30534933,0.00225834,404.21717791,0.00026231,0.01201409,630.08468302,-0.00521140,-0.00680269,0.00000000,0.00000000,0.00000000,0.00000000
36.00000000,0.07506700,6.17500000,0.00241900,411.76061177,0.00241608,412.75666069,-0.00008934,0.01251348,634.73429051,-0.00543209,-0.00708139,0.00000000,0.00000000,0.00000000,0.00000000
37.00000000,0.07915700,6.30580000,0.00259167,420.48260173,0.00258831,421.57235248,0.00031476,0.01300682,639.05846807,-0.00568662,-0.00732019,0.00000000,0.00000000,0.00000000,0.00000000
38.00000000,0.08510400,6.43100000,0.00279056,428.83117317,0.00278667,430.02785038,0.00017219,0.01357048,643.26910376,-0.00593742,-0.00763306,0.00000000,0.00000000,0.00000000,0.00000000
39.00000000,0.08885600,6.55620000,0.00285422,437.17974460,0.00285016,438.42755274,0.00012720,0.01402027,647.30843173,-0.00613609,-0.00788418,0.00000000,0.00000000,0.00000000,0.00000000
40.00000000,0.09554600,6.67820000,0.00311667,445.31493401,0.00311182,446.70283222,0.00023151,0.01463908,651.45505613,-0.00646821,-0.00817087,0.00000000,0.00000000,0.00000000,0.00000000
41.00000000,0.10148900,6.79780000,0.00330433,453.29008692,0.00329889,454.78790846,0.00039673,0.01511031,655.50968207,-0.00670189,-0.00840842,0.00000000,0.00000000,0.00000000,0.00000000
42.00000000,0.10662300,6.91350000,0.00342856,461.00518048,0.00342269,462.58576236,0.00009014,0.01564509,659.33754362,-0.00696351,-0.00868158,0.00000000,0.00000000,0.00000000,0.00000000
43.00000000,0.11442300,7.02830000,0.00378122,468.66026036,0.00377409,470.43236895,0.00026922,0.01623074,663.26468337,-0.00731590,-0.00891484,0.00000000,0.00000000,0.00000000,0.00000000
44.00000000,0.12155100,7.12720000,0.00400633,475.25509834,0.00399833,477.15912868,0.00035151,0.01673760,666.64545606,-0.00757451,-0.00916308,0.00000000,0.00000000,0.00000000,0.00000000
45.00000000,0.12901700,7.23170000,0.00419367,482.22335484,0.00418490,484.24563885,0.00016443,0.01729287,670.61520498,-0.00787446,-0.00941841,0.00000000,0.00000000,0.00000000,0.00000000
46.00000000,0.13580600,7.33770000,0.00441500,489.29163417,0.00440528,491.45185673,0.00026153,0.01792533,674.52539941,-0.00826392,-0.00966142,0.00000000,0.00000000,0.00000000,0.00000000
47.00000000,0.14441600,7.44140000,0.00462144,496.20654517,0.00461080,498.49973615,0.00022431,0.01845179,678.21102931,-0.00850744,-0.00994435,0.00000000,0.00000000,0.00000000,0.00000000
48.00000000,0.15275900,7.53870000,0.00495556,502.69469214,0.00494332,505.18582361,0.00034366,0.01902666,681.70786713,-0.00883105,-0.01019561,0.00000000,0.00000000,0.00000000,0.00000000
49.00000000,0.16140600,7.63280000,0.00519967,508.96945709,0.00518620,511.61592861,0.00004488,0.01957454,685.41593814,-0.00911307,-0.01046147,0.00000000,0.00000000,0.00000000,0.00000000
50.00000000,0.17188000,7.73170000,0.00563133,515.56429507,0.00561554,518.46760947,0.00046322,0.02019329,688.78659779,-0.00946382,-0.01072947,0.00000000,0.00000000,0.00000000,0.00000000
51.00000000,0.18184500,7.82180000,0.00583378,521.57233249,0.00581683,524.61506958,0.00004485,0.02078068,692.53013758,-0.00980459,-0.01097608,0.00000000,0.00000000,0.00000000,0.00000000
52.00000000,0.19282400,7.90790000,0.00629178,527.31364240,0.00627207,530.63138266,0.00050003,0.02143301,695.60324996,-0.01013707,-0.01129593,0.00000000,0.00000000,0.00000000,0.00000000
53.00000000,0.20306000,7.98930000,0.00652811,532.74154747,0.00650690,536.21934349,0.00010421,0.02192755,698.68621065,-0.01035454,-0.01157301,0.00000000,0.00000000,0.00000000,0.00000000
54.00000000,0.21383800,8.06660000,0.00700133,537.89605683,0.00697694,541.66204642,0.00062660,0.02255645,701.92168401,-0.01072102,-0.01183542,0.00000000,0.00000000,0.00000000,0.00000000
55.00000000,0.22610400,8.14960000,0.00735800,543.43065291,0.00733106,547.42921565,0.00043992,0.02319947,705.17104556,-0.01100994,-0.01218953,0.00000000,0.00000000,0.00000000,0.00000000
56.00000000,0.23718800,8.23490000,0.00770344,549.11861731,0.00767392,553.34872207,0.00033522,0.02381613,708.50877842,-0.01135695,-0.01245918,0.00000000,0.00000000,0.00000000,0.00000000
57.00000000,0.24921800,8.30990000,0.00816156,554.11975834,0.00812843,558.64223753,0.00045434,0.02439253,711.77356011,-0.01162466,-0.01276787,0.00000000,0.00000000,0.00000000,0.00000000
58.00000000,0.26212600,8.38720000,0.00849200,559.27426770,0.00845615,564.02362478,0.00035744,0.02508047,714.51618510,-0.01207316,-0.01300731,0.00000000,0.00000000,0.00000000,0.00000000
59.00000000,0.27456200,8.46140000,0.00905156,564.22206323,0.00901084,569.32915058,0.00060308,0.02569217,717.86876191,-0.01236440,-0.01332777,0.00000000,0.00000000,0.00000000,0.00000000
60.00000000,0.28706500,8.53630000,0.00928811,569.21653608,0.00924524,574.50348251,0.00031268,0.02632397,720.74351879,-0.01271149,-0.01361249,0.00000000,0.00000000,0.00000000,0.00000000
61.00000000,0.30115700,8.60890000,0.00987389,574.05764060,0.00982546,579.72582196,0.00052819,0.02698152,723.46793941,-0.01306529,-0.01391622,0.00000000,0.00000000,0.00000000,0.00000000
62.00000000,0.31521700,8.67430000,0.01021933,578.41863558,0.01016747,584.32968842,0.00046090,0.02760187,726.28594027,-0.01340101,-0.01420085,0.00000000,0.00000000,0.00000000,0.00000000
63.00000000,0.32789000,8.73890000,0.01074511,582.72628505,0.01068779,588.98774373,0.00039403,0.02821372,729.26678249,-0.01372579,-0.01448793,0.00000000,0.00000000,0.00000000,0.00000000
64.00000000,0.34262500,8.80830000,0.01121456,587.35400756,0.01115214,593.94092171,0.00054969,0.02889244,731.85787358,-0.01407593,-0.01481652,0.00000000,0.00000000,0.00000000,0.00000000
65.00000000,0.35732700,8.87770000,0.01165767,591.98173006,0.01159024,598.88285574,0.00044552,0.02957222,734.89564626,-0.01446694,-0.01510528,0.00000000,0.00000000,0.00000000,0.00000000
66.00000000,0.37037200,8.94470000,0.01208200,596.44941605,0.01200960,603.65571790,0.00034124,0.03018719,737.72321165,-0.01478396,-0.01540323,0.00000000,0.00000000,0.00000000,0.00000000
67.00000000,0.38578400,9.00840000,0.01264167,600.69705184,0.01256243,608.29086373,0.00058623,0.03087176,740.32873108,-0.01517513,-0.01569663,0.00000000,0.00000000,0.00000000,0.00000000
68.00000000,0.40089200,9.07070000,0.01306600,604.85133299,0.01298138,612.75432050,0.00032621,0.03156220,743.10825817,-0.01552927,-0.01603292,0.00000000,0.00000000,0.00000000,0.00000000
69.00000000,0.41600000,9.13600000,0.01367444,609.20565978,0.01358179,617.53620873,0.00067445,0.03218512,745.50790921,-0.01580744,-0.01637768,0.00000000,0.00000000,0.00000000,0.00000000
70.00000000,0.43185100,9.19740000,0.01402367,613.29992724,0.01392624,621.90064099,0.00033335,0.03286302,748.45127863,-0.01619338,-0.01666964,0.00000000,0.00000000,0.00000000,0.00000000
71.00000000,0.44756700,9.25730000,0.01461333,617.29417188,0.01450759,626.31489738,0.00047380,0.03356188,750.69187175,-0.01653900,-0.01702288,0.00000000,0.00000000,0.00000000,0.00000000
72.00000000,0.46227000,9.30830000,0.01512778,620.69494778,0.01501449,630.08468302,0.00055502,0.03422702,753.07660559,-0.01689433,-0.01733269,0.00000000,0.00000000,0.00000000,0.00000000
73.00000000,0.47927100,9.37210000,0.01565733,624.94925175,0.01553602,634.73429051,0.00053240,0.03493714,755.77654303,-0.01723601,-0.01770114,0.00000000,0.00000000,0.00000000,0.00000000
74.00000000,0.49546000,9.43110000,0.01617944,628.88348270,0.01604995,639.05846807,0.00039936,0.03559185,757.88799156,-0.01753012,-0.01806173,0.00000000,0.00000000,0.00000000,0.00000000
75.00000000,0.51215700,9.48770000,0.01677278,632.65767713,0.01663367,643.26910376,0.00067961,0.03626966,760.34688787,-0.01790436,-0.01836531,0.00000000,0.00000000,0.00000000,0.00000000
76.00000000,0.52861800,9.54280000,0.01724978,636.33184875,0.01710269,647.30843173,0.00036922,0.03693614,762.80015190,-0.01821853,-0.01871761,0.00000000,0.00000000,0.00000000,0.00000000
77.00000000,0.54551800,9.59780000,0.01789956,639.99935217,0.01774124,651.45505613,0.00060526,0.03766078,765.07788599,-0.01858744,-0.01907335,0.00000000,0.00000000,0.00000000,0.00000000
78.00000000,0.56241800,9.65280000,0.01839900,643.66685560,0.01823179,655.50968207,0.00056065,0.03835664,767.22472070,-0.01898587,-0.01937077,0.00000000,0.00000000,0.00000000,0.00000000
79.00000000,0.57952100,9.70380000,0.01896233,647.06763150,0.01878479,659.33754362,0.00047178,0.03905747,769.72031421,-0.01935168,-0.01970578,0.00000000,0.00000000,0.00000000,0.00000000
80.00000000,0.59726600,9.75570000,0.01957833,650.52842110,0.01938914,663.26468337,0.00060426,0.03979400,772.18385476,-0.01973012,-0.02006388,0.00000000,0.00000000,0.00000000,0.00000000
81.00000000,0.61480800,9.80030000,0.02011167,653.50243296,0.01991210,666.64545606,0.00059654,0.04048856,774.28225560,-0.02011689,-0.02037167,0.00000000,0.00000000,0.00000000,0.00000000
82.00000000,0.63224900,9.85300000,0.02069756,657.01656806,0.02048627,670.61520498,0.00049319,0.04123654,776.36886524,-0.02050553,-0.02073100,0.00000000,0.00000000,0.00000000,0.00000000
83.00000000,0.65056900,9.90400000,0.02136233,660.41734397,0.02113736,674.52539941,0.00067677,0.04190698,778.78992489,-0.02084277,-0.02106421,0.00000000,0.00000000,0.00000000,0.00000000
84.00000000,0.66865200,9.95270000,0.02191811,663.66475154,0.02168136,678.21102931,0.00064682,0.04266379,781.06432980,-0.02127367,-0.02139012,0.00000000,0.00000000,0.00000000,0.00000000
85.00000000,0.68704000,9.99810000,0.02252278,666.69210892,0.02227289,681.70786713,0.00058774,0.04334296,782.93696150,-0.02163932,-0.02170364,0.00000000,0.00000000,0.00000000,0.00000000
86.00000000,0.70498800,10.04680000,0.02310122,669.93951649,0.02283843,685.41593814,0.00060218,0.04408907,784.97688611,-0.02208672,-0.02200235,0.00000000,0.00000000,0.00000000,0.00000000
87.00000000,0.72520100,10.08980000,0.02375089,672.80683735,0.02347322,688.78659779,0.00067519,0.04479776,787.22175648,-0.02244798,-0.02234978,0.00000000,0.00000000,0.00000000,0.00000000
88.00000000,0.74426400,10.13850000,0.02437067,676.05424493,0.02407844,692.53013758,0.00054285,0.04555605,789.44549201,-0.02285802,-0.02269804,0.00000000,0.00000000,0.00000000,0.00000000
89.00000000,0.76251700,10.17670000,0.02505411,678.60149276,0.02474540,695.60324996,0.00069624,0.04623327,791.32630282,-0.02314402,-0.02308926,0.00000000,0.00000000,0.00000000,0.00000000
90.00000000,0.78161400,10.21660000,0.02557622,681.26209979,0.02525462,698.68621065,0.00053484,0.04706285,793.33769642,-0.02370243,-0.02336042,0.00000000,0.00000000,0.00000000,0.00000000
91.00000000,0.80047500,10.25730000,0.02623722,683.97605233,0.02589893,701.92168401,0.00055637,0.04776025,795.23934332,-0.02401874,-0.02374151,0.00000000,0.00000000,0.00000000,0.00000000
92.00000000,0.82058700,10.29800000,0.02691322,686.69000486,0.02655743,705.17104556,0.00059259,0.04850282,797.29229096,-0.02439454,-0.02410828,0.00000000,0.00000000,0.00000000,0.00000000
93.00000000,0.84009000,10.34020000,0.02756300,689.50398022,0.02718998,708.50877842,0.00065798,0.04923249,798.94932881,-0.02476984,-0.02446265,0.00000000,0.00000000,0.00000000,0.00000000
94.00000000,0.86043800,10.38170000,0.02817144,692.27127826,0.02778193,711.77356011,0.00048225,0.05003093,800.99567170,-0.02518972,-0.02484122,0.00000000,0.00000000,0.00000000,0.00000000
95.00000000,0.88017800,10.41440000,0.02889244,694.45177575,0.02848293,714.51618510,0.00065713,0.05072943,802.97131530,-0.02554088,-0.02518855,0.00000000,0.00000000,0.00000000,0.00000000
96.00000000,0.90042500,10.45670000,0.02953844,697.27241929,0.02911059,717.86876191,0.00068586,0.05151988,804.95999773,-0.02595515,-0.02556474,0.00000000,0.00000000,0.00000000,0.00000000
97.00000000,0.92077300,10.49180000,0.03020322,699.61295329,0.02975609,720.74351879,0.00061249,0.05224689,806.68048669,-0.02637439,-0.02587250,0.00000000,0.00000000,0.00000000,0.00000000
98.00000000,0.94142600,10.52440000,0.03089422,701.78678260,0.03042660,723.46793941,0.00064852,0.05303718,808.44734094,-0.02678014,-0.02625704,0.00000000,0.00000000,0.00000000,0.00000000
99.00000000,0.96130100,10.55870000,0.03154778,704.07397110,0.03106037,726.28594027,0.00065543,0.05375276,810.10612256,-0.02713019,-0.02662257,0.00000000,0.00000000,0.00000000,0.00000000
100.00000000,0.98181800,10.59540000,0.03219378,706.52119611,0.03168642,729.26678249,0.00060420,0.05455580,811.88783982,-0.02757539,-0.02698041,0.00000000,0.00000000,0.00000000,0.00000000
101.00000000,1.00297800,10.62570000,0.03290733,708.54165709,0.03237748,731.85787358,0.00064725,0.05534336,813.83683769,-0.02804158,-0.02730178,0.00000000,0.00000000,0.00000000,0.00000000
102.00000000,1.02410300,10.66240000,0.03362467,710.98888210,0.03307172,734.89564626,0.00068315,0.05599007,815.49542226,-0.02824083,-0.02774925,0.00000000,0.00000000,0.00000000,0.00000000
103.00000000,1.04512800,10.69670000,0.03427444,713.27607060,0.03370016,737.72321165,0.00060298,0.05679530,817.17918767,-0.02872131,-0.02807399,0.00000000,0.00000000,0.00000000,0.00000000
104.00000000,1.06605100,10.72700000,0.03499556,715.29653158,0.03439713,740.32873108,0.00070415,0.05761722,818.92871013,-0.02922785,-0.02838937,0.00000000,0.00000000,0.00000000,0.00000000
105.00000000,1.08761600,10.75970000,0.03572411,717.47702907,0.03510081,743.10825817,0.00081248,0.05835460,820.50407899,-0.02955620,-0.02879840,0.00000000,0.00000000,0.00000000,0.00000000
106.00000000,1.10857200,10.78760000,0.03638133,719.33745353,0.03573516,745.50790921,0.00061613,0.05909445,822.19032916,-0.02997794,-0.02911651,0.00000000,0.00000000,0.00000000,0.00000000
107.00000000,1.13054300,10.82270000,0.03709867,721.67798753,0.03642707,748.45127863,0.00059384,0.05988444,823.58475387,-0.03038194,-0.02950250,0.00000000,0.00000000,0.00000000,0.00000000
108.00000000,1.15237900,10.84740000,0.03783478,723.32502998,0.03713660,750.69187175,0.00073114,0.06067166,825.42848662,-0.03084418,-0.02982748,0.00000000,0.00000000,0.00000000,0.00000000
109.00000000,1.17455200,10.87450000,0.03853711,725.13210894,0.03781310,753.07660559,0.00072337,0.06143959,826.75120390,-0.03123893,-0.03020067,0.00000000,0.00000000,0.00000000,0.00000000
110.00000000,1.19638800,10.90560000,0.03928822,727.20591542,0.03853608,755.77654303,0.00067943,0.06220161,828.47109124,-0.03157542,-0.03062619,0.00000000,0.00000000,0.00000000,0.00000000
111.00000000,1.21832500,10.92880000,0.03997933,728.75293505,0.03920084,757.88799156,0.00077303,0.06302301,830.12095516,-0.03207968,-0.03094333,0.00000000,0.00000000,0.00000000,0.00000000
112.00000000,1.24036300,10.95670000,0.04069667,730.61335951,0.03989036,760.34688787,0.00066420,0.06374953,831.64362047,-0.03243013,-0.03131940,0.00000000,0.00000000,0.00000000,0.00000000
113.00000000,1.26294200,10.98460000,0.04140267,732.47378398,0.04056852,762.80015190,0.00069235,0.06455935,833.23059549,-0.03285142,-0.03170793,0.00000000,0.00000000,0.00000000,0.00000000
114.00000000,1.28521700,11.00930000,0.04216889,734.12082643,0.04130401,765.07788599,0.00067051,0.06530596,834.71640830,-0.03326135,-0.03204461,0.00000000,0.00000000,0.00000000,0.00000000
115.00000000,1.30803300,11.03240000,0.04290500,735.66117786,0.04201009,767.22472070,0.00077086,0.06618863,836.20332805,-0.03370887,-0.03247976,0.00000000,0.00000000,0.00000000,0.00000000
116.00000000,1.33007200,11.06040000,0.04364856,737.52827052,0.04272280,769.72031421,0.00077734,0.06693807,837.57301297,-0.03412419,-0.03281388,0.00000000,0.00000000,0.00000000,0.00000000
117.00000000,1.35356300,11.08750000,0.04442978,739.33534948,0.04347107,772.18385476,0.00077697,0.06774154,839.22716982,-0.03452507,-0.03321647,0.00000000,0.00000000,0.00000000,0.00000000
118.00000000,1.37617700,11.10980000,0.04516589,740.82235541,0.04417562,774.28225560,0.00071878,0.06847317,840.41972597,-0.03491864,-0.03355453,0.00000000,0.00000000,0.00000000,0.00000000
119.00000000,1.39963500,11.13130000,0.04595833,742.25601584,0.04493353,776.36886524,0.00081877,0.06931706,842.10468688,-0.03539040,-0.03392666,0.00000000,0.00000000,0.00000000,0.00000000
120.00000000,1.42295700,11.15840000,0.04667189,744.06309480,0.04561550,778.78992489,0.00063152,0.07010016,843.22850636,-0.03583233,-0.03426783,0.00000000,0.00000000,0.00000000,0.00000000
121.00000000,1.44607700,11.18240000,0.04747567,745.66345993,0.04638314,781.06432980,0.00078193,0.07087323,844.85739317,-0.03624065,-0.03463258,0.00000000,0.00000000,0.00000000,0.00000000
122.00000000,1.46953500,11.20150000,0.04819667,746.93708385,0.04707123,782.93696150,0.00069507,0.07163987,846.25898936,-0.03660014,-0.03503973,0.00000000,0.00000000,0.00000000,0.00000000
123.00000000,1.49383900,11.22220000,0.04898922,748.31739877,0.04782706,784.97688611,0.00072337,0.07247282,847.48741026,-0.03706563,-0.03540718,0.00000000,0.00000000,0.00000000,0.00000000
124.00000000,1.51702600,11.24620000,0.04974411,749.91776390,0.04854643,787.22175648,0.00055111,0.07328582,849.10538996,-0.03747874,-0.03580708,0.00000000,0.00000000,0.00000000,0.00000000
125.00000000,1.54004500,11.26930000,0.05055156,751.45811534,0.04931532,789.44549201,0.00086534,0.07403788,850.26077581,-0.03781428,-0.03622360,0.00000000,0.00000000,0.00000000,0.00000000
126.00000000,1.56340200,11.28840000,0.05127267,752.73173926,0.05000149,791.32630282,0.00066470,0.07485781,851.59861904,-0.03827259,-0.03658522,0.00000000,0.00000000,0.00000000,0.00000000
127.00000000,1.58932800,11.30760000,0.05215522,754.01203136,0.05084065,793.33769642,0.00086402,0.07566629,853.04430609,-0.03868414,-0.03698215,0.00000000,0.00000000,0.00000000,0.00000000
128.00000000,1.61308900,11.32670000,0.05289878,755.28565528,0.05154710,795.23934332,0.00068479,0.07650131,854.56537457,-0.03913732,-0.03736399,0.00000000,0.00000000,0.00000000,0.00000000
129.00000000,1.63705500,11.34740000,0.05369122,756.66597021,0.05229945,797.29229096,0.00071993,0.07728909,855.70643646,-0.03953586,-0.03775323,0.00000000,0.00000000,0.00000000,0.00000000
130.00000000,1.66112100,11.36260000,0.05446867,757.67953479,0.05303701,798.94932881,0.00069810,0.07806585,856.83928746,-0.03990414,-0.03816170,0.00000000,0.00000000,0.00000000,0.00000000
131.00000000,1.68613400,11.38250000,0.05532122,759.00650421,0.05384520,800.99567170,0.00081150,0.07883233,858.53922684,-0.04032616,-0.03850617,0.00000000,0.00000000,0.00000000,0.00000000
132.00000000,1.70962600,11.40250000,0.05606856,760.34014182,0.05455310,802.97131530,0.00073978,0.07969496,859.51617240,-0.04076960,-0.03892536,0.00000000,0.00000000,0.00000000,0.00000000
133.00000000,1.73538300,11.42160000,0.05691367,761.61376573,0.05535303,804.95999773,0.00079619,0.08051026,860.86134268,-0.04121177,-0.03929849,0.00000000,0.00000000,0.00000000,0.00000000
134.00000000,1.75934700,11.43760000,0.05769100,762.68067582,0.05608823,806.68048669,0.00072435,0.08135314,862.05699593,-0.04162410,-0.03972904,0.00000000,0.00000000,0.00000000,0.00000000
135.00000000,1.78409000,11.45350000,0.05853611,763.74091772,0.05688693,808.44734094,0.00085881,0.08216071,863.28185053,-0.04209374,-0.04006697,0.00000000,0.00000000,0.00000000,0.00000000
136.00000000,1.80866300,11.46870000,0.05930222,764.75448230,0.05761041,810.10612256,0.00080132,0.08291250,864.51084532,-0.04247423,-0.04043827,0.00000000,0.00000000,0.00000000,0.00000000
137.00000000,1.83374400,11.48460000,0.06016222,765.81472420,0.05842194,811.88783982,0.00082185,0.08380070,865.86711499,-0.04298330,-0.04081740,0.00000000,0.00000000,0.00000000,0.00000000
138.00000000,1.85906100,11.50300000,0.06100733,767.04167080,0.05921877,813.83683769,0.00091360,0.08455603,866.81675719,-0.04331611,-0.04123992,0.00000000,0.00000000,0.00000000,0.00000000
139.00000000,1.88353200,11.51890000,0.06170211,768.10191270,0.05987339,815.49542226,0.00062279,0.08539461,868.19139567,-0.04379221,-0.04160240,0.00000000,0.00000000,0.00000000,0.00000000
140.00000000,1.90945800,11.53330000,0.06256589,769.06213178,0.06068663,817.17918767,0.00073525,0.08618205,869.34720147,-0.04416139,-0.04202066,0.00000000,0.00000000,0.00000000,0.00000000
141.00000000,1.93508000,11.54840000,0.06344844,770.06902818,0.06151688,818.92871013,0.00086885,0.08703538,870.20980706,-0.04465470,-0.04238068,0.00000000,0.00000000,0.00000000,0.00000000
142.00000000,1.95985600,11.56200000,0.06424089,770.97590175,0.06226176,820.50407899,0.00083290,0.08785177,871.50344321,-0.04505304,-0.04279872,0.00000000,0.00000000,0.00000000,0.00000000
143.00000000,1.98483500,11.57710000,0.06503711,771.98279814,0.06300964,822.19032916,0.00070537,0.08865113,872.61472106,-0.04547748,-0.04317365,0.00000000,0.00000000,0.00000000,0.00000000
144.00000000,2.01059100,11.58750000,0.06588589,772.67628970,0.06380627,823.58475387,0.00080346,0.08948104,873.63636885,-0.04591778,-0.04356326,0.00000000,0.00000000,0.00000000,0.00000000
145.00000000,2.03617900,11.60420000,0.06673467,773.78987710,0.06460227,825.42848662,0.00076072,0.09027946,874.69034255,-0.04634289,-0.04393658,0.00000000,0.00000000,0.00000000,0.00000000
146.00000000,2.06183400,11.61380000,0.06756089,774.43002316,0.06537650,826.75120390,0.00081636,0.09107864,876.15120203,-0.04669464,-0.04438400,0.00000000,0.00000000,0.00000000,0.00000000
147.00000000,2.08759000,11.62900000,0.06838344,775.44358774,0.06614671,828.47109124,0.00068922,0.09195174,876.97868780,-0.04720007,-0.04475167,0.00000000,0.00000000,0.00000000,0.00000000
148.00000000,2.11314400,11.64250000,0.06926978,776.34379313,0.06697596,830.12095516,0.00090654,0.09271669,878.18378565,-0.04758285,-0.04513384,0.00000000,0.00000000,0.00000000,0.00000000
149.00000000,2.13859600,11.65530000,0.07005467,777.19732120,0.06770974,831.64362047,0.00076522,0.09356560,878.81459867,-0.04807937,-0.04548623,0.00000000,0.00000000,0.00000000,0.00000000
150.00000000,2.16485900,11.66800000,0.07092967,778.04418108,0.06852712,833.23059549,0.00082064,0.09438913,880.31023356,-0.04851540,-0.04587374,0.00000000,0.00000000,0.00000000,0.00000000
151.00000000,2.19048100,11.68000000,0.07173711,778.84436364,0.06928080,834.71640830,0.00065864,0.09518064,881.24688379,-0.04894046,-0.04624017,0.00000000,0.00000000,0.00000000,0.00000000
152.00000000,2.21671000,11.69040000,0.07269111,779.53785520,0.07017055,836.20332805,0.00087546,0.09599751,882.44381127,-0.04938915,-0.04660835,0.00000000,0.00000000,0.00000000,0.00000000
153.00000000,2.24273700,11.70070000,0.07350233,780.22467857,0.07092651,837.57301297,0.00088888,0.09685543,883.44147212,-0.04986424,-0.04699118,0.00000000,0.00000000,0.00000000,0.00000000
154.00000000,2.26876400,11.71430000,0.07437367,781.13155214,0.07173786,839.22716982,0.00085319,0.09769334,884.18516245,-0.05030587,-0.04738747,0.00000000,0.00000000,0.00000000,0.00000000
155.00000000,2.29506100,11.72230000,0.07516611,781.66500719,0.07247517,840.41972597,0.00074069,0.09847498,885.22824046,-0.05070853,-0.04776645,0.00000000,0.00000000,0.00000000,0.00000000
156.00000000,2.32169600,11.73580000,0.07608244,782.56521257,0.07332708,842.10468688,0.00083778,0.09928007,886.18189021,-0.05111056,-0.04816951,0.00000000,0.00000000,0.00000000,0.00000000
157.00000000,2.34799400,11.74220000,0.07693122,782.99197661,0.07411554,843.22850636,0.00087201,0.10005656,887.34886951,-0.05148459,-0.04857197,0.00000000,0.00000000,0.00000000,0.00000000
158.00000000,2.37517000,11.75570000,0.07777244,783.89218199,0.07489636,844.85739317,0.00081543,0.10084494,887.99217525,-0.05190593,-0.04893901,0.00000000,0.00000000,0.00000000,0.00000000
159.00000000,2.40167000,11.76610000,0.07860622,784.58567355,0.07566967,846.25898936,0.00079398,0.10171735,889.30653754,-0.05236783,-0.04934952,0.00000000,0.00000000,0.00000000,0.00000000
160.00000000,2.42850700,11.77330000,0.07951133,785.06578309,0.07650847,847.48741026,0.00080732,0.10255632,890.41379370,-0.05282389,-0.04973243,0.00000000,0.00000000,0.00000000,0.00000000
161.00000000,2.45531200,11.78610000,0.08039767,785.91931116,0.07732918,849.10538996,0.00084143,0.10332958,890.98620012,-0.05323005,-0.05009952,0.00000000,0.00000000,0.00000000,0.00000000
162.00000000,2.48228500,11.79320000,0.08121644,786.39275251,0.07808674,850.26077581,0.00076431,0.10403257,892.03334756,-0.05351817,-0.05051441,0.00000000,0.00000000,0.00000000,0.00000000
163.00000000,2.50942700,11.80200000,0.08211022,786.97955306,0.07891304,851.59861904,0.00080517,0.10493710,893.08304449,-0.05405622,-0.05088088,0.00000000,0.00000000,0.00000000,0.00000000
164.00000000,2.53660300,11.81240000,0.08299289,787.67304461,0.07972840,853.04430609,0.00072836,0.10577469,893.88692184,-0.05450906,-0.05126563,0.00000000,0.00000000,0.00000000,0.00000000
165.00000000,2.56394800,11.82350000,0.08390544,788.41321349,0.08057067,854.56537457,0.00090803,0.10657674,894.96634311,-0.05492390,-0.05165284,0.00000000,0.00000000,0.00000000,0.00000000
166.00000000,2.59190200,11.82990000,0.08476556,788.83997752,0.08136389,855.70643646,0.00090731,0.10734602,895.71793353,-0.05528918,-0.05205684,0.00000000,0.00000000,0.00000000,0.00000000
167.00000000,2.61857100,11.83630000,0.08561433,789.26674156,0.08214603,856.83928746,0.00071288,0.10818096,896.64918241,-0.05580334,-0.05237762,0.00000000,0.00000000,0.00000000,0.00000000
168.00000000,2.64594900,11.85060000,0.08645556,790.22029245,0.08292061,858.53922684,0.00071213,0.10894871,897.46079392,-0.05616160,-0.05278710,0.00000000,0.00000000,0.00000000,0.00000000
169.00000000,2.67359800,11.85380000,0.08739822,790.43367446,0.08378789,859.51617240,0.00078061,0.10974922,898.30269038,-0.05661364,-0.05313559,0.00000000,0.00000000,0.00000000,0.00000000
170.00000000,2.70114600,11.86260000,0.08829211,791.02047501,0.08460960,860.86134268,0.00086985,0.11051670,898.93525926,-0.05702153,-0.05349517,0.00000000,0.00000000,0.00000000,0.00000000
171.00000000,2.72910000,11.86900000,0.08921600,791.44723905,0.08545817,862.05699593,0.00086911,0.11131396,900.19657216,-0.05747782,-0.05383614,0.00000000,0.00000000,0.00000000,0.00000000
172.00000000,2.75708700,11.87620000,0.09010233,791.92734859,0.08627158,863.28185053,0.00083394,0.11204855,900.43965019,-0.05787022,-0.05417833,0.00000000,0.00000000,0.00000000,0.00000000
173.00000000,2.78514200,11.88410000,0.09092856,792.45413544,0.08702922,864.51084532,0.00063361,0.11281245,901.43187594,-0.05831473,-0.05449771,0.00000000,0.00000000,0.00000000,0.00000000
174.00000000,2.81309500,11.89210000,0.09190500,792.98759049,0.08792388,865.86711499,0.00090810,0.11361022,902.21468986,-0.05873196,-0.05487826,0.00000000,0.00000000,0.00000000,0.00000000
175.00000000,2.84074400,11.89610000,0.09273500,793.25431801,0.08868373,866.81675719,0.00072878,0.11434084,902.93727754,-0.05908733,-0.05525352,0.00000000,0.00000000,0.00000000,0.00000000
176.00000000,2.86852900,11.90490000,0.09365889,793.84111856,0.08952885,868.19139567,0.00090664,0.11507092,903.65995336,-0.05948094,-0.05558998,0.00000000,0.00000000,0.00000000,0.00000000
177.00000000,2.89786800,11.91130000,0.09452644,794.26788259,0.09032180,869.34720147,0.00079624,0.00000000,0.00000000,0.00000000,0.00000000,0.00000000,0.00000000,0.00000000,0.00000000
178.00000000,2.92595700,11.91290000,0.09546533,794.37457360,0.09117923,870.20980706,0.00083655,0.00000000,0.00000000,0.00000000,0.00000000,0.00000000,0.00000000,0.00000000,0.00000000
179.00000000,2.95441700,11.92080000,0.09636678,794.90136045,0.09200178,871.50344321,0.00078801,0.00000000,0.00000000,0.00000000,0.00000000,0.00000000,0.00000000,0.00000000,0.00000000
180.00000000,2.98250600,11.92640000,0.09724933,795.27477899,0.09280644,872.61472106,0.00084228,0.00000000,0.00000000,0.00000000,0.00000000,0.00000000,0.00000000,0.00000000,0.00000000
181.00000000,3.01093200,11.93040000,0.09816567,795.54150651,0.09364121,873.63636885,0.00090980,0.00000000,0.00000000,0.00000000,0.00000000,0.00000000,0.00000000,0.00000000,0.00000000
182.00000000,3.03979800,11.93520000,0.09904833,795.86157953,0.09444465,874.69034255,0.00073147,0.00000000,0.00000000,0.00000000,0.00000000,0.00000000,0.00000000,0.00000000,0.00000000
183.00000000,3.06859700,11.94550000,0.09993467,796.54840290,0.09525078,876.15120203,0.00075130,0.00000000,0.00000000,0.00000000,0.00000000,0.00000000,0.00000000,0.00000000,0.00000000
184.00000000,3.09722600,11.94630000,0.10089978,796.60174841,0.09612783,876.97868780,0.00086655,0.00000000,0.00000000,0.00000000,0.00000000,0.00000000,0.00000000,0.00000000,0.00000000
185.00000000,3.12605800,11.95350000,0.10174856,797.08185795,0.09689851,878.18378565,0.00079768,0.00000000,0.00000000,0.00000000,0.00000000,0.00000000,0.00000000,0.00000000,0.00000000
186.00000000,3.15472100,11.95190000,0.10268756,796.97516694,0.09775043,878.81459867,0.00079720,0.00000000,0.00000000,0.00000000,0.00000000,0.00000000,0.00000000,0.00000000,0.00000000
187.00000000,3.18352000,11.96230000,0.10360389,797.66865849,0.09858109,880.31023356,0.00081004,0.00000000,0.00000000,0.00000000,0.00000000,0.00000000,0.00000000,0.00000000,0.00000000
188.00000000,3.21258900,11.96550000,0.10448267,797.88204051,0.09937705,881.24688379,0.00081623,0.00000000,0.00000000,0.00000000,0.00000000,0.00000000,0.00000000,0.00000000,0.00000000
189.00000000,3.24172500,11.97190000,0.10539156,798.30880455,0.10019962,882.44381127,0.00082240,0.00000000,0.00000000,0.00000000,0.00000000,0.00000000,0.00000000,0.00000000,0.00000000
190.00000000,3.27130100,11.97510000,0.10634556,798.52218656,0.10106229,883.44147212,0.00088278,0.00000000,0.00000000,0.00000000,0.00000000,0.00000000,0.00000000,0.00000000,0.00000000
191.00000000,3.30084300,11.97510000,0.10727689,798.52218656,0.10190375,884.18516245,0.00088204,0.00000000,0.00000000,0.00000000,0.00000000,0.00000000,0.00000000,0.00000000,0.00000000
192.00000000,3.32997900,11.97980000,0.10814822,798.83559140,0.10269035,885.22824046,0.00084062,0.00000000,0.00000000,0.00000000,0.00000000,0.00000000,0.00000000,0.00000000,0.00000000
193.00000000,3.35992700,11.98300000,0.10904578,799.04897342,0.10349999,886.18189021,0.00077880,0.00000000,0.00000000,0.00000000,0.00000000,0.00000000,0.00000000,0.00000000,0.00000000
194.00000000,3.38923300,11.98940000,0.10991344,799.47573745,0.10428203,887.34886951,0.00076497,0.00000000,0.00000000,0.00000000,0.00000000,0.00000000,0.00000000,0.00000000,0.00000000
195.00000000,3.41863900,11.98860000,0.11079222,799.42239195,0.10507347,887.99217525,0.00074395,0.00000000,0.00000000,0.00000000,0.00000000,0.00000000,0.00000000,0.00000000,0.00000000
196.00000000,3.44882400,11.99580000,0.11176867,799.90250149,0.10595214,889.30653754,0.00087847,0.00000000,0.00000000,0.00000000,0.00000000,0.00000000,0.00000000,0.00000000,0.00000000
197.00000000,3.47873700,12.00060000,0.11270767,800.22257451,0.10679638,890.41379370,0.00094547,0.00000000,0.00000000,0.00000000,0.00000000,0.00000000,0.00000000,0.00000000,0.00000000
198.00000000,3.50827900,11.99900000,0.11357144,800.11588351,0.10757237,890.98620012,0.00087725,0.00000000,0.00000000,0.00000000,0.00000000,0.00000000,0.00000000,0.00000000,0.00000000
199.00000000,3.53849800,12.00460000,0.11436011,800.48930204,0.10828035,892.03334756,0.00074157,0.00000000,0.00000000,0.00000000,0.00000000,0.00000000,0.00000000,0.00000000,0.00000000
200.00000000,3.56888500,12.00780000,0.11537411,800.70268405,0.10918987,893.08304449,0.00080826,0.00000000,0.00000000,0.00000000,0.00000000,0.00000000,0.00000000,0.00000000,0.00000000
201.00000000,3.59890000,12.00850000,0.11631300,800.74936137,0.11003129,893.88692184,0.00094221,0.00000000,0.00000000,0.00000000,0.00000000,0.00000000,0.00000000,0.00000000,0.00000000
202.00000000,3.62972600,12.01330000,0.11721444,801.06943440,0.11083848,894.96634311,0.00080713,0.00000000,0.00000000,0.00000000,0.00000000,0.00000000,0.00000000,0.00000000,0.00000000
203.00000000,3.66068800,12.01410000,0.11807822,801.12277990,0.11161134,895.71793353,0.00073910,0.00000000,0.00000000,0.00000000,0.00000000,0.00000000,0.00000000,0.00000000,0.00000000
204.00000000,3.69192000,12.01650000,0.11901711,801.28281641,0.11245072,896.64918241,0.00087278,0.00000000,0.00000000,0.00000000,0.00000000,0.00000000,0.00000000,0.00000000,0.00000000
205.00000000,3.72230700,12.01810000,0.11988089,801.38950742,0.11322233,897.46079392,0.00073791,0.00000000,0.00000000,0.00000000,0.00000000,0.00000000,0.00000000,0.00000000,0.00000000
206.00000000,3.75299800,12.01970000,0.12078222,801.49619843,0.11402685,898.30269038,0.00073732,0.00000000,0.00000000,0.00000000,0.00000000,0.00000000,0.00000000,0.00000000,0.00000000
207.00000000,3.78416300,12.01890000,0.12164611,801.44285293,0.11479735,898.93525926,0.00073675,0.00000000,0.00000000,0.00000000,0.00000000,0.00000000,0.00000000,0.00000000,0.00000000
208.00000000,3.81610500,12.02610000,0.12254744,801.92296247,0.11560061,900.19657216,0.00087004,0.00000000,0.00000000,0.00000000,0.00000000,0.00000000,0.00000000,0.00000000,0.00000000
209.00000000,3.84723500,12.02050000,0.12337367,801.54954394,0.11633636,900.43965019,0.00066873,0.00000000,0.00000000,0.00000000,0.00000000,0.00000000,0.00000000,0.00000000,0.00000000
210.00000000,3.87813000,12.02450000,0.12423744,801.81627146,0.11710498,901.43187594,0.00080189,0.00000000,0.00000000,0.00000000,0.00000000,0.00000000,0.00000000,0.00000000,0.00000000
211.00000000,3.90980100,12.02530000,0.12513889,801.86961696,0.11790648,902.21468986,0.00086823,0.00000000,0.00000000,0.00000000,0.00000000,0.00000000,0.00000000,0.00000000,0.00000000
212.00000000,3.94140500,12.02610000,0.12596511,801.92296247,0.11864054,902.93727754,0.00066719,0.00000000,0.00000000,0.00000000,0.00000000,0.00000000,0.00000000,0.00000000,0.00000000
213.00000000,3.97415800,12.02690000,0.12679133,801.97630797,0.11937407,903.65995336,0.00066670,0.00000000,0.00000000,0.00000000,0.00000000,0.00000000,0.00000000,0.00000000,0.00000000
214.00000000,4.00599900,12.02610000,0.12761756,801.92296247,0.00000000,0.00000000,0.00000000,0.00000000,0.00000000,0.00000000,0.00000000,0.00000000,0.00000000,0.00000000,0.00000000
215.00000000,4.03834600,12.02610000,0.12848144,801.92296247,0.00000000,0.00000000,0.00000000,0.00000000,0.00000000,0.00000000,0.00000000,0.00000000,0.00000000,0.00000000,0.00000000
216.00000000,4.07086300,12.02450000,0.12923256,801.81627146,0.00000000,0.00000000,0.00000000,0.00000000,0.00000000,0.00000000,0.00000000,0.00000000,0.00000000,0.00000000,0.00000000
217.00000000,4.10337900,12.02290000,0.13005878,801.70958045,0.00000000,0.00000000,0.00000000,0.00000000,0.00000000,0.00000000,0.00000000,0.00000000,0.00000000,0.00000000,0.00000000
218.00000000,4.13565900,12.02290000,0.13084744,801.70958045,0.00000000,0.00000000,0.00000000,0.00000000,0.00000000,0.00000000,0.00000000,0.00000000,0.00000000,0.00000000,0.00000000
219.00000000,4.16827700,12.02050000,0.13159856,801.54954394,0.00000000,0.00000000,0.00000000,0.00000000,0.00000000,0.00000000,0.00000000,0.00000000,0.00000000,0.00000000,0.00000000
220.00000000,4.20133400,12.02210000,0.13234978,801.65623494,0.00000000,0.00000000,0.00000000,0.00000000,0.00000000,0.00000000,0.00000000,0.00000000,0.00000000,0.00000000,0.00000000
221.00000000,4.23462800,12.02050000,0.13306333,801.54954394,0.00000000,0.00000000,0.00000000,0.00000000,0.00000000,0.00000000,0.00000000,0.00000000,0.00000000,0.00000000,0.00000000
222.00000000,4.26761800,12.01970000,0.13381444,801.49619843,0.00000000,0.00000000,0.00000000,0.00000000,0.00000000,0.00000000,0.00000000,0.00000000,0.00000000,0.00000000,0.00000000
223.00000000,4.30172300,12.01890000,0.13445289,801.44285293,0.00000000,0.00000000,0.00000000,0.00000000,0.00000000,0.00000000,0.00000000,0.00000000,0.00000000,0.00000000,0.00000000
224.00000000,4.33576100,12.01490000,0.13512889,801.17612541,0.00000000,0.00000000,0.00000000,0.00000000,0.00000000,0.00000000,0.00000000,0.00000000,0.00000000,0.00000000,0.00000000
225.00000000,4.36962900,12.00930000,0.13572978,800.80270687,0.00000000,0.00000000,0.00000000,0.00000000,0.00000000,0.00000000,0.00000000,0.00000000,0.00000000,0.00000000,0.00000000
226.00000000,4.40349800,12.00850000,0.13636833,800.74936137,0.00000000,0.00000000,0.00000000,0.00000000,0.00000000,0.00000000,0.00000000,0.00000000,0.00000000,0.00000000,0.00000000
227.00000000,4.43841400,12.00460000,0.13693167,800.48930204,0.00000000,0.00000000,0.00000000,0.00000000,0.00000000,0.00000000,0.00000000,0.00000000,0.00000000,0.00000000,0.00000000
228.00000000,4.47306000,12.00300000,0.13749500,800.38261103,0.00000000,0.00000000,0.00000000,0.00000000,0.00000000,0.00000000,0.00000000,0.00000000,0.00000000,0.00000000,0.00000000
229.00000000,4.50824700,11.99500000,0.13798322,799.84915598,0.00000000,0.00000000,0.00000000,0.00000000,0.00000000,0.00000000,0.00000000,0.00000000,0.00000000,0.00000000,0.00000000
230.00000000,4.54350100,11.99020000,0.13850900,799.52908296,0.00000000,0.00000000,0.00000000,0.00000000,0.00000000,0.00000000,0.00000000,0.00000000,0.00000000,0.00000000,0.00000000
231.00000000,4.57953300,11.98220000,0.13899722,798.99562791,0.00000000,0.00000000,0.00000000,0.00000000,0.00000000,0.00000000,0.00000000,0.00000000,0.00000000,0.00000000,0.00000000
232.00000000,4.61529400,11.97980000,0.13941033,798.83559140,0.00000000,0.00000000,0.00000000,0.00000000,0.00000000,0.00000000,0.00000000,0.00000000,0.00000000,0.00000000,0.00000000
233.00000000,4.65139400,11.97030000,0.13978600,798.20211354,0.00000000,0.00000000,0.00000000,0.00000000,0.00000000,0.00000000,0.00000000,0.00000000,0.00000000,0.00000000,0.00000000
234.00000000,4.68810200,11.96550000,0.14016156,797.88204051,0.00000000,0.00000000,0.00000000,0.00000000,0.00000000,0.00000000,0.00000000,0.00000000,0.00000000,0.00000000,0.00000000
235.00000000,4.72521500,11.96230000,0.14046200,797.66865849,0.00000000,0.00000000,0.00000000,0.00000000,0.00000000,0.00000000,0.00000000,0.00000000,0.00000000,0.00000000,0.00000000
236.00000000,4.76283500,11.94550000,0.14076244,796.54840290,0.00000000,0.00000000,0.00000000,0.00000000,0.00000000,0.00000000,0.00000000,0.00000000,0.00000000,0.00000000,0.00000000
237.00000000,4.80038800,11.94000000,0.14098778,796.18165256,0.00000000,0.00000000,0.00000000,0.00000000,0.00000000,0.00000000,0.00000000,0.00000000,0.00000000,0.00000000,0.00000000
238.00000000,4.83905700,11.92640000,0.14121311,795.27477899,0.00000000,0.00000000,0.00000000,0.00000000,0.00000000,0.00000000,0.00000000,0.00000000,0.00000000,0.00000000,0.00000000
239.00000000,4.87735300,11.91520000,0.14140089,794.52794192,0.00000000,0.00000000,0.00000000,0.00000000,0.00000000,0.00000000,0.00000000,0.00000000,0.00000000,0.00000000,0.00000000
240.00000000,4.91581900,11.89930000,0.14158867,793.46770003,0.00000000,0.00000000,0.00000000,0.00000000,0.00000000,0.00000000,0.00000000,0.00000000,0.00000000,0.00000000,0.00000000
241.00000000,4.95492700,11.88100000,0.14170133,792.24742161,0.00000000,0.00000000,0.00000000,0.00000000,0.00000000,0.00000000,0.00000000,0.00000000,0.00000000,0.00000000,0.00000000
242.00000000,4.99477800,11.86260000,0.14177644,791.02047501,0.00000000,0.00000000,0.00000000,0.00000000,0.00000000,0.00000000,0.00000000,0.00000000,0.00000000,0.00000000,0.00000000
243.00000000,5.03419000,11.85140000,0.14185156,790.27363795,0.00000000,0.00000000,0.00000000,0.00000000,0.00000000,0.00000000,0.00000000,0.00000000,0.00000000,0.00000000,0.00000000
244.00000000,5.07492100,11.83310000,0.14192667,789.05335954,0.00000000,0.00000000,0.00000000,0.00000000,0.00000000,0.00000000,0.00000000,0.00000000,0.00000000,0.00000000,0.00000000
245.00000000,5.11544900,11.81080000,0.14196422,787.56635361,0.00000000,0.00000000,0.00000000,0.00000000,0.00000000,0.00000000,0.00000000,0.00000000,0.00000000,0.00000000,0.00000000
246.00000000,5.15641600,11.78610000,0.14203933,785.91931116,0.00000000,0.00000000,0.00000000,0.00000000,0.00000000,0.00000000,0.00000000,0.00000000,0.00000000,0.00000000,0.00000000
247.00000000,5.19779000,11.75650000,0.14203933,783.94552750,0.00000000,0.00000000,0.00000000,0.00000000,0.00000000,0.00000000,0.00000000,0.00000000,0.00000000,0.00000000,0.00000000
248.00000000,5.23967100,11.73420000,0.14207689,782.45852156,0.00000000,0.00000000,0.00000000,0.00000000,0.00000000,0.00000000,0.00000000,0.00000000,0.00000000,0.00000000,0.00000000
249.00000000,5.28185700,11.69510000,0.14207689,779.85126004,0.00000000,0.00000000,0.00000000,0.00000000,0.00000000,0.00000000,0.00000000,0.00000000,0.00000000,0.00000000,0.00000000
250.00000000,5.32384100,11.65530000,0.14207689,777.19732120,0.00000000,0.00000000,0.00000000,0.00000000,0.00000000,0.00000000,0.00000000,0.00000000,0.00000000,0.00000000,0.00000000
251.00000000,5.36545500,11.61780000,0.14207689,774.69675068,0.00000000,0.00000000,0.00000000,0.00000000,0.00000000,0.00000000,0.00000000,0.00000000,0.00000000,0.00000000,0.00000000
252.00000000,5.40838900,11.57950000,0.14207689,772.14283466,0.00000000,0.00000000,0.00000000,0.00000000,0.00000000,0.00000000,0.00000000,0.00000000,0.00000000,0.00000000,0.00000000
253.00000000,5.45183400,11.53090000,0.14200178,768.90209527,0.00000000,0.00000000,0.00000000,0.00000000,0.00000000,0.00000000,0.00000000,0.00000000,0.00000000,0.00000000,0.00000000
254.00000000,5.49562100,11.46950000,0.14196433,764.80782781,0.00000000,0.00000000,0.00000000,0.00000000,0.00000000,0.00000000,0.00000000,0.00000000,0.00000000,0.00000000,0.00000000
255.00000000,5.53934600,11.40810000,0.14196433,760.71356035,0.00000000,0.00000000,0.00000000,0.00000000,0.00000000,0.00000000,0.00000000,0.00000000,0.00000000,0.00000000,0.00000000
256.00000000,5.58466900,11.33630000,0.14196444,755.92580133,0.00000000,0.00000000,0.00000000,0.00000000,0.00000000,0.00000000,0.00000000,0.00000000,0.00000000,0.00000000,0.00000000
257.00000000,5.63030900,11.24300000,0.14188933,749.70438189,0.00000000,0.00000000,0.00000000,0.00000000,0.00000000,0.00000000,0.00000000,0.00000000,0.00000000,0.00000000,0.00000000
258.00000000,5.67721300,11.13610000,0.14185189,742.57608887,0.00000000,0.00000000,0.00000000,0.00000000,0.00000000,0.00000000,0.00000000,0.00000000,0.00000000,0.00000000,0.00000000
259.00000000,5.72654100,11.00210000,0.14185200,733.64071689,0.00000000,0.00000000,0.00000000,0.00000000,0.00000000,0.00000000,0.00000000,0.00000000,0.00000000,0.00000000,0.00000000
260.00000000,5.78149000,10.79640000,0.14173944,719.92425408,0.00000000,0.00000000,0.00000000,0.00000000,0.00000000,0.00000000,0.00000000,0.00000000,0.00000000,0.00000000,0.00000000