File: LAB_DATA/DP780_results/DATA/UT_90_1.csv
Time[s],Displacement[mm],Force[kN],EngStrain_longi,EngStress[MPa],TrueStrain,TrueStress[MPa],TrueStrainRate[1/s],PlasticStrain_longi,PlasticStress[MPa],PlasticStrain_thick,PlasticStrain_width,R-Value,Thickness[mm],Width[mm], Young's Modulus [MPa]
0.00000000,0.00000000,-0.01980000,0.00000000,-1.32727262,0.00000000,-1.32727262,0.00000000,0.00051473,424.58283279,0.00045262,-0.00096736,0.88240029,1.49660000,9.96780000,241203.37242429
1.50000000,0.00209500,0.42200000,0.00006500,28.28833553,0.00006500,28.29017428,0.00000689,0.00069118,437.86652286,0.00030039,-0.00099156,0.00000000,0.00000000,0.00000000,0.00000000
3.00000000,0.00349900,0.75460000,0.00012922,50.58383411,0.00012921,50.59037066,0.00004133,0.00097827,450.62706355,0.00004436,-0.00102263,0.00000000,0.00000000,0.00000000,0.00000000
4.50000000,0.00545600,1.09190000,0.00016822,73.19439234,0.00016821,73.20670527,-0.00003910,0.00125604,463.81009243,0.00009362,-0.00134966,0.00000000,0.00000000,0.00000000,0.00000000
6.00000000,0.00818500,1.42530000,0.00026933,95.54351810,0.00026930,95.56925115,0.00003599,0.00155186,476.26882060,-0.00007559,-0.00147627,0.00000000,0.00000000,0.00000000,0.00000000
7.50000000,0.01096900,1.71310000,0.00038511,114.83589479,0.00038504,114.88011937,0.00017350,0.00181514,487.63417191,-0.00025110,-0.00156404,0.00000000,0.00000000,0.00000000,0.00000000
9.00000000,0.01253700,1.97950000,0.00040889,132.69374452,0.00040881,132.74800152,0.00004443,0.00219016,499.87937110,-0.00042064,-0.00176952,0.00000000,0.00000000,0.00000000,0.00000000
10.50000000,0.01418200,2.25940000,0.00046278,151.45655286,0.00046267,151.52664358,0.00006397,0.00265944,510.40043343,-0.00056816,-0.00209127,0.00000000,0.00000000,0.00000000,0.00000000
12.00000000,0.01559800,2.51780000,0.00051900,168.77813082,0.00051887,168.86572667,-0.00001177,0.00306659,520.52146359,-0.00078763,-0.00227896,0.00000000,0.00000000,0.00000000,0.00000000
13.50000000,0.01801800,2.77140000,0.00059067,185.77794573,0.00059049,185.88767857,-0.00004930,0.00348308,530.98111985,-0.00100785,-0.00247523,0.00000000,0.00000000,0.00000000,0.00000000
15.00000000,0.02102400,3.02900000,0.00069378,203.04589652,0.00069354,203.18676525,0.00003109,0.00394886,540.45573318,-0.00119406,-0.00275480,0.00000000,0.00000000,0.00000000,0.00000000
16.50000000,0.02326200,3.27060000,0.00078933,219.24130378,0.00078902,219.41435825,0.00014212,0.00449668,549.93100230,-0.00145019,-0.00304650,0.00000000,0.00000000,0.00000000,0.00000000
18.00000000,0.02529200,3.51070000,0.00082000,235.33616009,0.00081966,235.52913574,0.00006994,0.00507493,559.21766499,-0.00175401,-0.00332093,0.00000000,0.00000000,0.00000000,0.00000000
19.50000000,0.02754800,3.77060000,0.00085456,252.75828901,0.00085419,252.97428501,-0.00001488,0.00563496,567.52930931,-0.00202507,-0.00360989,0.00000000,0.00000000,0.00000000,0.00000000
21.00000000,0.03049900,4.00990000,0.00097156,268.79951814,0.00097108,269.06067181,-0.00008214,0.00621713,575.80927924,-0.00231144,-0.00390569,0.00000000,0.00000000,0.00000000,0.00000000
22.50000000,0.03362200,4.23320000,0.00113722,283.76820375,0.00113658,284.09091126,-0.00000710,0.00688337,584.31149161,-0.00256328,-0.00432009,0.00000000,0.00000000,0.00000000,0.00000000
24.00000000,0.03603300,4.48040000,0.00129133,300.33900125,0.00129050,300.72683901,0.00027011,0.00757230,591.86762610,-0.00291069,-0.00466161,0.00000000,0.00000000,0.00000000,0.00000000
25.50000000,0.03959100,4.70770000,0.00131411,315.57582273,0.00131325,315.99052443,0.00017267,0.00817475,599.54558436,-0.00320977,-0.00496497,0.00000000,0.00000000,0.00000000,0.00000000
27.00000000,0.04345700,4.92860000,0.00136356,330.38362681,0.00136263,330.83412324,0.00000755,0.00888393,607.34576887,-0.00363412,-0.00524981,0.00000000,0.00000000,0.00000000,0.00000000
28.50000000,0.04745800,5.16460000,0.00151411,346.20364383,0.00151297,346.72783462,-0.00019481,0.00962269,614.25646889,-0.00404821,-0.00557448,0.00000000,0.00000000,0.00000000,0.00000000
30.00000000,0.05128400,5.38790000,0.00175822,361.17232944,0.00175668,361.80735065,0.00000000,0.01033836,621.21762640,-0.00444488,-0.00589348,0.00000000,0.00000000,0.00000000,0.00000000
31.50000000,0.05585300,5.60320000,0.00194633,375.60474328,0.00194444,376.33579531,0.00027748,0.01101134,628.48928301,-0.00478822,-0.00622312,0.00000000,0.00000000,0.00000000,0.00000000
33.00000000,0.06181100,5.83210000,0.00208922,390.94881912,0.00208704,391.76559808,0.00035973,0.01171636,635.13631694,-0.00509599,-0.00662037,0.00000000,0.00000000,0.00000000,0.00000000
34.50000000,0.06857300,6.03710000,0.00220544,404.69078306,0.00220302,405.58330610,0.00014214,0.01247917,641.18126619,-0.00549681,-0.00698236,0.00000000,0.00000000,0.00000000,0.00000000
36.00000000,0.07502700,6.24360000,0.00241967,418.53329796,0.00241674,419.54600903,-0.00009732,0.01322644,648.03866353,-0.00586541,-0.00736103,0.00000000,0.00000000,0.00000000,0.00000000
37.50000000,0.08317200,6.45650000,0.00278389,432.80483027,0.00278002,434.00971083,0.00011236,0.01394307,654.22962895,-0.00619701,-0.00774607,0.00000000,0.00000000,0.00000000,0.00000000
39.00000000,0.09229700,6.64150000,0.00308767,445.20611481,0.00308291,446.58076289,0.00025412,0.01475276,660.10777967,-0.00662621,-0.00812655,0.00000000,0.00000000,0.00000000,0.00000000
40.50000000,0.10091000,6.82890000,0.00338056,457.76828087,0.00337485,459.31579197,0.00034442,0.01558280,666.23507197,-0.00708898,-0.00849382,0.00000000,0.00000000,0.00000000,0.00000000
42.00000000,0.11073700,7.02430000,0.00366200,470.86671870,0.00365531,472.59103262,0.00029184,0.01636266,671.89969812,-0.00751256,-0.00885010,0.00000000,0.00000000,0.00000000,0.00000000
43.50000000,0.12289900,7.19500000,0.00405589,482.30941745,0.00404769,484.26561086,0.00024657,0.01716032,677.57829311,-0.00792912,-0.00923120,0.00000000,0.00000000,0.00000000,0.00000000
45.00000000,0.13448400,7.36010000,0.00447967,493.37672598,0.00446966,495.58688925,0.00037369,0.01803383,683.37966162,-0.00841617,-0.00961766,0.00000000,0.00000000,0.00000000,0.00000000
46.50000000,0.14728100,7.52670000,0.00487011,504.54458546,0.00485829,507.00177365,0.00036603,0.01891620,688.70199656,-0.00889382,-0.01002238,0.00000000,0.00000000,0.00000000,0.00000000
48.00000000,0.16149900,7.67990000,0.00527911,514.81418973,0.00526523,517.53195104,0.00021620,0.01974960,694.10260377,-0.00928649,-0.01046311,0.00000000,0.00000000,0.00000000,0.00000000
49.50000000,0.17612400,7.82340000,0.00577067,524.43356449,0.00575408,527.45989578,0.00009678,0.02063055,699.38694313,-0.00971441,-0.01091614,0.00000000,0.00000000,0.00000000,0.00000000
51.00000000,0.19294700,7.97250000,0.00639744,534.42832949,0.00637707,537.84730503,0.00020868,0.02151247,704.29487299,-0.01014222,-0.01137025,0.00000000,0.00000000,0.00000000,0.00000000
52.50000000,0.20933000,8.10410000,0.00701311,543.25000000,0.00698863,547.05987261,0.00038026,0.02245585,709.19966601,-0.01067573,-0.01178012,0.00000000,0.00000000,0.00000000,0.00000000
54.00000000,0.22673000,8.23090000,0.00755389,551.74990745,0.00752550,555.91776495,0.00034299,0.02336538,714.08906074,-0.01115695,-0.01220843,0.00000000,0.00000000,0.00000000,0.00000000
55.50000000,0.24612500,8.36010000,0.00818833,560.41069644,0.00815499,564.99952602,0.00031280,0.02429325,718.77893372,-0.01163700,-0.01265625,0.00000000,0.00000000,0.00000000,0.00000000
57.00000000,0.26525000,8.47730000,0.00885667,568.26707777,0.00881768,573.30002986,0.00044676,0.02522172,724.69585291,-0.01215616,-0.01306556,0.00000000,0.00000000,0.00000000,0.00000000
58.50000000,0.28592900,8.58660000,0.00954367,575.59389075,0.00949841,581.08716697,0.00058759,0.02616363,728.36751487,-0.01267974,-0.01348389,0.00000000,0.00000000,0.00000000,0.00000000
60.00000000,0.30562900,8.70380000,0.01019333,583.45027208,0.01014173,589.39757519,0.00060988,0.02711702,732.49097316,-0.01320027,-0.01391675,0.00000000,0.00000000,0.00000000,0.00000000
61.50000000,0.32671600,8.81310000,0.01085422,590.77708505,0.01079574,597.18951082,0.00049799,0.02810149,736.76279831,-0.01376182,-0.01433967,0.00000000,0.00000000,0.00000000,0.00000000
63.00000000,0.34777100,8.91430000,0.01162033,597.56092287,0.01155334,604.50477998,0.00056441,0.02909482,741.26455043,-0.01430991,-0.01478490,0.00000000,0.00000000,0.00000000,0.00000000
64.50000000,0.37017800,9.02280000,0.01234511,604.83410866,0.01226953,612.30085294,0.00063076,0.03006435,745.20032414,-0.01482179,-0.01524256,0.00000000,0.00000000,0.00000000,0.00000000
66.00000000,0.39177400,9.11530000,0.01305867,611.03475093,0.01297414,619.01405006,0.00054869,0.03105366,749.33215621,-0.01535837,-0.01569529,0.00000000,0.00000000,0.00000000,0.00000000
67.50000000,0.41550000,9.20540000,0.01377967,617.07451167,0.01368559,625.57759275,0.00037049,0.03208206,753.43841742,-0.01589988,-0.01618218,0.00000000,0.00000000,0.00000000,0.00000000
69.00000000,0.43780600,9.30350000,0.01455711,623.65054417,0.01445217,632.72909443,0.00037765,0.03312220,757.12171665,-0.01647400,-0.01664820,0.00000000,0.00000000,0.00000000,0.00000000
70.50000000,0.46166800,9.39120000,0.01535700,629.52942338,0.01524027,639.19710673,0.00047345,0.03412799,760.95344306,-0.01697449,-0.01715350,0.00000000,0.00000000,0.00000000,0.00000000
72.00000000,0.48485300,9.47740000,0.01611933,635.30775163,0.01599080,645.54848905,0.00045822,0.03516511,764.80930701,-0.01749216,-0.01767295,0.00000000,0.00000000,0.00000000,0.00000000
73.50000000,0.50949200,9.56510000,0.01691933,641.18663084,0.01677780,652.03508118,0.00029547,0.03620695,768.17902128,-0.01804927,-0.01815769,0.00000000,0.00000000,0.00000000,0.00000000
75.00000000,0.53423300,9.64960000,0.01781689,646.85100134,0.01766003,658.37587376,0.00050179,0.03727714,772.19380758,-0.01859823,-0.01867891,0.00000000,0.00000000,0.00000000,0.00000000
76.50000000,0.56012400,9.72540000,0.01866567,651.93217631,0.01849360,664.10092500,0.00057513,0.03834557,775.59056633,-0.01915810,-0.01918747,0.00000000,0.00000000,0.00000000,0.00000000
78.00000000,0.58489900,9.80750000,0.01946933,657.43566528,0.01928223,670.23549939,0.00055265,0.03940798,779.22093011,-0.01971577,-0.01969221,0.00000000,0.00000000,0.00000000,0.00000000
79.50000000,0.61085700,9.88330000,0.02036322,662.51684024,0.02015866,676.00781788,0.00052276,0.04045650,782.50978744,-0.02024893,-0.02020758,0.00000000,0.00000000,0.00000000,0.00000000
81.00000000,0.63762700,9.95350000,0.02123833,667.22262497,0.02101594,681.39332148,0.00059588,0.04155215,786.23621586,-0.02084251,-0.02070964,0.00000000,0.00000000,0.00000000,0.00000000
82.50000000,0.66470100,10.02520000,0.02214344,672.02896065,0.02190184,686.90999660,0.00063950,0.04266416,789.24994608,-0.02141823,-0.02124593,0.00000000,0.00000000,0.00000000,0.00000000
84.00000000,0.69174100,10.09460000,0.02302978,676.68111820,0.02276859,692.26493398,0.00055073,0.04377660,792.66499234,-0.02203957,-0.02173703,0.00000000,0.00000000,0.00000000,0.00000000
85.50000000,0.71884900,10.15920000,0.02395367,681.01151269,0.02367128,697.32423546,0.00052831,0.04487870,795.73941312,-0.02262799,-0.02225071,0.00000000,0.00000000,0.00000000,0.00000000
87.00000000,0.74700400,10.23100000,0.02490756,685.82455177,0.02460242,702.90676489,0.00058637,0.04602934,798.85866316,-0.02330936,-0.02271998,0.00000000,0.00000000,0.00000000,0.00000000
88.50000000,0.77553200,10.29480000,0.02585400,690.10131908,0.02552544,707.94319859,0.00065170,0.04714477,801.61589555,-0.02388498,-0.02325978,0.00000000,0.00000000,0.00000000,0.00000000
90.00000000,0.80409300,10.34900000,0.02682300,693.73456028,0.02646957,712.34260239,0.00060714,0.04829411,805.19974362,-0.02450361,-0.02379050,0.00000000,0.00000000,0.00000000,0.00000000
91.50000000,0.83245200,10.41440000,0.02779578,698.11858195,0.02741649,717.52333092,0.00064334,0.04945617,808.06304878,-0.02512098,-0.02433518,0.00000000,0.00000000,0.00000000,0.00000000
93.00000000,0.86152100,10.46860000,0.02877978,701.75182315,0.02837342,721.94808468,0.00069393,0.05062147,810.70723804,-0.02572821,-0.02489326,0.00000000,0.00000000,0.00000000,0.00000000
94.50000000,0.89133300,10.52600000,0.02974867,705.59957305,0.02931476,726.59021955,0.00064190,0.05175029,814.00976212,-0.02628487,-0.02546542,0.00000000,0.00000000,0.00000000,0.00000000
96.00000000,0.92111100,10.58190000,0.03076278,709.34677200,0.03029909,731.16824912,0.00063415,0.05289816,816.76461145,-0.02690193,-0.02599624,0.00000000,0.00000000,0.00000000,0.00000000
97.50000000,0.95136300,10.63050000,0.03181056,712.60462297,0.03131508,735.27297192,0.00071344,0.05408828,819.28142061,-0.02753434,-0.02655395,0.00000000,0.00000000,0.00000000,0.00000000
99.00000000,0.98161500,10.68230000,0.03282833,716.07698264,0.03230099,739.58459652,0.00070542,0.05527491,822.25006815,-0.02818496,-0.02708995,0.00000000,0.00000000,0.00000000,0.00000000
100.50000000,1.01240800,10.73260000,0.03386122,719.44879135,0.03330055,743.81020675,0.00069030,0.05645708,825.10661277,-0.02882164,-0.02763545,0.00000000,0.00000000,0.00000000,0.00000000
102.00000000,1.04384200,10.77880000,0.03490156,722.54576079,0.03430631,747.76373180,0.00068982,0.05767613,827.31236016,-0.02947783,-0.02819830,0.00000000,0.00000000,0.00000000,0.00000000
103.50000000,1.07504100,10.82670000,0.03598689,725.75668797,0.03535449,751.87441326,0.00076142,0.05887697,830.08761991,-0.03012706,-0.02874991,0.00000000,0.00000000,0.00000000,0.00000000
105.00000000,1.10681400,10.87370000,0.03703856,728.90728458,0.03636911,755.90495754,0.00069548,0.06007093,832.51108507,-0.03078373,-0.02928720,0.00000000,0.00000000,0.00000000,0.00000000
106.50000000,1.13868800,10.91920000,0.03813889,731.95733024,0.03742958,759.87336953,0.00065127,0.06125555,835.10379311,-0.03143995,-0.02981561,0.00000000,0.00000000,0.00000000,0.00000000
108.00000000,1.17123900,10.96310000,0.03922811,734.90012154,0.03847824,763.72886517,0.00068695,0.06249202,838.32057465,-0.03212534,-0.03036668,0.00000000,0.00000000,0.00000000,0.00000000
109.50000000,1.20422800,11.00130000,0.04032478,737.46081921,0.03953295,767.19876287,0.00071508,0.06373028,840.11244652,-0.03281201,-0.03091827,0.00000000,0.00000000,0.00000000,0.00000000
111.00000000,1.23664400,11.04040000,0.04142144,740.08184746,0.04058655,770.73710659,0.00075040,0.06494348,842.39828380,-0.03343614,-0.03150734,0.00000000,0.00000000,0.00000000,0.00000000
112.50000000,1.26976900,11.07950000,0.04255567,742.70287570,0.04167507,774.30909171,0.00072079,0.06618687,844.66354499,-0.03411018,-0.03207669,0.00000000,0.00000000,0.00000000,0.00000000
114.00000000,1.30360400,11.11860000,0.04366356,745.32390395,0.04273717,777.86739564,0.00069106,0.06746567,847.24523620,-0.03477205,-0.03269362,0.00000000,0.00000000,0.00000000,0.00000000
115.50000000,1.33706700,11.15840000,0.04482033,747.99185597,0.04384494,781.51710029,0.00072625,0.06872313,849.53169721,-0.03544169,-0.03328144,0.00000000,0.00000000,0.00000000,0.00000000
117.00000000,1.37151000,11.19110000,0.04594700,750.18386681,0.04492270,784.65256494,0.00067510,0.06997561,851.81110971,-0.03611484,-0.03386077,0.00000000,0.00000000,0.00000000,0.00000000
118.50000000,1.40622400,11.23020000,0.04711122,752.80489505,0.04603516,788.27045375,0.00071023,0.07126142,854.07272067,-0.03683351,-0.03442791,0.00000000,0.00000000,0.00000000,0.00000000
120.00000000,1.44053200,11.26370000,0.04828300,755.05053306,0.04715359,791.50663795,0.00065197,0.07251441,856.30329995,-0.03748004,-0.03503437,0.00000000,0.00000000,0.00000000,0.00000000
121.50000000,1.47585400,11.29240000,0.04949989,756.97440801,0.04831375,794.44455710,0.00075881,0.07378333,858.50097550,-0.03815569,-0.03562764,0.00000000,0.00000000,0.00000000,0.00000000
123.00000000,1.51073700,11.33070000,0.05067544,759.54180908,0.04943324,798.03192783,0.00075796,0.07511015,860.57078501,-0.03888132,-0.03622883,0.00000000,0.00000000,0.00000000,0.00000000
124.50000000,1.54622800,11.36260000,0.05186222,761.68019274,0.05056214,801.18262016,0.00071420,0.07639240,862.90512062,-0.03953470,-0.03685771,0.00000000,0.00000000,0.00000000,0.00000000
126.00000000,1.58226000,11.39050000,0.05310911,763.55044052,0.05174685,804.10192570,0.00079189,0.07767758,865.00555634,-0.04020354,-0.03747404,0.00000000,0.00000000,0.00000000,0.00000000
127.50000000,1.61829200,11.42000000,0.05432967,765.52794265,0.05290518,807.11882059,0.00079793,0.07901021,866.92456321,-0.04093168,-0.03807853,0.00000000,0.00000000,0.00000000,0.00000000
129.00000000,1.65476300,11.44630000,0.05555022,767.29093607,0.05406217,809.91411808,0.00080417,0.08033632,869.12715066,-0.04162050,-0.03871583,0.00000000,0.00000000,0.00000000,0.00000000
130.50000000,1.69116700,11.47260000,0.05678211,769.05392949,0.05522855,812.72243517,0.00078913,0.08161741,871.00867407,-0.04228332,-0.03933409,0.00000000,0.00000000,0.00000000,0.00000000
132.00000000,1.72818000,11.49900000,0.05808156,770.82362631,0.05645742,815.59426159,0.00087326,0.08294731,873.11266395,-0.04300392,-0.03994339,0.00000000,0.00000000,0.00000000,0.00000000
133.50000000,1.76465100,11.52690000,0.05929089,772.69387409,0.05759971,818.50758072,0.00078013,0.08431378,875.12786308,-0.04371088,-0.04060290,0.00000000,0.00000000,0.00000000,0.00000000
135.00000000,1.80196800,11.54920000,0.06055656,774.18873163,0.05879382,821.07093457,0.00079345,0.08567217,876.97047890,-0.04447215,-0.04120002,0.00000000,0.00000000,0.00000000,0.00000000
136.50000000,1.83948700,11.57390000,0.06181478,775.84447070,0.05997950,823.80312425,0.00079963,0.08699465,878.78482010,-0.04520186,-0.04179279,0.00000000,0.00000000,0.00000000,0.00000000
138.00000000,1.87704000,11.59550000,0.06311800,777.29240446,0.06120610,826.35354645,0.00082688,0.08834230,880.68379077,-0.04590277,-0.04243953,0.00000000,0.00000000,0.00000000,0.00000000
139.50000000,1.91577600,11.61860000,0.06442867,778.84088918,0.06243819,829.02056921,0.00086826,0.08971460,882.77822958,-0.04662806,-0.04308654,0.00000000,0.00000000,0.00000000,0.00000000
141.00000000,1.95346400,11.64010000,0.06570189,780.28211954,0.06363363,831.54812866,0.00080381,0.09110240,884.77949874,-0.04739632,-0.04370608,0.00000000,0.00000000,0.00000000,0.00000000
142.50000000,1.99182900,11.66560000,0.06700511,781.99148579,0.06485576,834.38891218,0.00083803,0.09247876,886.65582070,-0.04813721,-0.04434155,0.00000000,0.00000000,0.00000000,0.00000000
144.00000000,2.02972000,11.68560000,0.06830822,783.33216520,0.06607630,836.84019281,0.00082973,0.09384715,888.34291184,-0.04882885,-0.04501830,0.00000000,0.00000000,0.00000000,0.00000000
145.50000000,2.06859100,11.70630000,0.06963022,784.71976839,0.06731300,839.35998024,0.00082164,0.09527121,890.09016931,-0.04957507,-0.04569614,0.00000000,0.00000000,0.00000000,0.00000000
147.00000000,2.10695500,11.72230000,0.07094100,785.79231192,0.06853770,841.53720431,0.00077870,0.09664732,892.21470049,-0.05031713,-0.04633019,0.00000000,0.00000000,0.00000000,0.00000000
148.50000000,2.14592800,11.73820000,0.07229300,786.85815205,0.06979935,843.74248843,0.00082664,0.09810562,893.76097119,-0.05108615,-0.04701947,0.00000000,0.00000000,0.00000000,0.00000000
150.00000000,2.18577900,11.76130000,0.07365633,788.40663676,0.07106996,846.47777880,0.00084672,0.09950144,895.90343199,-0.05182504,-0.04767640,0.00000000,0.00000000,0.00000000,0.00000000
151.50000000,2.22495500,11.77970000,0.07501967,789.64006182,0.07233896,848.87859604,0.00084564,0.10093981,897.91652706,-0.05255764,-0.04838218,0.00000000,0.00000000,0.00000000,0.00000000
153.00000000,2.26507700,11.79320000,0.07639800,790.54502042,0.07362028,850.94107889,0.00084456,0.10236426,899.56149278,-0.05333861,-0.04902565,0.00000000,0.00000000,0.00000000,0.00000000
154.50000000,2.30448900,11.81080000,0.07773878,791.72481830,0.07486512,853.27253801,0.00080865,0.10383767,901.13363845,-0.05412874,-0.04970893,0.00000000,0.00000000,0.00000000,0.00000000
156.00000000,2.34430600,11.82510000,0.07911333,792.68340408,0.07613972,855.39523045,0.00080061,0.10528091,902.91400301,-0.05487870,-0.05040221,0.00000000,0.00000000,0.00000000,0.00000000
157.50000000,2.38439400,11.84350000,0.08053667,793.91682913,0.07745783,857.85624416,0.00084112,0.10678036,904.45531182,-0.05564563,-0.05113472,0.00000000,0.00000000,0.00000000,0.00000000
159.00000000,2.42526000,11.86100000,0.08195633,795.08992362,0.07877082,860.25257843,0.00091645,0.10829002,906.18936186,-0.05648872,-0.05180130,0.00000000,0.00000000,0.00000000,0.00000000
160.50000000,2.46612500,11.87380000,0.08334222,795.94795844,0.08005091,862.28403007,0.00080446,0.10980160,907.74723362,-0.05725939,-0.05254221,0.00000000,0.00000000,0.00000000,0.00000000
162.00000000,2.50726100,11.88330000,0.08479567,796.58478116,0.08139164,864.13171873,0.00085892,0.11134599,909.64006144,-0.05813591,-0.05321009,0.00000000,0.00000000,0.00000000,0.00000000
163.50000000,2.54816100,11.90010000,0.08623778,797.71095186,0.08272015,866.50377166,0.00087149,0.11287536,911.40172131,-0.05894028,-0.05393508,0.00000000,0.00000000,0.00000000,0.00000000
165.00000000,2.58980300,11.91050000,0.08767244,798.40810516,0.08404004,868.40649540,0.00093248,0.11444635,913.02287289,-0.05978378,-0.05466257,0.00000000,0.00000000,0.00000000,0.00000000
166.50000000,2.63117600,11.92240000,0.08909589,799.20580940,0.08534789,870.41176140,0.00086227,0.11601809,914.64756942,-0.06061845,-0.05539964,0.00000000,0.00000000,0.00000000,0.00000000
168.00000000,2.67285200,11.93840000,0.09054933,800.27835293,0.08668154,872.74302427,0.00088884,0.11760616,916.53355811,-0.06145291,-0.05615324,0.00000000,0.00000000,0.00000000,0.00000000
169.50000000,2.71452900,11.94870000,0.09200278,800.96880283,0.08801342,874.66015760,0.00087382,0.11919190,918.35254465,-0.06229757,-0.05689432,0.00000000,0.00000000,0.00000000,0.00000000
171.00000000,2.75708500,11.95910000,0.09348244,801.66595612,0.08936751,876.60764933,0.00087934,0.12080959,919.90695134,-0.06313861,-0.05767099,0.00000000,0.00000000,0.00000000,0.00000000
172.50000000,2.79984300,11.96630000,0.09499978,802.14860071,0.09075416,878.35253952,0.00094005,0.12248985,921.64419763,-0.06406568,-0.05842417,0.00000000,0.00000000,0.00000000,0.00000000
174.00000000,2.84246600,11.97350000,0.09645322,802.63124529,0.09208063,880.04761516,0.00093880,0.12413389,923.47362103,-0.06495693,-0.05917697,0.00000000,0.00000000,0.00000000,0.00000000
175.50000000,2.88485300,11.98220000,0.09798544,803.21444084,0.09347709,881.91776481,0.00092372,0.12584337,924.81519304,-0.06585729,-0.05998608,0.00000000,0.00000000,0.00000000,0.00000000
177.00000000,2.92805000,12.00060000,0.09945022,804.44786589,0.09481026,884.45038492,0.00089519,0.12754739,926.70674530,-0.06675150,-0.06079589,0.00000000,0.00000000,0.00000000,0.00000000
178.50000000,2.97178900,12.00300000,0.10102756,804.60874742,0.09624389,885.89640235,0.00096216,0.00000000,0.00000000,0.00000000,0.00000000,0.00000000,0.00000000,0.00000000,0.00000000
180.00000000,3.01488500,12.01330000,0.10254111,805.29919732,0.09761762,887.87547179,0.00089268,0.00000000,0.00000000,0.00000000,0.00000000,0.00000000,0.00000000,0.00000000,0.00000000
181.50000000,3.05879300,12.01890000,0.10409967,805.67458755,0.09903022,889.54504356,0.00091176,0.00000000,0.00000000,0.00000000,0.00000000,0.00000000,0.00000000,0.00000000,0.00000000
183.00000000,3.10310600,12.02930000,0.10566956,806.37174085,0.10045108,891.58068431,0.00097159,0.00000000,0.00000000,0.00000000,0.00000000,0.00000000,0.00000000,0.00000000,0.00000000
184.50000000,3.14704700,12.03890000,0.10724322,807.01526696,0.10187334,893.56218457,0.00091600,0.00000000,0.00000000,0.00000000,0.00000000,0.00000000,0.00000000,0.00000000,0.00000000
186.00000000,3.19102200,12.04440000,0.10881311,807.38395380,0.10329017,895.23791367,0.00094197,0.00000000,0.00000000,0.00000000,0.00000000,0.00000000,0.00000000,0.00000000,0.00000000
187.50000000,3.23543700,12.04840000,0.11038667,807.65208968,0.10470830,896.80611169,0.00089979,0.00000000,0.00000000,0.00000000,0.00000000,0.00000000,0.00000000,0.00000000,0.00000000
189.00000000,3.28008800,12.05960000,0.11202422,808.40287015,0.10618198,898.96357292,0.00093925,0.00000000,0.00000000,0.00000000,0.00000000,0.00000000,0.00000000,0.00000000,0.00000000
190.50000000,3.32531400,12.06120000,0.11364656,808.51012450,0.10763982,900.39451529,0.00093089,0.00000000,0.00000000,0.00000000,0.00000000,0.00000000,0.00000000,0.00000000,0.00000000
192.00000000,3.37033600,12.06920000,0.11531789,809.04639627,0.10913947,902.34391870,0.00102399,0.00000000,0.00000000,0.00000000,0.00000000,0.00000000,0.00000000,0.00000000,0.00000000
193.50000000,3.41600200,12.07310000,0.11696667,809.30782875,0.11061668,903.96986779,0.00104935,0.00000000,0.00000000,0.00000000,0.00000000,0.00000000,0.00000000,0.00000000,0.00000000
195.00000000,3.46163300,12.07950000,0.11862289,809.73684616,0.11209837,905.79017009,0.00101420,0.00000000,0.00000000,0.00000000,0.00000000,0.00000000,0.00000000,0.00000000,0.00000000
196.50000000,3.50790700,12.08430000,0.12034678,810.05860922,0.11363826,907.54655265,0.00103288,0.00000000,0.00000000,0.00000000,0.00000000,0.00000000,0.00000000,0.00000000,0.00000000
198.00000000,3.55394400,12.09070000,0.12206689,810.48762663,0.11517242,909.42132970,0.00112503,0.00000000,0.00000000,0.00000000,0.00000000,0.00000000,0.00000000,0.00000000,0.00000000
199.50000000,3.60031900,12.08910000,0.12373811,810.38037228,0.11666073,910.65530883,0.00095616,0.00000000,0.00000000,0.00000000,0.00000000,0.00000000,0.00000000,0.00000000,0.00000000
201.00000000,3.64699800,12.09950000,0.12551833,811.07752557,0.11824367,912.88262479,0.00107476,0.00000000,0.00000000,0.00000000,0.00000000,0.00000000,0.00000000,0.00000000,0.00000000
202.50000000,3.69469100,12.09470000,0.12731722,810.75576251,0.11984067,913.97893410,0.00113300,0.00000000,0.00000000,0.00000000,0.00000000,0.00000000,0.00000000,0.00000000,0.00000000
204.00000000,3.74231700,12.09870000,0.12912000,811.02389840,0.12143857,915.74330416,0.00106463,0.00000000,0.00000000,0.00000000,0.00000000,0.00000000,0.00000000,0.00000000,0.00000000
205.50000000,3.78987500,12.10420000,0.13092267,811.39258523,0.12303382,917.62226621,0.00099648,0.00000000,0.00000000,0.00000000,0.00000000,0.00000000,0.00000000,0.00000000,0.00000000
207.00000000,3.83770300,12.11300000,0.13280056,811.98248417,0.12469293,919.81420917,0.00112751,0.00000000,0.00000000,0.00000000,0.00000000,0.00000000,0.00000000,0.00000000,0.00000000
208.50000000,3.88634300,12.11380000,0.13464078,812.03611135,0.12631611,921.36928497,0.00119192,0.00000000,0.00000000,0.00000000,0.00000000,0.00000000,0.00000000,0.00000000,0.00000000
210.00000000,3.93474600,12.11060000,0.13651867,811.82160264,0.12796979,922.65040541,0.00105770,0.00000000,0.00000000,0.00000000,0.00000000,0.00000000,0.00000000,0.00000000,0.00000000
211.50000000,3.98365600,12.11380000,0.13847156,812.03611135,0.12968662,924.48001486,0.00112190,0.00000000,0.00000000,0.00000000,0.00000000,0.00000000,0.00000000,0.00000000,0.00000000
213.00000000,4.03290400,12.11380000,0.14042456,812.03611135,0.13140061,926.06592138,0.00125178,0.00000000,0.00000000,0.00000000,0.00000000,0.00000000,0.00000000,0.00000000,0.00000000
214.50000000,4.08215300,12.12420000,0.14237744,812.73326464,0.13311157,928.44814988,0.00111806,0.00000000,0.00000000,0.00000000,0.00000000,0.00000000,0.00000000,0.00000000,0.00000000
216.00000000,4.13221200,12.12180000,0.14444311,812.57238311,0.00000000,0.00000000,0.00000000,0.00000000,0.00000000,0.00000000,0.00000000,0.00000000,0.00000000,0.00000000,0.00000000
217.50000000,4.18288000,12.11860000,0.14647122,812.35787441,0.00000000,0.00000000,0.00000000,0.00000000,0.00000000,0.00000000,0.00000000,0.00000000,0.00000000,0.00000000,0.00000000
219.00000000,4.23219600,12.12020000,0.14853678,812.46512876,0.00000000,0.00000000,0.00000000,0.00000000,0.00000000,0.00000000,0.00000000,0.00000000,0.00000000,0.00000000,0.00000000
220.50000000,4.28303200,12.12020000,0.15067756,812.46512876,0.00000000,0.00000000,0.00000000,0.00000000,0.00000000,0.00000000,0.00000000,0.00000000,0.00000000,0.00000000,0.00000000
222.00000000,4.33471400,12.11620000,0.15289333,812.19699288,0.00000000,0.00000000,0.00000000,0.00000000,0.00000000,0.00000000,0.00000000,0.00000000,0.00000000,0.00000000,0.00000000
223.50000000,4.38609100,12.11780000,0.15503411,812.30424723,0.00000000,0.00000000,0.00000000,0.00000000,0.00000000,0.00000000,0.00000000,0.00000000,0.00000000,0.00000000,0.00000000
225.00000000,4.43780700,12.11620000,0.15732500,812.19699288,0.00000000,0.00000000,0.00000000,0.00000000,0.00000000,0.00000000,0.00000000,0.00000000,0.00000000,0.00000000,0.00000000
226.50000000,4.49026600,12.11620000,0.15965356,812.19699288,0.00000000,0.00000000,0.00000000,0.00000000,0.00000000,0.00000000,0.00000000,0.00000000,0.00000000,0.00000000,0.00000000
228.00000000,4.54255600,12.11300000,0.16205722,811.98248417,0.00000000,0.00000000,0.00000000,0.00000000,0.00000000,0.00000000,0.00000000,0.00000000,0.00000000,0.00000000,0.00000000
229.50000000,4.59548900,12.11380000,0.16446089,812.03611135,0.00000000,0.00000000,0.00000000,0.00000000,0.00000000,0.00000000,0.00000000,0.00000000,0.00000000,0.00000000,0.00000000
231.00000000,4.64879300,12.10900000,0.16693956,811.71434829,0.00000000,0.00000000,0.00000000,0.00000000,0.00000000,0.00000000,0.00000000,0.00000000,0.00000000,0.00000000,0.00000000
232.50000000,4.70226600,12.10660000,0.16949344,811.55346676,0.00000000,0.00000000,0.00000000,0.00000000,0.00000000,0.00000000,0.00000000,0.00000000,0.00000000,0.00000000,0.00000000
234.00000000,4.75617900,12.10580000,0.17219756,811.49983959,0.00000000,0.00000000,0.00000000,0.00000000,0.00000000,0.00000000,0.00000000,0.00000000,0.00000000,0.00000000,0.00000000
235.50000000,4.81066600,12.10110000,0.17493922,811.18477993,0.00000000,0.00000000,0.00000000,0.00000000,0.00000000,0.00000000,0.00000000,0.00000000,0.00000000,0.00000000,0.00000000
237.00000000,4.86562700,12.10110000,0.17779356,811.18477993,0.00000000,0.00000000,0.00000000,0.00000000,0.00000000,0.00000000,0.00000000,0.00000000,0.00000000,0.00000000,0.00000000
238.50000000,4.92001300,12.09390000,0.18068533,810.70213534,0.00000000,0.00000000,0.00000000,0.00000000,0.00000000,0.00000000,0.00000000,0.00000000,0.00000000,0.00000000,0.00000000
240.00000000,4.97527800,12.08830000,0.18372744,810.32674510,0.00000000,0.00000000,0.00000000,0.00000000,0.00000000,0.00000000,0.00000000,0.00000000,0.00000000,0.00000000,0.00000000
241.50000000,5.03128600,12.08270000,0.18688222,809.95135487,0.00000000,0.00000000,0.00000000,0.00000000,0.00000000,0.00000000,0.00000000,0.00000000,0.00000000,0.00000000,0.00000000
243.00000000,5.08705700,12.07790000,0.19014967,809.62959181,0.00000000,0.00000000,0.00000000,0.00000000,0.00000000,0.00000000,0.00000000,0.00000000,0.00000000,0.00000000,0.00000000
244.50000000,5.14337000,12.07000000,0.19360489,809.10002344,0.00000000,0.00000000,0.00000000,0.00000000,0.00000000,0.00000000,0.00000000,0.00000000,0.00000000,0.00000000,0.00000000
246.00000000,5.20093300,12.06120000,0.19717289,808.51012450,0.00000000,0.00000000,0.00000000,0.00000000,0.00000000,0.00000000,0.00000000,0.00000000,0.00000000,0.00000000,0.00000000
247.50000000,5.25883500,12.05320000,0.20096611,807.97385274,0.00000000,0.00000000,0.00000000,0.00000000,0.00000000,0.00000000,0.00000000,0.00000000,0.00000000,0.00000000,0.00000000
249.00000000,5.31677000,12.04520000,0.20487200,807.43758098,0.00000000,0.00000000,0.00000000,0.00000000,0.00000000,0.00000000,0.00000000,0.00000000,0.00000000,0.00000000,0.00000000
250.50000000,5.37419800,12.03250000,0.20896567,806.58624955,0.00000000,0.00000000,0.00000000,0.00000000,0.00000000,0.00000000,0.00000000,0.00000000,0.00000000,0.00000000,0.00000000
252.00000000,5.43314700,12.02530000,0.21324711,806.10360496,0.00000000,0.00000000,0.00000000,0.00000000,0.00000000,0.00000000,0.00000000,0.00000000,0.00000000,0.00000000,0.00000000
253.50000000,5.49229900,12.00850000,0.21779156,804.97743426,0.00000000,0.00000000,0.00000000,0.00000000,0.00000000,0.00000000,0.00000000,0.00000000,0.00000000,0.00000000,0.00000000
255.00000000,5.55226200,11.99500000,0.22248611,804.07247566,0.00000000,0.00000000,0.00000000,0.00000000,0.00000000,0.00000000,0.00000000,0.00000000,0.00000000,0.00000000,0.00000000
256.50000000,5.61165000,11.97510000,0.22740611,802.73849965,0.00000000,0.00000000,0.00000000,0.00000000,0.00000000,0.00000000,0.00000000,0.00000000,0.00000000,0.00000000,0.00000000
258.00000000,5.67178300,11.95590000,0.23255144,801.45144741,0.00000000,0.00000000,0.00000000,0.00000000,0.00000000,0.00000000,0.00000000,0.00000000,0.00000000,0.00000000,0.00000000
259.50000000,5.73262500,11.94160000,0.23795956,800.49286164,0.00000000,0.00000000,0.00000000,0.00000000,0.00000000,0.00000000,0.00000000,0.00000000,0.00000000,0.00000000,0.00000000
261.00000000,5.79326400,11.91840000,0.24348044,798.93767352,0.00000000,0.00000000,0.00000000,0.00000000,0.00000000,0.00000000,0.00000000,0.00000000,0.00000000,0.00000000,0.00000000
262.50000000,5.85407200,11.88890000,0.24922667,796.96017139,0.00000000,0.00000000,0.00000000,0.00000000,0.00000000,0.00000000,0.00000000,0.00000000,0.00000000,0.00000000,0.00000000
264.00000000,5.91555700,11.86100000,0.25516078,795.08992362,0.00000000,0.00000000,0.00000000,0.00000000,0.00000000,0.00000000,0.00000000,0.00000000,0.00000000,0.00000000,0.00000000
265.50000000,5.97727800,11.82990000,0.26132022,793.00516714,0.00000000,0.00000000,0.00000000,0.00000000,0.00000000,0.00000000,0.00000000,0.00000000,0.00000000,0.00000000,0.00000000
267.00000000,6.03981100,11.79080000,0.26762989,790.38413889,0.00000000,0.00000000,0.00000000,0.00000000,0.00000000,0.00000000,0.00000000,0.00000000,0.00000000,0.00000000,0.00000000
268.50000000,6.10160000,11.75180000,0.27409000,787.76981404,0.00000000,0.00000000,0.00000000,0.00000000,0.00000000,0.00000000,0.00000000,0.00000000,0.00000000,0.00000000,0.00000000
270.00000000,6.16447100,11.71350000,0.28070033,785.20241298,0.00000000,0.00000000,0.00000000,0.00000000,0.00000000,0.00000000,0.00000000,0.00000000,0.00000000,0.00000000,0.00000000
271.50000000,6.22761400,11.66400000,0.28749889,781.88423144,0.00000000,0.00000000,0.00000000,0.00000000,0.00000000,0.00000000,0.00000000,0.00000000,0.00000000,0.00000000,0.00000000
273.00000000,6.29055500,11.60900000,0.29437278,778.19736306,0.00000000,0.00000000,0.00000000,0.00000000,0.00000000,0.00000000,0.00000000,0.00000000,0.00000000,0.00000000,0.00000000
274.50000000,6.35407200,11.55240000,0.30132267,774.40324033,0.00000000,0.00000000,0.00000000,0.00000000,0.00000000,0.00000000,0.00000000,0.00000000,0.00000000,0.00000000,0.00000000
276.00000000,6.41816800,11.48140000,0.30842389,769.64382843,0.00000000,0.00000000,0.00000000,0.00000000,0.00000000,0.00000000,0.00000000,0.00000000,0.00000000,0.00000000,0.00000000
277.50000000,6.48331700,11.40170000,0.31567756,764.30122099,0.00000000,0.00000000,0.00000000,0.00000000,0.00000000,0.00000000,0.00000000,0.00000000,0.00000000,0.00000000,0.00000000
279.00000000,6.54935500,11.31000000,0.32312300,758.15420589,0.00000000,0.00000000,0.00000000,0.00000000,0.00000000,0.00000000,0.00000000,0.00000000,0.00000000,0.00000000,0.00000000
280.50000000,6.61699700,11.19030000,0.33083856,750.13023963,0.00000000,0.00000000,0.00000000,0.00000000,0.00000000,0.00000000,0.00000000,0.00000000,0.00000000,0.00000000,0.00000000
282.00000000,6.68943300,11.01810000,0.33901656,738.58698992,0.00000000,0.00000000,0.00000000,0.00000000,0.00000000,0.00000000,0.00000000,0.00000000,0.00000000,0.00000000,0.00000000
282.50000000,6.71654400,10.93750000,0.34226000,733.18405190,0.00000000,0.00000000,0.00000000,0.00000000,0.00000000,0.00000000,0.00000000,0.00000000,0.00000000,0.00000000,0.00000000