File: polyN_optimization/DP780_results/DATA/UT_00_2.csv
Time[s],Displacement[mm],Force[kN],EngStrain_longi,EngStress[MPa],TrueStrain,TrueStress[MPa],TrueStrainRate[1/s],PlasticStrain_longi,PlasticStress[MPa],PlasticStrain_thick,PlasticStrain_width,R-Value,Thickness[mm],Width[mm], Young's Modulus [MPa]
0.00000000,0.00000000,-0.01820000,0.00000000,-1.21216069,0.00000000,-1.21216069,0.00000000,0.00064040,406.15237870,0.00012867,-0.00076908,0.83204688,1.49820000,10.02170000,203022.59031069
1.50000000,0.00176036,0.29840000,0.00004578,19.87410720,0.00004578,19.87501699,0.00002844,0.00071989,418.45649198,0.00002569,-0.00074558,0.00000000,0.00000000,0.00000000,0.00000000
3.00000000,0.00331115,0.66370000,0.00009467,44.20390399,0.00009466,44.20808862,-0.00010354,0.00090562,431.29181211,-0.00004165,-0.00086398,0.00000000,0.00000000,0.00000000,0.00000000
4.50000000,0.00565325,0.99460000,0.00025689,66.24258386,0.00025686,66.25960084,0.00005021,0.00120065,442.42093541,-0.00011268,-0.00108797,0.00000000,0.00000000,0.00000000,0.00000000
6.00000000,0.00921062,1.30160000,0.00032033,86.68947029,0.00032028,86.71723981,0.00010508,0.00146343,453.97184404,-0.00043326,-0.00103016,0.00000000,0.00000000,0.00000000,0.00000000
7.50000000,0.01095925,1.61030000,0.00037033,107.24958052,0.00037026,107.28929861,0.00009752,0.00177040,465.70482182,-0.00045246,-0.00131794,0.00000000,0.00000000,0.00000000,0.00000000
9.00000000,0.01249945,1.87820000,0.00041389,125.09231952,0.00041380,125.14409384,0.00009152,0.00217476,475.84342808,-0.00061399,-0.00156077,0.00000000,0.00000000,0.00000000,0.00000000
10.50000000,0.01365696,2.13180000,0.00045300,141.98264656,0.00045290,142.04696469,-0.00007441,0.00257050,486.19489765,-0.00089856,-0.00167194,0.00000000,0.00000000,0.00000000,0.00000000
12.00000000,0.01602419,2.39900000,0.00054811,159.77876400,0.00054796,159.86634051,-0.00009772,0.00288858,496.35579346,-0.00110116,-0.00178742,0.00000000,0.00000000,0.00000000,0.00000000
13.50000000,0.01948160,2.63260000,0.00065189,175.33704631,0.00065168,175.45134658,-0.00006307,0.00328775,505.98110177,-0.00123763,-0.00205012,0.00000000,0.00000000,0.00000000,0.00000000
15.00000000,0.02184516,2.86070000,0.00079100,190.52901633,0.00079069,190.67972478,0.00033710,0.00389737,515.28694923,-0.00154462,-0.00235276,0.00000000,0.00000000,0.00000000,0.00000000
16.50000000,0.02302397,3.09600000,0.00073956,206.20052244,0.00073928,206.35301918,0.00010970,0.00449210,524.54988387,-0.00183798,-0.00265412,0.00000000,0.00000000,0.00000000,0.00000000
18.00000000,0.02467641,3.31290000,0.00078522,220.64654741,0.00078491,220.81980398,-0.00015454,0.00503752,533.15220174,-0.00216948,-0.00286804,0.00000000,0.00000000,0.00000000,0.00000000
19.50000000,0.02779506,3.52900000,0.00095111,235.03929060,0.00095066,235.26283908,-0.00002686,0.00569283,541.23838615,-0.00261794,-0.00307489,0.00000000,0.00000000,0.00000000,0.00000000
21.00000000,0.03014388,3.74670000,0.00109044,249.53859736,0.00108985,249.81070534,0.00027794,0.00632681,549.74829380,-0.00295731,-0.00336950,0.00000000,0.00000000,0.00000000,0.00000000
22.50000000,0.03230742,3.95480000,0.00103778,263.39852266,0.00103724,263.67187179,0.00016472,0.00691319,557.27195706,-0.00314476,-0.00376843,0.00000000,0.00000000,0.00000000,0.00000000
24.00000000,0.03514403,4.16140000,0.00104911,277.15854460,0.00104856,277.44931471,-0.00021021,0.00745598,564.51699877,-0.00340545,-0.00405052,0.00000000,0.00000000,0.00000000,0.00000000
25.50000000,0.03733413,4.37830000,0.00131244,291.60456957,0.00131158,291.98728437,-0.00005215,0.00816853,572.67102774,-0.00378172,-0.00438682,0.00000000,0.00000000,0.00000000,0.00000000
27.00000000,0.04035677,4.57690000,0.00142544,304.83177363,0.00142443,305.26629439,0.00035264,0.00890957,579.45489732,-0.00416904,-0.00474052,0.00000000,0.00000000,0.00000000,0.00000000
28.50000000,0.04391037,4.77470000,0.00142133,318.00569590,0.00142032,318.45768799,0.00023213,0.00952665,586.44654985,-0.00447428,-0.00505236,0.00000000,0.00000000,0.00000000,0.00000000
30.00000000,0.04867442,4.99160000,0.00143278,332.45172087,0.00143175,332.92805031,-0.00020237,0.01024249,593.61413010,-0.00490069,-0.00534180,0.00000000,0.00000000,0.00000000,0.00000000
31.50000000,0.05189515,5.18380000,0.00175611,345.25267061,0.00175457,345.85897267,-0.00002240,0.01109386,600.11523467,-0.00540971,-0.00568415,0.00000000,0.00000000,0.00000000,0.00000000
33.00000000,0.05535107,5.37990000,0.00195100,358.31336908,0.00194910,359.01243846,0.00029234,0.01181159,606.60708943,-0.00581578,-0.00599581,0.00000000,0.00000000,0.00000000,0.00000000
34.50000000,0.06141322,5.58650000,0.00202622,372.07339102,0.00202417,372.82729440,0.00039014,0.01248843,613.02216198,-0.00617504,-0.00631338,0.00000000,0.00000000,0.00000000,0.00000000
36.00000000,0.06717320,5.76990000,0.00205222,384.28824109,0.00205012,385.07688596,-0.00007540,0.01335808,619.13129912,-0.00667222,-0.00668587,0.00000000,0.00000000,0.00000000,0.00000000
37.50000000,0.07322297,5.95970000,0.00226978,396.92934547,0.00226721,397.83028688,-0.00024720,0.01412383,625.19259748,-0.00710610,-0.00701773,0.00000000,0.00000000,0.00000000,0.00000000
39.00000000,0.08100104,6.15350000,0.00267167,409.83685880,0.00266810,410.93180627,0.00018729,0.01485294,631.06995023,-0.00744947,-0.00740347,0.00000000,0.00000000,0.00000000,0.00000000
40.50000000,0.08915788,6.33290000,0.00291511,421.78529992,0.00291087,423.01485094,0.00039666,0.01569269,636.81555301,-0.00792893,-0.00776375,0.00000000,0.00000000,0.00000000,0.00000000
42.00000000,0.09578792,6.50760000,0.00307267,433.42071054,0.00306796,434.75246791,0.00021712,0.01650733,642.27517928,-0.00837180,-0.00813553,0.00000000,0.00000000,0.00000000,0.00000000
43.50000000,0.10586290,6.69180000,0.00333522,445.68884240,0.00332967,447.17531373,0.00004452,0.01732986,648.19190602,-0.00881402,-0.00851585,0.00000000,0.00000000,0.00000000,0.00000000
45.00000000,0.11639646,6.85530000,0.00374067,456.57830797,0.00373369,458.28621523,0.00021698,0.01814422,653.45774652,-0.00925815,-0.00888608,0.00000000,0.00000000,0.00000000,0.00000000
46.50000000,0.12725553,7.01080000,0.00411622,466.93495566,0.00410777,468.85696370,0.00023947,0.01904993,658.51911991,-0.00974211,-0.00930782,0.00000000,0.00000000,0.00000000,0.00000000
48.00000000,0.14087269,7.17430000,0.00448811,477.82442123,0.00447807,479.96895033,0.00007478,0.01992441,663.88994778,-0.01021879,-0.00970562,0.00000000,0.00000000,0.00000000,0.00000000
49.50000000,0.15424891,7.32100000,0.00504044,487.59496924,0.00502778,490.05266460,0.00028414,0.02074795,668.96884666,-0.01060848,-0.01013948,0.00000000,0.00000000,0.00000000,0.00000000
51.00000000,0.16995631,7.46450000,0.00558167,497.15239010,0.00556615,499.92732902,0.00062793,0.02163252,673.43960913,-0.01110533,-0.01052720,0.00000000,0.00000000,0.00000000,0.00000000
52.50000000,0.18591854,7.60010000,0.00609289,506.18365329,0.00607440,509.26777405,0.00075444,0.02260451,678.52594372,-0.01169560,-0.01090892,0.00000000,0.00000000,0.00000000,0.00000000
54.00000000,0.20338041,7.73730000,0.00654822,515.32148006,0.00652688,518.69591963,0.00035151,0.02348249,683.17983330,-0.01213108,-0.01135141,0.00000000,0.00000000,0.00000000,0.00000000
55.50000000,0.22131767,7.85690000,0.00713878,523.28710748,0.00711342,527.02273785,0.00024692,0.02445270,687.40372993,-0.01266453,-0.01178817,0.00000000,0.00000000,0.00000000,0.00000000
57.00000000,0.24000216,7.98610000,0.00778944,531.89211636,0.00775926,536.03526045,0.00036585,0.02538387,692.04836368,-0.01315905,-0.01222482,0.00000000,0.00000000,0.00000000,0.00000000
58.50000000,0.26022022,8.10330000,0.00840978,539.69789841,0.00837461,544.23663780,0.00020892,0.02632355,696.21159743,-0.01372086,-0.01260269,0.00000000,0.00000000,0.00000000,0.00000000
60.00000000,0.27996982,8.21500000,0.00910544,547.13736817,0.00906424,552.11929707,0.00023917,0.02728504,700.23906660,-0.01425331,-0.01303173,0.00000000,0.00000000,0.00000000,0.00000000
61.50000000,0.30033308,8.32580000,0.00990978,554.51689591,0.00986100,560.01203512,0.00058826,0.02830157,704.69205244,-0.01478988,-0.01351169,0.00000000,0.00000000,0.00000000,0.00000000
63.00000000,0.32083591,8.43350000,0.01055278,561.68995672,0.01049749,567.61734601,0.00070667,0.02927037,708.96079168,-0.01534398,-0.01392639,0.00000000,0.00000000,0.00000000,0.00000000
64.50000000,0.34278789,8.53630000,0.01125989,568.53666657,0.01119697,574.93832626,0.00060286,0.03028761,712.82271747,-0.01596769,-0.01431993,0.00000000,0.00000000,0.00000000,0.00000000
66.00000000,0.36483236,8.64240000,0.01202289,575.60316380,0.01195119,582.52357668,0.00056463,0.03128880,716.74263867,-0.01649041,-0.01479840,0.00000000,0.00000000,0.00000000,0.00000000
67.50000000,0.38800141,8.73730000,0.01272233,581.92371599,0.01264208,589.32714348,0.00064567,0.03223121,720.67581442,-0.01699506,-0.01523615,0.00000000,0.00000000,0.00000000,0.00000000
69.00000000,0.41051095,8.82500000,0.01339911,587.76473208,0.01331014,595.64025703,0.00048183,0.03330669,724.49773720,-0.01757556,-0.01573112,0.00000000,0.00000000,0.00000000,0.00000000
70.50000000,0.43475476,8.91990000,0.01424122,594.08528427,0.01414077,602.54578482,0.00037842,0.03433985,728.01168870,-0.01821159,-0.01612826,0.00000000,0.00000000,0.00000000,0.00000000
72.00000000,0.45778424,9.00690000,0.01504933,599.87967880,0.01493722,608.90746804,0.00047403,0.03531632,731.66432436,-0.01871956,-0.01659675,0.00000000,0.00000000,0.00000000,0.00000000
73.50000000,0.48110775,9.08900000,0.01579733,605.34772237,0.01567385,614.91060212,0.00053255,0.03634645,735.25184722,-0.01925563,-0.01709082,0.00000000,0.00000000,0.00000000,0.00000000
75.00000000,0.50706206,9.17430000,0.01661667,611.02889309,0.01648012,621.18215653,0.00034759,0.03745167,738.79036390,-0.01991269,-0.01753898,0.00000000,0.00000000,0.00000000,0.00000000
76.50000000,0.53220893,9.25810000,0.01746978,616.61016046,0.01731894,627.38220294,0.00043599,0.03849045,742.27946316,-0.02043885,-0.01805160,0.00000000,0.00000000,0.00000000,0.00000000
78.00000000,0.55843495,9.33700000,0.01834144,621.86507688,0.01817527,633.27098064,0.00063447,0.03952270,745.49809593,-0.02100805,-0.01851464,0.00000000,0.00000000,0.00000000,0.00000000
79.50000000,0.58353945,9.41280000,0.01916456,626.91352636,0.01898323,638.92804547,0.00051618,0.04057231,748.56807438,-0.02156414,-0.01900817,0.00000000,0.00000000,0.00000000,0.00000000
81.00000000,0.60913866,9.48690000,0.02007422,631.84875204,0.01987539,644.53262430,0.00061922,0.04166944,752.01530107,-0.02219728,-0.01947216,0.00000000,0.00000000,0.00000000,0.00000000
82.50000000,0.63641512,9.55230000,0.02096467,636.20453827,0.02074793,649.54235435,0.00066288,0.04276309,755.24261985,-0.02277739,-0.01998571,0.00000000,0.00000000,0.00000000,0.00000000
84.00000000,0.66359104,9.62970000,0.02182867,641.35955134,0.02159383,655.35957520,0.00067581,0.04380561,758.26905918,-0.02334978,-0.02045584,0.00000000,0.00000000,0.00000000,0.00000000
85.50000000,0.69094241,9.69990000,0.02275322,646.03502830,0.02249823,660.73440686,0.00062499,0.04494081,761.20348257,-0.02397884,-0.02096197,0.00000000,0.00000000,0.00000000,0.00000000
87.00000000,0.71794299,9.75970000,0.02363611,650.01784201,0.02336110,665.38173594,0.00055062,0.04596262,764.33769316,-0.02453825,-0.02142437,0.00000000,0.00000000,0.00000000,0.00000000
88.50000000,0.74677269,9.82750000,0.02459800,654.53347360,0.02430034,670.63368799,0.00073365,0.04710840,767.51684893,-0.02520119,-0.02190721,0.00000000,0.00000000,0.00000000,0.00000000
90.00000000,0.77487735,9.88730000,0.02552222,658.51628731,0.02520197,675.32308633,0.00072518,0.04825105,770.36199271,-0.02589693,-0.02235412,0.00000000,0.00000000,0.00000000,0.00000000
91.50000000,0.80319330,9.94230000,0.02647622,662.17941029,0.02613179,679.71141950,0.00059241,0.04933284,772.93992005,-0.02650708,-0.02282576,0.00000000,0.00000000,0.00000000,0.00000000
93.00000000,0.83172564,10.00210000,0.02747556,666.16222400,0.02710488,684.46540119,0.00073830,0.05041814,776.03339225,-0.02704891,-0.02336923,0.00000000,0.00000000,0.00000000,0.00000000
94.50000000,0.86146378,10.06030000,0.02841089,670.03847413,0.02801478,689.07486277,0.00057746,0.05157021,778.95890235,-0.02775008,-0.02382013,0.00000000,0.00000000,0.00000000,0.00000000
96.00000000,0.89039976,10.11530000,0.02940244,673.70159710,0.02897848,693.51007088,0.00059828,0.05272338,781.50202990,-0.02830891,-0.02441447,0.00000000,0.00000000,0.00000000,0.00000000
97.50000000,0.92049524,10.17120000,0.03040156,677.42466209,0.02994859,698.01942559,0.00061949,0.05382131,784.16944812,-0.02892217,-0.02489913,0.00000000,0.00000000,0.00000000,0.00000000
99.00000000,0.95056975,10.22140000,0.03146467,680.76809434,0.03097980,702.18823550,0.00072057,0.05497750,786.77443297,-0.02959149,-0.02538601,0.00000000,0.00000000,0.00000000,0.00000000
100.50000000,0.98011357,10.26610000,0.03247911,683.74521428,0.03196281,705.95265107,0.00061114,0.05608414,789.34519484,-0.03020502,-0.02587912,0.00000000,0.00000000,0.00000000,0.00000000
102.00000000,1.01103150,10.32430000,0.03348956,687.62146441,0.03294099,710.64960165,0.00058925,0.05722208,793.13941427,-0.03087246,-0.02634962,0.00000000,0.00000000,0.00000000,0.00000000
103.50000000,1.04199742,10.36580000,0.03460867,690.38545720,0.03402326,714.27877736,0.00068250,0.05842774,794.27063120,-0.03146875,-0.02695899,0.00000000,0.00000000,0.00000000,0.00000000
105.00000000,1.07200134,10.40800000,0.03563411,693.19607156,0.03501391,717.89749740,0.00062408,0.05955176,796.75567456,-0.03208820,-0.02746356,0.00000000,0.00000000,0.00000000,0.00000000
106.50000000,1.10397630,10.45590000,0.03671189,696.38631866,0.03605406,721.95197582,0.00078211,0.06070483,799.49686774,-0.03272691,-0.02797792,0.00000000,0.00000000,0.00000000,0.00000000
108.00000000,1.13566652,10.49570000,0.03768144,699.03708765,0.03698884,725.37781483,0.00046434,0.06185286,801.50395920,-0.03339839,-0.02845448,0.00000000,0.00000000,0.00000000,0.00000000
109.50000000,1.16734754,10.54200000,0.03882311,702.12077117,0.03808845,729.37928389,0.00056375,0.06296997,803.94000199,-0.03391825,-0.02905173,0.00000000,0.00000000,0.00000000,0.00000000
111.00000000,1.19949459,10.58430000,0.03994233,704.93804575,0.03916526,733.09491616,0.00072966,0.06416532,806.50828593,-0.03462734,-0.02953798,0.00000000,0.00000000,0.00000000,0.00000000
112.50000000,1.23179193,10.61860000,0.04100522,707.22250245,0.04018681,736.22231832,0.00067831,0.06535486,808.55385256,-0.03526477,-0.03009008,0.00000000,0.00000000,0.00000000,0.00000000
114.00000000,1.26441419,10.66000000,0.04212067,709.97983501,0.04125774,739.88465898,0.00057605,0.06654067,811.05926420,-0.03589016,-0.03065051,0.00000000,0.00000000,0.00000000,0.00000000
115.50000000,1.29710431,10.69990000,0.04324367,712.63726423,0.04233477,743.45431254,0.00061932,0.06769854,813.26661272,-0.03652813,-0.03117041,0.00000000,0.00000000,0.00000000,0.00000000
117.00000000,1.32940572,10.73260000,0.04438922,714.81515734,0.04343224,746.54524621,0.00071910,0.06883913,815.16908073,-0.03709465,-0.03174448,0.00000000,0.00000000,0.00000000,0.00000000
118.50000000,1.36300204,10.76850000,0.04550856,717.20617761,0.04450342,749.84519479,0.00073300,0.07005043,817.31283869,-0.03776763,-0.03228280,0.00000000,0.00000000,0.00000000,0.00000000
120.00000000,1.39674579,10.80440000,0.04666544,719.59719788,0.04560934,753.17752094,0.00071775,0.07125964,819.62470968,-0.03844849,-0.03281115,0.00000000,0.00000000,0.00000000,0.00000000
121.50000000,1.43071352,10.84100000,0.04781878,722.03483972,0.04671065,756.56166327,0.00070232,0.07244981,821.81706273,-0.03906493,-0.03338489,0.00000000,0.00000000,0.00000000,0.00000000
123.00000000,1.46433861,10.86980000,0.04895667,723.95298411,0.04779602,759.39530904,0.00075921,0.07361508,823.92788330,-0.03960632,-0.03400877,0.00000000,0.00000000,0.00000000,0.00000000
124.50000000,1.49804326,10.90170000,0.05012856,726.07759544,0.04891259,762.47481652,0.00069400,0.07477582,825.98815332,-0.04021983,-0.03455600,0.00000000,0.00000000,0.00000000,0.00000000
126.00000000,1.53299997,10.93360000,0.05129267,728.20220676,0.05002052,765.55363982,0.00083639,0.07603102,828.23930781,-0.04091501,-0.03511600,0.00000000,0.00000000,0.00000000,0.00000000
127.50000000,1.56772153,10.95830000,0.05247944,729.84728199,0.05114876,768.14926188,0.00077103,0.07724025,829.65154250,-0.04157029,-0.03566996,0.00000000,0.00000000,0.00000000,0.00000000
129.00000000,1.60274959,10.99020000,0.05361356,731.97189332,0.05222574,771.21550909,0.00061259,0.07842393,831.79981284,-0.04209867,-0.03632527,0.00000000,0.00000000,0.00000000,0.00000000
130.50000000,1.63717025,11.01890000,0.05481567,733.88337749,0.05336603,774.11168408,0.00070504,0.07957552,833.80158891,-0.04268562,-0.03688989,0.00000000,0.00000000,0.00000000,0.00000000
132.00000000,1.67311515,11.04680000,0.05607733,735.74157987,0.05456141,777.00000569,0.00089576,0.08084722,835.74030222,-0.04343259,-0.03741463,0.00000000,0.00000000,0.00000000,0.00000000
133.50000000,1.70828972,11.07470000,0.05722311,737.59978225,0.05564576,779.80753655,0.00073245,0.08212419,837.62146111,-0.04403996,-0.03808423,0.00000000,0.00000000,0.00000000,0.00000000
135.00000000,1.74451372,11.09860000,0.05846633,739.19157569,0.05682101,782.40939675,0.00075238,0.08334183,839.40500985,-0.04470051,-0.03864132,0.00000000,0.00000000,0.00000000,0.00000000
136.50000000,1.78080584,11.12100000,0.05964922,740.68346578,0.05793793,784.86465842,0.00076497,0.08460863,841.29165852,-0.04543600,-0.03917263,0.00000000,0.00000000,0.00000000,0.00000000
138.00000000,1.81704799,11.15130000,0.06084000,742.70151353,0.05906105,787.88747361,0.00067400,0.08586799,842.99256912,-0.04610703,-0.03976096,0.00000000,0.00000000,0.00000000,0.00000000
139.50000000,1.85343087,11.17120000,0.06212400,744.02689802,0.06027068,790.24882503,0.00085549,0.08717523,845.03741146,-0.04687972,-0.04029550,0.00000000,0.00000000,0.00000000,0.00000000
141.00000000,1.89087026,11.19430000,0.06332222,745.56540967,0.06139818,792.77626822,0.00079850,0.08840634,846.96277539,-0.04754475,-0.04086160,0.00000000,0.00000000,0.00000000,0.00000000
142.50000000,1.92687449,11.22140000,0.06458022,747.37033027,0.06258056,795.63567228,0.00074117,0.08969619,848.40555066,-0.04819523,-0.04150096,0.00000000,0.00000000,0.00000000,0.00000000
144.00000000,1.96345444,11.23340000,0.06581967,748.16955710,0.06374414,797.41382795,0.00079662,0.09097932,850.20526808,-0.04898926,-0.04199007,0.00000000,0.00000000,0.00000000,0.00000000
145.50000000,2.00092956,11.26050000,0.06705900,749.97447769,0.06490627,800.26701619,0.00078862,0.09230482,852.10338724,-0.04964255,-0.04266227,0.00000000,0.00000000,0.00000000,0.00000000
147.00000000,2.03800143,11.28050000,0.06832467,751.30652241,0.06609169,802.63929012,0.00084428,0.09364198,854.01507254,-0.05046519,-0.04317679,0.00000000,0.00000000,0.00000000,0.00000000
148.50000000,2.07547982,11.30040000,0.06953767,752.63190690,0.06722647,804.96817357,0.00085642,0.09498178,855.68898178,-0.05119278,-0.04378900,0.00000000,0.00000000,0.00000000,0.00000000
150.00000000,2.11250338,11.31470000,0.07084456,753.58431888,0.06844764,806.97166502,0.00088361,0.09624065,857.59932134,-0.05188855,-0.04435210,0.00000000,0.00000000,0.00000000,0.00000000
151.50000000,2.15037032,11.33790000,0.07211800,755.12949075,0.06963613,809.58791937,0.00086203,0.09755007,859.20142681,-0.05261125,-0.04493883,0.00000000,0.00000000,0.00000000,0.00000000
153.00000000,2.18786094,11.35380000,0.07335333,756.18846630,0.07078770,811.65741093,0.00076970,0.09900794,861.28304743,-0.05347199,-0.04553594,0.00000000,0.00000000,0.00000000,0.00000000
154.50000000,2.22650667,11.37220000,0.07466822,757.41394744,0.07201198,813.96870039,0.00088150,0.10031225,862.41179937,-0.05416975,-0.04614250,0.00000000,0.00000000,0.00000000,0.00000000
156.00000000,2.26514404,11.38730000,0.07591089,758.41964121,0.07316764,815.99195032,0.00089350,0.10168395,864.01678089,-0.05496192,-0.04672204,0.00000000,0.00000000,0.00000000,0.00000000
157.50000000,2.30289352,11.40330000,0.07721822,759.48527698,0.07438200,818.13137987,0.00087921,0.10306904,865.93397420,-0.05570581,-0.04736323,0.00000000,0.00000000,0.00000000,0.00000000
159.00000000,2.34171134,11.41600000,0.07844567,760.33112538,0.07552081,819.97580739,0.00071639,0.10440955,867.63708935,-0.05643947,-0.04797007,0.00000000,0.00000000,0.00000000,0.00000000
160.50000000,2.38187360,11.43840000,0.07973389,761.82301546,0.07671461,822.56612713,0.00070277,0.10576539,869.22972049,-0.05720292,-0.04856247,0.00000000,0.00000000,0.00000000,0.00000000
162.00000000,2.42103442,11.45030000,0.08105589,762.61558207,0.07793824,824.43006595,0.00079938,0.10714721,870.67588077,-0.05801529,-0.04913192,0.00000000,0.00000000,0.00000000,0.00000000
163.50000000,2.46060931,11.46470000,0.08238500,763.57465427,0.07916694,826.48175216,0.00091568,0.10846919,872.19175495,-0.05870118,-0.04976801,0.00000000,0.00000000,0.00000000,0.00000000
165.00000000,2.50039994,11.48220000,0.08361667,764.74019340,0.08030421,828.68521923,0.00065840,0.10983278,873.92653308,-0.05945384,-0.05037894,0.00000000,0.00000000,0.00000000,0.00000000
166.50000000,2.54075563,11.49260000,0.08500233,765.43285665,0.08158214,830.49643547,0.00078233,0.11131262,875.34628181,-0.06024960,-0.05106302,0.00000000,0.00000000,0.00000000,0.00000000
168.00000000,2.58067119,11.50530000,0.08629444,766.27870505,0.08277231,832.40430019,0.00077485,0.11265715,876.64921475,-0.06101473,-0.05164242,0.00000000,0.00000000,0.00000000,0.00000000
169.50000000,2.62140716,11.51970000,0.08760478,767.23777724,0.08397783,834.45147222,0.00086365,0.11401544,878.26730049,-0.06171541,-0.05230003,0.00000000,0.00000000,0.00000000,0.00000000
171.00000000,2.66226739,11.53170000,0.08901300,768.03700407,0.08527178,836.40228192,0.00088969,0.11547254,879.67396083,-0.06251019,-0.05296235,0.00000000,0.00000000,0.00000000,0.00000000
172.50000000,2.70245424,11.54600000,0.09035778,768.98941605,0.08650588,838.47359082,0.00078603,0.11688916,881.40185999,-0.06331464,-0.05357453,0.00000000,0.00000000,0.00000000,0.00000000
174.00000000,2.74281270,11.55400000,0.09167211,769.52223394,0.08771057,840.06596167,0.00074314,0.11827988,882.69414673,-0.06403434,-0.05424554,0.00000000,0.00000000,0.00000000,0.00000000
175.50000000,2.78487785,11.56360000,0.09310622,770.16161540,0.08902339,841.86845391,0.00081721,0.11976584,884.43630654,-0.06479585,-0.05496998,0.00000000,0.00000000,0.00000000,0.00000000
177.00000000,2.82608223,11.57310000,0.09448844,770.79433664,0.09028708,843.62549450,0.00080967,0.12128379,885.90687744,-0.06563326,-0.05565053,0.00000000,0.00000000,0.00000000,0.00000000
178.50000000,2.86719639,11.58510000,0.09592700,771.59356347,0.09160058,845.61021924,0.00080273,0.12273374,887.25853400,-0.06645422,-0.05627952,0.00000000,0.00000000,0.00000000,0.00000000
180.00000000,2.90961005,11.59550000,0.09730467,772.28622673,0.09285687,847.43328059,0.00083474,0.12424707,888.79050152,-0.06725015,-0.05699692,0.00000000,0.00000000,0.00000000,0.00000000
181.50000000,2.95071111,11.60260000,0.09873200,772.75910260,0.09415679,849.05515432,0.00084115,0.12569172,890.32462743,-0.06804796,-0.05764377,0.00000000,0.00000000,0.00000000,0.00000000
183.00000000,2.99376530,11.61460000,0.10014822,773.55832943,0.09544492,851.02882091,0.00083400,0.12723245,892.06945433,-0.06893484,-0.05829761,0.00000000,0.00000000,0.00000000,0.00000000
184.50000000,3.03605542,11.62420000,0.10166144,774.19771090,0.09681944,852.90376847,0.00091398,0.12870714,893.33045162,-0.06967136,-0.05903578,0.00000000,0.00000000,0.00000000,0.00000000
186.00000000,3.07773805,11.63050000,0.10313367,774.61730498,0.09815492,854.50642791,0.00089240,0.13030884,895.07466582,-0.07055588,-0.05975296,0.00000000,0.00000000,0.00000000,0.00000000
187.50000000,3.12109292,11.64250000,0.10454189,775.41653182,0.09943067,856.48004073,0.00074836,0.13181024,896.54792764,-0.07131855,-0.06049169,0.00000000,0.00000000,0.00000000,0.00000000
189.00000000,3.16364115,11.64810000,0.10604022,775.78950434,0.10078627,858.05439577,0.00092363,0.13331014,898.02225317,-0.07210180,-0.06120834,0.00000000,0.00000000,0.00000000,0.00000000
190.50000000,3.20687625,11.65610000,0.10756500,776.32232222,0.10216391,859.82743281,0.00104481,0.13500309,899.55038978,-0.07304886,-0.06195422,0.00000000,0.00000000,0.00000000,0.00000000
192.00000000,3.24973310,11.66090000,0.10904800,776.64201296,0.10350199,861.33327119,0.00078541,0.13649914,900.77976975,-0.07374332,-0.06275581,0.00000000,0.00000000,0.00000000,0.00000000
193.50000000,3.29500949,11.66960000,0.11062144,777.22145241,0.10491972,863.19881213,0.00100149,0.13812014,902.61763429,-0.07471230,-0.06340783,0.00000000,0.00000000,0.00000000,0.00000000
195.00000000,3.33789254,11.67760000,0.11209700,777.75427030,0.10624742,864.93819073,0.00089820,0.00000000,0.00000000,0.00000000,0.00000000,0.00000000,0.00000000,0.00000000,0.00000000
196.50000000,3.38135663,11.67760000,0.11359933,777.75427030,0.10759741,866.10663690,0.00080975,0.00000000,0.00000000,0.00000000,0.00000000,0.00000000,0.00000000,0.00000000,0.00000000
198.00000000,3.42578633,11.68800000,0.11512756,778.44693355,0.10896880,868.06762614,0.00085529,0.00000000,0.00000000,0.00000000,0.00000000,0.00000000,0.00000000,0.00000000,0.00000000
199.50000000,3.47021863,11.69270000,0.11667111,778.75996406,0.11035204,869.61875435,0.00089492,0.00000000,0.00000000,0.00000000,0.00000000,0.00000000,0.00000000,0.00000000,0.00000000
201.00000000,3.51426246,11.69590000,0.11823322,778.97309121,0.11174996,871.07358981,0.00091336,0.00000000,0.00000000,0.00000000,0.00000000,0.00000000,0.00000000,0.00000000,0.00000000
202.50000000,3.55986202,11.70390000,0.11973578,779.50590910,0.11309274,872.84065541,0.00094052,0.00000000,0.00000000,0.00000000,0.00000000,0.00000000,0.00000000,0.00000000,0.00000000
204.00000000,3.60499867,11.70630000,0.12131289,779.66575447,0.11450022,874.24925951,0.00101177,0.00000000,0.00000000,0.00000000,0.00000000,0.00000000,0.00000000,0.00000000,0.00000000
205.50000000,3.64996327,11.71350000,0.12289022,780.14529057,0.11590592,876.01751869,0.00084997,0.00000000,0.00000000,0.00000000,0.00000000,0.00000000,0.00000000,0.00000000,0.00000000
207.00000000,3.69624099,11.71350000,0.12441122,780.14529057,0.11725954,877.20411968,0.00085574,0.00000000,0.00000000,0.00000000,0.00000000,0.00000000,0.00000000,0.00000000,0.00000000
208.50000000,3.74223068,11.71590000,0.12604456,780.30513593,0.11871110,878.65834999,0.00102687,0.00000000,0.00000000,0.00000000,0.00000000,0.00000000,0.00000000,0.00000000,0.00000000
210.00000000,3.78808411,11.71910000,0.12763356,780.51826309,0.12012124,880.13858418,0.00091954,0.00000000,0.00000000,0.00000000,0.00000000,0.00000000,0.00000000,0.00000000,0.00000000
211.50000000,3.83373382,11.72390000,0.12932333,780.83795382,0.12161863,881.81852080,0.00106464,0.00000000,0.00000000,0.00000000,0.00000000,0.00000000,0.00000000,0.00000000,0.00000000
213.00000000,3.88110061,11.73020000,0.13086333,781.25754791,0.12298135,883.49551482,0.00099634,0.00000000,0.00000000,0.00000000,0.00000000,0.00000000,0.00000000,0.00000000,0.00000000
214.50000000,3.92847625,11.73100000,0.13259100,781.31082970,0.12450793,884.90561392,0.00106098,0.00000000,0.00000000,0.00000000,0.00000000,0.00000000,0.00000000,0.00000000,0.00000000
216.00000000,3.97552419,11.73580000,0.13420622,781.63052043,0.12593304,886.53019975,0.00086129,0.00000000,0.00000000,0.00000000,0.00000000,0.00000000,0.00000000,0.00000000,0.00000000
217.50000000,4.02288618,11.73740000,0.13593344,781.73708401,0.12745473,888.00129848,0.00099189,0.00000000,0.00000000,0.00000000,0.00000000,0.00000000,0.00000000,0.00000000,0.00000000
219.00000000,4.07015756,11.73820000,0.13758589,781.79036579,0.12890838,889.35368820,0.00085795,0.00000000,0.00000000,0.00000000,0.00000000,0.00000000,0.00000000,0.00000000,0.00000000
220.50000000,4.11746396,11.74380000,0.13935122,782.16333832,0.13045900,891.15875549,0.00105526,0.00000000,0.00000000,0.00000000,0.00000000,0.00000000,0.00000000,0.00000000,0.00000000
222.00000000,4.16668739,11.74380000,0.14107867,782.16333832,0.13197401,892.50989920,0.00098722,0.00000000,0.00000000,0.00000000,0.00000000,0.00000000,0.00000000,0.00000000,0.00000000
223.50000000,4.21578125,11.74700000,0.14284400,782.37646547,0.13351989,894.13424930,0.00111760,0.00000000,0.00000000,0.00000000,0.00000000,0.00000000,0.00000000,0.00000000,0.00000000
225.00000000,4.26351750,11.74700000,0.14460944,782.37646547,0.13506348,895.51549149,0.00098476,0.00000000,0.00000000,0.00000000,0.00000000,0.00000000,0.00000000,0.00000000,0.00000000
226.50000000,4.31135375,11.75100000,0.14637389,782.64287441,0.13660382,897.20135555,0.00104860,0.00000000,0.00000000,0.00000000,0.00000000,0.00000000,0.00000000,0.00000000,0.00000000
228.00000000,4.36151235,11.75100000,0.14813944,782.64287441,0.13814276,898.58315503,0.00111264,0.00000000,0.00000000,0.00000000,0.00000000,0.00000000,0.00000000,0.00000000,0.00000000
229.50000000,4.41125113,11.74940000,0.14997967,782.53631084,0.13974426,899.90084589,0.00091520,0.00000000,0.00000000,0.00000000,0.00000000,0.00000000,0.00000000,0.00000000,0.00000000
231.00000000,4.46119372,11.75020000,0.15181944,782.58959263,0.14134282,901.40190981,0.00110851,0.00000000,0.00000000,0.00000000,0.00000000,0.00000000,0.00000000,0.00000000,0.00000000
232.50000000,4.51074700,11.75180000,0.15373489,782.69615620,0.00000000,0.00000000,0.00000000,0.00000000,0.00000000,0.00000000,0.00000000,0.00000000,0.00000000,0.00000000,0.00000000
234.00000000,4.56010242,11.75260000,0.15561267,782.74943799,0.00000000,0.00000000,0.00000000,0.00000000,0.00000000,0.00000000,0.00000000,0.00000000,0.00000000,0.00000000,0.00000000
235.50000000,4.61097608,11.75100000,0.15760300,782.64287441,0.00000000,0.00000000,0.00000000,0.00000000,0.00000000,0.00000000,0.00000000,0.00000000,0.00000000,0.00000000,0.00000000
237.00000000,4.66189436,11.75180000,0.15948067,782.69615620,0.00000000,0.00000000,0.00000000,0.00000000,0.00000000,0.00000000,0.00000000,0.00000000,0.00000000,0.00000000,0.00000000
238.50000000,4.71336237,11.74860000,0.16150889,782.48302905,0.00000000,0.00000000,0.00000000,0.00000000,0.00000000,0.00000000,0.00000000,0.00000000,0.00000000,0.00000000,0.00000000
240.00000000,4.76402890,11.74940000,0.16357444,782.53631084,0.00000000,0.00000000,0.00000000,0.00000000,0.00000000,0.00000000,0.00000000,0.00000000,0.00000000,0.00000000,0.00000000
241.50000000,4.81571974,11.74860000,0.16571511,782.48302905,0.00000000,0.00000000,0.00000000,0.00000000,0.00000000,0.00000000,0.00000000,0.00000000,0.00000000,0.00000000,0.00000000
243.00000000,4.86839803,11.74620000,0.16778089,782.32318368,0.00000000,0.00000000,0.00000000,0.00000000,0.00000000,0.00000000,0.00000000,0.00000000,0.00000000,0.00000000,0.00000000
244.50000000,4.91994106,11.74780000,0.16984644,782.42974726,0.00000000,0.00000000,0.00000000,0.00000000,0.00000000,0.00000000,0.00000000,0.00000000,0.00000000,0.00000000,0.00000000
246.00000000,4.97201601,11.74460000,0.17217511,782.21662010,0.00000000,0.00000000,0.00000000,0.00000000,0.00000000,0.00000000,0.00000000,0.00000000,0.00000000,0.00000000,0.00000000
247.50000000,5.02527170,11.74140000,0.17442844,782.00349295,0.00000000,0.00000000,0.00000000,0.00000000,0.00000000,0.00000000,0.00000000,0.00000000,0.00000000,0.00000000,0.00000000
249.00000000,5.07970977,11.73820000,0.17671933,781.79036579,0.00000000,0.00000000,0.00000000,0.00000000,0.00000000,0.00000000,0.00000000,0.00000000,0.00000000,0.00000000,0.00000000
250.50000000,5.13328546,11.73660000,0.17901022,781.68380222,0.00000000,0.00000000,0.00000000,0.00000000,0.00000000,0.00000000,0.00000000,0.00000000,0.00000000,0.00000000,0.00000000
252.00000000,5.18725235,11.73420000,0.18156400,781.52395685,0.00000000,0.00000000,0.00000000,0.00000000,0.00000000,0.00000000,0.00000000,0.00000000,0.00000000,0.00000000,0.00000000
253.50000000,5.24147923,11.73260000,0.18396800,781.41739327,0.00000000,0.00000000,0.00000000,0.00000000,0.00000000,0.00000000,0.00000000,0.00000000,0.00000000,0.00000000,0.00000000
255.00000000,5.29605973,11.72860000,0.18648400,781.15098433,0.00000000,0.00000000,0.00000000,0.00000000,0.00000000,0.00000000,0.00000000,0.00000000,0.00000000,0.00000000,0.00000000
256.50000000,5.35197650,11.72230000,0.18911333,780.73139024,0.00000000,0.00000000,0.00000000,0.00000000,0.00000000,0.00000000,0.00000000,0.00000000,0.00000000,0.00000000,0.00000000
258.00000000,5.40686282,11.72150000,0.19185489,780.67810845,0.00000000,0.00000000,0.00000000,0.00000000,0.00000000,0.00000000,0.00000000,0.00000000,0.00000000,0.00000000,0.00000000
259.50000000,5.46184506,11.71510000,0.19459667,780.25185414,0.00000000,0.00000000,0.00000000,0.00000000,0.00000000,0.00000000,0.00000000,0.00000000,0.00000000,0.00000000,0.00000000
261.00000000,5.51809497,11.71350000,0.19756356,780.14529057,0.00000000,0.00000000,0.00000000,0.00000000,0.00000000,0.00000000,0.00000000,0.00000000,0.00000000,0.00000000,0.00000000
262.50000000,5.57438897,11.70790000,0.20056822,779.77231805,0.00000000,0.00000000,0.00000000,0.00000000,0.00000000,0.00000000,0.00000000,0.00000000,0.00000000,0.00000000,0.00000000
264.00000000,5.63035798,11.70390000,0.20349722,779.50590910,0.00000000,0.00000000,0.00000000,0.00000000,0.00000000,0.00000000,0.00000000,0.00000000,0.00000000,0.00000000,0.00000000
265.50000000,5.68769812,11.69750000,0.20695211,779.07965479,0.00000000,0.00000000,0.00000000,0.00000000,0.00000000,0.00000000,0.00000000,0.00000000,0.00000000,0.00000000,0.00000000
267.00000000,5.74470454,11.69040000,0.21025711,778.60677892,0.00000000,0.00000000,0.00000000,0.00000000,0.00000000,0.00000000,0.00000000,0.00000000,0.00000000,0.00000000,0.00000000
268.50000000,5.80256650,11.68320000,0.21389978,778.12724282,0.00000000,0.00000000,0.00000000,0.00000000,0.00000000,0.00000000,0.00000000,0.00000000,0.00000000,0.00000000,0.00000000
270.00000000,5.86043624,11.67520000,0.21761767,777.59442493,0.00000000,0.00000000,0.00000000,0.00000000,0.00000000,0.00000000,0.00000000,0.00000000,0.00000000,0.00000000,0.00000000
271.50000000,5.91769540,11.66480000,0.22152333,776.90176168,0.00000000,0.00000000,0.00000000,0.00000000,0.00000000,0.00000000,0.00000000,0.00000000,0.00000000,0.00000000,0.00000000
273.00000000,5.97675184,11.65770000,0.22557933,776.42888580,0.00000000,0.00000000,0.00000000,0.00000000,0.00000000,0.00000000,0.00000000,0.00000000,0.00000000,0.00000000,0.00000000
274.50000000,6.03565630,11.64890000,0.22997322,775.84278613,0.00000000,0.00000000,0.00000000,0.00000000,0.00000000,0.00000000,0.00000000,0.00000000,0.00000000,0.00000000,0.00000000
276.00000000,6.09395549,11.63530000,0.23440456,774.93699572,0.00000000,0.00000000,0.00000000,0.00000000,0.00000000,0.00000000,0.00000000,0.00000000,0.00000000,0.00000000,0.00000000
277.50000000,6.15239628,11.62420000,0.23917411,774.19771090,0.00000000,0.00000000,0.00000000,0.00000000,0.00000000,0.00000000,0.00000000,0.00000000,0.00000000,0.00000000,0.00000000
279.00000000,6.21308864,11.61380000,0.24398122,773.50504764,0.00000000,0.00000000,0.00000000,0.00000000,0.00000000,0.00000000,0.00000000,0.00000000,0.00000000,0.00000000,0.00000000
280.50000000,6.27303386,11.59940000,0.24920144,772.54597545,0.00000000,0.00000000,0.00000000,0.00000000,0.00000000,0.00000000,0.00000000,0.00000000,0.00000000,0.00000000,0.00000000
282.00000000,6.33230812,11.57550000,0.25472200,770.95418201,0.00000000,0.00000000,0.00000000,0.00000000,0.00000000,0.00000000,0.00000000,0.00000000,0.00000000,0.00000000,0.00000000
283.50000000,6.39269593,11.56120000,0.26035478,770.00177003,0.00000000,0.00000000,0.00000000,0.00000000,0.00000000,0.00000000,0.00000000,0.00000000,0.00000000,0.00000000,0.00000000
285.00000000,6.45316612,11.54360000,0.26617600,768.82957068,0.00000000,0.00000000,0.00000000,0.00000000,0.00000000,0.00000000,0.00000000,0.00000000,0.00000000,0.00000000,0.00000000
286.50000000,6.51436293,11.51650000,0.27222244,767.02465009,0.00000000,0.00000000,0.00000000,0.00000000,0.00000000,0.00000000,0.00000000,0.00000000,0.00000000,0.00000000,0.00000000
288.00000000,6.57583866,11.48940000,0.27860700,765.21972949,0.00000000,0.00000000,0.00000000,0.00000000,0.00000000,0.00000000,0.00000000,0.00000000,0.00000000,0.00000000,0.00000000
289.50000000,6.63761917,11.46230000,0.28502833,763.41480890,0.00000000,0.00000000,0.00000000,0.00000000,0.00000000,0.00000000,0.00000000,0.00000000,0.00000000,0.00000000,0.00000000
291.00000000,6.69944390,11.42880000,0.29171289,761.18363400,0.00000000,0.00000000,0.00000000,0.00000000,0.00000000,0.00000000,0.00000000,0.00000000,0.00000000,0.00000000,0.00000000
292.50000000,6.76165302,11.39610000,0.29847233,759.00574088,0.00000000,0.00000000,0.00000000,0.00000000,0.00000000,0.00000000,0.00000000,0.00000000,0.00000000,0.00000000,0.00000000
294.00000000,6.82396124,11.35860000,0.30530656,756.50815703,0.00000000,0.00000000,0.00000000,0.00000000,0.00000000,0.00000000,0.00000000,0.00000000,0.00000000,0.00000000,0.00000000
295.50000000,6.88623193,11.31320000,0.31221556,753.48441552,0.00000000,0.00000000,0.00000000,0.00000000,0.00000000,0.00000000,0.00000000,0.00000000,0.00000000,0.00000000,0.00000000
297.00000000,6.94925048,11.26690000,0.31916211,750.40073200,0.00000000,0.00000000,0.00000000,0.00000000,0.00000000,0.00000000,0.00000000,0.00000000,0.00000000,0.00000000,0.00000000
298.50000000,7.01272192,11.21510000,0.32625833,746.95073618,0.00000000,0.00000000,0.00000000,0.00000000,0.00000000,0.00000000,0.00000000,0.00000000,0.00000000,0.00000000,0.00000000
300.00000000,7.07706315,11.14970000,0.33342989,742.59494995,0.00000000,0.00000000,0.00000000,0.00000000,0.00000000,0.00000000,0.00000000,0.00000000,0.00000000,0.00000000,0.00000000
301.50000000,7.14095095,11.08190000,0.34063933,738.07931835,0.00000000,0.00000000,0.00000000,0.00000000,0.00000000,0.00000000,0.00000000,0.00000000,0.00000000,0.00000000,0.00000000
303.00000000,7.20675149,10.99740000,0.34792511,732.45142942,0.00000000,0.00000000,0.00000000,0.00000000,0.00000000,0.00000000,0.00000000,0.00000000,0.00000000,0.00000000,0.00000000
304.50000000,7.27288552,10.89450000,0.35551422,725.59805934,0.00000000,0.00000000,0.00000000,0.00000000,0.00000000,0.00000000,0.00000000,0.00000000,0.00000000,0.00000000,0.00000000
306.00000000,7.34107224,10.77410000,0.36329600,717.57915013,0.00000000,0.00000000,0.00000000,0.00000000,0.00000000,0.00000000,0.00000000,0.00000000,0.00000000,0.00000000,0.00000000
307.50000000,7.41233843,10.60580000,0.37142622,706.36999383,0.00000000,0.00000000,0.00000000,0.00000000,0.00000000,0.00000000,0.00000000,0.00000000,0.00000000,0.00000000,0.00000000
308.50000000,7.46773837,10.42480000,0.37787378,694.31498912,0.00000000,0.00000000,0.00000000,0.00000000,0.00000000,0.00000000,0.00000000,0.00000000,0.00000000,0.00000000,0.00000000