File: polyN_optimization/DP780_results/DATA/UT_00_3.csv
Time[s],Displacement[mm],Force[kN],EngStrain_longi,EngStress[MPa],TrueStrain,TrueStress[MPa],TrueStrainRate[1/s],PlasticStrain_longi,PlasticStress[MPa],PlasticStrain_thick,PlasticStrain_width,R-Value,Thickness[mm],Width[mm], Young's Modulus [MPa]
0.00000000,0.00000000,-0.01660000,0.00000000,-1.10532177,0.00000000,-1.10532177,0.00000000,0.00057929,391.89485169,0.00017373,-0.00075301,0.80585805,1.50010000,10.01150000,208215.14795580
1.50000000,0.00180600,0.30640000,0.00007589,20.40184286,0.00007589,20.40339113,0.00004933,0.00058013,405.12360358,0.00012895,-0.00070908,0.00000000,0.00000000,0.00000000,0.00000000
3.00000000,0.00367400,0.64050000,0.00012811,42.64810820,0.00012810,42.65357190,0.00001733,0.00069860,417.22594969,0.00026647,-0.00096507,0.00000000,0.00000000,0.00000000,0.00000000
4.50000000,0.00641300,0.96590000,0.00018933,64.31507839,0.00018932,64.32725538,0.00001511,0.00101214,429.25586132,-0.00013581,-0.00087633,0.00000000,0.00000000,0.00000000,0.00000000
6.00000000,0.00929400,1.30090000,0.00028289,86.62127081,0.00028285,86.64577501,0.00012841,0.00124829,441.74247430,-0.00007338,-0.00117490,0.00000000,0.00000000,0.00000000,0.00000000
7.50000000,0.01115500,1.58630000,0.00037989,105.62481504,0.00037982,105.66494074,0.00016017,0.00151117,453.29087600,-0.00030112,-0.00121005,0.00000000,0.00000000,0.00000000,0.00000000
9.00000000,0.01262800,1.84870000,0.00041222,123.09688935,0.00041214,123.14763262,0.00011862,0.00179488,464.37388220,-0.00047331,-0.00132158,0.00000000,0.00000000,0.00000000,0.00000000
10.50000000,0.01433400,2.12300000,0.00045978,141.36133287,0.00045967,141.42632767,0.00004442,0.00221914,475.74581375,-0.00055960,-0.00165954,0.00000000,0.00000000,0.00000000,0.00000000
12.00000000,0.01617700,2.36870000,0.00050667,157.72142684,0.00050654,157.80133903,-0.00001399,0.00257587,486.34441823,-0.00082577,-0.00175010,0.00000000,0.00000000,0.00000000,0.00000000
13.50000000,0.01807400,2.60710000,0.00059022,173.59544557,0.00059005,173.69790546,-0.00009972,0.00294222,496.41960049,-0.00103630,-0.00190591,0.00000000,0.00000000,0.00000000,0.00000000
15.00000000,0.02098800,2.85430000,0.00069711,190.05541800,0.00069687,190.18790775,-0.00006040,0.00338595,506.70348331,-0.00123847,-0.00214748,0.00000000,0.00000000,0.00000000,0.00000000
16.50000000,0.02380200,3.07760000,0.00081356,204.92399343,0.00081322,205.09071048,0.00008660,0.00402418,516.08374458,-0.00153937,-0.00248481,0.00000000,0.00000000,0.00000000,0.00000000
18.00000000,0.02613100,3.28900000,0.00088511,219.00019963,0.00088472,219.19403914,0.00025401,0.00458519,525.11324040,-0.00184538,-0.00273981,0.00000000,0.00000000,0.00000000,0.00000000
19.50000000,0.02829700,3.52980000,0.00090389,235.03402392,0.00090348,235.24646856,0.00017296,0.00513016,534.30634978,-0.00212804,-0.00300212,0.00000000,0.00000000,0.00000000,0.00000000
21.00000000,0.03030500,3.73790000,0.00095289,248.89049748,0.00095244,249.12766247,0.00004529,0.00577609,542.54190479,-0.00250275,-0.00327335,0.00000000,0.00000000,0.00000000,0.00000000
22.50000000,0.03268500,3.94530000,0.00100256,262.70036109,0.00100205,262.96373279,-0.00014940,0.00646917,550.97625042,-0.00289099,-0.00357818,0.00000000,0.00000000,0.00000000,0.00000000
24.00000000,0.03530600,4.16700000,0.00119067,277.46239948,0.00118996,277.79276471,-0.00005238,0.00708016,559.32273187,-0.00317414,-0.00390602,0.00000000,0.00000000,0.00000000,0.00000000
25.50000000,0.03829400,4.36870000,0.00134133,290.89272488,0.00134043,291.28290899,0.00024058,0.00769240,567.36350827,-0.00345051,-0.00424189,0.00000000,0.00000000,0.00000000,0.00000000
27.00000000,0.04141800,4.56250000,0.00139833,303.79702366,0.00139736,304.22183317,0.00030782,0.00838957,574.64661402,-0.00381430,-0.00457528,0.00000000,0.00000000,0.00000000,0.00000000
28.50000000,0.04606500,4.77310000,0.00140233,317.81996135,0.00140135,318.26565087,-0.00002219,0.00918664,582.65386854,-0.00428649,-0.00490015,0.00000000,0.00000000,0.00000000,0.00000000
30.00000000,0.04966100,4.96920000,0.00152311,330.87740712,0.00152195,331.38137018,-0.00020213,0.00984710,589.61944864,-0.00466598,-0.00518112,0.00000000,0.00000000,0.00000000,0.00000000
31.50000000,0.05227700,5.16060000,0.00183511,343.62190034,0.00183343,344.25248471,0.00013487,0.01052051,596.87288364,-0.00500205,-0.00551847,0.00000000,0.00000000,0.00000000,0.00000000
33.00000000,0.05621200,5.36560000,0.00194822,357.27195839,0.00194633,357.96800356,0.00038995,0.01132080,603.83389990,-0.00547206,-0.00584874,0.00000000,0.00000000,0.00000000,0.00000000
34.50000000,0.06203900,5.55860000,0.00198244,370.12298865,0.00198048,370.85673692,0.00015037,0.01215532,610.44747062,-0.00596417,-0.00619115,0.00000000,0.00000000,0.00000000,0.00000000
36.00000000,0.06714700,5.74040000,0.00210278,382.22825965,0.00210057,383.03200074,-0.00017984,0.01292264,617.03049017,-0.00640402,-0.00651862,0.00000000,0.00000000,0.00000000,0.00000000
37.50000000,0.07304100,5.94220000,0.00244100,395.66524362,0.00243803,396.63106248,-0.00001485,0.01366434,623.44467355,-0.00676493,-0.00689941,0.00000000,0.00000000,0.00000000,0.00000000
39.00000000,0.08067900,6.12480000,0.00268900,407.82378313,0.00268539,408.92042128,0.00035220,0.01450898,630.58594072,-0.00720335,-0.00730563,0.00000000,0.00000000,0.00000000,0.00000000
40.50000000,0.08653700,6.30500000,0.00288056,419.82251708,0.00287641,421.03183917,0.00038205,0.01541310,635.93370792,-0.00771744,-0.00769566,0.00000000,0.00000000,0.00000000,0.00000000
42.00000000,0.09454700,6.49400000,0.00304956,432.40720475,0.00304492,433.72585454,-0.00002260,0.01623839,642.15942946,-0.00814248,-0.00809590,0.00000000,0.00000000,0.00000000,0.00000000
43.50000000,0.10394100,6.66630000,0.00343989,443.87991208,0.00343399,445.40680965,0.00016433,0.01706291,647.63838969,-0.00856541,-0.00849750,0.00000000,0.00000000,0.00000000,0.00000000
45.00000000,0.11391400,6.83610000,0.00380033,455.18615528,0.00379313,456.91601440,0.00024685,0.01797043,653.28975940,-0.00906770,-0.00890272,0.00000000,0.00000000,0.00000000,0.00000000
46.50000000,0.12461800,7.00680000,0.00414189,466.55232557,0.00413333,468.48473346,0.00025430,0.01890092,659.34191174,-0.00962358,-0.00927734,0.00000000,0.00000000,0.00000000,0.00000000
48.00000000,0.13755900,7.15750000,0.00459611,476.58678288,0.00458558,478.77722868,0.00020197,0.01976180,664.38129672,-0.01007422,-0.00968759,0.00000000,0.00000000,0.00000000,0.00000000
49.50000000,0.15084000,7.31300000,0.00516644,486.94085130,0.00515314,489.45660415,0.00052270,0.02067075,669.18774807,-0.01058758,-0.01008317,0.00000000,0.00000000,0.00000000,0.00000000
51.00000000,0.16661200,7.47410000,0.00561678,497.66779936,0.00560106,500.46308879,0.00058989,0.02162258,674.79858329,-0.01116370,-0.01045888,0.00000000,0.00000000,0.00000000,0.00000000
52.50000000,0.18286000,7.60570000,0.00605589,506.43047077,0.00603763,509.49735743,0.00047761,0.02257716,679.65392557,-0.01170727,-0.01086989,0.00000000,0.00000000,0.00000000,0.00000000
54.00000000,0.19971900,7.74520000,0.00658144,515.71916881,0.00655988,519.11334586,0.00015631,0.02352787,684.35080562,-0.01225039,-0.01127748,0.00000000,0.00000000,0.00000000,0.00000000
55.50000000,0.21843700,7.87760000,0.00729478,524.53510874,0.00726830,528.36147579,0.00036515,0.02445834,689.26201783,-0.01276958,-0.01168875,0.00000000,0.00000000,0.00000000,0.00000000
57.00000000,0.23752800,8.00280000,0.00793300,532.87163199,0.00790170,537.09890265,0.00045445,0.02545747,694.11982125,-0.01336101,-0.01209645,0.00000000,0.00000000,0.00000000,0.00000000
58.50000000,0.25817300,8.11770000,0.00854489,540.52232307,0.00850859,545.14102626,0.00029792,0.02644335,698.48203059,-0.01392300,-0.01252035,0.00000000,0.00000000,0.00000000,0.00000000
60.00000000,0.27746800,8.24930000,0.00924311,549.28499448,0.00920065,554.36209671,0.00021557,0.02738683,703.09802045,-0.01440096,-0.01298587,0.00000000,0.00000000,0.00000000,0.00000000
61.50000000,0.29879100,8.35610000,0.01004289,556.39634179,0.00999279,561.98416843,0.00049839,0.02838965,707.32995837,-0.01493366,-0.01345600,0.00000000,0.00000000,0.00000000,0.00000000
63.00000000,0.31960900,8.46940000,0.01074122,563.94049583,0.01068395,569.99790601,0.00057964,0.02938456,711.44683246,-0.01542759,-0.01395697,0.00000000,0.00000000,0.00000000,0.00000000
64.50000000,0.34309500,8.57620000,0.01143956,571.05184314,0.01137462,577.58442243,0.00049726,0.03044019,715.56658315,-0.01601235,-0.01442784,0.00000000,0.00000000,0.00000000,0.00000000
66.00000000,0.36573900,8.67590000,0.01223189,577.69043235,0.01215768,584.75667753,0.00039301,0.03143655,719.70003022,-0.01652714,-0.01490941,0.00000000,0.00000000,0.00000000,0.00000000
67.50000000,0.38939600,8.77880000,0.01305067,584.54209564,0.01296624,592.17075968,0.00062286,0.03247807,723.27141457,-0.01714060,-0.01533747,0.00000000,0.00000000,0.00000000,0.00000000
69.00000000,0.41217500,8.89040000,0.01380544,591.97305407,0.01371102,600.14550518,0.00069651,0.03349976,727.71563993,-0.01767528,-0.01582448,0.00000000,0.00000000,0.00000000,0.00000000
70.50000000,0.43650900,8.97180000,0.01456033,597.39312590,0.01445535,606.09136894,0.00051830,0.03457246,731.10224023,-0.01827449,-0.01629797,0.00000000,0.00000000,0.00000000,0.00000000
72.00000000,0.46118000,9.06030000,0.01543156,603.28595584,0.01531370,612.59559658,0.00050297,0.03560543,735.02196765,-0.01883574,-0.01676969,0.00000000,0.00000000,0.00000000,0.00000000
73.50000000,0.48757500,9.15120000,0.01633278,609.33859133,0.01620083,619.29078313,0.00067990,0.03663569,738.49501878,-0.01939364,-0.01724205,0.00000000,0.00000000,0.00000000,0.00000000
75.00000000,0.51292400,9.24050000,0.01714767,615.28468979,0.01700230,625.83538655,0.00073837,0.03771409,742.24021232,-0.01997132,-0.01774278,0.00000000,0.00000000,0.00000000,0.00000000
76.50000000,0.53935300,9.32110000,0.01797400,620.65149310,0.01781438,631.80708304,0.00060522,0.03880320,745.72191716,-0.02065093,-0.01815227,0.00000000,0.00000000,0.00000000,0.00000000
78.00000000,0.56588300,9.40640000,0.01892033,626.33124896,0.01874357,638.18164497,0.00060443,0.03984866,749.06595736,-0.02119836,-0.01865030,0.00000000,0.00000000,0.00000000,0.00000000
79.50000000,0.59332600,9.47980000,0.01984044,631.21863560,0.01964619,643.74229387,0.00069980,0.04097938,752.36887187,-0.02190352,-0.01907586,0.00000000,0.00000000,0.00000000,0.00000000
81.00000000,0.62019600,9.55390000,0.02071167,636.15263219,0.02050010,649.32841346,0.00070639,0.04205527,755.62982895,-0.02248953,-0.01956574,0.00000000,0.00000000,0.00000000,0.00000000
82.50000000,0.64808100,9.63370000,0.02161300,641.46616698,0.02138275,655.33017525,0.00060284,0.04316176,758.98336786,-0.02312305,-0.02003871,0.00000000,0.00000000,0.00000000,0.00000000
84.00000000,0.67664000,9.70380000,0.02258578,646.13382098,0.02233450,660.72725588,0.00058770,0.04431093,762.09572512,-0.02375304,-0.02055790,0.00000000,0.00000000,0.00000000,0.00000000
85.50000000,0.70492800,9.77240000,0.02356967,650.70159650,0.02329619,666.03841623,0.00074133,0.04537372,765.09183414,-0.02432834,-0.02104538,0.00000000,0.00000000,0.00000000,0.00000000
87.00000000,0.73386000,9.84100000,0.02450100,655.26937203,0.02420566,671.32412691,0.00069661,0.04650891,768.37421395,-0.02494417,-0.02156474,0.00000000,0.00000000,0.00000000,0.00000000
88.50000000,0.76357100,9.90640000,0.02546622,659.62407347,0.02514736,676.42220671,0.00062290,0.04764719,771.44042951,-0.02558581,-0.02206138,0.00000000,0.00000000,0.00000000,0.00000000
90.00000000,0.79311000,9.96860000,0.02648767,663.76570084,0.02614294,681.34730547,0.00065866,0.04877782,774.39408488,-0.02618003,-0.02259779,0.00000000,0.00000000,0.00000000,0.00000000
91.50000000,0.82282100,10.03080000,0.02749411,667.90732821,0.02712294,686.27084650,0.00067251,0.04991842,777.19205508,-0.02677994,-0.02313848,0.00000000,0.00000000,0.00000000,0.00000000
93.00000000,0.85303800,10.08580000,0.02850444,671.56953891,0.02810575,690.71225552,0.00073043,0.05107134,780.12514511,-0.02741737,-0.02365398,0.00000000,0.00000000,0.00000000,0.00000000
94.50000000,0.88362700,10.14720000,0.02947711,675.65789776,0.02905101,695.57434068,0.00057643,0.05224346,782.45005543,-0.02806646,-0.02417700,0.00000000,0.00000000,0.00000000,0.00000000
96.00000000,0.91462100,10.20550000,0.03053622,679.53984110,0.03007927,700.29042069,0.00061962,0.05339602,785.61317342,-0.02871185,-0.02468417,0.00000000,0.00000000,0.00000000,0.00000000
97.50000000,0.94568400,10.25570000,0.03158767,682.88244068,0.03109904,704.45310358,0.00072824,0.05452771,788.42604690,-0.02932408,-0.02520362,0.00000000,0.00000000,0.00000000,0.00000000
99.00000000,0.97711800,10.30510000,0.03262800,686.17177174,0.03210701,708.56018431,0.00069823,0.05570584,790.88402143,-0.02999089,-0.02571495,0.00000000,0.00000000,0.00000000,0.00000000
100.50000000,1.00848400,10.35940000,0.03368333,689.78737248,0.03312848,713.02171048,0.00071214,0.05686993,793.73325880,-0.03065434,-0.02621560,0.00000000,0.00000000,0.00000000,0.00000000
102.00000000,1.04012100,10.40400000,0.03472378,692.75709243,0.03413451,716.81223576,0.00057372,0.05807136,795.88561683,-0.03135136,-0.02672000,0.00000000,0.00000000,0.00000000,0.00000000
103.50000000,1.07243500,10.45190000,0.03583911,695.94654501,0.03521183,720.88865057,0.00069628,0.05925723,798.76283947,-0.03200091,-0.02725633,0.00000000,0.00000000,0.00000000,0.00000000
105.00000000,1.10498400,10.49490000,0.03691700,698.80972792,0.03625189,724.60768665,0.00065933,0.06043713,801.12784267,-0.03267719,-0.02775993,0.00000000,0.00000000,0.00000000,0.00000000
106.50000000,1.13810900,10.54280000,0.03801367,701.99918051,0.03730895,728.68474336,0.00068776,0.06164707,803.52874022,-0.03334464,-0.02830243,0.00000000,0.00000000,0.00000000,0.00000000
108.00000000,1.16991600,10.58670000,0.03906522,704.92229050,0.03832148,732.46023643,0.00053517,0.06285391,806.26764492,-0.03404067,-0.02881325,0.00000000,0.00000000,0.00000000,0.00000000
109.50000000,1.20472800,10.63050000,0.04024444,707.83874193,0.03945573,736.32531885,0.00070039,0.06404472,808.37665057,-0.03470460,-0.02934012,0.00000000,0.00000000,0.00000000,0.00000000
111.00000000,1.23788700,10.66960000,0.04137867,710.44224081,0.04054548,739.83939347,0.00078629,0.06526064,810.78935311,-0.03535276,-0.02990788,0.00000000,0.00000000,0.00000000,0.00000000
112.50000000,1.27138300,10.70870000,0.04249789,713.04573968,0.04161965,743.34867830,0.00074216,0.06646895,813.02844532,-0.03602680,-0.03044215,0.00000000,0.00000000,0.00000000,0.00000000
114.00000000,1.30582500,10.74610000,0.04362078,715.53604296,0.04269618,746.74828168,0.00068385,0.06765048,815.42940540,-0.03665622,-0.03099426,0.00000000,0.00000000,0.00000000,0.00000000
115.50000000,1.33932200,10.78280000,0.04477744,717.97973628,0.04380389,750.12903403,0.00077650,0.06890477,817.65744346,-0.03737184,-0.03153293,0.00000000,0.00000000,0.00000000,0.00000000
117.00000000,1.37433900,10.81710000,0.04593044,720.26362404,0.04490687,753.34565241,0.00068956,0.07011284,819.74381607,-0.03803558,-0.03207725,0.00000000,0.00000000,0.00000000,0.00000000
118.50000000,1.40861300,10.85540000,0.04706089,722.81385439,0.04598709,756.83011688,0.00066716,0.07132917,821.94899527,-0.03868424,-0.03264493,0.00000000,0.00000000,0.00000000,0.00000000
120.00000000,1.44410300,10.88410000,0.04825900,724.72486252,0.04713069,759.69935966,0.00070945,0.07256879,824.06940112,-0.03939254,-0.03317625,0.00000000,0.00000000,0.00000000,0.00000000
121.50000000,1.47959300,10.92240000,0.04946078,727.27509288,0.04827649,763.24668463,0.00067305,0.07381155,825.95801141,-0.04008092,-0.03373063,0.00000000,0.00000000,0.00000000,0.00000000
123.00000000,1.51454200,10.95750000,0.05064378,729.61224916,0.04940310,766.56256977,0.00077216,0.07508470,828.40345651,-0.04081803,-0.03426667,0.00000000,0.00000000,0.00000000,0.00000000
124.50000000,1.55064100,10.98460000,0.05182678,731.41672025,0.05052844,769.32369207,0.00072120,0.07632025,830.40958636,-0.04150567,-0.03481458,0.00000000,0.00000000,0.00000000,0.00000000
126.00000000,1.58694200,11.01250000,0.05305111,733.27445986,0.05169177,772.17548470,0.00074211,0.07757254,832.20859670,-0.04220680,-0.03536574,0.00000000,0.00000000,0.00000000,0.00000000
127.50000000,1.62300700,11.04520000,0.05430167,735.45181058,0.05287862,775.38806965,0.00082642,0.07884885,834.43037646,-0.04289443,-0.03595442,0.00000000,0.00000000,0.00000000,0.00000000
129.00000000,1.65927500,11.06830000,0.05548844,736.98993907,0.05400364,777.88436436,0.00076862,0.08009644,836.52331472,-0.04357276,-0.03652368,0.00000000,0.00000000,0.00000000,0.00000000
130.50000000,1.69554300,11.09860000,0.05672411,739.00748424,0.05517366,780.92702688,0.00077487,0.08140179,838.49410420,-0.04429115,-0.03711064,0.00000000,0.00000000,0.00000000,0.00000000
132.00000000,1.73262200,11.12810000,0.05798222,740.97176088,0.05636353,783.93495018,0.00078824,0.08263840,840.05341164,-0.04494714,-0.03769126,0.00000000,0.00000000,0.00000000,0.00000000
133.50000000,1.76922800,11.15680000,0.05922533,742.88276901,0.05753782,786.88024863,0.00080158,0.08396263,842.39747112,-0.04569095,-0.03827168,0.00000000,0.00000000,0.00000000,0.00000000
135.00000000,1.80678000,11.17760000,0.06046100,744.26775051,0.05870372,789.26692297,0.00084321,0.08528485,844.04285238,-0.04644425,-0.03884059,0.00000000,0.00000000,0.00000000,0.00000000
136.50000000,1.84396100,11.20070000,0.06170789,745.80587900,0.05987883,791.82798532,0.00081374,0.08659244,846.25696784,-0.04718133,-0.03941111,0.00000000,0.00000000,0.00000000,0.00000000
138.00000000,1.88161500,11.22700000,0.06297722,747.55708157,0.06107367,794.63615002,0.00084811,0.08787600,848.11052201,-0.04788809,-0.03998791,0.00000000,0.00000000,0.00000000,0.00000000
139.50000000,1.91943800,11.24860000,0.06426544,748.99533159,0.06228484,797.12984946,0.00084709,0.08919002,849.69990830,-0.04865252,-0.04053750,0.00000000,0.00000000,0.00000000,0.00000000
141.00000000,1.95736100,11.26850000,0.06553489,750.32038601,0.06347692,799.49254913,0.00083210,0.09050045,851.63434635,-0.04937378,-0.04112667,0.00000000,0.00000000,0.00000000,0.00000000
142.50000000,1.99579300,11.29240000,0.06679678,751.91178302,0.06466049,802.13706730,0.00081694,0.09183167,853.18551352,-0.05010299,-0.04172868,0.00000000,0.00000000,0.00000000,0.00000000
144.00000000,2.03317600,11.31000000,0.06808122,753.08369044,0.06586379,804.35454852,0.00078078,0.09313237,855.00787224,-0.05082155,-0.04231082,0.00000000,0.00000000,0.00000000,0.00000000
145.50000000,2.07181000,11.32990000,0.06940689,754.40874486,0.06710419,806.76990879,0.00082181,0.09447973,856.69660939,-0.05159134,-0.04288839,0.00000000,0.00000000,0.00000000,0.00000000
147.00000000,2.11078300,11.35060000,0.07069144,755.78706779,0.06830465,809.21474731,0.00082103,0.09580826,858.36474942,-0.05232556,-0.04348270,0.00000000,0.00000000,0.00000000,0.00000000
148.50000000,2.14941700,11.36820000,0.07197589,756.95897521,0.06950357,811.44177031,0.00076405,0.09714130,860.16549909,-0.05301052,-0.04413078,0.00000000,0.00000000,0.00000000,0.00000000
150.00000000,2.18839000,11.38650000,0.07328656,758.17749259,0.07072549,813.74170952,0.00076995,0.09847668,861.79377099,-0.05377160,-0.04470507,0.00000000,0.00000000,0.00000000,0.00000000
151.50000000,2.22705600,11.40490000,0.07462344,759.40266853,0.07197032,816.07191138,0.00087368,0.09985713,863.52331412,-0.05453160,-0.04532553,0.00000000,0.00000000,0.00000000,0.00000000
153.00000000,2.26717900,11.42080000,0.07592678,760.46138035,0.07318241,818.20076259,0.00076806,0.10125290,865.20245655,-0.05531577,-0.04593714,0.00000000,0.00000000,0.00000000,0.00000000
154.50000000,2.30594900,11.43840000,0.07724878,761.63328777,0.07441036,820.46852837,0.00078796,0.10258694,867.37394822,-0.05602233,-0.04656461,0.00000000,0.00000000,0.00000000,0.00000000
156.00000000,2.34522500,11.45350000,0.07860456,762.63873107,0.07566813,822.58560958,0.00084984,0.10397123,868.52086541,-0.05679629,-0.04717494,0.00000000,0.00000000,0.00000000,0.00000000
157.50000000,2.38534700,11.46950000,0.07996411,763.70410146,0.07692781,824.77302108,0.00086977,0.10531713,870.23256209,-0.05749087,-0.04782626,0.00000000,0.00000000,0.00000000,0.00000000
159.00000000,2.42529900,11.48460000,0.08130856,764.70954476,0.07817193,826.88697326,0.00085450,0.10672218,871.87957679,-0.05828588,-0.04843630,0.00000000,0.00000000,0.00000000,0.00000000
160.50000000,2.46572500,11.49900000,0.08268700,765.66837811,0.07944591,828.97919929,0.00083288,0.10814971,873.30984130,-0.05908807,-0.04906163,0.00000000,0.00000000,0.00000000,0.00000000
162.00000000,2.50611900,11.51570000,0.08402033,766.78035844,0.08067666,831.20549975,0.00080416,0.10953984,875.12162170,-0.05989898,-0.04964086,0.00000000,0.00000000,0.00000000,0.00000000
163.50000000,2.54651100,11.52210000,0.08542111,767.20650660,0.08196803,832.74213884,0.00086519,0.11092969,876.58392009,-0.06070115,-0.05022853,0.00000000,0.00000000,0.00000000,0.00000000
165.00000000,2.58734200,11.53880000,0.08679944,768.31848694,0.08323709,835.00810476,0.00082952,0.11238358,878.22529274,-0.06151109,-0.05087248,0.00000000,0.00000000,0.00000000,0.00000000
166.50000000,2.62847600,11.55480000,0.08818900,769.38385732,0.08451485,837.23505031,0.00086993,0.11385185,879.88231025,-0.06235540,-0.05149645,0.00000000,0.00000000,0.00000000,0.00000000
168.00000000,2.66944400,11.56600000,0.08956356,770.12961659,0.08577721,839.10516329,0.00076518,0.11527828,881.50527514,-0.06310398,-0.05217430,0.00000000,0.00000000,0.00000000,0.00000000
169.50000000,2.71068100,11.57550000,0.09102833,770.76218026,0.08712068,840.92337692,0.00096405,0.11673712,882.85799148,-0.06389995,-0.05283717,0.00000000,0.00000000,0.00000000,0.00000000
171.00000000,2.75283100,11.58590000,0.09246300,771.45467101,0.08843478,842.78568425,0.00092147,0.11822359,884.95530630,-0.06472406,-0.05349953,0.00000000,0.00000000,0.00000000,0.00000000
172.50000000,2.79470900,11.59780000,0.09387889,772.24704023,0.08972999,844.74473431,0.00085179,0.11971114,886.33882903,-0.06553780,-0.05417334,0.00000000,0.00000000,0.00000000,0.00000000
174.00000000,2.83638600,11.60980000,0.09532100,773.04606802,0.09104747,846.73359227,0.00085046,0.12122972,887.69155212,-0.06637996,-0.05484977,0.00000000,0.00000000,0.00000000,0.00000000
175.50000000,2.87873900,11.61540000,0.09676322,773.41894765,0.09236332,848.25745715,0.00089739,0.12274464,889.34676597,-0.06723054,-0.05551411,0.00000000,0.00000000,0.00000000,0.00000000
177.00000000,2.92099200,11.62900000,0.09823933,774.32451248,0.09370829,850.39363637,0.00094416,0.12422455,890.91281525,-0.06803047,-0.05619408,0.00000000,0.00000000,0.00000000,0.00000000
178.50000000,2.96341100,11.63690000,0.09964011,774.85053911,0.09498295,852.05673292,0.00085420,0.12580076,892.56788381,-0.06896593,-0.05683483,0.00000000,0.00000000,0.00000000,0.00000000
180.00000000,3.00630400,11.64570000,0.10111600,775.43649282,0.09632421,853.84552922,0.00085951,0.12731004,893.92180322,-0.06979073,-0.05751931,0.00000000,0.00000000,0.00000000,0.00000000
181.50000000,3.04923100,11.65370000,0.10257700,775.96917801,0.09765017,855.56576838,0.00089265,0.12891388,895.66839308,-0.07071902,-0.05819486,0.00000000,0.00000000,0.00000000,0.00000000
183.00000000,3.09222500,11.66010000,0.10408300,776.39532616,0.09901513,857.20488090,0.00091177,0.13045257,896.74746123,-0.07154581,-0.05890675,0.00000000,0.00000000,0.00000000,0.00000000
184.50000000,3.13542400,11.66800000,0.10555522,776.92135279,0.10034767,858.92945883,0.00090392,0.13201773,898.64862195,-0.07240518,-0.05961255,0.00000000,0.00000000,0.00000000,0.00000000
186.00000000,3.17885700,11.67360000,0.10706500,777.29423242,0.10171237,860.51523942,0.00095008,0.13364828,900.06001387,-0.07333027,-0.06031801,0.00000000,0.00000000,0.00000000,0.00000000
187.50000000,3.22225700,11.68480000,0.10854478,778.03999169,0.10304814,862.49216969,0.00093538,0.13527490,901.71610648,-0.07422798,-0.06104692,0.00000000,0.00000000,0.00000000,0.00000000
189.00000000,3.26589400,11.68960000,0.11009200,778.35960281,0.10444289,864.05076820,0.00094749,0.13696495,903.18631335,-0.07516039,-0.06180456,0.00000000,0.00000000,0.00000000,0.00000000
190.50000000,3.30997100,11.69510000,0.11156056,778.72582388,0.10576493,865.60090942,0.00078404,0.13861942,904.68831615,-0.07608026,-0.06253916,0.00000000,0.00000000,0.00000000,0.00000000
192.00000000,3.35435100,11.70790000,0.11312289,779.57812019,0.10716948,867.76624926,0.00090437,0.00000000,0.00000000,0.00000000,0.00000000,0.00000000,0.00000000,0.00000000,0.00000000
193.50000000,3.39896700,11.71030000,0.11468900,779.73792574,0.10857544,869.16528871,0.00093680,0.00000000,0.00000000,0.00000000,0.00000000,0.00000000,0.00000000,0.00000000,0.00000000
195.00000000,3.44277400,11.71430000,0.11619500,780.00426834,0.10992558,870.63686430,0.00092897,0.00000000,0.00000000,0.00000000,0.00000000,0.00000000,0.00000000,0.00000000,0.00000000
196.50000000,3.48840500,11.72150000,0.11780989,780.48368501,0.11137131,872.43238122,0.00099465,0.00000000,0.00000000,0.00000000,0.00000000,0.00000000,0.00000000,0.00000000,0.00000000
198.00000000,3.53295400,11.72540000,0.11934978,780.74336904,0.11274796,873.92491664,0.00087928,0.00000000,0.00000000,0.00000000,0.00000000,0.00000000,0.00000000,0.00000000,0.00000000
199.50000000,3.57787600,11.73180000,0.12098722,781.16951720,0.11420975,875.68104717,0.00100532,0.00000000,0.00000000,0.00000000,0.00000000,0.00000000,0.00000000,0.00000000,0.00000000
201.00000000,3.62387800,11.73340000,0.12256078,781.27605424,0.11561248,877.02985510,0.00101718,0.00000000,0.00000000,0.00000000,0.00000000,0.00000000,0.00000000,0.00000000,0.00000000
202.50000000,3.66910400,11.73820000,0.12417200,781.59566535,0.11704676,878.64796231,0.00096232,0.00000000,0.00000000,0.00000000,0.00000000,0.00000000,0.00000000,0.00000000,0.00000000
204.00000000,3.71578300,11.74620000,0.12585456,782.12835054,0.11854235,880.56276649,0.00100117,0.00000000,0.00000000,0.00000000,0.00000000,0.00000000,0.00000000,0.00000000,0.00000000
205.50000000,3.76195500,11.74940000,0.12750700,782.34142462,0.12000900,882.09543265,0.00106616,0.00000000,0.00000000,0.00000000,0.00000000,0.00000000,0.00000000,0.00000000,0.00000000
207.00000000,3.80849900,11.75260000,0.12912200,782.55449870,0.12144034,883.59950068,0.00099827,0.00000000,0.00000000,0.00000000,0.00000000,0.00000000,0.00000000,0.00000000,0.00000000
208.50000000,3.85514300,11.75730000,0.13084956,782.86745125,0.12296917,885.30530930,0.00106300,0.00000000,0.00000000,0.00000000,0.00000000,0.00000000,0.00000000,0.00000000,0.00000000
210.00000000,3.90185600,11.75970000,0.13246444,783.02725681,0.12439618,886.75052736,0.00092877,0.00000000,0.00000000,0.00000000,0.00000000,0.00000000,0.00000000,0.00000000,0.00000000
211.50000000,3.94931200,11.76210000,0.13415444,783.18706236,0.12588739,888.25508761,0.00086113,0.00000000,0.00000000,0.00000000,0.00000000,0.00000000,0.00000000,0.00000000,0.00000000
213.00000000,3.99687000,11.76930000,0.13591967,783.66647904,0.12744260,890.18216564,0.00092594,0.00000000,0.00000000,0.00000000,0.00000000,0.00000000,0.00000000,0.00000000,0.00000000
214.50000000,4.04463100,11.76770000,0.13768478,783.55994200,0.12899530,891.44421849,0.00105662,0.00000000,0.00000000,0.00000000,0.00000000,0.00000000,0.00000000,0.00000000,0.00000000
216.00000000,4.09293200,11.76850000,0.13944989,783.61321052,0.13054559,892.88798566,0.00098903,0.00000000,0.00000000,0.00000000,0.00000000,0.00000000,0.00000000,0.00000000,0.00000000
217.50000000,4.14130100,11.77170000,0.14121500,783.82628459,0.13209348,894.51431337,0.00105335,0.00000000,0.00000000,0.00000000,0.00000000,0.00000000,0.00000000,0.00000000,0.00000000
219.00000000,4.18966900,11.77250000,0.14301778,783.87955311,0.13367194,895.98826484,0.00098594,0.00000000,0.00000000,0.00000000,0.00000000,0.00000000,0.00000000,0.00000000,0.00000000
220.50000000,4.23807200,11.77410000,0.14482044,783.98609015,0.13524781,897.52330417,0.00105003,0.00000000,0.00000000,0.00000000,0.00000000,0.00000000,0.00000000,0.00000000,0.00000000
222.00000000,4.28705000,11.77570000,0.14662322,784.09262719,0.13682129,899.05881471,0.00104857,0.00000000,0.00000000,0.00000000,0.00000000,0.00000000,0.00000000,0.00000000,0.00000000
223.50000000,4.33687200,11.77570000,0.14857611,784.09262719,0.13852301,900.59006049,0.00117746,0.00000000,0.00000000,0.00000000,0.00000000,0.00000000,0.00000000,0.00000000,0.00000000
225.00000000,4.38632200,11.77330000,0.15045378,783.93282163,0.14015645,901.87847617,0.00117534,0.00000000,0.00000000,0.00000000,0.00000000,0.00000000,0.00000000,0.00000000,0.00000000
226.50000000,4.43631300,11.77490000,0.15229411,784.03935867,0.14175483,903.44393588,0.00097800,0.00000000,0.00000000,0.00000000,0.00000000,0.00000000,0.00000000,0.00000000,0.00000000
228.00000000,4.48610100,11.78050000,0.15428467,784.41223831,0.14348082,905.43501902,0.00110672,0.00000000,0.00000000,0.00000000,0.00000000,0.00000000,0.00000000,0.00000000,0.00000000
229.50000000,4.53633100,11.77570000,0.15623756,784.09262719,0.00000000,0.00000000,0.00000000,0.00000000,0.00000000,0.00000000,0.00000000,0.00000000,0.00000000,0.00000000,0.00000000
231.00000000,4.58730200,11.77490000,0.15819056,784.03935867,0.00000000,0.00000000,0.00000000,0.00000000,0.00000000,0.00000000,0.00000000,0.00000000,0.00000000,0.00000000,0.00000000
232.50000000,4.63756300,11.77410000,0.16029356,783.98609015,0.00000000,0.00000000,0.00000000,0.00000000,0.00000000,0.00000000,0.00000000,0.00000000,0.00000000,0.00000000,0.00000000
234.00000000,4.68951500,11.77570000,0.16235922,784.09262719,0.00000000,0.00000000,0.00000000,0.00000000,0.00000000,0.00000000,0.00000000,0.00000000,0.00000000,0.00000000,0.00000000
235.50000000,4.74133100,11.77570000,0.16446244,784.09262719,0.00000000,0.00000000,0.00000000,0.00000000,0.00000000,0.00000000,0.00000000,0.00000000,0.00000000,0.00000000,0.00000000
237.00000000,4.79311400,11.77490000,0.16660311,784.03935867,0.00000000,0.00000000,0.00000000,0.00000000,0.00000000,0.00000000,0.00000000,0.00000000,0.00000000,0.00000000,0.00000000
238.50000000,4.84493100,11.77170000,0.16881889,783.82628459,0.00000000,0.00000000,0.00000000,0.00000000,0.00000000,0.00000000,0.00000000,0.00000000,0.00000000,0.00000000,0.00000000
240.00000000,4.89749100,11.76930000,0.17107233,783.66647904,0.00000000,0.00000000,0.00000000,0.00000000,0.00000000,0.00000000,0.00000000,0.00000000,0.00000000,0.00000000,0.00000000
241.50000000,4.95018600,11.77170000,0.17336322,783.82628459,0.00000000,0.00000000,0.00000000,0.00000000,0.00000000,0.00000000,0.00000000,0.00000000,0.00000000,0.00000000,0.00000000
243.00000000,5.00322000,11.76690000,0.17572933,783.50667348,0.00000000,0.00000000,0.00000000,0.00000000,0.00000000,0.00000000,0.00000000,0.00000000,0.00000000,0.00000000,0.00000000
244.50000000,5.05611900,11.76530000,0.17805789,783.40013644,0.00000000,0.00000000,0.00000000,0.00000000,0.00000000,0.00000000,0.00000000,0.00000000,0.00000000,0.00000000,0.00000000
246.00000000,5.11063900,11.76050000,0.18053656,783.08052532,0.00000000,0.00000000,0.00000000,0.00000000,0.00000000,0.00000000,0.00000000,0.00000000,0.00000000,0.00000000,0.00000000
247.50000000,5.16502400,11.75890000,0.18312789,782.97398829,0.00000000,0.00000000,0.00000000,0.00000000,0.00000000,0.00000000,0.00000000,0.00000000,0.00000000,0.00000000,0.00000000
249.00000000,5.21978100,11.75420000,0.18575689,782.66103574,0.00000000,0.00000000,0.00000000,0.00000000,0.00000000,0.00000000,0.00000000,0.00000000,0.00000000,0.00000000,0.00000000
250.50000000,5.27467300,11.75260000,0.18846089,782.55449870,0.00000000,0.00000000,0.00000000,0.00000000,0.00000000,0.00000000,0.00000000,0.00000000,0.00000000,0.00000000,0.00000000
252.00000000,5.32946500,11.74460000,0.19120256,782.02181351,0.00000000,0.00000000,0.00000000,0.00000000,0.00000000,0.00000000,0.00000000,0.00000000,0.00000000,0.00000000,0.00000000
253.50000000,5.38540400,11.74220000,0.19413200,781.86200795,0.00000000,0.00000000,0.00000000,0.00000000,0.00000000,0.00000000,0.00000000,0.00000000,0.00000000,0.00000000,0.00000000
255.00000000,5.44164900,11.73980000,0.19706133,781.70220239,0.00000000,0.00000000,0.00000000,0.00000000,0.00000000,0.00000000,0.00000000,0.00000000,0.00000000,0.00000000,0.00000000
256.50000000,5.49786000,11.73180000,0.20017856,781.16951720,0.00000000,0.00000000,0.00000000,0.00000000,0.00000000,0.00000000,0.00000000,0.00000000,0.00000000,0.00000000,0.00000000
258.00000000,5.55444200,11.73900000,0.20337089,781.64893387,0.00000000,0.00000000,0.00000000,0.00000000,0.00000000,0.00000000,0.00000000,0.00000000,0.00000000,0.00000000,0.00000000
259.50000000,5.61116000,11.72150000,0.20675089,780.48368501,0.00000000,0.00000000,0.00000000,0.00000000,0.00000000,0.00000000,0.00000000,0.00000000,0.00000000,0.00000000,0.00000000
261.00000000,5.66825000,11.71750000,0.21031878,780.21734242,0.00000000,0.00000000,0.00000000,0.00000000,0.00000000,0.00000000,0.00000000,0.00000000,0.00000000,0.00000000,0.00000000
262.50000000,5.72608300,11.70950000,0.21399933,779.68465722,0.00000000,0.00000000,0.00000000,0.00000000,0.00000000,0.00000000,0.00000000,0.00000000,0.00000000,0.00000000,0.00000000
264.00000000,5.78405100,11.69910000,0.21783011,778.99216647,0.00000000,0.00000000,0.00000000,0.00000000,0.00000000,0.00000000,0.00000000,0.00000000,0.00000000,0.00000000,0.00000000
265.50000000,5.84185100,11.69270000,0.22184867,778.56601832,0.00000000,0.00000000,0.00000000,0.00000000,0.00000000,0.00000000,0.00000000,0.00000000,0.00000000,0.00000000,0.00000000
267.00000000,5.90127200,11.68080000,0.22613011,777.77364910,0.00000000,0.00000000,0.00000000,0.00000000,0.00000000,0.00000000,0.00000000,0.00000000,0.00000000,0.00000000,0.00000000
268.50000000,5.96028900,11.67200000,0.23056178,777.18769539,0.00000000,0.00000000,0.00000000,0.00000000,0.00000000,0.00000000,0.00000000,0.00000000,0.00000000,0.00000000,0.00000000
270.00000000,6.01957500,11.66090000,0.23529389,776.44859468,0.00000000,0.00000000,0.00000000,0.00000000,0.00000000,0.00000000,0.00000000,0.00000000,0.00000000,0.00000000,0.00000000
271.50000000,6.07872600,11.64410000,0.24013878,775.32995578,0.00000000,0.00000000,0.00000000,0.00000000,0.00000000,0.00000000,0.00000000,0.00000000,0.00000000,0.00000000,0.00000000
273.00000000,6.13838500,11.63130000,0.24532156,774.47765947,0.00000000,0.00000000,0.00000000,0.00000000,0.00000000,0.00000000,0.00000000,0.00000000,0.00000000,0.00000000,0.00000000
274.50000000,6.19892100,11.61540000,0.25069211,773.41894765,0.00000000,0.00000000,0.00000000,0.00000000,0.00000000,0.00000000,0.00000000,0.00000000,0.00000000,0.00000000,0.00000000
276.00000000,6.25891800,11.59230000,0.25628811,771.88081916,0.00000000,0.00000000,0.00000000,0.00000000,0.00000000,0.00000000,0.00000000,0.00000000,0.00000000,0.00000000,0.00000000
277.50000000,6.31979300,11.57870000,0.26214700,770.97525433,0.00000000,0.00000000,0.00000000,0.00000000,0.00000000,0.00000000,0.00000000,0.00000000,0.00000000,0.00000000,0.00000000
279.00000000,6.38049900,11.55560000,0.26823111,769.43712584,0.00000000,0.00000000,0.00000000,0.00000000,0.00000000,0.00000000,0.00000000,0.00000000,0.00000000,0.00000000,0.00000000
280.50000000,6.44215100,11.52530000,0.27454067,767.41958067,0.00000000,0.00000000,0.00000000,0.00000000,0.00000000,0.00000000,0.00000000,0.00000000,0.00000000,0.00000000,0.00000000
282.00000000,6.50336500,11.49900000,0.28092533,765.66837811,0.00000000,0.00000000,0.00000000,0.00000000,0.00000000,0.00000000,0.00000000,0.00000000,0.00000000,0.00000000,0.00000000
283.50000000,6.56464600,11.46870000,0.28746022,763.65083294,0.00000000,0.00000000,0.00000000,0.00000000,0.00000000,0.00000000,0.00000000,0.00000000,0.00000000,0.00000000,0.00000000
285.00000000,6.62670400,11.43600000,0.29418289,761.47348222,0.00000000,0.00000000,0.00000000,0.00000000,0.00000000,0.00000000,0.00000000,0.00000000,0.00000000,0.00000000,0.00000000
286.50000000,6.68940400,11.39450000,0.30105578,758.71017778,0.00000000,0.00000000,0.00000000,0.00000000,0.00000000,0.00000000,0.00000000,0.00000000,0.00000000,0.00000000,0.00000000
288.00000000,6.75203800,11.35460000,0.30796633,756.05341039,0.00000000,0.00000000,0.00000000,0.00000000,0.00000000,0.00000000,0.00000000,0.00000000,0.00000000,0.00000000,0.00000000
289.50000000,6.81511100,11.30040000,0.31495200,752.44446821,0.00000000,0.00000000,0.00000000,0.00000000,0.00000000,0.00000000,0.00000000,0.00000000,0.00000000,0.00000000,0.00000000
291.00000000,6.87832000,11.25020000,0.32197522,749.10186863,0.00000000,0.00000000,0.00000000,0.00000000,0.00000000,0.00000000,0.00000000,0.00000000,0.00000000,0.00000000,0.00000000
292.50000000,6.94281300,11.19190000,0.32918633,745.21992529,0.00000000,0.00000000,0.00000000,0.00000000,0.00000000,0.00000000,0.00000000,0.00000000,0.00000000,0.00000000,0.00000000
294.00000000,7.00764500,11.11460000,0.33643522,740.07285462,0.00000000,0.00000000,0.00000000,0.00000000,0.00000000,0.00000000,0.00000000,0.00000000,0.00000000,0.00000000,0.00000000
295.50000000,7.07180200,11.04120000,0.34368411,735.18546798,0.00000000,0.00000000,0.00000000,0.00000000,0.00000000,0.00000000,0.00000000,0.00000000,0.00000000,0.00000000,0.00000000
297.00000000,7.13731300,10.95590000,0.35108367,729.50571212,0.00000000,0.00000000,0.00000000,0.00000000,0.00000000,0.00000000,0.00000000,0.00000000,0.00000000,0.00000000,0.00000000
298.50000000,7.20499200,10.83870000,0.35878433,721.70187406,0.00000000,0.00000000,0.00000000,0.00000000,0.00000000,0.00000000,0.00000000,0.00000000,0.00000000,0.00000000,0.00000000
300.00000000,7.27714100,10.68080000,0.36697578,711.18800008,0.00000000,0.00000000,0.00000000,0.00000000,0.00000000,0.00000000,0.00000000,0.00000000,0.00000000,0.00000000,0.00000000
300.50000000,7.30426100,10.60180000,0.37005844,705.92773380,0.00000000,0.00000000,0.00000000,0.00000000,0.00000000,0.00000000,0.00000000,0.00000000,0.00000000,0.00000000,0.00000000