File: polyN_optimization/DP780_results/DATA/UT_15_1.csv
Time[s],Displacement[mm],Force[kN],EngStrain_longi,EngStress[MPa],TrueStrain,TrueStress[MPa],TrueStrainRate[1/s],PlasticStrain_longi,PlasticStress[MPa],PlasticStrain_thick,PlasticStrain_width,R-Value,Thickness[mm],Width[mm], Young's Modulus [MPa]
0.00000000,0.00000000,-0.02060000,0.00000000,-1.36873186,0.00000000,-1.36873186,0.00000000,0.00058552,398.82559605,0.00000218,-0.00058770,0.80054807,1.50750000,9.98370000,215240.87023015
1.50000000,0.00205800,0.28730000,0.00007478,19.08915845,0.00007477,19.09058589,0.00007488,0.00064977,411.30562806,0.00018110,-0.00083087,0.00000000,0.00000000,0.00000000,0.00000000
3.00000000,0.00384400,0.62220000,0.00012578,41.34101770,0.00012577,41.34621748,0.00002178,0.00085582,423.16124121,-0.00004278,-0.00081304,0.00000000,0.00000000,0.00000000,0.00000000
4.50000000,0.00641300,0.97470000,0.00019422,64.76227893,0.00019420,64.77485721,0.00000600,0.00113720,435.74389636,-0.00024888,-0.00088832,0.00000000,0.00000000,0.00000000,0.00000000
6.00000000,0.00910900,1.28250000,0.00029044,85.21352491,0.00029040,85.23827471,0.00009020,0.00135858,447.34597381,-0.00015751,-0.00120107,0.00000000,0.00000000,0.00000000,0.00000000
7.50000000,0.01109300,1.56160000,0.00036678,103.75784834,0.00036671,103.79590442,0.00012396,0.00163388,458.71856638,-0.00039306,-0.00124082,0.00000000,0.00000000,0.00000000,0.00000000
9.00000000,0.01278400,1.85590000,0.00044089,123.31210985,0.00044079,123.36647679,0.00009618,0.00198251,470.44747874,-0.00068843,-0.00129409,0.00000000,0.00000000,0.00000000,0.00000000
10.50000000,0.01462600,2.11830000,0.00050222,140.74683027,0.00050210,140.81751645,0.00008329,0.00227177,481.09341032,-0.00073535,-0.00153642,0.00000000,0.00000000,0.00000000,0.00000000
12.00000000,0.01664900,2.36550000,0.00054489,157.17161261,0.00054474,157.25725368,-0.00004864,0.00264348,490.88361014,-0.00077700,-0.00186648,0.00000000,0.00000000,0.00000000,0.00000000
13.50000000,0.01918800,2.62310000,0.00063278,174.28740522,0.00063258,174.39769042,-0.00010193,0.00312247,501.63987900,-0.00106113,-0.00206134,0.00000000,0.00000000,0.00000000,0.00000000
15.00000000,0.02196400,2.86070000,0.00072922,190.07433194,0.00072896,190.21293837,-0.00001532,0.00371630,510.97196587,-0.00146170,-0.00225460,0.00000000,0.00000000,0.00000000,0.00000000
16.50000000,0.02447800,3.08960000,0.00088111,205.28320200,0.00088072,205.46407931,0.00026845,0.00422801,520.26625696,-0.00175307,-0.00247494,0.00000000,0.00000000,0.00000000,0.00000000
18.00000000,0.02641700,3.33840000,0.00092756,221.81429362,0.00092713,222.02003870,0.00022980,0.00473806,529.84496677,-0.00199798,-0.00274007,0.00000000,0.00000000,0.00000000,0.00000000
19.50000000,0.02821300,3.56490000,0.00093044,236.86369977,0.00093001,237.08408828,0.00003774,0.00537571,538.37516198,-0.00234907,-0.00302664,0.00000000,0.00000000,0.00000000,0.00000000
21.00000000,0.03076300,3.78580000,0.00099500,251.54102348,0.00099451,251.79130680,-0.00006682,0.00604815,546.51246263,-0.00272447,-0.00332368,0.00000000,0.00000000,0.00000000,0.00000000
22.50000000,0.03348600,4.01630000,0.00108967,266.85620281,0.00108907,267.14698712,-0.00022485,0.00665587,554.88735399,-0.00297658,-0.00367929,0.00000000,0.00000000,0.00000000,0.00000000
24.00000000,0.03627700,4.22680000,0.00130422,280.84251625,0.00130337,281.20879730,0.00012806,0.00723313,562.50209144,-0.00329281,-0.00394033,0.00000000,0.00000000,0.00000000,0.00000000
25.50000000,0.03919900,4.43730000,0.00140233,294.82882970,0.00140135,295.24227799,0.00029317,0.00796238,570.16574785,-0.00371434,-0.00424805,0.00000000,0.00000000,0.00000000,0.00000000
27.00000000,0.04263000,4.66060000,0.00139933,309.66561731,0.00139836,310.09894273,0.00014314,0.00871327,577.79946762,-0.00415434,-0.00455893,0.00000000,0.00000000,0.00000000,0.00000000
28.50000000,0.04673400,4.85600000,0.00147100,322.64863701,0.00146992,323.12325316,-0.00013491,0.00938745,585.06937688,-0.00452114,-0.00486630,0.00000000,0.00000000,0.00000000,0.00000000
30.00000000,0.04989400,5.05380000,0.00169689,335.79112062,0.00169545,336.36092084,-0.00002196,0.01010607,592.27449055,-0.00488626,-0.00521981,0.00000000,0.00000000,0.00000000,0.00000000
31.50000000,0.05285300,5.26670000,0.00190389,349.93689797,0.00190208,350.60313894,0.00030766,0.01093493,599.50238754,-0.00535671,-0.00557823,0.00000000,0.00000000,0.00000000,0.00000000
33.00000000,0.05813400,5.46370000,0.00195700,363.02622695,0.00195509,363.73666927,0.00026284,0.01170737,606.00483257,-0.00581207,-0.00589531,0.00000000,0.00000000,0.00000000,0.00000000
34.50000000,0.06379800,5.65030000,0.00203244,375.42454566,0.00203038,376.18757519,-0.00011975,0.01247898,612.57099405,-0.00623424,-0.00624474,0.00000000,0.00000000,0.00000000,0.00000000
36.00000000,0.06891300,5.85600000,0.00230711,389.09193129,0.00230445,389.98960961,-0.00005188,0.01328215,619.32949662,-0.00666315,-0.00661899,0.00000000,0.00000000,0.00000000,0.00000000
37.50000000,0.07558100,6.04660000,0.00258922,401.75602318,0.00258588,402.79625880,0.00020238,0.01412825,625.48183809,-0.00708493,-0.00704331,0.00000000,0.00000000,0.00000000,0.00000000
39.00000000,0.08208600,6.22530000,0.00276567,413.62943987,0.00276185,414.77340102,0.00030695,0.01499313,631.37821236,-0.00754086,-0.00745228,0.00000000,0.00000000,0.00000000,0.00000000
40.50000000,0.08895600,6.41670000,0.00290144,426.34668639,0.00289724,427.58370762,0.00005274,0.01581475,637.69843651,-0.00795865,-0.00785610,0.00000000,0.00000000,0.00000000,0.00000000
42.00000000,0.09792100,6.59130000,0.00324733,437.94768557,0.00324207,439.36984769,0.00005981,0.01668323,643.29113955,-0.00843657,-0.00824667,0.00000000,0.00000000,0.00000000,0.00000000
43.50000000,0.10729100,6.75880000,0.00362256,449.07693736,0.00361601,450.70374352,0.00025443,0.01753988,648.89247801,-0.00889038,-0.00864950,0.00000000,0.00000000,0.00000000,0.00000000
45.00000000,0.11746800,6.93820000,0.00391944,460.99686436,0.00391178,462.80371596,0.00018705,0.01843160,654.68290930,-0.00940485,-0.00902675,0.00000000,0.00000000,0.00000000,0.00000000
46.50000000,0.13024700,7.09770000,0.00433678,471.59456980,0.00432740,473.63977065,0.00020933,0.01933313,659.78784343,-0.00993575,-0.00939739,0.00000000,0.00000000,0.00000000,0.00000000
48.00000000,0.14248500,7.25320000,0.00485833,481.92650206,0.00484657,484.26786164,0.00056777,0.02023428,664.79227728,-0.01042431,-0.00980998,0.00000000,0.00000000,0.00000000,0.00000000
49.50000000,0.15694900,7.41030000,0.00527500,492.36474359,0.00526114,494.96196761,0.00056023,0.02118360,670.27492166,-0.01100345,-0.01018015,0.00000000,0.00000000,0.00000000,0.00000000
51.00000000,0.17293400,7.55150000,0.00571422,501.74653674,0.00569796,504.61362795,0.00037346,0.02210172,675.14489794,-0.01153780,-0.01056393,0.00000000,0.00000000,0.00000000,0.00000000
52.50000000,0.18935800,7.68780000,0.00625111,510.80275775,0.00623165,513.99584254,0.00016431,0.02303041,679.97593544,-0.01205270,-0.01097771,0.00000000,0.00000000,0.00000000,0.00000000
54.00000000,0.20767500,7.82580000,0.00692322,519.97193236,0.00689937,523.57181360,0.00038780,0.02401201,685.01635588,-0.01263222,-0.01137979,0.00000000,0.00000000,0.00000000,0.00000000
55.50000000,0.22626200,7.94940000,0.00752033,528.18432353,0.00749220,532.15644571,0.00046213,0.02495882,689.43874163,-0.01319335,-0.01176547,0.00000000,0.00000000,0.00000000,0.00000000
57.00000000,0.24718200,8.07060000,0.00811744,536.23725080,0.00808468,540.59012689,0.00029055,0.02593336,694.00507190,-0.01371031,-0.01222305,0.00000000,0.00000000,0.00000000,0.00000000
58.50000000,0.26708900,8.19740000,0.00885722,544.66226051,0.00881823,549.48645519,0.00033528,0.02691004,698.68441275,-0.01425606,-0.01265398,0.00000000,0.00000000,0.00000000,0.00000000
60.00000000,0.28878600,8.30990000,0.00960433,552.13713112,0.00955850,557.44004017,0.00052062,0.02791794,702.67913395,-0.01481507,-0.01310287,0.00000000,0.00000000,0.00000000,0.00000000
61.50000000,0.30936700,8.41750000,0.01031767,559.28642958,0.01026480,565.05696054,0.00070617,0.02889812,706.94399021,-0.01532861,-0.01356951,0.00000000,0.00000000,0.00000000,0.00000000
63.00000000,0.33180900,8.53240000,0.01098622,566.92076410,0.01092631,573.14908159,0.00049771,0.02990761,711.72700262,-0.01585021,-0.01405740,0.00000000,0.00000000,0.00000000,0.00000000
64.50000000,0.35448700,8.63200000,0.01180100,573.53851621,0.01173191,580.30684424,0.00053443,0.03092487,716.91115187,-0.01638295,-0.01454192,0.00000000,0.00000000,0.00000000,0.00000000
66.00000000,0.37872100,8.73410000,0.01260089,580.32237655,0.01252216,587.63495434,0.00069734,0.03195392,719.41313856,-0.01691459,-0.01503932,0.00000000,0.00000000,0.00000000,0.00000000
67.50000000,0.40207500,8.83220000,0.01333689,586.84046372,0.01324874,594.66708978,0.00064462,0.03297118,723.39765899,-0.01746378,-0.01550740,0.00000000,0.00000000,0.00000000,0.00000000
69.00000000,0.42684800,8.92950000,0.01411056,593.30539625,0.01401193,601.67726501,0.00044445,0.03403234,727.04101714,-0.01805072,-0.01598162,0.00000000,0.00000000,0.00000000,0.00000000
70.50000000,0.45060900,9.01800000,0.01498933,599.18562780,0.01487810,608.16702090,0.00056998,0.03505871,730.94309368,-0.01862303,-0.01643568,0.00000000,0.00000000,0.00000000,0.00000000
72.00000000,0.47666900,9.11210000,0.01586044,605.43794179,0.01573598,615.04045663,0.00068000,0.03614629,734.61326872,-0.01925068,-0.01689561,0.00000000,0.00000000,0.00000000,0.00000000
73.50000000,0.50198500,9.19590000,0.01664167,611.00588985,0.01650471,621.17404620,0.00054675,0.03721457,738.33889811,-0.01984668,-0.01736789,0.00000000,0.00000000,0.00000000,0.00000000
75.00000000,0.52909100,9.27720000,0.01751678,616.40772967,0.01736513,627.20520690,0.00051679,0.03826968,741.56139449,-0.02046649,-0.01780319,0.00000000,0.00000000,0.00000000,0.00000000
76.50000000,0.55511600,9.36410000,0.01841811,622.18165195,0.01825055,633.64106274,0.00050171,0.03935332,745.30546413,-0.02107211,-0.01828121,0.00000000,0.00000000,0.00000000,0.00000000
78.00000000,0.58239200,9.43910000,0.01934556,627.16489902,0.01916081,639.29775241,0.00061879,0.04041873,748.10951716,-0.02168286,-0.01873587,0.00000000,0.00000000,0.00000000,0.00000000
79.50000000,0.60977100,9.51010000,0.02021700,631.88237291,0.02001535,644.65713884,0.00053765,0.04148758,751.46545348,-0.02226055,-0.01922704,0.00000000,0.00000000,0.00000000,0.00000000
81.00000000,0.63725000,9.58900000,0.02114078,637.12474883,0.02092041,650.59406156,0.00058113,0.04262946,755.05773489,-0.02290001,-0.01972945,0.00000000,0.00000000,0.00000000,0.00000000
82.50000000,0.66540400,9.66080000,0.02209856,641.89537736,0.02185792,656.08033802,0.00061756,0.04369558,758.43188983,-0.02347563,-0.02021995,0.00000000,0.00000000,0.00000000,0.00000000
84.00000000,0.69399800,9.72940000,0.02305611,646.45338735,0.02279434,661.35808847,0.00063871,0.04482429,761.24438199,-0.02410529,-0.02071900,0.00000000,0.00000000,0.00000000,0.00000000
85.50000000,0.72296500,9.79950000,0.02398011,651.11106228,0.02369710,666.72477789,0.00059428,0.04594532,764.61705681,-0.02468727,-0.02125805,0.00000000,0.00000000,0.00000000,0.00000000
87.00000000,0.75189700,9.86730000,0.02497533,655.61591763,0.02466855,671.99014371,0.00058633,0.04707737,767.66817688,-0.02529746,-0.02177990,0.00000000,0.00000000,0.00000000,0.00000000
88.50000000,0.78157400,9.92950000,0.02598556,659.74869053,0.02565367,676.89262678,0.00067394,0.04816066,770.18190023,-0.02588129,-0.02227937,0.00000000,0.00000000,0.00000000,0.00000000
90.00000000,0.81131800,9.99650000,0.02695456,664.20039125,0.02659768,682.10361759,0.00065858,0.04931668,773.65671630,-0.02654852,-0.02276816,0.00000000,0.00000000,0.00000000,0.00000000
91.50000000,0.84136500,10.04840000,0.02795733,667.64879822,0.02757366,686.31447822,0.00059934,0.05047067,776.51753078,-0.02719815,-0.02327253,0.00000000,0.00000000,0.00000000,0.00000000
93.00000000,0.87185300,10.10820000,0.02899000,671.62210722,0.02857774,691.09243211,0.00067175,0.05161739,779.09636683,-0.02782548,-0.02379191,0.00000000,0.00000000,0.00000000,0.00000000
94.50000000,0.90288100,10.16640000,0.03002656,675.48910695,0.02958458,695.77171814,0.00069287,0.05274763,781.90009298,-0.02845895,-0.02428867,0.00000000,0.00000000,0.00000000,0.00000000
96.00000000,0.93407800,10.21980000,0.03104811,679.03717886,0.03057587,700.12000064,0.00067753,0.05392405,784.39942754,-0.02911307,-0.02481099,0.00000000,0.00000000,0.00000000,0.00000000
97.50000000,0.96540900,10.26690000,0.03208467,682.16665802,0.03158071,704.05374785,0.00063334,0.05508211,787.51157606,-0.02976173,-0.02532038,0.00000000,0.00000000,0.00000000,0.00000000
99.00000000,0.99687700,10.32270000,0.03316989,685.87419384,0.03263164,708.62456464,0.00073423,0.05624871,790.01354203,-0.03040959,-0.02583912,0.00000000,0.00000000,0.00000000,0.00000000
100.50000000,1.02922500,10.37290000,0.03422533,689.20964721,0.03365268,712.79807713,0.00071177,0.05741310,792.68874004,-0.03104904,-0.02636406,0.00000000,0.00000000,0.00000000,0.00000000
102.00000000,1.06086200,10.42160000,0.03525433,692.44543565,0.03464713,716.85713785,0.00061680,0.05860891,795.11738926,-0.03171368,-0.02689523,0.00000000,0.00000000,0.00000000,0.00000000
103.50000000,1.09341200,10.46780000,0.03635478,695.51511584,0.03570953,720.80041332,0.00065969,0.05979797,797.93627836,-0.03239184,-0.02740612,0.00000000,0.00000000,0.00000000,0.00000000
105.00000000,1.12646700,10.50930000,0.03744756,698.27251255,0.03676342,724.42111126,0.00069499,0.06099504,800.25489297,-0.03307979,-0.02791525,0.00000000,0.00000000,0.00000000,0.00000000
106.50000000,1.15928700,10.55550000,0.03857056,701.34219275,0.03784530,728.39335076,0.00070173,0.06218837,803.03094900,-0.03374848,-0.02843989,0.00000000,0.00000000,0.00000000,0.00000000
108.00000000,1.19298500,10.60260000,0.03967100,704.47167191,0.03890432,732.41876761,0.00072985,0.06337354,805.01412418,-0.03439683,-0.02897671,0.00000000,0.00000000,0.00000000,0.00000000
109.50000000,1.22702100,10.64090000,0.04079767,707.01645008,0.03998741,735.86107154,0.00068592,0.06458611,807.58736256,-0.03507371,-0.02951241,0.00000000,0.00000000,0.00000000,0.00000000
111.00000000,1.25984200,10.67760000,0.04190933,709.45491898,0.04105493,739.18770167,0.00064891,0.06579866,809.82959025,-0.03573639,-0.03006228,0.00000000,0.00000000,0.00000000,0.00000000
112.50000000,1.29408100,10.71980000,0.04304344,712.25882600,0.04214283,742.91689921,0.00068380,0.06698190,812.04505588,-0.03640416,-0.03057774,0.00000000,0.00000000,0.00000000,0.00000000
114.00000000,1.32805000,10.75330000,0.04419656,714.48467636,0.04324774,746.06243805,0.00069071,0.06818419,814.34477237,-0.03707397,-0.03111022,0.00000000,0.00000000,0.00000000,0.00000000
115.50000000,1.36242400,10.79080000,0.04532689,716.97629989,0.04432965,749.47460497,0.00069698,0.06944574,816.40318662,-0.03779151,-0.03165424,0.00000000,0.00000000,0.00000000,0.00000000
117.00000000,1.39750800,10.82750000,0.04648367,719.41476879,0.04543566,752.85580510,0.00073933,0.07064555,818.59446222,-0.03841249,-0.03223306,0.00000000,0.00000000,0.00000000,0.00000000
118.50000000,1.43205000,10.86420000,0.04764411,721.85323769,0.04654394,756.24529356,0.00063793,0.07186108,820.85319106,-0.03909746,-0.03276362,0.00000000,0.00000000,0.00000000,0.00000000
120.00000000,1.46733700,10.89370000,0.04885711,723.81331487,0.04770111,759.17674242,0.00078789,0.07309025,822.84655354,-0.03977391,-0.03331635,0.00000000,0.00000000,0.00000000,0.00000000
121.50000000,1.50333400,10.92800000,0.05004767,726.09231987,0.04883556,762.43154626,0.00077260,0.07437439,824.65106133,-0.04052038,-0.03385400,0.00000000,0.00000000,0.00000000,0.00000000
123.00000000,1.53814600,10.95750000,0.05120822,728.05239705,0.04994019,765.33466599,0.00070767,0.07560892,827.06055966,-0.04119665,-0.03441227,0.00000000,0.00000000,0.00000000,0.00000000
124.50000000,1.57441400,10.98940000,0.05242122,730.17193814,0.05109344,768.44844357,0.00072101,0.07686072,829.13480639,-0.04190090,-0.03495982,0.00000000,0.00000000,0.00000000,0.00000000
126.00000000,1.61034300,11.01970000,0.05362678,732.18516995,0.05223829,771.44990135,0.00082019,0.07808709,831.14108480,-0.04256043,-0.03552666,0.00000000,0.00000000,0.00000000,0.00000000
127.50000000,1.64721700,11.04600000,0.05485867,733.93262859,0.05340679,774.19519402,0.00081207,0.07939482,833.15386576,-0.04332636,-0.03606845,0.00000000,0.00000000,0.00000000,0.00000000
129.00000000,1.68358600,11.07390000,0.05606044,735.78639650,0.05454542,777.03490891,0.00075410,0.08062138,835.16780556,-0.04396952,-0.03665185,0.00000000,0.00000000,0.00000000,0.00000000
130.50000000,1.72025800,11.10660000,0.05731844,737.95909223,0.05573593,780.25775946,0.00081712,0.08189592,836.93503324,-0.04468607,-0.03720985,0.00000000,0.00000000,0.00000000,0.00000000
132.00000000,1.75723700,11.12890000,0.05854656,739.44077769,0.05689679,782.73248826,0.00085166,0.08314190,838.55765960,-0.04541062,-0.03773129,0.00000000,0.00000000,0.00000000,0.00000000
133.50000000,1.79434900,11.15530000,0.05975956,741.19488066,0.05804205,785.48835731,0.00076552,0.08439684,840.89749722,-0.04609990,-0.03829694,0.00000000,0.00000000,0.00000000,0.00000000
135.00000000,1.83196800,11.18320000,0.06101411,743.04864857,0.05922516,788.38510137,0.00078599,0.08571341,842.88546433,-0.04684606,-0.03886734,0.00000000,0.00000000,0.00000000,0.00000000
136.50000000,1.86864100,11.20470000,0.06227222,744.47717939,0.06041022,790.83742775,0.00079908,0.08700727,844.26612240,-0.04756474,-0.03944254,0.00000000,0.00000000,0.00000000,0.00000000
138.00000000,1.90676700,11.22780000,0.06354167,746.01201949,0.06160453,793.41486656,0.00083345,0.08825844,846.32237271,-0.04822155,-0.04003689,0.00000000,0.00000000,0.00000000,0.00000000
139.50000000,1.94486000,11.25410000,0.06481089,747.75947813,0.06279721,796.22243458,0.00080406,0.08959438,848.22025795,-0.04897540,-0.04061898,0.00000000,0.00000000,0.00000000,0.00000000
141.00000000,1.98281600,11.27330000,0.06609167,749.03518938,0.06399931,798.54017344,0.00080330,0.09092225,849.99013522,-0.04972055,-0.04120170,0.00000000,0.00000000,0.00000000,0.00000000
142.50000000,2.02087600,11.29560000,0.06737989,750.51687484,0.06520694,801.08661848,0.00080233,0.09222485,851.69021472,-0.05045669,-0.04176816,0.00000000,0.00000000,0.00000000,0.00000000
144.00000000,2.05930600,11.31550000,0.06868689,751.83909640,0.06643069,803.48058488,0.00083672,0.09347620,853.76126617,-0.05115292,-0.04232328,0.00000000,0.00000000,0.00000000,0.00000000
145.50000000,2.09787100,11.33790000,0.06997500,753.32742619,0.06763528,806.04151284,0.00085669,0.09483473,855.16234663,-0.05192511,-0.04290962,0.00000000,0.00000000,0.00000000,0.00000000
147.00000000,2.13650400,11.35140000,0.07127067,754.22441067,0.06884548,807.97848723,0.00082743,0.09613467,857.03887887,-0.05267331,-0.04346136,0.00000000,0.00000000,0.00000000,0.00000000
148.50000000,2.17483300,11.37140000,0.07257011,755.55327655,0.07005774,810.38386178,0.00080550,0.09747851,858.60965991,-0.05341422,-0.04406429,0.00000000,0.00000000,0.00000000,0.00000000
150.00000000,2.21424500,11.38810000,0.07388089,756.66287957,0.07127909,812.56580570,0.00086062,0.09877321,860.14068094,-0.05413417,-0.04463903,0.00000000,0.00000000,0.00000000,0.00000000
151.50000000,2.25335200,11.40570000,0.07519533,757.83228154,0.07250235,814.81773257,0.00088065,0.10015226,862.10266630,-0.05493213,-0.04522013,0.00000000,0.00000000,0.00000000,0.00000000
153.00000000,2.29293200,11.42320000,0.07652111,758.99503919,0.07373465,817.07418292,0.00080254,0.10147092,863.53411168,-0.05563809,-0.04583283,0.00000000,0.00000000,0.00000000,0.00000000
154.50000000,2.33224200,11.43990000,0.07785811,760.10464221,0.07497584,819.28495390,0.00086445,0.10282010,865.29876180,-0.05638888,-0.04643122,0.00000000,0.00000000,0.00000000,0.00000000
156.00000000,2.37219400,11.45510000,0.07918767,761.11458028,0.07620860,821.38546796,0.00087740,0.10421259,867.46124528,-0.05719800,-0.04701459,0.00000000,0.00000000,0.00000000,0.00000000
157.50000000,2.41214400,11.48780000,0.08049822,763.28727600,0.07742225,824.73054477,0.00082736,0.10552770,868.54797919,-0.05793205,-0.04759565,0.00000000,0.00000000,0.00000000,0.00000000
159.00000000,2.45277300,11.48300000,0.08187656,762.96834819,0.07869708,825.43756854,0.00079158,0.10688151,870.26630897,-0.05864233,-0.04823918,0.00000000,0.00000000,0.00000000,0.00000000
160.50000000,2.49323300,11.49980000,0.08325111,764.08459554,0.07996681,827.69548710,0.00083901,0.10829577,871.62254789,-0.05946352,-0.04883225,0.00000000,0.00000000,0.00000000,0.00000000
162.00000000,2.53379500,11.51490000,0.08458433,765.08788928,0.08119681,829.80233834,0.00077567,0.10964975,873.21963025,-0.06022103,-0.04942872,0.00000000,0.00000000,0.00000000,0.00000000
163.50000000,2.57432100,11.52690000,0.08595144,765.88520881,0.08245651,831.71414879,0.00082321,0.11100727,874.41081345,-0.06097051,-0.05003677,0.00000000,0.00000000,0.00000000,0.00000000
165.00000000,2.61549100,11.54280000,0.08736733,766.94165719,0.08375948,833.94730460,0.00079453,0.11245575,876.46334256,-0.06178557,-0.05067017,0.00000000,0.00000000,0.00000000,0.00000000
166.50000000,2.65659300,11.55080000,0.08873433,767.47320354,0.08501586,835.57442661,0.00083499,0.11386149,877.94172519,-0.06256429,-0.05129719,0.00000000,0.00000000,0.00000000,0.00000000
168.00000000,2.69776100,11.56600000,0.09010144,768.48314162,0.08627076,837.72458271,0.00077888,0.11522470,879.50528482,-0.06328732,-0.05193738,0.00000000,0.00000000,0.00000000,0.00000000
169.50000000,2.73923500,11.57550000,0.09152489,769.11435291,0.08757570,839.50745861,0.00088133,0.11665003,880.94575452,-0.06411679,-0.05253324,0.00000000,0.00000000,0.00000000,0.00000000
171.00000000,2.78111400,11.58910000,0.09295956,770.01798171,0.08888921,841.59851106,0.00097618,0.11810516,882.65625769,-0.06494500,-0.05316017,0.00000000,0.00000000,0.00000000,0.00000000
172.50000000,2.82329800,11.59710000,0.09431911,770.54952807,0.09013235,843.22707462,0.00081041,0.11952657,884.03034454,-0.06573684,-0.05378973,0.00000000,0.00000000,0.00000000,0.00000000
174.00000000,2.86527800,11.60740000,0.09578378,771.23389400,0.09146989,845.10558992,0.00088460,0.12101292,885.23742438,-0.06658100,-0.05443192,0.00000000,0.00000000,0.00000000,0.00000000
175.50000000,2.90732500,11.61620000,0.09720344,771.81859499,0.09276462,846.84202091,0.00095214,0.12242816,887.03416241,-0.06734226,-0.05508590,0.00000000,0.00000000,0.00000000,0.00000000
177.00000000,2.94984500,11.62660000,0.09861922,772.50960525,0.09405414,848.69390168,0.00084123,0.12387404,888.92985079,-0.06813705,-0.05573700,0.00000000,0.00000000,0.00000000,0.00000000
178.50000000,2.99209800,11.63530000,0.10003511,773.08766191,0.09534210,850.42357207,0.00074456,0.12538744,890.03883020,-0.06902039,-0.05636705,0.00000000,0.00000000,0.00000000,0.00000000
180.00000000,3.03502400,11.64650000,0.10152989,773.83182681,0.09670002,852.39888620,0.00083901,0.12686353,891.60261725,-0.06981898,-0.05704454,0.00000000,0.00000000,0.00000000,0.00000000
181.50000000,3.07808500,11.65370000,0.10296822,774.31021853,0.09800493,854.03956518,0.00092640,0.12833905,892.80288993,-0.07063700,-0.05770205,0.00000000,0.00000000,0.00000000,0.00000000
183.00000000,3.12111300,11.66240000,0.10444422,774.88827519,0.09934224,855.82087840,0.00087061,0.12987605,894.42623661,-0.07152434,-0.05835171,0.00000000,0.00000000,0.00000000,0.00000000
184.50000000,3.16458000,11.67120000,0.10594644,775.47297618,0.10070148,857.63158076,0.00097135,0.13137802,896.02095180,-0.07233073,-0.05904728,0.00000000,0.00000000,0.00000000,0.00000000
186.00000000,3.20821800,11.69670000,0.10738111,777.16728018,0.10199787,860.62036624,0.00086148,0.13294407,897.43129176,-0.07323613,-0.05970794,0.00000000,0.00000000,0.00000000,0.00000000
187.50000000,3.25151700,11.68400000,0.10888344,776.32345034,0.10335360,860.85222162,0.00096898,0.13447510,898.81224964,-0.07408523,-0.06038987,0.00000000,0.00000000,0.00000000,0.00000000
189.00000000,3.29532000,11.69120000,0.11036300,776.80184206,0.10468699,862.53202376,0.00085896,0.13600464,900.00972710,-0.07494594,-0.06105870,0.00000000,0.00000000,0.00000000,0.00000000
190.50000000,3.33926000,11.69430000,0.11187656,777.00781627,0.10604918,863.93677440,0.00093238,0.13759498,901.63292957,-0.07582690,-0.06176808,0.00000000,0.00000000,0.00000000,0.00000000
192.00000000,3.38340500,11.70630000,0.11338633,777.80513580,0.10740612,865.99760820,0.00093111,0.00000000,0.00000000,0.00000000,0.00000000,0.00000000,0.00000000,0.00000000,0.00000000
193.50000000,3.42805600,11.71030000,0.11485478,778.07090898,0.10872415,867.43607033,0.00076158,0.00000000,0.00000000,0.00000000,0.00000000,0.00000000,0.00000000,0.00000000,0.00000000
195.00000000,3.47304300,11.71910000,0.11642078,778.65560997,0.11012783,869.30730170,0.00092838,0.00000000,0.00000000,0.00000000,0.00000000,0.00000000,0.00000000,0.00000000,0.00000000
196.50000000,3.51772700,11.72150000,0.11794189,778.81507388,0.11148940,870.66999479,0.00092751,0.00000000,0.00000000,0.00000000,0.00000000,0.00000000,0.00000000,0.00000000,0.00000000
198.00000000,3.56274900,11.72460000,0.11951556,779.02104809,0.11289605,872.12618144,0.00089940,0.00000000,0.00000000,0.00000000,0.00000000,0.00000000,0.00000000,0.00000000,0.00000000
199.50000000,3.60770200,11.73100000,0.12108900,779.44628517,0.11430053,873.82865640,0.00098520,0.00000000,0.00000000,0.00000000,0.00000000,0.00000000,0.00000000,0.00000000,0.00000000
201.00000000,3.65316500,11.73020000,0.12260633,779.39313054,0.11565307,874.95166450,0.00096386,0.00000000,0.00000000,0.00000000,0.00000000,0.00000000,0.00000000,0.00000000,0.00000000
202.50000000,3.69947000,11.73820000,0.12420622,779.92467689,0.11707721,876.79617463,0.00089565,0.00000000,0.00000000,0.00000000,0.00000000,0.00000000,0.00000000,0.00000000,0.00000000
204.00000000,3.74594600,11.74140000,0.12582478,780.13729543,0.11851590,878.29789727,0.00094748,0.00000000,0.00000000,0.00000000,0.00000000,0.00000000,0.00000000,0.00000000,0.00000000
205.50000000,3.79157700,11.74780000,0.12739844,780.56253252,0.11991272,880.00498495,0.00099980,0.00000000,0.00000000,0.00000000,0.00000000,0.00000000,0.00000000,0.00000000,0.00000000
207.00000000,3.83839100,11.75020000,0.12901333,780.72199642,0.12134409,881.44554359,0.00099817,0.00000000,0.00000000,0.00000000,0.00000000,0.00000000,0.00000000,0.00000000,0.00000000
208.50000000,3.88503500,11.75420000,0.13066578,780.98776960,0.12280664,883.03614395,0.00099671,0.00000000,0.00000000,0.00000000,0.00000000,0.00000000,0.00000000,0.00000000,0.00000000
210.00000000,3.93225400,11.75500000,0.13228067,781.04092424,0.12423389,884.35753839,0.00099529,0.00000000,0.00000000,0.00000000,0.00000000,0.00000000,0.00000000,0.00000000,0.00000000
211.50000000,3.97964200,11.76290000,0.13389556,781.56582626,0.12565910,886.21401677,0.00086152,0.00000000,0.00000000,0.00000000,0.00000000,0.00000000,0.00000000,0.00000000,0.00000000
213.00000000,4.02723300,11.76290000,0.13562311,781.56582626,0.12718150,887.56421516,0.00105873,0.00000000,0.00000000,0.00000000,0.00000000,0.00000000,0.00000000,0.00000000,0.00000000
214.50000000,4.07482400,11.77010000,0.13723800,782.04421798,0.12860252,889.37040237,0.00099095,0.00000000,0.00000000,0.00000000,0.00000000,0.00000000,0.00000000,0.00000000,0.00000000
216.00000000,4.12302400,11.76450000,0.13896556,781.67213553,0.13012044,890.29763811,0.00098945,0.00000000,0.00000000,0.00000000,0.00000000,0.00000000,0.00000000,0.00000000,0.00000000
217.50000000,4.17179700,11.77250000,0.14069322,782.20368189,0.13163617,892.25443832,0.00105383,0.00000000,0.00000000,0.00000000,0.00000000,0.00000000,0.00000000,0.00000000,0.00000000
219.00000000,4.21999600,11.76850000,0.14238322,781.93790871,0.13311663,893.27274773,0.00105227,0.00000000,0.00000000,0.00000000,0.00000000,0.00000000,0.00000000,0.00000000,0.00000000
220.50000000,4.26856700,11.77410000,0.14411078,782.30999116,0.13462772,895.04929245,0.00098500,0.00000000,0.00000000,0.00000000,0.00000000,0.00000000,0.00000000,0.00000000,0.00000000
222.00000000,4.31747600,11.77570000,0.14583833,782.41630043,0.13613654,896.52258965,0.00098351,0.00000000,0.00000000,0.00000000,0.00000000,0.00000000,0.00000000,0.00000000,0.00000000
223.50000000,4.36702600,11.77250000,0.14764100,782.20368189,0.13770853,897.68901568,0.00098196,0.00000000,0.00000000,0.00000000,0.00000000,0.00000000,0.00000000,0.00000000,0.00000000
225.00000000,4.41600400,11.77490000,0.14940611,782.36314579,0.13924538,899.25298088,0.00098046,0.00000000,0.00000000,0.00000000,0.00000000,0.00000000,0.00000000,0.00000000,0.00000000
226.50000000,4.46565700,11.77650000,0.15120889,782.46945506,0.14081260,900.78579195,0.00104439,0.00000000,0.00000000,0.00000000,0.00000000,0.00000000,0.00000000,0.00000000,0.00000000
228.00000000,4.51628900,11.78290000,0.15304911,782.89469215,0.14240983,902.71602887,0.00104273,0.00000000,0.00000000,0.00000000,0.00000000,0.00000000,0.00000000,0.00000000,0.00000000
229.50000000,4.56634700,11.77410000,0.15492678,782.30999116,0.00000000,0.00000000,0.00000000,0.00000000,0.00000000,0.00000000,0.00000000,0.00000000,0.00000000,0.00000000,0.00000000
231.00000000,4.61708200,11.77650000,0.15676711,782.46945506,0.00000000,0.00000000,0.00000000,0.00000000,0.00000000,0.00000000,0.00000000,0.00000000,0.00000000,0.00000000,0.00000000
232.50000000,4.66757900,11.77890000,0.15864489,782.62891897,0.00000000,0.00000000,0.00000000,0.00000000,0.00000000,0.00000000,0.00000000,0.00000000,0.00000000,0.00000000,0.00000000
234.00000000,4.71871900,11.77650000,0.16056011,782.46945506,0.00000000,0.00000000,0.00000000,0.00000000,0.00000000,0.00000000,0.00000000,0.00000000,0.00000000,0.00000000,0.00000000
235.50000000,4.77050100,11.77010000,0.16251311,782.04421798,0.00000000,0.00000000,0.00000000,0.00000000,0.00000000,0.00000000,0.00000000,0.00000000,0.00000000,0.00000000,0.00000000
237.00000000,4.82208000,11.77410000,0.16446589,782.30999116,0.00000000,0.00000000,0.00000000,0.00000000,0.00000000,0.00000000,0.00000000,0.00000000,0.00000000,0.00000000,0.00000000
238.50000000,4.87386200,11.77250000,0.16645656,782.20368189,0.00000000,0.00000000,0.00000000,0.00000000,0.00000000,0.00000000,0.00000000,0.00000000,0.00000000,0.00000000,0.00000000
240.00000000,4.92628800,11.77410000,0.16852200,782.30999116,0.00000000,0.00000000,0.00000000,0.00000000,0.00000000,0.00000000,0.00000000,0.00000000,0.00000000,0.00000000,0.00000000
241.50000000,4.97817000,11.77170000,0.17055000,782.15052725,0.00000000,0.00000000,0.00000000,0.00000000,0.00000000,0.00000000,0.00000000,0.00000000,0.00000000,0.00000000,0.00000000
243.00000000,5.03110100,11.76610000,0.17272811,781.77844480,0.00000000,0.00000000,0.00000000,0.00000000,0.00000000,0.00000000,0.00000000,0.00000000,0.00000000,0.00000000,0.00000000
244.50000000,5.08453900,11.76530000,0.17483133,781.72529017,0.00000000,0.00000000,0.00000000,0.00000000,0.00000000,0.00000000,0.00000000,0.00000000,0.00000000,0.00000000,0.00000000
246.00000000,5.13750500,11.76610000,0.17697200,781.77844480,0.00000000,0.00000000,0.00000000,0.00000000,0.00000000,0.00000000,0.00000000,0.00000000,0.00000000,0.00000000,0.00000000
247.50000000,5.19155100,11.75970000,0.17922533,781.35320772,0.00000000,0.00000000,0.00000000,0.00000000,0.00000000,0.00000000,0.00000000,0.00000000,0.00000000,0.00000000,0.00000000
249.00000000,5.24644300,11.76690000,0.18155378,781.83159944,0.00000000,0.00000000,0.00000000,0.00000000,0.00000000,0.00000000,0.00000000,0.00000000,0.00000000,0.00000000,0.00000000
250.50000000,5.30038800,11.75730000,0.18388211,781.19374381,0.00000000,0.00000000,0.00000000,0.00000000,0.00000000,0.00000000,0.00000000,0.00000000,0.00000000,0.00000000,0.00000000
252.00000000,5.35494200,11.75260000,0.18621056,780.88146033,0.00000000,0.00000000,0.00000000,0.00000000,0.00000000,0.00000000,0.00000000,0.00000000,0.00000000,0.00000000,0.00000000
253.50000000,5.40969900,11.75020000,0.18865178,780.72199642,0.00000000,0.00000000,0.00000000,0.00000000,0.00000000,0.00000000,0.00000000,0.00000000,0.00000000,0.00000000,0.00000000
255.00000000,5.46550300,11.74540000,0.19120556,780.40306861,0.00000000,0.00000000,0.00000000,0.00000000,0.00000000,0.00000000,0.00000000,0.00000000,0.00000000,0.00000000,0.00000000
256.50000000,5.52117300,11.74380000,0.19375922,780.29675934,0.00000000,0.00000000,0.00000000,0.00000000,0.00000000,0.00000000,0.00000000,0.00000000,0.00000000,0.00000000,0.00000000
258.00000000,5.57701100,11.73980000,0.19646322,780.03098616,0.00000000,0.00000000,0.00000000,0.00000000,0.00000000,0.00000000,0.00000000,0.00000000,0.00000000,0.00000000,0.00000000
259.50000000,5.63349300,11.73100000,0.19912978,779.44628517,0.00000000,0.00000000,0.00000000,0.00000000,0.00000000,0.00000000,0.00000000,0.00000000,0.00000000,0.00000000,0.00000000
261.00000000,5.69010800,11.72860000,0.20198400,779.28682127,0.00000000,0.00000000,0.00000000,0.00000000,0.00000000,0.00000000,0.00000000,0.00000000,0.00000000,0.00000000,0.00000000
262.50000000,5.74628400,11.72230000,0.20487578,778.86822851,0.00000000,0.00000000,0.00000000,0.00000000,0.00000000,0.00000000,0.00000000,0.00000000,0.00000000,0.00000000,0.00000000
264.00000000,5.80371100,11.71910000,0.20795533,778.65560997,0.00000000,0.00000000,0.00000000,0.00000000,0.00000000,0.00000000,0.00000000,0.00000000,0.00000000,0.00000000,0.00000000
265.50000000,5.86130700,11.71430000,0.21107244,778.33668216,0.00000000,0.00000000,0.00000000,0.00000000,0.00000000,0.00000000,0.00000000,0.00000000,0.00000000,0.00000000,0.00000000
267.00000000,5.91870000,11.71030000,0.21437744,778.07090898,0.00000000,0.00000000,0.00000000,0.00000000,0.00000000,0.00000000,0.00000000,0.00000000,0.00000000,0.00000000,0.00000000
268.50000000,5.97700500,11.70070000,0.21783256,777.43305336,0.00000000,0.00000000,0.00000000,0.00000000,0.00000000,0.00000000,0.00000000,0.00000000,0.00000000,0.00000000,0.00000000
270.00000000,6.03504100,11.69510000,0.22140044,777.06097091,0.00000000,0.00000000,0.00000000,0.00000000,0.00000000,0.00000000,0.00000000,0.00000000,0.00000000,0.00000000,0.00000000
271.50000000,6.09338100,11.68000000,0.22511844,776.05767716,0.00000000,0.00000000,0.00000000,0.00000000,0.00000000,0.00000000,0.00000000,0.00000000,0.00000000,0.00000000,0.00000000
273.00000000,6.15215900,11.68000000,0.22906178,776.05767716,0.00000000,0.00000000,0.00000000,0.00000000,0.00000000,0.00000000,0.00000000,0.00000000,0.00000000,0.00000000,0.00000000
274.50000000,6.21110700,11.66240000,0.23319300,774.88827519,0.00000000,0.00000000,0.00000000,0.00000000,0.00000000,0.00000000,0.00000000,0.00000000,0.00000000,0.00000000,0.00000000
276.00000000,6.27002200,11.65370000,0.23747433,774.31021853,0.00000000,0.00000000,0.00000000,0.00000000,0.00000000,0.00000000,0.00000000,0.00000000,0.00000000,0.00000000,0.00000000
277.50000000,6.32927400,11.64490000,0.24201878,773.72551754,0.00000000,0.00000000,0.00000000,0.00000000,0.00000000,0.00000000,0.00000000,0.00000000,0.00000000,0.00000000,0.00000000
279.00000000,6.38957500,11.63210000,0.24678833,772.87504337,0.00000000,0.00000000,0.00000000,0.00000000,0.00000000,0.00000000,0.00000000,0.00000000,0.00000000,0.00000000,0.00000000
280.50000000,6.44950300,11.61380000,0.25189600,771.65913108,0.00000000,0.00000000,0.00000000,0.00000000,0.00000000,0.00000000,0.00000000,0.00000000,0.00000000,0.00000000,0.00000000
282.00000000,6.50966700,11.60020000,0.25711622,770.75550228,0.00000000,0.00000000,0.00000000,0.00000000,0.00000000,0.00000000,0.00000000,0.00000000,0.00000000,0.00000000,0.00000000
283.50000000,6.56966200,11.58430000,0.26259944,769.69905390,0.00000000,0.00000000,0.00000000,0.00000000,0.00000000,0.00000000,0.00000000,0.00000000,0.00000000,0.00000000,0.00000000
285.00000000,6.63003000,11.56360000,0.26830800,768.32367771,0.00000000,0.00000000,0.00000000,0.00000000,0.00000000,0.00000000,0.00000000,0.00000000,0.00000000,0.00000000,0.00000000
286.50000000,6.69104000,11.54360000,0.27427944,766.99481183,0.00000000,0.00000000,0.00000000,0.00000000,0.00000000,0.00000000,0.00000000,0.00000000,0.00000000,0.00000000,0.00000000
288.00000000,6.75221800,11.51890000,0.28047633,765.35366246,0.00000000,0.00000000,0.00000000,0.00000000,0.00000000,0.00000000,0.00000000,0.00000000,0.00000000,0.00000000,0.00000000
289.50000000,6.81380300,11.49180000,0.28682333,763.55304918,0.00000000,0.00000000,0.00000000,0.00000000,0.00000000,0.00000000,0.00000000,0.00000000,0.00000000,0.00000000,0.00000000
291.00000000,6.87562300,11.46710000,0.29332056,761.91189981,0.00000000,0.00000000,0.00000000,0.00000000,0.00000000,0.00000000,0.00000000,0.00000000,0.00000000,0.00000000,0.00000000
292.50000000,6.93791800,11.43680000,0.30000556,759.89866800,0.00000000,0.00000000,0.00000000,0.00000000,0.00000000,0.00000000,0.00000000,0.00000000,0.00000000,0.00000000,0.00000000
294.00000000,7.00007700,11.39930000,0.30676578,757.40704446,0.00000000,0.00000000,0.00000000,0.00000000,0.00000000,0.00000000,0.00000000,0.00000000,0.00000000,0.00000000,0.00000000
295.50000000,7.06162700,11.36100000,0.31360100,754.86226629,0.00000000,0.00000000,0.00000000,0.00000000,0.00000000,0.00000000,0.00000000,0.00000000,0.00000000,0.00000000,0.00000000
297.00000000,7.12436100,11.32030000,0.32047389,752.15802421,0.00000000,0.00000000,0.00000000,0.00000000,0.00000000,0.00000000,0.00000000,0.00000000,0.00000000,0.00000000,0.00000000
298.50000000,7.18794000,11.27250000,0.32757211,748.98203475,0.00000000,0.00000000,0.00000000,0.00000000,0.00000000,0.00000000,0.00000000,0.00000000,0.00000000,0.00000000,0.00000000
300.00000000,7.25148500,11.22060000,0.33463278,745.53362777,0.00000000,0.00000000,0.00000000,0.00000000,0.00000000,0.00000000,0.00000000,0.00000000,0.00000000,0.00000000,0.00000000
301.50000000,7.31509800,11.16480000,0.34184367,741.82609195,0.00000000,0.00000000,0.00000000,0.00000000,0.00000000,0.00000000,0.00000000,0.00000000,0.00000000,0.00000000,0.00000000
303.00000000,7.37921800,11.09620000,0.34897944,737.26808197,0.00000000,0.00000000,0.00000000,0.00000000,0.00000000,0.00000000,0.00000000,0.00000000,0.00000000,0.00000000,0.00000000
304.50000000,7.44418200,11.01970000,0.35634056,732.18516995,0.00000000,0.00000000,0.00000000,0.00000000,0.00000000,0.00000000,0.00000000,0.00000000,0.00000000,0.00000000,0.00000000
306.00000000,7.50985400,10.92720000,0.36370122,726.03916523,0.00000000,0.00000000,0.00000000,0.00000000,0.00000000,0.00000000,0.00000000,0.00000000,0.00000000,0.00000000,0.00000000
307.50000000,7.57704100,10.82110000,0.37124933,718.98953171,0.00000000,0.00000000,0.00000000,0.00000000,0.00000000,0.00000000,0.00000000,0.00000000,0.00000000,0.00000000,0.00000000
309.00000000,7.65544500,10.64810000,0.38037411,707.49484180,0.00000000,0.00000000,0.00000000,0.00000000,0.00000000,0.00000000,0.00000000,0.00000000,0.00000000,0.00000000,0.00000000