File: polyN_optimization/DP780_results/DATA/UT_15_3.csv
Time[s],Displacement[mm],Force[kN],EngStrain_longi,EngStress[MPa],TrueStrain,TrueStress[MPa],TrueStrainRate[1/s],PlasticStrain_longi,PlasticStress[MPa],PlasticStrain_thick,PlasticStrain_width,R-Value,Thickness[mm],Width[mm], Young's Modulus [MPa]
0.00000000,0.00000000,-0.01580000,0.00000000,-1.04814995,0.00000000,-1.04814995,0.00000000,0.00052784,403.48987584,0.00011493,-0.00064277,0.80974869,1.51000000,9.98290000,216643.59155842
1.50000000,0.00217300,0.34230000,0.00008444,22.70770435,0.00008444,22.70962189,0.00011999,0.00065934,415.23201268,0.00022612,-0.00088546,0.00000000,0.00000000,0.00000000,0.00000000
3.00000000,0.00413400,0.68360000,0.00009389,45.34907009,0.00009388,45.35332786,0.00005555,0.00096007,426.79093464,-0.00013719,-0.00082288,0.00000000,0.00000000,0.00000000,0.00000000
4.50000000,0.00674400,1.01140000,0.00015444,67.09486467,0.00015443,67.10522710,-0.00009309,0.00113244,439.25535997,-0.00010057,-0.00103187,0.00000000,0.00000000,0.00000000,0.00000000
6.00000000,0.00914200,1.34630000,0.00023256,89.31166334,0.00023253,89.33243327,-0.00009153,0.00133029,450.35612948,-0.00016369,-0.00116660,0.00000000,0.00000000,0.00000000,0.00000000
7.50000000,0.01130500,1.62620000,0.00035922,107.87983876,0.00035916,107.91859160,0.00003976,0.00164904,461.13794107,-0.00049071,-0.00115833,0.00000000,0.00000000,0.00000000,0.00000000
9.00000000,0.01375000,1.89180000,0.00045822,125.49937214,0.00045812,125.55687874,0.00010751,0.00197407,472.15100263,-0.00052587,-0.00144819,0.00000000,0.00000000,0.00000000,0.00000000
10.50000000,0.01610500,2.16450000,0.00055000,143.58990961,0.00054985,143.66888406,0.00022233,0.00223112,482.49819613,-0.00054748,-0.00168364,0.00000000,0.00000000,0.00000000,0.00000000
12.00000000,0.01810400,2.41810000,0.00061667,160.41337973,0.00061648,160.51230131,0.00025830,0.00261705,492.44090943,-0.00086552,-0.00175152,0.00000000,0.00000000,0.00000000,0.00000000
13.50000000,0.01955800,2.65580000,0.00064589,176.18206603,0.00064568,176.29586007,0.00016701,0.00320560,502.86201384,-0.00132270,-0.00188289,0.00000000,0.00000000,0.00000000,0.00000000
15.00000000,0.02112100,2.90220000,0.00063878,192.52789820,0.00063857,192.65088075,0.00001377,0.00367638,512.11828099,-0.00148917,-0.00218721,0.00000000,0.00000000,0.00000000,0.00000000
16.50000000,0.02341900,3.13110000,0.00072278,207.71280479,0.00072252,207.86293499,-0.00009793,0.00411659,520.67177092,-0.00168024,-0.00243635,0.00000000,0.00000000,0.00000000,0.00000000
18.00000000,0.02636200,3.36070000,0.00082511,222.94414840,0.00082477,223.12810210,-0.00020094,0.00462270,530.27980888,-0.00192438,-0.00269831,0.00000000,0.00000000,0.00000000,0.00000000
19.50000000,0.02912300,3.60320000,0.00097200,239.03126001,0.00097153,239.26359840,0.00006794,0.00522060,538.51358441,-0.00227780,-0.00294280,0.00000000,0.00000000,0.00000000,0.00000000
21.00000000,0.03137000,3.82010000,0.00109989,253.42010334,0.00109928,253.69883730,0.00032278,0.00572896,546.70187272,-0.00254366,-0.00318530,0.00000000,0.00000000,0.00000000,0.00000000
22.50000000,0.03385200,4.03380000,0.00109678,267.59666314,0.00109618,267.89015722,0.00017293,0.00629241,554.98332978,-0.00281268,-0.00347973,0.00000000,0.00000000,0.00000000,0.00000000
24.00000000,0.03670800,4.25950000,0.00108256,282.56928619,0.00108197,282.87518315,-0.00001443,0.00704099,562.57989057,-0.00324802,-0.00379297,0.00000000,0.00000000,0.00000000,0.00000000
25.50000000,0.04007000,4.47400000,0.00118422,296.79891688,0.00118352,297.15039275,-0.00021729,0.00773452,570.68761400,-0.00360614,-0.00412838,0.00000000,0.00000000,0.00000000,0.00000000
27.00000000,0.04295700,4.67820000,0.00142867,310.34525993,0.00142765,310.78863986,-0.00002974,0.00836569,578.50842008,-0.00391814,-0.00444755,0.00000000,0.00000000,0.00000000,0.00000000
28.50000000,0.04577700,4.89190000,0.00160589,324.52181973,0.00160460,325.04296571,0.00030043,0.00903857,585.34078106,-0.00424093,-0.00479764,0.00000000,0.00000000,0.00000000,0.00000000
30.00000000,0.05011400,5.08970000,0.00164367,337.64359571,0.00164232,338.19856924,0.00033747,0.00984632,592.52537939,-0.00474815,-0.00509817,0.00000000,0.00000000,0.00000000,0.00000000
31.50000000,0.05496100,5.29060000,0.00169278,350.97102137,0.00169135,351.56513732,-0.00006744,0.01057103,599.89427180,-0.00515337,-0.00541765,0.00000000,0.00000000,0.00000000,0.00000000
33.00000000,0.05966700,5.50040000,0.00182844,364.88886061,0.00182677,365.55603962,-0.00020206,0.01125461,606.43926320,-0.00551137,-0.00574323,0.00000000,0.00000000,0.00000000,0.00000000
34.50000000,0.06406800,5.69100000,0.00215900,377.53299865,0.00215667,378.34809239,0.00006763,0.01199768,612.82055854,-0.00592673,-0.00607095,0.00000000,0.00000000,0.00000000,0.00000000
36.00000000,0.06975700,5.87440000,0.00233200,389.69949873,0.00232929,390.60827796,0.00038980,0.01284903,619.65041484,-0.00643825,-0.00641078,0.00000000,0.00000000,0.00000000,0.00000000
37.50000000,0.07550200,6.06740000,0.00245222,402.50284941,0.00244922,403.48987584,0.00023965,0.01363140,626.06971214,-0.00689172,-0.00673968,0.00000000,0.00000000,0.00000000,0.00000000
39.00000000,0.08156000,6.24280000,0.00264011,414.13864065,0.00263663,415.23201268,-0.00012722,0.01440454,631.95154726,-0.00729117,-0.00711337,0.00000000,0.00000000,0.00000000,0.00000000
40.50000000,0.09004500,6.41430000,0.00299689,425.51571134,0.00299241,426.79093464,0.00021736,0.01523898,637.99687059,-0.00780087,-0.00743811,0.00000000,0.00000000,0.00000000,0.00000000
42.00000000,0.09808300,6.60010000,0.00322933,437.84142407,0.00322413,439.25535997,0.00019449,0.01608889,643.72981684,-0.00829196,-0.00779693,0.00000000,0.00000000,0.00000000,0.00000000
43.50000000,0.10683800,6.76520000,0.00348089,448.79392768,0.00347484,450.35612948,0.00023187,0.01692141,649.08764337,-0.00872283,-0.00819858,0.00000000,0.00000000,0.00000000,0.00000000
45.00000000,0.11751300,6.92460000,0.00385233,459.36830125,0.00384493,461.13794107,0.00027651,0.01773098,655.24773985,-0.00913790,-0.00859308,0.00000000,0.00000000,0.00000000,0.00000000
46.50000000,0.12798000,7.08730000,0.00423133,470.16159222,0.00422241,472.15100263,0.00037379,0.01862059,660.66151184,-0.00959823,-0.00902236,0.00000000,0.00000000,0.00000000,0.00000000
48.00000000,0.14027700,7.24040000,0.00453900,480.31803258,0.00452873,482.49819613,0.00023163,0.01956261,665.68398494,-0.01013155,-0.00943106,0.00000000,0.00000000,0.00000000,0.00000000
49.50000000,0.15287600,7.38640000,0.00497433,490.00346885,0.00496200,492.44090943,0.00003715,0.02042702,671.42655173,-0.01060507,-0.00982195,0.00000000,0.00000000,0.00000000,0.00000000
51.00000000,0.16685700,7.53790000,0.00561589,500.05376744,0.00560018,502.86201384,0.00038057,0.02133431,676.44407317,-0.01110410,-0.01023021,0.00000000,0.00000000,0.00000000,0.00000000
52.50000000,0.18300100,7.67270000,0.00613378,508.99621134,0.00611504,512.11828099,0.00058980,0.02226180,680.88338485,-0.01160828,-0.01065352,0.00000000,0.00000000,0.00000000,0.00000000
54.00000000,0.19860800,7.79710000,0.00661778,517.24873375,0.00659598,520.67177092,0.00053696,0.02320242,686.21434151,-0.01211723,-0.01108519,0.00000000,0.00000000,0.00000000,0.00000000
55.50000000,0.21647900,7.93660000,0.00717344,526.50296908,0.00714784,530.27980888,0.00033540,0.02411965,690.88205603,-0.01262629,-0.01149336,0.00000000,0.00000000,0.00000000,0.00000000
57.00000000,0.23390900,8.05470000,0.00781533,534.33755828,0.00778495,538.51358441,0.00050677,0.02508056,695.42410306,-0.01318205,-0.01189850,0.00000000,0.00000000,0.00000000,0.00000000
58.50000000,0.25259100,8.17270000,0.00836711,542.16551362,0.00833230,546.70187272,0.00041700,0.02605122,699.98128958,-0.01372242,-0.01232879,0.00000000,0.00000000,0.00000000,0.00000000
60.00000000,0.27191600,8.29150000,0.00897522,550.04653985,0.00893518,554.98332978,0.00022312,0.02703726,704.18035373,-0.01425381,-0.01278344,0.00000000,0.00000000,0.00000000,0.00000000
61.50000000,0.29225600,8.39840000,0.00976733,557.13813668,0.00971994,562.57989057,0.00037174,0.02797715,708.67719863,-0.01477657,-0.01320058,0.00000000,0.00000000,0.00000000,0.00000000
63.00000000,0.31313700,8.51320000,0.01050689,564.75380848,0.01045208,570.68761400,0.00052742,0.02898007,712.73214514,-0.01533957,-0.01364050,0.00000000,0.00000000,0.00000000,0.00000000
64.50000000,0.33486500,8.62410000,0.01118256,572.11075973,0.01112049,578.50842008,0.00055674,0.02998475,716.96799465,-0.01588216,-0.01410260,0.00000000,0.00000000,0.00000000,0.00000000
66.00000000,0.35699900,8.71980000,0.01189611,578.45936419,0.01182591,585.34078106,0.00037117,0.03102168,721.06290095,-0.01644890,-0.01457278,0.00000000,0.00000000,0.00000000,0.00000000
67.50000000,0.37950600,8.81940000,0.01274844,585.06668920,0.01266787,592.52537939,0.00059341,0.03202158,725.09045656,-0.01698145,-0.01504013,0.00000000,0.00000000,0.00000000,0.00000000
69.00000000,0.40262100,8.92230000,0.01351822,591.89293162,0.01342767,599.89427180,0.00077084,0.03303616,728.85316282,-0.01751237,-0.01552378,0.00000000,0.00000000,0.00000000,0.00000000
70.50000000,0.42590500,9.01320000,0.01424289,597.92311077,0.01414241,606.43926320,0.00062958,0.03409290,732.66080875,-0.01807840,-0.01601450,0.00000000,0.00000000,0.00000000,0.00000000
72.00000000,0.45013600,9.10100000,0.01502767,603.74764025,0.01491587,612.82055854,0.00046616,0.03515251,736.36722419,-0.01869438,-0.01645812,0.00000000,0.00000000,0.00000000,0.00000000
73.50000000,0.47501000,9.19430000,0.01592522,609.93703206,0.01579975,619.65041484,0.00062854,0.03616382,740.14884285,-0.01923936,-0.01692446,0.00000000,0.00000000,0.00000000,0.00000000
75.00000000,0.50032200,9.28200000,0.01675144,615.75492768,0.01661269,626.06971214,0.00081277,0.03721587,744.96646322,-0.01981987,-0.01739600,0.00000000,0.00000000,0.00000000,0.00000000
76.50000000,0.52573600,9.36170000,0.01756633,621.04211447,0.01741383,631.95154726,0.00064980,0.03828302,747.15310693,-0.02042475,-0.01785827,0.00000000,0.00000000,0.00000000,0.00000000
78.00000000,0.55176000,9.44310000,0.01844511,626.44207688,0.01827706,637.99687059,0.00050912,0.03936491,750.51530333,-0.02103099,-0.01833392,0.00000000,0.00000000,0.00000000,0.00000000
79.50000000,0.57798600,9.51960000,0.01933889,631.51698013,0.01915427,643.72981684,0.00067811,0.04042770,753.86259840,-0.02161946,-0.01880824,0.00000000,0.00000000,0.00000000,0.00000000
81.00000000,0.60471900,9.59060000,0.02021389,636.22702105,0.02001230,649.08764337,0.00075118,0.04150086,757.06394935,-0.02220256,-0.01929830,0.00000000,0.00000000,0.00000000,0.00000000
82.50000000,0.63182400,9.67350000,0.02107011,641.72649137,0.02085121,655.24773985,0.00056659,0.04265003,760.60833174,-0.02288528,-0.01976475,0.00000000,0.00000000,0.00000000,0.00000000
84.00000000,0.65926800,9.74450000,0.02200522,646.43653230,0.02176660,660.66151184,0.00052931,0.04374001,763.50025471,-0.02348110,-0.02025891,0.00000000,0.00000000,0.00000000,0.00000000
85.50000000,0.68765800,9.80910000,0.02299289,650.72200615,0.02273254,665.68398494,0.00066809,0.04483882,766.57218373,-0.02408644,-0.02075238,0.00000000,0.00000000,0.00000000,0.00000000
87.00000000,0.71557600,9.88490000,0.02390556,655.75047238,0.02362429,671.42655173,0.00066054,0.04595274,769.94158143,-0.02468957,-0.02126317,0.00000000,0.00000000,0.00000000,0.00000000
88.50000000,0.74437200,9.94950000,0.02485944,660.03594624,0.02455548,676.44407317,0.00060852,0.04707812,772.87820705,-0.02530907,-0.02176905,0.00000000,0.00000000,0.00000000,0.00000000
90.00000000,0.77330400,10.00530000,0.02583211,663.73764037,0.02550410,680.88338485,0.00054922,0.04816995,775.85053744,-0.02586354,-0.02230642,0.00000000,0.00000000,0.00000000,0.00000000
91.50000000,0.80267500,10.07390000,0.02682356,668.28846865,0.02647011,686.21434151,0.00068768,0.04931814,778.70406610,-0.02650098,-0.02281716,0.00000000,0.00000000,0.00000000,0.00000000
93.00000000,0.83224900,10.13290000,0.02778867,672.20244632,0.02740957,690.88205603,0.00065761,0.05048625,781.57882562,-0.02718111,-0.02330514,0.00000000,0.00000000,0.00000000,0.00000000
94.50000000,0.86236500,10.18950000,0.02879900,675.95721133,0.02839210,695.42410306,0.00061332,0.05158240,784.34636471,-0.02774036,-0.02384205,0.00000000,0.00000000,0.00000000,0.00000000
96.00000000,0.89251400,10.24610000,0.02982044,679.71197635,0.02938446,699.98128958,0.00057624,0.05271264,787.15307504,-0.02835225,-0.02436038,0.00000000,0.00000000,0.00000000,0.00000000
97.50000000,0.92290000,10.29720000,0.03085700,683.10187905,0.03039050,704.18035373,0.00071410,0.05389563,789.77424961,-0.02904043,-0.02485519,0.00000000,0.00000000,0.00000000,0.00000000
99.00000000,0.95355600,10.35300000,0.03184844,686.80357318,0.03135180,708.67719863,0.00065524,0.05505217,792.43605010,-0.02968497,-0.02536719,0.00000000,0.00000000,0.00000000,0.00000000
100.50000000,0.98492200,10.40160000,0.03290378,690.02762937,0.03237404,712.73214514,0.00064726,0.05624159,795.35553394,-0.03037904,-0.02586254,0.00000000,0.00000000,0.00000000,0.00000000
102.00000000,1.01638900,10.45270000,0.03396289,693.41753206,0.03339888,716.96799465,0.00066121,0.05741884,797.54197536,-0.03102527,-0.02639356,0.00000000,0.00000000,0.00000000,0.00000000
103.50000000,1.04809400,10.50130000,0.03505578,696.64158824,0.03445532,721.06290095,0.00074750,0.05856982,800.49817315,-0.03166308,-0.02690674,0.00000000,0.00000000,0.00000000,0.00000000
105.00000000,1.08013600,10.54920000,0.03611111,699.81920740,0.03547439,725.09045656,0.00069610,0.05973668,802.79175740,-0.03232412,-0.02741256,0.00000000,0.00000000,0.00000000,0.00000000
106.50000000,1.11275300,10.59300000,0.03718144,702.72483828,0.03650688,728.85316282,0.00068081,0.06094081,805.12687297,-0.03298230,-0.02795851,0.00000000,0.00000000,0.00000000,0.00000000
108.00000000,1.14536900,10.63690000,0.03829689,705.63710302,0.03758176,732.66080875,0.00068008,0.06213904,807.62533605,-0.03364035,-0.02849868,0.00000000,0.00000000,0.00000000,0.00000000
109.50000000,1.17825700,10.67920000,0.03941600,708.44322600,0.03865902,736.36722419,0.00076596,0.06334688,810.02254903,-0.03434320,-0.02900368,0.00000000,0.00000000,0.00000000,0.00000000
111.00000000,1.21117900,10.72300000,0.04048644,711.34885688,0.03968834,740.14884285,0.00072928,0.06451447,812.45577388,-0.03496457,-0.02954991,0.00000000,0.00000000,0.00000000,0.00000000
112.50000000,1.24453900,10.78120000,0.04160556,715.20976366,0.04076333,744.96646322,0.00069947,0.06574059,814.82013837,-0.03563810,-0.03010249,0.00000000,0.00000000,0.00000000,0.00000000
114.00000000,1.27806900,10.80120000,0.04272856,716.53653575,0.04184089,747.15310693,0.00073496,0.06694478,817.05675820,-0.03632936,-0.03061542,0.00000000,0.00000000,0.00000000,0.00000000
115.50000000,1.31203800,10.83790000,0.04387400,718.97116254,0.04293879,750.51530333,0.00079165,0.06815122,819.24937747,-0.03694863,-0.03120259,0.00000000,0.00000000,0.00000000,0.00000000
117.00000000,1.34624400,10.87450000,0.04500067,721.39915547,0.04401752,753.86259840,0.00072613,0.06936523,821.73186824,-0.03763582,-0.03172941,0.00000000,0.00000000,0.00000000,0.00000000
118.50000000,1.38045000,10.90880000,0.04613867,723.67456961,0.04510593,757.06394935,0.00069665,0.07060099,823.72778939,-0.03832173,-0.03227926,0.00000000,0.00000000,0.00000000,0.00000000
120.00000000,1.41533200,10.94710000,0.04735922,726.21533816,0.04627197,760.60833174,0.00079623,0.07180955,825.98505037,-0.03895590,-0.03285365,0.00000000,0.00000000,0.00000000,0.00000000
121.50000000,1.45034900,10.97660000,0.04851589,728.17232700,0.04737573,763.50025471,0.00080956,0.07305524,828.16958897,-0.03966989,-0.03338534,0.00000000,0.00000000,0.00000000,0.00000000
123.00000000,1.48543300,11.00850000,0.04968400,730.28852848,0.04848917,766.57218373,0.00078028,0.07433533,830.09170550,-0.04040831,-0.03392701,0.00000000,0.00000000,0.00000000,0.00000000
124.50000000,1.52041700,11.04440000,0.05087078,732.67008439,0.04961913,769.94158143,0.00070790,0.07554809,831.96839411,-0.04102965,-0.03451845,0.00000000,0.00000000,0.00000000,0.00000000
126.00000000,1.55627900,11.07390000,0.05206878,734.62707322,0.05075849,772.87820705,0.00083557,0.07679518,834.33206969,-0.04170914,-0.03508603,0.00000000,0.00000000,0.00000000,0.00000000
127.50000000,1.59234400,11.10420000,0.05323300,736.63713294,0.05186448,775.85053744,0.00068478,0.07806863,835.92002944,-0.04241300,-0.03565563,0.00000000,0.00000000,0.00000000,0.00000000
129.00000000,1.62854400,11.13210000,0.05445733,738.48798001,0.05302626,778.70406610,0.00069094,0.07927459,838.26468349,-0.04308449,-0.03619010,0.00000000,0.00000000,0.00000000,0.00000000
130.50000000,1.66504900,11.16000000,0.05570422,740.33882708,0.05420805,781.57882562,0.00081837,0.08058749,840.29092649,-0.04385756,-0.03672993,0.00000000,0.00000000,0.00000000,0.00000000
132.00000000,1.70141800,11.18710000,0.05687600,742.13660326,0.05531739,784.34636471,0.00075352,0.08185783,842.23429428,-0.04456965,-0.03728819,0.00000000,0.00000000,0.00000000,0.00000000
133.50000000,1.73785500,11.21430000,0.05808533,743.94101330,0.05646099,787.15307504,0.00067450,0.08313382,844.06250920,-0.04525246,-0.03788135,0.00000000,0.00000000,0.00000000,0.00000000
135.00000000,1.77463000,11.23820000,0.05935100,745.52650595,0.05765646,789.77424961,0.00080842,0.08439054,846.00138611,-0.04597143,-0.03841911,0.00000000,0.00000000,0.00000000,0.00000000
136.50000000,1.81171000,11.26290000,0.06059033,747.16506949,0.05882567,792.43605010,0.00077205,0.08570510,847.70163544,-0.04670145,-0.03900365,0.00000000,0.00000000,0.00000000,0.00000000
138.00000000,1.84970200,11.29080000,0.06186733,749.01591656,0.06002899,795.35553394,0.00077133,0.08696145,849.75651672,-0.04739691,-0.03956454,0.00000000,0.00000000,0.00000000,0.00000000
139.50000000,1.88728800,11.30840000,0.06312922,750.18347600,0.06121666,797.54197536,0.00081286,0.08826488,850.92778714,-0.04811703,-0.04014785,0.00000000,0.00000000,0.00000000,0.00000000
141.00000000,1.92484100,11.33710000,0.06436856,752.08739395,0.06238172,800.49817315,0.00076241,0.08956735,853.38723324,-0.04883606,-0.04073128,0.00000000,0.00000000,0.00000000,0.00000000
142.50000000,1.96235900,11.35620000,0.06562289,753.35446129,0.06355950,802.79175740,0.00075421,0.09086760,855.20525330,-0.04951580,-0.04135181,0.00000000,0.00000000,0.00000000,0.00000000
144.00000000,2.00062200,11.37540000,0.06691867,754.62816250,0.06477474,805.12687297,0.00080289,0.09217109,856.72866378,-0.05023507,-0.04193601,0.00000000,0.00000000,0.00000000,0.00000000
145.50000000,2.03861400,11.39690000,0.06821056,756.05444250,0.06598487,807.62533605,0.00080171,0.09352147,858.77239442,-0.05101976,-0.04250171,0.00000000,0.00000000,0.00000000,0.00000000
147.00000000,2.07687600,11.41680000,0.06951378,757.37458073,0.06720413,810.02254903,0.00085706,0.09480694,860.46986456,-0.05170143,-0.04310551,0.00000000,0.00000000,0.00000000,0.00000000
148.50000000,2.11557800,11.43760000,0.07077567,758.75442371,0.06838331,812.45577388,0.00079273,0.09610537,861.94589016,-0.05241013,-0.04369524,0.00000000,0.00000000,0.00000000,0.00000000
150.00000000,2.15424600,11.45670000,0.07210144,760.02149105,0.06962069,814.82013837,0.00086889,0.09740394,863.77097381,-0.05309867,-0.04430528,0.00000000,0.00000000,0.00000000,0.00000000
151.50000000,2.19342200,11.47420000,0.07340467,761.18241663,0.07083553,817.05675820,0.00082579,0.09876570,865.48447946,-0.05389755,-0.04486815,0.00000000,0.00000000,0.00000000,0.00000000
153.00000000,2.23229300,11.49100000,0.07471167,762.29690519,0.07205241,819.24937747,0.00083182,0.10012181,867.25529833,-0.05469020,-0.04543161,0.00000000,0.00000000,0.00000000,0.00000000
154.50000000,2.27160300,11.51170000,0.07602989,763.67011431,0.07327824,821.73186824,0.00079588,0.10141420,868.55918120,-0.05534243,-0.04607177,0.00000000,0.00000000,0.00000000,0.00000000
156.00000000,2.31091300,11.52530000,0.07737067,764.57231933,0.07452350,823.72778939,0.00089270,0.10279027,870.34582518,-0.05612827,-0.04666200,0.00000000,0.00000000,0.00000000,0.00000000
157.50000000,2.35032500,11.54280000,0.07868511,765.73324491,0.07574281,825.98505037,0.00080794,0.10412051,872.16244157,-0.05686727,-0.04725324,0.00000000,0.00000000,0.00000000,0.00000000
159.00000000,2.39058200,11.55880000,0.08004089,766.79466258,0.07699890,828.16958897,0.00084850,0.10549428,873.66376243,-0.05762869,-0.04786559,0.00000000,0.00000000,0.00000000,0.00000000
160.50000000,2.43097400,11.57070000,0.08143422,767.58409198,0.07828814,830.09170550,0.00088215,0.10683537,875.25796162,-0.05840109,-0.04843428,0.00000000,0.00000000,0.00000000,0.00000000
162.00000000,2.47140000,11.58270000,0.08275622,768.38015523,0.07950985,831.96839411,0.00084637,0.10820612,876.58283519,-0.05912649,-0.04907962,0.00000000,0.00000000,0.00000000,0.00000000
163.50000000,2.51165700,11.60100000,0.08411956,769.59415169,0.08076819,834.33206969,0.00080389,0.10956608,878.37791777,-0.05987668,-0.04968941,0.00000000,0.00000000,0.00000000,0.00000000
165.00000000,2.55231900,11.60820000,0.08550922,770.07178965,0.08204921,835.92002944,0.00089973,0.11096369,879.61157260,-0.06064075,-0.05032295,0.00000000,0.00000000,0.00000000,0.00000000
166.50000000,2.59335400,11.62660000,0.08683122,771.29241997,0.08326633,838.26468349,0.00080188,0.11232706,881.28824381,-0.06140136,-0.05092570,0.00000000,0.00000000,0.00000000,0.00000000
168.00000000,2.63425300,11.63930000,0.08826956,772.13492025,0.08458887,840.29092649,0.00084208,0.11377133,883.10706431,-0.06224633,-0.05152499,0.00000000,0.00000000,0.00000000,0.00000000
169.50000000,2.67569300,11.65130000,0.08966300,772.93098350,0.08586847,842.23429428,0.00091711,0.11515309,884.33332091,-0.06297006,-0.05218304,0.00000000,0.00000000,0.00000000,0.00000000
171.00000000,2.71726800,11.66160000,0.09106378,773.61427113,0.08715316,844.06250920,0.00091573,0.11653113,885.91878312,-0.06373856,-0.05279257,0.00000000,0.00000000,0.00000000,0.00000000
172.50000000,2.75887700,11.67360000,0.09244589,774.41033439,0.08841912,846.00138611,0.00082523,0.11797877,887.14742042,-0.06459996,-0.05337881,0.00000000,0.00000000,0.00000000,0.00000000
174.00000000,2.80129700,11.68160000,0.09389178,774.94104322,0.08974178,847.70163544,0.00087901,0.11930719,888.57294061,-0.06530298,-0.05400421,0.00000000,0.00000000,0.00000000,0.00000000
175.50000000,2.84273700,11.69510000,0.09527767,775.83661439,0.09100791,849.75651672,0.00085050,0.12077428,890.42661025,-0.06616098,-0.05461330,0.00000000,0.00000000,0.00000000,0.00000000
177.00000000,2.88488700,11.69590000,0.09671233,775.88968527,0.09231692,850.92778714,0.00086317,0.12220171,891.82492391,-0.06694889,-0.05525281,0.00000000,0.00000000,0.00000000,0.00000000
178.50000000,2.92747600,11.71430000,0.09815456,777.11031559,0.09363109,853.38723324,0.00084159,0.12361753,893.15445206,-0.06773858,-0.05587895,0.00000000,0.00000000,0.00000000,0.00000000
180.00000000,2.96996300,11.72390000,0.09959289,777.74716620,0.09494001,855.20525330,0.00086758,0.12503239,894.24248120,-0.06853269,-0.05649970,0.00000000,0.00000000,0.00000000,0.00000000
181.50000000,3.01285700,11.72940000,0.10103511,778.11202852,0.09625075,856.72866378,0.00083252,0.12644265,895.87432941,-0.06930432,-0.05713833,0.00000000,0.00000000,0.00000000,0.00000000
183.00000000,3.05575000,11.74140000,0.10253367,778.90809178,0.09761086,858.77239442,0.00096770,0.12785247,897.19688662,-0.07005757,-0.05779490,0.00000000,0.00000000,0.00000000,0.00000000
184.50000000,3.09915100,11.74940000,0.10396078,779.43880061,0.09890442,860.46986456,0.00087119,0.12929341,898.44288654,-0.07090557,-0.05838784,0.00000000,0.00000000,0.00000000,0.00000000
186.00000000,3.14234800,11.75420000,0.10540289,779.75722592,0.10020987,861.94589016,0.00081556,0.13070050,899.46939776,-0.07168647,-0.05901403,0.00000000,0.00000000,0.00000000,0.00000000
187.50000000,3.18541100,11.76370000,0.10684889,780.38744266,0.10151714,863.77097381,0.00084843,0.13213546,901.12549671,-0.07248323,-0.05965223,0.00000000,0.00000000,0.00000000,0.00000000
189.00000000,3.22925100,11.77090000,0.10836622,780.86508061,0.10288706,865.48447946,0.00085409,0.00000000,0.00000000,0.00000000,0.00000000,0.00000000,0.00000000,0.00000000,0.00000000
190.50000000,3.27336100,11.77890000,0.10987967,781.39578945,0.10425160,867.25529833,0.00092724,0.00000000,0.00000000,0.00000000,0.00000000,0.00000000,0.00000000,0.00000000,0.00000000
192.00000000,3.31774100,11.78130000,0.11132189,781.55500210,0.10555020,868.55918120,0.00082481,0.00000000,0.00000000,0.00000000,0.00000000,0.00000000,0.00000000,0.00000000,0.00000000
193.50000000,3.36181800,11.78920000,0.11286167,782.07907708,0.10693478,870.34582518,0.00095852,0.00000000,0.00000000,0.00000000,0.00000000,0.00000000,0.00000000,0.00000000,0.00000000
195.00000000,3.40687400,11.79800000,0.11435267,782.66285680,0.10827367,872.16244157,0.00082237,0.00000000,0.00000000,0.00000000,0.00000000,0.00000000,0.00000000,0.00000000,0.00000000
196.50000000,3.45152500,11.80200000,0.11589256,782.92821121,0.10965458,873.66376243,0.00088877,0.00000000,0.00000000,0.00000000,0.00000000,0.00000000,0.00000000,0.00000000,0.00000000
198.00000000,3.49648100,11.80760000,0.11739856,783.29970740,0.11100327,875.25796162,0.00087405,0.00000000,0.00000000,0.00000000,0.00000000,0.00000000,0.00000000,0.00000000,0.00000000
199.50000000,3.54153700,11.80920000,0.11893833,783.40584917,0.11238032,876.58283519,0.00093324,0.00000000,0.00000000,0.00000000,0.00000000,0.00000000,0.00000000,0.00000000,0.00000000
201.00000000,3.58662800,11.81720000,0.12047067,783.93655800,0.11374884,878.37791777,0.00089189,0.00000000,0.00000000,0.00000000,0.00000000,0.00000000,0.00000000,0.00000000,0.00000000
202.50000000,3.63290100,11.81720000,0.12204433,783.93655800,0.11515232,879.61157260,0.00095087,0.00000000,0.00000000,0.00000000,0.00000000,0.00000000,0.00000000,0.00000000,0.00000000
204.00000000,3.67900600,11.82350000,0.12358411,784.35449121,0.11652368,881.28824381,0.00085598,0.00000000,0.00000000,0.00000000,0.00000000,0.00000000,0.00000000,0.00000000,0.00000000
205.50000000,3.72585400,11.83070000,0.12521778,784.83212917,0.11797660,883.10706431,0.00094799,0.00000000,0.00000000,0.00000000,0.00000000,0.00000000,0.00000000,0.00000000,0.00000000
207.00000000,3.77162000,11.83070000,0.12678022,784.83212917,0.11936420,884.33332091,0.00092024,0.00000000,0.00000000,0.00000000,0.00000000,0.00000000,0.00000000,0.00000000,0.00000000
208.50000000,3.81829900,11.83550000,0.12834256,785.15055447,0.12074979,885.91878312,0.00096546,0.00000000,0.00000000,0.00000000,0.00000000,0.00000000,0.00000000,0.00000000,0.00000000
210.00000000,3.86514800,11.83470000,0.12998378,785.09748358,0.12220328,887.14742042,0.00107051,0.00000000,0.00000000,0.00000000,0.00000000,0.00000000,0.00000000,0.00000000,0.00000000
211.50000000,3.91196200,11.83790000,0.13149356,785.30976712,0.12353849,888.57294061,0.00092957,0.00000000,0.00000000,0.00000000,0.00000000,0.00000000,0.00000000,0.00000000,0.00000000
213.00000000,3.95995900,11.84510000,0.13316478,785.78740507,0.12501441,890.42661025,0.00100766,0.00000000,0.00000000,0.00000000,0.00000000,0.00000000,0.00000000,0.00000000,0.00000000
214.50000000,4.00778700,11.84670000,0.13479100,785.89354684,0.12644849,891.82492391,0.00099309,0.00000000,0.00000000,0.00000000,0.00000000,0.00000000,0.00000000,0.00000000,0.00000000
216.00000000,4.05622400,11.84750000,0.13640600,785.94661772,0.12787065,893.15445206,0.00099187,0.00000000,0.00000000,0.00000000,0.00000000,0.00000000,0.00000000,0.00000000,0.00000000
217.50000000,4.10425500,11.84510000,0.13802089,785.78740507,0.12929069,894.24248120,0.00092423,0.00000000,0.00000000,0.00000000,0.00000000,0.00000000,0.00000000,0.00000000,0.00000000
219.00000000,4.15232000,11.84990000,0.13963578,786.10583037,0.13070872,895.87432941,0.00085699,0.00000000,0.00000000,0.00000000,0.00000000,0.00000000,0.00000000,0.00000000,0.00000000
220.50000000,4.20119600,11.85060000,0.14125078,786.15226740,0.13212483,897.19688662,0.00092181,0.00000000,0.00000000,0.00000000,0.00000000,0.00000000,0.00000000,0.00000000,0.00000000
222.00000000,4.24993700,11.84990000,0.14290322,786.10583037,0.13357171,898.44288654,0.00098604,0.00000000,0.00000000,0.00000000,0.00000000,0.00000000,0.00000000,0.00000000,0.00000000
223.50000000,4.29948900,11.84670000,0.14451811,785.89354684,0.13498368,899.46939776,0.00085333,0.00000000,0.00000000,0.00000000,0.00000000,0.00000000,0.00000000,0.00000000,0.00000000
225.00000000,4.34880500,11.85140000,0.14617067,786.20533828,0.13642653,901.12549671,0.00091766,0.00000000,0.00000000,0.00000000,0.00000000,0.00000000,0.00000000,0.00000000,0.00000000
226.50000000,4.39906700,11.84670000,0.14782311,785.89354684,0.00000000,0.00000000,0.00000000,0.00000000,0.00000000,0.00000000,0.00000000,0.00000000,0.00000000,0.00000000,0.00000000
228.00000000,4.44932900,11.84750000,0.14943811,785.94661772,0.00000000,0.00000000,0.00000000,0.00000000,0.00000000,0.00000000,0.00000000,0.00000000,0.00000000,0.00000000,0.00000000
229.50000000,4.49921900,11.84750000,0.15105300,785.94661772,0.00000000,0.00000000,0.00000000,0.00000000,0.00000000,0.00000000,0.00000000,0.00000000,0.00000000,0.00000000,0.00000000
231.00000000,4.55009000,11.84670000,0.15270556,785.89354684,0.00000000,0.00000000,0.00000000,0.00000000,0.00000000,0.00000000,0.00000000,0.00000000,0.00000000,0.00000000,0.00000000
232.50000000,4.60106100,11.84510000,0.15428289,785.78740507,0.00000000,0.00000000,0.00000000,0.00000000,0.00000000,0.00000000,0.00000000,0.00000000,0.00000000,0.00000000,0.00000000
234.00000000,4.65264100,11.84670000,0.15586022,785.89354684,0.00000000,0.00000000,0.00000000,0.00000000,0.00000000,0.00000000,0.00000000,0.00000000,0.00000000,0.00000000,0.00000000
235.50000000,4.70520200,11.84510000,0.15747522,785.78740507,0.00000000,0.00000000,0.00000000,0.00000000,0.00000000,0.00000000,0.00000000,0.00000000,0.00000000,0.00000000,0.00000000
237.00000000,4.75698500,11.84110000,0.15897744,785.52205065,0.00000000,0.00000000,0.00000000,0.00000000,0.00000000,0.00000000,0.00000000,0.00000000,0.00000000,0.00000000,0.00000000
238.50000000,4.81015400,11.83790000,0.16059244,785.30976712,0.00000000,0.00000000,0.00000000,0.00000000,0.00000000,0.00000000,0.00000000,0.00000000,0.00000000,0.00000000,0.00000000
240.00000000,4.86183600,11.83550000,0.16201956,785.15055447,0.00000000,0.00000000,0.00000000,0.00000000,0.00000000,0.00000000,0.00000000,0.00000000,0.00000000,0.00000000,0.00000000
241.50000000,4.91551200,11.83150000,0.16352178,784.88520005,0.00000000,0.00000000,0.00000000,0.00000000,0.00000000,0.00000000,0.00000000,0.00000000,0.00000000,0.00000000,0.00000000
243.00000000,4.96861300,11.82750000,0.16483633,784.61984563,0.00000000,0.00000000,0.00000000,0.00000000,0.00000000,0.00000000,0.00000000,0.00000000,0.00000000,0.00000000,0.00000000
244.50000000,5.02296500,11.82270000,0.16618833,784.30142033,0.00000000,0.00000000,0.00000000,0.00000000,0.00000000,0.00000000,0.00000000,0.00000000,0.00000000,0.00000000,0.00000000
246.00000000,5.07751900,11.81400000,0.16750278,783.72427447,0.00000000,0.00000000,0.00000000,0.00000000,0.00000000,0.00000000,0.00000000,0.00000000,0.00000000,0.00000000,0.00000000
247.50000000,5.13325700,11.80760000,0.16870456,783.29970740,0.00000000,0.00000000,0.00000000,0.00000000,0.00000000,0.00000000,0.00000000,0.00000000,0.00000000,0.00000000,0.00000000
249.00000000,5.18889400,11.80200000,0.16983133,782.92821121,0.00000000,0.00000000,0.00000000,0.00000000,0.00000000,0.00000000,0.00000000,0.00000000,0.00000000,0.00000000,0.00000000
250.50000000,5.24490200,11.79000000,0.17084533,782.13214796,0.00000000,0.00000000,0.00000000,0.00000000,0.00000000,0.00000000,0.00000000,0.00000000,0.00000000,0.00000000,0.00000000
252.00000000,5.30158600,11.78290000,0.17182178,781.66114387,0.00000000,0.00000000,0.00000000,0.00000000,0.00000000,0.00000000,0.00000000,0.00000000,0.00000000,0.00000000,0.00000000
253.50000000,5.35898000,11.77090000,0.17264800,780.86508061,0.00000000,0.00000000,0.00000000,0.00000000,0.00000000,0.00000000,0.00000000,0.00000000,0.00000000,0.00000000,0.00000000
255.00000000,5.41664400,11.75570000,0.17339911,779.85673382,0.00000000,0.00000000,0.00000000,0.00000000,0.00000000,0.00000000,0.00000000,0.00000000,0.00000000,0.00000000,0.00000000
256.50000000,5.47549200,11.74460000,0.17400011,779.12037531,0.00000000,0.00000000,0.00000000,0.00000000,0.00000000,0.00000000,0.00000000,0.00000000,0.00000000,0.00000000,0.00000000
258.00000000,5.53437300,11.72460000,0.17456344,777.79360322,0.00000000,0.00000000,0.00000000,0.00000000,0.00000000,0.00000000,0.00000000,0.00000000,0.00000000,0.00000000,0.00000000
259.50000000,5.59393100,11.70630000,0.17493900,776.57960676,0.00000000,0.00000000,0.00000000,0.00000000,0.00000000,0.00000000,0.00000000,0.00000000,0.00000000,0.00000000,0.00000000
261.00000000,5.65416400,11.68400000,0.17531456,775.10025587,0.00000000,0.00000000,0.00000000,0.00000000,0.00000000,0.00000000,0.00000000,0.00000000,0.00000000,0.00000000,0.00000000
262.50000000,5.71463400,11.66560000,0.17553989,773.87962555,0.00000000,0.00000000,0.00000000,0.00000000,0.00000000,0.00000000,0.00000000,0.00000000,0.00000000,0.00000000,0.00000000
264.00000000,5.77520500,11.62900000,0.17576522,771.45163262,0.00000000,0.00000000,0.00000000,0.00000000,0.00000000,0.00000000,0.00000000,0.00000000,0.00000000,0.00000000,0.00000000
265.50000000,5.83723000,11.60580000,0.17587789,769.91257700,0.00000000,0.00000000,0.00000000,0.00000000,0.00000000,0.00000000,0.00000000,0.00000000,0.00000000,0.00000000,0.00000000
267.00000000,5.89901800,11.56750000,0.17595300,767.37180844,0.00000000,0.00000000,0.00000000,0.00000000,0.00000000,0.00000000,0.00000000,0.00000000,0.00000000,0.00000000,0.00000000
268.50000000,5.96073900,11.53800000,0.17599056,765.41481961,0.00000000,0.00000000,0.00000000,0.00000000,0.00000000,0.00000000,0.00000000,0.00000000,0.00000000,0.00000000,0.00000000
270.00000000,6.02283200,11.49740000,0.17606567,762.72147226,0.00000000,0.00000000,0.00000000,0.00000000,0.00000000,0.00000000,0.00000000,0.00000000,0.00000000,0.00000000,0.00000000
271.50000000,6.08600600,11.45030000,0.17606567,759.59692399,0.00000000,0.00000000,0.00000000,0.00000000,0.00000000,0.00000000,0.00000000,0.00000000,0.00000000,0.00000000,0.00000000
273.00000000,6.14897800,11.40330000,0.17599056,756.47900957,0.00000000,0.00000000,0.00000000,0.00000000,0.00000000,0.00000000,0.00000000,0.00000000,0.00000000,0.00000000,0.00000000
274.50000000,6.21211900,11.34500000,0.17602811,752.61146892,0.00000000,0.00000000,0.00000000,0.00000000,0.00000000,0.00000000,0.00000000,0.00000000,0.00000000,0.00000000,0.00000000
276.00000000,6.27570100,11.27330000,0.17599056,747.85499097,0.00000000,0.00000000,0.00000000,0.00000000,0.00000000,0.00000000,0.00000000,0.00000000,0.00000000,0.00000000,0.00000000
277.50000000,6.34067000,11.20390000,0.17595311,743.25109182,0.00000000,0.00000000,0.00000000,0.00000000,0.00000000,0.00000000,0.00000000,0.00000000,0.00000000,0.00000000,0.00000000
279.00000000,6.40669100,11.11540000,0.17591556,737.38012531,0.00000000,0.00000000,0.00000000,0.00000000,0.00000000,0.00000000,0.00000000,0.00000000,0.00000000,0.00000000,0.00000000
280.50000000,6.47461500,10.99340000,0.17587811,729.28681555,0.00000000,0.00000000,0.00000000,0.00000000,0.00000000,0.00000000,0.00000000,0.00000000,0.00000000,0.00000000,0.00000000
282.00000000,6.54547500,10.81870000,0.17572800,717.69746133,0.00000000,0.00000000,0.00000000,0.00000000,0.00000000,0.00000000,0.00000000,0.00000000,0.00000000,0.00000000,0.00000000
282.50000000,6.58785500,10.71900000,0.17557744,711.08350246,0.00000000,0.00000000,0.00000000,0.00000000,0.00000000,0.00000000,0.00000000,0.00000000,0.00000000,0.00000000,0.00000000