File: polyN_optimization/DP780_results/DATA/UT_30_1.csv
Time[s],Displacement[mm],Force[kN],EngStrain_longi,EngStress[MPa],TrueStrain,TrueStress[MPa],TrueStrainRate[1/s],PlasticStrain_longi,PlasticStress[MPa],PlasticStrain_thick,PlasticStrain_width,R-Value,Thickness[mm],Width[mm], Young's Modulus [MPa]
0.00000000,0.00000000,-0.02530000,0.00000000,-1.68456080,0.00000000,-1.68456080,0.00000000,0.00059354,407.19553113,0.00008043,-0.00067397,0.79804046,1.50490000,9.97990000,213498.69345568
1.50000000,0.00236300,0.40210000,0.00010600,26.77319747,0.00010599,26.77603543,0.00003977,0.00071311,419.83376705,0.00011337,-0.00082648,0.00000000,0.00000000,0.00000000,0.00000000
3.00000000,0.00380000,0.76260000,0.00014878,50.77652423,0.00014877,50.78407865,0.00006088,0.00079519,432.56735444,-0.00000326,-0.00079193,0.00000000,0.00000000,0.00000000,0.00000000
4.50000000,0.00562200,1.09030000,0.00018478,72.59591447,0.00018476,72.60932858,0.00002688,0.00100552,444.18378436,0.00009265,-0.00109817,0.00000000,0.00000000,0.00000000,0.00000000
6.00000000,0.00787200,1.39420000,0.00026867,92.83061905,0.00026863,92.85555954,-0.00002466,0.00133275,455.65218899,-0.00023315,-0.00109960,0.00000000,0.00000000,0.00000000,0.00000000
7.50000000,0.01072500,1.69560000,0.00035667,112.89886505,0.00035660,112.93913232,-0.00000133,0.00158419,467.24789309,-0.00034699,-0.00123720,0.00000000,0.00000000,0.00000000,0.00000000
9.00000000,0.01335300,1.96040000,0.00047511,130.53015750,0.00047500,130.59217382,0.00011573,0.00187438,477.75016347,-0.00037027,-0.00150411,0.00000000,0.00000000,0.00000000,0.00000000
10.50000000,0.01552900,2.21560000,0.00055600,147.52224900,0.00055585,147.60427138,0.00013215,0.00225989,487.88381247,-0.00069253,-0.00156736,0.00000000,0.00000000,0.00000000,0.00000000
12.00000000,0.01731900,2.48750000,0.00057533,165.62628381,0.00057517,165.72157413,0.00003442,0.00260490,498.58951827,-0.00095728,-0.00164762,0.00000000,0.00000000,0.00000000,0.00000000
13.50000000,0.01904200,2.73230000,0.00065233,181.92590763,0.00065212,182.04458397,0.00009772,0.00288895,507.93051452,-0.00088930,-0.00199965,0.00000000,0.00000000,0.00000000,0.00000000
15.00000000,0.02062200,2.97160000,0.00069344,197.85932260,0.00069320,197.99652704,0.00001377,0.00329360,517.02462994,-0.00110070,-0.00219291,0.00000000,0.00000000,0.00000000,0.00000000
16.50000000,0.02295100,3.22440000,0.00079322,214.69161387,0.00079291,214.86191203,-0.00013744,0.00387201,526.43343386,-0.00149171,-0.00238030,0.00000000,0.00000000,0.00000000,0.00000000
18.00000000,0.02578800,3.46120000,0.00088911,230.45857025,0.00088872,230.66347353,-0.00006727,0.00442772,535.03495334,-0.00183520,-0.00259251,0.00000000,0.00000000,0.00000000,0.00000000
19.50000000,0.02879500,3.69730000,0.00105878,246.17891824,0.00105822,246.43956700,0.00015806,0.00486653,543.09862710,-0.00203277,-0.00283376,0.00000000,0.00000000,0.00000000,0.00000000
21.00000000,0.03141500,3.94370000,0.00111533,262.58507556,0.00111471,262.87794544,0.00022509,0.00542690,551.35148143,-0.00230056,-0.00312634,0.00000000,0.00000000,0.00000000,0.00000000
22.50000000,0.03369400,4.17180000,0.00113467,277.77275609,0.00113402,278.08793558,0.00015783,0.00607928,559.01242680,-0.00270372,-0.00337555,0.00000000,0.00000000,0.00000000,0.00000000
24.00000000,0.03685500,4.39270000,0.00118056,292.48103593,0.00117986,292.82632604,-0.00002952,0.00657133,566.65325379,-0.00293251,-0.00363882,0.00000000,0.00000000,0.00000000,0.00000000
25.50000000,0.04018700,4.63270000,0.00133144,308.46105929,0.00133056,308.87175805,-0.00017199,0.00711464,574.37873693,-0.00318145,-0.00393318,0.00000000,0.00000000,0.00000000,0.00000000
27.00000000,0.04284000,4.84640000,0.00148578,322.68993843,0.00148468,323.16938397,-0.00002951,0.00777870,581.70442836,-0.00359080,-0.00418790,0.00000000,0.00000000,0.00000000,0.00000000
28.50000000,0.04657700,5.06170000,0.00168911,337.02535105,0.00168769,337.59462432,0.00025536,0.00848419,588.74044761,-0.00404232,-0.00444187,0.00000000,0.00000000,0.00000000,0.00000000
30.00000000,0.05078000,5.28660000,0.00179478,351.99996461,0.00179317,352.63172632,0.00037514,0.00909242,595.89064829,-0.00434215,-0.00475028,0.00000000,0.00000000,0.00000000,0.00000000
31.50000000,0.05596200,5.49960000,0.00187778,366.18223534,0.00187602,366.86984421,0.00021006,0.00976602,603.19078858,-0.00472466,-0.00504135,0.00000000,0.00000000,0.00000000,0.00000000
33.00000000,0.06131900,5.69810000,0.00198700,379.39904633,0.00198503,380.15291224,-0.00014970,0.01055215,609.33809965,-0.00523721,-0.00531494,0.00000000,0.00000000,0.00000000,0.00000000
34.50000000,0.06636000,5.90710000,0.00222033,393.31498334,0.00221787,394.18827371,-0.00011929,0.01129157,615.83877984,-0.00559107,-0.00570050,0.00000000,0.00000000,0.00000000,0.00000000
36.00000000,0.07295600,6.10010000,0.00253578,406.16558546,0.00253257,407.19553113,0.00031478,0.01200371,622.49481434,-0.00595531,-0.00604840,0.00000000,0.00000000,0.00000000,0.00000000
37.50000000,0.07975900,6.28830000,0.00271600,418.69658712,0.00271232,419.83376705,0.00039696,0.01272332,628.24929178,-0.00632001,-0.00640331,0.00000000,0.00000000,0.00000000,0.00000000
39.00000000,0.08624600,6.47810000,0.00285911,431.33412226,0.00285503,432.56735444,0.00020254,0.01358503,635.07344565,-0.00681611,-0.00676892,0.00000000,0.00000000,0.00000000,0.00000000
40.50000000,0.09463500,6.65030000,0.00312556,442.79978902,0.00312068,444.18378436,-0.00002237,0.01438769,640.94702897,-0.00724091,-0.00714678,0.00000000,0.00000000,0.00000000,0.00000000
42.00000000,0.10389800,6.81940000,0.00350867,454.05904715,0.00350253,455.65218899,0.00017229,0.01514235,646.69679798,-0.00759375,-0.00754860,0.00000000,0.00000000,0.00000000,0.00000000
43.50000000,0.11315300,6.99080000,0.00381644,465.47144717,0.00380918,467.24789309,0.00026169,0.01591794,652.57100555,-0.00799845,-0.00791948,0.00000000,0.00000000,0.00000000,0.00000000
45.00000000,0.12427500,7.14550000,0.00415800,475.77190389,0.00414938,477.75016347,0.00021689,0.01679006,658.14328274,-0.00846896,-0.00832110,0.00000000,0.00000000,0.00000000,0.00000000
46.50000000,0.13586900,7.29390000,0.00459367,485.65288500,0.00458315,487.88381247,0.00033670,0.01763298,663.48739939,-0.00893949,-0.00869349,0.00000000,0.00000000,0.00000000,0.00000000
48.00000000,0.14813100,7.45100000,0.00499156,496.11314196,0.00497914,498.58951827,0.00045578,0.01844063,669.13747672,-0.00935552,-0.00908511,0.00000000,0.00000000,0.00000000,0.00000000
49.50000000,0.16201400,7.58810000,0.00532178,505.24173031,0.00530767,507.93051452,0.00029843,0.01928681,674.28293207,-0.00985086,-0.00943596,0.00000000,0.00000000,0.00000000,0.00000000
51.00000000,0.17597100,7.72050000,0.00577222,514.05737653,0.00575563,517.02462994,0.00005966,0.02021259,679.49112488,-0.01041620,-0.00979639,0.00000000,0.00000000,0.00000000,0.00000000
52.50000000,0.19209300,7.85610000,0.00639922,523.08608973,0.00637883,526.43343386,0.00019410,0.02111667,684.41994443,-0.01093291,-0.01018376,0.00000000,0.00000000,0.00000000,0.00000000
54.00000000,0.20784000,7.97970000,0.00699989,531.31580176,0.00697550,535.03495334,0.00048467,0.02197545,689.49045070,-0.01143449,-0.01054096,0.00000000,0.00000000,0.00000000,0.00000000
55.50000000,0.22513900,8.09610000,0.00748056,539.06611309,0.00745271,543.09862710,0.00043237,0.02286871,694.04482677,-0.01194145,-0.01092725,0.00000000,0.00000000,0.00000000,0.00000000
57.00000000,0.24250400,8.21420000,0.00808489,546.92961626,0.00805238,551.35148143,0.00039463,0.02381465,698.91849463,-0.01246304,-0.01135161,0.00000000,0.00000000,0.00000000,0.00000000
58.50000000,0.26119100,8.32260000,0.00877956,554.14726014,0.00874124,559.01242680,0.00060302,0.02474513,703.73509978,-0.01298871,-0.01175642,0.00000000,0.00000000,0.00000000,0.00000000
60.00000000,0.27998000,8.43190000,0.00931278,561.42482911,0.00926968,566.65325379,0.00055821,0.02571646,708.21104503,-0.01354174,-0.01217472,0.00000000,0.00000000,0.00000000,0.00000000
61.50000000,0.29978300,8.54190000,0.00989844,568.74900649,0.00984978,574.37873693,0.00023018,0.02666156,712.66956582,-0.01409086,-0.01257070,0.00000000,0.00000000,0.00000000,0.00000000
63.00000000,0.32080500,8.64480000,0.01060456,575.60044150,0.01054872,581.70442836,0.00020825,0.02759923,716.91019087,-0.01454486,-0.01305437,0.00000000,0.00000000,0.00000000,0.00000000
64.50000000,0.34185900,8.74290000,0.01135167,582.13227605,0.01128772,588.74044761,0.00040082,0.02856169,721.12797492,-0.01507152,-0.01349017,0.00000000,0.00000000,0.00000000,0.00000000
66.00000000,0.36338600,8.84340000,0.01200144,588.82391084,0.01193000,595.89064829,0.00037114,0.02951275,725.28292750,-0.01553189,-0.01398085,0.00000000,0.00000000,0.00000000,0.00000000
67.50000000,0.38484700,8.94540000,0.01271856,595.61542077,0.01263835,603.19078858,0.00025192,0.03051463,730.69912388,-0.01606903,-0.01444560,0.00000000,0.00000000,0.00000000,0.00000000
69.00000000,0.40735500,9.02920000,0.01354467,601.19511226,0.01345376,609.33809965,0.00037781,0.03152304,733.03736655,-0.01664160,-0.01488144,0.00000000,0.00000000,0.00000000,0.00000000
70.50000000,0.43016800,9.11850000,0.01432578,607.14101262,0.01422413,615.83877984,0.00054077,0.03253613,737.21181724,-0.01715950,-0.01537663,0.00000000,0.00000000,0.00000000,0.00000000
72.00000000,0.45402800,9.21020000,0.01508056,613.24671321,0.01496797,622.49481434,0.00053292,0.03354690,740.88620656,-0.01772079,-0.01582611,0.00000000,0.00000000,0.00000000,0.00000000
73.50000000,0.47785300,9.28840000,0.01583911,618.45353749,0.01571498,628.24929178,0.00041415,0.03457509,744.47629224,-0.01830414,-0.01627095,0.00000000,0.00000000,0.00000000,0.00000000
75.00000000,0.50262600,9.38090000,0.01674789,624.61250482,0.01660919,635.07344565,0.00057643,0.03560446,748.35195031,-0.01888876,-0.01671570,0.00000000,0.00000000,0.00000000,0.00000000
76.50000000,0.52705900,9.45980000,0.01759278,629.86593750,0.01743982,640.94702897,0.00073083,0.03666277,751.97156657,-0.01949259,-0.01717018,0.00000000,0.00000000,0.00000000,0.00000000
78.00000000,0.55267700,9.53720000,0.01838889,635.01949504,0.01822186,646.69679798,0.00068595,0.03772156,755.27117081,-0.02008876,-0.01763280,0.00000000,0.00000000,0.00000000,0.00000000
79.50000000,0.57809300,9.61610000,0.01920756,640.27292772,0.01902542,652.57100555,0.00056762,0.03877757,758.90956576,-0.02067302,-0.01810455,0.00000000,0.00000000,0.00000000,0.00000000
81.00000000,0.60425200,9.68950000,0.02012389,645.16015153,0.01992408,658.14328274,0.00065558,0.03985849,762.35063473,-0.02131125,-0.01854724,0.00000000,0.00000000,0.00000000,0.00000000
82.50000000,0.63091600,9.75970000,0.02101011,649.83430836,0.02079244,663.48739939,0.00072098,0.04091493,765.38827934,-0.02186981,-0.01904513,0.00000000,0.00000000,0.00000000,0.00000000
84.00000000,0.65815800,9.83460000,0.02186256,654.82140732,0.02162700,669.13747672,0.00064685,0.04201809,768.96426304,-0.02249024,-0.01952786,0.00000000,0.00000000,0.00000000,0.00000000
85.50000000,0.68546500,9.90160000,0.02275267,659.28249718,0.02249769,674.28293207,0.00058022,0.04308974,772.08170840,-0.02309300,-0.01999673,0.00000000,0.00000000,0.00000000,0.00000000
87.00000000,0.71287600,9.96860000,0.02372533,663.74358703,0.02344826,679.49112488,0.00063135,0.04416483,774.98338921,-0.02367928,-0.02048556,0.00000000,0.00000000,0.00000000,0.00000000
88.50000000,0.74102800,10.03160000,0.02467533,667.93834317,0.02437581,684.41994443,0.00071841,0.04528217,778.54112219,-0.02429997,-0.02098220,0.00000000,0.00000000,0.00000000,0.00000000
90.00000000,0.76955200,10.09700000,0.02558044,672.29289953,0.02525874,689.49045070,0.00063736,0.04638906,781.76047255,-0.02488265,-0.02150641,0.00000000,0.00000000,0.00000000,0.00000000
91.50000000,0.79818000,10.15440000,0.02651922,676.11478845,0.02617368,694.04482677,0.00064392,0.04749653,784.59261551,-0.02549885,-0.02199767,0.00000000,0.00000000,0.00000000,0.00000000
93.00000000,0.82734900,10.21580000,0.02751456,680.20301110,0.02714283,698.91849463,0.00064351,0.04862772,787.44890074,-0.02611514,-0.02251258,0.00000000,0.00000000,0.00000000,0.00000000
94.50000000,0.85705800,10.27640000,0.02849467,684.23796699,0.02809624,703.73509978,0.00067921,0.04972225,790.23227932,-0.02671430,-0.02300795,0.00000000,0.00000000,0.00000000,0.00000000
96.00000000,0.88737500,10.33150000,0.02951611,687.90671402,0.02908890,708.21104503,0.00072237,0.05088340,793.68099486,-0.02738420,-0.02349920,0.00000000,0.00000000,0.00000000,0.00000000
97.50000000,0.91715100,10.38650000,0.03051144,691.56880271,0.03005523,712.66956582,0.00064897,0.05203031,796.12180065,-0.02801288,-0.02401743,0.00000000,0.00000000,0.00000000,0.00000000
99.00000000,0.94760300,10.43830000,0.03149900,695.01782442,0.03101308,716.91019087,0.00067723,0.05316346,798.94533950,-0.02865965,-0.02450380,0.00000000,0.00000000,0.00000000,0.00000000
100.50000000,0.97809100,10.48940000,0.03251300,698.42023773,0.03199564,721.12797492,0.00068389,0.05432481,801.51367369,-0.02932285,-0.02500196,0.00000000,0.00000000,0.00000000,0.00000000
102.00000000,1.00938900,10.53960000,0.03351589,701.76272595,0.03296647,725.28292750,0.00062536,0.05548579,804.59730814,-0.02999060,-0.02549519,0.00000000,0.00000000,0.00000000,0.00000000
103.50000000,1.04068700,10.60740000,0.03457856,706.27708255,0.03399415,730.69912388,0.00058819,0.05664091,807.17110600,-0.03061385,-0.02602707,0.00000000,0.00000000,0.00000000,0.00000000
105.00000000,1.07205200,10.63050000,0.03563389,707.81515980,0.03501369,733.03736655,0.00061679,0.05781373,809.43008000,-0.03128729,-0.02652644,0.00000000,0.00000000,0.00000000,0.00000000
106.50000000,1.10460100,10.68000000,0.03670422,711.11103962,0.03604666,737.21181724,0.00067404,0.05898969,812.20122269,-0.03194504,-0.02704465,0.00000000,0.00000000,0.00000000,0.00000000
108.00000000,1.13688000,10.72220000,0.03777078,713.92086039,0.03707493,740.88620656,0.00068042,0.06017355,814.52820152,-0.03259184,-0.02758172,0.00000000,0.00000000,0.00000000,0.00000000
109.50000000,1.16902300,10.76290000,0.03885611,716.63080602,0.03812021,744.47629224,0.00067950,0.06133750,817.02164209,-0.03328776,-0.02804974,0.00000000,0.00000000,0.00000000,0.00000000
111.00000000,1.20133600,10.80760000,0.03994522,719.60708537,0.03916804,748.35195031,0.00070059,0.06251687,819.69683493,-0.03390701,-0.02860986,0.00000000,0.00000000,0.00000000,0.00000000
112.50000000,1.23472900,10.84820000,0.04106433,722.31037265,0.04024359,751.97156657,0.00070709,0.06371138,821.81758895,-0.03459251,-0.02911887,0.00000000,0.00000000,0.00000000,0.00000000
114.00000000,1.26768300,10.88410000,0.04218356,724.70071782,0.04131808,755.27117081,0.00071359,0.06488639,824.04788248,-0.03519343,-0.02969296,0.00000000,0.00000000,0.00000000,0.00000000
115.50000000,1.30151700,10.92480000,0.04330278,727.41066344,0.04239143,758.90956576,0.00074883,0.06608079,826.34860261,-0.03589411,-0.03018668,0.00000000,0.00000000,0.00000000,0.00000000
117.00000000,1.33548600,10.96230000,0.04444822,729.90754210,0.04348873,762.35063473,0.00077674,0.06728438,828.61108192,-0.03654942,-0.03073496,0.00000000,0.00000000,0.00000000,0.00000000
118.50000000,1.37009600,10.99420000,0.04556733,732.03155353,0.04455964,765.38827934,0.00073998,0.06847584,830.91805260,-0.03721245,-0.03126340,0.00000000,0.00000000,0.00000000,0.00000000
120.00000000,1.40443600,11.03320000,0.04673922,734.62830733,0.04567983,768.96426304,0.00077526,0.06963849,833.09735961,-0.03787410,-0.03176439,0.00000000,0.00000000,0.00000000,0.00000000
121.50000000,1.43894600,11.06590000,0.04787711,736.80558551,0.04676632,772.08170840,0.00068107,0.07086867,835.44534553,-0.03854639,-0.03232227,0.00000000,0.00000000,0.00000000,0.00000000
123.00000000,1.47403000,11.09540000,0.04901878,738.76979672,0.04785523,774.98338921,0.00070894,0.07210935,837.46770335,-0.03926797,-0.03284139,0.00000000,0.00000000,0.00000000,0.00000000
124.50000000,1.50857200,11.13370000,0.05020933,741.31994211,0.04898951,778.54112219,0.00076550,0.07333457,839.47356796,-0.03994387,-0.03339070,0.00000000,0.00000000,0.00000000,0.00000000
126.00000000,1.54463700,11.16720000,0.05138856,743.55048704,0.05011172,781.76047255,0.00077880,0.07458915,841.57301660,-0.04065816,-0.03393098,0.00000000,0.00000000,0.00000000,0.00000000
127.50000000,1.57999200,11.19510000,0.05256778,745.40816476,0.05123268,784.59261551,0.00072788,0.07579362,843.62676563,-0.04128353,-0.03451008,0.00000000,0.00000000,0.00000000,0.00000000
129.00000000,1.61629200,11.22300000,0.05377344,747.26584247,0.05237748,787.44890074,0.00071312,0.07702030,845.82638846,-0.04197650,-0.03504380,0.00000000,0.00000000,0.00000000,0.00000000
130.50000000,1.65201800,11.25020000,0.05494144,749.07691179,0.05348526,790.23227932,0.00071233,0.07826353,847.86279649,-0.04264422,-0.03561932,0.00000000,0.00000000,0.00000000,0.00000000
132.00000000,1.68862400,11.28600000,0.05618444,751.46059860,0.05466283,793.68099486,0.00080368,0.07950708,849.50352758,-0.04334077,-0.03616632,0.00000000,0.00000000,0.00000000,0.00000000
133.50000000,1.72546600,11.30760000,0.05740878,752.89880071,0.05582137,796.12180065,0.00082399,0.08071830,851.81800088,-0.04401476,-0.03670354,0.00000000,0.00000000,0.00000000,0.00000000
135.00000000,1.76190300,11.33470000,0.05862189,754.70321168,0.05696796,798.94533950,0.00078062,0.08203283,853.81015600,-0.04479016,-0.03724267,0.00000000,0.00000000,0.00000000,0.00000000
136.50000000,1.79864400,11.35780000,0.05986500,756.24128893,0.05814154,801.51367369,0.00080110,0.08329136,855.64855309,-0.04550408,-0.03778728,0.00000000,0.00000000,0.00000000,0.00000000
138.00000000,1.83599300,11.38810000,0.06111178,758.25876688,0.05931721,804.59730814,0.00080686,0.08454856,857.43066092,-0.04620057,-0.03834799,0.00000000,0.00000000,0.00000000,0.00000000
139.50000000,1.87344300,11.41120000,0.06235122,759.79684413,0.06048459,807.17110600,0.00075675,0.08581052,860.03195091,-0.04690105,-0.03890947,0.00000000,0.00000000,0.00000000,0.00000000
141.00000000,1.91123100,11.42960000,0.06360933,761.02197925,0.06166816,809.43008000,0.00077696,0.08706772,861.11831897,-0.04761998,-0.03944774,0.00000000,0.00000000,0.00000000,0.00000000
142.50000000,1.94908700,11.45510000,0.06487489,762.71985673,0.06285732,812.20122269,0.00081821,0.08832448,863.43034090,-0.04831446,-0.04001002,0.00000000,0.00000000,0.00000000,0.00000000
144.00000000,1.98650400,11.47420000,0.06614811,763.99160026,0.06405226,814.52820152,0.00084559,0.08958440,864.69960370,-0.04899974,-0.04058466,0.00000000,0.00000000,0.00000000,0.00000000
145.50000000,2.02480000,11.49580000,0.06740244,765.42980236,0.06522808,817.02164209,0.00080232,0.09090445,866.67000967,-0.04973748,-0.04116698,0.00000000,0.00000000,0.00000000,0.00000000
147.00000000,2.06275800,11.51970000,0.06867567,767.02114635,0.06642019,819.69683493,0.00080157,0.09219606,868.50153500,-0.05046362,-0.04173243,0.00000000,0.00000000,0.00000000,0.00000000
148.50000000,2.10159400,11.53560000,0.06996378,768.07982290,0.06762480,821.81758895,0.00082844,0.09347806,869.85619955,-0.05116873,-0.04230934,0.00000000,0.00000000,0.00000000,0.00000000
150.00000000,2.14016000,11.55320000,0.07123311,769.25169128,0.06881043,824.04788248,0.00079945,0.09474323,871.54510360,-0.05186770,-0.04287554,0.00000000,0.00000000,0.00000000,0.00000000
151.50000000,2.17930100,11.57150000,0.07252511,770.47016806,0.07001579,826.34860261,0.00081921,0.09603461,873.08990506,-0.05255168,-0.04348293,0.00000000,0.00000000,0.00000000,0.00000000
153.00000000,2.21746200,11.58910000,0.07382833,771.64203644,0.07123014,828.61108192,0.00083250,0.09732931,874.99540112,-0.05327204,-0.04405728,0.00000000,0.00000000,0.00000000,0.00000000
154.50000000,2.25663700,11.60740000,0.07512033,772.86051322,0.07243259,830.91805260,0.00084556,0.09863803,876.44248615,-0.05402694,-0.04461109,0.00000000,0.00000000,0.00000000,0.00000000
156.00000000,2.29564300,11.62420000,0.07638222,773.97911486,0.07360562,833.09735961,0.00079562,0.09996315,878.37379667,-0.05479513,-0.04516802,0.00000000,0.00000000,0.00000000,0.00000000
157.50000000,2.33542500,11.64250000,0.07771922,775.19759164,0.07484698,835.44534553,0.00078081,0.10128841,879.90019016,-0.05553800,-0.04575040,0.00000000,0.00000000,0.00000000,0.00000000
159.00000000,2.37568300,11.65610000,0.07906756,776.10312630,0.07609729,837.46770335,0.00080085,0.10257846,882.05264684,-0.05625205,-0.04632641,0.00000000,0.00000000,0.00000000,0.00000000
160.50000000,2.41587200,11.66960000,0.08040078,777.00200261,0.07733206,839.47356796,0.00079986,0.10389036,883.51345300,-0.05699897,-0.04689139,0.00000000,0.00000000,0.00000000,0.00000000
162.00000000,2.45575700,11.68400000,0.08176789,777.96080401,0.07859664,841.57301660,0.00086112,0.10528170,884.86814281,-0.05782953,-0.04745217,0.00000000,0.00000000,0.00000000,0.00000000
163.50000000,2.49635100,11.69830000,0.08308222,778.91294707,0.07981089,843.62676563,0.00075601,0.10658650,886.37946364,-0.05852945,-0.04805705,0.00000000,0.00000000,0.00000000,0.00000000
165.00000000,2.53643900,11.71430000,0.08442300,779.97828196,0.08104805,845.82638846,0.00077578,0.10795574,888.07786024,-0.05934182,-0.04861391,0.00000000,0.00000000,0.00000000,0.00000000
166.50000000,2.57673000,11.72780000,0.08578256,780.87715828,0.08230098,847.86279649,0.00082333,0.10925697,889.59866247,-0.06004239,-0.04921458,0.00000000,0.00000000,0.00000000,0.00000000
168.00000000,2.61746000,11.73580000,0.08714211,781.40982572,0.08355234,849.50352758,0.00082230,0.11065584,891.32932857,-0.06083013,-0.04982572,0.00000000,0.00000000,0.00000000,0.00000000
169.50000000,2.65873000,11.75340000,0.08847167,782.58169410,0.08477457,851.81800088,0.00073838,0.11198757,892.70246216,-0.06158598,-0.05040159,0.00000000,0.00000000,0.00000000,0.00000000
171.00000000,2.70000100,11.76530000,0.08991378,783.37403693,0.08609859,853.81015600,0.00090996,0.11334933,894.40550188,-0.06233302,-0.05101631,0.00000000,0.00000000,0.00000000,0.00000000
172.50000000,2.74134000,11.77570000,0.09129589,784.06650461,0.08736588,855.64855309,0.00092266,0.11467839,895.60010621,-0.06305949,-0.05161890,0.00000000,0.00000000,0.00000000,0.00000000
174.00000000,2.78321900,11.78530000,0.09267800,784.70570554,0.08863156,857.43066092,0.00088019,0.11600519,896.85460850,-0.06379456,-0.05221063,0.00000000,0.00000000,0.00000000,0.00000000
175.50000000,2.82489400,11.80600000,0.09407133,786.08398256,0.08990591,860.03195091,0.00090650,0.11739399,898.70300126,-0.06461054,-0.05278345,0.00000000,0.00000000,0.00000000,0.00000000
177.00000000,2.86714500,11.80600000,0.09545333,786.08398256,0.09116828,861.11831897,0.00084346,0.11878482,899.71718595,-0.06542608,-0.05335874,0.00000000,0.00000000,0.00000000,0.00000000
178.50000000,2.90899100,11.82270000,0.09684300,787.19592585,0.09243605,863.43034090,0.00082902,0.12017035,901.45470755,-0.06616317,-0.05400718,0.00000000,0.00000000,0.00000000,0.00000000
180.00000000,2.95144400,11.82510000,0.09823244,787.35572608,0.09370202,864.69960370,0.00082756,0.12155586,902.77060986,-0.06697934,-0.05457652,0.00000000,0.00000000,0.00000000,0.00000000
181.50000000,2.99352500,11.83630000,0.09969344,788.10146051,0.09503145,866.67000967,0.00091541,0.12293962,904.02609700,-0.06778336,-0.05515626,0.00000000,0.00000000,0.00000000,0.00000000
183.00000000,3.03695900,11.84590000,0.10112433,788.74066144,0.09633178,868.50153500,0.00089383,0.12432078,905.46349739,-0.06855247,-0.05576831,0.00000000,0.00000000,0.00000000,0.00000000
184.50000000,3.07944700,11.84910000,0.10254400,788.95372842,0.09762024,869.85619955,0.00084509,0.12570059,906.78007630,-0.06932992,-0.05637067,0.00000000,0.00000000,0.00000000,0.00000000
186.00000000,3.12278000,11.85700000,0.10394867,789.47973752,0.09889345,871.54510360,0.00082348,0.12710992,908.36954627,-0.07013927,-0.05697065,0.00000000,0.00000000,0.00000000,0.00000000
187.50000000,3.16563900,11.86260000,0.10538333,789.85260473,0.10019218,873.08990506,0.00090406,0.12848662,909.50421234,-0.07091592,-0.05757070,0.00000000,0.00000000,0.00000000,0.00000000
189.00000000,3.20880200,11.87300000,0.10682544,790.54507241,0.10149596,874.99540112,0.00084845,0.12989296,910.91212245,-0.07171339,-0.05817957,0.00000000,0.00000000,0.00000000,0.00000000
190.50000000,3.25237100,11.87700000,0.10828256,790.81140613,0.10281157,876.44248615,0.00083370,0.00000000,0.00000000,0.00000000,0.00000000,0.00000000,0.00000000,0.00000000,0.00000000
192.00000000,3.29550200,11.88730000,0.10976233,791.49721547,0.10414588,878.37379667,0.00085963,0.00000000,0.00000000,0.00000000,0.00000000,0.00000000,0.00000000,0.00000000,0.00000000
193.50000000,3.34021900,11.89210000,0.11124211,791.81681594,0.10547841,879.90019016,0.00091950,0.00000000,0.00000000,0.00000000,0.00000000,0.00000000,0.00000000,0.00000000,0.00000000
195.00000000,3.38443100,11.90570000,0.11268800,792.72235059,0.10677871,882.05264684,0.00085757,0.00000000,0.00000000,0.00000000,0.00000000,0.00000000,0.00000000,0.00000000,0.00000000
196.50000000,3.42891300,11.90970000,0.11415644,792.98868432,0.10809757,883.51345300,0.00072834,0.00000000,0.00000000,0.00000000,0.00000000,0.00000000,0.00000000,0.00000000,0.00000000
198.00000000,3.47319200,11.91130000,0.11571489,793.09521781,0.10949536,884.86814281,0.00094252,0.00000000,0.00000000,0.00000000,0.00000000,0.00000000,0.00000000,0.00000000,0.00000000
199.50000000,3.51784300,11.91600000,0.11717967,793.40815993,0.11080735,886.37946364,0.00094148,0.00000000,0.00000000,0.00000000,0.00000000,0.00000000,0.00000000,0.00000000,0.00000000
201.00000000,3.56306700,11.92240000,0.11871944,793.83429389,0.11218468,888.07786024,0.00094018,0.00000000,0.00000000,0.00000000,0.00000000,0.00000000,0.00000000,0.00000000,0.00000000
202.50000000,3.60846100,11.92720000,0.12018422,794.15389435,0.11349316,889.59866247,0.00080499,0.00000000,0.00000000,0.00000000,0.00000000,0.00000000,0.00000000,0.00000000,0.00000000
204.00000000,3.65419400,11.93360000,0.12176156,794.58002831,0.11490027,891.32932857,0.00093783,0.00000000,0.00000000,0.00000000,0.00000000,0.00000000,0.00000000,0.00000000,0.00000000
205.50000000,3.69972400,11.93600000,0.12326378,794.73982854,0.11623853,892.70246216,0.00086948,0.00000000,0.00000000,0.00000000,0.00000000,0.00000000,0.00000000,0.00000000,0.00000000
207.00000000,3.74545700,11.94240000,0.12480356,795.16596250,0.11760840,894.40550188,0.00093510,0.00000000,0.00000000,0.00000000,0.00000000,0.00000000,0.00000000,0.00000000,0.00000000
208.50000000,3.79223600,11.94240000,0.12630589,795.16596250,0.11894315,895.60010621,0.00093405,0.00000000,0.00000000,0.00000000,0.00000000,0.00000000,0.00000000,0.00000000,0.00000000
210.00000000,3.83864400,11.94320000,0.12780800,795.21922924,0.12027593,896.85460850,0.00079935,0.00000000,0.00000000,0.00000000,0.00000000,0.00000000,0.00000000,0.00000000,0.00000000
211.50000000,3.88535700,11.95110000,0.12938533,795.74523835,0.12167353,898.70300126,0.00086477,0.00000000,0.00000000,0.00000000,0.00000000,0.00000000,0.00000000,0.00000000,0.00000000
213.00000000,3.93250900,11.94790000,0.13096267,795.53217137,0.12306919,899.71718595,0.00093000,0.00000000,0.00000000,0.00000000,0.00000000,0.00000000,0.00000000,0.00000000,0.00000000
214.50000000,3.97982900,11.95430000,0.13254011,795.95830533,0.12446300,901.45470755,0.00099506,0.00000000,0.00000000,0.00000000,0.00000000,0.00000000,0.00000000,0.00000000,0.00000000
216.00000000,4.02782700,11.95510000,0.13411744,796.01157207,0.12585477,902.77060986,0.00099368,0.00000000,0.00000000,0.00000000,0.00000000,0.00000000,0.00000000,0.00000000,0.00000000
217.50000000,4.07555300,11.95510000,0.13569467,796.01157207,0.12724450,904.02609700,0.00092593,0.00000000,0.00000000,0.00000000,0.00000000,0.00000000,0.00000000,0.00000000,0.00000000
219.00000000,4.12341500,11.95750000,0.13727211,796.17137230,0.12863251,905.46349739,0.00092484,0.00000000,0.00000000,0.00000000,0.00000000,0.00000000,0.00000000,0.00000000,0.00000000
220.50000000,4.17131000,11.95830000,0.13884956,796.22463905,0.13001859,906.78007630,0.00092376,0.00000000,0.00000000,0.00000000,0.00000000,0.00000000,0.00000000,0.00000000,0.00000000
222.00000000,4.21988200,11.96230000,0.14046433,796.49097277,0.13143549,908.36954627,0.00098795,0.00000000,0.00000000,0.00000000,0.00000000,0.00000000,0.00000000,0.00000000,0.00000000
223.50000000,4.26865700,11.96070000,0.14204167,796.38443928,0.13281760,909.50421234,0.00092079,0.00000000,0.00000000,0.00000000,0.00000000,0.00000000,0.00000000,0.00000000,0.00000000
225.00000000,4.31753200,11.96230000,0.14365656,796.49097277,0.13423063,910.91212245,0.00098539,0.00000000,0.00000000,0.00000000,0.00000000,0.00000000,0.00000000,0.00000000,0.00000000
226.50000000,4.36694900,11.96070000,0.14523389,796.38443928,0.00000000,0.00000000,0.00000000,0.00000000,0.00000000,0.00000000,0.00000000,0.00000000,0.00000000,0.00000000,0.00000000
228.00000000,4.41663500,11.95910000,0.14684878,796.27790579,0.00000000,0.00000000,0.00000000,0.00000000,0.00000000,0.00000000,0.00000000,0.00000000,0.00000000,0.00000000,0.00000000
229.50000000,4.46618700,11.96230000,0.14842622,796.49097277,0.00000000,0.00000000,0.00000000,0.00000000,0.00000000,0.00000000,0.00000000,0.00000000,0.00000000,0.00000000,0.00000000
231.00000000,4.51594200,11.95910000,0.15004111,796.27790579,0.00000000,0.00000000,0.00000000,0.00000000,0.00000000,0.00000000,0.00000000,0.00000000,0.00000000,0.00000000,0.00000000
232.50000000,4.56667700,11.95670000,0.15161833,796.11810556,0.00000000,0.00000000,0.00000000,0.00000000,0.00000000,0.00000000,0.00000000,0.00000000,0.00000000,0.00000000,0.00000000
234.00000000,4.61788400,11.95830000,0.15319567,796.22463905,0.00000000,0.00000000,0.00000000,0.00000000,0.00000000,0.00000000,0.00000000,0.00000000,0.00000000,0.00000000,0.00000000
235.50000000,4.66932900,11.95670000,0.15481056,796.11810556,0.00000000,0.00000000,0.00000000,0.00000000,0.00000000,0.00000000,0.00000000,0.00000000,0.00000000,0.00000000,0.00000000
237.00000000,4.72009800,11.95750000,0.15635033,796.17137230,0.00000000,0.00000000,0.00000000,0.00000000,0.00000000,0.00000000,0.00000000,0.00000000,0.00000000,0.00000000,0.00000000
238.50000000,4.77221800,11.95270000,0.15781500,795.85177184,0.00000000,0.00000000,0.00000000,0.00000000,0.00000000,0.00000000,0.00000000,0.00000000,0.00000000,0.00000000,0.00000000
240.00000000,4.82433800,11.94950000,0.15935478,795.63870486,0.00000000,0.00000000,0.00000000,0.00000000,0.00000000,0.00000000,0.00000000,0.00000000,0.00000000,0.00000000,0.00000000
241.50000000,4.87699900,11.94160000,0.16081944,795.11269576,0.00000000,0.00000000,0.00000000,0.00000000,0.00000000,0.00000000,0.00000000,0.00000000,0.00000000,0.00000000,0.00000000
243.00000000,4.92962700,11.94080000,0.16228411,795.05942901,0.00000000,0.00000000,0.00000000,0.00000000,0.00000000,0.00000000,0.00000000,0.00000000,0.00000000,0.00000000,0.00000000
244.50000000,4.98296500,11.94080000,0.16367367,795.05942901,0.00000000,0.00000000,0.00000000,0.00000000,0.00000000,0.00000000,0.00000000,0.00000000,0.00000000,0.00000000,0.00000000
246.00000000,5.03775500,11.93280000,0.16502556,794.52676157,0.00000000,0.00000000,0.00000000,0.00000000,0.00000000,0.00000000,0.00000000,0.00000000,0.00000000,0.00000000,0.00000000
247.50000000,5.09224100,11.92560000,0.16637756,794.04736086,0.00000000,0.00000000,0.00000000,0.00000000,0.00000000,0.00000000,0.00000000,0.00000000,0.00000000,0.00000000,0.00000000
249.00000000,5.14814700,11.91840000,0.16765433,793.56796016,0.00000000,0.00000000,0.00000000,0.00000000,0.00000000,0.00000000,0.00000000,0.00000000,0.00000000,0.00000000,0.00000000
250.50000000,5.20307400,11.91210000,0.16881856,793.14848455,0.00000000,0.00000000,0.00000000,0.00000000,0.00000000,0.00000000,0.00000000,0.00000000,0.00000000,0.00000000,0.00000000
252.00000000,5.25894600,11.90970000,0.16990756,792.98868432,0.00000000,0.00000000,0.00000000,0.00000000,0.00000000,0.00000000,0.00000000,0.00000000,0.00000000,0.00000000,0.00000000
253.50000000,5.31617000,11.89850000,0.17084644,792.24294989,0.00000000,0.00000000,0.00000000,0.00000000,0.00000000,0.00000000,0.00000000,0.00000000,0.00000000,0.00000000,0.00000000
255.00000000,5.37332700,11.88100000,0.17182278,791.07773986,0.00000000,0.00000000,0.00000000,0.00000000,0.00000000,0.00000000,0.00000000,0.00000000,0.00000000,0.00000000,0.00000000
256.50000000,5.43156500,11.86820000,0.17264900,790.22547194,0.00000000,0.00000000,0.00000000,0.00000000,0.00000000,0.00000000,0.00000000,0.00000000,0.00000000,0.00000000,0.00000000
258.00000000,5.48980300,11.85140000,0.17332489,789.10687031,0.00000000,0.00000000,0.00000000,0.00000000,0.00000000,0.00000000,0.00000000,0.00000000,0.00000000,0.00000000,0.00000000
259.50000000,5.54854800,11.83950000,0.17388822,788.31452748,0.00000000,0.00000000,0.00000000,0.00000000,0.00000000,0.00000000,0.00000000,0.00000000,0.00000000,0.00000000,0.00000000
261.00000000,5.60820600,11.81640000,0.17445156,786.77645024,0.00000000,0.00000000,0.00000000,0.00000000,0.00000000,0.00000000,0.00000000,0.00000000,0.00000000,0.00000000,0.00000000
262.50000000,5.66816800,11.79240000,0.17482700,785.17844790,0.00000000,0.00000000,0.00000000,0.00000000,0.00000000,0.00000000,0.00000000,0.00000000,0.00000000,0.00000000,0.00000000
264.00000000,5.72900900,11.77010000,0.17512733,783.69363739,0.00000000,0.00000000,0.00000000,0.00000000,0.00000000,0.00000000,0.00000000,0.00000000,0.00000000,0.00000000,0.00000000
265.50000000,5.79001900,11.74460000,0.17531500,781.99575991,0.00000000,0.00000000,0.00000000,0.00000000,0.00000000,0.00000000,0.00000000,0.00000000,0.00000000,0.00000000,0.00000000
267.00000000,5.85194100,11.71190000,0.17546522,779.81848173,0.00000000,0.00000000,0.00000000,0.00000000,0.00000000,0.00000000,0.00000000,0.00000000,0.00000000,0.00000000,0.00000000
268.50000000,5.91329000,11.67520000,0.17561533,777.37486982,0.00000000,0.00000000,0.00000000,0.00000000,0.00000000,0.00000000,0.00000000,0.00000000,0.00000000,0.00000000,0.00000000
270.00000000,5.97565300,11.63690000,0.17569044,774.82472443,0.00000000,0.00000000,0.00000000,0.00000000,0.00000000,0.00000000,0.00000000,0.00000000,0.00000000,0.00000000,0.00000000
271.50000000,6.03815000,11.59390000,0.17572789,771.96163691,0.00000000,0.00000000,0.00000000,0.00000000,0.00000000,0.00000000,0.00000000,0.00000000,0.00000000,0.00000000,0.00000000
273.00000000,6.10091900,11.54680000,0.17572789,768.82555732,0.00000000,0.00000000,0.00000000,0.00000000,0.00000000,0.00000000,0.00000000,0.00000000,0.00000000,0.00000000,0.00000000
274.50000000,6.16473700,11.48940000,0.17572789,765.00366840,0.00000000,0.00000000,0.00000000,0.00000000,0.00000000,0.00000000,0.00000000,0.00000000,0.00000000,0.00000000,0.00000000
276.00000000,6.22767700,11.42960000,0.17569022,761.02197925,0.00000000,0.00000000,0.00000000,0.00000000,0.00000000,0.00000000,0.00000000,0.00000000,0.00000000,0.00000000,0.00000000
277.50000000,6.29244300,11.36100000,0.17572778,756.45435591,0.00000000,0.00000000,0.00000000,0.00000000,0.00000000,0.00000000,0.00000000,0.00000000,0.00000000,0.00000000,0.00000000
279.00000000,6.35748100,11.28050000,0.17569022,751.09438974,0.00000000,0.00000000,0.00000000,0.00000000,0.00000000,0.00000000,0.00000000,0.00000000,0.00000000,0.00000000,0.00000000
280.50000000,6.42384300,11.18560000,0.17557744,744.77562216,0.00000000,0.00000000,0.00000000,0.00000000,0.00000000,0.00000000,0.00000000,0.00000000,0.00000000,0.00000000,0.00000000
282.00000000,6.48983800,11.06350000,0.17550233,736.64578528,0.00000000,0.00000000,0.00000000,0.00000000,0.00000000,0.00000000,0.00000000,0.00000000,0.00000000,0.00000000,0.00000000
283.50000000,6.55956500,10.92480000,0.17542722,727.41066344,0.00000000,0.00000000,0.00000000,0.00000000,0.00000000,0.00000000,0.00000000,0.00000000,0.00000000,0.00000000,0.00000000
284.00000000,6.58324000,10.85700000,0.17538967,722.89630684,0.00000000,0.00000000,0.00000000,0.00000000,0.00000000,0.00000000,0.00000000,0.00000000,0.00000000,0.00000000,0.00000000