File: polyN_optimization/DP780_results/DATA/UT_30_3.csv
Time[s],Displacement[mm],Force[kN],EngStrain_longi,EngStress[MPa],TrueStrain,TrueStress[MPa],TrueStrainRate[1/s],PlasticStrain_longi,PlasticStress[MPa],PlasticStrain_thick,PlasticStrain_width,R-Value,Thickness[mm],Width[mm], Young's Modulus [MPa]
0.00000000,0.00000000,-0.01740000,0.00000000,-1.15726913,0.00000000,-1.15726913,0.00000000,0.00060657,418.30769098,0.00019805,-0.00080462,0.81415840,1.50610000,9.98300000,220024.31726450
1.50000000,0.00235400,0.39170000,0.00006856,26.05185738,0.00006855,26.05364338,0.00011311,0.00074505,432.48684287,0.00023962,-0.00098467,0.00000000,0.00000000,0.00000000,0.00000000
3.00000000,0.00375200,0.73150000,0.00009311,48.65186028,0.00009311,48.65639031,0.00003377,0.00099145,444.48705350,0.00003039,-0.00102183,0.00000000,0.00000000,0.00000000,0.00000000
4.50000000,0.00553400,1.06560000,0.00015778,70.87275777,0.00015777,70.88393992,-0.00005555,0.00128002,456.23958922,-0.00015788,-0.00112213,0.00000000,0.00000000,0.00000000,0.00000000
6.00000000,0.00838200,1.39500000,0.00026644,92.78105959,0.00026641,92.80578058,0.00005865,0.00161710,468.61179889,-0.00020694,-0.00141016,0.00000000,0.00000000,0.00000000,0.00000000
7.50000000,0.01099500,1.67730000,0.00034389,111.55675358,0.00034383,111.59511671,0.00011796,0.00194653,479.44364456,-0.00027924,-0.00166729,0.00000000,0.00000000,0.00000000,0.00000000
9.00000000,0.01344100,1.94680000,0.00041089,129.48112315,0.00041080,129.53432551,0.00009619,0.00236396,489.90497288,-0.00060269,-0.00176127,0.00000000,0.00000000,0.00000000,0.00000000
10.50000000,0.01524600,2.22190000,0.00045333,147.77794716,0.00045323,147.84493983,0.00014816,0.00276230,500.35972209,-0.00086536,-0.00189694,0.00000000,0.00000000,0.00000000,0.00000000
12.00000000,0.01688100,2.47710000,0.00049978,164.75122774,0.00049965,164.83356674,0.00006997,0.00328739,509.97674482,-0.00119607,-0.00209132,0.00000000,0.00000000,0.00000000,0.00000000
13.50000000,0.01808800,2.71880000,0.00057311,180.82662710,0.00057295,180.93026085,0.00003243,0.00386567,519.37063318,-0.00147094,-0.00239473,0.00000000,0.00000000,0.00000000,0.00000000
15.00000000,0.02009300,2.97400000,0.00063244,197.79990768,0.00063224,197.92500513,-0.00009061,0.00442004,528.97823763,-0.00172656,-0.00269348,0.00000000,0.00000000,0.00000000,0.00000000
16.50000000,0.02340400,3.21160000,0.00074678,213.60261718,0.00074650,213.76213087,-0.00010148,0.00497325,537.19915601,-0.00203594,-0.00293732,0.00000000,0.00000000,0.00000000,0.00000000
18.00000000,0.02626900,3.45160000,0.00086778,229.56495001,0.00086740,229.76416137,0.00016986,0.00556990,545.66854263,-0.00234453,-0.00322537,0.00000000,0.00000000,0.00000000,0.00000000
19.50000000,0.02799100,3.70050000,0.00096100,246.11921935,0.00096054,246.35573992,0.00027020,0.00625866,554.25353515,-0.00274029,-0.00351837,0.00000000,0.00000000,0.00000000,0.00000000
21.00000000,0.03044400,3.93570000,0.00095800,261.76230553,0.00095754,262.01307382,0.00010568,0.00690775,561.65013375,-0.00308499,-0.00382277,0.00000000,0.00000000,0.00000000,0.00000000
22.50000000,0.03266200,4.16380000,0.00101500,276.93317269,0.00101449,277.21425986,-0.00000688,0.00756339,569.16816566,-0.00341643,-0.00414696,0.00000000,0.00000000,0.00000000,0.00000000
24.00000000,0.03609900,4.40620000,0.00110222,293.05512885,0.00110162,293.37814072,-0.00012697,0.00823037,576.53434530,-0.00374782,-0.00448254,0.00000000,0.00000000,0.00000000,0.00000000
25.50000000,0.03940100,4.63110000,0.00128700,308.01316491,0.00128617,308.40957785,0.00000799,0.00892952,584.09815863,-0.00412273,-0.00480679,0.00000000,0.00000000,0.00000000,0.00000000
27.00000000,0.04222700,4.86560000,0.00143789,323.60969428,0.00143686,324.07500906,0.00021770,0.00970185,590.90578681,-0.00450121,-0.00520064,0.00000000,0.00000000,0.00000000,0.00000000
28.50000000,0.04569700,5.08970000,0.00155889,338.51452256,0.00155768,339.04222909,0.00033795,0.01042376,598.12638688,-0.00495595,-0.00546781,0.00000000,0.00000000,0.00000000,0.00000000
30.00000000,0.05052200,5.30500000,0.00162344,352.83406530,0.00162213,353.40687181,0.00018770,0.01112393,604.31624110,-0.00529669,-0.00582725,0.00000000,0.00000000,0.00000000,0.00000000
31.50000000,0.05588200,5.52190000,0.00173656,367.26002360,0.00173505,367.89779104,0.00010538,0.01190821,610.62049383,-0.00578813,-0.00612007,0.00000000,0.00000000,0.00000000,0.00000000
33.00000000,0.06117000,5.74040000,0.00188733,381.79239745,0.00188555,382.51296697,-0.00015703,0.01271505,617.49067521,-0.00622787,-0.00648718,0.00000000,0.00000000,0.00000000,0.00000000
34.50000000,0.06696700,5.94220000,0.00212467,395.21405897,0.00212241,396.05375711,-0.00012684,0.01350629,623.60947216,-0.00668494,-0.00682135,0.00000000,0.00000000,0.00000000,0.00000000
36.00000000,0.07434800,6.14070000,0.00246300,408.41623842,0.00245997,409.42216762,0.00018023,0.01430235,629.35409080,-0.00716355,-0.00713881,0.00000000,0.00000000,0.00000000,0.00000000
37.50000000,0.08240100,6.34970000,0.00274078,422.31676993,0.00273703,423.47424635,0.00027704,0.01510174,635.81638841,-0.00751877,-0.00758297,0.00000000,0.00000000,0.00000000,0.00000000
39.00000000,0.09085800,6.53390000,0.00302233,434.56786038,0.00301778,435.88126931,0.00042653,0.01594955,641.23911126,-0.00799538,-0.00795417,0.00000000,0.00000000,0.00000000,0.00000000
40.50000000,0.09982300,6.71490000,0.00327444,446.60611972,0.00326910,448.06850665,0.00032208,0.01682458,646.96074017,-0.00848032,-0.00834426,0.00000000,0.00000000,0.00000000,0.00000000
42.00000000,0.11073800,6.90230000,0.00362000,459.07004127,0.00361346,460.73187482,0.00032175,0.01766743,652.34417586,-0.00889172,-0.00877571,0.00000000,0.00000000,0.00000000,0.00000000
43.50000000,0.12310200,7.07060000,0.00401356,470.26362717,0.00400552,472.15105636,0.00031388,0.01853536,657.69169059,-0.00937015,-0.00916521,0.00000000,0.00000000,0.00000000,0.00000000
45.00000000,0.13512700,7.22850000,0.00446378,480.76551198,0.00445384,482.91154239,0.00044849,0.01940610,663.05696631,-0.00984105,-0.00956506,0.00000000,0.00000000,0.00000000,0.00000000
46.50000000,0.14830100,7.38800000,0.00491411,491.37381234,0.00490208,493.78847785,0.00041047,0.02032246,668.68054064,-0.01037213,-0.00995033,0.00000000,0.00000000,0.00000000,0.00000000
48.00000000,0.16458400,7.53550000,0.00536078,501.18399606,0.00534646,503.87073209,0.00040299,0.02120142,673.52309779,-0.01086410,-0.01033731,0.00000000,0.00000000,0.00000000,0.00000000
49.50000000,0.18008500,7.67110000,0.00587856,510.20271411,0.00586134,513.20196911,0.00029098,0.02211276,678.28641993,-0.01140270,-0.01071007,0.00000000,0.00000000,0.00000000,0.00000000
51.00000000,0.19788800,7.81140000,0.00646389,519.53402785,0.00644309,522.89223808,0.00020844,0.02302331,683.05753483,-0.01188199,-0.01114132,0.00000000,0.00000000,0.00000000,0.00000000
52.50000000,0.21684000,7.93190000,0.00712078,527.54844912,0.00709554,531.30500440,0.00031313,0.02398926,687.54608179,-0.01244793,-0.01154133,0.00000000,0.00000000,0.00000000,0.00000000
54.00000000,0.23548900,8.05230000,0.00775511,535.55621943,0.00772519,539.70951741,0.00038770,0.02494300,692.03438179,-0.01300060,-0.01194240,0.00000000,0.00000000,0.00000000,0.00000000
55.50000000,0.25616800,8.18150000,0.00838578,544.14927527,0.00835081,548.71239017,0.00036497,0.02584350,696.83026224,-0.01348217,-0.01236133,0.00000000,0.00000000,0.00000000,0.00000000
57.00000000,0.27583000,8.29070000,0.00905778,551.41213671,0.00901700,556.40670530,0.00023808,0.02683630,701.19734338,-0.01403113,-0.01280517,0.00000000,0.00000000,0.00000000,0.00000000
58.50000000,0.29684400,8.39280000,0.00976356,558.20277913,0.00971620,563.65282298,0.00026785,0.02784112,705.08539445,-0.01458796,-0.01325316,0.00000000,0.00000000,0.00000000,0.00000000
60.00000000,0.31840200,8.50520000,0.01052567,565.67847167,0.01047066,571.63261471,0.00039389,0.02880633,709.45562626,-0.01507309,-0.01373325,0.00000000,0.00000000,0.00000000,0.00000000
61.50000000,0.34165000,8.60730000,0.01126900,572.46911410,0.01120598,578.92026855,0.00046042,0.02976419,713.65607959,-0.01558026,-0.01418392,0.00000000,0.00000000,0.00000000,0.00000000
63.00000000,0.36442700,8.70700000,0.01198233,579.10013320,0.01191111,586.03910403,0.00040035,0.03078575,717.19867224,-0.01614763,-0.01463812,0.00000000,0.00000000,0.00000000,0.00000000
64.50000000,0.38683100,8.80590000,0.01276722,585.67794452,0.01268641,593.15542499,0.00034145,0.03175911,721.53566339,-0.01665688,-0.01510223,0.00000000,0.00000000,0.00000000,0.00000000
66.00000000,0.41062200,8.89680000,0.01357811,591.72367808,0.01348675,599.75816793,0.00042955,0.03277045,725.25084161,-0.01722503,-0.01554542,0.00000000,0.00000000,0.00000000,0.00000000
67.50000000,0.43448200,8.98770000,0.01436678,597.76941164,0.01426455,606.35743194,0.00052585,0.03376566,729.12045327,-0.01770235,-0.01606330,0.00000000,0.00000000,0.00000000,0.00000000
69.00000000,0.46006400,9.07940000,0.01518911,603.86835297,0.01507491,613.04057648,0.00051798,0.03479590,733.02989932,-0.01829399,-0.01650190,0.00000000,0.00000000,0.00000000,0.00000000
70.50000000,0.48432900,9.16710000,0.01602289,609.70125543,0.01589588,619.47043090,0.00048080,0.03581924,736.60845398,-0.01885262,-0.01696663,0.00000000,0.00000000,0.00000000,0.00000000
72.00000000,0.50977700,9.24770000,0.01684522,615.06193887,0.01670491,625.42279391,0.00045811,0.03685342,739.97239556,-0.01942754,-0.01742588,0.00000000,0.00000000,0.00000000,0.00000000
73.50000000,0.53539600,9.33060000,0.01774267,620.57559467,0.01758710,631.58626059,0.00057565,0.03789971,743.58124048,-0.01998584,-0.01791388,0.00000000,0.00000000,0.00000000,0.00000000
75.00000000,0.56229700,9.41440000,0.01857267,626.14910922,0.01840230,637.77836791,0.00054572,0.03893380,746.51921478,-0.02058624,-0.01834756,0.00000000,0.00000000,0.00000000,0.00000000
76.50000000,0.58855700,9.48290000,0.01944389,630.70502505,0.01925727,642.96838348,0.00050840,0.03998374,750.36688081,-0.02122435,-0.01875940,0.00000000,0.00000000,0.00000000,0.00000000
78.00000000,0.61566200,9.56350000,0.02035633,636.06570849,0.02015191,649.01367407,0.00049313,0.04108471,753.14379317,-0.02185486,-0.01922985,0.00000000,0.00000000,0.00000000,0.00000000
79.50000000,0.64287000,9.63370000,0.02129911,640.73469084,0.02107546,654.38177022,0.00060324,0.04214184,756.50762053,-0.02241015,-0.01973169,0.00000000,0.00000000,0.00000000,0.00000000
81.00000000,0.67048000,9.70230000,0.02218533,645.29725765,0.02194282,659.61339241,0.00055118,0.04320535,759.82672995,-0.02301883,-0.02018652,0.00000000,0.00000000,0.00000000,0.00000000
82.50000000,0.69876800,9.77560000,0.02312044,650.17242013,0.02285722,665.20469545,0.00058740,0.04428902,763.16058759,-0.02359923,-0.02068980,0.00000000,0.00000000,0.00000000,0.00000000
84.00000000,0.72712300,9.84180000,0.02404800,654.57536360,0.02376340,670.31659195,0.00051350,0.04538855,766.68835264,-0.02420935,-0.02117920,0.00000000,0.00000000,0.00000000,0.00000000
85.50000000,0.75615600,9.89600000,0.02502822,658.18019044,0.02472015,674.65327050,0.00062295,0.04647804,769.04319449,-0.02479502,-0.02168302,0.00000000,0.00000000,0.00000000,0.00000000
87.00000000,0.78498500,9.96700000,0.02597833,662.90238056,0.02564663,680.12347957,0.00060786,0.04758503,771.97095301,-0.02539442,-0.02219060,0.00000000,0.00000000,0.00000000,0.00000000
88.50000000,0.81472900,10.02440000,0.02694356,666.72003850,0.02658697,684.68384690,0.00062201,0.04871920,774.92548133,-0.02602796,-0.02269124,0.00000000,0.00000000,0.00000000,0.00000000
90.00000000,0.84403100,10.08260000,0.02792744,670.59090421,0.02754459,689.31879443,0.00056259,0.04984607,777.65472752,-0.02661411,-0.02323196,0.00000000,0.00000000,0.00000000,0.00000000
91.50000000,0.87377400,10.13770000,0.02897522,674.25558979,0.02856338,693.79229534,0.00064994,0.05095317,780.48653538,-0.02721201,-0.02374117,0.00000000,0.00000000,0.00000000,0.00000000
93.00000000,0.90402400,10.19110000,0.02996289,677.80720885,0.02952277,698.11627093,0.00072205,0.05207599,783.50551113,-0.02783862,-0.02423738,0.00000000,0.00000000,0.00000000,0.00000000
94.50000000,0.93461200,10.24770000,0.03094689,681.57165901,0.03047769,702.66418141,0.00060471,0.05320739,785.97176781,-0.02849854,-0.02470886,0.00000000,0.00000000,0.00000000,0.00000000
96.00000000,0.96547100,10.29720000,0.03198344,684.86389015,0.03148262,706.76819634,0.00056792,0.05436094,788.68660393,-0.02909461,-0.02526633,0.00000000,0.00000000,0.00000000,0.00000000
97.50000000,0.99673400,10.34740000,0.03303500,688.20267810,0.03250107,710.93745357,0.00063276,0.05549899,791.40150032,-0.02973867,-0.02576032,0.00000000,0.00000000,0.00000000,0.00000000
99.00000000,1.02752500,10.40800000,0.03403400,692.23316714,0.03346766,715.79263075,0.00061022,0.05662629,793.87901487,-0.03037756,-0.02624873,0.00000000,0.00000000,0.00000000,0.00000000
100.50000000,1.05916200,10.44390000,0.03506678,694.62086610,0.03446594,718.97898165,0.00052993,0.05779361,796.56357694,-0.03102796,-0.02676565,0.00000000,0.00000000,0.00000000,0.00000000
102.00000000,1.09100000,10.48540000,0.03617078,697.38101948,0.03553197,722.60583336,0.00067396,0.05895011,799.01722119,-0.03163584,-0.02731426,0.00000000,0.00000000,0.00000000,0.00000000
103.50000000,1.12294200,10.53160000,0.03722989,700.45376855,0.03655359,726.53158453,0.00065913,0.06008330,801.63470849,-0.03226679,-0.02781651,0.00000000,0.00000000,0.00000000,0.00000000
105.00000000,1.15528900,10.57630000,0.03828144,703.42675304,0.03756689,730.35494521,0.00065846,0.06122024,803.91105418,-0.03290177,-0.02831847,0.00000000,0.00000000,0.00000000,0.00000000
106.50000000,1.18773600,10.62090000,0.03940067,706.39308656,0.03864426,734.22544510,0.00071550,0.06242257,806.24450266,-0.03353361,-0.02888896,0.00000000,0.00000000,0.00000000,0.00000000
108.00000000,1.22075700,10.66000000,0.04048978,708.99361662,0.03969154,737.70061060,0.00072928,0.06358082,808.66810098,-0.03420480,-0.02937602,0.00000000,0.00000000,0.00000000,0.00000000
109.50000000,1.25374500,10.69910000,0.04157133,711.59414667,0.04073047,741.17606414,0.00070675,0.06474195,810.91985482,-0.03483346,-0.02990850,0.00000000,0.00000000,0.00000000,0.00000000
111.00000000,1.28673500,10.73820000,0.04265678,714.19467673,0.04177205,744.65992035,0.00066295,0.06591478,813.36433031,-0.03544571,-0.03046908,0.00000000,0.00000000,0.00000000,0.00000000
112.50000000,1.32040000,10.77090000,0.04376844,716.36954458,0.04283767,747.72392519,0.00069802,0.06713510,815.84519976,-0.03612972,-0.03100537,0.00000000,0.00000000,0.00000000,0.00000000
114.00000000,1.35403000,10.81150000,0.04492511,719.06983922,0.04394522,751.37413164,0.00077660,0.06833254,817.68777315,-0.03682365,-0.03150889,0.00000000,0.00000000,0.00000000,0.00000000
115.50000000,1.38836900,10.84580000,0.04604422,721.35112262,0.04501564,754.56517401,0.00068906,0.06952315,819.92321233,-0.03746338,-0.03205977,0.00000000,0.00000000,0.00000000,0.00000000
117.00000000,1.42247400,10.87770000,0.04716344,723.47278269,0.04608503,757.59425108,0.00068153,0.07068542,821.91644906,-0.03812078,-0.03256464,0.00000000,0.00000000,0.00000000,0.00000000
118.50000000,1.45695000,10.91280000,0.04833900,725.80727387,0.04720701,760.89207168,0.00076686,0.07187414,823.92792661,-0.03877485,-0.03309929,0.00000000,0.00000000,0.00000000,0.00000000
120.00000000,1.49216800,10.94390000,0.04949189,727.87572616,0.04830613,763.89967073,0.00076602,0.07308727,826.36716404,-0.03945503,-0.03363225,0.00000000,0.00000000,0.00000000,0.00000000
121.50000000,1.52715000,10.97420000,0.05064478,729.89097068,0.04940405,766.85613669,0.00072921,0.07432200,828.31644036,-0.04014453,-0.03417747,0.00000000,0.00000000,0.00000000,0.00000000
123.00000000,1.56216600,11.00530000,0.05179033,731.95942298,0.05049379,769.86784548,0.00070728,0.07551907,830.58494701,-0.04078974,-0.03472933,0.00000000,0.00000000,0.00000000,0.00000000
124.50000000,1.59769100,11.03160000,0.05298467,733.70862862,0.05162867,772.58393574,0.00073519,0.07676172,832.42533027,-0.04146775,-0.03529398,0.00000000,0.00000000,0.00000000,0.00000000
126.00000000,1.63365400,11.06590000,0.05420511,735.98991202,0.05278703,775.88432698,0.00075542,0.07794359,834.34132845,-0.04212868,-0.03581491,0.00000000,0.00000000,0.00000000,0.00000000
127.50000000,1.66961600,11.09460000,0.05541444,737.89874099,0.05393353,778.78898977,0.00076867,0.07919900,836.48938526,-0.04281257,-0.03638643,0.00000000,0.00000000,0.00000000,0.00000000
129.00000000,1.70601900,11.12100000,0.05658244,739.65459760,0.05503959,781.50606277,0.00073963,0.08042516,837.92667408,-0.04350580,-0.03691936,0.00000000,0.00000000,0.00000000,0.00000000
130.50000000,1.74161000,11.14810000,0.05777678,741.45701101,0.05616933,784.29600797,0.00072471,0.08165674,840.06920350,-0.04418450,-0.03747224,0.00000000,0.00000000,0.00000000,0.00000000
132.00000000,1.77821600,11.16880000,0.05900478,742.83376222,0.05732958,786.66450329,0.00075893,0.08288856,841.85906814,-0.04486956,-0.03801900,0.00000000,0.00000000,0.00000000,0.00000000
133.50000000,1.81492300,11.19990000,0.06024411,744.90221452,0.05849918,789.77818629,0.00076517,0.08418293,843.88740899,-0.04560229,-0.03858064,0.00000000,0.00000000,0.00000000,0.00000000
135.00000000,1.85193400,11.22380000,0.06146844,746.49179683,0.05965327,792.37748637,0.00077141,0.08539796,845.61856856,-0.04624523,-0.03915273,0.00000000,0.00000000,0.00000000,0.00000000
136.50000000,1.88877500,11.24380000,0.06270033,747.82199123,0.06081315,794.71067935,0.00081298,0.08667234,847.57138696,-0.04696509,-0.03970725,0.00000000,0.00000000,0.00000000,0.00000000
138.00000000,1.92605700,11.26850000,0.06392456,749.46478132,0.06196448,797.37398437,0.00075542,0.08790118,849.37917412,-0.04762778,-0.04027340,0.00000000,0.00000000,0.00000000,0.00000000
139.50000000,1.96317000,11.29000000,0.06517900,750.89474030,0.06314286,799.83730858,0.00077582,0.08916245,851.21787340,-0.04834220,-0.04082025,0.00000000,0.00000000,0.00000000,0.00000000
141.00000000,2.00102500,11.30840000,0.06641822,752.11851915,0.06430558,802.07289409,0.00080994,0.09043334,852.88463003,-0.04903335,-0.04139999,0.00000000,0.00000000,0.00000000,0.00000000
142.50000000,2.03864500,11.32990000,0.06769156,753.54847813,0.06549889,804.55734680,0.00090100,0.09167650,855.00816745,-0.04967561,-0.04200089,0.00000000,0.00000000,0.00000000,0.00000000
144.00000000,2.07677200,11.35300000,0.06891578,755.08485267,0.06664484,807.12211258,0.00076603,0.09295443,856.63580737,-0.05040613,-0.04254829,0.00000000,0.00000000,0.00000000,0.00000000
145.50000000,2.11503400,11.36900000,0.07018144,756.14900819,0.06782821,809.21663780,0.00079317,0.09422355,858.36916951,-0.05110273,-0.04312082,0.00000000,0.00000000,0.00000000,0.00000000
147.00000000,2.15309300,11.38730000,0.07145833,757.36613607,0.06902065,811.48625788,0.00083434,0.09553288,859.85254983,-0.05185766,-0.04367522,0.00000000,0.00000000,0.00000000,0.00000000
148.50000000,2.19149100,11.40730000,0.07273911,758.69633047,0.07021529,813.88322715,0.00085469,0.09683180,861.74307257,-0.05255665,-0.04427515,0.00000000,0.00000000,0.00000000,0.00000000
150.00000000,2.22955000,11.42720000,0.07405356,760.01987390,0.07143986,816.30204786,0.00083957,0.09808768,863.06716607,-0.05328937,-0.04479830,0.00000000,0.00000000,0.00000000,0.00000000
151.50000000,2.26835400,11.44230000,0.07532667,761.02417068,0.07262449,818.34958471,0.00079640,0.09938053,864.83270769,-0.05399820,-0.04538233,0.00000000,0.00000000,0.00000000,0.00000000
153.00000000,2.30762900,11.46070000,0.07656978,762.24794953,0.07377985,820.61310563,0.00070463,0.10065913,866.35908211,-0.05469825,-0.04596088,0.00000000,0.00000000,0.00000000,0.00000000
154.50000000,2.34656800,11.47740000,0.07784289,763.35866185,0.07496172,822.78070535,0.00072483,0.10196953,867.97508368,-0.05546416,-0.04650536,0.00000000,0.00000000,0.00000000,0.00000000
156.00000000,2.38543900,11.49180000,0.07919111,764.31640182,0.07621179,824.84346692,0.00082836,0.10323596,869.25804064,-0.05614930,-0.04708666,0.00000000,0.00000000,0.00000000,0.00000000
157.50000000,2.42522200,11.50770000,0.08053189,765.37390637,0.07745341,827.01091276,0.00086211,0.10456533,871.13397003,-0.05689999,-0.04766534,0.00000000,0.00000000,0.00000000,0.00000000
159.00000000,2.46557900,11.52130000,0.08181256,766.27843857,0.07863793,828.96963589,0.00074313,0.10587728,872.75953193,-0.05763384,-0.04824344,0.00000000,0.00000000,0.00000000,0.00000000
160.50000000,2.50522700,11.53640000,0.08316089,767.28273534,0.07988352,831.09064964,0.00081855,0.10721624,873.98604396,-0.05836890,-0.04884733,0.00000000,0.00000000,0.00000000,0.00000000
162.00000000,2.54517900,11.54920000,0.08449400,768.13405976,0.08111352,833.03677900,0.00077573,0.10851823,875.54810201,-0.05910920,-0.04940903,0.00000000,0.00000000,0.00000000,0.00000000
163.50000000,2.58570700,11.56280000,0.08584989,769.03859195,0.08236299,835.06046962,0.00089269,0.10985056,877.43890177,-0.05981870,-0.05003186,0.00000000,0.00000000,0.00000000,0.00000000
165.00000000,2.62643700,11.57550000,0.08717556,769.88326540,0.08358310,836.99826677,0.00080163,0.11115068,878.64518432,-0.06053816,-0.05061252,0.00000000,0.00000000,0.00000000,0.00000000
166.50000000,2.66669200,11.58510000,0.08853133,770.52175871,0.08482939,838.73707737,0.00082820,0.11248021,880.35945361,-0.06126083,-0.05121938,0.00000000,0.00000000,0.00000000,0.00000000
168.00000000,2.70749000,11.59940000,0.08989467,771.47284771,0.08608106,840.82414220,0.00084797,0.11390935,881.80421056,-0.06210532,-0.05180403,0.00000000,0.00000000,0.00000000,0.00000000
169.50000000,2.74852400,11.60660000,0.09126544,771.95171769,0.08733798,842.40423430,0.00088113,0.11520407,883.07188023,-0.06279486,-0.05240921,0.00000000,0.00000000,0.00000000,0.00000000
171.00000000,2.78989800,11.61860000,0.09263244,772.74983434,0.08858987,844.33154043,0.00077687,0.11656300,884.45868353,-0.06353164,-0.05303136,0.00000000,0.00000000,0.00000000,0.00000000
172.50000000,2.83157400,11.63370000,0.09401456,773.75413111,0.08985401,846.49828186,0.00085859,0.11788557,886.10961033,-0.06428757,-0.05359800,0.00000000,0.00000000,0.00000000,0.00000000
174.00000000,2.87301300,11.64170000,0.09537778,774.28620887,0.09109931,848.13590684,0.00078182,0.11927445,887.40684544,-0.06508302,-0.05419143,0.00000000,0.00000000,0.00000000,0.00000000
175.50000000,2.91445200,11.65130000,0.09677111,774.92470218,0.09237051,849.91502664,0.00084934,0.12059536,888.64533407,-0.06581888,-0.05477648,0.00000000,0.00000000,0.00000000,0.00000000
177.00000000,2.95677100,11.66720000,0.09813822,775.98220673,0.09361622,852.13572098,0.00080071,0.12194566,890.27553737,-0.06653578,-0.05540988,0.00000000,0.00000000,0.00000000,0.00000000
178.50000000,2.99871700,11.67440000,0.09956522,776.46107672,0.09491485,853.76959637,0.00084031,0.12329518,891.72572485,-0.06721146,-0.05608372,0.00000000,0.00000000,0.00000000,0.00000000
180.00000000,3.04059600,11.68160000,0.10095111,776.93994670,0.09617445,855.37289759,0.00085298,0.12467706,892.90331938,-0.06801616,-0.05666090,0.00000000,0.00000000,0.00000000,0.00000000
181.50000000,3.08311700,11.68880000,0.10236689,777.41881669,0.09745959,857.00076232,0.00085188,0.12605578,894.32311320,-0.06878200,-0.05727378,0.00000000,0.00000000,0.00000000,0.00000000
183.00000000,3.12590900,11.69750000,0.10383544,777.99745125,0.09879088,858.78116238,0.00095971,0.12736768,895.56313247,-0.06946130,-0.05790639,0.00000000,0.00000000,0.00000000,0.00000000
184.50000000,3.16849700,11.70710000,0.10522122,778.63594457,0.10004552,860.56497032,0.00083621,0.12874343,896.86237313,-0.07024729,-0.05849614,0.00000000,0.00000000,0.00000000,0.00000000
186.00000000,3.21108600,11.71110000,0.10665578,778.90198345,0.10134265,861.97638031,0.00081463,0.00000000,0.00000000,0.00000000,0.00000000,0.00000000,0.00000000,0.00000000,0.00000000
187.50000000,3.25435100,11.71910000,0.10807911,779.43406121,0.10262799,863.67460171,0.00086093,0.00000000,0.00000000,0.00000000,0.00000000,0.00000000,0.00000000,0.00000000,0.00000000
189.00000000,3.29765000,11.72620000,0.10947633,779.90628022,0.10388813,865.28756012,0.00077870,0.00000000,0.00000000,0.00000000,0.00000000,0.00000000,0.00000000,0.00000000,0.00000000
190.50000000,3.34121900,11.73020000,0.11095978,780.17231910,0.10522431,866.74006626,0.00087931,0.00000000,0.00000000,0.00000000,0.00000000,0.00000000,0.00000000,0.00000000,0.00000000
192.00000000,3.38458500,11.73500000,0.11242067,780.49156576,0.10653842,868.23494791,0.00087136,0.00000000,0.00000000,0.00000000,0.00000000,0.00000000,0.00000000,0.00000000,0.00000000
193.50000000,3.42866200,11.74060000,0.11392289,780.86402019,0.10788792,869.82230520,0.00102527,0.00000000,0.00000000,0.00000000,0.00000000,0.00000000,0.00000000,0.00000000,0.00000000
195.00000000,3.47240000,11.75100000,0.11535011,781.55572128,0.10916836,871.70826057,0.00090954,0.00000000,0.00000000,0.00000000,0.00000000,0.00000000,0.00000000,0.00000000,0.00000000
196.50000000,3.51694800,11.75810000,0.11680344,782.02794029,0.11047054,873.37149737,0.00087451,0.00000000,0.00000000,0.00000000,0.00000000,0.00000000,0.00000000,0.00000000,0.00000000
198.00000000,3.56132800,11.75970000,0.11826811,782.13435585,0.11178116,874.63590875,0.00080617,0.00000000,0.00000000,0.00000000,0.00000000,0.00000000,0.00000000,0.00000000,0.00000000
199.50000000,3.60581000,11.76610000,0.11977033,782.56001806,0.11312360,876.28749227,0.00087219,0.00000000,0.00000000,0.00000000,0.00000000,0.00000000,0.00000000,0.00000000,0.00000000
201.00000000,3.65063000,11.76770000,0.12127256,782.66643361,0.11446425,877.58239216,0.00087083,0.00000000,0.00000000,0.00000000,0.00000000,0.00000000,0.00000000,0.00000000,0.00000000
202.50000000,3.69555100,11.77650000,0.12277478,783.25171914,0.11580310,879.41527491,0.00093679,0.00000000,0.00000000,0.00000000,0.00000000,0.00000000,0.00000000,0.00000000,0.00000000
204.00000000,3.74155200,11.77810000,0.12435222,783.35813470,0.11720707,880.77045954,0.00106935,0.00000000,0.00000000,0.00000000,0.00000000,0.00000000,0.00000000,0.00000000,0.00000000
205.50000000,3.78735200,11.78130000,0.12581678,783.57096580,0.11850880,882.15733988,0.00080076,0.00000000,0.00000000,0.00000000,0.00000000,0.00000000,0.00000000,0.00000000,0.00000000
207.00000000,3.83298300,11.78610000,0.12735656,783.89021246,0.11987556,883.72376985,0.00093278,0.00000000,0.00000000,0.00000000,0.00000000,0.00000000,0.00000000,0.00000000,0.00000000
208.50000000,3.87922300,11.78920000,0.12885878,784.09639259,0.12120719,885.13409540,0.00086497,0.00000000,0.00000000,0.00000000,0.00000000,0.00000000,0.00000000,0.00000000,0.00000000
210.00000000,3.92556300,11.79080000,0.13043611,784.20280814,0.12260350,886.49117276,0.00099672,0.00000000,0.00000000,0.00000000,0.00000000,0.00000000,0.00000000,0.00000000,0.00000000
211.50000000,3.97193700,11.79320000,0.13197589,784.36243147,0.12396468,887.87936058,0.00092898,0.00000000,0.00000000,0.00000000,0.00000000,0.00000000,0.00000000,0.00000000,0.00000000
213.00000000,4.01858200,11.79640000,0.13344056,784.57526258,0.12525775,889.26942149,0.00086148,0.00000000,0.00000000,0.00000000,0.00000000,0.00000000,0.00000000,0.00000000,0.00000000
214.50000000,4.06556500,11.80520000,0.13501800,785.16054811,0.12664851,891.17135500,0.00092688,0.00000000,0.00000000,0.00000000,0.00000000,0.00000000,0.00000000,0.00000000,0.00000000
216.00000000,4.11298700,11.79640000,0.13655778,784.57526258,0.12800420,891.71511693,0.00092542,0.00000000,0.00000000,0.00000000,0.00000000,0.00000000,0.00000000,0.00000000,0.00000000
217.50000000,4.16024100,11.80440000,0.13809744,785.10734034,0.12935796,893.52865765,0.00085795,0.00000000,0.00000000,0.00000000,0.00000000,0.00000000,0.00000000,0.00000000,0.00000000
219.00000000,4.20745900,11.80040000,0.13963722,784.84130146,0.13070999,894.43436068,0.00079105,0.00000000,0.00000000,0.00000000,0.00000000,0.00000000,0.00000000,0.00000000,0.00000000
220.50000000,4.25528700,11.80440000,0.14121456,785.10734034,0.13209309,895.97592447,0.00092165,0.00000000,0.00000000,0.00000000,0.00000000,0.00000000,0.00000000,0.00000000,0.00000000
222.00000000,4.30402700,11.81080000,0.14279200,785.53300255,0.13347439,897.70083104,0.00092038,0.00000000,0.00000000,0.00000000,0.00000000,0.00000000,0.00000000,0.00000000,0.00000000
223.50000000,4.35232800,11.80760000,0.14433167,785.32017144,0.00000000,0.00000000,0.00000000,0.00000000,0.00000000,0.00000000,0.00000000,0.00000000,0.00000000,0.00000000,0.00000000
225.00000000,4.40042600,11.81000000,0.14590900,785.47979477,0.00000000,0.00000000,0.00000000,0.00000000,0.00000000,0.00000000,0.00000000,0.00000000,0.00000000,0.00000000,0.00000000
226.50000000,4.44936900,11.80920000,0.14748633,785.42658699,0.00000000,0.00000000,0.00000000,0.00000000,0.00000000,0.00000000,0.00000000,0.00000000,0.00000000,0.00000000,0.00000000
228.00000000,4.49834600,11.81080000,0.14910122,785.53300255,0.00000000,0.00000000,0.00000000,0.00000000,0.00000000,0.00000000,0.00000000,0.00000000,0.00000000,0.00000000,0.00000000
229.50000000,4.54799900,11.81000000,0.15064100,785.47979477,0.00000000,0.00000000,0.00000000,0.00000000,0.00000000,0.00000000,0.00000000,0.00000000,0.00000000,0.00000000,0.00000000
231.00000000,4.59714500,11.80920000,0.15214322,785.42658699,0.00000000,0.00000000,0.00000000,0.00000000,0.00000000,0.00000000,0.00000000,0.00000000,0.00000000,0.00000000,0.00000000
232.50000000,4.64666200,11.80920000,0.15375822,785.42658699,0.00000000,0.00000000,0.00000000,0.00000000,0.00000000,0.00000000,0.00000000,0.00000000,0.00000000,0.00000000,0.00000000
234.00000000,4.69709200,11.80600000,0.15526033,785.21375589,0.00000000,0.00000000,0.00000000,0.00000000,0.00000000,0.00000000,0.00000000,0.00000000,0.00000000,0.00000000,0.00000000
235.50000000,4.74738700,11.80760000,0.15683767,785.32017144,0.00000000,0.00000000,0.00000000,0.00000000,0.00000000,0.00000000,0.00000000,0.00000000,0.00000000,0.00000000,0.00000000
237.00000000,4.79802000,11.79880000,0.15830233,784.73488590,0.00000000,0.00000000,0.00000000,0.00000000,0.00000000,0.00000000,0.00000000,0.00000000,0.00000000,0.00000000,0.00000000
238.50000000,4.84882300,11.80120000,0.15980456,784.89450923,0.00000000,0.00000000,0.00000000,0.00000000,0.00000000,0.00000000,0.00000000,0.00000000,0.00000000,0.00000000,0.00000000
240.00000000,4.90009800,11.79880000,0.16126922,784.73488590,0.00000000,0.00000000,0.00000000,0.00000000,0.00000000,0.00000000,0.00000000,0.00000000,0.00000000,0.00000000,0.00000000
241.50000000,4.95157600,11.78920000,0.16265878,784.09639259,0.00000000,0.00000000,0.00000000,0.00000000,0.00000000,0.00000000,0.00000000,0.00000000,0.00000000,0.00000000,0.00000000
243.00000000,5.00271500,11.79400000,0.16412344,784.41563925,0.00000000,0.00000000,0.00000000,0.00000000,0.00000000,0.00000000,0.00000000,0.00000000,0.00000000,0.00000000,0.00000000
244.50000000,5.05534300,11.78920000,0.16547533,784.09639259,0.00000000,0.00000000,0.00000000,0.00000000,0.00000000,0.00000000,0.00000000,0.00000000,0.00000000,0.00000000,0.00000000
246.00000000,5.10847700,11.78370000,0.16678989,783.73058913,0.00000000,0.00000000,0.00000000,0.00000000,0.00000000,0.00000000,0.00000000,0.00000000,0.00000000,0.00000000,0.00000000
247.50000000,5.16188200,11.78210000,0.16810422,783.62417358,0.00000000,0.00000000,0.00000000,0.00000000,0.00000000,0.00000000,0.00000000,0.00000000,0.00000000,0.00000000,0.00000000
249.00000000,5.21545500,11.77570000,0.16934367,783.19851137,0.00000000,0.00000000,0.00000000,0.00000000,0.00000000,0.00000000,0.00000000,0.00000000,0.00000000,0.00000000,0.00000000
250.50000000,5.26950100,11.76850000,0.17050778,782.71964138,0.00000000,0.00000000,0.00000000,0.00000000,0.00000000,0.00000000,0.00000000,0.00000000,0.00000000,0.00000000,0.00000000
252.00000000,5.32368300,11.75890000,0.17152178,782.08114807,0.00000000,0.00000000,0.00000000,0.00000000,0.00000000,0.00000000,0.00000000,0.00000000,0.00000000,0.00000000,0.00000000
253.50000000,5.37867700,11.75340000,0.17257333,781.71534461,0.00000000,0.00000000,0.00000000,0.00000000,0.00000000,0.00000000,0.00000000,0.00000000,0.00000000,0.00000000,0.00000000
255.00000000,5.43417700,11.74300000,0.17339956,781.02364352,0.00000000,0.00000000,0.00000000,0.00000000,0.00000000,0.00000000,0.00000000,0.00000000,0.00000000,0.00000000,0.00000000
256.50000000,5.48988000,11.73020000,0.17426333,780.17231910,0.00000000,0.00000000,0.00000000,0.00000000,0.00000000,0.00000000,0.00000000,0.00000000,0.00000000,0.00000000,0.00000000
258.00000000,5.54680000,11.71910000,0.17493933,779.43406121,0.00000000,0.00000000,0.00000000,0.00000000,0.00000000,0.00000000,0.00000000,0.00000000,0.00000000,0.00000000,0.00000000
259.50000000,5.60392200,11.70550000,0.17554022,778.52952902,0.00000000,0.00000000,0.00000000,0.00000000,0.00000000,0.00000000,0.00000000,0.00000000,0.00000000,0.00000000,0.00000000
261.00000000,5.66192300,11.69040000,0.17602833,777.52523224,0.00000000,0.00000000,0.00000000,0.00000000,0.00000000,0.00000000,0.00000000,0.00000000,0.00000000,0.00000000,0.00000000
262.50000000,5.72043100,11.67280000,0.17647900,776.35466117,0.00000000,0.00000000,0.00000000,0.00000000,0.00000000,0.00000000,0.00000000,0.00000000,0.00000000,0.00000000,0.00000000
264.00000000,5.77951400,11.65930000,0.17681700,775.45677995,0.00000000,0.00000000,0.00000000,0.00000000,0.00000000,0.00000000,0.00000000,0.00000000,0.00000000,0.00000000,0.00000000
265.50000000,5.83910400,11.65050000,0.17704233,774.87149441,0.00000000,0.00000000,0.00000000,0.00000000,0.00000000,0.00000000,0.00000000,0.00000000,0.00000000,0.00000000,0.00000000
267.00000000,5.89970600,11.61060000,0.17726767,772.21775657,0.00000000,0.00000000,0.00000000,0.00000000,0.00000000,0.00000000,0.00000000,0.00000000,0.00000000,0.00000000,0.00000000
268.50000000,5.96007200,11.58110000,0.17734278,770.25571983,0.00000000,0.00000000,0.00000000,0.00000000,0.00000000,0.00000000,0.00000000,0.00000000,0.00000000,0.00000000,0.00000000
270.00000000,6.02131600,11.55000000,0.17745544,768.18726753,0.00000000,0.00000000,0.00000000,0.00000000,0.00000000,0.00000000,0.00000000,0.00000000,0.00000000,0.00000000,0.00000000
271.50000000,6.08283100,11.51810000,0.17753056,766.06560746,0.00000000,0.00000000,0.00000000,0.00000000,0.00000000,0.00000000,0.00000000,0.00000000,0.00000000,0.00000000,0.00000000
273.00000000,6.14454700,11.47900000,0.17756811,763.46507741,0.00000000,0.00000000,0.00000000,0.00000000,0.00000000,0.00000000,0.00000000,0.00000000,0.00000000,0.00000000,0.00000000
274.50000000,6.20683700,11.44150000,0.17760567,760.97096290,0.00000000,0.00000000,0.00000000,0.00000000,0.00000000,0.00000000,0.00000000,0.00000000,0.00000000,0.00000000,0.00000000
276.00000000,6.26919400,11.39370000,0.17760578,757.79179828,0.00000000,0.00000000,0.00000000,0.00000000,0.00000000,0.00000000,0.00000000,0.00000000,0.00000000,0.00000000,0.00000000
277.50000000,6.33303800,11.34110000,0.17753078,754.29338700,0.00000000,0.00000000,0.00000000,0.00000000,0.00000000,0.00000000,0.00000000,0.00000000,0.00000000,0.00000000,0.00000000
279.00000000,6.39674600,11.28050000,0.17753078,750.26289796,0.00000000,0.00000000,0.00000000,0.00000000,0.00000000,0.00000000,0.00000000,0.00000000,0.00000000,0.00000000,0.00000000
280.50000000,6.46096200,11.20870000,0.17749333,745.48750005,0.00000000,0.00000000,0.00000000,0.00000000,0.00000000,0.00000000,0.00000000,0.00000000,0.00000000,0.00000000,0.00000000
282.00000000,6.52562100,11.13050000,0.17749356,740.28643994,0.00000000,0.00000000,0.00000000,0.00000000,0.00000000,0.00000000,0.00000000,0.00000000,0.00000000,0.00000000,0.00000000
283.50000000,6.59191000,11.03480000,0.17745622,733.92145972,0.00000000,0.00000000,0.00000000,0.00000000,0.00000000,0.00000000,0.00000000,0.00000000,0.00000000,0.00000000,0.00000000
285.00000000,6.66047900,10.89850000,0.17738144,724.85618487,0.00000000,0.00000000,0.00000000,0.00000000,0.00000000,0.00000000,0.00000000,0.00000000,0.00000000,0.00000000,0.00000000
286.50000000,6.73279000,10.71900000,0.17730689,712.91769010,0.00000000,0.00000000,0.00000000,0.00000000,0.00000000,0.00000000,0.00000000,0.00000000,0.00000000,0.00000000,0.00000000
287.50000000,6.78849100,10.51890000,0.17715722,699.60909511,0.00000000,0.00000000,0.00000000,0.00000000,0.00000000,0.00000000,0.00000000,0.00000000,0.00000000,0.00000000,0.00000000