File: polyN_optimization/DP780_results/DATA/UT_45_3.csv
Time[s],Displacement[mm],Force[kN],EngStrain_longi,EngStress[MPa],TrueStrain,TrueStress[MPa],TrueStrainRate[1/s],PlasticStrain_longi,PlasticStress[MPa],PlasticStrain_thick,PlasticStrain_width,R-Value,Thickness[mm],Width[mm], Young's Modulus [MPa]
0.00000000,0.00000000,-0.01820000,0.00000000,-1.21135557,0.00000000,-1.21135557,0.00000000,0.00057966,417.69800805,0.00038518,-0.00096484,0.84648299,1.51050000,9.94670000,210283.37950170
1.50000000,0.00229900,0.35420000,0.00007333,23.57484292,0.00007333,23.57657174,0.00001422,0.00073691,430.98539821,0.00011592,-0.00085283,0.00000000,0.00000000,0.00000000,0.00000000
3.00000000,0.00347500,0.69640000,0.00010700,46.35098987,0.00010699,46.35594942,-0.00002644,0.00104124,442.59110341,0.00004419,-0.00108542,0.00000000,0.00000000,0.00000000,0.00000000
4.50000000,0.00553400,1.02410000,0.00020656,68.16204584,0.00020653,68.17612509,0.00005177,0.00131166,454.12944227,-0.00012340,-0.00118826,0.00000000,0.00000000,0.00000000,0.00000000
6.00000000,0.00761000,1.35350000,0.00025311,90.08625041,0.00025308,90.10905224,-0.00000533,0.00152012,466.08155629,-0.00020844,-0.00131168,0.00000000,0.00000000,0.00000000,0.00000000
7.50000000,0.01075200,1.64220000,0.00034078,109.30154446,0.00034072,109.33879200,0.00002866,0.00188080,476.77318990,-0.00029846,-0.00158234,0.00000000,0.00000000,0.00000000,0.00000000
9.00000000,0.01245400,1.91730000,0.00042644,127.61164974,0.00042635,127.66606901,0.00019681,0.00223380,487.41620134,-0.00052177,-0.00171203,0.00000000,0.00000000,0.00000000,0.00000000
10.50000000,0.01559400,2.20200000,0.00050200,146.56071179,0.00050187,146.63428527,0.00022390,0.00257243,499.39481609,-0.00079086,-0.00178158,0.00000000,0.00000000,0.00000000,0.00000000
12.00000000,0.01570600,2.46040000,0.00052433,163.75929850,0.00052420,163.84516296,0.00021412,0.00313823,508.39965600,-0.00107909,-0.00205915,0.00000000,0.00000000,0.00000000,0.00000000
13.50000000,0.01862400,2.71320000,0.00061811,180.58516041,0.00061792,180.69678211,-0.00006107,0.00361016,518.27956820,-0.00121075,-0.00239941,0.00000000,0.00000000,0.00000000,0.00000000
15.00000000,0.02083400,2.97400000,0.00068367,197.94348632,0.00068343,198.07881368,-0.00012746,0.00401525,528.02006436,-0.00136968,-0.00264557,0.00000000,0.00000000,0.00000000,0.00000000
16.50000000,0.02352500,3.20840000,0.00079933,213.54468107,0.00079901,213.71537445,0.00008638,0.00458678,537.22054088,-0.00172443,-0.00286234,0.00000000,0.00000000,0.00000000,0.00000000
18.00000000,0.02569000,3.45560000,0.00090656,229.99781820,0.00090614,230.20632400,0.00031085,0.00516728,546.00668050,-0.00201189,-0.00315539,0.00000000,0.00000000,0.00000000,0.00000000
19.50000000,0.02820200,3.70280000,0.00091044,246.45095532,0.00091003,246.67533523,0.00012034,0.00572801,554.95408754,-0.00227971,-0.00344830,0.00000000,0.00000000,0.00000000,0.00000000
21.00000000,0.03033600,3.93490000,0.00094800,261.89906668,0.00094755,262.14734699,-0.00006016,0.00633777,562.91625531,-0.00254996,-0.00378781,0.00000000,0.00000000,0.00000000,0.00000000
22.50000000,0.03298200,4.15260000,0.00104967,276.38874286,0.00104912,276.67885891,-0.00023996,0.00706101,571.17590552,-0.00296047,-0.00410055,0.00000000,0.00000000,0.00000000,0.00000000
24.00000000,0.03572700,4.39110000,0.00124533,292.26282541,0.00124456,292.62679005,0.00011253,0.00774670,579.41929783,-0.00337104,-0.00437566,0.00000000,0.00000000,0.00000000,0.00000000
25.50000000,0.03877300,4.60640000,0.00128656,306.59276240,0.00128573,306.98721102,0.00024725,0.00843563,586.87305230,-0.00375705,-0.00467858,0.00000000,0.00000000,0.00000000,0.00000000
27.00000000,0.04293700,4.80730000,0.00132456,319.96426421,0.00132368,320.38807466,-0.00003706,0.00915010,594.29176947,-0.00417237,-0.00497773,0.00000000,0.00000000,0.00000000,0.00000000
28.50000000,0.04531000,5.03060000,0.00151978,334.82666519,0.00151862,335.33552731,-0.00010539,0.00993004,601.87575495,-0.00465709,-0.00527294,0.00000000,0.00000000,0.00000000,0.00000000
30.00000000,0.04926800,5.23080000,0.00168144,348.15157640,0.00168003,348.73697394,0.00028532,0.01064909,608.89324925,-0.00505733,-0.00559176,0.00000000,0.00000000,0.00000000,0.00000000
31.50000000,0.05481600,5.43100000,0.00171922,361.47648762,0.00171775,362.09794603,0.00005236,0.01136576,615.48615275,-0.00538645,-0.00597931,0.00000000,0.00000000,0.00000000,0.00000000
33.00000000,0.05911100,5.64150000,0.00191067,375.48694622,0.00190884,376.20437661,-0.00018719,0.01222370,622.61053457,-0.00584972,-0.00637398,0.00000000,0.00000000,0.00000000,0.00000000
34.50000000,0.06394600,5.82090000,0.00220767,387.42745107,0.00220523,388.28276174,0.00011974,0.01295069,629.12181914,-0.00619623,-0.00675447,0.00000000,0.00000000,0.00000000,0.00000000
36.00000000,0.06868100,6.01070000,0.00223356,400.06015911,0.00223106,400.95371570,0.00013459,0.01373358,635.40673881,-0.00660958,-0.00712400,0.00000000,0.00000000,0.00000000,0.00000000
37.50000000,0.07645300,6.21010000,0.00244800,413.33182393,0.00244501,414.34366024,0.00003037,0.01454650,642.21684052,-0.00703464,-0.00751186,0.00000000,0.00000000,0.00000000,0.00000000
39.00000000,0.08419400,6.38950000,0.00280078,425.27232879,0.00279686,426.46342208,0.00005208,0.01543060,647.88056571,-0.00759353,-0.00783707,0.00000000,0.00000000,0.00000000,0.00000000
40.50000000,0.09254200,6.56180000,0.00308611,436.74027186,0.00308136,438.08810086,0.00037444,0.01621966,653.98871779,-0.00798962,-0.00823004,0.00000000,0.00000000,0.00000000,0.00000000
42.00000000,0.09956700,6.74600000,0.00330767,449.00025511,0.00330221,450.48539828,0.00020179,0.01706691,660.08368425,-0.00842477,-0.00864215,0.00000000,0.00000000,0.00000000,0.00000000
43.50000000,0.11102300,6.91430000,0.00362267,460.20196619,0.00361612,461.86912451,0.00010451,0.01795714,665.51517270,-0.00891691,-0.00904023,0.00000000,0.00000000,0.00000000,0.00000000
45.00000000,0.12095600,7.07380000,0.00402089,470.81796688,0.00401283,472.71107361,0.00032959,0.01884347,670.78964921,-0.00935166,-0.00949181,0.00000000,0.00000000,0.00000000,0.00000000
46.50000000,0.13281400,7.24520000,0.00438133,482.22600775,0.00437176,484.33880063,0.00017944,0.01973819,676.45468969,-0.00980650,-0.00993169,0.00000000,0.00000000,0.00000000,0.00000000
48.00000000,0.14534900,7.39990000,0.00493678,492.52253006,0.00492463,494.95400434,0.00029877,0.02062863,681.31289426,-0.01025581,-0.01037282,0.00000000,0.00000000,0.00000000,0.00000000
49.50000000,0.15940400,7.54350000,0.00540578,502.08025858,0.00539122,504.79439289,0.00053032,0.02162278,686.52467257,-0.01086602,-0.01075676,0.00000000,0.00000000,0.00000000,0.00000000
51.00000000,0.17521500,7.69740000,0.00580378,512.32353449,0.00578700,515.29694643,0.00047795,0.02247638,691.81332142,-0.01125591,-0.01122048,0.00000000,0.00000000,0.00000000,0.00000000
52.50000000,0.19089300,7.83380000,0.00633322,521.40204543,0.00631325,524.70420045,0.00023144,0.02343667,696.80128090,-0.01181641,-0.01162026,0.00000000,0.00000000,0.00000000,0.00000000
54.00000000,0.20873500,7.96460000,0.00698656,530.10783158,0.00696226,533.81145939,0.00035047,0.02444150,701.44528030,-0.01243228,-0.01200922,0.00000000,0.00000000,0.00000000,0.00000000
55.50000000,0.22509100,8.09770000,0.00757600,538.96670112,0.00754745,543.04991285,0.00039505,0.02541984,706.07935369,-0.01294537,-0.01247447,0.00000000,0.00000000,0.00000000,0.00000000
57.00000000,0.24611000,8.21890000,0.00821044,547.03353049,0.00817692,551.52491890,0.00035005,0.02632080,710.67372401,-0.01340738,-0.01291342,0.00000000,0.00000000,0.00000000,0.00000000
58.50000000,0.26564200,8.33620000,0.00894267,554.84078367,0.00890292,559.80253985,0.00040200,0.02734300,714.86026468,-0.01391748,-0.01342551,0.00000000,0.00000000,0.00000000,0.00000000
60.00000000,0.28696600,8.46140000,0.00969378,563.17384503,0.00964709,568.63312713,0.00067711,0.02834750,719.48325782,-0.01445987,-0.01388763,0.00000000,0.00000000,0.00000000,0.00000000
61.50000000,0.30700700,8.57140000,0.01030589,570.49522482,0.01025315,576.37468522,0.00058011,0.02931104,723.31922515,-0.01496751,-0.01434353,0.00000000,0.00000000,0.00000000,0.00000000
63.00000000,0.32971800,8.67990000,0.01101933,577.71676761,0.01095906,584.08282125,0.00046053,0.03033998,727.70029408,-0.01553728,-0.01480270,0.00000000,0.00000000,0.00000000,0.00000000
64.50000000,0.35101100,8.79070000,0.01185311,585.09139380,0.01178341,592.02654710,0.00064600,0.03136554,731.81758803,-0.01602672,-0.01533882,0.00000000,0.00000000,0.00000000,0.00000000
66.00000000,0.37385900,8.88960000,0.01253667,591.67397981,0.01245873,599.09159927,0.00054173,0.03239106,735.71422564,-0.01659202,-0.01579904,0.00000000,0.00000000,0.00000000,0.00000000
67.50000000,0.39680700,8.98450000,0.01328389,597.99033383,0.01319643,605.93397098,0.00039282,0.03338235,739.71064673,-0.01711907,-0.01626329,0.00000000,0.00000000,0.00000000,0.00000000
69.00000000,0.42188500,9.08740000,0.01416267,604.83915183,0.01406331,613.40528713,0.00048869,0.03444895,743.65267481,-0.01769441,-0.01675453,0.00000000,0.00000000,0.00000000,0.00000000
70.50000000,0.44598400,9.20620000,0.01497389,612.74624200,0.01486289,621.92143615,0.00048108,0.03547616,747.24644103,-0.01826019,-0.01721597,0.00000000,0.00000000,0.00000000,0.00000000
72.00000000,0.47106200,9.26600000,0.01574378,616.72641029,0.01562113,626.43601384,0.00045839,0.03655012,750.65964798,-0.01887609,-0.01767403,0.00000000,0.00000000,0.00000000,0.00000000
73.50000000,0.49549900,9.36330000,0.01661889,623.20250350,0.01648231,633.55943667,0.00036945,0.03756744,754.36371912,-0.01943181,-0.01813563,0.00000000,0.00000000,0.00000000,0.00000000
75.00000000,0.52088300,9.44470000,0.01754278,628.62032455,0.01739068,639.64807121,0.00062033,0.03866523,757.58541153,-0.02001339,-0.01865184,0.00000000,0.00000000,0.00000000,0.00000000
76.50000000,0.54795700,9.52680000,0.01838022,634.08473619,0.01821335,645.73935455,0.00065649,0.03970860,761.38568434,-0.02058327,-0.01912533,0.00000000,0.00000000,0.00000000,0.00000000
78.00000000,0.57415200,9.60970000,0.01921400,639.60239423,0.01903174,651.89171464,0.00047908,0.04086058,764.77375593,-0.02123406,-0.01962652,0.00000000,0.00000000,0.00000000,0.00000000
79.50000000,0.60095500,9.68550000,0.02015667,644.64749049,0.01995621,657.64143507,0.00049345,0.04196553,767.96466790,-0.02183729,-0.02012825,0.00000000,0.00000000,0.00000000,0.00000000
81.00000000,0.62843500,9.76130000,0.02111433,649.69258674,0.02089451,663.41041258,0.00069892,0.04306122,771.32262647,-0.02241976,-0.02064146,0.00000000,0.00000000,0.00000000,0.00000000
82.50000000,0.65517100,9.84020000,0.02190300,654.94401279,0.02166658,669.28925151,0.00055851,0.04413181,774.44336581,-0.02294972,-0.02118209,0.00000000,0.00000000,0.00000000,0.00000000
84.00000000,0.68427300,9.90800000,0.02289078,659.45664506,0.02263271,674.55212058,0.00055080,0.04527223,777.67360453,-0.02358108,-0.02169115,0.00000000,0.00000000,0.00000000,0.00000000
85.50000000,0.71242800,9.97260000,0.02391233,663.75629174,0.02363091,679.62825344,0.00070439,0.04636215,780.70917487,-0.02411465,-0.02224750,0.00000000,0.00000000,0.00000000,0.00000000
87.00000000,0.74173300,10.04120000,0.02489633,668.32217041,0.02459147,684.96094194,0.00074775,0.04750501,783.63044909,-0.02470217,-0.02280284,0.00000000,0.00000000,0.00000000,0.00000000
88.50000000,0.77110600,10.10660000,0.02583144,672.67506348,0.02550345,690.05123202,0.00068097,0.04869597,786.64471554,-0.02542721,-0.02326876,0.00000000,0.00000000,0.00000000,0.00000000
90.00000000,0.80074900,10.16560000,0.02681922,676.60198537,0.02646589,694.74792437,0.00065845,0.04986336,789.81562495,-0.02607526,-0.02378810,0.00000000,0.00000000,0.00000000,0.00000000
91.50000000,0.83012200,10.22940000,0.02781444,680.84838565,0.02743465,699.78580525,0.00073092,0.05099514,792.68233257,-0.02670705,-0.02428809,0.00000000,0.00000000,0.00000000,0.00000000
93.00000000,0.86040700,10.28920000,0.02882478,684.82855393,0.02841716,704.56858482,0.00073020,0.05215432,795.51995707,-0.02729993,-0.02485440,0.00000000,0.00000000,0.00000000,0.00000000
94.50000000,0.89109800,10.34260000,0.02985756,688.38275103,0.02942050,708.93617727,0.00065651,0.05329790,798.35065838,-0.02789739,-0.02540050,0.00000000,0.00000000,0.00000000,0.00000000
96.00000000,0.92209300,10.40160000,0.03087533,692.30967292,0.03040828,713.68496484,0.00069230,0.05445394,801.25355530,-0.02850747,-0.02594647,0.00000000,0.00000000,0.00000000,0.00000000
97.50000000,0.95244600,10.45350000,0.03192689,695.76403302,0.03142782,717.97761400,0.00071336,0.05565059,803.52132645,-0.02922650,-0.02642408,0.00000000,0.00000000,0.00000000,0.00000000
99.00000000,0.98432000,10.50210000,0.03296356,698.99875173,0.03243191,722.04023591,0.00069822,0.05684610,806.46696057,-0.02989212,-0.02695398,0.00000000,0.00000000,0.00000000,0.00000000
100.50000000,1.01602600,10.55320000,0.03401889,702.39986543,0.03345304,726.29472841,0.00063215,0.05800316,809.04613766,-0.03051584,-0.02748732,0.00000000,0.00000000,0.00000000,0.00000000
102.00000000,1.04796700,10.60500000,0.03509678,705.84756973,0.03449493,730.62054503,0.00075498,0.05923305,811.57574193,-0.03121671,-0.02801633,0.00000000,0.00000000,0.00000000,0.00000000
103.50000000,1.08014600,10.64570000,0.03614456,708.55648025,0.03550667,734.16693932,0.00065982,0.06042538,814.25072407,-0.03185387,-0.02857151,0.00000000,0.00000000,0.00000000,0.00000000
105.00000000,1.11259500,10.69750000,0.03724500,712.00418455,0.03656816,738.52278041,0.00073885,0.06159374,816.51897173,-0.03250189,-0.02909186,0.00000000,0.00000000,0.00000000,0.00000000
106.50000000,1.14521300,10.74460000,0.03837167,715.13906626,0.03765378,742.58014414,0.00075239,0.06282684,818.89466215,-0.03316032,-0.02966652,0.00000000,0.00000000,0.00000000,0.00000000
108.00000000,1.17867600,10.77880000,0.03944211,717.41534980,0.03868414,745.71172574,0.00063613,0.06401618,821.30331643,-0.03383387,-0.03018231,0.00000000,0.00000000,0.00000000,0.00000000
109.50000000,1.21183400,10.82110000,0.04059133,720.23075312,0.03978914,749.46587970,0.00077257,0.06527310,823.93717945,-0.03455120,-0.03072191,0.00000000,0.00000000,0.00000000,0.00000000
111.00000000,1.24512800,10.86340000,0.04170667,723.04615644,0.04086039,753.20200147,0.00077879,0.06647164,826.01177500,-0.03518103,-0.03129061,0.00000000,0.00000000,0.00000000,0.00000000
112.50000000,1.27862500,10.90400000,0.04276211,725.74841116,0.04187307,756.78294536,0.00068462,0.06767343,827.81295395,-0.03583282,-0.03184061,0.00000000,0.00000000,0.00000000,0.00000000
114.00000000,1.31273000,10.94630000,0.04394889,728.56381448,0.04301053,760.58338461,0.00077733,0.06893521,830.63756666,-0.03650806,-0.03242715,0.00000000,0.00000000,0.00000000,0.00000000
115.50000000,1.34693700,10.97660000,0.04512811,730.58052182,0.04413947,763.55024079,0.00081942,0.07013720,832.50410315,-0.03713076,-0.03300644,0.00000000,0.00000000,0.00000000,0.00000000
117.00000000,1.38181900,11.01330000,0.04628489,733.02320035,0.04524569,766.95109773,0.00081150,0.07136365,834.79073636,-0.03778669,-0.03357696,0.00000000,0.00000000,0.00000000,0.00000000
118.50000000,1.41660000,11.05160000,0.04740778,735.57237168,0.04631833,770.44422321,0.00064551,0.07254341,837.04975360,-0.03840294,-0.03414047,0.00000000,0.00000000,0.00000000,0.00000000
120.00000000,1.45192200,11.08190000,0.04862844,737.58907902,0.04748307,773.45688857,0.00074524,0.07381946,839.21354409,-0.03913575,-0.03468372,0.00000000,0.00000000,0.00000000,0.00000000
121.50000000,1.48714300,11.11460000,0.04979267,739.76552556,0.04859268,776.60042378,0.00076580,0.07505213,841.40997531,-0.03975473,-0.03529739,0.00000000,0.00000000,0.00000000,0.00000000
123.00000000,1.52246500,11.14570000,0.05097200,741.83547930,0.04971545,779.64831735,0.00077213,0.07632277,843.29515841,-0.04046588,-0.03585689,0.00000000,0.00000000,0.00000000,0.00000000
124.50000000,1.55842900,11.17840000,0.05220756,744.01192584,0.05089039,782.85496979,0.00077101,0.07757758,845.27913560,-0.04110956,-0.03646802,0.00000000,0.00000000,0.00000000,0.00000000
126.00000000,1.59432600,11.21110000,0.05343567,746.18837237,0.05205689,786.06144551,0.00082013,0.07882092,847.14813033,-0.04178983,-0.03703109,0.00000000,0.00000000,0.00000000,0.00000000
127.50000000,1.63052700,11.23740000,0.05464122,747.93884772,0.05320064,788.80714051,0.00080486,0.08009935,849.27576974,-0.04248745,-0.03761190,0.00000000,0.00000000,0.00000000,0.00000000
129.00000000,1.66743700,11.26130000,0.05589189,749.52958388,0.05438580,791.42220810,0.00075422,0.08136301,851.28569757,-0.04315616,-0.03820685,0.00000000,0.00000000,0.00000000,0.00000000
130.50000000,1.70353700,11.29160000,0.05714256,751.54629122,0.05556957,794.49156692,0.00085279,0.08264503,853.42442843,-0.04387069,-0.03877434,0.00000000,0.00000000,0.00000000,0.00000000
132.00000000,1.74021100,11.31870000,0.05835189,753.35001297,0.05671288,797.30940922,0.00078796,0.08393704,855.29126283,-0.04456129,-0.03937575,0.00000000,0.00000000,0.00000000,0.00000000
133.50000000,1.77735800,11.34660000,0.05960244,755.20698111,0.05789379,800.21916325,0.00075850,0.08525069,857.29706291,-0.04530462,-0.03994607,0.00000000,0.00000000,0.00000000,0.00000000
135.00000000,1.81399800,11.36580000,0.06089444,756.48489468,0.05911237,802.55062207,0.00079320,0.08652252,859.08767837,-0.04598244,-0.04054008,0.00000000,0.00000000,0.00000000,0.00000000
136.50000000,1.85202400,11.39610000,0.06211878,758.50160202,0.06026576,805.61879448,0.00075691,0.08783437,860.74757976,-0.04667157,-0.04116280,0.00000000,0.00000000,0.00000000,0.00000000
138.00000000,1.88937500,11.41840000,0.06339944,759.98584538,0.06147080,808.16852576,0.00078422,0.08914893,862.94094883,-0.04743558,-0.04171335,0.00000000,0.00000000,0.00000000,0.00000000
139.50000000,1.92729900,11.43760000,0.06470267,761.26375894,0.06269557,810.51955418,0.00079725,0.09047008,864.78438730,-0.04819353,-0.04227655,0.00000000,0.00000000,0.00000000,0.00000000
141.00000000,1.96529200,11.46150000,0.06599844,762.85449509,0.06391187,813.20170511,0.00085989,0.09174556,866.53998870,-0.04884964,-0.04289592,0.00000000,0.00000000,0.00000000,0.00000000
142.50000000,2.00304700,11.48220000,0.06726033,764.23224565,0.06509493,815.63476124,0.00083075,0.09310109,868.30955951,-0.04956927,-0.04353182,0.00000000,0.00000000,0.00000000,0.00000000
144.00000000,2.04120900,11.50060000,0.06857100,765.45691282,0.06632224,817.94505879,0.00079436,0.09440716,870.09814474,-0.05031254,-0.04409462,0.00000000,0.00000000,0.00000000,0.00000000
145.50000000,2.07994500,11.52210000,0.06988178,766.88790978,0.06754815,820.47940027,0.00082165,0.09577710,871.64305852,-0.05105934,-0.04471776,0.00000000,0.00000000,0.00000000,0.00000000
147.00000000,2.11891700,11.53960000,0.07119622,768.05267475,0.06877599,822.73512365,0.00082044,0.09707054,873.19006575,-0.05174939,-0.04532115,0.00000000,0.00000000,0.00000000,0.00000000
148.50000000,2.15731500,11.56360000,0.07251456,769.65006670,0.07000594,825.46089922,0.00085466,0.09841208,874.95961522,-0.05248038,-0.04593170,0.00000000,0.00000000,0.00000000,0.00000000
150.00000000,2.19615200,11.57710000,0.07381022,770.54859967,0.07121328,827.42296305,0.00077662,0.09970621,877.04657678,-0.05312989,-0.04657632,0.00000000,0.00000000,0.00000000,0.00000000
151.50000000,2.23542900,11.59470000,0.07514344,771.72002044,0.07245409,829.70972092,0.00074071,0.10106550,878.60097947,-0.05382716,-0.04723833,0.00000000,0.00000000,0.00000000,0.00000000
153.00000000,2.27484100,11.61140000,0.07648422,772.83153901,0.07370038,831.94095818,0.00086535,0.10247580,880.37413579,-0.05464115,-0.04783465,0.00000000,0.00000000,0.00000000,0.00000000
154.50000000,2.31415200,11.62660000,0.07782122,773.84322058,0.07494162,834.06464581,0.00082942,0.10391154,882.06138845,-0.05545311,-0.04845842,0.00000000,0.00000000,0.00000000,0.00000000
156.00000000,2.35366500,11.64410000,0.07913200,775.00798555,0.07615701,836.33591746,0.00080060,0.10521016,883.80897809,-0.05616130,-0.04904885,0.00000000,0.00000000,0.00000000,0.00000000
157.50000000,2.39355000,11.66240000,0.08048778,776.22599691,0.07741259,838.70270246,0.00084136,0.10655851,885.36492979,-0.05683910,-0.04971941,0.00000000,0.00000000,0.00000000,0.00000000
159.00000000,2.43343500,11.67120000,0.08182478,776.81170729,0.07864922,840.37415262,0.00074990,0.10796218,886.91293478,-0.05771985,-0.05024232,0.00000000,0.00000000,0.00000000,0.00000000
160.50000000,2.47416600,11.68880000,0.08322567,777.98312806,0.07994332,842.73129255,0.00081153,0.10937320,888.58243975,-0.05844211,-0.05093109,0.00000000,0.00000000,0.00000000,0.00000000
162.00000000,2.51486200,11.70230000,0.08460400,778.88166103,0.08121494,844.77816508,0.00088675,0.11078647,890.08444921,-0.05924380,-0.05154267,0.00000000,0.00000000,0.00000000,0.00000000
163.50000000,2.55555900,11.71590000,0.08598978,779.78684981,0.08249181,846.84054774,0.00085777,0.11211393,891.63226226,-0.05991026,-0.05220367,0.00000000,0.00000000,0.00000000,0.00000000
165.00000000,2.59601800,11.72460000,0.08734189,780.36590439,0.08373608,848.52453651,0.00087756,0.11353619,893.20750090,-0.06065387,-0.05288232,0.00000000,0.00000000,0.00000000,0.00000000
166.50000000,2.63759400,11.73740000,0.08873144,781.21784677,0.08501321,850.53643474,0.00090401,0.11503260,894.91233262,-0.06151537,-0.05351723,0.00000000,0.00000000,0.00000000,0.00000000
168.00000000,2.67876300,11.75420000,0.09009856,782.33602113,0.08626811,852.82336660,0.00075808,0.11642695,896.58871085,-0.06220506,-0.05422189,0.00000000,0.00000000,0.00000000,0.00000000
169.50000000,2.72006800,11.76690000,0.09155944,783.18130771,0.08760736,854.88895314,0.00080513,0.11788448,897.84165964,-0.06306390,-0.05482058,0.00000000,0.00000000,0.00000000,0.00000000
171.00000000,2.76228600,11.77570000,0.09295656,783.76701809,0.08888646,856.62330045,0.00081101,0.11932172,899.44111268,-0.06377099,-0.05555073,0.00000000,0.00000000,0.00000000,0.00000000
172.50000000,2.80419900,11.78690000,0.09438744,784.51246767,0.09019480,858.56059463,0.00084428,0.12080060,900.89919563,-0.06462796,-0.05617264,0.00000000,0.00000000,0.00000000,0.00000000
174.00000000,2.84628100,11.79240000,0.09577711,784.87853666,0.09146380,860.05193548,0.00082962,0.12227994,902.47386096,-0.06543948,-0.05684046,0.00000000,0.00000000,0.00000000,0.00000000
175.50000000,2.88822800,11.80520000,0.09723800,785.73047904,0.09279611,862.13333936,0.00089011,0.12375743,903.99635451,-0.06627207,-0.05748536,0.00000000,0.00000000,0.00000000,0.00000000
177.00000000,2.93095300,11.81800000,0.09863889,786.58242141,0.09407204,864.17003748,0.00078638,0.12527207,905.55518407,-0.06711916,-0.05815291,0.00000000,0.00000000,0.00000000,0.00000000
178.50000000,2.97354200,11.82350000,0.10007733,786.94849040,0.09538048,865.70419679,0.00073766,0.12678235,906.86882817,-0.06792510,-0.05885725,0.00000000,0.00000000,0.00000000,0.00000000
180.00000000,3.01640200,11.82990000,0.10159833,787.37446159,0.09676216,867.37039460,0.00094794,0.12830604,908.31873210,-0.06878642,-0.05951962,0.00000000,0.00000000,0.00000000,0.00000000
181.50000000,3.05892300,11.84190000,0.10301044,788.17315757,0.09804321,869.36322483,0.00088545,0.12982951,910.01539327,-0.06964684,-0.06018267,0.00000000,0.00000000,0.00000000,0.00000000
183.00000000,3.10222200,11.84990000,0.10455400,788.70562155,0.09944163,871.16794911,0.00091138,0.13136551,911.35910240,-0.07043738,-0.06092813,0.00000000,0.00000000,0.00000000,0.00000000
184.50000000,3.14602900,11.85700000,0.10606011,789.17818334,0.10080425,872.87850915,0.00103256,0.13296366,912.88446451,-0.07137034,-0.06159332,0.00000000,0.00000000,0.00000000,0.00000000
186.00000000,3.18932800,11.86340000,0.10746467,789.60415453,0.10207332,874.45870179,0.00078011,0.13452678,914.38022378,-0.07218147,-0.06234531,0.00000000,0.00000000,0.00000000,0.00000000
187.50000000,3.23262700,11.86900000,0.10898944,789.97687932,0.10344919,876.07602052,0.00087386,0.13608910,915.50843407,-0.07305671,-0.06303239,0.00000000,0.00000000,0.00000000,0.00000000
189.00000000,3.27673700,11.87300000,0.11054433,790.24311131,0.10485029,877.60000922,0.00108244,0.00000000,0.00000000,0.00000000,0.00000000,0.00000000,0.00000000,0.00000000,0.00000000
190.50000000,3.32050900,11.88650000,0.11200900,791.14164428,0.10616829,879.75662872,0.00093906,0.00000000,0.00000000,0.00000000,0.00000000,0.00000000,0.00000000,0.00000000,0.00000000
192.00000000,3.36458600,11.89050000,0.11357511,791.40787627,0.10757566,881.29211376,0.00099165,0.00000000,0.00000000,0.00000000,0.00000000,0.00000000,0.00000000,0.00000000,0.00000000
193.50000000,3.40903400,11.89930000,0.11508489,791.99358666,0.10893054,883.14008058,0.00094325,0.00000000,0.00000000,0.00000000,0.00000000,0.00000000,0.00000000,0.00000000,0.00000000
195.00000000,3.45405700,11.90650000,0.11667733,792.47280424,0.11035761,884.93641778,0.00101597,0.00000000,0.00000000,0.00000000,0.00000000,0.00000000,0.00000000,0.00000000,0.00000000
196.50000000,3.49854000,11.90810000,0.11823222,792.57929704,0.11174907,886.28770862,0.00102808,0.00000000,0.00000000,0.00000000,0.00000000,0.00000000,0.00000000,0.00000000,0.00000000
198.00000000,3.54352900,11.91520000,0.11981711,793.05185883,0.11316538,888.07304151,0.00096626,0.00000000,0.00000000,0.00000000,0.00000000,0.00000000,0.00000000,0.00000000,0.00000000
199.50000000,3.58807800,11.91680000,0.12131933,793.15835162,0.11450597,889.38379407,0.00099174,0.00000000,0.00000000,0.00000000,0.00000000,0.00000000,0.00000000,0.00000000,0.00000000
201.00000000,3.63340600,11.93120000,0.12290044,794.11678680,0.11591502,891.71409283,0.00100361,0.00000000,0.00000000,0.00000000,0.00000000,0.00000000,0.00000000,0.00000000,0.00000000
202.50000000,3.67910500,11.92960000,0.12450411,794.01029400,0.11734215,892.86783987,0.00102214,0.00000000,0.00000000,0.00000000,0.00000000,0.00000000,0.00000000,0.00000000,0.00000000
204.00000000,3.72598700,11.93040000,0.12604022,794.06354040,0.11870725,894.14748549,0.00095421,0.00000000,0.00000000,0.00000000,0.00000000,0.00000000,0.00000000,0.00000000,0.00000000
205.50000000,3.77280100,11.93680000,0.12780533,794.48951159,0.12027356,896.02950844,0.00105247,0.00000000,0.00000000,0.00000000,0.00000000,0.00000000,0.00000000,0.00000000,0.00000000
207.00000000,3.81917600,11.94000000,0.12941656,794.70249718,0.12170118,897.55015706,0.00105116,0.00000000,0.00000000,0.00000000,0.00000000,0.00000000,0.00000000,0.00000000,0.00000000
208.50000000,3.86619300,11.94240000,0.13108400,794.86223638,0.12317646,899.05595777,0.00106278,0.00000000,0.00000000,0.00000000,0.00000000,0.00000000,0.00000000,0.00000000,0.00000000
210.00000000,3.91294000,11.94550000,0.13271022,795.06856617,0.12461319,900.58229227,0.00103476,0.00000000,0.00000000,0.00000000,0.00000000,0.00000000,0.00000000,0.00000000,0.00000000
211.50000000,3.96032900,11.94710000,0.13440400,795.17505897,0.12610740,902.04976759,0.00107280,0.00000000,0.00000000,0.00000000,0.00000000,0.00000000,0.00000000,0.00000000,0.00000000
213.00000000,4.00839400,11.94790000,0.13612033,795.22830536,0.12761924,903.47504737,0.00105807,0.00000000,0.00000000,0.00000000,0.00000000,0.00000000,0.00000000,0.00000000,0.00000000
214.50000000,4.05605400,11.95190000,0.13778789,795.49453736,0.12908593,905.10405028,0.00099711,0.00000000,0.00000000,0.00000000,0.00000000,0.00000000,0.00000000,0.00000000,0.00000000
216.00000000,4.10499800,11.95190000,0.13954556,795.49453736,0.13062955,906.50226451,0.00104182,0.00000000,0.00000000,0.00000000,0.00000000,0.00000000,0.00000000,0.00000000,0.00000000
217.50000000,4.15302900,11.95190000,0.14123556,795.49453736,0.13211150,907.84665028,0.00101378,0.00000000,0.00000000,0.00000000,0.00000000,0.00000000,0.00000000,0.00000000,0.00000000
219.00000000,4.20180400,11.95270000,0.14301578,795.54778376,0.13367019,909.32366881,0.00105169,0.00000000,0.00000000,0.00000000,0.00000000,0.00000000,0.00000000,0.00000000,0.00000000
220.50000000,4.24997000,11.95270000,0.14478100,795.54778376,0.13521335,910.72798744,0.00111591,0.00000000,0.00000000,0.00000000,0.00000000,0.00000000,0.00000000,0.00000000,0.00000000
222.00000000,4.29965800,11.95270000,0.14654611,795.54778376,0.13675404,912.13221767,0.00111399,0.00000000,0.00000000,0.00000000,0.00000000,0.00000000,0.00000000,0.00000000,0.00000000
223.50000000,4.34958200,11.95670000,0.14834889,795.81401575,0.13832516,913.87214075,0.00111244,0.00000000,0.00000000,0.00000000,0.00000000,0.00000000,0.00000000,0.00000000,0.00000000
225.00000000,4.39879700,11.95670000,0.15018911,795.81401575,0.13992637,915.33661538,0.00117580,0.00000000,0.00000000,0.00000000,0.00000000,0.00000000,0.00000000,0.00000000,0.00000000
226.50000000,4.44912600,11.95590000,0.15199189,795.76076935,0.00000000,0.00000000,0.00000000,0.00000000,0.00000000,0.00000000,0.00000000,0.00000000,0.00000000,0.00000000,0.00000000
228.00000000,4.49942200,11.95270000,0.15386967,795.54778376,0.00000000,0.00000000,0.00000000,0.00000000,0.00000000,0.00000000,0.00000000,0.00000000,0.00000000,0.00000000,0.00000000
229.50000000,4.55046200,11.95270000,0.15571000,795.54778376,0.00000000,0.00000000,0.00000000,0.00000000,0.00000000,0.00000000,0.00000000,0.00000000,0.00000000,0.00000000,0.00000000
231.00000000,4.60119700,11.95430000,0.15758778,795.65427655,0.00000000,0.00000000,0.00000000,0.00000000,0.00000000,0.00000000,0.00000000,0.00000000,0.00000000,0.00000000,0.00000000
232.50000000,4.65186500,11.95110000,0.15946567,795.44129096,0.00000000,0.00000000,0.00000000,0.00000000,0.00000000,0.00000000,0.00000000,0.00000000,0.00000000,0.00000000,0.00000000
234.00000000,4.70368200,11.95270000,0.16141856,795.54778376,0.00000000,0.00000000,0.00000000,0.00000000,0.00000000,0.00000000,0.00000000,0.00000000,0.00000000,0.00000000,0.00000000
235.50000000,4.75617500,11.94870000,0.16333400,795.28155176,0.00000000,0.00000000,0.00000000,0.00000000,0.00000000,0.00000000,0.00000000,0.00000000,0.00000000,0.00000000,0.00000000
237.00000000,4.80853300,11.94710000,0.16524933,795.17505897,0.00000000,0.00000000,0.00000000,0.00000000,0.00000000,0.00000000,0.00000000,0.00000000,0.00000000,0.00000000,0.00000000
238.50000000,4.86085700,11.94320000,0.16723989,794.91548277,0.00000000,0.00000000,0.00000000,0.00000000,0.00000000,0.00000000,0.00000000,0.00000000,0.00000000,0.00000000,0.00000000
240.00000000,4.91301200,11.94080000,0.16919289,794.75574358,0.00000000,0.00000000,0.00000000,0.00000000,0.00000000,0.00000000,0.00000000,0.00000000,0.00000000,0.00000000,0.00000000
241.50000000,4.96675500,11.94160000,0.17114578,794.80898998,0.00000000,0.00000000,0.00000000,0.00000000,0.00000000,0.00000000,0.00000000,0.00000000,0.00000000,0.00000000,0.00000000
243.00000000,5.02036400,11.94000000,0.17313633,794.70249718,0.00000000,0.00000000,0.00000000,0.00000000,0.00000000,0.00000000,0.00000000,0.00000000,0.00000000,0.00000000,0.00000000
244.50000000,5.07437800,11.93120000,0.17512689,794.11678680,0.00000000,0.00000000,0.00000000,0.00000000,0.00000000,0.00000000,0.00000000,0.00000000,0.00000000,0.00000000,0.00000000
246.00000000,5.12927100,11.92720000,0.17707978,793.85055480,0.00000000,0.00000000,0.00000000,0.00000000,0.00000000,0.00000000,0.00000000,0.00000000,0.00000000,0.00000000,0.00000000
247.50000000,5.18484000,11.91920000,0.17907033,793.31809082,0.00000000,0.00000000,0.00000000,0.00000000,0.00000000,0.00000000,0.00000000,0.00000000,0.00000000,0.00000000,0.00000000
249.00000000,5.24051000,11.91360000,0.18109844,792.94536603,0.00000000,0.00000000,0.00000000,0.00000000,0.00000000,0.00000000,0.00000000,0.00000000,0.00000000,0.00000000,0.00000000
250.50000000,5.29668700,11.90570000,0.18305144,792.41955785,0.00000000,0.00000000,0.00000000,0.00000000,0.00000000,0.00000000,0.00000000,0.00000000,0.00000000,0.00000000,0.00000000
252.00000000,5.35259400,11.90090000,0.18492933,792.10007945,0.00000000,0.00000000,0.00000000,0.00000000,0.00000000,0.00000000,0.00000000,0.00000000,0.00000000,0.00000000,0.00000000
253.50000000,5.40965000,11.89130000,0.18680722,791.46112267,0.00000000,0.00000000,0.00000000,0.00000000,0.00000000,0.00000000,0.00000000,0.00000000,0.00000000,0.00000000,0.00000000
255.00000000,5.46670700,11.88250000,0.18868511,790.87541229,0.00000000,0.00000000,0.00000000,0.00000000,0.00000000,0.00000000,0.00000000,0.00000000,0.00000000,0.00000000,0.00000000
256.50000000,5.52514800,11.86900000,0.19045033,789.97687932,0.00000000,0.00000000,0.00000000,0.00000000,0.00000000,0.00000000,0.00000000,0.00000000,0.00000000,0.00000000,0.00000000
258.00000000,5.58359000,11.85620000,0.19214056,789.12493694,0.00000000,0.00000000,0.00000000,0.00000000,0.00000000,0.00000000,0.00000000,0.00000000,0.00000000,0.00000000,0.00000000
259.50000000,5.64223500,11.84430000,0.19379322,788.33289676,0.00000000,0.00000000,0.00000000,0.00000000,0.00000000,0.00000000,0.00000000,0.00000000,0.00000000,0.00000000,0.00000000
261.00000000,5.70138700,11.82910000,0.19540822,787.32121519,0.00000000,0.00000000,0.00000000,0.00000000,0.00000000,0.00000000,0.00000000,0.00000000,0.00000000,0.00000000,0.00000000
262.50000000,5.76080900,11.81400000,0.19683556,786.31618942,0.00000000,0.00000000,0.00000000,0.00000000,0.00000000,0.00000000,0.00000000,0.00000000,0.00000000,0.00000000,0.00000000
264.00000000,5.82026500,11.79240000,0.19822533,784.87853666,0.00000000,0.00000000,0.00000000,0.00000000,0.00000000,0.00000000,0.00000000,0.00000000,0.00000000,0.00000000,0.00000000
265.50000000,5.88110700,11.77890000,0.19942744,783.98000369,0.00000000,0.00000000,0.00000000,0.00000000,0.00000000,0.00000000,0.00000000,0.00000000,0.00000000,0.00000000,0.00000000
267.00000000,5.94198200,11.75340000,0.20055444,782.28277474,0.00000000,0.00000000,0.00000000,0.00000000,0.00000000,0.00000000,0.00000000,0.00000000,0.00000000,0.00000000,0.00000000
268.50000000,6.00343200,11.72700000,0.20153122,780.52564359,0.00000000,0.00000000,0.00000000,0.00000000,0.00000000,0.00000000,0.00000000,0.00000000,0.00000000,0.00000000,0.00000000
270.00000000,6.06444200,11.69750000,0.20235789,778.56218264,0.00000000,0.00000000,0.00000000,0.00000000,0.00000000,0.00000000,0.00000000,0.00000000,0.00000000,0.00000000,0.00000000
271.50000000,6.12616300,11.66640000,0.20307189,776.49222890,0.00000000,0.00000000,0.00000000,0.00000000,0.00000000,0.00000000,0.00000000,0.00000000,0.00000000,0.00000000,0.00000000
273.00000000,6.18822100,11.63370000,0.20363567,774.31578237,0.00000000,0.00000000,0.00000000,0.00000000,0.00000000,0.00000000,0.00000000,0.00000000,0.00000000,0.00000000,0.00000000
274.50000000,6.25017700,11.59390000,0.20416200,771.66677404,0.00000000,0.00000000,0.00000000,0.00000000,0.00000000,0.00000000,0.00000000,0.00000000,0.00000000,0.00000000,0.00000000
276.00000000,6.31311400,11.54920000,0.20450056,768.69163153,0.00000000,0.00000000,0.00000000,0.00000000,0.00000000,0.00000000,0.00000000,0.00000000,0.00000000,0.00000000,0.00000000
277.50000000,6.37578100,11.50140000,0.20480156,765.51015922,0.00000000,0.00000000,0.00000000,0.00000000,0.00000000,0.00000000,0.00000000,0.00000000,0.00000000,0.00000000,0.00000000
279.00000000,6.44017300,11.44710000,0.20491478,761.89605992,0.00000000,0.00000000,0.00000000,0.00000000,0.00000000,0.00000000,0.00000000,0.00000000,0.00000000,0.00000000,0.00000000
280.50000000,6.50379000,11.37850000,0.20502811,757.33018125,0.00000000,0.00000000,0.00000000,0.00000000,0.00000000,0.00000000,0.00000000,0.00000000,0.00000000,0.00000000,0.00000000
282.00000000,6.56805300,11.31320000,0.20510411,752.98394398,0.00000000,0.00000000,0.00000000,0.00000000,0.00000000,0.00000000,0.00000000,0.00000000,0.00000000,0.00000000,0.00000000
283.50000000,6.63327000,11.22220000,0.20506744,746.92716615,0.00000000,0.00000000,0.00000000,0.00000000,0.00000000,0.00000000,0.00000000,0.00000000,0.00000000,0.00000000,0.00000000
285.00000000,6.70117300,11.10500000,0.20510611,739.12656878,0.00000000,0.00000000,0.00000000,0.00000000,0.00000000,0.00000000,0.00000000,0.00000000,0.00000000,0.00000000,0.00000000
286.50000000,6.78330400,10.91680000,0.20499822,726.60035354,0.00000000,0.00000000,0.00000000,0.00000000,0.00000000,0.00000000,0.00000000,0.00000000,0.00000000,0.00000000,0.00000000