File: polyN_optimization/DP780_results/DATA/UT_60_1.csv
Time[s],Displacement[mm],Force[kN],EngStrain_longi,EngStress[MPa],TrueStrain,TrueStress[MPa],TrueStrainRate[1/s],PlasticStrain_longi,PlasticStress[MPa],PlasticStrain_thick,PlasticStrain_width,R-Value,Thickness[mm],Width[mm], Young's Modulus [MPa]
0.00000000,0.00000000,-0.01580000,0.00000000,-1.05404109,0.00000000,-1.05404109,0.00000000,0.00060811,425.08215681,0.00025616,-0.00086427,0.89943472,1.50530000,9.95810000,241219.81994891
1.50000000,0.00162900,0.43000000,0.00004956,28.68592845,0.00004955,28.68734999,0.00001156,0.00079723,437.30358593,0.00034839,-0.00114562,0.00000000,0.00000000,0.00000000,0.00000000
3.00000000,0.00328900,0.75780000,0.00010333,50.55394553,0.00010333,50.55916943,0.00001733,0.00111572,449.04604456,0.00010897,-0.00122469,0.00000000,0.00000000,0.00000000,0.00000000
4.50000000,0.00541500,1.08870000,0.00015178,72.62876814,0.00015177,72.63979157,0.00004444,0.00135972,461.36001306,-0.00009640,-0.00126332,0.00000000,0.00000000,0.00000000,0.00000000
6.00000000,0.00757300,1.41650000,0.00025389,94.49678522,0.00025386,94.52077690,0.00003221,0.00165721,472.78720833,-0.00008164,-0.00157557,0.00000000,0.00000000,0.00000000,0.00000000
7.50000000,0.01013700,1.70600000,0.00033367,113.80975332,0.00033361,113.84772784,0.00004510,0.00199906,483.44481093,-0.00023937,-0.00175970,0.00000000,0.00000000,0.00000000,0.00000000
9.00000000,0.01240500,1.97790000,0.00041222,131.94859970,0.00041214,132.00299185,0.00013062,0.00229731,494.51908734,-0.00044160,-0.00185571,0.00000000,0.00000000,0.00000000,0.00000000
10.50000000,0.01370700,2.26020000,0.00041722,150.78124528,0.00041714,150.84415457,0.00003376,0.00269577,504.95285999,-0.00065744,-0.00203833,0.00000000,0.00000000,0.00000000,0.00000000
12.00000000,0.01547200,2.52340000,0.00048756,168.33970195,0.00048744,168.42177691,0.00009240,0.00326292,514.46746690,-0.00089194,-0.00237098,0.00000000,0.00000000,0.00000000,0.00000000
13.50000000,0.01768500,2.77060000,0.00054744,184.83077523,0.00054729,184.93195981,-0.00008395,0.00374232,525.12517970,-0.00114970,-0.00259262,0.00000000,0.00000000,0.00000000,0.00000000
15.00000000,0.02005800,3.04010000,0.00065222,202.80951411,0.00065201,202.94179098,-0.00007195,0.00419858,534.28008673,-0.00137831,-0.00282027,0.00000000,0.00000000,0.00000000,0.00000000
16.50000000,0.02317300,3.28420000,0.00079022,219.09378186,0.00078991,219.26691464,0.00012324,0.00476518,542.91123735,-0.00170375,-0.00306143,0.00000000,0.00000000,0.00000000,0.00000000
18.00000000,0.02537900,3.52500000,0.00087778,235.15790179,0.00087739,235.36431817,0.00019206,0.00534651,552.26204986,-0.00197314,-0.00337337,0.00000000,0.00000000,0.00000000,0.00000000
19.50000000,0.02736200,3.78260000,0.00088422,252.34277427,0.00088383,252.56590136,0.00014299,0.00589226,560.41696831,-0.00216407,-0.00372820,0.00000000,0.00000000,0.00000000,0.00000000
21.00000000,0.03003900,4.01390000,0.00091089,267.77313532,0.00091047,268.01704689,-0.00008237,0.00657228,568.44175918,-0.00248492,-0.00408737,0.00000000,0.00000000,0.00000000,0.00000000
22.50000000,0.03285400,4.23950000,0.00111000,282.82324103,0.00110938,283.13717483,0.00001509,0.00727730,576.60713993,-0.00289360,-0.00438370,0.00000000,0.00000000,0.00000000,0.00000000
24.00000000,0.03573400,4.48360000,0.00124922,299.10750878,0.00124844,299.48116053,0.00019554,0.00791279,584.41230206,-0.00325740,-0.00465539,0.00000000,0.00000000,0.00000000,0.00000000
25.50000000,0.03918800,4.69650000,0.00125711,313.31037894,0.00125632,313.70424490,0.00018777,0.00856150,591.70102355,-0.00361426,-0.00494723,0.00000000,0.00000000,0.00000000,0.00000000
27.00000000,0.04325000,4.91820000,0.00134711,328.10030995,0.00134620,328.54229753,0.00000000,0.00938156,599.53585669,-0.00413937,-0.00524219,0.00000000,0.00000000,0.00000000,0.00000000
28.50000000,0.04629800,5.14310000,0.00152422,343.10371764,0.00152306,343.62668396,-0.00005969,0.01008883,606.76602100,-0.00448274,-0.00560610,0.00000000,0.00000000,0.00000000,0.00000000
30.00000000,0.05022600,5.35280000,0.00176067,357.09311112,0.00175912,357.72183306,0.00024714,0.01076175,613.29360347,-0.00474910,-0.00601265,0.00000000,0.00000000,0.00000000,0.00000000
31.50000000,0.05597200,5.55780000,0.00182100,370.76896073,0.00181934,371.44413101,0.00027774,0.01153807,620.58682719,-0.00515000,-0.00638807,0.00000000,0.00000000,0.00000000,0.00000000
33.00000000,0.06162200,5.77470000,0.00192622,385.23867673,0.00192437,385.98073203,-0.00003770,0.01237283,627.07219197,-0.00555509,-0.00681774,0.00000000,0.00000000,0.00000000,0.00000000
34.50000000,0.06743700,5.96930000,0.00229033,398.22072714,0.00228771,399.13278534,0.00009002,0.01310038,633.43902510,-0.00592451,-0.00717587,0.00000000,0.00000000,0.00000000,0.00000000
36.00000000,0.07436500,6.15030000,0.00251222,410.29550167,0.00250907,411.32625514,0.00042697,0.01388443,640.23256512,-0.00627885,-0.00760558,0.00000000,0.00000000,0.00000000,0.00000000
37.50000000,0.08035000,6.35520000,0.00263578,423.96468013,0.00263231,425.08215681,0.00026177,0.01473651,646.53600587,-0.00678766,-0.00794884,0.00000000,0.00000000,0.00000000,0.00000000
39.00000000,0.08845900,6.53630000,0.00288378,436.04612581,0.00287963,437.30358593,0.00005274,0.01559745,652.37181324,-0.00729311,-0.00830434,0.00000000,0.00000000,0.00000000,0.00000000
40.50000000,0.09805500,6.70930000,0.00325933,447.58720865,0.00325403,449.04604456,0.00021708,0.01643743,658.57901313,-0.00771011,-0.00872731,0.00000000,0.00000000,0.00000000,0.00000000
42.00000000,0.10711300,6.89120000,0.00356300,459.72202349,0.00355667,461.36001306,0.00021679,0.01730056,664.38166402,-0.00816578,-0.00913478,0.00000000,0.00000000,0.00000000,0.00000000
43.50000000,0.11843100,7.05940000,0.00391622,470.94289132,0.00390857,472.78720833,0.00020986,0.01819305,670.04297329,-0.00868344,-0.00950960,0.00000000,0.00000000,0.00000000,0.00000000
45.00000000,0.12971400,7.21570000,0.00431044,481.36989275,0.00430118,483.44481093,0.00034388,0.01908078,675.77253622,-0.00910711,-0.00997367,0.00000000,0.00000000,0.00000000,0.00000000
46.50000000,0.14225000,7.37840000,0.00466300,492.22384754,0.00465216,494.51908734,0.00025372,0.01998737,681.19614624,-0.00954606,-0.01044132,0.00000000,0.00000000,0.00000000,0.00000000
48.00000000,0.15610400,7.53070000,0.00511333,502.38400312,0.00510030,504.95285999,0.00008954,0.02091917,685.76899825,-0.01007431,-0.01084485,0.00000000,0.00000000,0.00000000,0.00000000
49.50000000,0.17059800,7.66790000,0.00572911,511.53681564,0.00571276,514.46746690,0.00040329,0.02187974,691.79758441,-0.01056195,-0.01131779,0.00000000,0.00000000,0.00000000,0.00000000
51.00000000,0.18705300,7.82260000,0.00626244,521.85707874,0.00624292,525.12517970,0.00054488,0.02278440,696.31432094,-0.01096910,-0.01181530,0.00000000,0.00000000,0.00000000,0.00000000
52.50000000,0.20330700,7.95500000,0.00676556,530.68967624,0.00674277,534.28008673,0.00044018,0.02376197,700.67005398,-0.01149057,-0.01227140,0.00000000,0.00000000,0.00000000,0.00000000
54.00000000,0.22172400,8.07860000,0.00737756,538.93521288,0.00735047,542.91123735,0.00043991,0.02472738,705.85133061,-0.01201571,-0.01271166,0.00000000,0.00000000,0.00000000,0.00000000
55.50000000,0.24007200,8.21260000,0.00800822,547.87454872,0.00797633,552.26204986,0.00044714,0.02565003,710.62581854,-0.01248898,-0.01316105,0.00000000,0.00000000,0.00000000,0.00000000
57.00000000,0.26011000,8.32900000,0.00859767,555.63976284,0.00856092,560.41696831,0.00029791,0.02666819,715.03581061,-0.01308780,-0.01358039,0.00000000,0.00000000,0.00000000,0.00000000
58.50000000,0.27967700,8.44220000,0.00932233,563.19150028,0.00927915,568.44175918,0.00034239,0.02762948,719.69628564,-0.01358041,-0.01404907,0.00000000,0.00000000,0.00000000,0.00000000
60.00000000,0.30100200,8.55710000,0.01007344,570.85664721,0.01002305,576.60713993,0.00045370,0.02866464,723.91434643,-0.01418802,-0.01447662,0.00000000,0.00000000,0.00000000,0.00000000
61.50000000,0.32175300,8.66710000,0.01075311,578.19490797,0.01069571,584.41230206,0.00052025,0.02965892,728.11066554,-0.01473239,-0.01492652,0.00000000,0.00000000,0.00000000,0.00000000
63.00000000,0.34487100,8.76920000,0.01144411,585.00614819,0.01137912,591.70102355,0.00040101,0.03062257,732.41003718,-0.01524530,-0.01537728,0.00000000,0.00000000,0.00000000,0.00000000
64.50000000,0.36741400,8.87770000,0.01231167,592.24434176,0.01223649,599.53585669,0.00061585,0.03165547,736.42861207,-0.01578366,-0.01587181,0.00000000,0.00000000,0.00000000,0.00000000
66.00000000,0.39059900,8.97810000,0.01306278,598.94217250,0.01297820,606.76602100,0.00066739,0.03267384,740.22887607,-0.01632910,-0.01634474,0.00000000,0.00000000,0.00000000,0.00000000
67.50000000,0.41354900,9.06830000,0.01377622,604.95954633,0.01368219,613.29360347,0.00057045,0.03369061,744.13929476,-0.01683349,-0.01685711,0.00000000,0.00000000,0.00000000,0.00000000
69.00000000,0.43805200,9.16870000,0.01459878,611.65737706,0.01449324,620.58682719,0.00043700,0.03471480,747.79133345,-0.01733631,-0.01737849,0.00000000,0.00000000,0.00000000,0.00000000
70.50000000,0.46238700,9.25650000,0.01547744,617.51464338,0.01535889,627.07219197,0.00060648,0.03576116,751.85688082,-0.01788062,-0.01788054,0.00000000,0.00000000,0.00000000,0.00000000
72.00000000,0.48814100,9.34340000,0.01624733,623.31186939,0.01611676,633.43902510,0.00055440,0.03684328,755.00927682,-0.01844927,-0.01839400,0.00000000,0.00000000,0.00000000,0.00000000
73.50000000,0.51389600,9.43590000,0.01707733,629.48267957,0.01693315,640.23256512,0.00048008,0.03787780,758.79449245,-0.01896439,-0.01891341,0.00000000,0.00000000,0.00000000,0.00000000
75.00000000,0.53961700,9.52040000,0.01797489,635.11979807,0.01781525,646.53600587,0.00043533,0.03891390,762.03615528,-0.01954378,-0.01937013,0.00000000,0.00000000,0.00000000,0.00000000
76.50000000,0.56574400,9.59780000,0.01888000,640.28326519,0.01870398,652.37181324,0.00052352,0.03997373,765.35799533,-0.02014282,-0.01983091,0.00000000,0.00000000,0.00000000,0.00000000
78.00000000,0.59291900,9.68070000,0.01976633,645.81364535,0.01957352,658.57901313,0.00052306,0.04108822,769.00837810,-0.02073740,-0.02035082,0.00000000,0.00000000,0.00000000,0.00000000
79.50000000,0.62026300,9.75730000,0.02067511,650.92374330,0.02046428,664.38166402,0.00050779,0.04216123,772.07312369,-0.02129973,-0.02086150,0.00000000,0.00000000,0.00000000,0.00000000
81.00000000,0.64726900,9.83140000,0.02161400,655.86706260,0.02138373,670.04297329,0.00052930,0.04328063,775.67801513,-0.02189816,-0.02138247,0.00000000,0.00000000,0.00000000,0.00000000
82.50000000,0.67579600,9.90640000,0.02254922,660.87042221,0.02229875,675.77253622,0.00056577,0.04437791,778.38757418,-0.02245915,-0.02191876,0.00000000,0.00000000,0.00000000,0.00000000
84.00000000,0.70445900,9.97660000,0.02350311,665.55356681,0.02323117,681.19614624,0.00057979,0.04548633,781.49780774,-0.02305068,-0.02243565,0.00000000,0.00000000,0.00000000,0.00000000
85.50000000,0.73325700,10.03400000,0.02447956,669.38280470,0.02418473,685.76899825,0.00056470,0.04658190,784.82224835,-0.02362109,-0.02296082,0.00000000,0.00000000,0.00000000,0.00000000
87.00000000,0.76212200,10.11220000,0.02549356,674.59964099,0.02517401,691.79758441,0.00062982,0.04771639,787.91602878,-0.02424665,-0.02346974,0.00000000,0.00000000,0.00000000,0.00000000
88.50000000,0.79234000,10.16880000,0.02644378,678.37550971,0.02610019,696.31432094,0.00060758,0.04887590,790.74638772,-0.02486652,-0.02400938,0.00000000,0.00000000,0.00000000,0.00000000
90.00000000,0.82215200,10.22220000,0.02746900,681.93790175,0.02709850,700.67005398,0.00068724,0.04999339,793.88803724,-0.02542764,-0.02456575,0.00000000,0.00000000,0.00000000,0.00000000
91.50000000,0.85165900,10.28760000,0.02848678,686.30083133,0.02808857,705.85133061,0.00068656,0.05109552,796.23119469,-0.02597035,-0.02512517,0.00000000,0.00000000,0.00000000,0.00000000
93.00000000,0.88235000,10.34740000,0.02945956,690.29017673,0.02903396,710.62581854,0.00066410,0.05227194,799.14813028,-0.02660555,-0.02566639,0.00000000,0.00000000,0.00000000,0.00000000
94.50000000,0.91304100,10.40080000,0.03052989,693.85256878,0.03007313,715.03581061,0.00075100,0.05340449,802.03558115,-0.02717769,-0.02622680,0.00000000,0.00000000,0.00000000,0.00000000
96.00000000,0.94430700,10.45830000,0.03154389,697.68847781,0.03105660,719.69628564,0.00065544,0.05455325,804.94172125,-0.02779854,-0.02675471,0.00000000,0.00000000,0.00000000,0.00000000
97.50000000,0.97564000,10.50850000,0.03263300,701.03739318,0.03211185,723.91434643,0.00074193,0.05571420,807.24506620,-0.02843364,-0.02728056,0.00000000,0.00000000,0.00000000,0.00000000
99.00000000,1.00680400,10.55870000,0.03368089,704.38630855,0.03312611,728.11066554,0.00074871,0.05683643,809.96956446,-0.02901044,-0.02782599,0.00000000,0.00000000,0.00000000,0.00000000
100.50000000,1.03857700,10.61060000,0.03469867,707.84863340,0.03411024,732.41003718,0.00066805,0.05800530,812.28130942,-0.02962383,-0.02838147,0.00000000,0.00000000,0.00000000,0.00000000
102.00000000,1.07102500,10.65760000,0.03578778,710.98407209,0.03516228,736.42861207,0.00079054,0.05918187,814.89615525,-0.03024504,-0.02893683,0.00000000,0.00000000,0.00000000,0.00000000
103.50000000,1.10317000,10.70150000,0.03686189,713.91270525,0.03619874,740.22887607,0.00068102,0.06037730,817.69583256,-0.03089125,-0.02948605,0.00000000,0.00000000,0.00000000,0.00000000
105.00000000,1.13575400,10.74690000,0.03793600,716.94140560,0.03723413,744.13929476,0.00077455,0.06154262,819.84708211,-0.03144948,-0.03009313,0.00000000,0.00000000,0.00000000,0.00000000
106.50000000,1.16840500,10.78840000,0.03901767,719.70993125,0.03827572,747.79133345,0.00072304,0.06271598,822.24515844,-0.03211428,-0.03060170,0.00000000,0.00000000,0.00000000,0.00000000
108.00000000,1.20153000,10.83550000,0.04012556,722.85204109,0.03934143,751.85688082,0.00067888,0.06391571,824.71979118,-0.03276810,-0.03114761,0.00000000,0.00000000,0.00000000,0.00000000
109.50000000,1.23489100,10.86900000,0.04126733,725.08687505,0.04043856,755.00927682,0.00081541,0.06506340,826.75415552,-0.03331062,-0.03175278,0.00000000,0.00000000,0.00000000,0.00000000
111.00000000,1.26848900,10.91200000,0.04236389,727.95546790,0.04149110,758.79449245,0.00075676,0.06629875,829.21715262,-0.03402273,-0.03227602,0.00000000,0.00000000,0.00000000,0.00000000
112.50000000,1.30218900,10.94710000,0.04346056,730.29704019,0.04254265,762.03615528,0.00072720,0.06746318,831.56107350,-0.03458795,-0.03287523,0.00000000,0.00000000,0.00000000,0.00000000
114.00000000,1.33673300,10.98300000,0.04458356,732.69198166,0.04361829,765.35799533,0.00064725,0.06868066,833.50003154,-0.03524070,-0.03343995,0.00000000,0.00000000,0.00000000,0.00000000
115.50000000,1.37124400,11.02290000,0.04576656,735.35376898,0.04475016,769.00837810,0.00076875,0.06988442,835.76994112,-0.03587483,-0.03400959,0.00000000,0.00000000,0.00000000,0.00000000
117.00000000,1.40592400,11.05480000,0.04690456,737.48186460,0.04583777,772.07312369,0.00078936,0.07108841,837.70499837,-0.03656952,-0.03451889,0.00000000,0.00000000,0.00000000,0.00000000
118.50000000,1.44114400,11.09380000,0.04809511,740.08361160,0.04697434,775.67801513,0.00078146,0.07226124,840.01485113,-0.03712940,-0.03513184,0.00000000,0.00000000,0.00000000,0.00000000
120.00000000,1.47629700,11.12020000,0.04925933,741.84479418,0.04808452,778.38757418,0.00082340,0.07345827,842.06721872,-0.03779713,-0.03566114,0.00000000,0.00000000,0.00000000,0.00000000
121.50000000,1.51131500,11.15210000,0.05043856,743.97288980,0.04920775,781.49780774,0.00079369,0.07467033,844.30273984,-0.03836855,-0.03630179,0.00000000,0.00000000,0.00000000,0.00000000
123.00000000,1.54684000,11.18710000,0.05160667,746.30779095,0.05031915,784.82224835,0.00068584,0.07591339,846.28586369,-0.03906368,-0.03684971,0.00000000,0.00000000,0.00000000,0.00000000
124.50000000,1.58243200,11.21830000,0.05281589,748.38918855,0.05146837,787.91602878,0.00071356,0.07713752,848.25652979,-0.03970954,-0.03742798,0.00000000,0.00000000,0.00000000,0.00000000
126.00000000,1.61897000,11.24540000,0.05405156,750.19706916,0.05264136,790.74638772,0.00094810,0.07836362,850.22519292,-0.04038523,-0.03797839,0.00000000,0.00000000,0.00000000,0.00000000
127.50000000,1.65503600,11.27730000,0.05524589,752.32516478,0.05377381,793.88803724,0.00086865,0.07956430,852.12471661,-0.04097636,-0.03858795,0.00000000,0.00000000,0.00000000,0.00000000
129.00000000,1.69160900,11.29800000,0.05642133,753.70609203,0.05488710,796.23119469,0.00066841,0.08080800,854.11553603,-0.04164751,-0.03916049,0.00000000,0.00000000,0.00000000,0.00000000
130.50000000,1.72797900,11.32590000,0.05767956,755.56734181,0.05607741,799.14813028,0.00078132,0.08201343,855.85080184,-0.04224589,-0.03976754,0.00000000,0.00000000,0.00000000,0.00000000
132.00000000,1.76502400,11.35380000,0.05889267,757.42859159,0.05722371,802.03558115,0.00080897,0.08328536,857.76327394,-0.04297113,-0.04031424,0.00000000,0.00000000,0.00000000,0.00000000
133.50000000,1.80244200,11.38170000,0.06012444,759.28984136,0.05838630,804.94172125,0.00076526,0.08453802,859.77240169,-0.04357737,-0.04096065,0.00000000,0.00000000,0.00000000,0.00000000
135.00000000,1.83887900,11.40090000,0.06136756,760.57070142,0.05955822,807.24506620,0.00078572,0.08580585,861.86434482,-0.04425496,-0.04155090,0.00000000,0.00000000,0.00000000,0.00000000
136.50000000,1.87616200,11.42640000,0.06257311,762.27184369,0.06069343,809.96956446,0.00077772,0.08704644,863.58438593,-0.04492786,-0.04211858,0.00000000,0.00000000,0.00000000,0.00000000
138.00000000,1.91398500,11.44550000,0.06382756,763.54603261,0.06187331,812.28130942,0.00076970,0.08831357,865.14677059,-0.04557775,-0.04273582,0.00000000,0.00000000,0.00000000,0.00000000
139.50000000,1.95204500,11.46870000,0.06509322,765.09373851,0.06306233,814.89615525,0.00072641,0.08954387,866.92245763,-0.04624848,-0.04329539,0.00000000,0.00000000,0.00000000,0.00000000
141.00000000,1.99013900,11.49420000,0.06638144,766.79488078,0.06427109,817.69583256,0.00080329,0.09081478,868.44201326,-0.04693240,-0.04388238,0.00000000,0.00000000,0.00000000,0.00000000
142.50000000,2.02782700,11.51090000,0.06763578,767.90896219,0.06544665,819.84708211,0.00079506,0.09205757,870.52213920,-0.04754585,-0.04451172,0.00000000,0.00000000,0.00000000,0.00000000
144.00000000,2.06615700,11.53090000,0.06890144,769.24319142,0.06663143,822.24515844,0.00078705,0.09334258,872.00063173,-0.04823564,-0.04510694,0.00000000,0.00000000,0.00000000,0.00000000
145.50000000,2.10438600,11.55160000,0.07019722,770.62411867,0.06784295,824.71979118,0.00084945,0.09457957,873.91261198,-0.04892204,-0.04565753,0.00000000,0.00000000,0.00000000,0.00000000
147.00000000,2.14342600,11.56670000,0.07143656,771.63146174,0.06900032,826.75415552,0.00070821,0.09587565,875.22844698,-0.04957200,-0.04630365,0.00000000,0.00000000,0.00000000,0.00000000
148.50000000,2.18185800,11.58670000,0.07277356,772.96569097,0.07024740,829.21715262,0.00078441,0.09715542,876.76910393,-0.05028785,-0.04686756,0.00000000,0.00000000,0.00000000,0.00000000
150.00000000,2.22056000,11.60580000,0.07403544,774.23987988,0.07142300,831.56107350,0.00074830,0.09839575,878.38885029,-0.05090574,-0.04749001,0.00000000,0.00000000,0.00000000,0.00000000
151.50000000,2.25976900,11.61860000,0.07535378,775.09378659,0.07264970,833.50003154,0.00078956,0.09975426,880.47994955,-0.05164395,-0.04811030,0.00000000,0.00000000,0.00000000,0.00000000
153.00000000,2.29921500,11.63610000,0.07666067,776.26123717,0.07386428,835.76994112,0.00076052,0.10098132,882.10141865,-0.05225959,-0.04872173,0.00000000,0.00000000,0.00000000,0.00000000
154.50000000,2.33801900,11.64890000,0.07796767,777.11514388,0.07507748,837.70499837,0.00089200,0.10228273,883.37423385,-0.05293094,-0.04935180,0.00000000,0.00000000,0.00000000,0.00000000
156.00000000,2.37722800,11.66720000,0.07924456,778.33596362,0.07626131,840.01485113,0.00080051,0.10354379,884.97117894,-0.05359404,-0.04994975,0.00000000,0.00000000,0.00000000,0.00000000
157.50000000,2.41748500,11.68160000,0.08054778,779.29660867,0.07746811,842.06721872,0.00080634,0.10482117,886.33874722,-0.05428424,-0.05053693,0.00000000,0.00000000,0.00000000,0.00000000
159.00000000,2.45723500,11.69830000,0.08186978,780.41069007,0.07869082,844.30273984,0.00077063,0.10613653,887.86941246,-0.05497401,-0.05116252,0.00000000,0.00000000,0.00000000,0.00000000
160.50000000,2.49799900,11.71110000,0.08322567,781.26459678,0.07994332,846.28586369,0.00083226,0.10741389,889.24879962,-0.05565939,-0.05175450,0.00000000,0.00000000,0.00000000,0.00000000
162.00000000,2.53822300,11.72390000,0.08456267,782.11850349,0.08117683,848.25652979,0.00087284,0.10868241,890.74237568,-0.05630315,-0.05237926,0.00000000,0.00000000,0.00000000,0.00000000
163.50000000,2.57908800,11.73660000,0.08590344,782.96573905,0.08241231,850.22519292,0.00089265,0.10996395,891.94958530,-0.05701755,-0.05294640,0.00000000,0.00000000,0.00000000,0.00000000
165.00000000,2.61964900,11.74860000,0.08721789,783.76627659,0.08362204,852.12471661,0.00075313,0.11129334,893.32167608,-0.05770881,-0.05358453,0.00000000,0.00000000,0.00000000,0.00000000
166.50000000,2.66017700,11.76130000,0.08858122,784.61351215,0.08487522,854.11553603,0.00092476,0.11256235,895.06327066,-0.05837081,-0.05419153,0.00000000,0.00000000,0.00000000,0.00000000
168.00000000,2.70100800,11.77090000,0.08990322,785.25394218,0.08608891,855.85080184,0.00087550,0.11384003,896.75536824,-0.05904422,-0.05479580,0.00000000,0.00000000,0.00000000,0.00000000
169.50000000,2.74288800,11.78210000,0.09130033,786.00111055,0.08736995,857.76327394,0.00092938,0.11512301,897.66999313,-0.05976038,-0.05536263,0.00000000,0.00000000,0.00000000,0.00000000
171.00000000,2.78432800,11.79480000,0.09267867,786.84834611,0.08863217,859.77240169,0.00093513,0.11642035,898.71938564,-0.06043346,-0.05598689,0.00000000,0.00000000,0.00000000,0.00000000
172.50000000,2.82586900,11.80840000,0.09407578,787.75562198,0.08990997,861.86434482,0.00085143,0.11772092,900.13624899,-0.06115088,-0.05657004,0.00000000,0.00000000,0.00000000,0.00000000
174.00000000,2.86768100,11.81720000,0.09544289,788.34268285,0.09115875,863.58438593,0.00090537,0.11896176,901.19805510,-0.06175235,-0.05720941,0.00000000,0.00000000,0.00000000,0.00000000
175.50000000,2.90976400,11.82350000,0.09684000,788.76296505,0.09243332,865.14677059,0.00089043,0.12025182,902.72308946,-0.06246730,-0.05778453,0.00000000,0.00000000,0.00000000,0.00000000
177.00000000,2.95174500,11.83310000,0.09819956,789.40339508,0.09367207,866.92245763,0.00079358,0.12153867,903.89052981,-0.06318739,-0.05835128,0.00000000,0.00000000,0.00000000,0.00000000
178.50000000,2.99433400,11.83870000,0.09960411,789.77697927,0.09495022,868.44201326,0.00087445,0.12280700,905.10351890,-0.06385035,-0.05895665,0.00000000,0.00000000,0.00000000,0.00000000
180.00000000,3.03682200,11.85220000,0.10098244,790.67758400,0.09620291,870.52213920,0.00082549,0.12407306,905.77520169,-0.06455524,-0.05951782,0.00000000,0.00000000,0.00000000,0.00000000
181.50000000,3.07934400,11.85700000,0.10240589,790.99779901,0.09749496,872.00063173,0.00086557,0.12529132,907.12820771,-0.06520059,-0.06009074,0.00000000,0.00000000,0.00000000,0.00000000
183.00000000,3.12206800,11.86820000,0.10378044,791.74496738,0.09874106,873.91261198,0.00076902,0.12654793,909.12148901,-0.06587659,-0.06067134,0.00000000,0.00000000,0.00000000,0.00000000
184.50000000,3.16536700,11.87060000,0.10521889,791.90507489,0.10004340,875.22844698,0.00075454,0.00000000,0.00000000,0.00000000,0.00000000,0.00000000,0.00000000,0.00000000,0.00000000
186.00000000,3.20812600,11.87620000,0.10664233,792.27865907,0.10133051,876.76910393,0.00090303,0.00000000,0.00000000,0.00000000,0.00000000,0.00000000,0.00000000,0.00000000,0.00000000
187.50000000,3.25223600,11.88330000,0.10802433,792.75231045,0.10257855,878.38885029,0.00074581,0.00000000,0.00000000,0.00000000,0.00000000,0.00000000,0.00000000,0.00000000,0.00000000
189.00000000,3.29489300,11.89530000,0.10954167,793.55284799,0.10394702,880.47994955,0.00092773,0.00000000,0.00000000,0.00000000,0.00000000,0.00000000,0.00000000,0.00000000,0.00000000
190.50000000,3.33910500,11.90250000,0.11091256,794.03317051,0.10518180,882.10141865,0.00081151,0.00000000,0.00000000,0.00000000,0.00000000,0.00000000,0.00000000,0.00000000,0.00000000
192.00000000,3.38311400,11.90410000,0.11236600,794.13990885,0.10648928,883.37423385,0.00081724,0.00000000,0.00000000,0.00000000,0.00000000,0.00000000,0.00000000,0.00000000,0.00000000
193.50000000,3.42793400,11.91050000,0.11377811,794.56686220,0.10775794,884.97117894,0.00082299,0.00000000,0.00000000,0.00000000,0.00000000,0.00000000,0.00000000,0.00000000,0.00000000
195.00000000,3.47197600,11.91360000,0.11520900,794.77366773,0.10904183,886.33874722,0.00075436,0.00000000,0.00000000,0.00000000,0.00000000,0.00000000,0.00000000,0.00000000,0.00000000
196.50000000,3.51656000,11.91840000,0.11668500,795.09388275,0.11036447,887.86941246,0.00088814,0.00000000,0.00000000,0.00000000,0.00000000,0.00000000,0.00000000,0.00000000,0.00000000
198.00000000,3.56182000,11.92160000,0.11811967,795.30735943,0.11164841,889.24879962,0.00086672,0.00000000,0.00000000,0.00000000,0.00000000,0.00000000,0.00000000,0.00000000,0.00000000
199.50000000,3.60684300,11.92640000,0.11954689,795.62757444,0.11292404,890.74237568,0.00086582,0.00000000,0.00000000,0.00000000,0.00000000,0.00000000,0.00000000,0.00000000,0.00000000
201.00000000,3.65230500,11.92720000,0.12098900,795.68094361,0.11421133,891.94958530,0.00087125,0.00000000,0.00000000,0.00000000,0.00000000,0.00000000,0.00000000,0.00000000,0.00000000
202.50000000,3.69800400,11.92960000,0.12248756,795.84105112,0.11554725,893.32167608,0.00078987,0.00000000,0.00000000,0.00000000,0.00000000,0.00000000,0.00000000,0.00000000,0.00000000
204.00000000,3.74441300,11.93760000,0.12392222,796.37474281,0.11682455,895.06327066,0.00080884,0.00000000,0.00000000,0.00000000,0.00000000,0.00000000,0.00000000,0.00000000,0.00000000
205.50000000,3.79072100,11.94480000,0.12536822,796.85506533,0.11811029,896.75536824,0.00084790,0.00000000,0.00000000,0.00000000,0.00000000,0.00000000,0.00000000,0.00000000,0.00000000
207.00000000,3.83723100,11.94160000,0.12681789,796.64158866,0.11939763,897.66999313,0.00089337,0.00000000,0.00000000,0.00000000,0.00000000,0.00000000,0.00000000,0.00000000,0.00000000
208.50000000,3.88414700,11.94000000,0.12828633,796.53485032,0.12069996,898.71938564,0.00089891,0.00000000,0.00000000,0.00000000,0.00000000,0.00000000,0.00000000,0.00000000,0.00000000
210.00000000,3.93096100,11.94320000,0.12976233,796.74832699,0.12200729,900.13624899,0.00087097,0.00000000,0.00000000,0.00000000,0.00000000,0.00000000,0.00000000,0.00000000,0.00000000
211.50000000,3.97831600,11.94240000,0.13117078,796.69495783,0.12325318,901.19805510,0.00087677,0.00000000,0.00000000,0.00000000,0.00000000,0.00000000,0.00000000,0.00000000,0.00000000
213.00000000,4.02648300,11.94710000,0.13263922,797.00850169,0.12455050,902.72308946,0.00086896,0.00000000,0.00000000,0.00000000,0.00000000,0.00000000,0.00000000,0.00000000,0.00000000
214.50000000,4.07505500,11.94710000,0.13410400,797.00850169,0.12584291,903.89052981,0.00087450,0.00000000,0.00000000,0.00000000,0.00000000,0.00000000,0.00000000,0.00000000,0.00000000
216.00000000,4.12355900,11.94790000,0.13554989,797.06187086,0.12711702,905.10351890,0.00093290,0.00000000,0.00000000,0.00000000,0.00000000,0.00000000,0.00000000,0.00000000,0.00000000
217.50000000,4.17290900,11.94160000,0.13699211,796.64158866,0.12838628,905.77520169,0.00087873,0.00000000,0.00000000,0.00000000,0.00000000,0.00000000,0.00000000,0.00000000,0.00000000
219.00000000,4.22154900,11.94480000,0.13838544,796.85506533,0.12961098,907.12820771,0.00083156,0.00000000,0.00000000,0.00000000,0.00000000,0.00000000,0.00000000,0.00000000,0.00000000
220.50000000,4.27164200,11.95590000,0.13982767,797.59556256,0.13087708,909.12148901,0.00090307,0.00000000,0.00000000,0.00000000,0.00000000,0.00000000,0.00000000,0.00000000,0.00000000
222.00000000,4.32180200,11.94320000,0.14119478,796.74832699,0.00000000,0.00000000,0.00000000,0.00000000,0.00000000,0.00000000,0.00000000,0.00000000,0.00000000,0.00000000,0.00000000
223.50000000,4.37304500,11.94400000,0.14258433,796.80169616,0.00000000,0.00000000,0.00000000,0.00000000,0.00000000,0.00000000,0.00000000,0.00000000,0.00000000,0.00000000,0.00000000
225.00000000,4.42371300,11.93920000,0.14397400,796.48148115,0.00000000,0.00000000,0.00000000,0.00000000,0.00000000,0.00000000,0.00000000,0.00000000,0.00000000,0.00000000,0.00000000
226.50000000,4.47546200,11.93840000,0.14523211,796.42811198,0.00000000,0.00000000,0.00000000,0.00000000,0.00000000,0.00000000,0.00000000,0.00000000,0.00000000,0.00000000,0.00000000
228.00000000,4.52788700,11.93440000,0.14650911,796.16126613,0.00000000,0.00000000,0.00000000,0.00000000,0.00000000,0.00000000,0.00000000,0.00000000,0.00000000,0.00000000,0.00000000
229.50000000,4.58031300,11.92560000,0.14778600,795.57420527,0.00000000,0.00000000,0.00000000,0.00000000,0.00000000,0.00000000,0.00000000,0.00000000,0.00000000,0.00000000,0.00000000
231.00000000,4.63365100,11.92240000,0.14891278,795.36072860,0.00000000,0.00000000,0.00000000,0.00000000,0.00000000,0.00000000,0.00000000,0.00000000,0.00000000,0.00000000,0.00000000
232.50000000,4.68739400,11.91760000,0.15011456,795.04051358,0.00000000,0.00000000,0.00000000,0.00000000,0.00000000,0.00000000,0.00000000,0.00000000,0.00000000,0.00000000,0.00000000
234.00000000,4.74211800,11.91440000,0.15116622,794.82703690,0.00000000,0.00000000,0.00000000,0.00000000,0.00000000,0.00000000,0.00000000,0.00000000,0.00000000,0.00000000,0.00000000
235.50000000,4.79711300,11.90010000,0.15218033,793.87306300,0.00000000,0.00000000,0.00000000,0.00000000,0.00000000,0.00000000,0.00000000,0.00000000,0.00000000,0.00000000,0.00000000
237.00000000,4.85305300,11.89210000,0.15304411,793.33937131,0.00000000,0.00000000,0.00000000,0.00000000,0.00000000,0.00000000,0.00000000,0.00000000,0.00000000,0.00000000,0.00000000
238.50000000,4.90939900,11.88180000,0.15394544,792.65224326,0.00000000,0.00000000,0.00000000,0.00000000,0.00000000,0.00000000,0.00000000,0.00000000,0.00000000,0.00000000,0.00000000
240.00000000,4.96648900,11.87140000,0.15465911,791.95844406,0.00000000,0.00000000,0.00000000,0.00000000,0.00000000,0.00000000,0.00000000,0.00000000,0.00000000,0.00000000,0.00000000
241.50000000,5.02401900,11.85300000,0.15533511,790.73095317,0.00000000,0.00000000,0.00000000,0.00000000,0.00000000,0.00000000,0.00000000,0.00000000,0.00000000,0.00000000,0.00000000
243.00000000,5.08232500,11.83790000,0.15586100,789.72361010,0.00000000,0.00000000,0.00000000,0.00000000,0.00000000,0.00000000,0.00000000,0.00000000,0.00000000,0.00000000,0.00000000
244.50000000,5.14083400,11.82190000,0.15634922,788.65622671,0.00000000,0.00000000,0.00000000,0.00000000,0.00000000,0.00000000,0.00000000,0.00000000,0.00000000,0.00000000,0.00000000
246.00000000,5.20086500,11.80120000,0.15676233,787.27529946,0.00000000,0.00000000,0.00000000,0.00000000,0.00000000,0.00000000,0.00000000,0.00000000,0.00000000,0.00000000,0.00000000
247.50000000,5.26123300,11.78050000,0.15706278,785.89437221,0.00000000,0.00000000,0.00000000,0.00000000,0.00000000,0.00000000,0.00000000,0.00000000,0.00000000,0.00000000,0.00000000
249.00000000,5.32200700,11.75340000,0.15732578,784.08649160,0.00000000,0.00000000,0.00000000,0.00000000,0.00000000,0.00000000,0.00000000,0.00000000,0.00000000,0.00000000,0.00000000
250.50000000,5.38318600,11.72540000,0.15747600,782.21857068,0.00000000,0.00000000,0.00000000,0.00000000,0.00000000,0.00000000,0.00000000,0.00000000,0.00000000,0.00000000,0.00000000
252.00000000,5.44399400,11.69670000,0.15762622,780.30395173,0.00000000,0.00000000,0.00000000,0.00000000,0.00000000,0.00000000,0.00000000,0.00000000,0.00000000,0.00000000,0.00000000
253.50000000,5.50588300,11.66480000,0.15766378,778.17585611,0.00000000,0.00000000,0.00000000,0.00000000,0.00000000,0.00000000,0.00000000,0.00000000,0.00000000,0.00000000,0.00000000
255.00000000,5.56861700,11.62500000,0.15773900,775.52073995,0.00000000,0.00000000,0.00000000,0.00000000,0.00000000,0.00000000,0.00000000,0.00000000,0.00000000,0.00000000,0.00000000
256.50000000,5.63114800,11.58030000,0.15777644,772.53873762,0.00000000,0.00000000,0.00000000,0.00000000,0.00000000,0.00000000,0.00000000,0.00000000,0.00000000,0.00000000,0.00000000
258.00000000,5.69388200,11.53560000,0.15773889,769.55673529,0.00000000,0.00000000,0.00000000,0.00000000,0.00000000,0.00000000,0.00000000,0.00000000,0.00000000,0.00000000,0.00000000
259.50000000,5.75651400,11.48620000,0.15770133,766.26118909,0.00000000,0.00000000,0.00000000,0.00000000,0.00000000,0.00000000,0.00000000,0.00000000,0.00000000,0.00000000,0.00000000
261.00000000,5.82056600,11.43280000,0.15773878,762.69879704,0.00000000,0.00000000,0.00000000,0.00000000,0.00000000,0.00000000,0.00000000,0.00000000,0.00000000,0.00000000,0.00000000
262.50000000,5.88428100,11.36260000,0.15770122,758.01565245,0.00000000,0.00000000,0.00000000,0.00000000,0.00000000,0.00000000,0.00000000,0.00000000,0.00000000,0.00000000,0.00000000
264.00000000,5.94907900,11.29480000,0.15766356,753.49261536,0.00000000,0.00000000,0.00000000,0.00000000,0.00000000,0.00000000,0.00000000,0.00000000,0.00000000,0.00000000,0.00000000
265.50000000,6.01516300,11.21030000,0.15766333,747.85549686,0.00000000,0.00000000,0.00000000,0.00000000,0.00000000,0.00000000,0.00000000,0.00000000,0.00000000,0.00000000,0.00000000
267.00000000,6.08175900,11.09620000,0.15762567,740.24371910,0.00000000,0.00000000,0.00000000,0.00000000,0.00000000,0.00000000,0.00000000,0.00000000,0.00000000,0.00000000,0.00000000
268.50000000,6.15029000,10.96860000,0.15758789,731.73133662,0.00000000,0.00000000,0.00000000,0.00000000,0.00000000,0.00000000,0.00000000,0.00000000,0.00000000,0.00000000,0.00000000
270.00000000,6.22194400,10.80280000,0.15751267,720.67057630,0.00000000,0.00000000,0.00000000,0.00000000,0.00000000,0.00000000,0.00000000,0.00000000,0.00000000,0.00000000,0.00000000
270.50000000,6.24690400,10.71820000,0.15743756,715.02678666,0.00000000,0.00000000,0.00000000,0.00000000,0.00000000,0.00000000,0.00000000,0.00000000,0.00000000,0.00000000,0.00000000