File: polyN_optimization/DP780_results/DATA/UT_60_3.csv
Time[s],Displacement[mm],Force[kN],EngStrain_longi,EngStress[MPa],TrueStrain,TrueStress[MPa],TrueStrainRate[1/s],PlasticStrain_longi,PlasticStress[MPa],PlasticStrain_thick,PlasticStrain_width,R-Value,Thickness[mm],Width[mm], Young's Modulus [MPa]
0.00000000,0.00000000,-0.01580000,0.00000000,-1.04944512,0.00000000,-1.04944512,0.00000000,0.00057699,410.60098727,0.00038007,-0.00095706,0.90694707,1.51080000,9.96530000,238042.98003211
1.50000000,0.00215300,0.31920000,0.00006200,21.20144829,0.00006200,21.20276278,0.00008266,0.00072925,424.98478774,0.00020738,-0.00093663,0.00000000,0.00000000,0.00000000,0.00000000
3.00000000,0.00342100,0.66610000,0.00006578,44.24274658,0.00006578,44.24565677,-0.00000978,0.00084994,437.33167555,0.00019580,-0.00104575,0.00000000,0.00000000,0.00000000,0.00000000
4.50000000,0.00641200,1.02650000,0.00017244,68.18072266,0.00017243,68.19248005,0.00006177,0.00113172,449.75559014,0.00021219,-0.00134391,0.00000000,0.00000000,0.00000000,0.00000000
6.00000000,0.00848900,1.34310000,0.00021222,89.20947746,0.00021220,89.22840969,-0.00001044,0.00141921,462.35093101,-0.00008250,-0.00133671,0.00000000,0.00000000,0.00000000,0.00000000
7.50000000,0.01076200,1.64060000,0.00035722,108.96959922,0.00035716,109.00852559,0.00014195,0.00172070,473.63161130,-0.00023308,-0.00148761,0.00000000,0.00000000,0.00000000,0.00000000
9.00000000,0.01227200,1.94200000,0.00038178,128.98876124,0.00038170,129.03800629,0.00012929,0.00211014,484.53505849,-0.00028740,-0.00182274,0.00000000,0.00000000,0.00000000,0.00000000
10.50000000,0.01444400,2.20680000,0.00043222,146.57693013,0.00043213,146.64028394,0.00005775,0.00254653,495.68547536,-0.00052259,-0.00202394,0.00000000,0.00000000,0.00000000,0.00000000
12.00000000,0.01555700,2.47470000,0.00045300,164.37100280,0.00045290,164.44546287,-0.00007219,0.00285813,505.44466165,-0.00073359,-0.00212454,0.00000000,0.00000000,0.00000000,0.00000000
13.50000000,0.01812400,2.74190000,0.00053989,182.11858108,0.00053974,182.21690487,-0.00011838,0.00322311,515.03078570,-0.00087824,-0.00234487,0.00000000,0.00000000,0.00000000,0.00000000
15.00000000,0.02104600,2.99550000,0.00066822,198.96283950,0.00066800,199.09579089,-0.00006285,0.00385988,524.76097483,-0.00119873,-0.00266115,0.00000000,0.00000000,0.00000000,0.00000000
16.50000000,0.02424400,3.24590000,0.00079811,215.59455207,0.00079779,215.76662048,0.00022095,0.00438184,533.43024655,-0.00146256,-0.00291928,0.00000000,0.00000000,0.00000000,0.00000000
18.00000000,0.02629200,3.50830000,0.00083044,233.02331157,0.00083010,233.21682448,0.00018341,0.00487803,541.93411677,-0.00171448,-0.00316355,0.00000000,0.00000000,0.00000000,0.00000000
19.50000000,0.02820900,3.75070000,0.00087667,249.12365952,0.00087628,249.34205793,0.00003752,0.00549468,550.88944326,-0.00207148,-0.00342320,0.00000000,0.00000000,0.00000000,0.00000000
21.00000000,0.03024800,3.99390000,0.00094089,265.27714394,0.00094045,265.52674025,-0.00009702,0.00608313,558.66485157,-0.00227977,-0.00380337,0.00000000,0.00000000,0.00000000,0.00000000
22.50000000,0.03357200,4.24510000,0.00106167,281.96199297,0.00106110,282.26134262,-0.00014207,0.00659723,566.34706594,-0.00244010,-0.00415713,0.00000000,0.00000000,0.00000000,0.00000000
24.00000000,0.03699400,4.47640000,0.00128722,297.32507252,0.00128639,297.70779596,0.00025502,0.00719156,574.30576337,-0.00275878,-0.00443278,0.00000000,0.00000000,0.00000000,0.00000000
25.50000000,0.03987500,4.71090000,0.00133589,312.90069791,0.00133500,313.31869847,0.00035977,0.00792080,581.96937476,-0.00318706,-0.00473374,0.00000000,0.00000000,0.00000000,0.00000000
27.00000000,0.04451400,4.95090000,0.00132167,328.84163648,0.00132079,329.27625550,0.00000044,0.00857495,589.66065852,-0.00356668,-0.00500826,0.00000000,0.00000000,0.00000000,0.00000000
28.50000000,0.04838000,5.16700000,0.00147200,343.19512324,0.00147092,343.70030647,-0.00015754,0.00919283,596.31586605,-0.00391127,-0.00528156,0.00000000,0.00000000,0.00000000,0.00000000
30.00000000,0.05223800,5.39110000,0.00177244,358.07997463,0.00177088,358.71465149,0.00006766,0.01000142,603.31075073,-0.00437115,-0.00563027,0.00000000,0.00000000,0.00000000,0.00000000
31.50000000,0.05761600,5.62160000,0.00196067,373.38991771,0.00195875,374.12201088,0.00035999,0.01076012,609.74624960,-0.00481008,-0.00595003,0.00000000,0.00000000,0.00000000,0.00000000
33.00000000,0.06367500,5.82970000,0.00205067,387.21203986,0.00204857,388.00608269,0.00022444,0.01141893,616.83266442,-0.00508415,-0.00633478,0.00000000,0.00000000,0.00000000,0.00000000
34.50000000,0.07013000,6.03550000,0.00219733,400.88139469,0.00219492,401.76226474,-0.00008226,0.01213604,623.20762966,-0.00544176,-0.00669428,0.00000000,0.00000000,0.00000000,0.00000000
36.00000000,0.07760000,6.24360000,0.00260311,414.70351683,0.00259973,415.78303617,0.00013499,0.01293150,629.31638126,-0.00582277,-0.00710873,0.00000000,0.00000000,0.00000000,0.00000000
37.50000000,0.08635700,6.43500000,0.00288422,427.41641534,0.00288007,428.64917927,0.00025417,0.01370841,636.08013596,-0.00618935,-0.00751906,0.00000000,0.00000000,0.00000000,0.00000000
39.00000000,0.09513900,6.62400000,0.00311344,439.96990446,0.00310861,441.33972632,0.00035227,0.01444906,641.79371761,-0.00656507,-0.00788399,0.00000000,0.00000000,0.00000000,0.00000000
40.50000000,0.10466600,6.81380000,0.00340244,452.57653005,0.00339667,454.11639655,0.00024651,0.01532114,647.66218222,-0.00705055,-0.00827059,0.00000000,0.00000000,0.00000000,0.00000000
42.00000000,0.11521200,6.98450000,0.00377756,463.91452260,0.00377044,465.66698549,0.00029911,0.01613499,653.98480536,-0.00755200,-0.00858299,0.00000000,0.00000000,0.00000000,0.00000000
43.50000000,0.12635900,7.15430000,0.00414178,475.19273664,0.00413322,477.16087936,0.00031428,0.01696377,659.35540606,-0.00795874,-0.00900504,0.00000000,0.00000000,0.00000000,0.00000000
45.00000000,0.13973300,7.31860000,0.00452856,486.10563750,0.00451833,488.30699389,0.00020176,0.01775962,664.54267482,-0.00834130,-0.00941832,0.00000000,0.00000000,0.00000000,0.00000000
46.50000000,0.15240400,7.47250000,0.00504278,496.32776436,0.00503011,498.83063498,0.00024633,0.01866800,670.63772996,-0.00882414,-0.00984385,0.00000000,0.00000000,0.00000000,0.00000000
48.00000000,0.16700100,7.62800000,0.00555667,506.65616414,0.00554129,509.47148356,0.00055256,0.01954403,675.63100050,-0.00926984,-0.01027418,0.00000000,0.00000000,0.00000000,0.00000000
49.50000000,0.18223600,7.76440000,0.00598467,515.71593089,0.00596683,518.80231883,0.00058238,0.02040249,680.29323902,-0.00964908,-0.01075340,0.00000000,0.00000000,0.00000000,0.00000000
51.00000000,0.19852100,7.89200000,0.00647278,524.19119656,0.00645192,527.58416969,0.00018636,0.02125966,685.83645499,-0.01008351,-0.01117615,0.00000000,0.00000000,0.00000000,0.00000000
52.50000000,0.21632800,8.02120000,0.00709611,532.77273516,0.00707105,536.55334968,0.00029813,0.02221811,690.69357354,-0.01060668,-0.01161143,0.00000000,0.00000000,0.00000000,0.00000000
54.00000000,0.23400100,8.14560000,0.00770433,541.03545498,0.00767481,545.20377247,0.00043227,0.02313659,695.31273593,-0.01103182,-0.01210477,0.00000000,0.00000000,0.00000000,0.00000000
55.50000000,0.25363400,8.25880000,0.00829744,548.55426434,0.00826321,553.10586287,0.00029050,0.02404474,700.37110668,-0.01151943,-0.01252531,0.00000000,0.00000000,0.00000000,0.00000000
57.00000000,0.27289400,8.37450000,0.00897700,556.23912514,0.00893695,561.23248377,0.00038701,0.02497696,704.79720088,-0.01198281,-0.01299415,0.00000000,0.00000000,0.00000000,0.00000000
58.50000000,0.29327100,8.48770000,0.00965289,563.75793450,0.00960660,569.19982720,0.00062495,0.02594876,709.14949006,-0.01253335,-0.01341541,0.00000000,0.00000000,0.00000000,0.00000000
60.00000000,0.31334500,8.59380000,0.01023867,570.80515776,0.01018661,576.64944150,0.00052052,0.02690004,713.77672964,-0.01304915,-0.01385090,0.00000000,0.00000000,0.00000000,0.00000000
61.50000000,0.33524500,8.70060000,0.01095967,577.89887542,0.01090004,584.23245446,0.00041593,0.02780864,717.98961170,-0.01354370,-0.01426494,0.00000000,0.00000000,0.00000000,0.00000000
63.00000000,0.35603100,8.80670000,0.01167700,584.94609868,0.01160935,591.77651427,0.00045298,0.02879452,721.83209827,-0.01410557,-0.01468895,0.00000000,0.00000000,0.00000000,0.00000000
64.50000000,0.37867600,8.90400000,0.01239056,591.40882086,0.01231442,598.73670471,0.00056398,0.02977273,726.33059289,-0.01459480,-0.01517793,0.00000000,0.00000000,0.00000000,0.00000000
66.00000000,0.40152300,8.99490000,0.01309278,597.44645134,0.01300781,605.26868496,0.00026697,0.03079548,730.37343375,-0.01516101,-0.01563447,0.00000000,0.00000000,0.00000000,0.00000000
67.50000000,0.42497800,9.09220000,0.01394522,603.90917352,0.01384888,612.33082114,0.00037042,0.03174273,734.09901717,-0.01563612,-0.01610660,0.00000000,0.00000000,0.00000000,0.00000000
69.00000000,0.44877100,9.17990000,0.01472633,609.73425815,0.01461895,618.71340808,0.00052544,0.03272372,738.12567216,-0.01613908,-0.01658464,0.00000000,0.00000000,0.00000000,0.00000000
70.50000000,0.47303700,9.27160000,0.01550000,615.82502510,0.01538110,625.37031298,0.00055481,0.03378148,741.78095853,-0.01672370,-0.01705778,0.00000000,0.00000000,0.00000000,0.00000000
72.00000000,0.49730500,9.35770000,0.01630733,621.54383681,0.01617580,631.67955933,0.00049510,0.03475904,745.32788024,-0.01719072,-0.01756832,0.00000000,0.00000000,0.00000000,0.00000000
73.50000000,0.52255200,9.43990000,0.01718611,627.00360827,0.01704010,637.77936194,0.00060547,0.03577727,749.23757081,-0.01769367,-0.01808360,0.00000000,0.00000000,0.00000000,0.00000000
75.00000000,0.54901600,9.52440000,0.01799356,632.61614705,0.01783359,643.99916084,0.00065674,0.03683010,752.46584893,-0.01824143,-0.01858867,0.00000000,0.00000000,0.00000000,0.00000000
76.50000000,0.57507500,9.60420000,0.01881233,637.91650913,0.01863757,649.91720714,0.00046465,0.03787710,755.91811851,-0.01876959,-0.01910752,0.00000000,0.00000000,0.00000000,0.00000000
78.00000000,0.60170900,9.67910000,0.01975489,642.89141037,0.01956229,655.59165875,0.00062617,0.03888682,759.40413735,-0.01927986,-0.01960697,0.00000000,0.00000000,0.00000000,0.00000000
79.50000000,0.62749800,9.75170000,0.02063744,647.71354429,0.02042738,661.08069657,0.00064763,0.03995800,762.60935684,-0.01987045,-0.02008755,0.00000000,0.00000000,0.00000000,0.00000000
81.00000000,0.65582200,9.82510000,0.02150878,652.58881467,0.02128073,666.62520246,0.00071323,0.04101367,765.80875896,-0.02041191,-0.02060176,0.00000000,0.00000000,0.00000000,0.00000000
82.50000000,0.68316600,9.89840000,0.02238389,657.45744299,0.02213705,672.17389734,0.00055108,0.04212565,769.00179466,-0.02099839,-0.02112727,0.00000000,0.00000000,0.00000000,0.00000000
84.00000000,0.71162600,9.96620000,0.02336033,661.96075813,0.02309166,677.42438210,0.00066068,0.04318271,772.15152906,-0.02157097,-0.02161174,0.00000000,0.00000000,0.00000000,0.00000000
85.50000000,0.73957800,10.03160000,0.02428422,666.30466389,0.02399405,682.48535442,0.00070414,0.04422844,775.19343073,-0.02210533,-0.02212311,0.00000000,0.00000000,0.00000000,0.00000000
87.00000000,0.76888300,10.09140000,0.02514800,670.27661442,0.02483699,687.13273072,0.00062288,0.04536156,778.42123637,-0.02271593,-0.02264563,0.00000000,0.00000000,0.00000000,0.00000000
88.50000000,0.79828900,10.16160000,0.02614322,674.93933895,0.02580733,692.58442807,0.00060040,0.04642681,781.37790342,-0.02329067,-0.02313614,0.00000000,0.00000000,0.00000000,0.00000000
90.00000000,0.82732300,10.21980000,0.02716100,678.80501655,0.02679869,697.24203961,0.00070217,0.04748780,784.23145356,-0.02383000,-0.02365779,0.00000000,0.00000000,0.00000000,0.00000000
91.50000000,0.85689800,10.27880000,0.02809611,682.72383062,0.02770866,701.90571522,0.00065763,0.04861188,787.07688272,-0.02442713,-0.02418475,0.00000000,0.00000000,0.00000000,0.00000000
93.00000000,0.88735200,10.33390000,0.02908389,686.38360443,0.02866898,706.34630892,0.00067169,0.04973466,789.92675240,-0.02504194,-0.02469272,0.00000000,0.00000000,0.00000000,0.00000000
94.50000000,0.91800900,10.39210000,0.03009422,690.24928203,0.02965028,711.02179731,0.00064924,0.05082443,792.69950618,-0.02557204,-0.02525239,0.00000000,0.00000000,0.00000000,0.00000000
96.00000000,0.94846300,10.44150000,0.03105189,693.53045855,0.03057953,715.06588929,0.00056110,0.05195244,795.39518470,-0.02616928,-0.02578315,0.00000000,0.00000000,0.00000000,0.00000000
97.50000000,0.97952500,10.49330000,0.03209589,696.97104446,0.03159158,719.34094966,0.00072789,0.05309351,798.05000924,-0.02680631,-0.02628720,0.00000000,0.00000000,0.00000000,0.00000000
99.00000000,1.01092600,10.54440000,0.03312500,700.36513597,0.03258819,723.56473109,0.00071274,0.05424691,800.83288170,-0.02743594,-0.02681097,0.00000000,0.00000000,0.00000000,0.00000000
100.50000000,1.04219200,10.59060000,0.03412400,703.43376664,0.03355469,727.43774049,0.00064649,0.05531799,803.50527038,-0.02793480,-0.02738319,0.00000000,0.00000000,0.00000000,0.00000000
102.00000000,1.07396400,10.64250000,0.03519433,706.88099460,0.03458917,731.75919996,0.00063144,0.05650148,806.09644380,-0.02857227,-0.02792921,0.00000000,0.00000000,0.00000000,0.00000000
103.50000000,1.10617600,10.68790000,0.03624967,709.89648882,0.03560811,735.62999990,0.00073934,0.05764588,808.43405486,-0.02917010,-0.02847578,0.00000000,0.00000000,0.00000000,0.00000000
105.00000000,1.13852300,10.73100000,0.03725622,712.75921570,0.03657898,739.31393143,0.00068076,0.05876725,810.87794839,-0.02976410,-0.02900315,0.00000000,0.00000000,0.00000000,0.00000000
106.50000000,1.17151300,10.77490000,0.03836789,715.67507905,0.03765014,743.13402096,0.00067275,0.05994135,813.07801959,-0.03039119,-0.02955016,0.00000000,0.00000000,0.00000000,0.00000000
108.00000000,1.20457000,10.81390000,0.03945700,718.26548157,0.03869846,746.60608267,0.00078047,0.06106689,815.58397280,-0.03098291,-0.03008398,0.00000000,0.00000000,0.00000000,0.00000000
109.50000000,1.23779600,10.85220000,0.04051989,720.80938968,0.03972048,750.01650606,0.00075083,0.06219721,818.27661768,-0.03157447,-0.03062274,0.00000000,0.00000000,0.00000000,0.00000000
111.00000000,1.27095500,10.89610000,0.04160156,723.72525302,0.04075949,753.83334935,0.00069243,0.06338656,820.10295731,-0.03223407,-0.03115249,0.00000000,0.00000000,0.00000000,0.00000000
112.50000000,1.30455200,10.93200000,0.04271700,726.10975175,0.04182981,757.12698202,0.00070619,0.06454249,822.76182000,-0.03278538,-0.03175711,0.00000000,0.00000000,0.00000000,0.00000000
114.00000000,1.33892800,10.96700000,0.04382111,728.43447196,0.04288813,760.35527989,0.00077018,0.06566077,824.94422431,-0.03339163,-0.03226914,0.00000000,0.00000000,0.00000000,0.00000000
115.50000000,1.37225600,11.00530000,0.04493656,730.97838007,0.04395617,763.82603066,0.00073341,0.06682130,826.81489702,-0.03402608,-0.03279522,0.00000000,0.00000000,0.00000000,0.00000000
117.00000000,1.40751000,11.04120000,0.04607078,733.36287880,0.04504103,767.14947702,0.00076130,0.06799296,828.99189116,-0.03463812,-0.03335484,0.00000000,0.00000000,0.00000000,0.00000000
118.50000000,1.44205400,11.07230000,0.04720878,735.42855876,0.04612832,770.14724216,0.00068150,0.06915947,831.21882111,-0.03521634,-0.03394313,0.00000000,0.00000000,0.00000000,0.00000000
120.00000000,1.47720700,11.10580000,0.04835800,737.65364810,0.04722513,773.32510321,0.00073101,0.07033520,833.40729614,-0.03581190,-0.03452330,0.00000000,0.00000000,0.00000000,0.00000000
121.50000000,1.51266400,11.13850000,0.04948844,739.82560098,0.04830285,776.43841913,0.00076602,0.07147945,835.33608116,-0.03642676,-0.03505268,0.00000000,0.00000000,0.00000000,0.00000000
123.00000000,1.54774900,11.17120000,0.05068644,741.99755386,0.04944371,779.60677165,0.00075076,0.07264367,837.17702206,-0.03701589,-0.03562778,0.00000000,0.00000000,0.00000000,0.00000000
124.50000000,1.58283500,11.19830000,0.05178689,743.79755150,0.05049052,782.31651266,0.00068572,0.07385046,839.28768196,-0.03765513,-0.03619533,0.00000000,0.00000000,0.00000000,0.00000000
126.00000000,1.61954200,11.23180000,0.05297367,746.02264085,0.05161822,785.54219555,0.00079199,0.07506200,841.51452582,-0.03830508,-0.03675692,0.00000000,0.00000000,0.00000000,0.00000000
127.50000000,1.65574300,11.25490000,0.05416044,747.55695618,0.05274466,788.04497318,0.00076959,0.07623640,843.25887584,-0.03889321,-0.03734319,0.00000000,0.00000000,0.00000000,0.00000000
129.00000000,1.69191000,11.28280000,0.05539233,749.41009029,0.05391258,790.92166382,0.00083272,0.07744061,844.96636679,-0.03954934,-0.03789127,0.00000000,0.00000000,0.00000000,0.00000000
130.50000000,1.72858400,11.30920000,0.05652278,751.16359353,0.05498312,793.62144641,0.00076786,0.07858775,846.75138726,-0.04012011,-0.03846763,0.00000000,0.00000000,0.00000000,0.00000000
132.00000000,1.76522400,11.33550000,0.05769833,752.91045472,0.05609516,796.35213311,0.00071026,0.07980086,848.88571872,-0.04071757,-0.03908328,0.00000000,0.00000000,0.00000000,0.00000000
133.50000000,1.80220200,11.36340000,0.05894144,754.76358883,0.05726977,799.25044497,0.00075205,0.08098961,850.76359529,-0.04136609,-0.03962352,0.00000000,0.00000000,0.00000000,0.00000000
135.00000000,1.83951900,11.38490000,0.06016211,756.19163124,0.05842183,801.68571618,0.00072287,0.08223815,852.81955284,-0.04205097,-0.04018718,0.00000000,0.00000000,0.00000000,0.00000000
136.50000000,1.87670000,11.40810000,0.06134133,757.73258864,0.05953352,804.21291593,0.00077862,0.08340126,854.39840979,-0.04264315,-0.04075811,0.00000000,0.00000000,0.00000000,0.00000000
138.00000000,1.91438800,11.43120000,0.06257322,759.26690397,0.06069353,806.77668068,0.00070700,0.08463521,855.97509912,-0.04329285,-0.04134236,0.00000000,0.00000000,0.00000000,0.00000000
139.50000000,1.95200800,11.45350000,0.06382767,760.74808285,0.06187341,809.30485790,0.00075570,0.08584511,857.94961119,-0.04393718,-0.04190793,0.00000000,0.00000000,0.00000000,0.00000000
141.00000000,1.99013600,11.47180000,0.06504444,761.96357941,0.06301653,811.52507712,0.00077591,0.08708599,859.60373844,-0.04457792,-0.04250807,0.00000000,0.00000000,0.00000000,0.00000000
142.50000000,2.02792500,11.49180000,0.06625378,763.29199096,0.06415136,813.86296891,0.00067642,0.08828382,861.33317012,-0.04520207,-0.04308175,0.00000000,0.00000000,0.00000000,0.00000000
144.00000000,2.06598500,11.51650000,0.06753067,764.93257922,0.06534819,816.58898625,0.00079514,0.08953235,862.88242910,-0.04590004,-0.04363231,0.00000000,0.00000000,0.00000000,0.00000000
145.50000000,2.10445100,11.53410000,0.06874756,766.10158138,0.06648745,818.76919241,0.00078737,0.09073003,864.74208065,-0.04654207,-0.04418796,0.00000000,0.00000000,0.00000000,0.00000000
147.00000000,2.14295000,11.55480000,0.06999444,767.47648733,0.06765346,821.19557769,0.00072329,0.09195904,866.16233317,-0.04717900,-0.04478004,0.00000000,0.00000000,0.00000000,0.00000000
148.50000000,2.18158500,11.57150000,0.07121133,768.58571098,0.06879010,823.31772424,0.00065938,0.09319337,867.58207880,-0.04782149,-0.04537189,0.00000000,0.00000000,0.00000000,0.00000000
150.00000000,2.22032000,11.58750000,0.07248444,769.64844021,0.06997787,825.43597982,0.00077758,0.09438291,869.50222967,-0.04845331,-0.04592960,0.00000000,0.00000000,0.00000000,0.00000000
151.50000000,2.25996900,11.60500000,0.07376144,770.81080032,0.07116785,827.66691834,0.00081868,0.09560340,871.04015721,-0.04910743,-0.04649597,0.00000000,0.00000000,0.00000000,0.00000000
153.00000000,2.29890800,11.62100000,0.07504211,771.87352956,0.07235983,829.79654873,0.00083859,0.09684693,872.42365727,-0.04977832,-0.04706861,0.00000000,0.00000000,0.00000000,0.00000000
154.50000000,2.33815100,11.63770000,0.07631156,772.98275320,0.07353997,831.97026951,0.00084463,0.09805684,874.13437732,-0.05034409,-0.04771275,0.00000000,0.00000000,0.00000000,0.00000000
156.00000000,2.37729200,11.65290000,0.07759222,773.99234597,0.07472913,834.04813208,0.00085064,0.09928941,875.74216054,-0.05102092,-0.04826849,0.00000000,0.00000000,0.00000000,0.00000000
157.50000000,2.41707600,11.66880000,0.07882033,775.04843315,0.07586816,836.13800901,0.00082185,0.10051475,877.11664129,-0.05162294,-0.04889181,0.00000000,0.00000000,0.00000000,0.00000000
159.00000000,2.45719800,11.68160000,0.08014978,775.89861654,0.07709971,838.08671824,0.00093898,0.10174374,878.85235104,-0.05228123,-0.04946252,0.00000000,0.00000000,0.00000000,0.00000000
160.50000000,2.49779300,11.69510000,0.08141922,776.79529434,0.07827427,840.04136303,0.00085441,0.10299625,880.25543330,-0.05296000,-0.05003625,0.00000000,0.00000000,0.00000000,0.00000000
162.00000000,2.53801600,11.71030000,0.08268489,777.80488712,0.07944396,842.11759778,0.00074951,0.10423162,881.40760587,-0.05365699,-0.05057464,0.00000000,0.00000000,0.00000000,0.00000000
163.50000000,2.57844200,11.72070000,0.08398433,778.49566112,0.08064345,843.87710022,0.00078307,0.10542108,882.69922585,-0.05424755,-0.05117353,0.00000000,0.00000000,0.00000000,0.00000000
165.00000000,2.61890200,11.73180000,0.08532889,779.23292953,0.08188306,845.72400959,0.00083761,0.10666879,884.15618030,-0.05492811,-0.05174068,0.00000000,0.00000000,0.00000000,0.00000000
166.50000000,2.65997000,11.74140000,0.08662078,779.87056707,0.08307268,847.42356216,0.00090556,0.10787109,885.64217431,-0.05556825,-0.05230284,0.00000000,0.00000000,0.00000000,0.00000000
168.00000000,2.70107200,11.75890000,0.08790156,781.03292717,0.08425066,849.68693641,0.00081499,0.10916296,887.03097987,-0.05623874,-0.05292422,0.00000000,0.00000000,0.00000000,0.00000000
169.50000000,2.74203900,11.76770000,0.08923856,781.61742826,0.08547888,851.36783855,0.00087603,0.11036123,888.03919888,-0.05688794,-0.05347330,0.00000000,0.00000000,0.00000000,0.00000000
171.00000000,2.78408700,11.77970000,0.09056056,782.41447518,0.08669184,853.27036473,0.00078528,0.11161820,889.76005638,-0.05755016,-0.05406804,0.00000000,0.00000000,0.00000000,0.00000000
172.50000000,2.82569600,11.79080000,0.09187122,783.15174359,0.08789294,855.10085146,0.00084623,0.11283367,890.72682122,-0.05817721,-0.05465647,0.00000000,0.00000000,0.00000000,0.00000000
174.00000000,2.86679900,11.79640000,0.09323078,783.52369883,0.08913733,856.57222268,0.00085209,0.11408195,892.20452951,-0.05888094,-0.05520101,0.00000000,0.00000000,0.00000000,0.00000000
175.50000000,2.90877900,11.81320000,0.09455278,784.63956453,0.09034586,858.82941491,0.00083055,0.11528459,893.16248407,-0.05951000,-0.05577459,0.00000000,0.00000000,0.00000000,0.00000000
177.00000000,2.95079400,11.81950000,0.09590489,785.05801416,0.09158040,860.34891578,0.00080214,0.11654272,894.71322827,-0.06016576,-0.05637696,0.00000000,0.00000000,0.00000000,0.00000000
178.50000000,2.99287600,11.82510000,0.09724944,785.42996940,0.09280654,861.81259757,0.00084228,0.11776729,895.99510956,-0.06083797,-0.05692933,0.00000000,0.00000000,0.00000000,0.00000000
180.00000000,3.03566800,11.83470000,0.09860900,786.06760694,0.09404483,863.58094759,0.00080704,0.11898799,897.09420495,-0.06149406,-0.05749392,0.00000000,0.00000000,0.00000000,0.00000000
181.50000000,3.07832500,11.84350000,0.09995344,786.65210802,0.09526786,865.28069580,0.00084001,0.12017984,898.34995694,-0.06216037,-0.05801947,0.00000000,0.00000000,0.00000000,0.00000000
183.00000000,3.12081300,11.85540000,0.10130933,787.44251289,0.09649977,867.21778891,0.00083231,0.12140535,899.21425488,-0.06285866,-0.05854669,0.00000000,0.00000000,0.00000000,0.00000000
184.50000000,3.16370700,11.85300000,0.10266133,787.28310350,0.09772665,868.10663662,0.00080387,0.12255948,900.13597509,-0.06350876,-0.05905073,0.00000000,0.00000000,0.00000000,0.00000000
186.00000000,3.20690400,11.87140000,0.10400589,788.50524213,0.09894528,870.51443073,0.00084377,0.12377616,901.53982789,-0.06421285,-0.05956331,0.00000000,0.00000000,0.00000000,0.00000000
187.50000000,3.24976400,11.87140000,0.10532789,788.50524213,0.10014202,871.55683466,0.00078162,0.12502555,902.67176671,-0.06488757,-0.06013798,0.00000000,0.00000000,0.00000000,0.00000000
189.00000000,3.29265700,11.87860000,0.10668000,788.98347029,0.10136454,873.15222690,0.00072643,0.12617788,903.10900739,-0.06555387,-0.06062402,0.00000000,0.00000000,0.00000000,0.00000000
190.50000000,3.33693700,11.88100000,0.10807711,789.14287967,0.10262618,874.43116236,0.00081359,0.12735898,904.12003797,-0.06622184,-0.06113715,0.00000000,0.00000000,0.00000000,0.00000000
192.00000000,3.38037100,11.89210000,0.10945544,789.88014808,0.10386930,876.33683075,0.00081939,0.12850690,904.91919713,-0.06688647,-0.06162043,0.00000000,0.00000000,0.00000000,0.00000000
193.50000000,3.42441400,11.89210000,0.11083744,789.88014808,0.10511419,877.42844511,0.00084539,0.12965195,906.02147849,-0.06751232,-0.06213963,0.00000000,0.00000000,0.00000000,0.00000000
195.00000000,3.46855800,11.90010000,0.11219711,790.41151270,0.10633744,879.09340101,0.00081737,0.00000000,0.00000000,0.00000000,0.00000000,0.00000000,0.00000000,0.00000000,0.00000000
196.50000000,3.51310800,11.90810000,0.11360544,790.94287732,0.10760290,880.79829443,0.00082991,0.00000000,0.00000000,0.00000000,0.00000000,0.00000000,0.00000000,0.00000000,0.00000000
198.00000000,3.55759000,11.90890000,0.11498378,790.99601378,0.10883986,881.94772365,0.00082210,0.00000000,0.00000000,0.00000000,0.00000000,0.00000000,0.00000000,0.00000000,0.00000000
199.50000000,3.60251100,11.91360000,0.11638467,791.30819049,0.11009549,883.40433047,0.00094215,0.00000000,0.00000000,0.00000000,0.00000000,0.00000000,0.00000000,0.00000000,0.00000000
201.00000000,3.64702700,11.91600000,0.11774044,791.46759988,0.11130919,884.65534685,0.00086025,0.00000000,0.00000000,0.00000000,0.00000000,0.00000000,0.00000000,0.00000000,0.00000000
202.50000000,3.69249000,11.91920000,0.11913756,791.68014573,0.11255835,885.99898307,0.00093983,0.00000000,0.00000000,0.00000000,0.00000000,0.00000000,0.00000000,0.00000000,0.00000000
204.00000000,3.73849300,11.92480000,0.12054978,792.05210096,0.11381944,887.53380572,0.00086504,0.00000000,0.00000000,0.00000000,0.00000000,0.00000000,0.00000000,0.00000000,0.00000000
205.50000000,3.78429300,11.92320000,0.12188678,791.94582804,0.11501189,888.47355319,0.00084380,0.00000000,0.00000000,0.00000000,0.00000000,0.00000000,0.00000000,0.00000000,0.00000000
207.00000000,3.83019500,11.92560000,0.12328389,792.10523742,0.11625644,889.75905150,0.00080257,0.00000000,0.00000000,0.00000000,0.00000000,0.00000000,0.00000000,0.00000000,0.00000000
208.50000000,3.87697500,11.93360000,0.12463589,792.63660204,0.11745933,891.42756950,0.00076820,0.00000000,0.00000000,0.00000000,0.00000000,0.00000000,0.00000000,0.00000000,0.00000000
210.00000000,3.92324900,11.93200000,0.12605556,792.53032912,0.11872087,892.43318005,0.00078065,0.00000000,0.00000000,0.00000000,0.00000000,0.00000000,0.00000000,0.00000000,0.00000000
211.50000000,3.97030000,11.93600000,0.12750533,792.79601143,0.12000752,893.88173113,0.00093956,0.00000000,0.00000000,0.00000000,0.00000000,0.00000000,0.00000000,0.00000000,0.00000000
213.00000000,4.01768900,11.93760000,0.12886478,792.90228435,0.12121251,895.07946102,0.00081849,0.00000000,0.00000000,0.00000000,0.00000000,0.00000000,0.00000000,0.00000000,0.00000000
214.50000000,4.06555100,11.93760000,0.13028067,792.90228435,0.12246598,896.20212256,0.00086408,0.00000000,0.00000000,0.00000000,0.00000000,0.00000000,0.00000000,0.00000000,0.00000000
216.00000000,4.11358200,11.93680000,0.13164778,792.84914789,0.12367478,897.22597632,0.00082984,0.00000000,0.00000000,0.00000000,0.00000000,0.00000000,0.00000000,0.00000000,0.00000000
217.50000000,4.16161400,11.94000000,0.13298856,793.06169374,0.12485888,898.52982285,0.00080237,0.00000000,0.00000000,0.00000000,0.00000000,0.00000000,0.00000000,0.00000000,0.00000000
219.00000000,4.20913800,11.94080000,0.13441578,793.11483020,0.12611779,899.72197697,0.00086093,0.00000000,0.00000000,0.00000000,0.00000000,0.00000000,0.00000000,0.00000000,0.00000000
220.50000000,4.25784500,11.93760000,0.13573022,792.90228435,0.12727581,900.52308761,0.00085994,0.00000000,0.00000000,0.00000000,0.00000000,0.00000000,0.00000000,0.00000000,0.00000000
222.00000000,4.30662000,11.93920000,0.13715744,793.00855727,0.12853168,901.77558441,0.00092494,0.00000000,0.00000000,0.00000000,0.00000000,0.00000000,0.00000000,0.00000000,0.00000000
223.50000000,4.35644300,11.93840000,0.13850944,792.95542081,0.12971990,902.78723562,0.00079184,0.00000000,0.00000000,0.00000000,0.00000000,0.00000000,0.00000000,0.00000000,0.00000000
225.00000000,4.40602900,11.93520000,0.13982400,792.74287496,0.13087386,903.58735471,0.00079092,0.00000000,0.00000000,0.00000000,0.00000000,0.00000000,0.00000000,0.00000000,0.00000000
226.50000000,4.45669700,11.93520000,0.14117600,792.74287496,0.13205931,904.65914308,0.00078998,0.00000000,0.00000000,0.00000000,0.00000000,0.00000000,0.00000000,0.00000000,0.00000000
228.00000000,4.50695900,11.93360000,0.14245300,792.63660204,0.13317771,905.55006391,0.00072333,0.00000000,0.00000000,0.00000000,0.00000000,0.00000000,0.00000000,0.00000000,0.00000000
229.50000000,4.55806600,11.94320000,0.14376744,793.27423958,0.13432759,907.32124975,0.00072250,0.00000000,0.00000000,0.00000000,0.00000000,0.00000000,0.00000000,0.00000000,0.00000000
231.00000000,4.60913900,11.92400000,0.14508200,791.99896450,0.00000000,0.00000000,0.00000000,0.00000000,0.00000000,0.00000000,0.00000000,0.00000000,0.00000000,0.00000000,0.00000000
232.50000000,4.66088900,11.92160000,0.14628378,791.83955511,0.00000000,0.00000000,0.00000000,0.00000000,0.00000000,0.00000000,0.00000000,0.00000000,0.00000000,0.00000000,0.00000000
234.00000000,4.71331400,11.92000000,0.14748567,791.73328219,0.00000000,0.00000000,0.00000000,0.00000000,0.00000000,0.00000000,0.00000000,0.00000000,0.00000000,0.00000000,0.00000000
235.50000000,4.76648300,11.91210000,0.14864989,791.20855963,0.00000000,0.00000000,0.00000000,0.00000000,0.00000000,0.00000000,0.00000000,0.00000000,0.00000000,0.00000000,0.00000000
237.00000000,4.82042900,11.90570000,0.14981411,790.78346793,0.00000000,0.00000000,0.00000000,0.00000000,0.00000000,0.00000000,0.00000000,0.00000000,0.00000000,0.00000000,0.00000000
238.50000000,4.87383500,11.89770000,0.15086578,790.25210331,0.00000000,0.00000000,0.00000000,0.00000000,0.00000000,0.00000000,0.00000000,0.00000000,0.00000000,0.00000000,0.00000000
240.00000000,4.92866000,11.88890000,0.15191733,789.66760223,0.00000000,0.00000000,0.00000000,0.00000000,0.00000000,0.00000000,0.00000000,0.00000000,0.00000000,0.00000000,0.00000000
241.50000000,4.98399300,11.88250000,0.15289378,789.24251054,0.00000000,0.00000000,0.00000000,0.00000000,0.00000000,0.00000000,0.00000000,0.00000000,0.00000000,0.00000000,0.00000000
243.00000000,5.03993300,11.87220000,0.15375756,788.55837859,0.00000000,0.00000000,0.00000000,0.00000000,0.00000000,0.00000000,0.00000000,0.00000000,0.00000000,0.00000000,0.00000000
244.50000000,5.09678700,11.85860000,0.15462144,787.65505874,0.00000000,0.00000000,0.00000000,0.00000000,0.00000000,0.00000000,0.00000000,0.00000000,0.00000000,0.00000000,0.00000000
246.00000000,5.15374100,11.84670000,0.15537256,786.86465387,0.00000000,0.00000000,0.00000000,0.00000000,0.00000000,0.00000000,0.00000000,0.00000000,0.00000000,0.00000000,0.00000000
247.50000000,5.21154100,11.83390000,0.15604856,786.01447048,0.00000000,0.00000000,0.00000000,0.00000000,0.00000000,0.00000000,0.00000000,0.00000000,0.00000000,0.00000000,0.00000000
249.00000000,5.27089600,11.81560000,0.15661189,784.79897391,0.00000000,0.00000000,0.00000000,0.00000000,0.00000000,0.00000000,0.00000000,0.00000000,0.00000000,0.00000000,0.00000000
250.50000000,5.32984500,11.78920000,0.15710011,783.04547067,0.00000000,0.00000000,0.00000000,0.00000000,0.00000000,0.00000000,0.00000000,0.00000000,0.00000000,0.00000000,0.00000000
252.00000000,5.38903000,11.77250000,0.15747556,781.93624703,0.00000000,0.00000000,0.00000000,0.00000000,0.00000000,0.00000000,0.00000000,0.00000000,0.00000000,0.00000000,0.00000000
253.50000000,5.44885800,11.75340000,0.15781367,780.66761400,0.00000000,0.00000000,0.00000000,0.00000000,0.00000000,0.00000000,0.00000000,0.00000000,0.00000000,0.00000000,0.00000000
255.00000000,5.51000400,11.72940000,0.15800133,779.07352014,0.00000000,0.00000000,0.00000000,0.00000000,0.00000000,0.00000000,0.00000000,0.00000000,0.00000000,0.00000000,0.00000000
256.50000000,5.57192700,11.70070000,0.15822667,777.16724957,0.00000000,0.00000000,0.00000000,0.00000000,0.00000000,0.00000000,0.00000000,0.00000000,0.00000000,0.00000000,0.00000000
258.00000000,5.63334300,11.66880000,0.15837689,775.04843315,0.00000000,0.00000000,0.00000000,0.00000000,0.00000000,0.00000000,0.00000000,0.00000000,0.00000000,0.00000000,0.00000000
259.50000000,5.69482700,11.63050000,0.15845189,772.50452504,0.00000000,0.00000000,0.00000000,0.00000000,0.00000000,0.00000000,0.00000000,0.00000000,0.00000000,0.00000000,0.00000000
261.00000000,5.75705400,11.59550000,0.15852700,770.17980483,0.00000000,0.00000000,0.00000000,0.00000000,0.00000000,0.00000000,0.00000000,0.00000000,0.00000000,0.00000000,0.00000000
262.50000000,5.81989000,11.55080000,0.15852700,767.21080503,0.00000000,0.00000000,0.00000000,0.00000000,0.00000000,0.00000000,0.00000000,0.00000000,0.00000000,0.00000000,0.00000000
264.00000000,5.88269200,11.50690000,0.15856444,764.29494168,0.00000000,0.00000000,0.00000000,0.00000000,0.00000000,0.00000000,0.00000000,0.00000000,0.00000000,0.00000000,0.00000000
265.50000000,5.94634100,11.45270000,0.15852689,760.69494639,0.00000000,0.00000000,0.00000000,0.00000000,0.00000000,0.00000000,0.00000000,0.00000000,0.00000000,0.00000000,0.00000000
267.00000000,6.00989000,11.39850000,0.15852689,757.09495109,0.00000000,0.00000000,0.00000000,0.00000000,0.00000000,0.00000000,0.00000000,0.00000000,0.00000000,0.00000000,0.00000000
268.50000000,6.07449000,11.32350000,0.15852678,752.11340779,0.00000000,0.00000000,0.00000000,0.00000000,0.00000000,0.00000000,0.00000000,0.00000000,0.00000000,0.00000000,0.00000000
270.00000000,6.14007700,11.24140000,0.15848922,746.66027839,0.00000000,0.00000000,0.00000000,0.00000000,0.00000000,0.00000000,0.00000000,0.00000000,0.00000000,0.00000000,0.00000000
271.50000000,6.20971200,11.10820000,0.15841411,737.81305748,0.00000000,0.00000000,0.00000000,0.00000000,0.00000000,0.00000000,0.00000000,0.00000000,0.00000000,0.00000000,0.00000000