File: polyN_optimization/DP780_results/DATA/UT_75_1.csv
Time[s],Displacement[mm],Force[kN],EngStrain_longi,EngStress[MPa],TrueStrain,TrueStress[MPa],TrueStrainRate[1/s],PlasticStrain_longi,PlasticStress[MPa],PlasticStrain_thick,PlasticStrain_width,R-Value,Thickness[mm],Width[mm], Young's Modulus [MPa]
0.00000000,0.00000000,-0.02220000,0.00000000,-1.47929732,0.00000000,-1.47929732,0.00000000,0.00060349,423.79543851,0.00045158,-0.00105507,0.90998319,1.50550000,9.96820000,208114.49184915
1.00000000,0.00109500,0.22430000,0.00002711,14.94623377,0.00002711,14.94663898,0.00001733,0.00072190,432.76424257,0.00040205,-0.00112395,0.00000000,0.00000000,0.00000000,0.00000000
2.00000000,0.00282700,0.47550000,0.00010567,31.68494944,0.00010566,31.68829748,0.00007977,0.00082573,440.76509370,0.00029180,-0.00111753,0.00000000,0.00000000,0.00000000,0.00000000
3.00000000,0.00315400,0.68520000,0.00010400,45.65831200,0.00010399,45.66306046,0.00002622,0.00106790,448.83043582,0.00004578,-0.00111369,0.00000000,0.00000000,0.00000000,0.00000000
4.00000000,0.00530700,0.92130000,0.00016033,61.39083894,0.00016032,61.40068194,0.00007732,0.00117913,456.89392362,0.00010003,-0.00127916,0.00000000,0.00000000,0.00000000,0.00000000
5.00000000,0.00592600,1.14770000,0.00018822,76.47700625,0.00018820,76.49140092,0.00004444,0.00136584,464.84084692,0.00008022,-0.00144606,0.00000000,0.00000000,0.00000000,0.00000000
6.00000000,0.00798800,1.36620000,0.00026256,91.03675693,0.00026252,91.06065914,0.00001133,0.00153177,472.39935834,0.00007253,-0.00160429,0.00000000,0.00000000,0.00000000,0.00000000
7.00000000,0.00890200,1.56800000,0.00028133,104.48370288,0.00028129,104.51309763,0.00002555,0.00174848,480.25357305,-0.00010017,-0.00164831,0.00000000,0.00000000,0.00000000,0.00000000
8.00000000,0.00985700,1.77060000,0.00026378,117.98395683,0.00026374,118.01507838,-0.00010730,0.00193021,487.56475149,-0.00021238,-0.00171784,0.00000000,0.00000000,0.00000000,0.00000000
9.00000000,0.01246800,1.96440000,0.00038133,130.89782266,0.00038126,130.94773836,0.00008641,0.00221649,494.93094579,-0.00041628,-0.00180021,0.00000000,0.00000000,0.00000000,0.00000000
10.00000000,0.01212300,2.14780000,0.00041900,143.11868434,0.00041891,143.17865107,0.00002266,0.00237848,501.69563591,-0.00038151,-0.00199697,0.00000000,0.00000000,0.00000000,0.00000000
11.00000000,0.01538500,2.32800000,0.00050144,155.12631397,0.00050132,155.20410120,0.00011350,0.00268626,507.69131265,-0.00051067,-0.00217560,0.00000000,0.00000000,0.00000000,0.00000000
12.00000000,0.01536400,2.48670000,0.00047933,165.70129078,0.00047922,165.78071693,0.00005797,0.00290785,514.49948461,-0.00055887,-0.00234897,0.00000000,0.00000000,0.00000000,0.00000000
13.00000000,0.01817300,2.66690000,0.00061278,177.70892041,0.00061259,177.81781649,0.00005486,0.00329803,521.13045752,-0.00078074,-0.00251729,0.00000000,0.00000000,0.00000000,0.00000000
14.00000000,0.01855600,2.83760000,0.00059067,189.08351740,0.00059049,189.19520273,0.00004731,0.00349701,527.12815261,-0.00085719,-0.00263982,0.00000000,0.00000000,0.00000000,0.00000000
15.00000000,0.02065400,3.00350000,0.00066322,200.13826632,0.00066300,200.27100247,-0.00001732,0.00392224,533.41087026,-0.00114757,-0.00277468,0.00000000,0.00000000,0.00000000,0.00000000
16.00000000,0.02195500,3.17410000,0.00070244,211.50619981,0.00070220,211.65477117,0.00009016,0.00416973,539.38781841,-0.00120566,-0.00296408,0.00000000,0.00000000,0.00000000,0.00000000
17.00000000,0.02354200,3.34240000,0.00077411,222.72087277,0.00077381,222.89328347,-0.00007638,0.00457529,545.03054724,-0.00148064,-0.00309465,0.00000000,0.00000000,0.00000000,0.00000000
18.00000000,0.02548000,3.51070000,0.00084467,233.93554572,0.00084431,234.13314328,0.00018718,0.00489957,550.51876222,-0.00161118,-0.00328839,0.00000000,0.00000000,0.00000000,0.00000000
19.00000000,0.02649600,3.67090000,0.00090311,244.61047506,0.00090270,244.83138550,-0.00008770,0.00524677,555.86865668,-0.00177757,-0.00346920,0.00000000,0.00000000,0.00000000,0.00000000
20.00000000,0.02848300,3.83680000,0.00099711,255.66522398,0.00099661,255.92015062,0.00016495,0.00565150,560.81693127,-0.00197030,-0.00368120,0.00000000,0.00000000,0.00000000,0.00000000
21.00000000,0.02981000,3.98360000,0.00098589,265.44724412,0.00098540,265.70894561,-0.00002997,0.00594486,566.46774399,-0.00211413,-0.00383073,0.00000000,0.00000000,0.00000000,0.00000000
22.00000000,0.03211500,4.14310000,0.00113256,276.07552895,0.00113191,276.38819982,0.00027793,0.00643386,571.64097333,-0.00243056,-0.00400330,0.00000000,0.00000000,0.00000000,0.00000000
23.00000000,0.03404800,4.30570000,0.00106900,286.91038232,0.00106843,287.21708952,-0.00008235,0.00673390,576.59542852,-0.00255601,-0.00417789,0.00000000,0.00000000,0.00000000,0.00000000
24.00000000,0.03615000,4.46120000,0.00126467,297.27212709,0.00126387,297.64807724,0.00026302,0.00723888,581.46333928,-0.00287508,-0.00436381,0.00000000,0.00000000,0.00000000,0.00000000
25.00000000,0.03862500,4.62310000,0.00121978,308.06033595,0.00121903,308.43610111,-0.00001465,0.00754077,586.75697275,-0.00295643,-0.00458434,0.00000000,0.00000000,0.00000000,0.00000000
26.00000000,0.04018600,4.77860000,0.00142633,318.42208072,0.00142532,318.87625675,0.00026231,0.00807562,591.48977106,-0.00330766,-0.00476796,0.00000000,0.00000000,0.00000000,0.00000000
27.00000000,0.04333300,4.93260000,0.00135511,328.68387297,0.00135419,329.12927614,0.00000777,0.00847480,596.57235178,-0.00346144,-0.00501337,0.00000000,0.00000000,0.00000000,0.00000000
28.00000000,0.04499400,5.08090000,0.00159944,338.56584563,0.00159817,339.10736289,0.00018793,0.00894534,601.43847707,-0.00368719,-0.00525814,0.00000000,0.00000000,0.00000000,0.00000000
29.00000000,0.04888600,5.23400000,0.00154344,348.76766637,0.00154225,349.30596988,0.00009031,0.00939090,605.27253441,-0.00388433,-0.00550658,0.00000000,0.00000000,0.00000000,0.00000000
30.00000000,0.05071800,5.36240000,0.00171622,357.32360224,0.00171475,357.93684895,0.00006012,0.00985823,609.92880064,-0.00413061,-0.00572762,0.00000000,0.00000000,0.00000000,0.00000000
31.00000000,0.05491000,5.51230000,0.00172344,367.31219093,0.00172196,367.94523308,0.00007476,0.01029902,614.67471373,-0.00434830,-0.00595071,0.00000000,0.00000000,0.00000000,0.00000000
32.00000000,0.05781700,5.65430000,0.00196044,376.77436300,0.00195853,377.51300821,0.00018054,0.01080734,619.20938645,-0.00460856,-0.00619878,0.00000000,0.00000000,0.00000000,0.00000000
33.00000000,0.06217800,5.79940000,0.00197933,386.44310362,0.00197738,387.20800333,0.00015769,0.01122350,623.57581919,-0.00480445,-0.00641905,0.00000000,0.00000000,0.00000000,0.00000000
34.00000000,0.06603700,5.93900000,0.00223456,395.74535165,0.00223206,396.62966663,0.00013481,0.01177654,627.92364532,-0.00508855,-0.00668799,0.00000000,0.00000000,0.00000000,0.00000000
35.00000000,0.07002500,6.07770000,0.00225689,404.98762818,0.00225435,405.90164025,0.00014989,0.01224024,632.32819531,-0.00533863,-0.00690161,0.00000000,0.00000000,0.00000000,0.00000000
36.00000000,0.07458600,6.21330000,0.00249722,414.02333616,0.00249411,415.05724443,0.00015761,0.01273071,636.48238031,-0.00562493,-0.00710577,0.00000000,0.00000000,0.00000000,0.00000000
37.00000000,0.07931500,6.34330000,0.00262500,422.68588805,0.00262156,423.79543851,0.00029214,0.01326859,640.72547412,-0.00592087,-0.00734772,0.00000000,0.00000000,0.00000000,0.00000000
38.00000000,0.08492300,6.47650000,0.00278656,431.56167200,0.00278268,432.76424257,0.00006006,0.01381317,644.27727672,-0.00617549,-0.00763768,0.00000000,0.00000000,0.00000000,0.00000000
39.00000000,0.08985800,6.59530000,0.00292889,439.47791173,0.00292461,440.76509370,0.00019433,0.01427680,648.48080260,-0.00645650,-0.00782030,0.00000000,0.00000000,0.00000000,0.00000000
40.00000000,0.09621100,6.71410000,0.00321033,447.39415146,0.00320519,448.83043582,0.00018696,0.01483966,652.69878779,-0.00675399,-0.00808567,0.00000000,0.00000000,0.00000000,0.00000000
41.00000000,0.10239100,6.83370000,0.00336044,455.36369921,0.00335481,456.89392362,0.00035174,0.01535683,656.40793116,-0.00701306,-0.00834377,0.00000000,0.00000000,0.00000000,0.00000000
42.00000000,0.10880700,6.95100000,0.00358578,463.17998642,0.00357936,464.84084692,0.00021701,0.01589413,660.45440903,-0.00727641,-0.00861772,0.00000000,0.00000000,0.00000000,0.00000000
43.00000000,0.11573100,7.06260000,0.00378844,470.61645405,0.00378129,472.39935834,0.00028428,0.01644758,664.13421149,-0.00758896,-0.00885862,0.00000000,0.00000000,0.00000000,0.00000000
44.00000000,0.12350000,7.17820000,0.00404356,478.31946173,0.00403540,480.25357305,0.00023905,0.01698725,668.30671332,-0.00785123,-0.00913602,0.00000000,0.00000000,0.00000000,0.00000000
45.00000000,0.13133900,7.28590000,0.00426100,485.49605280,0.00425195,487.56475149,0.00018655,0.01751389,672.08589086,-0.00808692,-0.00942697,0.00000000,0.00000000,0.00000000,0.00000000
46.00000000,0.13924200,7.39360000,0.00458378,492.67264388,0.00457330,494.93094579,0.00038848,0.01812524,675.76253604,-0.00839002,-0.00973523,0.00000000,0.00000000,0.00000000,0.00000000
47.00000000,0.14802400,7.49320000,0.00477889,499.30949133,0.00476751,501.69563591,0.00007453,0.01863852,679.11022123,-0.00861615,-0.01002237,0.00000000,0.00000000,0.00000000,0.00000000
48.00000000,0.15640000,7.58020000,0.00511689,505.10673760,0.00510384,507.69131265,0.00038098,0.01922839,682.51371621,-0.00893741,-0.01029098,0.00000000,0.00000000,0.00000000,0.00000000
49.00000000,0.16650100,7.67990000,0.00537222,511.75024855,0.00535784,514.49948461,0.00008974,0.01978661,686.33032001,-0.00920326,-0.01058335,0.00000000,0.00000000,0.00000000,0.00000000
50.00000000,0.17670500,7.77560000,0.00579633,518.12721945,0.00577960,521.13045752,0.00054492,0.02040478,689.81610734,-0.00952883,-0.01087595,0.00000000,0.00000000,0.00000000,0.00000000
51.00000000,0.18613100,7.86330000,0.00602522,523.97111023,0.00600714,527.12815261,0.00014160,0.02098722,693.00035839,-0.00981253,-0.01117469,0.00000000,0.00000000,0.00000000,0.00000000
52.00000000,0.19748100,7.95340000,0.00648322,529.97492504,0.00646230,533.41087026,0.00049993,0.02161915,696.50378794,-0.01019210,-0.01142705,0.00000000,0.00000000,0.00000000,0.00000000
53.00000000,0.20822500,8.04030000,0.00676100,535.76550781,0.00673825,539.38781841,0.00020132,0.02216414,699.73095369,-0.01045951,-0.01170463,0.00000000,0.00000000,0.00000000,0.00000000
54.00000000,0.21856400,8.12090000,0.00719644,541.13628999,0.00717067,545.03054724,0.00047707,0.02275279,702.93056004,-0.01076697,-0.01198582,0.00000000,0.00000000,0.00000000,0.00000000
55.00000000,0.23103200,8.19980000,0.00754944,546.39379264,0.00752109,550.51876222,0.00035028,0.02336317,706.10111888,-0.01108737,-0.01227580,0.00000000,0.00000000,0.00000000,0.00000000
56.00000000,0.24333300,8.27640000,0.00792500,551.49803476,0.00789376,555.86865668,0.00038763,0.02400669,709.13404025,-0.01146653,-0.01254016,0.00000000,0.00000000,0.00000000,0.00000000
57.00000000,0.25435000,8.34650000,0.00835678,556.16914928,0.00832205,560.81693127,0.00044698,0.02458768,712.18099590,-0.01172396,-0.01286372,0.00000000,0.00000000,0.00000000,0.00000000
58.00000000,0.26796900,8.42790000,0.00867978,561.59323947,0.00864233,566.46774399,0.00032036,0.02520827,715.25287243,-0.01202486,-0.01318341,0.00000000,0.00000000,0.00000000,0.00000000
59.00000000,0.28118300,8.50050000,0.00919800,566.43094153,0.00915596,571.64097333,0.00054352,0.02583859,718.50751589,-0.01243463,-0.01340396,0.00000000,0.00000000,0.00000000,0.00000000
60.00000000,0.29294300,8.57140000,0.00952467,571.15536406,0.00947959,576.59542852,0.00037953,0.02645595,721.31577594,-0.01269397,-0.01376197,0.00000000,0.00000000,0.00000000,0.00000000
61.00000000,0.30707000,8.63920000,0.01005800,575.67321805,0.01000775,581.46333928,0.00046119,0.02705173,724.00132382,-0.01303825,-0.01401348,0.00000000,0.00000000,0.00000000,0.00000000
62.00000000,0.32119700,8.71500000,0.01038844,580.72415216,0.01033486,586.75697275,0.00039395,0.02769997,727.05926025,-0.01334000,-0.01435996,0.00000000,0.00000000,0.00000000,0.00000000
63.00000000,0.33434400,8.78040000,0.01095178,585.08208211,0.01089224,591.48977106,0.00046826,0.02833380,729.99994207,-0.01365798,-0.01467581,0.00000000,0.00000000,0.00000000,0.00000000
64.00000000,0.34833600,8.85210000,0.01137989,589.85981266,0.01131563,596.57235178,0.00043817,0.02894664,732.65241256,-0.01396247,-0.01498416,0.00000000,0.00000000,0.00000000,0.00000000
65.00000000,0.36327400,8.91990000,0.01187933,594.37766665,0.01180933,601.43847707,0.00048255,0.02963290,735.08562232,-0.01433964,-0.01529326,0.00000000,0.00000000,0.00000000,0.00000000
66.00000000,0.37750300,8.97260000,0.01234878,597.88933191,0.01227315,605.27253441,0.00046015,0.03027390,737.76504919,-0.01465530,-0.01561860,0.00000000,0.00000000,0.00000000,0.00000000
67.00000000,0.39223900,9.03720000,0.01284444,602.19395386,0.01276265,609.92880064,0.00060806,0.03091535,740.28190159,-0.01495276,-0.01596259,0.00000000,0.00000000,0.00000000,0.00000000
68.00000000,0.40738100,9.10330000,0.01331389,606.59852832,0.01322604,614.67471373,0.00042242,0.03153793,742.84307623,-0.01527719,-0.01626074,0.00000000,0.00000000,0.00000000,0.00000000
69.00000000,0.42259000,9.16560000,0.01385100,610.74988973,0.01375595,619.20938645,0.00061513,0.03227814,745.71702340,-0.01571577,-0.01656237,0.00000000,0.00000000,0.00000000,0.00000000
70.00000000,0.43871200,9.22620000,0.01429411,614.78797161,0.01419291,623.57581919,0.00037775,0.03289161,748.49967411,-0.01598066,-0.01691095,0.00000000,0.00000000,0.00000000,0.00000000
71.00000000,0.45497000,9.28520000,0.01487622,618.71943748,0.01476666,627.92364532,0.00059217,0.03357836,751.00764600,-0.01638768,-0.01719068,0.00000000,0.00000000,0.00000000,0.00000000
72.00000000,0.46984100,9.34580000,0.01536822,622.75751936,0.01525133,632.32819531,0.00055488,0.03426246,753.18338295,-0.01674973,-0.01751273,0.00000000,0.00000000,0.00000000,0.00000000
73.00000000,0.48579500,9.40240000,0.01588644,626.52906119,0.01576158,636.48238031,0.00051762,0.03497267,755.88202142,-0.01718665,-0.01778601,0.00000000,0.00000000,0.00000000,0.00000000
74.00000000,0.50283000,9.45980000,0.01645356,630.35391102,0.01631966,640.72547412,0.00050990,0.03558327,758.11887652,-0.01752142,-0.01806185,0.00000000,0.00000000,0.00000000,0.00000000
75.00000000,0.51996600,9.50690000,0.01702444,633.49242021,0.01688115,644.27727672,0.00073124,0.03627711,760.26167213,-0.01787113,-0.01840599,0.00000000,0.00000000,0.00000000,0.00000000
76.00000000,0.53642600,9.56430000,0.01751644,637.31727005,0.01736480,648.48080260,0.00039861,0.03696438,762.89659611,-0.01827253,-0.01869186,0.00000000,0.00000000,0.00000000,0.00000000
77.00000000,0.55369800,9.62090000,0.01810978,641.08881187,0.01794775,652.69878779,0.00063439,0.03760998,765.11253470,-0.01855233,-0.01905765,0.00000000,0.00000000,0.00000000,0.00000000
78.00000000,0.57073300,9.67040000,0.01865444,644.38724510,0.01848258,656.40793116,0.00053105,0.03831272,767.31928085,-0.01895275,-0.01935997,0.00000000,0.00000000,0.00000000,0.00000000
79.00000000,0.58685600,9.72460000,0.01922156,647.99886289,0.01903916,660.45440903,0.00064133,0.03905398,769.67022473,-0.01938919,-0.01966479,0.00000000,0.00000000,0.00000000,0.00000000
80.00000000,0.60575000,9.77320000,0.01980367,651.23732460,0.01961013,664.13421149,0.00052304,0.03972290,771.96823342,-0.01965825,-0.02006465,0.00000000,0.00000000,0.00000000,0.00000000
81.00000000,0.62339400,9.82910000,0.02037444,654.96222191,0.02016966,668.30671332,0.00064039,0.04040572,774.28681364,-0.02005279,-0.02035293,0.00000000,0.00000000,0.00000000,0.00000000
82.00000000,0.64110500,9.87930000,0.02093033,658.30729964,0.02071430,672.08589086,0.00042667,0.04109570,776.49492612,-0.02035296,-0.02074275,0.00000000,0.00000000,0.00000000,0.00000000
83.00000000,0.65878300,9.92710000,0.02157256,661.49245334,0.02134316,675.76253604,0.00070601,0.04182919,778.51577083,-0.02074460,-0.02108459,0.00000000,0.00000000,0.00000000,0.00000000
84.00000000,0.67777900,9.97100000,0.02211333,664.41773048,0.02187238,679.11022123,0.00047032,0.04253371,780.46746778,-0.02110433,-0.02142938,0.00000000,0.00000000,0.00000000,0.00000000
85.00000000,0.69603100,10.01490000,0.02273300,667.34300762,0.02247846,682.51371621,0.00060218,0.04322574,782.68514849,-0.02142682,-0.02179892,0.00000000,0.00000000,0.00000000,0.00000000
86.00000000,0.71458800,10.06510000,0.02332267,670.68808535,0.02305485,686.33032001,0.00056512,0.04395813,784.60063413,-0.02183334,-0.02212480,0.00000000,0.00000000,0.00000000,0.00000000
87.00000000,0.73398900,10.10980000,0.02397244,673.66667051,0.02368962,689.81610734,0.00065290,0.04466135,786.50252954,-0.02216755,-0.02249380,0.00000000,0.00000000,0.00000000,0.00000000
88.00000000,0.75318800,10.15040000,0.02458456,676.37205210,0.02428722,693.00035839,0.00062322,0.04535515,788.78569008,-0.02254693,-0.02280822,0.00000000,0.00000000,0.00000000,0.00000000
89.00000000,0.77201500,10.19510000,0.02524933,679.35063725,0.02493584,696.50378794,0.00071085,0.04609190,790.93705479,-0.02296783,-0.02312408,0.00000000,0.00000000,0.00000000,0.00000000
90.00000000,0.79134900,10.23660000,0.02582400,682.11599036,0.02549619,699.73095369,0.00058585,0.04683307,792.82031720,-0.02336066,-0.02347241,0.00000000,0.00000000,0.00000000,0.00000000
91.00000000,0.81037900,10.27720000,0.02644367,684.82137195,0.02610008,702.93056004,0.00058549,0.04753778,794.72617935,-0.02370088,-0.02383690,0.00000000,0.00000000,0.00000000,0.00000000
92.00000000,0.82988200,10.31710000,0.02708589,687.48010903,0.02672556,706.10111888,0.00062170,0.04823894,796.51878620,-0.02408409,-0.02415485,0.00000000,0.00000000,0.00000000,0.00000000
93.00000000,0.85009500,10.35460000,0.02776189,689.97892208,0.02738351,709.13404025,0.00067969,0.04899609,798.42188114,-0.02451457,-0.02448153,0.00000000,0.00000000,0.00000000,0.00000000
94.00000000,0.86997000,10.39290000,0.02837411,692.53104314,0.02797902,712.18099590,0.00063562,0.04974155,800.42389425,-0.02488640,-0.02485515,0.00000000,0.00000000,0.00000000,0.00000000
95.00000000,0.89021700,10.43110000,0.02902756,695.07650069,0.02861424,715.25287243,0.00062053,0.05045915,802.18712786,-0.02529390,-0.02516525,0.00000000,0.00000000,0.00000000,0.00000000
96.00000000,0.91066700,10.47180000,0.02969233,697.78854579,0.02926005,718.50751589,0.00070778,0.05120774,804.02697842,-0.02572930,-0.02547843,0.00000000,0.00000000,0.00000000,0.00000000
97.00000000,0.93064300,10.50610000,0.03034200,700.07412679,0.02989079,721.31577594,0.00062686,0.05191357,805.78507946,-0.02609664,-0.02581694,0.00000000,0.00000000,0.00000000,0.00000000
98.00000000,0.95132900,10.53880000,0.03096922,702.25309177,0.03049935,724.00132382,0.00057559,0.05265838,807.45655221,-0.02650464,-0.02615374,0.00000000,0.00000000,0.00000000,0.00000000
99.00000000,0.97161000,10.57630000,0.03165278,704.75190481,0.03116215,727.05926025,0.00058254,0.05339717,809.52188408,-0.02690353,-0.02649364,0.00000000,0.00000000,0.00000000,0.00000000
100.00000000,0.99253300,10.61220000,0.03232133,707.14410184,0.03180999,729.99994207,0.00062587,0.05414543,810.98084120,-0.02729822,-0.02684720,0.00000000,0.00000000,0.00000000,0.00000000
101.00000000,1.01352300,10.64410000,0.03296722,709.26975880,0.03243546,732.65241256,0.00053811,0.05487837,812.54256855,-0.02765327,-0.02722510,0.00000000,0.00000000,0.00000000,0.00000000
102.00000000,1.03458100,10.67200000,0.03368833,711.12887571,0.03313331,735.08562232,0.00058139,0.05558156,814.30192926,-0.02799266,-0.02758890,0.00000000,0.00000000,0.00000000,0.00000000
103.00000000,1.05577500,10.70390000,0.03436433,713.25453268,0.03378707,737.76504919,0.00067535,0.05635518,816.01452724,-0.02842035,-0.02793483,0.00000000,0.00000000,0.00000000,0.00000000
104.00000000,1.07679900,10.73340000,0.03504044,715.22026561,0.03444050,740.28190159,0.00071142,0.05708332,817.51421927,-0.02877707,-0.02830625,0.00000000,0.00000000,0.00000000,0.00000000
105.00000000,1.09758700,10.76370000,0.03569767,717.23930655,0.03507527,742.84307623,0.00059486,0.05786491,819.52215787,-0.02919481,-0.02867010,0.00000000,0.00000000,0.00000000,0.00000000
106.00000000,1.11962500,10.79720000,0.03647878,719.47157954,0.03582918,745.71702340,0.00080459,0.05860241,821.03353900,-0.02959625,-0.02900616,0.00000000,0.00000000,0.00000000,0.00000000
107.00000000,1.14129200,10.83070000,0.03712856,721.70385253,0.03645589,748.49967411,0.00068084,0.05932529,822.54177801,-0.02993496,-0.02939034,0.00000000,0.00000000,0.00000000,0.00000000
108.00000000,1.16329600,10.85940000,0.03785344,723.61627744,0.03715458,751.00764600,0.00073841,0.06005409,824.16365402,-0.03031396,-0.02974013,0.00000000,0.00000000,0.00000000,0.00000000
109.00000000,1.18519900,10.88330000,0.03857444,725.20885429,0.03784905,753.18338295,0.00070879,0.06083337,825.43677832,-0.03074134,-0.03009203,0.00000000,0.00000000,0.00000000,0.00000000
110.00000000,1.20730500,10.91440000,0.03932567,727.28120325,0.03857211,755.88202142,0.00088924,0.06156912,826.84670804,-0.03111139,-0.03045773,0.00000000,0.00000000,0.00000000,0.00000000
111.00000000,1.22924200,10.93990000,0.03997156,728.98039612,0.03919336,758.11887652,0.00070784,0.06229948,828.53256725,-0.03148399,-0.03081549,0.00000000,0.00000000,0.00000000,0.00000000
112.00000000,1.25128100,10.96310000,0.04070400,730.52632846,0.03989741,760.26167213,0.00072208,0.06303521,830.46101084,-0.03188662,-0.03114859,0.00000000,0.00000000,0.00000000,0.00000000
113.00000000,1.27379200,10.99340000,0.04143256,732.54536940,0.04059722,762.89659611,0.00075018,0.06381040,832.07406551,-0.03231679,-0.03149362,0.00000000,0.00000000,0.00000000,0.00000000
114.00000000,1.29637100,11.01810000,0.04211611,734.19125426,0.04125337,765.11253470,0.00068484,0.06457436,832.99909375,-0.03276229,-0.03181207,0.00000000,0.00000000,0.00000000,0.00000000
115.00000000,1.31881500,11.04200000,0.04285967,735.78383111,0.04196662,767.31928085,0.00065557,0.06529550,834.69224167,-0.03312323,-0.03217227,0.00000000,0.00000000,0.00000000,0.00000000
116.00000000,1.34230700,11.06750000,0.04364467,737.48302398,0.04271907,769.67022473,0.00079907,0.06608051,836.08944682,-0.03353473,-0.03254577,0.00000000,0.00000000,0.00000000,0.00000000
117.00000000,1.36465000,11.09300000,0.04435444,739.18221685,0.04339894,771.96823342,0.00081279,0.06678354,837.65639489,-0.03388529,-0.03289825,0.00000000,0.00000000,0.00000000,0.00000000
118.00000000,1.38777000,11.11860000,0.04507933,740.88807323,0.04409280,774.28681364,0.00068289,0.06759524,839.08673566,-0.03433372,-0.03326152,0.00000000,0.00000000,0.00000000,0.00000000
119.00000000,1.41065300,11.14250000,0.04581167,742.48065007,0.04479330,776.49492612,0.00071111,0.06830666,840.13938753,-0.03472078,-0.03358588,0.00000000,0.00000000,0.00000000,0.00000000
120.00000000,1.43397600,11.16320000,0.04658911,743.85999488,0.04553641,778.51577083,0.00078259,0.06909189,841.72330265,-0.03513926,-0.03395263,0.00000000,0.00000000,0.00000000,0.00000000
121.00000000,1.45750200,11.18320000,0.04733644,745.19269517,0.04625022,780.46746778,0.00080347,0.06982197,843.03201844,-0.03545796,-0.03436401,0.00000000,0.00000000,0.00000000,0.00000000
122.00000000,1.48031800,11.20710000,0.04807256,746.78527202,0.04695282,782.68514849,0.00064510,0.07062731,844.51414361,-0.03592525,-0.03470206,0.00000000,0.00000000,0.00000000,0.00000000
123.00000000,1.50374200,11.22620000,0.04885000,748.05800080,0.04769433,784.60063413,0.00078069,0.07133120,845.97689180,-0.03627032,-0.03506087,0.00000000,0.00000000,0.00000000,0.00000000
124.00000000,1.52713200,11.24540000,0.04959733,749.33739308,0.04840660,786.50252954,0.00072994,0.07212708,846.99974308,-0.03671436,-0.03541272,0.00000000,0.00000000,0.00000000,0.00000000
125.00000000,1.55082700,11.27010000,0.05033722,750.98327794,0.04911128,788.78569008,0.00071524,0.07287921,848.32603767,-0.03709788,-0.03578133,0.00000000,0.00000000,0.00000000,0.00000000
126.00000000,1.57475800,11.29240000,0.05112211,752.46923876,0.04985827,790.93705479,0.00067897,0.07363759,849.66642314,-0.03747185,-0.03616574,0.00000000,0.00000000,0.00000000,0.00000000
127.00000000,1.59848700,11.31080000,0.05191089,753.69532303,0.05060840,792.82031720,0.00076426,0.07438102,851.11137871,-0.03792110,-0.03645992,0.00000000,0.00000000,0.00000000,0.00000000
128.00000000,1.62255300,11.32990000,0.05266200,754.96805181,0.05132219,794.72617935,0.00069951,0.07511564,852.08701716,-0.03826084,-0.03685481,0.00000000,0.00000000,0.00000000,0.00000000
129.00000000,1.64726200,11.34740000,0.05340933,756.13416456,0.05203189,796.51878620,0.00069184,0.07589918,853.62011390,-0.03869227,-0.03720691,0.00000000,0.00000000,0.00000000,0.00000000
130.00000000,1.67129400,11.36580000,0.05421678,757.36024883,0.05279810,798.42188114,0.00068393,0.07666034,854.62090998,-0.03908206,-0.03757827,0.00000000,0.00000000,0.00000000,0.00000000
131.00000000,1.69542800,11.38570000,0.05501300,758.68628562,0.05355309,800.42389425,0.00076180,0.07742591,856.03303864,-0.03946899,-0.03795692,0.00000000,0.00000000,0.00000000,0.00000000
132.00000000,1.71986700,11.40250000,0.05577922,759.80575387,0.05427909,802.18712786,0.00076862,0.07816381,857.30679318,-0.03986570,-0.03829811,0.00000000,0.00000000,0.00000000,0.00000000
133.00000000,1.74457500,11.42000000,0.05657911,760.97186662,0.05503644,804.02697842,0.00071817,0.07893755,858.19847140,-0.04029526,-0.03864228,0.00000000,0.00000000,0.00000000,0.00000000
134.00000000,1.76874300,11.43680000,0.05733400,762.09133487,0.05575065,805.78507946,0.00067498,0.07971563,859.50949152,-0.04067506,-0.03904057,0.00000000,0.00000000,0.00000000,0.00000000
135.00000000,1.79335000,11.45190000,0.05813022,763.09752359,0.05650341,807.45655221,0.00071712,0.08046927,860.74266961,-0.04110940,-0.03935987,0.00000000,0.00000000,0.00000000,0.00000000
136.00000000,1.81826200,11.47260000,0.05892267,764.47686839,0.05725204,809.52188408,0.00080874,0.08123587,862.04674581,-0.04146746,-0.03976841,0.00000000,0.00000000,0.00000000,0.00000000
137.00000000,1.84317300,11.48460000,0.05972267,765.27648857,0.05800724,810.98084120,0.00080121,0.08196276,862.85119089,-0.04185198,-0.04011078,0.00000000,0.00000000,0.00000000,0.00000000
138.00000000,1.86828700,11.49820000,0.06050756,766.18272476,0.05874762,812.54256855,0.00080062,0.08271508,864.02141583,-0.04227901,-0.04043607,0.00000000,0.00000000,0.00000000,0.00000000
139.00000000,1.89296200,11.51490000,0.06126244,767.29552951,0.05945918,814.30192926,0.00071500,0.08345384,865.01315781,-0.04264206,-0.04081178,0.00000000,0.00000000,0.00000000,0.00000000
140.00000000,1.91804300,11.53010000,0.06209244,768.30838173,0.06024097,816.01452724,0.00081344,0.08422834,866.32934948,-0.04303062,-0.04119772,0.00000000,0.00000000,0.00000000,0.00000000
141.00000000,1.94332600,11.54280000,0.06287367,769.15464642,0.06097625,817.51421927,0.00069279,0.08496874,867.44181937,-0.04346257,-0.04150617,0.00000000,0.00000000,0.00000000,0.00000000
142.00000000,1.96840600,11.56200000,0.06371489,770.43403870,0.06176739,819.52215787,0.00078399,0.08573116,868.16473710,-0.04387286,-0.04185831,0.00000000,0.00000000,0.00000000,0.00000000
143.00000000,1.99365600,11.57470000,0.06450733,771.28030338,0.06251209,821.03353900,0.00078341,0.08646342,869.32345996,-0.04424129,-0.04222213,0.00000000,0.00000000,0.00000000,0.00000000
144.00000000,2.01890500,11.58750000,0.06528478,772.13323157,0.06324216,822.54177801,0.00071230,0.08727311,870.67575017,-0.04467511,-0.04259800,0.00000000,0.00000000,0.00000000,0.00000000
145.00000000,2.04462800,11.60180000,0.06606967,773.08611228,0.06397868,824.16365402,0.00068342,0.08800158,871.66507472,-0.04507814,-0.04292344,0.00000000,0.00000000,0.00000000,0.00000000
146.00000000,2.07018100,11.61060000,0.06690722,773.67250040,0.06476402,825.43677832,0.00076747,0.08876990,872.80778631,-0.04547467,-0.04329523,0.00000000,0.00000000,0.00000000,0.00000000
147.00000000,2.09560000,11.62180000,0.06769967,774.41881257,0.06550649,826.84670804,0.00077398,0.08950507,874.32682265,-0.04586529,-0.04363978,0.00000000,0.00000000,0.00000000,0.00000000
148.00000000,2.12084900,11.63690000,0.06848833,775.42500129,0.06624488,828.53256725,0.00075926,0.09025232,874.63750346,-0.04623975,-0.04401256,0.00000000,0.00000000,0.00000000,0.00000000
149.00000000,2.14660500,11.65530000,0.06928456,776.65108556,0.06698979,830.46101084,0.00070963,0.09095534,875.48331594,-0.04661190,-0.04434344,0.00000000,0.00000000,0.00000000,0.00000000
150.00000000,2.17259800,11.66880000,0.07012200,777.55065825,0.06777266,832.07406551,0.00076517,0.09174489,876.70801212,-0.04703553,-0.04470936,0.00000000,0.00000000,0.00000000,0.00000000
151.00000000,2.19845600,11.67280000,0.07094456,777.81719831,0.06854102,832.99909375,0.00084180,0.09243021,877.48845156,-0.04733856,-0.04509165,0.00000000,0.00000000,0.00000000,0.00000000
152.00000000,2.22458400,11.68800000,0.07172578,778.83005053,0.06927023,834.69224167,0.00071507,0.09321858,878.71449138,-0.04780719,-0.04541140,0.00000000,0.00000000,0.00000000,0.00000000
153.00000000,2.25067900,11.69830000,0.07257456,779.51639118,0.07006189,836.08944682,0.00077067,0.09394094,879.35213188,-0.04818334,-0.04575759,0.00000000,0.00000000,0.00000000,0.00000000
154.00000000,2.27640100,11.71190000,0.07333689,780.42262738,0.07077238,837.65639489,0.00060195,0.09463099,880.25716034,-0.04851989,-0.04611110,0.00000000,0.00000000,0.00000000,0.00000000
155.00000000,2.30236100,11.72230000,0.07421578,781.11563153,0.07159089,839.08673566,0.00078336,0.09540510,881.23740327,-0.04896390,-0.04644120,0.00000000,0.00000000,0.00000000,0.00000000
156.00000000,2.32815100,11.72860000,0.07498567,781.53543213,0.07230733,840.13938753,0.00071993,0.09614561,882.01133228,-0.04932529,-0.04682032,0.00000000,0.00000000,0.00000000,0.00000000
157.00000000,2.35492100,11.74140000,0.07583822,782.38836031,0.07310010,841.72330265,0.00076833,0.09683752,882.92051847,-0.04969458,-0.04714294,0.00000000,0.00000000,0.00000000,0.00000000
158.00000000,2.38115100,11.75100000,0.07663067,783.02805645,0.07383641,843.03201844,0.00072585,0.09757899,883.98566162,-0.05010048,-0.04747851,0.00000000,0.00000000,0.00000000,0.00000000
159.00000000,2.40771800,11.76210000,0.07750567,783.76770511,0.07464880,844.51414361,0.00080181,0.09828751,884.73348389,-0.05048593,-0.04780158,0.00000000,0.00000000,0.00000000,0.00000000
160.00000000,2.43411700,11.77410000,0.07827189,784.56732529,0.07535966,845.97689180,0.00073155,0.09899412,885.77699437,-0.05083535,-0.04815877,0.00000000,0.00000000,0.00000000,0.00000000
161.00000000,2.46115800,11.77890000,0.07913567,784.88717336,0.07616041,846.99974308,0.00074497,0.09970202,886.46630591,-0.05122349,-0.04847852,0.00000000,0.00000000,0.00000000,0.00000000
162.00000000,2.48779300,11.78840000,0.07995444,785.52020600,0.07691886,848.32603767,0.00085577,0.10040761,887.51074136,-0.05159187,-0.04881574,0.00000000,0.00000000,0.00000000,0.00000000
163.00000000,2.51463100,11.79800000,0.08078067,786.15990214,0.07768362,849.66642314,0.00077161,0.10111552,887.96346399,-0.05199747,-0.04911805,0.00000000,0.00000000,0.00000000,0.00000000
164.00000000,2.54136700,11.80920000,0.08159189,786.90621430,0.07843393,851.11137871,0.00081974,0.10175283,888.94860085,-0.05230310,-0.04944973,0.00000000,0.00000000,0.00000000,0.00000000
165.00000000,2.56827300,11.81400000,0.08239178,787.22606237,0.07917320,852.08701716,0.00069406,0.10245696,889.99435363,-0.05269061,-0.04976635,0.00000000,0.00000000,0.00000000,0.00000000
166.00000000,2.59544900,11.82590000,0.08324811,788.01901905,0.07996404,853.62011390,0.00072121,0.10312963,890.47657580,-0.05303640,-0.05009323,0.00000000,0.00000000,0.00000000,0.00000000
167.00000000,2.62255700,11.83070000,0.08407811,788.33886712,0.08072996,854.62090998,0.00078320,0.10380005,891.31489078,-0.05340818,-0.05039187,0.00000000,0.00000000,0.00000000,0.00000000
168.00000000,2.64932800,11.84110000,0.08491567,789.03187127,0.08150226,856.03303864,0.00076170,0.10450526,891.82698569,-0.05379337,-0.05071189,0.00000000,0.00000000,0.00000000,0.00000000
169.00000000,2.67650400,11.84990000,0.08572311,789.61825940,0.08224623,857.30679318,0.00069889,0.10517617,892.36834713,-0.05415964,-0.05101652,0.00000000,0.00000000,0.00000000,0.00000000
170.00000000,2.70405200,11.85300000,0.08656811,789.82482794,0.08302421,858.19847140,0.00074663,0.10577802,893.20669257,-0.05449011,-0.05128792,0.00000000,0.00000000,0.00000000,0.00000000
171.00000000,2.73163300,11.86180000,0.08742067,790.41121607,0.08380853,859.50949152,0.00081535,0.10637973,893.97832198,-0.05476543,-0.05161430,0.00000000,0.00000000,0.00000000,0.00000000
172.00000000,2.75914700,11.86980000,0.08824689,790.94429619,0.08456804,860.74266961,0.00073874,0.10704937,894.51988662,-0.05517258,-0.05187679,0.00000000,0.00000000,0.00000000,0.00000000
173.00000000,2.78628900,11.87860000,0.08908822,791.53068431,0.08534085,862.04674581,0.00081410,0.10765112,895.12050536,-0.05543450,-0.05221662,0.00000000,0.00000000,0.00000000,0.00000000
174.00000000,2.81390500,11.88100000,0.08988433,791.69060835,0.08607157,862.85119089,0.00071682,0.10825222,895.78085275,-0.05574357,-0.05250865,0.00000000,0.00000000,0.00000000,0.00000000
175.00000000,2.84111400,11.88810000,0.09071067,792.16371695,0.08682947,864.02141583,0.00071648,0.10882041,896.23220698,-0.05605407,-0.05276634,0.00000000,0.00000000,0.00000000,0.00000000
176.00000000,2.86889900,11.89290000,0.09152189,792.48356502,0.08757295,865.01315781,0.00068153,0.00000000,0.00000000,0.00000000,0.00000000,0.00000000,0.00000000,0.00000000,0.00000000
177.00000000,2.89675100,11.90170000,0.09237444,793.06995315,0.08835372,866.32934948,0.00073594,0.00000000,0.00000000,0.00000000,0.00000000,0.00000000,0.00000000,0.00000000,0.00000000
178.00000000,2.92453500,11.90810000,0.09318933,793.49641725,0.08909942,867.44181937,0.00068029,0.00000000,0.00000000,0.00000000,0.00000000,0.00000000,0.00000000,0.00000000,0.00000000
179.00000000,2.95272500,11.90890000,0.09402689,793.54972526,0.08986528,868.16473710,0.00074174,0.00000000,0.00000000,0.00000000,0.00000000,0.00000000,0.00000000,0.00000000,0.00000000
180.00000000,2.98051000,11.91600000,0.09483433,794.02283386,0.09060306,869.32345996,0.00071358,0.00000000,0.00000000,0.00000000,0.00000000,0.00000000,0.00000000,0.00000000,0.00000000
181.00000000,3.00819300,11.92480000,0.09572822,794.60922199,0.09141919,870.67575017,0.00074059,0.00000000,0.00000000,0.00000000,0.00000000,0.00000000,0.00000000,0.00000000,0.00000000
182.00000000,3.03641600,11.92960000,0.09653189,794.92907006,0.09215237,871.66507472,0.00076721,0.00000000,0.00000000,0.00000000,0.00000000,0.00000000,0.00000000,0.00000000,0.00000000
183.00000000,3.06409900,11.93600000,0.09738067,795.35553415,0.09292613,872.80778631,0.00074616,0.00000000,0.00000000,0.00000000,0.00000000,0.00000000,0.00000000,0.00000000,0.00000000
184.00000000,3.09215400,11.94790000,0.09819567,796.14849083,0.09366853,874.32682265,0.00078670,0.00000000,0.00000000,0.00000000,0.00000000,0.00000000,0.00000000,0.00000000,0.00000000
185.00000000,3.12024300,11.94320000,0.09901822,795.83530626,0.09441726,874.63750346,0.00077256,0.00000000,0.00000000,0.00000000,0.00000000,0.00000000,0.00000000,0.00000000,0.00000000
186.00000000,3.14900700,11.94630000,0.09979556,796.04187480,0.09512430,875.48331594,0.00066246,0.00000000,0.00000000,0.00000000,0.00000000,0.00000000,0.00000000,0.00000000,0.00000000
187.00000000,3.17689300,11.95350000,0.10067067,796.52164691,0.09591969,876.70801212,0.00074393,0.00000000,0.00000000,0.00000000,0.00000000,0.00000000,0.00000000,0.00000000,0.00000000
188.00000000,3.20518400,11.95590000,0.10142933,796.68157094,0.09660873,877.48845156,0.00067520,0.00000000,0.00000000,0.00000000,0.00000000,0.00000000,0.00000000,0.00000000,0.00000000
189.00000000,3.23300200,11.96310000,0.10230444,797.16134305,0.09740294,878.71449138,0.00077025,0.00000000,0.00000000,0.00000000,0.00000000,0.00000000,0.00000000,0.00000000,0.00000000
190.00000000,3.26176700,11.96310000,0.10310433,797.16134305,0.09812833,879.35213188,0.00074914,0.00000000,0.00000000,0.00000000,0.00000000,0.00000000,0.00000000,0.00000000,0.00000000
191.00000000,3.29039700,11.96710000,0.10387056,797.42788311,0.09882269,880.25716034,0.00068075,0.00000000,0.00000000,0.00000000,0.00000000,0.00000000,0.00000000,0.00000000,0.00000000
192.00000000,3.31872200,11.97110000,0.10473056,797.69442316,0.09960146,881.23740327,0.00082289,0.00000000,0.00000000,0.00000000,0.00000000,0.00000000,0.00000000,0.00000000,0.00000000
193.00000000,3.34785800,11.97270000,0.10555300,797.80103919,0.10034566,882.01133228,0.00077462,0.00000000,0.00000000,0.00000000,0.00000000,0.00000000,0.00000000,0.00000000,0.00000000
194.00000000,3.37621700,11.97670000,0.10632300,798.06757925,0.10104190,882.92051847,0.00067904,0.00000000,0.00000000,0.00000000,0.00000000,0.00000000,0.00000000,0.00000000,0.00000000
195.00000000,3.40477900,11.98220000,0.10714922,798.43407183,0.10178844,883.98566162,0.00074640,0.00000000,0.00000000,0.00000000,0.00000000,0.00000000,0.00000000,0.00000000,0.00000000
196.00000000,3.43364500,11.98380000,0.10793789,798.54068785,0.10250053,884.73348389,0.00067805,0.00000000,0.00000000,0.00000000,0.00000000,0.00000000,0.00000000,0.00000000,0.00000000
197.00000000,3.46247700,11.98940000,0.10872656,798.91384393,0.10321211,885.77699437,0.00067757,0.00000000,0.00000000,0.00000000,0.00000000,0.00000000,0.00000000,0.00000000,0.00000000
198.00000000,3.49120800,11.99020000,0.10951533,798.96715194,0.10392328,886.46630591,0.00074501,0.00000000,0.00000000,0.00000000,0.00000000,0.00000000,0.00000000,0.00000000,0.00000000
199.00000000,3.52017500,11.99580000,0.11030400,799.34030802,0.10463385,887.51074136,0.00074428,0.00000000,0.00000000,0.00000000,0.00000000,0.00000000,0.00000000,0.00000000,0.00000000
200.00000000,3.54894000,11.99340000,0.11109267,799.18038399,0.10534392,887.96346399,0.00081138,0.00000000,0.00000000,0.00000000,0.00000000,0.00000000,0.00000000,0.00000000,0.00000000
201.00000000,3.57804300,11.99900000,0.11180622,799.55354007,0.10598592,888.94860085,0.00067569,0.00000000,0.00000000,0.00000000,0.00000000,0.00000000,0.00000000,0.00000000,0.00000000
202.00000000,3.60745000,12.00460000,0.11259489,799.92669615,0.10669502,889.99435363,0.00060768,0.00000000,0.00000000,0.00000000,0.00000000,0.00000000,0.00000000,0.00000000,0.00000000
203.00000000,3.63692400,12.00300000,0.11334611,799.82008013,0.10737000,890.47657580,0.00067476,0.00000000,0.00000000,0.00000000,0.00000000,0.00000000,0.00000000,0.00000000,0.00000000
204.00000000,3.66616200,12.00620000,0.11409722,800.03331218,0.10804441,891.31489078,0.00053942,0.00000000,0.00000000,0.00000000,0.00000000,0.00000000,0.00000000,0.00000000,0.00000000
205.00000000,3.69600800,12.00460000,0.11488589,799.92669615,0.10875206,891.82698569,0.00067382,0.00000000,0.00000000,0.00000000,0.00000000,0.00000000,0.00000000,0.00000000,0.00000000
206.00000000,3.72460300,12.00380000,0.11563700,799.87338814,0.10942554,892.36834713,0.00074072,0.00000000,0.00000000,0.00000000,0.00000000,0.00000000,0.00000000,0.00000000,0.00000000
207.00000000,3.75455100,12.00780000,0.11631311,800.13992820,0.11003139,893.20669257,0.00074047,0.00000000,0.00000000,0.00000000,0.00000000,0.00000000,0.00000000,0.00000000,0.00000000
208.00000000,3.78253900,12.01090000,0.11698911,800.34649675,0.11063677,893.97832198,0.00060529,0.00000000,0.00000000,0.00000000,0.00000000,0.00000000,0.00000000,0.00000000,0.00000000
209.00000000,3.81289200,12.01010000,0.11774022,800.29318873,0.11130899,894.51988662,0.00073933,0.00000000,0.00000000,0.00000000,0.00000000,0.00000000,0.00000000,0.00000000,0.00000000
210.00000000,3.84229800,12.01090000,0.11841622,800.34649675,0.11191360,895.12050536,0.00060452,0.00000000,0.00000000,0.00000000,0.00000000,0.00000000,0.00000000,0.00000000,0.00000000
211.00000000,3.87194200,12.01250000,0.11909222,800.45311277,0.11251784,895.78085275,0.00053702,0.00000000,0.00000000,0.00000000,0.00000000,0.00000000,0.00000000,0.00000000,0.00000000
212.00000000,3.90124700,12.01170000,0.11973067,800.39980476,0.11308818,896.23220698,0.00046961,0.00000000,0.00000000,0.00000000,0.00000000,0.00000000,0.00000000,0.00000000,0.00000000
213.00000000,3.93092400,12.01170000,0.12040678,800.39980476,0.00000000,0.00000000,0.00000000,0.00000000,0.00000000,0.00000000,0.00000000,0.00000000,0.00000000,0.00000000,0.00000000
214.00000000,3.96094000,12.00930000,0.12104522,800.23988072,0.00000000,0.00000000,0.00000000,0.00000000,0.00000000,0.00000000,0.00000000,0.00000000,0.00000000,0.00000000,0.00000000
215.00000000,3.99068400,12.01250000,0.12168367,800.45311277,0.00000000,0.00000000,0.00000000,0.00000000,0.00000000,0.00000000,0.00000000,0.00000000,0.00000000,0.00000000,0.00000000
216.00000000,4.02022600,12.01650000,0.12232211,800.71965283,0.00000000,0.00000000,0.00000000,0.00000000,0.00000000,0.00000000,0.00000000,0.00000000,0.00000000,0.00000000,0.00000000
217.00000000,4.04990400,12.01090000,0.12288544,800.34649675,0.00000000,0.00000000,0.00000000,0.00000000,0.00000000,0.00000000,0.00000000,0.00000000,0.00000000,0.00000000,0.00000000
218.00000000,4.07961400,12.01010000,0.12348633,800.29318873,0.00000000,0.00000000,0.00000000,0.00000000,0.00000000,0.00000000,0.00000000,0.00000000,0.00000000,0.00000000,0.00000000
219.00000000,4.10861600,12.00700000,0.12401222,800.08662019,0.00000000,0.00000000,0.00000000,0.00000000,0.00000000,0.00000000,0.00000000,0.00000000,0.00000000,0.00000000,0.00000000
220.00000000,4.13822500,12.00380000,0.12457556,799.87338814,0.00000000,0.00000000,0.00000000,0.00000000,0.00000000,0.00000000,0.00000000,0.00000000,0.00000000,0.00000000,0.00000000
221.00000000,4.16861200,12.00700000,0.12506378,800.08662019,0.00000000,0.00000000,0.00000000,0.00000000,0.00000000,0.00000000,0.00000000,0.00000000,0.00000000,0.00000000,0.00000000
222.00000000,4.19869500,12.00380000,0.12558956,799.87338814,0.00000000,0.00000000,0.00000000,0.00000000,0.00000000,0.00000000,0.00000000,0.00000000,0.00000000,0.00000000,0.00000000
223.00000000,4.22833900,11.99980000,0.12600267,799.60684808,0.00000000,0.00000000,0.00000000,0.00000000,0.00000000,0.00000000,0.00000000,0.00000000,0.00000000,0.00000000,0.00000000
224.00000000,4.25798200,11.99340000,0.12645333,799.18038399,0.00000000,0.00000000,0.00000000,0.00000000,0.00000000,0.00000000,0.00000000,0.00000000,0.00000000,0.00000000,0.00000000
225.00000000,4.28789600,11.98700000,0.12686644,798.75391990,0.00000000,0.00000000,0.00000000,0.00000000,0.00000000,0.00000000,0.00000000,0.00000000,0.00000000,0.00000000,0.00000000
226.00000000,4.31791100,11.98380000,0.12727956,798.54068785,0.00000000,0.00000000,0.00000000,0.00000000,0.00000000,0.00000000,0.00000000,0.00000000,0.00000000,0.00000000,0.00000000
227.00000000,4.34704700,11.97510000,0.12758011,797.96096322,0.00000000,0.00000000,0.00000000,0.00000000,0.00000000,0.00000000,0.00000000,0.00000000,0.00000000,0.00000000,0.00000000
228.00000000,4.37767100,11.97510000,0.12791811,797.96096322,0.00000000,0.00000000,0.00000000,0.00000000,0.00000000,0.00000000,0.00000000,0.00000000,0.00000000,0.00000000,0.00000000
229.00000000,4.40772000,11.96950000,0.12821856,797.58780714,0.00000000,0.00000000,0.00000000,0.00000000,0.00000000,0.00000000,0.00000000,0.00000000,0.00000000,0.00000000,0.00000000
230.00000000,4.43814000,11.95910000,0.12848144,796.89480299,0.00000000,0.00000000,0.00000000,0.00000000,0.00000000,0.00000000,0.00000000,0.00000000,0.00000000,0.00000000,0.00000000
231.00000000,4.46781800,11.95590000,0.12870678,796.68157094,0.00000000,0.00000000,0.00000000,0.00000000,0.00000000,0.00000000,0.00000000,0.00000000,0.00000000,0.00000000,0.00000000
232.00000000,4.49776500,11.94480000,0.12893211,795.94192228,0.00000000,0.00000000,0.00000000,0.00000000,0.00000000,0.00000000,0.00000000,0.00000000,0.00000000,0.00000000,0.00000000
233.00000000,4.52869300,11.93520000,0.12911989,795.30222614,0.00000000,0.00000000,0.00000000,0.00000000,0.00000000,0.00000000,0.00000000,0.00000000,0.00000000,0.00000000,0.00000000
234.00000000,4.55935000,11.92400000,0.12927011,794.55591398,0.00000000,0.00000000,0.00000000,0.00000000,0.00000000,0.00000000,0.00000000,0.00000000,0.00000000,0.00000000,0.00000000
235.00000000,4.59041300,11.91050000,0.12938278,793.65634128,0.00000000,0.00000000,0.00000000,0.00000000,0.00000000,0.00000000,0.00000000,0.00000000,0.00000000,0.00000000,0.00000000
236.00000000,4.62076600,11.90010000,0.12953300,792.96333713,0.00000000,0.00000000,0.00000000,0.00000000,0.00000000,0.00000000,0.00000000,0.00000000,0.00000000,0.00000000,0.00000000
237.00000000,4.65199800,11.88180000,0.12964567,791.74391636,0.00000000,0.00000000,0.00000000,0.00000000,0.00000000,0.00000000,0.00000000,0.00000000,0.00000000,0.00000000,0.00000000
238.00000000,4.68326400,11.86900000,0.12972078,790.89098817,0.00000000,0.00000000,0.00000000,0.00000000,0.00000000,0.00000000,0.00000000,0.00000000,0.00000000,0.00000000,0.00000000
239.00000000,4.71469900,11.84910000,0.12975833,789.56495138,0.00000000,0.00000000,0.00000000,0.00000000,0.00000000,0.00000000,0.00000000,0.00000000,0.00000000,0.00000000,0.00000000
240.00000000,4.74633600,11.82910000,0.12983344,788.23225109,0.00000000,0.00000000,0.00000000,0.00000000,0.00000000,0.00000000,0.00000000,0.00000000,0.00000000,0.00000000,0.00000000
241.00000000,4.77824500,11.80840000,0.12987100,786.85290629,0.00000000,0.00000000,0.00000000,0.00000000,0.00000000,0.00000000,0.00000000,0.00000000,0.00000000,0.00000000,0.00000000
242.00000000,4.81028800,11.79000000,0.12987100,785.62682202,0.00000000,0.00000000,0.00000000,0.00000000,0.00000000,0.00000000,0.00000000,0.00000000,0.00000000,0.00000000,0.00000000
243.00000000,4.84294000,11.75890000,0.12990856,783.55447307,0.00000000,0.00000000,0.00000000,0.00000000,0.00000000,0.00000000,0.00000000,0.00000000,0.00000000,0.00000000,0.00000000
244.00000000,4.87620100,11.73180000,0.12990856,781.74866417,0.00000000,0.00000000,0.00000000,0.00000000,0.00000000,0.00000000,0.00000000,0.00000000,0.00000000,0.00000000,0.00000000
245.00000000,4.91017100,11.70550000,0.12994611,779.99616329,0.00000000,0.00000000,0.00000000,0.00000000,0.00000000,0.00000000,0.00000000,0.00000000,0.00000000,0.00000000,0.00000000
246.00000000,4.94468300,11.67040000,0.12990856,777.65727428,0.00000000,0.00000000,0.00000000,0.00000000,0.00000000,0.00000000,0.00000000,0.00000000,0.00000000,0.00000000,0.00000000
247.00000000,4.97939800,11.64170000,0.12990856,775.74484936,0.00000000,0.00000000,0.00000000,0.00000000,0.00000000,0.00000000,0.00000000,0.00000000,0.00000000,0.00000000,0.00000000
248.00000000,5.01478900,11.60420000,0.12987100,773.24603631,0.00000000,0.00000000,0.00000000,0.00000000,0.00000000,0.00000000,0.00000000,0.00000000,0.00000000,0.00000000,0.00000000
249.00000000,5.05089100,11.56120000,0.12987100,770.38073068,0.00000000,0.00000000,0.00000000,0.00000000,0.00000000,0.00000000,0.00000000,0.00000000,0.00000000,0.00000000,0.00000000
250.00000000,5.08746600,11.51650000,0.12987100,767.40214553,0.00000000,0.00000000,0.00000000,0.00000000,0.00000000,0.00000000,0.00000000,0.00000000,0.00000000,0.00000000,0.00000000
251.00000000,5.12377200,11.46550000,0.12987100,764.00375979,0.00000000,0.00000000,0.00000000,0.00000000,0.00000000,0.00000000,0.00000000,0.00000000,0.00000000,0.00000000,0.00000000
252.00000000,5.16278200,11.40960000,0.12987100,760.27886247,0.00000000,0.00000000,0.00000000,0.00000000,0.00000000,0.00000000,0.00000000,0.00000000,0.00000000,0.00000000,0.00000000
253.00000000,5.20165700,11.35060000,0.12983344,756.34739661,0.00000000,0.00000000,0.00000000,0.00000000,0.00000000,0.00000000,0.00000000,0.00000000,0.00000000,0.00000000,0.00000000
254.00000000,5.24144500,11.28130000,0.12979589,751.72959010,0.00000000,0.00000000,0.00000000,0.00000000,0.00000000,0.00000000,0.00000000,0.00000000,0.00000000,0.00000000,0.00000000
255.00000000,5.28170700,11.21030000,0.12975833,746.99850406,0.00000000,0.00000000,0.00000000,0.00000000,0.00000000,0.00000000,0.00000000,0.00000000,0.00000000,0.00000000,0.00000000
256.00000000,5.32376200,11.11780000,0.12972078,740.83476521,0.00000000,0.00000000,0.00000000,0.00000000,0.00000000,0.00000000,0.00000000,0.00000000,0.00000000,0.00000000,0.00000000
256.50000000,5.34600700,11.07310000,0.12972078,737.85618006,0.00000000,0.00000000,0.00000000,0.00000000,0.00000000,0.00000000,0.00000000,0.00000000,0.00000000,0.00000000,0.00000000