File: polyN_optimization/DP780_results/DATA/UT_90_2.csv
Time[s],Displacement[mm],Force[kN],EngStrain_longi,EngStress[MPa],TrueStrain,TrueStress[MPa],TrueStrainRate[1/s],PlasticStrain_longi,PlasticStress[MPa],PlasticStrain_thick,PlasticStrain_width,R-Value,Thickness[mm],Width[mm], Young's Modulus [MPa]
0.00000000,0.00000000,-0.02140000,0.00000000,-1.43343882,0.00000000,-1.43343882,0.00000000,0.00052009,419.43112309,0.00038296,-0.00090305,0.87398516,1.49640000,9.97670000,247465.55704587
1.50000000,0.00221400,0.35270000,0.00004322,23.62494722,0.00004322,23.62596835,0.00005267,0.00059428,432.98874020,0.00029630,-0.00089058,0.00000000,0.00000000,0.00000000,0.00000000
3.00000000,0.00357000,0.67560000,0.00011267,45.25379740,0.00011266,45.25889600,0.00003600,0.00081569,445.43111453,0.00035004,-0.00116574,0.00000000,0.00000000,0.00000000,0.00000000
4.50000000,0.00559800,1.03930000,0.00016456,69.61555897,0.00016454,69.62701460,0.00000222,0.00109040,457.68939333,0.00008243,-0.00117283,0.00000000,0.00000000,0.00000000,0.00000000
6.00000000,0.00826300,1.34950000,0.00022922,90.39372350,0.00022920,90.41444375,0.00001888,0.00140300,470.56659197,-0.00006244,-0.00134056,0.00000000,0.00000000,0.00000000,0.00000000
7.50000000,0.01059700,1.63980000,0.00033022,109.83892389,0.00033017,109.87519514,0.00009686,0.00165496,481.97481805,-0.00002158,-0.00163338,0.00000000,0.00000000,0.00000000,0.00000000
9.00000000,0.01232500,1.92850000,0.00038789,129.17695129,0.00038781,129.22705759,0.00016150,0.00198695,493.05196563,-0.00029822,-0.00168872,0.00000000,0.00000000,0.00000000,0.00000000
10.50000000,0.01360200,2.19080000,0.00041322,146.74662426,0.00041314,146.80726323,0.00007064,0.00239017,504.81452236,-0.00049814,-0.00189203,0.00000000,0.00000000,0.00000000,0.00000000
12.00000000,0.01550500,2.44360000,0.00048344,163.67995757,0.00048333,163.75908773,-0.00000866,0.00283972,515.48447049,-0.00062945,-0.00221026,0.00000000,0.00000000,0.00000000,0.00000000
13.50000000,0.01749300,2.70520000,0.00054456,181.20274235,0.00054441,181.30141731,-0.00011016,0.00334766,525.55412055,-0.00090815,-0.00243951,0.00000000,0.00000000,0.00000000,0.00000000
15.00000000,0.02113000,2.94130000,0.00063411,197.01745752,0.00063391,197.14238848,-0.00003065,0.00381578,536.03922799,-0.00116226,-0.00265351,0.00000000,0.00000000,0.00000000,0.00000000
16.50000000,0.02328200,3.17090000,0.00077633,212.39678239,0.00077603,212.56167309,0.00021940,0.00427067,545.39857570,-0.00136325,-0.00290742,0.00000000,0.00000000,0.00000000,0.00000000
18.00000000,0.02484300,3.41740000,0.00077756,228.90812203,0.00077725,229.08611081,0.00016632,0.00483223,554.28518685,-0.00161928,-0.00321295,0.00000000,0.00000000,0.00000000,0.00000000
19.50000000,0.02637500,3.64060000,0.00080644,243.85875492,0.00080612,244.05541346,0.00002287,0.00545430,563.69728802,-0.00195488,-0.00349941,0.00000000,0.00000000,0.00000000,0.00000000
21.00000000,0.02896200,3.85990000,0.00089711,258.54815363,0.00089671,258.78010005,-0.00007482,0.00604319,572.14051078,-0.00225674,-0.00378646,0.00000000,0.00000000,0.00000000,0.00000000
22.50000000,0.03229200,4.09440000,0.00105889,274.25569580,0.00105833,274.54610211,-0.00005994,0.00662628,580.15006427,-0.00250249,-0.00412379,0.00000000,0.00000000,0.00000000,0.00000000
24.00000000,0.03477200,4.31130000,0.00119078,288.78433502,0.00119007,289.12821299,0.00021820,0.00730935,588.93403762,-0.00286150,-0.00444785,0.00000000,0.00000000,0.00000000,0.00000000
25.50000000,0.03742700,4.52500000,0.00122167,303.09862825,0.00122092,303.46891374,0.00025570,0.00805252,596.68674334,-0.00320528,-0.00484725,0.00000000,0.00000000,0.00000000,0.00000000
27.00000000,0.04123300,4.75070000,0.00125978,318.21671895,0.00125898,318.61760130,0.00003773,0.00872680,603.97451116,-0.00347586,-0.00525094,0.00000000,0.00000000,0.00000000,0.00000000
28.50000000,0.04513700,4.95810000,0.00136900,332.10901850,0.00136806,332.56367575,-0.00018729,0.00939742,611.97061615,-0.00384830,-0.00554912,0.00000000,0.00000000,0.00000000,0.00000000
30.00000000,0.04799600,5.16380000,0.00155744,345.88744675,0.00155623,346.42614724,-0.00007477,0.01014577,619.10721843,-0.00423954,-0.00590623,0.00000000,0.00000000,0.00000000,0.00000000
31.50000000,0.05162500,5.39110000,0.00179822,361.11271044,0.00179661,361.76207135,0.00025489,0.01097066,626.35722817,-0.00473789,-0.00623277,0.00000000,0.00000000,0.00000000,0.00000000
33.00000000,0.05641300,5.59050000,0.00192267,374.46914502,0.00192082,375.18912437,0.00037509,0.01169479,633.66434757,-0.00511643,-0.00657836,0.00000000,0.00000000,0.00000000,0.00000000
34.50000000,0.06247500,5.78740000,0.00203944,387.65812180,0.00203737,388.44872900,0.00030008,0.01246647,640.19393832,-0.00552190,-0.00694457,0.00000000,0.00000000,0.00000000,0.00000000
36.00000000,0.06809300,5.99240000,0.00215256,401.38966186,0.00215024,402.25367541,0.00014281,0.01326611,646.91568867,-0.00595020,-0.00731591,0.00000000,0.00000000,0.00000000,0.00000000
37.50000000,0.07408700,6.18700000,0.00235156,414.42457746,0.00234879,415.39911987,-0.00006740,0.01409518,653.50345487,-0.00634786,-0.00774733,0.00000000,0.00000000,0.00000000,0.00000000
39.00000000,0.08135500,6.37760000,0.00263344,427.19156056,0.00262998,428.31654580,-0.00002239,0.01491815,659.66019271,-0.00677975,-0.00813840,0.00000000,0.00000000,0.00000000,0.00000000
40.50000000,0.08987700,6.57220000,0.00293367,440.22647615,0.00292937,441.51795389,0.00011256,0.01572179,665.87570990,-0.00713279,-0.00858900,0.00000000,0.00000000,0.00000000,0.00000000
42.00000000,0.09846100,6.75720000,0.00323378,452.61835377,0.00322856,454.08202095,0.00023946,0.01656475,672.17565334,-0.00759599,-0.00896877,0.00000000,0.00000000,0.00000000,0.00000000
43.50000000,0.10754500,6.93340000,0.00354156,464.42077991,0.00353530,466.06555191,0.00030672,0.01742896,677.73909979,-0.00806924,-0.00935973,0.00000000,0.00000000,0.00000000,0.00000000
45.00000000,0.11778200,7.11520000,0.00386789,476.59831154,0.00386043,478.44174086,0.00025414,0.01831244,683.70283503,-0.00855015,-0.00976229,0.00000000,0.00000000,0.00000000,0.00000000
46.50000000,0.12997500,7.27950000,0.00426556,487.60363853,0.00425648,489.68353894,0.00028392,0.01918616,689.23716449,-0.00902940,-0.01015677,0.00000000,0.00000000,0.00000000,0.00000000
48.00000000,0.14138100,7.44380000,0.00473811,498.60896552,0.00472692,500.97143020,0.00050810,0.02008534,694.63357769,-0.00952374,-0.01056160,0.00000000,0.00000000,0.00000000,0.00000000
49.50000000,0.15509200,7.60970000,0.00515089,509.72146550,0.00513767,512.34698414,0.00053797,0.02100740,699.66985238,-0.01000418,-0.01100322,0.00000000,0.00000000,0.00000000,0.00000000
51.00000000,0.17022400,7.75960000,0.00560467,519.76223553,0.00558902,522.67532961,0.00052977,0.02195187,705.22721948,-0.01053255,-0.01141932,0.00000000,0.00000000,0.00000000,0.00000000
52.50000000,0.18518200,7.90000000,0.00608489,529.16666590,0.00606645,532.38658626,0.00028341,0.02285328,710.37766685,-0.01099594,-0.01185733,0.00000000,0.00000000,0.00000000,0.00000000
54.00000000,0.20281000,8.04430000,0.00667011,538.83233044,0.00664796,542.42640195,0.00018632,0.02381314,715.35803715,-0.01151656,-0.01229658,0.00000000,0.00000000,0.00000000,0.00000000
55.50000000,0.21986500,8.17830000,0.00729311,547.80806882,0.00726664,551.80329394,0.00035787,0.02474622,720.38350155,-0.01203470,-0.01271152,0.00000000,0.00000000,0.00000000,0.00000000
57.00000000,0.23942500,8.29950000,0.00790133,555.92642324,0.00787028,560.31898322,0.00035765,0.02572527,724.78705688,-0.01250578,-0.01321949,0.00000000,0.00000000,0.00000000,0.00000000
58.50000000,0.25915300,8.43030000,0.00851711,564.68781563,0.00848105,569.49732450,0.00027545,0.02669127,729.41086584,-0.01303716,-0.01365411,0.00000000,0.00000000,0.00000000,0.00000000
60.00000000,0.27834100,8.54990000,0.00924167,572.69899706,0.00919922,577.99169029,0.00025301,0.02766763,733.93981164,-0.01354777,-0.01411986,0.00000000,0.00000000,0.00000000,0.00000000
61.50000000,0.29942400,8.65840000,0.01000744,579.96666582,0.00995770,585.77065001,0.00045351,0.02864631,738.54129606,-0.01405279,-0.01459352,0.00000000,0.00000000,0.00000000,0.00000000
63.00000000,0.31966500,8.77800000,0.01072444,587.97784725,0.01066735,594.28358300,0.00055721,0.02965982,742.50321109,-0.01456868,-0.01509113,0.00000000,0.00000000,0.00000000,0.00000000
64.50000000,0.34271200,8.88240000,0.01144522,594.97088521,0.01138022,601.78045921,0.00054209,0.03067778,746.81674611,-0.01513311,-0.01554466,0.00000000,0.00000000,0.00000000,0.00000000
66.00000000,0.36471100,8.98850000,0.01221122,602.07779448,0.01213727,609.42990023,0.00046746,0.03168871,750.84766735,-0.01566289,-0.01602582,0.00000000,0.00000000,0.00000000,0.00000000
67.50000000,0.38836600,9.09460000,0.01303356,609.18470375,0.01294935,617.12454643,0.00062287,0.03272462,754.74471486,-0.01626686,-0.01645776,0.00000000,0.00000000,0.00000000,0.00000000
69.00000000,0.41077000,9.19030000,0.01377700,615.59498856,0.01368296,624.07604071,0.00064456,0.03378258,759.10562575,-0.01683281,-0.01694976,0.00000000,0.00000000,0.00000000,0.00000000
70.50000000,0.43500100,9.28600000,0.01456944,622.00527336,0.01446433,631.06754463,0.00061448,0.03484396,762.47867162,-0.01741718,-0.01742678,0.00000000,0.00000000,0.00000000,0.00000000
72.00000000,0.45859000,9.38330000,0.01535811,628.52273115,0.01524137,638.17565309,0.00048834,0.03587448,766.05820381,-0.01796757,-0.01790691,0.00000000,0.00000000,0.00000000,0.00000000
73.50000000,0.48424100,9.47100000,0.01623300,634.39715098,0.01610265,644.69531993,0.00064300,0.03691682,769.92661568,-0.01848397,-0.01843286,0.00000000,0.00000000,0.00000000,0.00000000
75.00000000,0.50918200,9.55870000,0.01709689,640.27157080,0.01695238,651.21822270,0.00072398,0.03801595,773.74136992,-0.01909556,-0.01892039,0.00000000,0.00000000,0.00000000,0.00000000
76.50000000,0.53466500,9.64880000,0.01792300,646.30675011,0.01776428,657.89050600,0.00066421,0.03910883,777.10973314,-0.01970455,-0.01940428,0.00000000,0.00000000,0.00000000,0.00000000
78.00000000,0.56008000,9.73020000,0.01875667,651.75917627,0.01858293,663.98400588,0.00059711,0.04016964,780.90209495,-0.02026120,-0.01990845,0.00000000,0.00000000,0.00000000,0.00000000
79.50000000,0.58708400,9.80510000,0.01965422,656.77621212,0.01946357,669.68463775,0.00061861,0.04127486,784.18114038,-0.02087090,-0.02040396,0.00000000,0.00000000,0.00000000,0.00000000
81.00000000,0.61361500,9.88810000,0.02057067,662.33581127,0.02036195,675.96050047,0.00068448,0.04244666,787.51921042,-0.02154010,-0.02090656,0.00000000,0.00000000,0.00000000,0.00000000
82.50000000,0.64122800,9.96380000,0.02149078,667.40643363,0.02126311,681.74951698,0.00074284,0.04352369,790.90168915,-0.02210501,-0.02141868,0.00000000,0.00000000,0.00000000,0.00000000
84.00000000,0.66863900,10.03160000,0.02241833,671.94788932,0.02217074,687.01184108,0.00069803,0.04464922,794.38577928,-0.02268339,-0.02196583,0.00000000,0.00000000,0.00000000,0.00000000
85.50000000,0.69686000,10.11060000,0.02337600,677.23955598,0.02310697,693.07070784,0.00068999,0.04576481,797.41668058,-0.02326158,-0.02250324,0.00000000,0.00000000,0.00000000,0.00000000
87.00000000,0.72494600,10.17670000,0.02432233,681.66714036,0.02403126,698.24687577,0.00067460,0.04690564,800.86984717,-0.02388033,-0.02302531,0.00000000,0.00000000,0.00000000,0.00000000
88.50000000,0.75374300,10.24210000,0.02529500,686.04783655,0.02498038,703.40141658,0.00076199,0.04801969,803.68513694,-0.02442920,-0.02359048,0.00000000,0.00000000,0.00000000,0.00000000
90.00000000,0.78301200,10.31150000,0.02627522,690.69646524,0.02593596,708.84466835,0.00068804,0.04919361,806.38408824,-0.02508031,-0.02411330,0.00000000,0.00000000,0.00000000,0.00000000
91.50000000,0.81204500,10.37210000,0.02725922,694.75564245,0.02689431,713.69414090,0.00061424,0.05036697,809.65579627,-0.02571703,-0.02464994,0.00000000,0.00000000,0.00000000,0.00000000
93.00000000,0.84151800,10.43110000,0.02825822,698.70764666,0.02786632,718.45188261,0.00073060,0.05151623,812.45964137,-0.02633600,-0.02518024,0.00000000,0.00000000,0.00000000,0.00000000
94.50000000,0.87193700,10.49410000,0.02926089,702.92758336,0.02884096,723.49586928,0.00072255,0.05267493,815.22684314,-0.02695492,-0.02572001,0.00000000,0.00000000,0.00000000,0.00000000
96.00000000,0.90232300,10.54520000,0.03026733,706.35042091,0.02981832,727.72976455,0.00066337,0.05389179,818.15407673,-0.02763720,-0.02625459,0.00000000,0.00000000,0.00000000,0.00000000
97.50000000,0.93281000,10.60020000,0.03131144,710.03449264,0.03083124,732.26669821,0.00068468,0.05505612,820.64454968,-0.02828145,-0.02677467,0.00000000,0.00000000,0.00000000,0.00000000
99.00000000,0.96373700,10.65680000,0.03233678,713.82573736,0.03182495,736.90856160,0.00064783,0.05625662,823.39820598,-0.02892312,-0.02733351,0.00000000,0.00000000,0.00000000,0.00000000
100.50000000,0.99473100,10.70710000,0.03339578,717.19498841,0.03285025,741.14627286,0.00070503,0.05747765,826.00991700,-0.02960560,-0.02787205,0.00000000,0.00000000,0.00000000,0.00000000
102.00000000,1.02646900,10.75490000,0.03446989,720.39678165,0.03388911,745.22877867,0.00072621,0.05867199,828.71203334,-0.03020229,-0.02846970,0.00000000,0.00000000,0.00000000,0.00000000
103.50000000,1.05793700,10.80600000,0.03551400,723.81961920,0.03489792,749.52534916,0.00061664,0.05989806,831.10188979,-0.03090090,-0.02899716,0.00000000,0.00000000,0.00000000,0.00000000
105.00000000,1.09008100,10.85060000,0.03663700,726.80706645,0.03598182,753.43509695,0.00072491,0.06111687,833.94969172,-0.03154267,-0.02957420,0.00000000,0.00000000,0.00000000,0.00000000
106.50000000,1.12273200,10.89690000,0.03772233,729.90838501,0.03702825,757.44223242,0.00071687,0.06232474,836.57131256,-0.03218167,-0.03014307,0.00000000,0.00000000,0.00000000,0.00000000
108.00000000,1.15534900,10.94310000,0.03880767,733.00300526,0.03807358,761.44914156,0.00066540,0.06353602,838.90599006,-0.03283469,-0.03070133,0.00000000,0.00000000,0.00000000,0.00000000
109.50000000,1.18837200,10.98300000,0.03992311,735.67563184,0.03914678,765.04609183,0.00062856,0.06474279,841.13327979,-0.03346679,-0.03127600,0.00000000,0.00000000,0.00000000,0.00000000
111.00000000,1.22126000,11.01890000,0.04103856,738.08032593,0.04021883,768.37007639,0.00062789,0.06597893,843.49782404,-0.03410755,-0.03187138,0.00000000,0.00000000,0.00000000,0.00000000
112.50000000,1.25465400,11.06590000,0.04219900,741.22853268,0.04133290,772.50763553,0.00075688,0.06721940,846.10177260,-0.03479297,-0.03242643,0.00000000,0.00000000,0.00000000,0.00000000
114.00000000,1.28791400,11.10820000,0.04331822,744.06191875,0.04240623,776.29335829,0.00072005,0.06848447,848.33417420,-0.03547063,-0.03301384,0.00000000,0.00000000,0.00000000,0.00000000
115.50000000,1.32195100,11.14250000,0.04447867,746.35943984,0.04351788,779.55651258,0.00073351,0.06972257,850.77234277,-0.03616189,-0.03356068,0.00000000,0.00000000,0.00000000,0.00000000
117.00000000,1.35649500,11.18320000,0.04565800,749.08565292,0.04464635,783.28740566,0.00076160,0.07096182,852.64355881,-0.03680955,-0.03415227,0.00000000,0.00000000,0.00000000,0.00000000
118.50000000,1.39114000,11.21350000,0.04682600,751.11524152,0.04576273,786.28696382,0.00080386,0.07221465,854.98710551,-0.03747607,-0.03473858,0.00000000,0.00000000,0.00000000,0.00000000
120.00000000,1.42571800,11.25020000,0.04799400,753.57352211,0.04687786,789.74052973,0.00074548,0.07349029,857.30398190,-0.03814565,-0.03534464,0.00000000,0.00000000,0.00000000,0.00000000
121.50000000,1.46134300,11.28440000,0.04921833,755.86434489,0.04804544,793.06672817,0.00076622,0.07480343,859.41763232,-0.03888205,-0.03592138,0.00000000,0.00000000,0.00000000,0.00000000
123.00000000,1.49585400,11.32030000,0.05042767,758.26903898,0.04919738,796.50677732,0.00081528,0.07610364,861.70638994,-0.03956678,-0.03653686,0.00000000,0.00000000,0.00000000,0.00000000
124.50000000,1.53087100,11.35060000,0.05161822,760.29862759,0.05033014,799.54389110,0.00083592,0.07735474,863.77466593,-0.04021186,-0.03714287,0.00000000,0.00000000,0.00000000,0.00000000
126.00000000,1.56744300,11.38010000,0.05282378,762.27462969,0.05147587,802.54085534,0.00082779,0.07865782,866.19157332,-0.04086134,-0.03779648,0.00000000,0.00000000,0.00000000,0.00000000
127.50000000,1.60327100,11.40730000,0.05408189,764.09657062,0.05267014,805.42035645,0.00084093,0.07998297,867.98876711,-0.04155827,-0.03842469,0.00000000,0.00000000,0.00000000,0.00000000
129.00000000,1.63957300,11.43760000,0.05532878,766.12615922,0.05385236,808.51498324,0.00086142,0.08132204,870.08711883,-0.04229565,-0.03902639,0.00000000,0.00000000,0.00000000,0.00000000
130.50000000,1.67567200,11.46870000,0.05653811,768.20933432,0.05499763,811.64243903,0.00079647,0.08261294,872.50684222,-0.04296504,-0.03964790,0.00000000,0.00000000,0.00000000,0.00000000
132.00000000,1.71197400,11.49180000,0.05781133,769.75664445,0.05620199,814.25730241,0.00080266,0.08394647,874.31508339,-0.04367499,-0.04027148,0.00000000,0.00000000,0.00000000,0.00000000
133.50000000,1.74915500,11.51650000,0.05906189,771.41112757,0.05738351,816.97212587,0.00077316,0.08532229,876.23003926,-0.04442479,-0.04089751,0.00000000,0.00000000,0.00000000,0.00000000
135.00000000,1.78616600,11.54920000,0.06032011,773.60147567,0.05857085,820.26520264,0.00075107,0.08666222,878.05805579,-0.04513098,-0.04153124,0.00000000,0.00000000,0.00000000,0.00000000
136.50000000,1.82290700,11.56750000,0.06158956,774.82726680,0.05976737,822.54853380,0.00079980,0.08800841,879.65891619,-0.04588157,-0.04212683,0.00000000,0.00000000,0.00000000,0.00000000
138.00000000,1.86083200,11.58830000,0.06285889,776.22051575,0.06096234,825.01287490,0.00072083,0.08939052,881.93693158,-0.04665210,-0.04273842,0.00000000,0.00000000,0.00000000,0.00000000
139.50000000,1.89862100,11.61140000,0.06417711,777.76782587,0.06220183,827.68271805,0.00076944,0.09073747,884.01827109,-0.04735079,-0.04338668,0.00000000,0.00000000,0.00000000,0.00000000
141.00000000,1.93644400,11.63130000,0.06549167,779.10079001,0.06343635,830.12539924,0.00082504,0.09215303,885.63138405,-0.04813653,-0.04401651,0.00000000,0.00000000,0.00000000,0.00000000
142.50000000,1.97436900,11.65770000,0.06678733,780.86914443,0.06465164,833.02131227,0.00084508,0.09349452,887.35190721,-0.04883119,-0.04466333,0.00000000,0.00000000,0.00000000,0.00000000
144.00000000,2.01280000,11.67840000,0.06810189,782.25569506,0.06588314,835.52878549,0.00085820,0.09493718,889.58921783,-0.04958788,-0.04534930,0.00000000,0.00000000,0.00000000,0.00000000
145.50000000,2.05092700,11.69910000,0.06943511,783.64224569,0.06713058,838.05453210,0.00090619,0.09635994,891.27776605,-0.05032738,-0.04603256,0.00000000,0.00000000,0.00000000,0.00000000
147.00000000,2.08959500,11.72150000,0.07077589,785.14266763,0.06838352,840.71183784,0.00090505,0.09774689,892.93721753,-0.05105305,-0.04669384,0.00000000,0.00000000,0.00000000,0.00000000
148.50000000,2.12883800,11.73500000,0.07207156,786.04693978,0.06959281,842.69856547,0.00082682,0.09914945,894.48678814,-0.05177635,-0.04737310,0.00000000,0.00000000,0.00000000,0.00000000
150.00000000,2.16737100,11.76050000,0.07341989,787.75500940,0.07084971,845.59189466,0.00083303,0.10065475,896.73658528,-0.05261249,-0.04804225,0.00000000,0.00000000,0.00000000,0.00000000
151.50000000,2.20668100,11.77090000,0.07476444,788.45163387,0.07210152,847.39978225,0.00083198,0.10206967,898.37088325,-0.05333743,-0.04873224,0.00000000,0.00000000,0.00000000,0.00000000
153.00000000,2.24558600,11.79480000,0.07613522,790.05253050,0.07337613,850.20335547,0.00085881,0.10350121,900.32276086,-0.05413763,-0.04936358,0.00000000,0.00000000,0.00000000,0.00000000
154.50000000,2.28506500,11.80760000,0.07746844,790.90991446,0.07461426,852.18047523,0.00078780,0.10496947,901.89146027,-0.05490377,-0.05006570,0.00000000,0.00000000,0.00000000,0.00000000
156.00000000,2.32488300,11.82270000,0.07882800,791.92135961,0.07587527,854.34693654,0.00076600,0.10645407,903.83089050,-0.05568547,-0.05076860,0.00000000,0.00000000,0.00000000,0.00000000
157.50000000,2.36490300,11.84110000,0.08021767,793.15384906,0.07716256,856.77880014,0.00078600,0.10798738,905.64532182,-0.05661266,-0.05137473,0.00000000,0.00000000,0.00000000,0.00000000
159.00000000,2.40495700,11.85220000,0.08164478,793.89736171,0.07848283,858.71493539,0.00089596,0.10947910,907.24437918,-0.05736700,-0.05211210,0.00000000,0.00000000,0.00000000,0.00000000
160.50000000,2.44545000,11.87220000,0.08299678,795.23702416,0.07973199,861.23913473,0.00085316,0.11101184,908.88366001,-0.05817608,-0.05283576,0.00000000,0.00000000,0.00000000,0.00000000
162.00000000,2.48621400,11.88490000,0.08444278,796.08770981,0.08106629,863.31156738,0.00092153,0.11253475,910.69834042,-0.05900275,-0.05353200,0.00000000,0.00000000,0.00000000,0.00000000
163.50000000,2.52674200,11.89930000,0.08585111,797.05226677,0.08236411,865.48008949,0.00088552,0.11406276,912.33937856,-0.05977681,-0.05428595,0.00000000,0.00000000,0.00000000,0.00000000
165.00000000,2.56787800,11.91210000,0.08733089,797.90965074,0.08372597,867.59180979,0.00100189,0.11565484,914.04213819,-0.06064420,-0.05501064,0.00000000,0.00000000,0.00000000,0.00000000
166.50000000,2.60948600,11.92800000,0.08872422,798.97468238,0.08500657,869.86308965,0.00087645,0.11727655,915.95002231,-0.06153216,-0.05574439,0.00000000,0.00000000,0.00000000,0.00000000
168.00000000,2.65038600,11.93200000,0.09017767,799.24261487,0.08634068,871.31644898,0.00082001,0.11886461,917.41215628,-0.06240083,-0.05646378,0.00000000,0.00000000,0.00000000,0.00000000
169.50000000,2.69202800,11.94630000,0.09164244,800.20047352,0.08768339,873.53280096,0.00089488,0.12044947,918.99562189,-0.06325393,-0.05719553,0.00000000,0.00000000,0.00000000,0.00000000
171.00000000,2.73451600,11.95670000,0.09310711,800.89709799,0.08902420,875.46631308,0.00085910,0.12209604,921.00536761,-0.06414596,-0.05795009,0.00000000,0.00000000,0.00000000,0.00000000
172.50000000,2.77680200,11.96710000,0.09457556,801.59372246,0.09036667,877.40489409,0.00089918,0.12380730,922.71212724,-0.06508348,-0.05872382,0.00000000,0.00000000,0.00000000,0.00000000
174.00000000,2.81891700,11.97190000,0.09611533,801.91524145,0.09177241,878.99159219,0.00093889,0.12541797,924.14479893,-0.06595532,-0.05946265,0.00000000,0.00000000,0.00000000,0.00000000
175.50000000,2.86110100,11.98700000,0.09762144,802.92668659,0.09314552,881.30954952,0.00095826,0.12715522,926.12713103,-0.06690104,-0.06025418,0.00000000,0.00000000,0.00000000,0.00000000
177.00000000,2.90385900,11.99660000,0.09913122,803.56972457,0.09452007,883.22857351,0.00099801,0.12885835,927.71279090,-0.06779216,-0.06106619,0.00000000,0.00000000,0.00000000,0.00000000
178.50000000,2.94665100,12.00540000,0.10063344,804.15917604,0.09588587,885.08448381,0.00092150,0.13062311,929.54353218,-0.06871346,-0.06190964,0.00000000,0.00000000,0.00000000,0.00000000
180.00000000,2.98951100,12.01410000,0.10216956,804.74192921,0.09728056,886.96205445,0.00085889,0.13241811,931.22100448,-0.06967723,-0.06274088,0.00000000,0.00000000,0.00000000,0.00000000
181.50000000,3.03301300,12.02290000,0.10374311,805.33138068,0.09870723,888.87896359,0.00092575,0.13420385,934.18355128,-0.07061533,-0.06358852,0.00000000,0.00000000,0.00000000,0.00000000
183.00000000,3.07664900,12.03250000,0.10527922,805.97441866,0.10009799,890.82677859,0.00097214,0.00000000,0.00000000,0.00000000,0.00000000,0.00000000,0.00000000,0.00000000,0.00000000
184.50000000,3.12052300,12.03570000,0.10687167,806.18876465,0.10153772,892.34750158,0.00097074,0.00000000,0.00000000,0.00000000,0.00000000,0.00000000,0.00000000,0.00000000,0.00000000
186.00000000,3.16395700,12.04440000,0.10847156,806.77151781,0.10298209,894.28327933,0.00098960,0.00000000,0.00000000,0.00000000,0.00000000,0.00000000,0.00000000,0.00000000,0.00000000
187.50000000,3.20823600,12.05400000,0.11001889,807.41455579,0.10437703,896.24540809,0.00094756,0.00000000,0.00000000,0.00000000,0.00000000,0.00000000,0.00000000,0.00000000,0.00000000
189.00000000,3.25244800,12.05720000,0.11164133,807.62890178,0.10583760,897.79366921,0.00100717,0.00000000,0.00000000,0.00000000,0.00000000,0.00000000,0.00000000,0.00000000,0.00000000
190.50000000,3.29676100,12.07000000,0.11326000,808.48628574,0.10729265,900.05544247,0.00095159,0.00000000,0.00000000,0.00000000,0.00000000,0.00000000,0.00000000,0.00000000,0.00000000
192.00000000,3.34181800,12.07150000,0.11496511,808.58676043,0.10882311,901.54602718,0.00105143,0.00000000,0.00000000,0.00000000,0.00000000,0.00000000,0.00000000,0.00000000,0.00000000
193.50000000,3.38694200,12.07470000,0.11655744,808.80110642,0.11025024,903.07289645,0.00095555,0.00000000,0.00000000,0.00000000,0.00000000,0.00000000,0.00000000,0.00000000,0.00000000
195.00000000,3.43209900,12.08030000,0.11825500,809.17621190,0.11176943,904.86534484,0.00097418,0.00000000,0.00000000,0.00000000,0.00000000,0.00000000,0.00000000,0.00000000,0.00000000
196.50000000,3.47796700,12.08510000,0.11996756,809.49773089,0.11329972,906.61119489,0.00101954,0.00000000,0.00000000,0.00000000,0.00000000,0.00000000,0.00000000,0.00000000,0.00000000
198.00000000,3.52336200,12.09070000,0.12166889,809.87283637,0.11481766,908.40916452,0.00104495,0.00000000,0.00000000,0.00000000,0.00000000,0.00000000,0.00000000,0.00000000,0.00000000
199.50000000,3.56912800,12.09310000,0.12337400,810.03359587,0.11633666,909.97068072,0.00102337,0.00000000,0.00000000,0.00000000,0.00000000,0.00000000,0.00000000,0.00000000,0.00000000
201.00000000,3.61574000,12.09790000,0.12513911,810.35511485,0.11790668,911.76223361,0.00106840,0.00000000,0.00000000,0.00000000,0.00000000,0.00000000,0.00000000,0.00000000,0.00000000
202.50000000,3.66255400,12.10190000,0.12690433,810.62304734,0.11947435,913.49462475,0.00106692,0.00000000,0.00000000,0.00000000,0.00000000,0.00000000,0.00000000,0.00000000,0.00000000
204.00000000,3.70980800,12.10580000,0.12870700,810.88428152,0.12107273,915.25076474,0.00106502,0.00000000,0.00000000,0.00000000,0.00000000,0.00000000,0.00000000,0.00000000,0.00000000
205.50000000,3.75740000,12.11140000,0.13047211,811.25938700,0.12263534,917.10611189,0.00099688,0.00000000,0.00000000,0.00000000,0.00000000,0.00000000,0.00000000,0.00000000,0.00000000
207.00000000,3.80455200,12.11380000,0.13238756,811.42014650,0.12432828,918.84207622,0.00112793,0.00000000,0.00000000,0.00000000,0.00000000,0.00000000,0.00000000,0.00000000,0.00000000
208.50000000,3.85275200,12.11380000,0.13422778,811.42014650,0.12595205,920.33526961,0.00112610,0.00000000,0.00000000,0.00000000,0.00000000,0.00000000,0.00000000,0.00000000,0.00000000
210.00000000,3.90051300,12.11700000,0.13606811,811.63449249,0.12757328,922.07206480,0.00105812,0.00000000,0.00000000,0.00000000,0.00000000,0.00000000,0.00000000,0.00000000,0.00000000
211.50000000,3.94911900,12.12100000,0.13802100,811.90242498,0.12929079,923.96200958,0.00105630,0.00000000,0.00000000,0.00000000,0.00000000,0.00000000,0.00000000,0.00000000,0.00000000
213.00000000,3.99802800,12.12180000,0.13997400,811.95601148,0.13100546,925.60874223,0.00118654,0.00000000,0.00000000,0.00000000,0.00000000,0.00000000,0.00000000,0.00000000,0.00000000
214.50000000,4.04707300,12.12420000,0.14192689,812.11677097,0.13271709,927.37797769,0.00118431,0.00000000,0.00000000,0.00000000,0.00000000,0.00000000,0.00000000,0.00000000,0.00000000
216.00000000,4.09672700,12.12420000,0.14391733,812.11677097,0.13445863,928.99445100,0.00111655,0.00000000,0.00000000,0.00000000,0.00000000,0.00000000,0.00000000,0.00000000,0.00000000
217.50000000,4.14590700,12.12660000,0.14598300,812.27753046,0.13626278,930.85624119,0.00118012,0.00000000,0.00000000,0.00000000,0.00000000,0.00000000,0.00000000,0.00000000,0.00000000
219.00000000,4.19539200,12.12580000,0.14804856,812.22394397,0.13806359,932.47252566,0.00124346,0.00000000,0.00000000,0.00000000,0.00000000,0.00000000,0.00000000,0.00000000,0.00000000
220.50000000,4.24582300,12.12900000,0.15015178,812.43828996,0.00000000,0.00000000,0.00000000,0.00000000,0.00000000,0.00000000,0.00000000,0.00000000,0.00000000,0.00000000,0.00000000
222.00000000,4.29635500,12.12740000,0.15229256,812.33111696,0.00000000,0.00000000,0.00000000,0.00000000,0.00000000,0.00000000,0.00000000,0.00000000,0.00000000,0.00000000,0.00000000
223.50000000,4.34698900,12.12420000,0.15447078,812.11677097,0.00000000,0.00000000,0.00000000,0.00000000,0.00000000,0.00000000,0.00000000,0.00000000,0.00000000,0.00000000,0.00000000
225.00000000,4.39836600,12.12260000,0.15676167,812.00959797,0.00000000,0.00000000,0.00000000,0.00000000,0.00000000,0.00000000,0.00000000,0.00000000,0.00000000,0.00000000,0.00000000
226.50000000,4.44960800,12.12420000,0.15901511,812.11677097,0.00000000,0.00000000,0.00000000,0.00000000,0.00000000,0.00000000,0.00000000,0.00000000,0.00000000,0.00000000,0.00000000
228.00000000,4.50189800,12.12020000,0.16138122,811.84883848,0.00000000,0.00000000,0.00000000,0.00000000,0.00000000,0.00000000,0.00000000,0.00000000,0.00000000,0.00000000,0.00000000
229.50000000,4.55412100,12.12180000,0.16378478,811.95601148,0.00000000,0.00000000,0.00000000,0.00000000,0.00000000,0.00000000,0.00000000,0.00000000,0.00000000,0.00000000,0.00000000
231.00000000,4.60664700,12.11620000,0.16626356,811.58090599,0.00000000,0.00000000,0.00000000,0.00000000,0.00000000,0.00000000,0.00000000,0.00000000,0.00000000,0.00000000,0.00000000
232.50000000,4.65917400,12.11780000,0.16877978,811.68807899,0.00000000,0.00000000,0.00000000,0.00000000,0.00000000,0.00000000,0.00000000,0.00000000,0.00000000,0.00000000,0.00000000
234.00000000,4.71244400,12.11860000,0.17137122,811.74166549,0.00000000,0.00000000,0.00000000,0.00000000,0.00000000,0.00000000,0.00000000,0.00000000,0.00000000,0.00000000,0.00000000
235.50000000,4.76655900,12.11380000,0.17411289,811.42014650,0.00000000,0.00000000,0.00000000,0.00000000,0.00000000,0.00000000,0.00000000,0.00000000,0.00000000,0.00000000,0.00000000
237.00000000,4.82023500,12.10580000,0.17689200,810.88428152,0.00000000,0.00000000,0.00000000,0.00000000,0.00000000,0.00000000,0.00000000,0.00000000,0.00000000,0.00000000,0.00000000
238.50000000,4.87445200,12.10420000,0.17974633,810.77710852,0.00000000,0.00000000,0.00000000,0.00000000,0.00000000,0.00000000,0.00000000,0.00000000,0.00000000,0.00000000,0.00000000
240.00000000,4.92958100,12.09630000,0.18271333,810.24794186,0.00000000,0.00000000,0.00000000,0.00000000,0.00000000,0.00000000,0.00000000,0.00000000,0.00000000,0.00000000,0.00000000
241.50000000,4.98471000,12.09390000,0.18575533,810.08718237,0.00000000,0.00000000,0.00000000,0.00000000,0.00000000,0.00000000,0.00000000,0.00000000,0.00000000,0.00000000,0.00000000
243.00000000,5.04024500,12.08350000,0.18902278,809.39055789,0.00000000,0.00000000,0.00000000,0.00000000,0.00000000,0.00000000,0.00000000,0.00000000,0.00000000,0.00000000,0.00000000
244.50000000,5.09655700,12.08510000,0.19232778,809.49773089,0.00000000,0.00000000,0.00000000,0.00000000,0.00000000,0.00000000,0.00000000,0.00000000,0.00000000,0.00000000,0.00000000
246.00000000,5.15290300,12.07710000,0.19582056,808.96186591,0.00000000,0.00000000,0.00000000,0.00000000,0.00000000,0.00000000,0.00000000,0.00000000,0.00000000,0.00000000,0.00000000
247.50000000,5.21046600,12.06920000,0.19942589,808.43269925,0.00000000,0.00000000,0.00000000,0.00000000,0.00000000,0.00000000,0.00000000,0.00000000,0.00000000,0.00000000,0.00000000
249.00000000,5.26792800,12.05800000,0.20329422,807.68248828,0.00000000,0.00000000,0.00000000,0.00000000,0.00000000,0.00000000,0.00000000,0.00000000,0.00000000,0.00000000,0.00000000
250.50000000,5.32549000,12.04360000,0.20723767,806.71793132,0.00000000,0.00000000,0.00000000,0.00000000,0.00000000,0.00000000,0.00000000,0.00000000,0.00000000,0.00000000,0.00000000
252.00000000,5.38362800,12.03570000,0.21136889,806.18876465,0.00000000,0.00000000,0.00000000,0.00000000,0.00000000,0.00000000,0.00000000,0.00000000,0.00000000,0.00000000,0.00000000
253.50000000,5.44244200,12.02450000,0.21572544,805.43855368,0.00000000,0.00000000,0.00000000,0.00000000,0.00000000,0.00000000,0.00000000,0.00000000,0.00000000,0.00000000,0.00000000
255.00000000,5.50186400,12.00850000,0.22034500,804.36682372,0.00000000,0.00000000,0.00000000,0.00000000,0.00000000,0.00000000,0.00000000,0.00000000,0.00000000,0.00000000,0.00000000
256.50000000,5.56155600,11.99100000,0.22511467,803.19461908,0.00000000,0.00000000,0.00000000,0.00000000,0.00000000,0.00000000,0.00000000,0.00000000,0.00000000,0.00000000,0.00000000
258.00000000,5.62162000,11.97030000,0.23014722,801.80806845,0.00000000,0.00000000,0.00000000,0.00000000,0.00000000,0.00000000,0.00000000,0.00000000,0.00000000,0.00000000,0.00000000
259.50000000,5.68178500,11.94950000,0.23544278,800.41481951,0.00000000,0.00000000,0.00000000,0.00000000,0.00000000,0.00000000,0.00000000,0.00000000,0.00000000,0.00000000,0.00000000
261.00000000,5.74269500,11.92720000,0.24085100,798.92109588,0.00000000,0.00000000,0.00000000,0.00000000,0.00000000,0.00000000,0.00000000,0.00000000,0.00000000,0.00000000,0.00000000
262.50000000,5.80340100,11.90330000,0.24652211,797.32019926,0.00000000,0.00000000,0.00000000,0.00000000,0.00000000,0.00000000,0.00000000,0.00000000,0.00000000,0.00000000,0.00000000
264.00000000,5.86447800,11.87140000,0.25234356,795.18343766,0.00000000,0.00000000,0.00000000,0.00000000,0.00000000,0.00000000,0.00000000,0.00000000,0.00000000,0.00000000,0.00000000
265.50000000,5.92684100,11.84030000,0.25842789,793.10026256,0.00000000,0.00000000,0.00000000,0.00000000,0.00000000,0.00000000,0.00000000,0.00000000,0.00000000,0.00000000,0.00000000
267.00000000,5.98923600,11.80040000,0.26473778,790.42763598,0.00000000,0.00000000,0.00000000,0.00000000,0.00000000,0.00000000,0.00000000,0.00000000,0.00000000,0.00000000,0.00000000
268.50000000,6.05142900,11.76210000,0.27116044,787.86218240,0.00000000,0.00000000,0.00000000,0.00000000,0.00000000,0.00000000,0.00000000,0.00000000,0.00000000,0.00000000,0.00000000
270.00000000,6.11406100,11.71910000,0.27780889,784.98190814,0.00000000,0.00000000,0.00000000,0.00000000,0.00000000,0.00000000,0.00000000,0.00000000,0.00000000,0.00000000,0.00000000
271.50000000,6.17740400,11.66640000,0.28453300,781.45189760,0.00000000,0.00000000,0.00000000,0.00000000,0.00000000,0.00000000,0.00000000,0.00000000,0.00000000,0.00000000,0.00000000
273.00000000,6.24054300,11.60500000,0.29144611,777.33913389,0.00000000,0.00000000,0.00000000,0.00000000,0.00000000,0.00000000,0.00000000,0.00000000,0.00000000,0.00000000,0.00000000
274.50000000,6.30493600,11.53640000,0.29847378,772.74409170,0.00000000,0.00000000,0.00000000,0.00000000,0.00000000,0.00000000,0.00000000,0.00000000,0.00000000,0.00000000,0.00000000
276.00000000,6.36919700,11.46070000,0.30565489,767.67346935,0.00000000,0.00000000,0.00000000,0.00000000,0.00000000,0.00000000,0.00000000,0.00000000,0.00000000,0.00000000,0.00000000
277.50000000,6.43566400,11.37140000,0.31310533,761.69187653,0.00000000,0.00000000,0.00000000,0.00000000,0.00000000,0.00000000,0.00000000,0.00000000,0.00000000,0.00000000,0.00000000
279.00000000,6.51125000,11.18240000,0.32169967,749.03206642,0.00000000,0.00000000,0.00000000,0.00000000,0.00000000,0.00000000,0.00000000,0.00000000,0.00000000,0.00000000,0.00000000