File: lab_data/AA6014-T4_results/DATA/UT_00_3.csv
Time[s],Displacement[mm],Force[kN],EngStrain_longi,EngStress[MPa],TrueStrain,TrueStress[MPa],TrueStrainRate[1/s],PlasticStrain_longi,PlasticStress[MPa],PlasticStrain_thick,PlasticStrain_width,R-Value,Thickness[mm],Width[mm], Young's Modulus [MPa]
0.59000000,0.00000000,-0.00100000,0.00000000,-0.08979734,0.00000000,-0.08979734,0.00000000,0.00068837,119.35374226,-0.00001169,-0.00067668,0.77657661,1.11660000,9.97330000,101778.99731992
2.09000000,0.00548600,0.17300000,0.00016300,15.53494059,0.00016299,15.53747278,0.00011287,0.00178702,124.44988638,-0.00064163,-0.00114539,0.00000000,0.00000000,0.00000000,0.00000000
3.59000000,0.01224300,0.40400000,0.00036356,36.27812715,0.00036349,36.29131627,0.00009974,0.00300216,127.94584008,-0.00135611,-0.00164605,0.00000000,0.00000000,0.00000000,0.00000000
5.09000000,0.02090900,0.64100000,0.00064833,57.56009778,0.00064812,57.59741591,0.00023653,0.00419732,130.90477044,-0.00201174,-0.00218558,0.00000000,0.00000000,0.00000000,0.00000000
6.59000000,0.02936500,0.90400000,0.00096311,81.17679937,0.00096265,81.25498165,0.00038456,0.00535622,133.95660001,-0.00261841,-0.00273780,0.00000000,0.00000000,0.00000000,0.00000000
8.09000000,0.03998200,1.13600000,0.00124967,102.00978328,0.00124889,102.13726151,0.00033938,0.00657042,136.56949525,-0.00328060,-0.00328982,0.00000000,0.00000000,0.00000000,0.00000000
9.59000000,0.06199700,1.29900000,0.00190500,116.64675042,0.00190319,116.86896248,0.00040571,0.00781035,139.01060829,-0.00396784,-0.00384251,0.00000000,0.00000000,0.00000000,0.00000000
11.09000000,0.09611200,1.36800000,0.00306500,122.84276719,0.00306031,123.21928027,0.00057344,0.00893799,141.62375247,-0.00459185,-0.00434614,0.00000000,0.00000000,0.00000000,0.00000000
12.59000000,0.13338200,1.40700000,0.00432822,126.34486362,0.00431888,126.89171227,0.00081929,0.01005028,143.96737121,-0.00517341,-0.00487687,0.00000000,0.00000000,0.00000000,0.00000000
14.09000000,0.17065300,1.44000000,0.00555344,129.30817599,0.00553808,130.02628176,0.00079685,0.01123010,146.23490001,-0.00587170,-0.00535840,0.00000000,0.00000000,0.00000000,0.00000000
15.59000000,0.20860500,1.47200000,0.00681978,132.18169101,0.00679663,133.08314077,0.00077752,0.01238502,148.59531976,-0.00654976,-0.00583526,0.00000000,0.00000000,0.00000000,0.00000000
17.09000000,0.24572300,1.49900000,0.00812689,134.60621931,0.00809404,135.70014910,0.00083274,0.01350075,150.77241646,-0.00719559,-0.00630516,0.00000000,0.00000000,0.00000000,0.00000000
18.59000000,0.28299400,1.52600000,0.00933911,137.03074761,0.00929577,138.31049299,0.00093835,0.01461998,152.86334664,-0.00783926,-0.00678072,0.00000000,0.00000000,0.00000000,0.00000000
20.09000000,0.32039600,1.55200000,0.01058233,139.36547857,0.01052673,140.84029052,0.00085932,0.01577314,155.05578660,-0.00852303,-0.00725011,0.00000000,0.00000000,0.00000000,0.00000000
21.59000000,0.35572100,1.57600000,0.01180056,141.52061483,0.01173147,143.19063671,0.00081038,0.01692264,157.16090594,-0.00920183,-0.00772081,0.00000000,0.00000000,0.00000000,0.00000000
23.09000000,0.39242100,1.60000000,0.01304644,143.67575110,0.01296207,145.55020880,0.00095006,0.01800614,159.16841303,-0.00980005,-0.00820610,0.00000000,0.00000000,0.00000000,0.00000000
24.59000000,0.42748400,1.62400000,0.01418789,145.83088737,0.01408818,147.89991979,0.00089769,0.01910898,161.27527200,-0.01042499,-0.00868399,0.00000000,0.00000000,0.00000000,0.00000000
26.09000000,0.46335800,1.64600000,0.01535533,147.80642894,0.01523863,150.07604593,0.00080842,0.02026541,163.11931291,-0.01111217,-0.00915324,0.00000000,0.00000000,0.00000000,0.00000000
27.59000000,0.49872300,1.66800000,0.01656756,149.78197052,0.01643181,152.26349164,0.00080745,0.02134624,165.04716293,-0.01167866,-0.00966758,0.00000000,0.00000000,0.00000000,0.00000000
29.09000000,0.53385900,1.69000000,0.01776111,151.75751210,0.01760523,154.45289413,0.00082813,0.02241735,167.06973701,-0.01225840,-0.01015894,0.00000000,0.00000000,0.00000000,0.00000000
30.59000000,0.56946500,1.71100000,0.01892122,153.64325633,0.01874444,156.55037453,0.00082043,0.02353451,168.82725381,-0.01289328,-0.01064123,0.00000000,0.00000000,0.00000000,0.00000000
32.09000000,0.60568000,1.73100000,0.02011867,155.43920322,0.01991896,158.56643274,0.00074602,0.02465991,170.68247056,-0.01351199,-0.01114792,0.00000000,0.00000000,0.00000000,0.00000000
33.59000000,0.63967100,1.75200000,0.02124878,157.32494745,0.02102617,160.66791030,0.00065007,0.02573555,172.62572764,-0.01410987,-0.01162568,0.00000000,0.00000000,0.00000000,0.00000000
35.09000000,0.67400500,1.77100000,0.02240889,159.03109700,0.02216150,162.59480718,0.00078088,0.02681618,174.38856481,-0.01474972,-0.01206646,0.00000000,0.00000000,0.00000000,0.00000000
36.59000000,0.70901700,1.79000000,0.02355411,160.73724654,0.02328099,164.52326951,0.00075829,0.02789340,176.06170120,-0.01532417,-0.01256923,0.00000000,0.00000000,0.00000000,0.00000000
38.09000000,0.74364000,1.80900000,0.02470678,162.44339609,0.02440650,166.45684898,0.00066979,0.02898589,177.83394329,-0.01593628,-0.01304961,0.00000000,0.00000000,0.00000000,0.00000000
39.59000000,0.77828600,1.82700000,0.02589667,164.05974829,0.02556703,168.30834890,0.00079274,0.03008912,179.51886130,-0.01661563,-0.01347349,0.00000000,0.00000000,0.00000000,0.00000000
41.09000000,0.81313300,1.84500000,0.02703056,165.67610049,0.02667168,170.15441752,0.00077736,0.03118395,181.20583837,-0.01719812,-0.01398584,0.00000000,0.00000000,0.00000000,0.00000000
42.59000000,0.84761200,1.86300000,0.02817200,167.29245269,0.02778247,172.00541566,0.00074018,0.03228477,182.89747272,-0.01785031,-0.01443446,0.00000000,0.00000000,0.00000000,0.00000000
44.09000000,0.88212400,1.88000000,0.02933578,168.81900754,0.02891372,173.77144443,0.00071774,0.03337611,184.40428028,-0.01845606,-0.01492005,0.00000000,0.00000000,0.00000000,0.00000000
45.59000000,0.91643400,1.89700000,0.03048100,170.34556240,0.03002568,175.53786548,0.00073873,0.03446475,186.00715607,-0.01907151,-0.01539324,0.00000000,0.00000000,0.00000000,0.00000000
47.09000000,0.95077800,1.91400000,0.03161867,171.87211725,0.03112909,177.30648444,0.00067263,0.03555221,187.61315682,-0.01970218,-0.01585003,0.00000000,0.00000000,0.00000000,0.00000000
48.59000000,0.98525600,1.93000000,0.03279733,173.30887476,0.03227098,178.99294370,0.00075128,0.03660030,189.12139017,-0.02026499,-0.01633530,0.00000000,0.00000000,0.00000000,0.00000000
50.09000000,1.01986900,1.94600000,0.03394244,174.74563227,0.03337911,180.67692619,0.00074336,0.03767573,190.63787054,-0.02087214,-0.01680359,0.00000000,0.00000000,0.00000000,0.00000000
51.59000000,1.05495100,1.96100000,0.03510244,176.09259244,0.03450040,182.27387288,0.00080738,0.03880940,192.26254128,-0.02153328,-0.01727613,0.00000000,0.00000000,0.00000000,0.00000000
53.09000000,1.08882600,1.97700000,0.03623644,177.52934995,0.03559535,183.96238238,0.00074879,0.03989443,193.69334054,-0.02216988,-0.01772455,0.00000000,0.00000000,0.00000000,0.00000000
54.59000000,1.12350500,1.99200000,0.03738911,178.87631012,0.03670709,185.56433635,0.00076982,0.04096738,195.12471415,-0.02270518,-0.01826220,0.00000000,0.00000000,0.00000000,0.00000000
56.09000000,1.15761400,2.00700000,0.03851556,180.22327029,0.03779234,187.16466966,0.00072553,0.04204270,196.55946249,-0.02335794,-0.01868477,0.00000000,0.00000000,0.00000000,0.00000000
57.59000000,1.19232800,2.02100000,0.03967578,181.48043311,0.03890891,188.68081044,0.00072514,0.04312399,197.99831321,-0.02391853,-0.01920545,0.00000000,0.00000000,0.00000000,0.00000000
59.09000000,1.22647000,2.03500000,0.04082078,182.73759593,0.04000961,190.19708672,0.00074549,0.04424076,199.35281461,-0.02457611,-0.01966465,0.00000000,0.00000000,0.00000000,0.00000000
60.59000000,1.26118400,2.04900000,0.04196233,183.99475875,0.04110579,191.71560815,0.00070200,0.04531243,200.79556306,-0.02514838,-0.02016405,0.00000000,0.00000000,0.00000000,0.00000000
62.09000000,1.29606500,2.06300000,0.04314844,185.25192157,0.04224349,193.24525382,0.00072955,0.04638051,202.14590810,-0.02577064,-0.02060987,0.00000000,0.00000000,0.00000000,0.00000000
63.59000000,1.33054300,2.07600000,0.04429733,186.41928705,0.04334425,194.67716435,0.00075748,0.04746651,203.40791398,-0.02637807,-0.02108844,0.00000000,0.00000000,0.00000000,0.00000000
65.09000000,1.36488700,2.09000000,0.04544611,187.67644987,0.04444369,196.20561467,0.00070668,0.04856628,204.86491771,-0.02699038,-0.02157590,0.00000000,0.00000000,0.00000000,0.00000000
66.59000000,1.39892900,2.10300000,0.04660244,188.84381535,0.04554915,197.64439876,0.00076282,0.04963567,206.12882213,-0.02760347,-0.02203220,0.00000000,0.00000000,0.00000000,0.00000000
68.09000000,1.43421300,2.11500000,0.04775511,189.92138348,0.04664989,198.99110026,0.00078342,0.05073914,207.40232746,-0.02823215,-0.02250698,0.00000000,0.00000000,0.00000000,0.00000000
69.59000000,1.46896000,2.12800000,0.04893011,191.08874896,0.04777070,200.43874268,0.00081814,0.05181299,208.67224235,-0.02877373,-0.02303926,0.00000000,0.00000000,0.00000000,0.00000000
71.09000000,1.50377500,2.13900000,0.05009022,192.07651975,0.04887609,201.69767531,0.00080306,0.05291169,209.85468351,-0.02942212,-0.02348957,0.00000000,0.00000000,0.00000000,0.00000000
72.59000000,1.53832000,2.15100000,0.05124278,193.15408788,0.04997306,203.05183989,0.00077363,0.05399721,211.13206625,-0.03002771,-0.02396949,0.00000000,0.00000000,0.00000000,0.00000000
74.09000000,1.57323500,2.16300000,0.05241789,194.23165602,0.05109027,204.41286938,0.00073749,0.05508503,212.41251271,-0.03061157,-0.02447345,0.00000000,0.00000000,0.00000000,0.00000000
75.59000000,1.60845200,2.17400000,0.05356678,195.21942681,0.05218134,205.67670246,0.00073647,0.05619757,213.60528032,-0.03126556,-0.02493202,0.00000000,0.00000000,0.00000000,0.00000000
77.09000000,1.64356900,2.18500000,0.05476422,196.20719760,0.05331726,206.95233217,0.00077125,0.05729254,214.70102109,-0.03189354,-0.02539900,0.00000000,0.00000000,0.00000000,0.00000000
78.59000000,1.67787900,2.19600000,0.05591322,197.19496838,0.05440601,208.22077447,0.00076326,0.05839407,215.99191891,-0.03251542,-0.02587866,0.00000000,0.00000000,0.00000000,0.00000000
80.09000000,1.71279400,2.20700000,0.05705078,198.18273917,0.05548275,209.48921858,0.00071280,0.05947256,217.08865480,-0.03312065,-0.02635192,0.00000000,0.00000000,0.00000000,0.00000000
81.59000000,1.74861500,2.21800000,0.05825944,199.17050996,0.05662552,210.77407322,0.00074728,0.06056376,218.19032026,-0.03371542,-0.02684834,0.00000000,0.00000000,0.00000000,0.00000000
83.09000000,1.78359800,2.22900000,0.05941956,200.15828075,0.05772117,212.05159683,0.00075359,0.06168382,219.39661748,-0.03433997,-0.02734385,0.00000000,0.00000000,0.00000000,0.00000000
84.59000000,1.81884900,2.23800000,0.06059100,200.96645685,0.05882630,213.14321544,0.00069659,0.06277030,220.40553484,-0.03497655,-0.02779375,0.00000000,0.00000000,0.00000000,0.00000000
86.09000000,1.85457000,2.24800000,0.06177733,201.86443029,0.05994423,214.33507649,0.00075234,0.06388207,221.51834966,-0.03560231,-0.02827976,0.00000000,0.00000000,0.00000000,0.00000000
87.59000000,1.89025700,2.25900000,0.06295978,202.85220108,0.06105726,215.62373059,0.00075108,0.06495425,222.62456210,-0.03617253,-0.02878172,0.00000000,0.00000000,0.00000000,0.00000000
89.09000000,1.92534000,2.26800000,0.06414600,203.66037718,0.06217260,216.72437574,0.00075046,0.06609263,223.65124343,-0.03681026,-0.02928237,0.00000000,0.00000000,0.00000000,0.00000000
90.59000000,1.96082600,2.27700000,0.06530622,204.46855328,0.06326229,217.82162206,0.00067264,0.06720188,224.67343989,-0.03746798,-0.02973390,0.00000000,0.00000000,0.00000000,0.00000000
92.09000000,1.99651300,2.28700000,0.06648500,205.36652673,0.06436819,219.02032026,0.00067189,0.06829457,225.79066611,-0.03809195,-0.03020263,0.00000000,0.00000000,0.00000000,0.00000000
93.59000000,2.03267100,2.29600000,0.06769733,206.17470283,0.06550430,220.13218041,0.00073380,0.06943724,226.72773505,-0.03875588,-0.03068136,0.00000000,0.00000000,0.00000000,0.00000000
95.09000000,2.06845900,2.30400000,0.06887989,206.89308158,0.06661127,221.14385405,0.00071905,0.07053213,227.75274325,-0.03936716,-0.03116497,0.00000000,0.00000000,0.00000000,0.00000000
96.59000000,2.10411200,2.31300000,0.07008844,207.70125768,0.06774130,222.25871574,0.00073216,0.07163837,228.87945187,-0.03996570,-0.03167268,0.00000000,0.00000000,0.00000000,0.00000000
98.09000000,2.14020200,2.32200000,0.07128967,208.50943378,0.06886322,223.37400181,0.00076641,0.07275294,229.81592715,-0.04058818,-0.03216477,0.00000000,0.00000000,0.00000000,0.00000000
99.59000000,2.17609000,2.33000000,0.07249456,209.22781254,0.06998730,224.39568982,0.00076534,0.07386273,230.75312425,-0.04121678,-0.03264595,0.00000000,0.00000000,0.00000000,0.00000000
101.09000000,2.21228200,2.33900000,0.07369567,210.03598864,0.07110659,225.51473085,0.00070920,0.07497326,231.78973609,-0.04185359,-0.03311967,0.00000000,0.00000000,0.00000000,0.00000000
102.59000000,2.24853900,2.34600000,0.07489667,210.66457005,0.07222453,226.44264413,0.00076342,0.07608734,232.73169292,-0.04246764,-0.03361970,0.00000000,0.00000000,0.00000000,0.00000000
104.09000000,2.28493100,2.35400000,0.07610522,211.38294881,0.07334825,227.47029510,0.00076257,0.07721382,233.67839331,-0.04311410,-0.03409971,0.00000000,0.00000000,0.00000000,0.00000000
105.59000000,2.32142400,2.36200000,0.07731767,212.10132756,0.07447431,228.50050730,0.00069279,0.07833561,234.62585302,-0.04373055,-0.03460506,0.00000000,0.00000000,0.00000000,0.00000000
107.09000000,2.35751400,2.36900000,0.07855233,212.72990897,0.07561971,229.44033969,0.00076784,0.07945263,235.57404105,-0.04434588,-0.03510674,0.00000000,0.00000000,0.00000000,0.00000000
108.59000000,2.39457800,2.37700000,0.07976844,213.44828773,0.07674661,230.47472561,0.00074618,0.08055608,236.42287868,-0.04497310,-0.03558298,0.00000000,0.00000000,0.00000000,0.00000000
110.09000000,2.43076900,2.38400000,0.08094344,214.07686914,0.07783422,231.40498830,0.00066949,0.08168751,237.37807841,-0.04560860,-0.03607891,0.00000000,0.00000000,0.00000000,0.00000000
111.59000000,2.46722700,2.39200000,0.08221167,214.79524789,0.07900679,232.45392322,0.00079277,0.08281218,238.23533840,-0.04622499,-0.03658719,0.00000000,0.00000000,0.00000000,0.00000000
113.09000000,2.50408900,2.39900000,0.08341656,215.42382930,0.08011953,233.39374313,0.00077158,0.08393229,239.09315373,-0.04687950,-0.03705279,0.00000000,0.00000000,0.00000000,0.00000000
114.59000000,2.54115300,2.40600000,0.08465122,216.05241072,0.08125848,234.34151135,0.00076352,0.08505110,239.95229962,-0.04749276,-0.03755834,0.00000000,0.00000000,0.00000000,0.00000000
116.09000000,2.57825000,2.41200000,0.08586356,216.59119478,0.08237557,235.18848487,0.00073524,0.08619899,240.82011551,-0.04816412,-0.03803487,0.00000000,0.00000000,0.00000000,0.00000000
117.59000000,2.61484300,2.41900000,0.08710567,217.21977619,0.08351881,236.14084961,0.00073440,0.08731518,241.68194047,-0.04876988,-0.03854530,0.00000000,0.00000000,0.00000000,0.00000000
119.09000000,2.65220900,2.42500000,0.08835522,217.75856026,0.08466759,236.99866624,0.00078156,0.08843470,242.44744687,-0.04941700,-0.03901769,0.00000000,0.00000000,0.00000000,0.00000000
120.59000000,2.68917100,2.43200000,0.08957133,218.38714167,0.08578435,237.94836913,0.00073294,0.08954821,243.31179935,-0.05002653,-0.03952168,0.00000000,0.00000000,0.00000000,0.00000000
122.09000000,2.72596600,2.43800000,0.09080222,218.92592574,0.08691341,238.80488630,0.00073884,0.09069225,244.08627936,-0.05068259,-0.04000967,0.00000000,0.00000000,0.00000000,0.00000000
123.59000000,2.76326500,2.44400000,0.09204822,219.46470980,0.08805504,239.66604618,0.00075163,0.09182008,244.95735694,-0.05131220,-0.04050787,0.00000000,0.00000000,0.00000000,0.00000000
125.09000000,2.80083200,2.45000000,0.09330156,220.00349387,0.08920207,240.53016208,0.00075098,0.09293792,245.72842000,-0.05190910,-0.04102882,0.00000000,0.00000000,0.00000000,0.00000000
126.59000000,2.83850000,2.45600000,0.09455478,220.54227794,0.09034768,241.39560402,0.00078383,0.09406783,246.50390278,-0.05257521,-0.04149262,0.00000000,0.00000000,0.00000000,0.00000000
128.09000000,2.87539500,2.46100000,0.09577833,220.99126466,0.09146492,242.15743967,0.00073569,0.09523555,247.38968587,-0.05321980,-0.04201576,0.00000000,0.00000000,0.00000000,0.00000000
129.59000000,2.91329800,2.46700000,0.09703911,221.53004873,0.09261483,243.02712774,0.00080273,0.09638443,248.07337049,-0.05385883,-0.04252560,0.00000000,0.00000000,0.00000000,0.00000000
131.09000000,2.95099900,2.47300000,0.09830356,222.06883279,0.09376677,243.89898863,0.00077427,0.09753064,248.85734346,-0.05454243,-0.04298821,0.00000000,0.00000000,0.00000000,0.00000000
132.59000000,2.98866700,2.47800000,0.09953833,222.51781952,0.09489039,244.66687241,0.00075319,0.09865182,249.63653013,-0.05513349,-0.04351833,0.00000000,0.00000000,0.00000000,0.00000000
134.09000000,3.02643500,2.48400000,0.10078033,223.05660358,0.09601932,245.53632244,0.00074547,0.09978997,250.32151194,-0.05576498,-0.04402499,0.00000000,0.00000000,0.00000000,0.00000000
135.59000000,3.06413600,2.48800000,0.10206344,223.41579296,0.09718428,246.21837833,0.00077163,0.10092888,251.10797242,-0.05641419,-0.04451470,0.00000000,0.00000000,0.00000000,0.00000000
137.09000000,3.10257600,2.49400000,0.10331311,223.95457703,0.09831757,247.09202113,0.00073711,0.10204744,251.79061796,-0.05700019,-0.04504725,0.00000000,0.00000000,0.00000000,0.00000000
138.59000000,3.14115000,2.49800000,0.10460011,224.31376640,0.09948338,247.77701129,0.00072277,0.10325178,252.49622516,-0.05774876,-0.04550303,0.00000000,0.00000000,0.00000000,0.00000000
140.09000000,3.18009400,2.50300000,0.10590944,224.76275313,0.10066802,248.56725144,0.00079608,0.10438326,253.28505790,-0.05835766,-0.04602560,0.00000000,0.00000000,0.00000000,0.00000000
141.59000000,3.21786200,2.50800000,0.10714044,225.21173985,0.10178052,249.34102575,0.00077512,0.10554471,253.98250130,-0.05900026,-0.04654445,0.00000000,0.00000000,0.00000000,0.00000000
143.09000000,3.25603400,2.51300000,0.10843111,225.66072657,0.10294560,250.12936989,0.00078104,0.10668822,254.67665034,-0.05963035,-0.04705787,0.00000000,0.00000000,0.00000000,0.00000000
144.59000000,3.29444000,2.51700000,0.10969567,226.01991595,0.10408580,250.81332131,0.00075310,0.10781355,255.36740887,-0.06027079,-0.04754276,0.00000000,0.00000000,0.00000000,0.00000000
146.09000000,3.33321600,2.52200000,0.11095267,226.46890267,0.10521791,251.59623134,0.00069842,0.10899753,256.07448449,-0.06091404,-0.04808349,0.00000000,0.00000000,0.00000000,0.00000000
147.59000000,3.37219300,2.52600000,0.11227689,226.82809205,0.10640917,252.29564454,0.00079852,0.11015156,256.67418724,-0.06158014,-0.04857141,0.00000000,0.00000000,0.00000000,0.00000000
149.09000000,3.41110300,2.53000000,0.11356378,227.18728143,0.10756548,252.98752737,0.00079081,0.11134592,257.38646555,-0.06225194,-0.04909399,0.00000000,0.00000000,0.00000000,0.00000000
150.59000000,3.45041600,2.53500000,0.11486189,227.63626815,0.10873053,253.78299989,0.00074941,0.11250581,258.09116057,-0.06291875,-0.04958706,0.00000000,0.00000000,0.00000000,0.00000000
152.09000000,3.48882200,2.53900000,0.11615622,227.99545753,0.10989084,254.47854856,0.00078200,0.11368543,258.70093719,-0.06355186,-0.05013357,0.00000000,0.00000000,0.00000000,0.00000000
153.59000000,3.52790000,2.54200000,0.11743933,228.26484956,0.11103976,255.07212131,0.00076101,0.11482258,259.40221164,-0.06419422,-0.05062835,0.00000000,0.00000000,0.00000000,0.00000000
155.09000000,3.56724600,2.54700000,0.11874867,228.71383628,0.11221080,255.87329939,0.00075356,0.11602268,260.01960984,-0.06487772,-0.05114496,0.00000000,0.00000000,0.00000000,0.00000000
156.59000000,3.60676000,2.55000000,0.12009156,228.98322831,0.11341043,256.48218040,0.00081935,0.11718826,260.62909356,-0.06554887,-0.05163939,0.00000000,0.00000000,0.00000000,0.00000000
158.09000000,3.64681200,2.55400000,0.12140089,229.34241769,0.11457870,257.18479106,0.00083187,0.11834769,261.33986904,-0.06618245,-0.05216524,0.00000000,0.00000000,0.00000000,0.00000000
159.59000000,3.68689600,2.55800000,0.12272878,229.70160707,0.11576213,257.89260456,0.00081089,0.11949728,261.94742378,-0.06685352,-0.05264377,0.00000000,0.00000000,0.00000000,0.00000000
161.09000000,3.72671200,2.56100000,0.12402322,229.97099910,0.11691441,258.49274343,0.00075022,0.12068170,262.56521580,-0.06751557,-0.05316612,0.00000000,0.00000000,0.00000000,0.00000000
162.59000000,3.76636100,2.56500000,0.12535111,230.33018848,0.11809509,259.20233353,0.00075586,0.12186478,263.18376115,-0.06815525,-0.05370953,0.00000000,0.00000000,0.00000000,0.00000000
164.09000000,3.80658100,2.56800000,0.12666044,230.59958051,0.11925790,259.80742587,0.00076149,0.12303980,263.80127822,-0.06882919,-0.05421060,0.00000000,0.00000000,0.00000000,0.00000000
165.59000000,3.84696800,2.57100000,0.12800333,230.86897255,0.12044911,260.42097060,0.00074088,0.12422127,264.31917130,-0.06948878,-0.05473249,0.00000000,0.00000000,0.00000000,0.00000000
167.09000000,3.88671700,2.57400000,0.12930889,231.13836458,0.12160584,261.02660968,0.00074002,0.12541954,264.94495040,-0.07017292,-0.05524662,0.00000000,0.00000000,0.00000000,0.00000000
168.59000000,3.92733900,2.57800000,0.13067778,231.49755396,0.12281726,261.74913987,0.00078533,0.12661654,265.57152088,-0.07083964,-0.05577690,0.00000000,0.00000000,0.00000000,0.00000000
170.09000000,3.96806100,2.58100000,0.13202811,231.76694599,0.12401081,262.36669809,0.00081090,0.12788174,266.11463031,-0.07156789,-0.05631386,0.00000000,0.00000000,0.00000000,0.00000000
171.59000000,4.00905300,2.58300000,0.13337467,231.94654068,0.12519961,262.88233323,0.00085584,0.12907554,266.74252603,-0.07221636,-0.05685918,0.00000000,0.00000000,0.00000000,0.00000000
173.09000000,4.04964200,2.58700000,0.13469900,232.30573006,0.12636742,263.59707959,0.00076942,0.13029218,267.27461347,-0.07290554,-0.05738664,0.00000000,0.00000000,0.00000000,0.00000000
174.59000000,4.09023000,2.59000000,0.13602689,232.57512209,0.12753699,264.21159238,0.00072899,0.13149920,267.90821435,-0.07357326,-0.05792594,0.00000000,0.00000000,0.00000000,0.00000000
176.09000000,4.13075100,2.59200000,0.13739211,232.75471678,0.12873802,264.73337869,0.00079379,0.13270966,268.44057226,-0.07428518,-0.05842448,0.00000000,0.00000000,0.00000000,0.00000000
177.59000000,4.17254900,2.59500000,0.13879100,233.02410881,0.12996717,265.36575790,0.00085860,0.13394620,269.08432768,-0.07498770,-0.05895851,0.00000000,0.00000000,0.00000000,0.00000000
179.09000000,4.21468200,2.59700000,0.14019356,233.20370350,0.13119803,265.89735987,0.00086378,0.13514392,269.61518600,-0.07565199,-0.05949193,0.00000000,0.00000000,0.00000000,0.00000000
180.59000000,4.25577400,2.60000000,0.14157378,233.47309554,0.13240782,266.52676368,0.00076478,0.13633671,270.14560215,-0.07630965,-0.06002707,0.00000000,0.00000000,0.00000000,0.00000000
182.09000000,4.29784000,2.60300000,0.14301356,233.74248757,0.13366824,267.17083180,0.00088791,0.13754123,270.68009120,-0.07700452,-0.06053670,0.00000000,0.00000000,0.00000000,0.00000000
183.59000000,4.34000600,2.60500000,0.14437878,233.92208226,0.13486194,267.69546659,0.00084120,0.13874734,271.21591759,-0.07767390,-0.06107344,0.00000000,0.00000000,0.00000000,0.00000000
185.09000000,4.38240800,2.60700000,0.14578144,234.10167695,0.13608689,268.22935756,0.00078817,0.13989733,271.73734035,-0.07830951,-0.06158782,0.00000000,0.00000000,0.00000000,0.00000000
186.59000000,4.42447400,2.60900000,0.14719156,234.28127164,0.13731683,268.76549645,0.00081317,0.14108456,272.26978967,-0.07898712,-0.06209744,0.00000000,0.00000000,0.00000000,0.00000000
188.09000000,4.46711000,2.61200000,0.14856422,234.55066367,0.13851266,269.39650059,0.00077968,0.14229609,272.80978011,-0.07971912,-0.06257697,0.00000000,0.00000000,0.00000000,0.00000000
189.59000000,4.51011600,2.61400000,0.14998167,234.73025836,0.13974600,269.93549372,0.00079805,0.14351243,273.35200695,-0.08040689,-0.06310554,0.00000000,0.00000000,0.00000000,0.00000000
191.09000000,4.55224800,2.61600000,0.15140289,234.90985305,0.14098110,270.47588343,0.00091388,0.14465517,273.77034457,-0.08104119,-0.06361398,0.00000000,0.00000000,0.00000000,0.00000000
192.59000000,4.59515400,2.61800000,0.15277556,235.08944774,0.14217256,271.00536872,0.00084143,0.14589738,274.32137173,-0.08175716,-0.06414022,0.00000000,0.00000000,0.00000000,0.00000000
194.09000000,4.63805900,2.62000000,0.15412600,235.26904243,0.14334335,271.53011886,0.00081483,0.14712203,274.86850827,-0.08246216,-0.06465987,0.00000000,0.00000000,0.00000000,0.00000000
195.59000000,4.68197100,2.62200000,0.15553233,235.44863711,0.14456113,272.06851302,0.00083962,0.14830528,275.30016958,-0.08312163,-0.06518365,0.00000000,0.00000000,0.00000000,0.00000000
197.09000000,4.72447400,2.62400000,0.15692367,235.62823180,0.14576447,272.60387791,0.00081920,0.14954289,275.85261461,-0.08378999,-0.06575290,0.00000000,0.00000000,0.00000000,0.00000000
198.59000000,4.76714300,2.62600000,0.15824411,235.80782649,0.14690516,273.12302639,0.00081174,0.15086319,276.32372308,-0.08454831,-0.06631488,0.00000000,0.00000000,0.00000000,0.00000000
200.09000000,4.81082100,2.62700000,0.15965800,235.89762384,0.14812513,273.56056666,0.00083663,0.15219625,276.90452367,-0.08530268,-0.06689356,0.00000000,0.00000000,0.00000000,0.00000000
201.59000000,4.85486800,2.62900000,0.16107922,236.07721853,0.14934994,274.10435327,0.00080976,0.15349721,277.37193166,-0.08603458,-0.06746264,0.00000000,0.00000000,0.00000000,0.00000000
203.09000000,4.89864600,2.63100000,0.16247433,236.25681321,0.15055078,274.64248144,0.00084110,0.15489137,277.86608658,-0.08684147,-0.06804989,0.00000000,0.00000000,0.00000000,0.00000000
204.59000000,4.94215500,2.63300000,0.16391789,236.43640790,0.15179180,275.19256474,0.00083987,0.15628375,278.36058894,-0.08759787,-0.06868588,0.00000000,0.00000000,0.00000000,0.00000000
206.09000000,4.98660400,2.63400000,0.16538378,236.52620525,0.15305046,275.64380261,0.00081325,0.15767417,278.85538608,-0.08836299,-0.06931118,0.00000000,0.00000000,0.00000000,0.00000000
207.59000000,5.03142300,2.63500000,0.16685722,236.61600259,0.15431400,276.09709152,0.00084423,0.15909274,279.46503630,-0.08917203,-0.06992071,0.00000000,0.00000000,0.00000000,0.00000000
209.09000000,5.07667900,2.63700000,0.16837922,236.79559728,0.15561751,276.66705578,0.00083666,0.16044766,279.95170653,-0.08989426,-0.07055340,0.00000000,0.00000000,0.00000000,0.00000000
210.59000000,5.12223600,2.63800000,0.16998322,236.88539463,0.15698941,277.15193730,0.00089290,0.16180073,280.43866484,-0.09064435,-0.07115638,0.00000000,0.00000000,0.00000000,0.00000000
212.09000000,5.16782700,2.63900000,0.17158722,236.97519197,0.15835943,277.63710690,0.00101901,0.16324633,280.95253290,-0.09150203,-0.07174430,0.00000000,0.00000000,0.00000000,0.00000000
213.59000000,5.21435800,2.64100000,0.17319111,237.15478666,0.15972748,278.22788767,0.00095394,0.16456406,281.43117374,-0.09223706,-0.07232700,0.00000000,0.00000000,0.00000000,0.00000000
215.09000000,5.26119100,2.64200000,0.17483244,237.24458400,0.16112554,278.72263456,0.00095261,0.16588022,281.91014878,-0.09298443,-0.07289579,0.00000000,0.00000000,0.00000000,0.00000000
216.59000000,5.30789000,2.64300000,0.17651111,237.33438135,0.16255337,279.22653670,0.00101474,0.16713196,282.37163731,-0.09372384,-0.07340812,0.00000000,0.00000000,0.00000000,0.00000000
218.09000000,5.35448700,2.64500000,0.17811522,237.51397604,0.16391589,279.81883066,0.00095033,0.16835222,282.71779410,-0.09439815,-0.07395407,0.00000000,0.00000000,0.00000000,0.00000000
219.59000000,5.40216000,2.64600000,0.17979378,237.60377338,0.16533966,280.32345341,0.00094879,0.16953822,283.16188017,-0.09507467,-0.07446355,0.00000000,0.00000000,0.00000000,0.00000000
221.09000000,5.44966300,2.64700000,0.18139778,237.69357073,0.16669829,280.81065625,0.00094750,0.17069327,283.49044588,-0.09578923,-0.07490404,0.00000000,0.00000000,0.00000000,0.00000000
222.59000000,5.49864500,2.64800000,0.18300178,237.78336807,0.16805509,281.29814715,0.00088307,0.17181418,283.91715559,-0.09643728,-0.07537690,0.00000000,0.00000000,0.00000000,0.00000000
224.09000000,5.54651900,2.64800000,0.18456844,237.78336807,0.16937853,281.67067443,0.00088190,0.17290267,284.33521244,-0.09710533,-0.07579734,0.00000000,0.00000000,0.00000000,0.00000000
225.59000000,5.59486200,2.64900000,0.18609778,237.87316541,0.17066874,282.14083289,0.00081779,0.17392922,284.62842353,-0.09770097,-0.07622825,0.00000000,0.00000000,0.00000000,0.00000000
227.09000000,5.64434700,2.65000000,0.18758989,237.96296276,0.17192595,282.60240850,0.00081695,0.17498439,285.03795448,-0.09833446,-0.07664993,0.00000000,0.00000000,0.00000000,0.00000000
228.59000000,5.69306000,2.65100000,0.18904456,238.05276010,0.17315009,283.05533834,0.00087858,0.17591598,285.30468993,-0.09888800,-0.07702799,0.00000000,0.00000000,0.00000000,0.00000000
230.09000000,5.74261200,2.65100000,0.19038744,238.05276010,0.17427884,283.37501674,0.00075228,0.17690697,285.69674772,-0.09953731,-0.07736966,0.00000000,0.00000000,0.00000000,0.00000000
231.59000000,5.79240000,2.65200000,0.19176744,238.14255745,0.17543745,283.81054710,0.00075122,0.00000000,0.00000000,0.00000000,0.00000000,0.00000000,0.00000000,0.00000000,0.00000000
233.09000000,5.84262300,2.65200000,0.19303567,238.14255745,0.17650104,284.11256479,0.00062539,0.00000000,0.00000000,0.00000000,0.00000000,0.00000000,0.00000000,0.00000000,0.00000000
234.59000000,5.89247700,2.65300000,0.19434111,238.23235479,0.17759466,284.53069532,0.00062471,0.00000000,0.00000000,0.00000000,0.00000000,0.00000000,0.00000000,0.00000000,0.00000000
236.09000000,5.94270100,2.65300000,0.19560933,238.23235479,0.17865596,284.83282689,0.00068652,0.00000000,0.00000000,0.00000000,0.00000000,0.00000000,0.00000000,0.00000000,0.00000000
237.59000000,5.99309300,2.65400000,0.19676567,238.32215214,0.17962264,285.21576928,0.00062363,0.00000000,0.00000000,0.00000000,0.00000000,0.00000000,0.00000000,0.00000000,0.00000000
239.09000000,6.04388700,2.65400000,0.19799667,238.32215214,0.18065072,285.50914385,0.00074750,0.00000000,0.00000000,0.00000000,0.00000000,0.00000000,0.00000000,0.00000000,0.00000000
240.59000000,6.09572200,2.65400000,0.19907833,238.32215214,0.00000000,0.00000000,0.00000000,0.00000000,0.00000000,0.00000000,0.00000000,0.00000000,0.00000000,0.00000000,0.00000000
242.09000000,6.14732200,2.65500000,0.20023478,238.41194948,0.00000000,0.00000000,0.00000000,0.00000000,0.00000000,0.00000000,0.00000000,0.00000000,0.00000000,0.00000000,0.00000000
243.59000000,6.19993000,2.65500000,0.20146589,238.41194948,0.00000000,0.00000000,0.00000000,0.00000000,0.00000000,0.00000000,0.00000000,0.00000000,0.00000000,0.00000000,0.00000000
245.09000000,6.25287300,2.65500000,0.20262256,238.41194948,0.00000000,0.00000000,0.00000000,0.00000000,0.00000000,0.00000000,0.00000000,0.00000000,0.00000000,0.00000000,0.00000000
246.59000000,6.30608500,2.65500000,0.20381644,238.41194948,0.00000000,0.00000000,0.00000000,0.00000000,0.00000000,0.00000000,0.00000000,0.00000000,0.00000000,0.00000000,0.00000000
248.09000000,6.35943000,2.65500000,0.20497278,238.41194948,0.00000000,0.00000000,0.00000000,0.00000000,0.00000000,0.00000000,0.00000000,0.00000000,0.00000000,0.00000000,0.00000000
249.59000000,6.41324600,2.65400000,0.20605456,238.32215214,0.00000000,0.00000000,0.00000000,0.00000000,0.00000000,0.00000000,0.00000000,0.00000000,0.00000000,0.00000000,0.00000000
251.09000000,6.46763300,2.65300000,0.20706156,238.23235479,0.00000000,0.00000000,0.00000000,0.00000000,0.00000000,0.00000000,0.00000000,0.00000000,0.00000000,0.00000000,0.00000000
252.59000000,6.52339600,2.65200000,0.20795678,238.14255745,0.00000000,0.00000000,0.00000000,0.00000000,0.00000000,0.00000000,0.00000000,0.00000000,0.00000000,0.00000000,0.00000000
254.09000000,6.57962900,2.65000000,0.20874000,237.96296276,0.00000000,0.00000000,0.00000000,0.00000000,0.00000000,0.00000000,0.00000000,0.00000000,0.00000000,0.00000000,0.00000000
255.59000000,6.63542600,2.64900000,0.20937400,237.87316541,0.00000000,0.00000000,0.00000000,0.00000000,0.00000000,0.00000000,0.00000000,0.00000000,0.00000000,0.00000000,0.00000000
257.09000000,6.69236400,2.64600000,0.20989622,237.60377338,0.00000000,0.00000000,0.00000000,0.00000000,0.00000000,0.00000000,0.00000000,0.00000000,0.00000000,0.00000000,0.00000000
258.59000000,6.75071300,2.64200000,0.21030689,237.24458400,0.00000000,0.00000000,0.00000000,0.00000000,0.00000000,0.00000000,0.00000000,0.00000000,0.00000000,0.00000000,0.00000000
260.09000000,6.80899400,2.63800000,0.21060556,236.88539463,0.00000000,0.00000000,0.00000000,0.00000000,0.00000000,0.00000000,0.00000000,0.00000000,0.00000000,0.00000000,0.00000000
261.59000000,6.86717300,2.63400000,0.21079233,236.52620525,0.00000000,0.00000000,0.00000000,0.00000000,0.00000000,0.00000000,0.00000000,0.00000000,0.00000000,0.00000000,0.00000000
263.09000000,6.92602500,2.62600000,0.21101656,235.80782649,0.00000000,0.00000000,0.00000000,0.00000000,0.00000000,0.00000000,0.00000000,0.00000000,0.00000000,0.00000000,0.00000000
264.59000000,6.98608300,2.61600000,0.21112900,234.90985305,0.00000000,0.00000000,0.00000000,0.00000000,0.00000000,0.00000000,0.00000000,0.00000000,0.00000000,0.00000000,0.00000000
266.09000000,7.04765200,2.60100000,0.21113000,233.56289288,0.00000000,0.00000000,0.00000000,0.00000000,0.00000000,0.00000000,0.00000000,0.00000000,0.00000000,0.00000000,0.00000000
267.59000000,7.11002700,2.57500000,0.21116844,231.22816193,0.00000000,0.00000000,0.00000000,0.00000000,0.00000000,0.00000000,0.00000000,0.00000000,0.00000000,0.00000000,0.00000000
269.09000000,7.17425400,2.53300000,0.21113222,227.45667346,0.00000000,0.00000000,0.00000000,0.00000000,0.00000000,0.00000000,0.00000000,0.00000000,0.00000000,0.00000000,0.00000000
270.59000000,7.24161400,2.46800000,0.21102111,221.61984607,0.00000000,0.00000000,0.00000000,0.00000000,0.00000000,0.00000000,0.00000000,0.00000000,0.00000000,0.00000000,0.00000000
272.09000000,7.45597500,1.18400000,0.20819467,106.32005581,0.00000000,0.00000000,0.00000000,0.00000000,0.00000000,0.00000000,0.00000000,0.00000000,0.00000000,0.00000000,0.00000000
273.59000000,7.67580000,0.35800000,0.20635611,32.14744931,0.00000000,0.00000000,0.00000000,0.00000000,0.00000000,0.00000000,0.00000000,0.00000000,0.00000000,0.00000000,0.00000000
NaN,-100.00000000,NaN,-11.11111111,NaN,0.00000000,0.00000000,0.00000000,0.00000000,0.00000000,0.00000000,0.00000000,0.00000000,0.00000000,0.00000000,0.00000000