File: lab_data/AA6014-T4_results/DATA/UT_15_2.csv
Time[s],Displacement[mm],Force[kN],EngStrain_longi,EngStress[MPa],TrueStrain,TrueStress[MPa],TrueStrainRate[1/s],PlasticStrain_longi,PlasticStress[MPa],PlasticStrain_thick,PlasticStrain_width,R-Value,Thickness[mm],Width[mm], Young's Modulus [MPa]
0.58000000,0.00000000,-0.00100000,0.00000000,-0.09043719,0.00000000,-0.09043719,0.00000000,0.00086938,121.04484149,-0.00009253,-0.00077685,0.69311325,1.10840000,9.97600000,87144.66426896
2.08000000,0.00562700,0.16000000,0.00012444,14.46994982,0.00012444,14.47175053,0.00007955,0.00195454,125.54111544,-0.00075301,-0.00120154,0.00000000,0.00000000,0.00000000,0.00000000
3.58000000,0.01284800,0.40000000,0.00036856,36.17487455,0.00036849,36.18820700,0.00011241,0.00317988,129.24633067,-0.00153308,-0.00164680,0.00000000,0.00000000,0.00000000,0.00000000
5.08000000,0.02194600,0.64600000,0.00074644,58.42242240,0.00074617,58.46603150,0.00036243,0.00443663,131.96204553,-0.00234610,-0.00209053,0.00000000,0.00000000,0.00000000,0.00000000
6.58000000,0.02967400,0.87800000,0.00093922,79.40384964,0.00093878,79.47842750,0.00031084,0.00557634,134.85137939,-0.00300590,-0.00257044,0.00000000,0.00000000,0.00000000,0.00000000
8.08000000,0.03977000,1.10000000,0.00119556,99.48090502,0.00119484,99.59983997,0.00014605,0.00675997,137.47921689,-0.00376470,-0.00299527,0.00000000,0.00000000,0.00000000,0.00000000
9.58000000,0.05784300,1.27700000,0.00180800,115.48828701,0.00180637,115.69708983,0.00027774,0.00796879,140.02529941,-0.00452893,-0.00343987,0.00000000,0.00000000,0.00000000,0.00000000
11.08000000,0.08959100,1.35200000,0.00295411,122.27107599,0.00294976,122.63227833,0.00075103,0.00912855,142.38724708,-0.00524504,-0.00388351,0.00000000,0.00000000,0.00000000,0.00000000
12.58000000,0.12536700,1.39500000,0.00412400,126.15987500,0.00411552,126.68015833,0.00078558,0.01025968,144.84223564,-0.00591566,-0.00434402,0.00000000,0.00000000,0.00000000,0.00000000
14.08000000,0.16298400,1.43200000,0.00535078,129.50605090,0.00533651,130.19900900,0.00067252,0.01143554,146.85008564,-0.00665676,-0.00477879,0.00000000,0.00000000,0.00000000,0.00000000
15.58000000,0.19984000,1.46100000,0.00665467,132.12872930,0.00663262,133.00800195,0.00067474,0.01260591,149.13766294,-0.00734718,-0.00525872,0.00000000,0.00000000,0.00000000,0.00000000
17.08000000,0.23743700,1.49100000,0.00792256,134.84184490,0.00789134,135.91013690,0.00083137,0.01371154,151.23656594,-0.00798339,-0.00572815,0.00000000,0.00000000,0.00000000,0.00000000
18.58000000,0.27424700,1.51600000,0.00911889,137.10277455,0.00907756,138.35299952,0.00076253,0.01483514,153.52718919,-0.00865770,-0.00617744,0.00000000,0.00000000,0.00000000,0.00000000
20.08000000,0.31143000,1.54100000,0.01036322,139.36370421,0.01030989,140.80796125,0.00073782,0.01601240,155.55439605,-0.00936598,-0.00664642,0.00000000,0.00000000,0.00000000,0.00000000
21.58000000,0.34708200,1.56400000,0.01163933,141.44375950,0.01157212,143.09007057,0.00087622,0.01715771,157.67364681,-0.01009368,-0.00706402,0.00000000,0.00000000,0.00000000,0.00000000
23.08000000,0.38344300,1.58900000,0.01283067,143.70468916,0.01274905,145.54851613,0.00089867,0.01825301,159.60463255,-0.01076036,-0.00749265,0.00000000,0.00000000,0.00000000,0.00000000
24.58000000,0.41908500,1.61000000,0.01400211,145.60387007,0.01390499,147.64263164,0.00080226,0.01936892,161.54310170,-0.01142652,-0.00794240,0.00000000,0.00000000,0.00000000,0.00000000
26.08000000,0.45435000,1.63200000,0.01523300,147.59348818,0.01511814,149.84177978,0.00082341,0.02050156,163.48854851,-0.01211070,-0.00839086,0.00000000,0.00000000,0.00000000,0.00000000
27.58000000,0.49079700,1.65400000,0.01646767,149.58310628,0.01633355,152.04639101,0.00098382,0.02159785,165.33943222,-0.01272556,-0.00887229,0.00000000,0.00000000,0.00000000,0.00000000
29.08000000,0.52571600,1.67500000,0.01760911,151.48228719,0.01745587,154.14975562,0.00091674,0.02269639,167.19465430,-0.01343045,-0.00926594,0.00000000,0.00000000,0.00000000,0.00000000
30.58000000,0.56095400,1.69500000,0.01878400,153.29103092,0.01860976,156.17044964,0.00081290,0.02381921,169.05796554,-0.01407001,-0.00974920,0.00000000,0.00000000,0.00000000,0.00000000
32.08000000,0.59629200,1.71600000,0.02001122,155.19021183,0.01981363,158.29575765,0.00087033,0.02492730,170.82965851,-0.01474303,-0.01018427,0.00000000,0.00000000,0.00000000,0.00000000
33.58000000,0.63058900,1.73400000,0.02114900,156.81808119,0.02092846,160.13462679,0.00085499,0.02605937,172.60931036,-0.01538548,-0.01067389,0.00000000,0.00000000,0.00000000,0.00000000
35.08000000,0.66560600,1.75300000,0.02229789,158.53638773,0.02205293,162.07141449,0.00081750,0.02713582,174.38314025,-0.01602297,-0.01111284,0.00000000,0.00000000,0.00000000,0.00000000
36.58000000,0.70110700,1.77300000,0.02344667,160.34513146,0.02317602,164.10469030,0.00074360,0.02823414,176.07105202,-0.01665654,-0.01157760,0.00000000,0.00000000,0.00000000,0.00000000
38.08000000,0.73519400,1.79000000,0.02463667,161.88256362,0.02433808,165.87081038,0.00082301,0.02931433,177.66571628,-0.01730958,-0.01200475,0.00000000,0.00000000,0.00000000,0.00000000
39.58000000,0.77004300,1.80800000,0.02575578,163.51043298,0.02542969,167.72177135,0.00075688,0.03040875,179.45365521,-0.01795448,-0.01245426,0.00000000,0.00000000,0.00000000,0.00000000
41.08000000,0.80492400,1.82700000,0.02692700,165.22873952,0.02657085,169.67785379,0.00074107,0.03155606,180.97355448,-0.01866850,-0.01288755,0.00000000,0.00000000,0.00000000,0.00000000
42.58000000,0.83990600,1.84300000,0.02809456,166.67573450,0.02770714,171.35841518,0.00074759,0.03263955,182.57901530,-0.01933829,-0.01330125,0.00000000,0.00000000,0.00000000,0.00000000
44.08000000,0.87418200,1.85900000,0.02926956,168.12272948,0.02884938,173.04360705,0.00071779,0.03369544,184.27674437,-0.01999258,-0.01370287,0.00000000,0.00000000,0.00000000,0.00000000
45.58000000,0.90879600,1.87700000,0.03041100,169.75059884,0.02995775,174.91288430,0.00073167,0.03480658,185.79997330,-0.02066119,-0.01414538,0.00000000,0.00000000,0.00000000,0.00000000
47.08000000,0.94294000,1.89200000,0.03155611,171.10715663,0.03106845,176.50663308,0.00070887,0.03589969,187.22880299,-0.02132774,-0.01457196,0.00000000,0.00000000,0.00000000,0.00000000
48.58000000,0.97762000,1.90800000,0.03270878,172.55415162,0.03218523,178.19818702,0.00073714,0.03699240,188.84920706,-0.02198644,-0.01500595,0.00000000,0.00000000,0.00000000,0.00000000
50.08000000,1.01226700,1.92400000,0.03387633,174.00114660,0.03331517,179.89566744,0.00075781,0.03810806,190.28847851,-0.02269621,-0.01541185,0.00000000,0.00000000,0.00000000,0.00000000
51.58000000,1.04744900,1.93900000,0.03505133,175.35770439,0.03445102,181.50422574,0.00069209,0.03921156,191.72844684,-0.02334359,-0.01586796,0.00000000,0.00000000,0.00000000,0.00000000
53.08000000,1.08196200,1.95400000,0.03623000,176.71426219,0.03558913,183.11661991,0.00075609,0.04030181,193.26352627,-0.02399763,-0.01630418,0.00000000,0.00000000,0.00000000,0.00000000
54.58000000,1.11593800,1.96900000,0.03737156,178.07081999,0.03669016,184.72560353,0.00079854,0.04135660,194.70009088,-0.02460741,-0.01674920,0.00000000,0.00000000,0.00000000,0.00000000
56.08000000,1.15078500,1.98300000,0.03850922,179.33694060,0.03778624,186.24306669,0.00072553,0.04246820,196.05581870,-0.02525360,-0.01721460,0.00000000,0.00000000,0.00000000,0.00000000
57.58000000,1.18512900,1.99700000,0.03968800,180.60306120,0.03892067,187.77083550,0.00076790,0.04355372,197.40921252,-0.02587565,-0.01767807,0.00000000,0.00000000,0.00000000,0.00000000
59.08000000,1.21927100,2.01100000,0.04082933,181.86918181,0.04001783,189.29477926,0.00073117,0.04463677,198.85996791,-0.02652081,-0.01811595,0.00000000,0.00000000,0.00000000,0.00000000
60.58000000,1.25408600,2.02400000,0.04199322,183.04486524,0.04113544,190.73150894,0.00069452,0.04571764,200.12285176,-0.02713282,-0.01858481,0.00000000,0.00000000,0.00000000,0.00000000
62.08000000,1.28930300,2.03700000,0.04314589,184.22054866,0.04224104,192.16890798,0.00065816,0.04682285,201.58381924,-0.02780467,-0.01901818,0.00000000,0.00000000,0.00000000,0.00000000
63.58000000,1.32358100,2.05100000,0.04433578,185.48666927,0.04338106,193.71036502,0.00071446,0.04792228,202.85581265,-0.02844290,-0.01947938,0.00000000,0.00000000,0.00000000,0.00000000
65.08000000,1.35775800,2.06300000,0.04545867,186.57191551,0.04445570,195.05322602,0.00071369,0.04900643,204.12727960,-0.02908503,-0.01992140,0.00000000,0.00000000,0.00000000,0.00000000
66.58000000,1.39273900,2.07600000,0.04664856,187.74759893,0.04559321,196.50575323,0.00072732,0.05009281,205.40176901,-0.02973976,-0.02035306,0.00000000,0.00000000,0.00000000,0.00000000
68.08000000,1.42748600,2.08900000,0.04779744,188.92328235,0.04669029,197.95333244,0.00071231,0.05122024,206.68734122,-0.03044107,-0.02077917,0.00000000,0.00000000,0.00000000,0.00000000
69.58000000,1.46250200,2.10000000,0.04897622,189.91809140,0.04781466,199.21956205,0.00075410,0.05228434,207.86654029,-0.03107656,-0.02120778,0.00000000,0.00000000,0.00000000,0.00000000
71.08000000,1.49738300,2.11200000,0.05014378,191.00333764,0.04892709,200.58096656,0.00078163,0.05339156,209.15305525,-0.03173354,-0.02165802,0.00000000,0.00000000,0.00000000,0.00000000
72.58000000,1.53189500,2.12400000,0.05130011,192.08858388,0.05002760,201.94274957,0.00073108,0.05449317,210.24888775,-0.03240372,-0.02208946,0.00000000,0.00000000,0.00000000,0.00000000
74.08000000,1.56724400,2.13500000,0.05248244,193.08339293,0.05115161,203.21688137,0.00074441,0.05562936,211.54660941,-0.03310638,-0.02252299,0.00000000,0.00000000,0.00000000,0.00000000
75.58000000,1.60219300,2.14600000,0.05369111,194.07820198,0.05229934,204.49847628,0.00083576,0.05672139,212.64504763,-0.03373007,-0.02299132,0.00000000,0.00000000,0.00000000,0.00000000
77.08000000,1.63704000,2.15700000,0.05483244,195.07301103,0.05338193,205.76934107,0.00079228,0.05779320,213.83772862,-0.03435334,-0.02343986,0.00000000,0.00000000,0.00000000,0.00000000
78.58000000,1.67192000,2.16800000,0.05600378,196.06782008,0.05449176,207.04835870,0.00072088,0.05893168,214.95063412,-0.03506811,-0.02386357,0.00000000,0.00000000,0.00000000,0.00000000
80.08000000,1.70710300,2.17900000,0.05718244,197.06262913,0.05560730,208.33115197,0.00079052,0.06002897,216.15352306,-0.03573212,-0.02429685,0.00000000,0.00000000,0.00000000,0.00000000
81.58000000,1.74221800,2.18900000,0.05838356,197.96700099,0.05674280,209.52501839,0.00081083,0.06111949,217.26063079,-0.03633262,-0.02478687,0.00000000,0.00000000,0.00000000,0.00000000
83.08000000,1.77760200,2.19900000,0.05954733,198.87137285,0.05784177,210.71363278,0.00077469,0.06222951,218.37420341,-0.03699485,-0.02523466,0.00000000,0.00000000,0.00000000,0.00000000
84.58000000,1.81301800,2.20900000,0.06075211,199.77574472,0.05897820,211.91254296,0.00073861,0.06335928,219.49436361,-0.03768430,-0.02567498,0.00000000,0.00000000,0.00000000,0.00000000
86.08000000,1.84873700,2.21900000,0.06194200,200.68011658,0.06009931,213.11064436,0.00076583,0.06447022,220.61264369,-0.03833599,-0.02613423,0.00000000,0.00000000,0.00000000,0.00000000
87.58000000,1.88435400,2.22800000,0.06312811,201.49405126,0.06121561,214.21399012,0.00082123,0.06558474,221.63679780,-0.03898832,-0.02659643,0.00000000,0.00000000,0.00000000,0.00000000
89.08000000,1.91957000,2.23700000,0.06429556,202.30798594,0.06231313,215.31549029,0.00070795,0.06669660,222.75967921,-0.03967056,-0.02702604,0.00000000,0.00000000,0.00000000,0.00000000
90.58000000,1.95505500,2.24700000,0.06550411,203.21235780,0.06344803,216.52360266,0.00074929,0.06781000,223.69037549,-0.04033395,-0.02747605,0.00000000,0.00000000,0.00000000,0.00000000
92.08000000,1.99074000,2.25600000,0.06672389,204.02629248,0.06459217,217.63972015,0.00082533,0.06893094,224.72209923,-0.04099164,-0.02793930,0.00000000,0.00000000,0.00000000,0.00000000
93.58000000,2.02696300,2.26500000,0.06791378,204.84022716,0.06570700,218.75170082,0.00080360,0.07003890,225.85056399,-0.04168854,-0.02835036,0.00000000,0.00000000,0.00000000,0.00000000
95.08000000,2.06248100,2.27400000,0.06910367,205.65416183,0.06682060,219.86561848,0.00073970,0.07117248,226.79166002,-0.04235232,-0.02882017,0.00000000,0.00000000,0.00000000,0.00000000
96.58000000,2.09853600,2.28200000,0.07032344,206.37765932,0.06796089,220.89084718,0.00076689,0.07227371,227.72723334,-0.04299322,-0.02928049,0.00000000,0.00000000,0.00000000,0.00000000
98.08000000,2.13445800,2.29100000,0.07152078,207.19159400,0.06907893,222.01009795,0.00074508,0.07337918,228.76354119,-0.04365570,-0.02972349,0.00000000,0.00000000,0.00000000,0.00000000
99.58000000,2.17058200,2.29900000,0.07273689,207.91509149,0.07021322,223.03818840,0.00075833,0.07452604,229.71336800,-0.04434107,-0.03018497,0.00000000,0.00000000,0.00000000,0.00000000
101.08000000,2.20687200,2.30700000,0.07396033,208.63858898,0.07135306,224.06956857,0.00078500,0.07564411,230.65843424,-0.04502116,-0.03062295,0.00000000,0.00000000,0.00000000,0.00000000
102.58000000,2.24323000,2.31500000,0.07516511,209.36208647,0.07247424,225.09881097,0.00075641,0.07676772,231.60664121,-0.04571166,-0.03105606,0.00000000,0.00000000,0.00000000,0.00000000
104.08000000,2.27921900,2.32300000,0.07636622,210.08558397,0.07359076,226.12902636,0.00074173,0.07788992,232.55638296,-0.04635097,-0.03153895,0.00000000,0.00000000,0.00000000,0.00000000
105.58000000,2.31561000,2.33000000,0.07758600,210.71864427,0.07472335,227.06746100,0.00071324,0.07902111,233.51009661,-0.04702133,-0.03199977,0.00000000,0.00000000,0.00000000,0.00000000
107.08000000,2.35230400,2.33800000,0.07882444,211.44214176,0.07587197,228.10895112,0.00078166,0.08015107,234.46540689,-0.04769210,-0.03245897,0.00000000,0.00000000,0.00000000,0.00000000
108.58000000,2.38822500,2.34500000,0.08001433,212.07520207,0.07697431,229.04425798,0.00074622,0.08127417,235.32223550,-0.04835808,-0.03291608,0.00000000,0.00000000,0.00000000,0.00000000
110.08000000,2.42505300,2.35200000,0.08126400,212.70826237,0.07813073,229.99378660,0.00073857,0.08239596,236.18040403,-0.04900094,-0.03339502,0.00000000,0.00000000,0.00000000,0.00000000
111.58000000,2.46134400,2.36000000,0.08249867,213.43175986,0.07927195,231.03959547,0.00075827,0.08354031,237.04558696,-0.04968318,-0.03385713,0.00000000,0.00000000,0.00000000,0.00000000
113.08000000,2.49823900,2.36600000,0.08371467,213.97438298,0.08039465,231.88717713,0.00072972,0.08467177,238.00847615,-0.05035403,-0.03431774,0.00000000,0.00000000,0.00000000,0.00000000
114.58000000,2.53530200,2.37300000,0.08497178,214.60744328,0.08155398,232.84301926,0.00077723,0.08577744,238.76867621,-0.05100392,-0.03477351,0.00000000,0.00000000,0.00000000,0.00000000
116.08000000,2.57206300,2.37900000,0.08621022,215.15006640,0.08269478,233.69820144,0.00076959,0.08693822,239.64284980,-0.05169128,-0.03524695,0.00000000,0.00000000,0.00000000,0.00000000
117.58000000,2.60812000,2.38600000,0.08743000,215.78312671,0.08381711,234.64904548,0.00072743,0.08806699,240.51102648,-0.05236630,-0.03570069,0.00000000,0.00000000,0.00000000,0.00000000
119.08000000,2.64588800,2.39300000,0.08869078,216.41618701,0.08497585,235.61030696,0.00077458,0.08918908,241.27971079,-0.05302601,-0.03616307,0.00000000,0.00000000,0.00000000,0.00000000
120.58000000,2.68244700,2.39900000,0.08992544,216.95881013,0.08610929,236.46892756,0.00077370,0.09031875,242.15134001,-0.05364926,-0.03666949,0.00000000,0.00000000,0.00000000,0.00000000
122.08000000,2.71971200,2.40500000,0.09120111,217.50143325,0.08727903,237.33780563,0.00080009,0.09140439,242.91414008,-0.05429432,-0.03711007,0.00000000,0.00000000,0.00000000,0.00000000
123.58000000,2.75660700,2.41100000,0.09242089,218.04405637,0.08839623,238.19588187,0.00074446,0.09260712,243.70695805,-0.05501819,-0.03758893,0.00000000,0.00000000,0.00000000,0.00000000
125.08000000,2.79424100,2.41700000,0.09367056,218.58667949,0.08953952,239.06181519,0.00079829,0.09374285,244.58492545,-0.05571855,-0.03802430,0.00000000,0.00000000,0.00000000,0.00000000
126.58000000,2.83137200,2.42300000,0.09494622,219.12930260,0.09070525,239.93480206,0.00078355,0.09490896,245.37194524,-0.05641804,-0.03849092,0.00000000,0.00000000,0.00000000,0.00000000
128.08000000,2.86863600,2.42900000,0.09620333,219.67192572,0.09185269,240.80509722,0.00079644,0.09604671,246.15347864,-0.05708244,-0.03896427,0.00000000,0.00000000,0.00000000,0.00000000
129.58000000,2.90650500,2.43400000,0.09743056,220.12411165,0.09297159,241.57092614,0.00076841,0.09722016,246.94533867,-0.05778607,-0.03943409,0.00000000,0.00000000,0.00000000,0.00000000
131.08000000,2.94333400,2.44000000,0.09870256,220.66673477,0.09412999,242.44710542,0.00080131,0.09836341,247.63074130,-0.05845890,-0.03990451,0.00000000,0.00000000,0.00000000,0.00000000
132.58000000,2.98130400,2.44500000,0.09999322,221.11892070,0.09530402,243.22931408,0.00095660,0.09952728,248.42314277,-0.05914080,-0.04038648,0.00000000,0.00000000,0.00000000,0.00000000
134.08000000,3.01870300,2.45000000,0.10124656,221.57110664,0.09644277,244.00441799,0.00080632,0.10065293,249.20751474,-0.05978677,-0.04086616,0.00000000,0.00000000,0.00000000,0.00000000
135.58000000,3.05650500,2.45500000,0.10249989,222.02329257,0.09758023,244.78065539,0.00078504,0.10181886,249.90261871,-0.06045891,-0.04135995,0.00000000,0.00000000,0.00000000,0.00000000
137.08000000,3.09444100,2.46000000,0.10378311,222.47547850,0.09874347,245.56467580,0.00075714,0.10298339,250.59866725,-0.06115725,-0.04182614,0.00000000,0.00000000,0.00000000,0.00000000
138.58000000,3.13264600,2.46500000,0.10506256,222.92766443,0.09990194,246.34901456,0.00077658,0.10413517,251.39387194,-0.06180873,-0.04232644,0.00000000,0.00000000,0.00000000,0.00000000
140.08000000,3.17098400,2.47000000,0.10635689,223.37985036,0.10107254,247.13783629,0.00074854,0.10531352,252.09611894,-0.06252348,-0.04279004,0.00000000,0.00000000,0.00000000,0.00000000
141.58000000,3.20838400,2.47500000,0.10764011,223.83203630,0.10223173,247.92534155,0.00076112,0.10643728,252.78583730,-0.06318790,-0.04324939,0.00000000,0.00000000,0.00000000,0.00000000
143.08000000,3.24675600,2.48000000,0.10891956,224.28422223,0.10338617,248.71316003,0.00071995,0.10760294,253.48745856,-0.06386732,-0.04373562,0.00000000,0.00000000,0.00000000,0.00000000
144.58000000,3.28522800,2.48400000,0.11019900,224.64597097,0.10453928,249.40173233,0.00075276,0.10875731,254.18750556,-0.06454812,-0.04420920,0.00000000,0.00000000,0.00000000,0.00000000
146.08000000,3.32387000,2.48800000,0.11153444,225.00771972,0.10574144,250.10383073,0.00080566,0.10992030,254.89104799,-0.06523173,-0.04468857,0.00000000,0.00000000,0.00000000,0.00000000
147.58000000,3.36251200,2.49300000,0.11284378,225.45990565,0.10691870,250.90165314,0.00081150,0.11112148,255.60569474,-0.06595418,-0.04516730,0.00000000,0.00000000,0.00000000,0.00000000
149.08000000,3.40078400,2.49700000,0.11411567,225.82165440,0.10806097,251.59144303,0.00077007,0.11227973,256.20874177,-0.06664970,-0.04563003,0.00000000,0.00000000,0.00000000,0.00000000
150.58000000,3.43972600,2.50100000,0.11542878,226.18340314,0.10923889,252.29147692,0.00074943,0.11349131,256.92864081,-0.06737093,-0.04612038,0.00000000,0.00000000,0.00000000,0.00000000
152.08000000,3.47873600,2.50500000,0.11672311,226.54515189,0.11039860,252.98820682,0.00080191,0.11463213,257.63162817,-0.06802458,-0.04660756,0.00000000,0.00000000,0.00000000,0.00000000
153.58000000,3.51754500,2.51000000,0.11803989,226.99733782,0.11157705,253.79207835,0.00080773,0.11582582,258.24731822,-0.06872297,-0.04710285,0.00000000,0.00000000,0.00000000,0.00000000
155.08000000,3.55638900,2.51300000,0.11936044,227.26864938,0.11275749,254.39553638,0.00084014,0.11702309,258.96746164,-0.06944491,-0.04757818,0.00000000,0.00000000,0.00000000,0.00000000
156.58000000,3.59570200,2.51800000,0.12068089,227.72083531,0.11393644,255.20238813,0.00085224,0.11817103,259.57358758,-0.07007777,-0.04809326,0.00000000,0.00000000,0.00000000,0.00000000
158.08000000,3.63531500,2.52100000,0.12199389,227.99214687,0.11510736,255.80579550,0.00077159,0.11939508,260.30330647,-0.07084930,-0.04854579,0.00000000,0.00000000,0.00000000,0.00000000
159.58000000,3.67446000,2.52500000,0.12334789,228.35389561,0.11631341,256.52086656,0.00085022,0.12056799,260.81547799,-0.07150302,-0.04906496,0.00000000,0.00000000,0.00000000,0.00000000
161.08000000,3.71414200,2.52800000,0.12465722,228.62520717,0.11747830,257.12499043,0.00073656,0.12178572,261.54607012,-0.07222103,-0.04956469,0.00000000,0.00000000,0.00000000,0.00000000
162.58000000,3.75362400,2.53200000,0.12598522,228.98695592,0.11865841,257.83592845,0.00079531,0.12299507,262.06979805,-0.07292289,-0.05007218,0.00000000,0.00000000,0.00000000,0.00000000
164.08000000,3.79340500,2.53500000,0.12733556,229.25826748,0.11985693,258.45099633,0.00078766,0.12415893,262.68557783,-0.07361277,-0.05054616,0.00000000,0.00000000,0.00000000,0.00000000
165.58000000,3.83295200,2.53900000,0.12867467,229.62001622,0.12104408,259.16629527,0.00074713,0.12537540,263.41963565,-0.07433499,-0.05104042,0.00000000,0.00000000,0.00000000,0.00000000
167.08000000,3.87260100,2.54200000,0.13002867,229.89132778,0.12224300,259.78379061,0.00083201,0.12656732,263.94178007,-0.07504535,-0.05152197,0.00000000,0.00000000,0.00000000,0.00000000
168.58000000,3.91261900,2.54500000,0.13135667,230.16263934,0.12341750,260.39603644,0.00071235,0.12778555,264.57532180,-0.07574341,-0.05204214,0.00000000,0.00000000,0.00000000,0.00000000
170.08000000,3.95283800,2.54800000,0.13278533,230.43395090,0.12467950,261.03219988,0.00087611,0.12900237,265.20964835,-0.07649278,-0.05250959,0.00000000,0.00000000,0.00000000,0.00000000
171.58000000,3.99372800,2.55100000,0.13412822,230.70526246,0.12586427,261.64934917,0.00078960,0.13020277,265.73696827,-0.07720530,-0.05299747,0.00000000,0.00000000,0.00000000,0.00000000
173.08000000,4.03381200,2.55400000,0.13554933,230.97657402,0.12711653,262.28529464,0.00086066,0.13140682,266.37007000,-0.07790307,-0.05350375,0.00000000,0.00000000,0.00000000,0.00000000
174.58000000,4.07406500,2.55700000,0.13688478,231.24788558,0.12829187,262.90220101,0.00086630,0.13262380,266.90374137,-0.07859754,-0.05402625,0.00000000,0.00000000,0.00000000,0.00000000
176.08000000,4.11462000,2.56000000,0.13823889,231.51919714,0.12948223,263.52415371,0.00079339,0.13385391,267.54602507,-0.07931784,-0.05453608,0.00000000,0.00000000,0.00000000,0.00000000
177.58000000,4.15530900,2.56300000,0.13964889,231.79050870,0.13072022,264.15979569,0.00087083,0.13502258,268.06865649,-0.08000407,-0.05501851,0.00000000,0.00000000,0.00000000,0.00000000
179.08000000,4.19619900,2.56500000,0.14099922,231.97138307,0.13190439,264.67916766,0.00078485,0.13624480,268.60659122,-0.08072171,-0.05552309,0.00000000,0.00000000,0.00000000,0.00000000
180.58000000,4.23718900,2.56800000,0.14237933,232.24269463,0.13311322,265.30925466,0.00075101,0.13749624,269.25789750,-0.08144259,-0.05605365,0.00000000,0.00000000,0.00000000,0.00000000
182.08000000,4.27851600,2.57100000,0.14380800,232.51400619,0.13436305,265.95138039,0.00083501,0.13872508,269.79961525,-0.08216893,-0.05655616,0.00000000,0.00000000,0.00000000,0.00000000
183.58000000,4.31960800,2.57300000,0.14520689,232.69488056,0.13558531,266.48378023,0.00085359,0.13994271,270.33922090,-0.08288414,-0.05705858,0.00000000,0.00000000,0.00000000,0.00000000
185.08000000,4.36056600,2.57600000,0.14656467,232.96619212,0.13677023,267.11080441,0.00077444,0.14121341,270.89417843,-0.08363314,-0.05758027,0.00000000,0.00000000,0.00000000,0.00000000
186.58000000,4.40179200,2.57800000,0.14796344,233.14706649,0.13798945,267.64430951,0.00073458,0.14245359,271.44180140,-0.08434601,-0.05810758,0.00000000,0.00000000,0.00000000,0.00000000
188.08000000,4.44278300,2.58100000,0.14933989,233.41837805,0.13918777,268.27705269,0.00077915,0.14372114,271.99784761,-0.08509392,-0.05862722,0.00000000,0.00000000,0.00000000,0.00000000
189.58000000,4.48491500,2.58300000,0.15077978,233.59925242,0.14043978,268.82129579,0.00082357,0.14499336,272.55615056,-0.08580633,-0.05918703,0.00000000,0.00000000,0.00000000,0.00000000
191.08000000,4.52721500,2.58500000,0.15220844,233.78012680,0.14168049,269.36343624,0.00078377,0.14627679,273.11851624,-0.08656687,-0.05970993,0.00000000,0.00000000,0.00000000,0.00000000
192.58000000,4.56877800,2.58700000,0.15365944,233.96100117,0.14293902,269.91131863,0.00082788,0.14755846,273.68139824,-0.08734072,-0.06021774,0.00000000,0.00000000,0.00000000,0.00000000
194.08000000,4.61077500,2.59000000,0.15506944,234.23231273,0.14416047,270.55458734,0.00082032,0.14884003,274.13949160,-0.08810227,-0.06073777,0.00000000,0.00000000,0.00000000,0.00000000
195.58000000,4.65310900,2.59200000,0.15653544,234.41318710,0.14542885,271.10715953,0.00080006,0.15011846,274.70334903,-0.08884894,-0.06126952,0.00000000,0.00000000,0.00000000,0.00000000
197.08000000,4.69524200,2.59400000,0.15800133,234.59406147,0.14669553,271.66023598,0.00083763,0.15139201,275.26685857,-0.08959091,-0.06180109,0.00000000,0.00000000,0.00000000,0.00000000
198.58000000,4.73781100,2.59600000,0.15947856,234.77493585,0.14797038,272.21650350,0.00083657,0.15263047,275.71547927,-0.09030552,-0.06232496,0.00000000,0.00000000,0.00000000,0.00000000
200.08000000,4.78021200,2.59700000,0.16094078,234.86537303,0.14923069,272.66478884,0.00079702,0.15392942,276.28787199,-0.09106940,-0.06286001,0.00000000,0.00000000,0.00000000,0.00000000
201.58000000,4.82418900,2.59900000,0.16248133,235.04624741,0.15055680,273.23687508,0.00086653,0.15522804,276.75475544,-0.09182508,-0.06340296,0.00000000,0.00000000,0.00000000,0.00000000
203.08000000,4.86779900,2.60100000,0.16396967,235.22712178,0.15183629,273.79723453,0.00084633,0.15649189,277.31929742,-0.09256025,-0.06393164,0.00000000,0.00000000,0.00000000,0.00000000
204.58000000,4.91033500,2.60300000,0.16543933,235.40799615,0.15309813,274.35373810,0.00079395,0.15778724,277.78689530,-0.09331005,-0.06447719,0.00000000,0.00000000,0.00000000,0.00000000
206.08000000,4.95350800,2.60400000,0.16694267,235.49843334,0.15438722,274.81316980,0.00079940,0.15908081,278.25474356,-0.09407937,-0.06500143,0.00000000,0.00000000,0.00000000,0.00000000
207.58000000,4.99701700,2.60600000,0.16844589,235.67930771,0.15567457,275.37851819,0.00081112,0.16034122,278.71406563,-0.09481107,-0.06553015,0.00000000,0.00000000,0.00000000,0.00000000
209.08000000,5.04113000,2.60800000,0.16998644,235.86018208,0.15699216,275.95321582,0.00095675,0.16159843,279.28034904,-0.09551553,-0.06608289,0.00000000,0.00000000,0.00000000,0.00000000
210.58000000,5.08480600,2.60900000,0.17147856,235.95061927,0.15826667,276.41109065,0.00089176,0.16291857,279.75802423,-0.09631325,-0.06660532,0.00000000,0.00000000,0.00000000,0.00000000
212.08000000,5.12902000,2.61100000,0.17297067,236.13149364,0.15953956,276.97531552,0.00082713,0.16423686,280.23595650,-0.09705280,-0.06718407,0.00000000,0.00000000,0.00000000,0.00000000
213.58000000,5.17377200,2.61200000,0.17446267,236.22193083,0.16081074,277.43383881,0.00082589,0.16558478,280.72301809,-0.09782025,-0.06776453,0.00000000,0.00000000,0.00000000,0.00000000
215.08000000,5.21842200,2.61300000,0.17602944,236.31236802,0.16214389,277.91030287,0.00088831,0.16693087,281.21036981,-0.09858231,-0.06834856,0.00000000,0.00000000,0.00000000,0.00000000
216.58000000,5.26233400,2.61500000,0.17748422,236.49324239,0.16338015,278.46706157,0.00076052,0.16833611,281.82313379,-0.09942880,-0.06890731,0.00000000,0.00000000,0.00000000,0.00000000
218.08000000,5.30681700,2.61600000,0.17905089,236.58367958,0.16470978,278.94419770,0.00088603,0.16974238,282.22131527,-0.10019558,-0.06954681,0.00000000,0.00000000,0.00000000,0.00000000
219.58000000,5.35183700,2.61700000,0.18058022,236.67411676,0.16600603,279.41278136,0.00094816,0.17117645,282.73612924,-0.10105377,-0.07012268,0.00000000,0.00000000,0.00000000,0.00000000
221.08000000,5.39581700,2.61900000,0.18210967,236.85499113,0.16730070,279.98857462,0.00088374,0.17263942,283.26006369,-0.10187740,-0.07076202,0.00000000,0.00000000,0.00000000,0.00000000
222.58000000,5.44056900,2.62000000,0.18367633,236.94542832,0.16862513,280.46669579,0.00088257,0.17412991,283.90127836,-0.10272928,-0.07140063,0.00000000,0.00000000,0.00000000,0.00000000
224.08000000,5.48642900,2.62100000,0.18528033,237.03586551,0.16997931,280.95394968,0.00088137,0.17571431,284.35325824,-0.10366219,-0.07205212,0.00000000,0.00000000,0.00000000,0.00000000
225.58000000,5.53111300,2.62200000,0.18688433,237.12630269,0.17133167,281.44149369,0.00088018,0.17726364,284.90477977,-0.10453529,-0.07272835,0.00000000,0.00000000,0.00000000,0.00000000
227.08000000,5.57724000,2.62300000,0.18856289,237.21673988,0.17274492,281.94701364,0.00087894,0.17884142,285.46548859,-0.10547318,-0.07336824,0.00000000,0.00000000,0.00000000,0.00000000
228.58000000,5.62320200,2.62400000,0.19024156,237.30717707,0.17415627,282.45286358,0.00087789,0.18048005,285.93553885,-0.10641490,-0.07406515,0.00000000,0.00000000,0.00000000,0.00000000
230.08000000,5.66909400,2.62500000,0.19195744,237.39761425,0.17559687,282.96785360,0.00087644,0.18211599,286.40558911,-0.10733149,-0.07478450,0.00000000,0.00000000,0.00000000,0.00000000
231.58000000,5.71606000,2.62500000,0.19378522,237.39761425,0.17712912,283.40176369,0.00100024,0.18380932,287.00251850,-0.10831826,-0.07549106,0.00000000,0.00000000,0.00000000,0.00000000
233.08000000,5.76319600,2.62600000,0.19561300,237.48805144,0.17865902,283.94380165,0.00106101,0.18549976,287.59981899,-0.10928639,-0.07621336,0.00000000,0.00000000,0.00000000,0.00000000
234.58000000,5.81113700,2.62700000,0.19747811,237.57848863,0.18021777,284.49503980,0.00099697,0.18725008,288.10570637,-0.11028174,-0.07696834,0.00000000,0.00000000,0.00000000,0.00000000
236.08000000,5.85860800,2.62800000,0.19938056,237.66892581,0.18180522,285.05548828,0.00105768,0.18899587,288.72131674,-0.11129521,-0.07770066,0.00000000,0.00000000,0.00000000,0.00000000
237.58000000,5.90634800,2.62900000,0.20128300,237.75936300,0.18339015,285.61628086,0.00105619,0.19074013,289.22742285,-0.11225833,-0.07848181,0.00000000,0.00000000,0.00000000,0.00000000
239.08000000,5.95522900,2.62900000,0.20329722,237.75936300,0.18506547,286.09518105,0.00111632,0.19251188,289.74241544,-0.11323234,-0.07927954,0.00000000,0.00000000,0.00000000,0.00000000
240.58000000,6.00491600,2.63000000,0.20531156,237.84980018,0.18673809,286.68311265,0.00117644,0.19434135,290.27515454,-0.11428377,-0.08005758,0.00000000,0.00000000,0.00000000,0.00000000
242.08000000,6.05483800,2.63100000,0.20732589,237.94023737,0.18840790,287.27140859,0.00111259,0.00000000,0.00000000,0.00000000,0.00000000,0.00000000,0.00000000,0.00000000,0.00000000
243.58000000,6.10512900,2.63100000,0.20937756,237.94023737,0.19010581,287.75958264,0.00111071,0.00000000,0.00000000,0.00000000,0.00000000,0.00000000,0.00000000,0.00000000,0.00000000
245.08000000,6.15585600,2.63100000,0.21154100,237.94023737,0.19189310,288.27435312,0.00117039,0.00000000,0.00000000,0.00000000,0.00000000,0.00000000,0.00000000,0.00000000,0.00000000
246.58000000,6.20688600,2.63200000,0.21366722,238.03067456,0.19364654,288.89002759,0.00116833,0.00000000,0.00000000,0.00000000,0.00000000,0.00000000,0.00000000,0.00000000,0.00000000
248.08000000,6.25858600,2.63200000,0.21583078,238.03067456,0.19542761,289.40502018,0.00122770,0.00000000,0.00000000,0.00000000,0.00000000,0.00000000,0.00000000,0.00000000,0.00000000
249.58000000,6.31042100,2.63200000,0.21803156,238.03067456,0.19723608,289.92887280,0.00131290,0.00000000,0.00000000,0.00000000,0.00000000,0.00000000,0.00000000,0.00000000,0.00000000
251.08000000,6.36212300,2.63300000,0.22019511,238.12111174,0.19901077,290.55421640,0.00116208,0.00000000,0.00000000,0.00000000,0.00000000,0.00000000,0.00000000,0.00000000,0.00000000
252.58000000,6.41580400,2.63300000,0.22250789,238.12111174,0.00000000,0.00000000,0.00000000,0.00000000,0.00000000,0.00000000,0.00000000,0.00000000,0.00000000,0.00000000,0.00000000
254.08000000,6.46931700,2.63300000,0.22485789,238.12111174,0.00000000,0.00000000,0.00000000,0.00000000,0.00000000,0.00000000,0.00000000,0.00000000,0.00000000,0.00000000,0.00000000
255.58000000,6.52326800,2.63300000,0.22720800,238.12111174,0.00000000,0.00000000,0.00000000,0.00000000,0.00000000,0.00000000,0.00000000,0.00000000,0.00000000,0.00000000,0.00000000
257.08000000,6.57738500,2.63300000,0.22966989,238.12111174,0.00000000,0.00000000,0.00000000,0.00000000,0.00000000,0.00000000,0.00000000,0.00000000,0.00000000,0.00000000,0.00000000
258.58000000,6.63170600,2.63200000,0.23228111,238.03067456,0.00000000,0.00000000,0.00000000,0.00000000,0.00000000,0.00000000,0.00000000,0.00000000,0.00000000,0.00000000,0.00000000
260.08000000,6.68615900,2.63200000,0.23504144,238.03067456,0.00000000,0.00000000,0.00000000,0.00000000,0.00000000,0.00000000,0.00000000,0.00000000,0.00000000,0.00000000,0.00000000
261.58000000,6.74145100,2.63100000,0.23802556,237.94023737,0.00000000,0.00000000,0.00000000,0.00000000,0.00000000,0.00000000,0.00000000,0.00000000,0.00000000,0.00000000,0.00000000
263.08000000,6.79624100,2.63000000,0.24119622,237.84980018,0.00000000,0.00000000,0.00000000,0.00000000,0.00000000,0.00000000,0.00000000,0.00000000,0.00000000,0.00000000,0.00000000
264.58000000,6.85375000,2.62900000,0.24485178,237.75936300,0.00000000,0.00000000,0.00000000,0.00000000,0.00000000,0.00000000,0.00000000,0.00000000,0.00000000,0.00000000,0.00000000
266.08000000,6.91028500,2.62700000,0.24880578,237.57848863,0.00000000,0.00000000,0.00000000,0.00000000,0.00000000,0.00000000,0.00000000,0.00000000,0.00000000,0.00000000,0.00000000
267.58000000,6.96745700,2.62600000,0.25305833,237.48805144,0.00000000,0.00000000,0.00000000,0.00000000,0.00000000,0.00000000,0.00000000,0.00000000,0.00000000,0.00000000,0.00000000
269.08000000,7.02469700,2.62300000,0.25760944,237.21673988,0.00000000,0.00000000,0.00000000,0.00000000,0.00000000,0.00000000,0.00000000,0.00000000,0.00000000,0.00000000,0.00000000
270.58000000,7.08297700,2.61800000,0.26257089,236.76455395,0.00000000,0.00000000,0.00000000,0.00000000,0.00000000,0.00000000,0.00000000,0.00000000,0.00000000,0.00000000,0.00000000
272.08000000,7.14239700,2.61100000,0.26783156,236.13149364,0.00000000,0.00000000,0.00000000,0.00000000,0.00000000,0.00000000,0.00000000,0.00000000,0.00000000,0.00000000,0.00000000
273.58000000,7.20164700,2.59900000,0.27342967,235.04624741,0.00000000,0.00000000,0.00000000,0.00000000,0.00000000,0.00000000,0.00000000,0.00000000,0.00000000,0.00000000,0.00000000
275.08000000,7.26368000,2.57700000,0.27970378,233.05662931,0.00000000,0.00000000,0.00000000,0.00000000,0.00000000,0.00000000,0.00000000,0.00000000,0.00000000,0.00000000,0.00000000
276.58000000,7.33145400,2.53100000,0.28707122,228.89651873,0.00000000,0.00000000,0.00000000,0.00000000,0.00000000,0.00000000,0.00000000,0.00000000,0.00000000,0.00000000,0.00000000
278.08000000,7.44068600,2.08800000,0.30104700,188.83284517,0.00000000,0.00000000,0.00000000,0.00000000,0.00000000,0.00000000,0.00000000,0.00000000,0.00000000,0.00000000,0.00000000
279.58000000,7.52620200,1.81100000,0.31177022,163.78174454,0.00000000,0.00000000,0.00000000,0.00000000,0.00000000,0.00000000,0.00000000,0.00000000,0.00000000,0.00000000,0.00000000
281.08000000,7.63621400,1.41000000,0.32654300,127.51643280,0.00000000,0.00000000,0.00000000,0.00000000,0.00000000,0.00000000,0.00000000,0.00000000,0.00000000,0.00000000,0.00000000
282.58000000,7.71259800,1.25400000,0.33596500,113.40823172,0.00000000,0.00000000,0.00000000,0.00000000,0.00000000,0.00000000,0.00000000,0.00000000,0.00000000,0.00000000,0.00000000
284.08000000,7.83727200,0.93300000,0.35247178,84.37789489,0.00000000,0.00000000,0.00000000,0.00000000,0.00000000,0.00000000,0.00000000,0.00000000,0.00000000,0.00000000,0.00000000
285.58000000,7.96998200,0.00000000,0.36726611,0.00000000,0.00000000,0.00000000,0.00000000,0.00000000,0.00000000,0.00000000,0.00000000,0.00000000,0.00000000,0.00000000,0.00000000
NaN,-100.00000000,NaN,-11.11111111,NaN,0.00000000,0.00000000,0.00000000,0.00000000,0.00000000,0.00000000,0.00000000,0.00000000,0.00000000,0.00000000,0.00000000