File: lab_data/AA6014-T4_results/DATA/UT_15_3.csv
Time[s],Displacement[mm],Force[kN],EngStrain_longi,EngStress[MPa],TrueStrain,TrueStress[MPa],TrueStrainRate[1/s],PlasticStrain_longi,PlasticStress[MPa],PlasticStrain_thick,PlasticStrain_width,R-Value,Thickness[mm],Width[mm], Young's Modulus [MPa]
0.60000000,0.00000000,-0.00100000,0.00000000,-0.09060458,0.00000000,-0.09060458,0.00000000,0.00091082,120.45534038,-0.00017084,-0.00073998,0.69401355,1.10960000,9.94680000,75391.39736552
2.10000000,0.00612000,0.16700000,0.00018489,15.13096537,0.00018487,15.13376292,0.00011176,0.00200992,125.05201141,-0.00083138,-0.00117854,0.00000000,0.00000000,0.00000000,0.00000000
3.60000000,0.01366700,0.41900000,0.00043311,37.96332031,0.00043302,37.97976264,0.00006486,0.00324526,128.76463643,-0.00166794,-0.00157733,0.00000000,0.00000000,0.00000000,0.00000000
5.11000000,0.02259100,0.65900000,0.00076578,59.70842024,0.00076548,59.75414363,0.00024993,0.00445196,131.75204904,-0.00236045,-0.00209151,0.00000000,0.00000000,0.00000000,0.00000000
6.61000000,0.03188300,0.90500000,0.00106167,81.99714768,0.00106110,82.08420132,0.00034433,0.00562178,134.46737726,-0.00308801,-0.00253377,0.00000000,0.00000000,0.00000000,0.00000000
8.11000000,0.04337800,1.15600000,0.00137944,104.73889803,0.00137849,104.88337952,0.00032072,0.00684359,137.19623653,-0.00385247,-0.00299113,0.00000000,0.00000000,0.00000000,0.00000000
9.61000000,0.06657000,1.30300000,0.00212178,118.05777174,0.00211953,118.30826410,0.00050788,0.00805936,139.65583520,-0.00462213,-0.00343723,0.00000000,0.00000000,0.00000000,0.00000000
11.10000000,0.10140100,1.36200000,0.00336578,123.40344214,0.00336013,123.81879071,0.00077486,0.00920976,142.02026684,-0.00533983,-0.00386993,0.00000000,0.00000000,0.00000000,0.00000000
12.61000000,0.13884700,1.40300000,0.00462478,127.11823005,0.00461412,127.70612362,0.00090018,0.01033603,144.47854384,-0.00600908,-0.00432695,0.00000000,0.00000000,0.00000000,0.00000000
14.10000000,0.17540400,1.43500000,0.00582889,130.01757671,0.00581197,130.77543472,0.00093566,0.01151279,146.67368376,-0.00677597,-0.00473682,0.00000000,0.00000000,0.00000000,0.00000000
15.60000000,0.21342400,1.46400000,0.00707100,132.64510962,0.00704612,133.58304319,0.00078936,0.01268441,148.87316321,-0.00743474,-0.00524967,0.00000000,0.00000000,0.00000000,0.00000000
17.11000000,0.25077600,1.49300000,0.00844744,135.27264253,0.00841196,136.41535066,0.00099011,0.01381066,151.07086430,-0.00808487,-0.00572579,0.00000000,0.00000000,0.00000000,0.00000000
18.60000000,0.28912900,1.51900000,0.00970756,137.62836169,0.00966074,138.96439665,0.00105317,0.01495129,153.18330867,-0.00873846,-0.00621283,0.00000000,0.00000000,0.00000000,0.00000000
20.10000000,0.32501100,1.54300000,0.01087700,139.80287168,0.01081827,141.32350752,0.00087842,0.01613937,155.21540489,-0.00947884,-0.00666053,0.00000000,0.00000000,0.00000000,0.00000000
21.61000000,0.36123100,1.56600000,0.01213444,141.88677709,0.01206141,143.60849431,0.00084204,0.01727709,157.33688983,-0.01012874,-0.00714835,0.00000000,0.00000000,0.00000000,0.00000000
23.10000000,0.39773400,1.59000000,0.01332811,144.06128709,0.01324007,145.98135193,0.00089845,0.01836875,159.27036998,-0.01075466,-0.00761409,0.00000000,0.00000000,0.00000000,0.00000000
24.60000000,0.43353900,1.61200000,0.01449567,146.05458791,0.01439161,148.17174653,0.00084592,0.01949176,161.21305609,-0.01143047,-0.00806129,0.00000000,0.00000000,0.00000000,0.00000000
26.10000000,0.46945100,1.63500000,0.01568189,148.13849332,0.01556020,150.46158472,0.00070529,0.02062064,163.16097481,-0.01209256,-0.00852808,0.00000000,0.00000000,0.00000000,0.00000000
27.60000000,0.50521200,1.65600000,0.01689422,150.04118957,0.01675310,152.57601877,0.00070445,0.02177855,165.02496737,-0.01281325,-0.00896530,0.00000000,0.00000000,0.00000000,0.00000000
29.10000000,0.54107000,1.67600000,0.01809156,151.85328123,0.01792985,154.60054330,0.00079162,0.02285156,166.87895602,-0.01344206,-0.00940950,0.00000000,0.00000000,0.00000000,0.00000000
30.60000000,0.57654500,1.69600000,0.01926289,153.66537289,0.01907971,156.62541190,0.00076148,0.02397631,168.83882910,-0.01412963,-0.00984668,0.00000000,0.00000000,0.00000000,0.00000000
32.10000000,0.61201400,1.71600000,0.02043789,155.47746455,0.02023184,158.65509570,0.00070919,0.02508429,170.61343074,-0.01480016,-0.01028413,0.00000000,0.00000000,0.00000000,0.00000000
33.60000000,0.64691600,1.73500000,0.02161667,157.19895163,0.02138634,160.59706897,0.00072317,0.02619214,172.29836414,-0.01546915,-0.01072299,0.00000000,0.00000000,0.00000000,0.00000000
35.10000000,0.68191500,1.75500000,0.02277678,159.01104329,0.02252126,162.63280249,0.00073691,0.02730467,174.08128895,-0.01616310,-0.01114157,0.00000000,0.00000000,0.00000000,0.00000000
36.60000000,0.71769900,1.77200000,0.02392933,160.55132120,0.02364751,164.39320729,0.00071415,0.02835803,175.85762894,-0.01676561,-0.01159243,0.00000000,0.00000000,0.00000000,0.00000000
38.10000000,0.75231500,1.79100000,0.02513056,162.27280828,0.02481998,166.35081411,0.00073522,0.02947412,177.46121257,-0.01747090,-0.01200322,0.00000000,0.00000000,0.00000000,0.00000000
39.60000000,0.78743200,1.80800000,0.02630178,163.81308620,0.02596183,168.12166159,0.00073416,0.03060789,179.25919189,-0.01811151,-0.01249638,0.00000000,0.00000000,0.00000000,0.00000000
41.10000000,0.82261500,1.82700000,0.02746189,165.53457327,0.02709158,170.08046533,0.00076968,0.03172127,180.86940657,-0.01878288,-0.01293839,0.00000000,0.00000000,0.00000000,0.00000000
42.60000000,0.85729500,1.84300000,0.02864067,166.98424660,0.02823819,171.76678675,0.00076902,0.03282031,182.38632419,-0.01943690,-0.01338341,0.00000000,0.00000000,0.00000000,0.00000000
44.10000000,0.89217600,1.86100000,0.02979333,168.61512910,0.02935813,173.63873584,0.00073923,0.03389392,184.09016794,-0.02004610,-0.01384783,0.00000000,0.00000000,0.00000000,0.00000000
45.60000000,0.92675600,1.87600000,0.03094600,169.97419784,0.03047683,175.23421937,0.00072395,0.03499755,185.61448449,-0.02071267,-0.01428488,0.00000000,0.00000000,0.00000000,0.00000000
47.10000000,0.96140200,1.89200000,0.03210611,171.42387117,0.03160148,176.92762503,0.00075933,0.03610700,187.14310327,-0.02133648,-0.01477052,0.00000000,0.00000000,0.00000000,0.00000000
48.60000000,0.99675300,1.90900000,0.03328111,172.96414909,0.03273928,178.72058815,0.00079439,0.03720220,188.57771474,-0.02198883,-0.01521337,0.00000000,0.00000000,0.00000000,0.00000000
50.10000000,1.03126500,1.92400000,0.03445233,174.32321783,0.03387214,180.32905944,0.00072128,0.03830904,190.11216996,-0.02264438,-0.01566466,0.00000000,0.00000000,0.00000000,0.00000000
51.60000000,1.06624800,1.93900000,0.03563489,175.68228658,0.03501466,181.94270534,0.00074944,0.03941239,191.55443088,-0.02329467,-0.01611772,0.00000000,0.00000000,0.00000000,0.00000000
53.10000000,1.10076000,1.95400000,0.03678000,177.04135532,0.03611976,183.55293637,0.00071237,0.04051311,193.09405872,-0.02393273,-0.01658037,0.00000000,0.00000000,0.00000000,0.00000000
54.60000000,1.13577500,1.96900000,0.03793644,178.40042407,0.03723455,185.16830185,0.00071886,0.04158534,194.53638206,-0.02458384,-0.01700150,0.00000000,0.00000000,0.00000000,0.00000000
56.10000000,1.17042200,1.98200000,0.03908911,179.57828365,0.03834447,186.59783913,0.00072534,0.04268606,195.89215399,-0.02522436,-0.01746170,0.00000000,0.00000000,0.00000000,0.00000000
57.60000000,1.20503400,1.99600000,0.04026411,180.84674781,0.03947463,188.12838136,0.00073884,0.04378786,197.34612852,-0.02578196,-0.01800590,0.00000000,0.00000000,0.00000000,0.00000000
59.10000000,1.24018500,2.01000000,0.04145400,182.11521198,0.04061781,189.66461597,0.00079520,0.04487892,198.70569408,-0.02656370,-0.01831521,0.00000000,0.00000000,0.00000000,0.00000000
60.60000000,1.27523400,2.02300000,0.04262156,183.29307156,0.04173827,191.10530739,0.00078727,0.04597589,200.06922994,-0.02721474,-0.01876115,0.00000000,0.00000000,0.00000000,0.00000000
62.10000000,1.31028300,2.03700000,0.04378544,184.56153572,0.04285396,192.64264459,0.00073634,0.04710823,201.34720106,-0.02793716,-0.01917107,0.00000000,0.00000000,0.00000000,0.00000000
63.60000000,1.34529900,2.05000000,0.04496044,185.73939530,0.04397903,194.09032106,0.00075700,0.04817080,202.70930175,-0.02852675,-0.01964406,0.00000000,0.00000000,0.00000000,0.00000000
65.10000000,1.37964300,2.06200000,0.04610567,186.82665030,0.04507438,195.44041756,0.00071325,0.04930409,203.99286132,-0.02919949,-0.02010459,0.00000000,0.00000000,0.00000000,0.00000000
66.60000000,1.41442400,2.07500000,0.04726944,188.00450988,0.04618625,196.89137861,0.00079800,0.05039011,205.26938762,-0.02983801,-0.02055210,0.00000000,0.00000000,0.00000000,0.00000000
68.10000000,1.44994300,2.08700000,0.04845944,189.09176487,0.04732189,198.25504675,0.00076868,0.05149608,206.55262416,-0.03050698,-0.02098910,0.00000000,0.00000000,0.00000000,0.00000000
69.60000000,1.48448900,2.09800000,0.04961956,190.08841529,0.04842777,199.52051797,0.00069667,0.05259027,207.83604062,-0.03112125,-0.02146902,0.00000000,0.00000000,0.00000000,0.00000000
71.10000000,1.52010900,2.11100000,0.05083189,191.26627487,0.04958213,200.98870090,0.00078831,0.05369847,209.02883485,-0.03175944,-0.02193902,0.00000000,0.00000000,0.00000000,0.00000000
72.60000000,1.55465400,2.12200000,0.05196211,192.26292528,0.05065710,202.25331277,0.00069512,0.05480547,210.22380732,-0.03241625,-0.02238923,0.00000000,0.00000000,0.00000000,0.00000000
74.10000000,1.59091300,2.13300000,0.05315211,193.25957569,0.05178768,203.53173013,0.00070151,0.05593573,211.42614091,-0.03309522,-0.02284051,0.00000000,0.00000000,0.00000000,0.00000000
75.60000000,1.62596200,2.14400000,0.05436444,194.25622611,0.05293816,204.81685792,0.00077155,0.05703658,212.62469337,-0.03372600,-0.02331058,0.00000000,0.00000000,0.00000000,0.00000000
77.10000000,1.66037400,2.15500000,0.05550589,195.25287652,0.05402017,206.09056099,0.00071406,0.05813397,213.72831810,-0.03436939,-0.02376458,0.00000000,0.00000000,0.00000000,0.00000000
78.60000000,1.69572500,2.16500000,0.05666600,196.15892235,0.05511867,207.27446385,0.00072737,0.05923935,214.93258465,-0.03504553,-0.02419382,0.00000000,0.00000000,0.00000000,0.00000000
80.10000000,1.73117800,2.17600000,0.05786344,197.15557277,0.05625126,208.56367330,0.00071246,0.06036216,216.04624327,-0.03572003,-0.02464214,0.00000000,0.00000000,0.00000000,0.00000000
81.60000000,1.76693300,2.18700000,0.05908322,198.15222318,0.05740365,209.85969502,0.00080316,0.06147670,217.16036346,-0.03636585,-0.02511084,0.00000000,0.00000000,0.00000000,0.00000000
83.10000000,1.80241900,2.19600000,0.06025822,198.96766443,0.05851248,210.95710217,0.00073895,0.06260040,218.27874255,-0.03708762,-0.02551278,0.00000000,0.00000000,0.00000000,0.00000000
84.60000000,1.83840900,2.20600000,0.06144078,199.87371026,0.05962721,212.15410647,0.00071697,0.06367056,219.38761269,-0.03768361,-0.02598695,0.00000000,0.00000000,0.00000000,0.00000000
86.10000000,1.87423100,2.21600000,0.06266800,200.77975609,0.06078273,213.36222184,0.00077242,0.06480692,220.41600901,-0.03838242,-0.02642450,0.00000000,0.00000000,0.00000000,0.00000000
87.60000000,1.90991800,2.22500000,0.06385056,201.59519734,0.06189493,214.46716268,0.00079267,0.06591967,221.53863221,-0.03903217,-0.02688751,0.00000000,0.00000000,0.00000000,0.00000000
89.10000000,1.94547200,2.23500000,0.06504056,202.50124317,0.06301288,215.67203652,0.00077070,0.06705687,222.57147672,-0.03970411,-0.02735276,0.00000000,0.00000000,0.00000000,0.00000000
90.60000000,1.98152900,2.24400000,0.06626033,203.31668442,0.06415751,216.78851570,0.00076982,0.06816146,223.59910153,-0.04029690,-0.02786457,0.00000000,0.00000000,0.00000000,0.00000000
92.10000000,2.01755300,2.25300000,0.06747644,204.13212566,0.06529740,217.90623570,0.00080393,0.06928899,224.63392307,-0.04103092,-0.02825807,0.00000000,0.00000000,0.00000000,0.00000000
93.60000000,2.05374400,2.26100000,0.06866267,204.85696233,0.06640802,218.92298765,0.00069819,0.07042219,225.67210778,-0.04171759,-0.02870460,0.00000000,0.00000000,0.00000000,0.00000000
95.10000000,2.08943200,2.27100000,0.06984889,205.76300816,0.06751741,220.13532565,0.00069056,0.07153456,226.60970267,-0.04235115,-0.02918341,0.00000000,0.00000000,0.00000000,0.00000000
96.60000000,2.12565600,2.27800000,0.07110600,206.39724024,0.06869176,221.07332240,0.00075243,0.07266171,227.65056546,-0.04302976,-0.02963195,0.00000000,0.00000000,0.00000000,0.00000000
98.10000000,2.16228400,2.28700000,0.07231456,207.21268149,0.06981945,222.19717445,0.00077936,0.07378871,228.59530833,-0.04366939,-0.03011932,0.00000000,0.00000000,0.00000000,0.00000000
99.60000000,2.19850800,2.29500000,0.07349711,207.93751815,0.07092165,223.22032503,0.00074371,0.07491798,229.54243809,-0.04435384,-0.03056414,0.00000000,0.00000000,0.00000000,0.00000000
101.10000000,2.23540500,2.30300000,0.07474678,208.66235482,0.07208508,224.25919348,0.00073602,0.07604791,230.58999650,-0.04504702,-0.03100089,0.00000000,0.00000000,0.00000000,0.00000000
102.60000000,2.27179700,2.31100000,0.07596656,209.38719148,0.07321938,225.29361520,0.00079076,0.07716559,231.43978291,-0.04568585,-0.03147974,0.00000000,0.00000000,0.00000000,0.00000000
104.10000000,2.30808800,2.31900000,0.07718256,210.11202815,0.07434889,226.32901143,0.00076903,0.07830447,232.39477193,-0.04634545,-0.03195902,0.00000000,0.00000000,0.00000000,0.00000000
105.60000000,2.34532100,2.32600000,0.07842100,210.74626023,0.07549793,227.27319270,0.00080257,0.07942844,233.34817136,-0.04700564,-0.03242280,0.00000000,0.00000000,0.00000000,0.00000000
107.10000000,2.38194900,2.33300000,0.07964456,211.38049231,0.07663187,228.21579767,0.00077407,0.08058313,234.21181040,-0.04770029,-0.03288285,0.00000000,0.00000000,0.00000000,0.00000000
108.60000000,2.41857600,2.34100000,0.08087933,212.10532897,0.07777491,229.26026658,0.00080095,0.08170435,235.16822771,-0.04838708,-0.03331727,0.00000000,0.00000000,0.00000000,0.00000000
110.10000000,2.45510300,2.34800000,0.08209911,212.73956105,0.07890278,230.20528992,0.00079306,0.08285307,236.03395124,-0.04905521,-0.03379786,0.00000000,0.00000000,0.00000000,0.00000000
111.60000000,2.49206600,2.35500000,0.08333756,213.37379314,0.08004661,231.15584348,0.00078538,0.08398328,236.89697334,-0.04972346,-0.03425982,0.00000000,0.00000000,0.00000000,0.00000000
113.10000000,2.52936500,2.36200000,0.08459456,214.00802522,0.08120624,232.11193900,0.00075660,0.08511896,237.76297020,-0.05037451,-0.03474444,0.00000000,0.00000000,0.00000000,0.00000000
114.60000000,2.56653000,2.36800000,0.08582567,214.55165272,0.08234068,232.96569134,0.00073547,0.08623973,238.62708135,-0.05101284,-0.03522690,0.00000000,0.00000000,0.00000000,0.00000000
116.10000000,2.60339200,2.37500000,0.08708267,215.18588480,0.08349766,233.92484547,0.00078922,0.08737416,239.39658431,-0.05167808,-0.03569607,0.00000000,0.00000000,0.00000000,0.00000000
117.60000000,2.64055600,2.38200000,0.08831367,215.82011688,0.08462940,234.87998274,0.00075421,0.08854656,240.27636165,-0.05237768,-0.03616888,0.00000000,0.00000000,0.00000000,0.00000000
119.10000000,2.67839200,2.38800000,0.08956333,216.36374438,0.08577700,235.74200254,0.00078089,0.08968172,241.04909930,-0.05305361,-0.03662811,0.00000000,0.00000000,0.00000000,0.00000000
120.60000000,2.71555700,2.39400000,0.09082789,216.90737188,0.08693694,236.60861055,0.00075940,0.09081950,242.02372887,-0.05370575,-0.03711375,0.00000000,0.00000000,0.00000000,0.00000000
122.10000000,2.75258700,2.40100000,0.09204767,217.54160396,0.08805453,237.56580100,0.00073107,0.09196216,242.80145259,-0.05440401,-0.03755815,0.00000000,0.00000000,0.00000000,0.00000000
123.60000000,2.78965100,2.40600000,0.09329722,217.99462687,0.08919810,238.33292002,0.00071662,0.09310669,243.58111184,-0.05506385,-0.03804283,0.00000000,0.00000000,0.00000000,0.00000000
125.10000000,2.82741900,2.41200000,0.09459533,218.53825437,0.09038474,239.21095339,0.00080431,0.09423993,244.35948567,-0.05570603,-0.03853389,0.00000000,0.00000000,0.00000000,0.00000000
126.60000000,2.86552300,2.41800000,0.09585989,219.08188187,0.09153934,240.08304672,0.00078979,0.09540544,245.14726794,-0.05647733,-0.03892812,0.00000000,0.00000000,0.00000000,0.00000000
128.10000000,2.90339300,2.42300000,0.09712444,219.53490479,0.09269262,240.85711045,0.00081604,0.09656285,245.93456978,-0.05708136,-0.03948148,0.00000000,0.00000000,0.00000000,0.00000000
129.60000000,2.94065800,2.42800000,0.09838900,219.98792770,0.09384456,241.63231992,0.00076085,0.09773228,246.72636092,-0.05781662,-0.03991566,0.00000000,0.00000000,0.00000000,0.00000000
131.10000000,2.97849500,2.43400000,0.09967222,220.53155520,0.09501216,242.51242538,0.00080747,0.09884334,247.50518432,-0.05841507,-0.04042827,0.00000000,0.00000000,0.00000000,0.00000000
132.60000000,3.01656500,2.43900000,0.10092189,220.98457811,0.09614791,243.28675915,0.00077263,0.10002680,248.30349172,-0.05912422,-0.04090258,0.00000000,0.00000000,0.00000000,0.00000000
134.10000000,3.05426600,2.44400000,0.10218267,221.43760103,0.09729246,244.06468560,0.00073807,0.10118012,248.99486719,-0.05978812,-0.04139200,0.00000000,0.00000000,0.00000000,0.00000000
135.60000000,3.09263900,2.45000000,0.10348078,221.98122853,0.09846953,244.95201871,0.00074385,0.10234400,249.79124462,-0.06049868,-0.04184532,0.00000000,0.00000000,0.00000000,0.00000000
137.10000000,3.13074500,2.45400000,0.10476400,222.34364686,0.09963174,245.63725668,0.00079027,0.10347787,250.48041232,-0.06114254,-0.04233533,0.00000000,0.00000000,0.00000000,0.00000000
138.60000000,3.16978900,2.45900000,0.10605467,222.79666978,0.10079933,246.42529632,0.00076221,0.10466715,251.18480392,-0.06184060,-0.04282656,0.00000000,0.00000000,0.00000000,0.00000000
140.10000000,3.20819600,2.46400000,0.10736022,223.24969269,0.10197900,247.21782931,0.00078842,0.10585171,251.88933561,-0.06254658,-0.04330513,0.00000000,0.00000000,0.00000000,0.00000000
141.60000000,3.24643400,2.46900000,0.10865089,223.70271561,0.10314386,248.00821450,0.00081437,0.10702135,252.59141526,-0.06322136,-0.04379999,0.00000000,0.00000000,0.00000000,0.00000000
143.10000000,3.28504200,2.47300000,0.10992289,224.06513394,0.10429054,248.69502076,0.00080002,0.10817969,253.29193249,-0.06392284,-0.04425685,0.00000000,0.00000000,0.00000000,0.00000000
144.60000000,3.32375100,2.47800000,0.11121733,224.51815685,0.10545611,249.48846754,0.00078568,0.10936334,254.00020225,-0.06461119,-0.04475215,0.00000000,0.00000000,0.00000000,0.00000000
146.10000000,3.36289700,2.48300000,0.11253789,224.97117977,0.10664379,250.28896140,0.00077136,0.11053875,254.70769792,-0.06531525,-0.04522350,0.00000000,0.00000000,0.00000000,0.00000000
147.60000000,3.40167200,2.48600000,0.11385456,225.24299352,0.10782657,250.88793444,0.00078382,0.11167969,255.40768437,-0.06594476,-0.04573494,0.00000000,0.00000000,0.00000000,0.00000000
149.10000000,3.44112000,2.49100000,0.11516389,225.69601643,0.10900138,251.68804739,0.00082975,0.11290015,256.02722143,-0.06668320,-0.04621695,0.00000000,0.00000000,0.00000000,0.00000000
150.60000000,3.48019900,2.49500000,0.11647322,226.05843477,0.11017481,252.38818907,0.00074853,0.11410437,256.74601047,-0.06740715,-0.04669723,0.00000000,0.00000000,0.00000000,0.00000000
152.10000000,3.51917500,2.49900000,0.11782356,226.42085310,0.11138354,253.09856306,0.00083433,0.11525108,257.45131137,-0.06804798,-0.04720310,0.00000000,0.00000000,0.00000000,0.00000000
153.60000000,3.55815300,2.50300000,0.11912911,226.78327143,0.11255080,253.79976097,0.00078668,0.11639787,258.05539622,-0.06873122,-0.04766665,0.00000000,0.00000000,0.00000000,0.00000000
155.10000000,3.59786800,2.50700000,0.12040111,227.14568976,0.11368676,254.49428319,0.00073916,0.11759265,258.67299515,-0.06942960,-0.04816305,0.00000000,0.00000000,0.00000000,0.00000000
156.60000000,3.63782000,2.51100000,0.12178511,227.50810810,0.11492127,255.21520832,0.00073844,0.11878274,259.29049102,-0.07010950,-0.04867324,0.00000000,0.00000000,0.00000000,0.00000000
158.10000000,3.67767000,2.51400000,0.12312800,227.77992184,0.11611765,255.82600806,0.00079061,0.11995673,260.00780453,-0.07084093,-0.04911580,0.00000000,0.00000000,0.00000000,0.00000000
159.60000000,3.71758700,2.51800000,0.12446344,228.14234018,0.11730598,256.53772166,0.00082960,0.12116681,260.63287245,-0.07153954,-0.04962727,0.00000000,0.00000000,0.00000000,0.00000000
161.10000000,3.75710200,2.52100000,0.12576156,228.41415393,0.11845974,257.13987323,0.00074907,0.12239511,261.26385997,-0.07226713,-0.05012798,0.00000000,0.00000000,0.00000000,0.00000000
162.60000000,3.79712000,2.52500000,0.12711933,228.77657226,0.11966512,257.85849761,0.00079451,0.12358745,261.78327921,-0.07296853,-0.05061892,0.00000000,0.00000000,0.00000000,0.00000000
164.10000000,3.83747400,2.52800000,0.12847344,229.04838601,0.12086579,258.47502110,0.00087295,0.12480144,262.51609202,-0.07368025,-0.05112118,0.00000000,0.00000000,0.00000000,0.00000000
165.60000000,3.87712400,2.53100000,0.12979400,229.32019976,0.12203532,259.08458576,0.00081900,0.12601216,263.14591148,-0.07441387,-0.05159829,0.00000000,0.00000000,0.00000000,0.00000000
167.10000000,3.91704000,2.53500000,0.13115167,229.68261809,0.12323629,259.80587626,0.00077832,0.12723915,263.67752341,-0.07510435,-0.05213480,0.00000000,0.00000000,0.00000000,0.00000000
168.60000000,3.95799800,2.53800000,0.13252822,229.95443184,0.12445250,260.42988388,0.00080387,0.12848585,264.31907510,-0.07583775,-0.05264810,0.00000000,0.00000000,0.00000000,0.00000000
170.10000000,3.99902300,2.54100000,0.13391578,230.22624559,0.12567693,261.05717233,0.00088837,0.12970511,264.95452702,-0.07656652,-0.05313859,0.00000000,0.00000000,0.00000000,0.00000000
171.60000000,4.03974700,2.54400000,0.13524756,230.49805934,0.12685074,261.67235842,0.00070325,0.13096319,265.49744046,-0.07732370,-0.05363949,0.00000000,0.00000000,0.00000000,0.00000000
173.10000000,4.08036900,2.54600000,0.13663144,230.67926850,0.12806901,262.19731016,0.00070239,0.13221493,266.14380139,-0.07806478,-0.05415015,0.00000000,0.00000000,0.00000000,0.00000000
174.60000000,4.12146100,2.55000000,0.13801533,231.04168684,0.12928581,262.92898226,0.00075409,0.13339849,266.66880423,-0.07874085,-0.05465765,0.00000000,0.00000000,0.00000000,0.00000000
176.10000000,4.16245200,2.55200000,0.13942911,231.22289600,0.13052736,263.46209886,0.00083822,0.13462139,267.30967729,-0.07944312,-0.05517826,0.00000000,0.00000000,0.00000000,0.00000000
177.60000000,4.20455300,2.55500000,0.14085778,231.49470975,0.13178042,264.10254013,0.00073896,0.13583122,267.84364466,-0.08015463,-0.05567659,0.00000000,0.00000000,0.00000000,0.00000000
179.10000000,4.24604900,2.55800000,0.14232011,231.76652350,0.13306138,264.75156088,0.00090149,0.13705880,268.38329959,-0.08088118,-0.05617762,0.00000000,0.00000000,0.00000000,0.00000000
180.60000000,4.28741000,2.56100000,0.14374133,232.03833725,0.13430476,265.39183723,0.00091339,0.13824625,268.91304852,-0.08154822,-0.05669802,0.00000000,0.00000000,0.00000000,0.00000000
182.10000000,4.32974400,2.56300000,0.14515133,232.21954642,0.13553680,265.92652320,0.00091227,0.13945975,269.55569113,-0.08228469,-0.05717506,0.00000000,0.00000000,0.00000000,0.00000000
183.60000000,4.37194400,2.56500000,0.14656878,232.40075558,0.13677381,266.46345028,0.00085898,0.14064439,270.08659452,-0.08296597,-0.05767842,0.00000000,0.00000000,0.00000000,0.00000000
185.10000000,4.41350800,2.56800000,0.14796022,232.67256933,0.13798665,267.09885439,0.00085794,0.14177613,270.60401233,-0.08362787,-0.05814826,0.00000000,0.00000000,0.00000000,0.00000000
186.60000000,4.45507100,2.57000000,0.14934422,232.85377850,0.13919154,267.62914494,0.00077915,0.14298675,271.14373276,-0.08434246,-0.05864429,0.00000000,0.00000000,0.00000000,0.00000000
188.10000000,4.49649900,2.57300000,0.15067589,233.12559225,0.14034950,268.25199808,0.00071990,0.14426967,271.70408826,-0.08514112,-0.05912855,0.00000000,0.00000000,0.00000000,0.00000000
189.60000000,4.53953800,2.57500000,0.15213433,233.30680141,0.14161616,268.80077611,0.00081604,0.14547232,272.13790626,-0.08585278,-0.05961954,0.00000000,0.00000000,0.00000000,0.00000000
191.10000000,4.58187300,2.57700000,0.15354811,233.48801058,0.14284251,269.33965357,0.00086033,0.14672176,272.79664918,-0.08657978,-0.06014198,0.00000000,0.00000000,0.00000000,0.00000000
192.60000000,4.62360400,2.57900000,0.15488733,233.66921974,0.14400279,269.86162207,0.00069783,0.14808745,273.27677782,-0.08739663,-0.06069083,0.00000000,0.00000000,0.00000000,0.00000000
194.10000000,4.66543500,2.58100000,0.15631222,233.85042891,0.14523582,270.40410912,0.00084539,0.14939868,273.84876793,-0.08819970,-0.06119898,0.00000000,0.00000000,0.00000000,0.00000000
195.60000000,4.70763500,2.58300000,0.15769244,234.03163808,0.14642875,270.93665916,0.00079926,0.15072097,274.42484177,-0.08894401,-0.06177696,0.00000000,0.00000000,0.00000000,0.00000000
197.10000000,4.75057400,2.58500000,0.15912489,234.21284724,0.14766531,271.48194054,0.00092064,0.15212252,274.91753892,-0.08975691,-0.06236561,0.00000000,0.00000000,0.00000000,0.00000000
198.60000000,4.79391600,2.58700000,0.16055733,234.39405641,0.14890035,272.02774106,0.00077162,0.15350782,275.51305280,-0.09054575,-0.06296207,0.00000000,0.00000000,0.00000000,0.00000000
200.10000000,4.83719300,2.58900000,0.16205689,234.57526558,0.15019161,272.58980332,0.00089899,0.15495292,276.01965465,-0.09140358,-0.06354934,0.00000000,0.00000000,0.00000000,0.00000000
201.60000000,4.88076900,2.59000000,0.16355278,234.66587016,0.15147806,273.04612507,0.00088503,0.15640704,276.63642985,-0.09224200,-0.06416504,0.00000000,0.00000000,0.00000000,0.00000000
203.10000000,4.92501800,2.59200000,0.16508589,234.84707932,0.15279481,273.61701817,0.00087738,0.15779735,277.12973703,-0.09305494,-0.06474241,0.00000000,0.00000000,0.00000000,0.00000000
204.60000000,4.96852600,2.59400000,0.16665622,235.02828849,0.15414173,274.19721517,0.00079940,0.15918570,277.62334164,-0.09383091,-0.06535479,0.00000000,0.00000000,0.00000000,0.00000000
206.10000000,5.01358100,2.59600000,0.16824167,235.20949766,0.15549977,274.78153556,0.00094542,0.16063519,278.13486010,-0.09470088,-0.06593431,0.00000000,0.00000000,0.00000000,0.00000000
207.60000000,5.05816700,2.59700000,0.16989800,235.30010224,0.15691657,275.27711901,0.00088042,0.16198655,278.72721068,-0.09555813,-0.06642842,0.00000000,0.00000000,0.00000000,0.00000000
209.10000000,5.10453100,2.59800000,0.17159156,235.39070682,0.15836313,275.78176437,0.00091084,0.16324319,279.18658621,-0.09623794,-0.06700524,0.00000000,0.00000000,0.00000000,0.00000000
210.60000000,5.14934900,2.60000000,0.17327011,235.57191599,0.15979482,276.38948805,0.00101774,0.16452974,279.65508009,-0.09702166,-0.06750808,0.00000000,0.00000000,0.00000000,0.00000000
212.10000000,5.19551100,2.60200000,0.17491133,235.75312516,0.16119268,276.98901861,0.00088915,0.16581453,280.12382487,-0.09779894,-0.06801558,0.00000000,0.00000000,0.00000000,0.00000000
213.60000000,5.24237800,2.60300000,0.17662733,235.84372974,0.16265215,277.50017881,0.00095134,0.16697246,280.55758528,-0.09850782,-0.06846465,0.00000000,0.00000000,0.00000000,0.00000000
215.10000000,5.28850700,2.60400000,0.17834322,235.93433432,0.16410940,278.01162374,0.00107657,0.16812905,280.99159580,-0.09915315,-0.06897590,0.00000000,0.00000000,0.00000000,0.00000000
216.60000000,5.33480300,2.60500000,0.17991000,236.02493890,0.16543816,278.48818566,0.00088539,0.16925148,281.52476121,-0.09983966,-0.06941182,0.00000000,0.00000000,0.00000000,0.00000000
218.10000000,5.38079600,2.60700000,0.18147667,236.20614807,0.16676507,279.07205247,0.00082118,0.17037568,281.84268985,-0.10054536,-0.06983032,0.00000000,0.00000000,0.00000000,0.00000000
219.60000000,5.42709100,2.60800000,0.18304333,236.29675265,0.16809021,279.54929791,0.00094618,0.17146579,282.25973353,-0.10118275,-0.07028303,0.00000000,0.00000000,0.00000000,0.00000000
221.10000000,5.47395700,2.60900000,0.18449811,236.38735724,0.16931915,280.00037814,0.00088196,0.17255488,282.67706643,-0.10183337,-0.07072150,0.00000000,0.00000000,0.00000000,0.00000000
222.60000000,5.52042100,2.61000000,0.18595289,236.47796182,0.17054658,280.45172198,0.00081789,0.17370494,283.11230720,-0.10252371,-0.07118123,0.00000000,0.00000000,0.00000000,0.00000000
224.10000000,5.56701900,2.61100000,0.18737044,236.56856640,0.17174115,280.89452383,0.00075419,0.17482247,283.53891954,-0.10323099,-0.07159148,0.00000000,0.00000000,0.00000000,0.00000000
225.60000000,5.61230700,2.61200000,0.18871333,236.65917099,0.17287149,281.31991201,0.00081599,0.17596989,283.97465714,-0.10389736,-0.07207253,0.00000000,0.00000000,0.00000000,0.00000000
227.10000000,5.65880600,2.61300000,0.19001889,236.74977557,0.17396918,281.73670487,0.00075251,0.17724141,284.33741928,-0.10468725,-0.07255416,0.00000000,0.00000000,0.00000000,0.00000000
228.60000000,5.70399200,2.61400000,0.19132444,236.84038015,0.17506567,282.15373431,0.00075150,0.17854075,284.81778759,-0.10549906,-0.07304169,0.00000000,0.00000000,0.00000000,0.00000000
230.10000000,5.75018900,2.61500000,0.19266733,236.93098473,0.17619226,282.57984575,0.00075084,0.17996204,285.33386276,-0.10634508,-0.07361696,0.00000000,0.00000000,0.00000000,0.00000000
231.60000000,5.79614900,2.61600000,0.19401022,237.02158932,0.17731758,283.00620053,0.00081237,0.18153717,285.78547264,-0.10733640,-0.07420077,0.00000000,0.00000000,0.00000000,0.00000000
233.10000000,5.84217600,2.61600000,0.19531578,237.02158932,0.17841040,283.31564539,0.00074899,0.18329462,286.29020379,-0.10841942,-0.07487520,0.00000000,0.00000000,0.00000000,0.00000000
234.60000000,5.88971400,2.61700000,0.19673322,237.11219390,0.17959553,283.76003984,0.00068587,0.18523352,286.84808259,-0.10954531,-0.07568821,0.00000000,0.00000000,0.00000000,0.00000000
236.10000000,5.93627700,2.61800000,0.19818800,237.20279848,0.18081042,284.21354671,0.00074738,0.18750621,287.50339433,-0.11085104,-0.07665517,0.00000000,0.00000000,0.00000000,0.00000000
237.60000000,5.98358200,2.61900000,0.19971744,237.29340307,0.18208607,284.68503511,0.00080869,0.18992666,288.20296500,-0.11216863,-0.07775803,0.00000000,0.00000000,0.00000000,0.00000000
239.10000000,6.03138800,2.61900000,0.20139600,237.29340307,0.18348421,285.08334527,0.00093173,0.19261422,289.09248974,-0.11349822,-0.07911600,0.00000000,0.00000000,0.00000000,0.00000000
240.60000000,6.08010000,2.61900000,0.20318644,237.29340307,0.18497341,285.50820593,0.00099243,0.19544826,289.91631556,-0.11485912,-0.08058914,0.00000000,0.00000000,0.00000000,0.00000000
242.10000000,6.12992000,2.62000000,0.20527533,237.38400765,0.18670803,286.11308895,0.00123827,0.00000000,0.00000000,0.00000000,0.00000000,0.00000000,0.00000000,0.00000000,0.00000000
243.60000000,6.18105000,2.62000000,0.20755089,237.38400765,0.18859425,286.65326945,0.00129800,0.00000000,0.00000000,0.00000000,0.00000000,0.00000000,0.00000000,0.00000000,0.00000000
245.10000000,6.23278800,2.62000000,0.21016222,237.38400765,0.19075442,287.27315822,0.00154199,0.00000000,0.00000000,0.00000000,0.00000000,0.00000000,0.00000000,0.00000000,0.00000000
246.60000000,6.28408500,2.62000000,0.21307189,237.38400765,0.19315589,287.96386655,0.00166130,0.00000000,0.00000000,0.00000000,0.00000000,0.00000000,0.00000000,0.00000000,0.00000000
248.10000000,6.33625400,2.62100000,0.21620533,237.47461223,0.19573563,288.81788993,0.00177973,0.00000000,0.00000000,0.00000000,0.00000000,0.00000000,0.00000000,0.00000000,0.00000000
249.60000000,6.38970100,2.62100000,0.21963711,237.47461223,0.19855336,289.63285003,0.00189709,0.00000000,0.00000000,0.00000000,0.00000000,0.00000000,0.00000000,0.00000000,0.00000000
251.10000000,6.44234300,2.62200000,0.22321800,237.56521682,0.00000000,0.00000000,0.00000000,0.00000000,0.00000000,0.00000000,0.00000000,0.00000000,0.00000000,0.00000000,0.00000000
252.60000000,6.49750200,2.62200000,0.22705989,237.56521682,0.00000000,0.00000000,0.00000000,0.00000000,0.00000000,0.00000000,0.00000000,0.00000000,0.00000000,0.00000000,0.00000000
254.10000000,6.55215800,2.62200000,0.23097633,237.56521682,0.00000000,0.00000000,0.00000000,0.00000000,0.00000000,0.00000000,0.00000000,0.00000000,0.00000000,0.00000000,0.00000000
255.60000000,6.60728500,2.62200000,0.23489311,237.56521682,0.00000000,0.00000000,0.00000000,0.00000000,0.00000000,0.00000000,0.00000000,0.00000000,0.00000000,0.00000000,0.00000000
257.10000000,6.66308400,2.62100000,0.23881011,237.47461223,0.00000000,0.00000000,0.00000000,0.00000000,0.00000000,0.00000000,0.00000000,0.00000000,0.00000000,0.00000000,0.00000000
258.60000000,6.71908400,2.62100000,0.24239144,237.47461223,0.00000000,0.00000000,0.00000000,0.00000000,0.00000000,0.00000000,0.00000000,0.00000000,0.00000000,0.00000000,0.00000000
260.10000000,6.77498100,2.62100000,0.24545033,237.47461223,0.00000000,0.00000000,0.00000000,0.00000000,0.00000000,0.00000000,0.00000000,0.00000000,0.00000000,0.00000000,0.00000000
261.60000000,6.83074300,2.62000000,0.24817344,237.38400765,0.00000000,0.00000000,0.00000000,0.00000000,0.00000000,0.00000000,0.00000000,0.00000000,0.00000000,0.00000000,0.00000000
263.10000000,6.88778000,2.62000000,0.25085933,237.38400765,0.00000000,0.00000000,0.00000000,0.00000000,0.00000000,0.00000000,0.00000000,0.00000000,0.00000000,0.00000000,0.00000000
264.60000000,6.94542400,2.61900000,0.25384389,237.29340307,0.00000000,0.00000000,0.00000000,0.00000000,0.00000000,0.00000000,0.00000000,0.00000000,0.00000000,0.00000000,0.00000000
266.10000000,7.00303500,2.61600000,0.25764911,237.02158932,0.00000000,0.00000000,0.00000000,0.00000000,0.00000000,0.00000000,0.00000000,0.00000000,0.00000000,0.00000000,0.00000000
267.60000000,7.06155200,2.61400000,0.26216322,236.84038015,0.00000000,0.00000000,0.00000000,0.00000000,0.00000000,0.00000000,0.00000000,0.00000000,0.00000000,0.00000000,0.00000000
269.10000000,7.11929500,2.61200000,0.26716200,236.65917099,0.00000000,0.00000000,0.00000000,0.00000000,0.00000000,0.00000000,0.00000000,0.00000000,0.00000000,0.00000000,0.00000000
270.60000000,7.17767400,2.60900000,0.27216044,236.38735724,0.00000000,0.00000000,0.00000000,0.00000000,0.00000000,0.00000000,0.00000000,0.00000000,0.00000000,0.00000000,0.00000000
272.10000000,7.23672900,2.60400000,0.27738311,235.93433432,0.00000000,0.00000000,0.00000000,0.00000000,0.00000000,0.00000000,0.00000000,0.00000000,0.00000000,0.00000000,0.00000000
273.60000000,7.29592000,2.59900000,0.28283056,235.48131141,0.00000000,0.00000000,0.00000000,0.00000000,0.00000000,0.00000000,0.00000000,0.00000000,0.00000000,0.00000000,0.00000000
275.10000000,7.35534800,2.59300000,0.28854022,234.93768391,0.00000000,0.00000000,0.00000000,0.00000000,0.00000000,0.00000000,0.00000000,0.00000000,0.00000000,0.00000000,0.00000000
276.60000000,7.41628800,2.58200000,0.29469867,233.94103349,0.00000000,0.00000000,0.00000000,0.00000000,0.00000000,0.00000000,0.00000000,0.00000000,0.00000000,0.00000000,0.00000000
278.10000000,7.47710000,2.56700000,0.30119644,232.58196475,0.00000000,0.00000000,0.00000000,0.00000000,0.00000000,0.00000000,0.00000000,0.00000000,0.00000000,0.00000000,0.00000000
279.60000000,7.53943700,2.54200000,0.30807433,230.31685017,0.00000000,0.00000000,0.00000000,0.00000000,0.00000000,0.00000000,0.00000000,0.00000000,0.00000000,0.00000000,0.00000000
281.10000000,7.60373400,2.49900000,0.31537144,226.42085310,0.00000000,0.00000000,0.00000000,0.00000000,0.00000000,0.00000000,0.00000000,0.00000000,0.00000000,0.00000000,0.00000000
282.60000000,7.67016000,2.43800000,0.32305200,220.89397353,0.00000000,0.00000000,0.00000000,0.00000000,0.00000000,0.00000000,0.00000000,0.00000000,0.00000000,0.00000000,0.00000000
284.10000000,7.74033300,2.35300000,0.33138067,213.19258397,0.00000000,0.00000000,0.00000000,0.00000000,0.00000000,0.00000000,0.00000000,0.00000000,0.00000000,0.00000000,0.00000000
285.60000000,8.10889100,0.91800000,0.35493656,83.17500726,0.00000000,0.00000000,0.00000000,0.00000000,0.00000000,0.00000000,0.00000000,0.00000000,0.00000000,0.00000000,0.00000000
NaN,-100.00000000,NaN,-11.11111111,NaN,0.00000000,0.00000000,0.00000000,0.00000000,0.00000000,0.00000000,0.00000000,0.00000000,0.00000000,0.00000000,0.00000000