File: lab_data/AA6014-T4_results/DATA/UT_30_1.csv
Time[s],Displacement[mm],Force[kN],EngStrain_longi,EngStress[MPa],TrueStrain,TrueStress[MPa],TrueStrainRate[1/s],PlasticStrain_longi,PlasticStress[MPa],PlasticStrain_thick,PlasticStrain_width,R-Value,Thickness[mm],Width[mm], Young's Modulus [MPa]
0.55000000,0.00000000,-0.00100000,0.00000000,-0.08995412,0.00000000,-0.08995412,0.00000000,0.00053842,115.02948655,0.00006124,-0.00059967,0.55839669,1.11750000,9.94790000,74669.63644821
2.05000000,0.00539500,0.16600000,0.00016367,14.93238385,0.00016365,14.93482778,0.00013487,0.00170284,119.59361742,-0.00072697,-0.00097587,0.00000000,0.00000000,0.00000000,0.00000000
3.55000000,0.01248300,0.40300000,0.00040489,36.25151019,0.00040481,36.26618802,0.00016594,0.00290195,123.26782577,-0.00155148,-0.00135047,0.00000000,0.00000000,0.00000000,0.00000000
5.05000000,0.02153400,0.66100000,0.00070822,59.45967304,0.00070797,59.50178370,0.00018565,0.00402012,126.57820795,-0.00231225,-0.00170787,0.00000000,0.00000000,0.00000000,0.00000000
6.55000000,0.03018900,0.90800000,0.00103244,81.67834057,0.00103191,81.76266892,0.00034900,0.00520737,129.36061495,-0.00311834,-0.00208903,0.00000000,0.00000000,0.00000000,0.00000000
8.05000000,0.04224500,1.13800000,0.00134822,102.36778808,0.00134731,102.50580260,0.00037420,0.00646300,131.97697708,-0.00401574,-0.00244726,0.00000000,0.00000000,0.00000000,0.00000000
9.55000000,0.06793000,1.27600000,0.00216089,114.78145658,0.00215856,115.02948655,0.00053004,0.00765141,134.59083765,-0.00480986,-0.00284155,0.00000000,0.00000000,0.00000000,0.00000000
11.05000000,0.10370600,1.32500000,0.00339300,119.18920844,0.00338726,119.59361742,0.00072611,0.00874707,136.92488319,-0.00554881,-0.00319826,0.00000000,0.00000000,0.00000000,0.00000000
12.55000000,0.14026500,1.36400000,0.00464889,122.69741910,0.00463812,123.26782577,0.00093875,0.00990382,139.18135636,-0.00634444,-0.00355938,0.00000000,0.00000000,0.00000000,0.00000000
14.05000000,0.17633800,1.39900000,0.00581978,125.84581329,0.00580291,126.57820795,0.00085388,0.01113048,141.54424577,-0.00721659,-0.00391389,0.00000000,0.00000000,0.00000000,0.00000000
15.55000000,0.21341800,1.42800000,0.00705411,128.45448275,0.00702935,129.36061495,0.00078241,0.01221613,143.61826316,-0.00792996,-0.00428617,0.00000000,0.00000000,0.00000000,0.00000000
17.05000000,0.24957800,1.45500000,0.00835656,130.88324398,0.00832183,131.97697708,0.00093573,0.01331882,145.69922885,-0.00867891,-0.00463992,0.00000000,0.00000000,0.00000000,0.00000000
18.55000000,0.28712500,1.48200000,0.00959278,133.31200521,0.00954706,134.59083765,0.00105020,0.01447397,147.88414764,-0.00946557,-0.00500840,0.00000000,0.00000000,0.00000000,0.00000000
20.05000000,0.32302000,1.50600000,0.01073278,135.47090408,0.01067559,136.92488319,0.00086007,0.01559120,149.79309288,-0.01017880,-0.00541240,0.00000000,0.00000000,0.00000000,0.00000000
21.55000000,0.35826400,1.52900000,0.01193478,137.53984883,0.01186412,139.18135636,0.00078237,0.01668000,151.79375913,-0.01087403,-0.00580597,0.00000000,0.00000000,0.00000000,0.00000000
23.05000000,0.39538500,1.55300000,0.01321056,139.69874770,0.01312406,141.54424577,0.00090580,0.01783704,153.80923943,-0.01162611,-0.00621093,0.00000000,0.00000000,0.00000000,0.00000000
24.55000000,0.42997100,1.57400000,0.01434078,141.58778421,0.01423892,143.61826316,0.00090479,0.01893692,155.63621588,-0.01235468,-0.00658224,0.00000000,0.00000000,0.00000000,0.00000000
26.05000000,0.46593700,1.59500000,0.01548967,143.47682072,0.01537093,145.69922885,0.00074942,0.02001727,157.46403849,-0.01302864,-0.00698863,0.00000000,0.00000000,0.00000000,0.00000000
27.55000000,0.50128100,1.61700000,0.01669467,145.45581135,0.01655684,147.88414764,0.00071945,0.02114962,159.39631964,-0.01377408,-0.00737555,0.00000000,0.00000000,0.00000000,0.00000000
29.05000000,0.53618600,1.63600000,0.01785856,147.16493963,0.01770097,149.79309288,0.00074790,0.02223591,161.14064094,-0.01445123,-0.00778468,0.00000000,0.00000000,0.00000000,0.00000000
30.55000000,0.57164200,1.65600000,0.01899611,148.96402202,0.01881794,151.79375913,0.00072459,0.02333528,162.89078833,-0.01518796,-0.00814732,0.00000000,0.00000000,0.00000000,0.00000000
32.05000000,0.60697300,1.67600000,0.02020478,150.76310441,0.02000337,153.80923943,0.00071649,0.02441769,164.73448362,-0.01589345,-0.00852424,0.00000000,0.00000000,0.00000000,0.00000000
33.55000000,0.64118000,1.69400000,0.02135378,152.38227856,0.02112898,155.63621588,0.00070159,0.02553764,166.40291681,-0.01662912,-0.00890852,0.00000000,0.00000000,0.00000000,0.00000000
35.05000000,0.67576200,1.71200000,0.02248411,154.00145271,0.02223507,157.46403849,0.00070799,0.02661995,168.06861916,-0.01733788,-0.00928208,0.00000000,0.00000000,0.00000000,0.00000000
36.55000000,0.71064100,1.73100000,0.02367044,155.71058099,0.02339464,159.39631964,0.00075820,0.02771918,169.74068913,-0.01808913,-0.00963004,0.00000000,0.00000000,0.00000000,0.00000000
38.05000000,0.74532100,1.74800000,0.02480822,157.23980102,0.02450549,161.14064094,0.00067731,0.02879659,171.31953466,-0.01880589,-0.00999070,0.00000000,0.00000000,0.00000000,0.00000000
39.55000000,0.77969800,1.76500000,0.02596078,158.76902105,0.02562952,162.89078833,0.00074914,0.02990903,172.90772709,-0.01956848,-0.01034054,0.00000000,0.00000000,0.00000000,0.00000000
41.05000000,0.81451300,1.78300000,0.02709856,160.38819520,0.02673789,164.73448362,0.00077017,0.03101153,174.59082167,-0.02029538,-0.01071615,0.00000000,0.00000000,0.00000000,0.00000000
42.55000000,0.84946200,1.79900000,0.02827367,161.82746112,0.02788134,166.40291681,0.00075481,0.03209372,176.08720750,-0.02100409,-0.01108963,0.00000000,0.00000000,0.00000000,0.00000000
44.05000000,0.88367200,1.81500000,0.02941133,163.26672703,0.02898712,168.06861916,0.00068854,0.03316385,177.58454523,-0.02170364,-0.01146021,0.00000000,0.00000000,0.00000000,0.00000000
45.55000000,0.91798200,1.83100000,0.03056778,164.70599294,0.03010989,169.74068913,0.00075312,0.03426249,179.27719114,-0.02246138,-0.01180111,0.00000000,0.00000000,0.00000000,0.00000000
47.05000000,0.95239400,1.84600000,0.03170167,166.05530474,0.03120954,171.31953466,0.00074497,0.03533870,180.68835588,-0.02316104,-0.01217765,0.00000000,0.00000000,0.00000000,0.00000000
48.55000000,0.98677200,1.86100000,0.03287311,167.40461653,0.03234435,172.90772709,0.00076608,0.03644575,182.10803914,-0.02388840,-0.01255735,0.00000000,0.00000000,0.00000000,0.00000000
50.05000000,1.02162000,1.87700000,0.03403700,168.84388244,0.03347056,174.59082167,0.00075791,0.03751461,183.61755325,-0.02457976,-0.01293486,0.00000000,0.00000000,0.00000000,0.00000000
51.55000000,1.05630000,1.89100000,0.03517844,170.10324012,0.03457382,176.08720750,0.00071369,0.03860846,185.04080401,-0.02528371,-0.01332475,0.00000000,0.00000000,0.00000000,0.00000000
53.05000000,1.09037600,1.90500000,0.03630867,171.36259779,0.03566504,177.58454523,0.00070541,0.03967377,186.36758505,-0.02592977,-0.01374400,0.00000000,0.00000000,0.00000000,0.00000000
54.55000000,1.12512200,1.92100000,0.03747256,172.80186371,0.03678752,179.27719114,0.00072647,0.04078653,187.80015897,-0.02669059,-0.01409594,0.00000000,0.00000000,0.00000000,0.00000000
56.05000000,1.15953400,1.93400000,0.03861033,173.97126726,0.03788360,180.68835588,0.00072567,0.04186728,189.13537510,-0.02739570,-0.01447159,0.00000000,0.00000000,0.00000000,0.00000000
57.55000000,1.19397900,1.94700000,0.03978156,175.14067081,0.03901065,182.10803914,0.00072464,0.04295029,190.47373906,-0.02809287,-0.01485741,0.00000000,0.00000000,0.00000000,0.00000000
59.05000000,1.22839100,1.96100000,0.04091567,176.40002849,0.04010077,183.61755325,0.00066562,0.04404273,191.81664581,-0.02878964,-0.01525308,0.00000000,0.00000000,0.00000000,0.00000000
60.55000000,1.26287000,1.97400000,0.04207578,177.56943204,0.04121466,185.04080401,0.00074481,0.04512671,193.16067403,-0.02948718,-0.01563954,0.00000000,0.00000000,0.00000000,0.00000000
62.05000000,1.29738100,1.98600000,0.04320600,178.64888148,0.04229866,186.36758505,0.00076531,0.04623916,194.41826502,-0.03020573,-0.01603344,0.00000000,0.00000000,0.00000000,0.00000000
63.55000000,1.33226300,1.99900000,0.04438856,179.81828503,0.04343160,187.80015897,0.00077147,0.04730446,195.66920798,-0.03089084,-0.01641362,0.00000000,0.00000000,0.00000000,0.00000000
65.05000000,1.36711100,2.01100000,0.04553756,180.89773447,0.04453116,189.13537510,0.00076381,0.04840024,196.92866041,-0.03159422,-0.01680602,0.00000000,0.00000000,0.00000000,0.00000000
66.55000000,1.40101900,2.02300000,0.04669022,181.97718390,0.04563302,190.47373906,0.00081289,0.04948770,198.18903065,-0.03234344,-0.01714426,0.00000000,0.00000000,0.00000000,0.00000000
68.05000000,1.43620300,2.03500000,0.04785411,183.05663334,0.04674437,191.81664581,0.00078355,0.05054912,199.44674602,-0.03300876,-0.01754036,0.00000000,0.00000000,0.00000000,0.00000000
69.55000000,1.47105100,2.04700000,0.04901044,184.13608277,0.04784729,193.16067403,0.00075408,0.05164248,200.61812231,-0.03374271,-0.01789977,0.00000000,0.00000000,0.00000000,0.00000000
71.05000000,1.50606700,2.05800000,0.05019667,185.12557809,0.04897745,194.41826502,0.00078159,0.05273112,201.79090602,-0.03446423,-0.01826689,0.00000000,0.00000000,0.00000000,0.00000000
72.55000000,1.54047900,2.06900000,0.05133456,186.11507340,0.05006036,195.66920798,0.00075241,0.05381851,202.96579046,-0.03517451,-0.01864400,0.00000000,0.00000000,0.00000000,0.00000000
74.05000000,1.57549500,2.08000000,0.05250589,187.10456872,0.05117388,196.92866041,0.00074461,0.05491176,204.14423145,-0.03589199,-0.01901977,0.00000000,0.00000000,0.00000000,0.00000000
75.55000000,1.61051100,2.09100000,0.05366978,188.09406403,0.05227910,198.18903065,0.00074357,0.05603309,205.23513735,-0.03663485,-0.01939824,0.00000000,0.00000000,0.00000000,0.00000000
77.05000000,1.64502300,2.10200000,0.05480744,189.08355935,0.05335823,199.44674602,0.00070736,0.05713078,206.41917518,-0.03734131,-0.01978948,0.00000000,0.00000000,0.00000000,0.00000000
78.55000000,1.67983800,2.11200000,0.05597878,189.98310054,0.05446809,200.61812231,0.00075605,0.05820740,207.50531127,-0.03804787,-0.02015953,0.00000000,0.00000000,0.00000000,0.00000000
80.05000000,1.71515700,2.12200000,0.05714644,190.88264174,0.05557324,201.79090602,0.00075522,0.05929696,208.59628772,-0.03873013,-0.02056683,0.00000000,0.00000000,0.00000000,0.00000000
81.55000000,1.75027400,2.13200000,0.05831411,191.78218294,0.05667718,202.96579046,0.00071216,0.06037601,209.59110145,-0.03943942,-0.02093659,0.00000000,0.00000000,0.00000000,0.00000000
83.05000000,1.78549200,2.14200000,0.05948933,192.68172413,0.05778703,204.14423145,0.00070445,0.06149996,210.78979032,-0.04016818,-0.02133178,0.00000000,0.00000000,0.00000000,0.00000000
84.55000000,1.82094500,2.15100000,0.06069433,193.49131121,0.05892373,205.23513735,0.00076002,0.06259406,211.79192587,-0.04089625,-0.02169781,0.00000000,0.00000000,0.00000000,0.00000000
86.05000000,1.85639900,2.16100000,0.06187700,194.39085240,0.06003810,206.41917518,0.00076630,0.06372504,212.80390328,-0.04163029,-0.02209475,0.00000000,0.00000000,0.00000000,0.00000000
87.55000000,1.89165000,2.17000000,0.06303711,195.20043948,0.06113001,207.50531127,0.00076525,0.06482901,213.90869356,-0.04234465,-0.02248437,0.00000000,0.00000000,0.00000000,0.00000000
89.05000000,1.92703700,2.17900000,0.06421233,196.01002656,0.06223493,208.59628772,0.00075751,0.06590173,214.91229300,-0.04299423,-0.02290749,0.00000000,0.00000000,0.00000000,0.00000000
90.55000000,1.96245600,2.18700000,0.06537622,196.72965951,0.06332800,209.59110145,0.00067238,0.06700464,215.92436748,-0.04371713,-0.02328751,0.00000000,0.00000000,0.00000000,0.00000000
92.05000000,1.99831300,2.19700000,0.06659233,197.62920071,0.06446883,210.78979032,0.00079730,0.06810618,216.93814311,-0.04443499,-0.02367119,0.00000000,0.00000000,0.00000000,0.00000000
93.55000000,2.03390000,2.20500000,0.06777500,198.34883367,0.06557704,211.79192587,0.00070585,0.06920645,217.95364218,-0.04516715,-0.02403929,0.00000000,0.00000000,0.00000000,0.00000000
95.05000000,2.07005700,2.21300000,0.06899856,199.06846662,0.06672228,212.80390328,0.00075391,0.07030331,218.87329225,-0.04587961,-0.02442371,0.00000000,0.00000000,0.00000000,0.00000000
96.55000000,2.10571200,2.22200000,0.07019600,199.87805370,0.06784181,213.90869356,0.00073229,0.07143910,219.90051879,-0.04658469,-0.02485441,0.00000000,0.00000000,0.00000000,0.00000000
98.05000000,2.14143300,2.23000000,0.07135978,200.59768665,0.06892866,214.91229300,0.00078690,0.07256793,220.83095447,-0.04733944,-0.02522849,0.00000000,0.00000000,0.00000000,0.00000000
99.55000000,2.17755700,2.23800000,0.07255733,201.31731961,0.07004583,215.92436748,0.00071659,0.07364161,221.65353288,-0.04803429,-0.02560732,0.00000000,0.00000000,0.00000000,0.00000000
101.05000000,2.21331200,2.24600000,0.07375478,202.03695257,0.07116164,216.93814311,0.00070896,0.07472868,222.67571692,-0.04871762,-0.02601105,0.00000000,0.00000000,0.00000000,0.00000000
102.55000000,2.24977200,2.25400000,0.07495222,202.75658552,0.07227622,217.95364218,0.00076380,0.07583645,223.60688296,-0.04944494,-0.02639151,0.00000000,0.00000000,0.00000000,0.00000000
104.05000000,2.28562700,2.26100000,0.07614589,203.38626436,0.07338604,218.87329225,0.00076977,0.07697877,224.44987649,-0.05017426,-0.02680451,0.00000000,0.00000000,0.00000000,0.00000000
105.55000000,2.32208800,2.26900000,0.07738444,204.10589732,0.07453629,219.90051879,0.00075485,0.07806323,225.37932367,-0.05087028,-0.02719294,0.00000000,0.00000000,0.00000000,0.00000000
107.05000000,2.35844700,2.27600000,0.07861544,204.73557615,0.07567822,220.83095447,0.00073338,0.07915151,226.21342870,-0.05156519,-0.02758631,0.00000000,0.00000000,0.00000000,0.00000000
108.55000000,2.39453600,2.28200000,0.07978667,205.27530087,0.07676349,221.65353288,0.00070500,0.08028517,227.15753968,-0.05230355,-0.02798162,0.00000000,0.00000000,0.00000000,0.00000000
110.05000000,2.43072800,2.29000000,0.08097667,205.99493383,0.07786495,222.67571692,0.00071101,0.08141867,228.00527503,-0.05304732,-0.02837136,0.00000000,0.00000000,0.00000000,0.00000000
111.55000000,2.46698600,2.29700000,0.08218900,206.62461267,0.07898584,223.60688296,0.00070302,0.08249962,228.84259285,-0.05375091,-0.02874870,0.00000000,0.00000000,0.00000000,0.00000000
113.05000000,2.50361400,2.30300000,0.08343878,207.16433738,0.08014004,224.44987649,0.00078510,0.08360341,229.68674044,-0.05444850,-0.02915491,0.00000000,0.00000000,0.00000000,0.00000000
114.55000000,2.54020700,2.31000000,0.08462856,207.79401622,0.08123758,225.37932367,0.00077707,0.08471913,230.53525042,-0.05515317,-0.02956596,0.00000000,0.00000000,0.00000000,0.00000000
116.05000000,2.57646600,2.31600000,0.08582233,208.33374094,0.08233761,226.21342870,0.00070783,0.08583052,231.38438331,-0.05585151,-0.02997901,0.00000000,0.00000000,0.00000000,0.00000000
117.55000000,2.61346300,2.32300000,0.08706844,208.96341977,0.08348457,227.15753968,0.00075528,0.08694202,232.13639473,-0.05657628,-0.03036574,0.00000000,0.00000000,0.00000000,0.00000000
119.05000000,2.65039200,2.32900000,0.08831433,209.50314449,0.08463002,228.00527503,0.00076810,0.08807461,232.99361947,-0.05731398,-0.03076063,0.00000000,0.00000000,0.00000000,0.00000000
120.55000000,2.68681900,2.33500000,0.08950422,210.04286921,0.08572275,228.84259285,0.00072584,0.08920234,233.85136816,-0.05806434,-0.03113800,0.00000000,0.00000000,0.00000000,0.00000000
122.05000000,2.72337900,2.34100000,0.09072044,210.58259393,0.08683844,229.68674044,0.00073217,0.09029293,234.60292254,-0.05873491,-0.03155802,0.00000000,0.00000000,0.00000000,0.00000000
123.55000000,2.75983800,2.34700000,0.09195111,211.12231864,0.08796611,230.53525042,0.00071730,0.09141272,235.36274800,-0.05944498,-0.03196774,0.00000000,0.00000000,0.00000000,0.00000000
125.05000000,2.79757400,2.35300000,0.09317844,211.66204336,0.08908946,231.38438331,0.00077811,0.09254008,236.22512691,-0.06017408,-0.03236600,0.00000000,0.00000000,0.00000000,0.00000000
126.55000000,2.83473800,2.35800000,0.09440578,212.11181396,0.09021155,232.13639473,0.00074311,0.09365064,236.98572660,-0.06086655,-0.03278409,0.00000000,0.00000000,0.00000000,0.00000000
128.05000000,2.87186900,2.36400000,0.09565922,212.65153868,0.09135621,232.99361947,0.00077655,0.09476112,237.64816234,-0.06157670,-0.03318442,0.00000000,0.00000000,0.00000000,0.00000000
129.55000000,2.90849600,2.37000000,0.09690878,213.19126340,0.09249602,233.85136816,0.00080282,0.09590956,238.42053939,-0.06232136,-0.03358820,0.00000000,0.00000000,0.00000000,0.00000000
131.05000000,2.94562600,2.37500000,0.09811733,213.64103399,0.09359720,234.60292254,0.00077481,0.09701616,239.18435621,-0.06302433,-0.03399184,0.00000000,0.00000000,0.00000000,0.00000000
132.55000000,2.98285800,2.38000000,0.09935944,214.09080459,0.09472769,235.36274800,0.00075331,0.09812491,239.95010265,-0.06374413,-0.03438078,0.00000000,0.00000000,0.00000000,0.00000000
134.05000000,3.02002300,2.38600000,0.10061289,214.63052931,0.09586720,236.22512691,0.00080678,0.09925268,240.72186307,-0.06445576,-0.03479691,0.00000000,0.00000000,0.00000000,0.00000000
135.55000000,3.05762400,2.39100000,0.10184767,215.08029991,0.09698847,236.98572660,0.00080608,0.10037695,241.39409619,-0.06517466,-0.03520228,0.00000000,0.00000000,0.00000000,0.00000000
137.05000000,3.09468700,2.39500000,0.10308222,215.44011638,0.09810828,237.64816234,0.00070341,0.10150670,242.06888069,-0.06590016,-0.03560654,0.00000000,0.00000000,0.00000000,0.00000000
138.55000000,3.13279100,2.40000000,0.10436178,215.88988698,0.09926759,238.42053939,0.00068246,0.10262696,242.84294338,-0.06661750,-0.03600946,0.00000000,0.00000000,0.00000000,0.00000000
140.05000000,3.17002300,2.40500000,0.10559644,216.33965758,0.10038496,239.18435621,0.00076273,0.10376743,243.52291616,-0.06735145,-0.03641598,0.00000000,0.00000000,0.00000000,0.00000000
141.55000000,3.20799400,2.41000000,0.10683489,216.78942818,0.10150449,239.95010265,0.00077513,0.10492018,244.20714530,-0.06809799,-0.03682219,0.00000000,0.00000000,0.00000000,0.00000000
143.05000000,3.24559600,2.41500000,0.10809589,217.23919878,0.10264313,240.72186307,0.00080154,0.10603454,244.88320956,-0.06879186,-0.03724269,0.00000000,0.00000000,0.00000000,0.00000000
144.55000000,3.28356600,2.41900000,0.10935289,217.59901525,0.10377686,241.39409619,0.00070624,0.10714774,245.56020010,-0.06950724,-0.03764050,0.00000000,0.00000000,0.00000000,0.00000000
146.05000000,3.32180500,2.42300000,0.11061744,217.95883173,0.10491612,242.06888069,0.00077950,0.10827293,246.24137124,-0.07022882,-0.03804410,0.00000000,0.00000000,0.00000000,0.00000000
147.55000000,3.36034500,2.42800000,0.11187444,218.40860233,0.10604728,242.84294338,0.00071804,0.10943005,246.93168954,-0.07098672,-0.03844333,0.00000000,0.00000000,0.00000000,0.00000000
149.05000000,3.39831600,2.43200000,0.11315389,218.76841881,0.10719733,243.52291616,0.00071022,0.11052949,247.60895531,-0.07165815,-0.03887134,0.00000000,0.00000000,0.00000000,0.00000000
150.55000000,3.43689100,2.43600000,0.11444856,219.12823529,0.10835971,244.20714530,0.00087077,0.11171709,248.30939126,-0.07243583,-0.03928127,0.00000000,0.00000000,0.00000000,0.00000000
152.05000000,3.47499600,2.44000000,0.11570178,219.48805177,0.10948360,244.88320956,0.00077575,0.11284839,248.89567746,-0.07318555,-0.03966284,0.00000000,0.00000000,0.00000000,0.00000000
153.55000000,3.51316700,2.44400000,0.11695511,219.84786824,0.11060633,245.56020010,0.00072134,0.11396712,249.58135742,-0.07385829,-0.04010883,0.00000000,0.00000000,0.00000000,0.00000000
155.05000000,3.55137200,2.44800000,0.11822333,220.20768472,0.11174112,246.24137124,0.00072728,0.11510432,250.27291430,-0.07461131,-0.04049301,0.00000000,0.00000000,0.00000000,0.00000000
156.55000000,3.59001300,2.45200000,0.11952889,220.56750120,0.11290796,246.93168954,0.00077985,0.11626147,250.86899475,-0.07532237,-0.04093910,0.00000000,0.00000000,0.00000000,0.00000000
158.05000000,3.62905800,2.45600000,0.12077111,220.92731768,0.11401694,247.60895531,0.00070559,0.11739086,251.45912419,-0.07606655,-0.04132431,0.00000000,0.00000000,0.00000000,0.00000000
159.55000000,3.66763300,2.46000000,0.12211400,221.28713416,0.11521441,248.30939126,0.00073129,0.11852218,252.05076420,-0.07680080,-0.04172138,0.00000000,0.00000000,0.00000000,0.00000000
161.05000000,3.70661100,2.46300000,0.12339344,221.55699652,0.11635397,248.89567746,0.00077696,0.11970010,252.75736088,-0.07751588,-0.04218422,0.00000000,0.00000000,0.00000000,0.00000000
162.55000000,3.74521900,2.46700000,0.12466178,221.91681299,0.11748235,249.58135742,0.00070335,0.12084015,253.25118539,-0.07825481,-0.04258534,0.00000000,0.00000000,0.00000000,0.00000000
164.05000000,3.78470000,2.47100000,0.12595244,222.27662947,0.11862929,250.27291430,0.00077540,0.12196284,253.94609270,-0.07895589,-0.04300694,0.00000000,0.00000000,0.00000000,0.00000000
165.55000000,3.82351000,2.47400000,0.12726556,222.54649183,0.11979484,250.86899475,0.00077449,0.12309220,254.54149110,-0.07966731,-0.04342489,0.00000000,0.00000000,0.00000000,0.00000000
167.05000000,3.86245400,2.47700000,0.12854878,222.81635419,0.12093254,251.45912419,0.00078701,0.12425299,255.14596839,-0.08042025,-0.04383275,0.00000000,0.00000000,0.00000000,0.00000000
168.55000000,3.90196800,2.48000000,0.12983567,223.08621655,0.12207219,252.05076420,0.00075935,0.12543528,255.75703209,-0.08119082,-0.04424446,0.00000000,0.00000000,0.00000000,0.00000000
170.05000000,3.94165000,2.48400000,0.13117856,223.44603303,0.12326006,252.75736088,0.00083785,0.12658152,256.25708710,-0.08191687,-0.04466465,0.00000000,0.00000000,0.00000000,0.00000000
171.55000000,3.98129900,2.48600000,0.13247678,223.62594127,0.12440707,253.25118539,0.00079095,0.12774149,256.86444909,-0.08265824,-0.04508325,0.00000000,0.00000000,0.00000000,0.00000000
173.05000000,4.02047800,2.49000000,0.13376000,223.98575774,0.12553954,253.94609270,0.00077672,0.12890338,257.47338182,-0.08339625,-0.04550713,0.00000000,0.00000000,0.00000000,0.00000000
174.55000000,4.05962300,2.49300000,0.13505067,224.25562010,0.12667729,254.54149110,0.00069005,0.13003455,258.07543396,-0.08411472,-0.04591982,0.00000000,0.00000000,0.00000000,0.00000000
176.05000000,4.09997900,2.49600000,0.13637867,224.52548246,0.12784660,255.14596839,0.00082736,0.13120794,258.58617438,-0.08486691,-0.04634103,0.00000000,0.00000000,0.00000000,0.00000000
177.55000000,4.13993000,2.49900000,0.13773278,224.79534482,0.12903749,255.75703209,0.00083966,0.13236244,259.19628968,-0.08560200,-0.04676044,0.00000000,0.00000000,0.00000000,0.00000000
179.05000000,4.17951000,2.50100000,0.13904567,224.97525306,0.13019078,256.25708710,0.00077312,0.13352668,259.70645953,-0.08635762,-0.04716906,0.00000000,0.00000000,0.00000000,0.00000000
180.55000000,4.21993200,2.50400000,0.14037744,225.24511542,0.13135930,256.86444909,0.00081140,0.13468163,260.31872679,-0.08709877,-0.04758287,0.00000000,0.00000000,0.00000000,0.00000000
182.05000000,4.26005100,2.50700000,0.14171300,225.51497778,0.13252977,257.47338182,0.00081064,0.13585285,260.83252841,-0.08782229,-0.04803056,0.00000000,0.00000000,0.00000000,0.00000000
183.55000000,4.30000300,2.51000000,0.14301489,225.78484014,0.13366941,258.07543396,0.00071811,0.13696621,261.43592632,-0.08853674,-0.04842947,0.00000000,0.00000000,0.00000000,0.00000000
185.05000000,4.33981900,2.51200000,0.14436511,225.96474837,0.13485000,258.58617438,0.00078234,0.13815739,261.95677345,-0.08929832,-0.04885906,0.00000000,0.00000000,0.00000000,0.00000000
186.55000000,4.38003800,2.51500000,0.14569689,226.23461073,0.13601309,259.19628968,0.00082082,0.13931015,262.57254834,-0.09004594,-0.04926421,0.00000000,0.00000000,0.00000000,0.00000000
188.05000000,4.42106400,2.51700000,0.14703978,226.41451897,0.13718452,259.70645953,0.00076773,0.14044513,262.97612786,-0.09076247,-0.04968267,0.00000000,0.00000000,0.00000000,0.00000000
189.55000000,4.46135100,2.52000000,0.14837522,226.68438133,0.13834809,260.31872679,0.00072773,0.14161927,263.49505367,-0.09151757,-0.05010170,0.00000000,0.00000000,0.00000000,0.00000000
191.05000000,4.50224300,2.52200000,0.14972933,226.86428957,0.13952655,260.83252841,0.00083090,0.14276294,264.00676833,-0.09223509,-0.05052785,0.00000000,0.00000000,0.00000000,0.00000000
192.55000000,4.54263000,2.52500000,0.15101989,227.13415193,0.14064841,261.43592632,0.00073243,0.14391995,264.62751364,-0.09296078,-0.05095918,0.00000000,0.00000000,0.00000000,0.00000000
194.05000000,4.58345500,2.52700000,0.15240022,227.31406017,0.14184692,261.95677345,0.00084190,0.14508985,265.14800205,-0.09369401,-0.05139584,0.00000000,0.00000000,0.00000000,0.00000000
195.55000000,4.62448100,2.53000000,0.15373944,227.58392253,0.14300836,262.57254834,0.00085383,0.14630137,265.57554305,-0.09446671,-0.05183466,0.00000000,0.00000000,0.00000000,0.00000000
197.05000000,4.66510400,2.53100000,0.15505622,227.67387665,0.14414902,262.97612786,0.00080108,0.14748452,266.10119537,-0.09523933,-0.05224520,0.00000000,0.00000000,0.00000000,0.00000000
198.55000000,4.70639900,2.53300000,0.15642167,227.85378489,0.14533047,263.49505367,0.00082609,0.14860533,266.61104059,-0.09591968,-0.05268565,0.00000000,0.00000000,0.00000000,0.00000000
200.05000000,4.74779400,2.53500000,0.15775333,228.03369313,0.14648135,264.00676833,0.00074737,0.14981429,267.14533871,-0.09669104,-0.05312325,0.00000000,0.00000000,0.00000000,0.00000000
201.55000000,4.78959100,2.53800000,0.15910378,228.30355548,0.14764710,264.62751364,0.00073404,0.15102176,267.68014690,-0.09748091,-0.05354085,0.00000000,0.00000000,0.00000000,0.00000000
203.05000000,4.83135600,2.54000000,0.16046911,228.48346372,0.14882433,265.14800205,0.00075233,0.15222914,268.11029835,-0.09825053,-0.05397861,0.00000000,0.00000000,0.00000000,0.00000000
204.55000000,4.87295200,2.54100000,0.16188289,228.57341784,0.15004187,265.57554305,0.00080920,0.15343356,268.64597362,-0.09898248,-0.05445108,0.00000000,0.00000000,0.00000000,0.00000000
206.05000000,4.91471700,2.54300000,0.16326700,228.75332608,0.15123243,266.10119537,0.00082123,0.15466825,269.19073596,-0.09976156,-0.05490669,0.00000000,0.00000000,0.00000000,0.00000000
207.55000000,4.95621200,2.54500000,0.16457989,228.93323432,0.15236041,266.61104059,0.00076876,0.15587127,269.62193635,-0.10049165,-0.05537961,0.00000000,0.00000000,0.00000000,0.00000000
209.05000000,4.99898300,2.54700000,0.16599744,229.11314256,0.15357690,267.14533871,0.00076802,0.15707134,270.15904646,-0.10126094,-0.05581040,0.00000000,0.00000000,0.00000000,0.00000000
210.55000000,5.04128500,2.54900000,0.16741500,229.29305080,0.15479190,267.68014690,0.00083107,0.15830156,270.70526049,-0.10204588,-0.05625568,0.00000000,0.00000000,0.00000000,0.00000000
212.05000000,5.08382100,2.55000000,0.16883244,229.38300492,0.15600534,268.11029835,0.00082987,0.15950016,271.13748436,-0.10280576,-0.05669440,0.00000000,0.00000000,0.00000000,0.00000000
213.55000000,5.12676100,2.55200000,0.17024989,229.56291316,0.15721731,268.64597362,0.00082905,0.16069721,271.56993766,-0.10356120,-0.05713601,0.00000000,0.00000000,0.00000000,0.00000000
215.05000000,5.16932900,2.55400000,0.17170467,229.74282140,0.15845967,269.19073596,0.00082784,0.16182997,271.98548932,-0.10426279,-0.05756718,0.00000000,0.00000000,0.00000000,0.00000000
216.55000000,5.21156400,2.55500000,0.17312222,229.83277552,0.15966876,269.62193635,0.00082702,0.16289689,272.49031788,-0.10490183,-0.05799506,0.00000000,0.00000000,0.00000000,0.00000000
218.05000000,5.25369800,2.55700000,0.17453978,230.01268376,0.16087639,270.15904646,0.00076224,0.16402704,272.90644122,-0.10565139,-0.05837565,0.00000000,0.00000000,0.00000000,0.00000000
219.55000000,5.29673800,2.55900000,0.17599467,230.19259199,0.16211431,270.70526049,0.00082481,0.16509317,273.30559707,-0.10629801,-0.05879517,0.00000000,0.00000000,0.00000000,0.00000000
221.05000000,5.33960900,2.56000000,0.17741222,230.28254611,0.16331900,271.13748436,0.00082401,0.16609400,273.79438307,-0.10693456,-0.05915944,0.00000000,0.00000000,0.00000000,0.00000000
222.55000000,5.38308400,2.56100000,0.17882967,230.37250023,0.16452214,271.56993766,0.00088620,0.16718773,274.30946531,-0.10763981,-0.05954793,0.00000000,0.00000000,0.00000000,0.00000000
224.05000000,5.42656100,2.56200000,0.18017267,230.46245435,0.16566076,271.98548932,0.00082208,0.16825008,274.70942777,-0.10829951,-0.05995057,0.00000000,0.00000000,0.00000000,0.00000000
225.55000000,5.46906300,2.56400000,0.18144089,230.64236259,0.16673479,272.49031788,0.00075798,0.16937552,275.01997472,-0.10899160,-0.06038393,0.00000000,0.00000000,0.00000000,0.00000000
227.05000000,5.51337800,2.56500000,0.18278378,230.73231671,0.16787079,272.90644122,0.00082008,0.17056056,275.45486183,-0.10979332,-0.06076724,0.00000000,0.00000000,0.00000000,0.00000000
228.55000000,5.55608200,2.56600000,0.18405211,230.82227083,0.16894255,273.30559707,0.00081939,0.17171317,275.88141449,-0.11054706,-0.06116612,0.00000000,0.00000000,0.00000000,0.00000000
230.05000000,5.59868500,2.56800000,0.18524589,231.00217907,0.16995025,273.79438307,0.00069271,0.17292676,276.32550393,-0.11134240,-0.06158436,0.00000000,0.00000000,0.00000000,0.00000000
231.55000000,5.64108700,2.57000000,0.18655156,231.18208731,0.17105125,274.30946531,0.00075490,0.17410934,276.65375317,-0.11217704,-0.06193229,0.00000000,0.00000000,0.00000000,0.00000000
233.05000000,5.68328400,2.57100000,0.18781944,231.27204143,0.17211923,274.70942777,0.00069065,0.17529042,276.98197668,-0.11294411,-0.06234631,0.00000000,0.00000000,0.00000000,0.00000000
234.55000000,5.72568300,2.57100000,0.18916222,231.27204143,0.17324904,275.01997472,0.00081568,0.17625139,277.35745366,-0.11360128,-0.06265011,0.00000000,0.00000000,0.00000000,0.00000000
236.05000000,5.76821900,2.57200000,0.19057956,231.36199555,0.17444021,275.45486183,0.00075178,0.17730431,277.75904004,-0.11432732,-0.06297699,0.00000000,0.00000000,0.00000000,0.00000000
237.55000000,5.81122400,2.57300000,0.19195978,231.45194967,0.17559882,275.88141449,0.00075129,0.17829413,278.14354598,-0.11501947,-0.06327466,0.00000000,0.00000000,0.00000000,0.00000000
239.05000000,5.85661300,2.57400000,0.19341467,231.54190379,0.17681867,276.32550393,0.00075037,0.17934335,278.65362914,-0.11580032,-0.06354303,0.00000000,0.00000000,0.00000000,0.00000000
240.55000000,5.90253900,2.57400000,0.19483233,231.54190379,0.17800587,276.65375317,0.00081199,0.18048567,279.08197473,-0.11662163,-0.06386403,0.00000000,0.00000000,0.00000000,0.00000000
242.05000000,5.95118400,2.57400000,0.19624989,231.54190379,0.17919157,276.98197668,0.00081103,0.18181197,279.56257506,-0.11763633,-0.06417564,0.00000000,0.00000000,0.00000000,0.00000000
243.55000000,5.99949400,2.57500000,0.19740633,231.63185791,0.18015783,277.35745366,0.00068549,0.18316752,280.05218668,-0.11862455,-0.06454297,0.00000000,0.00000000,0.00000000,0.00000000
245.05000000,6.04904600,2.57600000,0.19867456,231.72181203,0.18121641,277.75904004,0.00074708,0.18461541,280.45957342,-0.11965093,-0.06496447,0.00000000,0.00000000,0.00000000,0.00000000
246.55000000,6.09893500,2.57700000,0.19986811,231.81176615,0.18221164,278.14354598,0.00068390,0.18612069,280.99295882,-0.12066849,-0.06545220,0.00000000,0.00000000,0.00000000,0.00000000
248.05000000,6.14795100,2.57900000,0.20113633,231.99167439,0.18326805,278.65362914,0.00068354,0.18765421,281.53529927,-0.12151785,-0.06613636,0.00000000,0.00000000,0.00000000,0.00000000
249.55000000,6.19649900,2.58000000,0.20251644,232.08162851,0.18441640,279.08197473,0.00068239,0.18918634,281.96869926,-0.12230239,-0.06688394,0.00000000,0.00000000,0.00000000,0.00000000
251.05000000,6.24387000,2.58100000,0.20412056,232.17158263,0.18574947,279.56257506,0.00086776,0.19089800,282.56342335,-0.12302879,-0.06786921,0.00000000,0.00000000,0.00000000,0.00000000
252.55000000,6.28936100,2.58200000,0.20576222,232.26153675,0.18711192,280.05218668,0.00092854,0.19272889,283.19326126,-0.12375333,-0.06897556,0.00000000,0.00000000,0.00000000,0.00000000
254.05000000,6.33334500,2.58200000,0.20751622,232.26153675,0.18856554,280.45957342,0.00092719,0.19486132,283.91040650,-0.12460040,-0.07026092,0.00000000,0.00000000,0.00000000,0.00000000
255.55000000,6.37467200,2.58300000,0.20934433,232.35149086,0.19007834,280.99295882,0.00098719,0.19723426,284.58762226,-0.12563438,-0.07159988,0.00000000,0.00000000,0.00000000,0.00000000
257.05000000,6.41620100,2.58400000,0.21120956,232.44144498,0.19161949,281.53529927,0.00104735,0.19993834,285.13981957,-0.12715520,-0.07278314,0.00000000,0.00000000,0.00000000,0.00000000
258.55000000,6.45567800,2.58400000,0.21307411,232.44144498,0.19315773,281.96869926,0.00110714,0.20296404,286.00736839,-0.12930015,-0.07366389,0.00000000,0.00000000,0.00000000,0.00000000
260.05000000,6.49693500,2.58500000,0.21516244,232.53139910,0.19487777,282.56342335,0.00122801,0.20582809,286.94241961,-0.13157146,-0.07425662,0.00000000,0.00000000,0.00000000,0.00000000
261.55000000,6.53983900,2.58600000,0.21740011,232.62135322,0.19671753,283.19326126,0.00116420,0.20796534,287.55884035,-0.13331185,-0.07465349,0.00000000,0.00000000,0.00000000,0.00000000
263.05000000,6.58486000,2.58700000,0.22001122,232.71130734,0.19886006,283.91040650,0.00146828,0.20934861,287.95850968,-0.13436521,-0.07498341,0.00000000,0.00000000,0.00000000,0.00000000
264.55000000,6.63297200,2.58700000,0.22292133,232.71130734,0.20124253,284.58762226,0.00170921,0.21027905,288.22765259,-0.13501335,-0.07526569,0.00000000,0.00000000,0.00000000,0.00000000
266.05000000,6.68366600,2.58500000,0.22624222,232.53139910,0.20395439,285.13981957,0.00188741,0.21096950,288.31555256,-0.13549787,-0.07547163,0.00000000,0.00000000,0.00000000,0.00000000
267.55000000,6.73590400,2.58500000,0.22997311,232.53139910,0.20699231,286.00736839,0.00206344,0.21153794,288.48015896,-0.13590077,-0.07563718,0.00000000,0.00000000,0.00000000,0.00000000
269.05000000,6.78864400,2.58600000,0.23351711,232.62135322,0.20986953,286.94241961,0.00175492,0.21201638,288.61877351,-0.13624099,-0.07577539,0.00000000,0.00000000,0.00000000,0.00000000
270.55000000,6.84302900,2.58600000,0.23616700,232.62135322,0.21201546,287.55884035,0.00120840,0.21240555,288.73157707,-0.13651246,-0.07589309,0.00000000,0.00000000,0.00000000,0.00000000
272.05000000,6.89825500,2.58600000,0.23788511,232.62135322,0.21340437,287.95850968,0.00084499,0.21276419,288.83557028,-0.13677580,-0.07598839,0.00000000,0.00000000,0.00000000,0.00000000
273.55000000,6.95284400,2.58600000,0.23904211,232.62135322,0.21433859,288.22765259,0.00060217,0.21303267,288.91344247,-0.13695916,-0.07607351,0.00000000,0.00000000,0.00000000,0.00000000
275.05000000,7.00907700,2.58500000,0.23989944,232.53139910,0.21503028,288.31555256,0.00048092,0.21330098,288.99128881,-0.13713791,-0.07616307,0.00000000,0.00000000,0.00000000,0.00000000
276.55000000,7.06537600,2.58500000,0.24060733,232.53139910,0.21560104,288.48015896,0.00036061,0.21356931,289.06916099,-0.13734368,-0.07622563,0.00000000,0.00000000,0.00000000,0.00000000
278.05000000,7.12190900,2.58500000,0.24120344,232.53139910,0.21608143,288.61877351,0.00036026,0.21380618,289.25023021,-0.13750526,-0.07630091,0.00000000,0.00000000,0.00000000,0.00000000
279.55000000,7.17844400,2.58500000,0.24168856,232.53139910,0.21647219,288.73157707,0.00024037,0.21401493,289.31086684,-0.13764561,-0.07636932,0.00000000,0.00000000,0.00000000,0.00000000
281.05000000,7.23481100,2.58500000,0.24213578,232.53139910,0.21683230,288.83557028,0.00023992,0.21422234,289.48348031,-0.13779474,-0.07642760,0.00000000,0.00000000,0.00000000,0.00000000
282.55000000,7.29174900,2.58500000,0.24247067,232.53139910,0.21710187,288.91344247,0.00011966,0.21437177,289.52691976,-0.13789141,-0.07648037,0.00000000,0.00000000,0.00000000,0.00000000
284.05000000,7.34908900,2.58500000,0.24280544,232.53139910,0.21737128,288.99128881,0.00011963,0.21457955,289.69972631,-0.13802984,-0.07654971,0.00000000,0.00000000,0.00000000,0.00000000
285.55000000,7.40612900,2.58500000,0.24314033,232.53139910,0.21764071,289.06916099,0.00023973,0.21478561,289.98451717,-0.13820504,-0.07658057,0.00000000,0.00000000,0.00000000,0.00000000
287.05000000,7.45682700,2.58600000,0.24343800,232.62135322,0.21788012,289.25023021,0.00023967,0.21496167,290.26067152,-0.13832328,-0.07663839,0.00000000,0.00000000,0.00000000,0.00000000
288.55000000,7.49238100,2.58600000,0.24369867,232.62135322,0.21808974,289.31086684,0.00017976,0.00000000,0.00000000,0.00000000,0.00000000,0.00000000,0.00000000,0.00000000,0.00000000
290.05000000,7.51544300,2.58700000,0.24395967,232.71130734,0.21829957,289.48348031,0.00023993,0.00000000,0.00000000,0.00000000,0.00000000,0.00000000,0.00000000,0.00000000,0.00000000
291.55000000,7.53212800,2.58700000,0.24414633,232.71130734,0.21844962,289.52691976,0.00006002,0.00000000,0.00000000,0.00000000,0.00000000,0.00000000,0.00000000,0.00000000,0.00000000
293.05000000,7.54807600,2.58800000,0.24440789,232.80126146,0.21865983,289.69972631,0.00018001,0.00000000,0.00000000,0.00000000,0.00000000,0.00000000,0.00000000,0.00000000,0.00000000
294.55000000,7.56496100,2.59000000,0.24466933,232.98116970,0.21886990,289.98451717,0.00018015,0.00000000,0.00000000,0.00000000,0.00000000,0.00000000,0.00000000,0.00000000,0.00000000
296.05000000,7.58493400,2.59200000,0.24489333,233.16107794,0.21904985,290.26067152,0.00017994,0.00000000,0.00000000,0.00000000,0.00000000,0.00000000,0.00000000,0.00000000,0.00000000
297.55000000,7.61729600,2.58900000,0.24508011,232.89121558,0.00000000,0.00000000,0.00000000,0.00000000,0.00000000,0.00000000,0.00000000,0.00000000,0.00000000,0.00000000,0.00000000
299.05000000,7.66130900,2.58400000,0.24519211,232.44144498,0.00000000,0.00000000,0.00000000,0.00000000,0.00000000,0.00000000,0.00000000,0.00000000,0.00000000,0.00000000,0.00000000
300.55000000,7.71035500,2.58200000,0.24541667,232.26153675,0.00000000,0.00000000,0.00000000,0.00000000,0.00000000,0.00000000,0.00000000,0.00000000,0.00000000,0.00000000,0.00000000
302.05000000,7.76148700,2.58000000,0.24552911,232.08162851,0.00000000,0.00000000,0.00000000,0.00000000,0.00000000,0.00000000,0.00000000,0.00000000,0.00000000,0.00000000,0.00000000
303.55000000,7.81413200,2.57700000,0.24564056,231.81176615,0.00000000,0.00000000,0.00000000,0.00000000,0.00000000,0.00000000,0.00000000,0.00000000,0.00000000,0.00000000,0.00000000
305.05000000,7.86865400,2.57500000,0.24571489,231.63185791,0.00000000,0.00000000,0.00000000,0.00000000,0.00000000,0.00000000,0.00000000,0.00000000,0.00000000,0.00000000,0.00000000
306.55000000,7.92421500,2.57100000,0.24582689,231.27204143,0.00000000,0.00000000,0.00000000,0.00000000,0.00000000,0.00000000,0.00000000,0.00000000,0.00000000,0.00000000,0.00000000
308.05000000,7.98044800,2.56500000,0.24586456,230.73231671,0.00000000,0.00000000,0.00000000,0.00000000,0.00000000,0.00000000,0.00000000,0.00000000,0.00000000,0.00000000,0.00000000
309.55000000,8.03799400,2.55900000,0.24593889,230.19259199,0.00000000,0.00000000,0.00000000,0.00000000,0.00000000,0.00000000,0.00000000,0.00000000,0.00000000,0.00000000,0.00000000
311.05000000,8.09668300,2.55100000,0.24601300,229.47295904,0.00000000,0.00000000,0.00000000,0.00000000,0.00000000,0.00000000,0.00000000,0.00000000,0.00000000,0.00000000,0.00000000
312.55000000,8.15543900,2.53900000,0.24601211,228.39350960,0.00000000,0.00000000,0.00000000,0.00000000,0.00000000,0.00000000,0.00000000,0.00000000,0.00000000,0.00000000,0.00000000
314.05000000,8.21591300,2.52300000,0.24601089,226.95424369,0.00000000,0.00000000,0.00000000,0.00000000,0.00000000,0.00000000,0.00000000,0.00000000,0.00000000,0.00000000,0.00000000
315.55000000,8.27807400,2.49900000,0.24597156,224.79534482,0.00000000,0.00000000,0.00000000,0.00000000,0.00000000,0.00000000,0.00000000,0.00000000,0.00000000,0.00000000,0.00000000
317.05000000,8.34249000,2.45800000,0.24589478,221.10722592,0.00000000,0.00000000,0.00000000,0.00000000,0.00000000,0.00000000,0.00000000,0.00000000,0.00000000,0.00000000,0.00000000
318.55000000,8.40976300,2.39900000,0.24578056,215.79993286,0.00000000,0.00000000,0.00000000,0.00000000,0.00000000,0.00000000,0.00000000,0.00000000,0.00000000,0.00000000,0.00000000
320.05000000,8.48009500,2.31300000,0.24559211,208.06387858,0.00000000,0.00000000,0.00000000,0.00000000,0.00000000,0.00000000,0.00000000,0.00000000,0.00000000,0.00000000,0.00000000
321.55000000,8.84660700,0.07300000,0.22208889,6.56665073,0.00000000,0.00000000,0.00000000,0.00000000,0.00000000,0.00000000,0.00000000,0.00000000,0.00000000,0.00000000,0.00000000
NaN,-100.00000000,NaN,-11.11111111,NaN,0.00000000,0.00000000,0.00000000,0.00000000,0.00000000,0.00000000,0.00000000,0.00000000,0.00000000,0.00000000,0.00000000