File: lab_data/AA6014-T4_results/DATA/UT_45_3.csv
Time[s],Displacement[mm],Force[kN],EngStrain_longi,EngStress[MPa],TrueStrain,TrueStress[MPa],TrueStrainRate[1/s],PlasticStrain_longi,PlasticStress[MPa],PlasticStrain_thick,PlasticStrain_width,R-Value,Thickness[mm],Width[mm], Young's Modulus [MPa]
0.65000000,0.00000000,-0.00100000,0.00000000,-0.09044395,0.00000000,-0.09044395,0.00000000,0.00097704,117.52431391,-0.00031043,-0.00066661,0.51574187,1.11390000,9.92600000,76814.70602899
2.15000000,0.00574800,0.15700000,0.00018756,14.19970028,0.00018754,14.20236351,0.00012265,0.00211418,121.29589572,-0.00107344,-0.00104074,0.00000000,0.00000000,0.00000000,0.00000000
3.65000000,0.01333100,0.41600000,0.00041922,37.62468354,0.00041913,37.64045665,0.00007619,0.00329146,124.99027652,-0.00190402,-0.00138744,0.00000000,0.00000000,0.00000000,0.00000000
5.15000000,0.02196600,0.65400000,0.00071844,59.15034384,0.00071819,59.19284008,0.00023562,0.00446138,127.96320988,-0.00272832,-0.00173306,0.00000000,0.00000000,0.00000000,0.00000000
6.65000000,0.03091700,0.90200000,0.00102733,81.58044364,0.00102681,81.66425395,0.00035034,0.00558735,130.66355706,-0.00351061,-0.00207673,0.00000000,0.00000000,0.00000000,0.00000000
8.15000000,0.04227500,1.13500000,0.00133956,102.65388419,0.00133866,102.79139477,0.00033691,0.00673002,133.37226445,-0.00428100,-0.00244903,0.00000000,0.00000000,0.00000000,0.00000000
9.65000000,0.06793200,1.28100000,0.00211167,115.85870101,0.00210944,116.10335596,0.00053649,0.00792831,135.72872993,-0.00517879,-0.00274952,0.00000000,0.00000000,0.00000000,0.00000000
11.15000000,0.10452800,1.32400000,0.00339867,119.74779089,0.00339290,120.15477372,0.00072877,0.00905522,137.98931391,-0.00593742,-0.00311781,0.00000000,0.00000000,0.00000000,0.00000000
12.65000000,0.14022000,1.36500000,0.00464533,123.45599288,0.00463458,124.02948712,0.00086462,0.01016257,140.34394692,-0.00671481,-0.00344776,0.00000000,0.00000000,0.00000000,0.00000000
14.15000000,0.17622000,1.39700000,0.00584911,126.35019930,0.00583207,127.08923566,0.00094602,0.01132636,142.43632910,-0.00752500,-0.00380136,0.00000000,0.00000000,0.00000000,0.00000000
15.65000000,0.21318300,1.42600000,0.00702222,128.97307388,0.00699768,129.87875146,0.00081136,0.01248635,144.44101300,-0.00835272,-0.00413362,0.00000000,0.00000000,0.00000000,0.00000000
17.15000000,0.24845700,1.45400000,0.00829133,131.50550450,0.00825715,132.59586047,0.00087847,0.01361663,146.63003843,-0.00914969,-0.00446693,0.00000000,0.00000000,0.00000000,0.00000000
18.65000000,0.28582700,1.47900000,0.00951778,133.76660327,0.00947277,135.03976407,0.00096175,0.01472606,148.63651429,-0.00988329,-0.00484277,0.00000000,0.00000000,0.00000000,0.00000000
20.15000000,0.32141000,1.50200000,0.01068911,135.84681414,0.01063239,137.29889583,0.00088958,0.01588662,150.56281326,-0.01073053,-0.00515609,0.00000000,0.00000000,0.00000000,0.00000000
21.65000000,0.35695300,1.52600000,0.01187378,138.01746896,0.01180384,139.65625772,0.00077056,0.01701168,152.58045641,-0.01147047,-0.00554121,0.00000000,0.00000000,0.00000000,0.00000000
23.15000000,0.39308900,1.54700000,0.01309733,139.91679193,0.01301230,141.74932879,0.00083238,0.01813914,154.32543429,-0.01224372,-0.00589542,0.00000000,0.00000000,0.00000000,0.00000000
24.65000000,0.42814200,1.56800000,0.01426856,141.81611489,0.01416772,143.83962601,0.00083866,0.01919838,156.15617363,-0.01293313,-0.00626525,0.00000000,0.00000000,0.00000000,0.00000000
26.15000000,0.46374600,1.59000000,0.01542867,143.80588181,0.01531086,146.02461483,0.00078625,0.02034603,158.09742978,-0.01371378,-0.00663225,0.00000000,0.00000000,0.00000000,0.00000000
27.65000000,0.49865400,1.61000000,0.01658878,145.61476083,0.01645269,148.03033174,0.00068257,0.02144754,159.84999943,-0.01447146,-0.00697608,0.00000000,0.00000000,0.00000000,0.00000000
29.15000000,0.53458900,1.62900000,0.01778989,147.33319589,0.01763350,149.95423708,0.00073310,0.02256732,161.51635458,-0.01525886,-0.00730846,0.00000000,0.00000000,0.00000000,0.00000000
30.65000000,0.56937300,1.64900000,0.01895000,149.14207491,0.01877269,151.96831723,0.00075430,0.02365894,163.27475295,-0.01598055,-0.00767839,0.00000000,0.00000000,0.00000000,0.00000000
32.15000000,0.60449000,1.66700000,0.02009144,150.77006603,0.01989227,153.79925443,0.00068764,0.02478196,165.04208047,-0.01676862,-0.00801334,0.00000000,0.00000000,0.00000000,0.00000000
33.65000000,0.63901900,1.68500000,0.02126278,152.39805714,0.02103988,155.63846316,0.00070883,0.02587725,166.62211986,-0.01749590,-0.00838135,0.00000000,0.00000000,0.00000000,0.00000000
35.15000000,0.67377500,1.70400000,0.02245633,154.11649221,0.02220790,157.57738353,0.00081737,0.02694698,168.38789838,-0.01823873,-0.00870825,0.00000000,0.00000000,0.00000000,0.00000000
36.65000000,0.70854900,1.72100000,0.02355300,155.65403937,0.02327991,159.32015896,0.00069248,0.02804102,169.88111108,-0.01895927,-0.00908175,0.00000000,0.00000000,0.00000000,0.00000000
38.15000000,0.74316200,1.73700000,0.02472811,157.10114258,0.02442732,160.98595709,0.00071381,0.02913966,171.47181285,-0.01972805,-0.00941162,0.00000000,0.00000000,0.00000000,0.00000000
39.65000000,0.77807600,1.75400000,0.02591056,158.63868975,0.02558057,162.74910633,0.00073466,0.03022263,173.06315820,-0.02045768,-0.00976495,0.00000000,0.00000000,0.00000000,0.00000000
41.15000000,0.81292400,1.77100000,0.02707433,160.17623691,0.02671431,164.51290174,0.00077733,0.03135247,174.57224543,-0.02125862,-0.01009385,0.00000000,0.00000000,0.00000000,0.00000000
42.65000000,0.84740300,1.78600000,0.02821211,161.53289617,0.02782148,166.09008019,0.00073301,0.03241984,176.07355849,-0.02198749,-0.01043235,0.00000000,0.00000000,0.00000000,0.00000000
44.15000000,0.88238500,1.80300000,0.02936844,163.07044334,0.02894545,167.85956859,0.00073932,0.03350967,177.67593869,-0.02273120,-0.01077847,0.00000000,0.00000000,0.00000000,0.00000000
45.65000000,0.91649400,1.81800000,0.03051733,164.42710260,0.03006094,169.44497930,0.00073137,0.03461892,179.09695731,-0.02349459,-0.01112433,0.00000000,0.00000000,0.00000000,0.00000000
47.15000000,0.95097300,1.83200000,0.03167744,165.69331791,0.03118606,170.94205879,0.00077386,0.03569454,180.51488102,-0.02419575,-0.01149879,0.00000000,0.00000000,0.00000000,0.00000000
48.65000000,0.98548400,1.84800000,0.03283011,167.14042113,0.03230271,172.62765972,0.00078742,0.03678330,181.93810379,-0.02497836,-0.01180494,0.00000000,0.00000000,0.00000000,0.00000000
50.15000000,1.02003000,1.86200000,0.03396033,168.40663644,0.03339641,174.12578195,0.00069282,0.03794211,183.37714634,-0.02580881,-0.01213330,0.00000000,0.00000000,0.00000000,0.00000000
51.65000000,1.05484400,1.87600000,0.03514278,169.67285175,0.03453937,175.63562707,0.00074249,0.03895113,184.69706028,-0.02642136,-0.01252977,0.00000000,0.00000000,0.00000000,0.00000000
53.15000000,1.08942300,1.89000000,0.03628800,170.93906706,0.03564510,177.14210393,0.00070563,0.04004674,186.13028327,-0.02716445,-0.01288228,0.00000000,0.00000000,0.00000000,0.00000000
54.65000000,1.12380100,1.90400000,0.03744056,172.20528237,0.03675668,178.65274381,0.00074792,0.04114599,187.47242901,-0.02791098,-0.01323501,0.00000000,0.00000000,0.00000000,0.00000000
56.15000000,1.15831300,1.91700000,0.03860067,173.38105373,0.03787429,180.07367799,0.00074708,0.04222750,188.71914323,-0.02862667,-0.01360082,0.00000000,0.00000000,0.00000000,0.00000000
57.65000000,1.19295900,1.93100000,0.03973100,174.64726904,0.03896203,181.58617969,0.00069624,0.04332298,190.16095367,-0.02937121,-0.01395177,0.00000000,0.00000000,0.00000000,0.00000000
59.15000000,1.22985300,1.94300000,0.04097678,175.73259645,0.04015948,182.93355201,0.00070950,0.04438772,191.40972734,-0.03007563,-0.01431209,0.00000000,0.00000000,0.00000000,0.00000000
60.65000000,1.26241800,1.95500000,0.04206600,176.81792386,0.04120528,184.25594665,0.00071601,0.04548110,192.57135573,-0.03082700,-0.01465410,0.00000000,0.00000000,0.00000000,0.00000000
62.15000000,1.29662900,1.96800000,0.04320378,177.99369522,0.04229653,185.68369528,0.00077959,0.04656471,193.82871017,-0.03154284,-0.01502187,0.00000000,0.00000000,0.00000000,0.00000000
63.65000000,1.33120800,1.98000000,0.04435267,179.07902263,0.04339724,187.02165483,0.00074318,0.04764002,195.08698449,-0.03226086,-0.01537916,0.00000000,0.00000000,0.00000000,0.00000000
65.15000000,1.36632400,1.99200000,0.04551644,180.16435004,0.04451097,188.36479067,0.00078488,0.04873883,196.35241444,-0.03301517,-0.01572366,0.00000000,0.00000000,0.00000000,0.00000000
66.65000000,1.40060100,2.00300000,0.04670267,181.15923350,0.04564491,189.61985280,0.00080544,0.04983424,197.52416470,-0.03374314,-0.01609110,0.00000000,0.00000000,0.00000000,0.00000000
68.15000000,1.43541500,2.01500000,0.04784789,182.24456091,0.04673843,190.96457841,0.00078335,0.05092482,198.69732239,-0.03448174,-0.01644307,0.00000000,0.00000000,0.00000000,0.00000000
69.65000000,1.47063200,2.02600000,0.04900800,183.23944437,0.04784496,192.21964306,0.00076828,0.05200923,199.96741831,-0.03522287,-0.01678635,0.00000000,0.00000000,0.00000000,0.00000000
71.15000000,1.50527800,2.03800000,0.05014567,184.32477178,0.04892888,193.56786035,0.00073908,0.05310210,201.04995255,-0.03595021,-0.01715190,0.00000000,0.00000000,0.00000000,0.00000000
72.65000000,1.54036000,2.04800000,0.05131700,185.22921129,0.05004366,194.73461873,0.00076659,0.05423110,202.23799939,-0.03673676,-0.01749434,0.00000000,0.00000000,0.00000000,0.00000000
74.15000000,1.57524100,2.05900000,0.05248078,186.22409475,0.05115002,195.99728008,0.00074441,0.05530742,203.32163034,-0.03746856,-0.01783886,0.00000000,0.00000000,0.00000000,0.00000000
75.65000000,1.61029000,2.06800000,0.05365200,187.03809031,0.05226222,197.07305793,0.00075055,0.05638962,204.40859934,-0.03818020,-0.01820942,0.00000000,0.00000000,0.00000000,0.00000000
77.15000000,1.64513700,2.07900000,0.05481211,188.03297377,0.05336266,198.33945802,0.00072865,0.05750199,205.50393328,-0.03892655,-0.01857544,0.00000000,0.00000000,0.00000000,0.00000000
78.65000000,1.67991800,2.08900000,0.05597967,188.93741327,0.05446893,199.51406669,0.00074194,0.05860608,206.59977022,-0.03967401,-0.01893207,0.00000000,0.00000000,0.00000000,0.00000000
80.15000000,1.71500000,2.09900000,0.05713978,189.84185278,0.05556694,200.68937406,0.00073419,0.05971597,207.69901828,-0.04043259,-0.01928338,0.00000000,0.00000000,0.00000000,0.00000000
81.65000000,1.75025000,2.10900000,0.05830356,190.74629229,0.05666721,201.86747934,0.00069788,0.06079660,208.79436049,-0.04112729,-0.01966931,0.00000000,0.00000000,0.00000000,0.00000000
83.15000000,1.78566800,2.11800000,0.05950467,191.56028785,0.05780150,202.95901892,0.00073234,0.06190872,209.80169945,-0.04189796,-0.02001076,0.00000000,0.00000000,0.00000000,0.00000000
84.65000000,1.82118700,2.12700000,0.06068344,192.37428341,0.05891346,204.04821755,0.00068940,0.06300566,210.80783823,-0.04261973,-0.02038593,0.00000000,0.00000000,0.00000000,0.00000000
86.15000000,1.85667200,2.13700000,0.06186589,193.27872291,0.06002763,205.23608291,0.00073071,0.06412557,211.82084348,-0.04336901,-0.02075656,0.00000000,0.00000000,0.00000000,0.00000000
87.65000000,1.89225700,2.14500000,0.06304467,194.00227452,0.06113712,206.23308325,0.00075123,0.06521303,212.82895433,-0.04409716,-0.02111588,0.00000000,0.00000000,0.00000000,0.00000000
89.15000000,1.92774200,2.15500000,0.06423078,194.90671403,0.06225226,207.42572387,0.00073619,0.06633740,213.84695129,-0.04486359,-0.02147381,0.00000000,0.00000000,0.00000000,0.00000000
90.65000000,1.96299200,2.16300000,0.06541700,195.63026564,0.06336627,208.42781072,0.00071430,0.06744310,214.86297552,-0.04562225,-0.02182085,0.00000000,0.00000000,0.00000000,0.00000000
92.15000000,1.99834300,2.17100000,0.06661444,196.35381724,0.06448956,209.43381769,0.00075560,0.06857175,215.88598533,-0.04639536,-0.02217640,0.00000000,0.00000000,0.00000000,0.00000000
93.65000000,2.03433200,2.18000000,0.06780433,197.16781280,0.06560452,210.53664490,0.00079660,0.06966594,216.80599768,-0.04713384,-0.02253210,0.00000000,0.00000000,0.00000000,0.00000000
95.15000000,2.07065700,2.18800000,0.06899422,197.89136441,0.06671823,211.54472518,0.00075371,0.07078296,217.73277488,-0.04787868,-0.02290429,0.00000000,0.00000000,0.00000000,0.00000000
96.65000000,2.10657900,2.19500000,0.07019167,198.52447206,0.06783776,212.45923563,0.00067642,0.07186775,218.65430706,-0.04859339,-0.02327436,0.00000000,0.00000000,0.00000000,0.00000000
98.15000000,2.14253400,2.20400000,0.07140767,199.33846762,0.06897336,213.57276247,0.00072420,0.07299597,219.58717239,-0.04935554,-0.02364043,0.00000000,0.00000000,0.00000000,0.00000000
99.65000000,2.17865700,2.21100000,0.07260878,199.97157528,0.07009379,214.49126695,0.00083469,0.07408513,220.51324955,-0.05009078,-0.02399436,0.00000000,0.00000000,0.00000000,0.00000000
101.15000000,2.21444500,2.21900000,0.07380622,200.69512688,0.07120955,215.50767602,0.00072259,0.07520737,221.44845533,-0.05084749,-0.02435988,0.00000000,0.00000000,0.00000000,0.00000000
102.65000000,2.24915800,2.22600000,0.07498867,201.32823454,0.07231012,216.42557041,0.00070091,0.07630912,222.28270591,-0.05157706,-0.02473206,0.00000000,0.00000000,0.00000000,0.00000000
104.15000000,2.28689300,2.23400000,0.07624200,202.05178614,0.07347534,217.45661842,0.00079717,0.07741497,223.21780530,-0.05230913,-0.02510584,0.00000000,0.00000000,0.00000000,0.00000000
105.65000000,2.32301600,2.24100000,0.07742456,202.68489380,0.07457352,218.37768162,0.00072717,0.07851767,224.05556428,-0.05307498,-0.02544269,0.00000000,0.00000000,0.00000000,0.00000000
107.15000000,2.35964300,2.24800000,0.07863311,203.31800146,0.07569460,219.30552846,0.00072636,0.07967375,224.90696462,-0.05383025,-0.02584350,0.00000000,0.00000000,0.00000000,0.00000000
108.65000000,2.39580000,2.25400000,0.07985667,203.86066516,0.07682832,220.14029834,0.00074633,0.08076694,225.74581122,-0.05456089,-0.02620606,0.00000000,0.00000000,0.00000000,0.00000000
110.15000000,2.43239400,2.26100000,0.08109878,204.49377282,0.07797791,221.07796785,0.00081436,0.08186779,226.68677073,-0.05530329,-0.02656450,0.00000000,0.00000000,0.00000000,0.00000000
111.65000000,2.46878500,2.26800000,0.08228500,205.12688047,0.07907455,222.00574583,0.00077916,0.08299264,227.53613238,-0.05602445,-0.02696818,0.00000000,0.00000000,0.00000000,0.00000000
113.15000000,2.50527800,2.27500000,0.08348989,205.75998813,0.08018721,222.93886667,0.00076455,0.08410396,228.28502559,-0.05676988,-0.02733409,0.00000000,0.00000000,0.00000000,0.00000000
114.65000000,2.54150200,2.28100000,0.08471711,206.30265183,0.08131923,223.78001651,0.00070159,0.08519560,229.12991747,-0.05748894,-0.02770666,0.00000000,0.00000000,0.00000000,0.00000000
116.15000000,2.57856600,2.28700000,0.08592567,206.84531554,0.08243277,224.61863717,0.00072824,0.08632336,229.98473861,-0.05826325,-0.02806011,0.00000000,0.00000000,0.00000000,0.00000000
117.65000000,2.61475600,2.29300000,0.08712678,207.38797924,0.08353823,225.45702562,0.00067263,0.08745454,230.74265379,-0.05901558,-0.02843897,0.00000000,0.00000000,0.00000000,0.00000000
119.15000000,2.65185300,2.29900000,0.08838389,207.93064295,0.08469393,226.30836179,0.00069248,0.08855056,231.49383829,-0.05972099,-0.02882957,0.00000000,0.00000000,0.00000000,0.00000000
120.65000000,2.68878200,2.30600000,0.08961489,208.56375060,0.08582432,227.25416794,0.00078759,0.08967581,232.25322092,-0.06047970,-0.02919612,0.00000000,0.00000000,0.00000000,0.00000000
122.15000000,2.72537600,2.31100000,0.09081978,209.01597036,0.08692950,227.99875434,0.00072517,0.09077135,233.10677829,-0.06119936,-0.02957199,0.00000000,0.00000000,0.00000000,0.00000000
123.65000000,2.76223800,2.31700000,0.09203956,209.55863406,0.08804710,228.84631760,0.00075856,0.09187369,233.86374136,-0.06191720,-0.02995648,0.00000000,0.00000000,0.00000000,0.00000000
125.15000000,2.79923400,2.32300000,0.09327422,210.10129777,0.08917707,229.69833290,0.00076442,0.09300525,234.62898485,-0.06267299,-0.03033226,0.00000000,0.00000000,0.00000000,0.00000000
126.65000000,2.83666700,2.32800000,0.09453500,210.55351752,0.09032962,230.45819430,0.00076353,0.09412203,235.39218598,-0.06341533,-0.03070669,0.00000000,0.00000000,0.00000000,0.00000000
128.15000000,2.87356200,2.33300000,0.09573989,211.00573728,0.09142983,231.20740312,0.00071502,0.09524756,236.15888830,-0.06416251,-0.03108505,0.00000000,0.00000000,0.00000000,0.00000000
129.65000000,2.91052500,2.33900000,0.09699322,211.54840098,0.09257300,232.06716205,0.00077540,0.09637649,236.82758322,-0.06489195,-0.03148454,0.00000000,0.00000000,0.00000000,0.00000000
131.15000000,2.94775700,2.34400000,0.09822056,212.00062073,0.09369119,232.82343948,0.00073385,0.09750622,237.59806393,-0.06565855,-0.03184767,0.00000000,0.00000000,0.00000000,0.00000000
132.65000000,2.98488700,2.34900000,0.09944778,212.45284049,0.09480803,233.58080336,0.00071261,0.09862924,238.26790401,-0.06638923,-0.03224001,0.00000000,0.00000000,0.00000000,0.00000000
134.15000000,3.02174900,2.35400000,0.10069367,212.90506024,0.09594059,234.34325141,0.00078653,0.09977642,239.04536354,-0.06713707,-0.03263936,0.00000000,0.00000000,0.00000000,0.00000000
135.65000000,3.05975300,2.35900000,0.10195444,213.35728000,0.09708537,235.11000295,0.00080580,0.10088007,239.71310986,-0.06787610,-0.03300397,0.00000000,0.00000000,0.00000000,0.00000000
137.15000000,3.09708500,2.36400000,0.10317056,213.80949975,0.09818836,235.86834462,0.00071705,0.10203127,240.49436378,-0.06864549,-0.03338578,0.00000000,0.00000000,0.00000000,0.00000000
138.65000000,3.13508800,2.36900000,0.10443878,214.26171951,0.09933731,236.63895162,0.00075669,0.10315575,241.16968946,-0.06940420,-0.03375155,0.00000000,0.00000000,0.00000000,0.00000000
140.15000000,3.17282300,2.37300000,0.10569211,214.62349531,0.10047148,237.30750562,0.00078277,0.10427565,241.84513113,-0.07011790,-0.03415775,0.00000000,0.00000000,0.00000000,0.00000000
141.65000000,3.21045700,2.37800000,0.10695289,215.07571506,0.10161110,238.07868412,0.00076842,0.10541760,242.52716202,-0.07091179,-0.03450581,0.00000000,0.00000000,0.00000000,0.00000000
143.15000000,3.24805800,2.38300000,0.10820633,215.52793482,0.10274279,238.84942237,0.00073405,0.10653153,243.20360921,-0.07164111,-0.03489042,0.00000000,0.00000000,0.00000000,0.00000000
144.65000000,3.28653100,2.38700000,0.10948578,215.88971062,0.10389664,239.52656350,0.00076667,0.10767084,243.88748624,-0.07238786,-0.03528299,0.00000000,0.00000000,0.00000000,0.00000000
146.15000000,3.32473600,2.39100000,0.11074656,216.25148642,0.10503236,240.20059368,0.00075239,0.10880546,244.57146592,-0.07313355,-0.03567191,0.00000000,0.00000000,0.00000000,0.00000000
147.65000000,3.36237000,2.39500000,0.11202600,216.61326223,0.10618358,240.87957954,0.00078511,0.10991888,245.25148112,-0.07387622,-0.03604266,0.00000000,0.00000000,0.00000000,0.00000000
149.15000000,3.40064200,2.40000000,0.11328689,217.06548198,0.10731680,241.65615512,0.00081118,0.11110533,245.84896785,-0.07466833,-0.03643701,0.00000000,0.00000000,0.00000000,0.00000000
150.65000000,3.43894800,2.40400000,0.11454389,217.42725778,0.10844525,242.33222144,0.00074304,0.11223270,246.53481735,-0.07540622,-0.03682649,0.00000000,0.00000000,0.00000000,0.00000000
152.15000000,3.47735400,2.40800000,0.11582711,217.78903359,0.10959593,243.01490818,0.00078901,0.11336345,247.12074252,-0.07613509,-0.03722836,0.00000000,0.00000000,0.00000000,0.00000000
153.65000000,3.51542500,2.41100000,0.11706556,218.06036544,0.11070521,243.58772327,0.00072803,0.11453112,247.81899312,-0.07690574,-0.03762538,0.00000000,0.00000000,0.00000000,0.00000000
155.15000000,3.55386500,2.41500000,0.11835244,218.42214124,0.11185657,244.27293558,0.00072044,0.11565597,248.40562626,-0.07764538,-0.03801059,0.00000000,0.00000000,0.00000000,0.00000000
156.65000000,3.59227100,2.42000000,0.11965811,218.87436100,0.11302338,245.06445361,0.00075990,0.11680440,249.10153305,-0.07839439,-0.03841001,0.00000000,0.00000000,0.00000000,0.00000000
158.15000000,3.63158400,2.42300000,0.12093378,219.14569285,0.11416207,245.64780937,0.00071897,0.11794634,249.69461299,-0.07913292,-0.03881342,0.00000000,0.00000000,0.00000000,0.00000000
159.65000000,3.67005800,2.42700000,0.12220211,219.50746865,0.11529293,246.33174473,0.00070489,0.11910008,250.29169386,-0.07992070,-0.03917938,0.00000000,0.00000000,0.00000000,0.00000000
161.15000000,3.70923600,2.43000000,0.12353000,219.77880051,0.11647551,246.92807573,0.00079032,0.12023935,250.88618671,-0.08066574,-0.03957362,0.00000000,0.00000000,0.00000000,0.00000000
162.65000000,3.74777700,2.43400000,0.12483189,220.14057631,0.11763359,247.62114027,0.00078289,0.12139049,251.48471324,-0.08143234,-0.03995815,0.00000000,0.00000000,0.00000000,0.00000000
164.15000000,3.78708900,2.43700000,0.12613378,220.41190816,0.11879033,248.21329481,0.00076876,0.12251724,252.07812523,-0.08217034,-0.04034690,0.00000000,0.00000000,0.00000000,0.00000000
165.65000000,3.82593200,2.44000000,0.12739078,220.68324001,0.11990592,248.79624960,0.00076100,0.12365576,252.67554823,-0.08290652,-0.04074924,0.00000000,0.00000000,0.00000000,0.00000000
167.15000000,3.86494300,2.44400000,0.12870011,221.04501582,0.12106663,249.49353391,0.00074692,0.12481924,253.28036055,-0.08367589,-0.04114335,0.00000000,0.00000000,0.00000000,0.00000000
168.65000000,3.90435600,2.44700000,0.13004300,221.31634767,0.12225569,250.09698947,0.00082531,0.12596491,253.88170749,-0.08444605,-0.04151886,0.00000000,0.00000000,0.00000000,0.00000000
170.15000000,3.94424000,2.45000000,0.13134856,221.58767952,0.12341033,250.69290116,0.00081119,0.12709621,254.48044216,-0.08518812,-0.04190809,0.00000000,0.00000000,0.00000000,0.00000000
171.65000000,3.98328400,2.45300000,0.13261311,221.85901137,0.12452745,251.28042510,0.00073119,0.12826862,255.09073720,-0.08594381,-0.04232481,0.00000000,0.00000000,0.00000000,0.00000000
173.15000000,4.02249600,2.45600000,0.13392244,222.13034323,0.12568281,251.87858178,0.00074367,0.12944098,255.59842432,-0.08672956,-0.04271142,0.00000000,0.00000000,0.00000000,0.00000000
174.65000000,4.06204400,2.45900000,0.13524667,222.40167508,0.12684995,252.48076030,0.00078217,0.13058125,256.20251677,-0.08746935,-0.04311190,0.00000000,0.00000000,0.00000000,0.00000000
176.15000000,4.10176000,2.46200000,0.13653356,222.67300693,0.12798289,253.07534430,0.00071556,0.13174766,256.71047181,-0.08825442,-0.04349323,0.00000000,0.00000000,0.00000000,0.00000000
177.65000000,4.14157600,2.46500000,0.13782056,222.94433878,0.12911464,253.67065141,0.00074777,0.13293073,257.32762654,-0.08904757,-0.04388316,0.00000000,0.00000000,0.00000000,0.00000000
179.15000000,4.18139300,2.46800000,0.13920067,223.21567064,0.13032685,254.28744080,0.00080560,0.13401842,257.92119889,-0.08972879,-0.04428963,0.00000000,0.00000000,0.00000000,0.00000000
180.65000000,4.22120900,2.47100000,0.14050633,223.48700249,0.13147232,254.88834176,0.00075907,0.13521631,258.44006515,-0.09048282,-0.04473349,0.00000000,0.00000000,0.00000000,0.00000000
182.15000000,4.26139500,2.47300000,0.14181933,223.66789039,0.13262290,255.38832149,0.00075800,0.13640947,258.95858164,-0.09127870,-0.04513077,0.00000000,0.00000000,0.00000000,0.00000000
183.65000000,4.30181600,2.47600000,0.14319200,223.93922224,0.13382435,256.00552736,0.00081582,0.13756108,259.57169620,-0.09205764,-0.04550344,0.00000000,0.00000000,0.00000000,0.00000000
185.15000000,4.34163200,2.47800000,0.14451622,224.12011015,0.13498203,256.50910179,0.00080186,0.13871923,260.08293190,-0.09279290,-0.04592633,0.00000000,0.00000000,0.00000000,0.00000000
186.65000000,4.38178400,2.48100000,0.14583678,224.39144200,0.13613518,257.11596686,0.00078153,0.13987928,260.59550625,-0.09355773,-0.04632155,0.00000000,0.00000000,0.00000000,0.00000000
188.15000000,4.42166800,2.48400000,0.14719089,224.66277385,0.13731625,257.73108723,0.00078061,0.14104428,261.11022460,-0.09431955,-0.04672473,0.00000000,0.00000000,0.00000000,0.00000000
189.65000000,4.46255900,2.48600000,0.14855233,224.84366175,0.13850231,258.24471234,0.00079246,0.14222733,261.63053283,-0.09512388,-0.04710345,0.00000000,0.00000000,0.00000000,0.00000000
191.15000000,4.50318100,2.48800000,0.14988411,225.02454965,0.13966116,258.75215426,0.00076583,0.14337350,262.14201086,-0.09586362,-0.04750988,0.00000000,0.00000000,0.00000000,0.00000000
192.65000000,4.54413900,2.49100000,0.15124556,225.29588151,0.14084445,259.37088227,0.00076473,0.14454086,262.65991057,-0.09663445,-0.04790641,0.00000000,0.00000000,0.00000000,0.00000000
194.15000000,4.58455900,2.49300000,0.15255122,225.47676941,0.14197794,259.87352616,0.00073821,0.14570998,263.17913391,-0.09740666,-0.04830332,0.00000000,0.00000000,0.00000000,0.00000000
195.65000000,4.62518100,2.49600000,0.15392022,225.74810126,0.14316503,260.49529917,0.00075024,0.14686181,263.69464214,-0.09815684,-0.04870497,0.00000000,0.00000000,0.00000000,0.00000000
197.15000000,4.66647500,2.49800000,0.15528167,225.92898916,0.14434418,261.01161915,0.00073627,0.14799631,264.20639997,-0.09888764,-0.04910867,0.00000000,0.00000000,0.00000000,0.00000000
198.65000000,4.70716500,2.50000000,0.15662089,226.10987706,0.14550273,261.52340700,0.00074830,0.14914224,264.72202091,-0.09962446,-0.04951778,0.00000000,0.00000000,0.00000000,0.00000000
200.15000000,4.74829100,2.50200000,0.15798989,226.29076497,0.14668565,262.04241778,0.00078619,0.15031862,265.24659112,-0.10041452,-0.04990410,0.00000000,0.00000000,0.00000000,0.00000000
201.65000000,4.78988600,2.50400000,0.15931778,226.47165287,0.14783171,262.55261333,0.00072086,0.15149368,265.77168591,-0.10117856,-0.05031513,0.00000000,0.00000000,0.00000000,0.00000000
203.15000000,4.83111300,2.50600000,0.16068311,226.65254077,0.14900872,263.07177616,0.00077785,0.15266735,266.29728003,-0.10194582,-0.05072153,0.00000000,0.00000000,0.00000000,0.00000000
204.65000000,4.87267500,2.50700000,0.16204833,226.74298472,0.15018425,263.48630749,0.00081539,0.15387278,266.72597146,-0.10274833,-0.05112445,0.00000000,0.00000000,0.00000000,0.00000000
206.15000000,4.91400300,2.51000000,0.16339867,227.01431657,0.15134561,264.10815321,0.00078234,0.15504360,267.25244614,-0.10350751,-0.05153610,0.00000000,0.00000000,0.00000000,0.00000000
207.65000000,4.95573300,2.51200000,0.16476400,227.19520447,0.15251849,264.62879514,0.00083296,0.15627783,267.69029092,-0.10433301,-0.05194481,0.00000000,0.00000000,0.00000000,0.00000000
209.15000000,4.99786600,2.51300000,0.16610689,227.28564842,0.15367076,265.03936037,0.00076794,0.15744580,268.21765292,-0.10506977,-0.05237603,0.00000000,0.00000000,0.00000000,0.00000000
210.65000000,5.03912600,2.51500000,0.16744978,227.46653633,0.15482169,265.55575729,0.00070308,0.15864391,268.75401809,-0.10581916,-0.05282474,0.00000000,0.00000000,0.00000000,0.00000000
212.15000000,5.08122600,2.51700000,0.16886722,227.64742423,0.15603509,266.08961240,0.00082985,0.15987363,269.19290536,-0.10667226,-0.05320137,0.00000000,0.00000000,0.00000000,0.00000000
213.65000000,5.12362800,2.51900000,0.17024744,227.82831213,0.15721522,266.61550004,0.00076523,0.16110183,269.63205578,-0.10745784,-0.05364399,0.00000000,0.00000000,0.00000000,0.00000000
215.15000000,5.16572700,2.52000000,0.17170222,227.91875608,0.15845758,267.05291299,0.00089159,0.16226409,270.16119914,-0.10818299,-0.05408110,0.00000000,0.00000000,0.00000000,0.00000000
216.65000000,5.20806200,2.52200000,0.17308244,228.09964398,0.15963485,267.57968794,0.00082705,0.16345786,270.59245459,-0.10897694,-0.05448092,0.00000000,0.00000000,0.00000000,0.00000000
218.15000000,5.24955600,2.52300000,0.17449989,228.19008793,0.16084243,268.00923292,0.00082586,0.16468170,271.03254137,-0.10980238,-0.05487932,0.00000000,0.00000000,0.00000000,0.00000000
219.65000000,5.29182300,2.52500000,0.17591733,228.37097583,0.16204855,268.54538891,0.00082487,0.16583965,271.56292783,-0.11054513,-0.05529452,0.00000000,0.00000000,0.00000000,0.00000000
221.15000000,5.33489600,2.52700000,0.17737222,228.55186374,0.16328502,269.09061570,0.00082404,0.16706044,272.00364030,-0.11133320,-0.05572724,0.00000000,0.00000000,0.00000000,0.00000000
222.65000000,5.37790200,2.52800000,0.17878967,228.64230769,0.16448821,269.52118966,0.00082286,0.16830953,272.56061313,-0.11219498,-0.05611455,0.00000000,0.00000000,0.00000000,0.00000000
224.15000000,5.42107600,2.52900000,0.18020711,228.73275164,0.16568994,269.95202003,0.00075858,0.16958972,273.01910084,-0.11304817,-0.05654155,0.00000000,0.00000000,0.00000000,0.00000000
225.65000000,5.46468600,2.53100000,0.18166189,228.91363954,0.16692183,270.49852369,0.00082086,0.17080589,273.46074446,-0.11383708,-0.05696881,0.00000000,0.00000000,0.00000000,0.00000000
227.15000000,5.50802700,2.53200000,0.18307944,229.00408349,0.16812074,270.93002387,0.00088301,0.17208294,273.91980423,-0.11466992,-0.05741302,0.00000000,0.00000000,0.00000000,0.00000000
228.65000000,5.55180600,2.53300000,0.18449689,229.09452744,0.16931812,271.36175502,0.00088196,0.17329604,274.36198091,-0.11543299,-0.05786305,0.00000000,0.00000000,0.00000000,0.00000000
230.15000000,5.59511400,2.53500000,0.18591444,229.27541534,0.17051416,271.90102681,0.00081810,0.17444543,274.78725423,-0.11614008,-0.05830535,0.00000000,0.00000000,0.00000000,0.00000000
231.65000000,5.63869000,2.53600000,0.18736922,229.36585929,0.17174012,272.34196195,0.00087982,0.17556402,275.09599583,-0.11682661,-0.05873741,0.00000000,0.00000000,0.00000000,0.00000000
233.15000000,5.68283700,2.53800000,0.18886122,229.54674720,0.17299589,272.89922643,0.00087872,0.17661782,275.49593149,-0.11747703,-0.05914079,0.00000000,0.00000000,0.00000000,0.00000000
234.65000000,5.72698500,2.53900000,0.19035333,229.63719115,0.17425018,273.34939594,0.00081486,0.17757754,275.87035212,-0.11809001,-0.05948754,0.00000000,0.00000000,0.00000000,0.00000000
236.15000000,5.77076300,2.54000000,0.19184544,229.72763510,0.17550290,273.79983535,0.00087652,0.17856713,276.25352417,-0.11875840,-0.05980874,0.00000000,0.00000000,0.00000000,0.00000000
237.65000000,5.81521200,2.54000000,0.19333744,229.72763510,0.17675396,274.14258898,0.00081283,0.17949401,276.61976977,-0.11934546,-0.06014855,0.00000000,0.00000000,0.00000000,0.00000000
239.15000000,5.85939300,2.54100000,0.19479222,229.81807905,0.17797230,274.58485337,0.00081184,0.18045084,276.99479235,-0.12000152,-0.06044932,0.00000000,0.00000000,0.00000000,0.00000000
240.65000000,5.90578900,2.54200000,0.19613511,229.90852300,0.17909562,275.00165670,0.00074848,0.18146855,277.38723111,-0.12073322,-0.06073532,0.00000000,0.00000000,0.00000000,0.00000000
242.15000000,5.95215200,2.54300000,0.19740344,229.99896695,0.18015542,275.40155524,0.00062311,0.18260711,277.92330963,-0.12157478,-0.06103233,0.00000000,0.00000000,0.00000000,0.00000000
243.65000000,5.99922000,2.54300000,0.19863444,229.99896695,0.18118295,275.68468397,0.00068479,0.18393208,278.29324348,-0.12263559,-0.06129649,0.00000000,0.00000000,0.00000000,0.00000000
245.15000000,6.04622100,2.54400000,0.19971622,230.08941090,0.18208505,276.04199882,0.00055984,0.18534598,278.79827229,-0.12370224,-0.06164374,0.00000000,0.00000000,0.00000000,0.00000000
246.65000000,6.09315500,2.54600000,0.20087256,230.27029880,0.18304842,276.52528219,0.00062131,0.18694049,279.46472753,-0.12492705,-0.06201345,0.00000000,0.00000000,0.00000000,0.00000000
248.15000000,6.13894700,2.54700000,0.20199167,230.36074275,0.18397990,276.89169312,0.00062092,0.18856465,280.03086760,-0.12604814,-0.06251652,0.00000000,0.00000000,0.00000000,0.00000000
249.65000000,6.18232200,2.54800000,0.20325989,230.45118670,0.18503445,277.29266931,0.00074404,0.19033907,280.64044966,-0.12706369,-0.06327538,0.00000000,0.00000000,0.00000000,0.00000000
251.15000000,6.22371700,2.54900000,0.20456556,230.54163065,0.18611897,277.70250741,0.00074342,0.19217299,281.15764199,-0.12792706,-0.06424594,0.00000000,0.00000000,0.00000000,0.00000000
252.65000000,6.26400400,2.55000000,0.20605767,230.63207460,0.18735691,278.15558176,0.00080425,0.19430681,281.87133274,-0.12879217,-0.06551464,0.00000000,0.00000000,0.00000000,0.00000000
254.15000000,6.30318200,2.55100000,0.20777356,230.72251856,0.18877863,278.66055658,0.00098847,0.19677202,282.56984005,-0.12968197,-0.06709005,0.00000000,0.00000000,0.00000000,0.00000000
255.65000000,6.34299900,2.55200000,0.20963867,230.81296251,0.19032169,279.20028422,0.00098695,0.19950557,283.23511547,-0.13065500,-0.06885057,0.00000000,0.00000000,0.00000000,0.00000000
257.15000000,6.38117100,2.55300000,0.21161567,230.90340646,0.19195473,279.76618475,0.00110865,0.20247189,284.07990830,-0.13197230,-0.07049959,0.00000000,0.00000000,0.00000000,0.00000000
258.65000000,6.41961100,2.55400000,0.21370456,230.99385041,0.19367730,280.35828855,0.00116830,0.20548967,284.94195542,-0.13390220,-0.07158747,0.00000000,0.00000000,0.00000000,0.00000000
260.15000000,6.45855400,2.55500000,0.21594267,231.08429436,0.19551963,280.98525311,0.00122741,0.20843818,285.78674825,-0.13632193,-0.07211625,0.00000000,0.00000000,0.00000000,0.00000000
261.65000000,6.50055300,2.55600000,0.21840456,231.17473831,0.19754226,281.66435429,0.00140871,0.21081007,286.35558188,-0.13844520,-0.07236487,0.00000000,0.00000000,0.00000000,0.00000000
263.15000000,6.54503600,2.55600000,0.22127700,231.17473831,0.19989703,282.32839088,0.00171133,0.21218890,286.63956342,-0.13963384,-0.07255506,0.00000000,0.00000000,0.00000000,0.00000000
264.65000000,6.59334600,2.55600000,0.22455967,231.17473831,0.20258132,283.08726049,0.00182861,0.21299640,286.87205749,-0.14026212,-0.07273428,0.00000000,0.00000000,0.00000000,0.00000000
266.15000000,6.64390600,2.55500000,0.22806622,231.08429436,0.20544076,283.78681639,0.00194492,0.21359425,287.04431143,-0.14075116,-0.07284309,0.00000000,0.00000000,0.00000000,0.00000000
267.65000000,6.69543900,2.55500000,0.23179667,231.08429436,0.20847381,284.64886351,0.00206038,0.21409740,287.52820427,-0.14113760,-0.07295980,0.00000000,0.00000000,0.00000000,0.00000000
269.15000000,6.74767700,2.55500000,0.23548967,231.08429436,0.21146738,285.50225781,0.00199373,0.21448569,287.64032402,-0.14142180,-0.07306388,0.00000000,0.00000000,0.00000000,0.00000000
270.65000000,6.80156100,2.55400000,0.23880978,230.99385041,0.21415106,286.15744049,0.00156645,0.21484395,287.74381324,-0.14170622,-0.07313773,0.00000000,0.00000000,0.00000000,0.00000000
272.15000000,6.85594800,2.55300000,0.24089822,230.90340646,0.21583549,286.52762658,0.00084168,0.21514245,287.83006710,-0.14192599,-0.07321646,0.00000000,0.00000000,0.00000000,0.00000000
273.65000000,6.91134200,2.55200000,0.24209156,230.81296251,0.21679670,286.69083164,0.00054056,0.21534971,288.00306258,-0.14206533,-0.07328437,0.00000000,0.00000000,0.00000000,0.00000000
275.15000000,6.96660100,2.55300000,0.24291211,230.90340646,0.21745710,286.99264038,0.00042020,0.21555850,288.06344849,-0.14221779,-0.07334072,0.00000000,0.00000000,0.00000000,0.00000000
276.65000000,7.02202800,2.55500000,0.24354622,231.08429436,0.21796715,287.36400127,0.00030006,0.21576744,288.12388579,-0.14234953,-0.07341790,0.00000000,0.00000000,0.00000000,0.00000000
278.15000000,7.07732000,2.55600000,0.24410578,231.17473831,0.21841702,287.60582761,0.00023990,0.21597474,288.29702717,-0.14250028,-0.07347445,0.00000000,0.00000000,0.00000000,0.00000000
279.65000000,7.13362100,2.55600000,0.24455344,231.17473831,0.21877679,287.70931683,0.00023981,0.21615207,288.46154945,-0.14263060,-0.07352147,0.00000000,0.00000000,0.00000000,0.00000000
281.15000000,7.18995600,2.55600000,0.24492656,231.17473831,0.21907654,287.79557070,0.00017994,0.21632929,288.62608650,-0.14275386,-0.07357543,0.00000000,0.00000000,0.00000000,0.00000000
282.65000000,7.24541900,2.55700000,0.24526222,231.26518226,0.21934613,287.98579478,0.00017971,0.21647497,288.89475231,-0.14284199,-0.07363298,0.00000000,0.00000000,0.00000000,0.00000000
284.15000000,7.30118200,2.55700000,0.24552344,231.26518226,0.21955588,288.04620639,0.00017967,0.21661913,289.27628957,-0.14293558,-0.07368355,0.00000000,0.00000000,0.00000000,0.00000000
285.65000000,7.35140400,2.55700000,0.24582200,231.26518226,0.21979555,288.11525189,0.00017981,0.21682289,289.67527010,-0.14311065,-0.07371223,0.00000000,0.00000000,0.00000000,0.00000000
287.15000000,7.38648800,2.55800000,0.24604600,231.35562621,0.21997534,288.27975262,0.00017978,0.00000000,0.00000000,0.00000000,0.00000000,0.00000000,0.00000000,0.00000000,0.00000000
288.65000000,7.40801300,2.55900000,0.24627000,231.44607016,0.22015509,288.44429386,0.00011983,0.00000000,0.00000000,0.00000000,0.00000000,0.00000000,0.00000000,0.00000000,0.00000000
290.15000000,7.42473500,2.56000000,0.24649378,231.53651411,0.22033463,288.60882417,0.00011963,0.00000000,0.00000000,0.00000000,0.00000000,0.00000000,0.00000000,0.00000000,0.00000000
291.65000000,7.44047900,2.56100000,0.24668011,231.62695806,0.22048411,288.76472182,0.00005972,0.00000000,0.00000000,0.00000000,0.00000000,0.00000000,0.00000000,0.00000000,0.00000000
293.15000000,7.45659000,2.56400000,0.24690378,231.89828992,0.22066350,289.15485376,0.00011959,0.00000000,0.00000000,0.00000000,0.00000000,0.00000000,0.00000000,0.00000000,0.00000000
294.65000000,7.47636200,2.56700000,0.24712756,232.16962177,0.22084295,289.54513287,0.00011957,0.00000000,0.00000000,0.00000000,0.00000000,0.00000000,0.00000000,0.00000000,0.00000000
296.15000000,7.50731900,2.56500000,0.24731422,231.98873387,0.00000000,0.00000000,0.00000000,0.00000000,0.00000000,0.00000000,0.00000000,0.00000000,0.00000000,0.00000000,0.00000000
297.65000000,7.55459300,2.55800000,0.24746322,231.35562621,0.00000000,0.00000000,0.00000000,0.00000000,0.00000000,0.00000000,0.00000000,0.00000000,0.00000000,0.00000000,0.00000000
299.15000000,7.60626100,2.55600000,0.24761244,231.17473831,0.00000000,0.00000000,0.00000000,0.00000000,0.00000000,0.00000000,0.00000000,0.00000000,0.00000000,0.00000000,0.00000000
300.65000000,7.65997400,2.55400000,0.24776189,230.99385041,0.00000000,0.00000000,0.00000000,0.00000000,0.00000000,0.00000000,0.00000000,0.00000000,0.00000000,0.00000000,0.00000000
302.15000000,7.71506600,2.55200000,0.24787378,230.81296251,0.00000000,0.00000000,0.00000000,0.00000000,0.00000000,0.00000000,0.00000000,0.00000000,0.00000000,0.00000000,0.00000000
303.65000000,7.77140200,2.55100000,0.24798567,230.72251856,0.00000000,0.00000000,0.00000000,0.00000000,0.00000000,0.00000000,0.00000000,0.00000000,0.00000000,0.00000000,0.00000000
305.15000000,7.82887700,2.54800000,0.24809756,230.45118670,0.00000000,0.00000000,0.00000000,0.00000000,0.00000000,0.00000000,0.00000000,0.00000000,0.00000000,0.00000000,0.00000000
306.65000000,7.88669000,2.54500000,0.24820944,230.17985485,0.00000000,0.00000000,0.00000000,0.00000000,0.00000000,0.00000000,0.00000000,0.00000000,0.00000000,0.00000000,0.00000000
308.15000000,7.94517600,2.54100000,0.24828400,229.81807905,0.00000000,0.00000000,0.00000000,0.00000000,0.00000000,0.00000000,0.00000000,0.00000000,0.00000000,0.00000000,0.00000000
309.65000000,8.00496900,2.53500000,0.24832122,229.27541534,0.00000000,0.00000000,0.00000000,0.00000000,0.00000000,0.00000000,0.00000000,0.00000000,0.00000000,0.00000000,0.00000000
311.15000000,8.06455900,2.52800000,0.24835856,228.64230769,0.00000000,0.00000000,0.00000000,0.00000000,0.00000000,0.00000000,0.00000000,0.00000000,0.00000000,0.00000000,0.00000000
312.65000000,8.12462600,2.51700000,0.24839567,227.64742423,0.00000000,0.00000000,0.00000000,0.00000000,0.00000000,0.00000000,0.00000000,0.00000000,0.00000000,0.00000000,0.00000000
314.15000000,8.18563800,2.50200000,0.24839556,226.29076497,0.00000000,0.00000000,0.00000000,0.00000000,0.00000000,0.00000000,0.00000000,0.00000000,0.00000000,0.00000000,0.00000000
315.65000000,8.24806700,2.47600000,0.24832100,223.93922224,0.00000000,0.00000000,0.00000000,0.00000000,0.00000000,0.00000000,0.00000000,0.00000000,0.00000000,0.00000000,0.00000000
317.15000000,8.31365700,2.42900000,0.24824689,219.68835656,0.00000000,0.00000000,0.00000000,0.00000000,0.00000000,0.00000000,0.00000000,0.00000000,0.00000000,0.00000000,0.00000000
318.65000000,8.38284700,2.35500000,0.24806167,212.99550419,0.00000000,0.00000000,0.00000000,0.00000000,0.00000000,0.00000000,0.00000000,0.00000000,0.00000000,0.00000000,0.00000000
320.15000000,8.49329000,1.94400000,0.24714344,175.82304040,0.00000000,0.00000000,0.00000000,0.00000000,0.00000000,0.00000000,0.00000000,0.00000000,0.00000000,0.00000000,0.00000000
321.65000000,8.79899800,0.00000000,0.27594578,0.00000000,0.00000000,0.00000000,0.00000000,0.00000000,0.00000000,0.00000000,0.00000000,0.00000000,0.00000000,0.00000000,0.00000000
NaN,-100.00000000,NaN,-11.11111111,NaN,0.00000000,0.00000000,0.00000000,0.00000000,0.00000000,0.00000000,0.00000000,0.00000000,0.00000000,0.00000000,0.00000000