File: lab_data/AA6014-T4_results/DATA/UT_45_1.csv
Time[s],Displacement[mm],Force[kN],EngStrain_longi,EngStress[MPa],TrueStrain,TrueStress[MPa],TrueStrainRate[1/s],PlasticStrain_longi,PlasticStress[MPa],PlasticStrain_thick,PlasticStrain_width,R-Value,Thickness[mm],Width[mm], Young's Modulus [MPa]
0.59000000,0.00000000,-0.00200000,0.00000000,-0.17954936,0.00000000,-0.17954936,0.00000000,0.00091951,116.37604200,-0.00018449,-0.00073502,0.50280509,1.11770000,9.96600000,82396.75937056
2.09000000,0.00551600,0.15800000,0.00017967,14.18439946,0.00017965,14.18694792,0.00012843,0.00211422,120.03572565,-0.00103012,-0.00108410,0.00000000,0.00000000,0.00000000,0.00000000
3.59000000,0.01274800,0.41100000,0.00039622,36.89739352,0.00039614,36.91201309,0.00006264,0.00330052,123.70332968,-0.00188806,-0.00141246,0.00000000,0.00000000,0.00000000,0.00000000
5.09000000,0.02065500,0.64100000,0.00069778,57.54556994,0.00069753,57.58572396,0.00026117,0.00445423,126.65170310,-0.00269336,-0.00176087,0.00000000,0.00000000,0.00000000,0.00000000
6.59000000,0.02872100,0.86900000,0.00091022,78.01419700,0.00090981,78.08520726,0.00021182,0.00557123,129.23977241,-0.00349189,-0.00207934,0.00000000,0.00000000,0.00000000,0.00000000
8.09000000,0.03825900,1.10100000,0.00116556,98.84192279,0.00116488,98.95712854,0.00011609,0.00669774,131.92562985,-0.00427955,-0.00241819,0.00000000,0.00000000,0.00000000,0.00000000
9.60000000,0.05661400,1.25000000,0.00176622,112.21835012,0.00176466,112.41655266,0.00033103,0.00790371,134.26497532,-0.00513233,-0.00277138,0.00000000,0.00000000,0.00000000,0.00000000
11.09000000,0.09148300,1.30500000,0.00301278,117.15595753,0.00300825,117.50892239,0.00089927,0.00900657,136.50488094,-0.00591821,-0.00308835,0.00000000,0.00000000,0.00000000,0.00000000
12.59000000,0.12715100,1.34700000,0.00417700,120.92649409,0.00416830,121.43160406,0.00072687,0.01010059,138.65743817,-0.00666608,-0.00343451,0.00000000,0.00000000,0.00000000,0.00000000
14.09000000,0.16275700,1.38100000,0.00529500,123.97883321,0.00528103,124.63530114,0.00047642,0.01125131,140.91382796,-0.00750035,-0.00375096,0.00000000,0.00000000,0.00000000,0.00000000
15.59000000,0.19869800,1.41000000,0.00658978,126.58229894,0.00656816,127.41644816,0.00066020,0.01240082,142.90141170,-0.00827544,-0.00412537,0.00000000,0.00000000,0.00000000,0.00000000
17.09000000,0.23491800,1.43900000,0.00783156,129.18576466,0.00780105,130.19749015,0.00081909,0.01350930,145.07027309,-0.00901200,-0.00449730,0.00000000,0.00000000,0.00000000,0.00000000
18.59000000,0.27089900,1.46400000,0.00897600,131.43013166,0.00893596,132.60984852,0.00076021,0.01463151,146.97149895,-0.00979083,-0.00484068,0.00000000,0.00000000,0.00000000,0.00000000
20.09000000,0.30708700,1.48800000,0.01015800,133.58472398,0.01010675,134.94167761,0.00062398,0.01574134,148.87506706,-0.01053426,-0.00520708,0.00000000,0.00000000,0.00000000,0.00000000
21.59000000,0.34188700,1.51200000,0.01138011,135.73931631,0.01131584,137.28404481,0.00077335,0.01688268,150.78754481,-0.01133448,-0.00554820,0.00000000,0.00000000,0.00000000,0.00000000
23.09000000,0.37770700,1.53400000,0.01260389,137.71435927,0.01252512,139.45009575,0.00094323,0.01799578,152.79177631,-0.01214323,-0.00585255,0.00000000,0.00000000,0.00000000,0.00000000
24.59000000,0.41300900,1.55500000,0.01369344,139.59962755,0.01360054,141.51122729,0.00072904,0.01905658,154.51658056,-0.01285308,-0.00620350,0.00000000,0.00000000,0.00000000,0.00000000
26.09000000,0.44759800,1.57700000,0.01491333,141.57467051,0.01480322,143.68602077,0.00077942,0.02019369,156.44092853,-0.01365246,-0.00654123,0.00000000,0.00000000,0.00000000,0.00000000
27.59000000,0.48353100,1.59700000,0.01612567,143.37016411,0.01599703,145.68210359,0.00088898,0.02129581,158.17977223,-0.01443837,-0.00685744,0.00000000,0.00000000,0.00000000,0.00000000
29.09000000,0.51862700,1.61600000,0.01727800,145.07588304,0.01713043,147.58250414,0.00085781,0.02237476,159.91863262,-0.01518511,-0.00718965,0.00000000,0.00000000,0.00000000,0.00000000
30.59000000,0.55216300,1.63700000,0.01841600,146.96115132,0.01824848,149.66758788,0.00082061,0.02345612,161.66153838,-0.01592844,-0.00752768,0.00000000,0.00000000,0.00000000,0.00000000
32.09000000,0.58767800,1.65500000,0.01960611,148.57709556,0.01941639,151.49011460,0.00081987,0.02462795,163.33049300,-0.01677646,-0.00785149,0.00000000,0.00000000,0.00000000,0.00000000
33.59000000,0.62205100,1.67300000,0.02078489,150.19303980,0.02057183,153.31478545,0.00084811,0.02570194,164.89449734,-0.01752930,-0.00817265,0.00000000,0.00000000,0.00000000,0.00000000
35.09000000,0.65624600,1.69200000,0.02188144,151.89875872,0.02164548,155.22252297,0.00082523,0.02678652,166.64880031,-0.01827510,-0.00851142,0.00000000,0.00000000,0.00000000,0.00000000
36.59000000,0.69122400,1.70900000,0.02306767,153.42492828,0.02280563,156.96408339,0.00081710,0.02786522,168.22031015,-0.01899768,-0.00886754,0.00000000,0.00000000,0.00000000,0.00000000
38.09000000,0.72552200,1.72600000,0.02422778,154.95109785,0.02393894,158.70521861,0.00083050,0.02894408,169.70226018,-0.01970651,-0.00923756,0.00000000,0.00000000,0.00000000,0.00000000
39.59000000,0.76010200,1.74300000,0.02535056,156.47726741,0.02503456,160.44405307,0.00081485,0.03006232,171.37995791,-0.02049603,-0.00956629,0.00000000,0.00000000,0.00000000,0.00000000
41.09000000,0.79377700,1.76000000,0.02645489,158.00343697,0.02611101,162.18340034,0.00075593,0.03114206,172.86846380,-0.02120652,-0.00993554,0.00000000,0.00000000,0.00000000,0.00000000
42.60000000,0.82892700,1.77600000,0.02766344,159.43983185,0.02728772,163.85048678,0.00070460,0.03221348,174.35859437,-0.02191642,-0.01029706,0.00000000,0.00000000,0.00000000,0.00000000
44.09000000,0.86307200,1.79100000,0.02879744,160.78645205,0.02839059,165.41669097,0.00073238,0.03330870,175.85597778,-0.02267160,-0.01063710,0.00000000,0.00000000,0.00000000,0.00000000
45.59000000,0.89731800,1.80700000,0.02992033,162.22284693,0.02948145,167.07660859,0.00069554,0.03438600,177.25992952,-0.02338806,-0.01099794,0.00000000,0.00000000,0.00000000,0.00000000
47.09000000,0.93102700,1.82200000,0.03106556,163.56946714,0.03059279,168.65084350,0.00071654,0.03547284,178.66846705,-0.02409336,-0.01137947,0.00000000,0.00000000,0.00000000,0.00000000
48.59000000,0.96540500,1.83800000,0.03222933,165.00586202,0.03172086,170.32389095,0.00077323,0.03654271,180.17044118,-0.02480404,-0.01173867,0.00000000,0.00000000,0.00000000,0.00000000
50.09000000,1.00008600,1.85100000,0.03336711,166.17293286,0.03282251,171.71764357,0.00069279,0.03762857,181.49101072,-0.02552702,-0.01210154,0.00000000,0.00000000,0.00000000,0.00000000
51.59000000,1.03443000,1.86600000,0.03451611,167.51955306,0.03393379,173.30167657,0.00071393,0.03870452,182.90626944,-0.02626236,-0.01244216,0.00000000,0.00000000,0.00000000,0.00000000
53.09000000,1.06944600,1.88000000,0.03565744,168.77639858,0.03503644,174.79453364,0.00073440,0.03980069,184.32815786,-0.02701512,-0.01278556,0.00000000,0.00000000,0.00000000,0.00000000
54.59000000,1.10292100,1.89400000,0.03680667,170.03324410,0.03614548,176.29160104,0.00071986,0.04087196,185.65435445,-0.02775910,-0.01311286,0.00000000,0.00000000,0.00000000,0.00000000
56.09000000,1.13713300,1.90700000,0.03795933,171.20031494,0.03725661,177.69896477,0.00074797,0.04195754,186.89179677,-0.02849251,-0.01346503,0.00000000,0.00000000,0.00000000,0.00000000
57.59000000,1.17171000,1.92100000,0.03909311,172.45716047,0.03834832,179.19904740,0.00071806,0.04301075,188.31408196,-0.02922472,-0.01378602,0.00000000,0.00000000,0.00000000,0.00000000
59.09000000,1.20595600,1.93400000,0.04024200,173.62423131,0.03945338,180.61121762,0.00074612,0.04412559,189.56228472,-0.02998900,-0.01413658,0.00000000,0.00000000,0.00000000,0.00000000
60.59000000,1.24010000,1.94700000,0.04138356,174.79130215,0.04055017,182.02478771,0.00073079,0.04522179,190.80951557,-0.03074738,-0.01447441,0.00000000,0.00000000,0.00000000,0.00000000
62.09000000,1.27407500,1.96000000,0.04251756,175.95837299,0.04163851,183.43969289,0.00071570,0.04628443,192.05283521,-0.03144316,-0.01484127,0.00000000,0.00000000,0.00000000,0.00000000
63.59000000,1.30858900,1.97200000,0.04367033,177.03566915,0.04274367,184.76687583,0.00069361,0.04738498,193.30597316,-0.03220815,-0.01517683,0.00000000,0.00000000,0.00000000,0.00000000
65.09000000,1.34270000,1.98400000,0.04481556,178.11296531,0.04384037,186.09519680,0.00070711,0.04847505,194.46488578,-0.03293579,-0.01553927,0.00000000,0.00000000,0.00000000,0.00000000
66.59000000,1.37764800,1.99600000,0.04599056,179.19026147,0.04496434,187.43132115,0.00074903,0.04955171,195.71835908,-0.03365834,-0.01589337,0.00000000,0.00000000,0.00000000,0.00000000
68.09000000,1.41256300,2.00700000,0.04713567,180.17778295,0.04605850,188.67058287,0.00079088,0.05061786,196.87731487,-0.03435444,-0.01626342,0.00000000,0.00000000,0.00000000,0.00000000
69.59000000,1.44680700,2.01800000,0.04829211,181.16530443,0.04716228,189.91415945,0.00073360,0.05172164,198.04602968,-0.03512685,-0.01659478,0.00000000,0.00000000,0.00000000,0.00000000
71.09000000,1.48158700,2.03000000,0.04946322,182.24260060,0.04827882,191.25690685,0.00073914,0.05283115,199.21827017,-0.03589948,-0.01693167,0.00000000,0.00000000,0.00000000,0.00000000
72.59000000,1.51566200,2.04100000,0.05060844,183.23012208,0.04936947,192.50311353,0.00076013,0.05391843,200.38843945,-0.03662089,-0.01729754,0.00000000,0.00000000,0.00000000,0.00000000
74.09000000,1.55057600,2.05100000,0.05177589,184.12786888,0.05048006,193.66125296,0.00074491,0.05501615,201.46767597,-0.03736962,-0.01764653,0.00000000,0.00000000,0.00000000,0.00000000
75.59000000,1.58535600,2.06200000,0.05295456,185.11539036,0.05160008,194.91809358,0.00077216,0.05610417,202.64260102,-0.03808054,-0.01802363,0.00000000,0.00000000,0.00000000,0.00000000
77.09000000,1.61970100,2.07200000,0.05410333,186.01313716,0.05269048,196.07706792,0.00076436,0.05721825,203.63399311,-0.03885991,-0.01835834,0.00000000,0.00000000,0.00000000,0.00000000
78.59000000,1.65451200,2.08200000,0.05526322,186.91088396,0.05379024,197.24018168,0.00079891,0.05829811,204.71606354,-0.03956797,-0.01873014,0.00000000,0.00000000,0.00000000,0.00000000
80.09000000,1.68935800,2.09300000,0.05643078,187.89840544,0.05489604,198.50165860,0.00077004,0.05936644,205.79788710,-0.04028351,-0.01908293,0.00000000,0.00000000,0.00000000,0.00000000
81.59000000,1.72460700,2.10200000,0.05760567,188.70637756,0.05600755,199.57693425,0.00074101,0.06045790,206.88662187,-0.04103604,-0.01942186,0.00000000,0.00000000,0.00000000,0.00000000
83.09000000,1.75958800,2.11100000,0.05878056,189.51434968,0.05711783,200.65410844,0.00075405,0.06156338,207.88440918,-0.04177153,-0.01979185,0.00000000,0.00000000,0.00000000,0.00000000
84.59000000,1.79463300,2.12100000,0.05994411,190.41209648,0.05821618,201.82618035,0.00072491,0.06265597,208.97762023,-0.04250668,-0.02014928,0.00000000,0.00000000,0.00000000,0.00000000
86.09000000,1.83018100,2.13000000,0.06114111,191.22006861,0.05934485,202.91147607,0.00077311,0.06375217,209.97751665,-0.04326930,-0.02048287,0.00000000,0.00000000,0.00000000,0.00000000
87.59000000,1.86519400,2.13900000,0.06231600,192.02804073,0.06045143,203.99446011,0.00073019,0.06484008,210.97762741,-0.04398626,-0.02085382,0.00000000,0.00000000,0.00000000,0.00000000
89.09000000,1.90128100,2.14900000,0.06349467,192.92578753,0.06156034,205.17554610,0.00075781,0.06596968,211.89208568,-0.04474845,-0.02122122,0.00000000,0.00000000,0.00000000,0.00000000
90.59000000,1.93542100,2.15700000,0.06460622,193.64398497,0.06260499,206.15459129,0.00067997,0.06704679,212.99031968,-0.04547116,-0.02157563,0.00000000,0.00000000,0.00000000,0.00000000
92.09000000,1.97093800,2.16600000,0.06581067,194.45195709,0.06373570,207.24897002,0.00072780,0.06816358,213.90584862,-0.04621880,-0.02194478,0.00000000,0.00000000,0.00000000,0.00000000
93.59000000,2.00632000,2.17400000,0.06700422,195.17015453,0.06485493,208.24737893,0.00072719,0.06927060,214.91787474,-0.04696051,-0.02231009,0.00000000,0.00000000,0.00000000,0.00000000
95.09000000,2.04210600,2.18300000,0.06821278,195.97812665,0.06598695,209.34633905,0.00077528,0.07039520,215.83880582,-0.04771685,-0.02267835,0.00000000,0.00000000,0.00000000,0.00000000
96.59000000,2.07765800,2.19000000,0.06937289,196.60654941,0.06707239,210.24571372,0.00072558,0.07148936,216.85196173,-0.04844942,-0.02303994,0.00000000,0.00000000,0.00000000,0.00000000
98.09000000,2.11327800,2.19900000,0.07055889,197.41452153,0.06818084,211.34387082,0.00073848,0.07258713,217.77076509,-0.04917489,-0.02341224,0.00000000,0.00000000,0.00000000,0.00000000
99.59000000,2.14916600,2.20700000,0.07177867,198.13271897,0.06931957,212.35442136,0.00073101,0.07371260,218.60018655,-0.04993320,-0.02377941,0.00000000,0.00000000,0.00000000,0.00000000
101.09000000,2.18488400,2.21400000,0.07296856,198.76114173,0.07042916,213.26445515,0.00076500,0.07479950,219.61742364,-0.05065275,-0.02414675,0.00000000,0.00000000,0.00000000,0.00000000
102.59000000,2.22077200,2.22200000,0.07418811,199.47933917,0.07156513,214.27833455,0.00077759,0.07588801,220.44208469,-0.05139055,-0.02449746,0.00000000,0.00000000,0.00000000,0.00000000
104.09000000,2.25689600,2.22900000,0.07538933,200.10776194,0.07268277,215.19375270,0.00077031,0.07700953,221.27562977,-0.05214635,-0.02486318,0.00000000,0.00000000,0.00000000,0.00000000
105.59000000,2.29328600,2.23600000,0.07658289,200.73618470,0.07379203,216.10914162,0.00071370,0.07813196,222.20866768,-0.05290463,-0.02522733,0.00000000,0.00000000,0.00000000,0.00000000
107.09000000,2.32937400,2.24300000,0.07781744,201.36460746,0.07493811,217.03428661,0.00078899,0.07921344,223.03659300,-0.05361689,-0.02559655,0.00000000,0.00000000,0.00000000,0.00000000
108.59000000,2.36556500,2.25000000,0.07899633,201.99303022,0.07603129,217.94973896,0.00075393,0.08033804,223.87575027,-0.05436133,-0.02597671,0.00000000,0.00000000,0.00000000,0.00000000
110.09000000,2.40091500,2.25700000,0.08018244,202.62145298,0.07712996,218.86813637,0.00067695,0.08143730,224.71082324,-0.05512116,-0.02631615,0.00000000,0.00000000,0.00000000,0.00000000
111.59000000,2.43693700,2.26400000,0.08138367,203.24987574,0.07824139,219.79109588,0.00069738,0.08253532,225.54719805,-0.05583759,-0.02669773,0.00000000,0.00000000,0.00000000,0.00000000
113.09000000,2.47369600,2.27100000,0.08260300,203.87829850,0.07936833,220.71925759,0.00075101,0.08364235,226.38720399,-0.05658849,-0.02705386,0.00000000,0.00000000,0.00000000,0.00000000
114.59000000,2.51008700,2.27700000,0.08380789,204.41694658,0.08048066,221.54869933,0.00070915,0.08477431,227.33284360,-0.05736206,-0.02741225,0.00000000,0.00000000,0.00000000,0.00000000
116.09000000,2.54641300,2.28400000,0.08503900,205.04536934,0.08161593,222.48222250,0.00070855,0.08588015,228.07746316,-0.05806579,-0.02781436,0.00000000,0.00000000,0.00000000,0.00000000
117.59000000,2.58243500,2.29000000,0.08625878,205.58401742,0.08273948,223.31744349,0.00076935,0.08700527,228.82789370,-0.05881863,-0.02818664,0.00000000,0.00000000,0.00000000,0.00000000
119.09000000,2.61919600,2.29600000,0.08747844,206.12266550,0.08386166,224.15395564,0.00074089,0.08811406,229.67465817,-0.05956575,-0.02854830,0.00000000,0.00000000,0.00000000,0.00000000
120.59000000,2.65565300,2.30200000,0.08868322,206.66131358,0.08496891,224.98870478,0.00073333,0.08921256,230.42186864,-0.06028642,-0.02892614,0.00000000,0.00000000,0.00000000,0.00000000
122.09000000,2.69261400,2.30800000,0.08991033,207.19996166,0.08609543,225.82937928,0.00076677,0.09033724,231.17653300,-0.06103316,-0.02930409,0.00000000,0.00000000,0.00000000,0.00000000
123.59000000,2.72857000,2.31400000,0.09113756,207.73860974,0.08722078,226.67139883,0.00077977,0.09146599,232.03258179,-0.06179391,-0.02967208,0.00000000,0.00000000,0.00000000,0.00000000
125.09000000,2.76560100,2.32000000,0.09237611,208.27725782,0.08835524,227.51710093,0.00075812,0.09257106,232.78562687,-0.06254217,-0.03002889,0.00000000,0.00000000,0.00000000,0.00000000
126.59000000,2.80256200,2.32500000,0.09359211,208.72613122,0.08946779,228.26125049,0.00075057,0.09368834,233.54292950,-0.06327788,-0.03041046,0.00000000,0.00000000,0.00000000,0.00000000
128.09000000,2.83962500,2.33100000,0.09483789,209.26477930,0.09060631,229.11100919,0.00075622,0.09483455,234.30845107,-0.06404046,-0.03079409,0.00000000,0.00000000,0.00000000,0.00000000
129.59000000,2.87598300,2.33700000,0.09606511,209.80342739,0.09172659,229.95821695,0.00075537,0.09593729,234.96571173,-0.06476224,-0.03117505,0.00000000,0.00000000,0.00000000,0.00000000
131.09000000,2.91334900,2.34200000,0.09729989,210.25230079,0.09285252,230.70982629,0.00078916,0.09704749,235.72549844,-0.06551203,-0.03153547,0.00000000,0.00000000,0.00000000,0.00000000
132.59000000,2.94997600,2.34700000,0.09853100,210.70117419,0.09397383,231.46177158,0.00076116,0.09814953,236.48475897,-0.06621985,-0.03192967,0.00000000,0.00000000,0.00000000,0.00000000
134.09000000,2.98724100,2.35200000,0.09977689,211.15004759,0.09510733,232.21794242,0.00074655,0.09925830,237.14722018,-0.06696483,-0.03229347,0.00000000,0.00000000,0.00000000,0.00000000
135.59000000,3.02433700,2.35700000,0.10100767,211.59892099,0.09622582,232.97203427,0.00075218,0.10037620,237.81304798,-0.06771526,-0.03266095,0.00000000,0.00000000,0.00000000,0.00000000
137.09000000,3.06163300,2.36200000,0.10223856,212.04779439,0.09734316,233.72725459,0.00073097,0.10150457,238.58262312,-0.06848420,-0.03302037,0.00000000,0.00000000,0.00000000,0.00000000
138.59000000,3.09896500,2.36700000,0.10346956,212.49666779,0.09845936,234.48360356,0.00064937,0.10261282,239.24866595,-0.06917904,-0.03343378,0.00000000,0.00000000,0.00000000,0.00000000
140.09000000,3.13653200,2.37200000,0.10473778,212.94554119,0.09960800,235.24898396,0.00072268,0.10372875,240.01801572,-0.06987117,-0.03385758,0.00000000,0.00000000,0.00000000,0.00000000
141.59000000,3.17356200,2.37600000,0.10597622,213.30463991,0.10072840,235.90985983,0.00072166,0.10485464,240.69082999,-0.07065919,-0.03419545,0.00000000,0.00000000,0.00000000,0.00000000
143.09000000,3.21055800,2.38100000,0.10720722,213.75351331,0.10184083,236.66943371,0.00072106,0.10597933,241.36457641,-0.07135861,-0.03462072,0.00000000,0.00000000,0.00000000,0.00000000
144.59000000,3.24781900,2.38600000,0.10845311,214.20238671,0.10296545,237.43330196,0.00073409,0.10715410,241.95109731,-0.07219301,-0.03496110,0.00000000,0.00000000,0.00000000,0.00000000
146.09000000,3.28649700,2.39000000,0.10974367,214.56148543,0.10412906,238.10824957,0.00080676,0.10832117,242.73826211,-0.07297719,-0.03534399,0.00000000,0.00000000,0.00000000,0.00000000
147.59000000,3.32288300,2.39400000,0.11097811,214.92058415,0.10524081,238.77206462,0.00075183,0.10941015,243.30618035,-0.07364994,-0.03576021,0.00000000,0.00000000,0.00000000,0.00000000
149.09000000,3.36182800,2.39900000,0.11222400,215.36945755,0.10636161,239.53907956,0.00075818,0.11053938,243.98586625,-0.07440169,-0.03613769,0.00000000,0.00000000,0.00000000,0.00000000
150.59000000,3.39942900,2.40300000,0.11347756,215.72855627,0.10748805,240.20890550,0.00075753,0.11178335,244.69496178,-0.07529010,-0.03649325,0.00000000,0.00000000,0.00000000,0.00000000
152.09000000,3.43535100,2.40700000,0.11466000,216.08765499,0.10854943,240.86426551,0.00060955,0.11284359,245.36021797,-0.07596628,-0.03687731,0.00000000,0.00000000,0.00000000,0.00000000
153.59000000,3.47496200,2.41100000,0.11606978,216.44675371,0.10981339,241.56968032,0.00086911,0.11400354,245.94992405,-0.07675842,-0.03724512,0.00000000,0.00000000,0.00000000,0.00000000
155.09000000,3.51427500,2.41500000,0.11733800,216.80585243,0.11094907,242.24541755,0.00077441,0.11509594,246.52396407,-0.07744941,-0.03764653,0.00000000,0.00000000,0.00000000,0.00000000
156.59000000,3.55241400,2.41900000,0.11858033,217.16495115,0.11206032,242.91644345,0.00064060,0.11623196,247.21133584,-0.07823431,-0.03799765,0.00000000,0.00000000,0.00000000,0.00000000
158.09000000,3.59028100,2.42200000,0.11986700,217.43427519,0.11320993,243.49746946,0.00074586,0.11736809,247.79832698,-0.07897583,-0.03839225,0.00000000,0.00000000,0.00000000,0.00000000
159.59000000,3.62982900,2.42600000,0.12119133,217.79337391,0.11439181,244.18804329,0.00083203,0.11853906,248.39502753,-0.07974839,-0.03879067,0.00000000,0.00000000,0.00000000,0.00000000
161.09000000,3.66830000,2.43000000,0.12249300,218.15247263,0.11555210,244.87462346,0.00064470,0.11966109,249.08246735,-0.08050501,-0.03915608,0.00000000,0.00000000,0.00000000,0.00000000
162.59000000,3.70646900,2.43300000,0.12377233,218.42179667,0.11669118,245.45637210,0.00078363,0.12074539,249.55766793,-0.08120749,-0.03953790,0.00000000,0.00000000,0.00000000,0.00000000
164.09000000,3.74571500,2.43700000,0.12505189,218.78089540,0.11782916,246.13985962,0.00072306,0.12191392,250.25901291,-0.08198168,-0.03993224,0.00000000,0.00000000,0.00000000,0.00000000
165.59000000,3.78391800,2.44000000,0.12634611,219.05021944,0.11897886,246.72636280,0.00082151,0.12305653,250.85289170,-0.08274667,-0.04030986,0.00000000,0.00000000,0.00000000,0.00000000
167.09000000,3.82218900,2.44400000,0.12760311,219.40931816,0.12009424,247.40662976,0.00076085,0.12418466,251.44415431,-0.08345844,-0.04072622,0.00000000,0.00000000,0.00000000,0.00000000
168.59000000,3.86203900,2.44700000,0.12893122,219.67864220,0.12127136,248.00207803,0.00082632,0.12536405,252.04940590,-0.08424650,-0.04111755,0.00000000,0.00000000,0.00000000,0.00000000
170.09000000,3.90067900,2.45000000,0.13020311,219.94796624,0.12239736,248.58587572,0.00071957,0.12652860,252.65198353,-0.08499614,-0.04153246,0.00000000,0.00000000,0.00000000,0.00000000
171.59000000,3.93952200,2.45300000,0.13144878,220.21729028,0.12349892,249.16458393,0.00065924,0.12772449,253.26359688,-0.08577849,-0.04194599,0.00000000,0.00000000,0.00000000,0.00000000
173.09000000,3.97806100,2.45600000,0.13274311,220.48661432,0.12464222,249.75469346,0.00076388,0.12890077,253.76846730,-0.08653929,-0.04236148,0.00000000,0.00000000,0.00000000,0.00000000
174.59000000,4.01763900,2.46000000,0.13408222,220.84571304,0.12582371,250.45719701,0.00077003,0.13008059,254.37806714,-0.08732368,-0.04275691,0.00000000,0.00000000,0.00000000,0.00000000
176.09000000,4.05661500,2.46300000,0.13538767,221.11503708,0.12697415,251.05128601,0.00076895,0.13124767,254.88239646,-0.08810002,-0.04314765,0.00000000,0.00000000,0.00000000,0.00000000
177.59000000,4.09659800,2.46600000,0.13672300,221.38436112,0.12814956,251.65269512,0.00084686,0.13239240,255.48505718,-0.08884758,-0.04354483,0.00000000,0.00000000,0.00000000,0.00000000
179.09000000,4.13567600,2.46800000,0.13803244,221.56391048,0.12930085,252.14691864,0.00077361,0.13356822,256.09676455,-0.08963505,-0.04393317,0.00000000,0.00000000,0.00000000,0.00000000
180.59000000,4.17549000,2.47100000,0.13938633,221.83323452,0.13048981,252.75375569,0.00080547,0.13473107,256.60275548,-0.09041414,-0.04431692,0.00000000,0.00000000,0.00000000,0.00000000
182.09000000,4.21601000,2.47400000,0.14074033,222.10255856,0.13167747,253.36134668,0.00077177,0.13585710,257.10008468,-0.09115775,-0.04469936,0.00000000,0.00000000,0.00000000,0.00000000
183.59000000,4.25595700,2.47700000,0.14207933,222.37188260,0.13285058,253.96633143,0.00075121,0.13693192,257.68867156,-0.09183365,-0.04509827,0.00000000,0.00000000,0.00000000,0.00000000
185.09000000,4.29587400,2.48000000,0.14345578,222.64120664,0.13405506,254.58037410,0.00078335,0.13806485,258.18948255,-0.09258165,-0.04548320,0.00000000,0.00000000,0.00000000,0.00000000
186.59000000,4.33579000,2.48200000,0.14480967,222.82075600,0.13523839,255.08735540,0.00080165,0.13915789,258.68074813,-0.09331472,-0.04584317,0.00000000,0.00000000,0.00000000,0.00000000
188.09000000,4.37624200,2.48500000,0.14614500,223.09008004,0.13640414,255.69357979,0.00082671,0.14028383,259.28539356,-0.09409343,-0.04619039,0.00000000,0.00000000,0.00000000,0.00000000
189.59000000,4.41693100,2.48800000,0.14744689,223.35940408,0.13753938,256.29305332,0.00072832,0.14135831,259.77349663,-0.09475920,-0.04659912,0.00000000,0.00000000,0.00000000,0.00000000
191.09000000,4.45664500,2.49000000,0.14881211,223.53895344,0.13872846,256.80425702,0.00076654,0.14248625,260.27631611,-0.09550594,-0.04698031,0.00000000,0.00000000,0.00000000,0.00000000
192.59000000,4.49642800,2.49200000,0.15006911,223.71850280,0.13982204,257.29173965,0.00068761,0.14355527,260.76452769,-0.09620312,-0.04735215,0.00000000,0.00000000,0.00000000,0.00000000
194.09000000,4.53610800,2.49500000,0.15138578,223.98782684,0.14096624,257.89639822,0.00080982,0.14468718,261.26997991,-0.09693033,-0.04775684,0.00000000,0.00000000,0.00000000,0.00000000
195.59000000,4.57629300,2.49700000,0.15267256,224.16737620,0.14208321,258.39158240,0.00076378,0.14588813,261.79439108,-0.09770422,-0.04818391,0.00000000,0.00000000,0.00000000,0.00000000
197.09000000,4.61610700,2.49900000,0.15397433,224.34692556,0.14321193,258.89059386,0.00082129,0.14716278,262.44387782,-0.09853679,-0.04862599,0.00000000,0.00000000,0.00000000,0.00000000
198.59000000,4.65676000,2.50100000,0.15523867,224.52647492,0.14430696,259.38166552,0.00074246,0.14843901,262.88518966,-0.09936999,-0.04906901,0.00000000,0.00000000,0.00000000,0.00000000
200.09000000,4.69664100,2.50400000,0.15647711,224.79579896,0.14537841,259.97119617,0.00072263,0.14974521,263.33512673,-0.10021432,-0.04953089,0.00000000,0.00000000,0.00000000,0.00000000
201.59000000,4.73706100,2.50600000,0.15774900,224.97534832,0.14647760,260.46498454,0.00065099,0.15111174,263.90696822,-0.10111476,-0.04999698,0.00000000,0.00000000,0.00000000,0.00000000
203.09000000,4.77724400,2.50800000,0.15907311,225.15489768,0.14762064,260.97098774,0.00078526,0.15241302,264.46256899,-0.10196733,-0.05044570,0.00000000,0.00000000,0.00000000,0.00000000
204.59000000,4.81742900,2.51000000,0.16039744,225.33444704,0.14876257,261.47751649,0.00079107,0.15368229,264.90518684,-0.10281899,-0.05086330,0.00000000,0.00000000,0.00000000,0.00000000
206.09000000,4.85814900,2.51200000,0.16182589,225.51399640,0.14999281,262.00799933,0.00083488,0.15485343,265.42796808,-0.10357307,-0.05128036,0.00000000,0.00000000,0.00000000,0.00000000
207.59000000,4.89917100,2.51400000,0.16331789,225.69354576,0.15127617,262.55333919,0.00083400,0.15599137,265.94275701,-0.10433861,-0.05165276,0.00000000,0.00000000,0.00000000,0.00000000
209.09000000,4.94056500,2.51600000,0.16488467,225.87309512,0.15262208,263.11610512,0.00096094,0.15709643,266.44958388,-0.10510425,-0.05199218,0.00000000,0.00000000,0.00000000,0.00000000
210.59000000,4.98313100,2.51700000,0.16641367,225.96286980,0.15393380,263.56617950,0.00095930,0.15816731,267.05400880,-0.10577920,-0.05238812,0.00000000,0.00000000,0.00000000,0.00000000
212.09000000,5.02586800,2.51900000,0.16798033,226.14241916,0.15527605,264.12989811,0.00089462,0.15927141,267.45621171,-0.10650139,-0.05277002,0.00000000,0.00000000,0.00000000,0.00000000
213.59000000,5.06971100,2.52000000,0.16947222,226.23219384,0.15655255,264.57226647,0.00082942,0.16043581,267.98139226,-0.10728219,-0.05315362,0.00000000,0.00000000,0.00000000,0.00000000
215.09000000,5.11392300,2.52200000,0.17092689,226.41174320,0.15779565,265.11159808,0.00076459,0.16163166,268.40959083,-0.10807777,-0.05355389,0.00000000,0.00000000,0.00000000,0.00000000
216.59000000,5.15763300,2.52400000,0.17230711,226.59129256,0.15897370,265.63458359,0.00076369,0.16285596,268.95256870,-0.10887340,-0.05398256,0.00000000,0.00000000,0.00000000,0.00000000
218.09000000,5.20100700,2.52600000,0.17361256,226.77084192,0.16008665,266.14110732,0.00069920,0.16414508,269.30082575,-0.10974263,-0.05440245,0.00000000,0.00000000,0.00000000,0.00000000
219.59000000,5.24435000,2.52800000,0.17491822,226.95039128,0.16119855,266.64815026,0.00069861,0.16536954,269.63203296,-0.11058830,-0.05478124,0.00000000,0.00000000,0.00000000,0.00000000
221.09000000,5.28604800,2.53000000,0.17626133,227.12994064,0.16234105,267.16416682,0.00082482,0.16646730,269.92931754,-0.11133743,-0.05512988,0.00000000,0.00000000,0.00000000,0.00000000
222.59000000,5.32643700,2.53200000,0.17756689,227.30949000,0.16345035,267.67212896,0.00082390,0.16743691,270.29912113,-0.11199413,-0.05544279,0.00000000,0.00000000,0.00000000,0.00000000
224.09000000,5.36564800,2.53300000,0.17894678,227.39926468,0.16462148,268.09163037,0.00082256,0.16828203,270.52852442,-0.11254734,-0.05573469,0.00000000,0.00000000,0.00000000,0.00000000
225.59000000,5.40448900,2.53500000,0.18036400,227.57881404,0.16582287,268.62583926,0.00082157,0.16893728,270.81363870,-0.11296028,-0.05597700,0.00000000,0.00000000,0.00000000,0.00000000
227.09000000,5.44396800,2.53600000,0.18185589,227.66858872,0.16708599,269.07146230,0.00088393,0.16955829,271.30405174,-0.11339471,-0.05616358,0.00000000,0.00000000,0.00000000,0.00000000
228.59000000,5.48556400,2.53600000,0.18334822,227.66858872,0.16834790,269.41121972,0.00081969,0.17014906,271.67948086,-0.11377150,-0.05637756,0.00000000,0.00000000,0.00000000,0.00000000
230.09000000,5.52866700,2.53600000,0.18476589,227.66858872,0.16954519,269.73397789,0.00075604,0.17067644,272.03795271,-0.11409937,-0.05657707,0.00000000,0.00000000,0.00000000,0.00000000
231.59000000,5.57365200,2.53600000,0.18607144,227.66858872,0.17064654,270.03121188,0.00075483,0.17126739,272.30674500,-0.11446386,-0.05680353,0.00000000,0.00000000,0.00000000,0.00000000
233.09000000,5.62038500,2.53600000,0.18715333,227.66858872,0.17155828,270.27752400,0.00062868,0.17179294,272.77271643,-0.11479149,-0.05700145,0.00000000,0.00000000,0.00000000,0.00000000
234.59000000,5.66852900,2.53700000,0.18804844,227.75836340,0.17231200,270.58796935,0.00043942,0.17238065,273.25616138,-0.11513515,-0.05724551,0.00000000,0.00000000,0.00000000,0.00000000
236.09000000,5.71646800,2.53900000,0.18883211,227.93791276,0.17297141,270.97991003,0.00043970,0.17315149,274.00555859,-0.11559770,-0.05755379,0.00000000,0.00000000,0.00000000,0.00000000
237.59000000,5.76001100,2.54100000,0.18954144,228.11746213,0.17356789,271.35517540,0.00037684,0.17439149,274.66998284,-0.11630457,-0.05808691,0.00000000,0.00000000,0.00000000,0.00000000
239.09000000,5.79472900,2.54400000,0.19021278,228.38678617,0.17413210,271.82887117,0.00031313,0.17682527,274.47810554,-0.11745428,-0.05937098,0.00000000,0.00000000,0.00000000,0.00000000
240.59000000,5.82101600,2.54600000,0.19092100,228.56633553,0.17472696,272.20444887,0.00043799,0.18007780,275.15913864,-0.11887509,-0.06120271,0.00000000,0.00000000,0.00000000,0.00000000
242.09000000,5.84199800,2.54700000,0.19151778,228.65611021,0.17522794,272.44782031,0.00025049,0.18368600,276.26636477,-0.12077909,-0.06290691,0.00000000,0.00000000,0.00000000,0.00000000
243.59000000,5.86150500,2.55000000,0.19218933,228.92543425,0.17579139,272.92246084,0.00031317,0.18746773,277.31721378,-0.12330526,-0.06416247,0.00000000,0.00000000,0.00000000,0.00000000
245.09000000,5.88157900,2.55400000,0.19297267,229.28453297,0.17644823,273.53018072,0.00043780,0.19117058,278.56911549,-0.12634464,-0.06482593,0.00000000,0.00000000,0.00000000,0.00000000
246.59000000,5.90671700,2.55800000,0.19401700,229.64363169,0.17732325,274.19840018,0.00062507,0.19404060,279.37292697,-0.12887766,-0.06516294,0.00000000,0.00000000,0.00000000,0.00000000
248.09000000,5.94226500,2.55800000,0.19588222,229.64363169,0.17888417,274.62673658,0.00124819,0.19577709,279.97045206,-0.13036206,-0.06541503,0.00000000,0.00000000,0.00000000,0.00000000
249.59000000,5.99003500,2.55000000,0.19931244,228.92543425,0.18174843,274.55312214,0.00211455,0.19681216,280.26154151,-0.13120950,-0.06560267,0.00000000,0.00000000,0.00000000,0.00000000
251.09000000,6.04119700,2.55100000,0.20337667,229.01520893,0.18513149,275.59155873,0.00235643,0.19751081,280.45819121,-0.13175188,-0.06575894,0.00000000,0.00000000,0.00000000,0.00000000
252.59000000,6.09471300,2.55100000,0.20785289,229.01520893,0.18884431,276.61668170,0.00253447,0.19805715,280.61206661,-0.13217131,-0.06588584,0.00000000,0.00000000,0.00000000,0.00000000
254.09000000,6.14930200,2.55200000,0.21247867,229.10498361,0.19266675,277.78490505,0.00258628,0.19848244,280.73190599,-0.13248545,-0.06599699,0.00000000,0.00000000,0.00000000,0.00000000
255.59000000,6.20432400,2.55300000,0.21673100,229.19475829,0.19616775,278.86836744,0.00214734,0.19884373,281.05454295,-0.13274650,-0.06609723,0.00000000,0.00000000,0.00000000,0.00000000
257.09000000,6.25948000,2.55400000,0.21979122,229.28453297,0.19867971,279.67926070,0.00140857,0.19911493,281.24150426,-0.13295592,-0.06615900,0.00000000,0.00000000,0.00000000,0.00000000
258.59000000,6.31520700,2.55400000,0.22154689,229.28453297,0.20011800,280.08180792,0.00079532,0.19938697,281.31832828,-0.13314654,-0.06624043,0.00000000,0.00000000,0.00000000,0.00000000
260.09000000,6.37124000,2.55300000,0.22270389,229.19475829,0.20106471,280.23732227,0.00061040,0.19959626,281.48792694,-0.13327210,-0.06632416,0.00000000,0.00000000,0.00000000,0.00000000
261.59000000,6.42686600,2.55400000,0.22344933,229.28453297,0.20167419,280.51800900,0.00042653,0.19980688,281.54745568,-0.13343651,-0.06637037,0.00000000,0.00000000,0.00000000,0.00000000
263.09000000,6.48356400,2.55400000,0.22404622,229.28453297,0.20216195,280.65486639,0.00030502,0.19998630,281.70870064,-0.13355105,-0.06643525,0.00000000,0.00000000,0.00000000,0.00000000
264.59000000,6.53999500,2.55500000,0.22453156,229.37430765,0.20255837,280.87607775,0.00024392,0.20019646,281.87869334,-0.13368625,-0.06651020,0.00000000,0.00000000,0.00000000,0.00000000
266.09000000,6.59753600,2.55600000,0.22494200,229.46408233,0.20289350,281.08019193,0.00018251,0.20031444,282.13320704,-0.13374477,-0.06656967,0.00000000,0.00000000,0.00000000,0.00000000
267.59000000,6.65440600,2.55700000,0.22531456,229.55385701,0.20319759,281.27568227,0.00024304,0.20049001,282.62527149,-0.13384129,-0.06664872,0.00000000,0.00000000,0.00000000,0.00000000
269.09000000,6.70970000,2.55700000,0.22557433,229.55385701,0.20340958,281.33531527,0.00012076,0.20069275,283.34644193,-0.13398458,-0.06670816,0.00000000,0.00000000,0.00000000,0.00000000
270.59000000,6.75882400,2.55800000,0.22587100,229.64363169,0.20365161,281.51346842,0.00018147,0.20089762,283.95788447,-0.13409441,-0.06680321,0.00000000,0.00000000,0.00000000,0.00000000
272.09000000,6.79041400,2.55900000,0.22609322,229.73340637,0.20383287,281.67457246,0.00012107,0.00000000,0.00000000,0.00000000,0.00000000,0.00000000,0.00000000,0.00000000,0.00000000
273.59000000,6.80685800,2.55900000,0.22631611,229.73340637,0.20401464,281.72577749,0.00012123,0.00000000,0.00000000,0.00000000,0.00000000,0.00000000,0.00000000,0.00000000,0.00000000
275.09000000,6.81840600,2.56100000,0.22653978,229.91295573,0.20419702,281.99738563,0.00006088,0.00000000,0.00000000,0.00000000,0.00000000,0.00000000,0.00000000,0.00000000,0.00000000
276.59000000,6.82887700,2.56300000,0.22676344,230.09250509,0.20437936,282.26907408,0.00018242,0.00000000,0.00000000,0.00000000,0.00000000,0.00000000,0.00000000,0.00000000,0.00000000
278.09000000,6.83985300,2.56800000,0.22695000,230.54137849,0.20453142,282.86274434,0.00012153,0.00000000,0.00000000,0.00000000,0.00000000,0.00000000,0.00000000,0.00000000,0.00000000
279.59000000,6.85351800,2.57500000,0.22724878,231.16980125,0.20477490,283.70285604,0.00018271,0.00000000,0.00000000,0.00000000,0.00000000,0.00000000,0.00000000,0.00000000,0.00000000
281.09000000,6.87483900,2.57700000,0.22751100,231.34935061,0.00000000,0.00000000,0.00000000,0.00000000,0.00000000,0.00000000,0.00000000,0.00000000,0.00000000,0.00000000,0.00000000
282.59000000,6.92099400,2.56500000,0.22777533,230.27205445,0.00000000,0.00000000,0.00000000,0.00000000,0.00000000,0.00000000,0.00000000,0.00000000,0.00000000,0.00000000,0.00000000
284.09000000,6.97377200,2.56400000,0.22796533,230.18227977,0.00000000,0.00000000,0.00000000,0.00000000,0.00000000,0.00000000,0.00000000,0.00000000,0.00000000,0.00000000,0.00000000
285.59000000,7.02911000,2.56100000,0.22822611,229.91295573,0.00000000,0.00000000,0.00000000,0.00000000,0.00000000,0.00000000,0.00000000,0.00000000,0.00000000,0.00000000,0.00000000
287.09000000,7.08514100,2.56000000,0.22844922,229.82318105,0.00000000,0.00000000,0.00000000,0.00000000,0.00000000,0.00000000,0.00000000,0.00000000,0.00000000,0.00000000,0.00000000
288.59000000,7.14167600,2.56100000,0.22870967,229.91295573,0.00000000,0.00000000,0.00000000,0.00000000,0.00000000,0.00000000,0.00000000,0.00000000,0.00000000,0.00000000,0.00000000
290.09000000,7.19918600,2.56100000,0.22889511,229.91295573,0.00000000,0.00000000,0.00000000,0.00000000,0.00000000,0.00000000,0.00000000,0.00000000,0.00000000,0.00000000,0.00000000
291.59000000,7.25666200,2.56100000,0.22915522,229.91295573,0.00000000,0.00000000,0.00000000,0.00000000,0.00000000,0.00000000,0.00000000,0.00000000,0.00000000,0.00000000,0.00000000
293.09000000,7.31420400,2.56200000,0.22941556,230.00273041,0.00000000,0.00000000,0.00000000,0.00000000,0.00000000,0.00000000,0.00000000,0.00000000,0.00000000,0.00000000,0.00000000
294.59000000,7.36936100,2.56200000,0.22956433,230.00273041,0.00000000,0.00000000,0.00000000,0.00000000,0.00000000,0.00000000,0.00000000,0.00000000,0.00000000,0.00000000,0.00000000
296.09000000,7.41699100,2.56300000,0.22978844,230.09250509,0.00000000,0.00000000,0.00000000,0.00000000,0.00000000,0.00000000,0.00000000,0.00000000,0.00000000,0.00000000,0.00000000
297.59000000,7.45344400,2.56300000,0.23001256,230.09250509,0.00000000,0.00000000,0.00000000,0.00000000,0.00000000,0.00000000,0.00000000,0.00000000,0.00000000,0.00000000,0.00000000
299.09000000,7.48104000,2.56400000,0.23023678,230.18227977,0.00000000,0.00000000,0.00000000,0.00000000,0.00000000,0.00000000,0.00000000,0.00000000,0.00000000,0.00000000,0.00000000
300.59000000,7.50511700,2.56500000,0.23049800,230.27205445,0.00000000,0.00000000,0.00000000,0.00000000,0.00000000,0.00000000,0.00000000,0.00000000,0.00000000,0.00000000,0.00000000
302.09000000,7.53215100,2.56400000,0.23072189,230.18227977,0.00000000,0.00000000,0.00000000,0.00000000,0.00000000,0.00000000,0.00000000,0.00000000,0.00000000,0.00000000,0.00000000
303.59000000,7.57056000,2.56100000,0.23090833,229.91295573,0.00000000,0.00000000,0.00000000,0.00000000,0.00000000,0.00000000,0.00000000,0.00000000,0.00000000,0.00000000,0.00000000
305.09000000,7.62088300,2.55800000,0.23109556,229.64363169,0.00000000,0.00000000,0.00000000,0.00000000,0.00000000,0.00000000,0.00000000,0.00000000,0.00000000,0.00000000,0.00000000
306.59000000,7.67553600,2.55700000,0.23124567,229.55385701,0.00000000,0.00000000,0.00000000,0.00000000,0.00000000,0.00000000,0.00000000,0.00000000,0.00000000,0.00000000,0.00000000
308.09000000,7.73150100,2.55400000,0.23132056,229.28453297,0.00000000,0.00000000,0.00000000,0.00000000,0.00000000,0.00000000,0.00000000,0.00000000,0.00000000,0.00000000,0.00000000
309.60000000,7.79086100,2.55100000,0.23150656,229.01520893,0.00000000,0.00000000,0.00000000,0.00000000,0.00000000,0.00000000,0.00000000,0.00000000,0.00000000,0.00000000,0.00000000
311.09000000,7.84814000,2.54900000,0.23161789,228.83565957,0.00000000,0.00000000,0.00000000,0.00000000,0.00000000,0.00000000,0.00000000,0.00000000,0.00000000,0.00000000,0.00000000
312.59000000,7.90644800,2.54400000,0.23165544,228.38678617,0.00000000,0.00000000,0.00000000,0.00000000,0.00000000,0.00000000,0.00000000,0.00000000,0.00000000,0.00000000,0.00000000
314.09000000,7.96622800,2.53900000,0.23169389,227.93791276,0.00000000,0.00000000,0.00000000,0.00000000,0.00000000,0.00000000,0.00000000,0.00000000,0.00000000,0.00000000,0.00000000
315.59000000,8.02567600,2.53300000,0.23173222,227.39926468,0.00000000,0.00000000,0.00000000,0.00000000,0.00000000,0.00000000,0.00000000,0.00000000,0.00000000,0.00000000,0.00000000
317.09000000,8.08596800,2.52200000,0.23184500,226.41174320,0.00000000,0.00000000,0.00000000,0.00000000,0.00000000,0.00000000,0.00000000,0.00000000,0.00000000,0.00000000,0.00000000
318.59000000,8.14635400,2.50800000,0.23180900,225.15489768,0.00000000,0.00000000,0.00000000,0.00000000,0.00000000,0.00000000,0.00000000,0.00000000,0.00000000,0.00000000,0.00000000
320.09000000,8.20908200,2.48600000,0.23177411,223.17985472,0.00000000,0.00000000,0.00000000,0.00000000,0.00000000,0.00000000,0.00000000,0.00000000,0.00000000,0.00000000,0.00000000
321.59000000,8.27284900,2.44900000,0.23173989,219.85819156,0.00000000,0.00000000,0.00000000,0.00000000,0.00000000,0.00000000,0.00000000,0.00000000,0.00000000,0.00000000,0.00000000
323.09000000,8.33930600,2.39200000,0.23163111,214.74103479,0.00000000,0.00000000,0.00000000,0.00000000,0.00000000,0.00000000,0.00000000,0.00000000,0.00000000,0.00000000,0.00000000
324.59000000,8.40919600,2.30700000,0.23141100,207.11018698,0.00000000,0.00000000,0.00000000,0.00000000,0.00000000,0.00000000,0.00000000,0.00000000,0.00000000,0.00000000,0.00000000
326.09000000,8.65191800,0.68600000,0.26061178,61.58543055,0.00000000,0.00000000,0.00000000,0.00000000,0.00000000,0.00000000,0.00000000,0.00000000,0.00000000,0.00000000,0.00000000
NaN,-100.00000000,NaN,-11.11111111,NaN,0.00000000,0.00000000,0.00000000,0.00000000,0.00000000,0.00000000,0.00000000,0.00000000,0.00000000,0.00000000,0.00000000