File: lab_data/AA6014-T4_results/DATA/UT_60_3.csv
Time[s],Displacement[mm],Force[kN],EngStrain_longi,EngStress[MPa],TrueStrain,TrueStress[MPa],TrueStrainRate[1/s],PlasticStrain_longi,PlasticStress[MPa],PlasticStrain_thick,PlasticStrain_width,R-Value,Thickness[mm],Width[mm], Young's Modulus [MPa]
0.66000000,0.00000000,-0.00100000,0.00000000,-0.09064477,0.00000000,-0.09064477,0.00000000,0.00065892,115.92808961,-0.00002082,-0.00063809,0.55698733,1.11280000,9.91380000,77340.95395782
2.16000000,0.00577900,0.17000000,0.00017911,15.40961013,0.00017910,15.41237017,0.00016353,0.00192345,119.17312625,-0.00086461,-0.00105884,0.00000000,0.00000000,0.00000000,0.00000000
3.66000000,0.01296900,0.39900000,0.00039833,36.16726143,0.00039825,36.18166806,0.00007153,0.00312896,122.60173437,-0.00167910,-0.00144987,0.00000000,0.00000000,0.00000000,0.00000000
5.16000000,0.02187200,0.62900000,0.00071767,57.01555750,0.00071741,57.05647566,0.00028848,0.00425517,125.75469582,-0.00245181,-0.00180335,0.00000000,0.00000000,0.00000000,0.00000000
6.66000000,0.03000300,0.88100000,0.00097922,79.85803840,0.00097874,79.93623717,0.00030861,0.00539845,128.45976071,-0.00321543,-0.00218302,0.00000000,0.00000000,0.00000000,0.00000000
8.16000000,0.04005500,1.10100000,0.00122200,99.79988681,0.00122125,99.92184228,0.00016913,0.00662255,130.99850937,-0.00399753,-0.00262502,0.00000000,0.00000000,0.00000000,0.00000000
9.66000000,0.06138900,1.25500000,0.00187744,113.75918070,0.00187568,113.97275724,0.00033939,0.00781369,133.53905522,-0.00479999,-0.00301370,0.00000000,0.00000000,0.00000000,0.00000000
11.16000000,0.09869400,1.29900000,0.00319622,117.74755038,0.00319113,118.12389772,0.00083152,0.00892133,135.79884461,-0.00549730,-0.00342403,0.00000000,0.00000000,0.00000000,0.00000000
12.66000000,0.13506800,1.33600000,0.00439344,121.10140671,0.00438382,121.63345901,0.00074841,0.01006001,137.97599965,-0.00622642,-0.00383359,0.00000000,0.00000000,0.00000000,0.00000000
14.16000000,0.17074600,1.36800000,0.00554644,124.00203920,0.00553112,124.68980962,0.00061889,0.01123382,140.16300541,-0.00699255,-0.00424127,0.00000000,0.00000000,0.00000000,0.00000000
15.66000000,0.20742900,1.39900000,0.00679289,126.81202693,0.00676992,127.67344694,0.00068568,0.01237428,142.25819503,-0.00772396,-0.00465033,0.00000000,0.00000000,0.00000000,0.00000000
17.16000000,0.24381500,1.42500000,0.00806944,129.16879084,0.00803706,130.21111122,0.00083213,0.01347303,144.35207332,-0.00842519,-0.00504783,0.00000000,0.00000000,0.00000000,0.00000000
18.66000000,0.28013100,1.45000000,0.00927467,131.43490997,0.00923192,132.65392495,0.00088444,0.01462058,146.27295029,-0.00920155,-0.00541903,0.00000000,0.00000000,0.00000000,0.00000000
20.16000000,0.31701300,1.47500000,0.01047800,133.70102911,0.01042349,135.10194849,0.00081144,0.01575951,148.19687130,-0.00997306,-0.00578645,0.00000000,0.00000000,0.00000000,0.00000000
21.66000000,0.35190600,1.49700000,0.01170978,135.69521395,0.01164175,137.28417475,0.00083045,0.01686766,150.12045970,-0.01070537,-0.00616229,0.00000000,0.00000000,0.00000000,0.00000000
23.16000000,0.38813100,1.51800000,0.01290011,137.59875403,0.01281761,139.37379324,0.00093549,0.01797087,152.04748469,-0.01145085,-0.00652002,0.00000000,0.00000000,0.00000000,0.00000000
24.66000000,0.42349300,1.54000000,0.01407522,139.59293887,0.01397709,141.55774050,0.00084627,0.01909728,153.79667772,-0.01221667,-0.00688061,0.00000000,0.00000000,0.00000000,0.00000000
26.16000000,0.45889900,1.56000000,0.01525022,141.40583418,0.01513511,143.56230457,0.00079383,0.02023554,155.64445767,-0.01297114,-0.00726440,0.00000000,0.00000000,0.00000000,0.00000000
27.66000000,0.49475800,1.58000000,0.01647378,143.21872949,0.01633956,145.57808301,0.00084427,0.02134089,157.39813658,-0.01369256,-0.00764833,0.00000000,0.00000000,0.00000000,0.00000000
29.16000000,0.52980400,1.60100000,0.01766378,145.12226956,0.01750959,147.68567708,0.00089462,0.02243410,159.15365396,-0.01440965,-0.00802445,0.00000000,0.00000000,0.00000000,0.00000000
30.66000000,0.56513700,1.61900000,0.01880522,146.75387534,0.01863059,149.51361458,0.00079826,0.02356729,160.82613083,-0.01515183,-0.00841546,0.00000000,0.00000000,0.00000000,0.00000000
32.16000000,0.60032400,1.63700000,0.01996911,148.38548112,0.01977234,151.34860728,0.00072434,0.02470491,162.59633381,-0.01589919,-0.00880572,0.00000000,0.00000000,0.00000000,0.00000000
33.66000000,0.63499700,1.65600000,0.02113667,150.10773167,0.02091639,153.28050875,0.00075986,0.02580765,164.17780748,-0.01659345,-0.00921419,0.00000000,0.00000000,0.00000000,0.00000000
35.16000000,0.67010100,1.67300000,0.02229689,151.64869268,0.02205195,155.02998673,0.00075922,0.02688378,165.75822241,-0.01726576,-0.00961801,0.00000000,0.00000000,0.00000000,0.00000000
36.66000000,0.70497300,1.69000000,0.02346444,153.18965369,0.02319339,156.78416381,0.00080201,0.02796455,167.43635514,-0.01798309,-0.00998145,0.00000000,0.00000000,0.00000000,0.00000000
38.16000000,0.73951600,1.70700000,0.02460222,154.73061471,0.02430446,158.53733167,0.00071368,0.02910071,168.93986021,-0.01873296,-0.01036775,0.00000000,0.00000000,0.00000000,0.00000000
39.66000000,0.77443000,1.72400000,0.02577722,156.27157572,0.02545059,160.29982285,0.00069098,0.03020189,170.53452625,-0.01948588,-0.01071601,0.00000000,0.00000000,0.00000000,0.00000000
41.16000000,0.80941300,1.74000000,0.02695611,157.72189197,0.02659919,161.97346081,0.00077764,0.03128143,172.03486008,-0.02018129,-0.01110015,0.00000000,0.00000000,0.00000000,0.00000000
42.66000000,0.84426200,1.75600000,0.02811622,159.17220822,0.02772822,163.64752939,0.00075492,0.03237043,173.53994389,-0.02089862,-0.01147181,0.00000000,0.00000000,0.00000000,0.00000000
44.16000000,0.87890800,1.77200000,0.02926522,160.62252446,0.02884517,165.32317834,0.00074673,0.03347391,174.95651511,-0.02162943,-0.01184448,0.00000000,0.00000000,0.00000000,0.00000000
45.66000000,0.91332000,1.78600000,0.03039544,161.89155118,0.02994266,166.81231683,0.00073124,0.03456761,176.46863052,-0.02232825,-0.01223937,0.00000000,0.00000000,0.00000000,0.00000000
47.16000000,0.94800000,1.80200000,0.03158178,163.34186743,0.03109333,168.50049399,0.00078837,0.03565411,177.88821607,-0.02304629,-0.01260782,0.00000000,0.00000000,0.00000000,0.00000000
48.66000000,0.98251300,1.81600000,0.03273822,164.61089415,0.03221374,169.99996218,0.00072980,0.03674296,179.31116059,-0.02374010,-0.01300286,0.00000000,0.00000000,0.00000000,0.00000000
50.16000000,1.01742800,1.83000000,0.03387967,165.87992086,0.03331839,171.49987729,0.00071437,0.03784853,180.74008121,-0.02444350,-0.01340503,0.00000000,0.00000000,0.00000000,0.00000000
51.66000000,1.05214200,1.84500000,0.03504733,167.23959235,0.03444716,173.10089409,0.00073547,0.03894329,182.07529559,-0.02514766,-0.01379563,0.00000000,0.00000000,0.00000000,0.00000000
53.16000000,1.08665400,1.85800000,0.03623733,168.41797430,0.03559620,174.52099257,0.00082838,0.04005823,183.41697861,-0.02584176,-0.01421647,0.00000000,0.00000000,0.00000000,0.00000000
54.66000000,1.12163700,1.87200000,0.03736011,169.68700101,0.03667913,176.02652623,0.00074091,0.04113126,184.84866089,-0.02652330,-0.01460796,0.00000000,0.00000000,0.00000000,0.00000000
56.16000000,1.15631700,1.88500000,0.03853144,170.86538297,0.03780764,177.44907298,0.00075441,0.04225913,186.10339664,-0.02726051,-0.01499862,0.00000000,0.00000000,0.00000000,0.00000000
57.66000000,1.19079600,1.89800000,0.03970656,172.04376492,0.03893852,178.87503023,0.00076810,0.04334527,187.44809449,-0.02795704,-0.01538823,0.00000000,0.00000000,0.00000000,0.00000000
59.16000000,1.22554400,1.91100000,0.04084056,173.22214687,0.04002861,180.29663558,0.00075295,0.04444690,188.60793662,-0.02868633,-0.01576056,0.00000000,0.00000000,0.00000000,0.00000000
60.66000000,1.26032500,1.92400000,0.04200811,174.40052882,0.04114973,181.72676561,0.00076619,0.04553400,189.95813625,-0.02934964,-0.01618436,0.00000000,0.00000000,0.00000000,0.00000000
62.16000000,1.29554200,1.93600000,0.04316089,175.48826601,0.04225542,183.06249556,0.00070823,0.04663891,191.21903038,-0.03007334,-0.01656557,0.00000000,0.00000000,0.00000000,0.00000000
63.66000000,1.33018900,1.94700000,0.04435078,176.48535843,0.04339543,184.31262134,0.00072147,0.04772135,192.47818795,-0.03078629,-0.01693506,0.00000000,0.00000000,0.00000000,0.00000000
65.16000000,1.36476900,1.96000000,0.04548489,177.66374038,0.04448079,185.74475587,0.00074238,0.04880736,193.64488780,-0.03146943,-0.01733793,0.00000000,0.00000000,0.00000000,0.00000000
66.66000000,1.40012100,1.97100000,0.04664878,178.66083280,0.04559342,186.99514229,0.00070587,0.04993092,194.82126861,-0.03225056,-0.01768037,0.00000000,0.00000000,0.00000000,0.00000000
68.16000000,1.43480000,1.98200000,0.04785733,179.65792522,0.04674744,188.25587443,0.00075491,0.05101084,195.99151029,-0.03294338,-0.01806745,0.00000000,0.00000000,0.00000000,0.00000000
69.66000000,1.47001800,1.99400000,0.04901367,180.74566241,0.04785036,189.60467005,0.00076806,0.05211774,197.16942667,-0.03366161,-0.01845613,0.00000000,0.00000000,0.00000000,0.00000000
71.16000000,1.50453000,2.00400000,0.05016644,181.65211006,0.04894867,190.76495055,0.00075325,0.05320364,198.24943977,-0.03437035,-0.01883329,0.00000000,0.00000000,0.00000000,0.00000000
72.66000000,1.53944500,2.01500000,0.05131900,182.64920248,0.05004557,192.02257690,0.00073107,0.05428194,199.52256060,-0.03505330,-0.01922864,0.00000000,0.00000000,0.00000000,0.00000000
74.16000000,1.57483000,2.02600000,0.05251278,183.64629490,0.05118043,193.29007197,0.00077290,0.05545787,200.52883261,-0.03587751,-0.01958036,0.00000000,0.00000000,0.00000000,0.00000000
75.66000000,1.60987900,2.03600000,0.05369900,184.55274256,0.05230683,194.46304028,0.00077900,0.05650489,201.60763108,-0.03651845,-0.01998644,0.00000000,0.00000000,0.00000000,0.00000000
77.16000000,1.64496100,2.04600000,0.05485900,185.45919021,0.05340711,195.63329593,0.00076381,0.05761729,202.70179377,-0.03723114,-0.02038615,0.00000000,0.00000000,0.00000000,0.00000000
78.66000000,1.67994300,2.05600000,0.05603033,186.36563787,0.05451691,196.80776668,0.00075601,0.05869329,203.79073499,-0.03792109,-0.02077219,0.00000000,0.00000000,0.00000000,0.00000000
80.16000000,1.71519400,2.06600000,0.05719044,187.27208552,0.05561487,197.98225932,0.00074109,0.05979960,204.88804764,-0.03862762,-0.02117198,0.00000000,0.00000000,0.00000000,0.00000000
81.66000000,1.75078000,2.07500000,0.05839156,188.08788841,0.05675036,199.07063280,0.00079655,0.06089902,205.88925296,-0.03932664,-0.02157238,0.00000000,0.00000000,0.00000000,0.00000000
83.16000000,1.78737100,2.08400000,0.05961122,188.90369130,0.05790207,200.16447122,0.00082374,0.06200278,206.99034653,-0.04004087,-0.02196191,0.00000000,0.00000000,0.00000000,0.00000000
84.66000000,1.82211800,2.09400000,0.06074522,189.81013895,0.05897170,201.34019803,0.00064011,0.06311699,207.99871842,-0.04074779,-0.02236920,0.00000000,0.00000000,0.00000000,0.00000000
86.16000000,1.85753500,2.10200000,0.06192400,190.53529708,0.06008236,202.33400482,0.00074470,0.06421955,209.00666618,-0.04146132,-0.02275823,0.00000000,0.00000000,0.00000000,0.00000000
87.66000000,1.89312100,2.11200000,0.06312133,191.44174473,0.06120924,203.52580292,0.00074386,0.06533128,210.01854643,-0.04218765,-0.02314364,0.00000000,0.00000000,0.00000000,0.00000000
89.16000000,1.92820400,2.12000000,0.06429644,192.16690286,0.06231397,204.52255145,0.00074325,0.06643480,211.03070848,-0.04289878,-0.02353603,0.00000000,0.00000000,0.00000000,0.00000000
90.66000000,1.96355400,2.12900000,0.06546389,192.98270575,0.06341028,205.61610415,0.00073534,0.06753491,211.94659287,-0.04361249,-0.02392242,0.00000000,0.00000000,0.00000000,0.00000000
92.16000000,2.00011300,2.13700000,0.06667256,193.70786387,0.06454404,206.62286219,0.00078348,0.06869127,212.97394531,-0.04437508,-0.02431619,0.00000000,0.00000000,0.00000000,0.00000000
93.66000000,2.03606800,2.14600000,0.06789600,194.52366676,0.06569036,207.73104564,0.00075448,0.06981650,213.89895189,-0.04511434,-0.02470216,0.00000000,0.00000000,0.00000000,0.00000000
95.16000000,2.07202300,2.15300000,0.06910833,195.15818012,0.06682497,208.64523668,0.00080270,0.07091974,214.82105549,-0.04583874,-0.02508100,0.00000000,0.00000000,0.00000000,0.00000000
96.66000000,2.10784500,2.16200000,0.07027967,195.97398301,0.06791999,209.74696921,0.00073224,0.07203199,215.74690728,-0.04653014,-0.02550184,0.00000000,0.00000000,0.00000000,0.00000000
98.16000000,2.14403600,2.16900000,0.07147333,196.60849637,0.06903465,210.66076096,0.00070341,0.07316358,216.67878161,-0.04728309,-0.02588049,0.00000000,0.00000000,0.00000000,0.00000000
99.66000000,2.18069600,2.17700000,0.07271922,197.33365449,0.07019675,211.68360436,0.00077907,0.07426426,217.50753200,-0.04799216,-0.02627209,0.00000000,0.00000000,0.00000000,0.00000000
101.16000000,2.21665100,2.18400000,0.07392411,197.96816785,0.07131933,212.60278869,0.00071568,0.07535544,218.43412655,-0.04867125,-0.02668419,0.00000000,0.00000000,0.00000000,0.00000000
102.66000000,2.25331100,2.19200000,0.07512144,198.69332597,0.07243363,213.61945562,0.00074259,0.07644548,219.36225841,-0.04938240,-0.02706308,0.00000000,0.00000000,0.00000000,0.00000000
104.16000000,2.28883100,2.19900000,0.07631522,199.32783933,0.07354338,214.53958769,0.00070045,0.07759729,220.20725837,-0.05014026,-0.02745703,0.00000000,0.00000000,0.00000000,0.00000000
105.66000000,2.32616300,2.20600000,0.07755744,199.96235269,0.07469685,215.47092175,0.00077577,0.07871899,221.14593915,-0.05087104,-0.02784795,0.00000000,0.00000000,0.00000000,0.00000000
107.16000000,2.36195000,2.21300000,0.07874733,200.59686605,0.07580049,216.39333433,0.00072628,0.07982027,221.98313300,-0.05155423,-0.02826604,0.00000000,0.00000000,0.00000000,0.00000000
108.66000000,2.39887900,2.21900000,0.07995956,201.14073464,0.07692359,217.22385839,0.00071847,0.08094759,222.82774174,-0.05228895,-0.02865864,0.00000000,0.00000000,0.00000000,0.00000000
110.16000000,2.43533700,2.22700000,0.08119067,201.86589277,0.07806290,218.25551918,0.00072464,0.08207014,223.67292164,-0.05300660,-0.02906354,0.00000000,0.00000000,0.00000000,0.00000000
111.66000000,2.47186500,2.23300000,0.08240678,202.40976136,0.07918706,219.08969758,0.00076531,0.08319158,224.51949029,-0.05372093,-0.02947065,0.00000000,0.00000000,0.00000000,0.00000000
113.16000000,2.50882800,2.24000000,0.08364144,203.04427472,0.08032708,220.02719114,0.00085389,0.08430127,225.36503902,-0.05442837,-0.02987290,0.00000000,0.00000000,0.00000000,0.00000000
114.66000000,2.54565600,2.24600000,0.08486133,203.58814331,0.08145218,220.86490460,0.00077731,0.08542477,226.11598067,-0.05515487,-0.03026990,0.00000000,0.00000000,0.00000000,0.00000000
116.16000000,2.58218100,2.25200000,0.08609600,204.13201190,0.08258962,221.70696160,0.00078318,0.08654556,226.96720053,-0.05587541,-0.03067015,0.00000000,0.00000000,0.00000000,0.00000000
117.66000000,2.61948000,2.25800000,0.08733078,204.67588050,0.08372587,222.55038433,0.00080989,0.08768011,227.72361870,-0.05662183,-0.03105827,0.00000000,0.00000000,0.00000000,0.00000000
119.16000000,2.65627500,2.26500000,0.08854689,205.31039386,0.08484368,223.48999049,0.00076120,0.08878476,228.57432458,-0.05728849,-0.03149627,0.00000000,0.00000000,0.00000000,0.00000000
120.66000000,2.69313800,2.27000000,0.08978533,205.76361768,0.08598073,224.23817268,0.00080113,0.08990306,229.32998114,-0.05801650,-0.03188656,0.00000000,0.00000000,0.00000000,0.00000000
122.16000000,2.73003300,2.27500000,0.09101633,206.21684151,0.08710968,224.98594230,0.00073869,0.09103036,230.08913337,-0.05873821,-0.03229215,0.00000000,0.00000000,0.00000000,0.00000000
123.66000000,2.76739900,2.28100000,0.09223989,206.76071010,0.08823053,225.83229503,0.00073787,0.09214940,230.84780966,-0.05944735,-0.03270205,0.00000000,0.00000000,0.00000000,0.00000000
125.16000000,2.80449500,2.28700000,0.09347833,207.30457870,0.08936375,226.68306521,0.00073012,0.09328083,231.61078966,-0.06018172,-0.03309911,0.00000000,0.00000000,0.00000000,0.00000000
126.66000000,2.84199500,2.29300000,0.09470933,207.84844729,0.09048888,227.53363517,0.00070899,0.09440752,232.37411311,-0.06091476,-0.03349276,0.00000000,0.00000000,0.00000000,0.00000000
128.16000000,2.87922800,2.29800000,0.09595900,208.30167112,0.09162978,228.29009118,0.00074895,0.09553622,233.13934715,-0.06163723,-0.03389899,0.00000000,0.00000000,0.00000000,0.00000000
129.66000000,2.91686200,2.30300000,0.09719000,208.75489494,0.09275237,229.04378318,0.00076169,0.09667513,233.80792117,-0.06240026,-0.03427487,0.00000000,0.00000000,0.00000000,0.00000000
131.16000000,2.95463100,2.30800000,0.09842100,209.20811877,0.09387369,229.79859103,0.00071995,0.09778098,234.57056672,-0.06308849,-0.03469249,0.00000000,0.00000000,0.00000000,0.00000000
132.66000000,2.99162700,2.31300000,0.09967444,209.66134260,0.09501418,230.55922044,0.00078018,0.09892397,235.24266404,-0.06380646,-0.03511750,0.00000000,0.00000000,0.00000000,0.00000000
134.16000000,3.02939500,2.31800000,0.10094278,210.11456643,0.09616688,231.32411441,0.00076595,0.10005082,236.01303561,-0.06454039,-0.03551043,0.00000000,0.00000000,0.00000000,0.00000000
135.66000000,3.06699700,2.32300000,0.10219256,210.56779025,0.09730143,232.08625086,0.00083286,0.10119631,236.78928983,-0.06530424,-0.03589208,0.00000000,0.00000000,0.00000000,0.00000000
137.16000000,3.10466400,2.32800000,0.10344589,211.02101408,0.09843791,232.85027046,0.00079806,0.10231188,237.45881248,-0.06598342,-0.03632846,0.00000000,0.00000000,0.00000000,0.00000000
138.66000000,3.14290300,2.33300000,0.10471422,211.47423791,0.09958668,233.61859825,0.00079051,0.10347109,238.03876894,-0.06674729,-0.03672380,0.00000000,0.00000000,0.00000000,0.00000000
140.16000000,3.18080500,2.33700000,0.10598244,211.83681697,0.10073403,234.28780066,0.00078940,0.10459596,238.81417730,-0.06744213,-0.03715383,0.00000000,0.00000000,0.00000000,0.00000000
141.66000000,3.21870800,2.34200000,0.10722467,212.29004080,0.10185658,235.05276966,0.00074816,0.10571757,239.48882754,-0.06816504,-0.03755252,0.00000000,0.00000000,0.00000000,0.00000000
143.16000000,3.25661200,2.34600000,0.10848189,212.65261986,0.10299141,235.72157774,0.00076756,0.10688787,240.17643766,-0.06895654,-0.03793133,0.00000000,0.00000000,0.00000000,0.00000000
144.66000000,3.29545300,2.35100000,0.10974633,213.10584369,0.10413146,236.49342864,0.00075307,0.10799368,240.84975267,-0.06960889,-0.03838479,0.00000000,0.00000000,0.00000000,0.00000000
146.16000000,3.33338900,2.35500000,0.11102211,213.46842275,0.10528041,237.16813770,0.00069178,0.10910618,241.42411525,-0.07033492,-0.03877126,0.00000000,0.00000000,0.00000000,0.00000000
147.66000000,3.37203100,2.35900000,0.11228667,213.83100181,0.10641796,237.84137224,0.00072436,0.11027579,242.11523832,-0.07107714,-0.03919865,0.00000000,0.00000000,0.00000000,0.00000000
149.16000000,3.41030300,2.36300000,0.11355500,214.19358087,0.10755760,238.51633295,0.00075049,0.11140574,242.69597641,-0.07180737,-0.03959837,0.00000000,0.00000000,0.00000000,0.00000000
150.66000000,3.44891000,2.36700000,0.11482711,214.55615994,0.10869934,239.19302395,0.00077655,0.11256915,243.38803596,-0.07253377,-0.04003537,0.00000000,0.00000000,0.00000000,0.00000000
152.16000000,3.48755100,2.37200000,0.11612156,215.00938376,0.10985978,239.97660787,0.00082923,0.11372151,244.07868639,-0.07328391,-0.04043759,0.00000000,0.00000000,0.00000000,0.00000000
153.66000000,3.52572300,2.37500000,0.11738989,215.28131806,0.11099551,240.55316807,0.00076821,0.11486381,244.66576595,-0.07401744,-0.04084637,0.00000000,0.00000000,0.00000000,0.00000000
155.16000000,3.56459900,2.37900000,0.11867678,215.64389712,0.11214654,241.23581998,0.00078720,0.11602988,245.36222773,-0.07478145,-0.04124843,0.00000000,0.00000000,0.00000000,0.00000000
156.66000000,3.60364400,2.38300000,0.11999356,216.00647618,0.11332293,241.92586128,0.00083292,0.11713004,245.94110330,-0.07548034,-0.04164969,0.00000000,0.00000000,0.00000000,0.00000000
158.16000000,3.64315800,2.38600000,0.12127678,216.27841048,0.11446802,242.50795921,0.00080520,0.11831121,246.54100638,-0.07625473,-0.04205648,0.00000000,0.00000000,0.00000000,0.00000000
159.66000000,3.68186600,2.39000000,0.12259356,216.64098954,0.11564168,243.19977873,0.00089733,0.11944826,247.13105255,-0.07698700,-0.04246127,0.00000000,0.00000000,0.00000000,0.00000000
161.16000000,3.72107800,2.39400000,0.12385078,217.00356860,0.11676098,243.87962936,0.00072383,0.12061354,247.72914524,-0.07772877,-0.04288477,0.00000000,0.00000000,0.00000000,0.00000000
162.66000000,3.76049200,2.39700000,0.12517867,217.27550290,0.11794184,244.47376065,0.00076249,0.12176756,248.32550152,-0.07848884,-0.04327872,0.00000000,0.00000000,0.00000000,0.00000000
164.16000000,3.79973800,2.40000000,0.12646944,217.54743720,0.11908836,245.06054072,0.00074188,0.12286128,248.90785244,-0.07917108,-0.04369020,0.00000000,0.00000000,0.00000000,0.00000000
165.66000000,3.83911600,2.40400000,0.12777122,217.91001626,0.12024332,245.75264537,0.00075424,0.12401275,249.50564719,-0.07989992,-0.04411283,0.00000000,0.00000000,0.00000000,0.00000000
167.16000000,3.87879800,2.40700000,0.12906567,218.18195056,0.12139045,246.34174946,0.00076656,0.12514963,250.10083515,-0.08063537,-0.04451426,0.00000000,0.00000000,0.00000000,0.00000000
168.66000000,3.91804500,2.41000000,0.13033411,218.45388485,0.12251326,246.92587775,0.00067995,0.12630162,250.70086553,-0.08138940,-0.04491222,0.00000000,0.00000000,0.00000000,0.00000000
170.16000000,3.95813000,2.41400000,0.13169189,218.81646391,0.12371376,247.63281737,0.00075162,0.12743584,251.29747459,-0.08206705,-0.04536879,0.00000000,0.00000000,0.00000000,0.00000000
171.66000000,3.99787900,2.41600000,0.13298633,218.99775345,0.12485692,248.12146168,0.00078373,0.12861589,251.80289036,-0.08283754,-0.04577836,0.00000000,0.00000000,0.00000000,0.00000000
173.16000000,4.03725800,2.41900000,0.13425456,219.26968774,0.12597566,248.70764222,0.00071033,0.12975413,252.40250523,-0.08355737,-0.04619675,0.00000000,0.00000000,0.00000000,0.00000000
174.66000000,4.07667200,2.42200000,0.13555644,219.54162204,0.12712279,249.30190373,0.00071617,0.13094291,253.01600435,-0.08432113,-0.04662178,0.00000000,0.00000000,0.00000000,0.00000000
176.16000000,4.11658900,2.42500000,0.13688089,219.81355634,0.12828845,249.90183132,0.00080079,0.13211547,253.52229690,-0.08506168,-0.04705379,0.00000000,0.00000000,0.00000000,0.00000000
177.66000000,4.15700900,2.42800000,0.13818267,220.08549063,0.12943284,250.49749062,0.00080652,0.13330286,254.03321439,-0.08582249,-0.04748037,0.00000000,0.00000000,0.00000000,0.00000000
179.16000000,4.19726100,2.43000000,0.13952556,220.26678016,0.13061200,250.99962504,0.00081200,0.13447115,254.64455350,-0.08657253,-0.04789861,0.00000000,0.00000000,0.00000000,0.00000000
180.66000000,4.23764800,2.43300000,0.14085722,220.53871446,0.13177993,251.60318517,0.00083717,0.13564606,255.15411790,-0.08733474,-0.04831132,0.00000000,0.00000000,0.00000000,0.00000000
182.16000000,4.27830300,2.43600000,0.14218900,220.81064876,0.13294660,252.20749409,0.00081673,0.13685042,255.77678253,-0.08807991,-0.04877051,0.00000000,0.00000000,0.00000000,0.00000000
183.66000000,4.31862400,2.43900000,0.14353578,221.08258305,0.13412502,252.81584356,0.00079613,0.13802874,256.28906798,-0.08886258,-0.04916616,0.00000000,0.00000000,0.00000000,0.00000000
185.16000000,4.35948000,2.44100000,0.14488600,221.26387258,0.13530507,253.32191003,0.00078859,0.13920267,256.80108159,-0.08962773,-0.04957494,0.00000000,0.00000000,0.00000000,0.00000000
186.66000000,4.40023600,2.44300000,0.14623256,221.44516211,0.13648053,253.82765409,0.00078766,0.14036858,257.31188074,-0.09039275,-0.04997582,0.00000000,0.00000000,0.00000000,0.00000000
188.16000000,4.44116000,2.44600000,0.14759044,221.71709641,0.13766448,254.44042121,0.00076736,0.14152038,257.81987558,-0.09114805,-0.05037233,0.00000000,0.00000000,0.00000000,0.00000000
189.66000000,4.48231900,2.44900000,0.14897067,221.98903071,0.13886647,255.05888460,0.00077302,0.14266610,258.43243879,-0.09186061,-0.05080548,0.00000000,0.00000000,0.00000000,0.00000000
191.16000000,4.52344600,2.45100000,0.15030989,222.17032024,0.14003137,255.56471639,0.00071994,0.14382151,258.94316404,-0.09260340,-0.05121811,0.00000000,0.00000000,0.00000000,0.00000000
192.66000000,4.56470500,2.45300000,0.15169756,222.35160977,0.14123699,256.08180544,0.00082929,0.14496426,259.34587942,-0.09335815,-0.05160611,0.00000000,0.00000000,0.00000000,0.00000000
194.16000000,4.60583000,2.45500000,0.15306278,222.53289930,0.14242169,256.59440301,0.00072477,0.14603386,259.83578124,-0.09396794,-0.05206593,0.00000000,0.00000000,0.00000000,0.00000000
195.66000000,4.64749200,2.45800000,0.15438700,222.80483360,0.14356947,257.20300344,0.00068523,0.14717581,260.34534117,-0.09471442,-0.05246139,0.00000000,0.00000000,0.00000000,0.00000000
197.16000000,4.68865100,2.46000000,0.15575600,222.98612313,0.14475468,257.71754972,0.00072943,0.14827496,260.84453017,-0.09542120,-0.05285377,0.00000000,0.00000000,0.00000000,0.00000000
198.66000000,4.72970900,2.46200000,0.15706167,223.16741266,0.14588375,258.21845844,0.00078701,0.14938875,261.34834699,-0.09609812,-0.05329063,0.00000000,0.00000000,0.00000000,0.00000000
200.16000000,4.77154000,2.46400000,0.15843811,223.34870219,0.14707264,258.73564868,0.00078589,0.15053152,261.75443384,-0.09685726,-0.05367426,0.00000000,0.00000000,0.00000000,0.00000000
201.66000000,4.81330200,2.46600000,0.15972878,223.52999172,0.14818617,259.23416409,0.00073364,0.15167311,262.37334860,-0.09756861,-0.05410450,0.00000000,0.00000000,0.00000000,0.00000000
203.16000000,4.85489800,2.46800000,0.16107911,223.71128125,0.14934984,259.74649558,0.00077146,0.15281496,262.88701586,-0.09830281,-0.05451215,0.00000000,0.00000000,0.00000000,0.00000000
204.66000000,4.89656000,2.47000000,0.16239967,223.89257078,0.15048655,260.25264965,0.00077690,0.15405209,263.32018318,-0.09910742,-0.05494467,0.00000000,0.00000000,0.00000000,0.00000000
206.16000000,4.93819000,2.47100000,0.16366800,223.98321555,0.15157709,260.64210047,0.00075675,0.15525604,263.74523996,-0.09991601,-0.05534003,0.00000000,0.00000000,0.00000000,0.00000000
207.66000000,4.97981900,2.47300000,0.16498856,224.16450508,0.15271126,261.14908298,0.00078796,0.15652021,264.29370744,-0.10072655,-0.05579366,0.00000000,0.00000000,0.00000000,0.00000000
209.16000000,5.02138000,2.47500000,0.16629778,224.34579461,0.15383444,261.65400171,0.00076782,0.15778426,264.73618222,-0.10153826,-0.05624600,0.00000000,0.00000000,0.00000000,0.00000000
210.66000000,5.06368000,2.47700000,0.16764067,224.52708414,0.15498519,262.16695421,0.00076694,0.15914010,265.31087001,-0.10243087,-0.05670923,0.00000000,0.00000000,0.00000000,0.00000000
212.16000000,5.10588000,2.47800000,0.16898367,224.61772891,0.15613471,262.57445634,0.00076605,0.16049549,265.77928986,-0.10332278,-0.05717271,0.00000000,0.00000000,0.00000000,0.00000000
213.66000000,5.14922100,2.48000000,0.17040122,224.79901844,0.15734662,263.10504593,0.00082895,0.16187903,266.36339672,-0.10421241,-0.05766662,0.00000000,0.00000000,0.00000000,0.00000000
215.16000000,5.19239500,2.48200000,0.17181867,224.98030797,0.15855696,263.63612451,0.00082775,0.16323076,266.83257202,-0.10508596,-0.05814480,0.00000000,0.00000000,0.00000000,0.00000000
216.66000000,5.23526600,2.48300000,0.17331078,225.07095273,0.15982948,264.07817461,0.00089037,0.16458054,267.30201303,-0.10594966,-0.05863088,0.00000000,0.00000000,0.00000000,0.00000000
218.16000000,5.27850600,2.48500000,0.17480278,225.25224227,0.16110028,264.62695991,0.00082565,0.16595846,267.88761927,-0.10681642,-0.05914204,0.00000000,0.00000000,0.00000000,0.00000000
219.66000000,5.32282200,2.48600000,0.17633222,225.34288703,0.16240131,265.07809906,0.00088827,0.16733596,268.36625903,-0.10768330,-0.05965266,0.00000000,0.00000000,0.00000000,0.00000000
221.16000000,5.36750600,2.48800000,0.17793622,225.52417656,0.16376394,265.65309656,0.00095010,0.16858643,268.81143494,-0.10842061,-0.06016582,0.00000000,0.00000000,0.00000000,0.00000000
222.66000000,5.41266000,2.48900000,0.17957756,225.61482133,0.16515637,266.13017944,0.00088564,0.16983523,269.25685623,-0.10922489,-0.06061033,0.00000000,0.00000000,0.00000000,0.00000000
224.16000000,5.45828500,2.49100000,0.18125622,225.79611086,0.16657847,266.72306090,0.00107410,0.17102009,269.68566636,-0.10993481,-0.06108528,0.00000000,0.00000000,0.00000000,0.00000000
225.66000000,5.50307000,2.49200000,0.18278567,225.88675562,0.16787239,267.17561684,0.00088323,0.17217091,270.21438761,-0.11065777,-0.06151314,0.00000000,0.00000000,0.00000000,0.00000000
227.16000000,5.54946600,2.49300000,0.18446444,225.97740039,0.16929073,267.66219601,0.00094524,0.17316766,270.48488670,-0.11126859,-0.06189906,0.00000000,0.00000000,0.00000000,0.00000000
228.66000000,5.59488900,2.49500000,0.18606856,226.15868992,0.17064410,268.23971068,0.00088098,0.17409809,270.95505620,-0.11185757,-0.06224052,0.00000000,0.00000000,0.00000000,0.00000000
230.16000000,5.64088300,2.49600000,0.18763544,226.24933469,0.17196431,268.70172915,0.00087981,0.17493758,271.18348735,-0.11238397,-0.06255361,0.00000000,0.00000000,0.00000000,0.00000000
231.66000000,5.68670800,2.49700000,0.18916478,226.33997945,0.17325119,269.15553137,0.00087868,0.17574384,271.51195137,-0.11289551,-0.06284833,0.00000000,0.00000000,0.00000000,0.00000000
233.16000000,5.73199700,2.49800000,0.19058233,226.43062422,0.17444254,269.58430092,0.00081471,0.17648753,271.82369425,-0.11337074,-0.06311679,0.00000000,0.00000000,0.00000000,0.00000000
234.66000000,5.77755500,2.49900000,0.19192544,226.52126898,0.17557002,269.99646421,0.00075131,0.17713755,272.11016819,-0.11377464,-0.06336291,0.00000000,0.00000000,0.00000000,0.00000000
236.16000000,5.82197000,2.50000000,0.19315644,226.61191375,0.17660227,270.38346528,0.00062533,0.17775613,272.38830370,-0.11419477,-0.06356136,0.00000000,0.00000000,0.00000000,0.00000000
237.66000000,5.86631800,2.50100000,0.19435000,226.70255851,0.17760210,270.76220076,0.00062471,0.17837432,272.66657449,-0.11458779,-0.06378653,0.00000000,0.00000000,0.00000000,0.00000000
239.16000000,5.91006200,2.50200000,0.19543178,226.79320328,0.17850744,271.11580218,0.00056185,0.17892999,272.92795554,-0.11495991,-0.06397008,0.00000000,0.00000000,0.00000000,0.00000000
240.66000000,5.95347000,2.50300000,0.19640167,226.88384804,0.17931844,271.44421394,0.00056121,0.17954680,273.20631321,-0.11536558,-0.06418122,0.00000000,0.00000000,0.00000000,0.00000000
242.16000000,5.99872600,2.50400000,0.19726000,226.97449281,0.18003561,271.74748126,0.00049861,0.18019407,273.49327477,-0.11586660,-0.06432747,0.00000000,0.00000000,0.00000000,0.00000000
243.66000000,6.04233600,2.50400000,0.19808078,226.97449281,0.18072092,271.93377688,0.00043593,0.18087527,273.57090511,-0.11637267,-0.06450260,0.00000000,0.00000000,0.00000000,0.00000000
245.16000000,6.08587900,2.50500000,0.19890167,227.06513758,0.18140586,272.22877188,0.00043563,0.18189300,273.96011717,-0.11718796,-0.06470504,0.00000000,0.00000000,0.00000000,0.00000000
246.66000000,6.12680400,2.50700000,0.19961067,227.24642711,0.18199706,272.60723792,0.00043556,0.18346470,274.50245514,-0.11859043,-0.06487427,0.00000000,0.00000000,0.00000000,0.00000000
248.16000000,6.16490900,2.50700000,0.20031933,227.24642711,0.18258763,272.76827989,0.00037290,0.18583468,275.15632524,-0.12074309,-0.06509158,0.00000000,0.00000000,0.00000000,0.00000000
249.66000000,6.20200700,2.50800000,0.20106500,227.33707187,0.18320866,273.04660023,0.00043448,0.18874880,276.07279728,-0.12320388,-0.06554492,0.00000000,0.00000000,0.00000000,0.00000000
251.16000000,6.23957300,2.50900000,0.20181033,227.42771664,0.18382903,273.32497994,0.00043421,0.19180718,277.03240729,-0.12497273,-0.06683444,0.00000000,0.00000000,0.00000000,0.00000000
252.66000000,6.27952300,2.50900000,0.20259322,227.42771664,0.18448024,273.50303057,0.00037219,0.19504076,277.93319136,-0.12617366,-0.06886711,0.00000000,0.00000000,0.00000000,0.00000000
254.16000000,6.32303200,2.51000000,0.20367533,227.51836140,0.18537965,273.85823950,0.00068229,0.19832304,278.96194716,-0.12714869,-0.07117435,0.00000000,0.00000000,0.00000000,0.00000000
255.66000000,6.36909300,2.51100000,0.20531722,227.60900617,0.18674279,274.34105507,0.00111482,0.20183787,279.94806395,-0.12827863,-0.07355924,0.00000000,0.00000000,0.00000000,0.00000000
257.16000000,6.41730200,2.51100000,0.20781722,227.60900617,0.18881478,274.91007758,0.00154516,0.20549222,280.86482716,-0.12997168,-0.07552054,0.00000000,0.00000000,0.00000000,0.00000000
258.66000000,6.46779300,2.51200000,0.21117444,227.69965093,0.19159050,275.78399822,0.00197188,0.20919337,281.79779900,-0.13272536,-0.07646801,0.00000000,0.00000000,0.00000000,0.00000000
260.16000000,6.51922500,2.51300000,0.21494211,227.79029570,0.19469643,276.75202275,0.00215069,0.21233863,282.80205707,-0.13550255,-0.07683608,0.00000000,0.00000000,0.00000000,0.00000000
261.66000000,6.57092700,2.51300000,0.21878444,227.79029570,0.19785401,277.62726899,0.00214372,0.21413142,283.31154803,-0.13704429,-0.07708712,0.00000000,0.00000000,0.00000000,0.00000000
263.16000000,6.62316500,2.51400000,0.22281344,227.88094046,0.20115431,278.65587773,0.00219778,0.21508669,283.58340310,-0.13783281,-0.07725387,0.00000000,0.00000000,0.00000000,0.00000000
264.66000000,6.67725000,2.51400000,0.22706633,227.88094046,0.20462623,279.62503005,0.00237274,0.21565226,283.85784256,-0.13823703,-0.07741523,0.00000000,0.00000000,0.00000000,0.00000000
266.16000000,6.73180300,2.51300000,0.23150544,227.79029570,0.20823736,280.52498934,0.00248541,0.21607168,283.86399012,-0.13854395,-0.07752773,0.00000000,0.00000000,0.00000000,0.00000000
267.66000000,6.78719700,2.51200000,0.23609356,227.69965093,0.21195605,281.45807112,0.00253666,0.21645774,284.08749591,-0.13883390,-0.07762384,0.00000000,0.00000000,0.00000000,0.00000000
269.16000000,6.84238900,2.51200000,0.24030844,227.69965093,0.21536009,282.41779985,0.00210614,0.21666633,284.14699815,-0.13894790,-0.07771844,0.00000000,0.00000000,0.00000000,0.00000000
270.66000000,6.89805200,2.51300000,0.24314211,227.79029570,0.21764214,283.17570909,0.00120001,0.21693451,284.22351551,-0.13916159,-0.07777292,0.00000000,0.00000000,0.00000000,0.00000000
272.16000000,6.95394800,2.51300000,0.24459622,227.79029570,0.21881116,283.50694149,0.00059930,0.21720101,284.41311959,-0.13936572,-0.07783529,0.00000000,0.00000000,0.00000000,0.00000000
273.66000000,7.01024800,2.51300000,0.24541711,227.79029570,0.21947050,283.69393201,0.00035975,0.21732014,284.44713802,-0.13942535,-0.07789479,0.00000000,0.00000000,0.00000000,0.00000000
275.16000000,7.06711900,2.51400000,0.24601433,227.88094046,0.21994992,283.94291811,0.00035940,0.21755542,284.74150554,-0.13959008,-0.07796534,0.00000000,0.00000000,0.00000000,0.00000000
276.66000000,7.12378900,2.51300000,0.24646222,227.79029570,0.22030932,283.93199818,0.00017972,0.21770464,284.78417012,-0.13970257,-0.07800207,0.00000000,0.00000000,0.00000000,0.00000000
278.16000000,7.18150000,2.51300000,0.24687256,227.79029570,0.22063846,284.02546813,0.00023919,0.21788177,284.94844096,-0.13982116,-0.07806061,0.00000000,0.00000000,0.00000000,0.00000000
279.66000000,7.23857300,2.51400000,0.24720844,227.88094046,0.22090781,284.21503328,0.00023930,0.21802917,285.10425330,-0.13992213,-0.07810704,0.00000000,0.00000000,0.00000000,0.00000000
281.16000000,7.29567900,2.51500000,0.24746944,227.97158523,0.22111705,284.38758678,0.00011953,0.00000000,0.00000000,0.00000000,0.00000000,0.00000000,0.00000000,0.00000000,0.00000000
282.66000000,7.35261700,2.51500000,0.24773056,227.97158523,0.22132635,284.44711269,0.00017936,0.00000000,0.00000000,0.00000000,0.00000000,0.00000000,0.00000000,0.00000000,0.00000000
284.16000000,7.41009100,2.51600000,0.24791733,228.06223000,0.22147603,284.60280989,0.00006001,0.00000000,0.00000000,0.00000000,0.00000000,0.00000000,0.00000000,0.00000000,0.00000000
285.66000000,7.46279900,2.51700000,0.24817878,228.15287476,0.22168551,284.77557637,0.00011947,0.00000000,0.00000000,0.00000000,0.00000000,0.00000000,0.00000000,0.00000000,0.00000000
287.16000000,7.50187700,2.51800000,0.24840311,228.24351953,0.22186522,284.93991987,0.00017944,0.00000000,0.00000000,0.00000000,0.00000000,0.00000000,0.00000000,0.00000000,0.00000000
288.66000000,7.52920500,2.51900000,0.24855267,228.33416429,0.22198501,285.08722972,0.00000018,0.00000000,0.00000000,0.00000000,0.00000000,0.00000000,0.00000000,0.00000000,0.00000000
290.16000000,7.55451800,2.52000000,0.24877633,228.42480906,0.22216414,285.25149550,0.00011941,0.00000000,0.00000000,0.00000000,0.00000000,0.00000000,0.00000000,0.00000000,0.00000000
291.66000000,7.58936400,2.51700000,0.24888878,228.15287476,0.00000000,0.00000000,0.00000000,0.00000000,0.00000000,0.00000000,0.00000000,0.00000000,0.00000000,0.00000000,0.00000000
293.16000000,7.63827700,2.51400000,0.24903889,227.88094046,0.00000000,0.00000000,0.00000000,0.00000000,0.00000000,0.00000000,0.00000000,0.00000000,0.00000000,0.00000000,0.00000000
294.66000000,7.69206100,2.51000000,0.24918789,227.51836140,0.00000000,0.00000000,0.00000000,0.00000000,0.00000000,0.00000000,0.00000000,0.00000000,0.00000000,0.00000000,0.00000000
296.16000000,7.74782900,2.50900000,0.24929878,227.42771664,0.00000000,0.00000000,0.00000000,0.00000000,0.00000000,0.00000000,0.00000000,0.00000000,0.00000000,0.00000000,0.00000000
297.66000000,7.80573900,2.50600000,0.24937300,227.15578234,0.00000000,0.00000000,0.00000000,0.00000000,0.00000000,0.00000000,0.00000000,0.00000000,0.00000000,0.00000000,0.00000000
299.16000000,7.86405100,2.50300000,0.24944822,226.88384804,0.00000000,0.00000000,0.00000000,0.00000000,0.00000000,0.00000000,0.00000000,0.00000000,0.00000000,0.00000000,0.00000000
300.66000000,7.92246400,2.49900000,0.24952356,226.52126898,0.00000000,0.00000000,0.00000000,0.00000000,0.00000000,0.00000000,0.00000000,0.00000000,0.00000000,0.00000000,0.00000000
302.16000000,7.98161600,2.49500000,0.24963589,226.15868992,0.00000000,0.00000000,0.00000000,0.00000000,0.00000000,0.00000000,0.00000000,0.00000000,0.00000000,0.00000000,0.00000000
303.66000000,8.04124100,2.48800000,0.24967322,225.52417656,0.00000000,0.00000000,0.00000000,0.00000000,0.00000000,0.00000000,0.00000000,0.00000000,0.00000000,0.00000000,0.00000000
305.16000000,8.10076300,2.47900000,0.24971078,224.70837367,0.00000000,0.00000000,0.00000000,0.00000000,0.00000000,0.00000000,0.00000000,0.00000000,0.00000000,0.00000000,0.00000000
306.66000000,8.16145800,2.46700000,0.24967456,223.62063649,0.00000000,0.00000000,0.00000000,0.00000000,0.00000000,0.00000000,0.00000000,0.00000000,0.00000000,0.00000000,0.00000000
308.16000000,8.22322700,2.44900000,0.24963933,221.98903071,0.00000000,0.00000000,0.00000000,0.00000000,0.00000000,0.00000000,0.00000000,0.00000000,0.00000000,0.00000000,0.00000000
309.66000000,8.28654300,2.42100000,0.24960489,219.45097727,0.00000000,0.00000000,0.00000000,0.00000000,0.00000000,0.00000000,0.00000000,0.00000000,0.00000000,0.00000000,0.00000000
311.16000000,8.35245000,2.37100000,0.24953344,214.91873900,0.00000000,0.00000000,0.00000000,0.00000000,0.00000000,0.00000000,0.00000000,0.00000000,0.00000000,0.00000000,0.00000000
312.66000000,8.42101900,2.30000000,0.24935067,208.48296065,0.00000000,0.00000000,0.00000000,0.00000000,0.00000000,0.00000000,0.00000000,0.00000000,0.00000000,0.00000000,0.00000000
314.16000000,8.78751200,1.42100000,0.29832311,128.80621177,0.00000000,0.00000000,0.00000000,0.00000000,0.00000000,0.00000000,0.00000000,0.00000000,0.00000000,0.00000000,0.00000000
NaN,-100.00000000,NaN,-11.11111111,NaN,0.00000000,0.00000000,0.00000000,0.00000000,0.00000000,0.00000000,0.00000000,0.00000000,0.00000000,0.00000000,0.00000000