File: lab_data/AA6014-T4_results/DATA/UT_60_2.csv
Time[s],Displacement[mm],Force[kN],EngStrain_longi,EngStress[MPa],TrueStrain,TrueStress[MPa],TrueStrainRate[1/s],PlasticStrain_longi,PlasticStress[MPa],PlasticStrain_thick,PlasticStrain_width,R-Value,Thickness[mm],Width[mm], Young's Modulus [MPa]
0.65000000,0.00000000,-0.00100000,0.00000000,-0.08982611,0.00000000,-0.08982611,0.00000000,0.00095143,116.26613136,-0.00024705,-0.00070438,0.56467637,1.11470000,9.98710000,96022.92980912
2.15000000,0.00548600,0.16300000,0.00016078,14.64165619,0.00016076,14.64401025,0.00014554,0.00212695,119.56421026,-0.00100682,-0.00112013,0.00000000,0.00000000,0.00000000,0.00000000
3.65000000,0.01310600,0.41800000,0.00039867,37.54731466,0.00039859,37.56228352,0.00013040,0.00330087,122.86999734,-0.00185993,-0.00144094,0.00000000,0.00000000,0.00000000,0.00000000
5.15000000,0.02184900,0.65800000,0.00069700,59.10558145,0.00069676,59.14677804,0.00024740,0.00447861,126.00307569,-0.00263631,-0.00184230,0.00000000,0.00000000,0.00000000,0.00000000
6.65000000,0.03076000,0.90200000,0.00099678,81.02315268,0.00099628,81.10391476,0.00034302,0.00559428,128.86363892,-0.00337069,-0.00222359,0.00000000,0.00000000,0.00000000,0.00000000
8.15000000,0.04207800,1.14800000,0.00131089,103.12037614,0.00131003,103.25555550,0.00029785,0.00675204,131.19159430,-0.00410272,-0.00264932,0.00000000,0.00000000,0.00000000,0.00000000
9.65000000,0.06628200,1.28000000,0.00207111,114.97742288,0.00206897,115.21555389,0.00057223,0.00792068,133.70814438,-0.00489539,-0.00302529,0.00000000,0.00000000,0.00000000,0.00000000
11.15000000,0.10424300,1.31400000,0.00337911,118.03151067,0.00337341,118.43035226,0.00076600,0.00909471,135.95832832,-0.00569763,-0.00339708,0.00000000,0.00000000,0.00000000,0.00000000
12.65000000,0.14043900,1.35300000,0.00466400,121.53472902,0.00465316,122.10156700,0.00094648,0.01021328,138.11497548,-0.00639797,-0.00381531,0.00000000,0.00000000,0.00000000,0.00000000
14.15000000,0.17667800,1.38600000,0.00583978,124.49899071,0.00582279,125.22603715,0.00095023,0.01136133,140.28055381,-0.00714048,-0.00422084,0.00000000,0.00000000,0.00000000,0.00000000
15.65000000,0.21344200,1.41400000,0.00704611,127.01412183,0.00702140,127.90907745,0.00089567,0.01248095,142.53832101,-0.00784678,-0.00463417,0.00000000,0.00000000,0.00000000,0.00000000
17.15000000,0.24922100,1.44200000,0.00830411,129.52925296,0.00826982,130.60487827,0.00087801,0.01367165,144.35425561,-0.00874004,-0.00493161,0.00000000,0.00000000,0.00000000,0.00000000
18.65000000,0.28675900,1.46600000,0.00953844,131.68507964,0.00949324,132.94115045,0.00098155,0.01477650,146.43645246,-0.00938617,-0.00539033,0.00000000,0.00000000,0.00000000,0.00000000
20.15000000,0.32188600,1.49000000,0.01071200,133.84090632,0.01065503,135.27461011,0.00092431,0.01594083,148.34874923,-0.01014827,-0.00579257,0.00000000,0.00000000,0.00000000,0.00000000
21.65000000,0.35787800,1.51400000,0.01187100,135.99673300,0.01180109,137.61115021,0.00075386,0.01708312,150.17032449,-0.01092062,-0.00616250,0.00000000,0.00000000,0.00000000,0.00000000
23.15000000,0.39386300,1.53500000,0.01309811,137.88308134,0.01301307,139.68908926,0.00077336,0.01819957,152.17576569,-0.01169974,-0.00649984,0.00000000,0.00000000,0.00000000,0.00000000
24.65000000,0.42959900,1.55600000,0.01429944,139.76942968,0.01419817,141.76805488,0.00083885,0.01930639,154.00017316,-0.01244240,-0.00686399,0.00000000,0.00000000,0.00000000,0.00000000
26.15000000,0.46452500,1.57700000,0.01539989,141.65577803,0.01528251,143.83726127,0.00072037,0.02042888,155.64680912,-0.01319529,-0.00723359,0.00000000,0.00000000,0.00000000,0.00000000
27.65000000,0.49970500,1.59700000,0.01657867,143.45230026,0.01644274,145.83054813,0.00063885,0.02154613,157.57277101,-0.01395138,-0.00759475,0.00000000,0.00000000,0.00000000,0.00000000
29.15000000,0.53515900,1.61600000,0.01777589,145.15899638,0.01761975,147.73932657,0.00069641,0.02262232,159.21950140,-0.01463337,-0.00798895,0.00000000,0.00000000,0.00000000,0.00000000
30.65000000,0.57044100,1.63600000,0.01896956,146.95551861,0.01879188,149.74319949,0.00075406,0.02373377,160.87535638,-0.01536440,-0.00836937,0.00000000,0.00000000,0.00000000,0.00000000
32.15000000,0.60569600,1.65400000,0.02009622,148.57238862,0.01989696,151.55813236,0.00066563,0.02485326,162.62859495,-0.01613350,-0.00871976,0.00000000,0.00000000,0.00000000,0.00000000
33.65000000,0.64045000,1.67200000,0.02128611,150.18925863,0.02106273,153.38620388,0.00067943,0.02595826,164.29064089,-0.01684222,-0.00911604,0.00000000,0.00000000,0.00000000,0.00000000
35.15000000,0.67535100,1.69100000,0.02248722,151.89595475,0.02223811,155.31167284,0.00077364,0.02703795,165.85930993,-0.01754636,-0.00949158,0.00000000,0.00000000,0.00000000,0.00000000
36.65000000,0.71046700,1.70800000,0.02363233,153.42299865,0.02335741,157.04874210,0.00075823,0.02812959,167.52607796,-0.01824020,-0.00988939,0.00000000,0.00000000,0.00000000,0.00000000
38.16000000,0.74501300,1.72400000,0.02477756,154.86021644,0.02447557,158.69727405,0.00073530,0.02923684,169.01314818,-0.01895729,-0.01027955,0.00000000,0.00000000,0.00000000,0.00000000
39.65000000,0.77982700,1.74100000,0.02595256,156.38726033,0.02562150,160.44590940,0.00074915,0.03033074,170.59412709,-0.01965266,-0.01067808,0.00000000,0.00000000,0.00000000,0.00000000
41.15000000,0.81437300,1.75800000,0.02712022,157.91430423,0.02675899,162.19697525,0.00079916,0.03141618,172.17697307,-0.02031175,-0.01110443,0.00000000,0.00000000,0.00000000,0.00000000
42.65000000,0.84938900,1.77300000,0.02827656,159.26169591,0.02788415,163.76506810,0.00079847,0.03253165,173.58185475,-0.02106397,-0.01146768,0.00000000,0.00000000,0.00000000,0.00000000
44.15000000,0.88413600,1.78900000,0.02941800,160.69891369,0.02899359,165.42635433,0.00069609,0.03360271,174.98192287,-0.02175553,-0.01184718,0.00000000,0.00000000,0.00000000,0.00000000
45.65000000,0.91824600,1.80400000,0.03057811,162.04630537,0.03011992,167.00137530,0.00073866,0.03469886,176.57620652,-0.02246832,-0.01223054,0.00000000,0.00000000,0.00000000,0.00000000
47.15000000,0.95292600,1.81900000,0.03175311,163.39369704,0.03125941,168.58195526,0.00082444,0.03579250,177.98626486,-0.02318739,-0.01260511,0.00000000,0.00000000,0.00000000,0.00000000
48.65000000,0.98754000,1.83300000,0.03288733,164.65126260,0.03235812,170.06620356,0.00075875,0.03689332,179.30687005,-0.02390768,-0.01298565,0.00000000,0.00000000,0.00000000,0.00000000
50.15000000,1.02198500,1.84800000,0.03403244,165.99865428,0.03346615,171.64799426,0.00072179,0.03797947,180.81511998,-0.02462776,-0.01335171,0.00000000,0.00000000,0.00000000,0.00000000
51.65000000,1.05757000,1.86200000,0.03519989,167.25621984,0.03459454,173.14362019,0.00075663,0.03906721,182.13901812,-0.02533896,-0.01372825,0.00000000,0.00000000,0.00000000,0.00000000
53.15000000,1.09188100,1.87700000,0.03633756,168.60361151,0.03569292,174.73025461,0.00074872,0.04016781,183.46799924,-0.02607689,-0.01409092,0.00000000,0.00000000,0.00000000,0.00000000
54.65000000,1.12602500,1.89000000,0.03749411,169.77135097,0.03680830,176.13677686,0.00072641,0.04127651,184.89533775,-0.02681015,-0.01446636,0.00000000,0.00000000,0.00000000,0.00000000
56.15000000,1.16104100,1.90300000,0.03867667,170.93909042,0.03794747,177.55044464,0.00076865,0.04233686,186.12823356,-0.02747065,-0.01486621,0.00000000,0.00000000,0.00000000,0.00000000
57.65000000,1.19572100,1.91600000,0.03982911,172.10682987,0.03905638,178.96169192,0.00078191,0.04343486,187.37065237,-0.02824569,-0.01518918,0.00000000,0.00000000,0.00000000,0.00000000
59.15000000,1.22993000,1.92900000,0.04097067,173.27456932,0.04015361,180.37374394,0.00074538,0.04454464,188.71226487,-0.02897197,-0.01557267,0.00000000,0.00000000,0.00000000,0.00000000
60.65000000,1.26508000,1.94200000,0.04212711,174.44230877,0.04126392,181.79105929,0.00073773,0.04562951,189.95740653,-0.02967343,-0.01595608,0.00000000,0.00000000,0.00000000,0.00000000
62.15000000,1.29959300,1.95400000,0.04330589,175.52022211,0.04239441,183.12128135,0.00074393,0.04672871,191.11318623,-0.03036502,-0.01636369,0.00000000,0.00000000,0.00000000,0.00000000
63.65000000,1.33457600,1.96600000,0.04446967,176.59813545,0.04350926,184.45139567,0.00080716,0.04781312,192.45794040,-0.03107747,-0.01673565,0.00000000,0.00000000,0.00000000,0.00000000
65.15000000,1.36902100,1.97700000,0.04564111,177.58622268,0.04463020,185.69145520,0.00073504,0.04893083,193.62221500,-0.03179645,-0.01713438,0.00000000,0.00000000,0.00000000,0.00000000
66.65000000,1.40353300,1.99000000,0.04677500,178.75396213,0.04571401,187.11517871,0.00071279,0.05002977,194.78522582,-0.03250329,-0.01752649,0.00000000,0.00000000,0.00000000,0.00000000
68.15000000,1.43848100,2.00100000,0.04794633,179.74204936,0.04683238,188.36002157,0.00076906,0.05110501,196.04099851,-0.03317389,-0.01793112,0.00000000,0.00000000,0.00000000,0.00000000
69.65000000,1.47339800,2.01200000,0.04911022,180.73013658,0.04794240,189.60583375,0.00075401,0.05219186,197.11125820,-0.03387785,-0.01831401,0.00000000,0.00000000,0.00000000,0.00000000
71.15000000,1.50844700,2.02200000,0.05025922,181.62839770,0.04903701,190.75689970,0.00069646,0.05330453,198.28405048,-0.03460364,-0.01870089,0.00000000,0.00000000,0.00000000,0.00000000
72.65000000,1.54319200,2.03400000,0.05145267,182.70631104,0.05017270,192.10703796,0.00071681,0.05441935,199.45967788,-0.03531977,-0.01909958,0.00000000,0.00000000,0.00000000,0.00000000
74.15000000,1.57844300,2.04400000,0.05261644,183.60457216,0.05127892,193.26519193,0.00073735,0.05549553,200.53445494,-0.03596657,-0.01952896,0.00000000,0.00000000,0.00000000,0.00000000
75.65000000,1.61315500,2.05500000,0.05376911,184.59265938,0.05237337,194.51804260,0.00074371,0.05658469,201.61397231,-0.03671060,-0.01987409,0.00000000,0.00000000,0.00000000,0.00000000
77.15000000,1.64787000,2.06400000,0.05494789,185.40109439,0.05349137,195.58849312,0.00072160,0.05769690,202.70032292,-0.03743310,-0.02026380,0.00000000,0.00000000,0.00000000,0.00000000
78.65000000,1.68295200,2.07400000,0.05610411,186.29935550,0.05458677,196.75151524,0.00068524,0.05880782,203.78860929,-0.03817050,-0.02063731,0.00000000,0.00000000,0.00000000,0.00000000
80.15000000,1.71790000,2.08500000,0.05729022,187.28744273,0.05570924,198.01718195,0.00074081,0.05988269,204.87169096,-0.03887090,-0.02101179,0.00000000,0.00000000,0.00000000,0.00000000
81.65000000,1.75361900,2.09400000,0.05845022,188.09587774,0.05680578,199.09012359,0.00076122,0.06098067,205.96167199,-0.03960543,-0.02137524,0.00000000,0.00000000,0.00000000,0.00000000
83.15000000,1.78870200,2.10300000,0.05964756,188.90431274,0.05793636,200.17199323,0.00073224,0.06208226,206.95844531,-0.04031208,-0.02177017,0.00000000,0.00000000,0.00000000,0.00000000
84.65000000,1.82432100,2.11200000,0.06085244,189.71274775,0.05907278,201.25723219,0.00078799,0.06320000,207.96056229,-0.04106387,-0.02213614,0.00000000,0.00000000,0.00000000,0.00000000
86.15000000,1.85960400,2.12200000,0.06202367,190.61100886,0.06017621,202.43340254,0.00075196,0.06429200,208.95929314,-0.04175870,-0.02253330,0.00000000,0.00000000,0.00000000,0.00000000
87.65000000,1.89525600,2.13100000,0.06320233,191.41944387,0.06128542,203.51759936,0.00073711,0.06540365,209.96412441,-0.04248078,-0.02292287,0.00000000,0.00000000,0.00000000,0.00000000
89.15000000,1.93087400,2.14000000,0.06437711,192.22787887,0.06238976,204.60295439,0.00072210,0.06651196,210.87367622,-0.04319585,-0.02331610,0.00000000,0.00000000,0.00000000,0.00000000
90.65000000,1.96612500,2.14800000,0.06559322,192.94648776,0.06353166,205.60246961,0.00077739,0.06761978,211.97827920,-0.04390584,-0.02371394,0.00000000,0.00000000,0.00000000,0.00000000
92.15000000,2.00177700,2.15600000,0.06676433,193.66509666,0.06463008,206.59501773,0.00073444,0.06873935,212.89402045,-0.04463382,-0.02410553,0.00000000,0.00000000,0.00000000,0.00000000
93.65000000,2.03780000,2.16400000,0.06796911,194.38370555,0.06575882,207.59579323,0.00077545,0.06984391,213.80835329,-0.04534731,-0.02449660,0.00000000,0.00000000,0.00000000,0.00000000
95.15000000,2.07341900,2.17300000,0.06916267,195.19214055,0.06687579,208.69214951,0.00076066,0.07095390,214.72563696,-0.04605309,-0.02490081,0.00000000,0.00000000,0.00000000,0.00000000
96.65000000,2.10947400,2.18100000,0.07036000,195.91074945,0.06799504,209.69502978,0.00072491,0.07207986,215.64817446,-0.04681337,-0.02526649,0.00000000,0.00000000,0.00000000,0.00000000
98.15000000,2.14496000,2.18800000,0.07154989,196.53953223,0.06910609,210.60191392,0.00072390,0.07318060,216.56705997,-0.04749897,-0.02568163,0.00000000,0.00000000,0.00000000,0.00000000
99.65000000,2.18118400,2.19600000,0.07275856,197.25814112,0.07023342,211.61035854,0.00075831,0.07429032,217.48969277,-0.04822548,-0.02606484,0.00000000,0.00000000,0.00000000,0.00000000
101.15000000,2.21730800,2.20300000,0.07397089,197.88692390,0.07136289,212.52479556,0.00074359,0.07538842,218.41158406,-0.04893108,-0.02645734,0.00000000,0.00000000,0.00000000,0.00000000
102.65000000,2.25329700,2.21200000,0.07517944,198.69535891,0.07248757,213.63316560,0.00072187,0.07649687,219.23996941,-0.04964449,-0.02685238,0.00000000,0.00000000,0.00000000,0.00000000
104.15000000,2.28962100,2.21800000,0.07637667,199.23431558,0.07360046,214.45116849,0.00072086,0.07764732,220.17689886,-0.05040951,-0.02723781,0.00000000,0.00000000,0.00000000,0.00000000
105.65000000,2.32591200,2.22600000,0.07758900,199.95292447,0.07472614,215.46707193,0.00072706,0.07874297,221.00576998,-0.05109403,-0.02764894,0.00000000,0.00000000,0.00000000,0.00000000
107.15000000,2.36237100,2.23200000,0.07879767,200.49188114,0.07584715,216.29017356,0.00071265,0.07985124,221.83902111,-0.05182534,-0.02802590,0.00000000,0.00000000,0.00000000,0.00000000
108.65000000,2.39856200,2.23900000,0.08001733,201.12066392,0.07697709,217.21380313,0.00075980,0.08096348,222.77276906,-0.05252776,-0.02843573,0.00000000,0.00000000,0.00000000,0.00000000
110.15000000,2.43461800,2.24600000,0.08121100,201.74944670,0.07808171,218.13372102,0.00073820,0.08205537,223.60565233,-0.05321307,-0.02884230,0.00000000,0.00000000,0.00000000,0.00000000
111.65000000,2.47154700,2.25200000,0.08244200,202.28840337,0.07921960,218.96546392,0.00076529,0.08318489,224.35034462,-0.05394964,-0.02923525,0.00000000,0.00000000,0.00000000,0.00000000
113.15000000,2.50800500,2.25900000,0.08366911,202.91718615,0.08035261,219.89508675,0.00077099,0.08427427,225.18573149,-0.05467646,-0.02959781,0.00000000,0.00000000,0.00000000,0.00000000
114.65000000,2.54459900,2.26500000,0.08486656,203.45614282,0.08145699,220.72276487,0.00073591,0.08538969,226.02859616,-0.05535874,-0.03003095,0.00000000,0.00000000,0.00000000,0.00000000
116.15000000,2.58082400,2.27100000,0.08610511,203.99509949,0.08259800,221.56012020,0.00073528,0.08651051,226.87430873,-0.05609198,-0.03041852,0.00000000,0.00000000,0.00000000,0.00000000
117.65000000,2.61761900,2.27800000,0.08732111,204.62388227,0.08371697,222.49186703,0.00069970,0.08762483,227.62148717,-0.05678922,-0.03083561,0.00000000,0.00000000,0.00000000,0.00000000
119.15000000,2.65454800,2.28400000,0.08854089,205.16283894,0.08483817,223.32813907,0.00071995,0.08875316,228.47206976,-0.05751947,-0.03123369,0.00000000,0.00000000,0.00000000,0.00000000
120.65000000,2.69114100,2.29000000,0.08978678,205.70179561,0.08598206,224.17109703,0.00077400,0.08987157,229.22311027,-0.05824595,-0.03162562,0.00000000,0.00000000,0.00000000,0.00000000
122.15000000,2.72793600,2.29600000,0.09096922,206.24075228,0.08706650,225.00231311,0.00073873,0.09096853,229.97061223,-0.05893037,-0.03203816,0.00000000,0.00000000,0.00000000,0.00000000
123.65000000,2.76463000,2.30100000,0.09221878,206.68988284,0.08821120,225.75057122,0.00079243,0.09210462,230.72855194,-0.05968274,-0.03242188,0.00000000,0.00000000,0.00000000,0.00000000
125.15000000,2.80159300,2.30700000,0.09341622,207.22883951,0.08930694,226.58737483,0.00070962,0.09323265,231.48605938,-0.06040759,-0.03282506,0.00000000,0.00000000,0.00000000,0.00000000
126.65000000,2.83872400,2.31200000,0.09468067,207.67797007,0.09046269,227.34105873,0.00072932,0.09433234,232.23839678,-0.06108230,-0.03325004,0.00000000,0.00000000,0.00000000,0.00000000
128.15000000,2.87588800,2.31800000,0.09591167,208.21692674,0.09158659,228.18735921,0.00073539,0.09545908,232.89897085,-0.06181174,-0.03364734,0.00000000,0.00000000,0.00000000,0.00000000
129.65000000,2.91312000,2.32300000,0.09713522,208.66605730,0.09270244,228.93488114,0.00071411,0.09658000,233.65897787,-0.06252716,-0.03405285,0.00000000,0.00000000,0.00000000,0.00000000
131.15000000,2.94998200,2.32800000,0.09837733,209.11518786,0.09383394,229.68738240,0.00074730,0.09771635,234.42403944,-0.06327167,-0.03444469,0.00000000,0.00000000,0.00000000,0.00000000
132.65000000,2.98748200,2.33400000,0.09961589,209.65414453,0.09496093,230.53902849,0.00071937,0.09882238,235.08358240,-0.06398682,-0.03483556,0.00000000,0.00000000,0.00000000,0.00000000
134.15000000,3.02468000,2.33800000,0.10088400,210.01344897,0.09611349,231.20044576,0.00077932,0.09994592,235.84838277,-0.06469689,-0.03524903,0.00000000,0.00000000,0.00000000,0.00000000
135.65000000,3.06201200,2.34400000,0.10210756,210.55240564,0.09722431,232.05139710,0.00073791,0.10106956,236.51460120,-0.06542280,-0.03564676,0.00000000,0.00000000,0.00000000,0.00000000
137.15000000,3.09914200,2.34800000,0.10335344,210.91171009,0.09835413,232.71016180,0.00069658,0.10220735,237.28555625,-0.06613873,-0.03606861,0.00000000,0.00000000,0.00000000,0.00000000
138.65000000,3.13701200,2.35200000,0.10465900,211.27101453,0.09953669,233.38242764,0.00080383,0.10334530,237.95774080,-0.06685847,-0.03648684,0.00000000,0.00000000,0.00000000,0.00000000
140.15000000,3.17471300,2.35700000,0.10587878,211.72014509,0.10064029,234.13681529,0.00076233,0.10445499,238.62439136,-0.06755907,-0.03689592,0.00000000,0.00000000,0.00000000,0.00000000
141.65000000,3.21208000,2.36200000,0.10710611,212.16927565,0.10174950,234.89390166,0.00076832,0.10556669,239.29272399,-0.06825461,-0.03731209,0.00000000,0.00000000,0.00000000,0.00000000
143.15000000,3.24994800,2.36600000,0.10835567,212.52858010,0.10287754,235.55725608,0.00069364,0.10675390,239.98044051,-0.06903826,-0.03771564,0.00000000,0.00000000,0.00000000,0.00000000
144.65000000,3.28738000,2.37100000,0.10966478,212.97771066,0.10405797,236.33386397,0.00078658,0.10786982,240.65225050,-0.06974415,-0.03812566,0.00000000,0.00000000,0.00000000,0.00000000
146.15000000,3.32508200,2.37500000,0.11088833,213.33701510,0.10516000,236.99360115,0.00079272,0.10899577,241.22684903,-0.07043390,-0.03856186,0.00000000,0.00000000,0.00000000,0.00000000
147.65000000,3.36355600,2.38000000,0.11214922,213.78614566,0.10629438,237.76209562,0.00073145,0.11014896,241.91002624,-0.07118694,-0.03896201,0.00000000,0.00000000,0.00000000,0.00000000
149.15000000,3.40162600,2.38300000,0.11342111,214.05562400,0.10743736,238.33405071,0.00073700,0.11127077,242.58683281,-0.07191072,-0.03936004,0.00000000,0.00000000,0.00000000,0.00000000
150.65000000,3.43939400,2.38800000,0.11470422,214.50475455,0.10858910,239.10935559,0.00080297,0.11240622,243.16699140,-0.07263122,-0.03977500,0.00000000,0.00000000,0.00000000,0.00000000
152.15000000,3.47766600,2.39100000,0.11596133,214.77423289,0.10971622,239.67973930,0.00078254,0.11353884,243.84879014,-0.07335959,-0.04017924,0.00000000,0.00000000,0.00000000,0.00000000
153.65000000,3.51573700,2.39500000,0.11724456,215.13353733,0.11086544,240.35677330,0.00082820,0.11470442,244.43848368,-0.07411455,-0.04058987,0.00000000,0.00000000,0.00000000,0.00000000
155.15000000,3.55411000,2.39900000,0.11849044,215.49284178,0.11197996,241.02668438,0.00073386,0.11584896,245.02405618,-0.07483391,-0.04101506,0.00000000,0.00000000,0.00000000,0.00000000
156.65000000,3.59278600,2.40300000,0.11984067,215.85214623,0.11318641,241.72001133,0.00079273,0.11694451,245.70025302,-0.07553222,-0.04141229,0.00000000,0.00000000,0.00000000,0.00000000
158.15000000,3.63172800,2.40700000,0.12109767,216.21145067,0.11430826,242.39415286,0.00077856,0.11808653,246.28735150,-0.07627434,-0.04181219,0.00000000,0.00000000,0.00000000,0.00000000
159.65000000,3.67003400,2.41000000,0.12238833,216.48092901,0.11545886,242.97566911,0.00079786,0.11923559,246.97912990,-0.07700177,-0.04223382,0.00000000,0.00000000,0.00000000,0.00000000
161.15000000,3.70887700,2.41400000,0.12368644,216.84023346,0.11661475,243.66043094,0.00077023,0.12036629,247.46357465,-0.07772874,-0.04263755,0.00000000,0.00000000,0.00000000,0.00000000
162.65000000,3.74751800,2.41700000,0.12496222,217.10971179,0.11774945,244.24022384,0.00075612,0.12149625,248.15290359,-0.07843974,-0.04305652,0.00000000,0.00000000,0.00000000,0.00000000
164.15000000,3.78619300,2.42100000,0.12626022,217.46901624,0.11890261,244.92670255,0.00077499,0.12261316,248.73796965,-0.07911947,-0.04349369,0.00000000,0.00000000,0.00000000,0.00000000
165.65000000,3.82533700,2.42400000,0.12753222,217.73849457,0.12003137,245.50716865,0.00077431,0.12377461,249.33518784,-0.07988150,-0.04389311,0.00000000,0.00000000,0.00000000,0.00000000
167.15000000,3.86397800,2.42700000,0.12881911,218.00797291,0.12117205,246.09156619,0.00074704,0.12493469,249.93312171,-0.08061340,-0.04432129,0.00000000,0.00000000,0.00000000,0.00000000
168.65000000,3.90262100,2.43000000,0.13010244,218.27745124,0.12230829,246.67588121,0.00074619,0.12609824,250.43036888,-0.08133496,-0.04476328,0.00000000,0.00000000,0.00000000,0.00000000
170.15000000,3.94233600,2.43400000,0.13142656,218.63675569,0.12347928,247.37143141,0.00081782,0.12723274,251.02386480,-0.08204018,-0.04519256,0.00000000,0.00000000,0.00000000,0.00000000
171.65000000,3.98107800,2.43600000,0.13270222,218.81640791,0.12460613,247.85383150,0.00069168,0.12840833,251.62876995,-0.08279684,-0.04561149,0.00000000,0.00000000,0.00000000,0.00000000
173.15000000,4.02039000,2.44000000,0.13400022,219.17571236,0.12575140,248.54530652,0.00072382,0.12957736,252.13011759,-0.08352019,-0.04605718,0.00000000,0.00000000,0.00000000,0.00000000
174.65000000,4.05960200,2.44200000,0.13532444,219.35536458,0.12691846,249.03950743,0.00083459,0.13078257,252.74458003,-0.08429612,-0.04648646,0.00000000,0.00000000,0.00000000,0.00000000
176.15000000,4.09931800,2.44600000,0.13660011,219.71466903,0.12804145,249.72771723,0.00076793,0.13192297,253.24046042,-0.08504823,-0.04687474,0.00000000,0.00000000,0.00000000,0.00000000
177.65000000,4.13896500,2.44900000,0.13791311,219.98414736,0.12919598,250.32284552,0.00074751,0.13307006,253.84220126,-0.08574289,-0.04732717,0.00000000,0.00000000,0.00000000,0.00000000
179.15000000,4.17864800,2.45100000,0.13925978,220.16379959,0.13037873,250.82376139,0.00073999,0.13422574,254.44719281,-0.08647721,-0.04774853,0.00000000,0.00000000,0.00000000,0.00000000
180.65000000,4.21883200,2.45400000,0.14061378,220.43327792,0.13156652,251.42923388,0.00079817,0.13536860,254.94638220,-0.08722396,-0.04814465,0.00000000,0.00000000,0.00000000,0.00000000
182.15000000,4.25881700,2.45700000,0.14191189,220.70275626,0.13270395,252.02310128,0.00071238,0.13649387,255.44187647,-0.08794745,-0.04854643,0.00000000,0.00000000,0.00000000,0.00000000
183.65000000,4.29910200,2.45900000,0.14329944,220.88240848,0.13391833,252.53473490,0.00078327,0.13759390,256.03550919,-0.08862718,-0.04896672,0.00000000,0.00000000,0.00000000,0.00000000
185.15000000,4.33868400,2.46200000,0.14463856,221.15188681,0.13508892,253.13897628,0.00070428,0.13871653,256.53202646,-0.08933274,-0.04938379,0.00000000,0.00000000,0.00000000,0.00000000
186.65000000,4.37843300,2.46500000,0.14600378,221.42136515,0.13628091,253.74972094,0.00083341,0.13982828,257.02653722,-0.09006149,-0.04976679,0.00000000,0.00000000,0.00000000,0.00000000
188.15000000,4.41875200,2.46700000,0.14730933,221.60101737,0.13741949,254.24491551,0.00077394,0.14093562,257.52069453,-0.09077457,-0.05016105,0.00000000,0.00000000,0.00000000,0.00000000
189.65000000,4.45873700,2.47000000,0.14863722,221.87049571,0.13857622,254.84870988,0.00073395,0.14203836,258.01444686,-0.09148102,-0.05055734,0.00000000,0.00000000,0.00000000,0.00000000
191.15000000,4.49872100,2.47200000,0.14994644,222.05014793,0.13971537,255.34577810,0.00071997,0.14316242,258.51451345,-0.09217881,-0.05098361,0.00000000,0.00000000,0.00000000,0.00000000
192.65000000,4.53883900,2.47400000,0.15125200,222.22980015,0.14085005,255.84250189,0.00078403,0.14427240,259.01172430,-0.09286982,-0.05140258,0.00000000,0.00000000,0.00000000,0.00000000
194.15000000,4.57798300,2.47600000,0.15253889,222.40945238,0.14196724,256.33554312,0.00073147,0.14542920,259.52192053,-0.09360542,-0.05182378,0.00000000,0.00000000,0.00000000,0.00000000
195.65000000,4.61820200,2.47800000,0.15381822,222.58910460,0.14307664,256.82736495,0.00067247,0.14661026,260.03928979,-0.09434428,-0.05226599,0.00000000,0.00000000,0.00000000,0.00000000
197.15000000,4.65805100,2.48000000,0.15507544,222.76875682,0.14416566,257.31472079,0.00069791,0.14785365,260.57382580,-0.09513373,-0.05271992,0.00000000,0.00000000,0.00000000,0.00000000
198.65000000,4.69820300,2.48200000,0.15638456,222.94840905,0.14529838,257.81409691,0.00078075,0.14906364,261.10054238,-0.09589247,-0.05317117,0.00000000,0.00000000,0.00000000,0.00000000
200.15000000,4.73825300,2.48400000,0.15767144,223.12806127,0.14641061,258.30898499,0.00076068,0.15033739,261.53973212,-0.09668420,-0.05365319,0.00000000,0.00000000,0.00000000,0.00000000
201.65000000,4.77927800,2.48700000,0.15901411,223.39753960,0.14756974,258.92090079,0.00081734,0.15163978,262.09245963,-0.09750920,-0.05413058,0.00000000,0.00000000,0.00000000,0.00000000
203.15000000,4.82053700,2.48900000,0.16036067,223.57719183,0.14873088,259.43017936,0.00083593,0.15294044,262.64573664,-0.09831908,-0.05462136,0.00000000,0.00000000,0.00000000,0.00000000
204.65000000,4.86132800,2.49000000,0.16166633,223.66701794,0.14985547,259.82644462,0.00070658,0.15427262,263.10275460,-0.09917438,-0.05509825,0.00000000,0.00000000,0.00000000,0.00000000
206.15000000,4.90285500,2.49200000,0.16312100,223.84667016,0.15110691,260.36076285,0.00083395,0.15556991,263.65702491,-0.09999911,-0.05557080,0.00000000,0.00000000,0.00000000,0.00000000
207.65000000,4.94468600,2.49400000,0.16453844,224.02632239,0.15232482,260.88726498,0.00076898,0.15683372,264.20341922,-0.10080823,-0.05602549,0.00000000,0.00000000,0.00000000,0.00000000
209.15000000,4.98722100,2.49600000,0.16603056,224.20597461,0.15360529,261.43101713,0.00083186,0.15806575,264.63634128,-0.10159472,-0.05647103,0.00000000,0.00000000,0.00000000,0.00000000
210.65000000,5.02985700,2.49700000,0.16752256,224.29580072,0.15488403,261.87040646,0.00083099,0.15926325,265.16687086,-0.10233162,-0.05693163,0.00000000,0.00000000,0.00000000,0.00000000
212.15000000,5.07289600,2.49900000,0.16905200,224.47545294,0.15619316,262.42347721,0.00082990,0.16042932,265.58366509,-0.10309231,-0.05733701,0.00000000,0.00000000,0.00000000,0.00000000
213.65000000,5.11620400,2.50100000,0.17061856,224.65510517,0.15753229,262.98543471,0.00095604,0.16159392,266.00068222,-0.10384477,-0.05774915,0.00000000,0.00000000,0.00000000,0.00000000
215.15000000,5.15978000,2.50200000,0.17214800,224.74493128,0.15883796,263.43432171,0.00082771,0.16266119,266.49877560,-0.10454644,-0.05811475,0.00000000,0.00000000,0.00000000,0.00000000
216.65000000,5.20255000,2.50400000,0.17367733,224.92458350,0.16014184,263.98888536,0.00089009,0.16363469,266.86591357,-0.10517129,-0.05846341,0.00000000,0.00000000,0.00000000,0.00000000
218.15000000,5.24508500,2.50600000,0.17516933,225.10423572,0.16141225,264.53559463,0.00088896,0.16448301,267.09325180,-0.10568800,-0.05879501,0.00000000,0.00000000,0.00000000,0.00000000
219.65000000,5.28718500,2.50800000,0.17658678,225.28388795,0.16261769,265.06604381,0.00082459,0.16526629,267.41010368,-0.10616653,-0.05909976,0.00000000,0.00000000,0.00000000,0.00000000
221.15000000,5.32962000,2.50900000,0.17800422,225.37371406,0.16382167,265.49118674,0.00076019,0.16604754,267.83360032,-0.10666799,-0.05937955,0.00000000,0.00000000,0.00000000,0.00000000
222.65000000,5.37037700,2.51000000,0.17930978,225.46354017,0.16492933,265.89135746,0.00075935,0.16676545,268.24054376,-0.10712307,-0.05964238,0.00000000,0.00000000,0.00000000,0.00000000
224.15000000,5.41083000,2.51100000,0.18061522,225.55336628,0.16603568,266.29173766,0.00069524,0.16748461,268.54126461,-0.10756514,-0.05991947,0.00000000,0.00000000,0.00000000,0.00000000
225.65000000,5.45031100,2.51200000,0.18180878,225.64319239,0.16704613,266.66710542,0.00063134,0.16814071,268.82526310,-0.10795676,-0.06018395,0.00000000,0.00000000,0.00000000,0.00000000
227.15000000,5.48898600,2.51400000,0.18289056,225.82284462,0.16796107,267.12371013,0.00056762,0.16879618,269.10935206,-0.10836316,-0.06043302,0.00000000,0.00000000,0.00000000,0.00000000
228.65000000,5.52709000,2.51400000,0.18386044,225.82284462,0.16878066,267.34273319,0.00050425,0.16948212,269.40193864,-0.10880213,-0.06067999,0.00000000,0.00000000,0.00000000,0.00000000
230.15000000,5.56583300,2.51600000,0.18475567,226.00249684,0.16953656,267.75773881,0.00037780,0.17019902,269.70318385,-0.10928516,-0.06091386,0.00000000,0.00000000,0.00000000,0.00000000
231.65000000,5.60524600,2.51700000,0.18565078,226.09232295,0.17029180,268.06653856,0.00044050,0.17107172,270.04695483,-0.10990522,-0.06116650,0.00000000,0.00000000,0.00000000,0.00000000
233.15000000,5.64533200,2.51800000,0.18654622,226.18214906,0.17104675,268.37557451,0.00056624,0.17275323,270.61074371,-0.11131918,-0.06143404,0.00000000,0.00000000,0.00000000,0.00000000
234.65000000,5.68669300,2.52000000,0.18736722,226.36180129,0.17173844,268.77458321,0.00050295,0.17545707,271.45410840,-0.11368334,-0.06177373,0.00000000,0.00000000,0.00000000,0.00000000
236.15000000,5.72896000,2.52100000,0.18811333,226.45162740,0.17236661,269.05019787,0.00037673,0.17864927,272.43359458,-0.11597876,-0.06267051,0.00000000,0.00000000,0.00000000,0.00000000
237.65000000,5.77270500,2.52200000,0.18885933,226.54145351,0.17299430,269.32592139,0.00037649,0.18204731,273.47308937,-0.11746711,-0.06458019,0.00000000,0.00000000,0.00000000,0.00000000
239.15000000,5.81809400,2.52200000,0.18971700,226.54145351,0.17371546,269.52021845,0.00043881,0.18549537,274.53030854,-0.11862372,-0.06687165,0.00000000,0.00000000,0.00000000,0.00000000
240.65000000,5.86502700,2.52300000,0.19068711,226.63127962,0.17453054,269.84694362,0.00068954,0.18899280,275.60524699,-0.11982116,-0.06917164,0.00000000,0.00000000,0.00000000,0.00000000
242.15000000,5.91343800,2.52400000,0.19229111,226.72110573,0.17587676,270.31755907,0.00118891,0.19253904,276.69792483,-0.12156177,-0.07097727,0.00000000,0.00000000,0.00000000,0.00000000
243.65000000,5.96195000,2.52500000,0.19512544,226.81093185,0.17825115,271.06751573,0.00174823,0.19604382,277.67320533,-0.12399903,-0.07204479,0.00000000,0.00000000,0.00000000,0.00000000
245.15000000,6.01197200,2.52600000,0.19885511,226.90075796,0.18136703,272.02113339,0.00211666,0.19889972,278.47047087,-0.12633887,-0.07256085,0.00000000,0.00000000,0.00000000,0.00000000
246.65000000,6.06269900,2.52700000,0.20288333,226.99058407,0.18472145,273.04319040,0.00223385,0.20050751,278.92032052,-0.12769690,-0.07281061,0.00000000,0.00000000,0.00000000,0.00000000
248.15000000,6.11305700,2.52900000,0.20706100,227.17023629,0.18818848,274.20833259,0.00228804,0.20132802,279.03944954,-0.12830591,-0.07302211,0.00000000,0.00000000,0.00000000,0.00000000
249.65000000,6.16371700,2.53000000,0.21135056,227.26006240,0.19173590,275.29160285,0.00240335,0.20193584,279.09897964,-0.12875721,-0.07317863,0.00000000,0.00000000,0.00000000,0.00000000
251.15000000,6.21447800,2.53100000,0.21560289,227.34988852,0.19524016,276.36718127,0.00239494,0.20232969,279.20935913,-0.12898697,-0.07334272,0.00000000,0.00000000,0.00000000,0.00000000
252.65000000,6.26594400,2.53100000,0.21996722,227.34988852,0.19882399,277.35941196,0.00244746,0.20265796,279.63402079,-0.12924202,-0.07341594,0.00000000,0.00000000,0.00000000,0.00000000
254.15000000,6.31781100,2.53100000,0.22384678,227.34988852,0.20199899,278.24142849,0.00189093,0.20292666,279.93127969,-0.12941703,-0.07350963,0.00000000,0.00000000,0.00000000,0.00000000
255.65000000,6.37011600,2.53100000,0.22631011,227.34988852,0.20400975,278.80146705,0.00103553,0.20319741,280.00738043,-0.12959928,-0.07359812,0.00000000,0.00000000,0.00000000,0.00000000
257.15000000,6.42299000,2.53000000,0.22758022,227.26006240,0.20504493,278.97995791,0.00048720,0.20340617,280.17703437,-0.12977542,-0.07363075,0.00000000,0.00000000,0.00000000,0.00000000
258.65000000,6.47650400,2.53000000,0.22832800,227.26006240,0.20565390,279.14989793,0.00036512,0.20358503,280.33833172,-0.12987347,-0.07371156,0.00000000,0.00000000,0.00000000,0.00000000
260.15000000,6.53008500,2.52900000,0.22892600,227.17023629,0.20614062,279.17540981,0.00030399,0.20379260,280.61876918,-0.13005025,-0.07374235,0.00000000,0.00000000,0.00000000,0.00000000
261.65000000,6.58433600,2.53100000,0.22937422,227.34988852,0.20650528,279.49809237,0.00024296,0.20394145,280.77173147,-0.13012843,-0.07381303,0.00000000,0.00000000,0.00000000,0.00000000
263.15000000,6.63758100,2.53300000,0.22971011,227.52954074,0.20677846,279.79537682,0.00012144,0.20411581,281.26505599,-0.13022662,-0.07388919,0.00000000,0.00000000,0.00000000,0.00000000
264.65000000,6.69059100,2.53400000,0.23008222,227.61936685,0.20708101,279.99053660,0.00018139,0.20429076,281.75871886,-0.13032217,-0.07396860,0.00000000,0.00000000,0.00000000,0.00000000
266.15000000,6.73812900,2.53400000,0.23034189,227.61936685,0.20729209,280.04964176,0.00018135,0.00000000,0.00000000,0.00000000,0.00000000,0.00000000,0.00000000,0.00000000,0.00000000
267.65000000,6.76985700,2.53600000,0.23060189,227.79901907,0.20750339,280.32990316,0.00018131,0.00000000,0.00000000,0.00000000,0.00000000,0.00000000,0.00000000,0.00000000,0.00000000
269.15000000,6.78939600,2.53700000,0.23078756,227.88884518,0.20765425,280.48275470,0.00012061,0.00000000,0.00000000,0.00000000,0.00000000,0.00000000,0.00000000,0.00000000,0.00000000
270.65000000,6.80470300,2.53900000,0.23097344,228.06849741,0.20780527,280.74626382,0.00006048,0.00000000,0.00000000,0.00000000,0.00000000,0.00000000,0.00000000,0.00000000,0.00000000
272.15000000,6.81906700,2.54200000,0.23123389,228.33797574,0.20801683,281.13745385,0.00012075,0.00000000,0.00000000,0.00000000,0.00000000,0.00000000,0.00000000,0.00000000,0.00000000
273.65000000,6.83407300,2.54500000,0.23145767,228.60745408,0.20819856,281.52040198,0.00012127,0.00000000,0.00000000,0.00000000,0.00000000,0.00000000,0.00000000,0.00000000,0.00000000
275.15000000,6.85230300,2.54900000,0.23171911,228.96675852,0.20841084,282.02273228,0.00018205,0.00000000,0.00000000,0.00000000,0.00000000,0.00000000,0.00000000,0.00000000,0.00000000
276.65000000,6.87241100,2.54000000,0.23186811,228.15832352,0.00000000,0.00000000,0.00000000,0.00000000,0.00000000,0.00000000,0.00000000,0.00000000,0.00000000,0.00000000,0.00000000
278.15000000,6.89272000,2.53600000,0.23201656,227.79901907,0.00000000,0.00000000,0.00000000,0.00000000,0.00000000,0.00000000,0.00000000,0.00000000,0.00000000,0.00000000,0.00000000
279.65000000,6.91259900,2.53200000,0.23220378,227.43971463,0.00000000,0.00000000,0.00000000,0.00000000,0.00000000,0.00000000,0.00000000,0.00000000,0.00000000,0.00000000,0.00000000
281.15000000,6.94114100,2.53300000,0.23231656,227.52954074,0.00000000,0.00000000,0.00000000,0.00000000,0.00000000,0.00000000,0.00000000,0.00000000,0.00000000,0.00000000,0.00000000
282.65000000,6.97793700,2.53300000,0.23242844,227.52954074,0.00000000,0.00000000,0.00000000,0.00000000,0.00000000,0.00000000,0.00000000,0.00000000,0.00000000,0.00000000,0.00000000
284.15000000,7.01792000,2.53400000,0.23254011,227.61936685,0.00000000,0.00000000,0.00000000,0.00000000,0.00000000,0.00000000,0.00000000,0.00000000,0.00000000,0.00000000,0.00000000
285.65000000,7.06142800,2.53400000,0.23265178,227.61936685,0.00000000,0.00000000,0.00000000,0.00000000,0.00000000,0.00000000,0.00000000,0.00000000,0.00000000,0.00000000,0.00000000
287.15000000,7.10785700,2.53500000,0.23272622,227.70919296,0.00000000,0.00000000,0.00000000,0.00000000,0.00000000,0.00000000,0.00000000,0.00000000,0.00000000,0.00000000,0.00000000
288.65000000,7.15593100,2.53600000,0.23287533,227.79901907,0.00000000,0.00000000,0.00000000,0.00000000,0.00000000,0.00000000,0.00000000,0.00000000,0.00000000,0.00000000,0.00000000
290.15000000,7.20524800,2.53600000,0.23294978,227.79901907,0.00000000,0.00000000,0.00000000,0.00000000,0.00000000,0.00000000,0.00000000,0.00000000,0.00000000,0.00000000,0.00000000
291.65000000,7.25473300,2.53600000,0.23302422,227.79901907,0.00000000,0.00000000,0.00000000,0.00000000,0.00000000,0.00000000,0.00000000,0.00000000,0.00000000,0.00000000,0.00000000
293.15000000,7.30102800,2.53500000,0.23309856,227.70919296,0.00000000,0.00000000,0.00000000,0.00000000,0.00000000,0.00000000,0.00000000,0.00000000,0.00000000,0.00000000,0.00000000
294.65000000,7.34148100,2.53300000,0.23321022,227.52954074,0.00000000,0.00000000,0.00000000,0.00000000,0.00000000,0.00000000,0.00000000,0.00000000,0.00000000,0.00000000,0.00000000
296.15000000,7.37612800,2.53000000,0.23324778,227.26006240,0.00000000,0.00000000,0.00000000,0.00000000,0.00000000,0.00000000,0.00000000,0.00000000,0.00000000,0.00000000,0.00000000
297.65000000,7.40721800,2.52900000,0.23332278,227.17023629,0.00000000,0.00000000,0.00000000,0.00000000,0.00000000,0.00000000,0.00000000,0.00000000,0.00000000,0.00000000,0.00000000
299.15000000,7.43790500,2.52600000,0.23339733,226.90075796,0.00000000,0.00000000,0.00000000,0.00000000,0.00000000,0.00000000,0.00000000,0.00000000,0.00000000,0.00000000,0.00000000
300.65000000,7.46926300,2.52400000,0.23347167,226.72110573,0.00000000,0.00000000,0.00000000,0.00000000,0.00000000,0.00000000,0.00000000,0.00000000,0.00000000,0.00000000,0.00000000
302.15000000,7.50092100,2.52000000,0.23347167,226.36180129,0.00000000,0.00000000,0.00000000,0.00000000,0.00000000,0.00000000,0.00000000,0.00000000,0.00000000,0.00000000,0.00000000
303.65000000,7.53217700,2.51500000,0.23350911,225.91267073,0.00000000,0.00000000,0.00000000,0.00000000,0.00000000,0.00000000,0.00000000,0.00000000,0.00000000,0.00000000,0.00000000
305.15000000,7.56242700,2.51000000,0.23354656,225.46354017,0.00000000,0.00000000,0.00000000,0.00000000,0.00000000,0.00000000,0.00000000,0.00000000,0.00000000,0.00000000,0.00000000
306.65000000,7.58921800,2.50200000,0.23358411,224.74493128,0.00000000,0.00000000,0.00000000,0.00000000,0.00000000,0.00000000,0.00000000,0.00000000,0.00000000,0.00000000,0.00000000
308.15000000,7.61419600,2.49300000,0.23358433,223.93649627,0.00000000,0.00000000,0.00000000,0.00000000,0.00000000,0.00000000,0.00000000,0.00000000,0.00000000,0.00000000,0.00000000
309.65000000,7.63894100,2.48100000,0.23354756,222.85858293,0.00000000,0.00000000,0.00000000,0.00000000,0.00000000,0.00000000,0.00000000,0.00000000,0.00000000,0.00000000,0.00000000
311.15000000,7.66214400,2.46100000,0.23354856,221.06206070,0.00000000,0.00000000,0.00000000,0.00000000,0.00000000,0.00000000,0.00000000,0.00000000,0.00000000,0.00000000,0.00000000
312.65000000,7.68303100,2.43400000,0.23351278,218.63675569,0.00000000,0.00000000,0.00000000,0.00000000,0.00000000,0.00000000,0.00000000,0.00000000,0.00000000,0.00000000,0.00000000
314.15000000,7.69658100,2.39400000,0.23340289,215.04371122,0.00000000,0.00000000,0.00000000,0.00000000,0.00000000,0.00000000,0.00000000,0.00000000,0.00000000,0.00000000,0.00000000
315.65000000,7.70445400,2.32700000,0.23329367,209.02536174,0.00000000,0.00000000,0.00000000,0.00000000,0.00000000,0.00000000,0.00000000,0.00000000,0.00000000,0.00000000,0.00000000
317.15000000,7.67555800,2.23100000,0.23303600,200.40205503,0.00000000,0.00000000,0.00000000,0.00000000,0.00000000,0.00000000,0.00000000,0.00000000,0.00000000,0.00000000,0.00000000
318.65000000,8.11890000,0.01700000,0.25463111,1.52704390,0.00000000,0.00000000,0.00000000,0.00000000,0.00000000,0.00000000,0.00000000,0.00000000,0.00000000,0.00000000,0.00000000
NaN,-100.00000000,NaN,-11.11111111,NaN,0.00000000,0.00000000,0.00000000,0.00000000,0.00000000,0.00000000,0.00000000,0.00000000,0.00000000,0.00000000,0.00000000