File: lab_data/AA6014-T4_results/DATA/UT_90_3.csv
Time[s],Displacement[mm],Force[kN],EngStrain_longi,EngStress[MPa],TrueStrain,TrueStress[MPa],TrueStrainRate[1/s],PlasticStrain_longi,PlasticStress[MPa],PlasticStrain_thick,PlasticStrain_width,R-Value,Thickness[mm],Width[mm], Young's Modulus [MPa]
0.61000000,0.00000000,-0.00200000,0.00000000,-0.17856166,0.00000000,-0.17856166,0.00000000,0.00092946,115.64631042,-0.00008602,-0.00084344,0.81962941,1.11670000,10.03010000,77833.48155640
2.12000000,0.00595800,0.16300000,0.00014600,14.55277535,0.00014599,14.55490006,0.00011981,0.00218719,118.48525725,-0.00080058,-0.00138661,0.00000000,0.00000000,0.00000000,0.00000000
3.61000000,0.01329800,0.39300000,0.00040478,35.08736634,0.00040470,35.10156893,0.00013484,0.00344410,121.60098208,-0.00154336,-0.00190074,0.00000000,0.00000000,0.00000000,0.00000000
5.11000000,0.02189900,0.62900000,0.00072700,56.15764231,0.00072674,56.19846892,0.00028848,0.00459826,124.71179400,-0.00215612,-0.00244214,0.00000000,0.00000000,0.00000000,0.00000000
6.61000000,0.03050000,0.89000000,0.00098967,79.45993904,0.00098918,79.53857790,0.00035568,0.00576680,127.38114001,-0.00279317,-0.00297363,0.00000000,0.00000000,0.00000000,0.00000000
8.12000000,0.04121000,1.12000000,0.00128056,99.99453003,0.00127974,100.12257858,0.00030160,0.00695261,129.87854182,-0.00342999,-0.00352262,0.00000000,0.00000000,0.00000000,0.00000000
9.61000000,0.06488200,1.27800000,0.00200356,114.10090123,0.00200155,114.32950873,0.00053633,0.00817483,132.38669738,-0.00411022,-0.00406462,0.00000000,0.00000000,0.00000000,0.00000000
11.11000000,0.10522900,1.31100000,0.00343033,117.04716863,0.00342446,117.44867944,0.00077106,0.00930035,134.70698375,-0.00472215,-0.00457819,0.00000000,0.00000000,0.00000000,0.00000000
12.61000000,0.14158800,1.34600000,0.00468933,120.17199770,0.00467837,120.73552425,0.00093295,0.01046182,136.85628117,-0.00533937,-0.00512246,0.00000000,0.00000000,0.00000000,0.00000000
14.11000000,0.17871800,1.37700000,0.00588300,122.93970344,0.00586576,123.66295772,0.00085162,0.01164038,139.19426340,-0.00602947,-0.00561091,0.00000000,0.00000000,0.00000000,0.00000000
15.62000000,0.21632600,1.40800000,0.00713856,125.70740918,0.00711320,126.60477851,0.00074731,0.01278080,141.25994413,-0.00666750,-0.00611330,0.00000000,0.00000000,0.00000000,0.00000000
17.11000000,0.25233500,1.43400000,0.00844344,128.02871077,0.00840800,129.10971408,0.00091625,0.01387941,143.32427367,-0.00726446,-0.00661495,0.00000000,0.00000000,0.00000000,0.00000000
18.61000000,0.29064400,1.45900000,0.00970200,130.26073153,0.00965524,131.52452115,0.00103093,0.01501215,145.48906654,-0.00790135,-0.00711080,0.00000000,0.00000000,0.00000000,0.00000000
20.11000000,0.32661700,1.48500000,0.01087556,132.58203312,0.01081684,134.02393639,0.00080540,0.01619108,147.39220108,-0.00857176,-0.00761932,0.00000000,0.00000000,0.00000000,0.00000000
21.61000000,0.36280800,1.50700000,0.01211956,134.54621139,0.01204670,136.17685167,0.00085603,0.01731369,149.29129964,-0.00920854,-0.00810515,0.00000000,0.00000000,0.00000000,0.00000000
23.11000000,0.39878700,1.52900000,0.01333189,136.51038966,0.01324380,138.33033101,0.00089845,0.01840336,151.37224403,-0.00979941,-0.00860395,0.00000000,0.00000000,0.00000000,0.00000000
24.61000000,0.43441000,1.55200000,0.01449944,138.56384876,0.01439533,140.57294758,0.00088996,0.01953550,153.18989301,-0.01044608,-0.00908942,0.00000000,0.00000000,0.00000000,0.00000000
26.11000000,0.47045700,1.57300000,0.01566700,140.43874620,0.01554554,142.63900003,0.00071996,0.02064804,155.00851432,-0.01106157,-0.00958647,0.00000000,0.00000000,0.00000000,0.00000000
27.61000000,0.50549900,1.59400000,0.01689056,142.31364363,0.01674950,144.71740014,0.00076326,0.02176531,156.92348027,-0.01163952,-0.01012579,0.00000000,0.00000000,0.00000000,0.00000000
29.11000000,0.54134400,1.61500000,0.01803944,144.18854107,0.01787866,146.78962225,0.00076960,0.02288012,158.65873200,-0.01227400,-0.01060611,0.00000000,0.00000000,0.00000000,0.00000000
30.61000000,0.57614200,1.63500000,0.01919211,145.97415768,0.01901027,148.77570993,0.00073950,0.02397187,160.39403852,-0.01284697,-0.01112490,0.00000000,0.00000000,0.00000000,0.00000000
32.11000000,0.61134500,1.65300000,0.02038200,147.58121263,0.02017707,150.58921290,0.00070923,0.02508272,162.22810267,-0.01346913,-0.01161359,0.00000000,0.00000000,0.00000000,0.00000000
33.61000000,0.64652900,1.67300000,0.02154589,149.36682923,0.02131706,152.58507034,0.00075956,0.02616228,163.87685042,-0.01403615,-0.01212612,0.00000000,0.00000000,0.00000000,0.00000000
35.11000000,0.68067500,1.69200000,0.02272467,151.06316501,0.02247031,154.49602508,0.00080998,0.02726586,165.53303419,-0.01465952,-0.01260635,0.00000000,0.00000000,0.00000000,0.00000000
36.61000000,0.71640600,1.70900000,0.02386233,152.58093913,0.02358208,156.22187636,0.00070682,0.02834512,167.28095774,-0.01525040,-0.01309472,0.00000000,0.00000000,0.00000000,0.00000000
38.11000000,0.75060500,1.72800000,0.02501122,154.27727491,0.02470356,158.13593811,0.00069149,0.02944740,168.85167392,-0.01589097,-0.01355643,0.00000000,0.00000000,0.00000000,0.00000000
39.61000000,0.78552100,1.74500000,0.02619000,155.79504902,0.02585291,159.87532136,0.00074161,0.03055556,170.42672497,-0.01649741,-0.01405815,0.00000000,0.00000000,0.00000000,0.00000000
41.11000000,0.82053600,1.76100000,0.02735389,157.22354231,0.02698646,161.52421762,0.00076262,0.03165756,172.09666978,-0.01715124,-0.01450633,0.00000000,0.00000000,0.00000000,0.00000000
42.61000000,0.85508200,1.78000000,0.02852144,158.91987809,0.02812228,163.45250256,0.00076176,0.03274641,173.58246608,-0.01775372,-0.01499270,0.00000000,0.00000000,0.00000000,0.00000000
44.11000000,0.88966200,1.79500000,0.02966656,160.25909054,0.02923502,165.01342575,0.00074623,0.03382683,175.06987760,-0.01837824,-0.01544859,0.00000000,0.00000000,0.00000000,0.00000000
45.61000000,0.92397200,1.81200000,0.03082667,161.77686466,0.03036107,166.76390614,0.00081073,0.03492978,176.65726838,-0.01898567,-0.01594412,0.00000000,0.00000000,0.00000000,0.00000000
47.11000000,0.95804800,1.82700000,0.03195700,163.11607711,0.03145700,168.32877759,0.00075922,0.03599338,178.14796911,-0.01957813,-0.01641525,0.00000000,0.00000000,0.00000000,0.00000000
48.61000000,0.99266100,1.84200000,0.03310967,164.45528957,0.03257335,169.90034939,0.00075127,0.03709286,179.55504309,-0.02017669,-0.01691618,0.00000000,0.00000000,0.00000000,0.00000000
50.11000000,1.02700500,1.85700000,0.03426978,165.79450203,0.03369565,171.47624277,0.00075043,0.03818964,181.05779271,-0.02074987,-0.01743978,0.00000000,0.00000000,0.00000000,0.00000000
51.61000000,1.06192000,1.87200000,0.03542233,167.13371448,0.03480940,173.05398063,0.00072061,0.03929718,182.47231828,-0.02135779,-0.01793939,0.00000000,0.00000000,0.00000000,0.00000000
53.11000000,1.09616400,1.88700000,0.03656011,168.47292694,0.03590765,174.63231586,0.00072711,0.04036915,183.78981493,-0.02193636,-0.01843279,0.00000000,0.00000000,0.00000000,0.00000000
54.61000000,1.13077700,1.90200000,0.03772022,169.81213939,0.03702621,176.21749103,0.00076229,0.04142656,185.29436229,-0.02250178,-0.01892479,0.00000000,0.00000000,0.00000000,0.00000000
56.11000000,1.16542300,1.91600000,0.03889900,171.06207102,0.03816150,177.71621452,0.00077576,0.04253640,186.53081439,-0.02312187,-0.01941453,0.00000000,0.00000000,0.00000000,0.00000000
57.61000000,1.19973400,1.92900000,0.04000311,172.22272181,0.03922370,179.11216649,0.00065288,0.04362823,187.95395115,-0.02372843,-0.01989980,0.00000000,0.00000000,0.00000000,0.00000000
59.11000000,1.23438000,1.94200000,0.04118933,173.38337261,0.04036365,180.52491814,0.00073818,0.04471651,189.28549433,-0.02432578,-0.02039073,0.00000000,0.00000000,0.00000000,0.00000000
60.61000000,1.26899300,1.95600000,0.04234944,174.63330423,0.04147725,182.02892765,0.00077319,0.04576231,190.51767921,-0.02490322,-0.02085909,0.00000000,0.00000000,0.00000000,0.00000000
62.11000000,1.30337100,1.96900000,0.04349089,175.79395503,0.04257172,183.43939039,0.00074380,0.04687291,191.85880982,-0.02553006,-0.02134285,0.00000000,0.00000000,0.00000000,0.00000000
63.61000000,1.33758100,1.98100000,0.04463611,176.86532499,0.04366861,184.75990529,0.00067871,0.04796224,193.10443786,-0.02613450,-0.02182775,0.00000000,0.00000000,0.00000000,0.00000000
65.11000000,1.37209400,1.99400000,0.04581489,178.02597579,0.04479638,186.18221609,0.00076361,0.04905748,194.35374610,-0.02677747,-0.02228000,0.00000000,0.00000000,0.00000000,0.00000000
66.61000000,1.40633700,2.00600000,0.04696000,179.09734575,0.04589073,187.50775711,0.00075556,0.05011612,195.59842875,-0.02733563,-0.02278050,0.00000000,0.00000000,0.00000000,0.00000000
68.11000000,1.44108400,2.01800000,0.04810144,180.16871572,0.04698038,188.83509119,0.00074031,0.05120529,196.85159716,-0.02794309,-0.02326220,0.00000000,0.00000000,0.00000000,0.00000000
69.61000000,1.47606700,2.03000000,0.04926156,181.24008568,0.04808664,190.16825423,0.00068970,0.05229096,198.01201419,-0.02854684,-0.02374412,0.00000000,0.00000000,0.00000000,0.00000000
71.11000000,1.51067900,2.04100000,0.05045900,182.22217482,0.04922721,191.41692354,0.00080277,0.05337194,199.17381888,-0.02914031,-0.02423163,0.00000000,0.00000000,0.00000000,0.00000000
72.61000000,1.54532600,2.05200000,0.05160044,183.20426395,0.05031324,192.65768539,0.00075920,0.05448540,200.43928385,-0.02975146,-0.02473394,0.00000000,0.00000000,0.00000000,0.00000000
74.11000000,1.58047500,2.06400000,0.05274933,184.27563391,0.05140515,193.99605075,0.00072289,0.05557443,201.60750248,-0.03035206,-0.02522237,0.00000000,0.00000000,0.00000000,0.00000000
75.61000000,1.61508800,2.07400000,0.05393178,185.16844222,0.05252772,195.15490550,0.00070795,0.05669507,202.68946484,-0.03097256,-0.02572251,0.00000000,0.00000000,0.00000000,0.00000000
77.11000000,1.64963400,2.08500000,0.05508444,186.15053135,0.05362081,196.40452996,0.00076386,0.05776749,203.85891400,-0.03154534,-0.02622215,0.00000000,0.00000000,0.00000000,0.00000000
78.61000000,1.68431400,2.09600000,0.05621100,187.13262049,0.05468798,197.65153222,0.00070642,0.05883659,204.93475601,-0.03213638,-0.02670021,0.00000000,0.00000000,0.00000000,0.00000000
80.11000000,1.71932900,2.10600000,0.05740833,188.02542879,0.05582095,198.81965528,0.00074094,0.05993935,206.01965186,-0.03275620,-0.02718315,0.00000000,0.00000000,0.00000000,0.00000000
81.61000000,1.75447900,2.11600000,0.05860578,188.91823709,0.05695274,199.98993732,0.00077538,0.06103034,207.10427973,-0.03336150,-0.02766884,0.00000000,0.00000000,0.00000000,0.00000000
83.12000000,1.78966200,2.12600000,0.05976956,189.81104540,0.05805148,201.15596722,0.00075935,0.06212372,208.19156042,-0.03396312,-0.02816060,0.00000000,0.00000000,0.00000000,0.00000000
84.61000000,1.82504700,2.13600000,0.06094456,190.70385370,0.05915960,202.32621531,0.00075251,0.06319623,209.18095932,-0.03455817,-0.02863806,0.00000000,0.00000000,0.00000000,0.00000000
86.11000000,1.86006200,2.14500000,0.06210844,191.50738118,0.06025603,203.40160672,0.00070962,0.06431478,210.27774962,-0.03518623,-0.02912854,0.00000000,0.00000000,0.00000000,0.00000000
87.61000000,1.89521200,2.15500000,0.06329833,192.40018948,0.06137571,204.57880081,0.00076485,0.06544391,211.28312201,-0.03582834,-0.02961557,0.00000000,0.00000000,0.00000000,0.00000000
89.11000000,1.93042800,2.16400000,0.06447333,193.20371695,0.06248015,205.66020460,0.00072203,0.06653213,212.37781000,-0.03641492,-0.03011721,0.00000000,0.00000000,0.00000000,0.00000000
90.61000000,1.96567800,2.17300000,0.06564089,194.00724443,0.06357639,206.74205240,0.00075629,0.06763790,213.38231745,-0.03700312,-0.03063478,0.00000000,0.00000000,0.00000000,0.00000000
92.11000000,2.00133200,2.18300000,0.06681967,194.90005273,0.06468195,207.92320929,0.00073461,0.06873188,214.38627934,-0.03760806,-0.03112382,0.00000000,0.00000000,0.00000000,0.00000000
93.61000000,2.03644800,2.19100000,0.06799833,195.61429937,0.06578618,208.91574571,0.00070549,0.06982946,215.29666867,-0.03822475,-0.03160471,0.00000000,0.00000000,0.00000000,0.00000000
95.11000000,2.07190000,2.19900000,0.06917333,196.32854602,0.06688576,209.90924597,0.00070472,0.07094511,216.30917177,-0.03886252,-0.03208259,0.00000000,0.00000000,0.00000000,0.00000000
96.61000000,2.10799000,2.20800000,0.07041178,197.13207349,0.06804341,211.01249324,0.00075977,0.07204016,217.22266563,-0.03947198,-0.03256818,0.00000000,0.00000000,0.00000000,0.00000000
98.11000000,2.14364300,2.21600000,0.07158311,197.84632013,0.06913710,212.00877525,0.00069629,0.07314095,218.13917871,-0.04006465,-0.03307630,0.00000000,0.00000000,0.00000000,0.00000000
99.61000000,2.17990100,2.22400000,0.07277678,198.56056678,0.07025041,213.01116502,0.00070256,0.07426998,219.16043578,-0.04070510,-0.03356488,0.00000000,0.00000000,0.00000000,0.00000000
101.11000000,2.21548700,2.23200000,0.07398911,199.27481342,0.07137986,214.01897973,0.00072267,0.07538879,220.08462409,-0.04131682,-0.03407198,0.00000000,0.00000000,0.00000000,0.00000000
102.61000000,2.25134200,2.24000000,0.07519022,199.98906006,0.07249760,215.02628193,0.00075639,0.07645813,220.99966073,-0.04189763,-0.03456050,0.00000000,0.00000000,0.00000000,0.00000000
104.11000000,2.28776800,2.24700000,0.07638756,200.61402588,0.07361058,215.93844092,0.00069318,0.07757440,221.92687505,-0.04250203,-0.03507237,0.00000000,0.00000000,0.00000000,0.00000000
105.61000000,2.32365600,2.25500000,0.07759622,201.32827252,0.07473284,216.95058589,0.00074088,0.07867360,222.75489352,-0.04311745,-0.03555615,0.00000000,0.00000000,0.00000000,0.00000000
107.11000000,2.36008200,2.26200000,0.07883089,201.95323833,0.07587794,217.87339162,0.00083008,0.07981462,223.69117635,-0.04374659,-0.03606803,0.00000000,0.00000000,0.00000000,0.00000000
108.61000000,2.39566800,2.26900000,0.08002089,202.57820414,0.07698038,218.78869211,0.00078080,0.08090644,224.61824153,-0.04435206,-0.03655438,0.00000000,0.00000000,0.00000000,0.00000000
110.11000000,2.43175800,2.27700000,0.08122200,203.29245079,0.07809188,219.80427022,0.00075916,0.08203937,225.45886046,-0.04497827,-0.03706110,0.00000000,0.00000000,0.00000000,0.00000000
111.61000000,2.46828400,2.28400000,0.08244544,203.91741660,0.07922278,220.72947864,0.00078582,0.08314029,226.29384880,-0.04559158,-0.03754872,0.00000000,0.00000000,0.00000000,0.00000000
113.11000000,2.50450800,2.29000000,0.08364667,204.45310158,0.08033190,221.55492202,0.00075746,0.08425011,227.13244837,-0.04619611,-0.03805400,0.00000000,0.00000000,0.00000000,0.00000000
114.61000000,2.54113600,2.29700000,0.08489256,205.07806739,0.08148095,222.48766862,0.00077729,0.08535876,227.97238189,-0.04679193,-0.03856682,0.00000000,0.00000000,0.00000000,0.00000000
116.11000000,2.57719200,2.30400000,0.08607122,205.70303321,0.08256680,223.40814469,0.00066632,0.08645256,228.81051176,-0.04740005,-0.03905251,0.00000000,0.00000000,0.00000000,0.00000000
117.61000000,2.61405500,2.31000000,0.08729100,206.23871819,0.08368928,224.24150214,0.00069297,0.08759933,229.66242658,-0.04800785,-0.03959148,0.00000000,0.00000000,0.00000000,0.00000000
119.11000000,2.65061500,2.31700000,0.08852944,206.86368400,0.08482765,225.17721102,0.00076080,0.08872926,230.41391685,-0.04864110,-0.04008815,0.00000000,0.00000000,0.00000000,0.00000000
120.61000000,2.68710700,2.32300000,0.08974556,207.39936898,0.08594423,226.01254058,0.00076689,0.08983943,231.26055975,-0.04925840,-0.04058103,0.00000000,0.00000000,0.00000000,0.00000000
122.11000000,2.72353300,2.32900000,0.09096156,207.93505397,0.08705947,226.84914993,0.00071122,0.09098368,232.01832608,-0.04989079,-0.04109289,0.00000000,0.00000000,0.00000000,0.00000000
123.61000000,2.76019400,2.33500000,0.09220000,208.47073895,0.08819401,227.69174108,0.00073097,0.09207583,232.76537544,-0.05049605,-0.04157978,0.00000000,0.00000000,0.00000000,0.00000000
125.11000000,2.79715600,2.34100000,0.09342356,209.00642393,0.08931365,228.53254719,0.00077793,0.09321734,233.52535798,-0.05114701,-0.04207033,0.00000000,0.00000000,0.00000000,0.00000000
126.61000000,2.83438800,2.34600000,0.09464700,209.45282808,0.09043194,229.27690990,0.00068832,0.09432248,234.37699987,-0.05172161,-0.04260087,0.00000000,0.00000000,0.00000000,0.00000000
128.11000000,2.87138400,2.35200000,0.09589289,209.98851307,0.09156945,230.12491822,0.00071492,0.09543243,235.03364883,-0.05232411,-0.04310832,0.00000000,0.00000000,0.00000000,0.00000000
129.61000000,2.90854900,2.35800000,0.09715744,210.52419805,0.09272269,230.97819112,0.00080933,0.09658022,235.79941493,-0.05293809,-0.04364213,0.00000000,0.00000000,0.00000000,0.00000000
131.11000000,2.94551200,2.36300000,0.09838478,210.97060220,0.09384072,231.72689802,0.00074730,0.09771314,236.56311601,-0.05358410,-0.04412905,0.00000000,0.00000000,0.00000000,0.00000000
132.61000000,2.98244100,2.36900000,0.09963433,211.50628718,0.09497770,232.57957510,0.00077354,0.09881114,237.31994653,-0.05416130,-0.04464985,0.00000000,0.00000000,0.00000000,0.00000000
134.11000000,3.01990700,2.37400000,0.10091011,211.95269133,0.09613721,233.34086097,0.00083363,0.09996962,237.99328399,-0.05479517,-0.04517445,0.00000000,0.00000000,0.00000000,0.00000000
135.61000000,3.05693700,2.37900000,0.10212989,212.39909549,0.09724457,234.09139151,0.00075827,0.10111535,238.76427059,-0.05544046,-0.04567489,0.00000000,0.00000000,0.00000000,0.00000000
137.11000000,3.09487400,2.38400000,0.10338700,212.84549964,0.09838454,234.85095731,0.00075741,0.10225634,239.53558867,-0.05607283,-0.04618351,0.00000000,0.00000000,0.00000000,0.00000000
138.61000000,3.13237400,2.38900000,0.10464033,213.29190379,0.09951979,235.61083970,0.00070241,0.10336066,240.19985602,-0.05665099,-0.04670967,0.00000000,0.00000000,0.00000000,0.00000000
140.11000000,3.16940400,2.39300000,0.10592356,213.64902711,0.10068078,236.27949170,0.00087729,0.10450380,240.87469059,-0.05726890,-0.04723490,0.00000000,0.00000000,0.00000000,0.00000000
141.61000000,3.20767600,2.39800000,0.10714333,214.09543126,0.10178312,237.03432942,0.00071533,0.10567220,241.55689143,-0.05793960,-0.04773260,0.00000000,0.00000000,0.00000000,0.00000000
143.11000000,3.24568000,2.40300000,0.10844889,214.54183542,0.10296164,237.80865909,0.00074733,0.10684922,242.24246476,-0.05861354,-0.04823568,0.00000000,0.00000000,0.00000000,0.00000000
144.61000000,3.28365000,2.40700000,0.10971344,214.89895874,0.10410182,238.47626371,0.00073286,0.10798164,242.91845647,-0.05921724,-0.04876440,0.00000000,0.00000000,0.00000000,0.00000000
146.11000000,3.32158600,2.41200000,0.11097800,215.34536289,0.10524071,239.24396057,0.00071862,0.10911264,243.59533522,-0.05981281,-0.04929982,0.00000000,0.00000000,0.00000000,0.00000000
147.61000000,3.36006000,2.41600000,0.11223878,215.70248621,0.10637490,239.91266963,0.00070441,0.11027563,244.28128889,-0.06048105,-0.04979458,0.00000000,0.00000000,0.00000000,0.00000000
149.11000000,3.39819800,2.42000000,0.11354811,216.05960953,0.10755141,240.59277008,0.00076387,0.11139735,244.95837756,-0.06107405,-0.05032331,0.00000000,0.00000000,0.00000000,0.00000000
150.61000000,3.43650300,2.42500000,0.11482756,216.50601368,0.10869973,241.36687000,0.00080986,0.11255427,245.64536462,-0.06174507,-0.05080921,0.00000000,0.00000000,0.00000000,0.00000000
152.11000000,3.47511100,2.42900000,0.11611078,216.86313701,0.10985012,242.04328451,0.00074877,0.11371448,246.23370958,-0.06237149,-0.05134299,0.00000000,0.00000000,0.00000000,0.00000000
153.61000000,3.51237600,2.43300000,0.11734544,217.22026033,0.11095573,242.71006832,0.00070775,0.11481907,246.91016710,-0.06296538,-0.05185369,0.00000000,0.00000000,0.00000000,0.00000000
155.11000000,3.55178900,2.43700000,0.11868833,217.57738365,0.11215687,243.40128068,0.00082037,0.11600303,247.50658454,-0.06361467,-0.05238835,0.00000000,0.00000000,0.00000000,0.00000000
156.61000000,3.59093400,2.44100000,0.11998644,217.93450697,0.11331658,244.08369358,0.00077953,0.11713943,248.09223774,-0.06424093,-0.05289849,0.00000000,0.00000000,0.00000000,0.00000000
158.11000000,3.62944200,2.44500000,0.12128833,218.29163029,0.11447832,244.76785831,0.00081193,0.11830926,248.78845571,-0.06488386,-0.05342540,0.00000000,0.00000000,0.00000000,0.00000000
159.61000000,3.66805000,2.44800000,0.12260511,218.55947278,0.11565198,245.35598123,0.00075771,0.11946932,249.38220912,-0.06547646,-0.05399286,0.00000000,0.00000000,0.00000000,0.00000000
161.11000000,3.70746300,2.45200000,0.12388822,218.91659610,0.11679430,246.03778401,0.00077009,0.12068375,249.99065338,-0.06615830,-0.05452545,0.00000000,0.00000000,0.00000000,0.00000000
162.61000000,3.74630600,2.45600000,0.12520500,219.27371943,0.11796524,246.72788547,0.00081562,0.12182781,250.58252266,-0.06678798,-0.05503984,0.00000000,0.00000000,0.00000000,0.00000000
164.11000000,3.78578600,2.45900000,0.12649944,219.54156192,0.11911499,247.31344753,0.00072213,0.12299536,251.28303034,-0.06743973,-0.05555563,0.00000000,0.00000000,0.00000000,0.00000000
165.61000000,3.82422700,2.46300000,0.12778267,219.89868524,0.12025346,247.99792563,0.00074772,0.12417742,251.78490508,-0.06809774,-0.05607968,0.00000000,0.00000000,0.00000000,0.00000000
167.11000000,3.86417700,2.46500000,0.12909567,220.07724690,0.12141702,248.48826581,0.00073366,0.12536646,252.39131678,-0.06875070,-0.05661576,0.00000000,0.00000000,0.00000000,0.00000000
168.61000000,3.90385900,2.46900000,0.13046467,220.43437022,0.12262876,249.19326685,0.00085155,0.12654745,252.99677953,-0.06938848,-0.05715897,0.00000000,0.00000000,0.00000000,0.00000000
170.11000000,3.94350700,2.47200000,0.13175900,220.70221271,0.12377306,249.78171556,0.00071210,0.12769129,253.59387396,-0.06999961,-0.05769167,0.00000000,0.00000000,0.00000000,0.00000000
171.61000000,3.98376100,2.47500000,0.13314300,220.97005520,0.12499519,250.39067126,0.00080343,0.12889226,254.20659045,-0.07069373,-0.05819853,0.00000000,0.00000000,0.00000000,0.00000000
173.11000000,4.02310700,2.47800000,0.13442989,221.23789769,0.12613022,250.97888370,0.00077626,0.13006405,254.71054284,-0.07133170,-0.05873235,0.00000000,0.00000000,0.00000000,0.00000000
174.61000000,4.06268800,2.48100000,0.13579144,221.50574019,0.12732972,251.58432460,0.00078845,0.13122314,255.31461527,-0.07195409,-0.05926905,0.00000000,0.00000000,0.00000000,0.00000000
176.11000000,4.10304200,2.48400000,0.13716411,221.77358268,0.12853754,252.19295901,0.00078085,0.13239862,255.82131001,-0.07259330,-0.05980532,0.00000000,0.00000000,0.00000000,0.00000000
177.61000000,4.14232000,2.48700000,0.13846222,222.04142517,0.12967842,252.78577432,0.00074071,0.13354858,256.42505945,-0.07318896,-0.06035963,0.00000000,0.00000000,0.00000000,0.00000000
179.11000000,4.18408400,2.49000000,0.13984989,222.30926766,0.13089658,253.39919404,0.00077901,0.13472447,256.93365796,-0.07384821,-0.06087626,0.00000000,0.00000000,0.00000000,0.00000000
180.61000000,4.22480700,2.49200000,0.14123378,222.48782932,0.13210994,253.91062596,0.00085657,0.13591195,257.44610010,-0.07452200,-0.06138995,0.00000000,0.00000000,0.00000000,0.00000000
182.11000000,4.26438800,2.49500000,0.14250944,222.75567181,0.13322711,254.50045885,0.00073789,0.13709319,258.06093320,-0.07515993,-0.06193326,0.00000000,0.00000000,0.00000000,0.00000000
183.61000000,4.30537900,2.49800000,0.14388967,223.02351430,0.13443444,255.11429343,0.00076323,0.13829069,258.57781823,-0.07582640,-0.06246429,0.00000000,0.00000000,0.00000000,0.00000000
185.11000000,4.34573300,2.50000000,0.14520267,223.20207596,0.13558162,255.61161260,0.00074935,0.13949315,259.09687041,-0.07645822,-0.06303494,0.00000000,0.00000000,0.00000000,0.00000000
186.61000000,4.38622100,2.50300000,0.14656056,223.46991845,0.13676664,256.22179385,0.00070290,0.14073919,259.62815619,-0.07713962,-0.06359957,0.00000000,0.00000000,0.00000000,0.00000000
188.11000000,4.42697700,2.50600000,0.14791089,223.73776095,0.13794367,256.83101204,0.00078670,0.14196757,260.15576074,-0.07780303,-0.06416454,0.00000000,0.00000000,0.00000000,0.00000000
189.61000000,4.46877400,2.50800000,0.14926489,223.91632261,0.13912251,257.33916762,0.00069467,0.14321858,260.79398540,-0.07846659,-0.06475199,0.00000000,0.00000000,0.00000000,0.00000000
191.11000000,4.50943000,2.51000000,0.15067489,224.09488427,0.14034863,257.86035605,0.00079757,0.14450307,261.23435026,-0.07918826,-0.06531482,0.00000000,0.00000000,0.00000000,0.00000000
192.61000000,4.55095800,2.51200000,0.15203644,224.27344593,0.14153120,258.37118323,0.00089388,0.14577796,261.77695366,-0.07985080,-0.06592716,0.00000000,0.00000000,0.00000000,0.00000000
194.11000000,4.59258800,2.51500000,0.15346144,224.54128842,0.14276737,258.99971888,0.00089278,0.14705119,262.32008858,-0.08055864,-0.06649255,0.00000000,0.00000000,0.00000000,0.00000000
195.61000000,4.63435100,2.51700000,0.15489756,224.71985008,0.14401164,259.52840554,0.00091746,0.14831964,262.86292712,-0.08126672,-0.06705292,0.00000000,0.00000000,0.00000000,0.00000000
197.11000000,4.67628200,2.51900000,0.15631122,224.89841174,0.14523496,260.05255736,0.00085828,0.14956728,263.40122410,-0.08194818,-0.06761910,0.00000000,0.00000000,0.00000000,0.00000000
198.61000000,4.71851500,2.52100000,0.15773622,225.07697340,0.14646657,260.57976489,0.00081209,0.15081656,263.94089762,-0.08261572,-0.06820084,0.00000000,0.00000000,0.00000000,0.00000000
200.11000000,4.76132000,2.52200000,0.15923944,225.16625423,0.14776414,261.02160346,0.00083674,0.15199259,264.35735672,-0.08323245,-0.06876014,0.00000000,0.00000000,0.00000000,0.00000000
201.61000000,4.80456000,2.52400000,0.16072789,225.34481589,0.14904730,261.56401242,0.00084218,0.15316565,264.87848449,-0.08388585,-0.06927980,0.00000000,0.00000000,0.00000000,0.00000000
203.11000000,4.84719600,2.52600000,0.16222733,225.52337755,0.15033828,262.10943370,0.00094381,0.15430566,265.39167076,-0.08450982,-0.06979584,0.00000000,0.00000000,0.00000000,0.00000000
204.61000000,4.89006700,2.52800000,0.16368222,225.70193921,0.15158931,262.64533418,0.00080813,0.15544582,265.80064947,-0.08515360,-0.07029222,0.00000000,0.00000000,0.00000000,0.00000000
206.11000000,4.93256900,2.53000000,0.16513700,225.88050087,0.15283868,263.18172915,0.00080693,0.15658466,266.20986796,-0.08580107,-0.07078359,0.00000000,0.00000000,0.00000000,0.00000000
207.61000000,4.97507200,2.53200000,0.16658433,226.05906254,0.15408011,263.71696076,0.00078040,0.15765742,266.70730744,-0.08639636,-0.07126106,0.00000000,0.00000000,0.00000000,0.00000000
209.11000000,5.01891700,2.53400000,0.16804656,226.23762420,0.15533274,264.25607768,0.00076667,0.15873058,267.10019156,-0.08697412,-0.07175645,0.00000000,0.00000000,0.00000000,0.00000000
210.61000000,5.06128400,2.53500000,0.16942678,226.32690503,0.15651370,264.67274327,0.00082964,0.15983406,267.50175646,-0.08761800,-0.07221606,0.00000000,0.00000000,0.00000000,0.00000000
212.11000000,5.10496100,2.53700000,0.17080689,226.50546669,0.15769316,265.19416077,0.00082847,0.16096637,268.01730731,-0.08824244,-0.07272393,0.00000000,0.00000000,0.00000000,0.00000000
213.61000000,5.14779900,2.53800000,0.17214978,226.59474752,0.15883948,265.60298295,0.00076398,0.16213027,268.43641215,-0.08891788,-0.07321239,0.00000000,0.00000000,0.00000000,0.00000000
215.11000000,5.19087200,2.54000000,0.17345533,226.77330918,0.15995267,266.10834911,0.00076294,0.16338721,268.88124203,-0.08964851,-0.07373870,0.00000000,0.00000000,0.00000000,0.00000000
216.61000000,5.23337400,2.54100000,0.17472367,226.86259001,0.16103294,266.50085356,0.00076231,0.16461112,269.31784215,-0.09025532,-0.07435580,0.00000000,0.00000000,0.00000000,0.00000000
218.11000000,5.27591000,2.54200000,0.17599189,226.95187084,0.16211195,266.89355927,0.00063446,0.16595897,269.78867487,-0.09101330,-0.07494566,0.00000000,0.00000000,0.00000000,0.00000000
219.61000000,5.31891600,2.54400000,0.17729744,227.13043250,0.16322151,267.40007774,0.00069720,0.16739891,270.28527731,-0.09180964,-0.07558927,0.00000000,0.00000000,0.00000000,0.00000000
221.11000000,5.36302900,2.54500000,0.17864033,227.21971333,0.16436151,267.81031866,0.00075959,0.16889934,270.79919854,-0.09258028,-0.07631907,0.00000000,0.00000000,0.00000000,0.00000000
222.61000000,5.40643800,2.54600000,0.18002056,227.30899416,0.16553186,268.22928557,0.00082219,0.17058476,271.36444605,-0.09343466,-0.07715010,0.00000000,0.00000000,0.00000000,0.00000000
224.11000000,5.45145800,2.54700000,0.18143800,227.39827499,0.16673234,268.65696321,0.00088424,0.17248550,271.98961799,-0.09441097,-0.07807453,0.00000000,0.00000000,0.00000000,0.00000000
225.61000000,5.49610900,2.54900000,0.18293011,227.57683665,0.16799451,269.20749267,0.00094627,0.17447576,272.64069416,-0.09537107,-0.07910469,0.00000000,0.00000000,0.00000000,0.00000000
227.11000000,5.54240400,2.55000000,0.18453411,227.66611748,0.16934954,269.67828210,0.00100806,0.17652412,273.30923568,-0.09638009,-0.08014403,0.00000000,0.00000000,0.00000000,0.00000000
228.61000000,5.58843100,2.55100000,0.18617544,227.75539831,0.17073422,270.15786082,0.00094368,0.17853709,273.96964323,-0.09747312,-0.08106397,0.00000000,0.00000000,0.00000000,0.00000000
230.11000000,5.63479400,2.55200000,0.18792856,227.84467914,0.17221108,270.66320059,0.00106788,0.18054614,274.63053443,-0.09860909,-0.08193706,0.00000000,0.00000000,0.00000000,0.00000000
231.61000000,5.68240000,2.55300000,0.18983100,227.93395997,0.17381128,271.20289153,0.00100338,0.18245863,275.26629538,-0.09976108,-0.08269755,0.00000000,0.00000000,0.00000000,0.00000000
233.11000000,5.73017200,2.55400000,0.19203189,228.02324080,0.17565932,271.81097445,0.00131471,0.18418417,275.74354308,-0.10079834,-0.08338583,0.00000000,0.00000000,0.00000000,0.00000000
234.61000000,5.77905300,2.55500000,0.19438200,228.11252163,0.17762890,272.45348981,0.00131213,0.18562860,276.25201208,-0.10164781,-0.08398079,0.00000000,0.00000000,0.00000000,0.00000000
236.11000000,5.82746400,2.55600000,0.19684400,228.20180246,0.17968809,273.12195807,0.00137185,0.18682682,276.58451453,-0.10231503,-0.08451179,0.00000000,0.00000000,0.00000000,0.00000000
237.61000000,5.87563900,2.55700000,0.19926856,228.29108329,0.18171183,273.78231771,0.00130678,0.18786877,276.98255750,-0.10289116,-0.08497761,0.00000000,0.00000000,0.00000000,0.00000000
239.11000000,5.92489000,2.55800000,0.20173044,228.38036413,0.18376256,274.45163648,0.00136627,0.18875789,277.22990405,-0.10337038,-0.08538751,0.00000000,0.00000000,0.00000000,0.00000000
240.61000000,5.97387200,2.55800000,0.20408044,228.38036413,0.18571616,274.98833034,0.00130155,0.18955428,277.45164200,-0.10383392,-0.08572036,0.00000000,0.00000000,0.00000000,0.00000000
242.11000000,6.02392900,2.55900000,0.20620667,228.46964496,0.18748045,275.58160888,0.00111363,0.19019709,277.63074976,-0.10420468,-0.08599241,0.00000000,0.00000000,0.00000000,0.00000000
243.61000000,6.07361500,2.55900000,0.20807178,228.46964496,0.18902552,276.00773015,0.00098823,0.19074623,277.89274144,-0.10451458,-0.08623165,0.00000000,0.00000000,0.00000000,0.00000000
245.11000000,6.12390600,2.55900000,0.20963856,228.46964496,0.19032160,276.36569131,0.00074030,0.19129506,278.15485301,-0.10488525,-0.08640981,0.00000000,0.00000000,0.00000000,0.00000000
246.61000000,6.17533800,2.56000000,0.21098144,228.55892579,0.19143114,276.78061809,0.00067780,0.19172290,278.27435144,-0.10508121,-0.08664169,0.00000000,0.00000000,0.00000000,0.00000000
248.11000000,6.22670300,2.56100000,0.21213778,228.64820662,0.19238556,277.15312906,0.00061554,0.19217959,278.51101637,-0.10538830,-0.08679128,0.00000000,0.00000000,0.00000000,0.00000000
249.61000000,6.27890700,2.56100000,0.21310767,228.64820662,0.19318539,277.37489242,0.00049209,0.19257505,278.73070759,-0.10559329,-0.08698176,0.00000000,0.00000000,0.00000000,0.00000000
251.11000000,6.33168200,2.56100000,0.21396556,228.64820662,0.19389232,277.57104717,0.00043023,0.19297026,278.95045997,-0.10579799,-0.08717227,0.00000000,0.00000000,0.00000000,0.00000000
252.61000000,6.38435600,2.56200000,0.21467433,228.73748745,0.19447600,277.84155507,0.00042997,0.19336378,279.27905245,-0.10605452,-0.08730926,0.00000000,0.00000000,0.00000000,0.00000000
254.11000000,6.43733300,2.56300000,0.21534578,228.82676828,0.19502863,278.10364667,0.00030702,0.19381663,279.73375398,-0.10631388,-0.08750275,0.00000000,0.00000000,0.00000000,0.00000000
255.61000000,6.48688500,2.56300000,0.21594256,228.82676828,0.19551954,278.24020540,0.00030669,0.19429977,280.19733478,-0.10660366,-0.08769612,0.00000000,0.00000000,0.00000000,0.00000000
257.11000000,6.52656600,2.56400000,0.21650211,228.91604911,0.19597962,278.47685701,0.00030655,0.00000000,0.00000000,0.00000000,0.00000000,0.00000000,0.00000000,0.00000000,0.00000000
258.61000000,6.55349100,2.56400000,0.21702444,228.91604911,0.19640890,278.59642749,0.00030660,0.00000000,0.00000000,0.00000000,0.00000000,0.00000000,0.00000000,0.00000000,0.00000000
260.11000000,6.57457500,2.56600000,0.21747200,229.09461077,0.19677658,278.91627396,0.00024515,0.00000000,0.00000000,0.00000000,0.00000000,0.00000000,0.00000000,0.00000000,0.00000000
261.61000000,6.59465000,2.56800000,0.21799422,229.27317243,0.19720543,279.25339933,0.00030617,0.00000000,0.00000000,0.00000000,0.00000000,0.00000000,0.00000000,0.00000000,0.00000000
263.11000000,6.61606900,2.57000000,0.21847922,229.45173409,0.19760354,279.58217049,0.00030623,0.00000000,0.00000000,0.00000000,0.00000000,0.00000000,0.00000000,0.00000000,0.00000000
264.61000000,6.64108100,2.57300000,0.21903867,229.71957658,0.19806257,280.03704634,0.00036717,0.00000000,0.00000000,0.00000000,0.00000000,0.00000000,0.00000000,0.00000000,0.00000000
266.11000000,6.67347800,2.57500000,0.21967278,229.89813824,0.19858261,280.40050088,0.00036698,0.00000000,0.00000000,0.00000000,0.00000000,0.00000000,0.00000000,0.00000000,0.00000000
267.61000000,6.71671900,2.57100000,0.22038156,229.54101492,0.00000000,0.00000000,0.00000000,0.00000000,0.00000000,0.00000000,0.00000000,0.00000000,0.00000000,0.00000000,0.00000000
269.11000000,6.76697600,2.56700000,0.22105300,229.18389160,0.00000000,0.00000000,0.00000000,0.00000000,0.00000000,0.00000000,0.00000000,0.00000000,0.00000000,0.00000000,0.00000000
270.61000000,6.81975100,2.56600000,0.22164978,229.09461077,0.00000000,0.00000000,0.00000000,0.00000000,0.00000000,0.00000000,0.00000000,0.00000000,0.00000000,0.00000000,0.00000000
272.11000000,6.87423800,2.56500000,0.22228400,229.00532994,0.00000000,0.00000000,0.00000000,0.00000000,0.00000000,0.00000000,0.00000000,0.00000000,0.00000000,0.00000000,0.00000000
273.61000000,6.92929600,2.56300000,0.22291811,228.82676828,0.00000000,0.00000000,0.00000000,0.00000000,0.00000000,0.00000000,0.00000000,0.00000000,0.00000000,0.00000000,0.00000000
275.11000000,6.98459000,2.56400000,0.22358956,228.91604911,0.00000000,0.00000000,0.00000000,0.00000000,0.00000000,0.00000000,0.00000000,0.00000000,0.00000000,0.00000000,0.00000000
276.61000000,7.04085600,2.56400000,0.22474589,228.91604911,0.00000000,0.00000000,0.00000000,0.00000000,0.00000000,0.00000000,0.00000000,0.00000000,0.00000000,0.00000000,0.00000000
278.11000000,7.09772700,2.56500000,0.22627533,229.00532994,0.00000000,0.00000000,0.00000000,0.00000000,0.00000000,0.00000000,0.00000000,0.00000000,0.00000000,0.00000000,0.00000000
279.61000000,7.15392700,2.56600000,0.22784200,229.09461077,0.00000000,0.00000000,0.00000000,0.00000000,0.00000000,0.00000000,0.00000000,0.00000000,0.00000000,0.00000000,0.00000000
281.11000000,7.21062900,2.56600000,0.22937133,229.09461077,0.00000000,0.00000000,0.00000000,0.00000000,0.00000000,0.00000000,0.00000000,0.00000000,0.00000000,0.00000000,0.00000000
282.61000000,7.26689600,2.56600000,0.23093811,229.09461077,0.00000000,0.00000000,0.00000000,0.00000000,0.00000000,0.00000000,0.00000000,0.00000000,0.00000000,0.00000000,0.00000000
284.11000000,7.32289400,2.56500000,0.23306433,229.00532994,0.00000000,0.00000000,0.00000000,0.00000000,0.00000000,0.00000000,0.00000000,0.00000000,0.00000000,0.00000000,0.00000000
285.61000000,7.37956300,2.56400000,0.23560089,228.91604911,0.00000000,0.00000000,0.00000000,0.00000000,0.00000000,0.00000000,0.00000000,0.00000000,0.00000000,0.00000000,0.00000000
287.11000000,7.43596400,2.56200000,0.23813744,228.73748745,0.00000000,0.00000000,0.00000000,0.00000000,0.00000000,0.00000000,0.00000000,0.00000000,0.00000000,0.00000000,0.00000000
288.61000000,7.49229700,2.56100000,0.24007711,228.64820662,0.00000000,0.00000000,0.00000000,0.00000000,0.00000000,0.00000000,0.00000000,0.00000000,0.00000000,0.00000000,0.00000000
290.11000000,7.54876500,2.56200000,0.24171856,228.73748745,0.00000000,0.00000000,0.00000000,0.00000000,0.00000000,0.00000000,0.00000000,0.00000000,0.00000000,0.00000000,0.00000000
291.61000000,7.60556900,2.56100000,0.24328567,228.64820662,0.00000000,0.00000000,0.00000000,0.00000000,0.00000000,0.00000000,0.00000000,0.00000000,0.00000000,0.00000000,0.00000000
293.11000000,7.66287600,2.55900000,0.24470344,228.46964496,0.00000000,0.00000000,0.00000000,0.00000000,0.00000000,0.00000000,0.00000000,0.00000000,0.00000000,0.00000000,0.00000000
294.61000000,7.72082200,2.55500000,0.24645633,228.11252163,0.00000000,0.00000000,0.00000000,0.00000000,0.00000000,0.00000000,0.00000000,0.00000000,0.00000000,0.00000000,0.00000000
296.11000000,7.77856600,2.55400000,0.24858211,228.02324080,0.00000000,0.00000000,0.00000000,0.00000000,0.00000000,0.00000000,0.00000000,0.00000000,0.00000000,0.00000000,0.00000000
297.61000000,7.83708300,2.55200000,0.25063367,227.84467914,0.00000000,0.00000000,0.00000000,0.00000000,0.00000000,0.00000000,0.00000000,0.00000000,0.00000000,0.00000000,0.00000000
299.11000000,7.89637200,2.55000000,0.25231256,227.66611748,0.00000000,0.00000000,0.00000000,0.00000000,0.00000000,0.00000000,0.00000000,0.00000000,0.00000000,0.00000000,0.00000000
300.61000000,7.95562500,2.54200000,0.25339433,226.95187084,0.00000000,0.00000000,0.00000000,0.00000000,0.00000000,0.00000000,0.00000000,0.00000000,0.00000000,0.00000000,0.00000000
302.11000000,8.01504700,2.54000000,0.25406556,226.77330918,0.00000000,0.00000000,0.00000000,0.00000000,0.00000000,0.00000000,0.00000000,0.00000000,0.00000000,0.00000000,0.00000000
303.61000000,8.07497400,2.53200000,0.25458778,226.05906254,0.00000000,0.00000000,0.00000000,0.00000000,0.00000000,0.00000000,0.00000000,0.00000000,0.00000000,0.00000000,0.00000000
305.11000000,8.13480000,2.52500000,0.25492356,225.43409672,0.00000000,0.00000000,0.00000000,0.00000000,0.00000000,0.00000000,0.00000000,0.00000000,0.00000000,0.00000000,0.00000000
306.61000000,8.19539700,2.51400000,0.25514733,224.45200759,0.00000000,0.00000000,0.00000000,0.00000000,0.00000000,0.00000000,0.00000000,0.00000000,0.00000000,0.00000000,0.00000000
308.11000000,8.25747200,2.49900000,0.25525933,223.11279513,0.00000000,0.00000000,0.00000000,0.00000000,0.00000000,0.00000000,0.00000000,0.00000000,0.00000000,0.00000000,0.00000000
309.61000000,8.31998600,2.47500000,0.25529678,220.97005520,0.00000000,0.00000000,0.00000000,0.00000000,0.00000000,0.00000000,0.00000000,0.00000000,0.00000000,0.00000000,0.00000000
311.11000000,8.38357700,2.44400000,0.25522256,218.20234946,0.00000000,0.00000000,0.00000000,0.00000000,0.00000000,0.00000000,0.00000000,0.00000000,0.00000000,0.00000000,0.00000000
312.61000000,8.44851800,2.39900000,0.25514867,214.18471209,0.00000000,0.00000000,0.00000000,0.00000000,0.00000000,0.00000000,0.00000000,0.00000000,0.00000000,0.00000000,0.00000000
314.11000000,8.51622100,2.33100000,0.25500056,208.11361563,0.00000000,0.00000000,0.00000000,0.00000000,0.00000000,0.00000000,0.00000000,0.00000000,0.00000000,0.00000000,0.00000000
315.61000000,8.58843900,2.23600000,0.25474133,199.63193674,0.00000000,0.00000000,0.00000000,0.00000000,0.00000000,0.00000000,0.00000000,0.00000000,0.00000000,0.00000000,0.00000000
317.11000000,8.94702600,0.05100000,0.25011189,4.55332235,0.00000000,0.00000000,0.00000000,0.00000000,0.00000000,0.00000000,0.00000000,0.00000000,0.00000000,0.00000000,0.00000000
NaN,-100.00000000,NaN,-11.11111111,NaN,0.00000000,0.00000000,0.00000000,0.00000000,0.00000000,0.00000000,0.00000000,0.00000000,0.00000000,0.00000000,0.00000000