File: polyN_optimization/results_exp/DP780/UT_15_2.csv
Time[s],Displacement[mm],Force[kN],EngStrain_longi,EngStress[MPa],TrueStrain,TrueStress[MPa],TrueStrainRate[1/s],PlasticStrain_longi,PlasticStress[MPa],PlasticStrain_thick,PlasticStrain_width,R-Value,Thickness[mm],Width[mm], Young's Modulus [MPa]
0.00000000,0.00000000,-0.01580000,0.00000000,-1.04964432,0.00000000,-1.04964432,0.00000000,0.00062519,400.64236935,0.00003856,-0.00066375,0.80784896,1.50850000,9.97860000,204624.51893418
1.50000000,0.00178400,0.31520000,0.00004989,20.93973978,0.00004989,20.94078444,0.00002267,0.00070814,413.12906975,0.00014294,-0.00085108,0.00000000,0.00000000,0.00000000,0.00000000
3.00000000,0.00373200,0.65730000,0.00013744,43.66653223,0.00013743,43.67253395,0.00007199,0.00087513,425.34139408,-0.00004807,-0.00082706,0.00000000,0.00000000,0.00000000,0.00000000
4.50000000,0.00613600,0.98980000,0.00021411,65.75556610,0.00021409,65.76964510,0.00002111,0.00112324,438.48970725,-0.00011665,-0.00100659,0.00000000,0.00000000,0.00000000,0.00000000
6.00000000,0.00920000,1.32320000,0.00033133,87.90438984,0.00033128,87.93351549,0.00019150,0.00143232,449.76286895,-0.00021456,-0.00121777,0.00000000,0.00000000,0.00000000,0.00000000
7.50000000,0.01131900,1.61270000,0.00038822,107.13679678,0.00038815,107.17838966,0.00014884,0.00169817,461.55890649,-0.00044972,-0.00124845,0.00000000,0.00000000,0.00000000,0.00000000
9.00000000,0.01345300,1.89420000,0.00044311,125.83773824,0.00044301,125.89349834,0.00010151,0.00204777,472.91409934,-0.00060245,-0.00144532,0.00000000,0.00000000,0.00000000,0.00000000
10.50000000,0.01523300,2.17570000,0.00050444,144.53867970,0.00050432,144.61159143,0.00013905,0.00249181,483.21359905,-0.00079226,-0.00169955,0.00000000,0.00000000,0.00000000,0.00000000
12.00000000,0.01683000,2.42850000,0.00055211,161.33298876,0.00055196,161.42206249,0.00001599,0.00284628,493.47216253,-0.00093470,-0.00191157,0.00000000,0.00000000,0.00000000,0.00000000
13.50000000,0.01884100,2.66770000,0.00062511,177.22380651,0.00062492,177.33459108,-0.00006041,0.00323779,503.75765455,-0.00112968,-0.00210812,0.00000000,0.00000000,0.00000000,0.00000000
15.00000000,0.02141000,2.92850000,0.00069433,194.54958105,0.00069409,194.68466331,-0.00018142,0.00370708,513.34843304,-0.00139547,-0.00231161,0.00000000,0.00000000,0.00000000,0.00000000
16.50000000,0.02451500,3.15900000,0.00083467,209.86243009,0.00083432,210.03759527,0.00002553,0.00431199,522.58424395,-0.00173157,-0.00258042,0.00000000,0.00000000,0.00000000,0.00000000
18.00000000,0.02680900,3.39900000,0.00097022,225.80639439,0.00096975,226.02547678,0.00024489,0.00490478,531.93946032,-0.00204426,-0.00286052,0.00000000,0.00000000,0.00000000,0.00000000
19.50000000,0.02922500,3.63030000,0.00100178,241.17238999,0.00100128,241.41399113,0.00023289,0.00547949,540.32974928,-0.00231778,-0.00316172,0.00000000,0.00000000,0.00000000,0.00000000
21.00000000,0.03150500,3.85120000,0.00105156,255.84748046,0.00105100,256.11651830,0.00012054,0.00611420,548.55489983,-0.00266457,-0.00344963,0.00000000,0.00000000,0.00000000,0.00000000
22.50000000,0.03433100,4.06970000,0.00106344,270.36313129,0.00106288,270.65064746,-0.00011965,0.00681167,556.81923613,-0.00309128,-0.00372039,0.00000000,0.00000000,0.00000000,0.00000000
24.00000000,0.03715400,4.30330000,0.00118756,285.88192321,0.00118685,286.22142388,-0.00018000,0.00746646,564.53296565,-0.00347500,-0.00399146,0.00000000,0.00000000,0.00000000,0.00000000
25.50000000,0.03977100,4.51790000,0.00138000,300.13848462,0.00137905,300.55267573,0.00001576,0.00812606,571.94338668,-0.00380193,-0.00432413,0.00000000,0.00000000,0.00000000,0.00000000
27.00000000,0.04286500,4.72600000,0.00153067,313.96323034,0.00152950,314.44380339,0.00028514,0.00884032,580.25153249,-0.00420926,-0.00463106,0.00000000,0.00000000,0.00000000,0.00000000
28.50000000,0.04666700,4.94770000,0.00159144,328.69146736,0.00159018,329.21456157,0.00027824,0.00959042,587.08893680,-0.00464118,-0.00494924,0.00000000,0.00000000,0.00000000,0.00000000
30.00000000,0.05196000,5.14870000,0.00164067,342.04453746,0.00163932,342.60571853,-0.00009739,0.01032187,593.87160219,-0.00498371,-0.00533815,0.00000000,0.00000000,0.00000000,0.00000000
31.50000000,0.05585600,5.35120000,0.00180267,355.49725734,0.00180104,356.13810039,-0.00016459,0.01098383,601.10884369,-0.00526944,-0.00571438,0.00000000,0.00000000,0.00000000,0.00000000
33.00000000,0.06002800,5.56180000,0.00214856,369.48808601,0.00214625,370.28195169,0.00022508,0.01175302,607.50185327,-0.00569529,-0.00605773,0.00000000,0.00000000,0.00000000,0.00000000
34.50000000,0.06596000,5.75240000,0.00226156,382.15025099,0.00225900,383.01450501,0.00036743,0.01257975,614.10932911,-0.00614325,-0.00643649,0.00000000,0.00000000,0.00000000,0.00000000
36.00000000,0.07160900,5.94300000,0.00236344,394.81241597,0.00236066,395.74553318,0.00021750,0.01333934,620.67917279,-0.00656128,-0.00677806,0.00000000,0.00000000,0.00000000,0.00000000
37.50000000,0.07780700,6.14390000,0.00251367,408.15884275,0.00251051,409.18481803,-0.00005253,0.01411576,626.72739078,-0.00694968,-0.00716608,0.00000000,0.00000000,0.00000000,0.00000000
39.00000000,0.08589400,6.32970000,0.00286322,420.50212845,0.00285913,421.70611949,0.00009772,0.01499076,632.79327436,-0.00748034,-0.00751042,0.00000000,0.00000000,0.00000000,0.00000000
40.50000000,0.09451600,6.50920000,0.00317900,432.42688508,0.00317396,433.80157015,0.00025432,0.01587821,639.21037830,-0.00798212,-0.00789609,0.00000000,0.00000000,0.00000000,0.00000000
42.00000000,0.10337400,6.69660000,0.00345289,444.87646387,0.00344694,446.41257287,0.00027684,0.01673285,644.58437106,-0.00847379,-0.00825906,0.00000000,0.00000000,0.00000000,0.00000000
43.50000000,0.11422700,6.86640000,0.00378333,456.15681861,0.00377619,457.88261191,0.00024708,0.01755653,650.10364398,-0.00889362,-0.00866291,0.00000000,0.00000000,0.00000000,0.00000000
45.00000000,0.12605300,7.02670000,0.00417778,466.80605810,0.00416908,468.75627008,0.00030674,0.01844042,656.00512157,-0.00936315,-0.00907727,0.00000000,0.00000000,0.00000000,0.00000000
46.50000000,0.13804600,7.19420000,0.00456033,477.93361652,0.00454997,480.11315312,0.00026901,0.01939331,661.09019705,-0.00988080,-0.00951251,0.00000000,0.00000000,0.00000000,0.00000000
48.00000000,0.15257500,7.34410000,0.00496189,487.89195089,0.00494962,490.31281654,0.00017182,0.02026036,666.29099521,-0.01035391,-0.00990645,0.00000000,0.00000000,0.00000000,0.00000000
49.50000000,0.16703800,7.48690000,0.00548367,497.37860965,0.00546869,500.10606815,0.00009703,0.02117670,671.74548147,-0.01083528,-0.01034143,0.00000000,0.00000000,0.00000000,0.00000000
51.00000000,0.18325600,7.63840000,0.00609933,507.44323711,0.00608081,510.53830256,0.00026860,0.02210124,676.83929435,-0.01130322,-0.01079802,0.00000000,0.00000000,0.00000000,0.00000000
52.50000000,0.20014700,7.77000000,0.00668867,516.18584420,0.00666640,519.63843925,0.00048482,0.02306494,681.20261927,-0.01183110,-0.01123383,0.00000000,0.00000000,0.00000000,0.00000000
54.00000000,0.21818400,7.90080000,0.00728178,524.87530475,0.00725539,528.69733008,0.00047725,0.02402436,686.28331452,-0.01235127,-0.01167309,0.00000000,0.00000000,0.00000000,0.00000000
55.50000000,0.23757600,8.03390000,0.00789733,533.71756161,0.00786631,537.93250710,0.00043969,0.02496327,690.81751139,-0.01285512,-0.01210815,0.00000000,0.00000000,0.00000000,0.00000000
57.00000000,0.25667000,8.14640000,0.00860689,541.19129488,0.00857006,545.84926822,0.00059585,0.02594504,695.38284786,-0.01340595,-0.01253908,0.00000000,0.00000000,0.00000000,0.00000000
58.50000000,0.27816200,8.26440000,0.00929033,549.03041066,0.00924744,554.13108619,0.00068465,0.02694298,700.18789951,-0.01393638,-0.01300659,0.00000000,0.00000000,0.00000000,0.00000000
60.00000000,0.29844000,8.38240000,0.00991356,556.86952644,0.00986474,562.39008343,0.00056514,0.02794075,704.01845692,-0.01454777,-0.01339298,0.00000000,0.00000000,0.00000000,0.00000000
61.50000000,0.32087700,8.48770000,0.01059689,563.86494078,0.01054114,569.84015490,0.00034922,0.02890255,708.31934646,-0.01505525,-0.01384730,0.00000000,0.00000000,0.00000000,0.00000000
63.00000000,0.34220600,8.58980000,0.01138178,570.64776892,0.01131749,577.14275502,0.00044586,0.02992884,712.61901907,-0.01563783,-0.01429100,0.00000000,0.00000000,0.00000000,0.00000000
64.50000000,0.36582800,8.69820000,0.01212889,577.84912613,0.01205592,584.85779398,0.00058631,0.03095802,716.82554172,-0.01621835,-0.01473967,0.00000000,0.00000000,0.00000000,0.00000000
66.00000000,0.38796300,8.79790000,0.01281978,584.47251464,0.01273830,591.96532239,0.00039278,0.03196755,720.35599953,-0.01678741,-0.01518014,0.00000000,0.00000000,0.00000000,0.00000000
67.50000000,0.41236400,8.89280000,0.01362711,590.77702385,0.01353510,598.82760800,0.00036309,0.03299954,724.30337432,-0.01735312,-0.01564642,0.00000000,0.00000000,0.00000000,0.00000000
69.00000000,0.43679800,8.98930000,0.01452833,597.18782616,0.01442381,605.86396997,0.00047362,0.03403006,728.30565187,-0.01792163,-0.01610843,0.00000000,0.00000000,0.00000000,0.00000000
70.50000000,0.46190800,9.07300000,0.01532822,602.74828371,0.01521193,611.98734335,0.00056213,0.03508157,732.22705561,-0.01851700,-0.01656457,0.00000000,0.00000000,0.00000000,0.00000000
72.00000000,0.48617300,9.16080000,0.01612811,608.58111732,0.01599943,618.39638120,0.00045844,0.03615041,736.05787311,-0.01911319,-0.01703722,0.00000000,0.00000000,0.00000000,0.00000000
73.50000000,0.51250000,9.25010000,0.01698811,614.51360070,0.01684543,624.95302603,0.00035467,0.03720274,739.32147069,-0.01969432,-0.01750842,0.00000000,0.00000000,0.00000000,0.00000000
75.00000000,0.53818600,9.32420000,0.01789289,619.43629968,0.01773470,630.51980456,0.00055307,0.03826700,742.88512211,-0.02023186,-0.01803514,0.00000000,0.00000000,0.00000000,0.00000000
76.50000000,0.56562900,9.40880000,0.01879811,625.05654710,0.01862361,636.80642952,0.00061934,0.03936537,745.81309769,-0.02084776,-0.01851761,0.00000000,0.00000000,0.00000000,0.00000000
78.00000000,0.59168700,9.49010000,0.01968056,630.45756500,0.01948940,642.86532014,0.00054556,0.04043701,749.56264748,-0.02142642,-0.01901060,0.00000000,0.00000000,0.00000000,0.00000000
79.50000000,0.61967200,9.56830000,0.02058922,635.65264004,0.02038013,648.74023350,0.00048562,0.04151072,752.65149603,-0.02202012,-0.01949060,0.00000000,0.00000000,0.00000000,0.00000000
81.00000000,0.64725100,9.63690000,0.02153556,640.20995650,0.02130694,653.99723358,0.00060289,0.04261805,755.93929171,-0.02261754,-0.02000050,0.00000000,0.00000000,0.00000000,0.00000000
82.50000000,0.67530400,9.71260000,0.02247067,645.23894857,0.02222192,659.73789791,0.00066843,0.04371047,759.11034337,-0.02322971,-0.02048076,0.00000000,0.00000000,0.00000000,0.00000000
84.00000000,0.70372900,9.77960000,0.02339067,649.68997194,0.02312130,664.88665351,0.00056530,0.04482295,762.30286090,-0.02383788,-0.02098507,0.00000000,0.00000000,0.00000000,0.00000000
85.50000000,0.73286200,9.84260000,0.02440467,653.87526257,0.02411163,669.83287039,0.00061595,0.04593082,765.44204426,-0.02447827,-0.02145255,0.00000000,0.00000000,0.00000000,0.00000000
87.00000000,0.76223400,9.90880000,0.02536600,658.27313939,0.02504962,674.97089584,0.00063727,0.04708172,768.28383203,-0.02515217,-0.02192955,0.00000000,0.00000000,0.00000000,0.00000000
88.50000000,0.79123300,9.97180000,0.02633489,662.45843002,0.02599410,679.90419916,0.00068800,0.04817800,771.81227875,-0.02575229,-0.02242571,0.00000000,0.00000000,0.00000000,0.00000000
90.00000000,0.82134800,10.02600000,0.02731889,666.05910862,0.02695239,684.25510340,0.00062892,0.04931227,774.60382941,-0.02635416,-0.02295811,0.00000000,0.00000000,0.00000000,0.00000000
91.50000000,0.85132800,10.08740000,0.02834033,670.13810615,0.02794618,689.13004346,0.00059890,0.05050171,777.49311136,-0.02703689,-0.02346482,0.00000000,0.00000000,0.00000000,0.00000000
93.00000000,0.88164500,10.14880000,0.02934689,674.21710369,0.02892451,694.00327812,0.00067865,0.05160650,779.92729940,-0.02763122,-0.02397528,0.00000000,0.00000000,0.00000000,0.00000000
94.50000000,0.91270600,10.20150000,0.03039100,677.71813251,0.02993834,698.31466428,0.00061259,0.05278361,782.59210576,-0.02831594,-0.02446766,0.00000000,0.00000000,0.00000000,0.00000000
96.00000000,0.94393700,10.25810000,0.03141244,681.47825076,0.03092917,702.88514845,0.00058267,0.05391461,785.67792761,-0.02891660,-0.02499801,0.00000000,0.00000000,0.00000000,0.00000000
97.50000000,0.97513500,10.31070000,0.03249789,684.97263627,0.03198100,707.23280090,0.00064751,0.05508720,787.96111869,-0.02955923,-0.02552797,0.00000000,0.00000000,0.00000000,0.00000000
99.00000000,1.00666900,10.35780000,0.03353444,688.10163926,0.03298443,711.17674546,0.00071268,0.05626679,790.70028529,-0.03020649,-0.02606030,0.00000000,0.00000000,0.00000000,0.00000000
100.50000000,1.03874300,10.41040000,0.03460100,691.59602477,0.03401585,715.52593883,0.00066080,0.05743051,793.48896352,-0.03085239,-0.02657811,0.00000000,0.00000000,0.00000000,0.00000000
102.00000000,1.07044800,10.45510000,0.03567133,694.56558812,0.03504985,719.34166874,0.00068180,0.05862000,795.79267363,-0.03153191,-0.02708809,0.00000000,0.00000000,0.00000000,0.00000000
103.50000000,1.10330200,10.49810000,0.03677178,697.42221506,0.03611183,723.06766977,0.00074626,0.05979040,798.82457747,-0.03216498,-0.02762542,0.00000000,0.00000000,0.00000000,0.00000000
105.00000000,1.13527700,10.54440000,0.03784211,700.49807151,0.03714366,727.00639736,0.00074570,0.06091144,800.86235635,-0.03274034,-0.02817110,0.00000000,0.00000000,0.00000000,0.00000000
106.50000000,1.16819800,10.58820000,0.03894244,703.40784499,0.03820332,730.80026592,0.00070126,0.06215252,803.22133087,-0.03347047,-0.02868205,0.00000000,0.00000000,0.00000000,0.00000000
108.00000000,1.20260500,10.62970000,0.04009167,706.16482215,0.03930885,734.47614681,0.00071502,0.06336008,805.67912629,-0.03415723,-0.02920286,0.00000000,0.00000000,0.00000000,0.00000000
109.50000000,1.23485100,10.67280000,0.04119211,709.02809241,0.04036632,738.23445637,0.00070722,0.06455629,808.01112184,-0.03481979,-0.02973650,0.00000000,0.00000000,0.00000000,0.00000000
111.00000000,1.26858400,10.70790000,0.04230378,711.35989719,0.04143343,741.45310820,0.00073526,0.06577160,810.42034000,-0.03551825,-0.03025335,0.00000000,0.00000000,0.00000000,0.00000000
112.50000000,1.30201100,10.74610000,0.04344922,713.89764484,0.04253179,744.91594225,0.00082074,0.06697171,812.77175802,-0.03618487,-0.03078684,0.00000000,0.00000000,0.00000000,0.00000000
114.00000000,1.33638500,10.78840000,0.04461344,716.70776855,0.04364691,748.68257076,0.00081982,0.06818482,815.01649217,-0.03683879,-0.03134603,0.00000000,0.00000000,0.00000000,0.00000000
115.50000000,1.37109800,10.82110000,0.04577022,718.88013368,0.04475367,751.78343715,0.00074706,0.06940338,817.27716968,-0.03751992,-0.03188346,0.00000000,0.00000000,0.00000000,0.00000000
117.00000000,1.40547300,10.85380000,0.04691567,721.05249882,0.04584838,754.88115750,0.00074625,0.07065304,819.27317389,-0.03824631,-0.03240673,0.00000000,0.00000000,0.00000000,0.00000000
118.50000000,1.44055700,10.88890000,0.04808744,723.38430360,0.04696702,758.17000611,0.00078147,0.07186835,821.59712884,-0.03892658,-0.03294177,0.00000000,0.00000000,0.00000000,0.00000000
120.00000000,1.47580800,10.92480000,0.04927422,725.76925492,0.04809871,761.53097047,0.00076618,0.07310175,823.41467973,-0.03957365,-0.03352810,0.00000000,0.00000000,0.00000000,0.00000000
121.50000000,1.51136600,10.95430000,0.05047222,727.72903387,0.04923980,764.45913538,0.00080827,0.07434246,825.59496749,-0.04027724,-0.03406522,0.00000000,0.00000000,0.00000000,0.00000000
123.00000000,1.54672100,10.98860000,0.05166644,730.00769210,0.05037600,767.72459397,0.00079276,0.07558207,827.65576047,-0.04096856,-0.03461351,0.00000000,0.00000000,0.00000000,0.00000000
124.50000000,1.58204200,11.01730000,0.05282700,731.91432450,0.05147893,770.57916252,0.00074923,0.07683332,829.85304092,-0.04163845,-0.03519486,0.00000000,0.00000000,0.00000000,0.00000000
126.00000000,1.61810600,11.04200000,0.05405867,733.55522416,0.05264811,773.21024150,0.00075532,0.07809685,832.05759882,-0.04235385,-0.03574300,0.00000000,0.00000000,0.00000000,0.00000000
127.50000000,1.65498100,11.07310000,0.05528311,735.62129620,0.05380908,776.28873005,0.00078309,0.07936356,833.98637043,-0.04306330,-0.03630026,0.00000000,0.00000000,0.00000000,0.00000000
129.00000000,1.69081000,11.10340000,0.05648489,737.63422169,0.05494725,779.29940874,0.00074664,0.08064544,835.98952951,-0.04378495,-0.03686049,0.00000000,0.00000000,0.00000000,0.00000000
130.50000000,1.72771900,11.12490000,0.05773933,739.06253516,0.05613393,781.73551323,0.00080965,0.08191735,837.57381021,-0.04446972,-0.03744763,0.00000000,0.00000000,0.00000000,0.00000000
132.00000000,1.76466200,11.14970000,0.05897489,740.71007814,0.05730135,784.39337269,0.00076609,0.08312453,839.40461883,-0.04510283,-0.03802170,0.00000000,0.00000000,0.00000000,0.00000000
133.50000000,1.80147100,11.17920000,0.06020300,742.66985708,0.05846040,787.38081049,0.00077946,0.08440728,841.65224379,-0.04580993,-0.03859736,0.00000000,0.00000000,0.00000000,0.00000000
135.00000000,1.83871900,11.20470000,0.06144989,744.36390329,0.05963579,790.10498244,0.00080682,0.08570147,843.32299593,-0.04653945,-0.03916203,0.00000000,0.00000000,0.00000000,0.00000000
136.50000000,1.87633900,11.22460000,0.06271556,745.68592366,0.06082748,792.45203063,0.00077761,0.08698567,845.28774150,-0.04725131,-0.03973436,0.00000000,0.00000000,0.00000000,0.00000000
138.00000000,1.91375600,11.24940000,0.06399244,747.33346664,0.06202829,795.15716198,0.00081178,0.08829377,846.92536614,-0.04798096,-0.04031281,0.00000000,0.00000000,0.00000000,0.00000000
139.50000000,1.95174600,11.27170000,0.06523556,748.81492665,0.06319595,797.66428440,0.00074030,0.08961968,848.74951258,-0.04871201,-0.04090768,0.00000000,0.00000000,0.00000000,0.00000000
141.00000000,1.98943400,11.29560000,0.06649756,750.40267977,0.06437997,800.30262365,0.00076089,0.09089025,851.06519682,-0.04939547,-0.04149477,0.00000000,0.00000000,0.00000000,0.00000000
142.50000000,2.02776300,11.31470000,0.06780444,751.67155359,0.06560462,802.63822569,0.00080201,0.09222371,852.73425467,-0.05011806,-0.04210566,0.00000000,0.00000000,0.00000000,0.00000000
144.00000000,2.06555300,11.33230000,0.06907389,752.84077764,0.06679275,804.84241787,0.00078692,0.09357311,854.23607243,-0.05089159,-0.04268151,0.00000000,0.00000000,0.00000000,0.00000000
145.50000000,2.10455900,11.35460000,0.07039956,754.32223766,0.06803200,807.42618793,0.00090537,0.09487303,855.76418335,-0.05160875,-0.04326428,0.00000000,0.00000000,0.00000000,0.00000000
147.00000000,2.14315700,11.37300000,0.07167278,755.54460825,0.06922077,809.69658906,0.00079207,0.09623327,857.81872504,-0.05238535,-0.04384792,0.00000000,0.00000000,0.00000000,0.00000000
148.50000000,2.18148800,11.39050000,0.07298356,756.70718898,0.07044314,811.93437015,0.00079130,0.09756818,859.08745541,-0.05314573,-0.04442245,0.00000000,0.00000000,0.00000000,0.00000000
150.00000000,2.22035800,11.40810000,0.07427544,757.87641303,0.07164643,814.16802044,0.00075538,0.09887511,860.86626137,-0.05388353,-0.04499157,0.00000000,0.00000000,0.00000000,0.00000000
151.50000000,2.26010800,11.42560000,0.07560133,759.03899376,0.07287989,816.42335374,0.00082431,0.10022392,862.73638534,-0.05462530,-0.04559862,0.00000000,0.00000000,0.00000000,0.00000000
153.00000000,2.29904600,11.44230000,0.07689311,760.14842794,0.07408015,818.59860547,0.00071143,0.10158156,864.50646697,-0.05540521,-0.04617636,0.00000000,0.00000000,0.00000000,0.00000000
154.50000000,2.33825500,11.45750000,0.07825267,761.15821235,0.07534183,820.72087222,0.00078723,0.10294812,866.10935078,-0.05614123,-0.04680689,0.00000000,0.00000000,0.00000000,0.00000000
156.00000000,2.37729400,11.47260000,0.07959344,762.16135344,0.07658453,822.82440078,0.00082105,0.10429087,867.39687964,-0.05687486,-0.04741600,0.00000000,0.00000000,0.00000000,0.00000000
157.50000000,2.41751800,11.48620000,0.08093056,763.06484475,0.07782230,824.82010656,0.00077150,0.10565265,869.23896450,-0.05765340,-0.04799925,0.00000000,0.00000000,0.00000000,0.00000000
159.00000000,2.45804400,11.50450000,0.08229378,764.28057203,0.07908266,827.17610758,0.00078429,0.10703287,871.03350972,-0.05839531,-0.04863756,0.00000000,0.00000000,0.00000000,0.00000000
160.50000000,2.49877400,11.51650000,0.08366833,765.07777024,0.08035189,829.09055215,0.00079725,0.10837978,872.39157647,-0.05912706,-0.04925272,0.00000000,0.00000000,0.00000000,0.00000000
162.00000000,2.53909900,11.53480000,0.08504667,766.29349752,0.08162300,831.46420517,0.00087245,0.10979538,874.41011118,-0.05991077,-0.04988462,0.00000000,0.00000000,0.00000000,0.00000000
163.50000000,2.57959300,11.54360000,0.08643633,766.87810954,0.08290292,833.16424144,0.00085763,0.11117856,875.80516506,-0.06070428,-0.05047428,0.00000000,0.00000000,0.00000000,0.00000000
165.00000000,2.62062700,11.55720000,0.08783722,767.78160085,0.08419153,835.22140394,0.00087042,0.11255637,877.19768050,-0.06147251,-0.05108386,0.00000000,0.00000000,0.00000000,0.00000000
166.50000000,2.66112000,11.56600000,0.08921922,768.36621288,0.08546113,836.91924877,0.00087605,0.11398415,878.92929605,-0.06226283,-0.05172132,0.00000000,0.00000000,0.00000000,0.00000000
168.00000000,2.70242400,11.58270000,0.09060133,769.47564706,0.08672923,839.19116665,0.00082663,0.11541670,880.61566864,-0.06306377,-0.05235293,0.00000000,0.00000000,0.00000000,0.00000000
169.50000000,2.74393200,11.58910000,0.09201722,769.90081944,0.08802665,840.74495423,0.00088073,0.11686925,881.84090051,-0.06389398,-0.05297527,0.00000000,0.00000000,0.00000000,0.00000000
171.00000000,2.78577700,11.60100000,0.09341811,770.69137434,0.08930867,842.68790678,0.00085215,0.11834060,883.56713361,-0.06475305,-0.05358755,0.00000000,0.00000000,0.00000000,0.00000000
172.50000000,2.82782600,11.61140000,0.09484144,771.38227946,0.09060955,844.54128906,0.00087825,0.11978422,885.09066123,-0.06554344,-0.05424078,0.00000000,0.00000000,0.00000000,0.00000000
174.00000000,2.86950100,11.62260000,0.09629489,772.12633112,0.09193621,846.47815039,0.00091825,0.12120203,886.71478874,-0.06630045,-0.05490158,0.00000000,0.00000000,0.00000000,0.00000000
175.50000000,2.91111100,11.63210000,0.09766944,772.75744638,0.09318925,848.23223686,0.00080773,0.12268608,887.91610173,-0.06716429,-0.05552179,0.00000000,0.00000000,0.00000000,0.00000000
177.00000000,2.95427400,11.64650000,0.09914544,773.71408424,0.09453301,850.42431099,0.00083395,0.12416725,889.23782482,-0.06796983,-0.05619742,0.00000000,0.00000000,0.00000000,0.00000000
178.50000000,2.99649000,11.64810000,0.10058378,773.82037733,0.09584075,851.65415420,0.00083266,0.12567598,891.25472596,-0.06880724,-0.05686874,0.00000000,0.00000000,0.00000000,0.00000000
180.00000000,3.03941700,11.66240000,0.10202600,774.77037187,0.09715030,853.81709383,0.00083177,0.12718547,892.60683062,-0.06965249,-0.05753297,0.00000000,0.00000000,0.00000000,0.00000000
181.50000000,3.08197300,11.66560000,0.10350200,774.98295806,0.09848876,855.19524419,0.00083751,0.12869334,893.83761506,-0.07045836,-0.05823498,0.00000000,0.00000000,0.00000000,0.00000000
183.00000000,3.12530500,11.68000000,0.10501167,775.93959592,0.09985589,857.42230612,0.00092449,0.13016469,895.34252673,-0.07127033,-0.05889436,0.00000000,0.00000000,0.00000000,0.00000000
184.50000000,3.16867000,11.68560000,0.10647644,776.31162175,0.10118059,858.97052302,0.00088951,0.13173149,896.99707121,-0.07215272,-0.05957877,0.00000000,0.00000000,0.00000000,0.00000000
186.00000000,3.21220600,11.68960000,0.10800489,776.57735449,0.10256100,860.45150538,0.00094246,0.13326438,898.37903850,-0.07300448,-0.06025991,0.00000000,0.00000000,0.00000000,0.00000000
187.50000000,3.25503100,11.69670000,0.10947722,777.04903010,0.10388893,862.11819945,0.00092117,0.13482687,899.91256700,-0.07386654,-0.06096033,0.00000000,0.00000000,0.00000000,0.00000000
189.00000000,3.29880400,11.70630000,0.11096811,777.68678867,0.10523181,863.98522265,0.00095355,0.13638815,901.20186718,-0.07478217,-0.06160598,0.00000000,0.00000000,0.00000000,0.00000000
190.50000000,3.34294600,11.70870000,0.11247411,777.84622832,0.10658646,865.33379143,0.00085094,0.13797845,902.70391403,-0.07568395,-0.06229450,0.00000000,0.00000000,0.00000000,0.00000000
192.00000000,3.38739400,11.71910000,0.11403278,778.53713344,0.10798656,867.31588537,0.00095771,0.13963213,904.01947464,-0.07665335,-0.06297877,0.00000000,0.00000000,0.00000000,0.00000000
193.50000000,3.43160600,11.72390000,0.11552000,778.85601272,0.10932066,868.82945931,0.00090940,0.14121665,905.64446955,-0.07750341,-0.06371324,0.00000000,0.00000000,0.00000000,0.00000000
195.00000000,3.47639200,11.73020000,0.11707867,779.27454179,0.11071694,870.51096610,0.00086096,0.14279961,907.08542875,-0.07835822,-0.06444139,0.00000000,0.00000000,0.00000000,0.00000000
196.50000000,3.52138100,11.73500000,0.11863711,779.59342107,0.11211108,872.08213239,0.00095357,0.00000000,0.00000000,0.00000000,0.00000000,0.00000000,0.00000000,0.00000000,0.00000000
198.00000000,3.56633500,11.73980000,0.12019956,779.91230036,0.11350684,873.65741223,0.00089885,0.00000000,0.00000000,0.00000000,0.00000000,0.00000000,0.00000000,0.00000000,0.00000000
199.50000000,3.61149300,11.74380000,0.12174300,780.17803310,0.11488373,875.15924738,0.00087066,0.00000000,0.00000000,0.00000000,0.00000000,0.00000000,0.00000000,0.00000000,0.00000000
201.00000000,3.65702300,11.74940000,0.12334300,780.55005893,0.11630906,876.82544485,0.00092978,0.00000000,0.00000000,0.00000000,0.00000000,0.00000000,0.00000000,0.00000000,0.00000000
202.50000000,3.70251900,11.75420000,0.12489778,780.86893822,0.11769217,878.39773333,0.00089490,0.00000000,0.00000000,0.00000000,0.00000000,0.00000000,0.00000000,0.00000000,0.00000000
204.00000000,3.74889200,11.75730000,0.12651644,781.07488109,0.11913008,879.89369789,0.00084684,0.00000000,0.00000000,0.00000000,0.00000000,0.00000000,0.00000000,0.00000000,0.00000000
205.50000000,3.79536800,11.75970000,0.12815011,781.23432073,0.12057922,881.34958574,0.00096543,0.00000000,0.00000000,0.00000000,0.00000000,0.00000000,0.00000000,0.00000000,0.00000000
207.00000000,3.84167600,11.76130000,0.12980267,781.34061383,0.12204299,882.76070908,0.00095103,0.00000000,0.00000000,0.00000000,0.00000000,0.00000000,0.00000000,0.00000000,0.00000000
208.50000000,3.88835400,11.76930000,0.13145144,781.87207930,0.12350127,884.65029350,0.00099622,0.00000000,0.00000000,0.00000000,0.00000000,0.00000000,0.00000000,0.00000000,0.00000000
210.00000000,3.93547200,11.77330000,0.13310389,782.13781204,0.12496067,886.24339647,0.00099476,0.00000000,0.00000000,0.00000000,0.00000000,0.00000000,0.00000000,0.00000000,0.00000000
211.50000000,3.98259100,11.77250000,0.13475633,782.08466549,0.12641794,887.47552737,0.00092689,0.00000000,0.00000000,0.00000000,0.00000000,0.00000000,0.00000000,0.00000000,0.00000000
213.00000000,4.03014800,11.77570000,0.13644633,782.29725168,0.12790614,889.03884325,0.00105777,0.00000000,0.00000000,0.00000000,0.00000000,0.00000000,0.00000000,0.00000000,0.00000000
214.50000000,4.07811100,11.77970000,0.13813633,782.56298442,0.12939213,890.66336569,0.00099017,0.00000000,0.00000000,0.00000000,0.00000000,0.00000000,0.00000000,0.00000000,0.00000000
216.00000000,4.12590400,11.78210000,0.13986400,782.72242407,0.13090896,892.19711318,0.00098867,0.00000000,0.00000000,0.00000000,0.00000000,0.00000000,0.00000000,0.00000000,0.00000000
217.50000000,4.17396900,11.78450000,0.14162911,782.88186371,0.13245629,893.76072617,0.00105277,0.00000000,0.00000000,0.00000000,0.00000000,0.00000000,0.00000000,0.00000000,0.00000000
219.00000000,4.22260800,11.78290000,0.14335667,782.77557061,0.13396838,894.99166716,0.00105137,0.00000000,0.00000000,0.00000000,0.00000000,0.00000000,0.00000000,0.00000000,0.00000000
220.50000000,4.27087600,11.78450000,0.14508433,782.88186371,0.13547829,896.46575698,0.00098416,0.00000000,0.00000000,0.00000000,0.00000000,0.00000000,0.00000000,0.00000000,0.00000000
222.00000000,4.32025800,11.78610000,0.14688700,782.98815680,0.13705132,897.99893819,0.00098261,0.00000000,0.00000000,0.00000000,0.00000000,0.00000000,0.00000000,0.00000000,0.00000000
223.50000000,4.36933600,11.78370000,0.14861456,782.82871716,0.13855648,899.16845904,0.00098113,0.00000000,0.00000000,0.00000000,0.00000000,0.00000000,0.00000000,0.00000000,0.00000000
225.00000000,4.41861700,11.78690000,0.15041733,783.04130335,0.14012478,900.82428809,0.00097959,0.00000000,0.00000000,0.00000000,0.00000000,0.00000000,0.00000000,0.00000000,0.00000000
226.50000000,4.46850700,11.79000000,0.15229511,783.24724622,0.14175570,902.53197261,0.00110843,0.00000000,0.00000000,0.00000000,0.00000000,0.00000000,0.00000000,0.00000000,0.00000000
228.00000000,4.51832900,11.78840000,0.15413533,783.14095313,0.14335143,903.85064499,0.00104155,0.00000000,0.00000000,0.00000000,0.00000000,0.00000000,0.00000000,0.00000000,0.00000000
229.50000000,4.56936800,11.78840000,0.15597556,783.14095313,0.14494462,905.29179837,0.00097488,0.00000000,0.00000000,0.00000000,0.00000000,0.00000000,0.00000000,0.00000000,0.00000000
231.00000000,4.61925800,11.78690000,0.15781578,783.04130335,0.14653528,906.61757567,0.00103824,0.00000000,0.00000000,0.00000000,0.00000000,0.00000000,0.00000000,0.00000000,0.00000000
232.50000000,4.66985700,11.78690000,0.15973111,783.04130335,0.00000000,0.00000000,0.00000000,0.00000000,0.00000000,0.00000000,0.00000000,0.00000000,0.00000000,0.00000000,0.00000000
234.00000000,4.72153800,11.78370000,0.16168411,782.82871716,0.00000000,0.00000000,0.00000000,0.00000000,0.00000000,0.00000000,0.00000000,0.00000000,0.00000000,0.00000000,0.00000000
235.50000000,4.77291400,11.78210000,0.16363700,782.72242407,0.00000000,0.00000000,0.00000000,0.00000000,0.00000000,0.00000000,0.00000000,0.00000000,0.00000000,0.00000000,0.00000000
237.00000000,4.82476500,11.78450000,0.16562744,782.88186371,0.00000000,0.00000000,0.00000000,0.00000000,0.00000000,0.00000000,0.00000000,0.00000000,0.00000000,0.00000000,0.00000000
238.50000000,4.87651400,11.78290000,0.16761789,782.77557061,0.00000000,0.00000000,0.00000000,0.00000000,0.00000000,0.00000000,0.00000000,0.00000000,0.00000000,0.00000000,0.00000000
240.00000000,4.92870200,11.78130000,0.16957089,782.66927752,0.00000000,0.00000000,0.00000000,0.00000000,0.00000000,0.00000000,0.00000000,0.00000000,0.00000000,0.00000000,0.00000000
241.50000000,4.98160000,11.77650000,0.17167400,782.35039823,0.00000000,0.00000000,0.00000000,0.00000000,0.00000000,0.00000000,0.00000000,0.00000000,0.00000000,0.00000000,0.00000000
243.00000000,5.03449700,11.77490000,0.17370200,782.24410514,0.00000000,0.00000000,0.00000000,0.00000000,0.00000000,0.00000000,0.00000000,0.00000000,0.00000000,0.00000000,0.00000000
244.50000000,5.08786800,11.77170000,0.17580522,782.03151895,0.00000000,0.00000000,0.00000000,0.00000000,0.00000000,0.00000000,0.00000000,0.00000000,0.00000000,0.00000000,0.00000000
246.00000000,5.14110500,11.77090000,0.17787067,781.97837240,0.00000000,0.00000000,0.00000000,0.00000000,0.00000000,0.00000000,0.00000000,0.00000000,0.00000000,0.00000000,0.00000000
247.50000000,5.19542200,11.76690000,0.18004889,781.71263966,0.00000000,0.00000000,0.00000000,0.00000000,0.00000000,0.00000000,0.00000000,0.00000000,0.00000000,0.00000000,0.00000000
249.00000000,5.25041500,11.76210000,0.18226478,781.39376037,0.00000000,0.00000000,0.00000000,0.00000000,0.00000000,0.00000000,0.00000000,0.00000000,0.00000000,0.00000000,0.00000000
250.50000000,5.30483400,11.75500000,0.18440544,780.92208476,0.00000000,0.00000000,0.00000000,0.00000000,0.00000000,0.00000000,0.00000000,0.00000000,0.00000000,0.00000000,0.00000000
252.00000000,5.35986200,11.75260000,0.18665878,780.76264512,0.00000000,0.00000000,0.00000000,0.00000000,0.00000000,0.00000000,0.00000000,0.00000000,0.00000000,0.00000000,0.00000000
253.50000000,5.41546300,11.74540000,0.18887456,780.28432619,0.00000000,0.00000000,0.00000000,0.00000000,0.00000000,0.00000000,0.00000000,0.00000000,0.00000000,0.00000000,0.00000000
255.00000000,5.47157300,11.73980000,0.19109033,779.91230036,0.00000000,0.00000000,0.00000000,0.00000000,0.00000000,0.00000000,0.00000000,0.00000000,0.00000000,0.00000000,0.00000000
256.50000000,5.52768100,11.73740000,0.19338133,779.75286071,0.00000000,0.00000000,0.00000000,0.00000000,0.00000000,0.00000000,0.00000000,0.00000000,0.00000000,0.00000000,0.00000000
258.00000000,5.58396000,11.73180000,0.19563467,779.38083488,0.00000000,0.00000000,0.00000000,0.00000000,0.00000000,0.00000000,0.00000000,0.00000000,0.00000000,0.00000000,0.00000000
259.50000000,5.64165800,11.72150000,0.19796311,778.69657308,0.00000000,0.00000000,0.00000000,0.00000000,0.00000000,0.00000000,0.00000000,0.00000000,0.00000000,0.00000000,0.00000000
261.00000000,5.69891500,11.71670000,0.20017878,778.37769379,0.00000000,0.00000000,0.00000000,0.00000000,0.00000000,0.00000000,0.00000000,0.00000000,0.00000000,0.00000000,0.00000000
262.50000000,5.75627500,11.71030000,0.20239456,777.95252141,0.00000000,0.00000000,0.00000000,0.00000000,0.00000000,0.00000000,0.00000000,0.00000000,0.00000000,0.00000000,0.00000000
264.00000000,5.81434500,11.69750000,0.20468544,777.10217665,0.00000000,0.00000000,0.00000000,0.00000000,0.00000000,0.00000000,0.00000000,0.00000000,0.00000000,0.00000000,0.00000000
265.50000000,5.87309000,11.68960000,0.20690122,776.57735449,0.00000000,0.00000000,0.00000000,0.00000000,0.00000000,0.00000000,0.00000000,0.00000000,0.00000000,0.00000000,0.00000000
267.00000000,5.93197100,11.67280000,0.20907944,775.46127699,0.00000000,0.00000000,0.00000000,0.00000000,0.00000000,0.00000000,0.00000000,0.00000000,0.00000000,0.00000000,0.00000000
268.50000000,5.99108800,11.66240000,0.21122000,774.77037187,0.00000000,0.00000000,0.00000000,0.00000000,0.00000000,0.00000000,0.00000000,0.00000000,0.00000000,0.00000000,0.00000000
270.00000000,6.05030700,11.64650000,0.21324800,773.71408424,0.00000000,0.00000000,0.00000000,0.00000000,0.00000000,0.00000000,0.00000000,0.00000000,0.00000000,0.00000000,0.00000000
271.50000000,6.11013400,11.63050000,0.21523833,772.65115328,0.00000000,0.00000000,0.00000000,0.00000000,0.00000000,0.00000000,0.00000000,0.00000000,0.00000000,0.00000000,0.00000000
273.00000000,6.17070500,11.61300000,0.21715356,771.48857255,0.00000000,0.00000000,0.00000000,0.00000000,0.00000000,0.00000000,0.00000000,0.00000000,0.00000000,0.00000000,0.00000000
274.50000000,6.23097200,11.59630000,0.21891867,770.37913837,0.00000000,0.00000000,0.00000000,0.00000000,0.00000000,0.00000000,0.00000000,0.00000000,0.00000000,0.00000000,0.00000000
276.00000000,6.29117000,11.56910000,0.22068367,768.57215575,0.00000000,0.00000000,0.00000000,0.00000000,0.00000000,0.00000000,0.00000000,0.00000000,0.00000000,0.00000000,0.00000000
277.50000000,6.35248500,11.54360000,0.22222344,766.87810954,0.00000000,0.00000000,0.00000000,0.00000000,0.00000000,0.00000000,0.00000000,0.00000000,0.00000000,0.00000000,0.00000000
279.00000000,6.41383300,11.52050000,0.22372556,765.34350298,0.00000000,0.00000000,0.00000000,0.00000000,0.00000000,0.00000000,0.00000000,0.00000000,0.00000000,0.00000000,0.00000000
280.50000000,6.47595800,11.48380000,0.22500233,762.90540510,0.00000000,0.00000000,0.00000000,0.00000000,0.00000000,0.00000000,0.00000000,0.00000000,0.00000000,0.00000000,0.00000000
282.00000000,6.53717200,11.45510000,0.22620400,760.99877271,0.00000000,0.00000000,0.00000000,0.00000000,0.00000000,0.00000000,0.00000000,0.00000000,0.00000000,0.00000000,0.00000000
283.50000000,6.59912800,11.41680000,0.22733067,758.45438174,0.00000000,0.00000000,0.00000000,0.00000000,0.00000000,0.00000000,0.00000000,0.00000000,0.00000000,0.00000000,0.00000000
285.00000000,6.66172600,11.37380000,0.22819444,755.59775480,0.00000000,0.00000000,0.00000000,0.00000000,0.00000000,0.00000000,0.00000000,0.00000000,0.00000000,0.00000000,0.00000000
286.50000000,6.72476500,11.32750000,0.22894544,752.52189835,0.00000000,0.00000000,0.00000000,0.00000000,0.00000000,0.00000000,0.00000000,0.00000000,0.00000000,0.00000000,0.00000000
288.00000000,6.78800500,11.27250000,0.22962144,748.86807320,0.00000000,0.00000000,0.00000000,0.00000000,0.00000000,0.00000000,0.00000000,0.00000000,0.00000000,0.00000000,0.00000000
289.50000000,6.85168600,11.21830000,0.23014722,745.26739460,0.00000000,0.00000000,0.00000000,0.00000000,0.00000000,0.00000000,0.00000000,0.00000000,0.00000000,0.00000000,0.00000000
291.00000000,6.91577100,11.14570000,0.23048522,740.44434540,0.00000000,0.00000000,0.00000000,0.00000000,0.00000000,0.00000000,0.00000000,0.00000000,0.00000000,0.00000000,0.00000000
292.50000000,6.98093600,11.07470000,0.23078578,735.72758929,0.00000000,0.00000000,0.00000000,0.00000000,0.00000000,0.00000000,0.00000000,0.00000000,0.00000000,0.00000000,0.00000000
294.00000000,7.04630500,10.98060000,0.23093600,729.47622662,0.00000000,0.00000000,0.00000000,0.00000000,0.00000000,0.00000000,0.00000000,0.00000000,0.00000000,0.00000000,0.00000000
295.50000000,7.11272100,10.88330000,0.23097356,723.01227776,0.00000000,0.00000000,0.00000000,0.00000000,0.00000000,0.00000000,0.00000000,0.00000000,0.00000000,0.00000000,0.00000000
297.00000000,7.18075700,10.76130000,0.23101111,714.90742924,0.00000000,0.00000000,0.00000000,0.00000000,0.00000000,0.00000000,0.00000000,0.00000000,0.00000000,0.00000000,0.00000000
298.50000000,7.25162900,10.60420000,0.23093600,704.47077595,0.00000000,0.00000000,0.00000000,0.00000000,0.00000000,0.00000000,0.00000000,0.00000000,0.00000000,0.00000000,0.00000000