File: polyN_optimization/results_exp/DP780/UT_45_2.csv
Time[s],Displacement[mm],Force[kN],EngStrain_longi,EngStress[MPa],TrueStrain,TrueStress[MPa],TrueStrainRate[1/s],PlasticStrain_longi,PlasticStress[MPa],PlasticStrain_thick,PlasticStrain_width,R-Value,Thickness[mm],Width[mm], Young's Modulus [MPa]
0.00000000,0.00000000,-0.01900000,0.00000000,-1.26692502,0.00000000,-1.26692502,0.00000000,0.00051667,414.74983430,0.00034155,-0.00085822,0.86269569,1.50770000,9.94690000,214741.74190678
1.50000000,0.00263100,0.34790000,0.00010178,23.19806399,0.00010177,23.20042504,0.00009733,0.00069251,427.32412888,0.00009178,-0.00078429,0.00000000,0.00000000,0.00000000,0.00000000
3.00000000,0.00439400,0.68520000,0.00013711,45.68931718,0.00013710,45.69558169,0.00007888,0.00098131,439.84689839,0.00009245,-0.00107376,0.00000000,0.00000000,0.00000000,0.00000000
4.50000000,0.00620600,1.03690000,0.00020622,69.14076617,0.00020620,69.15502454,-0.00000600,0.00121659,451.77076697,-0.00002017,-0.00119642,0.00000000,0.00000000,0.00000000,0.00000000
6.00000000,0.00843800,1.34630000,0.00024978,89.77163999,0.00024975,89.79406295,-0.00009620,0.00146330,462.74103532,-0.00032017,-0.00114312,0.00000000,0.00000000,0.00000000,0.00000000
7.50000000,0.01098600,1.63500000,0.00032422,109.02223232,0.00032417,109.05757975,0.00003066,0.00179593,474.61084252,-0.00031562,-0.00148031,0.00000000,0.00000000,0.00000000,0.00000000
9.00000000,0.01325300,1.92370000,0.00045467,128.27282466,0.00045456,128.33114604,0.00017504,0.00213163,484.99427438,-0.00044376,-0.00168787,0.00000000,0.00000000,0.00000000,0.00000000
10.50000000,0.01482200,2.18530000,0.00051300,145.71638183,0.00051287,145.79113434,0.00018636,0.00242482,495.58617535,-0.00065808,-0.00176675,0.00000000,0.00000000,0.00000000,0.00000000
12.00000000,0.01654500,2.44280000,0.00051356,162.88654992,0.00051342,162.97020121,0.00003620,0.00295967,506.35498902,-0.00098273,-0.00197694,0.00000000,0.00000000,0.00000000,0.00000000
13.50000000,0.01815300,2.70760000,0.00058311,180.54348394,0.00058294,180.64876085,-0.00003420,0.00354091,516.03059077,-0.00129487,-0.00224604,0.00000000,0.00000000,0.00000000,0.00000000
15.00000000,0.02075300,2.94840000,0.00064511,196.60009161,0.00064490,196.72692051,-0.00016589,0.00391901,525.18726528,-0.00137352,-0.00254549,0.00000000,0.00000000,0.00000000,0.00000000
16.50000000,0.02371100,3.18210000,0.00080300,212.18326940,0.00080268,212.35365257,-0.00000444,0.00441435,534.73752237,-0.00158091,-0.00283344,0.00000000,0.00000000,0.00000000,0.00000000
18.00000000,0.02615100,3.44290000,0.00089356,229.57348236,0.00089316,229.77861902,0.00022070,0.00502834,543.55436501,-0.00196616,-0.00306219,0.00000000,0.00000000,0.00000000,0.00000000
19.50000000,0.02804400,3.67170000,0.00091100,244.82992686,0.00091059,245.05296692,0.00018784,0.00558444,551.91910732,-0.00221694,-0.00336750,0.00000000,0.00000000,0.00000000,0.00000000
21.00000000,0.03028500,3.90460000,0.00091856,260.35976044,0.00091813,260.59891535,-0.00000733,0.00616991,560.31015332,-0.00246712,-0.00370279,0.00000000,0.00000000,0.00000000,0.00000000
22.50000000,0.03303300,4.14230000,0.00108422,276.20965930,0.00108363,276.50913195,-0.00011964,0.00688430,568.83904326,-0.00281649,-0.00406782,0.00000000,0.00000000,0.00000000,0.00000000
24.00000000,0.03574700,4.36400000,0.00126500,290.99267392,0.00126420,291.36077965,0.00015781,0.00761509,576.20771626,-0.00322568,-0.00438941,0.00000000,0.00000000,0.00000000,0.00000000
25.50000000,0.03873000,4.57690000,0.00132500,305.18890221,0.00132412,305.59327751,0.00036022,0.00829255,584.52300118,-0.00359017,-0.00470238,0.00000000,0.00000000,0.00000000,0.00000000
27.00000000,0.04286000,4.80580000,0.00130689,320.45201474,0.00130604,320.87080991,0.00000044,0.00897724,591.99493963,-0.00402841,-0.00494883,0.00000000,0.00000000,0.00000000,0.00000000
28.50000000,0.04635400,5.01390000,0.00144578,334.32817776,0.00144473,334.81154201,-0.00025517,0.00978283,598.89993567,-0.00448104,-0.00530179,0.00000000,0.00000000,0.00000000,0.00000000
30.00000000,0.04899300,5.21330000,0.00172033,347.62422249,0.00171886,348.22225202,0.00023272,0.01051812,606.42406505,-0.00488682,-0.00563130,0.00000000,0.00000000,0.00000000,0.00000000
31.50000000,0.05434600,5.43660000,0.00179933,362.51392553,0.00179772,363.16620892,0.00033742,0.01122088,612.85420511,-0.00526623,-0.00595466,0.00000000,0.00000000,0.00000000,0.00000000
33.00000000,0.05985800,5.62950000,0.00184456,375.37654854,0.00184286,376.06895144,-0.00002950,0.01201081,619.51054717,-0.00567235,-0.00633846,0.00000000,0.00000000,0.00000000,0.00000000
34.50000000,0.06466300,5.82250000,0.00209633,388.24583957,0.00209414,389.05973227,-0.00015012,0.01279513,626.44569811,-0.00606169,-0.00673343,0.00000000,0.00000000,0.00000000,0.00000000
36.00000000,0.07068600,6.02270000,0.00238922,401.59522851,0.00238637,402.55472875,0.00032237,0.01357405,632.78997665,-0.00643320,-0.00714084,0.00000000,0.00000000,0.00000000,0.00000000
37.50000000,0.07653200,6.20450000,0.00249478,413.71770058,0.00249167,414.74983430,0.00025494,0.01433054,639.07532058,-0.00677060,-0.00755994,0.00000000,0.00000000,0.00000000,0.00000000
39.00000000,0.08346800,6.39110000,0.00273111,426.16023792,0.00272739,427.32412888,-0.00002260,0.01519422,645.17392580,-0.00721877,-0.00797545,0.00000000,0.00000000,0.00000000,0.00000000
40.50000000,0.09279600,6.57610000,0.00308056,438.49608684,0.00307582,439.84689839,0.00013492,0.01604904,651.43396989,-0.00770736,-0.00834168,0.00000000,0.00000000,0.00000000,0.00000000
42.00000000,0.10154900,6.75240000,0.00337356,450.25181745,0.00336788,451.77076697,0.00023190,0.01687377,656.87270194,-0.00815311,-0.00872066,0.00000000,0.00000000,0.00000000,0.00000000
43.50000000,0.11213200,6.91430000,0.00367356,461.04735226,0.00366682,462.74103532,0.00026172,0.01775486,662.68555969,-0.00867086,-0.00908400,0.00000000,0.00000000,0.00000000,0.00000000
45.00000000,0.12331700,7.08890000,0.00406422,472.68972643,0.00405599,474.61084252,0.00030700,0.01865879,668.18877077,-0.00913867,-0.00952011,0.00000000,0.00000000,0.00000000,0.00000000
46.50000000,0.13487000,7.24120000,0.00445100,482.84513070,0.00444112,484.99427438,0.00033609,0.01956690,673.38286617,-0.00967833,-0.00988857,0.00000000,0.00000000,0.00000000,0.00000000
48.00000000,0.14892600,7.39680000,0.00479622,493.22057984,0.00478476,495.58617535,0.00006701,0.02045006,679.00751873,-0.01012137,-0.01032869,0.00000000,0.00000000,0.00000000,0.00000000
49.50000000,0.16217400,7.55310000,0.00538533,503.64270517,0.00537088,506.35498902,0.00021618,0.02137646,683.84878059,-0.01058362,-0.01079284,0.00000000,0.00000000,0.00000000,0.00000000
51.00000000,0.17832800,7.69260000,0.00601622,512.94460206,0.00599820,516.03059077,0.00068688,0.02233354,688.99439793,-0.01108058,-0.01125296,0.00000000,0.00000000,0.00000000,0.00000000
52.50000000,0.19478200,7.82580000,0.00644056,521.82641328,0.00641990,525.18726528,0.00057483,0.02329055,693.92959139,-0.01159980,-0.01169075,0.00000000,0.00000000,0.00000000,0.00000000
54.00000000,0.21302400,7.96380000,0.00698500,531.02828977,0.00696072,534.73752237,0.00024607,0.02421878,698.57856727,-0.01207443,-0.01214435,0.00000000,0.00000000,0.00000000,0.00000000
55.50000000,0.23106900,8.08980000,0.00764578,539.43000308,0.00761670,543.55436501,0.00036502,0.02513964,703.06537665,-0.01256400,-0.01257564,0.00000000,0.00000000,0.00000000,0.00000000
57.00000000,0.25070200,8.20940000,0.00824644,547.40496271,0.00821263,551.91910732,0.00042432,0.02612693,707.93797659,-0.01311271,-0.01301423,0.00000000,0.00000000,0.00000000,0.00000000
58.50000000,0.27023600,8.32900000,0.00887722,555.37992233,0.00883805,560.31015332,0.00026808,0.02712968,712.45140006,-0.01364199,-0.01348769,0.00000000,0.00000000,0.00000000,0.00000000
60.00000000,0.29091900,8.44940000,0.00963922,563.40822617,0.00959306,568.83904326,0.00025269,0.02810429,716.50428442,-0.01416876,-0.01393553,0.00000000,0.00000000,0.00000000,0.00000000
61.50000000,0.31234600,8.55230000,0.01041278,570.26962538,0.01035894,576.20771626,0.00051295,0.02910900,720.91810375,-0.01473372,-0.01437528,0.00000000,0.00000000,0.00000000,0.00000000
63.00000000,0.33488700,8.66950000,0.01113756,578.08455237,0.01107599,584.52300118,0.00055721,0.03012993,724.75005631,-0.01532527,-0.01480466,0.00000000,0.00000000,0.00000000,0.00000000
64.50000000,0.35776600,8.77400000,0.01186611,585.05264000,0.01179626,591.99493963,0.00047531,0.03113366,728.90220880,-0.01589233,-0.01524133,0.00000000,0.00000000,0.00000000,0.00000000
66.00000000,0.38128800,8.86890000,0.01271489,591.38059709,0.01263473,598.89993567,0.00059343,0.03217977,733.10023855,-0.01647869,-0.01570108,0.00000000,0.00000000,0.00000000,0.00000000
67.50000000,0.40450600,8.97340000,0.01349611,598.34868472,0.01340585,606.42406505,0.00074870,0.03314717,736.85253737,-0.01698550,-0.01616167,0.00000000,0.00000000,0.00000000,0.00000000
69.00000000,0.42857100,9.06190000,0.01423967,604.24988812,0.01413923,612.85420511,0.00062980,0.03420753,740.63199312,-0.01753532,-0.01667221,0.00000000,0.00000000,0.00000000,0.00000000
70.50000000,0.45277000,9.15280000,0.01507333,610.31112416,0.01496086,619.51054717,0.00053271,0.03528134,744.37316708,-0.01812883,-0.01715252,0.00000000,0.00000000,0.00000000,0.00000000
72.00000000,0.47842300,9.24770000,0.01590333,616.63908125,0.01577820,626.44569811,0.00064343,0.03627146,747.99614809,-0.01859634,-0.01767512,0.00000000,0.00000000,0.00000000,0.00000000
73.50000000,0.50363700,9.33380000,0.01672567,622.38025202,0.01658733,632.78997665,0.00067221,0.03735403,751.70241193,-0.01913690,-0.01821713,0.00000000,0.00000000,0.00000000,0.00000000
75.00000000,0.52996600,9.41910000,0.01752556,628.06807857,0.01737375,639.07532058,0.00040582,0.03839990,755.27646867,-0.01971563,-0.01868427,0.00000000,0.00000000,0.00000000,0.00000000
76.50000000,0.55568700,9.50050000,0.01843433,633.49585210,0.01826648,645.17392580,0.00047922,0.03949700,758.44914989,-0.02029513,-0.01920187,0.00000000,0.00000000,0.00000000,0.00000000
78.00000000,0.58296200,9.58420000,0.01933567,639.07699023,0.01915111,651.43396989,0.00056733,0.04053129,761.69188552,-0.02079895,-0.01973234,0.00000000,0.00000000,0.00000000,0.00000000
79.50000000,0.60996800,9.65600000,0.02020311,643.86463321,0.02000174,656.87270194,0.00048580,0.04162332,765.42608553,-0.02140416,-0.02021915,0.00000000,0.00000000,0.00000000,0.00000000
81.00000000,0.63802000,9.73260000,0.02113067,648.97234147,0.02091051,662.68555969,0.00051475,0.04272099,768.44997430,-0.02202626,-0.02069473,0.00000000,0.00000000,0.00000000,0.00000000
82.50000000,0.66587100,9.80430000,0.02208089,653.75331643,0.02184064,668.18877077,0.00049252,0.04379529,771.62999193,-0.02259827,-0.02119702,0.00000000,0.00000000,0.00000000,0.00000000
84.00000000,0.69456600,9.87130000,0.02303478,658.22089414,0.02277348,673.38286617,0.00063872,0.04488170,774.99409752,-0.02318024,-0.02170146,0.00000000,0.00000000,0.00000000,0.00000000
85.50000000,0.72346400,9.94470000,0.02396611,663.11522555,0.02368343,679.00751873,0.00049878,0.04600194,777.77215050,-0.02382997,-0.02217197,0.00000000,0.00000000,0.00000000,0.00000000
87.00000000,0.75273400,10.00610000,0.02493878,667.20939379,0.02463288,683.84878059,0.00052042,0.04712723,780.72849134,-0.02445508,-0.02267214,0.00000000,0.00000000,0.00000000,0.00000000
88.50000000,0.78217500,10.07150000,0.02594533,671.57028308,0.02561446,688.99439793,0.00061525,0.04820916,784.27686580,-0.02500430,-0.02320486,0.00000000,0.00000000,0.00000000,0.00000000
90.00000000,0.81188400,10.13370000,0.02695178,675.71779553,0.02659498,693.92959139,0.00065837,0.04938354,786.83236718,-0.02563504,-0.02374850,0.00000000,0.00000000,0.00000000,0.00000000
91.50000000,0.84196600,10.19190000,0.02792822,679.59858692,0.02754534,698.57856727,0.00064304,0.05052692,789.65801521,-0.02626300,-0.02426392,0.00000000,0.00000000,0.00000000,0.00000000
93.00000000,0.87218400,10.24770000,0.02889722,683.31934567,0.02848757,703.06537665,0.00060613,0.05161923,792.44147335,-0.02682144,-0.02479779,0.00000000,0.00000000,0.00000000,0.00000000
94.50000000,0.90331400,10.30830000,0.02993744,687.36016969,0.02949807,707.93797659,0.00056883,0.05276409,795.15876089,-0.02744014,-0.02532394,0.00000000,0.00000000,0.00000000,0.00000000
96.00000000,0.93461400,10.36340000,0.03099289,691.03425226,0.03052231,712.45140006,0.00067778,0.05391566,797.65976512,-0.02807159,-0.02584407,0.00000000,0.00000000,0.00000000,0.00000000
97.50000000,0.96564300,10.41200000,0.03201811,694.27491311,0.03151622,716.50428442,0.00068421,0.05507451,800.56895777,-0.02871520,-0.02635932,0.00000000,0.00000000,0.00000000,0.00000000
99.00000000,0.99714400,10.46540000,0.03307722,697.83563923,0.03254194,720.91810375,0.00069814,0.05620808,803.29291654,-0.02926339,-0.02694469,0.00000000,0.00000000,0.00000000,0.00000000
100.50000000,1.02966100,10.51010000,0.03415133,700.81624705,0.03358112,724.75005631,0.00075546,0.05741211,805.80156678,-0.02992953,-0.02748258,0.00000000,0.00000000,0.00000000,0.00000000
102.00000000,1.06163700,10.55950000,0.03521033,704.11025212,0.03460463,728.90220880,0.00071109,0.05857590,808.27536960,-0.03055371,-0.02802219,0.00000000,0.00000000,0.00000000,0.00000000
103.50000000,1.09388200,10.60900000,0.03631456,707.41092520,0.03567072,733.10023855,0.00075388,0.05975117,811.04857843,-0.03116993,-0.02858124,0.00000000,0.00000000,0.00000000,0.00000000
105.00000000,1.12670300,10.65280000,0.03733611,710.33152079,0.03665600,736.85253737,0.00063720,0.06092079,813.20129349,-0.03181755,-0.02910324,0.00000000,0.00000000,0.00000000,0.00000000
106.50000000,1.15979400,10.69590000,0.03845533,713.20544018,0.03773435,740.63199312,0.00074505,0.06211468,815.88554154,-0.03251044,-0.02960424,0.00000000,0.00000000,0.00000000,0.00000000
108.00000000,1.19291900,10.73820000,0.03958956,716.02601537,0.03882598,744.37316708,0.00075151,0.06328607,817.81920898,-0.03312836,-0.03015771,0.00000000,0.00000000,0.00000000,0.00000000
109.50000000,1.22692200,10.77960000,0.04063733,718.78657831,0.03983335,747.99614809,0.00067128,0.06447084,820.33359460,-0.03374940,-0.03072143,0.00000000,0.00000000,0.00000000,0.00000000
111.00000000,1.26079000,10.82110000,0.04178289,721.55380929,0.04093356,751.70241193,0.00077894,0.06565497,822.68008927,-0.03441745,-0.03123752,0.00000000,0.00000000,0.00000000,0.00000000
112.50000000,1.29398200,10.86100000,0.04289078,724.21435184,0.04199645,755.27646867,0.00062656,0.06685856,825.05434080,-0.03501952,-0.03183904,0.00000000,0.00000000,0.00000000,0.00000000
114.00000000,1.32845900,10.89450000,0.04405133,726.44814069,0.04310866,758.44914989,0.00084901,0.06803371,827.22968986,-0.03565627,-0.03237744,0.00000000,0.00000000,0.00000000,0.00000000
115.50000000,1.36290200,10.92960000,0.04514789,728.78861798,0.04415840,761.69188552,0.00073304,0.06925606,829.45556394,-0.03633724,-0.03291882,0.00000000,0.00000000,0.00000000,0.00000000
117.00000000,1.39805400,10.97100000,0.04630844,731.54918092,0.04526820,765.42608553,0.00068209,0.07045229,831.71436039,-0.03696700,-0.03348530,0.00000000,0.00000000,0.00000000,0.00000000
118.50000000,1.43263200,11.00210000,0.04747267,733.62293715,0.04638028,768.44997430,0.00075307,0.07168013,833.60674604,-0.03761969,-0.03406045,0.00000000,0.00000000,0.00000000,0.00000000
120.00000000,1.46825800,11.03560000,0.04861444,735.85672600,0.04746972,771.62999193,0.00073804,0.07287742,835.75888326,-0.03829852,-0.03457890,0.00000000,0.00000000,0.00000000,0.00000000
121.50000000,1.50415400,11.07150000,0.04977111,738.25054750,0.04857215,774.99409752,0.00067963,0.07412886,837.90990079,-0.03895657,-0.03517229,0.00000000,0.00000000,0.00000000,0.00000000
123.00000000,1.53927200,11.09860000,0.05096167,740.05758266,0.04970562,777.77215050,0.00065052,0.07537288,839.81959699,-0.03966575,-0.03570713,0.00000000,0.00000000,0.00000000,0.00000000
124.50000000,1.57520300,11.12810000,0.05215978,742.02465046,0.05084498,780.72849134,0.00079260,0.07661054,842.02494010,-0.04032119,-0.03628935,0.00000000,0.00000000,0.00000000,0.00000000
126.00000000,1.61150500,11.16640000,0.05331656,744.57850459,0.05194381,784.27686580,0.00074192,0.07785220,843.77285837,-0.04097051,-0.03688169,0.00000000,0.00000000,0.00000000,0.00000000
127.50000000,1.64774000,11.18950000,0.05456711,746.11881870,0.05313036,786.83236718,0.00069108,0.07908748,845.80216397,-0.04168164,-0.03740584,0.00000000,0.00000000,0.00000000,0.00000000
129.00000000,1.68492000,11.21670000,0.05578778,747.93252189,0.05428720,789.65801521,0.00077577,0.08031781,847.83830134,-0.04233370,-0.03798411,0.00000000,0.00000000,0.00000000,0.00000000
130.50000000,1.72125500,11.24380000,0.05695567,749.73955706,0.05539276,792.44147335,0.00077470,0.08158694,850.07906807,-0.04301585,-0.03857110,0.00000000,0.00000000,0.00000000,0.00000000
132.00000000,1.75840300,11.26930000,0.05818011,751.43990380,0.05655056,795.15876089,0.00073830,0.08280817,851.93997274,-0.04367418,-0.03913398,0.00000000,0.00000000,0.00000000,0.00000000
133.50000000,1.79571900,11.29160000,0.05941200,752.92687370,0.05771404,797.65976512,0.00068792,0.08408415,853.50014236,-0.04437229,-0.03971186,0.00000000,0.00000000,0.00000000,0.00000000
135.00000000,1.83300100,11.31950000,0.06065511,754.78725307,0.05888675,800.56895777,0.00077221,0.08534700,855.33719800,-0.04500092,-0.04034608,0.00000000,0.00000000,0.00000000,0.00000000
136.50000000,1.87038500,11.34500000,0.06187189,756.48759981,0.06003328,803.29291654,0.00074285,0.08658471,857.04594756,-0.04564194,-0.04094276,0.00000000,0.00000000,0.00000000,0.00000000
138.00000000,1.90807300,11.36660000,0.06316389,757.92789353,0.06124926,805.80156678,0.00078440,0.08784088,858.89101417,-0.04632691,-0.04151398,0.00000000,0.00000000,0.00000000,0.00000000
139.50000000,1.94616600,11.38810000,0.06441444,759.36151921,0.06242483,808.27536960,0.00079037,0.08911621,861.39536150,-0.04699473,-0.04212148,0.00000000,0.00000000,0.00000000,0.00000000
141.00000000,1.98402400,11.41360000,0.06568022,761.06186595,0.06361330,811.04857843,0.00074729,0.09040607,862.68835936,-0.04770203,-0.04270403,0.00000000,0.00000000,0.00000000,0.00000000
142.50000000,2.02255600,11.43040000,0.06693833,762.18209440,0.06479318,813.20129349,0.00072536,0.09168950,864.21350332,-0.04839559,-0.04329392,0.00000000,0.00000000,0.00000000,0.00000000
144.00000000,2.06048000,11.45430000,0.06822656,763.77575272,0.06599985,815.88554154,0.00075966,0.09293677,865.82776529,-0.04902682,-0.04390995,0.00000000,0.00000000,0.00000000,0.00000000
145.50000000,2.09908100,11.46790000,0.06948844,764.68260431,0.06718044,817.81920898,0.00074463,0.09422873,867.77178159,-0.04972901,-0.04449972,0.00000000,0.00000000,0.00000000,0.00000000
147.00000000,2.13798600,11.48940000,0.07076911,766.11623000,0.06837719,820.33359460,0.00075080,0.09555014,869.57498315,-0.05047919,-0.04507095,0.00000000,0.00000000,0.00000000,0.00000000
148.50000000,2.17685700,11.50850000,0.07204978,767.38982305,0.06957250,822.68008927,0.00077769,0.09681935,871.27652528,-0.05115864,-0.04566071,0.00000000,0.00000000,0.00000000,0.00000000
150.00000000,2.21643800,11.52770000,0.07335300,768.67008412,0.07078739,825.05434080,0.00076286,0.09813200,872.78174689,-0.05190373,-0.04622826,0.00000000,0.00000000,0.00000000,0.00000000
151.50000000,2.25547900,11.54440000,0.07462622,769.78364454,0.07197290,827.22968986,0.00076196,0.09941600,874.25686078,-0.05257155,-0.04684445,0.00000000,0.00000000,0.00000000,0.00000000
153.00000000,2.29472200,11.56120000,0.07595200,770.90387298,0.07320585,829.45556394,0.00083086,0.10076047,876.15191540,-0.05333061,-0.04742986,0.00000000,0.00000000,0.00000000,0.00000000
154.50000000,2.33423600,11.57870000,0.07725144,772.07077761,0.07441284,831.71436039,0.00084389,0.10204092,877.63664065,-0.05398026,-0.04806067,0.00000000,0.00000000,0.00000000,0.00000000
156.00000000,2.37381600,11.59070000,0.07858467,772.87094078,0.07564969,833.60674604,0.00084285,0.10335640,879.21431597,-0.05465659,-0.04869981,0.00000000,0.00000000,0.00000000,0.00000000
157.50000000,2.41380400,11.60660000,0.07988789,773.93115699,0.07685723,835.75888326,0.00082783,0.10467911,881.03996341,-0.05539807,-0.04928103,0.00000000,0.00000000,0.00000000,0.00000000
159.00000000,2.45399300,11.62180000,0.08125122,774.94469701,0.07811891,837.90990079,0.00091026,0.10604162,882.59768241,-0.05612415,-0.04991748,0.00000000,0.00000000,0.00000000,0.00000000
160.50000000,2.49462200,11.63370000,0.08260700,775.73819215,0.07937202,839.81959699,0.00092288,0.10733282,883.92251392,-0.05680542,-0.05052740,0.00000000,0.00000000,0.00000000,0.00000000
162.00000000,2.53548800,11.64970000,0.08395911,776.80507638,0.08062018,842.02494010,0.00090799,0.10867158,885.47151473,-0.05751548,-0.05115611,0.00000000,0.00000000,0.00000000,0.00000000
163.50000000,2.57618400,11.65930000,0.08531489,777.44520692,0.08187017,843.77285837,0.00089989,0.11002771,887.21872929,-0.05827254,-0.05175517,0.00000000,0.00000000,0.00000000,0.00000000
165.00000000,2.61725300,11.67280000,0.08666689,778.34539049,0.08311511,845.80216397,0.00089181,0.11133047,888.56062260,-0.05896626,-0.05236420,0.00000000,0.00000000,0.00000000,0.00000000
166.50000000,2.65795000,11.68640000,0.08801522,779.25224209,0.08435514,847.83830134,0.00087007,0.11272701,890.16900020,-0.05973243,-0.05299458,0.00000000,0.00000000,0.00000000,0.00000000
168.00000000,2.69986300,11.70230000,0.08940856,780.31245829,0.08563494,850.07906807,0.00095161,0.11409180,891.75171582,-0.06044928,-0.05364253,0.00000000,0.00000000,0.00000000,0.00000000
169.50000000,2.74110100,11.71350000,0.09074944,781.05927725,0.08686502,851.93997274,0.00079900,0.11544149,893.31601548,-0.06118345,-0.05425804,0.00000000,0.00000000,0.00000000,0.00000000
171.00000000,2.78277800,11.71990000,0.09215022,781.48603095,0.08814843,853.50014236,0.00081182,0.11684604,894.81885413,-0.06196368,-0.05488236,0.00000000,0.00000000,0.00000000,0.00000000
172.50000000,2.82421800,11.73020000,0.09353989,782.17283767,0.08942004,855.33719800,0.00083132,0.11823577,896.25026970,-0.06268507,-0.05555070,0.00000000,0.00000000,0.00000000,0.00000000
174.00000000,2.86667300,11.73900000,0.09490311,782.75962400,0.09066588,857.04594756,0.00080957,0.11962374,897.62172169,-0.06342324,-0.05620050,0.00000000,0.00000000,0.00000000,0.00000000
175.50000000,2.90909300,11.74940000,0.09628900,783.45309875,0.09193084,858.89101417,0.00078807,0.12100890,899.17490370,-0.06417185,-0.05683705,0.00000000,0.00000000,0.00000000,0.00000000
177.00000000,2.95066800,11.76850000,0.09770111,784.72669180,0.09321809,861.39536150,0.00076639,0.12239337,900.48682077,-0.06488202,-0.05751135,0.00000000,0.00000000,0.00000000,0.00000000
178.50000000,2.99359500,11.77090000,0.09912467,784.88672443,0.09451411,862.68835936,0.00082042,0.12384016,902.16159467,-0.06572981,-0.05811036,0.00000000,0.00000000,0.00000000,0.00000000
180.00000000,3.03591500,11.77650000,0.10054422,785.26013391,0.09580480,864.21350332,0.00088743,0.12525411,903.38263562,-0.06646079,-0.05879332,0.00000000,0.00000000,0.00000000,0.00000000
181.50000000,3.07904500,11.78370000,0.10192622,785.74023181,0.09705976,865.82776529,0.00084516,0.12669856,904.69411776,-0.06726338,-0.05943518,0.00000000,0.00000000,0.00000000,0.00000000
183.00000000,3.12210800,11.79480000,0.10336100,786.48038275,0.09836098,867.77178159,0.00087832,0.12813936,906.31000789,-0.06810109,-0.06003827,0.00000000,0.00000000,0.00000000,0.00000000
184.50000000,3.16530500,11.80360000,0.10482944,787.06716908,0.09969097,869.57498315,0.00091116,0.12948177,907.47150615,-0.06874423,-0.06073754,0.00000000,0.00000000,0.00000000,0.00000000
186.00000000,3.20850400,11.81160000,0.10624156,787.60061119,0.10096828,871.27652528,0.00082177,0.13098414,909.08717168,-0.06954749,-0.06143665,0.00000000,0.00000000,0.00000000,0.00000000
187.50000000,3.25187000,11.81640000,0.10770256,787.92067646,0.10228810,872.78174689,0.00085460,0.13242143,910.15471231,-0.07029918,-0.06212224,0.00000000,0.00000000,0.00000000,0.00000000
189.00000000,3.29547300,11.82110000,0.10913356,788.23407370,0.10357913,874.25686078,0.00084689,0.13388658,911.80261871,-0.07106939,-0.06281719,0.00000000,0.00000000,0.00000000,0.00000000
190.50000000,3.34005700,11.83070000,0.11063578,788.87420424,0.10493262,876.15191540,0.00096745,0.13538374,913.11310689,-0.07194887,-0.06343486,0.00000000,0.00000000,0.00000000,0.00000000
192.00000000,3.38389800,11.83550000,0.11206667,789.19426951,0.10622015,877.63664065,0.00089843,0.13687903,914.36206281,-0.07273195,-0.06414708,0.00000000,0.00000000,0.00000000,0.00000000
193.50000000,3.42814400,11.84110000,0.11353889,789.56767899,0.10754313,879.21431597,0.00090403,0.13833984,915.51922315,-0.07352360,-0.06481625,0.00000000,0.00000000,0.00000000,0.00000000
195.00000000,3.47188300,11.84990000,0.11502244,790.15446532,0.10887453,881.03996341,0.00088269,0.00000000,0.00000000,0.00000000,0.00000000,0.00000000,0.00000000,0.00000000,0.00000000
196.50000000,3.51690500,11.85460000,0.11655100,790.46786256,0.11024447,882.59768241,0.00096889,0.00000000,0.00000000,0.00000000,0.00000000,0.00000000,0.00000000,0.00000000,0.00000000
198.00000000,3.56162500,11.85700000,0.11800067,790.62789520,0.11154197,883.92251392,0.00087358,0.00000000,0.00000000,0.00000000,0.00000000,0.00000000,0.00000000,0.00000000,0.00000000
199.50000000,3.60658000,11.86180000,0.11950667,790.94796047,0.11288811,885.47151473,0.00093952,0.00000000,0.00000000,0.00000000,0.00000000,0.00000000,0.00000000,0.00000000,0.00000000
201.00000000,3.65143400,11.86900000,0.12103522,791.42805837,0.11425256,887.21872929,0.00097830,0.00000000,0.00000000,0.00000000,0.00000000,0.00000000,0.00000000,0.00000000,0.00000000
202.50000000,3.69720100,11.87140000,0.12250378,791.58809100,0.11556171,888.56062260,0.00083006,0.00000000,0.00000000,0.00000000,0.00000000,0.00000000,0.00000000,0.00000000,0.00000000
204.00000000,3.74371100,11.87620000,0.12408111,791.90815627,0.11696591,890.16900020,0.00093570,0.00000000,0.00000000,0.00000000,0.00000000,0.00000000,0.00000000,0.00000000,0.00000000
205.50000000,3.78951200,11.88100000,0.12562478,792.22822154,0.11833824,891.75171582,0.00093442,0.00000000,0.00000000,0.00000000,0.00000000,0.00000000,0.00000000,0.00000000,0.00000000
207.00000000,3.83538000,11.88570000,0.12715344,792.54161879,0.11969538,893.31601548,0.00088680,0.00000000,0.00000000,0.00000000,0.00000000,0.00000000,0.00000000,0.00000000,0.00000000
208.50000000,3.88199200,11.88890000,0.12874578,792.75499563,0.12110709,894.81885413,0.00095862,0.00000000,0.00000000,0.00000000,0.00000000,0.00000000,0.00000000,0.00000000,0.00000000
210.00000000,3.92890900,11.89130000,0.13032322,792.91502827,0.12250363,896.25026970,0.00099721,0.00000000,0.00000000,0.00000000,0.00000000,0.00000000,0.00000000,0.00000000,0.00000000
211.50000000,3.97541900,11.89290000,0.13190056,793.02171669,0.12389813,897.62172169,0.00092923,0.00000000,0.00000000,0.00000000,0.00000000,0.00000000,0.00000000,0.00000000,0.00000000
213.00000000,4.02331500,11.89690000,0.13347789,793.28843775,0.12529068,899.17490370,0.00099424,0.00000000,0.00000000,0.00000000,0.00000000,0.00000000,0.00000000,0.00000000,0.00000000
214.50000000,4.07029800,11.89770000,0.13505533,793.34178196,0.12668140,900.48682077,0.00086045,0.00000000,0.00000000,0.00000000,0.00000000,0.00000000,0.00000000,0.00000000,0.00000000
216.00000000,4.11809300,11.90250000,0.13670778,793.66184723,0.12813617,902.16159467,0.00092530,0.00000000,0.00000000,0.00000000,0.00000000,0.00000000,0.00000000,0.00000000,0.00000000
217.50000000,4.16544900,11.90170000,0.13832278,793.60850302,0.12955593,903.38263562,0.00099001,0.00000000,0.00000000,0.00000000,0.00000000,0.00000000,0.00000000,0.00000000,0.00000000
219.00000000,4.21371700,11.90170000,0.13997533,793.60850302,0.13100662,904.69411776,0.00098857,0.00000000,0.00000000,0.00000000,0.00000000,0.00000000,0.00000000,0.00000000,0.00000000
220.50000000,4.26205200,11.90570000,0.14162778,793.87522407,0.13245512,906.31000789,0.00105297,0.00000000,0.00000000,0.00000000,0.00000000,0.00000000,0.00000000,0.00000000,0.00000000
222.00000000,4.31032000,11.90490000,0.14316767,793.82187986,0.13380306,907.47150615,0.00092027,0.00000000,0.00000000,0.00000000,0.00000000,0.00000000,0.00000000,0.00000000,0.00000000
223.50000000,4.35912900,11.90810000,0.14489522,794.03525671,0.13531312,909.08717168,0.00104996,0.00000000,0.00000000,0.00000000,0.00000000,0.00000000,0.00000000,0.00000000,0.00000000
225.00000000,4.40790400,11.90490000,0.14654778,793.82187986,0.13675550,910.15471231,0.00104845,0.00000000,0.00000000,0.00000000,0.00000000,0.00000000,0.00000000,0.00000000,0.00000000
226.50000000,4.45691500,11.90890000,0.14823789,794.08860092,0.13822850,911.80261871,0.00098165,0.00000000,0.00000000,0.00000000,0.00000000,0.00000000,0.00000000,0.00000000,0.00000000
228.00000000,4.50684000,11.90810000,0.14996544,794.03525671,0.13973189,913.11310689,0.00091463,0.00000000,0.00000000,0.00000000,0.00000000,0.00000000,0.00000000,0.00000000,0.00000000
229.50000000,4.55679800,11.90650000,0.15169311,793.92856829,0.14123313,914.36206281,0.00097870,0.00000000,0.00000000,0.00000000,0.00000000,0.00000000,0.00000000,0.00000000,0.00000000
231.00000000,4.60618100,11.90410000,0.15338311,793.76853565,0.14269946,915.51922315,0.00097708,0.00000000,0.00000000,0.00000000,0.00000000,0.00000000,0.00000000,0.00000000,0.00000000
232.50000000,4.65617300,11.90410000,0.15511078,793.76853565,0.00000000,0.00000000,0.00000000,0.00000000,0.00000000,0.00000000,0.00000000,0.00000000,0.00000000,0.00000000,0.00000000
234.00000000,4.70687400,11.90890000,0.15691356,794.08860092,0.00000000,0.00000000,0.00000000,0.00000000,0.00000000,0.00000000,0.00000000,0.00000000,0.00000000,0.00000000,0.00000000
235.50000000,4.75842100,11.90810000,0.15871633,794.03525671,0.00000000,0.00000000,0.00000000,0.00000000,0.00000000,0.00000000,0.00000000,0.00000000,0.00000000,0.00000000,0.00000000
237.00000000,4.80905500,11.90570000,0.16051900,793.87522407,0.00000000,0.00000000,0.00000000,0.00000000,0.00000000,0.00000000,0.00000000,0.00000000,0.00000000,0.00000000,0.00000000
238.50000000,4.85931700,11.90330000,0.16232189,793.71519144,0.00000000,0.00000000,0.00000000,0.00000000,0.00000000,0.00000000,0.00000000,0.00000000,0.00000000,0.00000000,0.00000000
240.00000000,4.91059600,11.90170000,0.16408711,793.60850302,0.00000000,0.00000000,0.00000000,0.00000000,0.00000000,0.00000000,0.00000000,0.00000000,0.00000000,0.00000000,0.00000000
241.50000000,4.96383200,11.90170000,0.16600244,793.60850302,0.00000000,0.00000000,0.00000000,0.00000000,0.00000000,0.00000000,0.00000000,0.00000000,0.00000000,0.00000000,0.00000000
243.00000000,5.01547900,11.90090000,0.16788033,793.55515880,0.00000000,0.00000000,0.00000000,0.00000000,0.00000000,0.00000000,0.00000000,0.00000000,0.00000000,0.00000000,0.00000000
244.50000000,5.06726200,11.90090000,0.16975822,793.55515880,0.00000000,0.00000000,0.00000000,0.00000000,0.00000000,0.00000000,0.00000000,0.00000000,0.00000000,0.00000000,0.00000000
246.00000000,5.12043200,11.89850000,0.17171122,793.39512617,0.00000000,0.00000000,0.00000000,0.00000000,0.00000000,0.00000000,0.00000000,0.00000000,0.00000000,0.00000000,0.00000000
247.50000000,5.17377000,11.89530000,0.17370167,793.18174932,0.00000000,0.00000000,0.00000000,0.00000000,0.00000000,0.00000000,0.00000000,0.00000000,0.00000000,0.00000000,0.00000000
249.00000000,5.22764900,11.89450000,0.17565467,793.12840511,0.00000000,0.00000000,0.00000000,0.00000000,0.00000000,0.00000000,0.00000000,0.00000000,0.00000000,0.00000000,0.00000000
250.50000000,5.28091900,11.88330000,0.17768278,792.38158615,0.00000000,0.00000000,0.00000000,0.00000000,0.00000000,0.00000000,0.00000000,0.00000000,0.00000000,0.00000000,0.00000000
252.00000000,5.33459500,11.88570000,0.17974844,792.54161879,0.00000000,0.00000000,0.00000000,0.00000000,0.00000000,0.00000000,0.00000000,0.00000000,0.00000000,0.00000000,0.00000000
253.50000000,5.38881100,11.88180000,0.18181411,792.28156575,0.00000000,0.00000000,0.00000000,0.00000000,0.00000000,0.00000000,0.00000000,0.00000000,0.00000000,0.00000000,0.00000000
255.00000000,5.44357100,11.87940000,0.18403000,792.12153312,0.00000000,0.00000000,0.00000000,0.00000000,0.00000000,0.00000000,0.00000000,0.00000000,0.00000000,0.00000000,0.00000000
256.50000000,5.49893700,11.87780000,0.18617078,792.01484470,0.00000000,0.00000000,0.00000000,0.00000000,0.00000000,0.00000000,0.00000000,0.00000000,0.00000000,0.00000000,0.00000000
258.00000000,5.55339000,11.87620000,0.18838667,791.90815627,0.00000000,0.00000000,0.00000000,0.00000000,0.00000000,0.00000000,0.00000000,0.00000000,0.00000000,0.00000000,0.00000000
259.50000000,5.60906100,11.86740000,0.19064011,791.32136995,0.00000000,0.00000000,0.00000000,0.00000000,0.00000000,0.00000000,0.00000000,0.00000000,0.00000000,0.00000000,0.00000000
261.00000000,5.66473200,11.86180000,0.19289356,790.94796047,0.00000000,0.00000000,0.00000000,0.00000000,0.00000000,0.00000000,0.00000000,0.00000000,0.00000000,0.00000000,0.00000000
262.50000000,5.72009800,11.85620000,0.19525967,790.57455099,0.00000000,0.00000000,0.00000000,0.00000000,0.00000000,0.00000000,0.00000000,0.00000000,0.00000000,0.00000000,0.00000000
264.00000000,5.77617300,11.85380000,0.19770089,790.41451835,0.00000000,0.00000000,0.00000000,0.00000000,0.00000000,0.00000000,0.00000000,0.00000000,0.00000000,0.00000000,0.00000000
265.50000000,5.83309500,11.85140000,0.20017978,790.25448572,0.00000000,0.00000000,0.00000000,0.00000000,0.00000000,0.00000000,0.00000000,0.00000000,0.00000000,0.00000000,0.00000000
267.00000000,5.88940700,11.84750000,0.20273356,789.99443268,0.00000000,0.00000000,0.00000000,0.00000000,0.00000000,0.00000000,0.00000000,0.00000000,0.00000000,0.00000000,0.00000000
268.50000000,5.94693700,11.83870000,0.20536267,789.40764636,0.00000000,0.00000000,0.00000000,0.00000000,0.00000000,0.00000000,0.00000000,0.00000000,0.00000000,0.00000000,0.00000000
270.00000000,6.00402700,11.83390000,0.20806678,789.08758109,0.00000000,0.00000000,0.00000000,0.00000000,0.00000000,0.00000000,0.00000000,0.00000000,0.00000000,0.00000000,0.00000000
271.50000000,6.06185900,11.82830000,0.21084589,788.71417161,0.00000000,0.00000000,0.00000000,0.00000000,0.00000000,0.00000000,0.00000000,0.00000000,0.00000000,0.00000000,0.00000000
273.00000000,6.11908500,11.82190000,0.21377544,788.28741792,0.00000000,0.00000000,0.00000000,0.00000000,0.00000000,0.00000000,0.00000000,0.00000000,0.00000000,0.00000000,0.00000000
274.50000000,6.17712200,11.81560000,0.21678011,787.86733225,0.00000000,0.00000000,0.00000000,0.00000000,0.00000000,0.00000000,0.00000000,0.00000000,0.00000000,0.00000000,0.00000000
276.00000000,6.23519200,11.81000000,0.21989722,787.49392277,0.00000000,0.00000000,0.00000000,0.00000000,0.00000000,0.00000000,0.00000000,0.00000000,0.00000000,0.00000000,0.00000000
277.50000000,6.29370100,11.79640000,0.22316478,786.58707117,0.00000000,0.00000000,0.00000000,0.00000000,0.00000000,0.00000000,0.00000000,0.00000000,0.00000000,0.00000000,0.00000000
279.00000000,6.35248100,11.81480000,0.22658256,787.81398804,0.00000000,0.00000000,0.00000000,0.00000000,0.00000000,0.00000000,0.00000000,0.00000000,0.00000000,0.00000000,0.00000000
280.50000000,6.41109100,11.77650000,0.23018800,785.26013391,0.00000000,0.00000000,0.00000000,0.00000000,0.00000000,0.00000000,0.00000000,0.00000000,0.00000000,0.00000000,0.00000000
282.00000000,6.47051400,11.76690000,0.23386867,784.62000337,0.00000000,0.00000000,0.00000000,0.00000000,0.00000000,0.00000000,0.00000000,0.00000000,0.00000000,0.00000000,0.00000000
283.50000000,6.52946200,11.75500000,0.23769933,783.82650823,0.00000000,0.00000000,0.00000000,0.00000000,0.00000000,0.00000000,0.00000000,0.00000000,0.00000000,0.00000000,0.00000000
285.00000000,6.58854500,11.74380000,0.24175544,783.07968926,0.00000000,0.00000000,0.00000000,0.00000000,0.00000000,0.00000000,0.00000000,0.00000000,0.00000000,0.00000000,0.00000000
286.50000000,6.64901600,11.72940000,0.24607444,782.11949346,0.00000000,0.00000000,0.00000000,0.00000000,0.00000000,0.00000000,0.00000000,0.00000000,0.00000000,0.00000000,0.00000000
288.00000000,6.71005900,11.71430000,0.25069389,781.11262146,0.00000000,0.00000000,0.00000000,0.00000000,0.00000000,0.00000000,0.00000000,0.00000000,0.00000000,0.00000000,0.00000000
289.50000000,6.77046100,11.69670000,0.25542600,779.93904881,0.00000000,0.00000000,0.00000000,0.00000000,0.00000000,0.00000000,0.00000000,0.00000000,0.00000000,0.00000000,0.00000000
291.00000000,6.83164000,11.67040000,0.26038344,778.18535786,0.00000000,0.00000000,0.00000000,0.00000000,0.00000000,0.00000000,0.00000000,0.00000000,0.00000000,0.00000000,0.00000000
292.50000000,6.89308900,11.65290000,0.26564111,777.01845323,0.00000000,0.00000000,0.00000000,0.00000000,0.00000000,0.00000000,0.00000000,0.00000000,0.00000000,0.00000000,0.00000000
294.00000000,6.95399800,11.62580000,0.27097411,775.21141806,0.00000000,0.00000000,0.00000000,0.00000000,0.00000000,0.00000000,0.00000000,0.00000000,0.00000000,0.00000000,0.00000000
295.50000000,7.01588600,11.59390000,0.27656989,773.08431763,0.00000000,0.00000000,0.00000000,0.00000000,0.00000000,0.00000000,0.00000000,0.00000000,0.00000000,0.00000000,0.00000000
297.00000000,7.07750400,11.56520000,0.28239089,771.17059404,0.00000000,0.00000000,0.00000000,0.00000000,0.00000000,0.00000000,0.00000000,0.00000000,0.00000000,0.00000000,0.00000000
298.50000000,7.14006700,11.52850000,0.28851233,768.72342834,0.00000000,0.00000000,0.00000000,0.00000000,0.00000000,0.00000000,0.00000000,0.00000000,0.00000000,0.00000000,0.00000000
300.00000000,7.20276600,11.48380000,0.29478389,765.74282052,0.00000000,0.00000000,0.00000000,0.00000000,0.00000000,0.00000000,0.00000000,0.00000000,0.00000000,0.00000000,0.00000000
301.50000000,7.26539600,11.43760000,0.30128089,762.66219230,0.00000000,0.00000000,0.00000000,0.00000000,0.00000000,0.00000000,0.00000000,0.00000000,0.00000000,0.00000000,0.00000000
303.00000000,7.32910800,11.39610000,0.30792800,759.89496133,0.00000000,0.00000000,0.00000000,0.00000000,0.00000000,0.00000000,0.00000000,0.00000000,0.00000000,0.00000000,0.00000000
304.50000000,7.39278500,11.33550000,0.31472533,755.85413730,0.00000000,0.00000000,0.00000000,0.00000000,0.00000000,0.00000000,0.00000000,0.00000000,0.00000000,0.00000000,0.00000000
306.00000000,7.45686700,11.26850000,0.32171056,751.38655959,0.00000000,0.00000000,0.00000000,0.00000000,0.00000000,0.00000000,0.00000000,0.00000000,0.00000000,0.00000000,0.00000000
307.50000000,7.52149000,11.19510000,0.32880867,746.49222818,0.00000000,0.00000000,0.00000000,0.00000000,0.00000000,0.00000000,0.00000000,0.00000000,0.00000000,0.00000000,0.00000000
309.00000000,7.58722700,11.09780000,0.33616989,740.00423845,0.00000000,0.00000000,0.00000000,0.00000000,0.00000000,0.00000000,0.00000000,0.00000000,0.00000000,0.00000000,0.00000000
310.50000000,7.65485600,10.98140000,0.34375733,732.24265567,0.00000000,0.00000000,0.00000000,0.00000000,0.00000000,0.00000000,0.00000000,0.00000000,0.00000000,0.00000000,0.00000000
312.00000000,7.72866900,10.79640000,0.35213633,719.90680676,0.00000000,0.00000000,0.00000000,0.00000000,0.00000000,0.00000000,0.00000000,0.00000000,0.00000000,0.00000000,0.00000000
312.50000000,7.75776900,10.66880000,0.35555711,711.39840502,0.00000000,0.00000000,0.00000000,0.00000000,0.00000000,0.00000000,0.00000000,0.00000000,0.00000000,0.00000000,0.00000000