File: polyN_optimization/results_exp/DP780/UT_60_2.csv
Time[s],Displacement[mm],Force[kN],EngStrain_longi,EngStress[MPa],TrueStrain,TrueStress[MPa],TrueStrainRate[1/s],PlasticStrain_longi,PlasticStress[MPa],PlasticStrain_thick,PlasticStrain_width,R-Value,Thickness[mm],Width[mm], Young's Modulus [MPa]
0.00000000,0.00000000,-0.01420000,0.00000000,-0.94532863,0.00000000,-0.94532863,0.00000000,0.00058703,422.48009980,0.00036330,-0.00095033,0.89757091,1.50690000,9.96830000,219061.37491192
1.00000000,0.00168500,0.28810000,0.00008089,19.17951963,0.00008089,19.18107104,0.00016422,0.00080249,431.42855280,0.00010912,-0.00091162,0.00000000,0.00000000,0.00000000,0.00000000
2.00000000,0.00343700,0.53050000,0.00007100,35.31667880,0.00007100,35.31918629,0.00001955,0.00091058,439.37067711,0.00010688,-0.00101746,0.00000000,0.00000000,0.00000000,0.00000000
3.00000000,0.00415100,0.76260000,0.00010211,50.76814186,0.00010211,50.77332585,-0.00007288,0.00108497,447.61924861,0.00015579,-0.00124075,0.00000000,0.00000000,0.00000000,0.00000000
4.00000000,0.00606800,0.99540000,0.00014756,66.26620562,0.00014754,66.27598357,0.00007955,0.00127482,455.65747018,0.00002169,-0.00129651,0.00000000,0.00000000,0.00000000,0.00000000
5.00000000,0.00702800,1.21230000,0.00020844,80.70576760,0.00020842,80.72259027,0.00002777,0.00148042,463.49237206,-0.00021358,-0.00126684,0.00000000,0.00000000,0.00000000,0.00000000
6.00000000,0.00776900,1.42450000,0.00028244,94.83243913,0.00028240,94.85922402,0.00009975,0.00169269,471.49497753,-0.00033764,-0.00135505,0.00000000,0.00000000,0.00000000,0.00000000
7.00000000,0.00991300,1.62220000,0.00034744,107.99381028,0.00034738,108.03133213,0.00016373,0.00185244,478.03581180,-0.00024929,-0.00160315,0.00000000,0.00000000,0.00000000,0.00000000
8.00000000,0.01046800,1.79610000,0.00035011,119.57075740,0.00035005,119.61262045,-0.00008330,0.00212235,485.75862713,-0.00034279,-0.00177956,0.00000000,0.00000000,0.00000000,0.00000000
9.00000000,0.01314500,1.98670000,0.00045878,132.25946424,0.00045867,132.32014194,0.00020214,0.00235061,492.70795847,-0.00055035,-0.00180026,0.00000000,0.00000000,0.00000000,0.00000000
10.00000000,0.01292100,2.17010000,0.00040367,144.46884952,0.00040359,144.52716678,-0.00003665,0.00257112,499.71736677,-0.00066791,-0.00190321,0.00000000,0.00000000,0.00000000,0.00000000
11.00000000,0.01626600,2.34790000,0.00059378,156.30542915,0.00059360,156.39823984,0.00022455,0.00289800,506.35498107,-0.00088540,-0.00201260,0.00000000,0.00000000,0.00000000,0.00000000
12.00000000,0.01658000,2.52500000,0.00050211,168.09540807,0.00050199,168.17981064,-0.00002843,0.00311155,513.26113868,-0.00087069,-0.00224085,0.00000000,0.00000000,0.00000000,0.00000000
13.00000000,0.01862500,2.69480000,0.00061644,179.39940818,0.00061625,179.50999795,0.00006241,0.00354662,519.91021803,-0.00116358,-0.00238304,0.00000000,0.00000000,0.00000000,0.00000000
14.00000000,0.01979900,2.87110000,0.00062856,191.13612915,0.00062836,191.25626882,0.00010816,0.00372979,526.11009450,-0.00112575,-0.00260404,0.00000000,0.00000000,0.00000000,0.00000000
15.00000000,0.02159200,3.04010000,0.00069111,202.38687131,0.00069087,202.52674313,-0.00004708,0.00421825,532.42178192,-0.00146011,-0.00275814,0.00000000,0.00000000,0.00000000,0.00000000
16.00000000,0.02307900,3.20680000,0.00074589,213.48449687,0.00074561,213.64373258,0.00010770,0.00447619,537.76177110,-0.00152786,-0.00294833,0.00000000,0.00000000,0.00000000,0.00000000
17.00000000,0.02433200,3.35670000,0.00077500,223.46370545,0.00077470,223.63688982,-0.00015276,0.00487379,543.49685252,-0.00173589,-0.00313789,0.00000000,0.00000000,0.00000000,0.00000000
18.00000000,0.02635800,3.52420000,0.00094056,234.61458895,0.00094011,234.83525701,0.00043386,0.00529237,549.46356629,-0.00199076,-0.00330161,0.00000000,0.00000000,0.00000000,0.00000000
19.00000000,0.02729100,3.69250000,0.00085389,245.81873041,0.00085352,246.02863229,-0.00016496,0.00558555,555.15705667,-0.00204325,-0.00354230,0.00000000,0.00000000,0.00000000,0.00000000
20.00000000,0.02996800,3.85120000,0.00102678,256.38377645,0.00102625,256.64702562,0.00032281,0.00615156,560.62374526,-0.00243605,-0.00371551,0.00000000,0.00000000,0.00000000,0.00000000
21.00000000,0.03085200,4.01550000,0.00094833,267.32162816,0.00094788,267.57513817,-0.00003730,0.00636993,566.33727419,-0.00248130,-0.00388863,0.00000000,0.00000000,0.00000000,0.00000000
22.00000000,0.03285000,4.17500000,0.00115144,277.93993215,0.00115078,278.25996454,0.00034519,0.00695969,571.40389334,-0.00290848,-0.00405120,0.00000000,0.00000000,0.00000000,0.00000000
23.00000000,0.03498400,4.33050000,0.00106133,288.29194639,0.00106077,288.59792024,-0.00008258,0.00723639,576.55855760,-0.00297357,-0.00426281,0.00000000,0.00000000,0.00000000,0.00000000
24.00000000,0.03685000,4.49000000,0.00128656,298.91025038,0.00128573,299.29481503,0.00024747,0.00779184,581.66976740,-0.00335885,-0.00443298,0.00000000,0.00000000,0.00000000,0.00000000
25.00000000,0.03928900,4.64630000,0.00116311,309.31552258,0.00116244,309.67529090,-0.00004461,0.00819195,586.58733062,-0.00348659,-0.00470535,0.00000000,0.00000000,0.00000000,0.00000000
26.00000000,0.04088300,4.78100000,0.00144122,318.28283009,0.00144018,318.74154637,0.00007500,0.00865111,591.54400261,-0.00377149,-0.00487963,0.00000000,0.00000000,0.00000000,0.00000000
27.00000000,0.04426800,4.93260000,0.00135467,328.37521181,0.00135375,328.82005077,-0.00001509,0.00915079,596.52281100,-0.00399495,-0.00515584,0.00000000,0.00000000,0.00000000,0.00000000
28.00000000,0.04612900,5.08010000,0.00162533,338.19464654,0.00162401,338.74432558,0.00013556,0.00964372,601.29304547,-0.00429436,-0.00534935,0.00000000,0.00000000,0.00000000,0.00000000
29.00000000,0.04975000,5.22840000,0.00150167,348.06733922,0.00150054,348.59002034,-0.00003728,0.01000377,605.87908975,-0.00440390,-0.00559987,0.00000000,0.00000000,0.00000000,0.00000000
30.00000000,0.05171700,5.37590000,0.00182467,357.88677395,0.00182300,358.53979802,0.00009716,0.01061844,610.67860483,-0.00477590,-0.00584254,0.00000000,0.00000000,0.00000000,0.00000000
31.00000000,0.05641700,5.52350000,0.00175311,367.71286592,0.00175158,368.35750744,0.00017969,0.01099014,615.06322963,-0.00486645,-0.00612369,0.00000000,0.00000000,0.00000000,0.00000000
32.00000000,0.05908800,5.66380000,0.00198244,377.05297909,0.00198048,377.80046568,0.00004524,0.01157900,619.69454351,-0.00527651,-0.00630249,0.00000000,0.00000000,0.00000000,0.00000000
33.00000000,0.06358400,5.80500000,0.00198644,386.45300746,0.00198447,387.22067489,0.00019496,0.01202019,624.18461370,-0.00542145,-0.00659874,0.00000000,0.00000000,0.00000000,0.00000000
34.00000000,0.06734000,5.94220000,0.00227911,395.58674607,0.00227652,396.48833221,0.00012660,0.01251708,627.79833275,-0.00563968,-0.00687740,0.00000000,0.00000000,0.00000000,0.00000000
35.00000000,0.07176800,6.06340000,0.00229778,403.65532565,0.00229514,404.58283589,0.00022483,0.01310249,632.17061136,-0.00601172,-0.00709077,0.00000000,0.00000000,0.00000000,0.00000000
36.00000000,0.07690300,6.19580000,0.00254967,412.46951656,0.00254642,413.52117633,0.00006029,0.01363942,636.57134676,-0.00628991,-0.00734951,0.00000000,0.00000000,0.00000000,0.00000000
37.00000000,0.08105900,6.32970000,0.00260222,421.38356612,0.00259884,422.48009980,0.00023208,0.01409476,640.97869424,-0.00655468,-0.00754008,0.00000000,0.00000000,0.00000000,0.00000000
38.00000000,0.08701000,6.46210000,0.00286100,430.19775702,0.00285692,431.42855280,0.00005230,0.01470429,644.72862173,-0.00688166,-0.00782263,0.00000000,0.00000000,0.00000000,0.00000000
39.00000000,0.09211200,6.58010000,0.00300733,438.05330480,0.00300282,439.37067711,0.00041191,0.01525962,648.94426728,-0.00717016,-0.00808946,0.00000000,0.00000000,0.00000000,0.00000000
40.00000000,0.09866400,6.70220000,0.00322167,446.18179958,0.00321649,447.61924861,0.00004497,0.01574244,652.83805453,-0.00741219,-0.00833025,0.00000000,0.00000000,0.00000000,0.00000000
41.00000000,0.10440700,6.82100000,0.00345056,454.09060532,0.00344462,455.65747018,0.00032911,0.01637264,656.66926440,-0.00775591,-0.00861674,0.00000000,0.00000000,0.00000000,0.00000000
42.00000000,0.11136900,6.93660000,0.00369433,461.78637925,0.00368753,463.49237206,0.00016429,0.01688731,660.70798451,-0.00802223,-0.00886508,0.00000000,0.00000000,0.00000000,0.00000000
43.00000000,0.11937800,7.05460000,0.00394567,469.64192703,0.00393790,471.49497753,0.00033670,0.01743499,663.94796085,-0.00829005,-0.00914494,0.00000000,0.00000000,0.00000000,0.00000000
44.00000000,0.12640400,7.15110000,0.00413733,476.06616738,0.00412880,478.03581180,0.00023194,0.01809247,667.98119776,-0.00868389,-0.00940858,0.00000000,0.00000000,0.00000000,0.00000000
45.00000000,0.13488200,7.26440000,0.00444533,483.60882470,0.00443548,485.75862713,0.00018696,0.01863827,671.44602206,-0.00892720,-0.00971107,0.00000000,0.00000000,0.00000000,0.00000000
46.00000000,0.14282300,7.36640000,0.00470789,490.39921346,0.00469684,492.70795847,0.00041808,0.01919398,675.09200174,-0.00918070,-0.01001328,0.00000000,0.00000000,0.00000000,0.00000000
47.00000000,0.15187600,7.46930000,0.00496300,497.24951742,0.00495072,499.71736677,-0.00002278,0.01980741,678.88377711,-0.00949562,-0.01031179,0.00000000,0.00000000,0.00000000,0.00000000
48.00000000,0.16143800,7.56580000,0.00532333,503.67375776,0.00530921,506.35498107,0.00049321,0.02034567,682.19778587,-0.00975001,-0.01059567,0.00000000,0.00000000,0.00000000,0.00000000
49.00000000,0.17147200,7.66710000,0.00557111,510.41754582,0.00555565,513.26113868,-0.00000751,0.02101861,685.65580839,-0.01012379,-0.01089482,0.00000000,0.00000000,0.00000000,0.00000000
50.00000000,0.18194600,7.76280000,0.00604056,516.78852821,0.00602238,519.91021803,0.00071691,0.02161014,689.17841228,-0.01039422,-0.01121592,0.00000000,0.00000000,0.00000000,0.00000000
51.00000000,0.19245500,7.85370000,0.00625456,522.83996291,0.00623508,526.11009450,0.00002981,0.02219813,692.59297549,-0.01068404,-0.01151409,0.00000000,0.00000000,0.00000000,0.00000000
52.00000000,0.20391000,7.94380000,0.00677644,528.83813964,0.00675359,532.42178192,0.00067885,0.02282510,695.42844168,-0.01106222,-0.01176288,0.00000000,0.00000000,0.00000000,0.00000000
53.00000000,0.21658200,8.02120000,0.00706178,533.99084641,0.00703696,537.76177110,0.00029836,0.02346879,698.50539123,-0.01138952,-0.01207927,0.00000000,0.00000000,0.00000000,0.00000000
54.00000000,0.22695500,8.10330000,0.00748978,539.45644364,0.00746187,543.49685252,0.00033552,0.02407457,701.77910623,-0.01170770,-0.01236688,0.00000000,0.00000000,0.00000000,0.00000000
55.00000000,0.24003300,8.18860000,0.00794022,545.13507267,0.00790886,549.46356629,0.00046194,0.02472497,704.81340199,-0.01207130,-0.01265367,0.00000000,0.00000000,0.00000000,0.00000000
56.00000000,0.25348000,8.27080000,0.00826311,550.60732714,0.00822916,555.15705667,0.00030550,0.02530939,707.80457003,-0.01235908,-0.01295030,0.00000000,0.00000000,0.00000000,0.00000000
57.00000000,0.26557800,8.34730000,0.00886022,555.70011872,0.00882120,560.62374526,0.00067767,0.02597111,711.34262383,-0.01272723,-0.01324388,0.00000000,0.00000000,0.00000000,0.00000000
58.00000000,0.27879200,8.43030000,0.00910800,561.22563114,0.00906677,566.33727419,0.00031251,0.02659377,713.81775720,-0.01303374,-0.01356003,0.00000000,0.00000000,0.00000000,0.00000000
59.00000000,0.29356100,8.50050000,0.00972767,565.89901635,0.00968066,571.40389334,0.00059519,0.02726226,717.26548106,-0.01342176,-0.01384050,0.00000000,0.00000000,0.00000000,0.00000000
60.00000000,0.30701200,8.57460000,0.01003189,570.83203406,0.00998190,576.55855760,0.00044624,0.02789568,719.58941382,-0.01375306,-0.01414262,0.00000000,0.00000000,0.00000000,0.00000000
61.00000000,0.32127400,8.64560000,0.01061767,575.55867722,0.01056170,581.66976740,0.00042355,0.02856230,722.49190340,-0.01408557,-0.01447673,0.00000000,0.00000000,0.00000000,0.00000000
62.00000000,0.33570500,8.71500000,0.01104578,580.17880448,0.01098522,586.58733062,0.00051988,0.02921778,725.33469171,-0.01444601,-0.01477176,0.00000000,0.00000000,0.00000000,0.00000000
63.00000000,0.35010300,8.78440000,0.01153400,584.79893173,0.01146799,591.54400261,0.00046777,0.02988086,728.02076536,-0.01478891,-0.01509195,0.00000000,0.00000000,0.00000000,0.00000000
64.00000000,0.36558200,8.85370000,0.01206356,589.41240174,0.01199137,596.52281100,0.00046028,0.03051848,730.63618638,-0.01510964,-0.01540884,0.00000000,0.00000000,0.00000000,0.00000000
65.00000000,0.38092600,8.91990000,0.01258556,593.81949719,0.01250702,601.29304547,0.00071228,0.03119845,733.39654005,-0.01544683,-0.01575161,0.00000000,0.00000000,0.00000000,0.00000000
66.00000000,0.39512100,8.98450000,0.01297233,598.12007674,0.01288891,605.87908975,0.00031154,0.03188092,736.27297496,-0.01583892,-0.01604201,0.00000000,0.00000000,0.00000000,0.00000000
67.00000000,0.41093800,9.04990000,0.01361833,602.47391424,0.01352644,610.67860483,0.00081551,0.03251486,738.61840447,-0.01611275,-0.01640210,0.00000000,0.00000000,0.00000000,0.00000000
68.00000000,0.42777000,9.11130000,0.01401633,606.56146199,0.01391901,615.06322963,0.00042235,0.03318233,741.43506791,-0.01648232,-0.01670002,0.00000000,0.00000000,0.00000000,0.00000000
69.00000000,0.44294500,9.17430000,0.01463600,610.75552564,0.01452993,619.69454351,0.00063678,0.03387404,743.60751199,-0.01680619,-0.01706784,0.00000000,0.00000000,0.00000000,0.00000000
70.00000000,0.45896600,9.23650000,0.01510544,614.89633133,0.01499249,624.18461370,0.00044401,0.03456093,745.94562305,-0.01720504,-0.01735589,0.00000000,0.00000000,0.00000000,0.00000000
71.00000000,0.47576400,9.28520000,0.01562744,618.13840910,0.01550659,627.79833275,0.00045122,0.03524148,748.72639603,-0.01757081,-0.01767068,0.00000000,0.00000000,0.00000000,0.00000000
72.00000000,0.49208800,9.34420000,0.01624333,622.06618299,0.01611282,632.17061136,0.00049513,0.03594924,751.03076529,-0.01798531,-0.01796393,0.00000000,0.00000000,0.00000000,0.00000000
73.00000000,0.50892000,9.40400000,0.01681044,626.04721484,0.01667071,636.57134676,0.00084968,0.03662687,753.48221328,-0.01829582,-0.01833104,0.00000000,0.00000000,0.00000000,0.00000000
74.00000000,0.52659800,9.46460000,0.01729489,630.08150463,0.01714703,640.97869424,0.00036178,0.03728398,755.59401163,-0.01864300,-0.01864098,0.00000000,0.00000000,0.00000000,0.00000000
75.00000000,0.54309200,9.51400000,0.01793333,633.37018311,0.01777443,644.72862173,0.00067883,0.03801140,757.97769752,-0.01902292,-0.01898848,0.00000000,0.00000000,0.00000000,0.00000000
76.00000000,0.56056600,9.57070000,0.01851922,637.14484039,0.01834983,648.94426728,0.00057521,0.03869450,760.49796198,-0.01939305,-0.01930145,0.00000000,0.00000000,0.00000000,0.00000000
77.00000000,0.57878400,9.62330000,0.01903000,640.64655067,0.01885119,652.83805453,0.00049399,0.03942709,762.33383274,-0.01978438,-0.01964271,0.00000000,0.00000000,0.00000000,0.00000000
78.00000000,0.59683300,9.67350000,0.01969100,643.98848710,0.01949964,656.66926440,0.00069249,0.04013827,764.77686442,-0.02016004,-0.01997823,0.00000000,0.00000000,0.00000000,0.00000000
79.00000000,0.61437500,9.72780000,0.02023556,647.60337053,0.02003354,660.70798451,0.00065529,0.04084361,766.82035705,-0.02046821,-0.02037540,0.00000000,0.00000000,0.00000000,0.00000000
80.00000000,0.63269500,9.77000000,0.02081022,650.41272745,0.02059665,663.94796085,0.00035335,0.04150424,769.11151236,-0.02083350,-0.02067074,0.00000000,0.00000000,0.00000000,0.00000000
81.00000000,0.65118400,9.82270000,0.02150122,653.92109498,0.02127333,667.98119776,0.00076482,0.04226910,771.26223915,-0.02123515,-0.02103395,0.00000000,0.00000000,0.00000000,0.00000000
82.00000000,0.66876000,9.86810000,0.02207578,656.94348370,0.02183564,671.44602206,0.00055124,0.04301825,773.57869095,-0.02163618,-0.02138206,0.00000000,0.00000000,0.00000000,0.00000000
83.00000000,0.68755300,9.91600000,0.02266167,660.13230352,0.02240871,675.09200174,0.00055093,0.04371411,775.68157775,-0.02196589,-0.02174822,0.00000000,0.00000000,0.00000000,0.00000000
84.00000000,0.70631100,9.96540000,0.02330767,663.42098200,0.02304019,678.88377711,0.00063139,0.04448201,777.56282018,-0.02235796,-0.02212405,0.00000000,0.00000000,0.00000000,0.00000000
85.00000000,0.72594900,10.00850000,0.02387478,666.29025411,0.02359423,682.19778587,0.00049166,0.04520309,779.41691857,-0.02274331,-0.02245978,0.00000000,0.00000000,0.00000000,0.00000000
86.00000000,0.74494500,10.05230000,0.02458089,669.20612694,0.02428364,685.65580839,0.00059394,0.04588278,781.57088552,-0.02310612,-0.02277665,0.00000000,0.00000000,0.00000000,0.00000000
87.00000000,0.76444900,10.09780000,0.02520433,672.23517290,0.02489194,689.17841228,0.00061569,0.04663708,783.72994994,-0.02349918,-0.02313790,0.00000000,0.00000000,0.00000000,0.00000000
88.00000000,0.78412000,10.14170000,0.02582400,675.15770297,0.02549619,692.59297549,0.00054923,0.04740832,785.18083866,-0.02395734,-0.02345099,0.00000000,0.00000000,0.00000000,0.00000000
89.00000000,0.80314900,10.17670000,0.02648122,677.48773833,0.02613666,695.42844168,0.00070263,0.04810073,787.35248138,-0.02429100,-0.02380973,0.00000000,0.00000000,0.00000000,0.00000000
90.00000000,0.82268600,10.21500000,0.02715722,680.03746273,0.02679501,698.50539123,0.00071667,0.04890123,789.16871524,-0.02474784,-0.02415339,0.00000000,0.00000000,0.00000000,0.00000000
91.00000000,0.84320300,10.25650000,0.02779567,682.80021895,0.02741638,701.77910623,0.00059921,0.04962446,791.37011311,-0.02513286,-0.02449160,0.00000000,0.00000000,0.00000000,0.00000000
92.00000000,0.86297600,10.29400000,0.02847922,685.29668540,0.02808123,704.81340199,0.00068657,0.05039727,793.50095414,-0.02554102,-0.02485626,0.00000000,0.00000000,0.00000000,0.00000000
93.00000000,0.88315500,10.33150000,0.02909511,687.79315186,0.02867988,707.80457003,0.00062049,0.05109940,795.41583944,-0.02589014,-0.02520926,0.00000000,0.00000000,0.00000000,0.00000000
94.00000000,0.90384100,10.37610000,0.02979367,690.76228263,0.02935846,711.34262383,0.00068569,0.05193363,797.09258017,-0.02636918,-0.02556445,0.00000000,0.00000000,0.00000000,0.00000000
95.00000000,0.92459500,10.40560000,0.03044722,692.72616958,0.02999290,713.81775720,0.00067080,0.05266973,799.09595124,-0.02677715,-0.02589259,0.00000000,0.00000000,0.00000000,0.00000000
96.00000000,0.94487500,10.44870000,0.03115322,695.59544169,0.03067781,717.26548106,0.00072122,0.05340993,800.87165342,-0.02713750,-0.02627243,0.00000000,0.00000000,0.00000000,0.00000000
97.00000000,0.96573000,10.47580000,0.03181800,697.39955478,0.03132229,719.58941382,0.00066991,0.05418708,802.23319348,-0.02756366,-0.02662342,0.00000000,0.00000000,0.00000000,0.00000000
98.00000000,0.98645000,10.51090000,0.03252033,699.73624739,0.03200274,722.49190340,0.00067678,0.05496139,804.04060134,-0.02795240,-0.02700899,0.00000000,0.00000000,0.00000000,0.00000000
99.00000000,1.00740600,10.54520000,0.03321133,702.01968204,0.03267175,725.33469171,0.00073442,0.05567454,805.92146017,-0.02834488,-0.02732967,0.00000000,0.00000000,0.00000000,0.00000000
100.00000000,1.02880200,10.57710000,0.03390989,704.14334284,0.03334762,728.02076536,0.00069758,0.05645609,807.45548641,-0.02873059,-0.02772551,0.00000000,0.00000000,0.00000000,0.00000000
101.00000000,1.04992800,10.60820000,0.03458222,706.21374569,0.03399770,730.63618638,0.00068982,0.05727072,809.30957719,-0.02921534,-0.02805538,0.00000000,0.00000000,0.00000000,0.00000000
102.00000000,1.07179700,10.64090000,0.03529956,708.39066444,0.03469081,733.39654005,0.00060969,0.05801174,810.92850782,-0.02957695,-0.02843479,0.00000000,0.00000000,0.00000000,0.00000000
103.00000000,1.09309100,10.67520000,0.03602056,710.67409909,0.03538698,736.27297496,0.00073950,0.05875859,812.67512389,-0.02995873,-0.02879986,0.00000000,0.00000000,0.00000000,0.00000000
104.00000000,1.11438600,10.70230000,0.03668911,712.47821218,0.03603209,738.61840447,0.00068113,0.05952336,814.26056615,-0.03035693,-0.02916643,0.00000000,0.00000000,0.00000000,0.00000000
105.00000000,1.13605200,10.73580000,0.03739522,714.70838888,0.03671298,741.43506791,0.00068817,0.06037292,815.63948587,-0.03082355,-0.02954937,0.00000000,0.00000000,0.00000000,0.00000000
106.00000000,1.15815800,10.75970000,0.03812378,716.29947017,0.03741502,743.60751199,0.00069475,0.06103984,817.54788497,-0.03115468,-0.02988516,0.00000000,0.00000000,0.00000000,0.00000000
107.00000000,1.18083800,10.78600000,0.03884867,718.05032531,0.03811305,745.94562305,0.00065104,0.06183537,818.94335829,-0.03158835,-0.03024702,0.00000000,0.00000000,0.00000000,0.00000000
108.00000000,1.20253900,10.81870000,0.03956967,720.22724406,0.03880685,748.72639603,0.00056356,0.06264314,820.57922199,-0.03205546,-0.03058768,0.00000000,0.00000000,0.00000000,0.00000000
109.00000000,1.22457700,10.84420000,0.04031711,721.92484125,0.03952558,751.03076529,0.00074393,0.06336230,822.25130367,-0.03239729,-0.03096501,0.00000000,0.00000000,0.00000000,0.00000000
110.00000000,1.24631100,10.87210000,0.04103444,723.78221230,0.04021488,753.48221328,0.00070007,0.06419808,823.62835311,-0.03287434,-0.03132374,0.00000000,0.00000000,0.00000000,0.00000000
111.00000000,1.26875500,10.89530000,0.04172922,725.32669288,0.04088205,755.59401163,0.00058416,0.06499448,825.02465257,-0.03333005,-0.03166442,0.00000000,0.00000000,0.00000000,0.00000000
112.00000000,1.29146900,10.92160000,0.04249911,727.07754802,0.04162082,757.97769752,0.00069183,0.06571537,826.71114826,-0.03367185,-0.03204352,0.00000000,0.00000000,0.00000000,0.00000000
113.00000000,1.31371000,10.95030000,0.04322400,728.98817701,0.04231592,760.49796198,0.00070584,0.06649980,828.16566004,-0.03410072,-0.03239908,0.00000000,0.00000000,0.00000000,0.00000000
114.00000000,1.33635600,10.96860000,0.04399767,730.20645264,0.04305725,762.33383274,0.00074855,0.06730806,829.63463321,-0.03453503,-0.03277303,0.00000000,0.00000000,0.00000000,0.00000000
115.00000000,1.35920600,10.99580000,0.04475256,732.01722298,0.04378007,764.77686442,0.00076226,0.06807802,830.90829692,-0.03494190,-0.03313612,0.00000000,0.00000000,0.00000000,0.00000000
116.00000000,1.38239300,11.01730000,0.04549989,733.44853041,0.04449513,766.82035705,0.00080488,0.06886810,832.25775716,-0.03531249,-0.03355561,0.00000000,0.00000000,0.00000000,0.00000000
117.00000000,1.40537800,11.04280000,0.04620222,735.14612761,0.04516668,769.11151236,0.00053130,0.06970428,834.04315629,-0.03579431,-0.03390998,0.00000000,0.00000000,0.00000000,0.00000000
118.00000000,1.42846400,11.06510000,0.04701344,736.63069299,0.04594177,771.26223915,0.00074618,0.07044068,835.40884208,-0.03615213,-0.03428855,0.00000000,0.00000000,0.00000000,0.00000000
119.00000000,1.45212500,11.08990000,0.04780967,738.28168947,0.04670195,773.57869095,0.00078868,0.07121919,836.58089389,-0.03660853,-0.03461066,0.00000000,0.00000000,0.00000000,0.00000000
120.00000000,1.47588700,11.11220000,0.04854956,739.76625486,0.04740783,775.68157775,0.00073088,0.07207599,837.98600770,-0.03702848,-0.03504752,0.00000000,0.00000000,0.00000000,0.00000000
121.00000000,1.49921000,11.13050000,0.04936444,740.98453049,0.04818469,777.56282018,0.00083052,0.07288254,839.58878271,-0.03748597,-0.03539657,0.00000000,0.00000000,0.00000000,0.00000000
122.00000000,1.52236300,11.14890000,0.05013067,742.20946337,0.04891460,779.41691857,0.00079413,0.07361279,841.01360240,-0.03786771,-0.03574508,0.00000000,0.00000000,0.00000000,0.00000000
123.00000000,1.54619300,11.17200000,0.05085544,743.74728670,0.04960454,781.57088552,0.00064339,0.07445340,842.46836427,-0.03831706,-0.03613634,0.00000000,0.00000000,0.00000000,0.00000000
124.00000000,1.57009000,11.19430000,0.05165922,745.23185209,0.05036913,783.72994994,0.00065727,0.07531256,843.54273018,-0.03881437,-0.03649819,0.00000000,0.00000000,0.00000000,0.00000000
125.00000000,1.59419000,11.20630000,0.05247789,746.03072136,0.05114728,785.18083866,0.00079236,0.07605478,844.98261750,-0.03917527,-0.03687950,0.00000000,0.00000000,0.00000000,0.00000000
126.00000000,1.61754700,11.22940000,0.05321778,747.56854469,0.05185003,787.35248138,0.00073460,0.07689144,846.09859817,-0.03966304,-0.03722840,0.00000000,0.00000000,0.00000000,0.00000000
127.00000000,1.64201900,11.24620000,0.05407033,748.68696166,0.05265918,789.16871524,0.00070554,0.07771474,847.71951354,-0.04004021,-0.03767453,0.00000000,0.00000000,0.00000000,0.00000000
128.00000000,1.66652500,11.26930000,0.05484400,750.22478500,0.05339289,791.37011311,0.00074064,0.07849552,848.67470901,-0.04047042,-0.03802509,0.00000000,0.00000000,0.00000000,0.00000000
129.00000000,1.69055700,11.29080000,0.05567022,751.65609244,0.05417585,793.50095414,0.00082555,0.07930123,850.05902012,-0.04086514,-0.03843609,0.00000000,0.00000000,0.00000000,0.00000000
130.00000000,1.71509700,11.31000000,0.05642133,752.93428326,0.05488710,795.41583944,0.00072522,0.08017799,851.61484163,-0.04135770,-0.03882029,0.00000000,0.00000000,0.00000000,0.00000000
131.00000000,1.74000800,11.32430000,0.05731144,753.88626914,0.05572931,797.09258017,0.00079568,0.08090500,852.58602408,-0.04169315,-0.03921185,0.00000000,0.00000000,0.00000000,0.00000000
132.00000000,1.76417600,11.34430000,0.05810011,755.21771791,0.05647495,799.09595124,0.00073836,0.08179192,853.87004998,-0.04219750,-0.03959443,0.00000000,0.00000000,0.00000000,0.00000000
133.00000000,1.78878300,11.36100000,0.05889256,756.32947764,0.05722360,800.87165342,0.00073067,0.08259520,855.20051171,-0.04256914,-0.04002606,0.00000000,0.00000000,0.00000000,0.00000000
134.00000000,1.81325500,11.37140000,0.05972267,757.02183101,0.05800724,802.23319348,0.00079408,0.08340899,856.36652013,-0.04299662,-0.04041237,0.00000000,0.00000000,0.00000000,0.00000000
135.00000000,1.83870700,11.38810000,0.06055267,758.13359074,0.05879016,804.04060134,0.00082888,0.08426401,857.38681394,-0.04347007,-0.04079394,0.00000000,0.00000000,0.00000000,0.00000000
136.00000000,1.86240200,11.40650000,0.06131878,759.35852361,0.05951226,805.92146017,0.00070072,0.08509269,858.74364013,-0.04393282,-0.04115987,0.00000000,0.00000000,0.00000000,0.00000000
137.00000000,1.88788800,11.41920000,0.06215633,760.20399358,0.06030112,807.45548641,0.00070038,0.08589382,859.96132085,-0.04436351,-0.04153031,0.00000000,0.00000000,0.00000000,0.00000000
138.00000000,1.91273100,11.43600000,0.06303133,761.32241056,0.06112458,809.30957719,0.00082695,0.08668215,860.87654329,-0.04478976,-0.04189238,0.00000000,0.00000000,0.00000000,0.00000000
139.00000000,1.93818400,11.45030000,0.06382756,762.27439643,0.06187331,810.92850782,0.00086165,0.08755259,862.38391635,-0.04524697,-0.04230562,0.00000000,0.00000000,0.00000000,0.00000000
140.00000000,1.96326400,11.46630000,0.06463122,763.33955545,0.06262847,812.67512389,0.00073383,0.08839063,863.34455885,-0.04573130,-0.04265933,0.00000000,0.00000000,0.00000000,0.00000000
141.00000000,1.98861500,11.47980000,0.06545378,764.23828338,0.06340079,814.26056615,0.00069111,0.08925036,864.61858944,-0.04616355,-0.04308681,0.00000000,0.00000000,0.00000000,0.00000000
142.00000000,2.01372900,11.48940000,0.06636633,764.87737879,0.06425692,815.63948587,0.00097927,0.09005949,865.61515573,-0.04657831,-0.04348117,0.00000000,0.00000000,0.00000000,0.00000000
143.00000000,2.03911400,11.50850000,0.06708744,766.14891237,0.06493292,817.54788497,0.00076734,0.09085343,866.77598273,-0.04698343,-0.04387000,0.00000000,0.00000000,0.00000000,0.00000000
144.00000000,2.06459900,11.51890000,0.06794378,766.84126574,0.06573510,818.94335829,0.00075278,0.09167851,867.72983322,-0.04742285,-0.04425567,0.00000000,0.00000000,0.00000000,0.00000000
145.00000000,2.09025500,11.53250000,0.06881511,767.74665090,0.06655066,820.57922199,0.00086470,0.09250468,869.03169049,-0.04782112,-0.04468357,0.00000000,0.00000000,0.00000000,0.00000000
146.00000000,2.11587600,11.54760000,0.06959256,768.75189473,0.06727779,822.25130367,0.00077968,0.09332890,870.57660554,-0.04821818,-0.04511072,0.00000000,0.00000000,0.00000000,0.00000000
147.00000000,2.14186900,11.55720000,0.07049389,769.39099014,0.06812012,823.62835311,0.00074393,0.09418436,871.14775049,-0.04871325,-0.04547110,0.00000000,0.00000000,0.00000000,0.00000000
148.00000000,2.16755800,11.56750000,0.07135389,770.07668626,0.06892317,825.02465257,0.00088360,0.09503656,872.24789640,-0.04909539,-0.04594116,0.00000000,0.00000000,0.00000000,0.00000000
149.00000000,2.19324600,11.58270000,0.07213511,771.08858733,0.06965209,826.71114826,0.00074984,0.09585022,873.43370491,-0.04953316,-0.04631705,0.00000000,0.00000000,0.00000000,0.00000000
150.00000000,2.21934100,11.59390000,0.07298389,771.83419865,0.07044345,828.16566004,0.00065125,0.09668831,874.34656086,-0.04997082,-0.04671749,0.00000000,0.00000000,0.00000000,0.00000000
151.00000000,2.24570600,11.60500000,0.07385900,772.57315272,0.07125870,829.63463321,0.00081861,0.09750513,875.30083910,-0.05039807,-0.04710706,0.00000000,0.00000000,0.00000000,0.00000000
152.00000000,2.27186800,11.61380000,0.07469267,773.15899018,0.07203473,830.90829692,0.00077598,0.09839108,876.54656230,-0.05088374,-0.04750734,0.00000000,0.00000000,0.00000000,0.00000000
153.00000000,2.29830000,11.62340000,0.07554900,773.79808559,0.07283123,832.25775716,0.00071253,0.09920366,877.38071297,-0.05132237,-0.04788129,0.00000000,0.00000000,0.00000000,0.00000000
154.00000000,2.32439400,11.63850000,0.07645789,774.80332942,0.07367592,834.04315629,0.00085856,0.10003552,878.29201289,-0.05176928,-0.04826624,0.00000000,0.00000000,0.00000000,0.00000000
155.00000000,2.35055600,11.64890000,0.07725789,775.49568278,0.07441882,835.40884208,0.00081602,0.10090985,879.36053799,-0.05228243,-0.04862742,0.00000000,0.00000000,0.00000000,0.00000000
156.00000000,2.37712400,11.65610000,0.07810289,775.97500434,0.07520291,836.58089389,0.00070383,0.10174169,880.68999534,-0.05270077,-0.04904092,0.00000000,0.00000000,0.00000000,0.00000000
157.00000000,2.40315100,11.66560000,0.07903422,776.60744251,0.07606640,837.98600770,0.00087731,0.10258512,881.55526275,-0.05321764,-0.04936749,0.00000000,0.00000000,0.00000000,0.00000000
158.00000000,2.43042800,11.67840000,0.07991311,777.45956973,0.07688059,839.58878271,0.00092539,0.10340654,882.64009341,-0.05361191,-0.04979463,0.00000000,0.00000000,0.00000000,0.00000000
159.00000000,2.45763800,11.68960000,0.08070933,778.20518105,0.07761762,841.01360240,0.00075788,0.10425754,883.75238298,-0.05409645,-0.05016109,0.00000000,0.00000000,0.00000000,0.00000000
160.00000000,2.48434100,11.69990000,0.08162567,778.89087717,0.07846516,842.46836427,0.00076402,0.10513292,884.52961199,-0.05454671,-0.05058621,0.00000000,0.00000000,0.00000000,0.00000000
161.00000000,2.51117900,11.70470000,0.08256089,779.21042487,0.07932943,843.54273018,0.00102027,0.10597347,885.39598671,-0.05502167,-0.05095179,0.00000000,0.00000000,0.00000000,0.00000000
162.00000000,2.53835500,11.71590000,0.08337211,779.95603619,0.08007850,844.98261750,0.00079746,0.10679855,886.54078328,-0.05547136,-0.05132718,0.00000000,0.00000000,0.00000000,0.00000000
163.00000000,2.56563200,11.72150000,0.08428467,780.32884184,0.08092048,846.09859817,0.00081750,0.10771213,887.29470006,-0.05601857,-0.05169355,0.00000000,0.00000000,0.00000000,0.00000000
164.00000000,2.59277500,11.73420000,0.08518611,781.17431182,0.08175150,847.71951354,0.00090000,0.10852843,888.56118698,-0.05640664,-0.05212179,0.00000000,0.00000000,0.00000000,0.00000000
165.00000000,2.62028800,11.73820000,0.08603867,781.44060157,0.08253683,848.67470901,0.00079571,0.10936637,889.36915016,-0.05686088,-0.05250550,0.00000000,0.00000000,0.00000000,0.00000000
166.00000000,2.64739700,11.74780000,0.08692122,782.07969699,0.08334913,850.05902012,0.00075354,0.11023554,890.50561663,-0.05731194,-0.05292360,0.00000000,0.00000000,0.00000000,0.00000000
167.00000000,2.67477600,11.75890000,0.08788267,782.81865106,0.08423330,851.61484163,0.00086323,0.11113265,891.24823455,-0.05784841,-0.05328423,0.00000000,0.00000000,0.00000000,0.00000000
168.00000000,2.70208700,11.76370000,0.08867889,783.13819876,0.08496493,852.58602408,0.00073844,0.11200923,891.91301024,-0.05831822,-0.05369101,0.00000000,0.00000000,0.00000000,0.00000000
169.00000000,2.72983700,11.77090000,0.08965156,783.61752032,0.08585797,853.87004998,0.00078593,0.11285304,892.96979276,-0.05873497,-0.05411807,0.00000000,0.00000000,0.00000000,0.00000000
170.00000000,2.75758800,11.77970000,0.09053411,784.20335779,0.08666759,855.20051171,0.00075777,0.11367797,893.64970471,-0.05920391,-0.05447406,0.00000000,0.00000000,0.00000000,0.00000000
171.00000000,2.78581200,11.78610000,0.09142800,784.62942139,0.08748693,856.36652013,0.00083985,0.11456959,894.87190546,-0.05967743,-0.05489216,0.00000000,0.00000000,0.00000000,0.00000000
172.00000000,2.81376500,11.79000000,0.09236689,784.88905391,0.08834680,857.38681394,0.00079090,0.11546936,895.62060825,-0.06022902,-0.05524034,0.00000000,0.00000000,0.00000000,0.00000000
173.00000000,2.84127900,11.79880000,0.09327956,785.47489137,0.08918195,858.74364013,0.00083843,0.11628459,896.47485197,-0.06070598,-0.05557860,0.00000000,0.00000000,0.00000000,0.00000000
174.00000000,2.86950300,11.80600000,0.09416211,785.95421293,0.08998888,859.96132085,0.00089952,0.11717567,897.33786059,-0.06117833,-0.05599733,0.00000000,0.00000000,0.00000000,0.00000000
175.00000000,2.89715200,11.80920000,0.09502978,786.16724473,0.09078156,860.87654329,0.00076847,0.11802809,898.46906057,-0.06166097,-0.05636713,0.00000000,0.00000000,0.00000000,0.00000000
176.00000000,2.92571400,11.81950000,0.09599122,786.85294085,0.09165918,862.38391635,0.00076779,0.11886459,899.28466930,-0.06207633,-0.05678826,0.00000000,0.00000000,0.00000000,0.00000000
177.00000000,2.95420800,11.82270000,0.09691511,787.06597266,0.09250180,863.34455885,0.00093841,0.00000000,0.00000000,0.00000000,0.00000000,0.00000000,0.00000000,0.00000000,0.00000000
178.00000000,2.98260100,11.82990000,0.09786522,787.54529421,0.09336759,864.61858944,0.00085538,0.00000000,0.00000000,0.00000000,0.00000000,0.00000000,0.00000000,0.00000000,0.00000000
179.00000000,3.01116300,11.83390000,0.09875911,787.81158397,0.09418146,865.61515573,0.00085468,0.00000000,0.00000000,0.00000000,0.00000000,0.00000000,0.00000000,0.00000000,0.00000000
180.00000000,3.03972500,11.84030000,0.09963789,788.23764758,0.09498093,866.77598273,0.00081296,0.00000000,0.00000000,0.00000000,0.00000000,0.00000000,0.00000000,0.00000000,0.00000000
181.00000000,3.06832100,11.84350000,0.10055056,788.45067938,0.09581056,867.72983322,0.00077815,0.00000000,0.00000000,0.00000000,0.00000000,0.00000000,0.00000000,0.00000000,0.00000000
182.00000000,3.09715300,11.85140000,0.10146700,788.97660165,0.09664293,869.03169049,0.00081847,0.00000000,0.00000000,0.00000000,0.00000000,0.00000000,0.00000000,0.00000000,0.00000000
183.00000000,3.12601900,11.86260000,0.10238333,789.72221296,0.09747450,870.57660554,0.00085187,0.00000000,0.00000000,0.00000000,0.00000000,0.00000000,0.00000000,0.00000000,0.00000000
184.00000000,3.15542600,11.86020000,0.10332978,789.56243911,0.09833268,871.14775049,0.00080339,0.00000000,0.00000000,0.00000000,0.00000000,0.00000000,0.00000000,0.00000000,0.00000000
185.00000000,3.18422400,11.86500000,0.10427622,789.88198682,0.09919012,872.24789640,0.00080270,0.00000000,0.00000000,0.00000000,0.00000000,0.00000000,0.00000000,0.00000000,0.00000000
186.00000000,3.21356300,11.87140000,0.10518133,790.30805043,0.10000942,873.43370491,0.00080204,0.00000000,0.00000000,0.00000000,0.00000000,0.00000000,0.00000000,0.00000000,0.00000000
187.00000000,3.24246300,11.87380000,0.10611278,790.46782428,0.10085187,874.34656086,0.00076760,0.00000000,0.00000000,0.00000000,0.00000000,0.00000000,0.00000000,0.00000000,0.00000000
188.00000000,3.27153200,11.87700000,0.10702167,790.68085608,0.10167323,875.30083910,0.00073303,0.00000000,0.00000000,0.00000000,0.00000000,0.00000000,0.00000000,0.00000000,0.00000000
189.00000000,3.30056700,11.88330000,0.10800944,791.10026245,0.10256511,876.54656230,0.00088165,0.00000000,0.00000000,0.00000000,0.00000000,0.00000000,0.00000000,0.00000000,0.00000000
190.00000000,3.33051500,11.88490000,0.10891456,791.20677835,0.10338166,877.38071297,0.00084685,0.00000000,0.00000000,0.00000000,0.00000000,0.00000000,0.00000000,0.00000000,0.00000000
191.00000000,3.36046200,11.88730000,0.10984222,791.36655220,0.10421786,878.29201289,0.00089362,0.00000000,0.00000000,0.00000000,0.00000000,0.00000000,0.00000000,0.00000000,0.00000000
192.00000000,3.38953100,11.89130000,0.11081867,791.63284196,0.10509728,879.36053799,0.00087922,0.00000000,0.00000000,0.00000000,0.00000000,0.00000000,0.00000000,0.00000000,0.00000000
193.00000000,3.41927600,11.89930000,0.11175011,792.16542147,0.10593545,880.68999534,0.00085829,0.00000000,0.00000000,0.00000000,0.00000000,0.00000000,0.00000000,0.00000000,0.00000000
194.00000000,3.44912200,11.90090000,0.11269278,792.27193737,0.10678300,881.55526275,0.00087774,0.00000000,0.00000000,0.00000000,0.00000000,0.00000000,0.00000000,0.00000000,0.00000000
195.00000000,3.47947600,11.90570000,0.11361289,792.59148508,0.10760958,882.64009341,0.00080954,0.00000000,0.00000000,0.00000000,0.00000000,0.00000000,0.00000000,0.00000000,0.00000000
196.00000000,3.50942400,11.91050000,0.11456689,792.91103279,0.10846589,883.75238298,0.00093032,0.00000000,0.00000000,0.00000000,0.00000000,0.00000000,0.00000000,0.00000000,0.00000000
197.00000000,3.53970900,11.91050000,0.11554711,792.91103279,0.10934497,884.52961199,0.00088905,0.00000000,0.00000000,0.00000000,0.00000000,0.00000000,0.00000000,0.00000000,0.00000000
198.00000000,3.56942000,11.91210000,0.11648978,793.01754869,0.11018964,885.39598671,0.00078057,0.00000000,0.00000000,0.00000000,0.00000000,0.00000000,0.00000000,0.00000000,0.00000000
199.00000000,3.59987500,11.91760000,0.11741744,793.38369710,0.11102017,886.54078328,0.00083364,0.00000000,0.00000000,0.00000000,0.00000000,0.00000000,0.00000000,0.00000000,0.00000000
200.00000000,3.63063400,11.91680000,0.11844278,793.33043915,0.11193734,887.29470006,0.00090026,0.00000000,0.00000000,0.00000000,0.00000000,0.00000000,0.00000000,0.00000000,0.00000000
201.00000000,3.66108900,11.92400000,0.11936289,793.80976071,0.11275967,888.56118698,0.00089932,0.00000000,0.00000000,0.00000000,0.00000000,0.00000000,0.00000000,0.00000000,0.00000000
202.00000000,3.69194900,11.92480000,0.12030556,793.86301866,0.11360147,889.36915016,0.00081145,0.00000000,0.00000000,0.00000000,0.00000000,0.00000000,0.00000000,0.00000000,0.00000000
203.00000000,3.72297800,11.92960000,0.12128578,794.18256637,0.11447604,890.50561663,0.00078378,0.00000000,0.00000000,0.00000000,0.00000000,0.00000000,0.00000000,0.00000000,0.00000000
204.00000000,3.75400700,11.92880000,0.12229611,794.12930842,0.11537669,891.24823455,0.00097067,0.00000000,0.00000000,0.00000000,0.00000000,0.00000000,0.00000000,0.00000000,0.00000000
205.00000000,3.78544200,11.92720000,0.12328389,794.02279251,0.11625644,891.91301024,0.00093656,0.00000000,0.00000000,0.00000000,0.00000000,0.00000000,0.00000000,0.00000000,0.00000000
206.00000000,3.81650500,11.93120000,0.12423778,794.28908227,0.11710528,892.96979276,0.00086873,0.00000000,0.00000000,0.00000000,0.00000000,0.00000000,0.00000000,0.00000000,0.00000000
207.00000000,3.84794000,11.93040000,0.12516922,794.23582432,0.11793344,893.64970471,0.00075460,0.00000000,0.00000000,0.00000000,0.00000000,0.00000000,0.00000000,0.00000000,0.00000000
208.00000000,3.87974700,11.93600000,0.12617944,794.60862998,0.11883088,894.87190546,0.00076715,0.00000000,0.00000000,0.00000000,0.00000000,0.00000000,0.00000000,0.00000000,0.00000000
209.00000000,3.91091200,11.93520000,0.12719722,794.55537202,0.11973422,895.62060825,0.00095974,0.00000000,0.00000000,0.00000000,0.00000000,0.00000000,0.00000000,0.00000000,0.00000000
210.00000000,3.94332700,11.93680000,0.12812111,794.66188793,0.12055352,896.47485197,0.00080583,0.00000000,0.00000000,0.00000000,0.00000000,0.00000000,0.00000000,0.00000000,0.00000000
211.00000000,3.97499800,11.93760000,0.12913144,794.71514588,0.12144870,897.33786059,0.00085827,0.00000000,0.00000000,0.00000000,0.00000000,0.00000000,0.00000000,0.00000000,0.00000000
212.00000000,4.00710900,11.94240000,0.13010044,795.03469358,0.12230652,898.46906057,0.00087760,0.00000000,0.00000000,0.00000000,0.00000000,0.00000000,0.00000000,0.00000000,0.00000000
213.00000000,4.03966000,11.94320000,0.13105056,795.08795154,0.12314690,899.28466930,0.00087666,0.00000000,0.00000000,0.00000000,0.00000000,0.00000000,0.00000000,0.00000000,0.00000000
214.00000000,4.07248000,11.94080000,0.13210600,794.92817768,0.00000000,0.00000000,0.00000000,0.00000000,0.00000000,0.00000000,0.00000000,0.00000000,0.00000000,0.00000000,0.00000000
215.00000000,4.10520000,11.94240000,0.13307489,795.03469358,0.00000000,0.00000000,0.00000000,0.00000000,0.00000000,0.00000000,0.00000000,0.00000000,0.00000000,0.00000000,0.00000000
216.00000000,4.13751300,11.94160000,0.13402889,794.98143563,0.00000000,0.00000000,0.00000000,0.00000000,0.00000000,0.00000000,0.00000000,0.00000000,0.00000000,0.00000000,0.00000000
217.00000000,4.17107800,11.93680000,0.13502789,794.66188793,0.00000000,0.00000000,0.00000000,0.00000000,0.00000000,0.00000000,0.00000000,0.00000000,0.00000000,0.00000000,0.00000000
218.00000000,4.20379700,11.94080000,0.13595556,794.92817768,0.00000000,0.00000000,0.00000000,0.00000000,0.00000000,0.00000000,0.00000000,0.00000000,0.00000000,0.00000000,0.00000000
219.00000000,4.23668600,11.94000000,0.13689444,794.87491973,0.00000000,0.00000000,0.00000000,0.00000000,0.00000000,0.00000000,0.00000000,0.00000000,0.00000000,0.00000000,0.00000000
220.00000000,4.27008100,11.94000000,0.13787100,794.87491973,0.00000000,0.00000000,0.00000000,0.00000000,0.00000000,0.00000000,0.00000000,0.00000000,0.00000000,0.00000000,0.00000000
221.00000000,4.30401700,11.93520000,0.13888500,794.55537202,0.00000000,0.00000000,0.00000000,0.00000000,0.00000000,0.00000000,0.00000000,0.00000000,0.00000000,0.00000000,0.00000000
222.00000000,4.33822400,11.93440000,0.13978633,794.50211407,0.00000000,0.00000000,0.00000000,0.00000000,0.00000000,0.00000000,0.00000000,0.00000000,0.00000000,0.00000000,0.00000000
223.00000000,4.37209200,11.93760000,0.14068767,794.71514588,0.00000000,0.00000000,0.00000000,0.00000000,0.00000000,0.00000000,0.00000000,0.00000000,0.00000000,0.00000000,0.00000000
224.00000000,4.40629900,11.93440000,0.14166422,794.50211407,0.00000000,0.00000000,0.00000000,0.00000000,0.00000000,0.00000000,0.00000000,0.00000000,0.00000000,0.00000000,0.00000000
225.00000000,4.44091100,11.93360000,0.14264067,794.44885612,0.00000000,0.00000000,0.00000000,0.00000000,0.00000000,0.00000000,0.00000000,0.00000000,0.00000000,0.00000000,0.00000000
226.00000000,4.47532100,11.93040000,0.14357956,794.23582432,0.00000000,0.00000000,0.00000000,0.00000000,0.00000000,0.00000000,0.00000000,0.00000000,0.00000000,0.00000000,0.00000000
227.00000000,4.51047400,11.93200000,0.14448089,794.34234022,0.00000000,0.00000000,0.00000000,0.00000000,0.00000000,0.00000000,0.00000000,0.00000000,0.00000000,0.00000000,0.00000000
228.00000000,4.54586300,11.92720000,0.14541989,794.02279251,0.00000000,0.00000000,0.00000000,0.00000000,0.00000000,0.00000000,0.00000000,0.00000000,0.00000000,0.00000000,0.00000000
229.00000000,4.58135400,11.92320000,0.14628367,793.75650276,0.00000000,0.00000000,0.00000000,0.00000000,0.00000000,0.00000000,0.00000000,0.00000000,0.00000000,0.00000000,0.00000000
230.00000000,4.61738600,11.92160000,0.14722256,793.64998686,0.00000000,0.00000000,0.00000000,0.00000000,0.00000000,0.00000000,0.00000000,0.00000000,0.00000000,0.00000000,0.00000000
231.00000000,4.65314800,11.92000000,0.14812389,793.54347095,0.00000000,0.00000000,0.00000000,0.00000000,0.00000000,0.00000000,0.00000000,0.00000000,0.00000000,0.00000000,0.00000000
232.00000000,4.68911200,11.91680000,0.14891267,793.33043915,0.00000000,0.00000000,0.00000000,0.00000000,0.00000000,0.00000000,0.00000000,0.00000000,0.00000000,0.00000000,0.00000000
233.00000000,4.72578600,11.91130000,0.14973889,792.96429074,0.00000000,0.00000000,0.00000000,0.00000000,0.00000000,0.00000000,0.00000000,0.00000000,0.00000000,0.00000000,0.00000000
234.00000000,4.76269700,11.91290000,0.15064022,793.07080664,0.00000000,0.00000000,0.00000000,0.00000000,0.00000000,0.00000000,0.00000000,0.00000000,0.00000000,0.00000000,0.00000000
235.00000000,4.80001300,11.90010000,0.15135389,792.21867942,0.00000000,0.00000000,0.00000000,0.00000000,0.00000000,0.00000000,0.00000000,0.00000000,0.00000000,0.00000000,0.00000000
236.00000000,4.83753200,11.89050000,0.15221767,791.57958401,0.00000000,0.00000000,0.00000000,0.00000000,0.00000000,0.00000000,0.00000000,0.00000000,0.00000000,0.00000000,0.00000000
237.00000000,4.87525400,11.88330000,0.15289367,791.10026245,0.00000000,0.00000000,0.00000000,0.00000000,0.00000000,0.00000000,0.00000000,0.00000000,0.00000000,0.00000000,0.00000000
238.00000000,4.91263800,11.87620000,0.15364489,790.62759813,0.00000000,0.00000000,0.00000000,0.00000000,0.00000000,0.00000000,0.00000000,0.00000000,0.00000000,0.00000000,0.00000000
239.00000000,4.95093500,11.86420000,0.15428333,789.82872887,0.00000000,0.00000000,0.00000000,0.00000000,0.00000000,0.00000000,0.00000000,0.00000000,0.00000000,0.00000000,0.00000000
240.00000000,4.98980600,11.85700000,0.15495933,789.34940731,0.00000000,0.00000000,0.00000000,0.00000000,0.00000000,0.00000000,0.00000000,0.00000000,0.00000000,0.00000000,0.00000000
241.00000000,5.02874500,11.85060000,0.15544756,788.92334370,0.00000000,0.00000000,0.00000000,0.00000000,0.00000000,0.00000000,0.00000000,0.00000000,0.00000000,0.00000000,0.00000000
242.00000000,5.06741300,11.83470000,0.15597333,787.86484192,0.00000000,0.00000000,0.00000000,0.00000000,0.00000000,0.00000000,0.00000000,0.00000000,0.00000000,0.00000000,0.00000000
243.00000000,5.10638600,11.82430000,0.15653678,787.17248856,0.00000000,0.00000000,0.00000000,0.00000000,0.00000000,0.00000000,0.00000000,0.00000000,0.00000000,0.00000000,0.00000000
244.00000000,5.14640600,11.81000000,0.15694989,786.22050268,0.00000000,0.00000000,0.00000000,0.00000000,0.00000000,0.00000000,0.00000000,0.00000000,0.00000000,0.00000000,0.00000000
245.00000000,5.18669700,11.79400000,0.15736300,785.15534366,0.00000000,0.00000000,0.00000000,0.00000000,0.00000000,0.00000000,0.00000000,0.00000000,0.00000000,0.00000000,0.00000000
246.00000000,5.22732600,11.77330000,0.15777622,783.77729418,0.00000000,0.00000000,0.00000000,0.00000000,0.00000000,0.00000000,0.00000000,0.00000000,0.00000000,0.00000000,0.00000000
247.00000000,5.26785400,11.76130000,0.15807667,782.97842491,0.00000000,0.00000000,0.00000000,0.00000000,0.00000000,0.00000000,0.00000000,0.00000000,0.00000000,0.00000000,0.00000000
248.00000000,5.30905700,11.73980000,0.15837711,781.54711748,0.00000000,0.00000000,0.00000000,0.00000000,0.00000000,0.00000000,0.00000000,0.00000000,0.00000000,0.00000000,0.00000000
249.00000000,5.34887500,11.71830000,0.15864000,780.11581004,0.00000000,0.00000000,0.00000000,0.00000000,0.00000000,0.00000000,0.00000000,0.00000000,0.00000000,0.00000000,0.00000000
250.00000000,5.39018000,11.69750000,0.15882778,778.73110331,0.00000000,0.00000000,0.00000000,0.00000000,0.00000000,0.00000000,0.00000000,0.00000000,0.00000000,0.00000000,0.00000000
251.00000000,5.43141800,11.66880000,0.15897800,776.82047432,0.00000000,0.00000000,0.00000000,0.00000000,0.00000000,0.00000000,0.00000000,0.00000000,0.00000000,0.00000000,0.00000000
252.00000000,5.47258800,11.64570000,0.15912833,775.28265098,0.00000000,0.00000000,0.00000000,0.00000000,0.00000000,0.00000000,0.00000000,0.00000000,0.00000000,0.00000000,0.00000000
253.00000000,5.51450200,11.62020000,0.15924100,773.58505379,0.00000000,0.00000000,0.00000000,0.00000000,0.00000000,0.00000000,0.00000000,0.00000000,0.00000000,0.00000000,0.00000000
254.00000000,5.55658400,11.58750000,0.15931611,771.40813504,0.00000000,0.00000000,0.00000000,0.00000000,0.00000000,0.00000000,0.00000000,0.00000000,0.00000000,0.00000000,0.00000000
255.00000000,5.59900500,11.55160000,0.15939122,769.01818449,0.00000000,0.00000000,0.00000000,0.00000000,0.00000000,0.00000000,0.00000000,0.00000000,0.00000000,0.00000000,0.00000000
256.00000000,5.64092000,11.51970000,0.15939133,766.89452369,0.00000000,0.00000000,0.00000000,0.00000000,0.00000000,0.00000000,0.00000000,0.00000000,0.00000000,0.00000000,0.00000000
257.00000000,5.68337500,11.48220000,0.15939133,764.39805723,0.00000000,0.00000000,0.00000000,0.00000000,0.00000000,0.00000000,0.00000000,0.00000000,0.00000000,0.00000000,0.00000000
258.00000000,5.72613400,11.43440000,0.15942900,761.21589465,0.00000000,0.00000000,0.00000000,0.00000000,0.00000000,0.00000000,0.00000000,0.00000000,0.00000000,0.00000000,0.00000000
259.00000000,5.76906300,11.39130000,0.15942900,758.34662254,0.00000000,0.00000000,0.00000000,0.00000000,0.00000000,0.00000000,0.00000000,0.00000000,0.00000000,0.00000000,0.00000000
260.00000000,5.81273700,11.34190000,0.15939144,755.05794406,0.00000000,0.00000000,0.00000000,0.00000000,0.00000000,0.00000000,0.00000000,0.00000000,0.00000000,0.00000000,0.00000000
261.00000000,5.85597100,11.28680000,0.15935400,751.38980268,0.00000000,0.00000000,0.00000000,0.00000000,0.00000000,0.00000000,0.00000000,0.00000000,0.00000000,0.00000000,0.00000000
262.00000000,5.89947600,11.22060000,0.15935411,746.98270723,0.00000000,0.00000000,0.00000000,0.00000000,0.00000000,0.00000000,0.00000000,0.00000000,0.00000000,0.00000000,0.00000000
263.00000000,5.94376000,11.15920000,0.15935411,742.89515949,0.00000000,0.00000000,0.00000000,0.00000000,0.00000000,0.00000000,0.00000000,0.00000000,0.00000000,0.00000000,0.00000000
264.00000000,5.98814600,11.08110000,0.15931667,737.69585201,0.00000000,0.00000000,0.00000000,0.00000000,0.00000000,0.00000000,0.00000000,0.00000000,0.00000000,0.00000000,0.00000000
265.00000000,6.03398800,10.99180000,0.15927933,731.75093322,0.00000000,0.00000000,0.00000000,0.00000000,0.00000000,0.00000000,0.00000000,0.00000000,0.00000000,0.00000000,0.00000000
266.00000000,6.08077900,10.89050000,0.15916678,725.00714517,0.00000000,0.00000000,0.00000000,0.00000000,0.00000000,0.00000000,0.00000000,0.00000000,0.00000000,0.00000000,0.00000000
266.50000000,6.10471600,10.83390000,0.15924211,721.23914513,0.00000000,0.00000000,0.00000000,0.00000000,0.00000000,0.00000000,0.00000000,0.00000000,0.00000000,0.00000000,0.00000000