File: polyN_optimization/results_exp/DP780/UT_75_3.csv
Time[s],Displacement[mm],Force[kN],EngStrain_longi,EngStress[MPa],TrueStrain,TrueStress[MPa],TrueStrainRate[1/s],PlasticStrain_longi,PlasticStress[MPa],PlasticStrain_thick,PlasticStrain_width,R-Value,Thickness[mm],Width[mm], Young's Modulus [MPa]
0.00000000,0.00000000,-0.01980000,0.00000000,-1.31778865,0.00000000,-1.31778865,0.00000000,0.00060499,417.47569072,0.00035972,-0.00096471,0.89076212,1.50660000,9.97290000,289034.35710957
1.50000000,0.00192200,0.32160000,0.00007933,21.40408232,0.00007933,21.40578038,0.00011555,0.00070136,431.00398053,0.00028120,-0.00098256,0.00000000,0.00000000,0.00000000,0.00000000
3.00000000,0.00350900,0.67320000,0.00011944,44.80481412,0.00011944,44.81016580,-0.00000067,0.00096222,443.01765089,0.00010300,-0.00106523,0.00000000,0.00000000,0.00000000,0.00000000
4.50000000,0.00551700,1.03050000,0.00018067,68.58490931,0.00018065,68.59730032,0.00001889,0.00125668,455.04756551,0.00007655,-0.00133323,0.00000000,0.00000000,0.00000000,0.00000000
6.00000000,0.00810000,1.34310000,0.00026933,89.38999679,0.00026930,89.41407250,0.00006310,0.00150778,467.44054543,-0.00015351,-0.00135427,0.00000000,0.00000000,0.00000000,0.00000000
7.50000000,0.01024500,1.63660000,0.00038622,108.92388411,0.00038615,108.96595294,0.00016083,0.00183982,478.54716180,-0.00033329,-0.00150654,0.00000000,0.00000000,0.00000000,0.00000000
9.00000000,0.01175900,1.92610000,0.00041933,128.19155150,0.00041925,128.24530649,0.00008641,0.00220206,489.62348897,-0.00035038,-0.00185168,0.00000000,0.00000000,0.00000000,0.00000000
10.50000000,0.01316000,2.18840000,0.00044767,145.64892337,0.00044757,145.71412554,0.00007730,0.00259454,500.50958457,-0.00058741,-0.00200713,0.00000000,0.00000000,0.00000000,0.00000000
12.00000000,0.01497000,2.44680000,0.00045311,162.84673081,0.00045301,162.92051847,-0.00005397,0.00296769,509.89281045,-0.00083101,-0.00213668,0.00000000,0.00000000,0.00000000,0.00000000
13.50000000,0.01756600,2.71080000,0.00057544,180.41724615,0.00057528,180.52106625,-0.00007484,0.00330226,519.59255027,-0.00086883,-0.00243343,0.00000000,0.00000000,0.00000000,0.00000000
15.00000000,0.02029600,2.95160000,0.00072911,196.44368590,0.00072885,196.58691517,0.00009171,0.00375483,529.57038979,-0.00109955,-0.00265528,0.00000000,0.00000000,0.00000000,0.00000000
16.50000000,0.02284400,3.18850000,0.00083089,212.21056122,0.00083054,212.38688461,0.00021561,0.00436205,538.30468533,-0.00144438,-0.00291767,0.00000000,0.00000000,0.00000000,0.00000000
18.00000000,0.02444300,3.44610000,0.00082278,229.35512467,0.00082244,229.54383297,0.00013101,0.00488612,546.41961247,-0.00169618,-0.00318994,0.00000000,0.00000000,0.00000000,0.00000000
19.50000000,0.02649400,3.68370000,0.00083222,245.16858848,0.00083188,245.37262322,-0.00002243,0.00544406,555.20145593,-0.00192023,-0.00352383,0.00000000,0.00000000,0.00000000,0.00000000
21.00000000,0.02927700,3.91020000,0.00097133,260.24329198,0.00097086,260.49607496,-0.00008991,0.00604731,562.99604295,-0.00223551,-0.00381180,0.00000000,0.00000000,0.00000000,0.00000000
22.50000000,0.03209400,4.15820000,0.00113689,276.74892760,0.00113624,277.06356038,0.00009811,0.00672168,570.63227741,-0.00264627,-0.00407542,0.00000000,0.00000000,0.00000000,0.00000000
24.00000000,0.03474200,4.38950000,0.00123500,292.14309502,0.00123424,292.50389174,0.00035271,0.00728767,579.07240590,-0.00297093,-0.00431674,0.00000000,0.00000000,0.00000000,0.00000000
25.50000000,0.03796700,4.61040000,0.00123544,306.84509062,0.00123468,307.22418068,0.00014250,0.00790953,585.83529101,-0.00327003,-0.00463951,0.00000000,0.00000000,0.00000000,0.00000000
27.00000000,0.04179500,4.85040000,0.00131056,322.81828638,0.00130970,323.24135768,-0.00015024,0.00859998,592.91759847,-0.00358753,-0.00501244,0.00000000,0.00000000,0.00000000,0.00000000
28.50000000,0.04535400,5.06490000,0.00149533,337.09433009,0.00149422,337.59839848,-0.00020191,0.00927018,600.26794883,-0.00389566,-0.00537452,0.00000000,0.00000000,0.00000000,0.00000000
30.00000000,0.04908400,5.28420000,0.00177689,351.68983772,0.00177531,352.31475149,0.00026266,0.00989210,606.73361699,-0.00415790,-0.00573420,0.00000000,0.00000000,0.00000000,0.00000000
31.50000000,0.05378800,5.51070000,0.00188989,366.76454123,0.00188811,367.45768546,0.00040528,0.01055138,613.06810237,-0.00452666,-0.00602472,0.00000000,0.00000000,0.00000000,0.00000000
33.00000000,0.06045300,5.71970000,0.00193533,380.67453254,0.00193346,381.41126465,0.00017988,0.01131115,619.96101385,-0.00495655,-0.00635460,0.00000000,0.00000000,0.00000000,0.00000000
34.50000000,0.06596700,5.91900000,0.00209278,393.93894052,0.00209059,394.76336718,-0.00019514,0.01203120,626.51425741,-0.00532608,-0.00670512,0.00000000,0.00000000,0.00000000,0.00000000
36.00000000,0.07242600,6.13280000,0.00244967,408.16839574,0.00244667,409.16827226,0.00003015,0.01274859,632.74981972,-0.00570413,-0.00704447,0.00000000,0.00000000,0.00000000,0.00000000
37.50000000,0.08114600,6.33050000,0.00273522,421.32631575,0.00273149,422.47873686,0.00027704,0.01350155,639.13256219,-0.00605498,-0.00744658,0.00000000,0.00000000,0.00000000,0.00000000
39.00000000,0.08858200,6.51550000,0.00295267,433.63898749,0.00294832,434.91937887,0.00038911,0.01432888,645.29458222,-0.00646424,-0.00786464,0.00000000,0.00000000,0.00000000,0.00000000
40.50000000,0.09665500,6.70690000,0.00316300,446.37761111,0.00315801,447.78950349,0.00017235,0.01514355,650.86693361,-0.00689615,-0.00824739,0.00000000,0.00000000,0.00000000,0.00000000
42.00000000,0.10628100,6.87840000,0.00347822,457.79179058,0.00347219,459.38409216,0.00009722,0.01586745,656.76270813,-0.00727250,-0.00859495,0.00000000,0.00000000,0.00000000,0.00000000
43.50000000,0.11665200,7.05300000,0.00386444,469.41229050,0.00385700,471.22630822,0.00024662,0.01673779,662.71668648,-0.00777402,-0.00896376,0.00000000,0.00000000,0.00000000,0.00000000
45.00000000,0.12773000,7.21970000,0.00420222,480.50700606,0.00419342,482.52620328,0.00014960,0.01755335,667.66253625,-0.00819146,-0.00936189,0.00000000,0.00000000,0.00000000,0.00000000
46.50000000,0.14106900,7.38240000,0.00456256,491.33550169,0.00455218,493.57724721,0.00003716,0.01837843,673.54372123,-0.00865408,-0.00972436,0.00000000,0.00000000,0.00000000,0.00000000
48.00000000,0.15366800,7.52670000,0.00503511,500.93938564,0.00502248,503.46167111,0.00008911,0.01918805,678.66597911,-0.00905831,-0.01012974,0.00000000,0.00000000,0.00000000,0.00000000
49.50000000,0.16752000,7.67830000,0.00562433,511.02912096,0.00560858,513.90331908,0.00042565,0.02008519,683.74703897,-0.00955210,-0.01053309,0.00000000,0.00000000,0.00000000,0.00000000
51.00000000,0.18349600,7.81780000,0.00612733,520.31354100,0.00610864,523.50167550,0.00066426,0.02095899,688.93024118,-0.00998564,-0.01097335,0.00000000,0.00000000,0.00000000,0.00000000
52.50000000,0.19954000,7.94300000,0.00656289,528.64622479,0.00654145,532.11567123,0.00052971,0.02184556,693.58332108,-0.01045270,-0.01139286,0.00000000,0.00000000,0.00000000,0.00000000
54.00000000,0.21677000,8.07860000,0.00709578,537.67108040,0.00707072,541.48627490,0.00029063,0.02273274,698.68340847,-0.01093377,-0.01179897,0.00000000,0.00000000,0.00000000,0.00000000
55.50000000,0.23406900,8.19660000,0.00773400,545.52456831,0.00770425,549.74365533,0.00043226,0.02365743,703.43452960,-0.01143681,-0.01222061,0.00000000,0.00000000,0.00000000,0.00000000
57.00000000,0.25278700,8.30510000,0.00833844,552.74578390,0.00830387,557.35482391,0.00043200,0.02457307,708.35244955,-0.01188255,-0.01269052,0.00000000,0.00000000,0.00000000,0.00000000
58.50000000,0.27137100,8.42630000,0.00892044,560.81224776,0.00888089,565.81494226,0.00030530,0.02549892,712.46144888,-0.01235649,-0.01314243,0.00000000,0.00000000,0.00000000,0.00000000
60.00000000,0.29073400,8.53400000,0.00959256,567.98021936,0.00954684,573.42860117,0.00021572,0.02641664,717.34238595,-0.01282894,-0.01358769,0.00000000,0.00000000,0.00000000,0.00000000
61.50000000,0.31067300,8.63600000,0.01032489,574.76882756,0.01027195,580.70325184,0.00045359,0.02741877,721.14284319,-0.01338745,-0.01403132,0.00000000,0.00000000,0.00000000,0.00000000
63.00000000,0.33155900,8.75010000,0.01100456,582.36275104,0.01094445,588.77139429,0.00049044,0.02831922,725.42100339,-0.01385694,-0.01446228,0.00000000,0.00000000,0.00000000,0.00000000
64.50000000,0.35264600,8.84580000,0.01166922,588.73206285,0.01160166,595.60210813,0.00035654,0.02933038,729.96006801,-0.01443247,-0.01489791,0.00000000,0.00000000,0.00000000,0.00000000
66.00000000,0.37457900,8.93590000,0.01245778,594.72866676,0.01238082,602.13766433,0.00050445,0.03030249,734.08520215,-0.01495245,-0.01535003,0.00000000,0.00000000,0.00000000,0.00000000
67.50000000,0.39617400,9.03560000,0.01318633,601.36419850,0.01310015,609.29398728,0.00063769,0.03126448,737.82999118,-0.01546880,-0.01579568,0.00000000,0.00000000,0.00000000,0.00000000
69.00000000,0.41810900,9.12410000,0.01388489,607.25431444,0.01378938,615.68597313,0.00063725,0.03227510,741.83223241,-0.01595221,-0.01632289,0.00000000,0.00000000,0.00000000,0.00000000
70.50000000,0.44068500,9.21420000,0.01460967,613.25091835,0.01450397,622.21030985,0.00048125,0.03328422,745.90321412,-0.01651040,-0.01677383,0.00000000,0.00000000,0.00000000,0.00000000
72.00000000,0.46349900,9.30510000,0.01542456,619.30076625,0.01530681,628.85320532,0.00058441,0.03436060,749.31093000,-0.01709632,-0.01726428,0.00000000,0.00000000,0.00000000,0.00000000
73.50000000,0.48732700,9.39120000,0.01622078,625.03115023,0.01609063,635.16964162,0.00065788,0.03538305,753.17758015,-0.01765760,-0.01772545,0.00000000,0.00000000,0.00000000,0.00000000
75.00000000,0.51233800,9.47180000,0.01696811,630.39548180,0.01682576,641.09210238,0.00056144,0.03642366,756.79414516,-0.01821720,-0.01820646,0.00000000,0.00000000,0.00000000,0.00000000
76.50000000,0.53697700,9.55230000,0.01779433,635.75315788,0.01763787,647.06596149,0.00047232,0.03746109,760.08105391,-0.01873880,-0.01872228,0.00000000,0.00000000,0.00000000,0.00000000
78.00000000,0.56161600,9.63050000,0.01863189,640.95775750,0.01846044,652.90001122,0.00043505,0.03853505,763.78527396,-0.01930044,-0.01923461,0.00000000,0.00000000,0.00000000,0.00000000
79.50000000,0.58683000,9.70700000,0.01948444,646.04921365,0.01929705,658.63712366,0.00060432,0.03957754,767.03303680,-0.01986871,-0.01970883,0.00000000,0.00000000,0.00000000,0.00000000
81.00000000,0.61282200,9.78360000,0.02029567,651.14732530,0.02009245,664.36279437,0.00039775,0.04063689,770.29987777,-0.02038849,-0.02024840,0.00000000,0.00000000,0.00000000,0.00000000
82.50000000,0.63905000,9.85780000,0.02118200,656.08570499,0.02096078,669.98291239,0.00045617,0.04172177,773.98416487,-0.02096317,-0.02075860,0.00000000,0.00000000,0.00000000,0.00000000
84.00000000,0.66615800,9.92390000,0.02206456,660.48498932,0.02182466,675.05829706,0.00047774,0.04285059,777.20607291,-0.02160439,-0.02124620,0.00000000,0.00000000,0.00000000,0.00000000
85.50000000,0.69265700,9.99410000,0.02299967,665.15714909,0.02273916,680.45554180,0.00063875,0.04392521,780.27980502,-0.02213058,-0.02179463,0.00000000,0.00000000,0.00000000,0.00000000
87.00000000,0.72010200,10.05790000,0.02388600,669.40335696,0.02360519,685.39272554,0.00052812,0.04498733,783.46173386,-0.02268564,-0.02230169,0.00000000,0.00000000,0.00000000,0.00000000
88.50000000,0.74758200,10.12250000,0.02479489,673.70280882,0.02449248,690.40719511,0.00050575,0.04609647,786.29353919,-0.02329424,-0.02280222,0.00000000,0.00000000,0.00000000,0.00000000
90.00000000,0.77638000,10.18550000,0.02577889,677.89577271,0.02545222,695.37117251,0.00060776,0.04718735,789.67866151,-0.02386714,-0.02332022,0.00000000,0.00000000,0.00000000,0.00000000
91.50000000,0.80467000,10.24770000,0.02671411,682.03549261,0.02636352,700.25546454,0.00060742,0.04834829,792.33783551,-0.02451561,-0.02383268,0.00000000,0.00000000,0.00000000,0.00000000
93.00000000,0.83353600,10.30590000,0.02766433,685.90899258,0.02728859,704.88420759,0.00056295,0.04946505,795.75610596,-0.02509530,-0.02436975,0.00000000,0.00000000,0.00000000,0.00000000
94.50000000,0.86233400,10.36730000,0.02867078,689.99546850,0.02826746,709.77817524,0.00064257,0.05061665,798.30610198,-0.02573111,-0.02488554,0.00000000,0.00000000,0.00000000,0.00000000
96.00000000,0.89187600,10.42160000,0.02961722,693.60940404,0.02918710,714.15218789,0.00059103,0.05176803,801.36932185,-0.02636213,-0.02540589,0.00000000,0.00000000,0.00000000,0.00000000
97.50000000,0.92199200,10.47420000,0.03064256,697.11019611,0.03018245,718.47143402,0.00069979,0.05292335,804.04582548,-0.02697265,-0.02595070,0.00000000,0.00000000,0.00000000,0.00000000
99.00000000,0.95237900,10.52760000,0.03166789,700.66423217,0.03117680,722.85278922,0.00064803,0.05406132,806.38072489,-0.02757359,-0.02648773,0.00000000,0.00000000,0.00000000,0.00000000
100.50000000,0.98269800,10.57870000,0.03267067,704.06519177,0.03214833,727.06747096,0.00074944,0.05521621,809.35032116,-0.02817972,-0.02703649,0.00000000,0.00000000,0.00000000,0.00000000
102.00000000,1.01379500,10.62810000,0.03366589,707.35300789,0.03311160,731.16667566,0.00061043,0.05642241,811.62957933,-0.02880133,-0.02762108,0.00000000,0.00000000,0.00000000,0.00000000
103.50000000,1.04445200,10.67840000,0.03472500,710.70072351,0.03413569,735.37980613,0.00067512,0.05753248,814.51671404,-0.02938432,-0.02814816,0.00000000,0.00000000,0.00000000,0.00000000
105.00000000,1.07605600,10.72300000,0.03579167,713.66907572,0.03516603,739.21248139,0.00077615,0.05874502,817.10218170,-0.03006483,-0.02868019,0.00000000,0.00000000,0.00000000,0.00000000
106.50000000,1.10776100,10.76530000,0.03686200,716.48435147,0.03619884,742.89539764,0.00078243,0.05994341,819.38913498,-0.03070951,-0.02923390,0.00000000,0.00000000,0.00000000,0.00000000
108.00000000,1.14004100,10.81310000,0.03793233,719.66567963,0.03723059,746.96427808,0.00078890,0.06110066,821.87468503,-0.03127658,-0.02982408,0.00000000,0.00000000,0.00000000,0.00000000
109.50000000,1.17218500,10.85620000,0.03899522,722.53419937,0.03825411,750.70958104,0.00065073,0.06231622,824.36323354,-0.03194508,-0.03037114,0.00000000,0.00000000,0.00000000,0.00000000
111.00000000,1.20483700,10.89770000,0.04012200,725.29623113,0.03933801,754.39656652,0.00073680,0.06351741,826.60885977,-0.03258995,-0.03092746,0.00000000,0.00000000,0.00000000,0.00000000
112.50000000,1.23782700,10.93670000,0.04118478,727.89187545,0.04035927,757.86994058,0.00066367,0.06472279,829.14849493,-0.03322258,-0.03150021,0.00000000,0.00000000,0.00000000,0.00000000
114.00000000,1.27112000,10.97740000,0.04227022,730.60066323,0.04140124,761.48331562,0.00064144,0.06595542,831.55105064,-0.03391789,-0.03203753,0.00000000,0.00000000,0.00000000,0.00000000
115.50000000,1.30451600,11.01090000,0.04344578,732.83025514,0.04252848,764.66863555,0.00071272,0.06715240,833.74910678,-0.03455409,-0.03259830,0.00000000,0.00000000,0.00000000,0.00000000
117.00000000,1.33831700,11.05000000,0.04453489,735.43255495,0.04357170,768.18496207,0.00068325,0.06834070,836.00864616,-0.03518024,-0.03316046,0.00000000,0.00000000,0.00000000,0.00000000
118.50000000,1.37259100,11.08830000,0.04567667,737.98161077,0.04466420,771.69015081,0.00071843,0.06956869,838.41370501,-0.03586379,-0.03370489,0.00000000,0.00000000,0.00000000,0.00000000
120.00000000,1.40689900,11.12340000,0.04684089,740.31769065,0.04577695,774.99482934,0.00073908,0.07078232,840.58810833,-0.03652234,-0.03425997,0.00000000,0.00000000,0.00000000,0.00000000
121.50000000,1.44181500,11.15760000,0.04796011,742.59387105,0.04684552,778.20875561,0.00058790,0.07205050,842.69018558,-0.03718862,-0.03486189,0.00000000,0.00000000,0.00000000,0.00000000
123.00000000,1.47592100,11.19110000,0.04916944,744.82346296,0.04799885,781.44601884,0.00071604,0.07331042,844.73873121,-0.03785056,-0.03545987,0.00000000,0.00000000,0.00000000,0.00000000
124.50000000,1.51100600,11.21830000,0.05031500,746.63375848,0.04909012,784.20063603,0.00074404,0.07454479,846.70434930,-0.03847124,-0.03607355,0.00000000,0.00000000,0.00000000,0.00000000
126.00000000,1.54636200,11.25570000,0.05148678,749.12291482,0.05020514,787.69283986,0.00072884,0.07579737,848.87004351,-0.03913336,-0.03666401,0.00000000,0.00000000,0.00000000,0.00000000
127.50000000,1.58205600,11.28520000,0.05271489,751.08628679,0.05137244,790.67971695,0.00084941,0.07707631,850.99717140,-0.03977501,-0.03730130,0.00000000,0.00000000,0.00000000,0.00000000
129.00000000,1.61798600,11.31160000,0.05393167,752.84333833,0.05252762,793.44543430,0.00081257,0.07834326,853.12536927,-0.04045082,-0.03789244,0.00000000,0.00000000,0.00000000,0.00000000
130.50000000,1.65395100,11.34110000,0.05514478,754.80671031,0.05367799,796.43035861,0.00084725,0.07958181,855.05886928,-0.04107401,-0.03850779,0.00000000,0.00000000,0.00000000,0.00000000
132.00000000,1.68981400,11.36820000,0.05633911,756.61035033,0.05480926,799.23710492,0.00078231,0.08089808,856.99728764,-0.04180359,-0.03909448,0.00000000,0.00000000,0.00000000,0.00000000
133.50000000,1.72635300,11.39930000,0.05753711,758.68021028,0.05594272,802.33247784,0.00071731,0.08216726,859.08086833,-0.04247113,-0.03969613,0.00000000,0.00000000,0.00000000,0.00000000
135.00000000,1.76309400,11.42320000,0.05878033,760.27087436,0.05711762,804.95984978,0.00073095,0.08346028,860.83887578,-0.04319839,-0.04026189,0.00000000,0.00000000,0.00000000,0.00000000
136.50000000,1.79966700,11.44470000,0.05999344,761.70180648,0.05826272,807.39892149,0.00072299,0.08475807,862.71370737,-0.04388402,-0.04087405,0.00000000,0.00000000,0.00000000,0.00000000
138.00000000,1.83715200,11.47030000,0.06123278,763.40561403,0.05943123,810.15106035,0.00072193,0.08603098,864.40217433,-0.04454691,-0.04148407,0.00000000,0.00000000,0.00000000,0.00000000
139.50000000,1.87470500,11.49420000,0.06254356,764.99627811,0.06066561,812.84186533,0.00075661,0.08730762,866.38972611,-0.04523864,-0.04206898,0.00000000,0.00000000,0.00000000,0.00000000
141.00000000,1.91246100,11.51810000,0.06382422,766.58694218,0.06187017,815.51375753,0.00091807,0.08860940,868.51289435,-0.04590440,-0.04270500,0.00000000,0.00000000,0.00000000,0.00000000
142.50000000,1.94987900,11.53720000,0.06506356,767.85814235,0.06303447,817.81772325,0.00079698,0.08992552,870.13138505,-0.04658685,-0.04333867,0.00000000,0.00000000,0.00000000,0.00000000
144.00000000,1.98733100,11.56360000,0.06634800,769.61519388,0.06423973,820.67762276,0.00078893,0.09126289,871.94770503,-0.04730194,-0.04396095,0.00000000,0.00000000,0.00000000,0.00000000
145.50000000,2.02603300,11.57950000,0.06765500,770.67341810,0.06546465,822.81332820,0.00090062,0.09256756,873.79019837,-0.04797199,-0.04459557,0.00000000,0.00000000,0.00000000,0.00000000
147.00000000,2.06307800,11.59550000,0.06889444,771.73829782,0.06662488,824.90677910,0.00076626,0.09389821,875.54830521,-0.04864992,-0.04524829,0.00000000,0.00000000,0.00000000,0.00000000
148.50000000,2.10242300,11.61860000,0.07023144,773.27571791,0.06787493,827.58398853,0.00084257,0.09523433,877.19627872,-0.04931817,-0.04591616,0.00000000,0.00000000,0.00000000,0.00000000
150.00000000,2.14085500,11.63690000,0.07150833,774.49367409,0.06906731,829.87642590,0.00079239,0.09653721,879.05430911,-0.05001760,-0.04651960,0.00000000,0.00000000,0.00000000,0.00000000
151.50000000,2.17959100,11.65690000,0.07281911,775.82477373,0.07028987,832.31964413,0.00074936,0.09784695,880.49990803,-0.05071198,-0.04713497,0.00000000,0.00000000,0.00000000,0.00000000
153.00000000,2.21900300,11.66960000,0.07413356,776.67002201,0.07151434,834.24733223,0.00078342,0.09922163,882.19060804,-0.05149320,-0.04772843,0.00000000,0.00000000,0.00000000,0.00000000
154.50000000,2.25713000,11.68560000,0.07541800,777.73490173,0.07270942,836.39011255,0.00077546,0.10052337,883.87894564,-0.05215629,-0.04836708,0.00000000,0.00000000,0.00000000,0.00000000
156.00000000,2.29671100,11.70390000,0.07677000,778.95285790,0.07396582,838.75306881,0.00080937,0.10185872,885.24337478,-0.05288435,-0.04897436,0.00000000,0.00000000,0.00000000,0.00000000
157.50000000,2.33629200,11.72460000,0.07812578,780.33054604,0.07522414,841.29447687,0.00087805,0.10323739,887.06521012,-0.05372406,-0.04951332,0.00000000,0.00000000,0.00000000,0.00000000
159.00000000,2.37627900,11.73740000,0.07950411,781.18244981,0.07650178,843.28966610,0.00087693,0.10462209,888.59770057,-0.05441411,-0.05020798,0.00000000,0.00000000,0.00000000,0.00000000
160.50000000,2.41650200,11.75500000,0.08086000,782.35381750,0.07775702,845.61494719,0.00084806,0.10599385,890.35252369,-0.05511083,-0.05088302,0.00000000,0.00000000,0.00000000,0.00000000
162.00000000,2.45669200,11.77010000,0.08224578,783.35879774,0.07903831,847.78675133,0.00092319,0.10729383,892.65149326,-0.05580497,-0.05148887,0.00000000,0.00000000,0.00000000,0.00000000
163.50000000,2.49688100,11.78210000,0.08359033,784.15745752,0.08027991,849.70544078,0.00088060,0.10870006,893.43409011,-0.05656202,-0.05213804,0.00000000,0.00000000,0.00000000,0.00000000
165.00000000,2.53734100,11.79240000,0.08492356,784.84297384,0.08150953,851.49462973,0.00076169,0.11006631,895.14038791,-0.05727800,-0.05278831,0.00000000,0.00000000,0.00000000,0.00000000
166.50000000,2.57800300,11.80760000,0.08635078,785.85460957,0.08282417,853.71376633,0.00083682,0.11146577,896.51942626,-0.05802067,-0.05344510,0.00000000,0.00000000,0.00000000,0.00000000
168.00000000,2.61863200,11.82270000,0.08775156,786.85958981,0.08411277,855.90774282,0.00091852,0.11279636,897.89858151,-0.05868663,-0.05410973,0.00000000,0.00000000,0.00000000,0.00000000
169.50000000,2.65970000,11.83630000,0.08911489,787.76473757,0.08536534,857.96630463,0.00077264,0.11419026,899.63801317,-0.05944923,-0.05474103,0.00000000,0.00000000,0.00000000,0.00000000
171.00000000,2.70117400,11.84430000,0.09056456,788.29717743,0.08669550,859.68896094,0.00087476,0.11558410,900.95852561,-0.06020688,-0.05537722,0.00000000,0.00000000,0.00000000,0.00000000
172.50000000,2.74315500,11.85460000,0.09195800,788.98269374,0.08797242,861.53596430,0.00082580,0.11694260,902.30178393,-0.06092636,-0.05601625,0.00000000,0.00000000,0.00000000,0.00000000
174.00000000,2.78489900,11.86260000,0.09336633,789.51513360,0.08926132,863.22926674,0.00079017,0.11833153,903.86355605,-0.06166662,-0.05666491,0.00000000,0.00000000,0.00000000,0.00000000
175.50000000,2.82617000,11.87620000,0.09481600,790.42028136,0.09058631,865.36477076,0.00087827,0.11971869,905.36580435,-0.06236207,-0.05735662,0.00000000,0.00000000,0.00000000,0.00000000
177.00000000,2.86835400,11.88810000,0.09621311,791.21228565,0.09186161,867.33728120,0.00085667,0.12110544,906.56701925,-0.06309122,-0.05801422,0.00000000,0.00000000,0.00000000,0.00000000
178.50000000,2.91019900,11.89530000,0.09766278,791.69148153,0.09318317,869.01027075,0.00087599,0.12252166,908.10023274,-0.06383902,-0.05868263,0.00000000,0.00000000,0.00000000,0.00000000
180.00000000,2.95278900,11.90330000,0.09914633,792.22392138,0.09453382,870.77001837,0.00092962,0.12387150,909.27140141,-0.06458182,-0.05928968,0.00000000,0.00000000,0.00000000,0.00000000
181.50000000,2.99470200,11.91680000,0.10056600,793.12241365,0.09582459,872.88356230,0.00081914,0.12525160,910.65436469,-0.06529372,-0.05995787,0.00000000,0.00000000,0.00000000,0.00000000
183.00000000,3.03773000,11.91680000,0.10204567,793.12241365,0.09716815,874.05711909,0.00087937,0.12659725,911.94692380,-0.06601541,-0.06058184,0.00000000,0.00000000,0.00000000,0.00000000
184.50000000,3.08069100,11.94080000,0.10346911,794.71973322,0.09845895,876.94867760,0.00078294,0.12797317,913.39115887,-0.06675429,-0.06121888,0.00000000,0.00000000,0.00000000,0.00000000
186.00000000,3.12348400,11.93680000,0.10496011,794.45351329,0.09980924,877.83944232,0.00079556,0.00000000,0.00000000,0.00000000,0.00000000,0.00000000,0.00000000,0.00000000,0.00000000
187.50000000,3.16603900,11.94320000,0.10643978,794.87946518,0.10114745,879.48625881,0.00084855,0.00000000,0.00000000,0.00000000,0.00000000,0.00000000,0.00000000,0.00000000,0.00000000
189.00000000,3.20910100,11.95030000,0.10795711,795.35200555,0.10251788,881.21591039,0.00095614,0.00000000,0.00000000,0.00000000,0.00000000,0.00000000,0.00000000,0.00000000,0.00000000
190.50000000,3.25260300,11.95510000,0.10943689,795.67146947,0.10385258,882.74727967,0.00086008,0.00000000,0.00000000,0.00000000,0.00000000,0.00000000,0.00000000,0.00000000,0.00000000
192.00000000,3.29607100,11.95910000,0.11091667,795.93768940,0.10518550,884.22044478,0.00090636,0.00000000,0.00000000,0.00000000,0.00000000,0.00000000,0.00000000,0.00000000,0.00000000
193.50000000,3.34018100,11.96550000,0.11241889,796.36364129,0.10653682,885.88995699,0.00092533,0.00000000,0.00000000,0.00000000,0.00000000,0.00000000,0.00000000,0.00000000,0.00000000
195.00000000,3.38405500,11.96870000,0.11394367,796.57661723,0.10790657,887.34147778,0.00089013,0.00000000,0.00000000,0.00000000,0.00000000,0.00000000,0.00000000,0.00000000,0.00000000
196.50000000,3.42809800,11.97430000,0.11548733,796.94932513,0.10929138,888.98687749,0.00087574,0.00000000,0.00000000,0.00000000,0.00000000,0.00000000,0.00000000,0.00000000,0.00000000
198.00000000,3.47210700,11.97980000,0.11702711,797.31537753,0.11067079,890.62289281,0.00087434,0.00000000,0.00000000,0.00000000,0.00000000,0.00000000,0.00000000,0.00000000,0.00000000
199.50000000,3.51638600,11.98780000,0.11852944,797.84781739,0.11201483,892.41627594,0.00094054,0.00000000,0.00000000,0.00000000,0.00000000,0.00000000,0.00000000,0.00000000,0.00000000
201.00000000,3.56103700,11.98940000,0.12006922,797.95430536,0.11339049,893.76405818,0.00087196,0.00000000,0.00000000,0.00000000,0.00000000,0.00000000,0.00000000,0.00000000,0.00000000
202.50000000,3.60609400,11.99740000,0.12164656,798.48674522,0.11479774,895.61990744,0.00093773,0.00000000,0.00000000,0.00000000,0.00000000,0.00000000,0.00000000,0.00000000,0.00000000
204.00000000,3.65152200,11.99500000,0.12318644,798.32701327,0.11616969,896.67007953,0.00086954,0.00000000,0.00000000,0.00000000,0.00000000,0.00000000,0.00000000,0.00000000,0.00000000
205.50000000,3.69654500,12.00220000,0.12472622,798.80620914,0.11753965,898.43828989,0.00093516,0.00000000,0.00000000,0.00000000,0.00000000,0.00000000,0.00000000,0.00000000,0.00000000
207.00000000,3.74139900,12.00540000,0.12630367,799.01918508,0.11894118,899.93823789,0.00093385,0.00000000,0.00000000,0.00000000,0.00000000,0.00000000,0.00000000,0.00000000,0.00000000
208.50000000,3.78736900,12.00780000,0.12788100,799.17891704,0.12034065,901.37871613,0.00093255,0.00000000,0.00000000,0.00000000,0.00000000,0.00000000,0.00000000,0.00000000,0.00000000
210.00000000,3.83350700,12.01010000,0.12945833,799.33199350,0.12173817,902.81218116,0.00099778,0.00000000,0.00000000,0.00000000,0.00000000,0.00000000,0.00000000,0.00000000,0.00000000
211.50000000,3.87924000,12.01410000,0.13099822,799.59821343,0.12310063,904.34415788,0.00092997,0.00000000,0.00000000,0.00000000,0.00000000,0.00000000,0.00000000,0.00000000,0.00000000
213.00000000,3.92517500,12.01170000,0.13261311,799.43848147,0.12452745,905.45450564,0.00099500,0.00000000,0.00000000,0.00000000,0.00000000,0.00000000,0.00000000,0.00000000,0.00000000
214.50000000,3.97182000,12.01650000,0.13419056,799.75794539,0.12591923,907.07790839,0.00099361,0.00000000,0.00000000,0.00000000,0.00000000,0.00000000,0.00000000,0.00000000,0.00000000
216.00000000,4.01829700,12.01890000,0.13576789,799.91767734,0.12730898,908.52081168,0.00092607,0.00000000,0.00000000,0.00000000,0.00000000,0.00000000,0.00000000,0.00000000,0.00000000
217.50000000,4.06473900,12.01970000,0.13730778,799.97092133,0.12866387,909.81315082,0.00092501,0.00000000,0.00000000,0.00000000,0.00000000,0.00000000,0.00000000,0.00000000,0.00000000
219.00000000,4.11128300,12.01890000,0.13888511,799.91767734,0.13004981,911.01433284,0.00092353,0.00000000,0.00000000,0.00000000,0.00000000,0.00000000,0.00000000,0.00000000,0.00000000
220.50000000,4.15742200,12.01650000,0.14042500,799.75794539,0.13140100,912.06395487,0.00092229,0.00000000,0.00000000,0.00000000,0.00000000,0.00000000,0.00000000,0.00000000,0.00000000
222.00000000,4.20464200,12.02450000,0.14200233,800.29038524,0.13278315,913.93348729,0.00092101,0.00000000,0.00000000,0.00000000,0.00000000,0.00000000,0.00000000,0.00000000,0.00000000
223.50000000,4.25165900,12.01570000,0.14350467,799.70470140,0.00000000,0.00000000,0.00000000,0.00000000,0.00000000,0.00000000,0.00000000,0.00000000,0.00000000,0.00000000,0.00000000
225.00000000,4.29877700,12.01650000,0.14508200,799.75794539,0.00000000,0.00000000,0.00000000,0.00000000,0.00000000,0.00000000,0.00000000,0.00000000,0.00000000,0.00000000,0.00000000
226.50000000,4.34545700,12.01890000,0.14658433,799.91767734,0.00000000,0.00000000,0.00000000,0.00000000,0.00000000,0.00000000,0.00000000,0.00000000,0.00000000,0.00000000,0.00000000
228.00000000,4.39267700,12.02370000,0.14808656,800.23714126,0.00000000,0.00000000,0.00000000,0.00000000,0.00000000,0.00000000,0.00000000,0.00000000,0.00000000,0.00000000,0.00000000
229.50000000,4.44013300,12.01570000,0.14955133,799.70470140,0.00000000,0.00000000,0.00000000,0.00000000,0.00000000,0.00000000,0.00000000,0.00000000,0.00000000,0.00000000,0.00000000
231.00000000,4.48725200,12.00930000,0.15094089,799.27874951,0.00000000,0.00000000,0.00000000,0.00000000,0.00000000,0.00000000,0.00000000,0.00000000,0.00000000,0.00000000,0.00000000
232.50000000,4.53450600,12.01010000,0.15236800,799.33199350,0.00000000,0.00000000,0.00000000,0.00000000,0.00000000,0.00000000,0.00000000,0.00000000,0.00000000,0.00000000,0.00000000
234.00000000,4.58179300,12.00620000,0.15372011,799.07242907,0.00000000,0.00000000,0.00000000,0.00000000,0.00000000,0.00000000,0.00000000,0.00000000,0.00000000,0.00000000,0.00000000
235.50000000,4.62931700,12.00460000,0.15503467,798.96594110,0.00000000,0.00000000,0.00000000,0.00000000,0.00000000,0.00000000,0.00000000,0.00000000,0.00000000,0.00000000,0.00000000
237.00000000,4.67660500,11.99820000,0.15631156,798.53998921,0.00000000,0.00000000,0.00000000,0.00000000,0.00000000,0.00000000,0.00000000,0.00000000,0.00000000,0.00000000,0.00000000
238.50000000,4.72412900,11.99420000,0.15747589,798.27376928,0.00000000,0.00000000,0.00000000,0.00000000,0.00000000,0.00000000,0.00000000,0.00000000,0.00000000,0.00000000,0.00000000
240.00000000,4.77148500,11.98700000,0.15864011,797.79457341,0.00000000,0.00000000,0.00000000,0.00000000,0.00000000,0.00000000,0.00000000,0.00000000,0.00000000,0.00000000,0.00000000
241.50000000,4.81856900,11.98060000,0.15965411,797.36862152,0.00000000,0.00000000,0.00000000,0.00000000,0.00000000,0.00000000,0.00000000,0.00000000,0.00000000,0.00000000,0.00000000
243.00000000,4.86592500,11.97190000,0.16063067,796.78959317,0.00000000,0.00000000,0.00000000,0.00000000,0.00000000,0.00000000,0.00000000,0.00000000,0.00000000,0.00000000,0.00000000
244.50000000,4.91267200,11.96550000,0.16149444,796.36364129,0.00000000,0.00000000,0.00000000,0.00000000,0.00000000,0.00000000,0.00000000,0.00000000,0.00000000,0.00000000,0.00000000
246.00000000,4.96039900,11.95990000,0.16224556,795.99093339,0.00000000,0.00000000,0.00000000,0.00000000,0.00000000,0.00000000,0.00000000,0.00000000,0.00000000,0.00000000,0.00000000
247.50000000,5.00836300,11.94630000,0.16295911,795.08578563,0.00000000,0.00000000,0.00000000,0.00000000,0.00000000,0.00000000,0.00000000,0.00000000,0.00000000,0.00000000,0.00000000
249.00000000,5.05602300,11.92880000,0.16356000,793.92107343,0.00000000,0.00000000,0.00000000,0.00000000,0.00000000,0.00000000,0.00000000,0.00000000,0.00000000,0.00000000,0.00000000
250.50000000,5.10263500,11.91520000,0.16401078,793.01592567,0.00000000,0.00000000,0.00000000,0.00000000,0.00000000,0.00000000,0.00000000,0.00000000,0.00000000,0.00000000,0.00000000
252.00000000,5.15022800,11.89690000,0.16442389,791.79796950,0.00000000,0.00000000,0.00000000,0.00000000,0.00000000,0.00000000,0.00000000,0.00000000,0.00000000,0.00000000,0.00000000
253.50000000,5.19809100,11.87940000,0.16468678,790.63325731,0.00000000,0.00000000,0.00000000,0.00000000,0.00000000,0.00000000,0.00000000,0.00000000,0.00000000,0.00000000,0.00000000
255.00000000,5.24632700,11.85380000,0.16494978,788.92944976,0.00000000,0.00000000,0.00000000,0.00000000,0.00000000,0.00000000,0.00000000,0.00000000,0.00000000,0.00000000,0.00000000
256.50000000,5.29392200,11.82590000,0.16510011,787.07256575,0.00000000,0.00000000,0.00000000,0.00000000,0.00000000,0.00000000,0.00000000,0.00000000,0.00000000,0.00000000,0.00000000
258.00000000,5.34243000,11.79240000,0.16521278,784.84297384,0.00000000,0.00000000,0.00000000,0.00000000,0.00000000,0.00000000,0.00000000,0.00000000,0.00000000,0.00000000,0.00000000
259.50000000,5.39083900,11.76290000,0.16528800,782.87960186,0.00000000,0.00000000,0.00000000,0.00000000,0.00000000,0.00000000,0.00000000,0.00000000,0.00000000,0.00000000,0.00000000
261.00000000,5.44002700,11.71750000,0.16532556,779.85800566,0.00000000,0.00000000,0.00000000,0.00000000,0.00000000,0.00000000,0.00000000,0.00000000,0.00000000,0.00000000,0.00000000
262.50000000,5.48925100,11.67200000,0.16532578,776.82975397,0.00000000,0.00000000,0.00000000,0.00000000,0.00000000,0.00000000,0.00000000,0.00000000,0.00000000,0.00000000,0.00000000
264.00000000,5.53915500,11.61860000,0.16540089,773.27571791,0.00000000,0.00000000,0.00000000,0.00000000,0.00000000,0.00000000,0.00000000,0.00000000,0.00000000,0.00000000,0.00000000
265.50000000,5.58929900,11.55000000,0.16532589,768.71004612,0.00000000,0.00000000,0.00000000,0.00000000,0.00000000,0.00000000,0.00000000,0.00000000,0.00000000,0.00000000,0.00000000
267.00000000,5.64147700,11.48220000,0.16532600,764.19761832,0.00000000,0.00000000,0.00000000,0.00000000,0.00000000,0.00000000,0.00000000,0.00000000,0.00000000,0.00000000,0.00000000
268.50000000,5.69352200,11.40090000,0.16532600,758.78669825,0.00000000,0.00000000,0.00000000,0.00000000,0.00000000,0.00000000,0.00000000,0.00000000,0.00000000,0.00000000,0.00000000
270.00000000,5.74749700,11.30040000,0.16525089,752.09792253,0.00000000,0.00000000,0.00000000,0.00000000,0.00000000,0.00000000,0.00000000,0.00000000,0.00000000,0.00000000,0.00000000
271.50000000,5.80381400,11.18710000,0.16525089,744.55724303,0.00000000,0.00000000,0.00000000,0.00000000,0.00000000,0.00000000,0.00000000,0.00000000,0.00000000,0.00000000,0.00000000
273.00000000,5.86287500,11.03640000,0.16510044,734.52740719,0.00000000,0.00000000,0.00000000,0.00000000,0.00000000,0.00000000,0.00000000,0.00000000,0.00000000,0.00000000,0.00000000