File: polyN_optimization/results_exp/DP780/UT_90_3.csv
Time[s],Displacement[mm],Force[kN],EngStrain_longi,EngStress[MPa],TrueStrain,TrueStress[MPa],TrueStrainRate[1/s],PlasticStrain_longi,PlasticStress[MPa],PlasticStrain_thick,PlasticStrain_width,R-Value,Thickness[mm],Width[mm], Young's Modulus [MPa]
0.00000000,0.00000000,-0.01820000,0.00000000,-1.21186770,0.00000000,-1.21186770,0.00000000,0.00059185,420.86345443,0.00027600,-0.00086785,0.87774654,1.49780000,10.02680000,208408.92136452
1.50000000,0.00216200,0.29680000,0.00001789,19.76276553,0.00001789,19.76311906,0.00000244,0.00075530,433.68511352,0.00040106,-0.00115636,0.00000000,0.00000000,0.00000000,0.00000000
3.00000000,0.00380600,0.63420000,0.00008378,42.22892822,0.00008377,42.23246607,-0.00001133,0.00089441,446.92998606,0.00022021,-0.00111462,0.00000000,0.00000000,0.00000000,0.00000000
4.50000000,0.00599700,1.00020000,0.00018033,66.59945444,0.00018032,66.61146454,-0.00002177,0.00112201,459.63182730,0.00017539,-0.00129740,0.00000000,0.00000000,0.00000000,0.00000000
6.00000000,0.00841100,1.31760000,0.00025389,87.73389439,0.00025386,87.75616906,0.00019063,0.00140647,471.34978318,0.00012015,-0.00152662,0.00000000,0.00000000,0.00000000,0.00000000
7.50000000,0.01048900,1.60870000,0.00030089,107.11711894,0.00030084,107.14934929,0.00012841,0.00172176,483.63338060,-0.00020679,-0.00151497,0.00000000,0.00000000,0.00000000,0.00000000
9.00000000,0.01192900,1.90140000,0.00032589,126.60688130,0.00032584,126.64814108,0.00004443,0.00203712,495.06136308,-0.00020825,-0.00182887,0.00000000,0.00000000,0.00000000,0.00000000
10.50000000,0.01348600,2.16850000,0.00037822,144.39203855,0.00037815,144.44665083,-0.00000822,0.00239599,505.93635324,-0.00031550,-0.00208049,0.00000000,0.00000000,0.00000000,0.00000000
12.00000000,0.01525300,2.42450000,0.00044578,161.43808968,0.00044568,161.51005519,-0.00005464,0.00282017,517.17614534,-0.00059482,-0.00222534,0.00000000,0.00000000,0.00000000,0.00000000
13.50000000,0.01778900,2.69090000,0.00056011,179.17663663,0.00055995,179.27699546,-0.00004486,0.00338962,527.64405029,-0.00096357,-0.00242605,0.00000000,0.00000000,0.00000000,0.00000000
15.00000000,0.02097200,2.92530000,0.00067178,194.78442719,0.00067155,194.91527904,0.00011482,0.00384671,537.42586998,-0.00104008,-0.00280663,0.00000000,0.00000000,0.00000000,0.00000000
16.50000000,0.02306700,3.15420000,0.00075478,210.02599400,0.00075449,210.18451696,0.00021052,0.00439268,547.25947814,-0.00131448,-0.00307820,0.00000000,0.00000000,0.00000000,0.00000000
18.00000000,0.02445300,3.40460000,0.00076733,226.69916276,0.00076704,226.87311659,0.00015256,0.00500154,556.33913805,-0.00171733,-0.00328420,0.00000000,0.00000000,0.00000000,0.00000000
19.50000000,0.02640400,3.62870000,0.00076867,241.62111611,0.00076837,241.80684221,-0.00007483,0.00558837,565.25638670,-0.00200972,-0.00357865,0.00000000,0.00000000,0.00000000,0.00000000
21.00000000,0.02915700,3.84080000,0.00085911,255.74403581,0.00085874,255.96374836,-0.00021003,0.00626061,574.12604563,-0.00232885,-0.00393176,0.00000000,0.00000000,0.00000000,0.00000000
22.50000000,0.03187500,4.08240000,0.00103222,271.83124657,0.00103169,272.11183682,0.00001554,0.00681661,582.29299759,-0.00252156,-0.00429505,0.00000000,0.00000000,0.00000000,0.00000000
24.00000000,0.03466300,4.29380000,0.00119467,285.90755597,0.00119395,286.24912020,0.00034606,0.00748579,590.86709714,-0.00278588,-0.00469991,0.00000000,0.00000000,0.00000000,0.00000000
25.50000000,0.03722000,4.50750000,0.00119878,300.13701350,0.00119806,300.49681108,0.00024017,0.00819161,598.65816895,-0.00322727,-0.00496434,0.00000000,0.00000000,0.00000000,0.00000000
27.00000000,0.04071800,4.73000000,0.00122922,314.95242903,0.00122847,315.33957555,0.00000777,0.00888687,606.24463929,-0.00350591,-0.00538096,0.00000000,0.00000000,0.00000000,0.00000000
28.50000000,0.04438500,4.93730000,0.00132011,328.75573527,0.00131924,329.18972937,-0.00022458,0.00955292,613.60755825,-0.00390549,-0.00564743,0.00000000,0.00000000,0.00000000,0.00000000
30.00000000,0.04761300,5.14390000,0.00151589,342.51243122,0.00151474,343.03164201,-0.00010473,0.01028067,621.17461368,-0.00427648,-0.00600419,0.00000000,0.00000000,0.00000000,0.00000000
31.50000000,0.05121200,5.36640000,0.00178678,357.32784675,0.00178518,357.96631221,0.00029283,0.01109572,628.16449316,-0.00474209,-0.00635363,0.00000000,0.00000000,0.00000000,0.00000000
33.00000000,0.05542300,5.56500000,0.00185489,370.55185360,0.00185317,371.23918612,0.00034517,0.01183982,635.12062664,-0.00511407,-0.00672574,0.00000000,0.00000000,0.00000000,0.00000000
34.50000000,0.06147800,5.76510000,0.00196789,383.87573966,0.00196596,384.63116446,0.00025507,0.01260525,642.15524788,-0.00549694,-0.00710831,0.00000000,0.00000000,0.00000000,0.00000000
36.00000000,0.06717400,5.97010000,0.00203933,397.52589779,0.00203726,398.33658560,0.00001486,0.01336414,648.87055336,-0.00583780,-0.00752634,0.00000000,0.00000000,0.00000000,0.00000000
37.50000000,0.07289000,6.17020000,0.00227622,410.84978384,0.00227364,411.78496925,-0.00013480,0.01420171,655.21291087,-0.00624296,-0.00795876,0.00000000,0.00000000,0.00000000,0.00000000
39.00000000,0.08056600,6.36400000,0.00256556,423.75417723,0.00256227,424.84134212,-0.00006738,0.01508199,661.70980696,-0.00671114,-0.00837085,0.00000000,0.00000000,0.00000000,0.00000000
40.50000000,0.08888800,6.56420000,0.00290344,437.08472191,0.00289924,438.35377311,0.00015755,0.01594050,667.97876001,-0.00720171,-0.00873879,0.00000000,0.00000000,0.00000000,0.00000000
42.00000000,0.09750000,6.75320000,0.00317733,449.66950184,0.00317230,451.09825174,0.00029929,0.01673986,673.35289694,-0.00762182,-0.00911803,0.00000000,0.00000000,0.00000000,0.00000000
43.50000000,0.10638700,6.93100000,0.00347000,461.50851704,0.00346399,463.10995159,0.00030652,0.01763014,679.55453148,-0.00808371,-0.00954643,0.00000000,0.00000000,0.00000000,0.00000000
45.00000000,0.11713300,7.12000000,0.00380778,474.09329697,0.00380055,475.89853889,0.00029911,0.01853185,685.50862640,-0.00862937,-0.00990247,0.00000000,0.00000000,0.00000000,0.00000000
46.50000000,0.12881100,7.28990000,0.00425800,485.40628168,0.00424896,487.47314163,0.00044836,0.01943166,690.92520612,-0.00911921,-0.01031245,0.00000000,0.00000000,0.00000000,0.00000000
48.00000000,0.14056300,7.45260000,0.00464444,496.23984621,0.00463369,498.54460460,0.00047828,0.02033366,696.45539699,-0.00960166,-0.01073200,0.00000000,0.00000000,0.00000000,0.00000000
49.50000000,0.15454800,7.62320000,0.00500433,507.59944122,0.00499185,510.13963802,0.00037328,0.02126888,701.75163985,-0.01013897,-0.01112991,0.00000000,0.00000000,0.00000000,0.00000000
51.00000000,0.16950500,7.77480000,0.00545067,517.69389962,0.00543587,520.51567650,0.00030591,0.02221543,706.79133149,-0.01063600,-0.01157943,0.00000000,0.00000000,0.00000000,0.00000000
52.50000000,0.18453100,7.92150000,0.00597211,527.46208595,0.00595435,530.61214813,0.00010427,0.02310608,711.85512851,-0.01110374,-0.01200234,0.00000000,0.00000000,0.00000000,0.00000000
54.00000000,0.20094700,8.06740000,0.00658022,537.17700337,0.00655867,540.71174742,0.00030557,0.02410509,717.00559257,-0.01168147,-0.01242361,0.00000000,0.00000000,0.00000000,0.00000000
55.50000000,0.21938600,8.20220000,0.00721833,546.15281466,0.00719241,550.09512773,0.00038746,0.02503731,721.40254184,-0.01212423,-0.01291308,0.00000000,0.00000000,0.00000000,0.00000000
57.00000000,0.23955100,8.34180000,0.00785644,555.44823942,0.00782574,559.81208765,0.00034995,0.02600571,726.43917652,-0.01261590,-0.01338981,0.00000000,0.00000000,0.00000000,0.00000000
58.50000000,0.25894300,8.46220000,0.00844956,563.46521034,0.00841406,568.22624094,0.00026798,0.02702533,730.42740105,-0.01313067,-0.01389466,0.00000000,0.00000000,0.00000000,0.00000000
60.00000000,0.27921700,8.58100000,0.00924533,571.37564344,0.00920286,576.65820172,0.00041664,0.02801056,735.32875949,-0.01375234,-0.01425822,0.00000000,0.00000000,0.00000000,0.00000000
61.50000000,0.29999500,8.69900000,0.00996978,579.23280763,0.00992041,585.00763000,0.00066196,0.02897533,739.72709518,-0.01418394,-0.01479139,0.00000000,0.00000000,0.00000000,0.00000000
63.00000000,0.32091200,8.82340000,0.01066056,587.51612310,0.01060413,593.77937137,0.00060938,0.03001276,743.91817327,-0.01475990,-0.01525286,0.00000000,0.00000000,0.00000000,0.00000000
64.50000000,0.34406100,8.93830000,0.01140033,595.16687027,0.01133584,601.95197098,0.00058695,0.03105634,748.11502270,-0.01532033,-0.01573601,0.00000000,0.00000000,0.00000000,0.00000000
66.00000000,0.36460500,9.02840000,0.01210244,601.16628123,0.01202980,608.44186275,0.00051209,0.03206977,752.30415280,-0.01585149,-0.01621828,0.00000000,0.00000000,0.00000000,0.00000000
67.50000000,0.38957900,9.13520000,0.01293611,608.27768068,0.01285315,616.14642835,0.00075658,0.03311358,755.96269912,-0.01640672,-0.01670686,0.00000000,0.00000000,0.00000000,0.00000000
69.00000000,0.41272800,9.23890000,0.01367589,615.18266311,0.01358322,623.59583286,0.00068914,0.03416188,759.97167332,-0.01695334,-0.01720854,0.00000000,0.00000000,0.00000000,0.00000000
70.50000000,0.43675600,9.33300000,0.01445700,621.44841863,0.01435349,630.43269841,0.00053303,0.03520683,763.70096785,-0.01750355,-0.01770329,0.00000000,0.00000000,0.00000000,0.00000000
72.00000000,0.46095300,9.42390000,0.01527189,627.50109850,0.01515645,637.08422555,0.00058449,0.03627932,767.46552031,-0.01805786,-0.01822146,0.00000000,0.00000000,0.00000000,0.00000000
73.50000000,0.48660400,9.52280000,0.01610567,634.08646747,0.01597735,644.29885275,0.00062842,0.03734777,771.06716738,-0.01858837,-0.01875940,0.00000000,0.00000000,0.00000000,0.00000000
75.00000000,0.51178200,9.60970000,0.01693567,639.87280279,0.01679386,650.70947529,0.00067972,0.03841426,774.83455507,-0.01915404,-0.01926021,0.00000000,0.00000000,0.00000000,0.00000000
76.50000000,0.53783900,9.70070000,0.01780678,645.93214128,0.01765009,657.43411138,0.00065664,0.03950998,778.24826925,-0.01973436,-0.01977563,0.00000000,0.00000000,0.00000000,0.00000000
78.00000000,0.56376200,9.78200000,0.01866311,651.34559423,0.01849109,663.50172943,0.00051621,0.04059709,781.71777109,-0.02033128,-0.02026580,0.00000000,0.00000000,0.00000000,0.00000000
79.50000000,0.59103700,9.86090000,0.01960944,656.59924046,0.01941966,669.47478679,0.00059661,0.04171896,785.16546359,-0.02095941,-0.02075955,0.00000000,0.00000000,0.00000000,0.00000000
81.00000000,0.61753400,9.94630000,0.02049578,662.28569658,0.02028857,675.85975704,0.00068453,0.04283539,788.72775024,-0.02154270,-0.02129269,0.00000000,0.00000000,0.00000000,0.00000000
82.50000000,0.64508000,10.01880000,0.02140456,667.11319153,0.02117870,681.39245290,0.00062516,0.04398868,791.82166993,-0.02220952,-0.02177916,0.00000000,0.00000000,0.00000000,0.00000000
84.00000000,0.67343600,10.09380000,0.02237344,672.10715182,0.02212683,687.14450384,0.00066132,0.04512920,795.02387648,-0.02283072,-0.02229848,0.00000000,0.00000000,0.00000000,0.00000000
85.50000000,0.70172500,10.16560000,0.02330111,676.88803647,0.02303378,692.66027982,0.00062400,0.04623314,798.14693373,-0.02343498,-0.02279815,0.00000000,0.00000000,0.00000000,0.00000000
87.00000000,0.73025000,10.23500000,0.02428500,681.50911439,0.02399481,698.05956324,0.00068938,0.04739339,801.15246079,-0.02401669,-0.02337670,0.00000000,0.00000000,0.00000000,0.00000000
88.50000000,0.75928300,10.30280000,0.02525011,686.02365450,0.02493659,703.34582800,0.00065209,0.04856466,804.56731427,-0.02466879,-0.02389587,0.00000000,0.00000000,0.00000000,0.00000000
90.00000000,0.78855400,10.36970000,0.02620033,690.47826708,0.02586298,708.56902783,0.00056376,0.04975516,807.38417223,-0.02530251,-0.02445265,0.00000000,0.00000000,0.00000000,0.00000000
91.50000000,0.81795800,10.43030000,0.02721056,694.51338699,0.02684693,713.41148209,0.00070213,0.05090085,810.33967788,-0.02587705,-0.02502380,0.00000000,0.00000000,0.00000000,0.00000000
93.00000000,0.84800500,10.49330000,0.02818322,698.70831364,0.02779338,718.40016531,0.00054797,0.05208713,813.44722630,-0.02653783,-0.02554930,0.00000000,0.00000000,0.00000000,0.00000000
94.50000000,0.87832300,10.55320000,0.02923478,702.69682325,0.02881559,723.24000873,0.00068606,0.05326726,816.04645155,-0.02714760,-0.02611966,0.00000000,0.00000000,0.00000000,0.00000000
96.00000000,0.90945300,10.60900000,0.03027133,706.41232971,0.02982220,727.79637281,0.00071450,0.05445223,818.82480264,-0.02781230,-0.02663994,0.00000000,0.00000000,0.00000000,0.00000000
97.50000000,0.93970400,10.66480000,0.03119144,710.12783617,0.03071488,732.27774912,0.00042264,0.05563697,821.33175918,-0.02842705,-0.02720991,0.00000000,0.00000000,0.00000000,0.00000000
99.00000000,0.97208200,10.71740000,0.03234811,713.63026699,0.03183593,736.71485815,0.00064760,0.05687157,824.21869940,-0.02911500,-0.02775657,0.00000000,0.00000000,0.00000000,0.00000000
100.50000000,1.00344900,10.76850000,0.03342978,717.03281860,0.03288315,741.00306638,0.00077061,0.05805267,826.89646548,-0.02975319,-0.02829948,0.00000000,0.00000000,0.00000000,0.00000000
102.00000000,1.03545800,10.81710000,0.03447756,720.26890487,0.03389652,745.10201605,0.00068259,0.05928975,829.34836044,-0.03040575,-0.02888401,0.00000000,0.00000000,0.00000000,0.00000000
103.50000000,1.06790600,10.87060000,0.03557044,723.83126321,0.03495243,749.57826294,0.00066727,0.06049565,832.11419227,-0.03104303,-0.02945262,0.00000000,0.00000000,0.00000000,0.00000000
105.00000000,1.10028600,10.91680000,0.03664078,726.90754275,0.03598546,753.54200048,0.00066658,0.06165374,834.27438951,-0.03164839,-0.03000535,0.00000000,0.00000000,0.00000000,0.00000000
106.50000000,1.13341000,10.95990000,0.03778256,729.77740526,0.03708628,757.35026062,0.00074575,0.06289493,837.13730577,-0.03231587,-0.03057905,0.00000000,0.00000000,0.00000000,0.00000000
108.00000000,1.16650100,11.00850000,0.03886044,733.01349153,0.03812439,761.49872159,0.00068720,0.06413666,839.55570435,-0.03298993,-0.03114673,0.00000000,0.00000000,0.00000000,0.00000000
109.50000000,1.19972600,11.04680000,0.03996833,735.56374058,0.03919026,764.96299736,0.00069352,0.06533261,841.70370299,-0.03363839,-0.03169422,0.00000000,0.00000000,0.00000000,0.00000000
111.00000000,1.23322300,11.08990000,0.04111000,738.43360310,0.04028745,768.79060852,0.00070706,0.06658274,843.90876560,-0.03432220,-0.03226055,0.00000000,0.00000000,0.00000000,0.00000000
112.50000000,1.26688800,11.13290000,0.04224800,741.29680700,0.04137992,772.61511450,0.00072079,0.06781237,846.43827578,-0.03497782,-0.03283455,0.00000000,0.00000000,0.00000000,0.00000000
114.00000000,1.30136400,11.17440000,0.04340100,744.06013169,0.04248557,776.35308547,0.00076325,0.06907616,848.77893509,-0.03565850,-0.03341767,0.00000000,0.00000000,0.00000000,0.00000000
115.50000000,1.33573900,11.21030000,0.04455400,746.45057402,0.04359000,779.70793289,0.00074815,0.07032475,851.04640099,-0.03631408,-0.03401067,0.00000000,0.00000000,0.00000000,0.00000000
117.00000000,1.37045300,11.24460000,0.04573700,748.73447853,0.04472190,782.97934737,0.00080470,0.07159391,853.05463203,-0.03700045,-0.03459346,0.00000000,0.00000000,0.00000000,0.00000000
118.50000000,1.40546900,11.27890000,0.04694256,751.01838303,0.04587406,786.27310520,0.00083244,0.07287347,855.47269294,-0.03767845,-0.03519502,0.00000000,0.00000000,0.00000000,0.00000000
120.00000000,1.44062200,11.31320000,0.04810311,753.30228754,0.04698197,789.53847118,0.00078146,0.07417230,857.85435065,-0.03836930,-0.03580300,0.00000000,0.00000000,0.00000000,0.00000000
121.50000000,1.47634900,11.34820000,0.04931989,755.63280234,0.04814223,792.90052819,0.00076593,0.07543272,859.92528946,-0.03901562,-0.03641710,0.00000000,0.00000000,0.00000000,0.00000000
123.00000000,1.51163700,11.38170000,0.05051422,757.86343794,0.04927978,796.14632006,0.00072951,0.07672227,862.08332751,-0.03968031,-0.03704196,0.00000000,0.00000000,0.00000000,0.00000000
124.50000000,1.54739800,11.41360000,0.05171978,759.98753571,0.05042671,799.29392218,0.00078575,0.07804124,864.26381660,-0.04041980,-0.03762144,0.00000000,0.00000000,0.00000000,0.00000000
126.00000000,1.58397000,11.44950000,0.05296289,762.37797804,0.05160799,802.75571818,0.00079917,0.07931218,866.00707187,-0.04108556,-0.03822662,0.00000000,0.00000000,0.00000000,0.00000000
127.50000000,1.62034000,11.47340000,0.05419478,763.96938672,0.05277723,805.37253786,0.00076260,0.08065709,868.50924329,-0.04183028,-0.03882681,0.00000000,0.00000000,0.00000000,0.00000000
129.00000000,1.65731800,11.49980000,0.05547544,765.72726074,0.05399132,808.20632086,0.00078295,0.08195716,869.93530492,-0.04252919,-0.03942797,0.00000000,0.00000000,0.00000000,0.00000000
130.50000000,1.69378800,11.53090000,0.05672233,767.79808961,0.05517198,811.34938878,0.00082473,0.08326356,871.83616507,-0.04323717,-0.04002638,0.00000000,0.00000000,0.00000000,0.00000000
132.00000000,1.73090100,11.55640000,0.05798422,769.49603611,0.05636542,814.11466527,0.00080946,0.08459392,874.10500036,-0.04395260,-0.04064132,0.00000000,0.00000000,0.00000000,0.00000000
133.50000000,1.76764300,11.58510000,0.05925367,771.40705825,0.05756457,817.11575494,0.00082276,0.08594807,876.05540240,-0.04468402,-0.04126405,0.00000000,0.00000000,0.00000000,0.00000000
135.00000000,1.80573600,11.61140000,0.06047422,773.15827366,0.05871619,819.91441891,0.00072958,0.08729001,878.75343740,-0.04540623,-0.04188378,0.00000000,0.00000000,0.00000000,0.00000000
136.50000000,1.84305200,11.63370000,0.06179622,774.64314452,0.05996202,822.51316442,0.00082791,0.08863471,879.76477474,-0.04613745,-0.04249726,0.00000000,0.00000000,0.00000000,0.00000000
138.00000000,1.88128000,11.65530000,0.06310689,776.08140508,0.06119565,825.05748808,0.00079845,0.09001789,881.63418445,-0.04686665,-0.04315124,0.00000000,0.00000000,0.00000000,0.00000000
139.50000000,1.91957600,11.67600000,0.06437267,777.45973812,0.06238558,827.50689469,0.00079061,0.09138831,883.61351052,-0.04760258,-0.04378574,0.00000000,0.00000000,0.00000000,0.00000000
141.00000000,1.95810900,11.70390000,0.06568711,779.31749135,0.06361977,830.50860599,0.00076147,0.09276655,885.71409827,-0.04836515,-0.04440139,0.00000000,0.00000000,0.00000000,0.00000000
142.50000000,1.99633800,11.72070000,0.06699411,780.43613845,0.06484545,832.72076383,0.00077470,0.09414762,887.53361709,-0.04906869,-0.04507893,0.00000000,0.00000000,0.00000000,0.00000000
144.00000000,2.03503900,11.73900000,0.06828978,781.65466476,0.06605903,835.03368812,0.00086512,0.09550358,889.21586074,-0.04978267,-0.04572091,0.00000000,0.00000000,0.00000000,0.00000000
145.50000000,2.07374200,11.76370000,0.06960044,783.29934235,0.06728516,837.81732471,0.00080773,0.09691433,891.12765173,-0.05051919,-0.04639514,0.00000000,0.00000000,0.00000000,0.00000000
147.00000000,2.11278200,11.78210000,0.07094878,784.52452728,0.06854496,840.18558363,0.00082083,0.09833795,892.75825281,-0.05128486,-0.04705309,0.00000000,0.00000000,0.00000000,0.00000000
148.50000000,2.15239600,11.80280000,0.07226700,785.90286032,0.06977510,842.69770232,0.00086875,0.09978450,894.82042849,-0.05208240,-0.04770210,0.00000000,0.00000000,0.00000000,0.00000000
150.00000000,2.19174000,11.81800000,0.07358900,786.91496960,0.07100724,844.82325530,0.00081177,0.10118716,896.43849742,-0.05281023,-0.04837693,0.00000000,0.00000000,0.00000000,0.00000000
151.50000000,2.23135500,11.84750000,0.07497489,788.87926065,0.07229730,848.02539557,0.00090855,0.10260011,898.30678320,-0.05357419,-0.04902592,0.00000000,0.00000000,0.00000000,0.00000000
153.00000000,2.27161200,11.85220000,0.07634567,789.19221550,0.07357166,849.44362132,0.00090739,0.10404967,899.85395798,-0.05435587,-0.04969380,0.00000000,0.00000000,0.00000000,0.00000000
154.50000000,2.31105800,11.87380000,0.07767144,790.63047606,0.07480264,852.03988716,0.00085057,0.10551414,901.35753914,-0.05512024,-0.05039390,0.00000000,0.00000000,0.00000000,0.00000000
156.00000000,2.35097600,11.88490000,0.07902356,791.36958218,0.07605652,853.90642033,0.00080088,0.10698179,903.15800185,-0.05592893,-0.05105286,0.00000000,0.00000000,0.00000000,0.00000000
157.50000000,2.39126700,11.90330000,0.08046567,792.59476711,0.07739212,856.37143344,0.00088994,0.10846029,905.03905613,-0.05674592,-0.05171436,0.00000000,0.00000000,0.00000000,0.00000000
159.00000000,2.43270700,11.91290000,0.08184400,793.23399403,0.07866699,858.15543703,0.00081935,0.10997989,906.96116701,-0.05755651,-0.05242338,0.00000000,0.00000000,0.00000000,0.00000000
160.50000000,2.47370800,11.92720000,0.08321111,794.18617579,0.07992988,860.27128990,0.00080456,0.11147589,908.44503118,-0.05836218,-0.05311371,0.00000000,0.00000000,0.00000000,0.00000000
162.00000000,2.51460600,11.94400000,0.08461567,795.30482289,0.08122570,862.60007069,0.00079655,0.11300556,910.08241417,-0.05913470,-0.05387086,0.00000000,0.00000000,0.00000000,0.00000000
163.50000000,2.55594500,11.95670000,0.08605033,796.15046684,0.08254757,864.65947989,0.00078158,0.11453201,911.90051224,-0.05998240,-0.05454961,0.00000000,0.00000000,0.00000000,0.00000000
165.00000000,2.59738500,11.96790000,0.08747756,796.89623157,0.08386085,866.60676594,0.00084965,0.00000000,0.00000000,0.00000000,0.00000000,0.00000000,0.00000000,0.00000000,0.00000000
166.50000000,2.63902800,11.98060000,0.08896856,797.74187552,0.08523097,868.71581789,0.00087625,0.00000000,0.00000000,0.00000000,0.00000000,0.00000000,0.00000000,0.00000000,0.00000000
168.00000000,2.68084000,11.99020000,0.09036567,798.38110243,0.08651311,870.52734301,0.00082680,0.00000000,0.00000000,0.00000000,0.00000000,0.00000000,0.00000000,0.00000000,0.00000000
169.50000000,2.72278600,12.00620000,0.09189044,799.44648063,0.08791055,872.90797304,0.00099078,0.00000000,0.00000000,0.00000000,0.00000000,0.00000000,0.00000000,0.00000000,0.00000000
171.00000000,2.76527400,12.01250000,0.09333644,799.86597329,0.08923398,874.52261927,0.00095531,0.00000000,0.00000000,0.00000000,0.00000000,0.00000000,0.00000000,0.00000000,0.00000000
172.50000000,2.80799900,12.02690000,0.09478233,800.82481367,0.09055556,876.72885810,0.00087160,0.00000000,0.00000000,0.00000000,0.00000000,0.00000000,0.00000000,0.00000000,0.00000000
174.00000000,2.85082400,12.03410000,0.09626578,801.30423386,0.09190966,878.44240916,0.00087021,0.00000000,0.00000000,0.00000000,0.00000000,0.00000000,0.00000000,0.00000000,0.00000000
175.50000000,2.89348100,12.04440000,0.09776433,801.99007107,0.09327569,880.39609571,0.00090325,0.00000000,0.00000000,0.00000000,0.00000000,0.00000000,0.00000000,0.00000000,0.00000000
177.00000000,2.93610400,12.05720000,0.09927411,802.84237363,0.09465006,882.54383663,0.00086783,0.00000000,0.00000000,0.00000000,0.00000000,0.00000000,0.00000000,0.00000000,0.00000000
178.50000000,2.97977500,12.06600000,0.10079133,803.42833163,0.09602932,884.40694442,0.00086664,0.00000000,0.00000000,0.00000000,0.00000000,0.00000000,0.00000000,0.00000000,0.00000000
180.00000000,3.02287100,12.07230000,0.10232744,803.84782430,0.09742380,886.10351788,0.00087914,0.00000000,0.00000000,0.00000000,0.00000000,0.00000000,0.00000000,0.00000000,0.00000000
181.50000000,3.06671100,12.08350000,0.10388233,804.59358903,0.09883336,888.17664845,0.00091879,0.00000000,0.00000000,0.00000000,0.00000000,0.00000000,0.00000000,0.00000000,0.00000000
183.00000000,3.11041500,12.08750000,0.10539967,804.85993358,0.10020696,889.69190230,0.00093804,0.00000000,0.00000000,0.00000000,0.00000000,0.00000000,0.00000000,0.00000000,0.00000000
184.50000000,3.15489800,12.09710000,0.10703711,805.49916050,0.10168718,891.71746364,0.00105876,0.00000000,0.00000000,0.00000000,0.00000000,0.00000000,0.00000000,0.00000000,0.00000000
186.00000000,3.19870400,12.10110000,0.10857689,805.76550505,0.10307711,893.25301676,0.00097586,0.00000000,0.00000000,0.00000000,0.00000000,0.00000000,0.00000000,0.00000000,0.00000000
187.50000000,3.24321900,12.11060000,0.11016178,806.39807335,0.10450575,895.23231871,0.00092040,0.00000000,0.00000000,0.00000000,0.00000000,0.00000000,0.00000000,0.00000000,0.00000000
189.00000000,3.28763400,12.11780000,0.11174289,806.87749354,0.10592895,897.04031565,0.00094609,0.00000000,0.00000000,0.00000000,0.00000000,0.00000000,0.00000000,0.00000000,0.00000000
190.50000000,3.33289300,12.12180000,0.11334278,807.14383809,0.10736700,898.62776277,0.00097847,0.00000000,0.00000000,0.00000000,0.00000000,0.00000000,0.00000000,0.00000000,0.00000000
192.00000000,3.37798400,12.12660000,0.11498033,807.46345155,0.10883677,900.30586836,0.00100416,0.00000000,0.00000000,0.00000000,0.00000000,0.00000000,0.00000000,0.00000000,0.00000000
193.50000000,3.42304000,12.13690000,0.11661022,808.14928876,0.11029751,902.38775691,0.00098238,0.00000000,0.00000000,0.00000000,0.00000000,0.00000000,0.00000000,0.00000000,0.00000000
195.00000000,3.46850300,12.14010000,0.11828900,808.36236440,0.11179984,903.98274012,0.00103459,0.00000000,0.00000000,0.00000000,0.00000000,0.00000000,0.00000000,0.00000000,0.00000000
196.50000000,3.51440400,12.14330000,0.11996411,808.57544004,0.11329664,905.57547397,0.00105329,0.00000000,0.00000000,0.00000000,0.00000000,0.00000000,0.00000000,0.00000000,0.00000000
198.00000000,3.56111700,12.14730000,0.12162400,808.84178459,0.11477764,907.21635780,0.00095777,0.00000000,0.00000000,0.00000000,0.00000000,0.00000000,0.00000000,0.00000000,0.00000000
199.50000000,3.60708600,12.15130000,0.12333667,809.10812914,0.11630342,908.90082876,0.00100322,0.00000000,0.00000000,0.00000000,0.00000000,0.00000000,0.00000000,0.00000000,0.00000000
201.00000000,3.65369800,12.15930000,0.12502667,809.64081824,0.11780674,910.86751094,0.00093491,0.00000000,0.00000000,0.00000000,0.00000000,0.00000000,0.00000000,0.00000000,0.00000000
202.50000000,3.70068100,12.19440000,0.12682944,811.97799165,0.11940789,914.96070923,0.00106699,0.00000000,0.00000000,0.00000000,0.00000000,0.00000000,0.00000000,0.00000000,0.00000000
204.00000000,3.74837400,12.16410000,0.12863211,809.96043169,0.00000000,0.00000000,0.00000000,0.00000000,0.00000000,0.00000000,0.00000000,0.00000000,0.00000000,0.00000000,0.00000000
205.50000000,3.79593200,12.16640000,0.13035978,810.11357981,0.00000000,0.00000000,0.00000000,0.00000000,0.00000000,0.00000000,0.00000000,0.00000000,0.00000000,0.00000000,0.00000000
207.00000000,3.84379400,12.16880000,0.13216244,810.27338654,0.00000000,0.00000000,0.00000000,0.00000000,0.00000000,0.00000000,0.00000000,0.00000000,0.00000000,0.00000000,0.00000000
208.50000000,3.89158800,12.17120000,0.13396511,810.43319327,0.00000000,0.00000000,0.00000000,0.00000000,0.00000000,0.00000000,0.00000000,0.00000000,0.00000000,0.00000000,0.00000000
210.00000000,3.93958600,12.17360000,0.13580544,810.59300000,0.00000000,0.00000000,0.00000000,0.00000000,0.00000000,0.00000000,0.00000000,0.00000000,0.00000000,0.00000000,0.00000000
211.50000000,3.98839400,12.17200000,0.13768322,810.48646218,0.00000000,0.00000000,0.00000000,0.00000000,0.00000000,0.00000000,0.00000000,0.00000000,0.00000000,0.00000000,0.00000000
213.00000000,4.03791200,12.17680000,0.13959856,810.80607564,0.00000000,0.00000000,0.00000000,0.00000000,0.00000000,0.00000000,0.00000000,0.00000000,0.00000000,0.00000000,0.00000000
214.50000000,4.08736300,12.18240000,0.14155156,811.17895801,0.00000000,0.00000000,0.00000000,0.00000000,0.00000000,0.00000000,0.00000000,0.00000000,0.00000000,0.00000000,0.00000000
216.00000000,4.13722000,12.17840000,0.14354200,810.91261346,0.00000000,0.00000000,0.00000000,0.00000000,0.00000000,0.00000000,0.00000000,0.00000000,0.00000000,0.00000000,0.00000000
217.50000000,4.18717700,12.18080000,0.14553256,811.07242019,0.00000000,0.00000000,0.00000000,0.00000000,0.00000000,0.00000000,0.00000000,0.00000000,0.00000000,0.00000000,0.00000000
219.00000000,4.23662800,12.18000000,0.14752300,811.01915128,0.00000000,0.00000000,0.00000000,0.00000000,0.00000000,0.00000000,0.00000000,0.00000000,0.00000000,0.00000000,0.00000000
220.50000000,4.28692400,12.18000000,0.14962622,811.01915128,0.00000000,0.00000000,0.00000000,0.00000000,0.00000000,0.00000000,0.00000000,0.00000000,0.00000000,0.00000000,0.00000000
222.00000000,4.33830100,12.18160000,0.15176689,811.12568910,0.00000000,0.00000000,0.00000000,0.00000000,0.00000000,0.00000000,0.00000000,0.00000000,0.00000000,0.00000000,0.00000000
223.50000000,4.38917100,12.18000000,0.15387011,811.01915128,0.00000000,0.00000000,0.00000000,0.00000000,0.00000000,0.00000000,0.00000000,0.00000000,0.00000000,0.00000000,0.00000000
225.00000000,4.44071800,12.17520000,0.15612344,810.69953782,0.00000000,0.00000000,0.00000000,0.00000000,0.00000000,0.00000000,0.00000000,0.00000000,0.00000000,0.00000000,0.00000000
226.50000000,4.49240000,12.17520000,0.15830167,810.69953782,0.00000000,0.00000000,0.00000000,0.00000000,0.00000000,0.00000000,0.00000000,0.00000000,0.00000000,0.00000000,0.00000000
228.00000000,4.54516300,12.17360000,0.16059267,810.59300000,0.00000000,0.00000000,0.00000000,0.00000000,0.00000000,0.00000000,0.00000000,0.00000000,0.00000000,0.00000000,0.00000000
229.50000000,4.59762200,12.17120000,0.16295867,810.43319327,0.00000000,0.00000000,0.00000000,0.00000000,0.00000000,0.00000000,0.00000000,0.00000000,0.00000000,0.00000000,0.00000000
231.00000000,4.65001300,12.16800000,0.16536233,810.22011763,0.00000000,0.00000000,0.00000000,0.00000000,0.00000000,0.00000000,0.00000000,0.00000000,0.00000000,0.00000000,0.00000000
232.50000000,4.70308000,12.16880000,0.16780344,810.27338654,0.00000000,0.00000000,0.00000000,0.00000000,0.00000000,0.00000000,0.00000000,0.00000000,0.00000000,0.00000000,0.00000000
234.00000000,4.75682400,12.16490000,0.17028222,810.01370060,0.00000000,0.00000000,0.00000000,0.00000000,0.00000000,0.00000000,0.00000000,0.00000000,0.00000000,0.00000000,0.00000000
235.50000000,4.81141200,12.16330000,0.17294867,809.90716278,0.00000000,0.00000000,0.00000000,0.00000000,0.00000000,0.00000000,0.00000000,0.00000000,0.00000000,0.00000000,0.00000000
237.00000000,4.86559500,12.15530000,0.17565278,809.37447369,0.00000000,0.00000000,0.00000000,0.00000000,0.00000000,0.00000000,0.00000000,0.00000000,0.00000000,0.00000000,0.00000000
238.50000000,4.92021700,12.15290000,0.17839444,809.21466696,0.00000000,0.00000000,0.00000000,0.00000000,0.00000000,0.00000000,0.00000000,0.00000000,0.00000000,0.00000000,0.00000000
240.00000000,4.97494100,12.14890000,0.18117356,808.94832241,0.00000000,0.00000000,0.00000000,0.00000000,0.00000000,0.00000000,0.00000000,0.00000000,0.00000000,0.00000000,0.00000000
241.50000000,5.03084800,12.14010000,0.18417811,808.36236440,0.00000000,0.00000000,0.00000000,0.00000000,0.00000000,0.00000000,0.00000000,0.00000000,0.00000000,0.00000000,0.00000000
243.00000000,5.08648400,12.13770000,0.18729533,808.20255767,0.00000000,0.00000000,0.00000000,0.00000000,0.00000000,0.00000000,0.00000000,0.00000000,0.00000000,0.00000000,0.00000000
244.50000000,5.14326900,12.12980000,0.19041244,807.67652719,0.00000000,0.00000000,0.00000000,0.00000000,0.00000000,0.00000000,0.00000000,0.00000000,0.00000000,0.00000000,0.00000000
246.00000000,5.19995400,12.12500000,0.19386767,807.35691373,0.00000000,0.00000000,0.00000000,0.00000000,0.00000000,0.00000000,0.00000000,0.00000000,0.00000000,0.00000000,0.00000000
247.50000000,5.25741500,12.11460000,0.19728533,806.66441790,0.00000000,0.00000000,0.00000000,0.00000000,0.00000000,0.00000000,0.00000000,0.00000000,0.00000000,0.00000000,0.00000000
249.00000000,5.31507900,12.10500000,0.20096589,806.02519098,0.00000000,0.00000000,0.00000000,0.00000000,0.00000000,0.00000000,0.00000000,0.00000000,0.00000000,0.00000000,0.00000000
250.50000000,5.37362300,12.09230000,0.20468389,805.17954704,0.00000000,0.00000000,0.00000000,0.00000000,0.00000000,0.00000000,0.00000000,0.00000000,0.00000000,0.00000000,0.00000000
252.00000000,5.43192900,12.07950000,0.20862733,804.32724449,0.00000000,0.00000000,0.00000000,0.00000000,0.00000000,0.00000000,0.00000000,0.00000000,0.00000000,0.00000000,0.00000000
253.50000000,5.49084400,12.07000000,0.21272100,803.69467618,0.00000000,0.00000000,0.00000000,0.00000000,0.00000000,0.00000000,0.00000000,0.00000000,0.00000000,0.00000000,0.00000000
255.00000000,5.55074000,12.05080000,0.21700244,802.41622235,0.00000000,0.00000000,0.00000000,0.00000000,0.00000000,0.00000000,0.00000000,0.00000000,0.00000000,0.00000000,0.00000000
256.50000000,5.61033000,12.02930000,0.22143411,800.98462040,0.00000000,0.00000000,0.00000000,0.00000000,0.00000000,0.00000000,0.00000000,0.00000000,0.00000000,0.00000000,0.00000000
258.00000000,5.67090200,12.01170000,0.22616622,799.81270438,0.00000000,0.00000000,0.00000000,0.00000000,0.00000000,0.00000000,0.00000000,0.00000000,0.00000000,0.00000000,0.00000000
259.50000000,5.73174300,11.98860000,0.23097356,798.27456461,0.00000000,0.00000000,0.00000000,0.00000000,0.00000000,0.00000000,0.00000000,0.00000000,0.00000000,0.00000000,0.00000000
261.00000000,5.79251700,11.96150000,0.23600611,796.47008029,0.00000000,0.00000000,0.00000000,0.00000000,0.00000000,0.00000000,0.00000000,0.00000000,0.00000000,0.00000000,0.00000000
262.50000000,5.85403400,11.92960000,0.24118900,794.34598252,0.00000000,0.00000000,0.00000000,0.00000000,0.00000000,0.00000000,0.00000000,0.00000000,0.00000000,0.00000000,0.00000000
264.00000000,5.91572000,11.90010000,0.24648456,792.38169147,0.00000000,0.00000000,0.00000000,0.00000000,0.00000000,0.00000000,0.00000000,0.00000000,0.00000000,0.00000000,0.00000000
265.50000000,5.97818400,11.85700000,0.25204322,789.51182896,0.00000000,0.00000000,0.00000000,0.00000000,0.00000000,0.00000000,0.00000000,0.00000000,0.00000000,0.00000000,0.00000000
267.00000000,6.04074800,11.82190000,0.25786500,787.17465554,0.00000000,0.00000000,0.00000000,0.00000000,0.00000000,0.00000000,0.00000000,0.00000000,0.00000000,0.00000000,0.00000000
268.50000000,6.10375200,11.77650000,0.26372456,784.15164491,0.00000000,0.00000000,0.00000000,0.00000000,0.00000000,0.00000000,0.00000000,0.00000000,0.00000000,0.00000000,0.00000000
270.00000000,6.16736500,11.71670000,0.26996044,780.16979390,0.00000000,0.00000000,0.00000000,0.00000000,0.00000000,0.00000000,0.00000000,0.00000000,0.00000000,0.00000000,0.00000000
271.50000000,6.23104500,11.66090000,0.27642267,776.45428745,0.00000000,0.00000000,0.00000000,0.00000000,0.00000000,0.00000000,0.00000000,0.00000000,0.00000000,0.00000000,0.00000000
273.00000000,6.29513300,11.58830000,0.28303700,771.62013389,0.00000000,0.00000000,0.00000000,0.00000000,0.00000000,0.00000000,0.00000000,0.00000000,0.00000000,0.00000000,0.00000000
274.50000000,6.36013700,11.50610000,0.28987978,766.14675341,0.00000000,0.00000000,0.00000000,0.00000000,0.00000000,0.00000000,0.00000000,0.00000000,0.00000000,0.00000000,0.00000000
276.00000000,6.42599400,11.41280000,0.29702822,759.93426680,0.00000000,0.00000000,0.00000000,0.00000000,0.00000000,0.00000000,0.00000000,0.00000000,0.00000000,0.00000000,0.00000000
277.50000000,6.49429800,11.29480000,0.30456167,752.07710261,0.00000000,0.00000000,0.00000000,0.00000000,0.00000000,0.00000000,0.00000000,0.00000000,0.00000000,0.00000000,0.00000000
278.00000000,6.52074800,11.21750000,0.30750411,746.92999421,0.00000000,0.00000000,0.00000000,0.00000000,0.00000000,0.00000000,0.00000000,0.00000000,0.00000000,0.00000000,0.00000000