File: LAB_DATA/AA7020-T6_results/DATA/UT_00_1.csv
Time[s],Displacement[mm],Force[kN],EngStrain_longi,EngStress[MPa],TrueStrain,TrueStress[MPa],TrueStrainRate[1/s],PlasticStrain_longi,PlasticStress[MPa],PlasticStrain_thick,PlasticStrain_width,R-Value,Thickness[mm],Width[mm], Young's Modulus [MPa]
0.60000000,0.00000000,-0.01000000,0.00000000,-0.98810812,0.00000000,-0.98810812,0.00000000,0.00060277,341.48864022,-0.00052021,-0.00008255,0.67625064,1.00700000,10.05000000,68987.31020954
2.10000000,0.00913200,-0.00700000,0.00030567,-0.69167568,0.00030562,-0.69188711,0.00025638,0.00233340,342.68267257,-0.00187105,-0.00046235,0.00000000,0.00000000,0.00000000,0.00000000
3.60000000,0.01875200,0.31200000,0.00061822,30.82897331,0.00061803,30.84803246,-0.00000444,0.00586265,344.40148754,-0.00390715,-0.00195550,0.00000000,0.00000000,0.00000000,0.00000000
5.10000000,0.02804200,0.50300000,0.00098644,49.70183838,0.00098596,49.75086648,0.00011722,0.00633530,345.76952925,-0.00423338,-0.00210192,0.00000000,0.00000000,0.00000000,0.00000000
6.60000000,0.03498700,0.72300000,0.00134022,71.44021699,0.00133932,71.53596275,0.00040705,0.00701308,350.82660942,-0.00465087,-0.00236222,0.00000000,0.00000000,0.00000000,0.00000000
8.10000000,0.04453900,0.93400000,0.00165156,92.28929830,0.00165019,92.44171920,0.00056692,0.00822361,353.86870157,-0.00534191,-0.00288170,0.00000000,0.00000000,0.00000000,0.00000000
9.60000000,0.05331300,1.16400000,0.00183678,115.01578503,0.00183509,115.22704347,0.00046054,0.00978570,356.84250846,-0.00630636,-0.00347934,0.00000000,0.00000000,0.00000000,0.00000000
11.10000000,0.06284400,1.37600000,0.00208078,135.96367715,0.00207862,136.24658734,0.00013217,0.01109604,360.44020711,-0.00709316,-0.00400288,0.00000000,0.00000000,0.00000000,0.00000000
12.60000000,0.07089600,1.60400000,0.00234611,158.49254225,0.00234336,158.86438337,-0.00010797,0.01216314,363.55406536,-0.00777799,-0.00438515,0.00000000,0.00000000,0.00000000,0.00000000
14.10000000,0.07907500,1.79900000,0.00271156,177.76065057,0.00270789,178.24265845,-0.00002571,0.01314594,366.54223935,-0.00835750,-0.00478844,0.00000000,0.00000000,0.00000000,0.00000000
15.60000000,0.08867000,2.02700000,0.00306867,200.28951568,0.00306397,200.90413744,0.00012540,0.01431946,369.80950573,-0.00916136,-0.00515811,0.00000000,0.00000000,0.00000000,0.00000000
17.10000000,0.09819200,2.23600000,0.00340689,220.94097536,0.00340110,221.69369672,0.00028372,0.01548382,372.57393986,-0.00988974,-0.00559408,0.00000000,0.00000000,0.00000000,0.00000000
18.60000000,0.10616400,2.46000000,0.00368744,243.07459722,0.00368066,243.97092130,0.00021633,0.01669215,375.76710905,-0.01065188,-0.00604026,0.00000000,0.00000000,0.00000000,0.00000000
20.10000000,0.11461800,2.66700000,0.00401267,263.52843528,0.00400464,264.58588705,0.00019102,0.01794184,378.78021540,-0.01146980,-0.00647205,0.00000000,0.00000000,0.00000000,0.00000000
21.60000000,0.12473700,2.88800000,0.00436533,285.36562471,0.00435583,286.61134078,0.00028367,0.01910219,381.76622340,-0.01221094,-0.00689125,0.00000000,0.00000000,0.00000000,0.00000000
23.10000000,0.13326400,3.07400000,0.00469033,303.74443572,0.00467937,305.16909837,0.00042450,0.02017844,384.62448944,-0.01286369,-0.00731475,0.00000000,0.00000000,0.00000000,0.00000000
24.60000000,0.14239400,3.28000000,0.00487978,324.09946296,0.00486791,325.68099632,0.00023376,0.02124936,387.79260783,-0.01351264,-0.00773673,0.00000000,0.00000000,0.00000000,0.00000000
26.10000000,0.16002800,3.40700000,0.00504444,336.64843607,0.00503176,338.34664040,-0.00018439,0.02237806,390.37732470,-0.01419178,-0.00818628,0.00000000,0.00000000,0.00000000,0.00000000
27.60000000,0.20342300,3.44100000,0.00537378,340.00800368,0.00535939,341.83513113,0.00028383,0.02351491,393.07303096,-0.01486977,-0.00864514,0.00000000,0.00000000,0.00000000,0.00000000
29.10000000,0.25426900,3.44600000,0.00842267,340.50205774,0.00838739,343.36999307,0.00284629,0.02466718,395.88306096,-0.01551367,-0.00915351,0.00000000,0.00000000,0.00000000,0.00000000
30.60000000,0.30897800,3.44900000,0.01060900,340.79849017,0.01055312,344.41402135,0.00007278,0.02583280,398.39712439,-0.01616360,-0.00966919,0.00000000,0.00000000,0.00000000,0.00000000
32.10000000,0.33879600,3.49200000,0.01131644,345.04735508,0.01125289,348.95206431,0.00049007,0.02699288,401.22231832,-0.01683148,-0.01016141,0.00000000,0.00000000,0.00000000,0.00000000
33.60000000,0.36941200,3.51700000,0.01226289,347.51762538,0.01218831,351.77919541,0.00086865,0.02811160,404.03694253,-0.01750268,-0.01060892,0.00000000,0.00000000,0.00000000,0.00000000
35.10000000,0.41094600,3.54500000,0.01371478,350.28432811,0.01362158,355.08839983,0.00123193,0.02923455,406.44783456,-0.01819269,-0.01104186,0.00000000,0.00000000,0.00000000,0.00000000
36.60000000,0.45172000,3.56900000,0.01522267,352.65578760,0.01510796,358.02414910,0.00100014,0.03036047,409.07099533,-0.01887509,-0.01148538,0.00000000,0.00000000,0.00000000,0.00000000
38.10000000,0.48897400,3.59900000,0.01658356,355.62011195,0.01644755,361.51755784,0.00096140,0.03145613,411.68720323,-0.01954613,-0.01191000,0.00000000,0.00000000,0.00000000,0.00000000
39.60000000,0.52345200,3.62500000,0.01765111,358.18919306,0.01749714,364.51163031,0.00084220,0.03259660,414.12104276,-0.02028754,-0.01230906,0.00000000,0.00000000,0.00000000,0.00000000
41.10000000,0.55918400,3.65300000,0.01869267,360.95589579,0.01852011,367.70312404,0.00084178,0.03372460,416.55482913,-0.02092127,-0.01280332,0.00000000,0.00000000,0.00000000,0.00000000
42.60000000,0.59410200,3.67900000,0.01985067,363.52497690,0.01965621,370.74119004,0.00067865,0.03485794,419.30644334,-0.02167553,-0.01318241,0.00000000,0.00000000,0.00000000,0.00000000
44.10000000,0.63183300,3.70600000,0.02120811,366.19286882,0.02098635,373.95912787,0.00093549,0.03600761,421.55284814,-0.02239833,-0.01360929,0.00000000,0.00000000,0.00000000,0.00000000
45.60000000,0.66959200,3.72900000,0.02244856,368.46551750,0.02220030,376.73703614,0.00086043,0.03714575,424.00654997,-0.02311103,-0.01403472,0.00000000,0.00000000,0.00000000,0.00000000
47.10000000,0.70630600,3.75500000,0.02372689,371.03459861,0.02344978,379.83809530,0.00077857,0.03826877,426.14740158,-0.02380728,-0.01446149,0.00000000,0.00000000,0.00000000,0.00000000
48.60000000,0.74261300,3.77900000,0.02493000,373.40605809,0.02462432,382.71507112,0.00072625,0.03941574,428.82287923,-0.02448889,-0.01492685,0.00000000,0.00000000,0.00000000,0.00000000
50.10000000,0.77739500,3.80400000,0.02607678,375.87632839,0.02574258,385.67797188,0.00073302,0.04052879,430.96887861,-0.02515411,-0.01537469,0.00000000,0.00000000,0.00000000,0.00000000
51.60000000,0.81302800,3.82700000,0.02721978,378.14897706,0.02685591,388.44210818,0.00073221,0.04162924,433.42643201,-0.02576480,-0.01586444,0.00000000,0.00000000,0.00000000,0.00000000
53.10000000,0.84872500,3.85100000,0.02841533,380.52043655,0.02801911,391.33305159,0.00073136,0.04276246,435.48600260,-0.02646546,-0.01629700,0.00000000,0.00000000,0.00000000,0.00000000
54.60000000,0.88466000,3.87300000,0.02964856,382.69427441,0.02921754,394.04060686,0.00078165,0.04385098,437.84353624,-0.02707342,-0.01677755,0.00000000,0.00000000,0.00000000,0.00000000
56.10000000,0.92144100,3.89500000,0.03089689,384.86811227,0.03042919,396.75933957,0.00082448,0.04496858,439.80033991,-0.02773692,-0.01723166,0.00000000,0.00000000,0.00000000,0.00000000
57.60000000,0.95744500,3.91800000,0.03211878,387.14076094,0.03161376,399.57524901,0.00079442,0.04607423,442.27933910,-0.02837541,-0.01769882,0.00000000,0.00000000,0.00000000,0.00000000
59.10000000,0.99365100,3.93700000,0.03330689,389.01816637,0.03276423,401.97515121,0.00069885,0.04720196,444.35396510,-0.02908172,-0.01812025,0.00000000,0.00000000,0.00000000,0.00000000
60.60000000,1.02914700,3.96000000,0.03455511,391.29081504,0.03397149,404.81191263,0.00079986,0.04830781,446.63292106,-0.02971916,-0.01858865,0.00000000,0.00000000,0.00000000,0.00000000
62.10000000,1.06453900,3.98100000,0.03574322,393.36584209,0.03511926,407.42600480,0.00078435,0.04943421,448.61053290,-0.03042914,-0.01900507,0.00000000,0.00000000,0.00000000,0.00000000
63.60000000,1.10020400,4.00100000,0.03693500,395.34205833,0.03626925,409.94401725,0.00076158,0.05054576,450.79582722,-0.03115354,-0.01939223,0.00000000,0.00000000,0.00000000,0.00000000
65.10000000,1.13597100,4.02100000,0.03813078,397.31827457,0.03742177,412.46832940,0.00080460,0.05169898,452.68853367,-0.03187693,-0.01982206,0.00000000,0.00000000,0.00000000,0.00000000
66.60000000,1.17224400,4.04000000,0.03932633,399.19567999,0.03857275,414.89458237,0.00075982,0.05278666,454.87149511,-0.03252236,-0.02026430,0.00000000,0.00000000,0.00000000,0.00000000
68.10000000,1.20784100,4.06000000,0.04053700,401.17189623,0.03973693,417.43420139,0.00076642,0.05391951,456.76282632,-0.03325499,-0.02066452,0.00000000,0.00000000,0.00000000,0.00000000
69.60000000,1.24415000,4.07900000,0.04173633,403.04930165,0.04088887,419.87110166,0.00072926,0.05503492,459.07272651,-0.03395169,-0.02108322,0.00000000,0.00000000,0.00000000,0.00000000
71.10000000,1.28018700,4.09900000,0.04296967,405.02551789,0.04207209,422.42932939,0.00073564,0.05618397,460.87380458,-0.03466785,-0.02151611,0.00000000,0.00000000,0.00000000,0.00000000
72.60000000,1.31605600,4.11700000,0.04417278,406.80411251,0.04322497,424.77378017,0.00069881,0.05730914,462.77334512,-0.03531096,-0.02199818,0.00000000,0.00000000,0.00000000,0.00000000
74.10000000,1.35256600,4.13500000,0.04540222,408.58270712,0.04440171,427.13326998,0.00074839,0.05839808,464.65972527,-0.03592994,-0.02246814,0.00000000,0.00000000,0.00000000,0.00000000
75.60000000,1.38863800,4.15300000,0.04660167,410.36130173,0.04554841,429.48482233,0.00067553,0.05949607,466.55401187,-0.03660903,-0.02288703,0.00000000,0.00000000,0.00000000,0.00000000
77.10000000,1.42508200,4.17000000,0.04781233,412.04108554,0.04670450,431.74173126,0.00070360,0.06062282,468.57188047,-0.03725944,-0.02336338,0.00000000,0.00000000,0.00000000,0.00000000
78.60000000,1.46101600,4.18700000,0.04902300,413.72086934,0.04785925,434.00270752,0.00074581,0.06175939,470.27910636,-0.03796833,-0.02379106,0.00000000,0.00000000,0.00000000,0.00000000
80.10000000,1.49705300,4.20500000,0.05024122,415.49946395,0.04901987,436.37466485,0.00074494,0.06285775,472.39783160,-0.03861951,-0.02423824,0.00000000,0.00000000,0.00000000,0.00000000
81.60000000,1.53370100,4.22100000,0.05143667,417.08043694,0.05015748,438.53366435,0.00077940,0.06398121,474.10594649,-0.03928284,-0.02469837,0.00000000,0.00000000,0.00000000,0.00000000
83.10000000,1.56933100,4.23800000,0.05263233,418.76022074,0.05129401,440.80054827,0.00076437,0.06510188,475.92287201,-0.03995091,-0.02515097,0.00000000,0.00000000,0.00000000,0.00000000
84.60000000,1.60597700,4.25400000,0.05383178,420.34119373,0.05243283,442.96890747,0.00076371,0.06621422,477.73935653,-0.04060565,-0.02560858,0.00000000,0.00000000,0.00000000,0.00000000
86.10000000,1.64208200,4.26900000,0.05506500,421.82335591,0.05360238,445.05105900,0.00079126,0.06734769,479.46250309,-0.04127749,-0.02607021,0.00000000,0.00000000,0.00000000,0.00000000
87.60000000,1.67889800,4.28400000,0.05627578,423.30551809,0.05474930,447.12736536,0.00081182,0.06848163,481.29644772,-0.04199175,-0.02648988,0.00000000,0.00000000,0.00000000,0.00000000
89.10000000,1.71534100,4.30100000,0.05751644,424.98530189,0.05592318,449.42894540,0.00085333,0.06961428,483.13340220,-0.04268580,-0.02692848,0.00000000,0.00000000,0.00000000,0.00000000
90.60000000,1.75171700,4.31500000,0.05870833,426.36865326,0.05704961,451.40004628,0.00082402,0.07073311,484.85978344,-0.04335222,-0.02738089,0.00000000,0.00000000,0.00000000,0.00000000
92.10000000,1.78883700,4.33000000,0.05993789,427.85081544,0.05821031,453.49529007,0.00078783,0.07187959,486.49546697,-0.04405568,-0.02782392,0.00000000,0.00000000,0.00000000,0.00000000
93.60000000,1.82484200,4.34500000,0.06115600,429.33297761,0.05935888,455.58926519,0.00085062,0.07302882,488.35110419,-0.04473096,-0.02829786,0.00000000,0.00000000,0.00000000,0.00000000
95.10000000,1.86152200,4.35900000,0.06235911,430.71632898,0.06049201,457.57541640,0.00080006,0.07414992,489.87306342,-0.04538352,-0.02876641,0.00000000,0.00000000,0.00000000,0.00000000
96.60000000,1.89840500,4.37300000,0.06359244,432.09968035,0.06165228,459.57795526,0.00082735,0.07531690,491.74447985,-0.04609679,-0.02922011,0.00000000,0.00000000,0.00000000,0.00000000
98.10000000,1.93525600,4.38600000,0.06478811,433.38422090,0.06277582,461.46236596,0.00072766,0.07644574,493.27645115,-0.04675404,-0.02969170,0.00000000,0.00000000,0.00000000,0.00000000
99.60000000,1.97163300,4.40000000,0.06597622,434.76757227,0.06389102,463.45189423,0.00065637,0.07756612,494.80710540,-0.04739664,-0.03016948,0.00000000,0.00000000,0.00000000,0.00000000
101.10000000,2.00797500,4.41300000,0.06722067,436.05211282,0.06505776,465.36382655,0.00076100,0.07868038,496.44591421,-0.04807453,-0.03060585,0.00000000,0.00000000,0.00000000,0.00000000
102.60000000,2.04499400,4.42600000,0.06840889,437.33665338,0.06617052,467.25436790,0.00073935,0.07982418,498.10264813,-0.04876634,-0.03105784,0.00000000,0.00000000,0.00000000,0.00000000
104.10000000,2.08187500,4.43900000,0.06964589,438.62119393,0.06732765,469.16935687,0.00074556,0.08096649,499.76184273,-0.04944945,-0.03151705,0.00000000,0.00000000,0.00000000,0.00000000
105.60000000,2.11865900,4.45100000,0.07086778,439.80692367,0.06846933,470.97506301,0.00070962,0.08209004,501.19731584,-0.05010921,-0.03198083,0.00000000,0.00000000,0.00000000,0.00000000
107.10000000,2.15601700,4.46500000,0.07208600,441.19027504,0.06960628,472.99391721,0.00072955,0.08326712,502.88025543,-0.05083124,-0.03243589,0.00000000,0.00000000,0.00000000,0.00000000
108.60000000,2.19269500,4.47700000,0.07330422,442.37600478,0.07074195,474.80403374,0.00070780,0.08435565,504.41256390,-0.05144777,-0.03290788,0.00000000,0.00000000,0.00000000,0.00000000
110.10000000,2.23049300,4.48900000,0.07454489,443.56173452,0.07189721,476.62699474,0.00072788,0.08552276,505.87859300,-0.05217002,-0.03335274,0.00000000,0.00000000,0.00000000,0.00000000
111.60000000,2.26774900,4.50000000,0.07581200,444.64865346,0.07307573,478.35835717,0.00081113,0.08667468,507.33964568,-0.05283470,-0.03383998,0.00000000,0.00000000,0.00000000,0.00000000
113.10000000,2.30530900,4.51100000,0.07703022,445.73557239,0.07420746,480.07068258,0.00076108,0.08781690,508.90785914,-0.05350243,-0.03431446,0.00000000,0.00000000,0.00000000,0.00000000
114.60000000,2.34222700,4.52300000,0.07828978,446.92130213,0.07537625,481.91067156,0.00078122,0.08897976,510.38015728,-0.05418200,-0.03479775,0.00000000,0.00000000,0.00000000,0.00000000
116.10000000,2.38012500,4.53500000,0.07957944,448.10703187,0.07657156,483.76714052,0.00085690,0.09011589,511.95110802,-0.05483443,-0.03528146,0.00000000,0.00000000,0.00000000,0.00000000
117.60000000,2.41758300,4.54600000,0.08079756,449.19395080,0.07769925,485.48772400,0.00082796,0.09126187,513.20082439,-0.05545858,-0.03580329,0.00000000,0.00000000,0.00000000,0.00000000
119.10000000,2.45507600,4.55700000,0.08204589,450.28086973,0.07885359,487.22456394,0.00079947,0.09240216,514.77951122,-0.05612716,-0.03627500,0.00000000,0.00000000,0.00000000,0.00000000
120.60000000,2.49284000,4.56800000,0.08330167,451.36778866,0.08001348,488.96747774,0.00077063,0.09357086,516.15591116,-0.05681283,-0.03675804,0.00000000,0.00000000,0.00000000,0.00000000
122.10000000,2.53043600,4.57700000,0.08453500,452.25708597,0.08115132,490.48863873,0.00076299,0.09471505,517.74241384,-0.05746442,-0.03725063,0.00000000,0.00000000,0.00000000,0.00000000
123.60000000,2.56907700,4.58700000,0.08581333,453.24519409,0.08232932,492.13967501,0.00073445,0.09588577,519.01493723,-0.05816381,-0.03772196,0.00000000,0.00000000,0.00000000,0.00000000
125.10000000,2.60636600,4.59700000,0.08707667,454.23330221,0.08349214,493.78642405,0.00076100,0.09703878,520.50133711,-0.05887713,-0.03816166,0.00000000,0.00000000,0.00000000,0.00000000
126.60000000,2.64392600,4.60700000,0.08829867,455.22141033,0.08461562,495.41685390,0.00072583,0.09819505,521.88168701,-0.05955778,-0.03863728,0.00000000,0.00000000,0.00000000,0.00000000
128.10000000,2.68172300,4.61600000,0.08955444,456.11070763,0.08576885,496.95744866,0.00075948,0.09936678,523.27272762,-0.06027650,-0.03909028,0.00000000,0.00000000,0.00000000,0.00000000
129.60000000,2.71999400,4.62700000,0.09082522,457.19762656,0.08693449,498.72270260,0.00075839,0.10054529,524.55911900,-0.06098134,-0.03956395,0.00000000,0.00000000,0.00000000,0.00000000
131.10000000,2.75826400,4.63500000,0.09210356,457.98811306,0.08810570,500.17044667,0.00077134,0.10173769,525.96617010,-0.06169174,-0.04004594,0.00000000,0.00000000,0.00000000,0.00000000
132.60000000,2.79629900,4.64500000,0.09336689,458.97622118,0.08926182,501.82940302,0.00079770,0.10287315,527.23455392,-0.06231775,-0.04055540,0.00000000,0.00000000,0.00000000,0.00000000
134.10000000,2.83467000,4.65400000,0.09460756,459.86551849,0.09039590,503.37227107,0.00066620,0.10403234,528.62902730,-0.06300786,-0.04102448,0.00000000,0.00000000,0.00000000,0.00000000
135.60000000,2.87287300,4.66300000,0.09593867,460.75481579,0.09161123,504.95901848,0.00087838,0.10525194,529.94696554,-0.06374555,-0.04150639,0.00000000,0.00000000,0.00000000,0.00000000
137.10000000,2.91155000,4.67000000,0.09719822,461.44649148,0.09275986,506.29827010,0.00080180,0.10641987,531.23972631,-0.06445840,-0.04196147,0.00000000,0.00000000,0.00000000,0.00000000
138.60000000,2.94968500,4.68000000,0.09845400,462.43459959,0.09390374,507.96313566,0.00074624,0.10757979,532.53052628,-0.06512747,-0.04245232,0.00000000,0.00000000,0.00000000,0.00000000
140.10000000,2.98880000,4.68800000,0.09976611,463.22508609,0.09509753,509.43925150,0.00080700,0.10873162,533.81929941,-0.06579866,-0.04293296,0.00000000,0.00000000,0.00000000,0.00000000
141.60000000,3.02767800,4.69700000,0.10105200,464.11438340,0.09626609,511.01407007,0.00077860,0.10993839,535.13998489,-0.06654608,-0.04339231,0.00000000,0.00000000,0.00000000,0.00000000
143.10000000,3.06659300,4.70400000,0.10234544,464.80605908,0.09744013,512.37684178,0.00081197,0.11106576,536.30819002,-0.06719744,-0.04386832,0.00000000,0.00000000,0.00000000,0.00000000
144.60000000,3.10510100,4.71200000,0.10360878,465.59654557,0.09858552,513.83643460,0.00077700,0.11224982,537.62124200,-0.06788466,-0.04436516,0.00000000,0.00000000,0.00000000,0.00000000
146.10000000,3.14421800,4.71900000,0.10492478,466.28822126,0.09977726,515.21340925,0.00083724,0.11344903,538.94492123,-0.06860941,-0.04483961,0.00000000,0.00000000,0.00000000,0.00000000
147.60000000,3.18279200,4.72700000,0.10621444,467.07870775,0.10094378,516.68921321,0.00079566,0.11464302,540.04331062,-0.06931452,-0.04532849,0.00000000,0.00000000,0.00000000,0.00000000
149.10000000,3.22180700,4.73500000,0.10752656,467.86919425,0.10212920,518.17755716,0.00083527,0.11582427,541.24922191,-0.07000744,-0.04581683,0.00000000,0.00000000,0.00000000,0.00000000
150.60000000,3.26102400,4.74200000,0.10883122,468.56086993,0.10330651,519.55492209,0.00081404,0.11702355,542.46711599,-0.07075866,-0.04626489,0.00000000,0.00000000,0.00000000,0.00000000
152.10000000,3.30048000,4.75000000,0.11012456,469.35135643,0.10447222,521.03846595,0.00079927,0.11826113,543.70816152,-0.07153312,-0.04672800,0.00000000,0.00000000,0.00000000,0.00000000
153.60000000,3.33946100,4.75600000,0.11146689,469.94422130,0.10568066,522.32744160,0.00086631,0.11945106,544.92533027,-0.07225555,-0.04719551,0.00000000,0.00000000,0.00000000,0.00000000
155.10000000,3.37996300,4.76400000,0.11279033,470.73470779,0.10687067,523.82903240,0.00086528,0.12067044,546.04771954,-0.07292657,-0.04774387,0.00000000,0.00000000,0.00000000,0.00000000
156.60000000,3.41948900,4.76900000,0.11412889,471.22876185,0.10807283,525.00957685,0.00087781,0.12189665,547.28911552,-0.07363276,-0.04826389,0.00000000,0.00000000,0.00000000,0.00000000
158.10000000,3.45877300,4.77500000,0.11540722,471.82162672,0.10921956,526.27325005,0.00074845,0.12309516,548.51746616,-0.07434507,-0.04875009,0.00000000,0.00000000,0.00000000,0.00000000
159.60000000,3.49860000,4.78300000,0.11673444,472.61211322,0.11040875,527.78222569,0.00082161,0.12427585,549.73813500,-0.07503366,-0.04924219,0.00000000,0.00000000,0.00000000,0.00000000
161.10000000,3.53849600,4.78900000,0.11806167,473.20497809,0.11159653,529.07234648,0.00084112,0.12553653,550.77794652,-0.07579811,-0.04973842,0.00000000,0.00000000,0.00000000,0.00000000
162.60000000,3.57849300,4.79600000,0.11937389,473.89665377,0.11276950,530.46754026,0.00071223,0.12673195,551.89709671,-0.07654164,-0.05019032,0.00000000,0.00000000,0.00000000,0.00000000
164.10000000,3.61852500,4.80100000,0.12070111,474.39070783,0.11395448,531.65019337,0.00071139,0.12794218,553.02641000,-0.07722974,-0.05071244,0.00000000,0.00000000,0.00000000,0.00000000
165.60000000,3.65886200,4.80700000,0.12203967,474.98357270,0.11514816,532.95040959,0.00074402,0.12915425,554.15871164,-0.07792915,-0.05122510,0.00000000,0.00000000,0.00000000,0.00000000
167.10000000,3.69878800,4.81300000,0.12334811,475.57643757,0.11631361,534.23789284,0.00073643,0.13039074,555.30663821,-0.07865888,-0.05173186,0.00000000,0.00000000,0.00000000,0.00000000
168.60000000,3.74000300,4.81800000,0.12475422,476.07049163,0.11756454,535.46229554,0.00078907,0.13158180,556.31669692,-0.07935596,-0.05222584,0.00000000,0.00000000,0.00000000,0.00000000
170.10000000,3.77973100,4.82400000,0.12608156,476.66335650,0.11874396,536.76181397,0.00086158,0.13282488,557.47216826,-0.08013076,-0.05269412,0.00000000,0.00000000,0.00000000,0.00000000
171.60000000,3.82037100,4.83000000,0.12740511,477.25622138,0.11991863,538.06110329,0.00080733,0.13410205,558.64887872,-0.08094786,-0.05315419,0.00000000,0.00000000,0.00000000,0.00000000
173.10000000,3.86091000,4.83600000,0.12878878,477.84908625,0.12114518,539.39068603,0.00082623,0.13528052,559.77203960,-0.08165630,-0.05362422,0.00000000,0.00000000,0.00000000,0.00000000
174.60000000,3.90263200,4.84000000,0.13016478,478.24432949,0.12236344,540.49489637,0.00084509,0.13654629,560.60144165,-0.08239879,-0.05414751,0.00000000,0.00000000,0.00000000,0.00000000
176.10000000,3.94266200,4.84500000,0.13156722,478.73838355,0.12360359,541.72466285,0.00093029,0.13777672,561.75749714,-0.08313014,-0.05464658,0.00000000,0.00000000,0.00000000,0.00000000
177.60000000,3.98394600,4.85000000,0.13289822,479.23243761,0.12477915,542.92157660,0.00084992,0.13897653,562.89821597,-0.08382657,-0.05514996,0.00000000,0.00000000,0.00000000,0.00000000
179.10000000,4.02485600,4.85400000,0.13430811,479.62768086,0.12602287,544.04556871,0.00082867,0.14026492,564.09124168,-0.08459705,-0.05566787,0.00000000,0.00000000,0.00000000,0.00000000
180.60000000,4.06634300,4.85900000,0.13568811,480.12173492,0.12723873,545.26854623,0.00084763,0.14151436,564.91748995,-0.08532822,-0.05618613,0.00000000,0.00000000,0.00000000,0.00000000
182.10000000,4.10711700,4.86500000,0.13702289,480.71459979,0.12841335,546.58350299,0.00072776,0.14277532,565.98297621,-0.08609555,-0.05667977,0.00000000,0.00000000,0.00000000,0.00000000
183.60000000,4.14856800,4.86800000,0.13842533,481.01103223,0.12964602,547.59514470,0.00070714,0.14402177,567.04197809,-0.08684231,-0.05717946,0.00000000,0.00000000,0.00000000,0.00000000
185.10000000,4.19042700,4.87300000,0.13986156,481.50508629,0.13090681,548.84913666,0.00079850,0.14526671,568.10190348,-0.08754944,-0.05771727,0.00000000,0.00000000,0.00000000,0.00000000
186.60000000,4.23221900,4.87700000,0.14124900,481.90032953,0.13212328,549.96826918,0.00083707,0.14654190,569.18096476,-0.08834704,-0.05819486,0.00000000,0.00000000,0.00000000,0.00000000
188.10000000,4.27339800,4.88100000,0.14265133,482.29557278,0.13335129,551.09567930,0.00074363,0.14775308,570.10876976,-0.08902440,-0.05872869,0.00000000,0.00000000,0.00000000,0.00000000
189.60000000,4.31488300,4.88500000,0.14407256,482.69081603,0.13459431,552.23331544,0.00080858,0.14902677,571.07397323,-0.08977440,-0.05925237,0.00000000,0.00000000,0.00000000,0.00000000
191.10000000,4.35734900,4.88900000,0.14548989,483.08605928,0.13583240,553.37019636,0.00083378,0.15029556,572.27117140,-0.09054607,-0.05974949,0.00000000,0.00000000,0.00000000,0.00000000
192.60000000,4.39900300,4.89300000,0.14689978,483.48130252,0.13706246,554.50459842,0.00083915,0.15156740,573.12193092,-0.09125004,-0.06031736,0.00000000,0.00000000,0.00000000,0.00000000
194.10000000,4.44140300,4.89700000,0.14829478,483.87654577,0.13827804,555.63291060,0.00076631,0.15286775,574.10737363,-0.09202310,-0.06084464,0.00000000,0.00000000,0.00000000,0.00000000
195.60000000,4.48420800,4.90100000,0.14974989,484.27178902,0.13954443,556.79143562,0.00088967,0.15416627,575.09337128,-0.09280448,-0.06136179,0.00000000,0.00000000,0.00000000,0.00000000
197.10000000,4.52684400,4.90400000,0.15116356,484.56822145,0.14077322,557.81727672,0.00082986,0.15542985,576.17793090,-0.09353742,-0.06189243,0.00000000,0.00000000,0.00000000,0.00000000
198.60000000,4.56968500,4.90800000,0.15266378,484.96346470,0.14207559,558.99981931,0.00084846,0.15675676,577.18378822,-0.09437291,-0.06238385,0.00000000,0.00000000,0.00000000,0.00000000
200.10000000,4.61228500,4.91100000,0.15409633,485.25989714,0.14331764,560.03666800,0.00094526,0.15805169,578.05512853,-0.09513733,-0.06291436,0.00000000,0.00000000,0.00000000,0.00000000
201.60000000,4.65499000,4.91400000,0.15550622,485.55632957,0.14453854,561.06336006,0.00083309,0.15934352,579.04367207,-0.09588352,-0.06346000,0.00000000,0.00000000,0.00000000,0.00000000
203.10000000,4.69793100,4.91700000,0.15696511,485.85276201,0.14580029,562.11469478,0.00086452,0.16066671,579.93428518,-0.09667890,-0.06398781,0.00000000,0.00000000,0.00000000,0.00000000
204.60000000,4.74121100,4.92100000,0.15842778,486.24800526,0.14706372,563.28319618,0.00096092,0.16201797,580.96072198,-0.09749620,-0.06452177,0.00000000,0.00000000,0.00000000,0.00000000
206.10000000,4.78526700,4.92400000,0.15987522,486.54443769,0.14831243,564.33083779,0.00084931,0.16333754,581.85211901,-0.09823652,-0.06510102,0.00000000,0.00000000,0.00000000,0.00000000
207.60000000,4.82888600,4.92700000,0.16130778,486.84087013,0.14954676,565.37208902,0.00079677,0.16468670,582.76224531,-0.09902460,-0.06566210,0.00000000,0.00000000,0.00000000,0.00000000
209.10000000,4.87206300,4.92900000,0.16277800,487.03849175,0.15081197,566.31764336,0.00077645,0.16603073,583.90779884,-0.09977700,-0.06625372,0.00000000,0.00000000,0.00000000,0.00000000
210.60000000,4.91524200,4.93200000,0.16424422,487.33492419,0.15207214,567.37686977,0.00077528,0.16734491,584.80045164,-0.10052580,-0.06681910,0.00000000,0.00000000,0.00000000,0.00000000
212.10000000,4.95973800,4.93500000,0.16571056,487.63135662,0.15333082,568.43701964,0.00077412,0.16871818,585.84818861,-0.10134294,-0.06737524,0.00000000,0.00000000,0.00000000,0.00000000
213.60000000,5.00389600,4.93800000,0.16721467,487.92778906,0.15462028,569.51647166,0.00077350,0.17009441,586.54244171,-0.10216533,-0.06792907,0.00000000,0.00000000,0.00000000,0.00000000
215.10000000,5.04792100,4.94000000,0.16868089,488.12541068,0.15587567,570.46283885,0.00083683,0.17152611,587.62788233,-0.10300702,-0.06851908,0.00000000,0.00000000,0.00000000,0.00000000
216.60000000,5.09221500,4.94200000,0.17022256,488.32303231,0.15719395,571.44662680,0.00089994,0.17292462,588.69555592,-0.10382930,-0.06909532,0.00000000,0.00000000,0.00000000,0.00000000
218.10000000,5.13725500,4.94500000,0.17176400,488.61946474,0.15851031,572.54669848,0.00096269,0.17435547,589.54526469,-0.10465727,-0.06969820,0.00000000,0.00000000,0.00000000,0.00000000
219.60000000,5.18293700,4.94700000,0.17326800,488.81708637,0.15979302,573.51344529,0.00096146,0.17578415,590.39491888,-0.10548245,-0.07030170,0.00000000,0.00000000,0.00000000,0.00000000
221.10000000,5.22682600,4.94800000,0.17477200,488.91589718,0.16107409,574.36470636,0.00089626,0.17717838,591.34514283,-0.10629511,-0.07088328,0.00000000,0.00000000,0.00000000,0.00000000
222.60000000,5.27172900,4.95000000,0.17631356,489.11351880,0.16238544,575.35086237,0.00089528,0.17866167,592.47011000,-0.10719957,-0.07146210,0.00000000,0.00000000,0.00000000,0.00000000
224.10000000,5.31693800,4.95300000,0.17781744,489.40995124,0.16366310,576.43557805,0.00089413,0.18017679,593.37571658,-0.10810448,-0.07207231,0.00000000,0.00000000,0.00000000,0.00000000
225.60000000,5.36285700,4.95500000,0.17932156,489.60757286,0.16493932,577.40476444,0.00076556,0.18168968,594.28137779,-0.10900881,-0.07268086,0.00000000,0.00000000,0.00000000,0.00000000
227.10000000,5.40840400,4.95700000,0.18090056,489.80519448,0.16627733,578.41122628,0.00082816,0.18320042,595.18714823,-0.10990655,-0.07329387,0.00000000,0.00000000,0.00000000,0.00000000
228.60000000,5.45469400,4.95800000,0.18247989,489.90400530,0.16761383,579.30163375,0.00089079,0.18470686,596.21251781,-0.11077683,-0.07393003,0.00000000,0.00000000,0.00000000,0.00000000
230.10000000,5.50061300,4.96000000,0.18405889,490.10162692,0.16894827,580.30918781,0.00088923,0.18627415,597.15529188,-0.11169605,-0.07457810,0.00000000,0.00000000,0.00000000,0.00000000
231.60000000,5.54700600,4.96200000,0.18560056,490.29924854,0.17024944,581.29906146,0.00076132,0.00000000,0.00000000,0.00000000,0.00000000,0.00000000,0.00000000,0.00000000,0.00000000
233.10000000,5.59356800,4.96300000,0.18721722,490.39805936,0.17161210,582.20902181,0.00082338,0.00000000,0.00000000,0.00000000,0.00000000,0.00000000,0.00000000,0.00000000,0.00000000
234.60000000,5.64006100,4.96500000,0.18883400,490.59568098,0.17297299,583.23682580,0.00082226,0.00000000,0.00000000,0.00000000,0.00000000,0.00000000,0.00000000,0.00000000,0.00000000
236.10000000,5.68757100,4.96600000,0.19045078,490.69449179,0.17433204,584.14763940,0.00082133,0.00000000,0.00000000,0.00000000,0.00000000,0.00000000,0.00000000,0.00000000,0.00000000
237.60000000,5.73471000,4.96800000,0.19206767,490.89211342,0.17568933,585.17661622,0.00088344,0.00000000,0.00000000,0.00000000,0.00000000,0.00000000,0.00000000,0.00000000,0.00000000
239.10000000,5.78265800,4.96900000,0.19375944,490.99092423,0.17710752,586.12505293,0.00094495,0.00000000,0.00000000,0.00000000,0.00000000,0.00000000,0.00000000,0.00000000,0.00000000
240.60000000,5.83071300,4.96900000,0.19545156,490.99092423,0.17852398,586.95586413,0.00100666,0.00000000,0.00000000,0.00000000,0.00000000,0.00000000,0.00000000,0.00000000,0.00000000
242.10000000,5.87876100,4.97000000,0.19714333,491.08973504,0.17993816,587.90480237,0.00094228,0.00000000,0.00000000,0.00000000,0.00000000,0.00000000,0.00000000,0.00000000,0.00000000
243.60000000,5.92735400,4.97200000,0.19883533,491.28735666,0.18135053,588.97264199,0.00094113,0.00000000,0.00000000,0.00000000,0.00000000,0.00000000,0.00000000,0.00000000,0.00000000
245.10000000,5.97608100,4.97200000,0.20052733,491.28735666,0.18276090,589.80390019,0.00087721,0.00000000,0.00000000,0.00000000,0.00000000,0.00000000,0.00000000,0.00000000,0.00000000
246.60000000,6.02467300,4.97300000,0.20229433,491.38616747,0.18423168,590.79080463,0.00093843,0.00000000,0.00000000,0.00000000,0.00000000,0.00000000,0.00000000,0.00000000,0.00000000
248.10000000,6.07390900,4.97400000,0.20398633,491.48497829,0.18563800,591.74119690,0.00093692,0.00000000,0.00000000,0.00000000,0.00000000,0.00000000,0.00000000,0.00000000,0.00000000
249.60000000,6.12395400,4.97500000,0.20582867,491.58378910,0.18716702,592.76582496,0.00099800,0.00000000,0.00000000,0.00000000,0.00000000,0.00000000,0.00000000,0.00000000,0.00000000
251.10000000,6.17447500,4.97500000,0.20770867,491.58378910,0.18872490,593.69000249,0.00105903,0.00000000,0.00000000,0.00000000,0.00000000,0.00000000,0.00000000,0.00000000,0.00000000
252.60000000,6.22404900,4.97500000,0.20951333,491.58378910,0.19021807,594.57714736,0.00099514,0.00000000,0.00000000,0.00000000,0.00000000,0.00000000,0.00000000,0.00000000,0.00000000
254.10000000,6.27406200,4.97500000,0.21135567,491.58378910,0.19174012,595.48280857,0.00099326,0.00000000,0.00000000,0.00000000,0.00000000,0.00000000,0.00000000,0.00000000,0.00000000
255.60000000,6.32451600,4.97600000,0.21319800,491.68259991,0.19325985,596.50834685,0.00099211,0.00000000,0.00000000,0.00000000,0.00000000,0.00000000,0.00000000,0.00000000,0.00000000
257.10000000,6.37605100,4.97700000,0.21507789,491.78141072,0.19480818,597.55271833,0.00092873,0.00000000,0.00000000,0.00000000,0.00000000,0.00000000,0.00000000,0.00000000,0.00000000
258.60000000,6.42745100,4.97600000,0.21714578,491.68259991,0.00000000,0.00000000,0.00000000,0.00000000,0.00000000,0.00000000,0.00000000,0.00000000,0.00000000,0.00000000,0.00000000
260.10000000,6.47929100,4.97600000,0.21906333,491.68259991,0.00000000,0.00000000,0.00000000,0.00000000,0.00000000,0.00000000,0.00000000,0.00000000,0.00000000,0.00000000,0.00000000
261.60000000,6.53109900,4.97600000,0.22109367,491.68259991,0.00000000,0.00000000,0.00000000,0.00000000,0.00000000,0.00000000,0.00000000,0.00000000,0.00000000,0.00000000,0.00000000
263.10000000,6.58364900,4.97600000,0.22316156,491.68259991,0.00000000,0.00000000,0.00000000,0.00000000,0.00000000,0.00000000,0.00000000,0.00000000,0.00000000,0.00000000,0.00000000
264.60000000,6.63674200,4.97600000,0.22522933,491.68259991,0.00000000,0.00000000,0.00000000,0.00000000,0.00000000,0.00000000,0.00000000,0.00000000,0.00000000,0.00000000,0.00000000
266.10000000,6.68949700,4.97500000,0.22737256,491.58378910,0.00000000,0.00000000,0.00000000,0.00000000,0.00000000,0.00000000,0.00000000,0.00000000,0.00000000,0.00000000,0.00000000
267.60000000,6.74275600,4.97500000,0.22959089,491.58378910,0.00000000,0.00000000,0.00000000,0.00000000,0.00000000,0.00000000,0.00000000,0.00000000,0.00000000,0.00000000,0.00000000
269.10000000,6.79666100,4.97400000,0.23180900,491.48497829,0.00000000,0.00000000,0.00000000,0.00000000,0.00000000,0.00000000,0.00000000,0.00000000,0.00000000,0.00000000,0.00000000
270.60000000,6.85016000,4.97300000,0.23410267,491.38616747,0.00000000,0.00000000,0.00000000,0.00000000,0.00000000,0.00000000,0.00000000,0.00000000,0.00000000,0.00000000,0.00000000
272.10000000,6.90480800,4.97300000,0.23647122,491.38616747,0.00000000,0.00000000,0.00000000,0.00000000,0.00000000,0.00000000,0.00000000,0.00000000,0.00000000,0.00000000,0.00000000
273.60000000,6.95918500,4.97100000,0.23891500,491.18854585,0.00000000,0.00000000,0.00000000,0.00000000,0.00000000,0.00000000,0.00000000,0.00000000,0.00000000,0.00000000,0.00000000
275.10000000,7.01481400,4.97000000,0.24143400,491.08973504,0.00000000,0.00000000,0.00000000,0.00000000,0.00000000,0.00000000,0.00000000,0.00000000,0.00000000,0.00000000,0.00000000
276.60000000,7.06956200,4.96800000,0.24402833,490.89211342,0.00000000,0.00000000,0.00000000,0.00000000,0.00000000,0.00000000,0.00000000,0.00000000,0.00000000,0.00000000,0.00000000
278.10000000,7.12485600,4.96600000,0.24666011,490.69449179,0.00000000,0.00000000,0.00000000,0.00000000,0.00000000,0.00000000,0.00000000,0.00000000,0.00000000,0.00000000,0.00000000
279.60000000,7.18166700,4.96400000,0.24951744,490.49687017,0.00000000,0.00000000,0.00000000,0.00000000,0.00000000,0.00000000,0.00000000,0.00000000,0.00000000,0.00000000,0.00000000
281.10000000,7.23847900,4.96100000,0.25237467,490.20043773,0.00000000,0.00000000,0.00000000,0.00000000,0.00000000,0.00000000,0.00000000,0.00000000,0.00000000,0.00000000,0.00000000
282.60000000,7.29593500,4.95800000,0.25538233,489.90400530,0.00000000,0.00000000,0.00000000,0.00000000,0.00000000,0.00000000,0.00000000,0.00000000,0.00000000,0.00000000,0.00000000
284.10000000,7.35322300,4.95300000,0.25854044,489.40995124,0.00000000,0.00000000,0.00000000,0.00000000,0.00000000,0.00000000,0.00000000,0.00000000,0.00000000,0.00000000,0.00000000
285.60000000,7.41095200,4.94800000,0.26177389,488.91589718,0.00000000,0.00000000,0.00000000,0.00000000,0.00000000,0.00000000,0.00000000,0.00000000,0.00000000,0.00000000,0.00000000
287.10000000,7.46959400,4.94400000,0.26515733,488.52065393,0.00000000,0.00000000,0.00000000,0.00000000,0.00000000,0.00000000,0.00000000,0.00000000,0.00000000,0.00000000,0.00000000
288.60000000,7.52837100,4.93600000,0.26865367,487.73016743,0.00000000,0.00000000,0.00000000,0.00000000,0.00000000,0.00000000,0.00000000,0.00000000,0.00000000,0.00000000,0.00000000
290.10000000,7.58708400,4.92900000,0.27218800,487.03849175,0.00000000,0.00000000,0.00000000,0.00000000,0.00000000,0.00000000,0.00000000,0.00000000,0.00000000,0.00000000,0.00000000
291.60000000,7.64701500,4.92000000,0.27606022,486.14919444,0.00000000,0.00000000,0.00000000,0.00000000,0.00000000,0.00000000,0.00000000,0.00000000,0.00000000,0.00000000,0.00000000
293.10000000,7.70790200,4.90800000,0.28012089,484.96346470,0.00000000,0.00000000,0.00000000,0.00000000,0.00000000,0.00000000,0.00000000,0.00000000,0.00000000,0.00000000,0.00000000
294.60000000,7.77002000,4.88900000,0.28407011,483.08605928,0.00000000,0.00000000,0.00000000,0.00000000,0.00000000,0.00000000,0.00000000,0.00000000,0.00000000,0.00000000,0.00000000
296.10000000,7.83629700,4.85800000,0.28858578,480.02292411,0.00000000,0.00000000,0.00000000,0.00000000,0.00000000,0.00000000,0.00000000,0.00000000,0.00000000,0.00000000,0.00000000
296.60000000,7.86477200,4.83600000,0.29047044,477.84908625,0.00000000,0.00000000,0.00000000,0.00000000,0.00000000,0.00000000,0.00000000,0.00000000,0.00000000,0.00000000,0.00000000