File: LAB_DATA/AA7020-T6_results/DATA/UT_45_1.csv
Time[s],Displacement[mm],Force[kN],EngStrain_longi,EngStress[MPa],TrueStrain,TrueStress[MPa],TrueStrainRate[1/s],PlasticStrain_longi,PlasticStress[MPa],PlasticStrain_thick,PlasticStrain_width,R-Value,Thickness[mm],Width[mm], Young's Modulus [MPa]
0.65000000,0.00000000,-0.01000000,0.00000000,-0.99205660,0.00000000,-0.99205660,0.00000000,0.00050339,269.06596363,0.00024805,-0.00075144,0.76198356,1.00100000,10.07000000,72345.93900388
1.65000000,0.00360400,-0.01300000,0.00009689,-1.28967358,0.00009688,-1.28979854,0.00018021,0.00087862,278.17007307,0.00000357,-0.00088219,0.00000000,0.00000000,0.00000000,0.00000000
2.65000000,0.01019300,0.11600000,0.00027167,11.50785659,0.00027163,11.51098289,0.00019618,0.00146279,285.64138622,-0.00033585,-0.00112694,0.00000000,0.00000000,0.00000000,0.00000000
3.65000000,0.01467600,0.30700000,0.00041433,30.45613771,0.00041425,30.46875670,0.00013595,0.00184137,291.96039348,-0.00043709,-0.00140428,0.00000000,0.00000000,0.00000000,0.00000000
4.65000000,0.02075700,0.45600000,0.00065089,45.23778109,0.00065068,45.26722586,0.00038867,0.00258022,297.59100835,-0.00090708,-0.00167314,0.00000000,0.00000000,0.00000000,0.00000000
5.65000000,0.02440800,0.59600000,0.00069744,59.12657353,0.00069720,59.16781103,0.00007817,0.00312373,302.16783495,-0.00116746,-0.00195627,0.00000000,0.00000000,0.00000000,0.00000000
6.65000000,0.03073500,0.74000000,0.00096778,73.41218861,0.00096731,73.48323529,0.00024045,0.00373074,306.97049139,-0.00151624,-0.00221450,0.00000000,0.00000000,0.00000000,0.00000000
7.65000000,0.03620400,0.86900000,0.00101778,86.20971878,0.00101726,86.29746112,0.00008480,0.00435960,311.78633358,-0.00186130,-0.00249829,0.00000000,0.00000000,0.00000000,0.00000000
8.65000000,0.04154700,1.01800000,0.00127344,100.99136216,0.00127263,101.11996905,0.00002086,0.00515739,315.35499124,-0.00236369,-0.00279370,0.00000000,0.00000000,0.00000000,0.00000000
9.65000000,0.04686000,1.18300000,0.00151600,117.36029611,0.00151485,117.53821432,0.00046712,0.00574416,319.06318834,-0.00268721,-0.00305695,0.00000000,0.00000000,0.00000000,0.00000000
10.65000000,0.05408100,1.31700000,0.00157733,130.65385459,0.00157609,130.85993927,-0.00014554,0.00652703,322.53739084,-0.00318427,-0.00334277,0.00000000,0.00000000,0.00000000,0.00000000
11.65000000,0.05849300,1.46500000,0.00196422,145.33629231,0.00196230,145.62176508,0.00042188,0.00726758,325.80167717,-0.00363012,-0.00363745,0.00000000,0.00000000,0.00000000,0.00000000
12.65000000,0.06512300,1.61500000,0.00195856,160.21714135,0.00195664,160.53093552,0.00013884,0.00793608,328.84532094,-0.00397224,-0.00396385,0.00000000,0.00000000,0.00000000,0.00000000
13.65000000,0.07120400,1.76500000,0.00228567,175.09799039,0.00228306,175.49820603,0.00012683,0.00869775,331.82322502,-0.00444914,-0.00424861,0.00000000,0.00000000,0.00000000,0.00000000
14.65000000,0.07775900,1.91600000,0.00247411,190.07804509,0.00247106,190.54831930,0.00049528,0.00948394,334.30865750,-0.00489786,-0.00458609,0.00000000,0.00000000,0.00000000,0.00000000
15.65000000,0.08313000,2.06400000,0.00262111,204.76048281,0.00261768,205.29718279,-0.00000377,0.01018415,337.07228422,-0.00525409,-0.00493005,0.00000000,0.00000000,0.00000000,0.00000000
16.65000000,0.09128800,2.19400000,0.00293278,217.65721865,0.00292849,218.29555890,0.00041172,0.01090597,339.84720707,-0.00564731,-0.00525866,0.00000000,0.00000000,0.00000000,0.00000000
17.65000000,0.09730900,2.33300000,0.00304456,231.44680543,0.00303993,232.15145809,0.00008707,0.01175540,342.16353448,-0.00615621,-0.00559920,0.00000000,0.00000000,0.00000000,0.00000000
18.65000000,0.10573200,2.48200000,0.00340267,246.22844881,0.00339689,247.06628215,0.00031805,0.01242230,344.52191423,-0.00646560,-0.00595670,0.00000000,0.00000000,0.00000000,0.00000000
19.65000000,0.11657900,2.59200000,0.00373033,257.14107144,0.00372339,258.10029335,0.00037707,0.01322490,346.93073543,-0.00691681,-0.00630809,0.00000000,0.00000000,0.00000000,0.00000000
20.65000000,0.13011300,2.70100000,0.00414800,267.95448841,0.00413942,269.06596363,0.00045727,0.01396191,349.21878353,-0.00730763,-0.00665428,0.00000000,0.00000000,0.00000000,0.00000000
21.65000000,0.14582800,2.79100000,0.00464844,276.88299784,0.00463767,278.17007307,0.00036722,0.01477160,351.53582901,-0.00778581,-0.00698579,0.00000000,0.00000000,0.00000000,0.00000000
22.65000000,0.16321000,2.86400000,0.00533700,284.12501104,0.00532281,285.64138622,0.00088348,0.01544982,353.70808133,-0.00812206,-0.00732776,0.00000000,0.00000000,0.00000000,0.00000000
23.65000000,0.18176100,2.92600000,0.00580356,290.27576197,0.00578678,291.96039348,0.00035177,0.01630262,355.74205778,-0.00863287,-0.00766975,0.00000000,0.00000000,0.00000000,0.00000000
24.65000000,0.20213800,2.98000000,0.00662356,295.63286763,0.00660172,297.59100835,0.00071031,0.01701400,357.83041288,-0.00904354,-0.00797046,0.00000000,0.00000000,0.00000000,0.00000000
25.65000000,0.22278500,3.02400000,0.00723311,299.99791668,0.00720708,302.16783495,0.00073239,0.01779157,360.14956517,-0.00947680,-0.00831477,0.00000000,0.00000000,0.00000000,0.00000000
26.65000000,0.24333100,3.07000000,0.00791011,304.56137705,0.00787899,306.97049139,0.00064192,0.01855212,362.05781684,-0.00991492,-0.00863719,0.00000000,0.00000000,0.00000000,0.00000000
27.65000000,0.26526400,3.11600000,0.00860978,309.12483743,0.00857293,311.78633358,0.00049249,0.01935434,364.08625277,-0.01040139,-0.00895295,0.00000000,0.00000000,0.00000000,0.00000000
28.65000000,0.28753500,3.14900000,0.00946344,312.39862422,0.00941895,315.35499124,0.00103602,0.02005372,366.07998596,-0.01079556,-0.00925816,0.00000000,0.00000000,0.00000000,0.00000000
29.65000000,0.31004100,3.18400000,0.01010656,315.87082233,0.01005583,319.06318834,0.00054369,0.02083409,368.00408579,-0.01127437,-0.00955971,0.00000000,0.00000000,0.00000000,0.00000000
30.65000000,0.33221000,3.21600000,0.01094511,319.04540345,0.01088565,322.53739084,0.00081085,0.02158698,370.02324433,-0.01172117,-0.00986581,0.00000000,0.00000000,0.00000000,0.00000000
31.65000000,0.35502000,3.24600000,0.01173867,322.02157326,0.01167030,325.80167717,0.00084779,0.02235879,371.94994188,-0.01216134,-0.01019745,0.00000000,0.00000000,0.00000000,0.00000000
32.65000000,0.37904900,3.27400000,0.01245689,324.79933175,0.01237994,328.84532094,0.00082479,0.02312172,373.67104168,-0.01260911,-0.01051260,0.00000000,0.00000000,0.00000000,0.00000000
33.65000000,0.40273900,3.30100000,0.01326911,327.47788458,0.01318185,331.82322502,0.00064576,0.02389003,375.49930382,-0.01305248,-0.01083755,0.00000000,0.00000000,0.00000000,0.00000000
34.65000000,0.42602200,3.32300000,0.01410011,329.66040910,0.01400163,334.30865750,0.00101616,0.02463519,377.62963595,-0.01347931,-0.01115587,0.00000000,0.00000000,0.00000000,0.00000000
35.65000000,0.44981200,3.34800000,0.01484833,332.14055061,0.01473918,337.07228422,0.00071901,0.02540258,379.15469625,-0.01390939,-0.01149319,0.00000000,0.00000000,0.00000000,0.00000000
36.65000000,0.47400700,3.37300000,0.01561922,334.62069212,0.01549850,339.84720707,0.00071825,0.02616380,381.09113535,-0.01433799,-0.01182581,0.00000000,0.00000000,0.00000000,0.00000000
37.65000000,0.49833900,3.39300000,0.01651411,336.60480532,0.01637924,342.16353448,0.00081406,0.02691247,382.81962546,-0.01473473,-0.01217774,0.00000000,0.00000000,0.00000000,0.00000000
38.65000000,0.52253400,3.41400000,0.01722467,338.68812419,0.01707800,344.52191423,0.00079863,0.02765933,384.65293127,-0.01514427,-0.01251507,0.00000000,0.00000000,0.00000000,0.00000000
39.65000000,0.54629000,3.43500000,0.01807456,340.77144306,0.01791315,346.93073543,0.00064271,0.02842503,386.39302644,-0.01555973,-0.01286529,0.00000000,0.00000000,0.00000000,0.00000000
40.65000000,0.57089200,3.45500000,0.01885667,342.75555626,0.01868108,349.21878353,0.00074586,0.02919220,388.23944462,-0.01602356,-0.01316864,0.00000000,0.00000000,0.00000000,0.00000000
41.65000000,0.59498500,3.47500000,0.01971389,344.73966947,0.01952209,351.53582901,0.00089261,0.02994271,389.66880667,-0.01642201,-0.01352070,0.00000000,0.00000000,0.00000000,0.00000000
42.65000000,0.61928100,3.49400000,0.02043567,346.62457701,0.02022966,353.70808133,0.00068523,0.03069281,391.61691994,-0.01683195,-0.01386086,0.00000000,0.00000000,0.00000000,0.00000000
43.65000000,0.64276500,3.51100000,0.02133433,348.31107324,0.02110994,355.74205778,0.00084700,0.03143791,393.35892390,-0.01725739,-0.01418052,0.00000000,0.00000000,0.00000000,0.00000000
44.65000000,0.66702600,3.52900000,0.02209000,350.09677512,0.02184955,357.83041288,0.00080940,0.03221391,394.90855520,-0.01771284,-0.01450108,0.00000000,0.00000000,0.00000000,0.00000000
45.65000000,0.69125400,3.54900000,0.02291711,352.08088833,0.02265846,360.14956517,0.00078636,0.03295181,396.54886430,-0.01811836,-0.01483345,0.00000000,0.00000000,0.00000000,0.00000000
46.65000000,0.71585500,3.56500000,0.02372178,353.66817889,0.02344479,362.05781684,0.00071256,0.03371450,398.20137867,-0.01853934,-0.01517516,0.00000000,0.00000000,0.00000000,0.00000000
47.65000000,0.74001500,3.58200000,0.02457144,355.35467512,0.02427442,364.08625277,0.00088078,0.03444906,399.74114677,-0.01892901,-0.01552005,0.00000000,0.00000000,0.00000000,0.00000000
48.65000000,0.76404000,3.59900000,0.02531589,357.04117134,0.02500075,366.07998596,0.00071861,0.03522099,401.40199026,-0.01940685,-0.01581414,0.00000000,0.00000000,0.00000000,0.00000000
49.65000000,0.78776000,3.61500000,0.02614300,358.62846191,0.02580711,368.00408579,0.00079862,0.03596014,403.05194785,-0.01981784,-0.01614229,0.00000000,0.00000000,0.00000000,0.00000000
50.65000000,0.81205700,3.63200000,0.02694389,360.31495813,0.02658729,370.02324433,0.00074712,0.03669777,404.49548687,-0.02024685,-0.01645092,0.00000000,0.00000000,0.00000000,0.00000000
51.65000000,0.83635300,3.64800000,0.02776356,361.90224869,0.02738514,371.94994188,0.00083413,0.03747648,406.06189597,-0.02070704,-0.01676945,0.00000000,0.00000000,0.00000000,0.00000000
52.65000000,0.86071600,3.66200000,0.02857189,363.29112794,0.02817132,373.67104168,0.00078247,0.03823386,407.83024919,-0.02112260,-0.01711126,0.00000000,0.00000000,0.00000000,0.00000000
53.65000000,0.88514800,3.67700000,0.02938789,364.77921284,0.02896434,375.49930382,0.00081856,0.03897694,409.28234987,-0.02155508,-0.01742186,0.00000000,0.00000000,0.00000000,0.00000000
54.65000000,0.90957900,3.69500000,0.03018489,366.56491473,0.02973829,377.62963595,0.00074456,0.03974074,410.74500098,-0.02200279,-0.01773796,0.00000000,0.00000000,0.00000000,0.00000000
55.65000000,0.93387300,3.70700000,0.03099700,367.75538265,0.03052630,379.15469625,0.00076575,0.04047402,412.30151180,-0.02238341,-0.01809061,0.00000000,0.00000000,0.00000000,0.00000000
56.65000000,0.95810200,3.72300000,0.03180911,369.34267322,0.03131368,381.09113535,0.00079466,0.04121875,413.76037468,-0.02281340,-0.01840535,0.00000000,0.00000000,0.00000000,0.00000000
57.65000000,0.98212600,3.73700000,0.03260600,370.73155246,0.03208570,382.81962546,0.00079383,0.04198297,415.33400127,-0.02323817,-0.01874480,0.00000000,0.00000000,0.00000000,0.00000000
58.65000000,1.00621800,3.75200000,0.03340311,372.21963736,0.03285735,384.65293127,0.00069126,0.04276921,416.81437831,-0.02371294,-0.01905626,0.00000000,0.00000000,0.00000000,0.00000000
59.65000000,1.03061400,3.76600000,0.03421900,373.60851661,0.03364655,386.39302644,0.00078529,0.04351001,418.17297306,-0.02411241,-0.01939760,0.00000000,0.00000000,0.00000000,0.00000000
60.65000000,1.05487600,3.78100000,0.03503856,375.09660151,0.03443868,388.23944462,0.00075546,0.04424166,419.63441682,-0.02451493,-0.01972673,0.00000000,0.00000000,0.00000000,0.00000000
61.65000000,1.07900300,3.79200000,0.03583567,376.18786377,0.03520851,389.66880667,0.00076239,0.04500323,421.21546947,-0.02493833,-0.02006490,0.00000000,0.00000000,0.00000000,0.00000000
62.65000000,1.10312900,3.80800000,0.03664022,377.77515434,0.03598493,391.61691994,0.00078345,0.04573152,422.57451561,-0.02533447,-0.02039705,0.00000000,0.00000000,0.00000000,0.00000000
63.65000000,1.12752700,3.82200000,0.03743733,379.16403358,0.03675357,393.35892390,0.00074685,0.04647198,424.04567847,-0.02579572,-0.02067625,0.00000000,0.00000000,0.00000000,0.00000000
64.65000000,1.15199100,3.83400000,0.03826444,380.35450151,0.03755052,394.90855520,0.00075332,0.04724379,425.53226555,-0.02622239,-0.02102140,0.00000000,0.00000000,0.00000000,0.00000000
65.65000000,1.17652300,3.84700000,0.03905389,381.64417509,0.03831058,396.54886430,0.00077457,0.04799511,426.90686163,-0.02664709,-0.02134802,0.00000000,0.00000000,0.00000000,0.00000000
66.65000000,1.20078500,3.86000000,0.03986989,382.93384867,0.03909560,398.20137867,0.00075237,0.04872804,428.27540858,-0.02709080,-0.02163724,0.00000000,0.00000000,0.00000000,0.00000000
67.65000000,1.22504600,3.87200000,0.04065567,384.12431660,0.03985096,399.74114677,0.00070844,0.04949947,429.66242357,-0.02752851,-0.02197095,0.00000000,0.00000000,0.00000000,0.00000000
68.65000000,1.24907100,3.88500000,0.04148267,385.41399018,0.04064534,401.40199026,0.00080158,0.05025736,430.93996308,-0.02795100,-0.02230637,0.00000000,0.00000000,0.00000000,0.00000000
69.65000000,1.27340100,3.89800000,0.04227600,386.70366376,0.04140678,403.05194785,0.00076493,0.05100694,432.53249617,-0.02836689,-0.02264005,0.00000000,0.00000000,0.00000000,0.00000000
70.65000000,1.29783100,3.90900000,0.04306544,387.79492603,0.04216392,404.49548687,0.00068485,0.05176582,433.91988666,-0.02881301,-0.02295282,0.00000000,0.00000000,0.00000000,0.00000000
71.65000000,1.32178800,3.92100000,0.04390011,388.98539395,0.04296381,406.06189597,0.00079227,0.05253734,435.10312614,-0.02926548,-0.02327186,0.00000000,0.00000000,0.00000000,0.00000000
72.65000000,1.34608400,3.93500000,0.04471600,390.37427319,0.04374508,407.83024919,0.00079910,0.05328293,436.59422343,-0.02965954,-0.02362339,0.00000000,0.00000000,0.00000000,0.00000000
73.65000000,1.37061700,3.94600000,0.04551311,391.46553546,0.04450778,409.28234987,0.00072662,0.05404279,437.77576174,-0.03009830,-0.02394449,0.00000000,0.00000000,0.00000000,0.00000000
74.65000000,1.39487800,3.95700000,0.04633267,392.55679772,0.04529135,410.74500098,0.00078342,0.05482513,439.07485943,-0.03056265,-0.02426248,0.00000000,0.00000000,0.00000000,0.00000000
75.65000000,1.41903800,3.96900000,0.04712222,393.74726564,0.04604566,412.30151180,0.00078283,0.05555626,440.45921115,-0.03095481,-0.02460145,0.00000000,0.00000000,0.00000000,0.00000000
76.65000000,1.44313100,3.98000000,0.04792300,394.83852791,0.04681011,413.76037468,0.00076802,0.05632685,441.75672263,-0.03138721,-0.02493964,0.00000000,0.00000000,0.00000000,0.00000000
77.65000000,1.46773000,3.99200000,0.04874644,396.02899583,0.04759559,415.33400127,0.00073159,0.05709316,443.05411367,-0.03185118,-0.02524198,0.00000000,0.00000000,0.00000000,0.00000000
78.65000000,1.49250000,4.00300000,0.04959233,397.12025809,0.04840183,416.81437831,0.00083838,0.05784485,444.34674204,-0.03226775,-0.02557710,0.00000000,0.00000000,0.00000000,0.00000000
79.65000000,1.51679600,4.01300000,0.05038944,398.11231470,0.04916099,418.17297306,0.00080198,0.05859460,445.74670811,-0.03268156,-0.02591304,0.00000000,0.00000000,0.00000000,0.00000000
80.65000000,1.54122800,4.02400000,0.05117900,399.20357696,0.04991239,419.63441682,0.00075147,0.05937948,446.84471078,-0.03316024,-0.02621924,0.00000000,0.00000000,0.00000000,0.00000000
81.65000000,1.56552300,4.03600000,0.05200233,400.39404488,0.05069533,421.21546947,0.00076483,0.06014689,448.14960143,-0.03358162,-0.02656528,0.00000000,0.00000000,0.00000000,0.00000000
82.65000000,1.58964900,4.04600000,0.05278811,401.38610149,0.05144199,422.57451561,0.00078579,0.06089062,449.33884427,-0.03401028,-0.02688035,0.00000000,0.00000000,0.00000000,0.00000000
83.65000000,1.61431600,4.05700000,0.05358889,402.47736375,0.05220233,424.04567847,0.00075671,0.06162530,450.63235110,-0.03444153,-0.02718377,0.00000000,0.00000000,0.00000000,0.00000000
84.65000000,1.63881500,4.06800000,0.05442356,403.56862601,0.05299422,425.53226555,0.00077045,0.06239920,451.83849820,-0.03487746,-0.02752174,0.00000000,0.00000000,0.00000000,0.00000000
85.65000000,1.66317800,4.07800000,0.05523567,404.56068261,0.05376412,426.90686163,0.00073425,0.06315010,453.14277502,-0.03529765,-0.02785245,0.00000000,0.00000000,0.00000000,0.00000000
86.65000000,1.68760900,4.08800000,0.05602889,405.55273922,0.05451554,428.27540858,0.00076191,0.06394023,454.35967497,-0.03575694,-0.02818328,0.00000000,0.00000000,0.00000000,0.00000000
87.65000000,1.71207300,4.09800000,0.05686367,406.54479582,0.05530572,429.66242357,0.00071882,0.06470531,455.56677166,-0.03621841,-0.02848689,0.00000000,0.00000000,0.00000000,0.00000000
88.65000000,1.73657200,4.10700000,0.05768322,407.43764676,0.05608088,430.93996308,0.00078216,0.06546277,456.77198661,-0.03663607,-0.02882670,0.00000000,0.00000000,0.00000000,0.00000000
89.65000000,1.76090200,4.11900000,0.05849911,408.62811469,0.05685197,432.53249617,0.00073913,0.06620719,457.86547663,-0.03706820,-0.02913899,0.00000000,0.00000000,0.00000000,0.00000000
90.65000000,1.78526500,4.12900000,0.05932256,409.62017129,0.05762961,433.91988666,0.00070309,0.06700869,459.09414247,-0.03753114,-0.02947755,0.00000000,0.00000000,0.00000000,0.00000000
91.65000000,1.80989800,4.13700000,0.06015711,410.41381657,0.05841712,435.10312614,0.00079459,0.06775721,460.29998124,-0.03793744,-0.02981977,0.00000000,0.00000000,0.00000000,0.00000000
92.65000000,1.83463400,4.14800000,0.06096922,411.50507883,0.05918285,436.59422343,0.00072295,0.06851568,461.51202802,-0.03836875,-0.03014693,0.00000000,0.00000000,0.00000000,0.00000000
93.65000000,1.85913300,4.15600000,0.06179267,412.29872412,0.05995867,437.77576174,0.00072260,0.06928194,462.62165221,-0.03879848,-0.03048346,0.00000000,0.00000000,0.00000000,0.00000000
94.65000000,1.88366500,4.16500000,0.06264233,413.19157506,0.06075857,439.07485943,0.00079984,0.07004051,463.72915208,-0.03922511,-0.03081540,0.00000000,0.00000000,0.00000000,0.00000000
95.65000000,1.90809600,4.17500000,0.06343944,414.18363166,0.06150841,440.45921115,0.00075681,0.07077985,464.93693078,-0.03965612,-0.03112374,0.00000000,0.00000000,0.00000000,0.00000000
96.65000000,1.93289900,4.18400000,0.06427789,415.07648260,0.06229653,441.75672263,0.00077042,0.07157734,466.17355643,-0.04014367,-0.03143367,0.00000000,0.00000000,0.00000000,0.00000000
97.65000000,1.95773600,4.19300000,0.06511244,415.96933355,0.06308038,443.05411367,0.00081197,0.07232721,467.28150206,-0.04053681,-0.03179041,0.00000000,0.00000000,0.00000000,0.00000000
98.65000000,1.98260700,4.20200000,0.06593200,416.86218449,0.06384953,444.34674204,0.00076901,0.07310413,468.40362359,-0.04100668,-0.03209745,0.00000000,0.00000000,0.00000000,0.00000000
99.65000000,2.00734100,4.21200000,0.06675167,417.85424109,0.06461821,445.74670811,0.00075446,0.07385971,469.51716169,-0.04144474,-0.03241497,0.00000000,0.00000000,0.00000000,0.00000000
100.65000000,2.03228000,4.21900000,0.06760511,418.54868071,0.06541793,446.84471078,0.00077489,0.07461268,470.52264677,-0.04186435,-0.03274833,0.00000000,0.00000000,0.00000000,0.00000000
101.65000000,2.05698100,4.22800000,0.06844356,419.44153166,0.06620297,448.14960143,0.00080965,0.07536695,471.63836965,-0.04227673,-0.03309022,0.00000000,0.00000000,0.00000000,0.00000000
102.65000000,2.08168300,4.23600000,0.06925567,420.23517694,0.06696277,449.33884427,0.00075976,0.07614481,472.76676328,-0.04272759,-0.03341722,0.00000000,0.00000000,0.00000000,0.00000000
103.65000000,2.10638400,4.24500000,0.07006022,421.12802788,0.06771493,450.63235110,0.00072408,0.07693239,473.90129417,-0.04320167,-0.03373071,0.00000000,0.00000000,0.00000000,0.00000000
104.65000000,2.13142500,4.25300000,0.07090611,421.92167316,0.06850512,451.83849820,0.00078640,0.07771720,474.92742481,-0.04364159,-0.03407561,0.00000000,0.00000000,0.00000000,0.00000000
105.65000000,2.15629500,4.26200000,0.07172944,422.81452411,0.06927365,453.14277502,0.00073664,0.07846219,476.04451398,-0.04406900,-0.03439319,0.00000000,0.00000000,0.00000000,0.00000000
106.65000000,2.18123400,4.27000000,0.07259422,423.60816939,0.07008022,454.35967497,0.00078537,0.07922527,477.06294559,-0.04449175,-0.03473352,0.00000000,0.00000000,0.00000000,0.00000000
107.65000000,2.20624100,4.27800000,0.07343267,424.40181467,0.07086161,455.56677166,0.00080568,0.08000474,478.09056948,-0.04494188,-0.03506286,0.00000000,0.00000000,0.00000000,0.00000000
108.65000000,2.23121200,4.28600000,0.07426356,425.19545995,0.07163536,456.77198661,0.00076305,0.08074447,479.20932087,-0.04533731,-0.03540716,0.00000000,0.00000000,0.00000000,0.00000000
109.65000000,2.25628600,4.29300000,0.07507944,425.88989957,0.07239456,457.86547663,0.00070664,0.08155018,480.25235573,-0.04581721,-0.03573298,0.00000000,0.00000000,0.00000000,0.00000000
110.65000000,2.28180000,4.30100000,0.07595933,426.68354486,0.07321267,459.09414247,0.00081825,0.08231753,481.27820488,-0.04626872,-0.03604881,0.00000000,0.00000000,0.00000000,0.00000000
111.65000000,2.30690800,4.30900000,0.07678256,427.47719014,0.07397748,460.29998124,0.00076828,0.08309102,482.30835280,-0.04669547,-0.03639556,0.00000000,0.00000000,0.00000000,0.00000000
112.65000000,2.33174400,4.31700000,0.07761722,428.27083542,0.07475233,461.51202802,0.00073983,0.08384694,483.33128304,-0.04714063,-0.03670630,0.00000000,0.00000000,0.00000000,0.00000000
113.65000000,2.35644600,4.32400000,0.07845944,428.96527504,0.07553358,462.62165221,0.00076028,0.08463631,484.37182147,-0.04757659,-0.03705971,0.00000000,0.00000000,0.00000000,0.00000000
114.65000000,2.38148600,4.33100000,0.07929400,429.65971466,0.07630712,463.72915208,0.00082211,0.08538756,485.39510671,-0.04800845,-0.03737911,0.00000000,0.00000000,0.00000000,0.00000000
115.65000000,2.40686400,4.33900000,0.08010989,430.45335995,0.07706278,464.93693078,0.00073113,0.08616206,486.43106498,-0.04844986,-0.03771220,0.00000000,0.00000000,0.00000000,0.00000000
116.65000000,2.43220800,4.34700000,0.08098967,431.24700523,0.07787698,466.17355643,0.00081403,0.08692031,487.35073758,-0.04886703,-0.03805328,0.00000000,0.00000000,0.00000000,0.00000000
117.65000000,2.45721400,4.35400000,0.08181678,431.94144485,0.07864183,467.28150206,0.00075772,0.08772556,488.29465136,-0.04936208,-0.03836349,0.00000000,0.00000000,0.00000000,0.00000000
118.65000000,2.48249100,4.36100000,0.08267400,432.63588447,0.07943391,468.40362359,0.00081954,0.08847426,489.32176926,-0.04975556,-0.03871870,0.00000000,0.00000000,0.00000000,0.00000000
119.65000000,2.50770000,4.36800000,0.08350867,433.33032409,0.08020454,469.51716169,0.00078423,0.08924772,490.25247940,-0.05022039,-0.03902733,0.00000000,0.00000000,0.00000000,0.00000000
120.65000000,2.53311200,4.37400000,0.08433956,433.92555806,0.08097110,470.52264677,0.00079778,0.09003940,491.30338129,-0.05067408,-0.03936532,0.00000000,0.00000000,0.00000000,0.00000000
121.65000000,2.55815200,4.38100000,0.08517411,434.61999768,0.08174045,471.63836965,0.00069269,0.09083190,492.24597584,-0.05113174,-0.03970016,0.00000000,0.00000000,0.00000000,0.00000000
122.65000000,2.58397200,4.38800000,0.08603511,435.31443730,0.08253355,472.76676328,0.00070626,0.09161206,493.29383503,-0.05157632,-0.04003574,0.00000000,0.00000000,0.00000000,0.00000000
123.65000000,2.60934900,4.39500000,0.08690744,436.00887692,0.08333646,473.90129417,0.00083046,0.09240665,494.23996355,-0.05200734,-0.04039931,0.00000000,0.00000000,0.00000000,0.00000000
124.65000000,2.63472700,4.40100000,0.08777589,436.60411088,0.08413514,474.92742481,0.00082980,0.09318689,495.18015483,-0.05249574,-0.04069115,0.00000000,0.00000000,0.00000000,0.00000000
125.65000000,2.65973300,4.40800000,0.08860300,437.29855051,0.08489522,476.04451398,0.00078750,0.09394304,496.10950140,-0.05289462,-0.04104843,0.00000000,0.00000000,0.00000000,0.00000000
126.65000000,2.68487400,4.41400000,0.08944900,437.89378447,0.08567206,477.06294559,0.00081485,0.09471534,497.04807427,-0.05332858,-0.04138676,0.00000000,0.00000000,0.00000000,0.00000000
127.65000000,2.71049000,4.42000000,0.09031367,438.48901843,0.08646542,478.09056948,0.00085539,0.09550724,497.99764966,-0.05380099,-0.04170625,0.00000000,0.00000000,0.00000000,0.00000000
128.65000000,2.73661300,4.42700000,0.09113700,439.18345805,0.08722027,479.20932087,0.00075797,0.09630377,499.06148359,-0.05421022,-0.04209355,0.00000000,0.00000000,0.00000000,0.00000000
129.65000000,2.76212700,4.43300000,0.09203189,439.77869201,0.08804008,480.25235573,0.00078503,0.09706221,499.88593446,-0.05463845,-0.04242376,0.00000000,0.00000000,0.00000000,0.00000000
130.65000000,2.78760700,4.43900000,0.09288533,440.37392597,0.08882129,481.27820488,0.00082592,0.09788068,500.74162968,-0.05515193,-0.04272875,0.00000000,0.00000000,0.00000000,0.00000000
131.65000000,2.81322100,4.44500000,0.09374622,440.96915994,0.08960870,482.30835280,0.00081144,0.09863301,501.67599111,-0.05554870,-0.04308431,0.00000000,0.00000000,0.00000000,0.00000000
132.65000000,2.83876900,4.45100000,0.09458844,441.56439390,0.09037844,483.33128304,0.00072836,0.09943178,502.63499978,-0.05598816,-0.04344362,0.00000000,0.00000000,0.00000000,0.00000000
133.65000000,2.86475700,4.45700000,0.09546822,442.15962786,0.09118187,484.37182147,0.00081017,0.10024128,503.48951677,-0.05649794,-0.04374335,0.00000000,0.00000000,0.00000000,0.00000000
134.65000000,2.89003300,4.46300000,0.09630667,442.75486182,0.09194695,485.39510671,0.00077528,0.10100195,504.43156331,-0.05690166,-0.04410029,0.00000000,0.00000000,0.00000000,0.00000000
135.65000000,2.91558200,4.46900000,0.09717144,443.35009578,0.09273545,486.43106498,0.00076089,0.10177864,505.38292701,-0.05735390,-0.04442473,0.00000000,0.00000000,0.00000000,0.00000000
136.65000000,2.94160400,4.47400000,0.09801733,443.84612408,0.09350613,487.35073758,0.00072609,0.10256954,506.23129566,-0.05778933,-0.04478021,0.00000000,0.00000000,0.00000000,0.00000000
137.65000000,2.96715000,4.47900000,0.09891589,444.34215239,0.09432414,488.29465136,0.00083494,0.10337323,507.08723736,-0.05823582,-0.04513741,0.00000000,0.00000000,0.00000000,0.00000000
138.65000000,2.99340900,4.48500000,0.09975422,444.93738635,0.09508672,489.32176926,0.00074536,0.10413941,507.92506218,-0.05866871,-0.04547070,0.00000000,0.00000000,0.00000000,0.00000000
139.65000000,3.01915900,4.49000000,0.10061900,445.43341465,0.09587275,490.25247940,0.00077204,0.10492351,508.88477871,-0.05912095,-0.04580256,0.00000000,0.00000000,0.00000000,0.00000000
140.65000000,3.04477400,4.49600000,0.10150633,446.02864861,0.09667864,491.30338129,0.00079220,0.10571853,509.73951192,-0.05957622,-0.04614230,0.00000000,0.00000000,0.00000000,0.00000000
141.65000000,3.07113500,4.50100000,0.10239367,446.52467691,0.09748388,492.24597584,0.00078471,0.10654617,510.61208096,-0.06006828,-0.04647789,0.00000000,0.00000000,0.00000000,0.00000000
142.65000000,3.09742700,4.50700000,0.10326967,447.11991087,0.09827820,493.29383503,0.00074298,0.10731986,511.45797043,-0.06049693,-0.04682292,0.00000000,0.00000000,0.00000000,0.00000000
143.65000000,3.12365100,4.51200000,0.10416078,447.61593918,0.09908557,494.23996355,0.00081063,0.10811288,512.31485799,-0.06096376,-0.04714912,0.00000000,0.00000000,0.00000000,0.00000000
144.65000000,3.14960500,4.51700000,0.10503667,448.11196748,0.09987852,495.18015483,0.00080295,0.10889372,513.27867049,-0.06140074,-0.04749298,0.00000000,0.00000000,0.00000000,0.00000000
145.65000000,3.17518500,4.52200000,0.10588644,448.60799578,0.10064723,496.10950140,0.00076856,0.10972207,514.15603767,-0.06190952,-0.04781254,0.00000000,0.00000000,0.00000000,0.00000000
146.65000000,3.20144300,4.52700000,0.10675489,449.10402408,0.10143221,497.04807427,0.00074064,0.11052118,514.90701167,-0.06234254,-0.04817864,0.00000000,0.00000000,0.00000000,0.00000000
147.65000000,3.22803900,4.53200000,0.10764589,449.60005238,0.10223694,497.99764966,0.00082153,0.11129833,515.75990519,-0.06279290,-0.04850543,0.00000000,0.00000000,0.00000000,0.00000000
148.65000000,3.25419600,4.53800000,0.10854444,450.19528634,0.10304784,499.06148359,0.00083430,0.11206303,516.49482553,-0.06321176,-0.04885127,0.00000000,0.00000000,0.00000000,0.00000000
149.65000000,3.28062300,4.54200000,0.10939789,450.59210898,0.10381743,499.88593446,0.00073888,0.11288521,517.37315257,-0.06369102,-0.04919420,0.00000000,0.00000000,0.00000000,0.00000000
150.65000000,3.30664400,4.54600000,0.11031911,450.98893162,0.10464746,500.74162968,0.00087381,0.11370166,518.13687336,-0.06416090,-0.04954075,0.00000000,0.00000000,0.00000000,0.00000000
151.65000000,3.33320600,4.55100000,0.11116878,451.48495993,0.10541241,501.67599111,0.00075810,0.11447623,518.99244050,-0.06456494,-0.04991129,0.00000000,0.00000000,0.00000000,0.00000000
152.65000000,3.35949700,4.55600000,0.11207111,451.98098823,0.10622414,502.63499978,0.00081846,0.11528639,519.86767477,-0.06505263,-0.05023376,0.00000000,0.00000000,0.00000000,0.00000000
153.65000000,3.38643100,4.56000000,0.11298456,452.37781087,0.10704520,503.48951677,0.00084455,0.11609275,520.74200897,-0.06547410,-0.05061865,0.00000000,0.00000000,0.00000000,0.00000000
154.65000000,3.41258800,4.56500000,0.11384567,452.87383917,0.10781859,504.43156331,0.00081716,0.11691452,521.39934235,-0.06594874,-0.05096579,0.00000000,0.00000000,0.00000000,0.00000000
155.65000000,3.43952300,4.57000000,0.11472544,453.36986747,0.10860814,505.38292701,0.00076925,0.11773087,522.16774989,-0.06641757,-0.05131330,0.00000000,0.00000000,0.00000000,0.00000000
156.65000000,3.46595100,4.57400000,0.11562022,453.76669011,0.10941050,506.23129566,0.00078198,0.11854643,522.93666346,-0.06689863,-0.05164780,0.00000000,0.00000000,0.00000000,0.00000000
157.65000000,3.49261400,4.57800000,0.11653011,454.16351275,0.11022576,507.08723736,0.00082196,0.11934335,523.81004289,-0.06735150,-0.05199185,0.00000000,0.00000000,0.00000000,0.00000000
158.65000000,3.51924400,4.58200000,0.11739856,454.56033539,0.11100327,507.92506218,0.00082132,0.12014122,524.57153598,-0.06777483,-0.05236639,0.00000000,0.00000000,0.00000000,0.00000000
159.65000000,3.54580600,4.58700000,0.11828956,455.05636370,0.11180034,508.88477871,0.00078687,0.12092371,525.43934605,-0.06821124,-0.05271247,0.00000000,0.00000000,0.00000000,0.00000000
160.65000000,3.57253700,4.59100000,0.11919189,455.45318634,0.11260690,509.73951192,0.00081981,0.12174316,526.21414814,-0.06866885,-0.05307431,0.00000000,0.00000000,0.00000000,0.00000000
161.65000000,3.59953900,4.59500000,0.12013178,455.85000898,0.11344634,510.61208096,0.00087965,0.12257839,526.99825548,-0.06915225,-0.05342615,0.00000000,0.00000000,0.00000000,0.00000000
162.65000000,3.62667700,4.59900000,0.12101156,456.24683162,0.11423145,511.45797043,0.00077148,0.12337679,527.76373906,-0.06959273,-0.05378406,0.00000000,0.00000000,0.00000000,0.00000000
163.65000000,3.65344200,4.60300000,0.12191389,456.64365426,0.11503606,512.31485799,0.00074411,0.12423849,528.67777014,-0.07007911,-0.05415937,0.00000000,0.00000000,0.00000000,0.00000000
164.65000000,3.68030900,4.60800000,0.12280489,457.13968256,0.11582992,513.27867049,0.00075678,0.12501084,529.31727298,-0.07052629,-0.05448455,0.00000000,0.00000000,0.00000000,0.00000000
165.65000000,3.70707500,4.61200000,0.12374867,457.53650520,0.11667012,514.15603767,0.00087010,0.12586285,530.11411620,-0.07102224,-0.05484061,0.00000000,0.00000000,0.00000000,0.00000000
166.65000000,3.73438100,4.61500000,0.12465844,457.83412218,0.11747938,514.90701167,0.00082926,0.12666335,530.77016727,-0.07146386,-0.05519949,0.00000000,0.00000000,0.00000000,0.00000000
167.65000000,3.76131600,4.61900000,0.12554578,458.23094482,0.11826805,515.75990519,0.00079523,0.12747641,531.66231936,-0.07192441,-0.05555200,0.00000000,0.00000000,0.00000000,0.00000000
168.65000000,3.78791200,4.62200000,0.12641800,458.52856181,0.11904269,516.49482553,0.00073462,0.12829993,532.21793307,-0.07238415,-0.05591578,0.00000000,0.00000000,0.00000000,0.00000000
169.65000000,3.81491500,4.62600000,0.12735789,458.92538445,0.11987674,517.37315257,0.00080697,0.12912470,533.11833450,-0.07286007,-0.05626463,0.00000000,0.00000000,0.00000000,0.00000000
170.65000000,3.84188300,4.62900000,0.12829033,459.22300143,0.12070351,518.13687336,0.00083979,0.12994857,533.79015749,-0.07331671,-0.05663186,0.00000000,0.00000000,0.00000000,0.00000000
171.65000000,3.86919000,4.63300000,0.12917767,459.61982407,0.12148964,518.99244050,0.00077279,0.13073925,534.67429327,-0.07374278,-0.05699647,0.00000000,0.00000000,0.00000000,0.00000000
172.65000000,3.89642900,4.63700000,0.13010622,460.01664671,0.12231163,519.86767477,0.00077195,0.13162021,535.37858749,-0.07426911,-0.05735110,0.00000000,0.00000000,0.00000000,0.00000000
173.65000000,3.92380400,4.64100000,0.13103122,460.41346935,0.12312980,520.74200897,0.00083796,0.13241270,536.03594565,-0.07471337,-0.05769933,0.00000000,0.00000000,0.00000000,0.00000000
174.65000000,3.95070500,4.64300000,0.13197111,460.61188067,0.12396046,521.39934235,0.00077736,0.13326789,536.84292371,-0.07518164,-0.05808625,0.00000000,0.00000000,0.00000000,0.00000000
175.65000000,3.97811300,4.64600000,0.13290733,460.90949765,0.12478719,522.16774989,0.00086306,0.13409150,537.51869686,-0.07563748,-0.05845402,0.00000000,0.00000000,0.00000000,0.00000000
176.65000000,4.00586100,4.64900000,0.13384344,461.20711463,0.12561314,522.93666346,0.00086882,0.13492407,538.20008970,-0.07611421,-0.05880986,0.00000000,0.00000000,0.00000000,0.00000000
177.65000000,4.03320200,4.65300000,0.13476078,461.60393727,0.12642186,523.81004289,0.00083501,0.13576729,539.00333575,-0.07660337,-0.05916392,0.00000000,0.00000000,0.00000000,0.00000000
178.65000000,4.06023900,4.65600000,0.13567822,461.90155426,0.12723003,524.57153598,0.00076817,0.13657263,539.67157689,-0.07702385,-0.05954878,0.00000000,0.00000000,0.00000000,0.00000000
179.65000000,4.08768200,4.66000000,0.13658056,462.29837690,0.12802424,525.43934605,0.00073450,0.13743064,540.48471793,-0.07750558,-0.05992506,0.00000000,0.00000000,0.00000000,0.00000000
180.65000000,4.11536100,4.66300000,0.13752422,462.59599388,0.12885417,526.21414814,0.00076692,0.13826674,541.17132956,-0.07799148,-0.06027526,0.00000000,0.00000000,0.00000000,0.00000000
181.65000000,4.14304000,4.66600000,0.13848678,462.89361086,0.12969999,526.99825548,0.00075983,0.13910869,541.86191747,-0.07842550,-0.06068319,0.00000000,0.00000000,0.00000000,0.00000000
182.65000000,4.17109100,4.66900000,0.13940789,463.19122784,0.13050873,527.76373906,0.00079219,0.13994668,542.55112735,-0.07894878,-0.06099790,0.00000000,0.00000000,0.00000000,0.00000000
183.65000000,4.19880400,4.67300000,0.14040422,463.58805048,0.13138278,528.67777014,0.00088370,0.14081131,543.37159778,-0.07941363,-0.06139767,0.00000000,0.00000000,0.00000000,0.00000000
184.65000000,4.22675400,4.67500000,0.14129522,463.78646180,0.13216378,529.31727298,0.00075776,0.14165252,543.94826359,-0.07988046,-0.06177206,0.00000000,0.00000000,0.00000000,0.00000000
185.65000000,4.25436600,4.67800000,0.14228033,464.08407878,0.13302656,530.11411620,0.00083612,0.14248831,544.63864914,-0.08036896,-0.06211935,0.00000000,0.00000000,0.00000000,0.00000000
186.65000000,4.28258700,4.68000000,0.14320522,464.28249010,0.13383592,530.77016727,0.00081581,0.14338116,545.36116277,-0.08085692,-0.06252424,0.00000000,0.00000000,0.00000000,0.00000000
187.65000000,4.31067200,4.68400000,0.14414889,464.67931274,0.13466103,531.66231936,0.00086118,0.14419301,546.03998385,-0.08133611,-0.06285690,0.00000000,0.00000000,0.00000000,0.00000000
188.65000000,4.33875700,4.68500000,0.14510011,464.77851840,0.13549207,532.21793307,0.00079485,0.14508420,546.76325921,-0.08181001,-0.06327419,0.00000000,0.00000000,0.00000000,0.00000000
189.65000000,4.36653800,4.68900000,0.14605889,465.17534104,0.13632900,533.11833450,0.00089913,0.14591062,547.45167563,-0.08230260,-0.06360801,0.00000000,0.00000000,0.00000000,0.00000000
190.65000000,4.39445400,4.69100000,0.14701389,465.37375236,0.13716195,533.79015749,0.00089198,0.14678114,548.16522328,-0.08276640,-0.06401474,0.00000000,0.00000000,0.00000000,0.00000000
191.65000000,4.42243800,4.69500000,0.14793489,465.77057501,0.13796458,534.67429327,0.00081244,0.14760923,548.85614646,-0.08322361,-0.06438562,0.00000000,0.00000000,0.00000000,0.00000000
192.65000000,4.45082800,4.69700000,0.14895756,465.96898633,0.13885506,535.37858749,0.00092298,0.14847026,549.44927990,-0.08372606,-0.06474420,0.00000000,0.00000000,0.00000000,0.00000000
193.65000000,4.47975900,4.69900000,0.14987867,466.16739765,0.13965643,536.03594565,0.00087623,0.14936075,550.17626893,-0.08421487,-0.06514588,0.00000000,0.00000000,0.00000000,0.00000000
194.65000000,4.50814900,4.70200000,0.15087500,466.46501463,0.14052252,536.84292371,0.00088880,0.15025051,550.90372795,-0.08473633,-0.06551418,0.00000000,0.00000000,0.00000000,0.00000000
195.65000000,4.53660600,4.70400000,0.15183378,466.66342595,0.14135526,537.51869686,0.00079001,0.15110912,551.49762227,-0.08517207,-0.06593705,0.00000000,0.00000000,0.00000000,0.00000000
196.65000000,4.56469000,4.70600000,0.15280378,466.86183727,0.14219704,538.20008970,0.00085472,0.15199729,552.22580491,-0.08570866,-0.06628863,0.00000000,0.00000000,0.00000000,0.00000000
197.65000000,4.59345200,4.70900000,0.15378878,467.15945425,0.14305112,539.00333575,0.00086690,0.15288612,552.83789251,-0.08621508,-0.06667104,0.00000000,0.00000000,0.00000000,0.00000000
198.65000000,4.62187600,4.71100000,0.15472878,467.35786557,0.14386549,539.67157689,0.00082076,0.15380439,553.58449968,-0.08674180,-0.06706259,0.00000000,0.00000000,0.00000000,0.00000000
199.65000000,4.65090900,4.71400000,0.15573267,467.65548255,0.14473449,540.48471793,0.00083947,0.15465989,554.17941597,-0.08722262,-0.06743727,0.00000000,0.00000000,0.00000000,0.00000000
200.65000000,4.67950200,4.71600000,0.15671011,467.85389387,0.14557986,541.17132956,0.00089065,0.15554482,554.90906075,-0.08771158,-0.06783324,0.00000000,0.00000000,0.00000000,0.00000000
201.65000000,4.70863600,4.71800000,0.15769522,468.05230519,0.14643115,541.86191747,0.00085111,0.15646207,555.53990103,-0.08823087,-0.06823120,0.00000000,0.00000000,0.00000000,0.00000000
202.65000000,4.73712800,4.72000000,0.15867656,468.25071651,0.14727845,542.55112735,0.00088933,0.15734537,556.27028433,-0.08872778,-0.06861758,0.00000000,0.00000000,0.00000000,0.00000000
203.65000000,4.76609300,4.72300000,0.15969167,468.54833349,0.14815417,543.37159778,0.00084945,0.15829260,556.91943365,-0.08929972,-0.06899287,0.00000000,0.00000000,0.00000000,0.00000000
204.65000000,4.79502400,4.72400000,0.16067667,468.64753915,0.14900317,543.94826359,0.00086175,0.15920578,557.66828994,-0.08980171,-0.06940407,0.00000000,0.00000000,0.00000000,0.00000000
205.65000000,4.82449700,4.72600000,0.16165800,468.84595047,0.14984829,544.63864914,0.00080916,0.16008808,558.28248110,-0.09027233,-0.06981575,0.00000000,0.00000000,0.00000000,0.00000000
206.65000000,4.85400300,4.72800000,0.16270700,469.04436180,0.15075091,545.36116277,0.00092507,0.16103275,558.93245494,-0.09080817,-0.07022459,0.00000000,0.00000000,0.00000000,0.00000000
207.65000000,4.88296800,4.73000000,0.16366200,469.24277312,0.15157193,546.03998385,0.00085973,0.16194487,559.56480947,-0.09129101,-0.07065386,0.00000000,0.00000000,0.00000000,0.00000000
208.65000000,4.91217000,4.73200000,0.16471089,469.44118444,0.15247289,546.76325921,0.00089103,0.16288607,560.33281753,-0.09183115,-0.07105491,0.00000000,0.00000000,0.00000000,0.00000000
209.65000000,4.94083000,4.73400000,0.16568467,469.63959576,0.15330861,547.45167563,0.00083230,0.16386103,560.88356183,-0.09239564,-0.07146538,0.00000000,0.00000000,0.00000000,0.00000000
210.65000000,4.97053900,4.73600000,0.16671111,469.83800708,0.15418877,548.16522328,0.00092189,0.16480038,561.65224872,-0.09292596,-0.07187442,0.00000000,0.00000000,0.00000000,0.00000000
211.65000000,4.99997700,4.73800000,0.16768856,470.03641840,0.15502620,548.85614646,0.00083716,0.16580319,562.33896707,-0.09345889,-0.07234430,0.00000000,0.00000000,0.00000000,0.00000000
212.65000000,5.02955200,4.73900000,0.16870378,470.13562406,0.15589525,549.44927990,0.00083662,0.16674226,562.99035053,-0.09398449,-0.07275777,0.00000000,0.00000000,0.00000000,0.00000000
213.65000000,5.05902400,4.74100000,0.16975644,470.33403538,0.15679556,550.17626893,0.00083587,0.16768204,563.52374428,-0.09451122,-0.07317082,0.00000000,0.00000000,0.00000000,0.00000000
214.65000000,5.08890300,4.74300000,0.17080922,470.53244670,0.15769515,550.90372795,0.00089949,0.16861772,564.29378881,-0.09500527,-0.07361245,0.00000000,0.00000000,0.00000000,0.00000000
215.65000000,5.11810400,4.74400000,0.17182433,470.63165236,0.15856179,551.49762227,0.00089852,0.16961671,564.98149219,-0.09557158,-0.07404513,0.00000000,0.00000000,0.00000000,0.00000000
216.65000000,5.14839000,4.74600000,0.17287711,470.83006368,0.15945980,552.22580491,0.00089790,0.17064578,565.68715714,-0.09618020,-0.07446558,0.00000000,0.00000000,0.00000000,0.00000000
217.65000000,5.17877600,4.74700000,0.17392978,470.92926934,0.16035691,552.83789251,0.00089709,0.17164252,566.37523650,-0.09669408,-0.07494845,0.00000000,0.00000000,0.00000000,0.00000000
218.65000000,5.20885700,4.74900000,0.17502011,471.12768066,0.16128526,553.58449968,0.00089607,0.17264005,566.94485323,-0.09722098,-0.07541906,0.00000000,0.00000000,0.00000000,0.00000000
219.65000000,5.23876900,4.75000000,0.17603522,471.22688632,0.16214880,554.17941597,0.00089530,0.17366594,567.65112613,-0.09782021,-0.07584574,0.00000000,0.00000000,0.00000000,0.00000000
220.65000000,5.26847900,4.75200000,0.17708800,471.42529764,0.16304359,554.90906075,0.00089469,0.17469238,568.23859249,-0.09837603,-0.07631635,0.00000000,0.00000000,0.00000000,0.00000000
221.65000000,5.29845900,4.75300000,0.17817822,471.52450330,0.16396937,555.53990103,0.00095745,0.17568511,568.92744803,-0.09890916,-0.07677595,0.00000000,0.00000000,0.00000000,0.00000000
222.65000000,5.32867600,4.75500000,0.17923100,471.72291462,0.16486253,556.27028433,0.00089287,0.17673882,569.65212295,-0.09950705,-0.07723177,0.00000000,0.00000000,0.00000000,0.00000000
223.65000000,5.35906200,4.75600000,0.18035889,471.82212028,0.16581854,556.91943365,0.00095568,0.17782244,570.39489818,-0.10009319,-0.07772925,0.00000000,0.00000000,0.00000000,0.00000000
224.65000000,5.39005700,4.75800000,0.18144922,472.02053160,0.16674184,557.66828994,0.00089138,0.17887555,571.00058049,-0.10066403,-0.07821152,0.00000000,0.00000000,0.00000000,0.00000000
225.65000000,5.42091700,4.75900000,0.18250189,472.11973726,0.16763244,558.28248110,0.00089021,0.17995682,571.74374362,-0.10123756,-0.07871926,0.00000000,0.00000000,0.00000000,0.00000000
226.65000000,5.45150500,4.76000000,0.18362989,472.21894292,0.16858589,558.93245494,0.00095323,0.00000000,0.00000000,0.00000000,0.00000000,0.00000000,0.00000000,0.00000000,0.00000000
227.65000000,5.48290700,4.76100000,0.18472011,472.31814858,0.16950655,559.56480947,0.00088892,0.00000000,0.00000000,0.00000000,0.00000000,0.00000000,0.00000000,0.00000000,0.00000000
228.65000000,5.51349600,4.76300000,0.18584800,472.51655990,0.17045813,560.33281753,0.00095126,0.00000000,0.00000000,0.00000000,0.00000000,0.00000000,0.00000000,0.00000000,0.00000000
229.65000000,5.54425400,4.76300000,0.18701356,472.51655990,0.17144054,560.88356183,0.00101382,0.00000000,0.00000000,0.00000000,0.00000000,0.00000000,0.00000000,0.00000000,0.00000000
230.65000000,5.57589300,4.76500000,0.18814144,472.71497123,0.17239027,561.65224872,0.00094942,0.00000000,0.00000000,0.00000000,0.00000000,0.00000000,0.00000000,0.00000000,0.00000000
231.65000000,5.60722600,4.76600000,0.18934456,472.81417689,0.17340236,562.33896707,0.00101183,0.00000000,0.00000000,0.00000000,0.00000000,0.00000000,0.00000000,0.00000000,0.00000000
232.65000000,5.63869500,4.76700000,0.19047244,472.91338255,0.17435024,562.99035053,0.00101069,0.00000000,0.00000000,0.00000000,0.00000000,0.00000000,0.00000000,0.00000000,0.00000000
233.65000000,5.67013000,4.76700000,0.19160033,472.91338255,0.17529722,563.52374428,0.00100991,0.00000000,0.00000000,0.00000000,0.00000000,0.00000000,0.00000000,0.00000000,0.00000000
234.65000000,5.70180200,4.76900000,0.19272822,473.11179387,0.17624331,564.29378881,0.00094577,0.00000000,0.00000000,0.00000000,0.00000000,0.00000000,0.00000000,0.00000000,0.00000000
235.65000000,5.73371100,4.77000000,0.19393144,473.21099953,0.17725160,564.98149219,0.00100794,0.00000000,0.00000000,0.00000000,0.00000000,0.00000000,0.00000000,0.00000000,0.00000000
236.65000000,5.76575500,4.77100000,0.19517211,473.31020519,0.17829020,565.68715714,0.00106977,0.00000000,0.00000000,0.00000000,0.00000000,0.00000000,0.00000000,0.00000000,0.00000000
237.65000000,5.79813800,4.77200000,0.19637511,473.40941085,0.17929624,566.37523650,0.00100588,0.00000000,0.00000000,0.00000000,0.00000000,0.00000000,0.00000000,0.00000000,0.00000000
238.65000000,5.83011500,4.77200000,0.19757833,473.40941085,0.18030146,566.94485323,0.00100506,0.00000000,0.00000000,0.00000000,0.00000000,0.00000000,0.00000000,0.00000000,0.00000000
239.65000000,5.86222700,4.77300000,0.19881900,473.50861651,0.18133691,567.65112613,0.00106652,0.00000000,0.00000000,0.00000000,0.00000000,0.00000000,0.00000000,0.00000000,0.00000000
240.65000000,5.89417000,4.77300000,0.20005967,473.50861651,0.18237128,568.23859249,0.00106542,0.00000000,0.00000000,0.00000000,0.00000000,0.00000000,0.00000000,0.00000000,0.00000000
241.65000000,5.92695800,4.77400000,0.20126278,473.60782217,0.18337332,568.92744803,0.00100179,0.00000000,0.00000000,0.00000000,0.00000000,0.00000000,0.00000000,0.00000000,0.00000000
242.65000000,5.95957800,4.77500000,0.20254100,473.70702783,0.18443682,569.65212295,0.00112571,0.00000000,0.00000000,0.00000000,0.00000000,0.00000000,0.00000000,0.00000000,0.00000000
243.65000000,5.99212900,4.77600000,0.20385689,473.80623349,0.18553048,570.39489818,0.00118691,0.00000000,0.00000000,0.00000000,0.00000000,0.00000000,0.00000000,0.00000000,0.00000000
244.65000000,6.02491800,4.77600000,0.20513522,473.80623349,0.18659178,571.00058049,0.00112347,0.00000000,0.00000000,0.00000000,0.00000000,0.00000000,0.00000000,0.00000000,0.00000000
245.65000000,6.05811200,4.77700000,0.20645111,473.90543915,0.18768308,571.74374362,0.00112225,0.00000000,0.00000000,0.00000000,0.00000000,0.00000000,0.00000000,0.00000000,0.00000000
246.65000000,6.09090100,4.77700000,0.20776700,473.90543915,0.00000000,0.00000000,0.00000000,0.00000000,0.00000000,0.00000000,0.00000000,0.00000000,0.00000000,0.00000000,0.00000000
247.65000000,6.12467100,4.77700000,0.20915800,473.90543915,0.00000000,0.00000000,0.00000000,0.00000000,0.00000000,0.00000000,0.00000000,0.00000000,0.00000000,0.00000000,0.00000000
248.65000000,6.15837400,4.77700000,0.21058656,473.90543915,0.00000000,0.00000000,0.00000000,0.00000000,0.00000000,0.00000000,0.00000000,0.00000000,0.00000000,0.00000000,0.00000000
249.65000000,6.19241400,4.77700000,0.21205267,473.90543915,0.00000000,0.00000000,0.00000000,0.00000000,0.00000000,0.00000000,0.00000000,0.00000000,0.00000000,0.00000000,0.00000000
250.65000000,6.22730000,4.77700000,0.21370667,473.90543915,0.00000000,0.00000000,0.00000000,0.00000000,0.00000000,0.00000000,0.00000000,0.00000000,0.00000000,0.00000000,0.00000000
251.15000000,6.24533400,4.77500000,0.21464622,473.70702783,0.00000000,0.00000000,0.00000000,0.00000000,0.00000000,0.00000000,0.00000000,0.00000000,0.00000000,0.00000000,0.00000000