File: LAB_DATA/AA7020-T6_results/DATA/UT_75_2.csv
Time[s],Displacement[mm],Force[kN],EngStrain_longi,EngStress[MPa],TrueStrain,TrueStress[MPa],TrueStrainRate[1/s],PlasticStrain_longi,PlasticStress[MPa],PlasticStrain_thick,PlasticStrain_width,R-Value,Thickness[mm],Width[mm], Young's Modulus [MPa]
0.62000000,0.00000000,-0.01300000,0.00000000,-1.28710832,0.00000000,-1.28710832,0.00000000,0.00056122,279.12325680,0.00059125,-0.00115247,0.64629113,1.00800000,10.02000000,80798.76207732
2.12000000,0.00113400,-0.00800000,-0.00003522,-0.79206666,-0.00003522,-0.79203876,0.00003533,0.00133066,290.02893503,0.00015932,-0.00148998,0.00000000,0.00000000,0.00000000,0.00000000
3.62000000,0.00617900,0.27400000,0.00008044,27.12828312,0.00008044,27.13046544,0.00009999,0.00220087,298.38402598,-0.00038095,-0.00181992,0.00000000,0.00000000,0.00000000,0.00000000
5.12000000,0.01191400,0.45700000,0.00023989,45.24680797,0.00023986,45.25766218,0.00013619,0.00304833,306.14750591,-0.00089850,-0.00214983,0.00000000,0.00000000,0.00000000,0.00000000
6.62000000,0.01881100,0.66700000,0.00045122,66.03855781,0.00045112,66.06835587,0.00004154,0.00393151,312.03220497,-0.00141815,-0.00251336,0.00000000,0.00000000,0.00000000,0.00000000
8.12000000,0.02670500,0.86400000,0.00070456,85.54319932,0.00070431,85.60346925,0.00007284,0.00499358,318.38658695,-0.00212403,-0.00286955,0.00000000,0.00000000,0.00000000,0.00000000
9.62000000,0.03440000,1.07700000,0.00094489,106.63197415,0.00094444,106.73272951,0.00001510,0.00601283,323.13353298,-0.00275397,-0.00325887,0.00000000,0.00000000,0.00000000,0.00000000
11.12000000,0.04261600,1.26200000,0.00116967,124.94851567,0.00116898,125.09466378,-0.00004439,0.00703551,328.09276170,-0.00339250,-0.00364302,0.00000000,0.00000000,0.00000000,0.00000000
12.62000000,0.05034400,1.49000000,0.00145389,147.52241549,0.00145283,147.73689669,0.00004416,0.00810328,332.37253502,-0.00402984,-0.00407343,0.00000000,0.00000000,0.00000000,0.00000000
14.12000000,0.05825900,1.67400000,0.00178589,165.73994867,0.00178430,166.03594181,0.00021696,0.00922632,336.57943141,-0.00470175,-0.00452457,0.00000000,0.00000000,0.00000000,0.00000000
15.62000000,0.06707700,1.86900000,0.00208222,185.04657352,0.00208006,185.43188161,0.00032202,0.01030582,340.07421585,-0.00535596,-0.00494986,0.00000000,0.00000000,0.00000000,0.00000000
17.12000000,0.07676200,2.09200000,0.00238000,207.12543168,0.00237717,207.61839020,0.00045785,0.01139790,344.18730382,-0.00599654,-0.00540136,0.00000000,0.00000000,0.00000000,0.00000000
18.62000000,0.08630700,2.26500000,0.00266567,224.25387321,0.00266212,224.85165928,0.00046504,0.01252792,347.31066562,-0.00667508,-0.00585284,0.00000000,0.00000000,0.00000000,0.00000000
20.12000000,0.09742000,2.45800000,0.00298900,243.36248139,0.00298454,244.08989184,0.00041990,0.01369868,350.86058593,-0.00740943,-0.00628925,0.00000000,0.00000000,0.00000000,0.00000000
21.62000000,0.11241000,2.62200000,0.00344022,259.59984792,0.00343432,260.49292909,0.00038981,0.01479866,354.08912037,-0.00807496,-0.00672370,0.00000000,0.00000000,0.00000000,0.00000000
23.12000000,0.13274700,2.77100000,0.00413956,274.35208947,0.00413101,275.48778519,0.00053187,0.01590682,357.42912781,-0.00874175,-0.00716507,0.00000000,0.00000000,0.00000000,0.00000000
24.62000000,0.15765200,2.87900000,0.00500811,285.04498939,0.00499561,286.47252636,0.00077848,0.01703647,360.17402114,-0.00943526,-0.00760121,0.00000000,0.00000000,0.00000000,0.00000000
26.12000000,0.18702400,2.97100000,0.00586911,294.15375598,0.00585195,295.88017706,0.00082268,0.01817106,363.53758488,-0.01013153,-0.00803953,0.00000000,0.00000000,0.00000000,0.00000000
27.62000000,0.21649700,3.04500000,0.00682411,301.48037259,0.00680093,303.53770815,0.00067241,0.01929909,366.19259893,-0.01082804,-0.00847105,0.00000000,0.00000000,0.00000000,0.00000000
29.12000000,0.24725700,3.10800000,0.00788067,307.71789754,0.00784978,310.14291972,0.00070148,0.02044585,369.26855020,-0.01151785,-0.00892801,0.00000000,0.00000000,0.00000000,0.00000000
30.62000000,0.28018200,3.16300000,0.00894844,313.16335583,0.00890864,315.96568072,0.00084991,0.02158930,371.94131851,-0.01222820,-0.00936109,0.00000000,0.00000000,0.00000000,0.00000000
32.12000000,0.31256500,3.21600000,0.01002378,318.41079745,0.00997387,321.60247653,0.00087124,0.02269574,374.81060425,-0.01287451,-0.00982123,0.00000000,0.00000000,0.00000000,0.00000000
33.62000000,0.34677600,3.26000000,0.01113289,322.76716408,0.01107137,326.36049506,0.00071396,0.02383906,377.29025619,-0.01359817,-0.01024089,0.00000000,0.00000000,0.00000000,0.00000000
35.12000000,0.38254300,3.30300000,0.01236233,327.02452238,0.01228654,331.06730854,0.00089140,0.02494861,380.27516125,-0.01425663,-0.01069198,0.00000000,0.00000000,0.00000000,0.00000000
36.62000000,0.41685500,3.34000000,0.01349411,330.68783069,0.01340388,335.15016902,0.00095007,0.02608315,382.65999505,-0.01496264,-0.01112051,0.00000000,0.00000000,0.00000000,0.00000000
38.12000000,0.45245300,3.37400000,0.01459567,334.05411399,0.01449018,338.92985649,0.00077090,0.02719041,385.34775291,-0.01562540,-0.01156501,0.00000000,0.00000000,0.00000000,0.00000000
39.62000000,0.48811800,3.40600000,0.01583267,337.22238064,0.01570864,342.56151018,0.00086625,0.02831712,387.84292539,-0.01630223,-0.01201489,0.00000000,0.00000000,0.00000000,0.00000000
41.12000000,0.52361400,3.43900000,0.01705089,340.48965561,0.01690715,346.29530690,0.00089494,0.02942310,390.43831401,-0.01700935,-0.01241375,0.00000000,0.00000000,0.00000000,0.00000000
42.62000000,0.56009200,3.46800000,0.01819378,343.36089725,0.01803025,349.60792912,0.00087167,0.03056418,392.74350558,-0.01769532,-0.01286886,0.00000000,0.00000000,0.00000000,0.00000000
44.12000000,0.59528300,3.49800000,0.01937811,346.33114723,0.01919275,353.04239068,0.00084841,0.03169114,395.46116689,-0.01840438,-0.01328675,0.00000000,0.00000000,0.00000000,0.00000000
45.62000000,0.63145700,3.52500000,0.02063011,349.00437221,0.02042019,356.20437118,0.00082537,0.03280203,397.66113551,-0.01906091,-0.01374112,0.00000000,0.00000000,0.00000000,0.00000000
47.12000000,0.66813700,3.55100000,0.02178433,351.57858885,0.02155045,359.23749403,0.00081682,0.03393036,400.07972365,-0.01976060,-0.01416976,0.00000000,0.00000000,0.00000000,0.00000000
48.62000000,0.70383600,3.57700000,0.02296122,354.15280550,0.02270158,362.28458677,0.00074264,0.03504423,402.39391300,-0.02044364,-0.01460059,0.00000000,0.00000000,0.00000000,0.00000000
50.12000000,0.74014400,3.60300000,0.02420567,356.72702215,0.02391735,365.36183754,0.00078580,0.03616627,404.82001082,-0.02112799,-0.01503828,0.00000000,0.00000000,0.00000000,0.00000000
51.62000000,0.77604600,3.62700000,0.02535244,359.10322213,0.02503640,368.20736662,0.00070427,0.03729449,406.94201119,-0.02183618,-0.01545830,0.00000000,0.00000000,0.00000000,0.00000000
53.12000000,0.81198300,3.65200000,0.02655178,361.57843044,0.02620540,371.17898058,0.00074719,0.03844089,409.49202472,-0.02253540,-0.01590550,0.00000000,0.00000000,0.00000000,0.00000000
54.62000000,0.84825700,3.67400000,0.02776989,363.75661376,0.02739130,373.85809450,0.00084148,0.03956780,411.51865660,-0.02322240,-0.01634540,0.00000000,0.00000000,0.00000000,0.00000000
56.12000000,0.88415900,3.69500000,0.02893922,365.83578874,0.02852839,376.42279193,0.00076015,0.04069053,413.75626987,-0.02391380,-0.01677673,0.00000000,0.00000000,0.00000000,0.00000000
57.62000000,0.92006100,3.71700000,0.03013856,368.01397206,0.02969331,379.10538160,0.00078106,0.04181188,415.99794586,-0.02458870,-0.01722319,0.00000000,0.00000000,0.00000000,0.00000000
59.12000000,0.95647100,3.74000000,0.03134544,370.29116370,0.03086421,381.89810480,0.00077282,0.04293326,418.13974729,-0.02525654,-0.01767671,0.00000000,0.00000000,0.00000000,0.00000000
60.62000000,0.99206800,3.76000000,0.03252978,372.27133036,0.03201189,384.38123400,0.00080121,0.04404047,420.17531874,-0.02590392,-0.01813655,0.00000000,0.00000000,0.00000000,0.00000000
62.12000000,1.02790300,3.78200000,0.03372922,374.44951367,0.03317287,387.07940453,0.00077856,0.04518963,422.44236026,-0.02661789,-0.01857174,0.00000000,0.00000000,0.00000000,0.00000000
63.62000000,1.06366900,3.80200000,0.03490222,376.42968032,0.03430695,389.56791268,0.00075577,0.04628137,424.37498146,-0.02726699,-0.01901438,0.00000000,0.00000000,0.00000000,0.00000000
65.12000000,1.09977500,3.82100000,0.03613167,378.31083864,0.03549423,391.97983976,0.00086387,0.04743269,426.54701042,-0.02799062,-0.01944207,0.00000000,0.00000000,0.00000000,0.00000000
66.62000000,1.13631900,3.84000000,0.03731600,380.19199696,0.03663661,394.37924152,0.00080480,0.04855217,428.60472947,-0.02867495,-0.01987723,0.00000000,0.00000000,0.00000000,0.00000000
68.12000000,1.17249200,3.86000000,0.03851533,382.17216361,0.03779213,396.89165188,0.00074586,0.04967729,430.66907752,-0.02936020,-0.02031710,0.00000000,0.00000000,0.00000000,0.00000000
69.62000000,1.20856300,3.87800000,0.03974478,383.95431360,0.03897528,399.21449247,0.00081019,0.05082658,432.43196859,-0.03008660,-0.02073998,0.00000000,0.00000000,0.00000000,0.00000000
71.12000000,1.24470200,3.89800000,0.04093289,385.93448025,0.04011732,401.73189344,0.00078770,0.05190518,434.58962228,-0.03072577,-0.02117941,0.00000000,0.00000000,0.00000000,0.00000000
72.62000000,1.28124700,3.91600000,0.04213978,387.71663023,0.04127608,404.05492287,0.00075777,0.05303612,436.45762316,-0.03144013,-0.02159599,0.00000000,0.00000000,0.00000000,0.00000000
74.12000000,1.31704800,3.93200000,0.04333533,389.30076355,0.04242263,406.17124191,0.00071365,0.05414669,438.42616652,-0.03210841,-0.02203829,0.00000000,0.00000000,0.00000000,0.00000000
75.62000000,1.35332200,3.95000000,0.04454222,391.08291354,0.04357872,408.50261558,0.00072709,0.05525735,440.29279799,-0.03278992,-0.02246742,0.00000000,0.00000000,0.00000000,0.00000000
77.12000000,1.38942700,3.96800000,0.04574533,392.86506352,0.04472987,410.83680681,0.00071902,0.05638631,442.27728610,-0.03350530,-0.02288101,0.00000000,0.00000000,0.00000000,0.00000000
78.62000000,1.42604000,3.98400000,0.04696356,394.44919684,0.04589412,412.97393361,0.00073284,0.05752027,444.05575460,-0.03418740,-0.02333287,0.00000000,0.00000000,0.00000000,0.00000000
80.12000000,1.46238100,4.00100000,0.04817422,396.13233850,0.04704981,415.21570580,0.00069615,0.05864296,446.04524157,-0.03488726,-0.02375570,0.00000000,0.00000000,0.00000000,0.00000000
81.62000000,1.49858800,4.01800000,0.04938478,397.81548015,0.04820407,417.46150923,0.00073813,0.05975461,447.71460580,-0.03554334,-0.02421126,0.00000000,0.00000000,0.00000000,0.00000000
83.12000000,1.53479500,4.03300000,0.05056911,399.30060514,0.04933203,419.49288181,0.00073011,0.06088447,449.50195176,-0.03625168,-0.02463279,0.00000000,0.00000000,0.00000000,0.00000000
84.62000000,1.57174600,4.04900000,0.05180233,400.88473846,0.05050520,421.65150331,0.00073644,0.06199750,451.39184301,-0.03690609,-0.02509141,0.00000000,0.00000000,0.00000000,0.00000000
86.12000000,1.60734300,4.06400000,0.05300544,402.36986345,0.05164840,423.69765689,0.00078563,0.06312257,453.07744927,-0.03758007,-0.02554250,0.00000000,0.00000000,0.00000000,0.00000000
87.62000000,1.64399000,4.07900000,0.05420856,403.85498844,0.05279030,425.74738401,0.00074910,0.06428521,454.99732068,-0.03831016,-0.02597504,0.00000000,0.00000000,0.00000000,0.00000000
89.12000000,1.68036500,4.09500000,0.05541544,405.43912176,0.05393448,427.90671088,0.00074824,0.06541945,456.58703753,-0.03898576,-0.02643368,0.00000000,0.00000000,0.00000000,0.00000000
90.62000000,1.71711300,4.11000000,0.05665622,406.92424674,0.05510941,429.97903730,0.00079007,0.06654595,458.39055916,-0.03968069,-0.02686526,0.00000000,0.00000000,0.00000000,0.00000000
92.12000000,1.75359100,4.12300000,0.05785556,408.21135507,0.05624380,431.82864980,0.00074651,0.06768782,459.99022623,-0.04037566,-0.02731216,0.00000000,0.00000000,0.00000000,0.00000000
93.62000000,1.78983100,4.13700000,0.05907378,409.59747172,0.05739473,433.79394175,0.00082395,0.06882049,461.91093334,-0.04106723,-0.02775327,0.00000000,0.00000000,0.00000000,0.00000000
95.12000000,1.82634200,4.15200000,0.06026933,411.08259671,0.05852296,435.85827076,0.00080163,0.06995070,463.40425792,-0.04173916,-0.02821154,0.00000000,0.00000000,0.00000000,0.00000000
96.62000000,1.86275200,4.16500000,0.06148744,412.36970503,0.05967117,437.72526436,0.00079338,0.07108892,465.22712036,-0.04242218,-0.02866674,0.00000000,0.00000000,0.00000000,0.00000000
98.12000000,1.89980400,4.17900000,0.06272444,413.75582169,0.06083584,439.70842574,0.00077844,0.07220263,466.71877708,-0.04309792,-0.02910471,0.00000000,0.00000000,0.00000000,0.00000000
99.62000000,1.93624800,4.19200000,0.06396144,415.04293001,0.06199915,441.58967532,0.00082706,0.07334648,468.44324773,-0.04379722,-0.02954926,0.00000000,0.00000000,0.00000000,0.00000000
101.12000000,1.97306400,4.20400000,0.06514956,416.23103000,0.06311522,443.34829662,0.00076269,0.07448502,469.95255334,-0.04448140,-0.03000361,0.00000000,0.00000000,0.00000000,0.00000000
102.62000000,2.01001500,4.21700000,0.06640900,417.51813833,0.06429693,445.24510037,0.00083204,0.07562764,471.57484788,-0.04519816,-0.03042949,0.00000000,0.00000000,0.00000000,0.00000000
104.12000000,2.04669500,4.23100000,0.06762344,418.90425498,0.06543510,447.23200360,0.00078903,0.07673590,473.07565196,-0.04585506,-0.03088084,0.00000000,0.00000000,0.00000000,0.00000000
105.62000000,2.08347700,4.24200000,0.06884533,419.99334664,0.06657894,448.90792859,0.00077399,0.07792088,474.94116057,-0.04659731,-0.03132357,0.00000000,0.00000000,0.00000000,0.00000000
107.12000000,2.12036000,4.25400000,0.07004856,421.18144663,0.06770403,450.68459859,0.00075213,0.07906371,476.24756202,-0.04727655,-0.03178716,0.00000000,0.00000000,0.00000000,0.00000000
108.62000000,2.15754800,4.26700000,0.07129678,422.46855495,0.06886986,452.58920163,0.00078633,0.08021101,477.88454528,-0.04796886,-0.03224215,0.00000000,0.00000000,0.00000000,0.00000000
110.12000000,2.19497300,4.27800000,0.07251489,423.55764661,0.07000625,454.27188229,0.00076429,0.08133098,479.40273223,-0.04865626,-0.03267472,0.00000000,0.00000000,0.00000000,0.00000000
111.62000000,2.23263500,4.29100000,0.07378944,424.84475493,0.07119393,456.19381338,0.00079837,0.08252682,481.06944791,-0.04939290,-0.03313392,0.00000000,0.00000000,0.00000000,0.00000000
113.12000000,2.26951800,4.30000000,0.07505656,425.73582993,0.07237327,457.69009490,0.00082555,0.08363531,482.47897276,-0.05005371,-0.03358161,0.00000000,0.00000000,0.00000000,0.00000000
114.62000000,2.30677400,4.31200000,0.07628600,426.92392992,0.07351623,459.49224884,0.00078268,0.08478332,483.91032664,-0.05075955,-0.03402376,0.00000000,0.00000000,0.00000000,0.00000000
116.12000000,2.34443500,4.32400000,0.07752667,428.11202991,0.07466829,461.30212855,0.00074671,0.08596267,485.46902689,-0.05148843,-0.03447425,0.00000000,0.00000000,0.00000000,0.00000000
117.62000000,2.38152200,4.33400000,0.07879000,429.10211323,0.07584004,462.91106874,0.00076685,0.08711811,486.90961173,-0.05221091,-0.03490720,0.00000000,0.00000000,0.00000000,0.00000000
119.12000000,2.41904800,4.34400000,0.08004200,430.09219656,0.07699993,464.51763616,0.00081474,0.08824845,488.34059276,-0.05287023,-0.03537822,0.00000000,0.00000000,0.00000000,0.00000000
120.62000000,2.45704800,4.35600000,0.08127144,431.28029655,0.07813761,466.33106921,0.00077208,0.08938269,489.88587205,-0.05356854,-0.03581415,0.00000000,0.00000000,0.00000000,0.00000000
122.12000000,2.49514900,4.36500000,0.08254222,432.17137154,0.07931218,467.84375693,0.00075023,0.09055394,491.12287039,-0.05428509,-0.03626885,0.00000000,0.00000000,0.00000000,0.00000000
123.62000000,2.53267600,4.37600000,0.08380933,433.26046320,0.08048200,469.57173378,0.00077725,0.09169029,492.56478175,-0.05497164,-0.03671865,0.00000000,0.00000000,0.00000000,0.00000000
125.12000000,2.57050700,4.38500000,0.08503878,434.15153819,0.08161573,471.07125437,0.00079726,0.09281849,494.00533317,-0.05563354,-0.03718496,0.00000000,0.00000000,0.00000000,0.00000000
126.62000000,2.60796500,4.39500000,0.08630200,435.14162152,0.08277927,472.69521374,0.00076155,0.09402797,495.37886199,-0.05637574,-0.03765222,0.00000000,0.00000000,0.00000000,0.00000000
128.12000000,2.64586400,4.40500000,0.08756911,436.13170484,0.08394503,474.32337056,0.00074001,0.09518369,496.83852999,-0.05708422,-0.03809947,0.00000000,0.00000000,0.00000000,0.00000000
129.62000000,2.68430400,4.41400000,0.08884733,437.02277984,0.08511964,475.85108843,0.00082877,0.09633441,498.07744821,-0.05776865,-0.03856575,0.00000000,0.00000000,0.00000000,0.00000000
131.12000000,2.72237100,4.42300000,0.09008433,437.91385483,0.08625506,477.36303250,0.00074504,0.09752442,499.55962786,-0.05851121,-0.03901321,0.00000000,0.00000000,0.00000000,0.00000000
132.62000000,2.76030400,4.43200000,0.09137400,438.80492982,0.08743745,478.90029148,0.00076493,0.09870251,500.81712783,-0.05923401,-0.03946850,0.00000000,0.00000000,0.00000000,0.00000000
134.12000000,2.79830400,4.44100000,0.09266356,439.69600482,0.08861834,480.43979999,0.00082608,0.09988580,502.07956420,-0.05995949,-0.03992631,0.00000000,0.00000000,0.00000000,0.00000000
135.62000000,2.83694700,4.45000000,0.09391178,440.58707981,0.08976006,481.96339574,0.00077007,0.10102928,503.43519036,-0.06063351,-0.04039577,0.00000000,0.00000000,0.00000000,0.00000000
137.12000000,2.87484500,4.45800000,0.09522400,441.37914647,0.09095891,483.40903431,0.00076224,0.10220306,504.69753664,-0.06133328,-0.04086978,0.00000000,0.00000000,0.00000000,0.00000000
138.62000000,2.91348800,4.46700000,0.09652856,442.27022146,0.09214933,484.96192710,0.00089150,0.10339734,506.08393999,-0.06206136,-0.04133598,0.00000000,0.00000000,0.00000000,0.00000000
140.12000000,2.95196200,4.47500000,0.09775433,443.06228812,0.09326658,486.37354672,0.00078803,0.10456822,507.34958707,-0.06274641,-0.04182181,0.00000000,0.00000000,0.00000000,0.00000000
141.62000000,2.99067300,4.48400000,0.09903267,443.95336312,0.09443040,487.91924854,0.00073917,0.10574763,508.62191094,-0.06347671,-0.04227092,0.00000000,0.00000000,0.00000000,0.00000000
143.12000000,3.02945100,4.49200000,0.10037111,444.74542978,0.09564750,489.38502272,0.00075868,0.10693228,509.89926311,-0.06419487,-0.04273741,0.00000000,0.00000000,0.00000000,0.00000000
144.62000000,3.06785700,4.49900000,0.10165689,445.43848810,0.09681531,490.72037900,0.00082600,0.10811547,511.17821447,-0.06495332,-0.04316215,0.00000000,0.00000000,0.00000000,0.00000000
146.12000000,3.10619500,4.50600000,0.10292400,446.13154643,0.09796483,492.04918972,0.00077063,0.10929018,512.23117530,-0.06563345,-0.04365673,0.00000000,0.00000000,0.00000000,0.00000000
147.62000000,3.14477100,4.51400000,0.10423611,446.92361309,0.09915379,493.50919248,0.00077635,0.11046239,513.62099451,-0.06634873,-0.04411365,0.00000000,0.00000000,0.00000000,0.00000000
149.12000000,3.18395500,4.52100000,0.10551444,447.61667142,0.10031079,494.84669583,0.00074831,0.11162940,514.78621454,-0.06705211,-0.04457729,0.00000000,0.00000000,0.00000000,0.00000000
150.62000000,3.22259800,4.52900000,0.10683411,448.40873808,0.10150379,496.31408703,0.00080868,0.11283999,516.08852031,-0.06774547,-0.04509452,0.00000000,0.00000000,0.00000000,0.00000000
152.12000000,3.26201900,4.53600000,0.10812000,449.10179641,0.10266489,497.65868263,0.00070582,0.11405861,517.17238548,-0.06852262,-0.04553599,0.00000000,0.00000000,0.00000000,0.00000000
153.62000000,3.30120400,4.54300000,0.10945100,449.79485473,0.10386530,499.02535138,0.00074585,0.11526756,518.36577302,-0.06927063,-0.04599692,0.00000000,0.00000000,0.00000000,0.00000000
155.12000000,3.34113300,4.55000000,0.11077433,450.48791306,0.10505737,500.39041131,0.00081922,0.11643539,519.53981534,-0.06996289,-0.04647249,0.00000000,0.00000000,0.00000000,0.00000000
156.62000000,3.38018100,4.55600000,0.11209778,451.08196306,0.10624812,501.64724871,0.00076407,0.11763662,520.84638936,-0.07068431,-0.04695231,0.00000000,0.00000000,0.00000000,0.00000000
158.12000000,3.41970400,4.56200000,0.11343256,451.67601305,0.10744764,502.91077750,0.00086458,0.11882615,521.92306621,-0.07141807,-0.04740808,0.00000000,0.00000000,0.00000000,0.00000000
159.62000000,3.45946400,4.56900000,0.11474100,452.36907138,0.10862209,504.27435100,0.00083664,0.12001930,523.11672973,-0.07214427,-0.04787503,0.00000000,0.00000000,0.00000000,0.00000000
161.12000000,3.49905400,4.57600000,0.11603811,453.06212971,0.10978501,505.63460346,0.00080201,0.12123549,524.21133224,-0.07287384,-0.04836165,0.00000000,0.00000000,0.00000000,0.00000000
162.62000000,3.53861100,4.58200000,0.11740289,453.65617970,0.11100714,506.91672576,0.00080779,0.12244864,525.41974523,-0.07362630,-0.04882234,0.00000000,0.00000000,0.00000000,0.00000000
164.12000000,3.57840400,4.58700000,0.11875633,454.15122137,0.11221765,508.08455520,0.00085371,0.12366168,526.51665056,-0.07434723,-0.04931445,0.00000000,0.00000000,0.00000000,0.00000000
165.62000000,3.61880700,4.59400000,0.12008356,454.84427969,0.11340329,509.46359802,0.00085270,0.12486825,527.49824271,-0.07509573,-0.04977252,0.00000000,0.00000000,0.00000000,0.00000000
167.12000000,3.65870200,4.59900000,0.12146344,455.33932136,0.11463448,510.64640372,0.00088535,0.12607355,528.70864264,-0.07581089,-0.05026266,0.00000000,0.00000000,0.00000000,0.00000000
168.62000000,3.69866400,4.60500000,0.12281322,455.93337135,0.11583734,511.92801781,0.00087082,0.12726913,529.80197086,-0.07651186,-0.05075727,0.00000000,0.00000000,0.00000000,0.00000000
170.12000000,3.73839000,4.61000000,0.12412533,456.42841302,0.11700525,513.08274192,0.00080948,0.12852834,530.93121332,-0.07728433,-0.05124402,0.00000000,0.00000000,0.00000000,0.00000000
171.62000000,3.77916500,4.61600000,0.12547889,457.02246301,0.11820862,514.36913387,0.00080871,0.12973378,532.03367095,-0.07801709,-0.05171669,0.00000000,0.00000000,0.00000000,0.00000000
173.12000000,3.81943200,4.62200000,0.12683233,457.61651301,0.11941045,515.65708312,0.00077420,0.13091504,533.12506007,-0.07870312,-0.05221192,0.00000000,0.00000000,0.00000000,0.00000000
174.62000000,3.86037600,4.62600000,0.12825733,458.01254634,0.12067426,516.75601416,0.00083332,0.13221654,534.16836500,-0.07951399,-0.05270255,0.00000000,0.00000000,0.00000000,0.00000000
176.12000000,3.90094700,4.63100000,0.12958833,458.50758800,0.12185326,517.92482215,0.00083233,0.13344346,535.28809634,-0.08024212,-0.05320134,0.00000000,0.00000000,0.00000000,0.00000000
177.62000000,3.94145100,4.63700000,0.13092678,459.10163799,0.12303745,519.21033613,0.00075154,0.13463791,536.27732630,-0.08092749,-0.05371042,0.00000000,0.00000000,0.00000000,0.00000000
179.12000000,3.98209100,4.64200000,0.13232544,459.59667966,0.12427343,520.41301456,0.00075729,0.13590853,537.30939338,-0.08170350,-0.05420502,0.00000000,0.00000000,0.00000000,0.00000000
180.62000000,4.02300100,4.64700000,0.13369400,460.09172132,0.12548133,521.60322391,0.00078285,0.13713393,538.43395154,-0.08245125,-0.05468268,0.00000000,0.00000000,0.00000000,0.00000000
182.12000000,4.06391100,4.65200000,0.13503622,460.58676298,0.12666456,522.78265946,0.00074882,0.13836580,539.44863580,-0.08318291,-0.05518289,0.00000000,0.00000000,0.00000000,0.00000000
183.62000000,4.10468600,4.65500000,0.13646111,460.88378798,0.12791915,523.77650178,0.00082710,0.13965735,540.49751334,-0.08399720,-0.05566015,0.00000000,0.00000000,0.00000000,0.00000000
185.12000000,4.14556200,4.66000000,0.13783344,461.37882964,0.12912597,524.97226293,0.00083939,0.14087634,541.50863788,-0.08471510,-0.05616124,0.00000000,0.00000000,0.00000000,0.00000000
186.62000000,4.18758900,4.66500000,0.13922456,461.87387131,0.13034782,526.17805576,0.00075914,0.14213891,542.54526998,-0.08548987,-0.05664904,0.00000000,0.00000000,0.00000000,0.00000000
188.12000000,4.22897300,4.66900000,0.14067211,462.26990464,0.13161766,527.29838802,0.00087044,0.14338685,543.57566547,-0.08622781,-0.05715904,0.00000000,0.00000000,0.00000000,0.00000000
189.62000000,4.27015300,4.67200000,0.14201811,462.56692963,0.13279697,528.25981124,0.00082989,0.14466695,544.50934049,-0.08703359,-0.05763336,0.00000000,0.00000000,0.00000000,0.00000000
191.12000000,4.31150400,4.67700000,0.14340544,463.06197130,0.13401104,529.46757909,0.00072351,0.14587967,545.52376759,-0.08774376,-0.05813591,0.00000000,0.00000000,0.00000000,0.00000000
192.62000000,4.35342900,4.68100000,0.14486044,463.45800463,0.13528275,530.59473716,0.00088026,0.14718688,546.59191032,-0.08858440,-0.05860248,0.00000000,0.00000000,0.00000000,0.00000000
194.12000000,4.39565900,4.68500000,0.14627044,463.85403796,0.13651358,531.70217424,0.00082022,0.14842992,547.50996341,-0.08929753,-0.05913238,0.00000000,0.00000000,0.00000000,0.00000000
195.62000000,4.43721200,4.68800000,0.14770667,464.15106295,0.13776575,532.70926929,0.00079943,0.14973371,548.57976265,-0.09011549,-0.05961822,0.00000000,0.00000000,0.00000000,0.00000000
197.12000000,4.47974600,4.69200000,0.14917300,464.54709628,0.13904255,533.84498028,0.00090985,0.15097360,549.49918929,-0.09086940,-0.06010419,0.00000000,0.00000000,0.00000000,0.00000000
198.62000000,4.52207700,4.69600000,0.15057533,464.94312961,0.14026211,534.95209634,0.00090197,0.15227546,550.45443881,-0.09164438,-0.06063108,0.00000000,0.00000000,0.00000000,0.00000000
200.12000000,4.56481500,4.69900000,0.15198522,465.24015461,0.14148673,535.94978290,0.00078334,0.15357568,551.41035095,-0.09240820,-0.06116748,0.00000000,0.00000000,0.00000000,0.00000000
201.62000000,4.60677400,4.70200000,0.15344411,465.53717961,0.14275235,536.97111832,0.00078910,0.15487417,552.36687359,-0.09321134,-0.06166284,0.00000000,0.00000000,0.00000000,0.00000000
203.12000000,4.64944300,4.70500000,0.15486900,465.83420461,0.14398692,537.97748204,0.00082046,0.15616927,553.44056655,-0.09397208,-0.06219719,0.00000000,0.00000000,0.00000000,0.00000000
204.62000000,4.69262100,4.70900000,0.15630900,466.23023794,0.14523304,539.10622020,0.00073504,0.15746589,554.28169819,-0.09477106,-0.06269483,0.00000000,0.00000000,0.00000000,0.00000000
206.12000000,4.73576400,4.71200000,0.15779411,466.52726293,0.14651657,540.14251770,0.00087696,0.15878920,555.37463158,-0.09556428,-0.06322492,0.00000000,0.00000000,0.00000000,0.00000000
207.62000000,4.77853500,4.71500000,0.15924544,466.82428793,0.14776931,541.16392914,0.00086301,0.16011388,556.23434840,-0.09635431,-0.06375957,0.00000000,0.00000000,0.00000000,0.00000000
209.12000000,4.82279500,4.71800000,0.16073056,467.12131293,0.14904960,542.20198107,0.00090730,0.16143518,557.21161158,-0.09714175,-0.06429343,0.00000000,0.00000000,0.00000000,0.00000000
210.62000000,4.86539700,4.72100000,0.16215922,467.41833793,0.15027967,543.21453206,0.00077648,0.16278772,558.08978698,-0.09795248,-0.06483524,0.00000000,0.00000000,0.00000000,0.00000000
212.12000000,4.90931900,4.72400000,0.16366311,467.71536292,0.15157288,544.26311434,0.00084024,0.16410542,559.06815201,-0.09876617,-0.06533925,0.00000000,0.00000000,0.00000000,0.00000000
213.62000000,4.95300400,4.72600000,0.16512944,467.91337959,0.15283219,545.17965601,0.00077450,0.16551547,560.10026996,-0.09963947,-0.06587601,0.00000000,0.00000000,0.00000000,0.00000000
215.12000000,4.99662100,4.72800000,0.16659578,468.11139626,0.15408992,546.09677840,0.00083813,0.16686239,560.97972961,-0.10043967,-0.06642272,0.00000000,0.00000000,0.00000000,0.00000000
216.62000000,5.04105000,4.73200000,0.16813722,468.50742959,0.15541036,547.28096739,0.00083683,0.16827007,561.89496008,-0.10132382,-0.06694626,0.00000000,0.00000000,0.00000000,0.00000000
218.12000000,5.08504000,4.73400000,0.16967878,468.70544625,0.15672916,548.23481351,0.00096460,0.16958040,562.87556604,-0.10209927,-0.06748112,0.00000000,0.00000000,0.00000000,0.00000000
219.62000000,5.13007800,4.73600000,0.17110756,468.90346292,0.15794993,549.13638825,0.00077074,0.17101704,563.69101288,-0.10299402,-0.06802303,0.00000000,0.00000000,0.00000000,0.00000000
221.12000000,5.17393200,4.73800000,0.17268656,469.10147958,0.15929732,550.10899830,0.00089786,0.17241878,564.60724099,-0.10384787,-0.06857090,0.00000000,0.00000000,0.00000000,0.00000000
222.62000000,5.21886900,4.74000000,0.17422811,469.29949625,0.16061101,551.06466102,0.00089668,0.17381851,565.52380411,-0.10469788,-0.06912063,0.00000000,0.00000000,0.00000000,0.00000000
224.12000000,5.26329800,4.74300000,0.17573200,469.59652124,0.16189093,552.11965711,0.00083162,0.17521464,566.55957754,-0.10553562,-0.06967902,0.00000000,0.00000000,0.00000000,0.00000000
225.62000000,5.30881000,4.74600000,0.17723589,469.89354624,0.16316922,553.17554659,0.00083037,0.17667246,567.51248106,-0.10641899,-0.07025348,0.00000000,0.00000000,0.00000000,0.00000000
227.12000000,5.35378100,4.74600000,0.17885267,469.89354624,0.16454165,553.93526004,0.00089335,0.17809870,568.32873166,-0.10726605,-0.07083265,0.00000000,0.00000000,0.00000000,0.00000000
228.62000000,5.39939400,4.74800000,0.18039411,470.09156291,0.16584838,554.89331254,0.00089199,0.17955386,569.16275990,-0.10812025,-0.07143361,0.00000000,0.00000000,0.00000000,0.00000000
230.12000000,5.44524500,4.75100000,0.18193567,470.38858790,0.16715349,555.96904924,0.00082725,0.18100688,569.99678814,-0.10901262,-0.07199425,0.00000000,0.00000000,0.00000000,0.00000000
231.62000000,5.49119700,4.75200000,0.18359000,470.48759624,0.16855219,556.86441403,0.00088977,0.18245452,571.07030906,-0.10986663,-0.07258789,0.00000000,0.00000000,0.00000000,0.00000000
233.12000000,5.53731800,4.75400000,0.18513144,470.68561290,0.16985369,557.82432030,0.00082502,0.18393402,571.92241985,-0.11079473,-0.07313929,0.00000000,0.00000000,0.00000000,0.00000000
234.62000000,5.58330400,4.75500000,0.18671056,470.78462123,0.17118524,558.68507941,0.00082392,0.18541130,572.77453065,-0.11166228,-0.07374902,0.00000000,0.00000000,0.00000000,0.00000000
236.12000000,5.62973000,4.75600000,0.18836489,470.88362957,0.17257832,559.58157213,0.00088601,0.18688646,573.62669390,-0.11259259,-0.07429387,0.00000000,0.00000000,0.00000000,0.00000000
237.62000000,5.67646000,4.75900000,0.18998156,471.18065456,0.17393781,560.69628827,0.00088480,0.18838995,574.49653733,-0.11352868,-0.07486127,0.00000000,0.00000000,0.00000000,0.00000000
239.12000000,5.72369800,4.76000000,0.19171111,471.27966290,0.17539018,561.62921071,0.00100982,0.00000000,0.00000000,0.00000000,0.00000000,0.00000000,0.00000000,0.00000000,0.00000000
240.62000000,5.77130800,4.76100000,0.19332778,471.37867123,0.17674586,562.50926223,0.00094548,0.00000000,0.00000000,0.00000000,0.00000000,0.00000000,0.00000000,0.00000000,0.00000000
242.12000000,5.81895200,4.76200000,0.19501967,471.47767956,0.17816264,563.42509947,0.00094414,0.00000000,0.00000000,0.00000000,0.00000000,0.00000000,0.00000000,0.00000000,0.00000000
243.62000000,5.86696800,4.76300000,0.19671156,471.57668789,0.17957742,564.34127173,0.00094281,0.00000000,0.00000000,0.00000000,0.00000000,0.00000000,0.00000000,0.00000000,0.00000000
245.12000000,5.91417200,4.76400000,0.19844111,471.67569623,0.18102164,565.27554547,0.00094144,0.00000000,0.00000000,0.00000000,0.00000000,0.00000000,0.00000000,0.00000000,0.00000000
246.62000000,5.96266200,4.76500000,0.20009533,471.77470456,0.18240100,566.17462133,0.00093996,0.00000000,0.00000000,0.00000000,0.00000000,0.00000000,0.00000000,0.00000000,0.00000000
248.12000000,6.01135500,4.76600000,0.20182489,471.87371289,0.18384114,567.10957257,0.00087608,0.00000000,0.00000000,0.00000000,0.00000000,0.00000000,0.00000000,0.00000000,0.00000000
249.62000000,6.06082600,4.76700000,0.20359200,471.97272122,0.18531042,568.06259148,0.00099985,0.00000000,0.00000000,0.00000000,0.00000000,0.00000000,0.00000000,0.00000000,0.00000000
251.12000000,6.10985700,4.76700000,0.20535911,471.97272122,0.18677754,568.89661972,0.00093604,0.00000000,0.00000000,0.00000000,0.00000000,0.00000000,0.00000000,0.00000000,0.00000000
252.62000000,6.15919300,4.76800000,0.20712611,472.07172956,0.18824242,569.85011107,0.00099692,0.00000000,0.00000000,0.00000000,0.00000000,0.00000000,0.00000000,0.00000000,0.00000000
254.12000000,6.20934100,4.76800000,0.20889322,472.07172956,0.18970525,570.68431426,0.00099546,0.00000000,0.00000000,0.00000000,0.00000000,0.00000000,0.00000000,0.00000000,0.00000000
255.62000000,6.25965800,4.76900000,0.21066033,472.17073789,0.19116594,571.63838292,0.00099401,0.00000000,0.00000000,0.00000000,0.00000000,0.00000000,0.00000000,0.00000000,0.00000000
257.12000000,6.31011000,4.76900000,0.21246500,472.17073789,0.19265548,572.49049371,0.00093037,0.00000000,0.00000000,0.00000000,0.00000000,0.00000000,0.00000000,0.00000000,0.00000000
258.62000000,6.36096900,4.76900000,0.21426978,472.17073789,0.19414289,573.34265697,0.00099106,0.00000000,0.00000000,0.00000000,0.00000000,0.00000000,0.00000000,0.00000000,0.00000000
260.12000000,6.41169200,4.76900000,0.21611200,472.17073789,0.19565888,574.21250040,0.00105135,0.00000000,0.00000000,0.00000000,0.00000000,0.00000000,0.00000000,0.00000000,0.00000000
261.62000000,6.46353200,4.77000000,0.21791667,472.26974622,0.19714175,575.18519509,0.00104979,0.00000000,0.00000000,0.00000000,0.00000000,0.00000000,0.00000000,0.00000000,0.00000000
263.12000000,6.51587900,4.76900000,0.21972144,472.17073789,0.00000000,0.00000000,0.00000000,0.00000000,0.00000000,0.00000000,0.00000000,0.00000000,0.00000000,0.00000000,0.00000000
264.62000000,6.56853100,4.76800000,0.22152611,472.07172956,0.00000000,0.00000000,0.00000000,0.00000000,0.00000000,0.00000000,0.00000000,0.00000000,0.00000000,0.00000000,0.00000000
266.12000000,6.62128500,4.76700000,0.22333078,471.97272122,0.00000000,0.00000000,0.00000000,0.00000000,0.00000000,0.00000000,0.00000000,0.00000000,0.00000000,0.00000000,0.00000000
267.62000000,6.67410600,4.76700000,0.22509789,471.97272122,0.00000000,0.00000000,0.00000000,0.00000000,0.00000000,0.00000000,0.00000000,0.00000000,0.00000000,0.00000000,0.00000000
269.12000000,6.72797600,4.76600000,0.22678978,471.87371289,0.00000000,0.00000000,0.00000000,0.00000000,0.00000000,0.00000000,0.00000000,0.00000000,0.00000000,0.00000000,0.00000000
270.62000000,6.78232000,4.76400000,0.22851933,471.67569623,0.00000000,0.00000000,0.00000000,0.00000000,0.00000000,0.00000000,0.00000000,0.00000000,0.00000000,0.00000000,0.00000000
272.12000000,6.83663000,4.76200000,0.23009844,471.47767956,0.00000000,0.00000000,0.00000000,0.00000000,0.00000000,0.00000000,0.00000000,0.00000000,0.00000000,0.00000000,0.00000000
273.62000000,6.89185300,4.76000000,0.23163989,471.27966290,0.00000000,0.00000000,0.00000000,0.00000000,0.00000000,0.00000000,0.00000000,0.00000000,0.00000000,0.00000000,0.00000000
275.12000000,6.94704300,4.75800000,0.23306867,471.08164623,0.00000000,0.00000000,0.00000000,0.00000000,0.00000000,0.00000000,0.00000000,0.00000000,0.00000000,0.00000000,0.00000000
276.62000000,7.00321400,4.75500000,0.23442211,470.78462123,0.00000000,0.00000000,0.00000000,0.00000000,0.00000000,0.00000000,0.00000000,0.00000000,0.00000000,0.00000000,0.00000000
278.12000000,7.05955400,4.75100000,0.23566289,470.38858790,0.00000000,0.00000000,0.00000000,0.00000000,0.00000000,0.00000000,0.00000000,0.00000000,0.00000000,0.00000000,0.00000000
279.62000000,7.11691000,4.74700000,0.23671567,469.99255457,0.00000000,0.00000000,0.00000000,0.00000000,0.00000000,0.00000000,0.00000000,0.00000000,0.00000000,0.00000000,0.00000000
281.12000000,7.17480700,4.74100000,0.23773078,469.39850458,0.00000000,0.00000000,0.00000000,0.00000000,0.00000000,0.00000000,0.00000000,0.00000000,0.00000000,0.00000000,0.00000000
282.62000000,7.23388800,4.73400000,0.23855800,468.70544625,0.00000000,0.00000000,0.00000000,0.00000000,0.00000000,0.00000000,0.00000000,0.00000000,0.00000000,0.00000000,0.00000000
284.12000000,7.29317200,4.72400000,0.23923478,467.71536292,0.00000000,0.00000000,0.00000000,0.00000000,0.00000000,0.00000000,0.00000000,0.00000000,0.00000000,0.00000000,0.00000000
285.62000000,7.35299800,4.71200000,0.23976122,466.52726293,0.00000000,0.00000000,0.00000000,0.00000000,0.00000000,0.00000000,0.00000000,0.00000000,0.00000000,0.00000000,0.00000000
286.62000000,7.39536400,4.70200000,0.24002467,465.53717961,0.00000000,0.00000000,0.00000000,0.00000000,0.00000000,0.00000000,0.00000000,0.00000000,0.00000000,0.00000000,0.00000000