File: lab_data/AA7020-T6_results/DATA/UT_90_1.csv
Time[s],Displacement[mm],Force[kN],EngStrain_longi,EngStress[MPa],TrueStrain,TrueStress[MPa],TrueStrainRate[1/s],PlasticStrain_longi,PlasticStress[MPa],PlasticStrain_thick,PlasticStrain_width,R-Value,Thickness[mm],Width[mm], Young's Modulus [MPa]
0.60000000,0.00000000,-0.00900000,0.00000000,-0.88841507,0.00000000,-0.88841507,0.00000000,0.00054932,271.21881071,0.00038710,-0.00093642,0.60949041,1.00800000,10.05000000,78199.91603545
2.10000000,0.00511800,0.00600000,0.00014289,0.59227671,0.00014288,0.59236134,0.00015465,0.00112868,283.72313213,0.00004412,-0.00117280,0.00000000,0.00000000,0.00000000,0.00000000
3.60000000,0.01238500,0.30500000,0.00036900,30.10739951,0.00036893,30.11850914,0.00005642,0.00198419,292.14087492,-0.00056616,-0.00141803,0.00000000,0.00000000,0.00000000,0.00000000
5.10000000,0.02029500,0.50500000,0.00066133,49.84995657,0.00066111,49.88292400,0.00009661,0.00295427,301.00857880,-0.00122467,-0.00172960,0.00000000,0.00000000,0.00000000,0.00000000
6.60000000,0.02882000,0.73300000,0.00099189,72.35647161,0.00099140,72.42824119,0.00035057,0.00385449,307.27556977,-0.00174915,-0.00210534,0.00000000,0.00000000,0.00000000,0.00000000
8.10000000,0.03655500,0.94900000,0.00121667,93.67843323,0.00121593,93.79240866,0.00045306,0.00477084,313.75981205,-0.00229638,-0.00247445,0.00000000,0.00000000,0.00000000,0.00000000
9.60000000,0.04518700,1.18200000,0.00141500,116.67851220,0.00141400,116.84361230,0.00026986,0.00584497,319.20588299,-0.00297784,-0.00286712,0.00000000,0.00000000,0.00000000,0.00000000
11.10000000,0.05405000,1.39900000,0.00163156,138.09918661,0.00163023,138.32450310,0.00002219,0.00691263,324.56171813,-0.00362685,-0.00328578,0.00000000,0.00000000,0.00000000,0.00000000
12.60000000,0.06262300,1.63000000,0.00190700,160.90184001,0.00190518,161.20867982,-0.00013795,0.00797374,328.72251573,-0.00426460,-0.00370914,0.00000000,0.00000000,0.00000000,0.00000000
14.10000000,0.07096400,1.82600000,0.00229022,180.24954592,0.00228760,180.66235744,-0.00000044,0.00901414,333.48837634,-0.00491763,-0.00409650,0.00000000,0.00000000,0.00000000,0.00000000
15.60000000,0.08065800,2.06600000,0.00262700,203.94061439,0.00262356,204.47636638,0.00019638,0.01016777,337.49780114,-0.00568336,-0.00448441,0.00000000,0.00000000,0.00000000,0.00000000
17.10000000,0.09100600,2.25300000,0.00295511,222.39990524,0.00295075,223.05712167,0.00036961,0.01131145,341.31152859,-0.00641826,-0.00489319,0.00000000,0.00000000,0.00000000,0.00000000
18.60000000,0.10217900,2.46000000,0.00329600,242.83345179,0.00329058,243.63383085,0.00040316,0.01240194,345.11549651,-0.00711430,-0.00528763,0.00000000,0.00000000,0.00000000,0.00000000
20.10000000,0.11797500,2.63300000,0.00381367,259.91076364,0.00380641,260.90197666,0.00037549,0.01351926,348.53313666,-0.00787427,-0.00564499,0.00000000,0.00000000,0.00000000,0.00000000
21.60000000,0.13865300,2.78500000,0.00454967,274.91510700,0.00453935,276.16587910,0.00064982,0.01467369,352.07255515,-0.00862178,-0.00605191,0.00000000,0.00000000,0.00000000,0.00000000
23.10000000,0.16557200,2.88300000,0.00543867,284.58895996,0.00542393,286.13674445,0.00092231,0.01577857,355.09606083,-0.00930559,-0.00647298,0.00000000,0.00000000,0.00000000,0.00000000
24.60000000,0.19516400,2.97900000,0.00634644,294.06538735,0.00632639,295.93165699,0.00078871,0.01689028,358.63538853,-0.01006324,-0.00682704,0.00000000,0.00000000,0.00000000,0.00000000
26.10000000,0.22504000,3.04400000,0.00737222,300.48171839,0.00734518,302.69693639,0.00064645,0.01802448,361.48019335,-0.01074481,-0.00727967,0.00000000,0.00000000,0.00000000,0.00000000
27.60000000,0.25558100,3.11100000,0.00847411,307.09547501,0.00843841,309.69783618,0.00086310,0.01914370,364.52896321,-0.01147829,-0.00766541,0.00000000,0.00000000,0.00000000,0.00000000
29.10000000,0.28920700,3.16700000,0.00955767,312.62339098,0.00951228,315.61134114,0.00100289,0.02029186,367.49330629,-0.01220554,-0.00808631,0.00000000,0.00000000,0.00000000,0.00000000
30.60000000,0.32109200,3.22000000,0.01057833,317.85516860,0.01052277,321.21754653,0.00072843,0.02140213,370.45011056,-0.01290906,-0.00849307,0.00000000,0.00000000,0.00000000,0.00000000
32.10000000,0.35559100,3.26100000,0.01177211,321.90239280,0.01170336,325.69186353,0.00080952,0.02249509,372.99883370,-0.01356301,-0.00893208,0.00000000,0.00000000,0.00000000,0.00000000
33.60000000,0.39067300,3.30700000,0.01296267,326.44318092,0.01287937,330.67475506,0.00092687,0.02360509,376.06981567,-0.01421704,-0.00938805,0.00000000,0.00000000,0.00000000,0.00000000
35.10000000,0.42498100,3.34200000,0.01408567,329.89812841,0.01398739,334.54496348,0.00093330,0.02473599,378.54200981,-0.01487404,-0.00986195,0.00000000,0.00000000,0.00000000,0.00000000
36.60000000,0.46092300,3.37700000,0.01522422,333.35307589,0.01510950,338.42811720,0.00076188,0.02586768,381.42918509,-0.01555475,-0.01031293,0.00000000,0.00000000,0.00000000,0.00000000
38.10000000,0.49619300,3.41500000,0.01644578,337.10416173,0.01631201,342.64810186,0.00077649,0.02698878,383.90865119,-0.01623695,-0.01075183,0.00000000,0.00000000,0.00000000,0.00000000
39.60000000,0.53152800,3.44400000,0.01764444,339.96683250,0.01749059,345.96535839,0.00084986,0.02812400,386.60404380,-0.01695398,-0.01117002,0.00000000,0.00000000,0.00000000,0.00000000
41.10000000,0.56720800,3.47800000,0.01877200,343.32306720,0.01859798,349.76792782,0.00073763,0.02924014,388.98963753,-0.01765825,-0.01158188,0.00000000,0.00000000,0.00000000,0.00000000
42.60000000,0.60291800,3.50500000,0.02000089,345.98831241,0.01980350,352.90838620,0.00074415,0.03032772,391.78033894,-0.01833972,-0.01198800,0.00000000,0.00000000,0.00000000,0.00000000
44.10000000,0.63881400,3.53600000,0.02119644,349.04840875,0.02097492,356.44699395,0.00079552,0.03148181,394.08843595,-0.01910619,-0.01237563,0.00000000,0.00000000,0.00000000,0.00000000
45.60000000,0.67460200,3.56100000,0.02235811,351.51622838,0.02211183,359.37546727,0.00075026,0.03259965,396.59320093,-0.01977707,-0.01282259,0.00000000,0.00000000,0.00000000,0.00000000
47.10000000,0.71046100,3.58800000,0.02354589,354.18147358,0.02327296,362.52099121,0.00072723,0.03371420,398.99871508,-0.02051678,-0.01319742,0.00000000,0.00000000,0.00000000,0.00000000
48.60000000,0.74608200,3.61100000,0.02474911,356.45186765,0.02444781,365.27373452,0.00075610,0.03480782,401.50414040,-0.02119770,-0.01361012,0.00000000,0.00000000,0.00000000,0.00000000
50.10000000,0.78221100,3.63900000,0.02594800,359.21582563,0.02561706,368.53675788,0.00071816,0.03594502,403.61863656,-0.02192246,-0.01402256,0.00000000,0.00000000,0.00000000,0.00000000
51.60000000,0.81759800,3.66000000,0.02713600,361.28879412,0.02677435,371.09272684,0.00073227,0.03705541,406.24446699,-0.02265336,-0.01440205,0.00000000,0.00000000,0.00000000,0.00000000
53.10000000,0.85298900,3.68600000,0.02830889,363.85532654,0.02791560,374.15566655,0.00075997,0.03816875,408.35856037,-0.02334873,-0.01482003,0.00000000,0.00000000,0.00000000,0.00000000
54.60000000,0.88898200,3.70700000,0.02948178,365.92829503,0.02905555,376.71651171,0.00073686,0.03925629,410.67395246,-0.02404265,-0.01521364,0.00000000,0.00000000,0.00000000,0.00000000
56.10000000,0.92481000,3.73100000,0.03071122,368.29740188,0.03024907,379.60826523,0.00079529,0.04040070,412.91372245,-0.02476494,-0.01563576,0.00000000,0.00000000,0.00000000,0.00000000
57.60000000,0.96056900,3.75000000,0.03192933,370.17294480,0.03143019,381.99232015,0.00081611,0.04150000,415.24344697,-0.02544966,-0.01605034,0.00000000,0.00000000,0.00000000,0.00000000
59.10000000,0.99673900,3.77400000,0.03310222,372.54205165,0.03256614,384.87402143,0.00077882,0.04260186,417.26647433,-0.02608097,-0.01652089,0.00000000,0.00000000,0.00000000,0.00000000
60.60000000,1.03240200,3.79300000,0.03428311,374.41759457,0.03370854,387.25379456,0.00072033,0.04374446,419.62365994,-0.02678075,-0.01696371,0.00000000,0.00000000,0.00000000,0.00000000
62.10000000,1.06836800,3.81700000,0.03549689,376.78670141,0.03488140,390.16145709,0.00076929,0.04485433,421.65866817,-0.02749476,-0.01735957,0.00000000,0.00000000,0.00000000,0.00000000
63.60000000,1.10419300,3.83500000,0.03670733,378.56353155,0.03604967,392.45958929,0.00085524,0.04591855,423.78287728,-0.02809772,-0.01782083,0.00000000,0.00000000,0.00000000,0.00000000
65.10000000,1.13998800,3.85500000,0.03788078,380.53778725,0.03718092,394.95285461,0.00074717,0.04701175,425.81900379,-0.02876433,-0.01824742,0.00000000,0.00000000,0.00000000,0.00000000
66.60000000,1.17568800,3.87300000,0.03907244,382.31461739,0.03832843,397.25258404,0.00073883,0.04815164,427.98407179,-0.02950213,-0.01864951,0.00000000,0.00000000,0.00000000,0.00000000
68.10000000,1.21189600,3.89400000,0.04029822,384.38758588,0.03950742,399.87772224,0.00080271,0.04929618,429.94582721,-0.03024006,-0.01905612,0.00000000,0.00000000,0.00000000,0.00000000
69.60000000,1.24796000,3.91100000,0.04145622,386.06570323,0.04061995,402.07052882,0.00077279,0.05036965,432.09080817,-0.03088752,-0.01948213,0.00000000,0.00000000,0.00000000,0.00000000
71.10000000,1.28365000,3.93200000,0.04261389,388.13867172,0.04173091,404.67876995,0.00066319,0.05152036,433.95828143,-0.03166290,-0.01985745,0.00000000,0.00000000,0.00000000,0.00000000
72.60000000,1.31924600,3.94800000,0.04385111,389.71807629,0.04291687,406.80764695,0.00074333,0.05262633,436.12580796,-0.03236384,-0.02026249,0.00000000,0.00000000,0.00000000,0.00000000
74.10000000,1.35531300,3.96700000,0.04505789,391.59361921,0.04407228,409.23800099,0.00077033,0.05373189,437.98132573,-0.03305804,-0.02067385,0.00000000,0.00000000,0.00000000,0.00000000
75.60000000,1.39131700,3.98200000,0.04621978,393.07431098,0.04518346,411.24211829,0.00075503,0.05484721,440.05588465,-0.03374908,-0.02109813,0.00000000,0.00000000,0.00000000,0.00000000
77.10000000,1.42697700,4.00200000,0.04742678,395.04856669,0.04633647,413.78444727,0.00071171,0.05596555,441.81902594,-0.03444611,-0.02151943,0.00000000,0.00000000,0.00000000,0.00000000
78.60000000,1.46314500,4.01700000,0.04866756,396.52925847,0.04752036,415.82736819,0.00081792,0.05704997,443.88782204,-0.03508457,-0.02196540,0.00000000,0.00000000,0.00000000,0.00000000
80.10000000,1.49894500,4.03600000,0.04984422,398.40480139,0.04864179,418.26297884,0.00080240,0.05821322,445.78426886,-0.03586095,-0.02235227,0.00000000,0.00000000,0.00000000,0.00000000
81.60000000,1.53531200,4.05000000,0.05102489,399.78678038,0.04976577,420.18585643,0.00070145,0.05932256,447.66034510,-0.03654993,-0.02277264,0.00000000,0.00000000,0.00000000,0.00000000
83.10000000,1.57097300,4.06700000,0.05223167,401.46489773,0.05091331,422.43407845,0.00072177,0.06042849,449.43243900,-0.03721506,-0.02321343,0.00000000,0.00000000,0.00000000,0.00000000
84.60000000,1.60667500,4.08000000,0.05343456,402.74816394,0.05205583,424.26883308,0.00082098,0.06154211,451.31774538,-0.03789669,-0.02364542,0.00000000,0.00000000,0.00000000,0.00000000
86.10000000,1.64281000,4.09800000,0.05463033,404.52499408,0.05319031,426.62432935,0.00084850,0.06267881,453.21731927,-0.03860321,-0.02407560,0.00000000,0.00000000,0.00000000,0.00000000
87.60000000,1.67904700,4.11200000,0.05582600,405.90697307,0.05432340,428.56713575,0.00077637,0.06378786,455.00153968,-0.03929716,-0.02449070,0.00000000,0.00000000,0.00000000,0.00000000
89.10000000,1.71572500,4.12900000,0.05707033,407.58509042,0.05550125,430.84610739,0.00078997,0.06491070,456.68893984,-0.04001117,-0.02489953,0.00000000,0.00000000,0.00000000,0.00000000
90.60000000,1.75159600,4.14100000,0.05824344,408.76964384,0.05661041,432.57779589,0.00080338,0.06604811,458.49312540,-0.04072921,-0.02531890,0.00000000,0.00000000,0.00000000,0.00000000
92.10000000,1.78800200,4.15700000,0.05946544,410.34904841,0.05776448,434.75063695,0.00075965,0.06718096,460.29879461,-0.04144046,-0.02574050,0.00000000,0.00000000,0.00000000,0.00000000
93.60000000,1.82413600,4.17000000,0.06066089,411.63231462,0.05889219,436.60229672,0.00074454,0.06828445,462.09440238,-0.04214863,-0.02613582,0.00000000,0.00000000,0.00000000,0.00000000
95.10000000,1.86013300,4.18600000,0.06184522,413.21171918,0.06000817,438.76688978,0.00071524,0.06938449,463.78474414,-0.04282739,-0.02655710,0.00000000,0.00000000,0.00000000,0.00000000
96.60000000,1.89650800,4.19800000,0.06305178,414.39627261,0.06114381,440.52469430,0.00069979,0.07055225,465.51004550,-0.04358697,-0.02696528,0.00000000,0.00000000,0.00000000,0.00000000
98.10000000,1.93254600,4.21300000,0.06428922,415.87696438,0.06230718,442.61337096,0.00074221,0.07166179,467.10405015,-0.04421784,-0.02744395,0.00000000,0.00000000,0.00000000,0.00000000
99.60000000,1.96922200,4.22500000,0.06551844,417.06151781,0.06346148,444.38673969,0.00082606,0.07277520,468.81043438,-0.04493362,-0.02784159,0.00000000,0.00000000,0.00000000,0.00000000
101.10000000,2.00627300,4.23900000,0.06671400,418.44349680,0.06458290,446.35953625,0.00069113,0.07392317,470.42883210,-0.04560545,-0.02831773,0.00000000,0.00000000,0.00000000,0.00000000
102.60000000,2.04278100,4.25100000,0.06796222,419.62805023,0.06575237,448.14690503,0.00076068,0.07507206,472.15860955,-0.04633455,-0.02873751,0.00000000,0.00000000,0.00000000,0.00000000
104.10000000,2.07935700,4.26500000,0.06916533,421.01002922,0.06687828,450.12932823,0.00075275,0.07616204,473.75582060,-0.04700093,-0.02916111,0.00000000,0.00000000,0.00000000,0.00000000
105.60000000,2.11563100,4.27600000,0.07037211,422.09586986,0.06800636,451.79964731,0.00073072,0.07731258,475.38499749,-0.04770821,-0.02960437,0.00000000,0.00000000,0.00000000,0.00000000
107.10000000,2.15271500,4.29000000,0.07162400,423.47784885,0.06917525,453.80902630,0.00074377,0.07847726,476.91599564,-0.04843671,-0.03004054,0.00000000,0.00000000,0.00000000,0.00000000
108.60000000,2.18946000,4.30100000,0.07289467,424.56368949,0.07036029,455.51211811,0.00084752,0.07958530,478.42270289,-0.04912482,-0.03046048,0.00000000,0.00000000,0.00000000,0.00000000
110.10000000,2.22613700,4.31400000,0.07407922,425.84695570,0.07146376,457.39336696,0.00076318,0.08069433,480.04110737,-0.04980717,-0.03088716,0.00000000,0.00000000,0.00000000,0.00000000
111.60000000,2.26338700,4.32500000,0.07531956,426.93279634,0.07261788,459.08918481,0.00074782,0.08181903,481.67017762,-0.05051366,-0.03130536,0.00000000,0.00000000,0.00000000,0.00000000
113.10000000,2.29993100,4.33700000,0.07660556,428.11734976,0.07381309,460.91351718,0.00082375,0.08294353,483.19362000,-0.05120810,-0.03173544,0.00000000,0.00000000,0.00000000,0.00000000
114.60000000,2.33729100,4.34700000,0.07784656,429.10447761,0.07496512,462.50878317,0.00087230,0.08407376,484.72272961,-0.05192279,-0.03215097,0.00000000,0.00000000,0.00000000,0.00000000
116.10000000,2.37420100,4.35900000,0.07901933,430.28903104,0.07605260,464.29018341,0.00080151,0.08519090,486.13942048,-0.05262389,-0.03256701,0.00000000,0.00000000,0.00000000,0.00000000
117.60000000,2.41115100,4.36900000,0.08027889,431.27615889,0.07721924,465.89852973,0.00075262,0.08635585,487.69123683,-0.05334498,-0.03301088,0.00000000,0.00000000,0.00000000,0.00000000
119.10000000,2.44860300,4.38200000,0.08152667,432.55942510,0.07837362,467.82455316,0.00079924,0.08746639,489.11009755,-0.05403450,-0.03343189,0.00000000,0.00000000,0.00000000,0.00000000
120.60000000,2.48582200,4.39100000,0.08275633,433.44784016,0.07950995,469.31839411,0.00079894,0.08861977,490.55272112,-0.05476910,-0.03385068,0.00000000,0.00000000,0.00000000,0.00000000
122.10000000,2.52281200,4.40200000,0.08395567,434.53368080,0.08061700,471.01524566,0.00067337,0.08974674,492.09441740,-0.05547979,-0.03426694,0.00000000,0.00000000,0.00000000,0.00000000
123.60000000,2.55992300,4.41100000,0.08522600,435.42209587,0.08178826,472.53137941,0.00067135,0.09088927,493.64676617,-0.05622275,-0.03466652,0.00000000,0.00000000,0.00000000,0.00000000
125.10000000,2.59761400,4.42200000,0.08650433,436.50793651,0.08296551,474.26776455,0.00080273,0.09205046,494.99200302,-0.05693194,-0.03511852,0.00000000,0.00000000,0.00000000,0.00000000
126.60000000,2.63483400,4.43100000,0.08771867,437.39635158,0.08408254,475.76417634,0.00069168,0.09322141,496.23479203,-0.05765764,-0.03556377,0.00000000,0.00000000,0.00000000,0.00000000
128.10000000,2.67252700,4.44200000,0.08897044,438.48219221,0.08523270,477.49414774,0.00062127,0.09434098,497.67402570,-0.05835345,-0.03598753,0.00000000,0.00000000,0.00000000,0.00000000
129.60000000,2.71004800,4.45100000,0.09023744,439.37060728,0.08639551,479.01828805,0.00069008,0.09549959,499.13552662,-0.05907538,-0.03642421,0.00000000,0.00000000,0.00000000,0.00000000
131.10000000,2.74740500,4.46100000,0.09151578,440.35773513,0.08756735,480.65741577,0.00077196,0.09668037,500.61097501,-0.05983794,-0.03684243,0.00000000,0.00000000,0.00000000,0.00000000
132.60000000,2.78560200,4.46900000,0.09277111,441.14743742,0.08871677,482.07317535,0.00077738,0.09778423,501.94004185,-0.06048329,-0.03730094,0.00000000,0.00000000,0.00000000,0.00000000
134.10000000,2.82322500,4.47900000,0.09402667,442.13456527,0.08986508,483.70700466,0.00078380,0.09893684,503.29618551,-0.06120272,-0.03773412,0.00000000,0.00000000,0.00000000,0.00000000
135.60000000,2.86074700,4.48700000,0.09530489,442.92426755,0.09103276,485.13711566,0.00081739,0.10011484,504.66773140,-0.06195990,-0.03815494,0.00000000,0.00000000,0.00000000,0.00000000
137.10000000,2.89814000,4.49700000,0.09656433,443.91139540,0.09218196,486.77740336,0.00084321,0.10130159,506.04631422,-0.06272579,-0.03857580,0.00000000,0.00000000,0.00000000,0.00000000
138.60000000,2.93644300,4.50500000,0.09783878,444.70109769,0.09334350,488.21010956,0.00079445,0.10241464,507.27898847,-0.06343794,-0.03897671,0.00000000,0.00000000,0.00000000,0.00000000
140.10000000,2.97440300,4.51300000,0.09909067,445.49079997,0.09448317,489.63478033,0.00081437,0.10359873,508.66119265,-0.06419688,-0.03940184,0.00000000,0.00000000,0.00000000,0.00000000
141.60000000,3.01263600,4.52100000,0.10036489,446.28050225,0.09564184,491.07139527,0.00078595,0.10473882,509.91227658,-0.06490765,-0.03983117,0.00000000,0.00000000,0.00000000,0.00000000
143.10000000,3.05076400,4.53000000,0.10165056,447.16891732,0.09680956,492.62388619,0.00082580,0.10590642,511.29102105,-0.06560904,-0.04029738,0.00000000,0.00000000,0.00000000,0.00000000
144.60000000,3.08933500,4.53800000,0.10290989,447.95861960,0.09795204,494.05799137,0.00078374,0.10708257,512.45394140,-0.06632669,-0.04075588,0.00000000,0.00000000,0.00000000,0.00000000
146.10000000,3.12801300,4.54500000,0.10419956,448.64960910,0.09912069,495.39869897,0.00076229,0.10826532,513.73387915,-0.06707848,-0.04118684,0.00000000,0.00000000,0.00000000,0.00000000
147.60000000,3.16651600,4.55200000,0.10553044,449.34059859,0.10032526,496.75971167,0.00079596,0.10941546,515.11092421,-0.06781526,-0.04160020,0.00000000,0.00000000,0.00000000,0.00000000
149.10000000,3.20457900,4.55900000,0.10677456,450.03158809,0.10144998,498.08351090,0.00076734,0.11057044,516.26941516,-0.06850102,-0.04206942,0.00000000,0.00000000,0.00000000,0.00000000
150.60000000,3.24355800,4.56800000,0.10808689,450.92000316,0.10263500,499.65854344,0.00078068,0.11172780,517.65504061,-0.06921738,-0.04251042,0.00000000,0.00000000,0.00000000,0.00000000
152.10000000,3.28237400,4.57500000,0.10938389,451.61099266,0.10380481,501.00995930,0.00071885,0.11285661,518.80417219,-0.06990393,-0.04295268,0.00000000,0.00000000,0.00000000,0.00000000
153.60000000,3.32105000,4.58300000,0.11072600,452.40069494,0.10501386,502.49321429,0.00089331,0.11406537,519.88492614,-0.07064703,-0.04341834,0.00000000,0.00000000,0.00000000,0.00000000
155.10000000,3.35966000,4.58900000,0.11196300,452.99297165,0.10612692,503.71142373,0.00077756,0.11524627,521.17763493,-0.07136583,-0.04388045,0.00000000,0.00000000,0.00000000,0.00000000
156.60000000,3.39887700,4.59500000,0.11329422,453.58524836,0.10732339,504.97383629,0.00077742,0.11639910,522.45793967,-0.07202508,-0.04437402,0.00000000,0.00000000,0.00000000,0.00000000
158.10000000,3.43778800,4.60200000,0.11465111,454.27623786,0.10854145,506.35951328,0.00080280,0.11760834,523.65768519,-0.07279852,-0.04480982,0.00000000,0.00000000,0.00000000,0.00000000
159.60000000,3.47676900,4.61000000,0.11592211,455.06594014,0.10968107,507.81814462,0.00082261,0.11880133,524.73825720,-0.07352893,-0.04527240,0.00000000,0.00000000,0.00000000,0.00000000
161.10000000,3.51575300,4.61600000,0.11723789,455.65821685,0.11085947,509.07862425,0.00077388,0.11997311,526.03523919,-0.07424346,-0.04572965,0.00000000,0.00000000,0.00000000,0.00000000
162.60000000,3.55527500,4.62300000,0.11851233,456.34920635,0.11199953,510.43221561,0.00074001,0.12113808,527.21793888,-0.07494933,-0.04618875,0.00000000,0.00000000,0.00000000,0.00000000
164.10000000,3.59499500,4.62900000,0.11986578,456.94148306,0.11320884,511.71312933,0.00078616,0.12235608,528.31776712,-0.07571246,-0.04664362,0.00000000,0.00000000,0.00000000,0.00000000
165.60000000,3.63448500,4.63400000,0.12116278,457.43504699,0.11436634,512.85914793,0.00071744,0.12353172,529.51024106,-0.07645815,-0.04707358,0.00000000,0.00000000,0.00000000,0.00000000
167.10000000,3.67370200,4.64100000,0.12251656,458.12603648,0.11557309,514.25406048,0.00073083,0.12471865,530.48396444,-0.07719418,-0.04752446,0.00000000,0.00000000,0.00000000,0.00000000
168.60000000,3.71356300,4.64600000,0.12382856,458.61960041,0.11674121,515.40980308,0.00072958,0.12591277,531.80387783,-0.07793594,-0.04797684,0.00000000,0.00000000,0.00000000,0.00000000
170.10000000,3.75328400,4.65200000,0.12518933,459.21187712,0.11795132,516.70030588,0.00080852,0.12713902,532.80230215,-0.07871075,-0.04842827,0.00000000,0.00000000,0.00000000,0.00000000
171.60000000,3.79247000,4.65800000,0.12648278,459.80415383,0.11910019,517.96146044,0.00075411,0.12828089,533.87089031,-0.07939098,-0.04888992,0.00000000,0.00000000,0.00000000,0.00000000
173.10000000,3.83229600,4.66300000,0.12782478,460.29771776,0.12029080,519.13517124,0.00084665,0.12948328,534.97386059,-0.08014568,-0.04933760,0.00000000,0.00000000,0.00000000,0.00000000
174.60000000,3.87147700,4.66900000,0.12919356,460.88999447,0.12150371,520.43401158,0.00082574,0.13069572,536.19830262,-0.08087935,-0.04981637,0.00000000,0.00000000,0.00000000,0.00000000
176.10000000,3.91266000,4.67400000,0.13056600,461.38355840,0.12271839,521.62456408,0.00085836,0.13188397,537.41187482,-0.08158013,-0.05030384,0.00000000,0.00000000,0.00000000,0.00000000
177.60000000,3.95254700,4.67900000,0.13192311,461.87712232,0.12391805,522.80938925,0.00091743,0.13306539,538.28064792,-0.08228181,-0.05078358,0.00000000,0.00000000,0.00000000,0.00000000
179.10000000,3.99261300,4.68400000,0.13323122,462.37068625,0.12507304,523.97289790,0.00077650,0.13432331,539.42141455,-0.08304995,-0.05127336,0.00000000,0.00000000,0.00000000,0.00000000
180.60000000,4.03288000,4.68900000,0.13459978,462.86425018,0.12627997,525.16567539,0.00077517,0.13551170,540.52637247,-0.08382710,-0.05168460,0.00000000,0.00000000,0.00000000,0.00000000
182.10000000,4.07273700,4.69400000,0.13597956,463.35781410,0.12749532,526.36500373,0.00082726,0.13670551,541.63617775,-0.08451977,-0.05218574,0.00000000,0.00000000,0.00000000,0.00000000
183.60000000,4.11367400,4.69800000,0.13732533,463.75266525,0.12867931,527.43765458,0.00083332,0.13794737,542.65917002,-0.08529790,-0.05264946,0.00000000,0.00000000,0.00000000,0.00000000
185.10000000,4.15424700,4.70400000,0.13869778,464.34494196,0.12988531,528.74855353,0.00077960,0.13914582,543.66011684,-0.08605804,-0.05308778,0.00000000,0.00000000,0.00000000,0.00000000
186.60000000,4.19460900,4.70800000,0.14009267,464.73979310,0.13110955,529.84643002,0.00084455,0.14033134,544.77088822,-0.08680128,-0.05353007,0.00000000,0.00000000,0.00000000,0.00000000
188.10000000,4.23619600,4.71200000,0.14142700,465.13464424,0.13227923,530.91724157,0.00078377,0.14155241,545.78768696,-0.08753199,-0.05402042,0.00000000,0.00000000,0.00000000,0.00000000
189.60000000,4.27761300,4.71600000,0.14275433,465.52949538,0.13344143,531.98584814,0.00068423,0.14283326,546.83911001,-0.08837917,-0.05445409,0.00000000,0.00000000,0.00000000,0.00000000
191.10000000,4.31821300,4.72100000,0.14423556,466.02305931,0.13473678,533.24015417,0.00079545,0.14398407,547.82058556,-0.08905103,-0.05493305,0.00000000,0.00000000,0.00000000,0.00000000
192.60000000,4.35932300,4.72500000,0.14559256,466.41791045,0.13592202,534.32488599,0.00085331,0.14526162,548.87369327,-0.08987427,-0.05538735,0.00000000,0.00000000,0.00000000,0.00000000
194.10000000,4.40066900,4.73000000,0.14695378,466.91147437,0.13710954,535.52587942,0.00079376,0.14653759,549.92774408,-0.09062990,-0.05590769,0.00000000,0.00000000,0.00000000,0.00000000
195.60000000,4.44218900,4.73300000,0.14838633,467.20761273,0.13835777,536.53483729,0.00083226,0.14778114,550.84947053,-0.09142182,-0.05635933,0.00000000,0.00000000,0.00000000,0.00000000
197.10000000,4.48347100,4.73700000,0.14980000,467.60246387,0.13958801,537.64931296,0.00088344,0.14898987,551.86958994,-0.09213631,-0.05685356,0.00000000,0.00000000,0.00000000,0.00000000
198.60000000,4.52539300,4.74100000,0.15113789,467.99731501,0.14075092,538.72944121,0.00082293,0.15026085,552.92607860,-0.09293619,-0.05732466,0.00000000,0.00000000,0.00000000,0.00000000
200.10000000,4.56687600,4.74500000,0.15255544,468.39216615,0.14198160,539.84794124,0.00073763,0.15149995,553.84998862,-0.09372513,-0.05777481,0.00000000,0.00000000,0.00000000,0.00000000
201.60000000,4.60869900,4.74800000,0.15401411,468.68830451,0.14324640,540.87291712,0.00086056,0.15276747,554.90799409,-0.09447945,-0.05828802,0.00000000,0.00000000,0.00000000,0.00000000
203.10000000,4.65062200,4.75200000,0.15538644,469.08315565,0.14443487,541.97231936,0.00081990,0.15403500,555.85092290,-0.09527899,-0.05875602,0.00000000,0.00000000,0.00000000,0.00000000
204.60000000,4.69258300,4.75500000,0.15678133,469.37929401,0.14564144,542.96920556,0.00072167,0.15527079,556.66051225,-0.09604341,-0.05922738,0.00000000,0.00000000,0.00000000,0.00000000
206.10000000,4.73473900,4.75900000,0.15823233,469.77414515,0.14689499,544.10760427,0.00080484,0.15653388,557.72099610,-0.09681524,-0.05971863,0.00000000,0.00000000,0.00000000,0.00000000
207.60000000,4.77760800,4.76200000,0.15969100,470.07028350,0.14815359,545.13627715,0.00092096,0.15785823,558.81778741,-0.09763133,-0.06022690,0.00000000,0.00000000,0.00000000,0.00000000
209.10000000,4.81966900,4.76500000,0.16107800,470.36642186,0.14934888,546.13210436,0.00084192,0.15915080,559.78109453,-0.09840998,-0.06074083,0.00000000,0.00000000,0.00000000,0.00000000
210.60000000,4.86240600,4.76800000,0.16258222,470.66256021,0.15064358,547.18392517,0.00084122,0.16041155,560.61033342,-0.09918429,-0.06122726,0.00000000,0.00000000,0.00000000,0.00000000
212.10000000,4.90483800,4.77000000,0.16401067,470.85998579,0.15187151,548.08604596,0.00096892,0.16176387,561.61041505,-0.10005311,-0.06171076,0.00000000,0.00000000,0.00000000,0.00000000
213.60000000,4.94770800,4.77400000,0.16543956,471.25483693,0.15309832,549.21902770,0.00083896,0.16308122,562.71035418,-0.10086402,-0.06221720,0.00000000,0.00000000,0.00000000,0.00000000
215.10000000,4.99040900,4.77600000,0.16690567,471.45226250,0.15435552,550.14031667,0.00077294,0.16439996,563.57674689,-0.10169929,-0.06270067,0.00000000,0.00000000,0.00000000,0.00000000
216.60000000,5.03392300,4.77900000,0.16837200,471.74840085,0.15561133,551.17762260,0.00077254,0.16571664,564.44329315,-0.10247937,-0.06323727,0.00000000,0.00000000,0.00000000,0.00000000
218.10000000,5.07696700,4.78100000,0.16983844,471.94582642,0.15686566,552.10037145,0.00083619,0.16702866,565.54541447,-0.10328974,-0.06373891,0.00000000,0.00000000,0.00000000,0.00000000
219.60000000,5.12081900,4.78500000,0.17130433,472.34067756,0.15811794,553.25468244,0.00077023,0.16837334,566.43089328,-0.10411562,-0.06425772,0.00000000,0.00000000,0.00000000,0.00000000
221.10000000,5.16450100,4.78700000,0.17284578,472.53810314,0.15943308,554.21431910,0.00089735,0.16974570,567.45235673,-0.10495840,-0.06478730,0.00000000,0.00000000,0.00000000,0.00000000
222.60000000,5.20777800,4.78900000,0.17431200,472.73552871,0.16068244,555.13900419,0.00083243,0.17108657,568.33858436,-0.10577242,-0.06531415,0.00000000,0.00000000,0.00000000,0.00000000
224.10000000,5.25132600,4.79100000,0.17581567,472.93295428,0.16196209,556.08197692,0.00083118,0.17248803,569.26094466,-0.10667010,-0.06581793,0.00000000,0.00000000,0.00000000,0.00000000
225.60000000,5.29562100,4.79400000,0.17735733,473.22909263,0.16327238,557.15974256,0.00095831,0.17385605,570.16557000,-0.10751603,-0.06634002,0.00000000,0.00000000,0.00000000,0.00000000
227.10000000,5.33964600,4.79600000,0.17886133,473.42651820,0.16454900,558.10421648,0.00095671,0.17525214,571.20723260,-0.10838151,-0.06687064,0.00000000,0.00000000,0.00000000,0.00000000
228.60000000,5.38448100,4.79900000,0.18044056,473.72265656,0.16588772,559.20143589,0.00095580,0.17664757,572.13070538,-0.10923852,-0.06740905,0.00000000,0.00000000,0.00000000,0.00000000
230.10000000,5.42928200,4.80000000,0.18194467,473.82136934,0.16716110,560.03064045,0.00089139,0.17804235,572.93548725,-0.11010007,-0.06794228,0.00000000,0.00000000,0.00000000,0.00000000
231.60000000,5.47384600,4.80200000,0.18348589,474.01879491,0.16846423,560.99455485,0.00095372,0.17949419,574.01435242,-0.11097765,-0.06851655,0.00000000,0.00000000,0.00000000,0.00000000
233.10000000,5.51942400,4.80400000,0.18502722,474.21622048,0.16976575,561.95913049,0.00082509,0.18097617,574.99247428,-0.11188461,-0.06909156,0.00000000,0.00000000,0.00000000,0.00000000
234.60000000,5.56487000,4.80600000,0.18660611,474.41364606,0.17109722,562.94213160,0.00082362,0.18239599,575.81584854,-0.11274733,-0.06964866,0.00000000,0.00000000,0.00000000,0.00000000
236.10000000,5.61037800,4.80700000,0.18818511,474.51235884,0.17242703,563.80851981,0.00082234,0.18393521,576.83031746,-0.11370576,-0.07022944,0.00000000,0.00000000,0.00000000,0.00000000
237.60000000,5.65558200,4.80900000,0.18976433,474.70978441,0.17375525,564.79277018,0.00082199,0.18544102,577.82711141,-0.11462764,-0.07081339,0.00000000,0.00000000,0.00000000,0.00000000
239.10000000,5.70163600,4.81100000,0.19134333,474.90720998,0.17508152,565.77753856,0.00082072,0.18691432,578.80664262,-0.11551262,-0.07140169,0.00000000,0.00000000,0.00000000,0.00000000
240.60000000,5.74846400,4.81300000,0.19307267,475.10463555,0.17653205,566.83435448,0.00100848,0.18844808,579.70209308,-0.11647235,-0.07197573,0.00000000,0.00000000,0.00000000,0.00000000
242.10000000,5.79523100,4.81400000,0.19468911,475.20334834,0.17788599,567.72026582,0.00094403,0.19003880,580.75353326,-0.11744131,-0.07259749,0.00000000,0.00000000,0.00000000,0.00000000
243.60000000,5.84168600,4.81400000,0.19634356,475.20334834,0.17926987,568.50646336,0.00100610,0.19159841,581.66716987,-0.11836323,-0.07323519,0.00000000,0.00000000,0.00000000,0.00000000
245.10000000,5.88794200,4.81600000,0.19799733,475.40077391,0.18065127,569.52885941,0.00094105,0.19327726,582.65227948,-0.11942621,-0.07385106,0.00000000,0.00000000,0.00000000,0.00000000
246.60000000,5.93514500,4.81800000,0.19965156,475.59819948,0.18203114,570.55211982,0.00094031,0.19492284,583.61949436,-0.12042894,-0.07449390,0.00000000,0.00000000,0.00000000,0.00000000
248.10000000,5.98231600,4.81900000,0.20126833,475.69691226,0.18337794,571.43963697,0.00081356,0.19656603,584.58692102,-0.12141553,-0.07515049,0.00000000,0.00000000,0.00000000,0.00000000
249.60000000,6.03023200,4.82000000,0.20303522,475.79562505,0.18484772,572.39889551,0.00093729,0.19829716,585.60787300,-0.12250692,-0.07579024,0.00000000,0.00000000,0.00000000,0.00000000
251.10000000,6.07807600,4.82100000,0.20476478,475.89433783,0.18628434,573.34073617,0.00099925,0.00000000,0.00000000,0.00000000,0.00000000,0.00000000,0.00000000,0.00000000,0.00000000
252.60000000,6.12608900,4.82300000,0.20656922,476.09176341,0.18778098,574.43766868,0.00105967,0.00000000,0.00000000,0.00000000,0.00000000,0.00000000,0.00000000,0.00000000,0.00000000
254.10000000,6.17478200,4.82300000,0.20833622,476.09176341,0.18924439,575.27892282,0.00099611,0.00000000,0.00000000,0.00000000,0.00000000,0.00000000,0.00000000,0.00000000,0.00000000
255.60000000,6.22344100,4.82300000,0.21017833,476.09176341,0.19076773,576.15593675,0.00118089,0.00000000,0.00000000,0.00000000,0.00000000,0.00000000,0.00000000,0.00000000,0.00000000
257.10000000,6.27196500,4.82400000,0.21186989,476.19047619,0.19216453,577.08089947,0.00086864,0.00000000,0.00000000,0.00000000,0.00000000,0.00000000,0.00000000,0.00000000,0.00000000
258.60000000,6.32139900,4.82600000,0.21378733,476.38790176,0.19374550,578.23360091,0.00099200,0.00000000,0.00000000,0.00000000,0.00000000,0.00000000,0.00000000,0.00000000,0.00000000
260.10000000,6.37076900,4.82600000,0.21562922,476.38790176,0.19526182,579.11105449,0.00105158,0.00000000,0.00000000,0.00000000,0.00000000,0.00000000,0.00000000,0.00000000,0.00000000
261.60000000,6.42037300,4.82600000,0.21750900,476.38790176,0.19680697,580.00655789,0.00105014,0.00000000,0.00000000,0.00000000,0.00000000,0.00000000,0.00000000,0.00000000,0.00000000
263.10000000,6.47041800,4.82700000,0.21950122,476.48661455,0.19844194,581.07600881,0.00111023,0.00000000,0.00000000,0.00000000,0.00000000,0.00000000,0.00000000,0.00000000,0.00000000
264.60000000,6.52059800,4.82700000,0.22145622,476.48661455,0.20004377,582.00754014,0.00116998,0.00000000,0.00000000,0.00000000,0.00000000,0.00000000,0.00000000,0.00000000,0.00000000
266.10000000,6.57151900,4.82700000,0.22341078,476.48661455,0.20164268,582.93885970,0.00098347,0.00000000,0.00000000,0.00000000,0.00000000,0.00000000,0.00000000,0.00000000,0.00000000
267.60000000,6.62237400,4.82700000,0.22551600,476.48661455,0.20336198,583.94196991,0.00110478,0.00000000,0.00000000,0.00000000,0.00000000,0.00000000,0.00000000,0.00000000,0.00000000
269.10000000,6.67346200,4.82700000,0.22758367,476.48661455,0.20504774,584.92718540,0.00116378,0.00000000,0.00000000,0.00000000,0.00000000,0.00000000,0.00000000,0.00000000,0.00000000
270.60000000,6.72539900,4.82800000,0.22972633,476.58532733,0.20679165,586.06952710,0.00116175,0.00000000,0.00000000,0.00000000,0.00000000,0.00000000,0.00000000,0.00000000,0.00000000
272.10000000,6.77767600,4.82700000,0.23201967,476.48661455,0.00000000,0.00000000,0.00000000,0.00000000,0.00000000,0.00000000,0.00000000,0.00000000,0.00000000,0.00000000,0.00000000
273.60000000,6.83066000,4.82700000,0.23427478,476.48661455,0.00000000,0.00000000,0.00000000,0.00000000,0.00000000,0.00000000,0.00000000,0.00000000,0.00000000,0.00000000,0.00000000
275.10000000,6.88351500,4.82600000,0.23664333,476.38790176,0.00000000,0.00000000,0.00000000,0.00000000,0.00000000,0.00000000,0.00000000,0.00000000,0.00000000,0.00000000,0.00000000
276.60000000,6.93630200,4.82500000,0.23908700,476.28918898,0.00000000,0.00000000,0.00000000,0.00000000,0.00000000,0.00000000,0.00000000,0.00000000,0.00000000,0.00000000,0.00000000
278.10000000,6.99000000,4.82500000,0.24164289,476.28918898,0.00000000,0.00000000,0.00000000,0.00000000,0.00000000,0.00000000,0.00000000,0.00000000,0.00000000,0.00000000,0.00000000
279.60000000,7.04373700,4.82400000,0.24427422,476.19047619,0.00000000,0.00000000,0.00000000,0.00000000,0.00000000,0.00000000,0.00000000,0.00000000,0.00000000,0.00000000,0.00000000
281.10000000,7.09869100,4.82300000,0.24709367,476.09176341,0.00000000,0.00000000,0.00000000,0.00000000,0.00000000,0.00000000,0.00000000,0.00000000,0.00000000,0.00000000,0.00000000
282.60000000,7.15289800,4.82100000,0.24998800,475.89433783,0.00000000,0.00000000,0.00000000,0.00000000,0.00000000,0.00000000,0.00000000,0.00000000,0.00000000,0.00000000,0.00000000
284.10000000,7.20860100,4.81900000,0.25307056,475.69691226,0.00000000,0.00000000,0.00000000,0.00000000,0.00000000,0.00000000,0.00000000,0.00000000,0.00000000,0.00000000,0.00000000
285.60000000,7.26479800,4.81700000,0.25637844,475.49948669,0.00000000,0.00000000,0.00000000,0.00000000,0.00000000,0.00000000,0.00000000,0.00000000,0.00000000,0.00000000,0.00000000
287.10000000,7.32080000,4.81300000,0.25987411,475.10463555,0.00000000,0.00000000,0.00000000,0.00000000,0.00000000,0.00000000,0.00000000,0.00000000,0.00000000,0.00000000,0.00000000
288.60000000,7.37717600,4.81000000,0.26352011,474.80849720,0.00000000,0.00000000,0.00000000,0.00000000,0.00000000,0.00000000,0.00000000,0.00000000,0.00000000,0.00000000,0.00000000
290.10000000,7.43415900,4.80600000,0.26742867,474.41364606,0.00000000,0.00000000,0.00000000,0.00000000,0.00000000,0.00000000,0.00000000,0.00000000,0.00000000,0.00000000,0.00000000
291.60000000,7.49191700,4.80100000,0.27163778,473.92008213,0.00000000,0.00000000,0.00000000,0.00000000,0.00000000,0.00000000,0.00000000,0.00000000,0.00000000,0.00000000,0.00000000
293.10000000,7.54998200,4.79500000,0.27610956,473.32780542,0.00000000,0.00000000,0.00000000,0.00000000,0.00000000,0.00000000,0.00000000,0.00000000,0.00000000,0.00000000,0.00000000
294.60000000,7.60827900,4.78700000,0.28076833,472.53810314,0.00000000,0.00000000,0.00000000,0.00000000,0.00000000,0.00000000,0.00000000,0.00000000,0.00000000,0.00000000,0.00000000
296.10000000,7.66792100,4.77800000,0.28591444,471.64968807,0.00000000,0.00000000,0.00000000,0.00000000,0.00000000,0.00000000,0.00000000,0.00000000,0.00000000,0.00000000,0.00000000
297.60000000,7.72873000,4.76300000,0.29147156,470.16899629,0.00000000,0.00000000,0.00000000,0.00000000,0.00000000,0.00000000,0.00000000,0.00000000,0.00000000,0.00000000,0.00000000
299.10000000,7.79078300,4.74400000,0.29766411,468.29345337,0.00000000,0.00000000,0.00000000,0.00000000,0.00000000,0.00000000,0.00000000,0.00000000,0.00000000,0.00000000,0.00000000
300.10000000,7.83540500,4.72000000,0.30246756,465.92434652,0.00000000,0.00000000,0.00000000,0.00000000,0.00000000,0.00000000,0.00000000,0.00000000,0.00000000,0.00000000,0.00000000