File: polyN_optimization/results_exp/AA6014-T4/UT_00_1.csv
Time[s],Displacement[mm],Force[kN],EngStrain_longi,EngStress[MPa],TrueStrain,TrueStress[MPa],TrueStrainRate[1/s],PlasticStrain_longi,PlasticStress[MPa],PlasticStrain_thick,PlasticStrain_width,R-Value,Thickness[mm],Width[mm], Young's Modulus [MPa]
0.61000000,0.00000000,-0.00200000,0.00000000,-0.18084899,0.00000000,-0.18084899,0.00000000,0.00082492,120.02355995,-0.00000282,-0.00082210,0.76682736,1.10840000,9.97740000,89157.87697383
2.11000000,0.00476600,0.16900000,0.00011344,15.28173991,0.00011344,15.28347354,0.00007510,0.00164062,125.75668268,-0.00049463,-0.00114599,0.00000000,0.00000000,0.00000000,0.00000000
3.61000000,0.01174000,0.40700000,0.00034733,36.80277007,0.00034727,36.81555290,0.00010663,0.00259454,129.60735623,-0.00111344,-0.00148110,0.00000000,0.00000000,0.00000000,0.00000000
5.11000000,0.02032200,0.64300000,0.00061778,58.14295125,0.00061759,58.17887067,0.00023942,0.00359614,133.10769287,-0.00174799,-0.00184815,0.00000000,0.00000000,0.00000000,0.00000000
6.61000000,0.02916500,0.90900000,0.00092322,82.19586732,0.00092280,82.27175237,0.00035704,0.00462255,135.88911301,-0.00236408,-0.00225846,0.00000000,0.00000000,0.00000000,0.00000000
8.11000000,0.04105400,1.14100000,0.00129856,103.17435050,0.00129771,103.30832813,0.00039486,0.00568637,138.68152281,-0.00298803,-0.00269834,0.00000000,0.00000000,0.00000000,0.00000000
9.61000000,0.06434600,1.29600000,0.00209856,117.19014746,0.00209636,117.43607749,0.00053251,0.00683053,141.39992491,-0.00371084,-0.00311969,0.00000000,0.00000000,0.00000000,0.00000000
11.11000000,0.09671100,1.37200000,0.00309089,124.06240919,0.00308612,124.44587232,0.00053641,0.00795915,143.75626240,-0.00438097,-0.00357817,0.00000000,0.00000000,0.00000000,0.00000000
12.61000000,0.13241300,1.41600000,0.00407056,128.04108704,0.00406229,128.56228540,0.00067404,0.00903809,146.11062583,-0.00502766,-0.00401043,0.00000000,0.00000000,0.00000000,0.00000000
14.11000000,0.16824100,1.45100000,0.00505344,131.20594442,0.00504072,131.86898637,0.00072757,0.01013909,148.56507139,-0.00565211,-0.00448698,0.00000000,0.00000000,0.00000000,0.00000000
15.61000000,0.20482100,1.48400000,0.00608344,134.18995280,0.00606502,135.00628992,0.00065722,0.01130878,150.75978690,-0.00635633,-0.00495246,0.00000000,0.00000000,0.00000000,0.00000000
17.11000000,0.24186500,1.51300000,0.00727267,136.81226320,0.00724635,137.80725319,0.00071934,0.01242922,152.95202177,-0.00698791,-0.00544132,0.00000000,0.00000000,0.00000000,0.00000000
18.61000000,0.27834500,1.54000000,0.00846900,139.25372460,0.00843334,140.43306440,0.00087677,0.01349939,155.23335726,-0.00755451,-0.00594489,0.00000000,0.00000000,0.00000000,0.00000000
20.11000000,0.31416600,1.56700000,0.00960567,141.69518601,0.00955983,143.05626274,0.00092026,0.01462941,157.34466862,-0.00816491,-0.00646451,0.00000000,0.00000000,0.00000000,0.00000000
21.61000000,0.35017600,1.59100000,0.01075867,143.86537393,0.01070120,145.41317353,0.00079208,0.01577751,159.37129394,-0.00885474,-0.00692277,0.00000000,0.00000000,0.00000000,0.00000000
23.11000000,0.38655700,1.61400000,0.01197844,145.94513735,0.01190727,147.69333307,0.00089218,0.01687915,161.48735092,-0.00945014,-0.00742901,0.00000000,0.00000000,0.00000000,0.00000000
24.61000000,0.42132200,1.63900000,0.01317589,148.20574976,0.01308984,150.15849225,0.00095761,0.01796020,163.41965428,-0.01006553,-0.00789467,0.00000000,0.00000000,0.00000000,0.00000000
26.11000000,0.45734500,1.66000000,0.01430989,150.10466418,0.01420847,152.25264525,0.00089013,0.01910910,165.36729770,-0.01074255,-0.00836655,0.00000000,0.00000000,0.00000000,0.00000000
27.61000000,0.49269900,1.68200000,0.01548122,152.09400311,0.01536261,154.44860417,0.00080109,0.02022610,167.40666900,-0.01139113,-0.00883497,0.00000000,0.00000000,0.00000000,0.00000000
29.11000000,0.52784200,1.70400000,0.01665989,154.08334203,0.01652264,156.65035339,0.00079251,0.02129725,169.25709572,-0.01201250,-0.00928475,0.00000000,0.00000000,0.00000000,0.00000000
30.61000000,0.56352300,1.72500000,0.01783867,155.98225646,0.01768142,158.76477194,0.00082108,0.02239980,171.11677897,-0.01263906,-0.00976074,0.00000000,0.00000000,0.00000000,0.00000000
32.11000000,0.59777000,1.74500000,0.01896522,157.79074639,0.01878762,160.78328296,0.00076890,0.02351408,173.07551948,-0.01330094,-0.01021315,0.00000000,0.00000000,0.00000000,0.00000000
33.61000000,0.63261200,1.76600000,0.02011789,159.68966081,0.01991820,162.90227967,0.00070963,0.02464418,174.85502156,-0.01400130,-0.01064288,0.00000000,0.00000000,0.00000000,0.00000000
35.11000000,0.66764700,1.78500000,0.02132278,161.40772625,0.02109863,164.84938732,0.00081110,0.02568381,176.52915486,-0.01455632,-0.01112749,0.00000000,0.00000000,0.00000000,0.00000000
36.61000000,0.70260600,1.80300000,0.02243067,163.03536718,0.02218280,166.69235916,0.00072977,0.02677378,178.40234741,-0.01520117,-0.01157261,0.00000000,0.00000000,0.00000000,0.00000000
38.11000000,0.73691700,1.82300000,0.02356089,164.84385711,0.02328762,168.72772491,0.00067054,0.02786519,180.09286781,-0.01585990,-0.01200528,0.00000000,0.00000000,0.00000000,0.00000000
39.61000000,0.77186500,1.84000000,0.02474711,166.38107355,0.02444586,170.49852447,0.00071358,0.02895651,181.69337372,-0.01647730,-0.01247921,0.00000000,0.00000000,0.00000000,0.00000000
41.11000000,0.80604200,1.85800000,0.02587367,168.00871449,0.02554461,172.35571597,0.00066924,0.03004756,183.48451425,-0.01707120,-0.01297637,0.00000000,0.00000000,0.00000000,0.00000000
42.61000000,0.84176300,1.87700000,0.02707489,169.72677992,0.02671485,174.32211363,0.00079941,0.03112914,185.09013413,-0.01767647,-0.01345267,0.00000000,0.00000000,0.00000000,0.00000000
44.11000000,0.87543500,1.89300000,0.02817522,171.17357187,0.02778560,175.99642529,0.00078385,0.03219864,186.69682701,-0.01829471,-0.01390393,0.00000000,0.00000000,0.00000000,0.00000000
45.61000000,0.91018200,1.90900000,0.02933167,172.62036381,0.02890972,177.68360678,0.00071775,0.03330999,188.31472033,-0.01888277,-0.01442722,0.00000000,0.00000000,0.00000000,0.00000000
47.11000000,0.94445900,1.92700000,0.03046567,174.24800475,0.03001080,179.55658638,0.00070984,0.03436399,189.83104458,-0.01944896,-0.01491503,0.00000000,0.00000000,0.00000000,0.00000000
48.61000000,0.97903800,1.94300000,0.03162944,175.69479669,0.03113954,181.25192550,0.00073059,0.03548485,191.36325007,-0.02010544,-0.01537941,0.00000000,0.00000000,0.00000000,0.00000000
50.11000000,1.01388700,1.95800000,0.03280078,177.05116414,0.03227431,182.85858003,0.00077324,0.03655659,192.98352096,-0.02072846,-0.01582812,0.00000000,0.00000000,0.00000000,0.00000000
51.61000000,1.04766000,1.97400000,0.03392356,178.49795608,0.03336084,184.55324141,0.00072896,0.03764751,194.42204429,-0.02135187,-0.01629563,0.00000000,0.00000000,0.00000000,0.00000000
53.11000000,1.08254100,1.98900000,0.03508733,179.85432353,0.03448580,186.16493213,0.00072084,0.03871940,195.85979957,-0.02193138,-0.01678803,0.00000000,0.00000000,0.00000000,0.00000000
54.61000000,1.11718800,2.00400000,0.03623256,181.21069098,0.03559159,187.77641741,0.00072005,0.03982070,197.40091330,-0.02255149,-0.01726922,0.00000000,0.00000000,0.00000000,0.00000000
56.11000000,1.15183400,2.01900000,0.03737033,182.56705843,0.03668899,189.38965026,0.00069054,0.04088073,198.74756285,-0.02315386,-0.01772687,0.00000000,0.00000000,0.00000000,0.00000000
57.61000000,1.18627900,2.03300000,0.03855278,183.83300138,0.03782818,190.92027423,0.00080470,0.04197382,200.19836754,-0.02382807,-0.01814575,0.00000000,0.00000000,0.00000000,0.00000000
59.11000000,1.22055600,2.04700000,0.03964956,185.09894433,0.03888369,192.43803521,0.00071062,0.04306686,201.55721493,-0.02446152,-0.01860534,0.00000000,0.00000000,0.00000000,0.00000000
60.61000000,1.25510200,2.06100000,0.04081711,186.36488728,0.04000609,193.97176359,0.00069551,0.04413964,203.00977141,-0.02504160,-0.01909804,0.00000000,0.00000000,0.00000000,0.00000000
62.11000000,1.29011700,2.07400000,0.04197722,187.54040573,0.04112008,195.41283102,0.00076643,0.04523508,204.27960957,-0.02567670,-0.01955839,0.00000000,0.00000000,0.00000000,0.00000000
63.61000000,1.32506600,2.08700000,0.04312233,188.71592419,0.04221846,196.85379518,0.00068673,0.04633140,205.64747516,-0.02631926,-0.02001214,0.00000000,0.00000000,0.00000000,0.00000000
65.11000000,1.35930900,2.10100000,0.04428244,189.98186714,0.04332999,198.39472862,0.00072173,0.04742083,206.92134640,-0.02692466,-0.02049617,0.00000000,0.00000000,0.00000000,0.00000000
66.61000000,1.39351900,2.11300000,0.04543511,191.06696110,0.04443317,199.74810970,0.00080663,0.04848427,208.19236932,-0.02748178,-0.02100249,0.00000000,0.00000000,0.00000000,0.00000000
68.11000000,1.42799700,2.12500000,0.04656911,192.15205506,0.04551730,201.10040546,0.00074161,0.04959938,209.47676375,-0.02812776,-0.02147162,0.00000000,0.00000000,0.00000000,0.00000000
69.61000000,1.46321500,2.13800000,0.04772544,193.32757351,0.04662157,202.55421788,0.00075501,0.05066383,210.75310152,-0.02873952,-0.02192430,0.00000000,0.00000000,0.00000000,0.00000000
71.11000000,1.49779400,2.15000000,0.04890789,194.41266747,0.04774952,203.92098061,0.00079675,0.05171658,212.02947954,-0.02929048,-0.02242610,0.00000000,0.00000000,0.00000000,0.00000000
72.61000000,1.53307800,2.16100000,0.05006811,195.40733693,0.04885503,205.19101319,0.00074633,0.05284683,213.22903021,-0.02995427,-0.02289256,0.00000000,0.00000000,0.00000000,0.00000000
74.11000000,1.56819500,2.17300000,0.05123567,196.49243089,0.04996630,206.55985158,0.00080218,0.05393366,214.42172611,-0.03055002,-0.02338363,0.00000000,0.00000000,0.00000000,0.00000000
75.61000000,1.60321000,2.18400000,0.05240322,197.48710035,0.05107633,207.83606075,0.00078714,0.05502970,215.61879433,-0.03115829,-0.02387140,0.00000000,0.00000000,0.00000000,0.00000000
77.11000000,1.63795800,2.19400000,0.05354467,198.39134531,0.05216035,209.01414377,0.00076497,0.05614556,216.82258108,-0.03181352,-0.02433204,0.00000000,0.00000000,0.00000000,0.00000000
78.61000000,1.67250400,2.20600000,0.05469733,199.47643927,0.05325384,210.38726856,0.00074285,0.05719127,217.91715003,-0.03239036,-0.02480092,0.00000000,0.00000000,0.00000000,0.00000000
80.11000000,1.70795700,2.21600000,0.05589100,200.38068424,0.05438496,211.58016106,0.00084791,0.05832210,219.12895213,-0.03307190,-0.02525020,0.00000000,0.00000000,0.00000000,0.00000000
81.61000000,1.74334200,2.22700000,0.05706233,201.37535370,0.05549368,212.86630126,0.00080470,0.05941443,220.23819319,-0.03370114,-0.02571329,0.00000000,0.00000000,0.00000000,0.00000000
83.11000000,1.77879400,2.23700000,0.05822622,202.27959866,0.05659413,214.05757553,0.00076873,0.06050551,221.34935287,-0.03434113,-0.02616438,0.00000000,0.00000000,0.00000000,0.00000000
84.61000000,1.81384400,2.24700000,0.05938267,203.18384363,0.05768635,215.24944209,0.00071144,0.06162326,222.46866358,-0.03496262,-0.02666064,0.00000000,0.00000000,0.00000000,0.00000000
86.11000000,1.84980100,2.25700000,0.06058011,204.08808859,0.05881603,216.45176768,0.00072468,0.06273960,223.58991830,-0.03559743,-0.02714217,0.00000000,0.00000000,0.00000000,0.00000000
87.61000000,1.88528800,2.26700000,0.06177011,204.99233356,0.05993743,217.65473278,0.00073790,0.06384906,224.61488397,-0.03621232,-0.02763674,0.00000000,0.00000000,0.00000000,0.00000000
89.11000000,1.92047200,2.27600000,0.06291900,205.80615403,0.06101890,218.75527143,0.00070196,0.06496426,225.64317995,-0.03686018,-0.02810408,0.00000000,0.00000000,0.00000000,0.00000000
90.61000000,1.95595800,2.28500000,0.06410900,206.61997449,0.06213783,219.86617444,0.00077848,0.06605592,226.76538584,-0.03746422,-0.02859170,0.00000000,0.00000000,0.00000000,0.00000000
92.11000000,1.99221700,2.29500000,0.06532889,207.52421946,0.06328357,221.08154613,0.00077758,0.06716992,227.70025468,-0.03812545,-0.02904447,0.00000000,0.00000000,0.00000000,0.00000000
93.61000000,2.02820700,2.30300000,0.06651878,208.24761543,0.06439987,222.09999229,0.00075546,0.06827084,228.73139072,-0.03871827,-0.02955257,0.00000000,0.00000000,0.00000000,0.00000000
95.11000000,2.06399500,2.31200000,0.06768644,209.06143590,0.06549411,223.21206117,0.00068488,0.06938770,229.76822404,-0.03933481,-0.03005289,0.00000000,0.00000000,0.00000000,0.00000000
96.61000000,2.09995000,2.32000000,0.06890244,209.78483187,0.06663237,224.23951960,0.00071904,0.07050123,230.70868510,-0.03999434,-0.03050688,0.00000000,0.00000000,0.00000000,0.00000000
98.11000000,2.13587300,2.32900000,0.07010367,210.59865234,0.06775553,225.36239006,0.00073921,0.07161209,231.74813597,-0.04062691,-0.03098519,0.00000000,0.00000000,0.00000000,0.00000000
99.61000000,2.17229900,2.33700000,0.07130478,211.32204831,0.06887732,226.39032001,0.00074523,0.07273341,232.69419635,-0.04128154,-0.03145187,0.00000000,0.00000000,0.00000000,0.00000000
101.11000000,2.20815400,2.34500000,0.07249844,212.04544428,0.06999092,227.41840915,0.00072347,0.07382933,233.63615798,-0.04189009,-0.03193924,0.00000000,0.00000000,0.00000000,0.00000000
102.61000000,2.24495000,2.35300000,0.07372200,212.76884026,0.07113112,228.45458470,0.00077130,0.07496854,234.59012037,-0.04253267,-0.03243587,0.00000000,0.00000000,0.00000000,0.00000000
104.11000000,2.28070400,2.36100000,0.07493056,213.49223623,0.07225606,229.48932810,0.00077746,0.07607899,235.53918136,-0.04315645,-0.03292255,0.00000000,0.00000000,0.00000000,0.00000000
105.61000000,2.31733000,2.36800000,0.07613911,214.12520770,0.07337974,230.42851069,0.00074188,0.07721238,236.49552751,-0.04383274,-0.03337964,0.00000000,0.00000000,0.00000000,0.00000000
107.11000000,2.35392500,2.37600000,0.07735156,214.84860368,0.07450577,231.46747738,0.00075487,0.07833055,237.45013966,-0.04445113,-0.03387941,0.00000000,0.00000000,0.00000000,0.00000000
108.61000000,2.39045200,2.38300000,0.07856389,215.48157515,0.07563042,232.41064568,0.00072641,0.07946592,238.31216945,-0.04509894,-0.03436698,0.00000000,0.00000000,0.00000000,0.00000000
110.11000000,2.42697800,2.39000000,0.07976878,216.11454663,0.07674692,233.35373987,0.00073260,0.08057267,239.16900264,-0.04571452,-0.03485815,0.00000000,0.00000000,0.00000000,0.00000000
111.61000000,2.46397400,2.39700000,0.08101089,216.74751810,0.07789661,234.30642721,0.00078687,0.08171213,240.03533675,-0.04635097,-0.03536116,0.00000000,0.00000000,0.00000000,0.00000000
113.11000000,2.50076800,2.40400000,0.08224556,217.38048958,0.07903810,235.25906871,0.00079973,0.08279589,240.88989366,-0.04695262,-0.03584327,0.00000000,0.00000000,0.00000000,0.00000000
114.61000000,2.53803400,2.41100000,0.08348400,218.01346105,0.08018177,236.21409684,0.00077809,0.08394307,241.76142603,-0.04764614,-0.03629693,0.00000000,0.00000000,0.00000000,0.00000000
116.11000000,2.57493000,2.41700000,0.08468889,218.55600803,0.08129321,237.06527351,0.00074977,0.08508889,242.63433057,-0.04826966,-0.03681923,0.00000000,0.00000000,0.00000000,0.00000000
117.61000000,2.61199400,2.42400000,0.08593489,219.18897951,0.08244126,238.02496011,0.00081094,0.08621969,243.50526789,-0.04893099,-0.03728870,0.00000000,0.00000000,0.00000000,0.00000000
119.11000000,2.64875500,2.43000000,0.08712478,219.73152649,0.08353639,238.87558690,0.00066568,0.08733710,244.27524606,-0.04952510,-0.03781200,0.00000000,0.00000000,0.00000000,0.00000000
120.61000000,2.68612000,2.43600000,0.08837433,220.27407347,0.08468515,239.74064786,0.00076786,0.08845990,245.04797997,-0.05018085,-0.03827905,0.00000000,0.00000000,0.00000000,0.00000000
122.11000000,2.72331800,2.44300000,0.08964644,220.90704494,0.08585328,240.71057607,0.00080817,0.08960038,245.92610799,-0.05079002,-0.03881035,0.00000000,0.00000000,0.00000000,0.00000000
123.61000000,2.76048200,2.44800000,0.09085867,221.35916742,0.08696515,241.47156623,0.00053339,0.09072055,246.70121072,-0.05142105,-0.03929950,0.00000000,0.00000000,0.00000000,0.00000000
125.11000000,2.79815000,2.45400000,0.09212333,221.90171440,0.08812381,242.34404001,0.00078578,0.09195095,247.50513369,-0.05214460,-0.03980635,0.00000000,0.00000000,0.00000000,0.00000000
126.61000000,2.83554900,2.46000000,0.09336544,222.44426138,0.08926050,243.21286871,0.00077797,0.09300447,248.26660816,-0.05270078,-0.04030370,0.00000000,0.00000000,0.00000000,0.00000000
128.11000000,2.87314900,2.46500000,0.09461889,222.89638386,0.09040626,243.98659204,0.00075007,0.09414091,249.05014878,-0.05334585,-0.04079505,0.00000000,0.00000000,0.00000000,0.00000000
129.61000000,2.91048100,2.47100000,0.09586467,223.43893084,0.09154370,244.85882947,0.00075591,0.09528624,249.83739787,-0.05400934,-0.04127690,0.00000000,0.00000000,0.00000000,0.00000000
131.11000000,2.94808100,2.47600000,0.09710689,223.89105333,0.09267661,245.63241696,0.00075506,0.09644505,250.52924525,-0.05465164,-0.04179341,0.00000000,0.00000000,0.00000000,0.00000000
132.61000000,2.98668900,2.48200000,0.09839011,224.43360030,0.09384557,246.51564718,0.00080174,0.09755735,251.31104569,-0.05527160,-0.04228575,0.00000000,0.00000000,0.00000000,0.00000000
134.11000000,3.02529700,2.48600000,0.09967322,224.79529829,0.09501306,247.20137001,0.00079393,0.09873705,252.01082531,-0.05596205,-0.04277500,0.00000000,0.00000000,0.00000000,0.00000000
135.61000000,3.06152100,2.49200000,0.10087067,225.33784527,0.09610138,248.06782395,0.00071855,0.09987687,252.80244291,-0.05660154,-0.04327533,0.00000000,0.00000000,0.00000000,0.00000000
137.11000000,3.10012800,2.49600000,0.10216133,225.69954326,0.09727310,248.75730953,0.00077862,0.10102684,253.49738231,-0.05719515,-0.04383169,0.00000000,0.00000000,0.00000000,0.00000000
138.61000000,3.13880300,2.50100000,0.10342589,226.15166574,0.09841978,249.54160279,0.00073038,0.10218561,254.19584439,-0.05788715,-0.04429846,0.00000000,0.00000000,0.00000000,0.00000000
140.11000000,3.17720900,2.50600000,0.10471656,226.60378822,0.09958879,250.33295640,0.00074301,0.10334281,254.89519470,-0.05856305,-0.04477975,0.00000000,0.00000000,0.00000000,0.00000000
141.61000000,3.21568300,2.51000000,0.10595500,226.96548621,0.10070922,251.01361430,0.00074218,0.10450886,255.59810941,-0.05921338,-0.04529549,0.00000000,0.00000000,0.00000000,0.00000000
143.11000000,3.25398900,2.51500000,0.10723444,227.41760869,0.10186541,251.80460961,0.00072787,0.10569000,256.30620933,-0.05985816,-0.04583184,0.00000000,0.00000000,0.00000000,0.00000000
144.61000000,3.29259600,2.52000000,0.10855500,227.86973117,0.10305737,252.60612984,0.00080120,0.10681647,257.00153872,-0.06049791,-0.04631857,0.00000000,0.00000000,0.00000000,0.00000000
146.11000000,3.33110400,2.52400000,0.10981200,228.23142916,0.10419063,253.29397886,0.00075963,0.10795838,257.70211367,-0.06114425,-0.04681413,0.00000000,0.00000000,0.00000000,0.00000000
147.61000000,3.37071800,2.52800000,0.11112878,228.59312714,0.10537642,253.99640197,0.00080595,0.10919670,258.32737767,-0.06190693,-0.04728977,0.00000000,0.00000000,0.00000000,0.00000000
149.11000000,3.40952700,2.53200000,0.11240456,228.95482513,0.10652394,254.69039049,0.00069771,0.11036555,259.03746726,-0.06253240,-0.04783315,0.00000000,0.00000000,0.00000000,0.00000000
150.61000000,3.44890800,2.53600000,0.11376611,229.31652312,0.10774717,255.40497216,0.00085773,0.11151460,259.64187994,-0.06316004,-0.04835456,0.00000000,0.00000000,0.00000000,0.00000000
152.11000000,3.48812000,2.54000000,0.11504178,229.67822110,0.10889187,256.10081197,0.00082964,0.11269724,260.35807860,-0.06383401,-0.04886322,0.00000000,0.00000000,0.00000000,0.00000000
153.61000000,3.52723100,2.54400000,0.11638100,230.03991909,0.11009220,256.81219491,0.00080216,0.11386343,260.96923612,-0.06449617,-0.04936726,0.00000000,0.00000000,0.00000000,0.00000000
155.11000000,3.56624000,2.54800000,0.11763422,230.40161707,0.11121415,257.50473210,0.00070757,0.11503483,261.58283945,-0.06515451,-0.04988031,0.00000000,0.00000000,0.00000000,0.00000000
156.61000000,3.60649300,2.55100000,0.11896222,230.67289056,0.11240167,258.11425023,0.00081342,0.11617173,262.18845477,-0.06579970,-0.05037203,0.00000000,0.00000000,0.00000000,0.00000000
158.11000000,3.64819000,2.55500000,0.12033867,231.03458855,0.11363102,258.83698289,0.00074575,0.11741140,262.92467498,-0.06648891,-0.05092249,0.00000000,0.00000000,0.00000000,0.00000000
159.61000000,3.68653000,2.55800000,0.12162200,231.30586204,0.11477585,259.43774359,0.00066522,0.11854375,263.42880131,-0.06712481,-0.05141894,0.00000000,0.00000000,0.00000000,0.00000000
161.11000000,3.72661400,2.56100000,0.12294989,231.57713553,0.11595905,260.04951861,0.00079073,0.11972267,264.04876247,-0.06777663,-0.05194604,0.00000000,0.00000000,0.00000000,0.00000000
162.61000000,3.76629500,2.56500000,0.12421811,231.93883351,0.11708778,260.74983731,0.00073665,0.12092968,264.67729270,-0.06847342,-0.05245626,0.00000000,0.00000000,0.00000000,0.00000000
164.11000000,3.80685100,2.56800000,0.12557233,232.21010700,0.11829165,261.36927196,0.00077585,0.12210250,265.29786238,-0.06913854,-0.05296396,0.00000000,0.00000000,0.00000000,0.00000000
165.61000000,3.84703800,2.57100000,0.12690778,232.48138049,0.11947740,261.98507587,0.00074830,0.12329165,265.82083119,-0.06982290,-0.05346875,0.00000000,0.00000000,0.00000000,0.00000000
167.11000000,3.88755900,2.57400000,0.12824311,232.75265398,0.12066165,262.60157845,0.00080022,0.12449427,266.45146215,-0.07049480,-0.05399947,0.00000000,0.00000000,0.00000000,0.00000000
168.61000000,3.92791200,2.57700000,0.12956367,233.02392747,0.12183142,263.21536194,0.00076642,0.12574122,267.09511999,-0.07117473,-0.05456649,0.00000000,0.00000000,0.00000000,0.00000000
170.11000000,3.96907000,2.58000000,0.13095122,233.29520096,0.12305907,263.84549267,0.00085119,0.12696181,267.62945202,-0.07186756,-0.05509425,0.00000000,0.00000000,0.00000000,0.00000000
171.61000000,4.01019700,2.58300000,0.13233144,233.56647445,0.12427873,264.47466339,0.00084347,0.12821678,268.17395163,-0.07259841,-0.05561837,0.00000000,0.00000000,0.00000000,0.00000000
173.11000000,4.05132300,2.58600000,0.13364833,233.83774794,0.12544105,265.08977322,0.00084916,0.12944263,268.81525338,-0.07324525,-0.05619739,0.00000000,0.00000000,0.00000000,0.00000000
174.61000000,4.09207900,2.58900000,0.13500989,234.10902143,0.12664136,265.71605440,0.00078253,0.13064896,269.34862287,-0.07396662,-0.05668234,0.00000000,0.00000000,0.00000000,0.00000000
176.11000000,4.13417800,2.59100000,0.13640867,234.28987042,0.12787300,266.24903926,0.00082734,0.13188628,269.89129174,-0.07467426,-0.05721202,0.00000000,0.00000000,0.00000000,0.00000000
177.61000000,4.17550500,2.59400000,0.13778133,234.56114391,0.12908017,266.87929107,0.00080661,0.13308178,270.52763259,-0.07533764,-0.05774414,0.00000000,0.00000000,0.00000000,0.00000000
179.11000000,4.21915000,2.59600000,0.13923256,234.74199291,0.13035484,267.42572047,0.00074021,0.13423324,270.94471506,-0.07592619,-0.05830705,0.00000000,0.00000000,0.00000000,0.00000000
180.61000000,4.26004000,2.59900000,0.14064256,235.01326639,0.13159175,268.06613277,0.00075235,0.13544197,271.58667413,-0.07663162,-0.05881035,0.00000000,0.00000000,0.00000000,0.00000000
182.11000000,4.30197100,2.60100000,0.14203389,235.19411539,0.13281079,268.59965024,0.00077752,0.13668606,272.13499753,-0.07736156,-0.05932450,0.00000000,0.00000000,0.00000000,0.00000000
183.61000000,4.34390200,2.60300000,0.14342156,235.37496438,0.13402513,269.13280791,0.00071786,0.13785462,272.66359574,-0.07801597,-0.05983865,0.00000000,0.00000000,0.00000000,0.00000000
185.11000000,4.38751200,2.60600000,0.14484278,235.64623787,0.13526732,269.77789354,0.00083445,0.13901347,273.08568899,-0.07866038,-0.06035309,0.00000000,0.00000000,0.00000000,0.00000000
186.61000000,4.42894100,2.60800000,0.14624167,235.82708686,0.13648847,270.31483309,0.00078766,0.14017917,273.61511602,-0.07932500,-0.06085418,0.00000000,0.00000000,0.00000000,0.00000000
188.11000000,4.47198000,2.61000000,0.14763311,236.00793586,0.13770166,270.85052167,0.00082583,0.14135632,274.14856288,-0.07997870,-0.06137762,0.00000000,0.00000000,0.00000000,0.00000000
189.61000000,4.51381100,2.61200000,0.14895356,236.18878485,0.13885158,271.36994414,0.00074033,0.14258330,274.69663588,-0.08067754,-0.06190576,0.00000000,0.00000000,0.00000000,0.00000000
191.11000000,4.55762200,2.61400000,0.15040467,236.36963384,0.14011376,271.92072983,0.00083022,0.14379447,275.13605851,-0.08135634,-0.06243813,0.00000000,0.00000000,0.00000000,0.00000000
192.61000000,4.59938600,2.61600000,0.15178122,236.55048284,0.14130963,272.45440424,0.00090721,0.14501036,275.57745114,-0.08201660,-0.06299376,0.00000000,0.00000000,0.00000000,0.00000000
194.11000000,4.64259300,2.61800000,0.15312789,236.73133183,0.14247815,272.98150091,0.00093854,0.14630966,276.14811857,-0.08278214,-0.06352753,0.00000000,0.00000000,0.00000000,0.00000000
195.61000000,4.68570000,2.61900000,0.15448933,236.82175632,0.14365811,273.40819158,0.00083364,0.14759275,276.60968110,-0.08349639,-0.06409637,0.00000000,0.00000000,0.00000000,0.00000000
197.11000000,4.72823600,2.62100000,0.15588444,237.00260532,0.14486580,273.94762478,0.00085859,0.14889179,277.18217848,-0.08421004,-0.06468175,0.00000000,0.00000000,0.00000000,0.00000000
198.61000000,4.77164400,2.62300000,0.15723111,237.18345431,0.14603018,274.47607237,0.00080611,0.15027351,277.67284847,-0.08501942,-0.06525409,0.00000000,0.00000000,0.00000000,0.00000000
200.11000000,4.81525500,2.62500000,0.15860756,237.36430330,0.14721890,275.01207523,0.00076639,0.15167243,278.16915500,-0.08579473,-0.06587771,0.00000000,0.00000000,0.00000000,0.00000000
201.61000000,4.85943600,2.62600000,0.16005867,237.45472780,0.14847058,275.46141493,0.00070756,0.15306780,278.77152757,-0.08656016,-0.06650764,0.00000000,0.00000000,0.00000000,0.00000000
203.11000000,4.90452400,2.62800000,0.16158056,237.63557679,0.14978163,276.03286531,0.00088635,0.15449432,279.27742200,-0.08736018,-0.06713415,0.00000000,0.00000000,0.00000000,0.00000000
204.61000000,4.94887200,2.62900000,0.16302422,237.72600129,0.15102370,276.48109775,0.00080840,0.15595038,279.79249560,-0.08816260,-0.06778779,0.00000000,0.00000000,0.00000000,0.00000000
206.11000000,4.99348900,2.63000000,0.16457978,237.81642579,0.15236032,276.95620029,0.00089723,0.15737294,280.29905353,-0.08896237,-0.06841057,0.00000000,0.00000000,0.00000000,0.00000000
207.61000000,5.03951700,2.63200000,0.16614644,237.99727478,0.15370468,277.53967577,0.00092158,0.15879327,280.80586204,-0.08977967,-0.06901360,0.00000000,0.00000000,0.00000000,0.00000000
209.11000000,5.08594800,2.63300000,0.16775056,238.08769928,0.15507930,278.02704310,0.00089461,0.16021165,281.31300063,-0.09056759,-0.06964406,0.00000000,0.00000000,0.00000000,0.00000000
210.61000000,5.13258000,2.63400000,0.16942922,238.17812377,0.15651579,278.53245803,0.00095739,0.16162790,281.82041628,-0.09135297,-0.07027493,0.00000000,0.00000000,0.00000000,0.00000000
212.11000000,5.17954700,2.63600000,0.17107044,238.35897277,0.15791824,279.13514817,0.00101946,0.16294782,282.30140506,-0.09205691,-0.07089091,0.00000000,0.00000000,0.00000000,0.00000000
213.61000000,5.22691600,2.63700000,0.17274900,238.44939726,0.15935057,279.64129219,0.00089079,0.16426748,282.67568411,-0.09280679,-0.07146069,0.00000000,0.00000000,0.00000000,0.00000000
215.11000000,5.27458900,2.63800000,0.17450222,238.53982176,0.16084442,280.16555074,0.00101648,0.16555259,283.14820208,-0.09353780,-0.07201480,0.00000000,0.00000000,0.00000000,0.00000000
216.61000000,5.32253000,2.63900000,0.17618100,238.63024625,0.16227275,280.67236167,0.00095189,0.16680460,283.61204434,-0.09422171,-0.07258289,0.00000000,0.00000000,0.00000000,0.00000000
218.11000000,5.37010100,2.64000000,0.17785956,238.72067075,0.16369886,281.17942315,0.00095035,0.16802380,284.06725388,-0.09494439,-0.07307941,0.00000000,0.00000000,0.00000000,0.00000000
219.61000000,5.41827700,2.64100000,0.17950089,238.81109525,0.16509137,281.67789912,0.00101217,0.16918047,284.39733891,-0.09562227,-0.07355820,0.00000000,0.00000000,0.00000000,0.00000000
221.11000000,5.46688800,2.64200000,0.18114211,238.90151974,0.16648186,282.17664538,0.00088446,0.17027199,284.81725954,-0.09622860,-0.07404339,0.00000000,0.00000000,0.00000000,0.00000000
222.61000000,5.51503000,2.64300000,0.18274611,238.99194424,0.16783895,282.66679264,0.00094642,0.17133253,285.12069847,-0.09686945,-0.07446308,0.00000000,0.00000000,0.00000000,0.00000000
224.11000000,5.56327200,2.64300000,0.18427556,238.99194424,0.16913124,283.03231754,0.00088231,0.17235935,285.52309817,-0.09744029,-0.07491906,0.00000000,0.00000000,0.00000000,0.00000000
225.61000000,5.61205200,2.64400000,0.18576756,239.08236874,0.17039029,283.49611595,0.00081802,0.17338652,285.81771591,-0.09806284,-0.07532368,0.00000000,0.00000000,0.00000000,0.00000000
227.11000000,5.66120200,2.64400000,0.18725967,239.08236874,0.17164785,283.85285341,0.00087990,0.17441110,286.22042293,-0.09866958,-0.07574153,0.00000000,0.00000000,0.00000000,0.00000000
228.61000000,5.70974600,2.64500000,0.18863978,239.17279323,0.17280961,284.29029580,0.00081604,0.17537409,286.49730009,-0.09922728,-0.07614681,0.00000000,0.00000000,0.00000000,0.00000000
230.11000000,5.75845900,2.64600000,0.18998267,239.26321773,0.17393874,284.71908187,0.00075253,0.17646032,286.80993423,-0.09993622,-0.07652410,0.00000000,0.00000000,0.00000000,0.00000000
231.61000000,5.80794500,2.64600000,0.19125089,239.26321773,0.17500392,285.02252080,0.00075155,0.17757466,287.23988773,-0.10063269,-0.07694197,0.00000000,0.00000000,0.00000000,0.00000000
233.11000000,5.85726100,2.64600000,0.19248178,239.26321773,0.17603666,285.31702724,0.00068813,0.00000000,0.00000000,0.00000000,0.00000000,0.00000000,0.00000000,0.00000000,0.00000000
234.61000000,5.90758500,2.64700000,0.19371278,239.35364223,0.17706843,285.71950113,0.00062504,0.00000000,0.00000000,0.00000000,0.00000000,0.00000000,0.00000000,0.00000000,0.00000000
236.11000000,5.95753900,2.64700000,0.19486911,239.35364223,0.17803665,285.99627373,0.00056193,0.00000000,0.00000000,0.00000000,0.00000000,0.00000000,0.00000000,0.00000000,0.00000000
237.61000000,6.00789800,2.64800000,0.19613744,239.44406672,0.17909757,286.40801406,0.00074866,0.00000000,0.00000000,0.00000000,0.00000000,0.00000000,0.00000000,0.00000000,0.00000000
239.11000000,6.05882700,2.64800000,0.19740567,239.44406672,0.18015727,286.71168234,0.00081025,0.00000000,0.00000000,0.00000000,0.00000000,0.00000000,0.00000000,0.00000000,0.00000000
240.61000000,6.10955300,2.64800000,0.19863656,239.44406672,0.18118471,287.00641139,0.00068478,0.00000000,0.00000000,0.00000000,0.00000000,0.00000000,0.00000000,0.00000000,0.00000000
242.11000000,6.16159000,2.64900000,0.20009133,239.53449122,0.00000000,0.00000000,0.00000000,0.00000000,0.00000000,0.00000000,0.00000000,0.00000000,0.00000000,0.00000000,0.00000000
243.61000000,6.21295400,2.64900000,0.20169522,239.53449122,0.00000000,0.00000000,0.00000000,0.00000000,0.00000000,0.00000000,0.00000000,0.00000000,0.00000000,0.00000000,0.00000000
245.11000000,6.26552900,2.64900000,0.20352311,239.53449122,0.00000000,0.00000000,0.00000000,0.00000000,0.00000000,0.00000000,0.00000000,0.00000000,0.00000000,0.00000000,0.00000000
246.61000000,6.31864000,2.64800000,0.20572411,239.44406672,0.00000000,0.00000000,0.00000000,0.00000000,0.00000000,0.00000000,0.00000000,0.00000000,0.00000000,0.00000000,0.00000000
248.11000000,6.37168300,2.64700000,0.20833544,239.35364223,0.00000000,0.00000000,0.00000000,0.00000000,0.00000000,0.00000000,0.00000000,0.00000000,0.00000000,0.00000000,0.00000000
249.61000000,6.42563300,2.64600000,0.21146933,239.26321773,0.00000000,0.00000000,0.00000000,0.00000000,0.00000000,0.00000000,0.00000000,0.00000000,0.00000000,0.00000000,0.00000000
251.11000000,6.48075800,2.64400000,0.21527444,239.08236874,0.00000000,0.00000000,0.00000000,0.00000000,0.00000000,0.00000000,0.00000000,0.00000000,0.00000000,0.00000000,0.00000000
252.61000000,6.53776200,2.64000000,0.21948933,238.72067075,0.00000000,0.00000000,0.00000000,0.00000000,0.00000000,0.00000000,0.00000000,0.00000000,0.00000000,0.00000000,0.00000000
254.11000000,6.59523700,2.63200000,0.22433844,237.99727478,0.00000000,0.00000000,0.00000000,0.00000000,0.00000000,0.00000000,0.00000000,0.00000000,0.00000000,0.00000000,0.00000000
255.61000000,6.65506200,2.61700000,0.22982189,236.64090733,0.00000000,0.00000000,0.00000000,0.00000000,0.00000000,0.00000000,0.00000000,0.00000000,0.00000000,0.00000000,0.00000000
257.11000000,6.71790800,2.58100000,0.23627533,233.38562546,0.00000000,0.00000000,0.00000000,0.00000000,0.00000000,0.00000000,0.00000000,0.00000000,0.00000000,0.00000000,0.00000000
258.61000000,6.84674400,2.07600000,0.25292433,187.72125473,0.00000000,0.00000000,0.00000000,0.00000000,0.00000000,0.00000000,0.00000000,0.00000000,0.00000000,0.00000000,0.00000000
260.11000000,6.94536900,1.65700000,0.26543978,149.83339070,0.00000000,0.00000000,0.00000000,0.00000000,0.00000000,0.00000000,0.00000000,0.00000000,0.00000000,0.00000000,0.00000000
261.61000000,7.02235300,1.43700000,0.27480611,129.94000147,0.00000000,0.00000000,0.00000000,0.00000000,0.00000000,0.00000000,0.00000000,0.00000000,0.00000000,0.00000000,0.00000000
263.11000000,7.09845200,1.31400000,0.28401489,118.81778840,0.00000000,0.00000000,0.00000000,0.00000000,0.00000000,0.00000000,0.00000000,0.00000000,0.00000000,0.00000000,0.00000000
264.61000000,7.17310400,1.18600000,0.29299633,107.24345285,0.00000000,0.00000000,0.00000000,0.00000000,0.00000000,0.00000000,0.00000000,0.00000000,0.00000000,0.00000000,0.00000000
266.11000000,7.25775400,0.99200000,0.30354144,89.70110052,0.00000000,0.00000000,0.00000000,0.00000000,0.00000000,0.00000000,0.00000000,0.00000000,0.00000000,0.00000000,0.00000000
267.61000000,7.34690400,0.76400000,0.31472244,69.08431532,0.00000000,0.00000000,0.00000000,0.00000000,0.00000000,0.00000000,0.00000000,0.00000000,0.00000000,0.00000000,0.00000000
269.11000000,7.42515500,0.61600000,0.32404489,55.70148984,0.00000000,0.00000000,0.00000000,0.00000000,0.00000000,0.00000000,0.00000000,0.00000000,0.00000000,0.00000000,0.00000000
270.61000000,7.51224000,0.42800000,0.33460211,38.70168450,0.00000000,0.00000000,0.00000000,0.00000000,0.00000000,0.00000000,0.00000000,0.00000000,0.00000000,0.00000000,0.00000000
272.11000000,7.59899700,0.25800000,0.34493933,23.32952010,0.00000000,0.00000000,0.00000000,0.00000000,0.00000000,0.00000000,0.00000000,0.00000000,0.00000000,0.00000000,0.00000000
273.61000000,7.69564700,0.04600000,0.35642478,4.15952684,0.00000000,0.00000000,0.00000000,0.00000000,0.00000000,0.00000000,0.00000000,0.00000000,0.00000000,0.00000000,0.00000000
NaN,-100.00000000,NaN,-11.11111111,NaN,0.00000000,0.00000000,0.00000000,0.00000000,0.00000000,0.00000000,0.00000000,0.00000000,0.00000000,0.00000000,0.00000000