File: polyN_optimization/results_exp/AA6014-T4/UT_00_2.csv
Time[s],Displacement[mm],Force[kN],EngStrain_longi,EngStress[MPa],TrueStrain,TrueStress[MPa],TrueStrainRate[1/s],PlasticStrain_longi,PlasticStress[MPa],PlasticStrain_thick,PlasticStrain_width,R-Value,Thickness[mm],Width[mm], Young's Modulus [MPa]
0.59000000,0.00000000,-0.00100000,0.00000000,-0.08959253,0.00000000,-0.08959253,0.00000000,0.00080138,119.81426545,-0.00012116,-0.00068022,0.78073493,1.11660000,9.99610000,82946.46398571
2.09000000,0.00675600,0.16200000,0.00020689,14.51398931,0.00020687,14.51699209,0.00017419,0.00189515,124.53929271,-0.00072903,-0.00116612,0.00000000,0.00000000,0.00000000,0.00000000
3.59000000,0.01402700,0.39700000,0.00044444,35.56823307,0.00044435,35.58404117,0.00010618,0.00315804,128.21462312,-0.00147382,-0.00168423,0.00000000,0.00000000,0.00000000,0.00000000
5.09000000,0.02247000,0.65500000,0.00074011,58.68310493,0.00073984,58.72653695,0.00025183,0.00433941,131.16612255,-0.00219560,-0.00214381,0.00000000,0.00000000,0.00000000,0.00000000
6.59000000,0.03150700,0.90300000,0.00102611,80.90205153,0.00102559,80.98506603,0.00032036,0.00549553,133.94041970,-0.00282477,-0.00267077,0.00000000,0.00000000,0.00000000,0.00000000
8.09000000,0.04281600,1.13900000,0.00133144,102.04588781,0.00133056,102.18175624,0.00025279,0.00670061,136.72788304,-0.00355061,-0.00314999,0.00000000,0.00000000,0.00000000,0.00000000
9.59000000,0.06507600,1.30900000,0.00203756,117.27661734,0.00203548,117.51557496,0.00049128,0.00794823,139.16539043,-0.00427719,-0.00367104,0.00000000,0.00000000,0.00000000,0.00000000
11.09000000,0.09959200,1.37100000,0.00323767,122.83135399,0.00323244,123.22904097,0.00068302,0.00905760,141.58932271,-0.00491519,-0.00414241,0.00000000,0.00000000,0.00000000,0.00000000
12.59000000,0.13713800,1.41100000,0.00451256,126.41505505,0.00450240,126.98551001,0.00091519,0.01019093,144.11296694,-0.00552052,-0.00467041,0.00000000,0.00000000,0.00000000,0.00000000
14.09000000,0.17440300,1.44600000,0.00573122,129.55079348,0.00571486,130.29327787,0.00088667,0.01134875,146.37296175,-0.00621175,-0.00513701,0.00000000,0.00000000,0.00000000,0.00000000
15.59000000,0.21233600,1.47500000,0.00697744,132.14897675,0.00695321,133.07103890,0.00075730,0.01255391,148.55408834,-0.00689078,-0.00566312,0.00000000,0.00000000,0.00000000,0.00000000
17.09000000,0.24940600,1.50300000,0.00829289,134.65756750,0.00825869,135.77426774,0.00086612,0.01363526,150.81290589,-0.00745695,-0.00617831,0.00000000,0.00000000,0.00000000,0.00000000
18.59000000,0.28684200,1.53000000,0.00953756,137.07656572,0.00949236,138.38394108,0.00100313,0.01475312,152.99086367,-0.00802426,-0.00672886,0.00000000,0.00000000,0.00000000,0.00000000
20.09000000,0.32318700,1.55600000,0.01073644,139.40597141,0.01067922,140.90269588,0.00085566,0.01590027,155.08676800,-0.00867304,-0.00722723,0.00000000,0.00000000,0.00000000,0.00000000
21.59000000,0.35922300,1.57900000,0.01193378,141.46659952,0.01186313,143.15483048,0.00072482,0.01705327,157.18832602,-0.00933987,-0.00771340,0.00000000,0.00000000,0.00000000,0.00000000
23.09000000,0.39564200,1.60500000,0.01319089,143.79600521,0.01310465,145.69280234,0.00088387,0.01814407,159.19307838,-0.00997721,-0.00816686,0.00000000,0.00000000,0.00000000,0.00000000
24.59000000,0.43096000,1.62700000,0.01436233,145.76704080,0.01426017,147.86059563,0.00088285,0.01924201,161.11153770,-0.01056646,-0.00867555,0.00000000,0.00000000,0.00000000,0.00000000
26.09000000,0.46665000,1.64900000,0.01552611,147.73807638,0.01540681,150.03187417,0.00077151,0.02038352,163.22496065,-0.01123683,-0.00914669,0.00000000,0.00000000,0.00000000,0.00000000
27.59000000,0.50171200,1.67200000,0.01670478,149.79870450,0.01656679,152.30105857,0.00069714,0.02148256,165.15215786,-0.01186700,-0.00961555,0.00000000,0.00000000,0.00000000,0.00000000
29.09000000,0.53726800,1.69300000,0.01789844,151.68014756,0.01774015,154.39498625,0.00078434,0.02256708,166.98899979,-0.01249336,-0.01007372,0.00000000,0.00000000,0.00000000,0.00000000
30.59000000,0.57263300,1.71400000,0.01903244,153.56159061,0.01885359,156.48424306,0.00070297,0.02370345,168.93068306,-0.01317183,-0.01053162,0.00000000,0.00000000,0.00000000,0.00000000
32.09000000,0.60745400,1.73500000,0.02020756,155.44303367,0.02000609,158.58415741,0.00066577,0.02479602,170.77688479,-0.01377413,-0.01102189,0.00000000,0.00000000,0.00000000,0.00000000
33.59000000,0.64211000,1.75500000,0.02137878,157.23488421,0.02115346,160.59637385,0.00067937,0.02589958,172.53652657,-0.01443886,-0.01146073,0.00000000,0.00000000,0.00000000,0.00000000
35.09000000,0.67687700,1.77400000,0.02253511,158.93714221,0.02228495,162.51880837,0.00075904,0.02697168,174.38693084,-0.01504589,-0.01192579,0.00000000,0.00000000,0.00000000,0.00000000
36.59000000,0.71171800,1.79400000,0.02368033,160.72899274,0.02340430,164.53510887,0.00070716,0.02807393,176.06132678,-0.01567303,-0.01240090,0.00000000,0.00000000,0.00000000,0.00000000
38.09000000,0.74655600,1.81200000,0.02484422,162.34165822,0.02454062,166.37491046,0.00069898,0.02915318,177.73518386,-0.01625756,-0.01289562,0.00000000,0.00000000,0.00000000,0.00000000
39.59000000,0.78137000,1.83000000,0.02599689,163.95432370,0.02566471,168.21662604,0.00068368,0.03024658,179.60069904,-0.01688223,-0.01336435,0.00000000,0.00000000,0.00000000,0.00000000
41.09000000,0.81628500,1.84900000,0.02716433,165.65658171,0.02680193,170.15653231,0.00073355,0.03134613,181.19254217,-0.01746578,-0.01388035,0.00000000,0.00000000,0.00000000,0.00000000
42.59000000,0.85086400,1.86700000,0.02832067,167.26924719,0.02792705,172.00642378,0.00073294,0.03243378,182.78556165,-0.01805644,-0.01437733,0.00000000,0.00000000,0.00000000,0.00000000
44.09000000,0.88571200,1.88300000,0.02951067,168.70272761,0.02908361,173.68125757,0.00076102,0.03350441,184.47188791,-0.01864123,-0.01486319,0.00000000,0.00000000,0.00000000,0.00000000
45.59000000,0.91988800,1.90000000,0.03062600,170.22580056,0.03016638,175.43913593,0.00076732,0.03459658,186.07248137,-0.01924543,-0.01535115,0.00000000,0.00000000,0.00000000,0.00000000
47.09000000,0.95440000,1.91800000,0.03178244,171.83846604,0.03128784,177.29991254,0.00074491,0.03571032,187.58714131,-0.01988468,-0.01582564,0.00000000,0.00000000,0.00000000,0.00000000
48.59000000,0.98901300,1.93300000,0.03293500,173.18235394,0.03240426,178.88611477,0.00076582,0.03676410,189.18708734,-0.02044391,-0.01632019,0.00000000,0.00000000,0.00000000,0.00000000
50.09000000,1.02329000,1.95000000,0.03408767,174.70542690,0.03351956,180.66072725,0.00079399,0.03784321,190.70156747,-0.02105236,-0.01679085,0.00000000,0.00000000,0.00000000,0.00000000
51.59000000,1.05793600,1.96500000,0.03522911,176.04931479,0.03462277,182.25137567,0.00074243,0.03894706,192.13027058,-0.02171433,-0.01723273,0.00000000,0.00000000,0.00000000,0.00000000
53.09000000,1.09228000,1.98100000,0.03637433,177.48279522,0.03572840,183.93861357,0.00069850,0.04002223,193.74391191,-0.02229961,-0.01772262,0.00000000,0.00000000,0.00000000,0.00000000
54.59000000,1.12706100,1.99700000,0.03754933,178.91627565,0.03686152,185.63446252,0.00077677,0.04110360,195.08049089,-0.02292297,-0.01818063,0.00000000,0.00000000,0.00000000,0.00000000
56.09000000,1.16120400,2.01100000,0.03869078,180.17057102,0.03796105,187.14151054,0.00077591,0.04217532,196.51185322,-0.02353248,-0.01864284,0.00000000,0.00000000,0.00000000,0.00000000
57.59000000,1.19574900,2.02500000,0.03982100,181.42486639,0.03904858,188.64938600,0.00071072,0.04329073,198.04887095,-0.02417371,-0.01911702,0.00000000,0.00000000,0.00000000,0.00000000
59.09000000,1.23036200,2.04000000,0.04098111,182.76875429,0.04016364,190.25882092,0.00069541,0.04438599,199.39673537,-0.02480162,-0.01958437,0.00000000,0.00000000,0.00000000,0.00000000
60.59000000,1.26504200,2.05300000,0.04214489,183.93345714,0.04128098,191.68531225,0.00076588,0.04544831,200.74073406,-0.02535220,-0.02009611,0.00000000,0.00000000,0.00000000,0.00000000
62.09000000,1.29962100,2.06700000,0.04330500,185.18775251,0.04239356,193.20730813,0.00077951,0.04653051,202.09144589,-0.02597750,-0.02055302,0.00000000,0.00000000,0.00000000,0.00000000
63.59000000,1.33396500,2.08100000,0.04444267,186.44204788,0.04348341,194.72802967,0.00070715,0.04765045,203.45259623,-0.02660821,-0.02104224,0.00000000,0.00000000,0.00000000,0.00000000
65.09000000,1.36874600,2.09300000,0.04559156,187.51715820,0.04458281,196.06635714,0.00072083,0.04873155,204.71400836,-0.02721621,-0.02151535,0.00000000,0.00000000,0.00000000,0.00000000
66.59000000,1.40335800,2.10600000,0.04677789,188.68186105,0.04571677,197.50800018,0.00081983,0.04978529,206.06701555,-0.02778247,-0.02200281,0.00000000,0.00000000,0.00000000,0.00000000
68.09000000,1.43800500,2.11900000,0.04792667,189.84656389,0.04681361,198.94527688,0.00079729,0.05089565,207.33965711,-0.02837950,-0.02251615,0.00000000,0.00000000,0.00000000,0.00000000
69.59000000,1.47281900,2.13100000,0.04905322,190.92167421,0.04788806,200.28699752,0.00064004,0.05196368,208.51113164,-0.02898307,-0.02298061,0.00000000,0.00000000,0.00000000,0.00000000
71.09000000,1.50776700,2.14300000,0.05025811,191.99678453,0.04903595,201.64618026,0.00076017,0.05304564,209.87790911,-0.02959067,-0.02345496,0.00000000,0.00000000,0.00000000,0.00000000
72.59000000,1.54271600,2.15600000,0.05141822,193.16148738,0.05013994,203.09350766,0.00078069,0.05412892,211.05745271,-0.03018756,-0.02394136,0.00000000,0.00000000,0.00000000,0.00000000
74.09000000,1.57739600,2.16700000,0.05255967,194.14700517,0.05122498,204.35130705,0.00071605,0.05524608,212.24655743,-0.03082406,-0.02442203,0.00000000,0.00000000,0.00000000,0.00000000
75.59000000,1.61237800,2.17800000,0.05371622,195.13252296,0.05232317,205.61430493,0.00064460,0.05632186,213.52459214,-0.03143702,-0.02488484,0.00000000,0.00000000,0.00000000,0.00000000
77.09000000,1.64736000,2.18900000,0.05490244,196.11804076,0.05344829,206.88540059,0.00072163,0.05745185,214.62592638,-0.03206106,-0.02539080,0.00000000,0.00000000,0.00000000,0.00000000
78.59000000,1.68217400,2.20000000,0.05604756,197.10355855,0.05453322,208.15073120,0.00075600,0.05855469,215.81921009,-0.03270342,-0.02585127,0.00000000,0.00000000,0.00000000,0.00000000
80.09000000,1.71799500,2.21100000,0.05723744,198.08907634,0.05565932,209.42718884,0.00075515,0.05964917,217.01308630,-0.03332397,-0.02632520,0.00000000,0.00000000,0.00000000,0.00000000
81.59000000,1.75321300,2.22200000,0.05842767,199.07459413,0.05678447,210.70605816,0.00075472,0.06076120,218.11740491,-0.03395730,-0.02680390,0.00000000,0.00000000,0.00000000,0.00000000
83.09000000,1.78769100,2.23200000,0.05958778,199.97051940,0.05787994,211.88631827,0.00073249,0.06185095,219.21904980,-0.03457806,-0.02727289,0.00000000,0.00000000,0.00000000,0.00000000
84.59000000,1.82334500,2.24200000,0.06076656,200.86644467,0.05899181,213.07240664,0.00068264,0.06296030,220.32720173,-0.03518094,-0.02777936,0.00000000,0.00000000,0.00000000,0.00000000
86.09000000,1.85849500,2.25200000,0.06190811,201.76236993,0.06006739,214.25309715,0.00062539,0.06408732,221.34538106,-0.03581087,-0.02827645,0.00000000,0.00000000,0.00000000,0.00000000
87.59000000,1.89461900,2.26200000,0.06316533,202.65829520,0.06125062,215.45927397,0.00082141,0.06517659,222.45341323,-0.03642383,-0.02875276,0.00000000,0.00000000,0.00000000,0.00000000
89.09000000,1.92953400,2.27100000,0.06430311,203.46462794,0.06232023,216.54803652,0.00071525,0.06628218,223.56729179,-0.03705073,-0.02923145,0.00000000,0.00000000,0.00000000,0.00000000
90.59000000,1.96502000,2.28100000,0.06548189,204.36055320,0.06342717,217.74246824,0.00074242,0.06740858,224.59163994,-0.03769768,-0.02971091,0.00000000,0.00000000,0.00000000,0.00000000
92.09000000,2.00094200,2.29000000,0.06669044,205.16688594,0.06456081,218.84955675,0.00074137,0.06851975,225.61459196,-0.03831000,-0.03020975,0.00000000,0.00000000,0.00000000,0.00000000
93.59000000,2.03723300,2.29900000,0.06791411,205.97321868,0.06570732,219.96170674,0.00080360,0.06962633,226.63852718,-0.03895132,-0.03067501,0.00000000,0.00000000,0.00000000,0.00000000
95.09000000,2.07308900,2.30800000,0.06911900,206.77955142,0.06683494,221.07194724,0.00080955,0.07072453,227.66256873,-0.03955444,-0.03117009,0.00000000,0.00000000,0.00000000,0.00000000
96.59000000,2.10904400,2.31600000,0.07030156,207.49629164,0.06794044,222.08360371,0.00075985,0.07185396,228.59889170,-0.04019456,-0.03165940,0.00000000,0.00000000,0.00000000,0.00000000
98.09000000,2.14483200,2.32500000,0.07148778,208.30262437,0.06904813,223.19371610,0.00070340,0.07297373,229.63183879,-0.04083843,-0.03213530,0.00000000,0.00000000,0.00000000,0.00000000
99.59000000,2.18119100,2.33400000,0.07271878,209.10895711,0.07019634,224.31510490,0.00074425,0.07408002,230.56661296,-0.04146584,-0.03261418,0.00000000,0.00000000,0.00000000,0.00000000
101.09000000,2.21751600,2.34200000,0.07393478,209.82569733,0.07132927,225.33911363,0.00077818,0.07516425,231.49807558,-0.04203794,-0.03312631,0.00000000,0.00000000,0.00000000,0.00000000
102.59000000,2.25367300,2.34900000,0.07514722,210.45284501,0.07245760,226.26779173,0.00076345,0.07627678,232.53524018,-0.04266502,-0.03361176,0.00000000,0.00000000,0.00000000,0.00000000
104.09000000,2.28993100,2.35700000,0.07635589,211.16958523,0.07358116,227.29362661,0.00074194,0.07742708,233.48586367,-0.04332302,-0.03410406,0.00000000,0.00000000,0.00000000,0.00000000
105.59000000,2.32649100,2.36500000,0.07756444,211.88632544,0.07470335,228.32117056,0.00076174,0.07855349,234.33521783,-0.04396850,-0.03458499,0.00000000,0.00000000,0.00000000,0.00000000
107.09000000,2.36311800,2.37300000,0.07878056,212.60306565,0.07583129,229.35205328,0.00076809,0.07965654,235.27836037,-0.04456892,-0.03508761,0.00000000,0.00000000,0.00000000,0.00000000
108.59000000,2.39961100,2.38000000,0.08000033,213.23021334,0.07696135,230.28870148,0.00078760,0.08076524,236.22466425,-0.04516704,-0.03559820,0.00000000,0.00000000,0.00000000,0.00000000
110.09000000,2.43546600,2.38700000,0.08120144,213.85736102,0.07807287,231.22288765,0.00075219,0.08190820,237.08306422,-0.04580739,-0.03610081,0.00000000,0.00000000,0.00000000,0.00000000
111.59000000,2.47175700,2.39400000,0.08242122,214.48450871,0.07920040,232.16258407,0.00076510,0.08304153,238.03884375,-0.04649092,-0.03655061,0.00000000,0.00000000,0.00000000,0.00000000
113.09000000,2.50925700,2.40100000,0.08363356,215.11165640,0.08031980,233.10220906,0.00073675,0.08414446,238.89110582,-0.04708265,-0.03706181,0.00000000,0.00000000,0.00000000,0.00000000
114.59000000,2.54669000,2.40800000,0.08490189,215.73880408,0.08148956,234.05543606,0.00078404,0.08528343,239.75364698,-0.04773953,-0.03754390,0.00000000,0.00000000,0.00000000,0.00000000
116.09000000,2.58291400,2.41500000,0.08610678,216.36595177,0.08259954,234.99652670,0.00076250,0.08640739,240.61424042,-0.04835481,-0.03805258,0.00000000,0.00000000,0.00000000,0.00000000
117.59000000,2.61997700,2.42200000,0.08731900,216.99309946,0.08371503,235.94071991,0.00069296,0.08754153,241.38049698,-0.04900396,-0.03853757,0.00000000,0.00000000,0.00000000,0.00000000
119.09000000,2.65714200,2.42800000,0.08856500,217.53065462,0.08486032,236.79625704,0.00076098,0.08867317,242.24615986,-0.04963811,-0.03903505,0.00000000,0.00000000,0.00000000,0.00000000
120.59000000,2.69460800,2.43400000,0.08984444,218.06820978,0.08603497,237.66042693,0.00077376,0.08980819,243.01563532,-0.05026165,-0.03954655,0.00000000,0.00000000,0.00000000,0.00000000
122.09000000,2.73123500,2.44000000,0.09103444,218.60576494,0.08712628,238.50641930,0.00069773,0.09096066,243.88962834,-0.05091650,-0.04004416,0.00000000,0.00000000,0.00000000,0.00000000
123.59000000,2.76840000,2.44700000,0.09228400,219.23291262,0.08827092,239.46460273,0.00071036,0.09206925,244.65564794,-0.05151793,-0.04055133,0.00000000,0.00000000,0.00000000,0.00000000
125.09000000,2.80603400,2.45300000,0.09354478,219.77046778,0.08942451,240.32884735,0.00077764,0.09321388,245.43195531,-0.05214613,-0.04106775,0.00000000,0.00000000,0.00000000,0.00000000
126.59000000,2.84370100,2.45900000,0.09476467,220.30802294,0.09053942,241.18543930,0.00070225,0.09434552,246.30567098,-0.05278206,-0.04156346,0.00000000,0.00000000,0.00000000,0.00000000
128.09000000,2.88120100,2.46400000,0.09604400,220.75598557,0.09170733,241.95827345,0.00076269,0.09548545,246.98460867,-0.05340539,-0.04208006,0.00000000,0.00000000,0.00000000,0.00000000
129.59000000,2.91843300,2.46900000,0.09727878,221.20394821,0.09283328,242.72239793,0.00070733,0.09662935,247.76515035,-0.05406355,-0.04256580,0.00000000,0.00000000,0.00000000,0.00000000
131.09000000,2.95603300,2.47600000,0.09852844,221.83109589,0.09397151,243.68776870,0.00074720,0.09776171,248.54428947,-0.05466857,-0.04309314,0.00000000,0.00000000,0.00000000,0.00000000
132.59000000,2.99400300,2.48000000,0.09979289,222.18946600,0.09512188,244.36239469,0.00077363,0.09889433,249.22535802,-0.05531158,-0.04358275,0.00000000,0.00000000,0.00000000,0.00000000
134.09000000,3.03190600,2.48600000,0.10103878,222.72702116,0.09625408,245.23108716,0.00073883,0.10005629,250.11446025,-0.05597547,-0.04408082,0.00000000,0.00000000,0.00000000,0.00000000
135.59000000,3.06964100,2.49100000,0.10234433,223.17498379,0.09743912,246.01567873,0.00078535,0.10121297,250.80430731,-0.05662336,-0.04458961,0.00000000,0.00000000,0.00000000,0.00000000
137.09000000,3.10761100,2.49600000,0.10362011,223.62294643,0.09859579,246.79478098,0.00081808,0.10234139,251.48829552,-0.05723339,-0.04510800,0.00000000,0.00000000,0.00000000,0.00000000
138.59000000,3.14625200,2.50100000,0.10489211,224.07090906,0.09974769,247.57417975,0.00084430,0.10353405,252.28985243,-0.05790106,-0.04563299,0.00000000,0.00000000,0.00000000,0.00000000
140.09000000,3.18432300,2.50600000,0.10617156,224.51887169,0.10090500,248.35638955,0.00080956,0.10470310,252.98679150,-0.05856533,-0.04613777,0.00000000,0.00000000,0.00000000,0.00000000
141.59000000,3.22293000,2.51000000,0.10743978,224.87724180,0.10205084,249.03800268,0.00082871,0.10586102,253.68219559,-0.05922275,-0.04663827,0.00000000,0.00000000,0.00000000,0.00000000
143.09000000,3.26110200,2.51500000,0.10871178,225.32520443,0.10319878,249.82070798,0.00081432,0.10701737,254.37848227,-0.05985864,-0.04715873,0.00000000,0.00000000,0.00000000,0.00000000
144.59000000,3.29977700,2.52000000,0.11000256,225.77316706,0.10436232,250.60879242,0.00077312,0.10816908,255.07486561,-0.06049954,-0.04766954,0.00000000,0.00000000,0.00000000,0.00000000
146.09000000,3.33865400,2.52400000,0.11130444,226.13153717,0.10553450,251.30098229,0.00071160,0.10933941,255.77730703,-0.06118100,-0.04815841,0.00000000,0.00000000,0.00000000,0.00000000
147.59000000,3.37719400,2.52800000,0.11258378,226.48990728,0.10668504,251.98899667,0.00071058,0.11049967,256.37767955,-0.06181254,-0.04868713,0.00000000,0.00000000,0.00000000,0.00000000
149.09000000,3.41617100,2.53200000,0.11385211,226.84827738,0.10782438,252.67543267,0.00073692,0.11168378,257.08616790,-0.06246348,-0.04922029,0.00000000,0.00000000,0.00000000,0.00000000
150.59000000,3.45578700,2.53700000,0.11517267,227.29624002,0.10900925,253.47455410,0.00072269,0.11284989,257.79133313,-0.06310981,-0.04974008,0.00000000,0.00000000,0.00000000,0.00000000
152.09000000,3.49513300,2.54000000,0.11649322,227.56501760,0.11019272,254.07479976,0.00074194,0.11401938,258.39753393,-0.06374742,-0.05027196,0.00000000,0.00000000,0.00000000,0.00000000
153.59000000,3.53404300,2.54500000,0.11782489,228.01298023,0.11138473,254.87858429,0.00080112,0.11519062,259.00526436,-0.06442724,-0.05076338,0.00000000,0.00000000,0.00000000,0.00000000
155.09000000,3.57345600,2.54800000,0.11914911,228.28175781,0.11256867,255.48132634,0.00087347,0.11636045,259.61370860,-0.06510084,-0.05125961,0.00000000,0.00000000,0.00000000,0.00000000
156.59000000,3.61310500,2.55200000,0.12043967,228.64012792,0.11372117,256.17746871,0.00075243,0.11753404,260.32571940,-0.06573110,-0.05180294,0.00000000,0.00000000,0.00000000,0.00000000
158.09000000,3.65305500,2.55600000,0.12179756,228.99849802,0.11493236,256.88995531,0.00079808,0.11870450,260.93661010,-0.06642335,-0.05228116,0.00000000,0.00000000,0.00000000,0.00000000
159.59000000,3.69287200,2.55900000,0.12308078,229.26727560,0.11607560,257.48567020,0.00075085,0.11988668,261.55165826,-0.06706915,-0.05281752,0.00000000,0.00000000,0.00000000,0.00000000
161.09000000,3.73218500,2.56300000,0.12440500,229.62564571,0.11725401,258.19222416,0.00080948,0.12107387,262.16912739,-0.06774247,-0.05333140,0.00000000,0.00000000,0.00000000,0.00000000
162.59000000,3.77237000,2.56700000,0.12573667,229.98401582,0.11843764,258.90143935,0.00073565,0.12225973,262.78735010,-0.06842146,-0.05383827,0.00000000,0.00000000,0.00000000,0.00000000
164.09000000,3.81279100,2.57000000,0.12707578,230.25279340,0.11962647,259.51234620,0.00082097,0.12341140,263.39764108,-0.06904799,-0.05436341,0.00000000,0.00000000,0.00000000,0.00000000
165.59000000,3.85267500,2.57300000,0.12840756,230.52157097,0.12080740,260.12228241,0.00078691,0.12462383,264.02510198,-0.06972522,-0.05489861,0.00000000,0.00000000,0.00000000,0.00000000
167.09000000,3.89289400,2.57600000,0.12975789,230.79034855,0.12200335,260.73721696,0.00085228,0.12583299,264.55047082,-0.07040499,-0.05542800,0.00000000,0.00000000,0.00000000,0.00000000
168.59000000,3.93287900,2.58000000,0.13108956,231.14871866,0.12318138,261.44990146,0.00084440,0.12706526,265.18537363,-0.07109622,-0.05596904,0.00000000,0.00000000,0.00000000,0.00000000
170.09000000,3.97353400,2.58300000,0.13239133,231.41749624,0.12433162,262.05516713,0.00073133,0.12832197,265.82797287,-0.07181022,-0.05651175,0.00000000,0.00000000,0.00000000,0.00000000
171.59000000,4.01476100,2.58500000,0.13376789,231.59668129,0.12554650,262.57688042,0.00078319,0.12953628,266.35768388,-0.07249406,-0.05704222,0.00000000,0.00000000,0.00000000,0.00000000
173.09000000,4.05534900,2.58800000,0.13512200,231.86545887,0.12674013,263.19558341,0.00078891,0.13074764,266.99038638,-0.07313862,-0.05760902,0.00000000,0.00000000,0.00000000,0.00000000
174.59000000,4.09617300,2.59100000,0.13648356,232.13423645,0.12793889,263.81674241,0.00088656,0.13201742,267.53692326,-0.07388497,-0.05813245,0.00000000,0.00000000,0.00000000,0.00000000
176.09000000,4.13756700,2.59400000,0.13788989,232.40301403,0.12917557,264.44903982,0.00084599,0.13321433,268.06481695,-0.07453804,-0.05867629,0.00000000,0.00000000,0.00000000,0.00000000
177.59000000,4.17876000,2.59600000,0.13929233,232.58219909,0.13040731,264.97911629,0.00087091,0.13446136,268.60711091,-0.07527404,-0.05918732,0.00000000,0.00000000,0.00000000,0.00000000
179.09000000,4.22079300,2.59800000,0.14068756,232.76138414,0.13163120,265.50801430,0.00077200,0.13565376,269.23897743,-0.07593194,-0.05972182,0.00000000,0.00000000,0.00000000,0.00000000
180.59000000,4.26201900,2.60100000,0.14205656,233.03016172,0.13283063,266.13362383,0.00072514,0.13685894,269.77192692,-0.07660105,-0.06025789,0.00000000,0.00000000,0.00000000,0.00000000
182.09000000,4.30512600,2.60400000,0.14352244,233.29893930,0.13411336,266.78257335,0.00078934,0.13800156,270.28880123,-0.07724767,-0.06075389,0.00000000,0.00000000,0.00000000,0.00000000
183.59000000,4.34692300,2.60600000,0.14491389,233.47812435,0.13532943,267.31234732,0.00077556,0.13919102,270.81924300,-0.07792236,-0.06126865,0.00000000,0.00000000,0.00000000,0.00000000
185.09000000,4.38919000,2.60900000,0.14634644,233.74690193,0.13657988,267.95492993,0.00078778,0.14036619,271.34668179,-0.07857067,-0.06179553,0.00000000,0.00000000,0.00000000,0.00000000
186.59000000,4.43105500,2.61100000,0.14772667,233.92608699,0.13778317,268.48320806,0.00070858,0.14157213,271.88338656,-0.07925588,-0.06231625,0.00000000,0.00000000,0.00000000,0.00000000
188.09000000,4.47419500,2.61300000,0.14919644,234.10527204,0.13906295,269.03294625,0.00090267,0.14275431,272.41450308,-0.07991527,-0.06283904,0.00000000,0.00000000,0.00000000,0.00000000
189.59000000,4.51609300,2.61600000,0.15056533,234.37404962,0.14025342,269.66265652,0.00088865,0.14396381,272.95398743,-0.08058881,-0.06337499,0.00000000,0.00000000,0.00000000,0.00000000
191.09000000,4.55913300,2.61700000,0.15193433,234.46364215,0.14144256,270.08671931,0.00080982,0.14521171,273.40053391,-0.08131866,-0.06389305,0.00000000,0.00000000,0.00000000,0.00000000
192.59000000,4.60136600,2.61900000,0.15333322,234.64282720,0.14265620,270.62136796,0.00087996,0.14644204,273.84294270,-0.08198603,-0.06445601,0.00000000,0.00000000,0.00000000,0.00000000
194.09000000,4.64370100,2.62200000,0.15467611,234.91160478,0.14381988,271.24681826,0.00077555,0.14766272,274.38802624,-0.08266682,-0.06499590,0.00000000,0.00000000,0.00000000,0.00000000
195.59000000,4.68633700,2.62300000,0.15602633,235.00119731,0.14498855,271.66757245,0.00079387,0.14898751,274.96277916,-0.08346001,-0.06552751,0.00000000,0.00000000,0.00000000,0.00000000
197.09000000,4.72924200,2.62500000,0.15740289,235.18038236,0.14617861,272.19845395,0.00074779,0.15029597,275.42912642,-0.08419589,-0.06610008,0.00000000,0.00000000,0.00000000,0.00000000
198.59000000,4.77245000,2.62700000,0.15879444,235.35956741,0.14738019,272.73335916,0.00078564,0.15160425,276.00125297,-0.08492153,-0.06668272,0.00000000,0.00000000,0.00000000,0.00000000
200.09000000,4.81555700,2.62900000,0.16023444,235.53875247,0.14862209,273.28017361,0.00077835,0.15300130,276.49383891,-0.08569750,-0.06730379,0.00000000,0.00000000,0.00000000,0.00000000
201.59000000,4.85973800,2.63000000,0.16168544,235.62834499,0.14987192,273.72601868,0.00082847,0.15436296,277.08279511,-0.08645470,-0.06790826,0.00000000,0.00000000,0.00000000,0.00000000
203.09000000,4.90324700,2.63200000,0.16315878,235.80753005,0.15113939,274.28159844,0.00087234,0.15578791,277.58497281,-0.08726452,-0.06852338,0.00000000,0.00000000,0.00000000,0.00000000
204.59000000,4.94746200,2.63300000,0.16462489,235.89712257,0.15239905,274.73166016,0.00088441,0.15727391,278.10507258,-0.08811484,-0.06915907,0.00000000,0.00000000,0.00000000,0.00000000
206.09000000,4.99214700,2.63500000,0.16615811,236.07630762,0.15371468,275.30230098,0.00093434,0.15872609,278.61664622,-0.08892086,-0.06980523,0.00000000,0.00000000,0.00000000,0.00000000
207.59000000,5.03703300,2.63600000,0.16773600,236.16590015,0.15506683,275.77942358,0.00099058,0.16023924,279.14621457,-0.08978322,-0.07045602,0.00000000,0.00000000,0.00000000,0.00000000
209.09000000,5.08252400,2.63800000,0.16931389,236.34508520,0.15641716,276.36159070,0.00095730,0.16165565,279.64958919,-0.09059356,-0.07106209,0.00000000,0.00000000,0.00000000,0.00000000
210.59000000,5.12845000,2.63900000,0.17095500,236.43467773,0.15781966,276.85436806,0.00095576,0.16307003,280.15326461,-0.09135238,-0.07171766,0.00000000,0.00000000,0.00000000,0.00000000
212.09000000,5.17444400,2.64000000,0.17263367,236.52427026,0.15925222,277.35632229,0.00095458,0.16445097,280.64838717,-0.09211997,-0.07233100,0.00000000,0.00000000,0.00000000,0.00000000
213.59000000,5.22188200,2.64200000,0.17434967,236.70345531,0.16071452,277.97262384,0.00101680,0.16582988,281.14377746,-0.09291868,-0.07291120,0.00000000,0.00000000,0.00000000,0.00000000
215.09000000,5.26935300,2.64300000,0.17606556,236.79304784,0.16217459,278.48414736,0.00088828,0.16708172,281.60407322,-0.09359723,-0.07348449,0.00000000,0.00000000,0.00000000,0.00000000
216.59000000,5.31662300,2.64400000,0.17781878,236.88264036,0.16366423,279.00482195,0.00095038,0.16833196,282.06463633,-0.09435485,-0.07397712,0.00000000,0.00000000,0.00000000,0.00000000
218.09000000,5.36379100,2.64500000,0.17953478,236.97223289,0.16512010,279.51699006,0.00094919,0.16951970,282.40119265,-0.09502540,-0.07449430,0.00000000,0.00000000,0.00000000,0.00000000
219.59000000,5.41109400,2.64600000,0.18121344,237.06182542,0.16654225,280.02061535,0.00088441,0.17064206,282.82670839,-0.09568805,-0.07495401,0.00000000,0.00000000,0.00000000,0.00000000
221.09000000,5.45900100,2.64700000,0.18289200,237.15141794,0.16796229,280.52451507,0.00094612,0.17173196,283.24359438,-0.09633813,-0.07539383,0.00000000,0.00000000,0.00000000,0.00000000
222.59000000,5.50784800,2.64800000,0.18449600,237.24101047,0.16931737,281.01102794,0.00088177,0.17282056,283.66068790,-0.09702525,-0.07579531,0.00000000,0.00000000,0.00000000,0.00000000
224.09000000,5.55619100,2.64800000,0.18606267,237.24101047,0.17063914,281.38270552,0.00081781,0.17381486,284.05146340,-0.09758885,-0.07622601,0.00000000,0.00000000,0.00000000,0.00000000
225.59000000,5.60406400,2.65000000,0.18755478,237.42019552,0.17189638,281.94948754,0.00081697,0.17484049,284.34411597,-0.09821220,-0.07662829,0.00000000,0.00000000,0.00000000,0.00000000
227.09000000,5.65318100,2.65000000,0.18900978,237.42019552,0.17312084,282.29493392,0.00081597,0.17589603,284.64561919,-0.09884106,-0.07705496,0.00000000,0.00000000,0.00000000,0.00000000
228.59000000,5.70209600,2.65100000,0.19038989,237.50978805,0.17428089,282.72925021,0.00081484,0.17688715,285.03680603,-0.09940635,-0.07748080,0.00000000,0.00000000,0.00000000,0.00000000
230.09000000,5.75053900,2.65200000,0.19165811,237.59938058,0.17534571,283.13722906,0.00075166,0.17790818,285.43706408,-0.10003760,-0.07787058,0.00000000,0.00000000,0.00000000,0.00000000
231.59000000,5.80029400,2.65300000,0.19296367,237.68897310,0.17644069,283.55430888,0.00068785,0.00000000,0.00000000,0.00000000,0.00000000,0.00000000,0.00000000,0.00000000,0.00000000
233.09000000,5.84830200,2.65400000,0.19419467,237.77856563,0.17747204,283.95389492,0.00062497,0.00000000,0.00000000,0.00000000,0.00000000,0.00000000,0.00000000,0.00000000,0.00000000
234.59000000,5.89671300,2.65400000,0.19546278,237.77856563,0.17853337,284.25542456,0.00068642,0.00000000,0.00000000,0.00000000,0.00000000,0.00000000,0.00000000,0.00000000,0.00000000
236.09000000,5.94462000,2.65400000,0.19669367,237.77856563,0.17956248,284.54810356,0.00074813,0.00000000,0.00000000,0.00000000,0.00000000,0.00000000,0.00000000,0.00000000,0.00000000
237.59000000,5.99209100,2.65500000,0.19788711,237.86815816,0.18055926,284.93920080,0.00068521,0.00000000,0.00000000,0.00000000,0.00000000,0.00000000,0.00000000,0.00000000,0.00000000
239.08000000,6.04053500,2.65500000,0.19915544,237.86815816,0.18161751,285.24089691,0.00076202,0.00000000,0.00000000,0.00000000,0.00000000,0.00000000,0.00000000,0.00000000,0.00000000
240.59000000,6.08958400,2.65600000,0.20042367,237.95775068,0.00000000,0.00000000,0.00000000,0.00000000,0.00000000,0.00000000,0.00000000,0.00000000,0.00000000,0.00000000,0.00000000
242.09000000,6.13906900,2.65600000,0.20172900,237.95775068,0.00000000,0.00000000,0.00000000,0.00000000,0.00000000,0.00000000,0.00000000,0.00000000,0.00000000,0.00000000,0.00000000
243.59000000,6.18895700,2.65600000,0.20299711,237.95775068,0.00000000,0.00000000,0.00000000,0.00000000,0.00000000,0.00000000,0.00000000,0.00000000,0.00000000,0.00000000,0.00000000
245.09000000,6.23992000,2.65600000,0.20437722,237.95775068,0.00000000,0.00000000,0.00000000,0.00000000,0.00000000,0.00000000,0.00000000,0.00000000,0.00000000,0.00000000,0.00000000
246.59000000,6.29185600,2.65600000,0.20575744,237.95775068,0.00000000,0.00000000,0.00000000,0.00000000,0.00000000,0.00000000,0.00000000,0.00000000,0.00000000,0.00000000,0.00000000
248.09000000,6.34476500,2.65600000,0.20728700,237.95775068,0.00000000,0.00000000,0.00000000,0.00000000,0.00000000,0.00000000,0.00000000,0.00000000,0.00000000,0.00000000,0.00000000
249.59000000,6.39750700,2.65600000,0.20889133,237.95775068,0.00000000,0.00000000,0.00000000,0.00000000,0.00000000,0.00000000,0.00000000,0.00000000,0.00000000,0.00000000,0.00000000
251.09000000,6.45058500,2.65600000,0.21079422,237.95775068,0.00000000,0.00000000,0.00000000,0.00000000,0.00000000,0.00000000,0.00000000,0.00000000,0.00000000,0.00000000,0.00000000
252.59000000,6.50584600,2.65500000,0.21299556,237.86815816,0.00000000,0.00000000,0.00000000,0.00000000,0.00000000,0.00000000,0.00000000,0.00000000,0.00000000,0.00000000,0.00000000
254.09000000,6.56103800,2.65500000,0.21549500,237.86815816,0.00000000,0.00000000,0.00000000,0.00000000,0.00000000,0.00000000,0.00000000,0.00000000,0.00000000,0.00000000,0.00000000
255.59000000,6.61636400,2.65500000,0.21821800,237.86815816,0.00000000,0.00000000,0.00000000,0.00000000,0.00000000,0.00000000,0.00000000,0.00000000,0.00000000,0.00000000,0.00000000
257.08000000,6.67246300,2.65400000,0.22101522,237.77856563,0.00000000,0.00000000,0.00000000,0.00000000,0.00000000,0.00000000,0.00000000,0.00000000,0.00000000,0.00000000,0.00000000
258.58000000,6.72873000,2.65300000,0.22355144,237.68897310,0.00000000,0.00000000,0.00000000,0.00000000,0.00000000,0.00000000,0.00000000,0.00000000,0.00000000,0.00000000,0.00000000
260.08000000,6.78553400,2.65200000,0.22571467,237.59938058,0.00000000,0.00000000,0.00000000,0.00000000,0.00000000,0.00000000,0.00000000,0.00000000,0.00000000,0.00000000,0.00000000
261.58000000,6.84274000,2.65000000,0.22757967,237.42019552,0.00000000,0.00000000,0.00000000,0.00000000,0.00000000,0.00000000,0.00000000,0.00000000,0.00000000,0.00000000,0.00000000
263.08000000,6.89940900,2.64800000,0.22933289,237.24101047,0.00000000,0.00000000,0.00000000,0.00000000,0.00000000,0.00000000,0.00000000,0.00000000,0.00000000,0.00000000,0.00000000
264.58000000,6.95792700,2.64600000,0.23097444,237.06182542,0.00000000,0.00000000,0.00000000,0.00000000,0.00000000,0.00000000,0.00000000,0.00000000,0.00000000,0.00000000,0.00000000
266.08000000,7.01701500,2.64200000,0.23239189,236.70345531,0.00000000,0.00000000,0.00000000,0.00000000,0.00000000,0.00000000,0.00000000,0.00000000,0.00000000,0.00000000,0.00000000
267.58000000,7.07603500,2.63900000,0.23358578,236.43467773,0.00000000,0.00000000,0.00000000,0.00000000,0.00000000,0.00000000,0.00000000,0.00000000,0.00000000,0.00000000,0.00000000
269.08000000,7.13407900,2.63400000,0.23440667,235.98671510,0.00000000,0.00000000,0.00000000,0.00000000,0.00000000,0.00000000,0.00000000,0.00000000,0.00000000,0.00000000,0.00000000
270.58000000,7.19403900,2.62700000,0.23504111,235.35956741,0.00000000,0.00000000,0.00000000,0.00000000,0.00000000,0.00000000,0.00000000,0.00000000,0.00000000,0.00000000,0.00000000
272.08000000,7.25379700,2.61800000,0.23541411,234.55323467,0.00000000,0.00000000,0.00000000,0.00000000,0.00000000,0.00000000,0.00000000,0.00000000,0.00000000,0.00000000,0.00000000
273.58000000,7.31425900,2.60700000,0.23575044,233.56771688,0.00000000,0.00000000,0.00000000,0.00000000,0.00000000,0.00000000,0.00000000,0.00000000,0.00000000,0.00000000,0.00000000
275.08000000,7.37612800,2.58900000,0.23597500,231.95505140,0.00000000,0.00000000,0.00000000,0.00000000,0.00000000,0.00000000,0.00000000,0.00000000,0.00000000,0.00000000,0.00000000
276.58000000,7.43836500,2.56400000,0.23605044,229.71523824,0.00000000,0.00000000,0.00000000,0.00000000,0.00000000,0.00000000,0.00000000,0.00000000,0.00000000,0.00000000,0.00000000
278.09000000,7.50241700,2.52700000,0.23605167,226.40031475,0.00000000,0.00000000,0.00000000,0.00000000,0.00000000,0.00000000,0.00000000,0.00000000,0.00000000,0.00000000,0.00000000
279.58000000,7.56906000,2.46900000,0.23590378,221.20394821,0.00000000,0.00000000,0.00000000,0.00000000,0.00000000,0.00000000,0.00000000,0.00000000,0.00000000,0.00000000,0.00000000
281.08000000,7.63732800,2.39100000,0.23579322,214.21573113,0.00000000,0.00000000,0.00000000,0.00000000,0.00000000,0.00000000,0.00000000,0.00000000,0.00000000,0.00000000,0.00000000
282.58000000,7.71091800,2.28200000,0.23553344,204.45014573,0.00000000,0.00000000,0.00000000,0.00000000,0.00000000,0.00000000,0.00000000,0.00000000,0.00000000,0.00000000,0.00000000
284.08000000,8.07146700,0.12600000,0.23105067,11.28865835,0.00000000,0.00000000,0.00000000,0.00000000,0.00000000,0.00000000,0.00000000,0.00000000,0.00000000,0.00000000,0.00000000
NaN,-100.00000000,NaN,-11.11111111,NaN,0.00000000,0.00000000,0.00000000,0.00000000,0.00000000,0.00000000,0.00000000,0.00000000,0.00000000,0.00000000,0.00000000