File: polyN_optimization/results_exp/AA6014-T4/UT_15_1.csv
Time[s],Displacement[mm],Force[kN],EngStrain_longi,EngStress[MPa],TrueStrain,TrueStress[MPa],TrueStrainRate[1/s],PlasticStrain_longi,PlasticStress[MPa],PlasticStrain_thick,PlasticStrain_width,R-Value,Thickness[mm],Width[mm], Young's Modulus [MPa]
0.60000000,0.00000000,-0.00100000,0.00000000,-0.09006775,0.00000000,-0.09006775,0.00000000,0.00085692,119.73397170,-0.00028202,-0.00057491,0.69287549,1.11240000,9.98090000,80628.72602891
2.10000000,0.00674200,0.16100000,0.00020811,14.50090781,0.00020809,14.50392561,0.00014086,0.00202350,124.40203635,-0.00103103,-0.00099247,0.00000000,0.00000000,0.00000000,0.00000000
3.60000000,0.01463100,0.40300000,0.00047789,36.29730340,0.00047777,36.31464948,0.00014038,0.00324570,127.90969587,-0.00183709,-0.00140861,0.00000000,0.00000000,0.00000000,0.00000000
5.10000000,0.02405200,0.65800000,0.00083078,59.26457974,0.00083043,59.31381544,0.00037728,0.00444078,131.15011506,-0.00253575,-0.00190503,0.00000000,0.00000000,0.00000000,0.00000000
6.60000000,0.03279400,0.90400000,0.00109556,81.42124633,0.00109496,81.51044783,0.00032789,0.00561503,133.85008512,-0.00320400,-0.00241103,0.00000000,0.00000000,0.00000000,0.00000000
8.10000000,0.04359500,1.13800000,0.00134633,102.49709992,0.00134543,102.63509518,0.00014470,0.00678956,136.46543137,-0.00388246,-0.00290710,0.00000000,0.00000000,0.00000000,0.00000000
9.60000000,0.06692400,1.30200000,0.00213800,117.26821098,0.00213572,117.51893041,0.00035150,0.00798439,139.08976222,-0.00457889,-0.00340550,0.00000000,0.00000000,0.00000000,0.00000000
11.10000000,0.10203600,1.36300000,0.00335900,122.76234375,0.00335337,123.17470246,0.00072503,0.00914758,141.44209849,-0.00524505,-0.00390253,0.00000000,0.00000000,0.00000000,0.00000000
12.60000000,0.13853200,1.40200000,0.00458744,126.27498601,0.00457695,126.85426550,0.00085648,0.01028843,143.70529008,-0.00592907,-0.00435936,0.00000000,0.00000000,0.00000000,0.00000000
14.10000000,0.17517300,1.43800000,0.00578633,129.51742503,0.00576966,130.26685602,0.00085921,0.01149844,146.16669732,-0.00665671,-0.00484174,0.00000000,0.00000000,0.00000000,0.00000000
15.60000000,0.21328500,1.46700000,0.00709011,132.12938979,0.00706509,133.06620184,0.00086693,0.01266063,148.26051093,-0.00739101,-0.00526962,0.00000000,0.00000000,0.00000000,0.00000000
17.10000000,0.24962700,1.49400000,0.00837400,134.56121905,0.00833913,135.68803470,0.00092271,0.01377237,150.44322190,-0.00805328,-0.00571909,0.00000000,0.00000000,0.00000000,0.00000000
18.60000000,0.28656000,1.52200000,0.00955467,137.08311606,0.00950931,138.39289954,0.00093066,0.01493025,152.63779959,-0.00876411,-0.00616614,0.00000000,0.00000000,0.00000000,0.00000000
20.10000000,0.32360400,1.54600000,0.01079756,139.24474207,0.01073968,140.74824491,0.00092930,0.01604907,154.64748439,-0.00947219,-0.00657688,0.00000000,0.00000000,0.00000000,0.00000000
21.60000000,0.36076500,1.56900000,0.01207633,141.31630033,0.01200400,143.02288307,0.00085673,0.01721034,156.66825591,-0.01020838,-0.00700196,0.00000000,0.00000000,0.00000000,0.00000000
23.10000000,0.39669200,1.59400000,0.01329511,143.56799408,0.01320751,145.47674652,0.00089848,0.01828140,158.77142516,-0.01085826,-0.00742315,0.00000000,0.00000000,0.00000000,0.00000000
24.60000000,0.43158700,1.61600000,0.01443656,145.54948459,0.01433334,147.65071781,0.00085342,0.01941563,160.70472992,-0.01155037,-0.00786526,0.00000000,0.00000000,0.00000000,0.00000000
26.10000000,0.46860000,1.63700000,0.01566378,147.44090735,0.01554237,149.75038896,0.00082284,0.02056796,162.55291188,-0.01225583,-0.00831213,0.00000000,0.00000000,0.00000000,0.00000000
27.60000000,0.50386100,1.66000000,0.01684256,149.51246561,0.01670229,152.03063762,0.00076329,0.02165087,164.57873453,-0.01288700,-0.00876387,0.00000000,0.00000000,0.00000000,0.00000000
29.10000000,0.53927000,1.68000000,0.01803256,151.31382062,0.01787190,154.04239549,0.00076240,0.02274721,166.33339323,-0.01352934,-0.00921787,0.00000000,0.00000000,0.00000000,0.00000000
30.60000000,0.57464200,1.70000000,0.01919633,153.11517562,0.01901441,156.05442557,0.00076873,0.02387366,168.18954551,-0.01420485,-0.00966880,0.00000000,0.00000000,0.00000000,0.00000000
32.10000000,0.60976600,1.72100000,0.02034900,155.00659838,0.02014473,158.16082765,0.00065805,0.02500228,170.05013882,-0.01486101,-0.01014127,0.00000000,0.00000000,0.00000000,0.00000000
33.60000000,0.64437300,1.74000000,0.02153900,156.71788564,0.02131031,160.09343218,0.00073040,0.02609463,171.81566793,-0.01549561,-0.01059902,0.00000000,0.00000000,0.00000000,0.00000000
35.10000000,0.67960400,1.75900000,0.02269167,158.42917290,0.02243804,162.02419488,0.00073697,0.02720151,173.49446524,-0.01612142,-0.01108009,0.00000000,0.00000000,0.00000000,0.00000000
36.60000000,0.71450600,1.77800000,0.02387422,160.14046015,0.02359369,163.96368908,0.00074350,0.02828771,175.26632716,-0.01677184,-0.01151587,0.00000000,0.00000000,0.00000000,0.00000000
38.10000000,0.74931100,1.79600000,0.02502689,161.76167966,0.02471885,165.81007124,0.00070623,0.02936663,176.94741699,-0.01738792,-0.01197871,0.00000000,0.00000000,0.00000000,0.00000000
39.60000000,0.78436100,1.81300000,0.02620189,163.29283142,0.02586450,167.57141204,0.00073445,0.03046242,178.63503132,-0.01804477,-0.01241765,0.00000000,0.00000000,0.00000000,0.00000000
41.10000000,0.81914200,1.83200000,0.02736578,165.00411867,0.02699803,169.51958472,0.00077733,0.03158561,180.33116842,-0.01873506,-0.01285055,0.00000000,0.00000000,0.00000000,0.00000000
42.60000000,0.85409100,1.84900000,0.02853711,166.53527043,0.02813751,171.28770594,0.00076196,0.03270644,181.84345877,-0.01940447,-0.01330197,0.00000000,0.00000000,0.00000000,0.00000000
44.10000000,0.88883800,1.86500000,0.02969722,167.97635443,0.02926480,172.96478556,0.00075376,0.03377811,183.44358869,-0.02005333,-0.01372478,0.00000000,0.00000000,0.00000000,0.00000000
45.60000000,0.92308200,1.88200000,0.03084989,169.50750619,0.03038360,174.73679392,0.00077470,0.03484129,185.04543628,-0.02067909,-0.01416220,0.00000000,0.00000000,0.00000000,0.00000000
47.10000000,0.95799800,1.89800000,0.03200622,170.94859020,0.03150470,176.42000876,0.00080248,0.03595105,186.56541791,-0.02138921,-0.01456184,0.00000000,0.00000000,0.00000000,0.00000000
48.60000000,0.99261000,1.91400000,0.03316633,172.38967420,0.03262820,178.10720760,0.00075102,0.03705236,188.08701706,-0.02205991,-0.01499245,0.00000000,0.00000000,0.00000000,0.00000000
50.10000000,1.02735800,1.93000000,0.03430778,173.83075821,0.03373239,179.79450523,0.00075019,0.03813811,189.60885049,-0.02270662,-0.01543150,0.00000000,0.00000000,0.00000000,0.00000000
51.60000000,1.06207200,1.94500000,0.03549778,175.18177446,0.03488226,181.40033816,0.00077831,0.03923827,191.04241565,-0.02335909,-0.01587918,0.00000000,0.00000000,0.00000000,0.00000000
53.10000000,1.09621600,1.95900000,0.03664300,176.44272297,0.03598761,182.90811367,0.00074850,0.04031559,192.47455666,-0.02398999,-0.01632560,0.00000000,0.00000000,0.00000000,0.00000000
54.60000000,1.13136600,1.97500000,0.03779567,177.88380697,0.03709891,184.60704405,0.00074788,0.04140826,194.00699574,-0.02461908,-0.01678918,0.00000000,0.00000000,0.00000000,0.00000000
56.10000000,1.16560900,1.98900000,0.03894822,179.14475548,0.03820888,186.12212523,0.00072522,0.04250579,195.35458005,-0.02527787,-0.01722792,0.00000000,0.00000000,0.00000000,0.00000000
57.60000000,1.20055900,2.00300000,0.04010100,180.40570398,0.03931782,187.64015312,0.00073169,0.04358078,196.70049418,-0.02589364,-0.01768714,0.00000000,0.00000000,0.00000000,0.00000000
59.10000000,1.23480300,2.01700000,0.04124244,181.66665249,0.04041466,189.15902931,0.00069523,0.04466738,198.14614120,-0.02651379,-0.01815358,0.00000000,0.00000000,0.00000000,0.00000000
60.60000000,1.26965200,2.03100000,0.04240633,182.92760100,0.04153182,190.68488982,0.00073007,0.04576829,199.50280582,-0.02717606,-0.01859223,0.00000000,0.00000000,0.00000000,0.00000000
62.10000000,1.30480200,2.04300000,0.04358889,184.00841400,0.04266563,192.02913631,0.00077227,0.04688685,200.77089840,-0.02782147,-0.01906537,0.00000000,0.00000000,0.00000000,0.00000000
63.60000000,1.33887700,2.05700000,0.04473400,185.26936250,0.04376231,193.55720217,0.00076419,0.04796042,202.12754122,-0.02844726,-0.01951316,0.00000000,0.00000000,0.00000000,0.00000000
65.10000000,1.37375900,2.06900000,0.04590911,186.35017551,0.04488647,194.90534642,0.00080627,0.04904104,203.39321827,-0.02909319,-0.01994785,0.00000000,0.00000000,0.00000000,0.00000000
66.60000000,1.40844000,2.08200000,0.04705800,187.52105626,0.04598433,196.34542213,0.00073404,0.05015583,204.66845440,-0.02977428,-0.02038155,0.00000000,0.00000000,0.00000000,0.00000000
68.10000000,1.44322100,2.09400000,0.04822189,188.60186927,0.04709529,197.69660765,0.00071902,0.05121987,205.93584646,-0.03037044,-0.02084943,0.00000000,0.00000000,0.00000000,0.00000000
69.60000000,1.47806900,2.10600000,0.04938578,189.68268227,0.04820502,199.05030907,0.00076101,0.05230735,207.21062007,-0.03103563,-0.02127172,0.00000000,0.00000000,0.00000000,0.00000000
71.10000000,1.51308500,2.11800000,0.05057944,190.76349528,0.04934186,200.41220689,0.00078850,0.05338791,208.39095391,-0.03168713,-0.02170077,0.00000000,0.00000000,0.00000000,0.00000000
72.60000000,1.54810200,2.13000000,0.05173578,191.84430828,0.05044192,201.76952278,0.00070943,0.05453617,209.68354990,-0.03239713,-0.02213904,0.00000000,0.00000000,0.00000000,0.00000000
74.10000000,1.58318500,2.14100000,0.05290722,192.83505354,0.05155512,203.03742057,0.00071582,0.05563540,210.87272063,-0.03306969,-0.02256570,0.00000000,0.00000000,0.00000000,0.00000000
75.60000000,1.61830300,2.15200000,0.05407478,193.82579879,0.05266339,204.30688579,0.00073633,0.05673104,211.96763476,-0.03371096,-0.02302008,0.00000000,0.00000000,0.00000000,0.00000000
77.10000000,1.65338700,2.16300000,0.05523122,194.81654404,0.05375991,205.57649988,0.00071424,0.05785076,213.26189036,-0.03438534,-0.02346542,0.00000000,0.00000000,0.00000000,0.00000000
78.60000000,1.68830200,2.17400000,0.05641367,195.80728930,0.05487984,206.85349645,0.00069219,0.05893688,214.35936326,-0.03501474,-0.02392214,0.00000000,0.00000000,0.00000000,0.00000000
80.10000000,1.72352000,2.18400000,0.05760733,196.70796680,0.05600912,208.03978821,0.00074059,0.06002529,215.45949936,-0.03565580,-0.02436948,0.00000000,0.00000000,0.00000000,0.00000000
81.60000000,1.75863700,2.19500000,0.05873022,197.69871206,0.05707029,209.30960135,0.00076122,0.06112648,216.56458711,-0.03631483,-0.02481165,0.00000000,0.00000000,0.00000000,0.00000000
83.10000000,1.79446100,2.20400000,0.05991656,198.50932181,0.05819018,210.40331662,0.00068298,0.06225753,217.67840141,-0.03697013,-0.02528740,0.00000000,0.00000000,0.00000000,0.00000000
84.60000000,1.82984800,2.21400000,0.06112522,199.40999931,0.05932988,211.59897983,0.00068911,0.06336651,218.78964976,-0.03761544,-0.02575107,0.00000000,0.00000000,0.00000000,0.00000000
86.10000000,1.86560400,2.22500000,0.06233756,200.40074457,0.06047172,212.89323711,0.00074462,0.06446363,219.90051616,-0.03825245,-0.02621119,0.00000000,0.00000000,0.00000000,0.00000000
87.60000000,1.90105700,2.23400000,0.06352378,201.21135432,0.06158771,213.99305968,0.00070846,0.06558536,220.92227278,-0.03892851,-0.02665686,0.00000000,0.00000000,0.00000000,0.00000000
89.10000000,1.93637700,2.24300000,0.06468411,202.02196407,0.06267815,215.08957524,0.00067303,0.06669184,221.94267744,-0.03958212,-0.02710971,0.00000000,0.00000000,0.00000000,0.00000000
90.60000000,1.97176400,2.25300000,0.06588156,202.92264158,0.06380221,216.29150086,0.00074214,0.06778865,223.05993222,-0.04020975,-0.02757890,0.00000000,0.00000000,0.00000000,0.00000000
92.10000000,2.00788900,2.26200000,0.06708644,203.73325133,0.06493199,217.40099078,0.00076922,0.06890278,224.08619533,-0.04086136,-0.02804142,0.00000000,0.00000000,0.00000000,0.00000000
93.60000000,2.04398100,2.27000000,0.06830633,204.45379333,0.06607453,218.41928229,0.00078249,0.07002758,225.01969214,-0.04154152,-0.02848605,0.00000000,0.00000000,0.00000000,0.00000000
95.10000000,2.08030600,2.27900000,0.06951111,205.26440309,0.06720164,219.53255982,0.00071156,0.07114270,226.05016426,-0.04218960,-0.02895310,0.00000000,0.00000000,0.00000000,0.00000000
96.60000000,2.11589300,2.28800000,0.07073100,206.07501284,0.06834159,220.65090457,0.00080148,0.07226340,227.08395653,-0.04287409,-0.02938931,0.00000000,0.00000000,0.00000000,0.00000000
98.10000000,2.15191800,2.29600000,0.07188378,206.79555484,0.06941764,221.66080055,0.00073114,0.07337381,228.01990418,-0.04351382,-0.02985998,0.00000000,0.00000000,0.00000000,0.00000000
99.60000000,2.18810900,2.30400000,0.07310356,207.51609685,0.07055497,222.68626136,0.00076491,0.07448979,228.95895754,-0.04419045,-0.03029934,0.00000000,0.00000000,0.00000000,0.00000000
101.10000000,2.22413200,2.31200000,0.07432700,208.23663885,0.07169442,223.71424350,0.00071520,0.07559625,229.99542295,-0.04485816,-0.03073809,0.00000000,0.00000000,0.00000000,0.00000000
102.60000000,2.26042300,2.32000000,0.07552822,208.95718085,0.07281191,224.73934524,0.00073548,0.07669395,230.83613788,-0.04550304,-0.03119091,0.00000000,0.00000000,0.00000000,0.00000000
104.10000000,2.29691700,2.32800000,0.07674433,209.67772285,0.07394198,225.76929991,0.00073465,0.07784586,231.88703725,-0.04620175,-0.03164412,0.00000000,0.00000000,0.00000000,0.00000000
105.60000000,2.33361400,2.33600000,0.07796044,210.39826486,0.07507078,226.80100710,0.00074063,0.07898538,232.74096018,-0.04687326,-0.03211212,0.00000000,0.00000000,0.00000000,0.00000000
107.10000000,2.37004000,2.34300000,0.07920633,211.02873911,0.07622589,227.74355176,0.00081579,0.08007785,233.68374525,-0.04749723,-0.03258062,0.00000000,0.00000000,0.00000000,0.00000000
108.60000000,2.40629800,2.35000000,0.08040011,211.65921336,0.07733145,228.67663763,0.00075974,0.08120455,234.53806088,-0.04815791,-0.03304665,0.00000000,0.00000000,0.00000000,0.00000000
110.10000000,2.44299300,2.35700000,0.08162356,212.28968761,0.07846320,229.61752673,0.00079341,0.08233665,235.39529957,-0.04883078,-0.03350587,0.00000000,0.00000000,0.00000000,0.00000000
111.60000000,2.47965400,2.36400000,0.08282844,212.92016187,0.07957655,230.55600767,0.00073053,0.08345263,236.34894086,-0.04947454,-0.03397809,0.00000000,0.00000000,0.00000000,0.00000000
113.10000000,2.51628300,2.37200000,0.08409678,213.64070387,0.08074718,231.60719867,0.00078463,0.08458554,237.20979743,-0.05018638,-0.03439916,0.00000000,0.00000000,0.00000000,0.00000000
114.60000000,2.55324600,2.37800000,0.08534278,214.18111037,0.08189586,232.45992128,0.00080441,0.08571388,238.07123019,-0.05082241,-0.03489147,0.00000000,0.00000000,0.00000000,0.00000000
116.10000000,2.59000800,2.38400000,0.08653633,214.72151687,0.08299496,233.30272963,0.00072108,0.08683541,238.83379063,-0.05146659,-0.03536882,0.00000000,0.00000000,0.00000000,0.00000000
117.60000000,2.62737300,2.39100000,0.08779344,215.35199113,0.08415128,234.25848420,0.00076152,0.08797456,239.70103348,-0.05213464,-0.03583992,0.00000000,0.00000000,0.00000000,0.00000000
119.10000000,2.66400000,2.39800000,0.08901322,215.98246538,0.08527199,235.20776057,0.00079476,0.08912934,240.57373286,-0.05283888,-0.03629045,0.00000000,0.00000000,0.00000000,0.00000000
120.60000000,2.70109900,2.40400000,0.09024422,216.52287188,0.08640173,236.06281005,0.00074595,0.09023008,241.33581336,-0.05348929,-0.03674079,0.00000000,0.00000000,0.00000000,0.00000000
122.10000000,2.73809500,2.41000000,0.09148644,217.06327838,0.08754048,236.92162594,0.00076567,0.09135849,242.20537858,-0.05414157,-0.03721692,0.00000000,0.00000000,0.00000000,0.00000000
123.60000000,2.77559600,2.41600000,0.09273233,217.60368489,0.08868129,237.78258233,0.00077151,0.09247340,242.97385319,-0.05477306,-0.03770034,0.00000000,0.00000000,0.00000000,0.00000000
125.10000000,2.81218900,2.42200000,0.09397078,218.14409139,0.08981399,238.64326132,0.00073670,0.09361416,243.75007933,-0.05548070,-0.03813345,0.00000000,0.00000000,0.00000000,0.00000000
126.60000000,2.84999200,2.42800000,0.09523156,218.68449789,0.09096581,239.51016280,0.00077665,0.09474002,244.52412298,-0.05614100,-0.03859903,0.00000000,0.00000000,0.00000000,0.00000000
128.10000000,2.88776100,2.43300000,0.09647756,219.13483664,0.09210282,240.27643002,0.00075549,0.09588153,245.30346615,-0.05680355,-0.03907798,0.00000000,0.00000000,0.00000000,0.00000000
129.60000000,2.92502700,2.43800000,0.09773833,219.58517539,0.09325200,241.04706446,0.00078865,0.09702490,246.08474641,-0.05747792,-0.03954698,0.00000000,0.00000000,0.00000000,0.00000000
131.10000000,2.96259400,2.44400000,0.09899544,220.12558190,0.09439653,241.91701171,0.00078774,0.09815691,246.86469776,-0.05812728,-0.04002964,0.00000000,0.00000000,0.00000000,0.00000000
132.60000000,3.00002500,2.44900000,0.10025244,220.57592065,0.09553965,242.68919588,0.00079351,0.09930100,247.64911511,-0.05880969,-0.04049131,0.00000000,0.00000000,0.00000000,0.00000000
134.10000000,3.03792800,2.45400000,0.10150956,221.02625940,0.09668156,243.46253676,0.00075870,0.10046190,248.33892927,-0.05950398,-0.04095793,0.00000000,0.00000000,0.00000000,0.00000000
135.60000000,3.07542900,2.46000000,0.10277033,221.56666590,0.09782550,244.33714601,0.00075098,0.10162012,249.12975579,-0.06018330,-0.04143682,0.00000000,0.00000000,0.00000000,0.00000000
137.10000000,3.11350100,2.46500000,0.10402756,222.01700465,0.09896491,245.11289094,0.00077066,0.10276482,249.81818816,-0.06084365,-0.04192117,0.00000000,0.00000000,0.00000000,0.00000000
138.60000000,3.15163900,2.47000000,0.10531444,222.46734341,0.10012986,245.89636808,0.00079651,0.10395174,250.51849454,-0.06157260,-0.04237914,0.00000000,0.00000000,0.00000000,0.00000000
140.10000000,3.19004500,2.47500000,0.10656033,222.91768216,0.10125641,246.67186467,0.00073515,0.10512576,251.31763817,-0.06227033,-0.04285543,0.00000000,0.00000000,0.00000000,0.00000000
141.60000000,3.22794900,2.47900000,0.10783978,223.27795316,0.10241197,247.35619801,0.00073410,0.10619314,251.99047515,-0.06284712,-0.04334602,0.00000000,0.00000000,0.00000000,0.00000000
143.10000000,3.26612100,2.48400000,0.10910433,223.72829191,0.10355278,248.13801805,0.00071983,0.10735577,252.68862800,-0.06354449,-0.04381128,0.00000000,0.00000000,0.00000000,0.00000000
144.60000000,3.30476300,2.48800000,0.11039500,224.08856291,0.10471581,248.82681982,0.00077265,0.10849375,253.38180950,-0.06420802,-0.04428573,0.00000000,0.00000000,0.00000000,0.00000000
146.10000000,3.34293300,2.49300000,0.11168933,224.53890166,0.10588078,249.61750190,0.00077855,0.10964721,254.08020106,-0.06487972,-0.04476749,0.00000000,0.00000000,0.00000000,0.00000000
147.60000000,3.38194400,2.49700000,0.11300244,224.89917267,0.10706127,250.31332893,0.00078462,0.11082047,254.68359579,-0.06558033,-0.04524014,0.00000000,0.00000000,0.00000000,0.00000000
149.10000000,3.42055400,2.50100000,0.11431178,225.25944367,0.10823697,251.00925113,0.00078350,0.11200413,255.39219758,-0.06628263,-0.04572150,0.00000000,0.00000000,0.00000000,0.00000000
150.60000000,3.45943000,2.50600000,0.11562856,225.70978242,0.10941797,251.80827854,0.00085610,0.11315009,256.09244683,-0.06694544,-0.04620465,0.00000000,0.00000000,0.00000000,0.00000000
152.10000000,3.49810500,2.51000000,0.11688933,226.07005342,0.11054744,252.49523125,0.00084837,0.11430922,256.69566370,-0.06762808,-0.04668114,0.00000000,0.00000000,0.00000000,0.00000000
153.60000000,3.53667900,2.51400000,0.11820978,226.43032442,0.11172899,253.19660275,0.00089409,0.11546890,257.40191218,-0.06831209,-0.04715680,0.00000000,0.00000000,0.00000000,0.00000000
155.10000000,3.57592500,2.51800000,0.11948933,226.79059542,0.11287263,253.88965248,0.00085335,0.11665826,258.01520826,-0.06905081,-0.04760746,0.00000000,0.00000000,0.00000000,0.00000000
156.60000000,3.61544000,2.52100000,0.12079122,227.06079867,0.11403488,254.48775007,0.00082558,0.11785932,258.63264426,-0.06974337,-0.04811596,0.00000000,0.00000000,0.00000000,0.00000000
158.10000000,3.65502100,2.52500000,0.12210044,227.42106968,0.11520233,255.18928336,0.00077112,0.11899510,259.33640814,-0.07041516,-0.04857994,0.00000000,0.00000000,0.00000000,0.00000000
159.60000000,3.69406700,2.52900000,0.12342100,227.78134068,0.11637849,255.89434153,0.00081692,0.12015720,259.94600694,-0.07108762,-0.04906959,0.00000000,0.00000000,0.00000000,0.00000000
161.10000000,3.73347900,2.53200000,0.12469300,228.05154393,0.11751011,256.48797510,0.00070985,0.12137039,260.57004129,-0.07181016,-0.04956023,0.00000000,0.00000000,0.00000000,0.00000000
162.60000000,3.77296100,2.53600000,0.12606211,228.41181493,0.11872669,257.20589052,0.00082862,0.12257232,261.19226558,-0.07251138,-0.05006094,0.00000000,0.00000000,0.00000000,0.00000000
164.10000000,3.81311300,2.53900000,0.12737878,228.68201818,0.11989527,257.81125416,0.00079413,0.12373671,261.80575629,-0.07319032,-0.05054639,0.00000000,0.00000000,0.00000000,0.00000000
165.60000000,3.85279600,2.54300000,0.12871422,229.04228918,0.12107913,258.52328929,0.00083968,0.12488989,262.41737708,-0.07385593,-0.05103395,0.00000000,0.00000000,0.00000000,0.00000000
167.10000000,3.89308300,2.54600000,0.13002733,229.31249243,0.12224182,259.12938433,0.00074624,0.12609732,263.04439430,-0.07458758,-0.05150974,0.00000000,0.00000000,0.00000000,0.00000000
168.60000000,3.93256200,2.54900000,0.13138500,229.58269569,0.12344255,259.74641816,0.00086402,0.12727208,263.56085174,-0.07525382,-0.05201826,0.00000000,0.00000000,0.00000000,0.00000000
170.10000000,3.97365600,2.55200000,0.13277644,229.85289894,0.12467165,260.37194960,0.00083666,0.12846999,264.18748114,-0.07596737,-0.05250262,0.00000000,0.00000000,0.00000000,0.00000000
171.60000000,4.01380800,2.55500000,0.13411933,230.12310219,0.12585643,260.98705924,0.00080274,0.12968270,264.81918028,-0.07668543,-0.05299727,0.00000000,0.00000000,0.00000000,0.00000000
173.10000000,4.05322100,2.55800000,0.13545844,230.39330544,0.12703649,261.60202420,0.00074913,0.13084990,265.33647373,-0.07735238,-0.05349752,0.00000000,0.00000000,0.00000000,0.00000000
174.60000000,4.09357500,2.56100000,0.13682000,230.66350869,0.12823489,262.22288995,0.00082704,0.13203194,265.85858361,-0.07808126,-0.05395068,0.00000000,0.00000000,0.00000000,0.00000000
176.10000000,4.13439900,2.56400000,0.13814056,230.93371194,0.12939584,262.83502320,0.00078682,0.13319171,266.47928287,-0.07872868,-0.05446303,0.00000000,0.00000000,0.00000000,0.00000000
177.60000000,4.17545900,2.56600000,0.13951700,231.11384744,0.13060449,263.35815809,0.00081845,0.13439677,267.00941739,-0.07947148,-0.05492529,0.00000000,0.00000000,0.00000000,0.00000000
179.10000000,4.21635000,2.56900000,0.14088978,231.38405069,0.13180846,263.98369818,0.00081103,0.13556992,267.63580363,-0.08015379,-0.05541613,0.00000000,0.00000000,0.00000000,0.00000000
180.60000000,4.25687100,2.57200000,0.14223644,231.65425394,0.13298813,264.60393136,0.00079704,0.13680756,268.17661316,-0.08086995,-0.05593761,0.00000000,0.00000000,0.00000000,0.00000000
182.10000000,4.29782900,2.57500000,0.14361656,231.92445719,0.13419566,265.23264889,0.00085459,0.13799216,268.70405124,-0.08157299,-0.05641917,0.00000000,0.00000000,0.00000000,0.00000000
183.60000000,4.33932600,2.57700000,0.14495578,232.10459270,0.13536601,265.74949446,0.00076912,0.13923971,269.24938259,-0.08231127,-0.05692844,0.00000000,0.00000000,0.00000000,0.00000000
185.10000000,4.38058700,2.57900000,0.14635844,232.28472820,0.13659035,266.28155968,0.00082675,0.14043748,269.78218276,-0.08301948,-0.05741799,0.00000000,0.00000000,0.00000000,0.00000000
186.60000000,4.42164500,2.58200000,0.14770122,232.55493145,0.13776100,266.90357906,0.00083217,0.14167226,270.32592398,-0.08374719,-0.05792507,0.00000000,0.00000000,0.00000000,0.00000000
188.10000000,4.46290500,2.58400000,0.14906278,232.73506695,0.13894663,267.42720251,0.00077276,0.14290875,270.87106623,-0.08448035,-0.05842840,0.00000000,0.00000000,0.00000000,0.00000000
189.60000000,4.50470300,2.58700000,0.15048022,233.00527020,0.14017944,268.06795504,0.00081722,0.14416465,271.52727305,-0.08520227,-0.05896238,0.00000000,0.00000000,0.00000000,0.00000000
191.10000000,4.54680300,2.58900000,0.15187167,233.18540570,0.14138816,268.59966191,0.00081623,0.14543475,271.97865489,-0.08595463,-0.05948012,0.00000000,0.00000000,0.00000000,0.00000000
192.60000000,4.58809700,2.59100000,0.15326689,233.36554120,0.14259869,269.13275167,0.00083490,0.14669527,272.53323248,-0.08668521,-0.06001006,0.00000000,0.00000000,0.00000000,0.00000000
194.10000000,4.63006200,2.59300000,0.15464700,233.54567670,0.14379467,269.66281497,0.00081427,0.14792546,273.08046789,-0.08737923,-0.06054623,0.00000000,0.00000000,0.00000000,0.00000000
195.60000000,4.67233000,2.59500000,0.15614656,233.72581220,0.14509254,270.22129272,0.00089070,0.14918104,273.53025234,-0.08813515,-0.06104589,0.00000000,0.00000000,0.00000000,0.00000000
197.10000000,4.71479900,2.59700000,0.15756778,233.90594770,0.14632106,270.76198809,0.00083795,0.15044958,274.08980647,-0.08891470,-0.06153488,0.00000000,0.00000000,0.00000000,0.00000000
198.60000000,4.75733700,2.59900000,0.15901522,234.08608320,0.14757070,271.30933374,0.00084994,0.15169100,274.64287065,-0.08964780,-0.06204320,0.00000000,0.00000000,0.00000000,0.00000000
200.10000000,4.80014200,2.60000000,0.16048878,234.17615095,0.14884128,271.75879521,0.00088105,0.15289733,275.08143382,-0.09034253,-0.06255480,0.00000000,0.00000000,0.00000000,0.00000000
201.60000000,4.84341700,2.60200000,0.16196589,234.35628645,0.15011330,272.31401071,0.00089256,0.15410080,275.62576095,-0.09106721,-0.06303359,0.00000000,0.00000000,0.00000000,0.00000000
203.10000000,4.88662400,2.60400000,0.16342067,234.53642196,0.15136452,272.86452039,0.00088513,0.15533581,276.07372594,-0.09180414,-0.06353167,0.00000000,0.00000000,0.00000000,0.00000000
204.60000000,4.92979600,2.60600000,0.16488667,234.71655746,0.15262380,273.41818823,0.00078154,0.15653779,276.51321230,-0.09250775,-0.06403004,0.00000000,0.00000000,0.00000000,0.00000000
206.10000000,4.97310600,2.60700000,0.16635267,234.80662521,0.15388150,273.86733346,0.00084460,0.15773672,277.05879669,-0.09324285,-0.06449387,0.00000000,0.00000000,0.00000000,0.00000000
207.60000000,5.01671900,2.60900000,0.16777400,234.98676071,0.15509937,274.41142950,0.00079236,0.15890427,277.49014452,-0.09392944,-0.06497483,0.00000000,0.00000000,0.00000000,0.00000000
209.10000000,5.06059700,2.61100000,0.16920633,235.16689621,0.15632517,274.95862444,0.00076572,0.16007035,277.92171478,-0.09460434,-0.06546600,0.00000000,0.00000000,0.00000000,0.00000000
210.60000000,5.10421000,2.61200000,0.17066111,235.25696396,0.15756864,275.40617882,0.00082857,0.16126499,278.46856244,-0.09533056,-0.06593442,0.00000000,0.00000000,0.00000000,0.00000000
212.10000000,5.14818800,2.61400000,0.17211589,235.43709946,0.15881057,275.95956511,0.00082754,0.16249116,278.91836448,-0.09603687,-0.06645429,0.00000000,0.00000000,0.00000000,0.00000000
213.60000000,5.19277200,2.61500000,0.17357067,235.52716721,0.16005095,276.40777464,0.00089017,0.16368445,279.35963493,-0.09673759,-0.06694686,0.00000000,0.00000000,0.00000000,0.00000000
215.10000000,5.23719000,2.61600000,0.17495089,235.61723496,0.16122635,276.83867965,0.00088912,0.16493903,279.81878101,-0.09750574,-0.06743329,0.00000000,0.00000000,0.00000000,0.00000000
216.60000000,5.28150400,2.61800000,0.17633111,235.79737046,0.16240037,277.37578279,0.00076108,0.16622339,280.28702252,-0.09826144,-0.06796195,0.00000000,0.00000000,0.00000000,0.00000000
218.10000000,5.32558400,2.61900000,0.17771133,235.88743821,0.16357301,277.80730937,0.00076038,0.16756854,280.77314698,-0.09903257,-0.06853597,0.00000000,0.00000000,0.00000000,0.00000000
219.60000000,5.37003300,2.62000000,0.17916611,235.97750596,0.16480750,278.25667801,0.00075944,0.16894324,281.26842001,-0.09983702,-0.06910622,0.00000000,0.00000000,0.00000000,0.00000000
221.10000000,5.41484900,2.62100000,0.18058367,236.06757371,0.16600895,278.69752175,0.00082180,0.17040955,281.79044629,-0.10069554,-0.06971401,0.00000000,0.00000000,0.00000000,0.00000000
222.60000000,5.46020500,2.62300000,0.18203844,236.24770921,0.16724044,279.25387470,0.00088379,0.17193606,282.33046854,-0.10156467,-0.07037139,0.00000000,0.00000000,0.00000000,0.00000000
224.10000000,5.50485600,2.62400000,0.18345600,236.33777696,0.16843897,279.69536017,0.00088273,0.17355505,282.78975856,-0.10250421,-0.07105084,0.00000000,0.00000000,0.00000000,0.00000000
225.60000000,5.54960700,2.62500000,0.18494822,236.42784471,0.16969908,280.15475428,0.00081877,0.17523196,283.37444938,-0.10345110,-0.07178086,0.00000000,0.00000000,0.00000000,0.00000000
227.10000000,5.59522900,2.62600000,0.18655200,236.51791246,0.17105162,280.64080207,0.00088024,0.17690774,283.85162732,-0.10440336,-0.07250438,0.00000000,0.00000000,0.00000000,0.00000000
228.60000000,5.64082100,2.62700000,0.18819333,236.60798021,0.17243395,281.13602470,0.00094208,0.17864103,284.45458237,-0.10541259,-0.07322844,0.00000000,0.00000000,0.00000000,0.00000000
230.10000000,5.68725100,2.62700000,0.18990922,236.60798021,0.17387702,281.54201771,0.00094072,0.18034027,285.04903721,-0.10640733,-0.07393294,0.00000000,0.00000000,0.00000000,0.00000000
231.60000000,5.73307700,2.62800000,0.19169967,236.69804796,0.17538058,282.07298486,0.00100181,0.18203812,285.53537552,-0.10744368,-0.07459445,0.00000000,0.00000000,0.00000000,0.00000000
233.10000000,5.78078300,2.62900000,0.19367667,236.78811571,0.17703818,282.64844867,0.00112532,0.18357763,286.08616970,-0.10836339,-0.07521423,0.00000000,0.00000000,0.00000000,0.00000000
234.60000000,5.82798300,2.63000000,0.19561622,236.87818346,0.17866172,283.21539884,0.00112331,0.18508396,286.62844295,-0.10930917,-0.07577480,0.00000000,0.00000000,0.00000000,0.00000000
236.10000000,5.87612800,2.63000000,0.19763067,236.87818346,0.18034516,283.69257678,0.00105941,0.18652817,287.04437468,-0.11022181,-0.07630636,0.00000000,0.00000000,0.00000000,0.00000000
237.60000000,5.92467300,2.63100000,0.19968233,236.96825122,0.18205680,284.28662454,0.00105760,0.18784617,287.53405260,-0.11102644,-0.07681973,0.00000000,0.00000000,0.00000000,0.00000000
239.10000000,5.97372000,2.63200000,0.20173389,237.05831897,0.18376542,284.88101554,0.00105561,0.18916386,287.91472755,-0.11186017,-0.07730370,0.00000000,0.00000000,0.00000000,0.00000000
240.60000000,6.02377500,2.63200000,0.20378544,237.05831897,0.18547113,285.36735386,0.00105362,0.19038671,288.37830078,-0.11259691,-0.07778980,0.00000000,0.00000000,0.00000000,0.00000000
242.10000000,6.07450000,2.63300000,0.20576244,237.14838672,0.18711210,285.94461846,0.00111404,0.19164016,288.74147208,-0.11338725,-0.07825291,0.00000000,0.00000000,0.00000000,0.00000000
243.60000000,6.12573300,2.63300000,0.20759033,237.14838672,0.18862691,286.37809936,0.00098881,0.19286140,289.09575338,-0.11411443,-0.07874697,0.00000000,0.00000000,0.00000000,0.00000000
245.10000000,6.17740000,2.63400000,0.20934356,237.23845447,0.19007770,286.90279604,0.00092560,0.19401860,289.54210723,-0.11483448,-0.07918412,0.00000000,0.00000000,0.00000000,0.00000000
246.60000000,6.22920100,2.63400000,0.21102211,237.23845447,0.19146472,287.30101396,0.00092413,0.19520636,289.88762955,-0.11550743,-0.07969893,0.00000000,0.00000000,0.00000000,0.00000000
248.10000000,6.28140500,2.63500000,0.21262622,237.32852222,0.19278844,287.79078932,0.00092310,0.00000000,0.00000000,0.00000000,0.00000000,0.00000000,0.00000000,0.00000000,0.00000000
249.60000000,6.33327300,2.63600000,0.21415578,237.41858997,0.19404900,288.26315276,0.00086059,0.00000000,0.00000000,0.00000000,0.00000000,0.00000000,0.00000000,0.00000000,0.00000000
251.10000000,6.38571500,2.63600000,0.21564822,237.41858997,0.19527745,288.61748682,0.00085972,0.00000000,0.00000000,0.00000000,0.00000000,0.00000000,0.00000000,0.00000000,0.00000000
252.60000000,6.43842300,2.63600000,0.21714033,237.41858997,0.19650412,288.97174173,0.00073574,0.00000000,0.00000000,0.00000000,0.00000000,0.00000000,0.00000000,0.00000000,0.00000000
254.10000000,6.49166700,2.63700000,0.21859522,237.50865772,0.19769874,289.42691553,0.00073486,0.00000000,0.00000000,0.00000000,0.00000000,0.00000000,0.00000000,0.00000000,0.00000000
255.60000000,6.54393900,2.63700000,0.22008733,237.50865772,0.19892244,289.78130484,0.00079500,0.00000000,0.00000000,0.00000000,0.00000000,0.00000000,0.00000000,0.00000000,0.00000000
257.10000000,6.59560600,2.63800000,0.22150489,237.59872547,0.20008361,290.22800475,0.00085523,0.00000000,0.00000000,0.00000000,0.00000000,0.00000000,0.00000000,0.00000000,0.00000000
258.60000000,6.64600000,2.63700000,0.22299689,237.50865772,0.00000000,0.00000000,0.00000000,0.00000000,0.00000000,0.00000000,0.00000000,0.00000000,0.00000000,0.00000000,0.00000000
260.10000000,6.69508200,2.63700000,0.22448878,237.50865772,0.00000000,0.00000000,0.00000000,0.00000000,0.00000000,0.00000000,0.00000000,0.00000000,0.00000000,0.00000000,0.00000000
261.60000000,6.74299100,2.63800000,0.22601800,237.59872547,0.00000000,0.00000000,0.00000000,0.00000000,0.00000000,0.00000000,0.00000000,0.00000000,0.00000000,0.00000000,0.00000000
263.10000000,6.79110000,2.63700000,0.22765911,237.50865772,0.00000000,0.00000000,0.00000000,0.00000000,0.00000000,0.00000000,0.00000000,0.00000000,0.00000000,0.00000000,0.00000000
264.60000000,6.84048500,2.63700000,0.22930011,237.50865772,0.00000000,0.00000000,0.00000000,0.00000000,0.00000000,0.00000000,0.00000000,0.00000000,0.00000000,0.00000000,0.00000000
266.10000000,6.89249000,2.63600000,0.23101589,237.41858997,0.00000000,0.00000000,0.00000000,0.00000000,0.00000000,0.00000000,0.00000000,0.00000000,0.00000000,0.00000000,0.00000000
267.60000000,6.94469400,2.63500000,0.23269433,237.32852222,0.00000000,0.00000000,0.00000000,0.00000000,0.00000000,0.00000000,0.00000000,0.00000000,0.00000000,0.00000000,0.00000000
269.10000000,6.99857600,2.63400000,0.23437300,237.23845447,0.00000000,0.00000000,0.00000000,0.00000000,0.00000000,0.00000000,0.00000000,0.00000000,0.00000000,0.00000000,0.00000000
270.60000000,7.05346600,2.63300000,0.23605200,237.14838672,0.00000000,0.00000000,0.00000000,0.00000000,0.00000000,0.00000000,0.00000000,0.00000000,0.00000000,0.00000000,0.00000000
272.10000000,7.10976800,2.63200000,0.23788033,237.05831897,0.00000000,0.00000000,0.00000000,0.00000000,0.00000000,0.00000000,0.00000000,0.00000000,0.00000000,0.00000000,0.00000000
273.60000000,7.16620600,2.63000000,0.23985800,236.87818346,0.00000000,0.00000000,0.00000000,0.00000000,0.00000000,0.00000000,0.00000000,0.00000000,0.00000000,0.00000000,0.00000000
275.10000000,7.22331200,2.62900000,0.24172400,236.78811571,0.00000000,0.00000000,0.00000000,0.00000000,0.00000000,0.00000000,0.00000000,0.00000000,0.00000000,0.00000000,0.00000000
276.60000000,7.28108700,2.62600000,0.24355278,236.51791246,0.00000000,0.00000000,0.00000000,0.00000000,0.00000000,0.00000000,0.00000000,0.00000000,0.00000000,0.00000000,0.00000000
278.10000000,7.33923000,2.62300000,0.24512033,236.24770921,0.00000000,0.00000000,0.00000000,0.00000000,0.00000000,0.00000000,0.00000000,0.00000000,0.00000000,0.00000000,0.00000000
279.60000000,7.39798100,2.61900000,0.24635189,235.88743821,0.00000000,0.00000000,0.00000000,0.00000000,0.00000000,0.00000000,0.00000000,0.00000000,0.00000000,0.00000000,0.00000000
281.10000000,7.45592500,2.61500000,0.24735967,235.52716721,0.00000000,0.00000000,0.00000000,0.00000000,0.00000000,0.00000000,0.00000000,0.00000000,0.00000000,0.00000000,0.00000000
282.60000000,7.51541400,2.61100000,0.24825522,235.16689621,0.00000000,0.00000000,0.00000000,0.00000000,0.00000000,0.00000000,0.00000000,0.00000000,0.00000000,0.00000000,0.00000000
284.10000000,7.57513300,2.60400000,0.24892733,234.53642196,0.00000000,0.00000000,0.00000000,0.00000000,0.00000000,0.00000000,0.00000000,0.00000000,0.00000000,0.00000000,0.00000000
285.60000000,7.63552300,2.59500000,0.24945078,233.72581220,0.00000000,0.00000000,0.00000000,0.00000000,0.00000000,0.00000000,0.00000000,0.00000000,0.00000000,0.00000000,0.00000000
287.10000000,7.69634800,2.58400000,0.24975100,232.73506695,0.00000000,0.00000000,0.00000000,0.00000000,0.00000000,0.00000000,0.00000000,0.00000000,0.00000000,0.00000000,0.00000000
288.60000000,7.75736700,2.56600000,0.24994000,231.11384744,0.00000000,0.00000000,0.00000000,0.00000000,0.00000000,0.00000000,0.00000000,0.00000000,0.00000000,0.00000000,0.00000000
290.10000000,7.82036300,2.53900000,0.24998122,228.68201818,0.00000000,0.00000000,0.00000000,0.00000000,0.00000000,0.00000000,0.00000000,0.00000000,0.00000000,0.00000000,0.00000000
291.60000000,7.88500500,2.49600000,0.24994889,224.80910492,0.00000000,0.00000000,0.00000000,0.00000000,0.00000000,0.00000000,0.00000000,0.00000000,0.00000000,0.00000000,0.00000000
293.10000000,7.95270700,2.42500000,0.24988078,218.41429464,0.00000000,0.00000000,0.00000000,0.00000000,0.00000000,0.00000000,0.00000000,0.00000000,0.00000000,0.00000000,0.00000000
294.60000000,8.02367500,2.32800000,0.24966567,209.67772285,0.00000000,0.00000000,0.00000000,0.00000000,0.00000000,0.00000000,0.00000000,0.00000000,0.00000000,0.00000000,0.00000000
296.10000000,8.38821300,1.39000000,0.24460844,125.19417301,0.00000000,0.00000000,0.00000000,0.00000000,0.00000000,0.00000000,0.00000000,0.00000000,0.00000000,0.00000000,0.00000000
NaN,-100.00000000,NaN,-11.11111111,NaN,0.00000000,0.00000000,0.00000000,0.00000000,0.00000000,0.00000000,0.00000000,0.00000000,0.00000000,0.00000000,0.00000000