File: polyN_optimization/results_exp/AA6014-T4/UT_30_2.csv
Time[s],Displacement[mm],Force[kN],EngStrain_longi,EngStress[MPa],TrueStrain,TrueStress[MPa],TrueStrainRate[1/s],PlasticStrain_longi,PlasticStress[MPa],PlasticStrain_thick,PlasticStrain_width,R-Value,Thickness[mm],Width[mm], Young's Modulus [MPa]
0.63000000,0.00000000,-0.00200000,0.00000000,-0.18035957,0.00000000,-0.18035957,0.00000000,0.00084040,118.34167472,-0.00015579,-0.00068461,0.55572702,1.11240000,9.96850000,76937.99492446
2.13000000,0.00544600,0.17000000,0.00014289,15.33056384,0.00014288,15.33275441,0.00010354,0.00194880,122.73431223,-0.00090050,-0.00104830,0.00000000,0.00000000,0.00000000,0.00000000
3.63000000,0.01232800,0.40000000,0.00037900,36.07191492,0.00037893,36.08558617,0.00007464,0.00314373,126.24024101,-0.00172714,-0.00141659,0.00000000,0.00000000,0.00000000,0.00000000
5.13000000,0.02137900,0.65700000,0.00067922,59.24812025,0.00067899,59.28836289,0.00019521,0.00433580,129.57254787,-0.00255642,-0.00177937,0.00000000,0.00000000,0.00000000,0.00000000
6.63000000,0.03021500,0.90400000,0.00100867,81.52252771,0.00100816,81.60475677,0.00037499,0.00546868,132.26796167,-0.00329289,-0.00217579,0.00000000,0.00000000,0.00000000,0.00000000
8.13000000,0.04164600,1.13700000,0.00129700,102.53441815,0.00129616,102.66740529,0.00030918,0.00661097,134.87967149,-0.00403174,-0.00257923,0.00000000,0.00000000,0.00000000,0.00000000
9.63000000,0.06487200,1.28900000,0.00203200,116.24174582,0.00202994,116.47794905,0.00047600,0.00783019,137.50797162,-0.00493307,-0.00289712,0.00000000,0.00000000,0.00000000,0.00000000
11.13000000,0.09940000,1.34200000,0.00326944,121.02127455,0.00326411,121.41694688,0.00068588,0.00898237,139.76785174,-0.00571623,-0.00326614,0.00000000,0.00000000,0.00000000,0.00000000
12.63000000,0.13558200,1.38300000,0.00450344,124.71864583,0.00449333,125.28030932,0.00086562,0.01007600,142.02457162,-0.00644023,-0.00363577,0.00000000,0.00000000,0.00000000,0.00000000
14.13000000,0.17156500,1.41600000,0.00568256,127.69457881,0.00566647,128.42021035,0.00085849,0.01123373,144.29547535,-0.00722290,-0.00401083,0.00000000,0.00000000,0.00000000,0.00000000
15.63000000,0.20855000,1.44800000,0.00689111,130.58033200,0.00686748,131.48017558,0.00082250,0.01241081,146.39106914,-0.00801022,-0.00440059,0.00000000,0.00000000,0.00000000,0.00000000
17.13000000,0.24474700,1.47500000,0.00819822,133.01518626,0.00816480,134.10567431,0.00088979,0.01354609,148.48530335,-0.00879065,-0.00475544,0.00000000,0.00000000,0.00000000,0.00000000
18.63000000,0.28172300,1.50200000,0.00944289,135.45004052,0.00939858,136.72908020,0.00098010,0.01465073,150.57960678,-0.00952456,-0.00512617,0.00000000,0.00000000,0.00000000,0.00000000
20.13000000,0.31772900,1.52600000,0.01060378,137.61435541,0.01054795,139.07358745,0.00094289,0.01582469,152.59707513,-0.01031050,-0.00551418,0.00000000,0.00000000,0.00000000,0.00000000
21.63000000,0.35348600,1.54900000,0.01179522,139.68849052,0.01172620,141.33614731,0.00075723,0.01697668,154.52366231,-0.01107670,-0.00589998,0.00000000,0.00000000,0.00000000,0.00000000
23.13000000,0.38949900,1.57100000,0.01302989,141.67244584,0.01294573,143.51842207,0.00083763,0.01804923,156.53436480,-0.01176728,-0.00628196,0.00000000,0.00000000,0.00000000,0.00000000
24.63000000,0.42429600,1.59400000,0.01420489,143.74658095,0.01410494,145.78848516,0.00083666,0.01913636,158.45930062,-0.01244713,-0.00668922,0.00000000,0.00000000,0.00000000,0.00000000
26.13000000,0.46040600,1.61500000,0.01537244,145.64035648,0.01525549,147.87920477,0.00074211,0.02028667,160.21361292,-0.01321934,-0.00706734,0.00000000,0.00000000,0.00000000,0.00000000
27.63000000,0.49564900,1.63600000,0.01656233,147.53413201,0.01642667,149.97764148,0.00072688,0.02139658,162.15038428,-0.01391140,-0.00748519,0.00000000,0.00000000,0.00000000,0.00000000
29.13000000,0.53132600,1.65500000,0.01776344,149.24754797,0.01760752,151.89869850,0.00076178,0.02249694,163.90447574,-0.01462861,-0.00786832,0.00000000,0.00000000,0.00000000,0.00000000
30.63000000,0.56629500,1.67600000,0.01890122,151.14132350,0.01872481,153.99807925,0.00073248,0.02360321,165.66330311,-0.01535847,-0.00824475,0.00000000,0.00000000,0.00000000,0.00000000
32.13000000,0.60079000,1.69400000,0.02005011,152.76455968,0.01985175,155.82750607,0.00067306,0.02472131,167.52076901,-0.01609709,-0.00862423,0.00000000,0.00000000,0.00000000,0.00000000
33.63000000,0.63570500,1.71400000,0.02121756,154.56815542,0.02099560,157.84771385,0.00065890,0.02583345,169.19530249,-0.01683289,-0.00900056,0.00000000,0.00000000,0.00000000,0.00000000
35.13000000,0.67048900,1.73200000,0.02241878,156.19139159,0.02217117,159.69301169,0.00075913,0.02690583,170.77353991,-0.01754227,-0.00936356,0.00000000,0.00000000,0.00000000,0.00000000
36.63000000,0.70515500,1.75100000,0.02356389,157.90480755,0.02329055,161.62565889,0.00075089,0.02801392,172.54759637,-0.01831418,-0.00969975,0.00000000,0.00000000,0.00000000,0.00000000
38.13000000,0.73966700,1.76700000,0.02469044,159.34768415,0.02439056,163.28204929,0.00066264,0.02909463,174.13408132,-0.01903154,-0.01006309,0.00000000,0.00000000,0.00000000,0.00000000
39.63000000,0.77444700,1.78500000,0.02585800,160.97092032,0.02552934,165.13330638,0.00067640,0.03021366,175.73061765,-0.01978388,-0.01042979,0.00000000,0.00000000,0.00000000,0.00000000
41.13000000,0.80919300,1.80100000,0.02705167,162.41379692,0.02669224,166.80736081,0.00078471,0.03130020,177.23129187,-0.02049672,-0.01080347,0.00000000,0.00000000,0.00000000,0.00000000
42.63000000,0.84357100,1.81800000,0.02818189,163.94685330,0.02779209,168.56718530,0.00066039,0.03239143,178.82954524,-0.02122290,-0.01116853,0.00000000,0.00000000,0.00000000,0.00000000
44.13000000,0.87858700,1.83400000,0.02935689,165.38972990,0.02893423,170.24505782,0.00073220,0.03345393,180.33223012,-0.02192348,-0.01153046,0.00000000,0.00000000,0.00000000,0.00000000
45.62000000,0.91272900,1.85100000,0.03051700,166.92278628,0.03006062,172.01676895,0.00073155,0.03456410,181.94049119,-0.02264112,-0.01192298,0.00000000,0.00000000,0.00000000,0.00000000
47.12000000,0.94730800,1.86600000,0.03167333,168.27548309,0.03118208,173.60532856,0.00074546,0.03568866,183.46088292,-0.02343676,-0.01225190,0.00000000,0.00000000,0.00000000,0.00000000
48.62000000,0.98161800,1.88100000,0.03283344,169.62817990,0.03230594,175.19765732,0.00079624,0.03673796,184.87653098,-0.02407006,-0.01266791,0.00000000,0.00000000,0.00000000,0.00000000
50.13000000,1.01656700,1.89700000,0.03399722,171.07105650,0.03343209,176.88699722,0.00080094,0.03781243,186.20555604,-0.02475474,-0.01305768,0.00000000,0.00000000,0.00000000,0.00000000
51.62000000,1.05114600,1.91100000,0.03514244,172.33357352,0.03453904,178.38979655,0.00070615,0.03896168,187.73985776,-0.02553463,-0.01342705,0.00000000,0.00000000,0.00000000,0.00000000
53.12000000,1.08535500,1.92500000,0.03630622,173.59609054,0.03566268,179.89870878,0.00074191,0.04003588,189.16889983,-0.02622530,-0.01381058,0.00000000,0.00000000,0.00000000,0.00000000
54.63000000,1.12000200,1.94000000,0.03744767,174.94878735,0.03676353,181.50021122,0.00074084,0.04109453,190.59788172,-0.02690253,-0.01419200,0.00000000,0.00000000,0.00000000,0.00000000
56.12000000,1.15451300,1.95300000,0.03859289,176.12112458,0.03786681,182.91814758,0.00072569,0.04221163,191.85183544,-0.02761828,-0.01459335,0.00000000,0.00000000,0.00000000,0.00000000
57.62000000,1.18902500,1.96600000,0.03973811,177.29346182,0.03896887,184.33876910,0.00069583,0.04329413,193.19638072,-0.02828422,-0.01500991,0.00000000,0.00000000,0.00000000,0.00000000
59.13000000,1.22296700,1.98100000,0.04089444,178.64615863,0.04008039,185.95179404,0.00069546,0.04439889,194.64279938,-0.02902535,-0.01537354,0.00000000,0.00000000,0.00000000,0.00000000
60.63000000,1.25818300,1.99300000,0.04208433,179.72831608,0.04122287,187.29206244,0.00078768,0.04547302,195.89641928,-0.02970713,-0.01576589,0.00000000,0.00000000,0.00000000,0.00000000
62.13000000,1.29279600,2.00600000,0.04323700,180.90065331,0.04232838,188.72225486,0.00074339,0.04654245,197.15162293,-0.03042724,-0.01611521,0.00000000,0.00000000,0.00000000,0.00000000
63.62000000,1.32717400,2.01900000,0.04438222,182.07299055,0.04342554,190.15379447,0.00077168,0.04765895,198.51381070,-0.03115804,-0.01650091,0.00000000,0.00000000,0.00000000,0.00000000
65.13000000,1.36229000,2.03100000,0.04556089,183.15514799,0.04455348,191.49985934,0.00078363,0.04874838,199.68298435,-0.03187023,-0.01687816,0.00000000,0.00000000,0.00000000,0.00000000
66.63000000,1.39586200,2.04300000,0.04669867,184.23730544,0.04564108,192.84094196,0.00072698,0.04985646,200.95359223,-0.03258090,-0.01727556,0.00000000,0.00000000,0.00000000,0.00000000
68.13000000,1.43151500,2.05500000,0.04785878,185.31946289,0.04674882,194.18862588,0.00076798,0.05092093,202.21797267,-0.03330120,-0.01761973,0.00000000,0.00000000,0.00000000,0.00000000
69.63000000,1.46545600,2.06600000,0.04900767,186.31144055,0.04784464,195.44212952,0.00072538,0.05199747,203.29624866,-0.03400202,-0.01799545,0.00000000,0.00000000,0.00000000,0.00000000
71.13000000,1.50050500,2.07700000,0.05022000,187.30341821,0.04899967,196.70979587,0.00078016,0.05310531,204.57435588,-0.03475678,-0.01834854,0.00000000,0.00000000,0.00000000,0.00000000
72.62000000,1.53548600,2.08900000,0.05136522,188.38557566,0.05008953,198.06204261,0.00075958,0.05420964,205.75860988,-0.03545578,-0.01875386,0.00000000,0.00000000,0.00000000,0.00000000
74.13000000,1.57043500,2.10000000,0.05253278,189.37755332,0.05119943,199.32608224,0.00069520,0.05531268,206.94500333,-0.03619676,-0.01911591,0.00000000,0.00000000,0.00000000,0.00000000
75.62000000,1.60571900,2.11000000,0.05371522,190.27935119,0.05232223,200.50024882,0.00074354,0.05639125,208.03272357,-0.03687798,-0.01951327,0.00000000,0.00000000,0.00000000,0.00000000
77.12000000,1.64019700,2.12200000,0.05487156,191.36150864,0.05341901,201.86181229,0.00074968,0.05749176,209.22326544,-0.03757419,-0.01991757,0.00000000,0.00000000,0.00000000,0.00000000
78.62000000,1.67460800,2.13100000,0.05601311,192.17312672,0.05450060,202.93734142,0.00074213,0.05861328,210.32445834,-0.03833395,-0.02027933,0.00000000,0.00000000,0.00000000,0.00000000
80.12000000,1.70958900,2.14200000,0.05717322,193.16510438,0.05559857,204.20897582,0.00067760,0.05969862,211.42022157,-0.03904330,-0.02065532,0.00000000,0.00000000,0.00000000,0.00000000
81.62000000,1.74504100,2.15100000,0.05838922,193.97672247,0.05674815,205.30287242,0.00075536,0.06075134,212.51119560,-0.03969692,-0.02105443,0.00000000,0.00000000,0.00000000,0.00000000
83.12000000,1.78056000,2.16200000,0.05953811,194.96870013,0.05783307,206.57676826,0.00074726,0.06189478,213.52718681,-0.04043960,-0.02145518,0.00000000,0.00000000,0.00000000,0.00000000
84.62000000,1.81547400,2.17100000,0.06073933,195.78031821,0.05896615,207.67188422,0.00077529,0.06301476,214.63683270,-0.04115989,-0.02185487,0.00000000,0.00000000,0.00000000,0.00000000
86.13000000,1.85102700,2.18100000,0.06191067,196.68211609,0.06006980,208.85883702,0.00067510,0.06411375,215.64745309,-0.04184868,-0.02226507,0.00000000,0.00000000,0.00000000,0.00000000
87.63000000,1.88651200,2.19000000,0.06310433,197.49373417,0.06119324,209.95644461,0.00070879,0.06522546,216.66282579,-0.04259998,-0.02262548,0.00000000,0.00000000,0.00000000,0.00000000
89.12000000,1.92196400,2.19900000,0.06427933,198.30535226,0.06229789,211.05228810,0.00070813,0.06633450,217.77659772,-0.04331684,-0.02301766,0.00000000,0.00000000,0.00000000,0.00000000
90.62000000,1.95708000,2.20700000,0.06546189,199.02679056,0.06340840,212.05546021,0.00074932,0.06744362,218.79555609,-0.04403022,-0.02341340,0.00000000,0.00000000,0.00000000,0.00000000
92.12000000,1.99246500,2.21700000,0.06667422,199.92858843,0.06454560,213.25867156,0.00075555,0.06854251,219.71710240,-0.04473959,-0.02380292,0.00000000,0.00000000,0.00000000,0.00000000
93.62000000,2.02855500,2.22500000,0.06786422,200.65002673,0.06566060,214.26698473,0.00080580,0.06963178,220.73558979,-0.04542243,-0.02420935,0.00000000,0.00000000,0.00000000,0.00000000
95.12000000,2.06347000,2.23300000,0.06903922,201.37146503,0.06676032,215.27399435,0.00067008,0.07070251,221.75194397,-0.04611255,-0.02458997,0.00000000,0.00000000,0.00000000,0.00000000
96.62000000,2.10013000,2.24200000,0.07025900,202.18308311,0.06790068,216.38826435,0.00069715,0.07188728,222.69822319,-0.04690516,-0.02498212,0.00000000,0.00000000,0.00000000,0.00000000
98.13000000,2.13571600,2.25000000,0.07148633,202.90452141,0.06904678,217.40942166,0.00079884,0.07295348,223.61985935,-0.04757038,-0.02538310,0.00000000,0.00000000,0.00000000,0.00000000
99.62000000,2.17207500,2.25800000,0.07266511,203.62595971,0.07014631,218.42246270,0.00076667,0.07410104,224.56155725,-0.04833160,-0.02576943,0.00000000,0.00000000,0.00000000,0.00000000
101.12000000,2.20759400,2.26600000,0.07386256,204.34739801,0.07126201,219.44101905,0.00075753,0.07524722,225.50483750,-0.04909051,-0.02615671,0.00000000,0.00000000,0.00000000,0.00000000
102.63000000,2.24385200,2.27300000,0.07508978,204.97865652,0.07240417,220.37045829,0.00077569,0.07634407,226.43880227,-0.04978378,-0.02656028,0.00000000,0.00000000,0.00000000,0.00000000
104.12000000,2.27930400,2.28100000,0.07628344,205.70009482,0.07351385,221.39160657,0.00078330,0.07747042,227.38129886,-0.05052368,-0.02694673,0.00000000,0.00000000,0.00000000,0.00000000
105.62000000,2.31619900,2.28900000,0.07749956,206.42153312,0.07464313,222.41911019,0.00074796,0.07859693,228.22750989,-0.05127080,-0.02732612,0.00000000,0.00000000,0.00000000,0.00000000
107.13000000,2.35175200,2.29600000,0.07869322,207.05279163,0.07575033,223.34644297,0.00069854,0.07968986,229.16593488,-0.05195775,-0.02773211,0.00000000,0.00000000,0.00000000,0.00000000
108.62000000,2.38844600,2.30200000,0.07993922,207.59387035,0.07690476,224.18876288,0.00064273,0.08082060,230.01648579,-0.05270424,-0.02811636,0.00000000,0.00000000,0.00000000,0.00000000
110.12000000,2.42433500,2.31000000,0.08114411,208.31530865,0.07801984,225.21886920,0.00075922,0.08195337,230.86915835,-0.05343534,-0.02851803,0.00000000,0.00000000,0.00000000,0.00000000
111.62000000,2.46099600,2.31700000,0.08235644,208.94656716,0.07914056,226.15466351,0.00071010,0.08303707,231.71207913,-0.05407480,-0.02896228,0.00000000,0.00000000,0.00000000,0.00000000
113.13000000,2.49782400,2.32300000,0.08360600,209.48764588,0.08029437,227.00207000,0.00075611,0.08418301,232.66984348,-0.05485414,-0.02932887,0.00000000,0.00000000,0.00000000,0.00000000
114.62000000,2.53448500,2.33000000,0.08482589,210.11890439,0.08141950,227.94242723,0.00072242,0.08531324,233.42812060,-0.05559745,-0.02971578,0.00000000,0.00000000,0.00000000,0.00000000
116.12000000,2.57097800,2.33600000,0.08604567,210.65998312,0.08254327,228.78636181,0.00072836,0.08642719,234.28297920,-0.05630530,-0.03012189,0.00000000,0.00000000,0.00000000,0.00000000
117.62000000,2.60743700,2.34300000,0.08726544,211.29124163,0.08366578,229.72966574,0.00073429,0.08753780,235.03960264,-0.05701481,-0.03052299,0.00000000,0.00000000,0.00000000,0.00000000
119.12000000,2.64450000,2.34900000,0.08850389,211.83232035,0.08480417,230.58030450,0.00077451,0.08869333,235.90746011,-0.05777199,-0.03092134,0.00000000,0.00000000,0.00000000,0.00000000
120.62000000,2.68099300,2.35500000,0.08973856,212.37339908,0.08593781,231.43148115,0.00071202,0.08980468,236.66722184,-0.05849053,-0.03131415,0.00000000,0.00000000,0.00000000,0.00000000
122.12000000,2.71792200,2.36100000,0.09101433,212.91447780,0.08710784,232.29274705,0.00088907,0.09088978,237.52156693,-0.05917644,-0.03171334,0.00000000,0.00000000,0.00000000,0.00000000
123.63000000,2.75434800,2.36700000,0.09222678,213.45555652,0.08821853,233.14187470,0.00079704,0.09202912,238.29094057,-0.05990983,-0.03211929,0.00000000,0.00000000,0.00000000,0.00000000
125.12000000,2.79134400,2.37300000,0.09342789,213.99663525,0.08931761,233.98988911,0.00073706,0.09316722,239.06147869,-0.06061998,-0.03254723,0.00000000,0.00000000,0.00000000,0.00000000
126.62000000,2.82857600,2.37900000,0.09471111,214.53771397,0.09049050,234.85681924,0.00079062,0.09431051,239.83472823,-0.06136436,-0.03294615,0.00000000,0.00000000,0.00000000,0.00000000
128.12000000,2.86607600,2.38400000,0.09597567,214.98861291,0.09164499,235.62228836,0.00083738,0.09540881,240.59858979,-0.06205859,-0.03335022,0.00000000,0.00000000,0.00000000,0.00000000
129.62000000,2.90293800,2.39000000,0.09718800,215.52969163,0.09275054,236.47659130,0.00078215,0.09656650,241.37823713,-0.06280475,-0.03376174,0.00000000,0.00000000,0.00000000,0.00000000
131.12000000,2.93976600,2.39500000,0.09841522,215.98059057,0.09386843,237.23636838,0.00071995,0.09772071,242.05842058,-0.06355716,-0.03416354,0.00000000,0.00000000,0.00000000,0.00000000
132.62000000,2.97686300,2.40000000,0.09969111,216.43148950,0.09502933,238.00778517,0.00080766,0.09882516,242.82797673,-0.06425903,-0.03456613,0.00000000,0.00000000,0.00000000,0.00000000
134.12000000,3.01422900,2.40500000,0.10092944,216.88238844,0.09615477,238.77220742,0.00077929,0.09994522,243.60277136,-0.06496277,-0.03498245,0.00000000,0.00000000,0.00000000,0.00000000
135.62000000,3.05146000,2.41000000,0.10216789,217.33328738,0.09727905,239.53777053,0.00075825,0.10110889,244.28924182,-0.06573927,-0.03536962,0.00000000,0.00000000,0.00000000,0.00000000
137.12000000,3.08902800,2.41600000,0.10344367,217.87436610,0.09843590,240.41208940,0.00075737,0.10225303,245.07277166,-0.06642805,-0.03582498,0.00000000,0.00000000,0.00000000,0.00000000
138.62000000,3.12699700,2.42000000,0.10474178,218.23508525,0.09961162,241.09341605,0.00079693,0.10340389,245.75875283,-0.06717906,-0.03622483,0.00000000,0.00000000,0.00000000,0.00000000
140.12000000,3.16456500,2.42500000,0.10599522,218.68598419,0.10074558,241.86565368,0.00078276,0.10455198,246.54613218,-0.06790834,-0.03664364,0.00000000,0.00000000,0.00000000,0.00000000
141.62000000,3.20216500,2.43000000,0.10723744,219.13688312,0.10186812,242.63656245,0.00075497,0.10570351,247.23492941,-0.06865427,-0.03704924,0.00000000,0.00000000,0.00000000,0.00000000
143.12000000,3.23983300,2.43400000,0.10848322,219.49760227,0.10299261,243.30940944,0.00069316,0.10684693,247.92298299,-0.06940117,-0.03744576,0.00000000,0.00000000,0.00000000,0.00000000
144.62000000,3.27810500,2.43900000,0.10981133,219.94850121,0.10419003,244.10133939,0.00078667,0.10798574,248.61114957,-0.07015427,-0.03783147,0.00000000,0.00000000,0.00000000,0.00000000
146.12000000,3.31627700,2.44300000,0.11106089,220.30922036,0.10531531,244.77695820,0.00074537,0.10908814,249.19018184,-0.07083147,-0.03825668,0.00000000,0.00000000,0.00000000,0.00000000
147.62000000,3.35397800,2.44700000,0.11229567,220.66993951,0.10642605,245.45021748,0.00065061,0.11027404,249.89253349,-0.07159949,-0.03867455,0.00000000,0.00000000,0.00000000,0.00000000
149.12000000,3.39251900,2.45200000,0.11363111,221.12083844,0.10762595,246.24704501,0.00069015,0.11141547,250.58502993,-0.07231982,-0.03909566,0.00000000,0.00000000,0.00000000,0.00000000
150.62000000,3.43079100,2.45600000,0.11494411,221.48155759,0.10880428,246.93955836,0.00076949,0.11254571,251.27597155,-0.07304843,-0.03949728,0.00000000,0.00000000,0.00000000,0.00000000
152.12000000,3.46913000,2.46000000,0.11620500,221.84227674,0.10993454,247.62145851,0.00080208,0.11370904,251.87477880,-0.07376186,-0.03994719,0.00000000,0.00000000,0.00000000,0.00000000
153.62000000,3.50760400,2.46400000,0.11745833,222.20299589,0.11105676,248.30258945,0.00067446,0.11485305,252.57162796,-0.07449431,-0.04035874,0.00000000,0.00000000,0.00000000,0.00000000
155.12000000,3.54574200,2.46800000,0.11880133,222.56371504,0.11225787,249.00458114,0.00081393,0.11603015,253.17616711,-0.07526933,-0.04076081,0.00000000,0.00000000,0.00000000,0.00000000
156.62000000,3.58441700,2.47200000,0.12008456,222.92443419,0.11340418,249.69421579,0.00085290,0.11717477,253.87563568,-0.07598770,-0.04118707,0.00000000,0.00000000,0.00000000,0.00000000
158.12000000,3.62299100,2.47600000,0.12137889,223.28515334,0.11455908,250.38725716,0.00081186,0.11833594,254.47837733,-0.07672233,-0.04161361,0.00000000,0.00000000,0.00000000,0.00000000
159.62000000,3.66193500,2.47900000,0.12267333,223.55569270,0.11571275,250.98001471,0.00074439,0.11953186,255.09108064,-0.07748763,-0.04204423,0.00000000,0.00000000,0.00000000,0.00000000
161.12000000,3.70064300,2.48300000,0.12399011,223.91641185,0.11688495,251.67983264,0.00082323,0.12071501,255.80410398,-0.07822325,-0.04249176,0.00000000,0.00000000,0.00000000,0.00000000
162.62000000,3.73928500,2.48700000,0.12528078,224.27713100,0.11803258,252.37474441,0.00070296,0.12189306,256.31194008,-0.07898548,-0.04290758,0.00000000,0.00000000,0.00000000,0.00000000
164.12000000,3.77879900,2.49000000,0.12660133,224.54767036,0.11920543,252.97570483,0.00074851,0.12304067,257.01823690,-0.07968724,-0.04335343,0.00000000,0.00000000,0.00000000,0.00000000
165.62000000,3.81774300,2.49400000,0.12791433,224.90838951,0.12037020,253.67739622,0.00073423,0.12422754,257.63313216,-0.08046308,-0.04376447,0.00000000,0.00000000,0.00000000,0.00000000
167.12000000,3.85708900,2.49700000,0.12923867,225.17892887,0.12154366,254.28075340,0.00076664,0.12537707,258.23945581,-0.08121461,-0.04416246,0.00000000,0.00000000,0.00000000,0.00000000
168.62000000,3.89633500,2.50000000,0.13058522,225.44946823,0.12273539,254.88983714,0.00073918,0.12652204,258.84565868,-0.08193375,-0.04458830,0.00000000,0.00000000,0.00000000,0.00000000
170.12000000,3.93568100,2.50300000,0.13190578,225.72000760,0.12390274,255.49378076,0.00077132,0.12766712,259.34973710,-0.08267293,-0.04499419,0.00000000,0.00000000,0.00000000,0.00000000
171.62000000,3.97546400,2.50600000,0.13325611,225.99054696,0.12509500,256.10516839,0.00076373,0.12884200,259.96574349,-0.08342946,-0.04541254,0.00000000,0.00000000,0.00000000,0.00000000
173.12000000,4.01491100,2.51000000,0.13459156,226.35126611,0.12627272,256.81623511,0.00073657,0.13001857,260.58329116,-0.08417027,-0.04584830,0.00000000,0.00000000,0.00000000,0.00000000
174.62000000,4.05456000,2.51300000,0.13591578,226.62180547,0.12743918,257.42328442,0.00075548,0.13118086,261.19819849,-0.08491151,-0.04626935,0.00000000,0.00000000,0.00000000,0.00000000
176.12000000,4.09437600,2.51600000,0.13723633,226.89234483,0.12860105,258.03021830,0.00078080,0.13235298,261.71307352,-0.08564702,-0.04670596,0.00000000,0.00000000,0.00000000,0.00000000
177.62000000,4.13426000,2.51900000,0.13858678,227.16288419,0.12978782,258.64465634,0.00080933,0.13351569,262.33015091,-0.08639847,-0.04711722,0.00000000,0.00000000,0.00000000,0.00000000
179.12000000,4.17390900,2.52100000,0.13995578,227.34324377,0.13098947,259.16124427,0.00083139,0.13468493,262.84609519,-0.08714368,-0.04754125,0.00000000,0.00000000,0.00000000,0.00000000
180.62000000,4.21359100,2.52400000,0.14127267,227.61378313,0.13214401,259.76938924,0.00087621,0.13584487,263.46450672,-0.08784779,-0.04799709,0.00000000,0.00000000,0.00000000,0.00000000
182.12000000,4.25374300,2.52700000,0.14258933,227.88432249,0.13329703,260.37819611,0.00076391,0.13705010,263.99181437,-0.08863216,-0.04841794,0.00000000,0.00000000,0.00000000,0.00000000
183.62000000,4.29419800,2.53000000,0.14392111,228.15486185,0.13446193,260.99116308,0.00074378,0.13825068,264.51878373,-0.08939605,-0.04885463,0.00000000,0.00000000,0.00000000,0.00000000
185.12000000,4.33421600,2.53200000,0.14527522,228.33522143,0.13564498,261.50667146,0.00081453,0.13944834,265.15031715,-0.09015649,-0.04929184,0.00000000,0.00000000,0.00000000,0.00000000
186.62000000,4.37399900,2.53500000,0.14659578,228.60576079,0.13679736,262.11840010,0.00083298,0.14064736,265.57420268,-0.09092779,-0.04971958,0.00000000,0.00000000,0.00000000,0.00000000
188.12000000,4.41492300,2.53800000,0.14794244,228.87630015,0.13797116,262.73681947,0.00078649,0.14188707,266.21900923,-0.09169580,-0.05019127,0.00000000,0.00000000,0.00000000,0.00000000
189.62000000,4.45537800,2.54000000,0.14930767,229.05665973,0.13915973,263.25657512,0.00077259,0.14312993,266.76101903,-0.09249377,-0.05063616,0.00000000,0.00000000,0.00000000,0.00000000
191.12000000,4.49600000,2.54200000,0.15069911,229.23701930,0.14036968,263.78283434,0.00081069,0.14435518,267.29924830,-0.09325658,-0.05109860,0.00000000,0.00000000,0.00000000,0.00000000
192.62000000,4.53692400,2.54400000,0.15207933,229.41737888,0.14156843,264.30702091,0.00077730,0.14561085,267.84657936,-0.09406076,-0.05155009,0.00000000,0.00000000,0.00000000,0.00000000
194.12000000,4.57798300,2.54700000,0.15346333,229.68791824,0.14276901,264.93659180,0.00073763,0.14682968,268.38494833,-0.09481556,-0.05201412,0.00000000,0.00000000,0.00000000,0.00000000
195.62000000,4.61897500,2.54900000,0.15489944,229.86827781,0.14401328,265.47474634,0.00081409,0.14805034,268.92472976,-0.09560432,-0.05244601,0.00000000,0.00000000,0.00000000,0.00000000
197.12000000,4.66016800,2.55100000,0.15635056,230.04863739,0.14526897,266.01686965,0.00089708,0.14923756,269.45639434,-0.09635146,-0.05288610,0.00000000,0.00000000,0.00000000,0.00000000
198.62000000,4.70139400,2.55400000,0.15777922,230.31917675,0.14650371,266.65875732,0.00083779,0.15041377,269.98596400,-0.09710086,-0.05331291,0.00000000,0.00000000,0.00000000,0.00000000
200.12000000,4.74339300,2.55500000,0.15919311,230.40935654,0.14772417,267.08893883,0.00082411,0.15162190,270.41933274,-0.09788426,-0.05373764,0.00000000,0.00000000,0.00000000,0.00000000
201.62000000,4.78522400,2.55700000,0.16064422,230.58971611,0.14897521,267.63262171,0.00079090,0.15276347,270.94113133,-0.09860484,-0.05415863,0.00000000,0.00000000,0.00000000,0.00000000
203.12000000,4.82708900,2.56000000,0.16208411,230.86025547,0.15021504,268.27903477,0.00086033,0.15390371,271.46341432,-0.09931299,-0.05459071,0.00000000,0.00000000,0.00000000,0.00000000
204.62000000,4.86902100,2.56100000,0.16350533,230.95043526,0.15143729,268.71206316,0.00080807,0.15501238,271.87181473,-0.10002672,-0.05498567,0.00000000,0.00000000,0.00000000,0.00000000
206.12000000,4.91018000,2.56300000,0.16488189,231.13079483,0.15261970,269.24007687,0.00079433,0.15618171,272.40360462,-0.10077658,-0.05540514,0.00000000,0.00000000,0.00000000,0.00000000
207.62000000,4.95228000,2.56500000,0.16633300,231.31115441,0.15386464,269.78583265,0.00083184,0.15728634,272.91854707,-0.10147771,-0.05580863,0.00000000,0.00000000,0.00000000,0.00000000
209.12000000,4.99464800,2.56700000,0.16767589,231.49151398,0.15501535,270.30705936,0.00083088,0.15845446,273.34524813,-0.10221564,-0.05623882,0.00000000,0.00000000,0.00000000,0.00000000
210.62000000,5.03684800,2.56800000,0.16901889,231.58169377,0.15616484,270.72337434,0.00070214,0.15961971,273.87839370,-0.10294676,-0.05667294,0.00000000,0.00000000,0.00000000,0.00000000
212.12000000,5.07881300,2.57000000,0.17039900,231.76205334,0.15734472,271.25407547,0.00076494,0.16081661,274.31440321,-0.10369535,-0.05712126,0.00000000,0.00000000,0.00000000,0.00000000
213.62000000,5.12094600,2.57200000,0.17174189,231.94241292,0.15849144,271.77664103,0.00082781,0.16207488,274.76799563,-0.10452499,-0.05754989,0.00000000,0.00000000,0.00000000,0.00000000
215.12000000,5.16314600,2.57300000,0.17304744,232.03259271,0.15960502,272.18523990,0.00076321,0.16333174,275.22190890,-0.10532144,-0.05801031,0.00000000,0.00000000,0.00000000,0.00000000
216.62000000,5.20511200,2.57500000,0.17439044,232.21295228,0.16074924,272.70867224,0.00069892,0.16461683,275.79149209,-0.10611163,-0.05850519,0.00000000,0.00000000,0.00000000,0.00000000
218.12000000,5.24664000,2.57600000,0.17573333,232.30313207,0.16189207,273.12653581,0.00069813,0.16596441,276.27213860,-0.10697464,-0.05898977,0.00000000,0.00000000,0.00000000,0.00000000
219.62000000,5.28907500,2.57800000,0.17715078,232.48349164,0.16309692,273.66812301,0.00082400,0.16731016,276.75307441,-0.10781491,-0.05949524,0.00000000,0.00000000,0.00000000,0.00000000
221.12000000,5.33140900,2.58000000,0.17856822,232.66385122,0.16430033,274.21022150,0.00082301,0.16871656,277.25169297,-0.10870185,-0.06001471,0.00000000,0.00000000,0.00000000,0.00000000
222.62000000,5.37438100,2.58100000,0.18002311,232.75403100,0.16553402,274.65513579,0.00082200,0.17015070,277.86665317,-0.10957790,-0.06057280,0.00000000,0.00000000,0.00000000,0.00000000
224.12000000,5.41745400,2.58200000,0.18147800,232.84421079,0.16676620,275.10031248,0.00082117,0.17170898,278.40960492,-0.11056821,-0.06114076,0.00000000,0.00000000,0.00000000,0.00000000
225.62000000,5.46106400,2.58300000,0.18300733,232.93439058,0.16805978,275.56309224,0.00088307,0.17326480,278.95289306,-0.11151799,-0.06174680,0.00000000,0.00000000,0.00000000,0.00000000
227.12000000,5.50544600,2.58500000,0.18461133,233.11475015,0.16941473,276.15037500,0.00100780,0.17481817,279.49651759,-0.11247822,-0.06233995,0.00000000,0.00000000,0.00000000,0.00000000
228.62000000,5.54929200,2.58600000,0.18617811,233.20492994,0.17073647,276.62258330,0.00088071,0.17640016,280.04920839,-0.11345194,-0.06294821,0.00000000,0.00000000,0.00000000,0.00000000
230.12000000,5.59394200,2.58700000,0.18785667,233.29510973,0.17215056,277.12115139,0.00094216,0.17794718,280.70170528,-0.11440632,-0.06354086,0.00000000,0.00000000,0.00000000,0.00000000
231.62000000,5.63899600,2.58800000,0.18957256,233.38528952,0.17359405,277.62873528,0.00094080,0.17949483,281.13819814,-0.11537681,-0.06411802,0.00000000,0.00000000,0.00000000,0.00000000
233.12000000,5.68478900,2.59000000,0.19140033,233.56564909,0.17512937,278.27019218,0.00100206,0.18100755,281.67443164,-0.11634561,-0.06466194,0.00000000,0.00000000,0.00000000,0.00000000
234.62000000,5.73007700,2.59100000,0.19319089,233.65582888,0.17663114,278.79600615,0.00100056,0.18242555,282.18481678,-0.11723721,-0.06518835,0.00000000,0.00000000,0.00000000,0.00000000
236.12000000,5.77603700,2.59200000,0.19505600,233.74600867,0.17819305,279.33957013,0.00093667,0.18381215,282.57792930,-0.11815408,-0.06565807,0.00000000,0.00000000,0.00000000,0.00000000
237.62000000,5.82152700,2.59300000,0.19695844,233.83618845,0.17978371,279.89220038,0.00099741,0.18504148,283.03629500,-0.11895120,-0.06609028,0.00000000,0.00000000,0.00000000,0.00000000
239.12000000,5.86728600,2.59400000,0.19886089,233.92636824,0.18137185,280.44517376,0.00105814,0.18614794,283.35089050,-0.11967454,-0.06647340,0.00000000,0.00000000,0.00000000,0.00000000
240.62000000,5.91307700,2.59500000,0.20076344,234.01654803,0.18295756,280.99851627,0.00111868,0.18715966,283.74847392,-0.12036976,-0.06678991,0.00000000,0.00000000,0.00000000,0.00000000
242.12000000,5.95950700,2.59600000,0.20255400,234.10672781,0.18444763,281.52598196,0.00099276,0.18808002,284.01079417,-0.12099132,-0.06708871,0.00000000,0.00000000,0.00000000,0.00000000
243.62000000,6.00650800,2.59600000,0.20430733,234.10672781,0.18590457,281.93644909,0.00086745,0.18881421,284.33002369,-0.12143081,-0.06738340,0.00000000,0.00000000,0.00000000,0.00000000
245.12000000,6.05347500,2.59700000,0.20602311,234.19690760,0.18732826,282.44688312,0.00092797,0.18960886,284.66685016,-0.12199063,-0.06761823,0.00000000,0.00000000,0.00000000,0.00000000
246.62000000,6.10134900,2.59700000,0.20751511,234.19690760,0.18856462,282.79630490,0.00080310,0.19028040,284.96881081,-0.12242404,-0.06785636,0.00000000,0.00000000,0.00000000,0.00000000
248.12000000,6.14979400,2.59800000,0.20900711,234.28708739,0.18979945,283.25475469,0.00080229,0.19095176,285.27099768,-0.12285541,-0.06809634,0.00000000,0.00000000,0.00000000,0.00000000
249.62000000,6.19911100,2.59800000,0.21020078,234.28708739,0.19078628,283.53441538,0.00067824,0.19162265,285.57333258,-0.12330712,-0.06831553,0.00000000,0.00000000,0.00000000,0.00000000
251.12000000,6.24883100,2.59900000,0.21139456,234.37726718,0.19177222,283.92334540,0.00067757,0.19220306,285.73979965,-0.12363132,-0.06857174,0.00000000,0.00000000,0.00000000,0.00000000
252.62000000,6.29912200,2.60000000,0.21240189,234.46744696,0.19260342,284.26877558,0.00055398,0.19287302,286.04232042,-0.12412381,-0.06874921,0.00000000,0.00000000,0.00000000,0.00000000
254.12000000,6.34860700,2.60100000,0.21329722,234.55762675,0.19334163,284.58811699,0.00043046,0.19360200,286.47242235,-0.12462213,-0.06897987,0.00000000,0.00000000,0.00000000,0.00000000
255.62000000,6.39624600,2.60200000,0.21415500,234.64780654,0.19404836,284.89880755,0.00043016,0.19445368,286.82792380,-0.12519315,-0.06926053,0.00000000,0.00000000,0.00000000,0.00000000
257.12000000,6.44166900,2.60200000,0.21501289,234.64780654,0.19475468,285.10010929,0.00042985,0.00000000,0.00000000,0.00000000,0.00000000,0.00000000,0.00000000,0.00000000,0.00000000
258.62000000,6.48021100,2.60300000,0.21579633,234.73798633,0.19539928,285.39358307,0.00042958,0.00000000,0.00000000,0.00000000,0.00000000,0.00000000,0.00000000,0.00000000,0.00000000
260.12000000,6.51331300,2.60400000,0.21657989,234.82816611,0.19604355,285.68722424,0.00036791,0.00000000,0.00000000,0.00000000,0.00000000,0.00000000,0.00000000,0.00000000,0.00000000
261.62000000,6.54369600,2.60500000,0.21736344,234.91834590,0.19668741,285.98100673,0.00036786,0.00000000,0.00000000,0.00000000,0.00000000,0.00000000,0.00000000,0.00000000,0.00000000
263.12000000,6.57313800,2.60600000,0.21825867,235.00852569,0.19742252,286.30117316,0.00049019,0.00000000,0.00000000,0.00000000,0.00000000,0.00000000,0.00000000,0.00000000,0.00000000
264.62000000,6.60412500,2.60800000,0.21919122,235.18888526,0.19818771,286.74022448,0.00055090,0.00000000,0.00000000,0.00000000,0.00000000,0.00000000,0.00000000,0.00000000,0.00000000
266.12000000,6.63944200,2.60900000,0.22038478,235.27906505,0.00000000,0.00000000,0.00000000,0.00000000,0.00000000,0.00000000,0.00000000,0.00000000,0.00000000,0.00000000,0.00000000
267.62000000,6.68070300,2.60800000,0.22206333,235.18888526,0.00000000,0.00000000,0.00000000,0.00000000,0.00000000,0.00000000,0.00000000,0.00000000,0.00000000,0.00000000,0.00000000
269.12000000,6.72753600,2.60700000,0.22426389,235.09870547,0.00000000,0.00000000,0.00000000,0.00000000,0.00000000,0.00000000,0.00000000,0.00000000,0.00000000,0.00000000,0.00000000
270.62000000,6.77812800,2.60500000,0.22706100,234.91834590,0.00000000,0.00000000,0.00000000,0.00000000,0.00000000,0.00000000,0.00000000,0.00000000,0.00000000,0.00000000,0.00000000
272.12000000,6.83093600,2.60400000,0.23008189,234.82816611,0.00000000,0.00000000,0.00000000,0.00000000,0.00000000,0.00000000,0.00000000,0.00000000,0.00000000,0.00000000,0.00000000
273.62000000,6.88431700,2.60500000,0.23299156,234.91834590,0.00000000,0.00000000,0.00000000,0.00000000,0.00000000,0.00000000,0.00000000,0.00000000,0.00000000,0.00000000,0.00000000
275.12000000,6.93900800,2.60500000,0.23593922,234.91834590,0.00000000,0.00000000,0.00000000,0.00000000,0.00000000,0.00000000,0.00000000,0.00000000,0.00000000,0.00000000,0.00000000
276.62000000,6.99406600,2.60500000,0.23914811,234.91834590,0.00000000,0.00000000,0.00000000,0.00000000,0.00000000,0.00000000,0.00000000,0.00000000,0.00000000,0.00000000,0.00000000
278.12000000,7.04962700,2.60500000,0.24243111,234.91834590,0.00000000,0.00000000,0.00000000,0.00000000,0.00000000,0.00000000,0.00000000,0.00000000,0.00000000,0.00000000,0.00000000
279.62000000,7.10502000,2.60500000,0.24586244,234.91834590,0.00000000,0.00000000,0.00000000,0.00000000,0.00000000,0.00000000,0.00000000,0.00000000,0.00000000,0.00000000,0.00000000
281.12000000,7.16138800,2.60500000,0.24959189,234.91834590,0.00000000,0.00000000,0.00000000,0.00000000,0.00000000,0.00000000,0.00000000,0.00000000,0.00000000,0.00000000,0.00000000
282.62000000,7.21674900,2.60400000,0.25354544,234.82816611,0.00000000,0.00000000,0.00000000,0.00000000,0.00000000,0.00000000,0.00000000,0.00000000,0.00000000,0.00000000,0.00000000
284.12000000,7.27331800,2.60300000,0.25790933,234.73798633,0.00000000,0.00000000,0.00000000,0.00000000,0.00000000,0.00000000,0.00000000,0.00000000,0.00000000,0.00000000,0.00000000
285.62000000,7.33143200,2.60100000,0.26249767,234.55762675,0.00000000,0.00000000,0.00000000,0.00000000,0.00000000,0.00000000,0.00000000,0.00000000,0.00000000,0.00000000,0.00000000
287.12000000,7.38941200,2.59900000,0.26708633,234.37726718,0.00000000,0.00000000,0.00000000,0.00000000,0.00000000,0.00000000,0.00000000,0.00000000,0.00000000,0.00000000,0.00000000
288.62000000,7.44708900,2.59700000,0.27148822,234.19690760,0.00000000,0.00000000,0.00000000,0.00000000,0.00000000,0.00000000,0.00000000,0.00000000,0.00000000,0.00000000,0.00000000
290.12000000,7.50516700,2.59300000,0.27570289,233.83618845,0.00000000,0.00000000,0.00000000,0.00000000,0.00000000,0.00000000,0.00000000,0.00000000,0.00000000,0.00000000,0.00000000
291.62000000,7.56398300,2.58900000,0.27999189,233.47546930,0.00000000,0.00000000,0.00000000,0.00000000,0.00000000,0.00000000,0.00000000,0.00000000,0.00000000,0.00000000,0.00000000
293.12000000,7.62296800,2.58500000,0.28469156,233.11475015,0.00000000,0.00000000,0.00000000,0.00000000,0.00000000,0.00000000,0.00000000,0.00000000,0.00000000,0.00000000,0.00000000
294.62000000,7.68215600,2.57900000,0.28991367,232.57367143,0.00000000,0.00000000,0.00000000,0.00000000,0.00000000,0.00000000,0.00000000,0.00000000,0.00000000,0.00000000,0.00000000
296.12000000,7.74157700,2.57000000,0.29565800,231.76205334,0.00000000,0.00000000,0.00000000,0.00000000,0.00000000,0.00000000,0.00000000,0.00000000,0.00000000,0.00000000,0.00000000
297.62000000,7.80197000,2.55900000,0.30181233,230.77007568,0.00000000,0.00000000,0.00000000,0.00000000,0.00000000,0.00000000,0.00000000,0.00000000,0.00000000,0.00000000,0.00000000
299.12000000,7.86397400,2.54300000,0.30822911,229.32719909,0.00000000,0.00000000,0.00000000,0.00000000,0.00000000,0.00000000,0.00000000,0.00000000,0.00000000,0.00000000,0.00000000
300.62000000,7.92648300,2.51700000,0.31498533,226.98252462,0.00000000,0.00000000,0.00000000,0.00000000,0.00000000,0.00000000,0.00000000,0.00000000,0.00000000,0.00000000,0.00000000
302.12000000,7.99118000,2.47800000,0.32223300,223.46551291,0.00000000,0.00000000,0.00000000,0.00000000,0.00000000,0.00000000,0.00000000,0.00000000,0.00000000,0.00000000,0.00000000
303.62000000,8.05853700,2.41800000,0.32997444,218.05472568,0.00000000,0.00000000,0.00000000,0.00000000,0.00000000,0.00000000,0.00000000,0.00000000,0.00000000,0.00000000,0.00000000
305.12000000,8.12993800,2.31500000,0.33858800,208.76620758,0.00000000,0.00000000,0.00000000,0.00000000,0.00000000,0.00000000,0.00000000,0.00000000,0.00000000,0.00000000,0.00000000
306.62000000,8.50419600,0.02900000,0.36851378,2.61521383,0.00000000,0.00000000,0.00000000,0.00000000,0.00000000,0.00000000,0.00000000,0.00000000,0.00000000,0.00000000,0.00000000
NaN,-100.00000000,NaN,-11.11111111,NaN,0.00000000,0.00000000,0.00000000,0.00000000,0.00000000,0.00000000,0.00000000,0.00000000,0.00000000,0.00000000,0.00000000