File: polyN_optimization/results_exp/AA6014-T4/UT_30_3.csv
Time[s],Displacement[mm],Force[kN],EngStrain_longi,EngStress[MPa],TrueStrain,TrueStress[MPa],TrueStrainRate[1/s],PlasticStrain_longi,PlasticStress[MPa],PlasticStrain_thick,PlasticStrain_width,R-Value,Thickness[mm],Width[mm], Young's Modulus [MPa]
0.61000000,0.00000000,-0.00100000,0.00000000,-0.09049364,0.00000000,-0.09049364,0.00000000,0.00051710,116.53559562,-0.00000085,-0.00051625,0.56578525,1.11200000,9.93750000,73898.79643335
2.11000000,0.00609400,0.17600000,0.00018089,15.92688114,0.00018087,15.92976213,0.00013265,0.00170757,121.40418955,-0.00085751,-0.00085006,0.00000000,0.00000000,0.00000000,0.00000000
3.61000000,0.01404300,0.41700000,0.00044056,37.73584906,0.00044046,37.75247379,0.00005686,0.00289103,125.46429754,-0.00164105,-0.00124998,0.00000000,0.00000000,0.00000000,0.00000000
5.11000000,0.02288600,0.65500000,0.00077144,59.27333605,0.00077115,59.31906213,0.00029157,0.00401827,128.61513027,-0.00238112,-0.00163715,0.00000000,0.00000000,0.00000000,0.00000000
6.61000000,0.03200100,0.92200000,0.00109189,83.43513868,0.00109129,83.52624058,0.00038695,0.00521114,131.59924697,-0.00319747,-0.00201367,0.00000000,0.00000000,0.00000000,0.00000000
8.11000000,0.04403100,1.15200000,0.00139700,104.24867653,0.00139603,104.39431193,0.00034865,0.00645999,134.23240145,-0.00406445,-0.00239555,0.00000000,0.00000000,0.00000000,0.00000000
9.61000000,0.06914200,1.28500000,0.00216078,116.28433103,0.00215845,116.53559562,0.00048812,0.00765333,136.68143241,-0.00489274,-0.00276059,0.00000000,0.00000000,0.00000000,0.00000000
11.11000000,0.10447500,1.33700000,0.00342333,120.99000045,0.00341749,121.40418955,0.00070593,0.00875250,139.12316130,-0.00564598,-0.00310652,0.00000000,0.00000000,0.00000000,0.00000000
12.61000000,0.14049700,1.38000000,0.00466900,124.88122709,0.00465813,125.46429754,0.00089447,0.00993101,141.39799687,-0.00645368,-0.00347733,0.00000000,0.00000000,0.00000000,0.00000000
14.11000000,0.17662700,1.41300000,0.00584678,127.86751731,0.00582975,128.61513027,0.00088060,0.01110107,143.58505823,-0.00723942,-0.00386165,0.00000000,0.00000000,0.00000000,0.00000000
15.61000000,0.21411100,1.44400000,0.00708967,130.67282023,0.00706465,131.59924697,0.00084088,0.01222439,145.86233764,-0.00798170,-0.00424269,0.00000000,0.00000000,0.00000000,0.00000000
17.11000000,0.25034300,1.47100000,0.00838556,133.11614859,0.00835059,134.23240145,0.00094342,0.01331711,147.86388781,-0.00869753,-0.00461958,0.00000000,0.00000000,0.00000000,0.00000000
18.61000000,0.28742400,1.49600000,0.00962444,135.37848966,0.00957842,136.68143241,0.00102088,0.01447810,149.88000606,-0.00947875,-0.00499934,0.00000000,0.00000000,0.00000000,0.00000000
20.11000000,0.32327500,1.52100000,0.01076956,137.64083073,0.01071198,139.12316130,0.00090051,0.01562782,152.08363682,-0.01024641,-0.00538141,0.00000000,0.00000000,0.00000000,0.00000000
21.61000000,0.35912100,1.54400000,0.01199389,139.72218452,0.01192253,141.39799687,0.00078452,0.01673973,154.00916329,-0.01094384,-0.00579589,0.00000000,0.00000000,0.00000000,0.00000000
23.11000000,0.39528400,1.56600000,0.01320989,141.71304466,0.01312340,143.58505823,0.00084699,0.01782964,155.84292459,-0.01165020,-0.00617944,0.00000000,0.00000000,0.00000000,0.00000000
24.61000000,0.43029400,1.58900000,0.01438122,143.79439844,0.01427879,145.86233764,0.00086070,0.01897393,157.87446834,-0.01241664,-0.00655729,0.00000000,0.00000000,0.00000000,0.00000000
26.11000000,0.46611500,1.60900000,0.01551889,145.60427130,0.01539970,147.86388781,0.00069074,0.02009771,159.72179379,-0.01318956,-0.00690816,0.00000000,0.00000000,0.00000000,0.00000000
27.61000000,0.50164300,1.62900000,0.01672744,147.41414416,0.01658908,149.88000606,0.00066783,0.02116912,161.56468817,-0.01384790,-0.00732122,0.00000000,0.00000000,0.00000000,0.00000000
29.11000000,0.53696300,1.65100000,0.01792867,149.40500430,0.01776984,152.08363682,0.00074785,0.02229000,163.41954942,-0.01459671,-0.00769329,0.00000000,0.00000000,0.00000000,0.00000000
30.61000000,0.57227000,1.67000000,0.01908878,151.12438351,0.01890887,154.00916329,0.00079804,0.02341235,165.09256806,-0.01536528,-0.00804707,0.00000000,0.00000000,0.00000000,0.00000000
32.11000000,0.60747700,1.68800000,0.02022644,152.75326908,0.02002461,155.84292459,0.00064353,0.02452102,166.86010794,-0.01610175,-0.00841926,0.00000000,0.00000000,0.00000000,0.00000000
33.61000000,0.64231100,1.70800000,0.02142378,154.56314194,0.02119751,157.87446834,0.00070850,0.02562113,168.63000781,-0.01681484,-0.00880629,0.00000000,0.00000000,0.00000000,0.00000000
35.11000000,0.67701400,1.72600000,0.02259889,156.19202751,0.02234732,159.72179379,0.00078813,0.02672856,170.31154777,-0.01755960,-0.00916896,0.00000000,0.00000000,0.00000000,0.00000000
36.61000000,0.71183800,1.74400000,0.02372167,157.82091308,0.02344468,161.56468817,0.00071430,0.02783588,171.90316602,-0.01827988,-0.00955600,0.00000000,0.00000000,0.00000000,0.00000000
38.11000000,0.74673200,1.76200000,0.02489656,159.44979865,0.02459169,163.41954942,0.00067682,0.02890822,173.58569629,-0.01899792,-0.00991031,0.00000000,0.00000000,0.00000000,0.00000000
39.61000000,0.78191500,1.77800000,0.02607167,160.89769694,0.02573759,165.09256806,0.00073454,0.03000210,175.18179021,-0.01971797,-0.01028413,0.00000000,0.00000000,0.00000000,0.00000000
41.11000000,0.81656100,1.79500000,0.02723544,162.43608886,0.02687116,166.86010794,0.00077721,0.03112716,176.78676815,-0.02048854,-0.01063862,0.00000000,0.00000000,0.00000000,0.00000000
42.61000000,0.85147700,1.81200000,0.02839178,163.97448079,0.02799620,168.63000781,0.00075450,0.03221489,178.38853393,-0.02118318,-0.01103171,0.00000000,0.00000000,0.00000000,0.00000000
44.11000000,0.88575400,1.82800000,0.02955567,165.42237908,0.02912732,170.31154777,0.00071025,0.03329551,179.89833120,-0.02190386,-0.01139164,0.00000000,0.00000000,0.00000000,0.00000000
45.61000000,0.92033300,1.84300000,0.03071944,166.77978372,0.03025705,171.90316602,0.00080348,0.03439997,181.41558578,-0.02261296,-0.01178700,0.00000000,0.00000000,0.00000000,0.00000000
47.11000000,0.95457600,1.85900000,0.03184978,168.22768201,0.03135309,173.58569629,0.00073043,0.03550664,182.93644444,-0.02333144,-0.01217520,0.00000000,0.00000000,0.00000000,0.00000000
48.61000000,0.98942400,1.87400000,0.03300233,169.58508665,0.03246945,175.18179021,0.00072940,0.03659190,184.36219921,-0.02405618,-0.01253572,0.00000000,0.00000000,0.00000000,0.00000000
50.11000000,1.02396900,1.88900000,0.03418856,170.94249129,0.03361711,176.78676815,0.00075027,0.03770093,185.79531673,-0.02480954,-0.01289139,0.00000000,0.00000000,0.00000000,0.00000000
51.61000000,1.05851500,1.90400000,0.03533744,172.29989593,0.03472741,178.38853393,0.00076383,0.03876807,187.31815333,-0.02545008,-0.01331799,0.00000000,0.00000000,0.00000000,0.00000000
53.11000000,1.09326100,1.91800000,0.03647889,173.56680693,0.03582928,179.89833120,0.00072717,0.03985450,188.65839446,-0.02617245,-0.01368205,0.00000000,0.00000000,0.00000000,0.00000000
54.61000000,1.12777400,1.93200000,0.03764644,174.83371793,0.03695511,181.41558578,0.00076213,0.04096449,190.00586821,-0.02693080,-0.01403369,0.00000000,0.00000000,0.00000000,0.00000000
56.11000000,1.16248600,1.94600000,0.03881767,176.10062893,0.03808321,182.93644444,0.00076127,0.04204355,191.44510775,-0.02760233,-0.01444122,0.00000000,0.00000000,0.00000000,0.00000000
57.61000000,1.19720000,1.95900000,0.03996656,177.27704629,0.03918855,184.36219921,0.00077496,0.04310481,192.78885445,-0.02829044,-0.01481437,0.00000000,0.00000000,0.00000000,0.00000000
59.11000000,1.23198000,1.97200000,0.04114156,178.45346364,0.04031776,185.79531673,0.00079544,0.04420174,194.04712927,-0.02902914,-0.01517260,0.00000000,0.00000000,0.00000000,0.00000000
60.61000000,1.26635700,1.98600000,0.04227556,179.72037464,0.04140636,187.31815333,0.00077324,0.04531020,195.40544923,-0.02971555,-0.01559465,0.00000000,0.00000000,0.00000000,0.00000000
62.11000000,1.30103800,1.99800000,0.04342822,180.80629836,0.04251166,188.65839446,0.00072232,0.04641735,196.76633727,-0.03044749,-0.01596986,0.00000000,0.00000000,0.00000000,0.00000000
63.61000000,1.33608600,2.01000000,0.04460689,181.89222207,0.04364063,190.00586821,0.00072853,0.04750337,198.03042445,-0.03113735,-0.01636602,0.00000000,0.00000000,0.00000000,0.00000000
65.11000000,1.37056400,2.02300000,0.04575589,183.06863943,0.04473996,191.44510775,0.00072794,0.04860223,199.29963990,-0.03187136,-0.01673087,0.00000000,0.00000000,0.00000000,0.00000000
66.61000000,1.40497600,2.03500000,0.04688611,184.15456314,0.04582015,192.78885445,0.00069127,0.04966942,200.46943790,-0.03255974,-0.01710968,0.00000000,0.00000000,0.00000000,0.00000000
68.11000000,1.44002500,2.04600000,0.04805367,185.14999321,0.04693479,194.04712927,0.00076898,0.05078465,201.65126139,-0.03330864,-0.01747601,0.00000000,0.00000000,0.00000000,0.00000000
69.61000000,1.47530900,2.05800000,0.04923611,186.23591693,0.04806239,195.40544923,0.00069692,0.05185862,202.92297640,-0.03399448,-0.01786415,0.00000000,0.00000000,0.00000000,0.00000000
71.11000000,1.51039000,2.07000000,0.05041856,187.32184064,0.04918871,196.76633727,0.00067498,0.05295378,204.10560961,-0.03471283,-0.01824096,0.00000000,0.00000000,0.00000000,0.00000000
72.61000000,1.54520400,2.08100000,0.05157867,188.31727071,0.05029253,198.03042445,0.00075224,0.05403711,205.28819312,-0.03540798,-0.01862913,0.00000000,0.00000000,0.00000000,0.00000000
74.11000000,1.58001800,2.09200000,0.05275367,189.31270078,0.05140927,199.29963990,0.00078666,0.05514732,206.47870626,-0.03610791,-0.01903941,0.00000000,0.00000000,0.00000000,0.00000000
75.61000000,1.61513300,2.10200000,0.05389511,190.21763721,0.05249293,200.46943790,0.00071515,0.05626802,207.57754284,-0.03684937,-0.01941865,0.00000000,0.00000000,0.00000000,0.00000000
77.11000000,1.64981200,2.11200000,0.05508867,191.12257364,0.05362481,201.65126139,0.00076364,0.05734757,208.76640405,-0.03753588,-0.01981169,0.00000000,0.00000000,0.00000000,0.00000000
78.61000000,1.68496200,2.12300000,0.05624133,192.11800371,0.05471669,202.92297640,0.00077712,0.05843432,209.86264033,-0.03823956,-0.02019476,0.00000000,0.00000000,0.00000000,0.00000000
80.11000000,1.72001100,2.13300000,0.05741633,193.02294014,0.05582851,204.10560961,0.00078319,0.05954762,210.96666395,-0.03896774,-0.02057988,0.00000000,0.00000000,0.00000000,0.00000000
81.61000000,1.75539500,2.14300000,0.05858011,193.92787657,0.05692849,205.28819312,0.00072584,0.06062969,211.96955110,-0.03966793,-0.02096176,0.00000000,0.00000000,0.00000000,0.00000000
83.11000000,1.79104700,2.15300000,0.05977378,194.83281299,0.05805547,206.47870626,0.00072523,0.06172173,213.17018995,-0.04040090,-0.02132083,0.00000000,0.00000000,0.00000000,0.00000000
84.61000000,1.82669900,2.16200000,0.06097856,195.64725578,0.05919165,207.57754284,0.00078769,0.06281524,214.17966592,-0.04110090,-0.02171433,0.00000000,0.00000000,0.00000000,0.00000000
86.11000000,1.86211700,2.17200000,0.06214233,196.55219221,0.06028794,208.76640405,0.00076569,0.06393888,215.19762963,-0.04182069,-0.02211819,0.00000000,0.00000000,0.00000000,0.00000000
87.61000000,1.89726700,2.18100000,0.06331367,197.36663499,0.06139013,209.86264033,0.00065278,0.06504929,216.31193557,-0.04256381,-0.02248548,0.00000000,0.00000000,0.00000000,0.00000000
89.11000000,1.93288500,2.19000000,0.06451467,198.18107778,0.06251898,210.96666395,0.00073579,0.06614251,217.32746138,-0.04327662,-0.02286589,0.00000000,0.00000000,0.00000000,0.00000000
90.61000000,1.96847000,2.19800000,0.06568222,198.90502692,0.06361518,211.96955110,0.00070014,0.06728300,218.35533300,-0.04403411,-0.02324889,0.00000000,0.00000000,0.00000000,0.00000000
92.11000000,2.00405600,2.20800000,0.06686467,199.80996335,0.06472413,213.17018995,0.00074833,0.06839576,219.28169380,-0.04476747,-0.02362829,0.00000000,0.00000000,0.00000000,0.00000000
93.61000000,2.03994400,2.21600000,0.06804711,200.53391249,0.06583185,214.17966592,0.00069152,0.06948166,220.30154485,-0.04544918,-0.02403248,0.00000000,0.00000000,0.00000000,0.00000000
95.11000000,2.07583200,2.22400000,0.06926322,201.25786164,0.06696983,215.19762963,0.00070487,0.07059538,221.23183711,-0.04615334,-0.02444204,0.00000000,0.00000000,0.00000000,0.00000000
96.61000000,2.11195500,2.23300000,0.07046800,202.07230442,0.06809594,216.31193557,0.00073190,0.07171332,222.26272635,-0.04688699,-0.02482633,0.00000000,0.00000000,0.00000000,0.00000000
98.11000000,2.14754100,2.24100000,0.07165422,202.79625356,0.06920346,217.32746138,0.00073814,0.07286233,223.20468648,-0.04762868,-0.02523365,0.00000000,0.00000000,0.00000000,0.00000000
99.61000000,2.18433500,2.24900000,0.07289267,203.52020271,0.07035843,218.35533300,0.00078598,0.07394117,224.13276406,-0.04831673,-0.02562444,0.00000000,0.00000000,0.00000000,0.00000000
101.11000000,2.22032400,2.25600000,0.07410122,204.15365821,0.07148424,219.28169380,0.00079897,0.07501183,225.06076246,-0.04900866,-0.02600316,0.00000000,0.00000000,0.00000000,0.00000000
102.61000000,2.25638100,2.26400000,0.07528367,204.87760735,0.07258450,220.30154485,0.00077721,0.07615352,226.00662145,-0.04972954,-0.02642398,0.00000000,0.00000000,0.00000000,0.00000000
104.11000000,2.29253700,2.27100000,0.07649600,205.51106285,0.07371132,221.23183711,0.00076931,0.07725953,226.94624597,-0.05046811,-0.02679142,0.00000000,0.00000000,0.00000000,0.00000000
105.61000000,2.32913100,2.27900000,0.07771578,206.23501199,0.07484378,222.26272635,0.00071316,0.07839300,227.79547311,-0.05117632,-0.02721669,0.00000000,0.00000000,0.00000000,0.00000000
107.11000000,2.36552200,2.28600000,0.07896911,206.86846749,0.07600606,223.20468648,0.00077455,0.07948752,228.63741906,-0.05191728,-0.02757025,0.00000000,0.00000000,0.00000000,0.00000000
108.61000000,2.40181300,2.29300000,0.08014789,207.50192299,0.07709797,224.13276406,0.00075313,0.08060681,229.58538461,-0.05261509,-0.02799173,0.00000000,0.00000000,0.00000000,0.00000000
110.11000000,2.43787000,2.30000000,0.08131911,208.13537849,0.07818170,225.06076246,0.00067624,0.08175691,230.44349306,-0.05335626,-0.02840065,0.00000000,0.00000000,0.00000000,0.00000000
111.61000000,2.47459700,2.30700000,0.08256878,208.76883399,0.07933671,226.00662145,0.00073070,0.08284762,231.28951133,-0.05403347,-0.02881414,0.00000000,0.00000000,0.00000000,0.00000000
113.11000000,2.51152600,2.31400000,0.08378111,209.40228949,0.08045596,226.94624597,0.00070917,0.08396440,232.14319280,-0.05477498,-0.02918941,0.00000000,0.00000000,0.00000000,0.00000000
114.61000000,2.54811900,2.32000000,0.08502322,209.94525135,0.08160139,227.79547311,0.00072905,0.08512408,233.00854392,-0.05554281,-0.02958127,0.00000000,0.00000000,0.00000000,0.00000000
116.11000000,2.58518200,2.32600000,0.08622433,210.48821320,0.08270777,228.63741906,0.00066623,0.08623479,233.86411740,-0.05623475,-0.03000004,0.00000000,0.00000000,0.00000000,0.00000000
117.61000000,2.62110500,2.33300000,0.08745533,211.12166870,0.08384041,229.58538461,0.00074111,0.08736455,234.72581136,-0.05697873,-0.03038581,0.00000000,0.00000000,0.00000000,0.00000000
119.11000000,2.65850400,2.33900000,0.08871989,211.66463056,0.08500259,230.44349306,0.00080192,0.08847751,235.48568061,-0.05770506,-0.03077245,0.00000000,0.00000000,0.00000000,0.00000000
120.61000000,2.69543300,2.34500000,0.08992100,212.20759242,0.08610522,231.28951133,0.00071884,0.08960948,236.25147185,-0.05842468,-0.03118479,0.00000000,0.00000000,0.00000000,0.00000000
122.11000000,2.73169000,2.35100000,0.09115200,212.75055427,0.08723402,232.14319280,0.00075918,0.09071514,237.11220624,-0.05912917,-0.03158596,0.00000000,0.00000000,0.00000000,0.00000000
123.61000000,2.76929100,2.35700000,0.09243144,213.29351613,0.08840589,233.00854392,0.00082646,0.09180734,237.87150003,-0.05982497,-0.03198237,0.00000000,0.00000000,0.00000000,0.00000000
125.11000000,2.80655500,2.36300000,0.09365867,213.83647799,0.08952865,233.86411740,0.00081192,0.09296238,238.64723074,-0.06055823,-0.03240415,0.00000000,0.00000000,0.00000000,0.00000000
126.61000000,2.84382000,2.36900000,0.09490822,214.37943984,0.09067054,234.72581136,0.00080408,0.09405547,239.40957121,-0.06126023,-0.03279524,0.00000000,0.00000000,0.00000000,0.00000000
128.11000000,2.88095100,2.37400000,0.09613922,214.83190806,0.09179421,235.48568061,0.00074193,0.09517753,240.18029094,-0.06198188,-0.03319565,0.00000000,0.00000000,0.00000000,0.00000000
129.61000000,2.91794700,2.37900000,0.09739256,215.28437627,0.09293696,236.25147185,0.00079558,0.09634549,240.96355479,-0.06272816,-0.03361733,0.00000000,0.00000000,0.00000000,0.00000000
131.11000000,2.95561500,2.38500000,0.09861989,215.82733813,0.09405475,237.11220624,0.00078801,0.09745290,241.63320928,-0.06341962,-0.03403328,0.00000000,0.00000000,0.00000000,0.00000000
132.61000000,2.99277900,2.39000000,0.09983222,216.27980634,0.09515764,237.87150003,0.00069214,0.09858454,242.41050874,-0.06414727,-0.03443727,0.00000000,0.00000000,0.00000000,0.00000000
134.11000000,3.03001000,2.39500000,0.10111533,216.73227456,0.09632361,238.64723074,0.00071839,0.09970137,243.18566219,-0.06486811,-0.03483326,0.00000000,0.00000000,0.00000000,0.00000000
135.61000000,3.06730900,2.40000000,0.10233144,217.18474277,0.09742743,239.40957121,0.00073797,0.10087059,243.97508610,-0.06563353,-0.03523707,0.00000000,0.00000000,0.00000000,0.00000000
137.11000000,3.10548000,2.40500000,0.10358100,217.63721099,0.09856035,240.18029094,0.00072343,0.10201443,244.55799474,-0.06636160,-0.03565283,0.00000000,0.00000000,0.00000000,0.00000000
138.61000000,3.14304700,2.41000000,0.10488289,218.08967920,0.09973935,240.96355479,0.00074974,0.10313738,245.33882979,-0.06706572,-0.03607166,0.00000000,0.00000000,0.00000000,0.00000000
140.11000000,3.18121800,2.41400000,0.10611756,218.45165377,0.10085619,241.63320928,0.00070831,0.10427725,246.02416710,-0.06779537,-0.03648188,0.00000000,0.00000000,0.00000000,0.00000000
141.61000000,3.21908700,2.41900000,0.10738211,218.90412199,0.10199877,242.41050874,0.00076812,0.10541906,246.71124203,-0.06850671,-0.03691235,0.00000000,0.00000000,0.00000000,0.00000000
143.11000000,3.25645300,2.42400000,0.10863167,219.35659020,0.10312652,243.18566219,0.00074701,0.10657140,247.50356746,-0.06925626,-0.03731515,0.00000000,0.00000000,0.00000000,0.00000000
144.61000000,3.29539600,2.42900000,0.10994100,219.80905841,0.10430686,243.97508610,0.00078658,0.10766866,248.08070548,-0.06993141,-0.03773725,0.00000000,0.00000000,0.00000000,0.00000000
146.11000000,3.33333200,2.43200000,0.11122044,220.08053934,0.10545891,244.55799474,0.00085270,0.10883302,248.77717606,-0.07070883,-0.03812419,0.00000000,0.00000000,0.00000000,0.00000000
147.61000000,3.37150300,2.43700000,0.11248122,220.53300756,0.10659286,245.33882979,0.00077120,0.10996950,249.46796552,-0.07141218,-0.03855732,0.00000000,0.00000000,0.00000000,0.00000000
149.11000000,3.40970800,2.44100000,0.11376078,220.89498213,0.10774238,246.02416710,0.00077730,0.11109133,250.15633797,-0.07212312,-0.03896822,0.00000000,0.00000000,0.00000000,0.00000000
150.61000000,3.44861800,2.44500000,0.11504400,221.25695670,0.10889387,246.71124203,0.00077640,0.11225640,250.75487480,-0.07286814,-0.03938826,0.00000000,0.00000000,0.00000000,0.00000000
152.11000000,3.48662200,2.45000000,0.11634211,221.70942491,0.11005737,247.50356746,0.00079561,0.11339225,251.44918691,-0.07362229,-0.03976996,0.00000000,0.00000000,0.00000000,0.00000000
153.61000000,3.52519600,2.45300000,0.11757678,221.98090584,0.11116275,248.08070548,0.00073446,0.11454645,252.14940991,-0.07433897,-0.04020748,0.00000000,0.00000000,0.00000000,0.00000000
155.11000000,3.56393800,2.45700000,0.11888978,222.34288041,0.11233692,248.77717606,0.00074016,0.11570740,252.75031980,-0.07509720,-0.04061020,0.00000000,0.00000000,0.00000000,0.00000000
156.61000000,3.60281400,2.46100000,0.12017300,222.70485498,0.11348314,249.46796552,0.00079269,0.11684581,253.44900218,-0.07583109,-0.04101472,0.00000000,0.00000000,0.00000000,0.00000000
158.11000000,3.64195900,2.46500000,0.12144122,223.06682956,0.11461466,250.15633797,0.00073847,0.11804022,254.06067874,-0.07660162,-0.04143860,0.00000000,0.00000000,0.00000000,0.00000000
159.61000000,3.68097000,2.46800000,0.12275800,223.33831048,0.11578816,250.75487480,0.00066455,0.11914768,254.65124438,-0.07727854,-0.04186913,0.00000000,0.00000000,0.00000000,0.00000000
161.11000000,3.71893900,2.47200000,0.12404500,223.70028505,0.11693379,251.44918691,0.00071698,0.12035570,255.26857858,-0.07805864,-0.04229706,0.00000000,0.00000000,0.00000000,0.00000000
162.61000000,3.75855400,2.47600000,0.12535422,224.06225963,0.11809785,252.14940991,0.00080900,0.12151633,255.87486931,-0.07881026,-0.04270607,0.00000000,0.00000000,0.00000000,0.00000000
164.11000000,3.79813500,2.47900000,0.12667100,224.33374055,0.11926727,252.75031980,0.00077490,0.12263626,256.47175689,-0.07950145,-0.04313480,0.00000000,0.00000000,0.00000000,0.00000000
165.61000000,3.83701200,2.48300000,0.12796544,224.69571513,0.12041552,253.44900218,0.00070799,0.12375821,257.07019417,-0.08020995,-0.04354826,0.00000000,0.00000000,0.00000000,0.00000000
167.11000000,3.87612300,2.48600000,0.12932322,224.96719605,0.12161853,254.06067874,0.00087879,0.12492972,257.78575690,-0.08096522,-0.04396449,0.00000000,0.00000000,0.00000000,0.00000000
168.61000000,3.91600700,2.48900000,0.13058400,225.23867698,0.12273431,254.65124438,0.00075904,0.12610592,258.29706365,-0.08171652,-0.04438940,0.00000000,0.00000000,0.00000000,0.00000000
170.11000000,3.95636000,2.49200000,0.13196044,225.51015791,0.12395104,255.26857858,0.00079111,0.12725975,258.90693724,-0.08246630,-0.04479345,0.00000000,0.00000000,0.00000000,0.00000000
171.61000000,3.99577300,2.49500000,0.13328467,225.78163884,0.12512020,255.87486931,0.00080333,0.12842201,259.52008189,-0.08318282,-0.04523920,0.00000000,0.00000000,0.00000000,0.00000000
173.11000000,4.03525400,2.49800000,0.13456411,226.05311977,0.12624853,256.47175689,0.00074972,0.12957137,260.02717117,-0.08389621,-0.04567516,0.00000000,0.00000000,0.00000000,0.00000000
174.61000000,4.07436600,2.50100000,0.13584733,226.32460070,0.12737892,257.07019417,0.00078175,0.13076331,260.65012268,-0.08467876,-0.04608456,0.00000000,0.00000000,0.00000000,0.00000000
176.11000000,4.11468500,2.50500000,0.13719022,226.68657527,0.12856050,257.78575690,0.00072179,0.13193757,261.26956099,-0.08540578,-0.04653179,0.00000000,0.00000000,0.00000000,0.00000000
177.61000000,4.15440100,2.50700000,0.13853678,226.86756255,0.12974391,258.29706365,0.00070786,0.13309257,261.78090098,-0.08614117,-0.04695140,0.00000000,0.00000000,0.00000000,0.00000000
179.11000000,4.19532500,2.51000000,0.13986100,227.13904348,0.13090633,258.90693724,0.00079850,0.13426732,262.40254462,-0.08690003,-0.04736728,0.00000000,0.00000000,0.00000000,0.00000000
180.61000000,4.23510800,2.51300000,0.14119644,227.41052441,0.13207722,259.52008189,0.00073893,0.13544711,263.02662920,-0.08763798,-0.04780913,0.00000000,0.00000000,0.00000000,0.00000000
182.11000000,4.27502500,2.51500000,0.14251700,227.59151170,0.13323372,260.02717117,0.00071201,0.13662377,263.54648749,-0.08836827,-0.04825550,0.00000000,0.00000000,0.00000000,0.00000000
183.61000000,4.31544600,2.51800000,0.14388967,227.86299262,0.13443444,260.65012268,0.00086760,0.13781190,264.07025146,-0.08914558,-0.04866632,0.00000000,0.00000000,0.00000000,0.00000000
185.11000000,4.35643700,2.52100000,0.14524367,228.13447355,0.13561742,261.26956099,0.00091219,0.13899543,264.59367253,-0.08987710,-0.04911833,0.00000000,0.00000000,0.00000000,0.00000000
186.61000000,4.39658900,2.52300000,0.14657544,228.31546084,0.13677963,261.78090098,0.00083319,0.14016775,265.11498858,-0.09061731,-0.04955044,0.00000000,0.00000000,0.00000000,0.00000000
188.11000000,4.43721100,2.52600000,0.14793322,228.58694177,0.13796313,262.40254462,0.00081264,0.14135161,265.64024389,-0.09137613,-0.04997547,0.00000000,0.00000000,0.00000000,0.00000000
189.61000000,4.47776600,2.52900000,0.14929844,228.85842270,0.13915171,263.02662920,0.00084398,0.14256470,266.27933393,-0.09214897,-0.05041572,0.00000000,0.00000000,0.00000000,0.00000000
191.11000000,4.51912700,2.53100000,0.15066000,229.03940998,0.14033569,263.54648749,0.00079758,0.14372962,266.80141966,-0.09287864,-0.05085098,0.00000000,0.00000000,0.00000000,0.00000000
192.61000000,4.56042100,2.53300000,0.15203644,229.22039727,0.14153120,264.07025146,0.00076420,0.14490919,267.32829762,-0.09363146,-0.05127773,0.00000000,0.00000000,0.00000000,0.00000000
194.11000000,4.60097500,2.53500000,0.15340922,229.40138455,0.14272210,264.59367253,0.00075057,0.14606820,267.85052425,-0.09435366,-0.05171454,0.00000000,0.00000000,0.00000000,0.00000000
195.61000000,4.64210100,2.53700000,0.15477067,229.58237184,0.14390177,265.11498858,0.00074950,0.14721133,268.26369081,-0.09508906,-0.05212227,0.00000000,0.00000000,0.00000000,0.00000000
197.11000000,4.68383100,2.53900000,0.15614711,229.76335912,0.14509302,265.64024389,0.00067112,0.14834842,268.78159055,-0.09579986,-0.05254857,0.00000000,0.00000000,0.00000000,0.00000000
198.61000000,4.72583000,2.54200000,0.15756089,230.03484005,0.14631511,266.27933393,0.00083795,0.14955750,269.31978957,-0.09657951,-0.05297800,0.00000000,0.00000000,0.00000000,0.00000000
200.11000000,4.76665300,2.54400000,0.15891867,230.21582734,0.14748739,266.80141966,0.00083697,0.15073333,269.84989548,-0.09731394,-0.05341939,0.00000000,0.00000000,0.00000000,0.00000000
201.61000000,4.80848400,2.54600000,0.16029511,230.39681462,0.14867438,267.32829762,0.00077160,0.15187593,270.37186235,-0.09802923,-0.05384669,0.00000000,0.00000000,0.00000000,0.00000000
203.11000000,4.85112100,2.54800000,0.16164922,230.57780191,0.14984074,267.85052425,0.00077721,0.15308217,270.80571419,-0.09879443,-0.05428775,0.00000000,0.00000000,0.00000000,0.00000000
204.61000000,4.89211200,2.54900000,0.16298467,230.66829555,0.15098969,268.26369081,0.00070578,0.15428545,271.34581703,-0.09955354,-0.05473191,0.00000000,0.00000000,0.00000000,0.00000000
206.11000000,4.93438000,2.55100000,0.16431633,230.84928284,0.15213408,268.78159055,0.00068569,0.15548885,271.78033597,-0.10027141,-0.05521744,0.00000000,0.00000000,0.00000000,0.00000000
207.61000000,4.97644500,2.55300000,0.16573378,231.03027012,0.15335074,269.31978957,0.00076819,0.15672087,272.32999564,-0.10108183,-0.05563904,0.00000000,0.00000000,0.00000000,0.00000000
209.11000000,5.01814200,2.55500000,0.16711400,231.21125741,0.15453403,269.84989548,0.00083128,0.15795284,272.77379586,-0.10187188,-0.05608096,0.00000000,0.00000000,0.00000000,0.00000000
210.61000000,5.06047600,2.55700000,0.16845689,231.39224469,0.15568398,270.37186235,0.00070247,0.15915018,273.31570801,-0.10261001,-0.05654017,0.00000000,0.00000000,0.00000000,0.00000000
212.11000000,5.10304600,2.55800000,0.16987433,231.48273834,0.15689634,270.80571419,0.00076547,0.16037762,273.86680904,-0.10336830,-0.05700932,0.00000000,0.00000000,0.00000000,0.00000000
213.61000000,5.14611900,2.56000000,0.17129178,231.66372562,0.15810722,271.34581703,0.00076435,0.16160504,274.31165907,-0.10411465,-0.05749038,0.00000000,0.00000000,0.00000000,0.00000000
215.11000000,5.18825200,2.56100000,0.17270933,231.75421927,0.15931674,271.78033597,0.00076362,0.16286240,274.76545496,-0.10492425,-0.05793815,0.00000000,0.00000000,0.00000000,0.00000000
216.61000000,5.23098900,2.56300000,0.17416411,231.93520655,0.16055650,272.32999564,0.00076267,0.16411667,275.32656855,-0.10570214,-0.05841453,0.00000000,0.00000000,0.00000000,0.00000000
218.11000000,5.27382700,2.56400000,0.17561889,232.02570019,0.16179472,272.77379586,0.00082527,0.16533944,275.77234687,-0.10645533,-0.05888411,0.00000000,0.00000000,0.00000000,0.00000000
219.61000000,5.31656400,2.56600000,0.17703633,232.20668748,0.16299970,273.31570801,0.00082408,0.16662333,276.23575476,-0.10725249,-0.05937084,0.00000000,0.00000000,0.00000000,0.00000000
221.11000000,5.35990600,2.56800000,0.17849111,232.38767477,0.16423490,273.86680904,0.00088645,0.16784310,276.68209231,-0.10799312,-0.05984997,0.00000000,0.00000000,0.00000000,0.00000000
222.61000000,5.40307900,2.56900000,0.17994589,232.47816841,0.16546858,274.31165907,0.00082205,0.16912374,277.14604705,-0.10881362,-0.06031011,0.00000000,0.00000000,0.00000000,0.00000000
224.11000000,5.44668900,2.57000000,0.18143800,232.56866205,0.16673234,274.76545496,0.00088424,0.17040281,277.61030448,-0.10962265,-0.06078016,0.00000000,0.00000000,0.00000000,0.00000000
225.61000000,5.49033300,2.57200000,0.18293011,232.74964934,0.16799451,275.32656855,0.00088312,0.17164894,278.06610321,-0.11039622,-0.06125271,0.00000000,0.00000000,0.00000000,0.00000000
227.11000000,5.53397600,2.57300000,0.18438489,232.84014298,0.16922356,275.77234687,0.00088204,0.17283135,278.50479790,-0.11117560,-0.06165575,0.00000000,0.00000000,0.00000000,0.00000000
228.61000000,5.57755300,2.57400000,0.18591422,232.93063662,0.17051397,276.23575476,0.00088090,0.17398114,278.93500686,-0.11193658,-0.06204456,0.00000000,0.00000000,0.00000000,0.00000000
230.11000000,5.62129800,2.57500000,0.18736911,233.02113027,0.17174003,276.68209231,0.00075419,0.17500693,279.22241286,-0.11259667,-0.06241026,0.00000000,0.00000000,0.00000000,0.00000000
231.61000000,5.66615000,2.57600000,0.18889844,233.11162391,0.17302720,277.14604705,0.00081586,0.17605967,279.73521624,-0.11332467,-0.06273500,0.00000000,0.00000000,0.00000000,0.00000000
233.11000000,5.71103600,2.57700000,0.19042789,233.20211755,0.17431281,277.61030448,0.00081500,0.17701972,280.11384399,-0.11395521,-0.06306451,0.00000000,0.00000000,0.00000000,0.00000000
234.61000000,5.75699600,2.57800000,0.19191989,233.29261119,0.17556536,278.06610321,0.00081379,0.17804084,280.51014074,-0.11466991,-0.06337093,0.00000000,0.00000000,0.00000000,0.00000000
236.11000000,5.80258700,2.57900000,0.19333744,233.38310484,0.17675396,278.50479790,0.00075042,0.17902993,280.89792704,-0.11530704,-0.06372290,0.00000000,0.00000000,0.00000000,0.00000000
237.61000000,5.84965500,2.58000000,0.19471756,233.47359848,0.17790980,278.93500686,0.00081189,0.18004897,281.29466600,-0.11599917,-0.06404980,0.00000000,0.00000000,0.00000000,0.00000000
239.11000000,5.89675600,2.58000000,0.19594856,233.47359848,0.17893964,279.22241286,0.00068632,0.18106687,281.69160175,-0.11667095,-0.06439592,0.00000000,0.00000000,0.00000000,0.00000000
240.61000000,5.94439500,2.58200000,0.19721689,233.65458577,0.17999960,279.73521624,0.00068560,0.18217632,282.11499039,-0.11738563,-0.06479070,0.00000000,0.00000000,0.00000000,0.00000000
242.11000000,5.99153000,2.58300000,0.19837322,233.74507941,0.18096499,280.11384399,0.00062261,0.18328454,282.53862208,-0.11809237,-0.06519216,0.00000000,0.00000000,0.00000000,0.00000000
243.61000000,6.03906800,2.58400000,0.19960422,233.83557305,0.18199169,280.51014074,0.00068423,0.18448535,282.87945912,-0.11885493,-0.06563042,0.00000000,0.00000000,0.00000000,0.00000000
245.11000000,6.08533000,2.58500000,0.20079789,233.92606669,0.18298624,280.89792704,0.00068355,0.18577535,283.35591421,-0.11956032,-0.06621503,0.00000000,0.00000000,0.00000000,0.00000000
246.61000000,6.13068600,2.58600000,0.20202889,234.01656034,0.18401087,281.29466600,0.00068285,0.18721715,283.87639435,-0.12036158,-0.06685557,0.00000000,0.00000000,0.00000000,0.00000000
248.11000000,6.17426200,2.58700000,0.20325978,234.10705398,0.18503436,281.69160175,0.00062008,0.18887286,284.34869313,-0.12114982,-0.06772304,0.00000000,0.00000000,0.00000000,0.00000000
249.61000000,6.21565700,2.58800000,0.20460267,234.19754762,0.18614978,282.11499039,0.00074321,0.19089280,284.92595588,-0.12207786,-0.06881494,0.00000000,0.00000000,0.00000000,0.00000000
251.11000000,6.25537300,2.58900000,0.20594556,234.28804127,0.18726395,282.53862208,0.00074257,0.19321358,285.59064952,-0.12309331,-0.07012027,0.00000000,0.00000000,0.00000000,0.00000000
252.61000000,6.29404800,2.58900000,0.20740033,234.28804127,0.18846956,282.87945912,0.00080336,0.19568122,286.29911072,-0.12423617,-0.07144505,0.00000000,0.00000000,0.00000000,0.00000000
254.11000000,6.33299200,2.59000000,0.20896700,234.37853491,0.18976628,283.35591421,0.00086410,0.19838700,286.96672388,-0.12584375,-0.07254325,0.00000000,0.00000000,0.00000000,0.00000000
255.61000000,6.37287600,2.59100000,0.21072022,234.46902855,0.19121541,283.87639435,0.00104777,0.20111259,287.86468647,-0.12780148,-0.07331111,0.00000000,0.00000000,0.00000000,0.00000000
257.11000000,6.41490900,2.59100000,0.21273456,234.46902855,0.19287777,284.34869313,0.00116923,0.20344140,288.42677194,-0.12960934,-0.07383207,0.00000000,0.00000000,0.00000000,0.00000000
258.61000000,6.45969400,2.59100000,0.21519656,234.46902855,0.19490584,284.92595588,0.00135113,0.20507028,288.89888844,-0.13090244,-0.07416784,0.00000000,0.00000000,0.00000000,0.00000000
260.11000000,6.50756800,2.59100000,0.21803144,234.46902855,0.19723599,285.59064952,0.00165435,0.20606441,289.18740841,-0.13159062,-0.07447378,0.00000000,0.00000000,0.00000000,0.00000000
261.61000000,6.55668300,2.59100000,0.22105300,234.46902855,0.19971360,286.29911072,0.00171146,0.20681528,289.51771918,-0.13210328,-0.07471200,0.00000000,0.00000000,0.00000000,0.00000000
263.11000000,6.60741100,2.59000000,0.22437289,234.37853491,0.20242879,286.96672388,0.00182889,0.20744689,289.70138658,-0.13254773,-0.07489916,0.00000000,0.00000000,0.00000000,0.00000000
264.61000000,6.65981700,2.59100000,0.22773011,234.46902855,0.20516703,287.86468647,0.00176302,0.20798795,289.85881951,-0.13290232,-0.07508563,0.00000000,0.00000000,0.00000000,0.00000000
266.11000000,6.71366700,2.59000000,0.23060233,234.37853491,0.20750375,288.42677194,0.00145546,0.20843705,290.10194000,-0.13320130,-0.07523575,0.00000000,0.00000000,0.00000000,0.00000000
267.61000000,6.76765100,2.59000000,0.23261667,234.37853491,0.20913928,288.89888844,0.00090812,0.20882743,290.21567531,-0.13344849,-0.07537894,0.00000000,0.00000000,0.00000000,0.00000000
269.11000000,6.82166800,2.59000000,0.23384767,234.37853491,0.21013747,289.18740841,0.00060470,0.20921607,290.44142042,-0.13373632,-0.07547975,0.00000000,0.00000000,0.00000000,0.00000000
270.61000000,6.87588700,2.59100000,0.23478022,234.46902855,0.21089300,289.51771918,0.00048346,0.20948620,290.52021068,-0.13388455,-0.07560166,0.00000000,0.00000000,0.00000000,0.00000000
272.11000000,6.93128100,2.59100000,0.23556356,234.46902855,0.21152719,289.70138658,0.00036226,0.20981463,290.72857272,-0.13409802,-0.07571661,0.00000000,0.00000000,0.00000000,0.00000000
273.61000000,6.98627200,2.59100000,0.23623500,234.46902855,0.21207047,289.85881951,0.00030184,0.21011452,290.81613093,-0.13434107,-0.07577345,0.00000000,0.00000000,0.00000000,0.00000000
275.11000000,7.04200200,2.59200000,0.23679456,234.55952219,0.21252300,290.10194000,0.00024132,0.21038432,290.89492550,-0.13450009,-0.07588423,0.00000000,0.00000000,0.00000000,0.00000000
276.61000000,7.09769800,2.59200000,0.23727944,234.55952219,0.21291497,290.21567531,0.00024122,0.21059256,291.06838393,-0.13464432,-0.07594825,0.00000000,0.00000000,0.00000000,0.00000000
278.11000000,7.15376300,2.59300000,0.23776433,234.65001584,0.21330680,290.44142042,0.00024095,0.21080076,291.24188963,-0.13479005,-0.07601070,0.00000000,0.00000000,0.00000000,0.00000000
279.61000000,7.20949300,2.59300000,0.23810011,234.65001584,0.21357804,290.52021068,0.00012062,0.21103573,291.64864779,-0.13491911,-0.07611662,0.00000000,0.00000000,0.00000000,0.00000000
281.11000000,7.25931400,2.59400000,0.23851044,234.74050948,0.21390940,290.72857272,0.00018069,0.21130220,291.95211257,-0.13512011,-0.07618209,0.00000000,0.00000000,0.00000000,0.00000000
282.61000000,7.29574100,2.59400000,0.23888344,234.74050948,0.21421053,290.81613093,0.00024091,0.00000000,0.00000000,0.00000000,0.00000000,0.00000000,0.00000000,0.00000000,0.00000000
284.11000000,7.32018300,2.59400000,0.23921911,234.74050948,0.21448143,290.89492550,0.00018059,0.00000000,0.00000000,0.00000000,0.00000000,0.00000000,0.00000000,0.00000000,0.00000000
285.61000000,7.33968800,2.59500000,0.23948022,234.83100312,0.21469212,291.06838393,0.00018055,0.00000000,0.00000000,0.00000000,0.00000000,0.00000000,0.00000000,0.00000000,0.00000000
287.11000000,7.35751400,2.59600000,0.23974133,234.92149676,0.21490276,291.24188963,0.00012028,0.00000000,0.00000000,0.00000000,0.00000000,0.00000000,0.00000000,0.00000000,0.00000000
288.61000000,7.37607700,2.59900000,0.24003978,235.19297769,0.21514346,291.64864779,0.00012025,0.00000000,0.00000000,0.00000000,0.00000000,0.00000000,0.00000000,0.00000000,0.00000000
290.11000000,7.40041700,2.60100000,0.24037556,235.37396498,0.21541420,291.95211257,0.00018042,0.00000000,0.00000000,0.00000000,0.00000000,0.00000000,0.00000000,0.00000000,0.00000000
291.61000000,7.43566900,2.59700000,0.24059933,235.01199041,0.00000000,0.00000000,0.00000000,0.00000000,0.00000000,0.00000000,0.00000000,0.00000000,0.00000000,0.00000000,0.00000000
293.11000000,7.48344400,2.59100000,0.24086044,234.46902855,0.00000000,0.00000000,0.00000000,0.00000000,0.00000000,0.00000000,0.00000000,0.00000000,0.00000000,0.00000000,0.00000000
294.61000000,7.53491100,2.59000000,0.24104700,234.37853491,0.00000000,0.00000000,0.00000000,0.00000000,0.00000000,0.00000000,0.00000000,0.00000000,0.00000000,0.00000000,0.00000000
296.11000000,7.58909500,2.58800000,0.24123344,234.19754762,0.00000000,0.00000000,0.00000000,0.00000000,0.00000000,0.00000000,0.00000000,0.00000000,0.00000000,0.00000000,0.00000000
297.61000000,7.64556100,2.58400000,0.24138278,233.83557305,0.00000000,0.00000000,0.00000000,0.00000000,0.00000000,0.00000000,0.00000000,0.00000000,0.00000000,0.00000000,0.00000000
299.11000000,7.70273500,2.58300000,0.24153200,233.74507941,0.00000000,0.00000000,0.00000000,0.00000000,0.00000000,0.00000000,0.00000000,0.00000000,0.00000000,0.00000000,0.00000000
300.61000000,7.76024700,2.58000000,0.24164389,233.47359848,0.00000000,0.00000000,0.00000000,0.00000000,0.00000000,0.00000000,0.00000000,0.00000000,0.00000000,0.00000000,0.00000000
302.11000000,7.81816100,2.57600000,0.24175567,233.11162391,0.00000000,0.00000000,0.00000000,0.00000000,0.00000000,0.00000000,0.00000000,0.00000000,0.00000000,0.00000000,0.00000000
303.61000000,7.87711400,2.57100000,0.24186767,232.65915569,0.00000000,0.00000000,0.00000000,0.00000000,0.00000000,0.00000000,0.00000000,0.00000000,0.00000000,0.00000000,0.00000000
305.11000000,7.93677300,2.56300000,0.24190489,231.93520655,0.00000000,0.00000000,0.00000000,0.00000000,0.00000000,0.00000000,0.00000000,0.00000000,0.00000000,0.00000000,0.00000000
306.61000000,7.99660400,2.55300000,0.24190500,231.03027012,0.00000000,0.00000000,0.00000000,0.00000000,0.00000000,0.00000000,0.00000000,0.00000000,0.00000000,0.00000000,0.00000000
308.11000000,8.05821900,2.53700000,0.24197978,229.58237184,0.00000000,0.00000000,0.00000000,0.00000000,0.00000000,0.00000000,0.00000000,0.00000000,0.00000000,0.00000000,0.00000000
309.61000000,8.12027800,2.51100000,0.24194300,227.22953713,0.00000000,0.00000000,0.00000000,0.00000000,0.00000000,0.00000000,0.00000000,0.00000000,0.00000000,0.00000000,0.00000000
311.11000000,8.18506400,2.46600000,0.24183222,223.15732320,0.00000000,0.00000000,0.00000000,0.00000000,0.00000000,0.00000000,0.00000000,0.00000000,0.00000000,0.00000000,0.00000000
312.61000000,8.25258100,2.40300000,0.24168467,217.45622370,0.00000000,0.00000000,0.00000000,0.00000000,0.00000000,0.00000000,0.00000000,0.00000000,0.00000000,0.00000000,0.00000000
314.11000000,8.32410300,2.30700000,0.24150078,208.76883399,0.00000000,0.00000000,0.00000000,0.00000000,0.00000000,0.00000000,0.00000000,0.00000000,0.00000000,0.00000000,0.00000000
315.61000000,8.45123800,0.00500000,0.25369511,0.45246821,0.00000000,0.00000000,0.00000000,0.00000000,0.00000000,0.00000000,0.00000000,0.00000000,0.00000000,0.00000000,0.00000000
NaN,-100.00000000,NaN,-11.11111111,NaN,0.00000000,0.00000000,0.00000000,0.00000000,0.00000000,0.00000000,0.00000000,0.00000000,0.00000000,0.00000000,0.00000000