File: polyN_optimization/results_exp/AA6014-T4/UT_45_2.csv
Time[s],Displacement[mm],Force[kN],EngStrain_longi,EngStress[MPa],TrueStrain,TrueStress[MPa],TrueStrainRate[1/s],PlasticStrain_longi,PlasticStress[MPa],PlasticStrain_thick,PlasticStrain_width,R-Value,Thickness[mm],Width[mm], Young's Modulus [MPa]
0.65000000,0.00000000,-0.00100000,0.00000000,-0.09065774,0.00000000,-0.09065774,0.00000000,0.00096258,117.52773152,-0.00037108,-0.00059150,0.50468502,1.11300000,9.91060000,77951.26448999
2.15000000,0.00639000,0.15200000,0.00019900,13.77997646,0.00019898,13.78271867,0.00019330,0.00209160,121.39803530,-0.00112946,-0.00096214,0.00000000,0.00000000,0.00000000,0.00000000
3.65000000,0.01355000,0.40700000,0.00042000,36.89770012,0.00041991,36.91319715,0.00014705,0.00329482,124.83027879,-0.00199770,-0.00129712,0.00000000,0.00000000,0.00000000,0.00000000
5.15000000,0.02257000,0.64500000,0.00071511,58.47424221,0.00071486,58.51605779,0.00023718,0.00445186,128.08222708,-0.00283462,-0.00161725,0.00000000,0.00000000,0.00000000,0.00000000
6.65000000,0.03092300,0.90900000,0.00101233,82.40788553,0.00101182,82.49130978,0.00025487,0.00556928,130.78761404,-0.00359283,-0.00197645,0.00000000,0.00000000,0.00000000,0.00000000
8.15000000,0.04249200,1.13800000,0.00131900,103.16850795,0.00131813,103.30458721,0.00028009,0.00674690,133.32391907,-0.00440096,-0.00234594,0.00000000,0.00000000,0.00000000,0.00000000
9.65000000,0.06771000,1.27500000,0.00211067,115.58861831,0.00210844,115.83258736,0.00053982,0.00794405,135.86886020,-0.00524892,-0.00269514,0.00000000,0.00000000,0.00000000,0.00000000
11.15000000,0.10387800,1.31800000,0.00338311,119.48690113,0.00337740,119.89113859,0.00067915,0.00907164,138.13471895,-0.00599153,-0.00308011,0.00000000,0.00000000,0.00000000,0.00000000
12.65000000,0.13975700,1.36000000,0.00463156,123.29452620,0.00462086,123.86557165,0.00087636,0.01019210,140.31270985,-0.00674319,-0.00344891,0.00000000,0.00000000,0.00000000,0.00000000
14.15000000,0.17554500,1.39300000,0.00582456,126.28623162,0.00580766,127.02179279,0.00091554,0.01134959,142.59289424,-0.00753869,-0.00381090,0.00000000,0.00000000,0.00000000,0.00000000
15.65000000,0.21249100,1.42400000,0.00701778,129.09662155,0.00699327,130.00259295,0.00078399,0.01250205,144.60106826,-0.00834282,-0.00415923,0.00000000,0.00000000,0.00000000,0.00000000
17.15000000,0.24827300,1.45000000,0.00829389,131.45372279,0.00825968,132.54398536,0.00089390,0.01364946,146.61305498,-0.00911633,-0.00453313,0.00000000,0.00000000,0.00000000,0.00000000
18.65000000,0.28537300,1.47500000,0.00952333,133.72016628,0.00947827,134.99362800,0.00097496,0.01475019,148.71502426,-0.00986745,-0.00488274,0.00000000,0.00000000,0.00000000,0.00000000
20.15000000,0.32087800,1.50000000,0.01069689,135.98660978,0.01064008,137.44124343,0.00089705,0.01589737,150.55108322,-0.01064634,-0.00525104,0.00000000,0.00000000,0.00000000,0.00000000
21.65000000,0.35629000,1.52200000,0.01188456,137.98108006,0.01181449,139.62092387,0.00076242,0.01703693,152.57531754,-0.01145601,-0.00558092,0.00000000,0.00000000,0.00000000,0.00000000
23.15000000,0.39257800,1.54400000,0.01311556,139.97555033,0.01303029,141.81140744,0.00083237,0.01814715,154.50682027,-0.01224396,-0.00590319,0.00000000,0.00000000,0.00000000,0.00000000
24.65000000,0.42763100,1.56600000,0.01428311,141.97002061,0.01418207,143.99779419,0.00086823,0.01922813,156.34512145,-0.01295570,-0.00627243,0.00000000,0.00000000,0.00000000,0.00000000
26.15000000,0.46305200,1.58600000,0.01541711,143.78317541,0.01529947,145.99989660,0.00074970,0.02037829,158.10534473,-0.01378715,-0.00659114,0.00000000,0.00000000,0.00000000,0.00000000
27.65000000,0.49853100,1.60600000,0.01664433,145.59633020,0.01650733,148.01968406,0.00074879,0.02148208,159.95511513,-0.01455967,-0.00692241,0.00000000,0.00000000,0.00000000,0.00000000
29.15000000,0.53356700,1.62600000,0.01779322,147.40948500,0.01763678,150.03237473,0.00075515,0.02255688,161.71102208,-0.01529167,-0.00726521,0.00000000,0.00000000,0.00000000,0.00000000
30.65000000,0.56898200,1.64500000,0.01896456,149.13198206,0.01878697,151.96020382,0.00077632,0.02368606,163.38625922,-0.01608225,-0.00760381,0.00000000,0.00000000,0.00000000,0.00000000
32.15000000,0.60378600,1.66400000,0.02010967,150.85447912,0.01991014,153.88811241,0.00070223,0.02479585,165.06194582,-0.01684179,-0.00795406,0.00000000,0.00000000,0.00000000,0.00000000
33.65000000,0.63856700,1.68200000,0.02129589,152.48631843,0.02107230,155.73365013,0.00070141,0.02590289,166.83424649,-0.01759799,-0.00830490,0.00000000,0.00000000,0.00000000,0.00000000
35.15000000,0.67317600,1.70000000,0.02246344,154.11815775,0.02221486,157.58018242,0.00080280,0.02699680,168.42097714,-0.01837137,-0.00862543,0.00000000,0.00000000,0.00000000,0.00000000
36.65000000,0.70878900,1.71700000,0.02363478,155.65933933,0.02335980,159.33831322,0.00081665,0.02809542,170.10554300,-0.01910795,-0.00898746,0.00000000,0.00000000,0.00000000,0.00000000
38.15000000,0.74207900,1.73500000,0.02474256,157.29117864,0.02444142,161.18296437,0.00059710,0.02917722,171.60320279,-0.01982952,-0.00934770,0.00000000,0.00000000,0.00000000,0.00000000
39.65000000,0.77749700,1.75100000,0.02594367,158.74170248,0.02561284,162.86004430,0.00071275,0.03027446,173.20055035,-0.02056192,-0.00971254,0.00000000,0.00000000,0.00000000,0.00000000
41.15000000,0.81247900,1.76700000,0.02710756,160.19222632,0.02674665,164.53464599,0.00078467,0.03141856,174.71546624,-0.02132806,-0.01009049,0.00000000,0.00000000,0.00000000,0.00000000
42.65000000,0.84729300,1.78400000,0.02825644,161.73340790,0.02786460,166.30341895,0.00068931,0.03248812,176.31463819,-0.02205352,-0.01043460,0.00000000,0.00000000,0.00000000,0.00000000
44.15000000,0.88160400,1.79900000,0.02941656,163.09327400,0.02899219,167.89091635,0.00074662,0.03356614,177.73016806,-0.02275139,-0.01081476,0.00000000,0.00000000,0.00000000,0.00000000
45.65000000,0.91608200,1.81400000,0.03056544,164.45314009,0.03010763,169.47972341,0.00075291,0.03467396,179.24828439,-0.02349636,-0.01117760,0.00000000,0.00000000,0.00000000,0.00000000
47.15000000,0.95059400,1.83000000,0.03172933,165.90366393,0.03123636,171.16767658,0.00072340,0.03578531,180.67581185,-0.02423114,-0.01155417,0.00000000,0.00000000,0.00000000,0.00000000
48.65000000,0.98534100,1.84500000,0.03288189,167.26353003,0.03235285,172.76347084,0.00073680,0.03687030,182.10153788,-0.02496315,-0.01190715,0.00000000,0.00000000,0.00000000,0.00000000
50.15000000,1.01985300,1.85900000,0.03404200,168.53273839,0.03347539,174.26992987,0.00075769,0.03795404,183.52997197,-0.02567454,-0.01227950,0.00000000,0.00000000,0.00000000,0.00000000
51.65000000,1.05429800,1.87300000,0.03519089,169.80194674,0.03458584,175.77742819,0.00069908,0.03906511,184.96641690,-0.02644076,-0.01262436,0.00000000,0.00000000,0.00000000,0.00000000
53.15000000,1.08904500,1.88700000,0.03633978,171.07115510,0.03569506,177.28784286,0.00069101,0.04017032,186.21504800,-0.02719965,-0.01297066,0.00000000,0.00000000,0.00000000,0.00000000
54.65000000,1.12369100,1.90100000,0.03749989,172.34036346,0.03681387,178.80310794,0.00074788,0.04121111,187.64409615,-0.02788583,-0.01332527,0.00000000,0.00000000,0.00000000,0.00000000
56.15000000,1.15833700,1.91400000,0.03866000,173.51891408,0.03793142,180.22715530,0.00076138,0.04233036,188.99576927,-0.02869058,-0.01363978,0.00000000,0.00000000,0.00000000,0.00000000
57.65000000,1.19295000,1.92700000,0.03981644,174.69746470,0.03904420,181.65329659,0.00071778,0.04344243,190.25372122,-0.02943177,-0.01401066,0.00000000,0.00000000,0.00000000,0.00000000
59.15000000,1.22695800,1.94000000,0.04097278,175.87601531,0.04015564,183.08214421,0.00073107,0.04449868,191.59886111,-0.03013050,-0.01436818,0.00000000,0.00000000,0.00000000,0.00000000
60.65000000,1.26217500,1.95300000,0.04215156,177.05456593,0.04128738,184.51769130,0.00078763,0.04558338,192.85678297,-0.03087858,-0.01470480,0.00000000,0.00000000,0.00000000,0.00000000
62.15000000,1.29709000,1.96500000,0.04332278,178.14245881,0.04241060,185.86008497,0.00080805,0.04670361,194.02865665,-0.03164575,-0.01505786,0.00000000,0.00000000,0.00000000,0.00000000
63.65000000,1.33146700,1.97700000,0.04447544,179.23035169,0.04351479,187.20170124,0.00077864,0.04779160,195.38788394,-0.03238866,-0.01540294,0.00000000,0.00000000,0.00000000,0.00000000
65.15000000,1.36644900,1.98900000,0.04564678,180.31824457,0.04463562,188.54919141,0.00087068,0.04891628,196.56566528,-0.03317869,-0.01573758,0.00000000,0.00000000,0.00000000,0.00000000
66.65000000,1.40096200,2.00100000,0.04682178,181.40613745,0.04575870,189.89989530,0.00082701,0.05001145,197.74003898,-0.03388744,-0.01612400,0.00000000,0.00000000,0.00000000,0.00000000
68.15000000,1.43597700,2.01200000,0.04797444,182.40337258,0.04685920,191.15407305,0.00082610,0.05109687,199.01079069,-0.03461760,-0.01647927,0.00000000,0.00000000,0.00000000,0.00000000
69.65000000,1.47112700,2.02300000,0.04914567,183.40060772,0.04797618,192.41395286,0.00078238,0.05220492,200.09654660,-0.03534961,-0.01685531,0.00000000,0.00000000,0.00000000,0.00000000
71.15000000,1.50547100,2.03400000,0.05028711,184.39784286,0.04906357,193.67067767,0.00068205,0.05330332,201.27871498,-0.03606118,-0.01724214,0.00000000,0.00000000,0.00000000,0.00000000
72.65000000,1.54048600,2.04500000,0.05145844,185.39507800,0.05017820,194.93522032,0.00069545,0.05438988,202.46087501,-0.03680750,-0.01758238,0.00000000,0.00000000,0.00000000,0.00000000
74.15000000,1.57563600,2.05600000,0.05262967,186.39231314,0.05129148,196.20207845,0.00072298,0.05553622,203.56122979,-0.03756646,-0.01796976,0.00000000,0.00000000,0.00000000,0.00000000
75.65000000,1.61071900,2.06600000,0.05380844,187.29889054,0.05241069,197.37715248,0.00067977,0.05660759,204.64848842,-0.03827719,-0.01833041,0.00000000,0.00000000,0.00000000,0.00000000
77.15000000,1.64560000,2.07600000,0.05499100,188.20546793,0.05353224,198.55507482,0.00076392,0.05772885,205.84477481,-0.03903138,-0.01869747,0.00000000,0.00000000,0.00000000,0.00000000
78.65000000,1.68058200,2.08600000,0.05616967,189.11204533,0.05464884,199.73440588,0.00077002,0.05880827,206.93812878,-0.03975025,-0.01905802,0.00000000,0.00000000,0.00000000,0.00000000
80.15000000,1.71600000,2.09600000,0.05732611,190.01862273,0.05574318,200.91165141,0.00071997,0.05992622,207.94485316,-0.04050259,-0.01942364,0.00000000,0.00000000,0.00000000,0.00000000
81.65000000,1.75101600,2.10500000,0.05852722,190.83454239,0.05687853,202.00355806,0.00079665,0.06101002,209.04337164,-0.04123637,-0.01977365,0.00000000,0.00000000,0.00000000,0.00000000
83.15000000,1.78670200,2.11600000,0.05970967,191.83177753,0.05799497,203.28598902,0.00075339,0.06211844,210.05221108,-0.04198958,-0.02012886,0.00000000,0.00000000,0.00000000,0.00000000
84.65000000,1.82205400,2.12400000,0.06089589,192.55703945,0.05911373,204.28297153,0.00073851,0.06328125,211.07457419,-0.04279326,-0.02048799,0.00000000,0.00000000,0.00000000,0.00000000
86.15000000,1.85770700,2.13300000,0.06209333,193.37295911,0.06024180,205.38013071,0.00073767,0.06436612,212.08248072,-0.04350472,-0.02086141,0.00000000,0.00000000,0.00000000,0.00000000
87.65000000,1.89289000,2.14300000,0.06328333,194.27953650,0.06136161,206.57419317,0.00076507,0.06547623,213.19512271,-0.04423300,-0.02124323,0.00000000,0.00000000,0.00000000,0.00000000
89.15000000,1.92847600,2.15100000,0.06446211,195.00479842,0.06246961,207.57521941,0.00076423,0.06658778,214.11534564,-0.04498919,-0.02159859,0.00000000,0.00000000,0.00000000,0.00000000
90.65000000,1.96429800,2.16000000,0.06564833,195.82071808,0.06358338,208.67602186,0.00073521,0.06772092,215.13963350,-0.04576119,-0.02195973,0.00000000,0.00000000,0.00000000,0.00000000
92.15000000,1.99971600,2.16900000,0.06685322,196.63663774,0.06471340,209.78243058,0.00074855,0.06881946,216.06078419,-0.04649990,-0.02231956,0.00000000,0.00000000,0.00000000,0.00000000
93.65000000,2.03627600,2.17700000,0.06808044,197.36189966,0.06586306,210.79838550,0.00076143,0.06992227,217.08247286,-0.04722604,-0.02269623,0.00000000,0.00000000,0.00000000,0.00000000
95.15000000,2.07203000,2.18500000,0.06928156,198.08716158,0.06698698,211.81094827,0.00071172,0.07105635,218.01508900,-0.04799427,-0.02306208,0.00000000,0.00000000,0.00000000,0.00000000
96.65000000,2.10788500,2.19300000,0.07048644,198.81242350,0.06811317,212.82600434,0.00073895,0.07217173,218.94545906,-0.04873261,-0.02343912,0.00000000,0.00000000,0.00000000,0.00000000
98.15000000,2.14380700,2.20100000,0.07167644,199.53768542,0.06922419,213.83983724,0.00072423,0.07327217,219.87436212,-0.04948422,-0.02378795,0.00000000,0.00000000,0.00000000,0.00000000
99.65000000,2.18003100,2.20900000,0.07287011,200.26294733,0.07033740,214.85613056,0.00072342,0.07439185,220.80933073,-0.05024643,-0.02414542,0.00000000,0.00000000,0.00000000,0.00000000
101.14000000,2.21628900,2.21600000,0.07408611,200.89755151,0.07147017,215.78126984,0.00073017,0.07550347,221.74434899,-0.05097183,-0.02453164,0.00000000,0.00000000,0.00000000,0.00000000
102.65000000,2.25201000,2.22300000,0.07530589,201.53215569,0.07260517,216.70871382,0.00076313,0.07662193,222.58423407,-0.05173940,-0.02488253,0.00000000,0.00000000,0.00000000,0.00000000
104.15000000,2.28830100,2.23100000,0.07652578,202.25741761,0.07373898,217.73532381,0.00075566,0.07772750,223.52145491,-0.05244547,-0.02528203,0.00000000,0.00000000,0.00000000,0.00000000
105.65000000,2.32486100,2.23800000,0.07774178,202.89202179,0.07486791,218.66520826,0.00081690,0.07886411,224.36876904,-0.05323495,-0.02562916,0.00000000,0.00000000,0.00000000,0.00000000
107.15000000,2.36108500,2.24500000,0.07895044,203.52662597,0.07598876,219.59514355,0.00071234,0.07998898,225.21508993,-0.05399292,-0.02599605,0.00000000,0.00000000,0.00000000,0.00000000
108.65000000,2.39761200,2.25200000,0.08018511,204.16123015,0.07713243,220.53192107,0.00075989,0.08109068,226.15674261,-0.05471297,-0.02637772,0.00000000,0.00000000,0.00000000,0.00000000
110.15000000,2.43366800,2.25800000,0.08139378,204.70517659,0.07825074,221.36690424,0.00075904,0.08223489,226.91178440,-0.05550260,-0.02673229,0.00000000,0.00000000,0.00000000,0.00000000
111.65000000,2.46992600,2.26500000,0.08261722,205.33978077,0.07938146,222.30438307,0.00074443,0.08335919,227.76290078,-0.05624236,-0.02711683,0.00000000,0.00000000,0.00000000,0.00000000
113.15000000,2.50709000,2.27200000,0.08384078,205.97438495,0.08051101,223.24343758,0.00071610,0.08447559,228.61385186,-0.05699602,-0.02747957,0.00000000,0.00000000,0.00000000,0.00000000
114.65000000,2.54391900,2.27800000,0.08507922,206.51833138,0.08165300,224.08875039,0.00077716,0.08560752,229.47001491,-0.05775034,-0.02785718,0.00000000,0.00000000,0.00000000,0.00000000
116.15000000,2.58054600,2.28400000,0.08629533,207.06227782,0.08277313,224.93078611,0.00074886,0.08673962,230.22836713,-0.05850435,-0.02823527,0.00000000,0.00000000,0.00000000,0.00000000
117.65000000,2.61747500,2.29100000,0.08753000,207.69688200,0.08390907,225.87659008,0.00073411,0.08787911,231.08950317,-0.05926299,-0.02861612,0.00000000,0.00000000,0.00000000,0.00000000
119.15000000,2.65433700,2.29700000,0.08879078,208.24082844,0.08506770,226.73069356,0.00076062,0.08897807,231.84314545,-0.05998754,-0.02899052,0.00000000,0.00000000,0.00000000,0.00000000
120.65000000,2.69116600,2.30200000,0.09000311,208.69411714,0.08618055,227.47723695,0.00075304,0.09010281,232.60419915,-0.06072689,-0.02937591,0.00000000,0.00000000,0.00000000,0.00000000
122.15000000,2.72802800,2.30900000,0.09123033,209.32872132,0.08730581,228.42585034,0.00077950,0.09123834,233.46918897,-0.06148493,-0.02975341,0.00000000,0.00000000,0.00000000,0.00000000
123.65000000,2.76472200,2.31400000,0.09248744,209.78201002,0.08845716,229.18421202,0.00073750,0.09236388,234.23342552,-0.06223007,-0.03013381,0.00000000,0.00000000,0.00000000,0.00000000
125.15000000,2.80212100,2.32000000,0.09372589,210.32595646,0.08959011,230.03894368,0.00076410,0.09348812,234.99879499,-0.06296723,-0.03052089,0.00000000,0.00000000,0.00000000,0.00000000
126.65000000,2.83942000,2.32500000,0.09497178,210.77924516,0.09072859,230.79732479,0.00076323,0.09464128,235.77244682,-0.06372780,-0.03091348,0.00000000,0.00000000,0.00000000,0.00000000
128.15000000,2.87645000,2.33000000,0.09622511,211.23253386,0.09187256,231.55840790,0.00076236,0.09578303,236.54488163,-0.06449104,-0.03129199,0.00000000,0.00000000,0.00000000,0.00000000
129.65000000,2.91348000,2.33600000,0.09747100,211.77648030,0.09300844,232.41854561,0.00080221,0.09691143,237.21505570,-0.06523158,-0.03167986,0.00000000,0.00000000,0.00000000,0.00000000
131.15000000,2.95098000,2.34100000,0.09872811,212.22976900,0.09415325,233.18281321,0.00084216,0.09804052,237.98728544,-0.06596806,-0.03207246,0.00000000,0.00000000,0.00000000,0.00000000
132.65000000,2.98868100,2.34600000,0.09998900,212.68305769,0.09530018,233.94902395,0.00075975,0.09917970,238.66260542,-0.06672898,-0.03245072,0.00000000,0.00000000,0.00000000,0.00000000
134.15000000,3.02567700,2.35100000,0.10123856,213.13634639,0.09643551,234.71396224,0.00076555,0.10029936,239.43538116,-0.06746102,-0.03283834,0.00000000,0.00000000,0.00000000,0.00000000
135.65000000,3.06324400,2.35600000,0.10248822,213.58963509,0.09756965,235.48005708,0.00075803,0.10142583,240.11022830,-0.06821559,-0.03321023,0.00000000,0.00000000,0.00000000,0.00000000
137.15000000,3.10104700,2.36100000,0.10375278,214.04292379,0.09871599,236.25047170,0.00078415,0.10259649,240.89811845,-0.06901394,-0.03358255,0.00000000,0.00000000,0.00000000,0.00000000
138.65000000,3.13921800,2.36500000,0.10502856,214.40555475,0.09987118,236.92426047,0.00079008,0.10370697,241.57169625,-0.06973440,-0.03397257,0.00000000,0.00000000,0.00000000,0.00000000
140.15000000,3.17655000,2.37000000,0.10630800,214.85884345,0.10102835,237.70005738,0.00077570,0.10487620,242.26076742,-0.07051353,-0.03436267,0.00000000,0.00000000,0.00000000,0.00000000
141.65000000,3.21475500,2.37500000,0.10757256,215.31213215,0.10217073,238.47380845,0.00078827,0.10602746,242.94675020,-0.07128454,-0.03474292,0.00000000,0.00000000,0.00000000,0.00000000
143.15000000,3.25202000,2.37900000,0.10882211,215.67476311,0.10329829,239.14494614,0.00074026,0.10719391,243.63771917,-0.07206992,-0.03512399,0.00000000,0.00000000,0.00000000,0.00000000
144.65000000,3.29062800,2.38400000,0.11010533,216.12805181,0.10445491,239.92490300,0.00077966,0.10834571,244.32638742,-0.07282654,-0.03551916,0.00000000,0.00000000,0.00000000,0.00000000
146.15000000,3.32876600,2.38800000,0.11138111,216.49068277,0.10560349,240.60365556,0.00071835,0.10948951,245.01436793,-0.07360626,-0.03588325,0.00000000,0.00000000,0.00000000,0.00000000
147.65000000,3.36680300,2.39200000,0.11266433,216.85331373,0.10675744,241.28494775,0.00079145,0.11065000,245.60576049,-0.07436505,-0.03628494,0.00000000,0.00000000,0.00000000,0.00000000
149.15000000,3.40557900,2.39600000,0.11392144,217.21594469,0.10788662,241.96149886,0.00071692,0.11179110,246.29550291,-0.07510349,-0.03668762,0.00000000,0.00000000,0.00000000,0.00000000
150.65000000,3.44395100,2.40100000,0.11521956,217.66923339,0.10905130,242.74898572,0.00072266,0.11293087,246.98618140,-0.07587471,-0.03705616,0.00000000,0.00000000,0.00000000,0.00000000
152.15000000,3.48245900,2.40400000,0.11655867,217.94120661,0.11025134,243.34414306,0.00082194,0.11405420,247.57172013,-0.07661905,-0.03743515,0.00000000,0.00000000,0.00000000,0.00000000
153.65000000,3.52069700,2.40900000,0.11783444,218.39449531,0.11139328,244.12888933,0.00076770,0.11522761,248.27318665,-0.07739006,-0.03783755,0.00000000,0.00000000,0.00000000,0.00000000
155.15000000,3.55943900,2.41300000,0.11910267,218.75712626,0.11252717,244.81168336,0.00077339,0.11637139,248.86600479,-0.07817215,-0.03819924,0.00000000,0.00000000,0.00000000,0.00000000
156.65000000,3.59841600,2.41600000,0.12043067,219.02909948,0.11371314,245.40691995,0.00081255,0.11750392,249.45704866,-0.07890817,-0.03859575,0.00000000,0.00000000,0.00000000,0.00000000
158.15000000,3.63695700,2.42000000,0.12172878,219.39173044,0.11487105,246.09801765,0.00080487,0.11866340,250.15868290,-0.07967692,-0.03898648,0.00000000,0.00000000,0.00000000,0.00000000
159.65000000,3.67603500,2.42400000,0.12302311,219.75436140,0.11602426,246.78922662,0.00081048,0.11984593,250.76450282,-0.08045100,-0.03939493,0.00000000,0.00000000,0.00000000,0.00000000
161.15000000,3.71474300,2.42700000,0.12432878,220.02633462,0.11718622,247.38193989,0.00080301,0.12102039,251.36937845,-0.08122552,-0.03979487,0.00000000,0.00000000,0.00000000,0.00000000
162.65000000,3.75355300,2.43100000,0.12564178,220.38896558,0.11835334,248.07902702,0.00084849,0.12220330,251.97747609,-0.08202386,-0.04017944,0.00000000,0.00000000,0.00000000,0.00000000
164.15000000,3.79286600,2.43400000,0.12693611,220.66093880,0.11950254,248.67078025,0.00080766,0.12339132,252.58796443,-0.08280539,-0.04058593,0.00000000,0.00000000,0.00000000,0.00000000
165.65000000,3.83187600,2.43700000,0.12821189,220.93291202,0.12063398,249.25913799,0.00074074,0.12455180,253.19255845,-0.08357274,-0.04097906,0.00000000,0.00000000,0.00000000,0.00000000
167.15000000,3.87122300,2.44100000,0.12952867,221.29554298,0.12180044,249.95965960,0.00073988,0.12572394,253.80119532,-0.08434384,-0.04138009,0.00000000,0.00000000,0.00000000,0.00000000
168.65000000,3.91033400,2.44400000,0.13084922,221.56751620,0.12296887,250.55945336,0.00076555,0.12692401,254.41805528,-0.08514857,-0.04177545,0.00000000,0.00000000,0.00000000,0.00000000
170.15000000,3.95025100,2.44700000,0.13220333,221.83948942,0.12416559,251.16740939,0.00079762,0.12810312,255.03067105,-0.08591798,-0.04218514,0.00000000,0.00000000,0.00000000,0.00000000
171.65000000,3.98993300,2.45000000,0.13356856,222.11146264,0.12537067,251.77856988,0.00084922,0.12925618,255.53379443,-0.08666763,-0.04258855,0.00000000,0.00000000,0.00000000,0.00000000
173.15000000,4.02948100,2.45300000,0.13489656,222.38343586,0.12654151,252.38219537,0.00082864,0.13044545,256.15108779,-0.08745340,-0.04299205,0.00000000,0.00000000,0.00000000,0.00000000
174.65000000,4.06896200,2.45600000,0.13619833,222.65540908,0.12768789,252.98070470,0.00071577,0.13158783,256.75741303,-0.08818927,-0.04339856,0.00000000,0.00000000,0.00000000,0.00000000
176.15000000,4.10988600,2.45900000,0.13760467,222.92738230,0.12892488,253.60323043,0.00090523,0.13275304,257.26641397,-0.08897838,-0.04377466,0.00000000,0.00000000,0.00000000,0.00000000
177.65000000,4.14983700,2.46200000,0.13895500,223.19935552,0.13011118,254.21402196,0.00081905,0.13387333,257.86904025,-0.08971915,-0.04415418,0.00000000,0.00000000,0.00000000,0.00000000
179.15000000,4.18988900,2.46400000,0.14030167,223.38067100,0.13129285,254.72135144,0.00085083,0.13501964,258.37492955,-0.09045451,-0.04456513,0.00000000,0.00000000,0.00000000,0.00000000
180.65000000,4.22970500,2.46800000,0.14163700,223.74330196,0.13246320,255.43363202,0.00080388,0.13617287,258.98808774,-0.09121167,-0.04496120,0.00000000,0.00000000,0.00000000,0.00000000
182.15000000,4.27009300,2.47000000,0.14297244,223.92461744,0.13363228,255.93966736,0.00074420,0.13728092,259.48579411,-0.09193262,-0.04534830,0.00000000,0.00000000,0.00000000,0.00000000
183.65000000,4.31011000,2.47300000,0.14433022,224.19659066,0.13481951,256.55493441,0.00082802,0.13843949,259.99747411,-0.09273904,-0.04570045,0.00000000,0.00000000,0.00000000,0.00000000
185.15000000,4.35043100,2.47500000,0.14564333,224.37790614,0.13596634,257.05705231,0.00082067,0.13961262,260.51380474,-0.09348153,-0.04613109,0.00000000,0.00000000,0.00000000,0.00000000
186.65000000,4.39024700,2.47800000,0.14698622,224.64987936,0.13713783,257.67031644,0.00081971,0.14078454,261.03067926,-0.09428206,-0.04650248,0.00000000,0.00000000,0.00000000,0.00000000
188.15000000,4.43160800,2.48100000,0.14831789,224.92185257,0.13829817,258.28178691,0.00081217,0.14201129,261.66807328,-0.09509552,-0.04691578,0.00000000,0.00000000,0.00000000,0.00000000
189.65000000,4.47095400,2.48300000,0.14960489,225.10316805,0.13941831,258.77970250,0.00073353,0.14323484,262.20040788,-0.09588026,-0.04735458,0.00000000,0.00000000,0.00000000,0.00000000
191.15000000,4.51194600,2.48500000,0.15094033,225.28448353,0.14057929,259.28899857,0.00077150,0.14444397,262.72986093,-0.09663545,-0.04780852,0.00000000,0.00000000,0.00000000,0.00000000
192.65000000,4.55337400,2.48700000,0.15229811,225.46579901,0.14175831,259.80381432,0.00083541,0.14573485,263.28181858,-0.09750065,-0.04823420,0.00000000,0.00000000,0.00000000,0.00000000
194.15000000,4.59379500,2.49000000,0.15363356,225.73777223,0.14291657,260.41866881,0.00076970,0.14699852,263.82756566,-0.09832955,-0.04866897,0.00000000,0.00000000,0.00000000,0.00000000
195.65000000,4.63391400,2.49200000,0.15498767,225.91908771,0.14408967,260.93375997,0.00075590,0.14826371,264.37468111,-0.09913747,-0.04912624,0.00000000,0.00000000,0.00000000,0.00000000
197.15000000,4.67487200,2.49400000,0.15635289,226.10040319,0.14527099,261.45185441,0.00078730,0.14954636,264.92740947,-0.09995121,-0.04959515,0.00000000,0.00000000,0.00000000,0.00000000
198.65000000,4.71677000,2.49600000,0.15778167,226.28171867,0.14650582,261.98482538,0.00083146,0.15079556,265.47221637,-0.10075065,-0.05004491,0.00000000,0.00000000,0.00000000,0.00000000
200.15000000,4.75782800,2.49900000,0.15919533,226.55369189,0.14772609,262.61998239,0.00074663,0.15209876,265.92605085,-0.10162640,-0.05047236,0.00000000,0.00000000,0.00000000,0.00000000
201.65000000,4.80046500,2.50000000,0.16070622,226.64434963,0.14902863,263.06750685,0.00089372,0.15333518,266.46924393,-0.10245316,-0.05088202,0.00000000,0.00000000,0.00000000,0.00000000
203.15000000,4.84219500,2.50200000,0.16219456,226.82566511,0.15031008,263.61555305,0.00088607,0.15453839,267.00448110,-0.10324885,-0.05128954,0.00000000,0.00000000,0.00000000,0.00000000
204.65000000,4.88446300,2.50400000,0.16365300,227.00698059,0.15156419,264.15735399,0.00082707,0.15570833,267.53169143,-0.10403471,-0.05167361,0.00000000,0.00000000,0.00000000,0.00000000
206.15000000,4.92646100,2.50600000,0.16516378,227.18829607,0.15286166,264.71157332,0.00090308,0.15687846,267.95297032,-0.10481007,-0.05206840,0.00000000,0.00000000,0.00000000,0.00000000
207.65000000,4.96882900,2.50800000,0.16666700,227.36961155,0.15415097,265.26462260,0.00089544,0.15791926,268.44700447,-0.10548240,-0.05243686,0.00000000,0.00000000,0.00000000,0.00000000
209.15000000,5.01166800,2.51000000,0.16815922,227.55092703,0.15542920,265.81571394,0.00083054,0.15892735,268.93295255,-0.10613616,-0.05279119,0.00000000,0.00000000,0.00000000,0.00000000
210.65000000,5.05447200,2.51200000,0.16961400,227.73224251,0.15667378,266.35881909,0.00076564,0.15996748,269.32108403,-0.10685505,-0.05311243,0.00000000,0.00000000,0.00000000,0.00000000
212.15000000,5.09690700,2.51400000,0.17103144,227.91355799,0.15788494,266.89394302,0.00076452,0.16100652,269.70943871,-0.10754247,-0.05346405,0.00000000,0.00000000,0.00000000,0.00000000
213.65000000,5.14011400,2.51500000,0.17241167,228.00421573,0.15906288,267.31480257,0.00070010,0.16197994,270.18793648,-0.10817371,-0.05380622,0.00000000,0.00000000,0.00000000,0.00000000
215.15000000,5.18204600,2.51700000,0.17379189,228.18553121,0.16023944,267.84232570,0.00069928,0.16298538,270.56829300,-0.10883430,-0.05415108,0.00000000,0.00000000,0.00000000,0.00000000
216.65000000,5.22404500,2.51800000,0.17509744,228.27618895,0.16135108,268.24676626,0.00068481,0.16401973,271.06464366,-0.10953525,-0.05448448,0.00000000,0.00000000,0.00000000,0.00000000
218.15000000,5.26564100,2.52000000,0.17632844,228.45750443,0.16239810,268.74106081,0.00063428,0.16505450,271.45410418,-0.11021087,-0.05484363,0.00000000,0.00000000,0.00000000,0.00000000
219.65000000,5.30706800,2.52200000,0.17752211,228.63881991,0.16341232,269.22726590,0.00063363,0.16611957,271.85235083,-0.11092127,-0.05519829,0.00000000,0.00000000,0.00000000,0.00000000
221.15000000,5.34883200,2.52300000,0.17871578,228.72947765,0.16442552,269.60704415,0.00063299,0.16721464,272.25934277,-0.11160868,-0.05560597,0.00000000,0.00000000,0.00000000,0.00000000
222.65000000,5.39059600,2.52500000,0.17990944,228.91079313,0.16543769,270.09400675,0.00063235,0.16846352,272.81712502,-0.11246159,-0.05600193,0.00000000,0.00000000,0.00000000,0.00000000
224.15000000,5.43178900,2.52600000,0.18110322,229.00145087,0.16644894,270.47435151,0.00055751,0.16971223,273.26758242,-0.11325578,-0.05645646,0.00000000,0.00000000,0.00000000,0.00000000
225.65000000,5.47331700,2.52700000,0.18229689,229.09210861,0.16745906,270.85488728,0.00063107,0.17111539,273.76118404,-0.11416588,-0.05694951,0.00000000,0.00000000,0.00000000,0.00000000
227.15000000,5.51518100,2.52900000,0.18349056,229.27342409,0.16846817,271.34293205,0.00063044,0.17264116,274.28939741,-0.11510790,-0.05753326,0.00000000,0.00000000,0.00000000,0.00000000
228.65000000,5.55775100,2.53000000,0.18479611,229.36408183,0.16957070,271.74967218,0.00074101,0.17422673,274.83508985,-0.11612738,-0.05809935,0.00000000,0.00000000,0.00000000,0.00000000
230.15000000,5.59998400,2.53100000,0.18617622,229.45473957,0.17073487,272.17375615,0.00081773,0.17599609,275.43264167,-0.11721565,-0.05878044,0.00000000,0.00000000,0.00000000,0.00000000
231.65000000,5.64359400,2.53200000,0.18755644,229.54539731,0.17189779,272.59811587,0.00086244,0.17797924,276.09070714,-0.11848919,-0.05949005,0.00000000,0.00000000,0.00000000,0.00000000
233.15000000,5.68787600,2.53300000,0.18904844,229.63605505,0.17315336,273.04839404,0.00086135,0.18005125,276.77499580,-0.11979377,-0.06025748,0.00000000,0.00000000,0.00000000,0.00000000
234.65000000,5.73309600,2.53400000,0.19061511,229.72671279,0.17447007,273.51609567,0.00087742,0.18227311,277.50268723,-0.12122215,-0.06105096,0.00000000,0.00000000,0.00000000,0.00000000
236.15000000,5.77885500,2.53600000,0.19236822,229.90802827,0.17594143,274.13502694,0.00093878,0.18448836,278.34029357,-0.12267409,-0.06181427,0.00000000,0.00000000,0.00000000,0.00000000
237.65000000,5.82464700,2.53600000,0.19430789,229.90802827,0.17756685,274.58097188,0.00110267,0.18660780,279.04329467,-0.12408693,-0.06252087,0.00000000,0.00000000,0.00000000,0.00000000
239.15000000,5.87151400,2.53800000,0.19635956,230.08934375,0.17928324,275.26958502,0.00118524,0.18854059,279.58528291,-0.12543239,-0.06310820,0.00000000,0.00000000,0.00000000,0.00000000
240.65000000,5.91945500,2.53900000,0.19867233,230.18000149,0.18121456,275.91039947,0.00134290,0.19016214,280.15132403,-0.12651759,-0.06364455,0.00000000,0.00000000,0.00000000,0.00000000
242.15000000,5.96746200,2.54000000,0.20109711,230.27065923,0.18323540,276.57742357,0.00134019,0.19162851,280.67474080,-0.12749422,-0.06413429,0.00000000,0.00000000,0.00000000,0.00000000
243.65000000,6.01684700,2.54100000,0.20378300,230.36131697,0.18546910,277.30503722,0.00151958,0.19281969,281.01060170,-0.12827666,-0.06454302,0.00000000,0.00000000,0.00000000,0.00000000
245.15000000,6.06441800,2.54200000,0.20635689,230.45197471,0.18760498,278.00732724,0.00127363,0.19385533,281.41386556,-0.12895952,-0.06489581,0.00000000,0.00000000,0.00000000,0.00000000
246.65000000,6.11481000,2.54300000,0.20907978,230.54263245,0.18985956,278.74443481,0.00145233,0.19473913,281.66367940,-0.12953518,-0.06520395,0.00000000,0.00000000,0.00000000,0.00000000
248.15000000,6.16409400,2.54400000,0.21154156,230.63329019,0.19189356,279.42181515,0.00138892,0.19553067,281.88760620,-0.13009736,-0.06543332,0.00000000,0.00000000,0.00000000,0.00000000
249.65000000,6.21381500,2.54500000,0.21363044,230.72394793,0.19361623,280.01360746,0.00114546,0.19613905,282.05983587,-0.13049995,-0.06563910,0.00000000,0.00000000,0.00000000,0.00000000
251.15000000,6.26370300,2.54500000,0.21549578,230.72394793,0.19515204,280.44398454,0.00098237,0.19665431,282.31702927,-0.13079778,-0.06585653,0.00000000,0.00000000,0.00000000,0.00000000
252.65000000,6.31419600,2.54600000,0.21706278,230.81460567,0.19644040,280.91586512,0.00091973,0.19711004,282.44623298,-0.13108536,-0.06602468,0.00000000,0.00000000,0.00000000,0.00000000
254.15000000,6.36441900,2.54700000,0.21829400,230.90526341,0.19745152,281.31049698,0.00067392,0.19753360,282.67771035,-0.13141372,-0.06611988,0.00000000,0.00000000,0.00000000,0.00000000
255.65000000,6.41474400,2.54700000,0.21948789,230.90526341,0.19843101,281.58617220,0.00053996,0.19786600,282.88344188,-0.13155759,-0.06630840,0.00000000,0.00000000,0.00000000,0.00000000
257.14000000,6.46624300,2.54700000,0.22045767,230.90526341,0.19922593,281.81009900,0.00055032,0.19819837,283.08927349,-0.13178844,-0.06640993,0.00000000,0.00000000,0.00000000,0.00000000
258.64000000,6.51781000,2.54700000,0.22127811,230.90526341,0.19989794,281.99954394,0.00042747,0.19853073,283.29520521,-0.13200333,-0.06652740,0.00000000,0.00000000,0.00000000,0.00000000
260.14000000,6.57004800,2.54700000,0.22198678,230.90526341,0.20047804,282.16317880,0.00036629,0.19880225,283.48392980,-0.13216941,-0.06663284,0.00000000,0.00000000,0.00000000,0.00000000
261.64000000,6.62258800,2.54800000,0.22258333,230.99592115,0.20096611,282.41176326,0.00030502,0.19913109,283.91210558,-0.13240748,-0.06672361,0.00000000,0.00000000,0.00000000,0.00000000
263.14000000,6.67281200,2.54900000,0.22306811,231.08657888,0.20136255,282.63462554,0.00024403,0.19939766,284.43431528,-0.13256039,-0.06683727,0.00000000,0.00000000,0.00000000,0.00000000
264.64000000,6.71937600,2.55000000,0.22351567,231.17723662,0.20172841,282.84897079,0.00024394,0.19978703,284.88032930,-0.13284454,-0.06694250,0.00000000,0.00000000,0.00000000,0.00000000
266.14000000,6.75180600,2.55000000,0.22392589,231.17723662,0.20206363,282.94380483,0.00018284,0.00000000,0.00000000,0.00000000,0.00000000,0.00000000,0.00000000,0.00000000,0.00000000
267.64000000,6.77188400,2.55100000,0.22437367,231.26789436,0.20242942,283.15831981,0.00024377,0.00000000,0.00000000,0.00000000,0.00000000,0.00000000,0.00000000,0.00000000,0.00000000
269.14000000,6.78810100,2.55200000,0.22470944,231.35855210,0.20270363,283.34700382,0.00018273,0.00000000,0.00000000,0.00000000,0.00000000,0.00000000,0.00000000,0.00000000,0.00000000
270.64000000,6.80354300,2.55500000,0.22504511,231.63052532,0.20297767,283.75784263,0.00012190,0.00000000,0.00000000,0.00000000,0.00000000,0.00000000,0.00000000,0.00000000,0.00000000
272.14000000,6.81915300,2.55800000,0.22541800,231.90249854,0.20328201,284.17749596,0.00012169,0.00000000,0.00000000,0.00000000,0.00000000,0.00000000,0.00000000,0.00000000,0.00000000
273.64000000,6.83818800,2.56200000,0.22586567,232.26512950,0.20364726,284.72584782,0.00024347,0.00000000,0.00000000,0.00000000,0.00000000,0.00000000,0.00000000,0.00000000,0.00000000
275.14000000,6.86343300,2.56400000,0.22631333,232.44644498,0.00000000,0.00000000,0.00000000,0.00000000,0.00000000,0.00000000,0.00000000,0.00000000,0.00000000,0.00000000,0.00000000
276.64000000,6.90428800,2.55200000,0.22672378,231.35855210,0.00000000,0.00000000,0.00000000,0.00000000,0.00000000,0.00000000,0.00000000,0.00000000,0.00000000,0.00000000,0.00000000
278.14000000,6.95280100,2.55100000,0.22709711,231.26789436,0.00000000,0.00000000,0.00000000,0.00000000,0.00000000,0.00000000,0.00000000,0.00000000,0.00000000,0.00000000,0.00000000
279.65000000,7.00299200,2.55300000,0.22735822,231.44920984,0.00000000,0.00000000,0.00000000,0.00000000,0.00000000,0.00000000,0.00000000,0.00000000,0.00000000,0.00000000,0.00000000
281.14000000,7.05241000,2.55200000,0.22773133,231.35855210,0.00000000,0.00000000,0.00000000,0.00000000,0.00000000,0.00000000,0.00000000,0.00000000,0.00000000,0.00000000,0.00000000
282.64000000,7.09719500,2.55300000,0.22802967,231.44920984,0.00000000,0.00000000,0.00000000,0.00000000,0.00000000,0.00000000,0.00000000,0.00000000,0.00000000,0.00000000,0.00000000
284.14000000,7.13711300,2.55400000,0.22825322,231.53986758,0.00000000,0.00000000,0.00000000,0.00000000,0.00000000,0.00000000,0.00000000,0.00000000,0.00000000,0.00000000,0.00000000
285.64000000,7.17679500,2.55400000,0.22851422,231.53986758,0.00000000,0.00000000,0.00000000,0.00000000,0.00000000,0.00000000,0.00000000,0.00000000,0.00000000,0.00000000,0.00000000
287.14000000,7.22006800,2.55400000,0.22877533,231.53986758,0.00000000,0.00000000,0.00000000,0.00000000,0.00000000,0.00000000,0.00000000,0.00000000,0.00000000,0.00000000,0.00000000
288.64000000,7.26710200,2.55400000,0.22903667,231.53986758,0.00000000,0.00000000,0.00000000,0.00000000,0.00000000,0.00000000,0.00000000,0.00000000,0.00000000,0.00000000,0.00000000
290.14000000,7.31692400,2.55300000,0.22926078,231.44920984,0.00000000,0.00000000,0.00000000,0.00000000,0.00000000,0.00000000,0.00000000,0.00000000,0.00000000,0.00000000,0.00000000
291.64000000,7.36885900,2.55300000,0.22978311,231.44920984,0.00000000,0.00000000,0.00000000,0.00000000,0.00000000,0.00000000,0.00000000,0.00000000,0.00000000,0.00000000,0.00000000
293.14000000,7.42257400,2.55300000,0.23127456,231.44920984,0.00000000,0.00000000,0.00000000,0.00000000,0.00000000,0.00000000,0.00000000,0.00000000,0.00000000,0.00000000,0.00000000
294.64000000,7.47746400,2.55400000,0.23422089,231.53986758,0.00000000,0.00000000,0.00000000,0.00000000,0.00000000,0.00000000,0.00000000,0.00000000,0.00000000,0.00000000,0.00000000
296.14000000,7.53161500,2.55400000,0.23798833,231.53986758,0.00000000,0.00000000,0.00000000,0.00000000,0.00000000,0.00000000,0.00000000,0.00000000,0.00000000,0.00000000,0.00000000
297.64000000,7.58835200,2.55300000,0.24242722,231.44920984,0.00000000,0.00000000,0.00000000,0.00000000,0.00000000,0.00000000,0.00000000,0.00000000,0.00000000,0.00000000,0.00000000
299.14000000,7.64498800,2.55400000,0.24716467,231.53986758,0.00000000,0.00000000,0.00000000,0.00000000,0.00000000,0.00000000,0.00000000,0.00000000,0.00000000,0.00000000,0.00000000
300.64000000,7.70206000,2.55400000,0.25186478,231.53986758,0.00000000,0.00000000,0.00000000,0.00000000,0.00000000,0.00000000,0.00000000,0.00000000,0.00000000,0.00000000,0.00000000
302.14000000,7.75758800,2.55400000,0.25656500,231.53986758,0.00000000,0.00000000,0.00000000,0.00000000,0.00000000,0.00000000,0.00000000,0.00000000,0.00000000,0.00000000,0.00000000
303.64000000,7.81617200,2.55300000,0.26148933,231.44920984,0.00000000,0.00000000,0.00000000,0.00000000,0.00000000,0.00000000,0.00000000,0.00000000,0.00000000,0.00000000,0.00000000
305.14000000,7.87297600,2.55300000,0.26648844,231.44920984,0.00000000,0.00000000,0.00000000,0.00000000,0.00000000,0.00000000,0.00000000,0.00000000,0.00000000,0.00000000,0.00000000
306.64000000,7.93082000,2.55300000,0.27156167,231.44920984,0.00000000,0.00000000,0.00000000,0.00000000,0.00000000,0.00000000,0.00000000,0.00000000,0.00000000,0.00000000,0.00000000
308.14000000,7.98842800,2.55300000,0.27659700,231.44920984,0.00000000,0.00000000,0.00000000,0.00000000,0.00000000,0.00000000,0.00000000,0.00000000,0.00000000,0.00000000,0.00000000
309.64000000,8.04654200,2.55200000,0.28152033,231.35855210,0.00000000,0.00000000,0.00000000,0.00000000,0.00000000,0.00000000,0.00000000,0.00000000,0.00000000,0.00000000,0.00000000
311.14000000,8.10492400,2.55100000,0.28614556,231.26789436,0.00000000,0.00000000,0.00000000,0.00000000,0.00000000,0.00000000,0.00000000,0.00000000,0.00000000,0.00000000,0.00000000
312.64000000,8.16371100,2.54700000,0.28983822,230.90526341,0.00000000,0.00000000,0.00000000,0.00000000,0.00000000,0.00000000,0.00000000,0.00000000,0.00000000,0.00000000,0.00000000
314.14000000,8.22229600,2.54600000,0.29282256,230.81460567,0.00000000,0.00000000,0.00000000,0.00000000,0.00000000,0.00000000,0.00000000,0.00000000,0.00000000,0.00000000,0.00000000
315.64000000,8.28148200,2.54300000,0.29621744,230.54263245,0.00000000,0.00000000,0.00000000,0.00000000,0.00000000,0.00000000,0.00000000,0.00000000,0.00000000,0.00000000,0.00000000
317.14000000,8.34137200,2.53900000,0.29983578,230.18000149,0.00000000,0.00000000,0.00000000,0.00000000,0.00000000,0.00000000,0.00000000,0.00000000,0.00000000,0.00000000,0.00000000
318.64000000,8.40092800,2.53500000,0.30296878,229.81737053,0.00000000,0.00000000,0.00000000,0.00000000,0.00000000,0.00000000,0.00000000,0.00000000,0.00000000,0.00000000,0.00000000
320.14000000,8.46062000,2.53200000,0.30610211,229.54539731,0.00000000,0.00000000,0.00000000,0.00000000,0.00000000,0.00000000,0.00000000,0.00000000,0.00000000,0.00000000,0.00000000
321.64000000,8.52051600,2.52800000,0.30934778,229.18276635,0.00000000,0.00000000,0.00000000,0.00000000,0.00000000,0.00000000,0.00000000,0.00000000,0.00000000,0.00000000,0.00000000
323.14000000,8.58004200,2.52200000,0.31255622,228.63881991,0.00000000,0.00000000,0.00000000,0.00000000,0.00000000,0.00000000,0.00000000,0.00000000,0.00000000,0.00000000,0.00000000
324.64000000,8.64057600,2.51300000,0.31580189,227.82290025,0.00000000,0.00000000,0.00000000,0.00000000,0.00000000,0.00000000,0.00000000,0.00000000,0.00000000,0.00000000,0.00000000
326.14000000,8.70131400,2.49900000,0.31927144,226.55369189,0.00000000,0.00000000,0.00000000,0.00000000,0.00000000,0.00000000,0.00000000,0.00000000,0.00000000,0.00000000,0.00000000
327.64000000,8.76353500,2.47900000,0.32281611,224.74053710,0.00000000,0.00000000,0.00000000,0.00000000,0.00000000,0.00000000,0.00000000,0.00000000,0.00000000,0.00000000,0.00000000
329.14000000,8.82704000,2.44700000,0.32632456,221.83948942,0.00000000,0.00000000,0.00000000,0.00000000,0.00000000,0.00000000,0.00000000,0.00000000,0.00000000,0.00000000,0.00000000
330.64000000,8.89193300,2.39300000,0.32927978,216.94397147,0.00000000,0.00000000,0.00000000,0.00000000,0.00000000,0.00000000,0.00000000,0.00000000,0.00000000,0.00000000,0.00000000
332.14000000,8.96324900,2.31500000,0.33249244,209.87266776,0.00000000,0.00000000,0.00000000,0.00000000,0.00000000,0.00000000,0.00000000,0.00000000,0.00000000,0.00000000,0.00000000
333.64000000,9.33028300,0.02600000,0.33025256,2.35710124,0.00000000,0.00000000,0.00000000,0.00000000,0.00000000,0.00000000,0.00000000,0.00000000,0.00000000,0.00000000,0.00000000
NaN,-100.00000000,NaN,-11.11111111,NaN,0.00000000,0.00000000,0.00000000,0.00000000,0.00000000,0.00000000,0.00000000,0.00000000,0.00000000,0.00000000,0.00000000