File: polyN_optimization/results_exp/AA6014-T4/UT_60_1.csv
Time[s],Displacement[mm],Force[kN],EngStrain_longi,EngStress[MPa],TrueStrain,TrueStress[MPa],TrueStrainRate[1/s],PlasticStrain_longi,PlasticStress[MPa],PlasticStrain_thick,PlasticStrain_width,R-Value,Thickness[mm],Width[mm], Young's Modulus [MPa]
0.56000000,0.00000000,-0.00100000,0.00000000,-0.09034917,0.00000000,-0.09034917,0.00000000,0.00097638,116.31204988,-0.00019322,-0.00078316,0.56396809,1.11490000,9.92750000,94773.75090473
2.06000000,0.00591000,0.16600000,0.00017011,14.99796296,0.00017010,15.00051429,0.00015331,0.00216104,119.90232150,-0.00096958,-0.00119146,0.00000000,0.00000000,0.00000000,0.00000000
3.56000000,0.01316700,0.40100000,0.00038978,36.23001897,0.00038970,36.24414063,0.00009663,0.00334663,123.13755066,-0.00175116,-0.00159546,0.00000000,0.00000000,0.00000000,0.00000000
5.06000000,0.02218800,0.63900000,0.00070089,57.73312250,0.00070064,57.77358700,0.00022297,0.00451548,126.10521929,-0.00256584,-0.00194965,0.00000000,0.00000000,0.00000000,0.00000000
6.56000000,0.03078900,0.90300000,0.00097700,81.58530456,0.00097652,81.66501340,0.00030128,0.00564461,128.89238988,-0.00329936,-0.00234525,0.00000000,0.00000000,0.00000000,0.00000000
8.06000000,0.04202600,1.13100000,0.00129144,102.18491635,0.00129061,102.31688249,0.00030030,0.00681649,131.41764204,-0.00408684,-0.00272965,0.00000000,0.00000000,0.00000000,0.00000000
9.56000000,0.06681200,1.26900000,0.00208389,114.65310242,0.00208172,114.89202675,0.00059285,0.00800115,133.76769631,-0.00489729,-0.00310386,0.00000000,0.00000000,0.00000000,0.00000000
11.06000000,0.10526600,1.30800000,0.00343200,118.17672023,0.00342612,118.58230273,0.00078745,0.00916737,136.12077743,-0.00568347,-0.00348390,0.00000000,0.00000000,0.00000000,0.00000000
12.56000000,0.14111200,1.34400000,0.00470478,121.42929051,0.00469374,122.00058834,0.00094688,0.01027243,138.28756177,-0.00642087,-0.00385156,0.00000000,0.00000000,0.00000000,0.00000000
14.06000000,0.17722300,1.37600000,0.00588767,124.32046409,0.00587040,125.05242155,0.00095395,0.01142513,140.37405935,-0.00718954,-0.00423560,0.00000000,0.00000000,0.00000000,0.00000000
15.56000000,0.21448100,1.40600000,0.00709033,127.03093933,0.00706532,127.93163103,0.00084331,0.01262284,142.56359850,-0.00802007,-0.00460277,0.00000000,0.00000000,0.00000000,0.00000000
17.06000000,0.25024500,1.43200000,0.00834700,129.38001787,0.00831236,130.45995288,0.00090664,0.01378500,144.56920712,-0.00877069,-0.00501431,0.00000000,0.00000000,0.00000000,0.00000000
18.56000000,0.28764500,1.45700000,0.00960367,131.63874723,0.00955784,132.90296188,0.00099558,0.01488101,146.47760353,-0.00947668,-0.00540433,0.00000000,0.00000000,0.00000000,0.00000000
20.06000000,0.32335900,1.48200000,0.01075678,133.89747659,0.01069934,135.33778199,0.00087852,0.01602060,148.58098001,-0.01020753,-0.00581307,0.00000000,0.00000000,0.00000000,0.00000000
21.56000000,0.35934500,1.50300000,0.01194444,135.79480925,0.01187367,137.41680281,0.00073821,0.01719191,150.41695719,-0.01098658,-0.00620533,0.00000000,0.00000000,0.00000000,0.00000000
23.06000000,0.39547200,1.52500000,0.01317167,137.78249109,0.01308567,139.59731614,0.00078076,0.01828515,152.24521708,-0.01169532,-0.00658983,0.00000000,0.00000000,0.00000000,0.00000000
24.56000000,0.43070200,1.54700000,0.01437656,139.77017293,0.01427419,141.77958659,0.00084602,0.01938804,154.07888182,-0.01238144,-0.00700660,0.00000000,0.00000000,0.00000000,0.00000000
26.06000000,0.46638000,1.56700000,0.01550311,141.57715642,0.01538417,143.77204281,0.00072752,0.02052592,155.92196907,-0.01311854,-0.00740738,0.00000000,0.00000000,0.00000000,0.00000000
27.56000000,0.50177200,1.58700000,0.01668933,143.38413991,0.01655160,145.77712562,0.00064599,0.02161779,157.57640644,-0.01382966,-0.00778813,0.00000000,0.00000000,0.00000000,0.00000000
29.06000000,0.53732800,1.60700000,0.01790156,145.19112340,0.01774321,147.79027036,0.00072559,0.02273486,159.42405507,-0.01456358,-0.00817128,0.00000000,0.00000000,0.00000000,0.00000000
30.56000000,0.57254500,1.62600000,0.01906544,146.90775772,0.01888598,149.70861941,0.00077624,0.02384583,161.08884705,-0.01529153,-0.00855431,0.00000000,0.00000000,0.00000000,0.00000000
32.06000000,0.60773800,1.64400000,0.02022922,148.53404286,0.02002733,151.53877102,0.00075335,0.02497004,162.75937945,-0.01602663,-0.00894340,0.00000000,0.00000000,0.00000000,0.00000000
33.56000000,0.64251600,1.66300000,0.02141178,150.25067717,0.02118577,153.46781128,0.00071613,0.02609288,164.43331989,-0.01678279,-0.00931009,0.00000000,0.00000000,0.00000000,0.00000000
35.06000000,0.67745100,1.68000000,0.02258300,151.78661314,0.02233178,155.21441022,0.00074422,0.02715067,166.00679202,-0.01744803,-0.00970264,0.00000000,0.00000000,0.00000000,0.00000000
36.56000000,0.71250000,1.69700000,0.02373189,153.32254911,0.02345467,156.96118280,0.00075055,0.02826121,167.59234332,-0.01818400,-0.01007721,0.00000000,0.00000000,0.00000000,0.00000000
38.06000000,0.74715300,1.71500000,0.02488833,154.94883425,0.02458366,158.80525248,0.00072086,0.02934399,169.27005946,-0.01888721,-0.01045678,0.00000000,0.00000000,0.00000000,0.00000000
39.56000000,0.78196700,1.73000000,0.02609311,156.30407186,0.02575849,160.38253138,0.00079996,0.03047854,170.77297562,-0.01962617,-0.01085238,0.00000000,0.00000000,0.00000000,0.00000000
41.06000000,0.81708400,1.74700000,0.02725322,157.84000783,0.02688847,162.14165664,0.00079170,0.03155065,172.26836564,-0.02032666,-0.01122399,0.00000000,0.00000000,0.00000000,0.00000000
42.56000000,0.85189800,1.76200000,0.02839100,159.19524545,0.02799544,163.71495766,0.00069657,0.03266455,173.77410925,-0.02104275,-0.01162180,0.00000000,0.00000000,0.00000000,0.00000000
44.06000000,0.88647800,1.77800000,0.02957722,160.64083224,0.02914825,165.39214183,0.00076832,0.03376643,175.28094709,-0.02177884,-0.01198758,0.00000000,0.00000000,0.00000000,0.00000000
45.56000000,0.92105700,1.79300000,0.03069622,161.99606986,0.03023452,166.96873722,0.00074570,0.03485028,176.69374481,-0.02245885,-0.01239143,0.00000000,0.00000000,0.00000000,0.00000000
47.06000000,0.95543500,1.80900000,0.03186378,163.44165665,0.03136666,168.64952527,0.00078816,0.03596024,178.20824787,-0.02319782,-0.01276242,0.00000000,0.00000000,0.00000000,0.00000000
48.56000000,0.99068500,1.82300000,0.03302767,164.70654509,0.03249397,170.14641796,0.00075133,0.03703936,179.53193521,-0.02391021,-0.01312915,0.00000000,0.00000000,0.00000000,0.00000000
50.06000000,1.02543300,1.83700000,0.03419522,165.97143353,0.03362356,171.64686359,0.00066386,0.03811373,180.85746092,-0.02456407,-0.01354966,0.00000000,0.00000000,0.00000000,0.00000000
51.56000000,1.06021300,1.85100000,0.03534789,167.23632198,0.03473749,173.14777290,0.00069189,0.03921536,182.19065699,-0.02528237,-0.01393299,0.00000000,0.00000000,0.00000000,0.00000000
53.06000000,1.09449000,1.86500000,0.03649300,168.50121042,0.03584290,174.65032509,0.00070549,0.04030004,183.61805567,-0.02596787,-0.01433217,0.00000000,0.00000000,0.00000000,0.00000000
54.56000000,1.12933800,1.87900000,0.03766056,169.76609886,0.03696871,176.15958446,0.00071177,0.04140982,184.95839064,-0.02670205,-0.01470777,0.00000000,0.00000000,0.00000000,0.00000000
56.06000000,1.16395200,1.89300000,0.03880578,171.03098730,0.03807176,177.66797779,0.00072554,0.04247210,186.29265475,-0.02739353,-0.01507857,0.00000000,0.00000000,0.00000000,0.00000000
57.56000000,1.19836300,1.90500000,0.03995089,172.11517740,0.03917349,178.99133173,0.00074611,0.04355219,187.53807369,-0.02807526,-0.01547692,0.00000000,0.00000000,0.00000000,0.00000000
59.06000000,1.23277400,1.91800000,0.04111100,173.28971667,0.04028841,180.41383021,0.00072393,0.04466655,188.79249872,-0.02880754,-0.01585901,0.00000000,0.00000000,0.00000000,0.00000000
60.56000000,1.26795700,1.93100000,0.04228233,174.46425594,0.04141286,181.84101176,0.00070883,0.04579375,190.05197735,-0.02954687,-0.01624688,0.00000000,0.00000000,0.00000000,0.00000000
62.06000000,1.30267100,1.94300000,0.04345367,175.54844603,0.04253604,183.17666969,0.00077961,0.04685805,191.39723223,-0.03021360,-0.01664446,0.00000000,0.00000000,0.00000000,0.00000000
63.56000000,1.33751900,1.95400000,0.04461378,176.54228695,0.04364723,184.41850531,0.00075725,0.04796628,192.56306668,-0.03095176,-0.01701452,0.00000000,0.00000000,0.00000000,0.00000000
65.06000000,1.37213200,1.96700000,0.04572900,177.71682622,0.04471425,185.84363896,0.00067056,0.04906840,193.82551573,-0.03166137,-0.01740703,0.00000000,0.00000000,0.00000000,0.00000000
66.56000000,1.40677800,1.97800000,0.04691156,178.71066714,0.04584445,187.09426253,0.00069147,0.05014587,194.99021977,-0.03234686,-0.01779901,0.00000000,0.00000000,0.00000000,0.00000000
68.06000000,1.44165900,1.98900000,0.04809400,179.70450806,0.04697328,188.34721667,0.00078316,0.05122337,196.06162529,-0.03303167,-0.01819170,0.00000000,0.00000000,0.00000000,0.00000000
69.56000000,1.47660800,2.00100000,0.04925411,180.78869815,0.04807954,189.69328478,0.00080370,0.05234634,197.33560824,-0.03376930,-0.01857703,0.00000000,0.00000000,0.00000000,0.00000000
71.06000000,1.51172400,2.01100000,0.05042533,181.69218989,0.04919516,190.85407913,0.00068894,0.05346009,198.41872435,-0.03448104,-0.01897905,0.00000000,0.00000000,0.00000000,0.00000000
72.56000000,1.54663900,2.02200000,0.05160411,182.68603081,0.05031672,192.11338105,0.00073087,0.05453259,199.59173977,-0.03518579,-0.01934680,0.00000000,0.00000000,0.00000000,0.00000000
74.06000000,1.58215700,2.03300000,0.05277911,183.67987173,0.05143344,193.37433209,0.00073702,0.05564368,200.67879184,-0.03588391,-0.01975978,0.00000000,0.00000000,0.00000000,0.00000000
75.56000000,1.61673700,2.04300000,0.05393922,184.58336348,0.05253478,194.53964654,0.00071512,0.05675014,201.76710909,-0.03661773,-0.02013241,0.00000000,0.00000000,0.00000000,0.00000000
77.06000000,1.65168500,2.05300000,0.05508067,185.48685522,0.05361723,195.70359487,0.00065767,0.05785521,202.85734040,-0.03733391,-0.02052130,0.00000000,0.00000000,0.00000000,0.00000000
78.56000000,1.68673400,2.06300000,0.05628178,186.39034697,0.05475498,196.88072706,0.00072763,0.05894504,203.94665230,-0.03801300,-0.02093204,0.00000000,0.00000000,0.00000000,0.00000000
80.06000000,1.72164900,2.07300000,0.05746056,187.29383871,0.05587033,198.05584674,0.00079031,0.06002322,205.03573581,-0.03870890,-0.02131433,0.00000000,0.00000000,0.00000000,0.00000000
81.56000000,1.75713400,2.08200000,0.05862067,188.10698128,0.05696680,199.13393793,0.00072602,0.06114675,206.03973200,-0.03942561,-0.02172114,0.00000000,0.00000000,0.00000000,0.00000000
83.06000000,1.79241700,2.09200000,0.05979933,189.01047303,0.05807958,200.31317331,0.00069690,0.06225721,207.13975901,-0.04015274,-0.02210447,0.00000000,0.00000000,0.00000000,0.00000000
84.56000000,1.82793600,2.10100000,0.06098922,189.82361560,0.05920170,201.40081027,0.00073844,0.06336568,208.04794086,-0.04085931,-0.02250637,0.00000000,0.00000000,0.00000000,0.00000000
86.06000000,1.86369000,2.11000000,0.06219044,190.63675817,0.06033323,202.49254289,0.00079391,0.06444365,209.04844645,-0.04153360,-0.02291006,0.00000000,0.00000000,0.00000000,0.00000000
87.56000000,1.89870500,2.11900000,0.06335044,191.44990074,0.06142472,203.57833704,0.00072258,0.06557596,210.06234335,-0.04229320,-0.02328276,0.00000000,0.00000000,0.00000000,0.00000000
89.06000000,1.93435800,2.12700000,0.06454789,192.17269413,0.06255019,204.57703584,0.00072908,0.06670001,211.07654872,-0.04302231,-0.02367771,0.00000000,0.00000000,0.00000000,0.00000000
90.56000000,1.96957400,2.13600000,0.06573778,192.98583671,0.06366731,205.67229675,0.00075622,0.06777774,212.08294506,-0.04371777,-0.02405997,0.00000000,0.00000000,0.00000000,0.00000000
92.06000000,2.00559700,2.14500000,0.06694267,193.79897928,0.06479724,206.77239975,0.00078328,0.06888676,213.00060605,-0.04442561,-0.02446115,0.00000000,0.00000000,0.00000000,0.00000000
93.56000000,2.04125000,2.15200000,0.06812889,194.43142350,0.06590842,207.67782035,0.00073350,0.07000130,213.92124940,-0.04513255,-0.02486875,0.00000000,0.00000000,0.00000000,0.00000000
95.06000000,2.07737300,2.16100000,0.06936722,195.24456607,0.06706709,208.78813927,0.00079544,0.07114571,214.85014226,-0.04589854,-0.02524716,0.00000000,0.00000000,0.00000000,0.00000000
96.56000000,2.11306000,2.16800000,0.07056467,195.87701029,0.06818624,209.69900623,0.00082943,0.07225084,215.77240597,-0.04662133,-0.02562952,0.00000000,0.00000000,0.00000000,0.00000000
98.06000000,2.14908200,2.17600000,0.07175833,196.59980368,0.06930060,210.70747793,0.00077292,0.07335471,216.69619374,-0.04733333,-0.02602138,0.00000000,0.00000000,0.00000000,0.00000000
99.56000000,2.18507100,2.18400000,0.07295578,197.32259708,0.07041725,211.71842062,0.00077206,0.07448140,217.62676402,-0.04805776,-0.02642364,0.00000000,0.00000000,0.00000000,0.00000000
101.06000000,2.22109400,2.19100000,0.07419422,197.95504130,0.07157082,212.64216163,0.00076413,0.07556203,218.54908216,-0.04873660,-0.02682543,0.00000000,0.00000000,0.00000000,0.00000000
102.56000000,2.25688200,2.19900000,0.07536922,198.67783470,0.07266407,213.65202857,0.00078417,0.07667918,219.48120473,-0.04945928,-0.02721990,0.00000000,0.00000000,0.00000000,0.00000000
104.06000000,2.29334100,2.20600000,0.07657033,199.31027892,0.07378037,214.57153341,0.00076244,0.07782737,220.32375357,-0.05018384,-0.02764353,0.00000000,0.00000000,0.00000000,0.00000000
105.56000000,2.32973300,2.21300000,0.07777144,199.94272314,0.07489543,215.49255753,0.00067166,0.07895021,221.16234554,-0.05089749,-0.02805272,0.00000000,0.00000000,0.00000000,0.00000000
107.06000000,2.36602400,2.22000000,0.07901733,200.57516736,0.07605075,216.42408222,0.00073311,0.08005799,221.99920796,-0.05164899,-0.02840900,0.00000000,0.00000000,0.00000000,0.00000000
108.56000000,2.40214800,2.22700000,0.08021100,201.20761158,0.07715639,217.34667532,0.00070451,0.08115096,222.83436195,-0.05231366,-0.02883730,0.00000000,0.00000000,0.00000000,0.00000000
110.06000000,2.43837200,2.23300000,0.08140467,201.74970663,0.07826081,218.17307425,0.00072450,0.08225286,223.67310011,-0.05302706,-0.02922580,0.00000000,0.00000000,0.00000000,0.00000000
111.56000000,2.47473000,2.24000000,0.08260956,202.38215085,0.07937438,219.10085039,0.00071038,0.08338418,224.52006196,-0.05376472,-0.02961946,0.00000000,0.00000000,0.00000000,0.00000000
113.06000000,2.51142400,2.24700000,0.08386656,203.01459507,0.08053479,220.04072989,0.00079156,0.08448009,225.36066719,-0.05449027,-0.02998982,0.00000000,0.00000000,0.00000000,0.00000000
114.56000000,2.54811800,2.25300000,0.08508633,203.55669012,0.08165955,220.87658251,0.00076322,0.08559995,226.10924981,-0.05519163,-0.03040832,0.00000000,0.00000000,0.00000000,0.00000000
116.06000000,2.58451000,2.25900000,0.08631733,204.09878517,0.08279338,221.71604804,0.00078302,0.08671724,226.95782019,-0.05589472,-0.03082252,0.00000000,0.00000000,0.00000000,0.00000000
117.56000000,2.62103700,2.26500000,0.08752222,204.64088021,0.08390192,222.55150481,0.00072737,0.08784807,227.71184073,-0.05660695,-0.03124112,0.00000000,0.00000000,0.00000000,0.00000000
119.06000000,2.65773100,2.27100000,0.08878678,205.18297526,0.08506403,223.40051049,0.00077451,0.08895396,228.46157326,-0.05732491,-0.03162904,0.00000000,0.00000000,0.00000000,0.00000000
120.56000000,2.69439100,2.27700000,0.08999167,205.72507031,0.08617005,224.23861226,0.00077365,0.09008079,229.31702555,-0.05803408,-0.03204671,0.00000000,0.00000000,0.00000000,0.00000000
122.06000000,2.73115200,2.28300000,0.09120022,206.26716535,0.08727821,225.07877667,0.00077952,0.09120781,230.07455739,-0.05876933,-0.03243848,0.00000000,0.00000000,0.00000000,0.00000000
123.56000000,2.76804800,2.28800000,0.09245733,206.71891123,0.08842959,225.83159051,0.00080609,0.09235032,230.83711108,-0.05951432,-0.03283600,0.00000000,0.00000000,0.00000000,0.00000000
125.06000000,2.80481000,2.29400000,0.09369200,207.26100627,0.08955913,226.67970447,0.00077774,0.09345782,231.59298490,-0.06019535,-0.03326247,0.00000000,0.00000000,0.00000000,0.00000000
126.56000000,2.84197400,2.30000000,0.09492300,207.80310132,0.09068404,227.52839511,0.00076326,0.09456746,232.35076688,-0.06090170,-0.03366576,0.00000000,0.00000000,0.00000000,0.00000000
128.06000000,2.87893600,2.30500000,0.09616144,208.25484719,0.09181448,228.28093411,0.00072853,0.09569058,233.01303600,-0.06162748,-0.03406310,0.00000000,0.00000000,0.00000000,0.00000000
129.56000000,2.91589900,2.31000000,0.09737744,208.70659307,0.09292319,229.02990774,0.00067303,0.09682793,233.78004157,-0.06235343,-0.03447451,0.00000000,0.00000000,0.00000000,0.00000000
131.06000000,2.95323100,2.31500000,0.09862711,209.15833894,0.09406132,229.78702167,0.00074045,0.09793834,234.44185908,-0.06305880,-0.03487955,0.00000000,0.00000000,0.00000000,0.00000000
132.56000000,2.99032800,2.32000000,0.09986922,209.61008481,0.09519128,230.54368095,0.00078691,0.09903948,235.20310172,-0.06376475,-0.03527473,0.00000000,0.00000000,0.00000000,0.00000000
134.06000000,3.02695500,2.32500000,0.10108900,210.06183068,0.09629969,231.29677109,0.00069802,0.10017960,235.97498403,-0.06448953,-0.03569007,0.00000000,0.00000000,0.00000000,0.00000000
135.56000000,3.06465700,2.33000000,0.10235356,210.51357656,0.09744749,232.06038961,0.00077849,0.10132977,236.65007019,-0.06519397,-0.03613580,0.00000000,0.00000000,0.00000000,0.00000000
137.06000000,3.10202200,2.33500000,0.10358078,210.96532243,0.09856015,232.81727461,0.00075043,0.10249532,237.33007175,-0.06595723,-0.03653810,0.00000000,0.00000000,0.00000000,0.00000000
138.56000000,3.13958900,2.33900000,0.10489011,211.32671913,0.09974588,233.49280218,0.00080366,0.10358605,237.99348072,-0.06664184,-0.03694421,0.00000000,0.00000000,0.00000000,0.00000000
140.06000000,3.17759300,2.34400000,0.10614722,211.77846500,0.10088301,234.25816078,0.00080958,0.10473079,238.77200394,-0.06738569,-0.03734511,0.00000000,0.00000000,0.00000000,0.00000000
141.56000000,3.21458900,2.34800000,0.10739311,212.13986170,0.10200870,234.92222143,0.00078157,0.10586709,239.34774763,-0.06811490,-0.03775219,0.00000000,0.00000000,0.00000000,0.00000000
143.06000000,3.25265900,2.35300000,0.10865022,212.59160757,0.10314326,235.68973297,0.00078088,0.10699064,240.02266406,-0.06881848,-0.03817216,0.00000000,0.00000000,0.00000000,0.00000000
144.56000000,3.29019300,2.35800000,0.10992967,213.04335344,0.10429665,236.46313827,0.00078659,0.10811616,240.69928395,-0.06953901,-0.03857715,0.00000000,0.00000000,0.00000000,0.00000000
146.06000000,3.32812900,2.36100000,0.11117556,213.31440096,0.10541851,237.02974800,0.00069168,0.10924711,241.37844996,-0.07025394,-0.03899317,0.00000000,0.00000000,0.00000000,0.00000000
147.56000000,3.36599800,2.36600000,0.11241400,213.76614684,0.10653243,237.79645447,0.00067752,0.11042319,242.06981939,-0.07101157,-0.03941162,0.00000000,0.00000000,0.00000000,0.00000000
149.06000000,3.40393500,2.37000000,0.11369722,214.12754354,0.10768531,238.47325044,0.00069011,0.11153957,242.64624673,-0.07170566,-0.03983391,0.00000000,0.00000000,0.00000000,0.00000000
150.56000000,3.44237500,2.37400000,0.11497289,214.48894023,0.10883009,239.14935333,0.00070926,0.11267976,243.33130308,-0.07243755,-0.04024221,0.00000000,0.00000000,0.00000000,0.00000000
152.06000000,3.48017700,2.37700000,0.11626356,214.75998776,0.10998700,239.72874752,0.00078447,0.11382331,243.91649851,-0.07318270,-0.04064060,0.00000000,0.00000000,0.00000000,0.00000000
153.56000000,3.51767700,2.38200000,0.11751689,215.21173363,0.11110916,240.50274702,0.00074107,0.11496561,244.50241972,-0.07391939,-0.04104622,0.00000000,0.00000000,0.00000000,0.00000000
155.06000000,3.55611600,2.38500000,0.11880389,215.48278115,0.11226016,241.08297354,0.00079366,0.11612958,245.09469688,-0.07467168,-0.04145789,0.00000000,0.00000000,0.00000000,0.00000000
156.56000000,3.59485800,2.38900000,0.12012811,215.84417785,0.11344306,241.77313123,0.00087271,0.11726442,245.78314839,-0.07542402,-0.04184040,0.00000000,0.00000000,0.00000000,0.00000000
158.06000000,3.63299600,2.39300000,0.12138511,216.20557455,0.11456463,242.44971224,0.00073177,0.11838292,246.36640252,-0.07610587,-0.04227705,0.00000000,0.00000000,0.00000000,0.00000000
159.56000000,3.67173800,2.39600000,0.12267956,216.47662207,0.11571829,243.03387786,0.00075766,0.11956772,247.06963148,-0.07686554,-0.04270218,0.00000000,0.00000000,0.00000000,0.00000000
161.06000000,3.71041300,2.40000000,0.12398144,216.83801877,0.11687724,243.72190955,0.00073700,0.12071465,247.55946764,-0.07760741,-0.04310724,0.00000000,0.00000000,0.00000000,0.00000000
162.56000000,3.74912100,2.40300000,0.12529822,217.10906629,0.11804809,244.31244633,0.00080252,0.12186848,248.15459901,-0.07831538,-0.04355310,0.00000000,0.00000000,0.00000000,0.00000000
164.06000000,3.78796400,2.40700000,0.12653656,217.47046299,0.11914793,244.98842631,0.00067554,0.12300984,248.85056731,-0.07905973,-0.04395011,0.00000000,0.00000000,0.00000000,0.00000000
165.56000000,3.82647100,2.41000000,0.12787200,217.74151051,0.12033267,245.58455295,0.00072776,0.12407920,249.42677537,-0.07967438,-0.04440482,0.00000000,0.00000000,0.00000000,0.00000000
167.06000000,3.86467600,2.41300000,0.12915522,218.01255804,0.12146976,246.17001842,0.00070704,0.12523246,250.02499358,-0.08042554,-0.04480693,0.00000000,0.00000000,0.00000000,0.00000000
168.56000000,3.90402200,2.41700000,0.13044589,218.37395474,0.12261215,246.85993937,0.00071941,0.12638903,250.52185093,-0.08114142,-0.04524761,0.00000000,0.00000000,0.00000000,0.00000000
170.06000000,3.94387200,2.42000000,0.13180000,218.64500226,0.12380929,247.46241356,0.00079791,0.12756231,251.12710961,-0.08190110,-0.04566121,0.00000000,0.00000000,0.00000000,0.00000000
171.56000000,3.98231200,2.42200000,0.13310922,218.82570061,0.12496538,247.95341942,0.00080326,0.12873428,251.73312275,-0.08263460,-0.04609968,0.00000000,0.00000000,0.00000000,0.00000000
173.06000000,4.02145700,2.42600000,0.13439989,219.18709731,0.12610378,248.64581883,0.00079588,0.12985098,252.22261355,-0.08334217,-0.04650881,0.00000000,0.00000000,0.00000000,0.00000000
174.56000000,4.06040100,2.42800000,0.13569433,219.36779566,0.12724421,249.13476244,0.00080163,0.13102012,252.82992331,-0.08408798,-0.04693214,0.00000000,0.00000000,0.00000000,0.00000000
176.06000000,4.09957900,2.43200000,0.13698500,219.72919235,0.12838002,249.82879577,0.00079427,0.13218942,253.33450131,-0.08482559,-0.04736382,0.00000000,0.00000000,0.00000000,0.00000000
177.56000000,4.13865700,2.43400000,0.13830544,219.90989070,0.12954070,250.32462587,0.00079315,0.13330721,253.93077300,-0.08551847,-0.04778874,0.00000000,0.00000000,0.00000000,0.00000000
179.06000000,4.17837200,2.43600000,0.13961478,220.09058905,0.13069029,250.81848773,0.00070719,0.13446723,254.43476140,-0.08624316,-0.04822407,0.00000000,0.00000000,0.00000000,0.00000000
180.56000000,4.21751700,2.44000000,0.14096133,220.45198575,0.13187118,251.52719160,0.00077162,0.13565179,254.94586331,-0.08701197,-0.04863982,0.00000000,0.00000000,0.00000000,0.00000000
182.06000000,4.25709900,2.44200000,0.14227444,220.63268410,0.13302140,252.02307665,0.00071858,0.13679470,255.55148710,-0.08775656,-0.04903814,0.00000000,0.00000000,0.00000000,0.00000000
183.56000000,4.29715000,2.44500000,0.14360989,220.90373162,0.13418983,252.62769198,0.00077003,0.13795714,256.05873034,-0.08848349,-0.04947365,0.00000000,0.00000000,0.00000000,0.00000000
185.06000000,4.33642900,2.44800000,0.14494900,221.17477915,0.13536009,253.23384221,0.00078855,0.13911812,256.56643554,-0.08921835,-0.04989977,0.00000000,0.00000000,0.00000000,0.00000000
186.56000000,4.37577500,2.45000000,0.14624711,221.35547749,0.13649322,253.72807661,0.00078125,0.14027782,257.07465211,-0.08994006,-0.05033777,0.00000000,0.00000000,0.00000000,0.00000000
188.06000000,4.41575900,2.45300000,0.14760122,221.62652502,0.13767387,254.33887099,0.00077374,0.14143290,257.58251368,-0.09068667,-0.05074623,0.00000000,0.00000000,0.00000000,0.00000000
189.56000000,4.45571000,2.45500000,0.14891800,221.80722337,0.13882063,254.83831146,0.00075989,0.14257875,258.19377481,-0.09138677,-0.05119197,0.00000000,0.00000000,0.00000000,0.00000000
191.06000000,4.49629800,2.45700000,0.15027578,221.98792172,0.14000172,255.34732931,0.00078489,0.14377918,258.71520434,-0.09217740,-0.05160178,0.00000000,0.00000000,0.00000000,0.00000000
192.56000000,4.53635000,2.45900000,0.15160378,222.16862006,0.14115556,255.85022217,0.00075812,0.14493162,259.11983000,-0.09289506,-0.05203656,0.00000000,0.00000000,0.00000000,0.00000000
194.06000000,4.57606500,2.46200000,0.15296522,222.43966759,0.14233708,256.46520077,0.00078306,0.14605571,259.62298553,-0.09358780,-0.05246791,0.00000000,0.00000000,0.00000000,0.00000000
195.56000000,4.61621800,2.46400000,0.15430811,222.62036594,0.14350113,256.97249410,0.00080796,0.14722001,260.13745287,-0.09434607,-0.05287394,0.00000000,0.00000000,0.00000000,0.00000000
197.06000000,4.65660500,2.46600000,0.15564356,222.80106429,0.14465738,257.47861411,0.00076182,0.14836697,260.64823307,-0.09506417,-0.05330280,0.00000000,0.00000000,0.00000000,0.00000000
198.56000000,4.69685700,2.46800000,0.15700889,222.98176264,0.14583813,257.99188143,0.00078686,0.14954440,261.16783882,-0.09581294,-0.05373146,0.00000000,0.00000000,0.00000000,0.00000000
200.06000000,4.73734500,2.47000000,0.15839278,223.16246098,0.14703351,258.50978308,0.00081163,0.15065677,261.67122451,-0.09649757,-0.05415920,0.00000000,0.00000000,0.00000000,0.00000000
201.56000000,4.77840400,2.47200000,0.15970578,223.34315933,0.14816633,259.01235231,0.00073979,0.15183156,262.19183926,-0.09722031,-0.05461125,0.00000000,0.00000000,0.00000000,0.00000000
203.06000000,4.81912600,2.47400000,0.16106367,223.52385768,0.14933654,259.52542979,0.00076477,0.15300643,262.60727585,-0.09795808,-0.05504836,0.00000000,0.00000000,0.00000000,0.00000000
204.56000000,4.85961400,2.47600000,0.16241400,223.70455603,0.15049888,260.03730779,0.00072544,0.15417833,263.12873855,-0.09871621,-0.05546212,0.00000000,0.00000000,0.00000000,0.00000000
206.06000000,4.90037100,2.47800000,0.16375689,223.88525438,0.15165347,260.54800711,0.00083349,0.15535041,263.54479863,-0.09943363,-0.05591678,0.00000000,0.00000000,0.00000000,0.00000000
207.56000000,4.94109300,2.47900000,0.16509978,223.97560355,0.15280673,260.95392593,0.00076861,0.15655270,263.96947862,-0.10022099,-0.05633171,0.00000000,0.00000000,0.00000000,0.00000000
209.06000000,4.98178300,2.48100000,0.16644267,224.15630190,0.15395866,261.46547454,0.00070369,0.15772048,264.49222001,-0.10094303,-0.05677744,0.00000000,0.00000000,0.00000000,0.00000000
210.56000000,5.02280800,2.48300000,0.16782278,224.33700025,0.15514114,261.98585879,0.00076663,0.15882374,264.99866728,-0.10163350,-0.05719023,0.00000000,0.00000000,0.00000000,0.00000000
212.06000000,5.06359800,2.48500000,0.16920300,224.51769860,0.15632232,262.50676676,0.00076591,0.15999022,265.41594598,-0.10238225,-0.05760797,0.00000000,0.00000000,0.00000000,0.00000000
213.56000000,5.10505900,2.48600000,0.17058322,224.60804778,0.15750211,262.92241230,0.00076501,0.16112398,265.82510843,-0.10308662,-0.05803736,0.00000000,0.00000000,0.00000000,0.00000000
215.06000000,5.14608400,2.48800000,0.17196333,224.78874612,0.15868041,263.44416820,0.00076392,0.16222334,266.33273049,-0.10378989,-0.05843345,0.00000000,0.00000000,0.00000000,0.00000000
216.56000000,5.18788100,2.48900000,0.17338089,224.87909530,0.15988923,263.86883273,0.00082684,0.16335444,266.74247117,-0.10449278,-0.05886166,0.00000000,0.00000000,0.00000000,0.00000000
218.06000000,5.22840300,2.49100000,0.17468644,225.05979365,0.16100126,264.37468879,0.00076233,0.16451417,267.26779084,-0.10526928,-0.05924489,0.00000000,0.00000000,0.00000000,0.00000000
219.56000000,5.26946100,2.49300000,0.17610389,225.24049200,0.16220719,264.90621857,0.00076123,0.16570535,267.69498836,-0.10601946,-0.05968589,0.00000000,0.00000000,0.00000000,0.00000000
221.06000000,5.31166100,2.49400000,0.17744689,225.33084117,0.16334844,265.31509791,0.00076055,0.16695780,268.13932069,-0.10681555,-0.06014224,0.00000000,0.00000000,0.00000000,0.00000000
222.56000000,5.35413000,2.49500000,0.17875244,225.42119035,0.16445663,265.71577915,0.00069634,0.16820706,268.69120230,-0.10758062,-0.06062644,0.00000000,0.00000000,0.00000000,0.00000000
224.06000000,5.39572600,2.49600000,0.18009533,225.51153952,0.16559523,266.12511540,0.00075865,0.16955007,269.16153188,-0.10846318,-0.06108689,0.00000000,0.00000000,0.00000000,0.00000000
225.56000000,5.43799300,2.49800000,0.18143822,225.69223787,0.16673253,266.64143628,0.00082101,0.17098636,269.54987989,-0.10937134,-0.06161502,0.00000000,0.00000000,0.00000000,0.00000000
227.06000000,5.47985700,2.50000000,0.18278111,225.87293622,0.16786854,267.15824247,0.00075693,0.17238789,270.03753484,-0.11023094,-0.06215694,0.00000000,0.00000000,0.00000000,0.00000000
228.56000000,5.52212400,2.50100000,0.18416133,225.96328539,0.16903479,267.57698532,0.00075605,0.17381704,270.64186073,-0.11110184,-0.06271520,0.00000000,0.00000000,0.00000000,0.00000000
230.06000000,5.56439200,2.50200000,0.18565344,226.05363457,0.17029405,268.02127045,0.00088110,0.17524574,271.13876547,-0.11195227,-0.06329347,0.00000000,0.00000000,0.00000000,0.00000000
231.56000000,5.60672600,2.50300000,0.18714544,226.14398374,0.17155164,268.46580009,0.00087999,0.17661170,271.51080770,-0.11279537,-0.06381633,0.00000000,0.00000000,0.00000000,0.00000000
233.06000000,5.64976500,2.50400000,0.18878667,226.23433292,0.17293318,268.94435851,0.00100426,0.17788295,271.85751146,-0.11356780,-0.06431514,0.00000000,0.00000000,0.00000000,0.00000000
234.56000000,5.69317400,2.50500000,0.19039067,226.32468209,0.17428154,269.41478920,0.00087759,0.17902724,272.27886626,-0.11428080,-0.06474644,0.00000000,0.00000000,0.00000000,0.00000000
236.06000000,5.73705200,2.50600000,0.19206922,226.41503127,0.17569064,269.90239022,0.00093883,0.18001559,272.65814721,-0.11489577,-0.06511982,0.00000000,0.00000000,0.00000000,0.00000000
237.56000000,5.78039400,2.50700000,0.19382244,226.50538044,0.17716030,270.40720696,0.00093745,0.18084702,273.10400543,-0.11537822,-0.06546880,0.00000000,0.00000000,0.00000000,0.00000000
239.06000000,5.82504400,2.50800000,0.19550111,226.59572961,0.17856544,270.89544653,0.00093632,0.18170999,273.44988952,-0.11591693,-0.06579305,0.00000000,0.00000000,0.00000000,0.00000000
240.56000000,5.86989600,2.50900000,0.19721700,226.68607879,0.17999970,271.39242719,0.00093498,0.18247825,273.87941835,-0.11638963,-0.06608862,0.00000000,0.00000000,0.00000000,0.00000000
242.06000000,5.91545400,2.50900000,0.19878378,226.68607879,0.18130752,271.74759390,0.00087163,0.18327820,274.20880952,-0.11691593,-0.06636228,0.00000000,0.00000000,0.00000000,0.00000000
243.56000000,5.96121200,2.51000000,0.20023856,226.77642796,0.18252033,272.18581233,0.00080834,0.18404840,274.42090619,-0.11739199,-0.06665641,0.00000000,0.00000000,0.00000000,0.00000000
245.06000000,6.00700500,2.51000000,0.20146956,226.77642796,0.18354544,272.46497412,0.00074534,0.18481484,274.85120007,-0.11786213,-0.06695271,0.00000000,0.00000000,0.00000000,0.00000000
246.56000000,6.05125200,2.51200000,0.20255133,226.95712631,0.18444541,272.92759486,0.00062044,0.18567298,275.30734124,-0.11842162,-0.06725136,0.00000000,0.00000000,0.00000000,0.00000000
248.06000000,6.09268000,2.51400000,0.20355844,227.13782466,0.18528254,273.37364692,0.00055787,0.00000000,0.00000000,0.00000000,0.00000000,0.00000000,0.00000000,0.00000000,0.00000000
249.56000000,6.12793100,2.51500000,0.20452822,227.22817384,0.18608797,273.70274827,0.00055742,0.00000000,0.00000000,0.00000000,0.00000000,0.00000000,0.00000000,0.00000000,0.00000000
251.06000000,6.15999200,2.51700000,0.20546078,227.40887219,0.18686188,274.13247594,0.00049522,0.00000000,0.00000000,0.00000000,0.00000000,0.00000000,0.00000000,0.00000000,0.00000000
252.56000000,6.18953500,2.51700000,0.20643067,227.40887219,0.18766614,274.35303728,0.00049482,0.00000000,0.00000000,0.00000000,0.00000000,0.00000000,0.00000000,0.00000000,0.00000000
254.06000000,6.21730000,2.51900000,0.20736322,227.58957053,0.18843883,274.78327722,0.00055611,0.00000000,0.00000000,0.00000000,0.00000000,0.00000000,0.00000000,0.00000000,0.00000000
255.56000000,6.24677600,2.52100000,0.20833322,227.77026888,0.18924191,275.22238293,0.00055585,0.00000000,0.00000000,0.00000000,0.00000000,0.00000000,0.00000000,0.00000000,0.00000000
257.06000000,6.27897200,2.52200000,0.20941500,227.86061806,0.00000000,0.00000000,0.00000000,0.00000000,0.00000000,0.00000000,0.00000000,0.00000000,0.00000000,0.00000000,0.00000000
258.56000000,6.31885600,2.52000000,0.21064600,227.67991971,0.00000000,0.00000000,0.00000000,0.00000000,0.00000000,0.00000000,0.00000000,0.00000000,0.00000000,0.00000000,0.00000000
260.06000000,6.36515300,2.51600000,0.21169044,227.31852301,0.00000000,0.00000000,0.00000000,0.00000000,0.00000000,0.00000000,0.00000000,0.00000000,0.00000000,0.00000000,0.00000000
261.56000000,6.41232200,2.51800000,0.21269756,227.49922136,0.00000000,0.00000000,0.00000000,0.00000000,0.00000000,0.00000000,0.00000000,0.00000000,0.00000000,0.00000000,0.00000000
263.06000000,6.45788000,2.51500000,0.21348111,227.22817384,0.00000000,0.00000000,0.00000000,0.00000000,0.00000000,0.00000000,0.00000000,0.00000000,0.00000000,0.00000000,0.00000000
264.56000000,6.50243000,2.51600000,0.21419033,227.31852301,0.00000000,0.00000000,0.00000000,0.00000000,0.00000000,0.00000000,0.00000000,0.00000000,0.00000000,0.00000000,0.00000000
266.06000000,6.54369000,2.51700000,0.21478733,227.40887219,0.00000000,0.00000000,0.00000000,0.00000000,0.00000000,0.00000000,0.00000000,0.00000000,0.00000000,0.00000000,0.00000000
267.56000000,6.58145700,2.51800000,0.21534667,227.49922136,0.00000000,0.00000000,0.00000000,0.00000000,0.00000000,0.00000000,0.00000000,0.00000000,0.00000000,0.00000000,0.00000000
269.06000000,6.61865400,2.52000000,0.21590600,227.67991971,0.00000000,0.00000000,0.00000000,0.00000000,0.00000000,0.00000000,0.00000000,0.00000000,0.00000000,0.00000000,0.00000000
270.56000000,6.65689100,2.52000000,0.21642789,227.67991971,0.00000000,0.00000000,0.00000000,0.00000000,0.00000000,0.00000000,0.00000000,0.00000000,0.00000000,0.00000000,0.00000000
272.06000000,6.69704400,2.52000000,0.21687544,227.67991971,0.00000000,0.00000000,0.00000000,0.00000000,0.00000000,0.00000000,0.00000000,0.00000000,0.00000000,0.00000000,0.00000000
273.56000000,6.73961400,2.51800000,0.21732289,227.49922136,0.00000000,0.00000000,0.00000000,0.00000000,0.00000000,0.00000000,0.00000000,0.00000000,0.00000000,0.00000000,0.00000000
275.06000000,6.78577700,2.51900000,0.21765856,227.58957053,0.00000000,0.00000000,0.00000000,0.00000000,0.00000000,0.00000000,0.00000000,0.00000000,0.00000000,0.00000000,0.00000000
276.56000000,6.83439100,2.52000000,0.21806889,227.67991971,0.00000000,0.00000000,0.00000000,0.00000000,0.00000000,0.00000000,0.00000000,0.00000000,0.00000000,0.00000000,0.00000000
278.06000000,6.88186400,2.52000000,0.21840456,227.67991971,0.00000000,0.00000000,0.00000000,0.00000000,0.00000000,0.00000000,0.00000000,0.00000000,0.00000000,0.00000000,0.00000000
279.56000000,6.92577700,2.51700000,0.21874033,227.40887219,0.00000000,0.00000000,0.00000000,0.00000000,0.00000000,0.00000000,0.00000000,0.00000000,0.00000000,0.00000000,0.00000000
281.06000000,6.96804500,2.51600000,0.21900144,227.31852301,0.00000000,0.00000000,0.00000000,0.00000000,0.00000000,0.00000000,0.00000000,0.00000000,0.00000000,0.00000000,0.00000000
282.56000000,7.01152100,2.51500000,0.21918789,227.22817384,0.00000000,0.00000000,0.00000000,0.00000000,0.00000000,0.00000000,0.00000000,0.00000000,0.00000000,0.00000000,0.00000000
284.06000000,7.05949400,2.51200000,0.21948633,226.95712631,0.00000000,0.00000000,0.00000000,0.00000000,0.00000000,0.00000000,0.00000000,0.00000000,0.00000000,0.00000000,0.00000000
285.56000000,7.11284100,2.50900000,0.21963556,226.68607879,0.00000000,0.00000000,0.00000000,0.00000000,0.00000000,0.00000000,0.00000000,0.00000000,0.00000000,0.00000000,0.00000000
287.06000000,7.16672600,2.50600000,0.21978478,226.41503127,0.00000000,0.00000000,0.00000000,0.00000000,0.00000000,0.00000000,0.00000000,0.00000000,0.00000000,0.00000000,0.00000000
288.56000000,7.22182100,2.50100000,0.21993389,225.96328539,0.00000000,0.00000000,0.00000000,0.00000000,0.00000000,0.00000000,0.00000000,0.00000000,0.00000000,0.00000000,0.00000000
290.06000000,7.27584000,2.49400000,0.22004578,225.33084117,0.00000000,0.00000000,0.00000000,0.00000000,0.00000000,0.00000000,0.00000000,0.00000000,0.00000000,0.00000000,0.00000000
291.56000000,7.33063400,2.48600000,0.22008311,224.60804778,0.00000000,0.00000000,0.00000000,0.00000000,0.00000000,0.00000000,0.00000000,0.00000000,0.00000000,0.00000000,0.00000000
293.06000000,7.38801900,2.47400000,0.22012044,223.52385768,0.00000000,0.00000000,0.00000000,0.00000000,0.00000000,0.00000000,0.00000000,0.00000000,0.00000000,0.00000000,0.00000000
294.56000000,7.44712000,2.45700000,0.22012056,221.98792172,0.00000000,0.00000000,0.00000000,0.00000000,0.00000000,0.00000000,0.00000000,0.00000000,0.00000000,0.00000000,0.00000000
296.06000000,7.50918500,2.43100000,0.22012100,219.63884318,0.00000000,0.00000000,0.00000000,0.00000000,0.00000000,0.00000000,0.00000000,0.00000000,0.00000000,0.00000000,0.00000000
297.56000000,7.57415100,2.39000000,0.22000978,215.93452703,0.00000000,0.00000000,0.00000000,0.00000000,0.00000000,0.00000000,0.00000000,0.00000000,0.00000000,0.00000000,0.00000000
299.06000000,7.64161700,2.32400000,0.21993611,209.97148151,0.00000000,0.00000000,0.00000000,0.00000000,0.00000000,0.00000000,0.00000000,0.00000000,0.00000000,0.00000000,0.00000000
300.56000000,7.71233300,2.23100000,0.21967611,201.56900828,0.00000000,0.00000000,0.00000000,0.00000000,0.00000000,0.00000000,0.00000000,0.00000000,0.00000000,0.00000000,0.00000000
302.06000000,8.07185000,0.06400000,0.17715633,5.78234717,0.00000000,0.00000000,0.00000000,0.00000000,0.00000000,0.00000000,0.00000000,0.00000000,0.00000000,0.00000000,0.00000000
NaN,-100.00000000,NaN,-11.11111111,NaN,0.00000000,0.00000000,0.00000000,0.00000000,0.00000000,0.00000000,0.00000000,0.00000000,0.00000000,0.00000000,0.00000000