File: polyN_optimization/results_exp/AA6014-T4/UT_75_1.csv
Time[s],Displacement[mm],Force[kN],EngStrain_longi,EngStress[MPa],TrueStrain,TrueStress[MPa],TrueStrainRate[1/s],PlasticStrain_longi,PlasticStress[MPa],PlasticStrain_thick,PlasticStrain_width,R-Value,Thickness[mm],Width[mm], Young's Modulus [MPa]
0.57000000,0.00000000,-0.00200000,0.00000000,-0.18079400,0.00000000,-0.18079400,0.00000000,0.00097347,116.28259724,-0.00028129,-0.00069218,0.67980449,1.11540000,9.91780000,76223.25745379
2.07000000,0.00601300,0.15100000,0.00020478,13.64994687,0.00020476,13.65274208,0.00018664,0.00224587,119.52155893,-0.00101691,-0.00122896,0.00000000,0.00000000,0.00000000,0.00000000
3.57000000,0.01398000,0.40900000,0.00043867,36.97237265,0.00043857,36.98859120,0.00007775,0.00348470,122.67372227,-0.00180646,-0.00167824,0.00000000,0.00000000,0.00000000,0.00000000
5.07000000,0.02306400,0.64700000,0.00077856,58.48685844,0.00077825,58.53239371,0.00030046,0.00464992,125.55109642,-0.00247846,-0.00217147,0.00000000,0.00000000,0.00000000,0.00000000
6.57000000,0.03185700,0.90900000,0.00106278,82.17087222,0.00106221,82.25820160,0.00036009,0.00578923,128.34066231,-0.00313413,-0.00265510,0.00000000,0.00000000,0.00000000,0.00000000
8.07000000,0.04328200,1.13600000,0.00135378,102.69099102,0.00135286,102.83001181,0.00028319,0.00695797,130.86641586,-0.00379121,-0.00316675,0.00000000,0.00000000,0.00000000,0.00000000
9.57000000,0.06888700,1.27300000,0.00210544,115.07537991,0.00210323,115.31766473,0.00051676,0.00817671,133.22180113,-0.00453273,-0.00364399,0.00000000,0.00000000,0.00000000,0.00000000
11.07000000,0.10915600,1.30500000,0.00348489,117.96808388,0.00347883,118.37918954,0.00084546,0.00932443,135.66483831,-0.00517726,-0.00414717,0.00000000,0.00000000,0.00000000,0.00000000
12.57000000,0.14615600,1.34000000,0.00479422,121.13197885,0.00478277,121.71271247,0.00095211,0.01042230,137.83148132,-0.00580010,-0.00462220,0.00000000,0.00000000,0.00000000,0.00000000
14.07000000,0.18320300,1.37100000,0.00596589,123.93428582,0.00594816,124.67366400,0.00088580,0.01159202,140.01293313,-0.00648871,-0.00510331,0.00000000,0.00000000,0.00000000,0.00000000
15.57000000,0.22087100,1.40100000,0.00721067,126.64619580,0.00718479,127.55939930,0.00084100,0.01276013,142.19920641,-0.00721159,-0.00554854,0.00000000,0.00000000,0.00000000,0.00000000
17.07000000,0.25719600,1.42800000,0.00850356,129.08691477,0.00846760,130.18461252,0.00098564,0.01388415,144.29212166,-0.00789244,-0.00599171,0.00000000,0.00000000,0.00000000,0.00000000
18.57000000,0.29478900,1.45200000,0.00973444,131.25644275,0.00968737,132.53415130,0.00100492,0.01501898,146.29912892,-0.00858785,-0.00643113,0.00000000,0.00000000,0.00000000,0.00000000
20.07000000,0.33131200,1.47700000,0.01090167,133.51636773,0.01084267,134.97191867,0.00087092,0.01619627,148.31693271,-0.00933274,-0.00686354,0.00000000,0.00000000,0.00000000,0.00000000
21.57000000,0.36771100,1.50000000,0.01211589,135.59549871,0.01204308,137.23835871,0.00073655,0.01734051,150.24205361,-0.01001527,-0.00732524,0.00000000,0.00000000,0.00000000,0.00000000
23.07000000,0.40375400,1.52100000,0.01333189,137.49383569,0.01324380,139.32688823,0.00083943,0.01845182,152.07399500,-0.01070109,-0.00775073,0.00000000,0.00000000,0.00000000,0.00000000
24.57000000,0.43973000,1.54400000,0.01449944,139.57296667,0.01439533,141.59669715,0.00080910,0.01957014,154.09616941,-0.01140089,-0.00816925,0.00000000,0.00000000,0.00000000,0.00000000
26.07000000,0.47498700,1.56400000,0.01564467,141.38090666,0.01552355,143.59276381,0.00069065,0.02070909,155.84793653,-0.01208433,-0.00862476,0.00000000,0.00000000,0.00000000,0.00000000
27.57000000,0.51076400,1.58400000,0.01686444,143.18884664,0.01672382,145.60364699,0.00068982,0.02182131,157.59936053,-0.01274632,-0.00907499,0.00000000,0.00000000,0.00000000,0.00000000
29.07000000,0.54630400,1.60500000,0.01803200,145.08718362,0.01787135,147.70339572,0.00069645,0.02291498,159.53743171,-0.01338997,-0.00952501,0.00000000,0.00000000,0.00000000,0.00000000
30.57000000,0.58196700,1.62400000,0.01924056,146.80472660,0.01905780,149.62933110,0.00071744,0.02404755,161.20689863,-0.01407173,-0.00997581,0.00000000,0.00000000,0.00000000,0.00000000
32.07000000,0.61790900,1.64300000,0.02040067,148.52226959,0.02019536,151.55222290,0.00070203,0.02511714,162.86974317,-0.01467770,-0.01043945,0.00000000,0.00000000,0.00000000,0.00000000
33.57000000,0.65233700,1.66200000,0.02156444,150.23981257,0.02133522,153.47965066,0.00069383,0.02623718,164.73082207,-0.01533322,-0.01090395,0.00000000,0.00000000,0.00000000,0.00000000
35.07000000,0.68765800,1.68000000,0.02275067,151.86695856,0.02249573,155.32203311,0.00075149,0.02731997,166.30973291,-0.01598990,-0.01133007,0.00000000,0.00000000,0.00000000,0.00000000
36.57000000,0.72304300,1.69700000,0.02388844,153.40370754,0.02360758,157.06828349,0.00070702,0.02840515,167.89234404,-0.01661132,-0.01179382,0.00000000,0.00000000,0.00000000,0.00000000
38.07000000,0.75789100,1.71600000,0.02507089,155.12125053,0.02476177,159.01027816,0.00069883,0.02948774,169.57137558,-0.01726303,-0.01222471,0.00000000,0.00000000,0.00000000,0.00000000
39.57000000,0.79310800,1.73200000,0.02624967,156.56760251,0.02591106,160.67744989,0.00077081,0.03058840,171.16337222,-0.01790699,-0.01268142,0.00000000,0.00000000,0.00000000,0.00000000
41.07000000,0.82802300,1.74900000,0.02740978,158.10435150,0.02704086,162.43795664,0.00079893,0.03169261,172.66559218,-0.01857515,-0.01311746,0.00000000,0.00000000,0.00000000,0.00000000
42.57000000,0.86293800,1.76600000,0.02857356,159.64110048,0.02817294,164.20261434,0.00076907,0.03280511,174.26630459,-0.01921613,-0.01358898,0.00000000,0.00000000,0.00000000,0.00000000
44.07000000,0.89785300,1.78100000,0.02973744,160.99705547,0.02930386,165.78469646,0.00073927,0.03387442,175.76884793,-0.01989274,-0.01398167,0.00000000,0.00000000,0.00000000,0.00000000
45.57000000,0.93253200,1.79600000,0.03086389,162.35301046,0.03039718,167.36385573,0.00071646,0.03495813,177.18294752,-0.02053546,-0.01442266,0.00000000,0.00000000,0.00000000,0.00000000
47.07000000,0.96684300,1.81300000,0.03200167,163.88975944,0.03150028,169.13450489,0.00068702,0.03607739,178.79471149,-0.02122247,-0.01485492,0.00000000,0.00000000,0.00000000,0.00000000
48.57000000,1.00155600,1.82700000,0.03321022,165.15531743,0.03267068,170.64016222,0.00078713,0.03716227,180.21512274,-0.02187220,-0.01529007,0.00000000,0.00000000,0.00000000,0.00000000
50.07000000,1.03637000,1.84200000,0.03432556,166.51127242,0.03374958,172.22686435,0.00072137,0.03821137,181.53754662,-0.02248155,-0.01572982,0.00000000,0.00000000,0.00000000,0.00000000
51.57000000,1.07125100,1.85600000,0.03546700,167.77683041,0.03485253,173.72737125,0.00068451,0.03933517,183.06531467,-0.02317935,-0.01615582,0.00000000,0.00000000,0.00000000,0.00000000
53.07000000,1.10623300,1.87100000,0.03666067,169.13278539,0.03600465,175.33330606,0.00073412,0.04042823,184.40142834,-0.02382125,-0.01660698,0.00000000,0.00000000,0.00000000,0.00000000
54.57000000,1.14064500,1.88400000,0.03780956,170.30794638,0.03711230,176.74721414,0.00079799,0.04150570,185.73739309,-0.02446726,-0.01703844,0.00000000,0.00000000,0.00000000,0.00000000
56.07000000,1.17542500,1.89900000,0.03895100,171.66390137,0.03821155,178.35038199,0.00081873,0.04256424,187.07252437,-0.02508464,-0.01747961,0.00000000,0.00000000,0.00000000,0.00000000
57.57000000,1.21044100,1.91100000,0.04009989,172.74866536,0.03931676,179.67586764,0.00071737,0.04363937,188.41345768,-0.02572330,-0.01791607,0.00000000,0.00000000,0.00000000,0.00000000
59.07000000,1.24498600,1.92400000,0.04123767,173.92382635,0.04041007,181.09603912,0.00067367,0.04475360,189.66950820,-0.02636365,-0.01838995,0.00000000,0.00000000,0.00000000,0.00000000
60.57000000,1.27973300,1.93700000,0.04242389,175.09898734,0.04154866,182.52736732,0.00078039,0.04583319,191.01668609,-0.02699053,-0.01884266,0.00000000,0.00000000,0.00000000,0.00000000
62.07000000,1.31461400,1.95000000,0.04357644,176.27414832,0.04265370,183.95554896,0.00081510,0.04689886,192.26866495,-0.02762755,-0.01927131,0.00000000,0.00000000,0.00000000,0.00000000
63.57000000,1.34973000,1.96200000,0.04471422,177.35891231,0.04374338,185.28937813,0.00071420,0.04803400,193.53662163,-0.02833505,-0.01969894,0.00000000,0.00000000,0.00000000,0.00000000
65.07000000,1.38444400,1.97500000,0.04589300,178.53407330,0.04487107,186.72753753,0.00072062,0.04910770,194.79525513,-0.02895309,-0.02015460,0.00000000,0.00000000,0.00000000,0.00000000
66.57000000,1.41929200,1.98700000,0.04706056,179.61883729,0.04598677,188.07179956,0.00077693,0.05018510,195.96156388,-0.02959008,-0.02059502,0.00000000,0.00000000,0.00000000,0.00000000
68.07000000,1.45383700,1.99800000,0.04818700,180.61320428,0.04706201,189.31641276,0.00074746,0.05126473,197.13064137,-0.03020561,-0.02105912,0.00000000,0.00000000,0.00000000,0.00000000
69.57000000,1.48905400,2.01000000,0.04932100,181.69796827,0.04814329,190.65949377,0.00066128,0.05236644,198.40223303,-0.03087516,-0.02149127,0.00000000,0.00000000,0.00000000,0.00000000
71.07000000,1.52413700,2.02100000,0.05050344,182.69233526,0.04926952,191.91892747,0.00068169,0.05344715,199.57633253,-0.03154093,-0.02190622,0.00000000,0.00000000,0.00000000,0.00000000
72.57000000,1.55908500,2.03100000,0.05167478,183.59630525,0.05038392,193.08360353,0.00073780,0.05454200,200.65961726,-0.03220385,-0.02233814,0.00000000,0.00000000,0.00000000,0.00000000
74.07000000,1.59433600,2.04300000,0.05281622,184.68106924,0.05146869,194.43522564,0.00070870,0.05563434,201.84067581,-0.03285498,-0.02277936,0.00000000,0.00000000,0.00000000,0.00000000
75.57000000,1.62898200,2.05300000,0.05398378,185.58503924,0.05257706,195.60362075,0.00070792,0.05672532,203.02383764,-0.03351753,-0.02320779,0.00000000,0.00000000,0.00000000,0.00000000
77.07000000,1.66406500,2.06300000,0.05513267,186.48900923,0.05366651,196.77064561,0.00068587,0.05781995,204.11379627,-0.03416796,-0.02365199,0.00000000,0.00000000,0.00000000,0.00000000
78.57000000,1.69938300,2.07400000,0.05631522,187.48337622,0.05478665,198.04154421,0.00072761,0.05890623,205.20421542,-0.03483309,-0.02407314,0.00000000,0.00000000,0.00000000,0.00000000
80.07000000,1.73439900,2.08400000,0.05744544,188.38734621,0.05585604,199.20934104,0.00070560,0.05998087,206.29438788,-0.03543704,-0.02454384,0.00000000,0.00000000,0.00000000,0.00000000
81.57000000,1.76998500,2.09300000,0.05863544,189.20091920,0.05698076,200.29479919,0.00071194,0.06106615,207.29226093,-0.03609111,-0.02497504,0.00000000,0.00000000,0.00000000,0.00000000
83.07000000,1.80543700,2.10300000,0.05982533,190.10488919,0.05810411,201.47797756,0.00073925,0.06216971,208.39266495,-0.03672622,-0.02544350,0.00000000,0.00000000,0.00000000,0.00000000
84.57000000,1.84075500,2.11300000,0.06100033,191.00885918,0.05921217,202.66046326,0.00075247,0.06326993,209.39770666,-0.03741712,-0.02585281,0.00000000,0.00000000,0.00000000,0.00000000
86.07000000,1.87667800,2.12200000,0.06219033,191.82243218,0.06033313,203.75193317,0.00077277,0.06437230,210.40519078,-0.03806936,-0.02630293,0.00000000,0.00000000,0.00000000,0.00000000
87.57000000,1.91213000,2.13100000,0.06334300,192.63600517,0.06141772,204.83814764,0.00075102,0.06544772,211.50604543,-0.03869569,-0.02675203,0.00000000,0.00000000,0.00000000,0.00000000
89.07000000,1.94785100,2.14000000,0.06451422,193.44957816,0.06251857,205.92982724,0.00073600,0.06656494,212.52077198,-0.03937578,-0.02718916,0.00000000,0.00000000,0.00000000,0.00000000
90.57000000,1.98316900,2.14900000,0.06570422,194.26315115,0.06363582,207.02706041,0.00078419,0.06765446,213.43428960,-0.04000749,-0.02764697,0.00000000,0.00000000,0.00000000,0.00000000
92.07000000,2.01885600,2.15800000,0.06687544,195.07672415,0.06473423,208.12256677,0.00080417,0.06876220,214.45090599,-0.04067096,-0.02809124,0.00000000,0.00000000,0.00000000,0.00000000
93.57000000,2.05481200,2.16600000,0.06805422,195.79990014,0.06583851,209.12491005,0.00074042,0.06983745,215.46252096,-0.04131156,-0.02852589,0.00000000,0.00000000,0.00000000,0.00000000
95.07000000,2.09107000,2.17400000,0.06923678,196.52307613,0.06694510,210.12970068,0.00072588,0.07091986,216.38001200,-0.04194220,-0.02897767,0.00000000,0.00000000,0.00000000,0.00000000
96.57000000,2.12682400,2.18200000,0.07043789,197.24625213,0.06806781,211.13986172,0.00073192,0.07204247,217.30802138,-0.04262742,-0.02941505,0.00000000,0.00000000,0.00000000,0.00000000
98.07000000,2.16301500,2.19000000,0.07162411,197.96942812,0.06917536,212.14881243,0.00075912,0.07311891,218.22776044,-0.04326406,-0.02985484,0.00000000,0.00000000,0.00000000,0.00000000
99.57000000,2.19813000,2.19800000,0.07275800,198.69260411,0.07023290,213.14908060,0.00070236,0.07422510,219.15579330,-0.04392514,-0.03029996,0.00000000,0.00000000,0.00000000,0.00000000
101.07000000,2.23563000,2.20600000,0.07401511,199.41578010,0.07140407,214.17556123,0.00075722,0.07531292,220.08157990,-0.04457005,-0.03074287,0.00000000,0.00000000,0.00000000,0.00000000
102.57000000,2.27172100,2.21300000,0.07520133,200.04855910,0.07250793,215.09247747,0.00072868,0.07642693,221.01495065,-0.04524556,-0.03118137,0.00000000,0.00000000,0.00000000,0.00000000
104.07000000,2.30791100,2.22100000,0.07639878,200.77173509,0.07362100,216.11045026,0.00076959,0.07752722,221.84880411,-0.04589821,-0.03162901,0.00000000,0.00000000,0.00000000,0.00000000
105.57000000,2.34423600,2.22800000,0.07757000,201.40451409,0.07470851,217.02746224,0.00071305,0.07862162,222.78133321,-0.04655257,-0.03206905,0.00000000,0.00000000,0.00000000,0.00000000
107.07000000,2.38082900,2.23500000,0.07878611,202.03729308,0.07583644,217.95502570,0.00074006,0.07971259,223.61637512,-0.04719354,-0.03251905,0.00000000,0.00000000,0.00000000,0.00000000
108.57000000,2.41715400,2.24200000,0.07997600,202.67007207,0.07693882,218.87881376,0.00071167,0.08082635,224.45812751,-0.04784449,-0.03298187,0.00000000,0.00000000,0.00000000,0.00000000
110.07000000,2.45351300,2.24900000,0.08118467,203.30285107,0.07805735,219.80792526,0.00072465,0.08190466,225.29348220,-0.04847790,-0.03342676,0.00000000,0.00000000,0.00000000,0.00000000
111.57000000,2.49000600,2.25600000,0.08237833,203.93563006,0.07916078,220.73550737,0.00075157,0.08301580,226.13784583,-0.04914306,-0.03387273,0.00000000,0.00000000,0.00000000,0.00000000
113.07000000,2.52683400,2.26200000,0.08359067,204.47801206,0.08028022,221.57046540,0.00075073,0.08409845,226.97734272,-0.04978401,-0.03431444,0.00000000,0.00000000,0.00000000,0.00000000
114.57000000,2.56332700,2.26900000,0.08476567,205.11079105,0.08136399,222.49714399,0.00068782,0.08520038,227.82281516,-0.05043599,-0.03476439,0.00000000,0.00000000,0.00000000,0.00000000
116.07000000,2.60015500,2.27500000,0.08598544,205.65317305,0.08248782,223.33635253,0.00071469,0.08629416,228.66802701,-0.05107478,-0.03521938,0.00000000,0.00000000,0.00000000,0.00000000
117.57000000,2.63715100,2.28100000,0.08717167,206.19555504,0.08357952,224.16996523,0.00069325,0.08739831,229.41793002,-0.05172410,-0.03567421,0.00000000,0.00000000,0.00000000,0.00000000
119.07000000,2.67351000,2.28700000,0.08839144,206.73793703,0.08470087,225.01180191,0.00070616,0.08853709,230.27663169,-0.05240626,-0.03613083,0.00000000,0.00000000,0.00000000,0.00000000
120.57000000,2.71097600,2.29300000,0.08962611,207.28031903,0.08583462,225.85804793,0.00073270,0.08959468,231.01866955,-0.05303602,-0.03655866,0.00000000,0.00000000,0.00000000,0.00000000
122.07000000,2.74743500,2.29900000,0.09081233,207.82270102,0.08692268,226.69556542,0.00073883,0.09069508,231.77198738,-0.05366539,-0.03702968,0.00000000,0.00000000,0.00000000,0.00000000
123.57000000,2.78453200,2.30500000,0.09201344,208.36508302,0.08802319,227.53747201,0.00073110,0.09181114,232.53035472,-0.05434361,-0.03746753,0.00000000,0.00000000,0.00000000,0.00000000
125.07000000,2.82126000,2.31100000,0.09322578,208.90746501,0.08913275,228.38302592,0.00071666,0.09290902,233.28588628,-0.05499153,-0.03791749,0.00000000,0.00000000,0.00000000,0.00000000
126.57000000,2.85919600,2.31600000,0.09447167,209.35945001,0.09027175,229.13798618,0.00079080,0.09401581,234.04490344,-0.05565129,-0.03836452,0.00000000,0.00000000,0.00000000,0.00000000
128.07000000,2.89629300,2.32100000,0.09567656,209.81143501,0.09137203,229.88547042,0.00073555,0.09515836,234.81375796,-0.05635591,-0.03880245,0.00000000,0.00000000,0.00000000,0.00000000
129.57000000,2.93372600,2.32700000,0.09691122,210.35381700,0.09249825,230.73946251,0.00075499,0.09624715,235.47117807,-0.05698431,-0.03926284,0.00000000,0.00000000,0.00000000,0.00000000
131.07000000,2.97085600,2.33200000,0.09812356,210.80580200,0.09360286,231.49081682,0.00076104,0.09734333,236.23181848,-0.05763262,-0.03971071,0.00000000,0.00000000,0.00000000,0.00000000
132.57000000,3.00791900,2.33800000,0.09934700,211.34818399,0.09471637,232.34499203,0.00077374,0.09845317,236.89669264,-0.05827972,-0.04017346,0.00000000,0.00000000,0.00000000,0.00000000
134.07000000,3.04582200,2.34300000,0.10056689,211.80016899,0.09582540,233.10025305,0.00072562,0.09954356,237.65865493,-0.05893087,-0.04061269,0.00000000,0.00000000,0.00000000,0.00000000
135.57000000,3.08322100,2.34700000,0.10180156,212.16175698,0.09694662,233.76015387,0.00073812,0.10065090,238.32542553,-0.05957238,-0.04107853,0.00000000,0.00000000,0.00000000,0.00000000
137.07000000,3.12092300,2.35300000,0.10304367,212.70413898,0.09807333,234.62195337,0.00074414,0.10175886,239.09429820,-0.06023273,-0.04152613,0.00000000,0.00000000,0.00000000,0.00000000
138.57000000,3.15916100,2.35700000,0.10428211,213.06572697,0.09919545,235.28467079,0.00074331,0.10286707,239.76378778,-0.06088176,-0.04198531,0.00000000,0.00000000,0.00000000,0.00000000
140.07000000,3.19693000,2.36200000,0.10551311,213.51771197,0.10030958,236.04663004,0.00071553,0.10398396,240.43657524,-0.06153197,-0.04245199,0.00000000,0.00000000,0.00000000,0.00000000
141.57000000,3.23473200,2.36600000,0.10673667,213.87929997,0.10141575,236.70806351,0.00070791,0.10511299,241.11351388,-0.06222778,-0.04288521,0.00000000,0.00000000,0.00000000,0.00000000
143.07000000,3.27219800,2.37100000,0.10797878,214.33128496,0.10253743,237.47451515,0.00076771,0.10621401,241.78489338,-0.06284984,-0.04336418,0.00000000,0.00000000,0.00000000,0.00000000
144.57000000,3.31053700,2.37500000,0.10919111,214.69287296,0.10363102,238.13542631,0.00073320,0.10732370,242.45958008,-0.06352172,-0.04380199,0.00000000,0.00000000,0.00000000,0.00000000
146.07000000,3.34884300,2.37900000,0.11046689,215.05446096,0.10478055,238.81085820,0.00076619,0.10842560,243.13357613,-0.06415479,-0.04427081,0.00000000,0.00000000,0.00000000,0.00000000
147.57000000,3.38694700,2.38400000,0.11170522,215.50644595,0.10589507,239.57964139,0.00081873,0.10954276,243.81251130,-0.06481643,-0.04472633,0.00000000,0.00000000,0.00000000,0.00000000
149.07000000,3.42542000,2.38800000,0.11294744,215.86803395,0.10701185,240.24977672,0.00083140,0.11067005,244.39348211,-0.06551184,-0.04515820,0.00000000,0.00000000,0.00000000,0.00000000
150.57000000,3.46362500,2.39200000,0.11416722,216.22962194,0.10810724,240.91595724,0.00070997,0.11181118,245.08065860,-0.06616856,-0.04564263,0.00000000,0.00000000,0.00000000,0.00000000
152.07000000,3.50233400,2.39600000,0.11542056,216.59120994,0.10923151,241.59028772,0.00072911,0.11290609,245.65579168,-0.06683175,-0.04607434,0.00000000,0.00000000,0.00000000,0.00000000
153.57000000,3.54087400,2.39900000,0.11666278,216.86240094,0.11034457,242.16217103,0.00070162,0.11401956,246.23648617,-0.06748573,-0.04653384,0.00000000,0.00000000,0.00000000,0.00000000
155.07000000,3.57914600,2.40400000,0.11794222,217.31438593,0.11148969,242.94492753,0.00080104,0.11512050,246.91720833,-0.06816659,-0.04695391,0.00000000,0.00000000,0.00000000,0.00000000
156.57000000,3.61859300,2.40700000,0.11921044,217.58557693,0.11262348,243.52405026,0.00075325,0.11621495,247.49528270,-0.06878771,-0.04742724,0.00000000,0.00000000,0.00000000,0.00000000
158.07000000,3.65763700,2.41100000,0.12046011,217.94716493,0.11373941,244.20110463,0.00073257,0.11727854,248.06665373,-0.06941506,-0.04786349,0.00000000,0.00000000,0.00000000,0.00000000
159.57000000,3.69648000,2.41400000,0.12173211,218.21835593,0.11487402,244.78253708,0.00075176,0.11837257,248.74903613,-0.07005565,-0.04831692,0.00000000,0.00000000,0.00000000,0.00000000
161.07000000,3.73572600,2.41800000,0.12297056,218.57994392,0.11597746,245.45884106,0.00069114,0.11953052,249.24344096,-0.07075464,-0.04877588,0.00000000,0.00000000,0.00000000,0.00000000
162.57000000,3.77497100,2.42200000,0.12421644,218.94153192,0.11708630,246.13767055,0.00071687,0.12060039,249.81929424,-0.07139470,-0.04920569,0.00000000,0.00000000,0.00000000,0.00000000
164.07000000,3.81371400,2.42500000,0.12548100,219.21272292,0.11821050,246.71975460,0.00074254,0.12169214,250.40160239,-0.07202679,-0.04966535,0.00000000,0.00000000,0.00000000,0.00000000
165.57000000,3.85319400,2.42800000,0.12673433,219.48391391,0.11932348,247.30006142,0.00077486,0.12281527,250.99279538,-0.07269698,-0.05011829,0.00000000,0.00000000,0.00000000,0.00000000
167.07000000,3.89200400,2.43100000,0.12796900,219.75510491,0.12041867,247.87694593,0.00072099,0.12394374,251.58635765,-0.07336436,-0.05057937,0.00000000,0.00000000,0.00000000,0.00000000
168.57000000,3.93148400,2.43500000,0.12921489,220.11669291,0.12152260,248.55904692,0.00071350,0.12508404,252.18394612,-0.07402723,-0.05105681,0.00000000,0.00000000,0.00000000,0.00000000
170.07000000,3.97146800,2.43800000,0.13046833,220.38788391,0.12263200,249.14152381,0.00079216,0.12623410,252.68175956,-0.07470770,-0.05152640,0.00000000,0.00000000,0.00000000,0.00000000
171.57000000,4.01081500,2.44000000,0.13173278,220.56867790,0.12374989,249.62480253,0.00072508,0.12737825,253.28230345,-0.07539366,-0.05198460,0.00000000,0.00000000,0.00000000,0.00000000
173.07000000,4.05012700,2.44400000,0.13298989,220.93026590,0.12486006,250.31175741,0.00074409,0.12857636,253.89764912,-0.07612721,-0.05244915,0.00000000,0.00000000,0.00000000,0.00000000
174.57000000,4.08974200,2.44600000,0.13426567,221.11105990,0.12598545,250.79868376,0.00076305,0.12963455,254.37472583,-0.07669347,-0.05294107,0.00000000,0.00000000,0.00000000,0.00000000
176.07000000,4.12989400,2.44900000,0.13556378,221.38225090,0.12712925,251.39366516,0.00074260,0.13082671,254.99057931,-0.07741336,-0.05341335,0.00000000,0.00000000,0.00000000,0.00000000
177.57000000,4.17055000,2.45200000,0.13684700,221.65344189,0.12825864,251.98605046,0.00072201,0.13194415,255.48448897,-0.07808191,-0.05386223,0.00000000,0.00000000,0.00000000,0.00000000
179.07000000,4.21016500,2.45400000,0.13817489,221.83423589,0.12942600,252.48615679,0.00079324,0.13303945,256.07751050,-0.07872870,-0.05431075,0.00000000,0.00000000,0.00000000,0.00000000
180.57000000,4.25078700,2.45700000,0.13946189,222.10542689,0.13055612,253.08066926,0.00071391,0.13409611,256.55746029,-0.07933072,-0.05476539,0.00000000,0.00000000,0.00000000,0.00000000
182.07000000,4.29151000,2.46000000,0.14078233,222.37661789,0.13171428,253.68331703,0.00072595,0.13515164,257.03785114,-0.07997477,-0.05517686,0.00000000,0.00000000,0.00000000,0.00000000
183.57000000,4.33209900,2.46300000,0.14211778,222.64780888,0.13288424,254.29002071,0.00071868,0.13620603,257.51868304,-0.08059188,-0.05561414,0.00000000,0.00000000,0.00000000,0.00000000
185.07000000,4.37295600,2.46500000,0.14340844,222.82860288,0.13401367,254.78410620,0.00069823,0.13719794,257.98407021,-0.08118013,-0.05601781,0.00000000,0.00000000,0.00000000,0.00000000
186.57000000,4.41324200,2.46700000,0.14472522,223.00939688,0.13516463,255.28448140,0.00077569,0.13823262,258.56578625,-0.08181577,-0.05641685,0.00000000,0.00000000,0.00000000,0.00000000
188.07000000,4.45386400,2.47000000,0.14595989,223.28058788,0.13624262,255.87059768,0.00074226,0.13922069,258.92698941,-0.08238877,-0.05683192,0.00000000,0.00000000,0.00000000,0.00000000
189.57000000,4.49499000,2.47200000,0.14720578,223.46138188,0.13732923,256.35618840,0.00068294,0.14028219,259.51731694,-0.08304057,-0.05724163,0.00000000,0.00000000,0.00000000,0.00000000
191.07000000,4.53507500,2.47400000,0.14846289,223.64217587,0.13842443,256.84473938,0.00071471,0.14137757,259.90767611,-0.08370240,-0.05767517,0.00000000,0.00000000,0.00000000,0.00000000
192.57000000,4.57559700,2.47600000,0.14969011,223.82296987,0.13949244,257.32705510,0.00072690,0.14241564,260.38861186,-0.08431493,-0.05810071,0.00000000,0.00000000,0.00000000,0.00000000
194.07000000,4.61571500,2.47900000,0.15088011,224.09416087,0.14052696,257.90551276,0.00072615,0.14351042,260.88512164,-0.08499515,-0.05851526,0.00000000,0.00000000,0.00000000,0.00000000
195.57000000,4.65627000,2.48100000,0.15205511,224.27495487,0.14154740,258.37710805,0.00074489,0.14464559,261.39301015,-0.08565252,-0.05899308,0.00000000,0.00000000,0.00000000,0.00000000
197.07000000,4.69652300,2.48300000,0.15322267,224.45574887,0.14256034,258.84745726,0.00064699,0.14584814,261.81406724,-0.08634121,-0.05950694,0.00000000,0.00000000,0.00000000,0.00000000
198.57000000,4.73724600,2.48500000,0.15441267,224.63654286,0.14359170,259.32327048,0.00072412,0.14706051,262.34384167,-0.08706664,-0.05999387,0.00000000,0.00000000,0.00000000,0.00000000
200.07000000,4.77847300,2.48700000,0.15564733,224.81733686,0.14466065,259.80955583,0.00067160,0.14836723,262.89941954,-0.08784720,-0.06052003,0.00000000,0.00000000,0.00000000,0.00000000
201.57000000,4.81959800,2.48800000,0.15685222,224.90773386,0.14570272,260.18501171,0.00065149,0.14964180,263.34173454,-0.08858107,-0.06106072,0.00000000,0.00000000,0.00000000,0.00000000
203.07000000,4.86163000,2.49000000,0.15812789,225.08852786,0.14680481,260.68130158,0.00070855,0.15097687,263.90668876,-0.08934319,-0.06163368,0.00000000,0.00000000,0.00000000,0.00000000
204.57000000,4.90369600,2.49200000,0.15948578,225.26932186,0.14797661,261.19657486,0.00081087,0.15240550,264.49752587,-0.09018788,-0.06221761,0.00000000,0.00000000,0.00000000,0.00000000
206.07000000,4.94626600,2.49400000,0.16081000,225.45011586,0.14911804,261.70474899,0.00074579,0.15370664,264.94939407,-0.09090800,-0.06279863,0.00000000,0.00000000,0.00000000,0.00000000
207.57000000,4.98910400,2.49600000,0.16226478,225.63090986,0.15037050,262.24285930,0.00077048,0.15500606,265.40153879,-0.09166282,-0.06334325,0.00000000,0.00000000,0.00000000,0.00000000
209.07000000,5.03268000,2.49700000,0.16371956,225.72130685,0.15162139,262.67629889,0.00083371,0.15620721,265.93466496,-0.09235666,-0.06385055,0.00000000,0.00000000,0.00000000,0.00000000
210.57000000,5.07649200,2.49900000,0.16521167,225.90210085,0.15290276,263.22376344,0.00076853,0.15728193,266.32829286,-0.09295675,-0.06432518,0.00000000,0.00000000,0.00000000,0.00000000
212.07000000,5.12077300,2.50000000,0.16681567,225.99249785,0.15427839,263.69158704,0.00095935,0.15835540,266.72212486,-0.09360722,-0.06474817,0.00000000,0.00000000,0.00000000,0.00000000
213.57000000,5.16525600,2.50200000,0.16838233,226.17329185,0.15562017,264.25687847,0.00095806,0.15930150,267.08235337,-0.09417655,-0.06512496,0.00000000,0.00000000,0.00000000,0.00000000
215.07000000,5.21037700,2.50300000,0.16998633,226.26368885,0.15699207,264.72542368,0.00089290,0.16012043,267.40888750,-0.09466448,-0.06545595,0.00000000,0.00000000,0.00000000,0.00000000
216.57000000,5.25415500,2.50400000,0.17151578,226.35408585,0.15829845,265.17738294,0.00089192,0.16084422,267.71021477,-0.09512536,-0.06571886,0.00000000,0.00000000,0.00000000,0.00000000
218.07000000,5.29816800,2.50600000,0.17297056,226.53487985,0.15953947,265.71874387,0.00082713,0.16153596,268.00321623,-0.09555670,-0.06597926,0.00000000,0.00000000,0.00000000,0.00000000
219.57000000,5.34157700,2.50800000,0.17431344,226.71567384,0.16068367,266.23526386,0.00069897,0.16213279,268.27093841,-0.09591481,-0.06621798,0.00000000,0.00000000,0.00000000,0.00000000
221.07000000,5.38488400,2.50900000,0.17561900,226.80607084,0.16179482,266.63752620,0.00069819,0.16272766,268.64553834,-0.09629209,-0.06643557,0.00000000,0.00000000,0.00000000,0.00000000
222.57000000,5.42752100,2.51000000,0.17673811,226.89646784,0.16274630,266.99772099,0.00063425,0.16329230,268.90508644,-0.09664997,-0.06664233,0.00000000,0.00000000,0.00000000,0.00000000
224.07000000,5.46978800,2.51100000,0.17778256,226.98686484,0.16363348,267.34116975,0.00057027,0.16382516,269.15625814,-0.09698872,-0.06683644,0.00000000,0.00000000,0.00000000,0.00000000
225.57000000,5.51098100,2.51200000,0.17864044,227.07726184,0.16436161,267.64244482,0.00050630,0.16442060,269.42454683,-0.09738069,-0.06703991,0.00000000,0.00000000,0.00000000,0.00000000
227.07000000,5.55187100,2.51300000,0.17946111,227.16765884,0.16505765,267.93541930,0.00037949,0.16498426,269.68445911,-0.09775008,-0.06723418,0.00000000,0.00000000,0.00000000,0.00000000
228.57000000,5.59252700,2.51400000,0.18020722,227.25805584,0.16569004,268.21159881,0.00031617,0.16554751,269.94446747,-0.09811795,-0.06742956,0.00000000,0.00000000,0.00000000,0.00000000
230.07000000,5.63130200,2.51500000,0.18095322,227.34845284,0.16632193,268.48788795,0.00044225,0.16617319,270.22161980,-0.09855972,-0.06761347,0.00000000,0.00000000,0.00000000,0.00000000
231.57000000,5.67088300,2.51700000,0.18162467,227.52924684,0.16689033,268.85417045,0.00031560,0.16676872,270.38320783,-0.09894589,-0.06782283,0.00000000,0.00000000,0.00000000,0.00000000
233.07000000,5.70885300,2.51800000,0.18225878,227.61964384,0.16742683,269.10532192,0.00031543,0.16745781,270.57030443,-0.09946820,-0.06798961,0.00000000,0.00000000,0.00000000,0.00000000
234.57000000,5.74870300,2.51900000,0.18296756,227.71004084,0.16802616,269.37359038,0.00044150,0.16811511,270.74888972,-0.09992459,-0.06819052,0.00000000,0.00000000,0.00000000,0.00000000
236.07000000,5.78848600,2.52000000,0.18363889,227.80043783,0.16859350,269.63345713,0.00037815,0.16883447,270.94447229,-0.10048109,-0.06835339,0.00000000,0.00000000,0.00000000,0.00000000
237.57000000,5.82840300,2.52100000,0.18431033,227.89083483,0.16916061,269.89347057,0.00037794,0.16964561,271.27310881,-0.10107192,-0.06857369,0.00000000,0.00000000,0.00000000,0.00000000
239.07000000,5.87080400,2.52200000,0.18501900,227.98123183,0.16975881,270.16209137,0.00044074,0.17057942,271.74358875,-0.10181929,-0.06876013,0.00000000,0.00000000,0.00000000,0.00000000
240.57000000,5.91488500,2.52200000,0.18576511,227.98123183,0.17038823,270.33219070,0.00044046,0.17167142,272.04163570,-0.10265762,-0.06901380,0.00000000,0.00000000,0.00000000,0.00000000
242.07000000,5.96114700,2.52200000,0.18651111,227.98123183,0.17101716,270.50226469,0.00044018,0.17272953,272.43901514,-0.10340903,-0.06932049,0.00000000,0.00000000,0.00000000,0.00000000
243.57000000,6.00959100,2.52200000,0.18733178,227.98123183,0.17170859,270.68936129,0.00043988,0.17391247,272.76272914,-0.10422020,-0.06969227,0.00000000,0.00000000,0.00000000,0.00000000
245.07000000,6.05944600,2.52200000,0.18818967,227.98123183,0.17243086,270.88494386,0.00050223,0.17496952,273.05231858,-0.10479741,-0.07017211,0.00000000,0.00000000,0.00000000,0.00000000
246.57000000,6.11064300,2.52300000,0.18912222,228.07162883,0.17321541,271.20504210,0.00050183,0.17602392,273.45011938,-0.10536353,-0.07066039,0.00000000,0.00000000,0.00000000,0.00000000
248.07000000,6.16271400,2.52400000,0.19016678,228.16202583,0.17409345,271.55086309,0.00062690,0.17707719,273.84814947,-0.10583666,-0.07124053,0.00000000,0.00000000,0.00000000,0.00000000
249.57000000,6.21485200,2.52500000,0.19139789,228.25242283,0.17512731,271.93945469,0.00068913,0.17819287,274.15503130,-0.10629612,-0.07189675,0.00000000,0.00000000,0.00000000,0.00000000
251.07000000,6.26776100,2.52600000,0.19274100,228.34281983,0.17625402,272.35384327,0.00075098,0.00000000,0.00000000,0.00000000,0.00000000,0.00000000,0.00000000,0.00000000,0.00000000
252.57000000,6.32060300,2.52600000,0.19404667,228.34281983,0.17734810,272.65198287,0.00081234,0.00000000,0.00000000,0.00000000,0.00000000,0.00000000,0.00000000,0.00000000,0.00000000
254.07000000,6.37351300,2.52700000,0.19538967,228.43321683,0.17847221,273.06670692,0.00074913,0.00000000,0.00000000,0.00000000,0.00000000,0.00000000,0.00000000,0.00000000,0.00000000
255.57000000,6.42346800,2.52700000,0.19665778,228.43321683,0.17953249,273.35638562,0.00074815,0.00000000,0.00000000,0.00000000,0.00000000,0.00000000,0.00000000,0.00000000,0.00000000
257.07000000,6.46704500,2.52800000,0.19785144,228.52361383,0.18052949,273.73734091,0.00062288,0.00000000,0.00000000,0.00000000,0.00000000,0.00000000,0.00000000,0.00000000,0.00000000
258.57000000,6.50528300,2.52800000,0.19919433,228.52361383,0.18164994,274.04422274,0.00074675,0.00000000,0.00000000,0.00000000,0.00000000,0.00000000,0.00000000,0.00000000,0.00000000
260.07000000,6.54332000,2.52900000,0.20064911,228.61401083,0.00000000,0.00000000,0.00000000,0.00000000,0.00000000,0.00000000,0.00000000,0.00000000,0.00000000,0.00000000,0.00000000
261.57000000,6.58417700,2.52900000,0.20236500,228.61401083,0.00000000,0.00000000,0.00000000,0.00000000,0.00000000,0.00000000,0.00000000,0.00000000,0.00000000,0.00000000,0.00000000
263.07000000,6.62949800,2.52800000,0.20441656,228.52361383,0.00000000,0.00000000,0.00000000,0.00000000,0.00000000,0.00000000,0.00000000,0.00000000,0.00000000,0.00000000,0.00000000
264.57000000,6.67891600,2.52800000,0.20672911,228.52361383,0.00000000,0.00000000,0.00000000,0.00000000,0.00000000,0.00000000,0.00000000,0.00000000,0.00000000,0.00000000,0.00000000
266.07000000,6.73105400,2.52700000,0.20896711,228.43321683,0.00000000,0.00000000,0.00000000,0.00000000,0.00000000,0.00000000,0.00000000,0.00000000,0.00000000,0.00000000,0.00000000
267.57000000,6.78500500,2.52600000,0.21075756,228.34281983,0.00000000,0.00000000,0.00000000,0.00000000,0.00000000,0.00000000,0.00000000,0.00000000,0.00000000,0.00000000,0.00000000
269.07000000,6.83972800,2.52500000,0.21198856,228.25242283,0.00000000,0.00000000,0.00000000,0.00000000,0.00000000,0.00000000,0.00000000,0.00000000,0.00000000,0.00000000,0.00000000
270.57000000,6.89492000,2.52500000,0.21288378,228.25242283,0.00000000,0.00000000,0.00000000,0.00000000,0.00000000,0.00000000,0.00000000,0.00000000,0.00000000,0.00000000,0.00000000
272.07000000,6.95148900,2.52300000,0.21366722,228.07162883,0.00000000,0.00000000,0.00000000,0.00000000,0.00000000,0.00000000,0.00000000,0.00000000,0.00000000,0.00000000,0.00000000
273.57000000,7.00876200,2.52100000,0.21418956,227.89083483,0.00000000,0.00000000,0.00000000,0.00000000,0.00000000,0.00000000,0.00000000,0.00000000,0.00000000,0.00000000,0.00000000
275.07000000,7.06590200,2.51800000,0.21463744,227.61964384,0.00000000,0.00000000,0.00000000,0.00000000,0.00000000,0.00000000,0.00000000,0.00000000,0.00000000,0.00000000,0.00000000
276.57000000,7.12465300,2.51500000,0.21497322,227.34845284,0.00000000,0.00000000,0.00000000,0.00000000,0.00000000,0.00000000,0.00000000,0.00000000,0.00000000,0.00000000,0.00000000
278.07000000,7.18317100,2.51300000,0.21519678,227.16765884,0.00000000,0.00000000,0.00000000,0.00000000,0.00000000,0.00000000,0.00000000,0.00000000,0.00000000,0.00000000,0.00000000
279.57000000,7.24185500,2.50800000,0.21534600,226.71567384,0.00000000,0.00000000,0.00000000,0.00000000,0.00000000,0.00000000,0.00000000,0.00000000,0.00000000,0.00000000,0.00000000
281.07000000,7.30094000,2.50200000,0.21545789,226.17329185,0.00000000,0.00000000,0.00000000,0.00000000,0.00000000,0.00000000,0.00000000,0.00000000,0.00000000,0.00000000,0.00000000
282.57000000,7.36033000,2.49400000,0.21553244,225.45011586,0.00000000,0.00000000,0.00000000,0.00000000,0.00000000,0.00000000,0.00000000,0.00000000,0.00000000,0.00000000,0.00000000
284.07000000,7.42113200,2.48400000,0.21560689,224.54614587,0.00000000,0.00000000,0.00000000,0.00000000,0.00000000,0.00000000,0.00000000,0.00000000,0.00000000,0.00000000,0.00000000
285.57000000,7.48304400,2.46700000,0.21564411,223.00939688,0.00000000,0.00000000,0.00000000,0.00000000,0.00000000,0.00000000,0.00000000,0.00000000,0.00000000,0.00000000,0.00000000
287.07000000,7.54539500,2.44300000,0.21560689,220.83986890,0.00000000,0.00000000,0.00000000,0.00000000,0.00000000,0.00000000,0.00000000,0.00000000,0.00000000,0.00000000,0.00000000
288.57000000,7.60923000,2.40500000,0.21553267,217.40478293,0.00000000,0.00000000,0.00000000,0.00000000,0.00000000,0.00000000,0.00000000,0.00000000,0.00000000,0.00000000,0.00000000
290.07000000,7.67595900,2.34300000,0.21545900,211.80016899,0.00000000,0.00000000,0.00000000,0.00000000,0.00000000,0.00000000,0.00000000,0.00000000,0.00000000,0.00000000,0.00000000
291.57000000,7.74679600,2.25600000,0.21519956,203.93563006,0.00000000,0.00000000,0.00000000,0.00000000,0.00000000,0.00000000,0.00000000,0.00000000,0.00000000,0.00000000,0.00000000
293.07000000,7.82258500,2.11400000,0.21490356,191.09925618,0.00000000,0.00000000,0.00000000,0.00000000,0.00000000,0.00000000,0.00000000,0.00000000,0.00000000,0.00000000,0.00000000
294.57000000,7.96517100,0.00000000,0.24648889,0.00000000,0.00000000,0.00000000,0.00000000,0.00000000,0.00000000,0.00000000,0.00000000,0.00000000,0.00000000,0.00000000,0.00000000
NaN,-100.00000000,NaN,-11.11111111,NaN,0.00000000,0.00000000,0.00000000,0.00000000,0.00000000,0.00000000,0.00000000,0.00000000,0.00000000,0.00000000,0.00000000