File: polyN_optimization/results_exp/AA6014-T4/UT_75_3.csv
Time[s],Displacement[mm],Force[kN],EngStrain_longi,EngStress[MPa],TrueStrain,TrueStress[MPa],TrueStrainRate[1/s],PlasticStrain_longi,PlasticStress[MPa],PlasticStrain_thick,PlasticStrain_width,R-Value,Thickness[mm],Width[mm], Young's Modulus [MPa]
0.61000000,0.00000000,-0.00200000,0.00000000,-0.18192492,0.00000000,-0.18192492,0.00000000,0.00052708,115.77185293,0.00011230,-0.00063938,0.70289421,1.11120000,9.89340000,84721.39474174
2.12000000,0.00590500,0.16300000,0.00018756,14.82688105,0.00018754,14.82966191,0.00019278,0.00202836,118.96390245,-0.00079603,-0.00123233,0.00000000,0.00000000,0.00000000,0.00000000
3.62000000,0.01365900,0.39700000,0.00043522,36.11209678,0.00043513,36.12781357,0.00018704,0.00325797,122.40705149,-0.00153907,-0.00171890,0.00000000,0.00000000,0.00000000,0.00000000
5.12000000,0.02197100,0.63800000,0.00073867,58.03404974,0.00073839,58.07691756,0.00030935,0.00443669,125.30226687,-0.00224390,-0.00219279,0.00000000,0.00000000,0.00000000,0.00000000
6.62000000,0.02998300,0.86700000,0.00094289,78.86445317,0.00094244,78.93881359,0.00028153,0.00564891,128.11687316,-0.00296658,-0.00268234,0.00000000,0.00000000,0.00000000,0.00000000
8.12000000,0.04020600,1.08400000,0.00119967,98.60330708,0.00119895,98.72159818,0.00006459,0.00692132,130.76237696,-0.00376000,-0.00316133,0.00000000,0.00000000,0.00000000,0.00000000
9.62000000,0.05954800,1.25100000,0.00182656,113.79403797,0.00182489,114.00188910,0.00023181,0.00811665,133.12815768,-0.00446085,-0.00365580,0.00000000,0.00000000,0.00000000,0.00000000
11.12000000,0.09928100,1.29200000,0.00330389,117.52349884,0.00329844,117.91178342,0.00093801,0.00924042,135.48985521,-0.00505582,-0.00418461,0.00000000,0.00000000,0.00000000,0.00000000
12.62000000,0.13721400,1.32600000,0.00448800,120.61622250,0.00447796,121.15754810,0.00068991,0.01044624,137.77590966,-0.00579284,-0.00465340,0.00000000,0.00000000,0.00000000,0.00000000
14.12000000,0.17351800,1.36100000,0.00572244,123.79990861,0.00570613,124.50834671,0.00056507,0.01161565,139.96993249,-0.00645871,-0.00515693,0.00000000,0.00000000,0.00000000,0.00000000
15.62000000,0.21094700,1.38900000,0.00702044,126.34685750,0.00699592,127.23386859,0.00067559,0.01273710,142.06970741,-0.00711227,-0.00562483,0.00000000,0.00000000,0.00000000,0.00000000
17.11000000,0.24855400,1.41500000,0.00828311,128.71188147,0.00824899,129.77801629,0.00081255,0.01384866,144.26532038,-0.00780347,-0.00604519,0.00000000,0.00000000,0.00000000,0.00000000
18.61000000,0.28502500,1.44200000,0.00948822,131.16786790,0.00944349,132.41241778,0.00074133,0.01503591,146.19871953,-0.00852933,-0.00650658,0.00000000,0.00000000,0.00000000,0.00000000
20.11000000,0.32280900,1.46600000,0.01074489,133.35096695,0.01068757,134.78380828,0.00074414,0.01616915,148.22142912,-0.00922433,-0.00694481,0.00000000,0.00000000,0.00000000,0.00000000
21.61000000,0.35830700,1.48800000,0.01205189,135.35214108,0.01197984,136.98339005,0.00094660,0.01728271,150.24569033,-0.00991671,-0.00736599,0.00000000,0.00000000,0.00000000,0.00000000
23.11000000,0.39491200,1.51100000,0.01324333,137.44427767,0.01315641,139.26449805,0.00097949,0.01844129,152.09515745,-0.01060617,-0.00783513,0.00000000,0.00000000,0.00000000,0.00000000
24.61000000,0.43121900,1.53200000,0.01441456,139.35448934,0.01431165,141.36322237,0.00083854,0.01956924,153.94407989,-0.01129693,-0.00827231,0.00000000,0.00000000,0.00000000,0.00000000
26.11000000,0.46637700,1.55300000,0.01565667,141.26470101,0.01553537,143.47643534,0.00088151,0.02067044,155.79290299,-0.01190478,-0.00876567,0.00000000,0.00000000,0.00000000,0.00000000
27.61000000,0.50304600,1.57400000,0.01689133,143.17491268,0.01675026,145.59332785,0.00097598,0.02181027,157.65181093,-0.01260109,-0.00920918,0.00000000,0.00000000,0.00000000,0.00000000
29.11000000,0.53845900,1.59400000,0.01805511,144.99416188,0.01789405,147.61204759,0.00090891,0.02294763,159.32747395,-0.01325425,-0.00969337,0.00000000,0.00000000,0.00000000,0.00000000
30.61000000,0.57437300,1.61200000,0.01923756,146.63148617,0.01905485,149.45231753,0.00078331,0.02407871,161.09941646,-0.01392213,-0.01015659,0.00000000,0.00000000,0.00000000,0.00000000
32.12000000,0.60908600,1.63200000,0.02044244,148.45073538,0.02023630,151.48543129,0.00081724,0.02518175,162.96438665,-0.01457599,-0.01060577,0.00000000,0.00000000,0.00000000,0.00000000
33.62000000,0.64453900,1.65100000,0.02161000,150.17902213,0.02137981,153.42439079,0.00086201,0.02630907,164.55592110,-0.01525017,-0.01105890,0.00000000,0.00000000,0.00000000,0.00000000
35.12000000,0.67967700,1.66800000,0.02278489,151.72538395,0.02252919,155.18242997,0.00080972,0.02739989,166.33268768,-0.01588074,-0.01151915,0.00000000,0.00000000,0.00000000,0.00000000
36.62000000,0.71453600,1.68600000,0.02395989,153.36270824,0.02367735,157.03726169,0.00075777,0.02849560,167.92597836,-0.01655419,-0.01194141,0.00000000,0.00000000,0.00000000,0.00000000
38.12000000,0.75004700,1.70300000,0.02514611,154.90907007,0.02483515,158.80443076,0.00078617,0.02960452,169.52487702,-0.01722357,-0.01238095,0.00000000,0.00000000,0.00000000,0.00000000
39.62000000,0.78470300,1.72000000,0.02630244,156.45543189,0.02596248,160.57059220,0.00077055,0.03072426,171.03479283,-0.01789099,-0.01283327,0.00000000,0.00000000,0.00000000,0.00000000
41.12000000,0.81995400,1.73800000,0.02747000,158.09275618,0.02709947,162.43556419,0.00073354,0.03182202,172.73286325,-0.01851749,-0.01330453,0.00000000,0.00000000,0.00000000,0.00000000
42.62000000,0.85517300,1.75400000,0.02865244,159.54815555,0.02824964,164.11960021,0.00073248,0.03292830,174.24708685,-0.01916461,-0.01376369,0.00000000,0.00000000,0.00000000,0.00000000
44.12000000,0.88962000,1.76900000,0.02979767,160.91259245,0.02936234,165.70741225,0.00071034,0.03404395,175.76616707,-0.01984617,-0.01419777,0.00000000,0.00000000,0.00000000,0.00000000
45.62000000,0.92436900,1.78500000,0.03095767,162.36799182,0.03048814,167.39452599,0.00070907,0.03513328,177.28381015,-0.02046004,-0.01467325,0.00000000,0.00000000,0.00000000,0.00000000
47.12000000,0.95905200,1.80000000,0.03214022,163.73242873,0.03163453,168.99482537,0.00075138,0.03622620,178.71046391,-0.02108089,-0.01514531,0.00000000,0.00000000,0.00000000,0.00000000
48.61000000,0.99369900,1.81500000,0.03330400,165.09686563,0.03276144,170.59525165,0.00079588,0.03733450,180.23776559,-0.02170652,-0.01562798,0.00000000,0.00000000,0.00000000,0.00000000
50.11000000,1.02905200,1.83000000,0.03447900,166.46130254,0.03389792,172.20072179,0.00077282,0.03845336,181.67520875,-0.02238849,-0.01606486,0.00000000,0.00000000,0.00000000,0.00000000
51.61000000,1.06390000,1.84400000,0.03564656,167.73477698,0.03502592,173.71394403,0.00078663,0.03954735,183.01601649,-0.02302189,-0.01652546,0.00000000,0.00000000,0.00000000,0.00000000
53.11000000,1.09858200,1.85900000,0.03682533,169.09921389,0.03616348,175.32634881,0.00081527,0.04066728,184.45961835,-0.02371203,-0.01695525,0.00000000,0.00000000,0.00000000,0.00000000
54.61000000,1.13306300,1.87300000,0.03796678,170.37268834,0.03726378,176.84119033,0.00075559,0.04178710,185.81092224,-0.02438006,-0.01740705,0.00000000,0.00000000,0.00000000,0.00000000
56.12000000,1.16824800,1.88600000,0.03912689,171.55520032,0.03838083,178.26762158,0.00066071,0.04286303,187.15683593,-0.02500802,-0.01785500,0.00000000,0.00000000,0.00000000,0.00000000
57.61000000,1.20313000,1.89900000,0.04030189,172.73771231,0.03951095,179.69936840,0.00073176,0.04396607,188.51060749,-0.02565433,-0.01831174,0.00000000,0.00000000,0.00000000,0.00000000
59.11000000,1.23777800,1.91300000,0.04145822,174.01118675,0.04062187,181.22538120,0.00072369,0.04509050,189.77559441,-0.02635414,-0.01873636,0.00000000,0.00000000,0.00000000,0.00000000
60.61000000,1.27299800,1.92500000,0.04262578,175.10273628,0.04174232,182.56662660,0.00071563,0.04619093,191.13441387,-0.02699076,-0.01920017,0.00000000,0.00000000,0.00000000,0.00000000
62.12000000,1.30767900,1.93900000,0.04380078,176.37621072,0.04286865,184.10162593,0.00068682,0.04728436,192.39880968,-0.02765045,-0.01963391,0.00000000,0.00000000,0.00000000,0.00000000
63.61000000,1.34286400,1.95000000,0.04497956,177.37679779,0.04399732,185.35512732,0.00067828,0.04839063,193.66828179,-0.02831873,-0.02007190,0.00000000,0.00000000,0.00000000,0.00000000
65.11000000,1.37751200,1.96200000,0.04613589,178.46834731,0.04510327,186.70214315,0.00070600,0.04949695,194.84427941,-0.02895805,-0.02053891,0.00000000,0.00000000,0.00000000,0.00000000
66.61000000,1.41229500,1.97500000,0.04730722,179.65085930,0.04622232,188.14964242,0.00074809,0.05057470,196.20948836,-0.02957308,-0.02100162,0.00000000,0.00000000,0.00000000,0.00000000
68.11000000,1.44727700,1.98600000,0.04848222,180.65144636,0.04734362,189.40982993,0.00072584,0.05166577,197.29114446,-0.03020706,-0.02145871,0.00000000,0.00000000,0.00000000,0.00000000
69.61000000,1.48236200,1.99700000,0.04967967,181.65203343,0.04848504,190.67644590,0.00075360,0.05279993,198.47996586,-0.03088509,-0.02191484,0.00000000,0.00000000,0.00000000,0.00000000
71.11000000,1.51781500,2.00800000,0.05087333,182.65262049,0.04962156,191.94476814,0.00078109,0.05389275,199.75953423,-0.03151300,-0.02237974,0.00000000,0.00000000,0.00000000,0.00000000
72.61000000,1.55259700,2.01900000,0.05204089,183.65320756,0.05073198,193.21068372,0.00076607,0.05500814,200.85295560,-0.03218983,-0.02281831,0.00000000,0.00000000,0.00000000,0.00000000
74.11000000,1.58814900,2.03000000,0.05323078,184.65379462,0.05186237,194.48305973,0.00078631,0.05613131,202.04694147,-0.03282757,-0.02330374,0.00000000,0.00000000,0.00000000,0.00000000
75.61000000,1.62323200,2.04000000,0.05442078,185.56341922,0.05299159,195.66192483,0.00080692,0.05727559,203.15082104,-0.03351606,-0.02375953,0.00000000,0.00000000,0.00000000,0.00000000
77.11000000,1.65814900,2.05100000,0.05559944,186.56400629,0.05410880,196.93686139,0.00080581,0.05836254,204.24525344,-0.03414548,-0.02421706,0.00000000,0.00000000,0.00000000,0.00000000
78.61000000,1.69333300,2.06100000,0.05678200,187.47363089,0.05522844,198.11875860,0.00079797,0.05947124,205.44343585,-0.03482211,-0.02464912,0.00000000,0.00000000,0.00000000,0.00000000
80.11000000,1.72915400,2.07100000,0.05797933,188.38325550,0.05636080,199.30559106,0.00081808,0.06061151,206.55339764,-0.03547463,-0.02513688,0.00000000,0.00000000,0.00000000,0.00000000
81.61000000,1.76437000,2.08100000,0.05917300,189.29288010,0.05748841,200.49390769,0.00076783,0.06173787,207.56543816,-0.03618944,-0.02554843,0.00000000,0.00000000,0.00000000,0.00000000
83.11000000,1.80022600,2.09100000,0.06039278,190.20250470,0.05863938,201.68936230,0.00078812,0.06284058,208.67201241,-0.03681581,-0.02602477,0.00000000,0.00000000,0.00000000,0.00000000
84.61000000,1.83614800,2.10100000,0.06157533,191.11212931,0.05975397,202.87992237,0.00075206,0.06395033,209.68474534,-0.03746876,-0.02648157,0.00000000,0.00000000,0.00000000,0.00000000
86.11000000,1.87243900,2.11000000,0.06278389,191.93079145,0.06089178,203.98095294,0.00062487,0.06509005,210.70583155,-0.03814854,-0.02694151,0.00000000,0.00000000,0.00000000,0.00000000
87.61000000,1.90708400,2.11900000,0.06397389,192.74945360,0.06201085,205.08038572,0.00074347,0.06620071,211.72283147,-0.03878473,-0.02741598,0.00000000,0.00000000,0.00000000,0.00000000
89.11000000,1.94297200,2.12700000,0.06517122,193.47715328,0.06313556,206.08629583,0.00077060,0.06730306,212.74008674,-0.03944314,-0.02785991,0.00000000,0.00000000,0.00000000,0.00000000
90.61000000,1.97825700,2.13600000,0.06636122,194.29581542,0.06425213,207.18952321,0.00074181,0.06847004,213.77321545,-0.04014535,-0.02832468,0.00000000,0.00000000,0.00000000,0.00000000
92.11000000,2.01427800,2.14500000,0.06756233,195.11447757,0.06537786,208.29686694,0.00072702,0.06957328,214.79476220,-0.04080015,-0.02877313,0.00000000,0.00000000,0.00000000,0.00000000
93.61000000,2.05060300,2.15400000,0.06879333,195.93313971,0.06653029,209.41203350,0.00078193,0.07070770,215.72686018,-0.04144645,-0.02926125,0.00000000,0.00000000,0.00000000,0.00000000
95.11000000,2.08716400,2.16200000,0.07002422,196.66083939,0.06768129,210.43186171,0.00082279,0.07182711,216.65755975,-0.04211221,-0.02971490,0.00000000,0.00000000,0.00000000,0.00000000
96.61000000,2.12268300,2.17000000,0.07121789,197.38853908,0.06879622,211.44613412,0.00073824,0.07297125,217.69394426,-0.04279576,-0.03017549,0.00000000,0.00000000,0.00000000,0.00000000
98.11000000,2.15887400,2.17800000,0.07246011,198.11623876,0.06995518,212.47176343,0.00078630,0.07411551,218.63390744,-0.04349172,-0.03062379,0.00000000,0.00000000,0.00000000,0.00000000
99.61000000,2.19540100,2.18600000,0.07368356,198.84393844,0.07109531,213.49546683,0.00081294,0.07524120,219.57167218,-0.04413574,-0.03110546,0.00000000,0.00000000,0.00000000,0.00000000
101.11000000,2.23186100,2.19300000,0.07488844,199.48067567,0.07221688,214.41947316,0.00072889,0.07638067,220.41554918,-0.04483959,-0.03154108,0.00000000,0.00000000,0.00000000,0.00000000
102.61000000,2.26781600,2.20100000,0.07611567,200.20837535,0.07335795,215.44736931,0.00074872,0.07751939,221.45873736,-0.04551150,-0.03200790,0.00000000,0.00000000,0.00000000,0.00000000
104.11000000,2.30488100,2.20800000,0.07736911,200.84511257,0.07452206,216.38432040,0.00074124,0.07867679,222.31016061,-0.04619591,-0.03248088,0.00000000,0.00000000,0.00000000,0.00000000
105.61000000,2.34124000,2.21600000,0.07860756,201.57281225,0.07567091,217.41795829,0.00075420,0.07981221,223.15835836,-0.04685522,-0.03295698,0.00000000,0.00000000,0.00000000,0.00000000
107.11000000,2.37806900,2.22300000,0.07983478,202.20954948,0.07680805,218.35290392,0.00073255,0.08094144,224.10608116,-0.04755815,-0.03338329,0.00000000,0.00000000,0.00000000,0.00000000
108.61000000,2.41473000,2.23000000,0.08107322,202.84628670,0.07795427,219.29168878,0.00074549,0.08204693,224.95095871,-0.04816903,-0.03387791,0.00000000,0.00000000,0.00000000,0.00000000
110.11000000,2.45112300,2.23600000,0.08229300,203.39206146,0.07908194,220.12980438,0.00073089,0.08325001,225.81955585,-0.04888241,-0.03436760,0.00000000,0.00000000,0.00000000,0.00000000
111.61000000,2.48822100,2.24300000,0.08354256,204.02879869,0.08023582,221.07388594,0.00073681,0.08435622,226.66790875,-0.04951460,-0.03484162,0.00000000,0.00000000,0.00000000,0.00000000
113.11000000,2.52538400,2.25000000,0.08481456,204.66553591,0.08140906,222.02415237,0.00079087,0.08549176,227.52457980,-0.05017190,-0.03531986,0.00000000,0.00000000,0.00000000,0.00000000
114.61000000,2.56181100,2.25600000,0.08603811,205.21131067,0.08253631,222.86730422,0.00072837,0.08664643,228.38730440,-0.05088443,-0.03576200,0.00000000,0.00000000,0.00000000,0.00000000
116.11000000,2.59857400,2.26300000,0.08729144,205.84804789,0.08368969,223.81682133,0.00074797,0.08778402,229.14786180,-0.05151428,-0.03626974,0.00000000,0.00000000,0.00000000,0.00000000
117.61000000,2.63526700,2.26900000,0.08852989,206.39382266,0.08482806,224.66584484,0.00078837,0.08893939,230.01403767,-0.05218556,-0.03675383,0.00000000,0.00000000,0.00000000,0.00000000
119.11000000,2.67394400,2.27500000,0.08985044,206.93959742,0.08604048,225.53321222,0.00087656,0.09011162,230.78564861,-0.05288873,-0.03722289,0.00000000,0.00000000,0.00000000,0.00000000
120.61000000,2.71016800,2.28100000,0.09107022,207.48537218,0.08715907,226.38111113,0.00075231,0.09125393,231.65212300,-0.05357478,-0.03767915,0.00000000,0.00000000,0.00000000,0.00000000
122.11000000,2.74756800,2.28700000,0.09234222,208.03114694,0.08832422,227.24120534,0.00078562,0.09238955,232.41831466,-0.05421683,-0.03817272,0.00000000,0.00000000,0.00000000,0.00000000
123.61000000,2.78500300,2.29300000,0.09364400,208.57692171,0.08951524,228.10889896,0.00088694,0.09353741,233.18882819,-0.05487090,-0.03866651,0.00000000,0.00000000,0.00000000,0.00000000
125.11000000,2.82206800,2.29900000,0.09486378,209.12269647,0.09062995,228.96086547,0.00077691,0.09469396,233.96285913,-0.05556952,-0.03912445,0.00000000,0.00000000,0.00000000,0.00000000
126.61000000,2.86010400,2.30400000,0.09615822,209.57750877,0.09181154,229.73010943,0.00079648,0.09585926,234.74044628,-0.05623861,-0.03962065,0.00000000,0.00000000,0.00000000,0.00000000
128.11000000,2.89770600,2.30900000,0.09745633,210.03232107,0.09299508,230.50130097,0.00080242,0.09700104,235.41309075,-0.05689201,-0.04010903,0.00000000,0.00000000,0.00000000,0.00000000
129.61000000,2.93527500,2.31500000,0.09870589,210.57809583,0.09413302,231.36339396,0.00078087,0.09817038,236.19452187,-0.05759838,-0.04057200,0.00000000,0.00000000,0.00000000,0.00000000
131.11000000,2.97237400,2.32000000,0.09995556,211.03290814,0.09526977,232.12681971,0.00077331,0.09937179,236.98510073,-0.05832574,-0.04104605,0.00000000,0.00000000,0.00000000,0.00000000
132.61000000,3.01064700,2.32500000,0.10124244,211.48772044,0.09643904,232.89925423,0.00072497,0.10053959,237.66797971,-0.05902527,-0.04151432,0.00000000,0.00000000,0.00000000,0.00000000
134.11000000,3.04828100,2.33000000,0.10253689,211.94253274,0.09761379,233.67446067,0.00077836,0.10172462,238.45764241,-0.05972257,-0.04200205,0.00000000,0.00000000,0.00000000,0.00000000
135.61000000,3.08655300,2.33500000,0.10382011,212.39734504,0.09877699,234.44846101,0.00078430,0.10288632,239.14175992,-0.06041299,-0.04247333,0.00000000,0.00000000,0.00000000,0.00000000
137.12000000,3.12459100,2.34000000,0.10510700,212.85215735,0.09994216,235.22440905,0.00072148,0.10404850,239.92889316,-0.06105397,-0.04299452,0.00000000,0.00000000,0.00000000,0.00000000
138.61000000,3.16299900,2.34400000,0.10642000,213.21600719,0.10112958,235.90645467,0.00081601,0.10521746,240.61744755,-0.06173959,-0.04347787,0.00000000,0.00000000,0.00000000,0.00000000
140.11000000,3.20140600,2.34900000,0.10773678,213.67081949,0.10231899,236.69102509,0.00076788,0.10641827,241.31500560,-0.06242093,-0.04399734,0.00000000,0.00000000,0.00000000,0.00000000
141.61000000,3.23937500,2.35400000,0.10902378,214.12563179,0.10348015,237.47041709,0.00077589,0.10758093,242.00464238,-0.06310568,-0.04447525,0.00000000,0.00000000,0.00000000,0.00000000
143.12000000,3.27825100,2.35900000,0.11032556,214.58044409,0.10465327,238.25415080,0.00071809,0.10876893,242.70174024,-0.06383500,-0.04493392,0.00000000,0.00000000,0.00000000,0.00000000
144.61000000,3.31655700,2.36300000,0.11165722,214.94429393,0.10585189,238.94437673,0.00075177,0.10995538,243.39978850,-0.06453836,-0.04541702,0.00000000,0.00000000,0.00000000,0.00000000
146.11000000,3.35526700,2.36700000,0.11298144,215.30814378,0.10704240,239.63396886,0.00078423,0.11113521,243.99518611,-0.06519665,-0.04593856,0.00000000,0.00000000,0.00000000,0.00000000
147.61000000,3.39364100,2.37100000,0.11426467,215.67199362,0.10819470,240.31568208,0.00076532,0.11232875,244.69750464,-0.06591606,-0.04641269,0.00000000,0.00000000,0.00000000,0.00000000
149.12000000,3.43295400,2.37600000,0.11562622,216.12680592,0.10941588,241.11673201,0.00078032,0.11355068,245.40815557,-0.06661319,-0.04693749,0.00000000,0.00000000,0.00000000,0.00000000
150.61000000,3.47125800,2.38000000,0.11690567,216.49065576,0.11056206,241.79964020,0.00074824,0.11473133,246.10999762,-0.06731200,-0.04741933,0.00000000,0.00000000,0.00000000,0.00000000
152.11000000,3.50996500,2.38400000,0.11825978,216.85450560,0.11177371,242.49967125,0.00084077,0.11589548,246.70623012,-0.06796277,-0.04793271,0.00000000,0.00000000,0.00000000,0.00000000
153.61000000,3.54971700,2.38700000,0.11959889,217.12739298,0.11297049,243.09558793,0.00071983,0.11711440,247.31711590,-0.06869672,-0.04841768,0.00000000,0.00000000,0.00000000,0.00000000
155.11000000,3.58869700,2.39200000,0.12093056,217.58220529,0.11415919,243.89454225,0.00083876,0.11834015,248.03394395,-0.06942911,-0.04891104,0.00000000,0.00000000,0.00000000,0.00000000
156.61000000,3.62864700,2.39500000,0.12229956,217.85509267,0.11537976,244.49867368,0.00079773,0.11952303,248.63823697,-0.07011949,-0.04940354,0.00000000,0.00000000,0.00000000,0.00000000
158.11000000,3.66842900,2.39900000,0.12368722,218.21894251,0.11661544,245.20983734,0.00082345,0.12074721,249.25395339,-0.07086771,-0.04987950,0.00000000,0.00000000,0.00000000,0.00000000
159.61000000,3.70780900,2.40200000,0.12498911,218.49182989,0.11777336,245.80092949,0.00075610,0.12195678,249.86714969,-0.07155673,-0.05040005,0.00000000,0.00000000,0.00000000,0.00000000
161.11000000,3.74695600,2.40600000,0.12633567,218.85567973,0.11896959,246.50495793,0.00071553,0.12316476,250.48107476,-0.07228966,-0.05087510,0.00000000,0.00000000,0.00000000,0.00000000
162.61000000,3.78700700,2.40900000,0.12770844,219.12856711,0.12018765,247.11313555,0.00081401,0.12437787,251.09742245,-0.07296696,-0.05141091,0.00000000,0.00000000,0.00000000,0.00000000
164.11000000,3.82692300,2.41300000,0.12907000,219.49241695,0.12139429,247.82230321,0.00080633,0.12559600,251.71617435,-0.07368943,-0.05190657,0.00000000,0.00000000,0.00000000,0.00000000
165.61000000,3.86700800,2.41600000,0.13045011,219.76530434,0.12261588,248.43371270,0.00077880,0.12680610,252.33403877,-0.07438896,-0.05241714,0.00000000,0.00000000,0.00000000,0.00000000
167.11000000,3.90685900,2.41900000,0.13182289,220.03819172,0.12382951,249.04426181,0.00079789,0.12803753,252.95845112,-0.07513057,-0.05290696,0.00000000,0.00000000,0.00000000,0.00000000
168.61000000,3.94714700,2.42300000,0.13321422,220.40204156,0.12505804,249.76272810,0.00085596,0.12924782,253.57865151,-0.07582544,-0.05342238,0.00000000,0.00000000,0.00000000,0.00000000
170.11000000,3.98766800,2.42600000,0.13460189,220.67492894,0.12628183,250.37819121,0.00080906,0.13047937,254.20541609,-0.07651656,-0.05396281,0.00000000,0.00000000,0.00000000,0.00000000
171.61000000,4.02829000,2.42800000,0.13600067,220.85685386,0.12751391,250.89353322,0.00082098,0.13172389,254.73215071,-0.07725372,-0.05447017,0.00000000,0.00000000,0.00000000,0.00000000
173.11000000,4.06793700,2.43100000,0.13741444,221.12974124,0.12875766,251.51616178,0.00084635,0.13296537,255.36367916,-0.07799207,-0.05497330,0.00000000,0.00000000,0.00000000,0.00000000
174.61000000,4.10862600,2.43400000,0.13876478,221.40262862,0.12994415,252.12551518,0.00081255,0.13419373,255.88824223,-0.07869808,-0.05549566,0.00000000,0.00000000,0.00000000,0.00000000
176.11000000,4.14924800,2.43700000,0.14013756,221.67551600,0.13114892,252.74058094,0.00077881,0.13543209,256.52119988,-0.07941361,-0.05601849,0.00000000,0.00000000,0.00000000,0.00000000
177.61000000,4.19037400,2.44000000,0.14158856,221.94840339,0.13242076,253.37375723,0.00083001,0.13670904,257.06025585,-0.08016489,-0.05654415,0.00000000,0.00000000,0.00000000,0.00000000
179.11000000,4.23116300,2.44300000,0.14300611,222.22129077,0.13366173,254.00029337,0.00085524,0.13796502,257.59485585,-0.08088419,-0.05708083,0.00000000,0.00000000,0.00000000,0.00000000
180.61000000,4.27239000,2.44500000,0.14439744,222.40321569,0.13487825,254.51767167,0.00079553,0.13924521,258.13667334,-0.08164736,-0.05759785,0.00000000,0.00000000,0.00000000,0.00000000
182.11000000,4.31358300,2.44800000,0.14584844,222.67610307,0.13614536,255.15306632,0.00085312,0.14056079,258.79410683,-0.08242602,-0.05813476,0.00000000,0.00000000,0.00000000,0.00000000
183.61000000,4.35504200,2.45100000,0.14728467,222.94899045,0.13739799,255.78595819,0.00084565,0.14179903,259.32710770,-0.08315243,-0.05864660,0.00000000,0.00000000,0.00000000,0.00000000
185.11000000,4.39616800,2.45300000,0.14870956,223.13091537,0.13863919,256.31261463,0.00087054,0.14304212,259.86230305,-0.08382820,-0.05921392,0.00000000,0.00000000,0.00000000,0.00000000
186.62000000,4.43813200,2.45500000,0.15014567,223.31284029,0.13988860,256.84229557,0.00080768,0.14439582,260.42734599,-0.08467178,-0.05972404,0.00000000,0.00000000,0.00000000,0.00000000
188.11000000,4.47942600,2.45800000,0.15161911,223.58572767,0.14116887,257.48559696,0.00088127,0.14568684,260.97702948,-0.08539788,-0.06028896,0.00000000,0.00000000,0.00000000,0.00000000
189.61000000,4.52226400,2.46000000,0.15312611,223.76765259,0.14247661,258.03232303,0.00089940,0.14693629,261.62293749,-0.08609519,-0.06084110,0.00000000,0.00000000,0.00000000,0.00000000
191.11000000,4.56379200,2.46200000,0.15455856,223.94957751,0.14371807,258.56290073,0.00077563,0.14820959,262.06378306,-0.08684879,-0.06136080,0.00000000,0.00000000,0.00000000,0.00000000
192.61000000,4.60629400,2.46500000,0.15608422,224.22246490,0.14503862,259.22005393,0.00082614,0.14953065,262.62433787,-0.08763399,-0.06189666,0.00000000,0.00000000,0.00000000,0.00000000
194.11000000,4.64755200,2.46700000,0.15752778,224.40438982,0.14628650,259.75431467,0.00082511,0.15078631,263.16864394,-0.08836514,-0.06242117,0.00000000,0.00000000,0.00000000,0.00000000
195.61000000,4.69096100,2.46900000,0.15907956,224.58631474,0.14762620,260.31340587,0.00095271,0.15203079,263.71095352,-0.08908246,-0.06294833,0.00000000,0.00000000,0.00000000,0.00000000
197.11000000,4.73373000,2.47100000,0.16058656,224.76823966,0.14892553,260.86299706,0.00089362,0.15325146,264.24789768,-0.08978077,-0.06347070,0.00000000,0.00000000,0.00000000,0.00000000
198.61000000,4.77609700,2.47300000,0.16207122,224.95016458,0.15020395,261.40811269,0.00078343,0.15453884,264.69653548,-0.09053643,-0.06400241,0.00000000,0.00000000,0.00000000,0.00000000
200.11000000,4.81866500,2.47500000,0.16354467,225.13208950,0.15147109,261.95124203,0.00071175,0.15581973,265.25126778,-0.09131370,-0.06450603,0.00000000,0.00000000,0.00000000,0.00000000
201.61000000,4.86210500,2.47600000,0.16508900,225.22305196,0.15279748,262.40490038,0.00085181,0.15715748,265.71492156,-0.09213054,-0.06502695,0.00000000,0.00000000,0.00000000,0.00000000
203.11000000,4.90507700,2.47800000,0.16654756,225.40497688,0.15404858,262.94562479,0.00079967,0.15848251,266.28333186,-0.09287807,-0.06560444,0.00000000,0.00000000,0.00000000,0.00000000
204.61000000,4.94811700,2.48000000,0.16805078,225.58690180,0.15533636,263.49695611,0.00083043,0.15980716,266.74516048,-0.09362465,-0.06618252,0.00000000,0.00000000,0.00000000,0.00000000
206.11000000,4.99034800,2.48200000,0.16950933,225.76882672,0.15658429,264.03875003,0.00083585,0.16122457,267.23262674,-0.09446529,-0.06675927,0.00000000,0.00000000,0.00000000,0.00000000
207.61000000,5.03342300,2.48300000,0.17097900,225.85978918,0.15784015,264.47707008,0.00084752,0.16263852,267.82785550,-0.09530301,-0.06733550,0.00000000,0.00000000,0.00000000,0.00000000
209.11000000,5.07693000,2.48500000,0.17246733,226.04171410,0.15911036,265.02652576,0.00086541,0.16411324,268.44061554,-0.09617410,-0.06793914,0.00000000,0.00000000,0.00000000,0.00000000
210.61000000,5.12063900,2.48700000,0.17400800,226.22363902,0.16042354,265.58836200,0.00088984,0.16564997,268.96318984,-0.09704147,-0.06860849,0.00000000,0.00000000,0.00000000,0.00000000
212.11000000,5.16495400,2.48900000,0.17561200,226.40556395,0.16178886,266.16509784,0.00095217,0.16724700,269.50305594,-0.09795471,-0.06929229,0.00000000,0.00000000,0.00000000,0.00000000
213.61000000,5.20873200,2.49000000,0.17714133,226.49652641,0.16308890,266.61842309,0.00095093,0.16887266,270.05172594,-0.09886882,-0.07000384,0.00000000,0.00000000,0.00000000,0.00000000
215.11000000,5.25355100,2.49100000,0.17878267,226.58748887,0.16448227,267.09740436,0.00088623,0.17049422,270.70905769,-0.09978754,-0.07070668,0.00000000,0.00000000,0.00000000,0.00000000
216.61000000,5.29806600,2.49300000,0.18049856,226.76941379,0.16593685,267.70096542,0.00094822,0.17208336,271.25011666,-0.10063433,-0.07144903,0.00000000,0.00000000,0.00000000,0.00000000
218.11000000,5.34355500,2.49400000,0.18225178,226.86037625,0.16742091,268.20608313,0.00107301,0.17379451,271.82550819,-0.10162640,-0.07216810,0.00000000,0.00000000,0.00000000,0.00000000
219.61000000,5.38954900,2.49500000,0.18404233,226.95133871,0.16893429,268.71999264,0.00100848,0.17534736,272.35879818,-0.10246473,-0.07288263,0.00000000,0.00000000,0.00000000,0.00000000
221.11000000,5.43604700,2.49700000,0.18587011,227.13326363,0.17047678,269.35054858,0.00094393,0.17689777,272.89242749,-0.10335028,-0.07354749,0.00000000,0.00000000,0.00000000,0.00000000
222.61000000,5.48301400,2.49800000,0.18780978,227.22422609,0.17211109,269.89915750,0.00106798,0.17838377,273.40938248,-0.10419330,-0.07419047,0.00000000,0.00000000,0.00000000,0.00000000
224.11000000,5.52998000,2.49900000,0.18978678,227.31518855,0.17377411,270.45660572,0.00112900,0.17989858,273.93519873,-0.10512434,-0.07477424,0.00000000,0.00000000,0.00000000,0.00000000
225.61000000,5.57735100,2.50000000,0.19172656,227.40615101,0.17540314,271.00594905,0.00106447,0.18131837,274.43580672,-0.10597933,-0.07533903,0.00000000,0.00000000,0.00000000,0.00000000
227.11000000,5.62562600,2.50200000,0.19362889,227.58807593,0.17699815,271.65570220,0.00100019,0.18267440,274.91969288,-0.10682682,-0.07584758,0.00000000,0.00000000,0.00000000,0.00000000
228.61000000,5.67380400,2.50300000,0.19560589,227.67903839,0.17865308,272.21439908,0.00106102,0.18396712,275.38688755,-0.10763491,-0.07633221,0.00000000,0.00000000,0.00000000,0.00000000
230.11000000,5.72184500,2.50400000,0.19750833,227.77000085,0.18024301,272.75647410,0.00105933,0.18525960,275.74443976,-0.10845224,-0.07680737,0.00000000,0.00000000,0.00000000,0.00000000
231.61000000,5.76995300,2.50500000,0.19933622,227.86096331,0.18176826,273.28190693,0.00099561,0.18657960,276.22056039,-0.10928369,-0.07729591,0.00000000,0.00000000,0.00000000,0.00000000
233.11000000,5.81870000,2.50600000,0.20108933,227.95192577,0.18322892,273.79062656,0.00086977,0.18783652,276.67994384,-0.11008218,-0.07775434,0.00000000,0.00000000,0.00000000,0.00000000
234.61000000,5.86748100,2.50700000,0.20287989,228.04288823,0.18471859,274.30820406,0.00093058,0.18909331,277.02925388,-0.11085623,-0.07823708,0.00000000,0.00000000,0.00000000,0.00000000
236.11000000,5.91515300,2.50700000,0.20452122,228.04288823,0.18608216,274.68249845,0.00092931,0.19040829,277.50611584,-0.11169917,-0.07870911,0.00000000,0.00000000,0.00000000,0.00000000
237.61000000,5.96309300,2.50800000,0.20612522,228.13385069,0.18741293,275.15799136,0.00086632,0.19166182,277.85556499,-0.11243001,-0.07923182,0.00000000,0.00000000,0.00000000,0.00000000
239.11000000,6.01046300,2.50900000,0.20772922,228.22481315,0.18874192,275.63377608,0.00086517,0.19300540,278.23060589,-0.11327591,-0.07972949,0.00000000,0.00000000,0.00000000,0.00000000
240.61000000,6.05863800,2.51000000,0.20929589,228.31577561,0.19003828,276.10132882,0.00086387,0.19437600,278.72506525,-0.11413371,-0.08024230,0.00000000,0.00000000,0.00000000,0.00000000
242.11000000,6.10594100,2.51100000,0.21082522,228.40673807,0.19130213,276.56063939,0.00080108,0.19580709,279.12580657,-0.11504128,-0.08076581,0.00000000,0.00000000,0.00000000,0.00000000
243.61000000,6.15351200,2.51100000,0.21235467,228.40673807,0.19256447,276.90997480,0.00086169,0.00000000,0.00000000,0.00000000,0.00000000,0.00000000,0.00000000,0.00000000,0.00000000
245.11000000,6.20088100,2.51100000,0.21392144,228.40673807,0.19385598,277.26783740,0.00079922,0.00000000,0.00000000,0.00000000,0.00000000,0.00000000,0.00000000,0.00000000,0.00000000
246.61000000,6.24828300,2.51200000,0.21552544,228.49770053,0.19517645,277.74476900,0.00092089,0.00000000,0.00000000,0.00000000,0.00000000,0.00000000,0.00000000,0.00000000,0.00000000
248.11000000,6.29713000,2.51200000,0.21709211,228.49770053,0.19646450,278.10274873,0.00085833,0.00000000,0.00000000,0.00000000,0.00000000,0.00000000,0.00000000,0.00000000,0.00000000
249.61000000,6.34507000,2.51300000,0.21877067,228.58866299,0.19784270,278.59715719,0.00091826,0.00000000,0.00000000,0.00000000,0.00000000,0.00000000,0.00000000,0.00000000,0.00000000
251.11000000,6.39455500,2.51300000,0.22041200,228.58866299,0.19918851,278.97234738,0.00085600,0.00000000,0.00000000,0.00000000,0.00000000,0.00000000,0.00000000,0.00000000,0.00000000
252.61000000,6.44551800,2.51400000,0.22238889,228.67962546,0.00000000,0.00000000,0.00000000,0.00000000,0.00000000,0.00000000,0.00000000,0.00000000,0.00000000,0.00000000,0.00000000
254.11000000,6.49685100,2.51300000,0.22462700,228.58866299,0.00000000,0.00000000,0.00000000,0.00000000,0.00000000,0.00000000,0.00000000,0.00000000,0.00000000,0.00000000,0.00000000
255.61000000,6.54932500,2.51300000,0.22735011,228.58866299,0.00000000,0.00000000,0.00000000,0.00000000,0.00000000,0.00000000,0.00000000,0.00000000,0.00000000,0.00000000,0.00000000
257.11000000,6.60253400,2.51300000,0.23022244,228.58866299,0.00000000,0.00000000,0.00000000,0.00000000,0.00000000,0.00000000,0.00000000,0.00000000,0.00000000,0.00000000,0.00000000
258.61000000,6.65611400,2.51300000,0.23331856,228.58866299,0.00000000,0.00000000,0.00000000,0.00000000,0.00000000,0.00000000,0.00000000,0.00000000,0.00000000,0.00000000,0.00000000
260.11000000,6.71143900,2.51200000,0.23652644,228.49770053,0.00000000,0.00000000,0.00000000,0.00000000,0.00000000,0.00000000,0.00000000,0.00000000,0.00000000,0.00000000,0.00000000
261.61000000,6.76636500,2.51100000,0.23947344,228.40673807,0.00000000,0.00000000,0.00000000,0.00000000,0.00000000,0.00000000,0.00000000,0.00000000,0.00000000,0.00000000,0.00000000
263.11000000,6.82115600,2.51100000,0.24201022,228.40673807,0.00000000,0.00000000,0.00000000,0.00000000,0.00000000,0.00000000,0.00000000,0.00000000,0.00000000,0.00000000,0.00000000
264.61000000,6.87765500,2.51000000,0.24439778,228.31577561,0.00000000,0.00000000,0.00000000,0.00000000,0.00000000,0.00000000,0.00000000,0.00000000,0.00000000,0.00000000,0.00000000
266.11000000,6.93499400,2.50700000,0.24667311,228.04288823,0.00000000,0.00000000,0.00000000,0.00000000,0.00000000,0.00000000,0.00000000,0.00000000,0.00000000,0.00000000,0.00000000
267.61000000,6.99253700,2.50500000,0.24879922,227.86096331,0.00000000,0.00000000,0.00000000,0.00000000,0.00000000,0.00000000,0.00000000,0.00000000,0.00000000,0.00000000,0.00000000
269.11000000,7.05004900,2.50300000,0.25092533,227.67903839,0.00000000,0.00000000,0.00000000,0.00000000,0.00000000,0.00000000,0.00000000,0.00000000,0.00000000,0.00000000,0.00000000
270.61000000,7.10856400,2.49900000,0.25305156,227.31518855,0.00000000,0.00000000,0.00000000,0.00000000,0.00000000,0.00000000,0.00000000,0.00000000,0.00000000,0.00000000,0.00000000
272.11000000,7.16841500,2.49200000,0.25525256,226.67845133,0.00000000,0.00000000,0.00000000,0.00000000,0.00000000,0.00000000,0.00000000,0.00000000,0.00000000,0.00000000,0.00000000
273.61000000,7.22735900,2.48400000,0.25726733,225.95075164,0.00000000,0.00000000,0.00000000,0.00000000,0.00000000,0.00000000,0.00000000,0.00000000,0.00000000,0.00000000,0.00000000
275.11000000,7.28865100,2.46500000,0.25909611,224.22246490,0.00000000,0.00000000,0.00000000,0.00000000,0.00000000,0.00000000,0.00000000,0.00000000,0.00000000,0.00000000,0.00000000
276.61000000,7.35409700,2.42200000,0.26066567,220.31107910,0.00000000,0.00000000,0.00000000,0.00000000,0.00000000,0.00000000,0.00000000,0.00000000,0.00000000,0.00000000,0.00000000
278.11000000,7.45461200,2.05100000,0.26133422,186.56400629,0.00000000,0.00000000,0.00000000,0.00000000,0.00000000,0.00000000,0.00000000,0.00000000,0.00000000,0.00000000,0.00000000
279.61000000,7.54228100,1.80900000,0.26107456,164.55109087,0.00000000,0.00000000,0.00000000,0.00000000,0.00000000,0.00000000,0.00000000,0.00000000,0.00000000,0.00000000,0.00000000
281.11000000,7.61875700,1.65600000,0.26079967,150.63383443,0.00000000,0.00000000,0.00000000,0.00000000,0.00000000,0.00000000,0.00000000,0.00000000,0.00000000,0.00000000,0.00000000
282.61000000,7.70489100,1.41200000,0.26007522,128.43899409,0.00000000,0.00000000,0.00000000,0.00000000,0.00000000,0.00000000,0.00000000,0.00000000,0.00000000,0.00000000,0.00000000
284.11000000,7.78592800,1.22500000,0.25955378,111.42901399,0.00000000,0.00000000,0.00000000,0.00000000,0.00000000,0.00000000,0.00000000,0.00000000,0.00000000,0.00000000,0.00000000
285.61000000,7.88327800,0.97100000,0.25872578,88.32454905,0.00000000,0.00000000,0.00000000,0.00000000,0.00000000,0.00000000,0.00000000,0.00000000,0.00000000,0.00000000,0.00000000
287.11000000,7.99274000,0.57200000,0.25771167,52.03052735,0.00000000,0.00000000,0.00000000,0.00000000,0.00000000,0.00000000,0.00000000,0.00000000,0.00000000,0.00000000,0.00000000
288.61000000,8.09069900,0.31900000,0.25722489,29.01702487,0.00000000,0.00000000,0.00000000,0.00000000,0.00000000,0.00000000,0.00000000,0.00000000,0.00000000,0.00000000,0.00000000
290.11000000,8.19219800,0.16100000,0.25659956,14.64495613,0.00000000,0.00000000,0.00000000,0.00000000,0.00000000,0.00000000,0.00000000,0.00000000,0.00000000,0.00000000,0.00000000
NaN,-100.00000000,NaN,-11.11111111,NaN,0.00000000,0.00000000,0.00000000,0.00000000,0.00000000,0.00000000,0.00000000,0.00000000,0.00000000,0.00000000,0.00000000