File: polyN_optimization/results_exp/AA6014-T4/UT_75_2.csv
Time[s],Displacement[mm],Force[kN],EngStrain_longi,EngStress[MPa],TrueStrain,TrueStress[MPa],TrueStrainRate[1/s],PlasticStrain_longi,PlasticStress[MPa],PlasticStrain_thick,PlasticStrain_width,R-Value,Thickness[mm],Width[mm], Young's Modulus [MPa]
0.65000000,0.00000000,-0.00100000,0.00000000,-0.09050804,0.00000000,-0.09050804,0.00000000,0.00102763,116.15929565,-0.00031296,-0.00071467,0.70345793,1.11170000,9.93860000,77149.27350692
2.15000000,0.00627400,0.15800000,0.00019756,14.30027106,0.00019754,14.30309615,0.00015664,0.00226925,119.30735371,-0.00103896,-0.00123029,0.00000000,0.00000000,0.00000000,0.00000000
3.65000000,0.01380200,0.38800000,0.00044089,35.11712133,0.00044079,35.13260408,0.00008396,0.00349900,122.55301827,-0.00178891,-0.00171010,0.00000000,0.00000000,0.00000000,0.00000000
5.15000000,0.02242300,0.64000000,0.00074078,57.92514858,0.00074050,57.96805825,0.00024450,0.00469623,125.43766183,-0.00245170,-0.00224453,0.00000000,0.00000000,0.00000000,0.00000000
6.65000000,0.03112100,0.88000000,0.00103100,79.64707930,0.00103047,79.72919544,0.00038164,0.00585269,128.14129677,-0.00309410,-0.00275859,0.00000000,0.00000000,0.00000000,0.00000000
8.15000000,0.04167000,1.10800000,0.00131344,100.28291349,0.00131258,100.41462952,0.00032427,0.00703805,130.76353263,-0.00378271,-0.00325534,0.00000000,0.00000000,0.00000000,0.00000000
9.65000000,0.06575800,1.27000000,0.00209311,114.94521672,0.00209092,115.18580983,0.00060172,0.00824755,133.12042519,-0.00450802,-0.00373953,0.00000000,0.00000000,0.00000000,0.00000000
11.15000000,0.10568500,1.30000000,0.00352100,117.66045806,0.00351482,118.07474053,0.00078074,0.00940540,135.38426481,-0.00517084,-0.00423456,0.00000000,0.00000000,0.00000000,0.00000000
12.65000000,0.14197300,1.33400000,0.00479111,120.73773158,0.00477967,121.31619947,0.00095056,0.01052674,137.74010230,-0.00581788,-0.00470886,0.00000000,0.00000000,0.00000000,0.00000000
14.15000000,0.17886500,1.36800000,0.00603400,123.81500510,0.00601587,124.56210484,0.00093370,0.01172934,139.92874310,-0.00655232,-0.00517702,0.00000000,0.00000000,0.00000000,0.00000000
15.65000000,0.21676100,1.39600000,0.00723144,126.34923035,0.00720542,127.26291779,0.00079110,0.01293153,142.03047532,-0.00730630,-0.00562524,0.00000000,0.00000000,0.00000000,0.00000000
17.15000000,0.25300200,1.42300000,0.00857511,128.79294755,0.00853855,129.89736139,0.00093223,0.01401866,144.12056873,-0.00793420,-0.00608446,0.00000000,0.00000000,0.00000000,0.00000000
18.65000000,0.29072400,1.44900000,0.00979711,131.14615671,0.00974943,132.43101018,0.00101983,0.01514600,146.12878702,-0.00863552,-0.00651048,0.00000000,0.00000000,0.00000000,0.00000000
20.15000000,0.32693800,1.47200000,0.01099600,133.22784174,0.01093598,134.69281509,0.00087546,0.01632082,148.05613205,-0.00936975,-0.00695107,0.00000000,0.00000000,0.00000000,0.00000000
21.65000000,0.36294700,1.49500000,0.01221656,135.30952677,0.01214254,136.96254312,0.00074987,0.01751339,150.17557421,-0.01011123,-0.00740216,0.00000000,0.00000000,0.00000000,0.00000000
23.15000000,0.39921500,1.51800000,0.01345500,137.39121180,0.01336529,139.23981055,0.00089834,0.01861720,152.00862827,-0.01077976,-0.00783743,0.00000000,0.00000000,0.00000000,0.00000000
24.65000000,0.43494200,1.53900000,0.01461878,139.29188073,0.01451295,141.32815779,0.00077220,0.01973052,153.84711044,-0.01144520,-0.00828532,0.00000000,0.00000000,0.00000000,0.00000000
26.15000000,0.47102200,1.56000000,0.01580122,141.19254967,0.01567768,143.42356453,0.00073453,0.02085582,155.78428517,-0.01210750,-0.00874832,0.00000000,0.00000000,0.00000000,0.00000000
27.65000000,0.50654800,1.58100000,0.01700611,143.09321861,0.01686313,145.52667779,0.00071901,0.02200409,157.54349801,-0.01279711,-0.00920699,0.00000000,0.00000000,0.00000000,0.00000000
29.15000000,0.54263800,1.60100000,0.01822589,144.90337950,0.01806179,147.54437240,0.00074741,0.02310382,159.29888300,-0.01344444,-0.00965938,0.00000000,0.00000000,0.00000000,0.00000000
30.65000000,0.57735100,1.62000000,0.01938222,146.62303235,0.01919678,149.46491255,0.00076859,0.02420449,161.15132636,-0.01408319,-0.01012130,0.00000000,0.00000000,0.00000000,0.00000000
32.15000000,0.61321600,1.64000000,0.02056478,148.43319325,0.02035618,151.48568888,0.00069473,0.02532101,162.82383156,-0.01473617,-0.01058484,0.00000000,0.00000000,0.00000000,0.00000000
33.65000000,0.64809400,1.65800000,0.02174344,150.06233805,0.02151043,153.32521016,0.00070828,0.02646139,164.50388500,-0.01543958,-0.01102181,0.00000000,0.00000000,0.00000000,0.00000000
35.15000000,0.68292500,1.67500000,0.02290733,151.60097481,0.02264890,155.07374887,0.00069292,0.02756078,166.18081146,-0.01608525,-0.01147553,0.00000000,0.00000000,0.00000000,0.00000000
36.65000000,0.71819600,1.69400000,0.02411222,153.32062766,0.02382611,157.01752870,0.00081605,0.02864435,167.85864627,-0.01674325,-0.01190110,0.00000000,0.00000000,0.00000000,0.00000000
38.15000000,0.75308700,1.71100000,0.02527233,154.85926442,0.02495827,158.77291937,0.00074964,0.02975451,169.35714555,-0.01739125,-0.01236327,0.00000000,0.00000000,0.00000000,0.00000000
39.65000000,0.78806900,1.72700000,0.02645100,156.30739313,0.02610722,160.44187999,0.00075593,0.03087509,171.04820679,-0.01805213,-0.01282296,0.00000000,0.00000000,0.00000000,0.00000000
41.15000000,0.82321900,1.74500000,0.02760744,157.93653793,0.02723323,162.29676213,0.00075529,0.03199209,172.64840281,-0.01872198,-0.01327011,0.00000000,0.00000000,0.00000000,0.00000000
42.65000000,0.85806700,1.76100000,0.02879356,159.38466665,0.02838681,163.97391790,0.00076155,0.03307445,174.05795893,-0.01935238,-0.01372206,0.00000000,0.00000000,0.00000000,0.00000000
44.15000000,0.89288100,1.77800000,0.02995744,160.92330341,0.02951749,165.74415433,0.00074623,0.03415644,175.65859109,-0.01995805,-0.01419839,0.00000000,0.00000000,0.00000000,0.00000000
45.65000000,0.92725900,1.79300000,0.03111756,162.28092408,0.03064322,167.33070975,0.00073806,0.03530669,177.18045715,-0.02066016,-0.01464653,0.00000000,0.00000000,0.00000000,0.00000000
47.15000000,0.96173800,1.80800000,0.03228878,163.63854475,0.03177845,168.92223336,0.00076608,0.03638159,178.59782457,-0.02129762,-0.01508397,0.00000000,0.00000000,0.00000000,0.00000000
48.65000000,0.99648500,1.82400000,0.03344889,165.08667346,0.03290164,170.60863926,0.00073640,0.03747906,180.11660783,-0.02196662,-0.01551243,0.00000000,0.00000000,0.00000000,0.00000000
50.15000000,1.03136600,1.83800000,0.03460156,166.35378609,0.03401638,172.10988586,0.00072849,0.03857294,181.54337386,-0.02260826,-0.01596468,0.00000000,0.00000000,0.00000000,0.00000000
51.65000000,1.06618000,1.85200000,0.03577289,167.62089871,0.03514790,173.61718250,0.00070599,0.03969536,182.88367709,-0.02325351,-0.01644185,0.00000000,0.00000000,0.00000000,0.00000000
53.15000000,1.10052500,1.86700000,0.03694044,168.97851938,0.03627450,175.22066099,0.00075557,0.04076172,184.31122476,-0.02386076,-0.01690097,0.00000000,0.00000000,0.00000000,0.00000000
54.65000000,1.13547300,1.88100000,0.03810800,170.24563201,0.03739983,176.73335255,0.00078363,0.04186372,185.65342955,-0.02454035,-0.01732336,0.00000000,0.00000000,0.00000000,0.00000000
56.15000000,1.17038800,1.89400000,0.03927178,171.42223659,0.03852025,178.15429257,0.00072521,0.04298941,187.00286341,-0.02526998,-0.01771942,0.00000000,0.00000000,0.00000000,0.00000000
57.65000000,1.20486700,1.90800000,0.04046544,172.68934921,0.03966816,179.67730048,0.00077459,0.04408890,188.35020490,-0.02592115,-0.01816775,0.00000000,0.00000000,0.00000000,0.00000000
59.15000000,1.23934500,1.92100000,0.04161811,173.86595380,0.04077538,181.10192638,0.00075943,0.04518351,189.69940760,-0.02658719,-0.01859633,0.00000000,0.00000000,0.00000000,0.00000000
60.65000000,1.27426000,1.93400000,0.04275956,175.04255838,0.04187062,182.52730038,0.00073707,0.04628392,191.05250075,-0.02721985,-0.01906407,0.00000000,0.00000000,0.00000000,0.00000000
62.15000000,1.30900800,1.94700000,0.04392711,176.21916296,0.04298967,183.95996171,0.00070771,0.04739279,192.21919259,-0.02786839,-0.01952440,0.00000000,0.00000000,0.00000000,0.00000000
63.65000000,1.34399000,1.95900000,0.04510589,177.30525949,0.04411821,185.30277083,0.00067841,0.04849554,193.48261587,-0.02850560,-0.01998994,0.00000000,0.00000000,0.00000000,0.00000000
65.15000000,1.37883800,1.97100000,0.04630700,178.39135603,0.04526682,186.65212455,0.00078450,0.04960048,194.74906396,-0.02917226,-0.02042822,0.00000000,0.00000000,0.00000000,0.00000000
66.65000000,1.41331600,1.98300000,0.04746333,179.47745256,0.04637137,187.99605072,0.00077642,0.05067597,196.01233341,-0.02978450,-0.02089147,0.00000000,0.00000000,0.00000000,0.00000000
68.15000000,1.44816400,1.99400000,0.04860478,180.47304106,0.04746050,189.24489311,0.00071876,0.05179030,197.18997309,-0.03044837,-0.02134193,0.00000000,0.00000000,0.00000000,0.00000000
69.65000000,1.48307900,2.00600000,0.04981711,181.55913759,0.04861597,190.60388932,0.00079606,0.05288928,198.36698000,-0.03110497,-0.02178430,0.00000000,0.00000000,0.00000000,0.00000000
71.15000000,1.51843000,2.01700000,0.05097356,182.55472608,0.04971693,191.86018955,0.00073131,0.05398698,199.54612069,-0.03176182,-0.02222516,0.00000000,0.00000000,0.00000000,0.00000000
72.65000000,1.55354700,2.02800000,0.05215600,183.55031457,0.05084139,193.12356478,0.00075183,0.05509743,200.73021561,-0.03239971,-0.02269771,0.00000000,0.00000000,0.00000000,0.00000000
74.15000000,1.58856200,2.03900000,0.05335333,184.54590307,0.05197873,194.39204215,0.00077904,0.05621148,201.82117643,-0.03305296,-0.02315852,0.00000000,0.00000000,0.00000000,0.00000000
75.65000000,1.62364500,2.05000000,0.05450600,185.54149156,0.05307241,195.65461610,0.00072886,0.05733685,203.01305637,-0.03373828,-0.02359857,0.00000000,0.00000000,0.00000000,0.00000000
77.15000000,1.65845900,2.06000000,0.05569600,186.44657200,0.05420027,196.83090028,0.00073520,0.05844474,204.10731411,-0.03440979,-0.02403495,0.00000000,0.00000000,0.00000000,0.00000000
78.65000000,1.69374300,2.07000000,0.05688967,187.35165245,0.05533032,198.01002551,0.00078379,0.05953729,205.20062477,-0.03505721,-0.02448008,0.00000000,0.00000000,0.00000000,0.00000000
80.15000000,1.72886000,2.08000000,0.05803856,188.25673290,0.05641677,199.18288175,0.00074050,0.06064969,206.30022233,-0.03572785,-0.02492184,0.00000000,0.00000000,0.00000000,0.00000000
81.65000000,1.76424400,2.09000000,0.05924711,189.16181334,0.05755838,200.36910432,0.00077491,0.06176069,207.40175525,-0.03638857,-0.02537212,0.00000000,0.00000000,0.00000000,0.00000000
83.15000000,1.79973000,2.09900000,0.06044833,189.97638575,0.05869177,201.46014164,0.00080926,0.06287529,208.40931768,-0.03706445,-0.02581084,0.00000000,0.00000000,0.00000000,0.00000000
84.65000000,1.83528300,2.10900000,0.06166067,190.88146619,0.05983435,202.65134465,0.00080833,0.06396629,209.51100081,-0.03768386,-0.02628243,0.00000000,0.00000000,0.00000000,0.00000000
86.15000000,1.87053300,2.11800000,0.06282444,191.69603859,0.06092993,203.73923572,0.00074428,0.06512344,210.53167346,-0.03838504,-0.02673840,0.00000000,0.00000000,0.00000000,0.00000000
87.65000000,1.90608600,2.12700000,0.06404800,192.51061100,0.06208050,204.84053061,0.00074342,0.06625500,211.54902875,-0.03906680,-0.02718819,0.00000000,0.00000000,0.00000000,0.00000000
89.15000000,1.94160500,2.13700000,0.06523044,193.41569144,0.06319116,206.03228296,0.00076347,0.06733659,212.55779299,-0.03968200,-0.02765459,0.00000000,0.00000000,0.00000000,0.00000000
90.65000000,1.97752600,2.14500000,0.06642411,194.13975580,0.06431110,207.03531651,0.00075552,0.06844470,213.57420208,-0.04035271,-0.02809200,0.00000000,0.00000000,0.00000000,0.00000000
92.15000000,2.01375000,2.15400000,0.06762156,194.95432820,0.06543333,208.13744314,0.00071282,0.06959092,214.50321387,-0.04104592,-0.02854500,0.00000000,0.00000000,0.00000000,0.00000000
93.65000000,2.04893400,2.16300000,0.06884133,195.76890060,0.06657520,209.24589275,0.00069807,0.07072401,215.52899488,-0.04171067,-0.02901334,0.00000000,0.00000000,0.00000000,0.00000000
95.15000000,2.08556100,2.17100000,0.07006856,196.49296496,0.06772272,210.26094319,0.00078100,0.07182821,216.55058066,-0.04236302,-0.02946519,0.00000000,0.00000000,0.00000000,0.00000000
96.65000000,2.12104700,2.17800000,0.07125111,197.12652127,0.06882723,211.17200494,0.00069671,0.07296140,217.38460191,-0.04305141,-0.02990999,0.00000000,0.00000000,0.00000000,0.00000000
98.15000000,2.15686800,2.18700000,0.07246711,197.94109368,0.06996171,212.28531290,0.00073738,0.07411122,218.42003989,-0.04373194,-0.03037928,0.00000000,0.00000000,0.00000000,0.00000000
99.65000000,2.19329400,2.19500000,0.07368689,198.66515803,0.07109842,213.30417546,0.00070879,0.07521638,219.34958779,-0.04437926,-0.03083712,0.00000000,0.00000000,0.00000000,0.00000000
101.15000000,2.22951800,2.20200000,0.07490300,199.29871435,0.07223042,214.22678595,0.00075659,0.07633874,220.18645127,-0.04505484,-0.03128390,0.00000000,0.00000000,0.00000000,0.00000000
102.65000000,2.26527200,2.21000000,0.07610044,200.02277870,0.07334381,215.24460106,0.00071423,0.07747758,221.22541051,-0.04572237,-0.03175521,0.00000000,0.00000000,0.00000000,0.00000000
104.15000000,2.30166400,2.21700000,0.07735000,200.65633502,0.07450432,216.17710253,0.00073403,0.07860761,222.06747053,-0.04641648,-0.03219113,0.00000000,0.00000000,0.00000000,0.00000000
105.65000000,2.33815700,2.22500000,0.07860333,201.38039937,0.07566699,217.20957003,0.00078162,0.07974316,222.91240308,-0.04707318,-0.03266998,0.00000000,0.00000000,0.00000000,0.00000000
107.15000000,2.37465000,2.23200000,0.07982322,202.01395569,0.07679734,218.13936056,0.00076715,0.08087263,223.85637614,-0.04777967,-0.03309296,0.00000000,0.00000000,0.00000000,0.00000000
108.65000000,2.41114200,2.23900000,0.08103556,202.64751200,0.07791943,219.06916571,0.00072495,0.08201233,224.70566200,-0.04842296,-0.03358937,0.00000000,0.00000000,0.00000000,0.00000000
110.15000000,2.44726600,2.24500000,0.08226278,203.19056027,0.07905401,219.90558017,0.00072392,0.08312681,225.55090667,-0.04906102,-0.03406579,0.00000000,0.00000000,0.00000000,0.00000000
111.65000000,2.48375900,2.25300000,0.08351233,203.91462462,0.08020792,220.94401073,0.00075058,0.08425705,226.40135653,-0.04974019,-0.03451686,0.00000000,0.00000000,0.00000000,0.00000000
113.15000000,2.52105700,2.25900000,0.08475822,204.45767289,0.08135713,221.78714177,0.00078415,0.08541668,227.26016178,-0.05042324,-0.03499344,0.00000000,0.00000000,0.00000000,0.00000000
114.65000000,2.55775200,2.26500000,0.08599300,205.00072116,0.08249478,222.62934817,0.00072840,0.08651701,228.10710348,-0.05106423,-0.03545279,0.00000000,0.00000000,0.00000000,0.00000000
116.15000000,2.59374100,2.27200000,0.08721278,205.63427747,0.08361734,223.56821402,0.00072063,0.08765491,228.86484252,-0.05173061,-0.03592430,0.00000000,0.00000000,0.00000000,0.00000000
117.65000000,2.63117400,2.27800000,0.08848844,206.17732574,0.08478999,224.42163657,0.00078146,0.08880360,229.72607133,-0.05241140,-0.03639220,0.00000000,0.00000000,0.00000000,0.00000000
119.15000000,2.66796900,2.28400000,0.08971200,206.72037401,0.08591344,225.26567220,0.00073958,0.08993195,230.48461996,-0.05306041,-0.03687154,0.00000000,0.00000000,0.00000000,0.00000000
120.65000000,2.70503200,2.29100000,0.09097656,207.35393032,0.08707322,226.21827668,0.00080026,0.09107804,231.34850788,-0.05373388,-0.03734416,0.00000000,0.00000000,0.00000000,0.00000000
122.15000000,2.74219600,2.29600000,0.09221878,207.80647054,0.08821120,226.97012927,0.00075152,0.09222408,232.11417691,-0.05440558,-0.03781850,0.00000000,0.00000000,0.00000000,0.00000000
123.65000000,2.77899100,2.30200000,0.09347211,208.34951881,0.08935806,227.82438818,0.00077790,0.09339571,232.88729302,-0.05511423,-0.03828148,0.00000000,0.00000000,0.00000000,0.00000000
125.15000000,2.81582000,2.30800000,0.09474033,208.89256708,0.09051720,228.68311852,0.00079060,0.09450868,233.64816831,-0.05575909,-0.03874959,0.00000000,0.00000000,0.00000000,0.00000000
126.65000000,2.85342100,2.31300000,0.09600489,209.34510730,0.09167165,229.44326107,0.00078969,0.09564395,234.41570872,-0.05641600,-0.03922795,0.00000000,0.00000000,0.00000000,0.00000000
128.15000000,2.89068600,2.31900000,0.09725822,209.88815557,0.09281454,230.30150445,0.00076164,0.09681487,235.19311782,-0.05712919,-0.03968567,0.00000000,0.00000000,0.00000000,0.00000000
129.65000000,2.92775000,2.32500000,0.09852656,210.43120384,0.09396979,231.16426553,0.00074720,0.09797096,235.96853368,-0.05780014,-0.04017082,0.00000000,0.00000000,0.00000000,0.00000000
131.15000000,2.96535000,2.32900000,0.09979856,210.79323602,0.09512703,231.83009649,0.00075988,0.09909690,236.63767703,-0.05845710,-0.04063980,0.00000000,0.00000000,0.00000000,0.00000000
132.65000000,3.00261500,2.33400000,0.10105189,211.24577624,0.09626599,232.59256095,0.00071843,0.10028043,237.42247983,-0.05916792,-0.04111251,0.00000000,0.00000000,0.00000000,0.00000000
134.15000000,3.03994800,2.34000000,0.10230522,211.78882451,0.09740364,233.45592726,0.00072427,0.10143382,238.10077648,-0.05984486,-0.04158896,0.00000000,0.00000000,0.00000000,0.00000000
135.65000000,3.07758200,2.34400000,0.10359589,212.15085669,0.09857384,234.12881326,0.00073692,0.10258104,238.87981963,-0.06047642,-0.04210462,0.00000000,0.00000000,0.00000000,0.00000000
137.15000000,3.11568600,2.34900000,0.10487167,212.60339691,0.09972919,234.89946948,0.00078355,0.10373509,239.56091387,-0.06116006,-0.04257503,0.00000000,0.00000000,0.00000000,0.00000000
138.65000000,3.15362300,2.35400000,0.10614733,213.05593713,0.10088311,235.67125671,0.00076215,0.10487773,240.24052596,-0.06184564,-0.04303209,0.00000000,0.00000000,0.00000000,0.00000000
140.15000000,3.19139100,2.35800000,0.10744178,213.41796931,0.10205265,236.34797535,0.00076808,0.10605229,240.92910541,-0.06254485,-0.04350745,0.00000000,0.00000000,0.00000000,0.00000000
141.65000000,3.22949500,2.36300000,0.10875111,213.87050954,0.10323426,237.12916508,0.00082793,0.10721552,241.61623746,-0.06323330,-0.04398222,0.00000000,0.00000000,0.00000000,0.00000000
143.15000000,3.26723100,2.36800000,0.11004178,214.32304976,0.10439765,237.90753917,0.00082697,0.10839921,242.41119073,-0.06393376,-0.04446545,0.00000000,0.00000000,0.00000000,0.00000000
144.65000000,3.30553600,2.37200000,0.11132500,214.68508194,0.10555300,238.58489868,0.00075220,0.10958431,243.00467990,-0.06465458,-0.04492972,0.00000000,0.00000000,0.00000000,0.00000000
146.15000000,3.34384200,2.37700000,0.11262678,215.13762216,0.10672369,239.36787932,0.00075791,0.11074995,243.69629340,-0.06533640,-0.04541354,0.00000000,0.00000000,0.00000000,0.00000000
147.65000000,3.38208100,2.38100000,0.11396589,215.49965434,0.10792652,240.05926400,0.00084401,0.11190749,244.38721502,-0.06600359,-0.04590390,0.00000000,0.00000000,0.00000000,0.00000000
149.15000000,3.42025200,2.38500000,0.11524911,215.86168652,0.10907780,240.73955401,0.00079619,0.11310154,244.98635565,-0.06670896,-0.04639259,0.00000000,0.00000000,0.00000000,0.00000000
150.65000000,3.45896000,2.38900000,0.11654356,216.22371870,0.11023780,241.42319967,0.00074191,0.11423986,245.67501712,-0.06736237,-0.04687749,0.00000000,0.00000000,0.00000000,0.00000000
152.15000000,3.49750100,2.39300000,0.11787156,216.58575088,0.11142648,242.11505024,0.00078776,0.11544291,246.38094705,-0.06806344,-0.04737947,0.00000000,0.00000000,0.00000000,0.00000000
153.65000000,3.53627700,2.39700000,0.11918078,216.94778305,0.11259697,242.80378858,0.00079995,0.11661292,246.97762821,-0.06876923,-0.04784369,0.00000000,0.00000000,0.00000000,0.00000000
155.15000000,3.57488500,2.40100000,0.12047144,217.30981523,0.11374953,243.48944257,0.00071253,0.11777163,247.57256950,-0.06942414,-0.04834749,0.00000000,0.00000000,0.00000000,0.00000000
156.65000000,3.61416400,2.40500000,0.12183678,217.67184741,0.11496732,244.19228391,0.00077170,0.11894389,248.27459705,-0.07010265,-0.04884124,0.00000000,0.00000000,0.00000000,0.00000000
158.15000000,3.65314200,2.40900000,0.12317956,218.03387959,0.11616355,244.89119597,0.00085035,0.12015571,248.88504633,-0.07084167,-0.04931404,0.00000000,0.00000000,0.00000000,0.00000000
159.65000000,3.69208500,2.41200000,0.12450011,218.30540372,0.11733859,245.48445074,0.00084935,0.12136271,249.49541325,-0.07154268,-0.04982003,0.00000000,0.00000000,0.00000000,0.00000000
161.15000000,3.73102900,2.41500000,0.12584300,218.57692786,0.11853209,246.08330419,0.00082187,0.12254206,250.09996230,-0.07220382,-0.05033825,0.00000000,0.00000000,0.00000000,0.00000000
162.65000000,3.77050900,2.41900000,0.12715233,218.93896004,0.11969439,246.77755966,0.00076806,0.12376572,250.71674615,-0.07293128,-0.05083444,0.00000000,0.00000000,0.00000000,0.00000000
164.15000000,3.80948600,2.42300000,0.12849144,219.30099222,0.12088174,247.47929347,0.00081994,0.12496507,251.32854306,-0.07363768,-0.05132739,0.00000000,0.00000000,0.00000000,0.00000000
165.65000000,3.84866500,2.42600000,0.12981200,219.57251635,0.12205125,248.07566384,0.00073320,0.12614651,251.93693008,-0.07432509,-0.05182142,0.00000000,0.00000000,0.00000000,0.00000000
167.15000000,3.88821300,2.42900000,0.13117722,219.84404048,0.12325888,248.68257104,0.00077830,0.12737558,252.55848457,-0.07505748,-0.05231810,0.00000000,0.00000000,0.00000000,0.00000000
168.65000000,3.92803000,2.43200000,0.13252011,220.11556462,0.12444534,249.28530370,0.00074459,0.12859651,253.17912874,-0.07577608,-0.05282043,0.00000000,0.00000000,0.00000000,0.00000000
170.15000000,3.96784600,2.43500000,0.13394133,220.38708875,0.12569947,249.90602927,0.00086855,0.12980440,253.69380578,-0.07648710,-0.05331729,0.00000000,0.00000000,0.00000000,0.00000000
171.65000000,4.00799800,2.43800000,0.13529167,220.65861289,0.12688959,250.51188439,0.00081503,0.13100276,254.31085314,-0.07717639,-0.05382637,0.00000000,0.00000000,0.00000000,0.00000000
173.15000000,4.04754600,2.44100000,0.13663833,220.93013702,0.12807508,251.11766272,0.00083382,0.13222064,254.82997149,-0.07788343,-0.05433722,0.00000000,0.00000000,0.00000000,0.00000000
174.65000000,4.08766400,2.44400000,0.13802222,221.20166115,0.12929186,251.73240599,0.00075408,0.13344212,255.45508118,-0.07861790,-0.05482422,0.00000000,0.00000000,0.00000000,0.00000000
176.15000000,4.12771600,2.44700000,0.13941733,221.47318529,0.13051702,252.35038619,0.00083823,0.13464578,256.07676896,-0.07933113,-0.05531465,0.00000000,0.00000000,0.00000000,0.00000000
177.65000000,4.16860600,2.45000000,0.14081989,221.74470942,0.13174720,252.97077476,0.00088299,0.13583335,256.59101765,-0.08000647,-0.05582688,0.00000000,0.00000000,0.00000000,0.00000000
179.15000000,4.20902700,2.45200000,0.14225233,221.92572551,0.13300204,253.49517779,0.00085580,0.13703090,257.21326622,-0.08070662,-0.05632427,0.00000000,0.00000000,0.00000000,0.00000000
180.65000000,4.24914600,2.45500000,0.14363622,222.19724964,0.13421285,254.11282317,0.00089384,0.13822340,257.62597388,-0.08140332,-0.05682007,0.00000000,0.00000000,0.00000000,0.00000000
182.15000000,4.28980200,2.45800000,0.14501644,222.46877378,0.13541900,254.73040435,0.00084733,0.13947282,258.26367689,-0.08213454,-0.05733828,0.00000000,0.00000000,0.00000000,0.00000000
183.65000000,4.33062500,2.46100000,0.14642267,222.74029791,0.13664637,255.35452631,0.00089826,0.14066099,258.78172360,-0.08281605,-0.05784494,0.00000000,0.00000000,0.00000000,0.00000000
185.15000000,4.37077700,2.46300000,0.14778056,222.92131400,0.13783013,255.86474963,0.00074767,0.14187338,259.30694582,-0.08350953,-0.05836385,0.00000000,0.00000000,0.00000000,0.00000000
186.65000000,4.41123100,2.46500000,0.14919433,223.10233009,0.13906112,256.38793349,0.00080517,0.14308752,259.83352613,-0.08423470,-0.05885283,0.00000000,0.00000000,0.00000000,0.00000000
188.15000000,4.45158500,2.46800000,0.15059689,223.37385423,0.14028084,257.01326173,0.00087549,0.14433865,260.37067314,-0.08495439,-0.05938425,0.00000000,0.00000000,0.00000000,0.00000000
189.65000000,4.49287900,2.47000000,0.15193233,223.55487031,0.14144082,257.52008339,0.00076447,0.14561550,261.02097010,-0.08568352,-0.05993198,0.00000000,0.00000000,0.00000000,0.00000000
191.15000000,4.53353400,2.47200000,0.15332744,223.73588640,0.14265119,258.04073810,0.00074407,0.14689679,261.46247011,-0.08644075,-0.06045604,0.00000000,0.00000000,0.00000000,0.00000000
192.65000000,4.57405500,2.47400000,0.15474122,223.91690249,0.14387627,258.56607766,0.00077550,0.14817503,262.00961756,-0.08715754,-0.06101749,0.00000000,0.00000000,0.00000000,0.00000000
194.15000000,4.61528100,2.47700000,0.15616611,224.18842663,0.14510945,259.19906137,0.00081320,0.14950253,262.57072291,-0.08796486,-0.06153766,0.00000000,0.00000000,0.00000000,0.00000000
195.65000000,4.65674300,2.47900000,0.15760978,224.36944272,0.14635734,259.73226072,0.00083158,0.15079646,263.12399943,-0.08871593,-0.06208052,0.00000000,0.00000000,0.00000000,0.00000000
197.15000000,4.69773400,2.48100000,0.15904211,224.55045881,0.14759390,260.26343783,0.00081751,0.15216181,263.69718020,-0.08954498,-0.06261683,0.00000000,0.00000000,0.00000000,0.00000000
198.65000000,4.74000100,2.48300000,0.16051567,224.73147490,0.14886445,260.80439741,0.00088103,0.15346330,264.14819225,-0.09030977,-0.06315353,0.00000000,0.00000000,0.00000000,0.00000000
200.15000000,4.78173000,2.48500000,0.16198911,224.91249098,0.15013329,261.34586548,0.00087341,0.15479322,264.71394185,-0.09106613,-0.06372709,0.00000000,0.00000000,0.00000000,0.00000000
201.65000000,4.82483700,2.48600000,0.16351100,225.00299903,0.15144216,261.79346440,0.00087226,0.15612145,265.28028375,-0.09185700,-0.06426445,0.00000000,0.00000000,0.00000000,0.00000000
203.15000000,4.86784300,2.48800000,0.16503667,225.18401512,0.15275256,262.34763436,0.00089039,0.15747945,265.85561515,-0.09263621,-0.06484324,0.00000000,0.00000000,0.00000000,0.00000000
204.65000000,4.91105000,2.49000000,0.16658467,225.36503121,0.15408039,262.90738981,0.00083795,0.15880546,266.31658903,-0.09338184,-0.06542362,0.00000000,0.00000000,0.00000000,0.00000000
206.15000000,4.95449200,2.49200000,0.16809922,225.54604730,0.15537783,263.46016242,0.00091356,0.16016126,266.78630068,-0.09416291,-0.06599835,0.00000000,0.00000000,0.00000000,0.00000000
207.65000000,4.99746400,2.49300000,0.16968089,225.63655534,0.15673097,263.92276662,0.00085493,0.16145074,267.34618039,-0.09491295,-0.06653780,0.00000000,0.00000000,0.00000000,0.00000000
209.15000000,5.04157800,2.49500000,0.17125500,225.81757143,0.15807582,264.48995963,0.00089193,0.16270855,267.79124342,-0.09558539,-0.06712317,0.00000000,0.00000000,0.00000000,0.00000000
210.65000000,5.08559000,2.49700000,0.17285911,225.99858752,0.15944445,265.06450247,0.00089090,0.16396476,268.23657655,-0.09629993,-0.06766483,0.00000000,0.00000000,0.00000000,0.00000000
212.15000000,5.12920000,2.49900000,0.17442578,226.17960361,0.16077933,265.63115689,0.00088952,0.16518797,268.67370870,-0.09700567,-0.06818230,0.00000000,0.00000000,0.00000000,0.00000000
213.65000000,5.17281000,2.50000000,0.17599244,226.27011165,0.16211242,266.09194171,0.00088834,0.16628426,269.07723162,-0.09761100,-0.06867326,0.00000000,0.00000000,0.00000000,0.00000000
215.15000000,5.21638600,2.50100000,0.17759644,226.36061970,0.16347545,266.56146092,0.00095037,0.16737783,269.58839660,-0.09823926,-0.06913857,0.00000000,0.00000000,0.00000000,0.00000000
216.65000000,5.25888800,2.50300000,0.17912589,226.54163579,0.16477339,267.12110767,0.00088597,0.16840917,269.97556641,-0.09883753,-0.06957164,0.00000000,0.00000000,0.00000000,0.00000000
218.15000000,5.30071900,2.50500000,0.18065533,226.72265188,0.16606965,267.68130813,0.00094810,0.16946910,270.47905369,-0.09948025,-0.06998885,0.00000000,0.00000000,0.00000000,0.00000000
219.65000000,5.34278500,2.50600000,0.18211000,226.81315992,0.16730098,268.11810448,0.00082055,0.17046701,270.85828923,-0.10005830,-0.07040872,0.00000000,0.00000000,0.00000000,0.00000000
221.15000000,5.38511900,2.50700000,0.18356489,226.90366797,0.16853098,268.55521457,0.00081973,0.17152634,271.25473704,-0.10070267,-0.07082367,0.00000000,0.00000000,0.00000000,0.00000000
222.65000000,5.42742000,2.50800000,0.18498233,226.99417601,0.16972787,268.98408834,0.00081856,0.17261409,271.76786355,-0.10135696,-0.07125713,0.00000000,0.00000000,0.00000000,0.00000000
224.15000000,5.46972100,2.50900000,0.18632522,227.08468406,0.17086048,269.39628828,0.00081763,0.17385919,272.10775420,-0.10212421,-0.07173497,0.00000000,0.00000000,0.00000000,0.00000000
225.65000000,5.51242400,2.51000000,0.18755622,227.17519210,0.17189760,269.78331291,0.00075407,0.17519439,272.58138726,-0.10295375,-0.07224064,0.00000000,0.00000000,0.00000000,0.00000000
227.15000000,5.55512800,2.51200000,0.18874978,227.35620819,0.17290215,270.26964196,0.00069029,0.17680866,273.02346117,-0.10396717,-0.07284149,0.00000000,0.00000000,0.00000000,0.00000000
228.65000000,5.59732900,2.51400000,0.18998078,227.53722428,0.17393715,270.76492312,0.00068977,0.17860596,273.51650855,-0.10513034,-0.07347562,0.00000000,0.00000000,0.00000000,0.00000000
230.15000000,5.63973000,2.51500000,0.19121178,227.62773232,0.17497109,271.15283569,0.00068905,0.18052373,274.04358889,-0.10634724,-0.07417650,0.00000000,0.00000000,0.00000000,0.00000000
231.65000000,5.68166100,2.51600000,0.19255467,227.71824037,0.17609778,271.56645024,0.00081336,0.18246868,274.57917746,-0.10749479,-0.07497388,0.00000000,0.00000000,0.00000000,0.00000000
233.15000000,5.72392900,2.51700000,0.19397211,227.80874841,0.17728566,271.99729227,0.00081239,0.18437602,275.32479486,-0.10854257,-0.07583345,0.00000000,0.00000000,0.00000000,0.00000000
234.65000000,5.76690100,2.51800000,0.19553867,227.89925646,0.17859685,272.46237320,0.00093611,0.18625202,275.84380419,-0.10954374,-0.07670828,0.00000000,0.00000000,0.00000000,0.00000000
236.15000000,5.81151800,2.51800000,0.19732922,227.89925646,0.18009343,272.87043948,0.00105968,0.18812274,276.47243060,-0.11044054,-0.07768220,0.00000000,0.00000000,0.00000000,0.00000000
237.65000000,5.85744500,2.51800000,0.19934344,227.89925646,0.18177428,273.32947923,0.00112000,0.18998985,277.10144352,-0.11128752,-0.07870233,0.00000000,0.00000000,0.00000000,0.00000000
239.15000000,5.90552000,2.51800000,0.20165622,227.89925646,0.18370079,273.85655956,0.00118002,0.19173131,277.69681850,-0.11205379,-0.07967752,0.00000000,0.00000000,0.00000000,0.00000000
240.65000000,5.95544100,2.51800000,0.20408089,227.89925646,0.18571653,274.40913929,0.00142548,0.19319521,278.21589788,-0.11271882,-0.08047639,0.00000000,0.00000000,0.00000000,0.00000000
242.15000000,6.00633700,2.51900000,0.20631922,227.98976450,0.18757376,275.02843539,0.00117564,0.19441482,278.55675918,-0.11328169,-0.08113314,0.00000000,0.00000000,0.00000000,0.00000000
243.65000000,6.05857500,2.52000000,0.20863211,228.08027255,0.18948923,275.66514131,0.00129684,0.19550973,278.97404196,-0.11387055,-0.08163917,0.00000000,0.00000000,0.00000000,0.00000000
245.15000000,6.11114800,2.52100000,0.21090756,228.17078059,0.19137012,276.29372218,0.00117100,0.19645299,279.23835286,-0.11435343,-0.08209956,0.00000000,0.00000000,0.00000000,0.00000000
246.65000000,6.16469500,2.52200000,0.21325733,228.26128864,0.19330875,276.93968236,0.00135311,0.19730268,279.58777747,-0.11480912,-0.08249355,0.00000000,0.00000000,0.00000000,0.00000000
248.15000000,6.21817600,2.52300000,0.21538333,228.35179668,0.19505953,277.53496782,0.00110503,0.19815007,280.04816972,-0.11533999,-0.08281007,0.00000000,0.00000000,0.00000000,0.00000000
249.65000000,6.27148800,2.52400000,0.21728567,228.44230473,0.19662352,278.07954320,0.00104212,0.19893905,280.27008451,-0.11580713,-0.08313191,0.00000000,0.00000000,0.00000000,0.00000000
251.15000000,6.32587400,2.52400000,0.21888978,228.44230473,0.19794043,278.44599004,0.00079596,0.19975451,280.72243086,-0.11631660,-0.08343791,0.00000000,0.00000000,0.00000000,0.00000000
252.65000000,6.38032800,2.52500000,0.22027000,228.53281277,0.19907215,278.87173544,0.00067264,0.20069034,281.20931308,-0.11694613,-0.08374421,0.00000000,0.00000000,0.00000000,0.00000000
254.15000000,6.43216200,2.52500000,0.22150122,228.53281277,0.20008061,279.15311012,0.00067215,0.00000000,0.00000000,0.00000000,0.00000000,0.00000000,0.00000000,0.00000000,0.00000000
255.65000000,6.47426300,2.52600000,0.22254589,228.62332082,0.20093548,279.50250097,0.00048848,0.00000000,0.00000000,0.00000000,0.00000000,0.00000000,0.00000000,0.00000000,0.00000000
257.15000000,6.50598900,2.52700000,0.22359044,228.71382886,0.20178952,279.85205551,0.00048788,0.00000000,0.00000000,0.00000000,0.00000000,0.00000000,0.00000000,0.00000000,0.00000000
258.65000000,6.53053000,2.52800000,0.22463500,228.80433691,0.20264284,280.20179913,0.00067024,0.00000000,0.00000000,0.00000000,0.00000000,0.00000000,0.00000000,0.00000000,0.00000000
260.15000000,6.55255300,2.52900000,0.22560489,228.89484495,0.20343451,280.53464101,0.00048708,0.00000000,0.00000000,0.00000000,0.00000000,0.00000000,0.00000000,0.00000000,0.00000000
261.65000000,6.57544800,2.53200000,0.22668656,229.16636908,0.20431668,281.11530394,0.00066912,0.00000000,0.00000000,0.00000000,0.00000000,0.00000000,0.00000000,0.00000000,0.00000000
263.15000000,6.60250700,2.53400000,0.22810367,229.34738517,0.20547125,281.66236467,0.00097192,0.00000000,0.00000000,0.00000000,0.00000000,0.00000000,0.00000000,0.00000000,0.00000000
264.65000000,6.64178700,2.53100000,0.23060244,229.07586104,0.00000000,0.00000000,0.00000000,0.00000000,0.00000000,0.00000000,0.00000000,0.00000000,0.00000000,0.00000000,0.00000000
266.15000000,6.69154000,2.53000000,0.23384767,228.98535299,0.00000000,0.00000000,0.00000000,0.00000000,0.00000000,0.00000000,0.00000000,0.00000000,0.00000000,0.00000000,0.00000000
267.65000000,6.74411300,2.52800000,0.23668278,228.80433691,0.00000000,0.00000000,0.00000000,0.00000000,0.00000000,0.00000000,0.00000000,0.00000000,0.00000000,0.00000000,0.00000000
269.15000000,6.79927100,2.52700000,0.23944400,228.71382886,0.00000000,0.00000000,0.00000000,0.00000000,0.00000000,0.00000000,0.00000000,0.00000000,0.00000000,0.00000000,0.00000000
270.65000000,6.85432900,2.52600000,0.24235411,228.62332082,0.00000000,0.00000000,0.00000000,0.00000000,0.00000000,0.00000000,0.00000000,0.00000000,0.00000000,0.00000000,0.00000000
272.15000000,6.91093300,2.52500000,0.24563656,228.53281277,0.00000000,0.00000000,0.00000000,0.00000000,0.00000000,0.00000000,0.00000000,0.00000000,0.00000000,0.00000000,0.00000000
273.65000000,6.96773700,2.52500000,0.24955278,228.53281277,0.00000000,0.00000000,0.00000000,0.00000000,0.00000000,0.00000000,0.00000000,0.00000000,0.00000000,0.00000000,0.00000000
275.15000000,7.02521200,2.52500000,0.25387978,228.53281277,0.00000000,0.00000000,0.00000000,0.00000000,0.00000000,0.00000000,0.00000000,0.00000000,0.00000000,0.00000000,0.00000000
276.65000000,7.08205000,2.52600000,0.25820700,228.62332082,0.00000000,0.00000000,0.00000000,0.00000000,0.00000000,0.00000000,0.00000000,0.00000000,0.00000000,0.00000000,0.00000000
278.15000000,7.14016400,2.52600000,0.26257100,228.62332082,0.00000000,0.00000000,0.00000000,0.00000000,0.00000000,0.00000000,0.00000000,0.00000000,0.00000000,0.00000000,0.00000000
279.65000000,7.19831300,2.52100000,0.26727056,228.17078059,0.00000000,0.00000000,0.00000000,0.00000000,0.00000000,0.00000000,0.00000000,0.00000000,0.00000000,0.00000000,0.00000000
281.15000000,7.25605600,2.52000000,0.27178400,228.08027255,0.00000000,0.00000000,0.00000000,0.00000000,0.00000000,0.00000000,0.00000000,0.00000000,0.00000000,0.00000000,0.00000000
282.65000000,7.31436900,2.51800000,0.27570100,227.89925646,0.00000000,0.00000000,0.00000000,0.00000000,0.00000000,0.00000000,0.00000000,0.00000000,0.00000000,0.00000000,0.00000000
284.15000000,7.37325300,2.51700000,0.27961833,227.80874841,0.00000000,0.00000000,0.00000000,0.00000000,0.00000000,0.00000000,0.00000000,0.00000000,0.00000000,0.00000000,0.00000000
285.65000000,7.43227300,2.51400000,0.28353489,227.53722428,0.00000000,0.00000000,0.00000000,0.00000000,0.00000000,0.00000000,0.00000000,0.00000000,0.00000000,0.00000000,0.00000000
287.15000000,7.49196500,2.50900000,0.28812244,227.08468406,0.00000000,0.00000000,0.00000000,0.00000000,0.00000000,0.00000000,0.00000000,0.00000000,0.00000000,0.00000000,0.00000000
288.65000000,7.55135300,2.50500000,0.29293433,226.72265188,0.00000000,0.00000000,0.00000000,0.00000000,0.00000000,0.00000000,0.00000000,0.00000000,0.00000000,0.00000000,0.00000000
290.15000000,7.61104200,2.49900000,0.29804478,226.17960361,0.00000000,0.00000000,0.00000000,0.00000000,0.00000000,0.00000000,0.00000000,0.00000000,0.00000000,0.00000000,0.00000000
291.65000000,7.67130500,2.49200000,0.30352822,225.54604730,0.00000000,0.00000000,0.00000000,0.00000000,0.00000000,0.00000000,0.00000000,0.00000000,0.00000000,0.00000000,0.00000000
293.15000000,7.73160400,2.48300000,0.30934900,224.73147490,0.00000000,0.00000000,0.00000000,0.00000000,0.00000000,0.00000000,0.00000000,0.00000000,0.00000000,0.00000000,0.00000000
294.65000000,7.79217500,2.47100000,0.31547122,223.64537836,0.00000000,0.00000000,0.00000000,0.00000000,0.00000000,0.00000000,0.00000000,0.00000000,0.00000000,0.00000000,0.00000000
296.15000000,7.85449600,2.45100000,0.32204556,221.83521747,0.00000000,0.00000000,0.00000000,0.00000000,0.00000000,0.00000000,0.00000000,0.00000000,0.00000000,0.00000000,0.00000000
297.65000000,7.91816900,2.41600000,0.32914967,218.66743590,0.00000000,0.00000000,0.00000000,0.00000000,0.00000000,0.00000000,0.00000000,0.00000000,0.00000000,0.00000000,0.00000000
299.15000000,7.98430500,2.36700000,0.33663656,214.23254171,0.00000000,0.00000000,0.00000000,0.00000000,0.00000000,0.00000000,0.00000000,0.00000000,0.00000000,0.00000000,0.00000000
300.65000000,8.05236800,2.29800000,0.34458244,207.98748663,0.00000000,0.00000000,0.00000000,0.00000000,0.00000000,0.00000000,0.00000000,0.00000000,0.00000000,0.00000000,0.00000000
302.15000000,8.12495100,2.18900000,0.35321478,198.12210976,0.00000000,0.00000000,0.00000000,0.00000000,0.00000000,0.00000000,0.00000000,0.00000000,0.00000000,0.00000000,0.00000000
303.65000000,8.48677600,0.57900000,0.36996789,52.40415786,0.00000000,0.00000000,0.00000000,0.00000000,0.00000000,0.00000000,0.00000000,0.00000000,0.00000000,0.00000000,0.00000000
NaN,-100.00000000,NaN,-11.11111111,NaN,0.00000000,0.00000000,0.00000000,0.00000000,0.00000000,0.00000000,0.00000000,0.00000000,0.00000000,0.00000000,0.00000000