File: polyN_optimization/results_exp/AA6014-T4/UT_90_1.csv
Time[s],Displacement[mm],Force[kN],EngStrain_longi,EngStress[MPa],TrueStrain,TrueStress[MPa],TrueStrainRate[1/s],PlasticStrain_longi,PlasticStress[MPa],PlasticStrain_thick,PlasticStrain_width,R-Value,Thickness[mm],Width[mm], Young's Modulus [MPa]
0.62000000,0.00000000,-0.00200000,0.00000000,-0.17979398,0.00000000,-0.17979398,0.00000000,0.00098401,117.08407805,-0.00019632,-0.00078769,0.83133003,1.10940000,10.02690000,77230.82613104
2.12000000,0.00584100,0.15600000,0.00016700,14.02393058,0.00016699,14.02627257,0.00011576,0.00222297,120.03183094,-0.00084732,-0.00137564,0.00000000,0.00000000,0.00000000,0.00000000
3.62000000,0.01339500,0.39500000,0.00043678,35.50931139,0.00043668,35.52482107,0.00012573,0.00345857,123.25811150,-0.00153434,-0.00192423,0.00000000,0.00000000,0.00000000,0.00000000
5.12000000,0.02217400,0.65000000,0.00075833,58.43304406,0.00075805,58.47735579,0.00031912,0.00463768,126.12277457,-0.00219530,-0.00244238,0.00000000,0.00000000,0.00000000,0.00000000
6.62000000,0.03080900,0.89500000,0.00103589,80.45780683,0.00103535,80.54115217,0.00039141,0.00577323,128.89788175,-0.00274710,-0.00302613,0.00000000,0.00000000,0.00000000,0.00000000
8.12000000,0.04230400,1.12800000,0.00133433,101.40380570,0.00133344,101.53911218,0.00023992,0.00697084,131.41495124,-0.00342367,-0.00354716,0.00000000,0.00000000,0.00000000,0.00000000
9.62000000,0.06652300,1.28900000,0.00209456,115.87722123,0.00209237,116.11993251,0.00052120,0.00816798,133.75603045,-0.00400747,-0.00416051,0.00000000,0.00000000,0.00000000,0.00000000
11.12000000,0.10699100,1.31700000,0.00349033,118.39433697,0.00348426,118.80757267,0.00084612,0.00930304,136.18530488,-0.00465397,-0.00464906,0.00000000,0.00000000,0.00000000,0.00000000
12.62000000,0.14353000,1.35100000,0.00473667,121.45083466,0.00472548,122.02610678,0.00089507,0.01041008,138.43381468,-0.00524411,-0.00516597,0.00000000,0.00000000,0.00000000,0.00000000
14.12000000,0.18051300,1.38500000,0.00597400,124.50733235,0.00595623,125.25113916,0.00090436,0.01160567,140.60845463,-0.00591445,-0.00569122,0.00000000,0.00000000,0.00000000,0.00000000
15.62000000,0.21870800,1.41300000,0.00720978,127.02444810,0.00718391,127.94026614,0.00082975,0.01277261,142.87555497,-0.00661983,-0.00615278,0.00000000,0.00000000,0.00000000,0.00000000
17.12000000,0.25458700,1.43900000,0.00847289,129.36176986,0.00843720,130.45783776,0.00087831,0.01385045,144.86037241,-0.00722730,-0.00662315,0.00000000,0.00000000,0.00000000,0.00000000
18.62000000,0.29214000,1.46600000,0.00970044,131.78898861,0.00965370,133.06740037,0.00098359,0.01497814,146.85675114,-0.00785220,-0.00712594,0.00000000,0.00000000,0.00000000,0.00000000
20.12000000,0.32842500,1.49000000,0.01088144,133.94651639,0.01082267,135.40404797,0.00092504,0.01615802,148.95709392,-0.00854642,-0.00761160,0.00000000,0.00000000,0.00000000,0.00000000
21.62000000,0.36467900,1.51200000,0.01212700,135.92425019,0.01205406,137.57260357,0.00084417,0.01727686,150.86936888,-0.00914519,-0.00813167,0.00000000,0.00000000,0.00000000,0.00000000
23.12000000,0.40086700,1.53600000,0.01333556,138.08177797,0.01324742,139.92317519,0.00091315,0.01839792,152.78618112,-0.00979224,-0.00860568,0.00000000,0.00000000,0.00000000,0.00000000
24.62000000,0.43680900,1.55700000,0.01450689,139.96961478,0.01440267,142.00013843,0.00085336,0.01949462,154.79549698,-0.01040009,-0.00909453,0.00000000,0.00000000,0.00000000,0.00000000
26.12000000,0.47195900,1.57800000,0.01566322,141.85745159,0.01554182,144.07939638,0.00071997,0.02062878,156.63068591,-0.01100707,-0.00962171,0.00000000,0.00000000,0.00000000,0.00000000
27.62000000,0.50750200,1.60000000,0.01687189,143.83518539,0.01673114,146.26195665,0.00077792,0.02172300,158.37131106,-0.01158553,-0.01013748,0.00000000,0.00000000,0.00000000,0.00000000
29.12000000,0.54380300,1.62000000,0.01805433,145.63312521,0.01789329,148.26243419,0.00078422,0.02282415,160.30153218,-0.01219544,-0.01062871,0.00000000,0.00000000,0.00000000,0.00000000
30.62000000,0.57846600,1.63900000,0.01918833,147.34116803,0.01900656,150.16839948,0.00071721,0.02393023,162.05173130,-0.01273545,-0.01119478,0.00000000,0.00000000,0.00000000,0.00000000
32.12000000,0.61389500,1.66000000,0.02036711,149.22900484,0.02016248,152.26836856,0.00067286,0.02505085,163.71547689,-0.01336464,-0.01168621,0.00000000,0.00000000,0.00000000,0.00000000
33.62000000,0.64852100,1.67800000,0.02156822,150.84715068,0.02133892,154.10065554,0.00075976,0.02613487,165.56217715,-0.01393520,-0.01219967,0.00000000,0.00000000,0.00000000,0.00000000
35.12000000,0.68313100,1.69600000,0.02270222,152.46529651,0.02244836,155.92659755,0.00074414,0.02726843,167.14264591,-0.01459423,-0.01267420,0.00000000,0.00000000,0.00000000,0.00000000
36.62000000,0.71830700,1.71400000,0.02383989,154.08344235,0.02356016,157.75677449,0.00065581,0.02832364,168.80622530,-0.01517044,-0.01315320,0.00000000,0.00000000,0.00000000,0.00000000
38.12000000,0.75302100,1.73200000,0.02500744,155.70158818,0.02469988,159.59528700,0.00069150,0.02940276,170.47729628,-0.01576168,-0.01364108,0.00000000,0.00000000,0.00000000,0.00000000
39.62000000,0.78739900,1.74900000,0.02616011,157.22983703,0.02582379,161.34298703,0.00070523,0.03049642,172.06123304,-0.01639037,-0.01410604,0.00000000,0.00000000,0.00000000,0.00000000
41.12000000,0.82261600,1.76700000,0.02732022,158.84798286,0.02695369,163.18774505,0.00069730,0.03161396,173.65266087,-0.01702708,-0.01458687,0.00000000,0.00000000,0.00000000,0.00000000
42.62000000,0.85716100,1.78300000,0.02848411,160.28633472,0.02808598,164.85194848,0.00068937,0.03268703,175.23969198,-0.01762222,-0.01506481,0.00000000,0.00000000,0.00000000,0.00000000
44.12000000,0.89197600,1.79900000,0.02964422,161.72468657,0.02921333,166.51888912,0.00077561,0.03377450,176.73910363,-0.01824207,-0.01553242,0.00000000,0.00000000,0.00000000,0.00000000
45.62000000,0.92618500,1.81600000,0.03077067,163.25293542,0.03030674,168.27633707,0.00073831,0.03484639,178.23885069,-0.01881912,-0.01602727,0.00000000,0.00000000,0.00000000,0.00000000
47.12000000,0.96066400,1.83100000,0.03192333,164.60139028,0.03142437,169.85601533,0.00075192,0.03595288,179.74790941,-0.01944016,-0.01651272,0.00000000,0.00000000,0.00000000,0.00000000
48.62000000,0.99467300,1.84700000,0.03309089,166.03974213,0.03255517,171.53414479,0.00072955,0.03704006,181.25664503,-0.02003396,-0.01700610,0.00000000,0.00000000,0.00000000,0.00000000
50.12000000,1.02901700,1.86200000,0.03421000,167.38819700,0.03363785,173.11454722,0.00072876,0.03809526,182.66878469,-0.02059666,-0.01749860,0.00000000,0.00000000,0.00000000,0.00000000
51.62000000,1.06349600,1.87600000,0.03537389,168.64675487,0.03476261,174.61244644,0.00071356,0.03919923,184.09276031,-0.02119536,-0.01800386,0.00000000,0.00000000,0.00000000,0.00000000
53.12000000,1.09878000,1.89100000,0.03654511,169.99520973,0.03589317,176.20770356,0.00078460,0.04028395,185.51613640,-0.02180843,-0.01847552,0.00000000,0.00000000,0.00000000,0.00000000
54.62000000,1.13288900,1.90600000,0.03769033,171.34366459,0.03699741,177.80166443,0.00073360,0.04133682,186.84228554,-0.02236233,-0.01897449,0.00000000,0.00000000,0.00000000,0.00000000
56.12000000,1.16736800,1.91900000,0.03884300,172.51232548,0.03810759,179.21322173,0.00076874,0.04241568,188.27026682,-0.02292792,-0.01948775,0.00000000,0.00000000,0.00000000,0.00000000
57.62000000,1.20191300,1.93300000,0.03999189,173.77088335,0.03921291,180.72030921,0.00073903,0.04351229,189.61014883,-0.02351933,-0.01999296,0.00000000,0.00000000,0.00000000,0.00000000
59.12000000,1.23619000,1.94600000,0.04111089,174.93954423,0.04028831,182.13146439,0.00070236,0.04461244,190.85896634,-0.02417045,-0.02044199,0.00000000,0.00000000,0.00000000,0.00000000
60.62000000,1.27120600,1.95900000,0.04230456,176.10820511,0.04143418,183.55838446,0.00080884,0.04564847,192.28721018,-0.02470845,-0.02094001,0.00000000,0.00000000,0.00000000,0.00000000
62.12000000,1.30565100,1.97200000,0.04342744,177.27686599,0.04251091,184.97554724,0.00072232,0.04675329,193.54220010,-0.02535078,-0.02140251,0.00000000,0.00000000,0.00000000,0.00000000
63.62000000,1.34013000,1.98500000,0.04459500,178.44552687,0.04362925,186.40330514,0.00072875,0.04786388,194.80089995,-0.02594502,-0.02191887,0.00000000,0.00000000,0.00000000,0.00000000
65.12000000,1.37457500,1.99700000,0.04575511,179.52429076,0.04473922,187.73844463,0.00076344,0.04896612,196.06055985,-0.02660490,-0.02236123,0.00000000,0.00000000,0.00000000,0.00000000
66.62000000,1.40895300,2.00900000,0.04688533,180.60305465,0.04581941,189.07068907,0.00075540,0.05001757,197.31275606,-0.02717370,-0.02284387,0.00000000,0.00000000,0.00000000,0.00000000
68.12000000,1.44353200,2.02200000,0.04803422,181.77171553,0.04691624,190.50297851,0.00072615,0.05108693,198.47583947,-0.02775600,-0.02333092,0.00000000,0.00000000,0.00000000,0.00000000
69.62000000,1.47858100,2.03300000,0.04917944,182.76058243,0.04800838,191.74864634,0.00068976,0.05215720,199.73665180,-0.02834627,-0.02381093,0.00000000,0.00000000,0.00000000,0.00000000
71.12000000,1.51346300,2.04400000,0.05036944,183.74944933,0.04914195,193.00480701,0.00079565,0.05324876,200.90891941,-0.02890361,-0.02434515,0.00000000,0.00000000,0.00000000,0.00000000
72.62000000,1.54750500,2.05600000,0.05150333,184.82821322,0.05022089,194.34748230,0.00073073,0.05432849,202.08115123,-0.02950471,-0.02482378,0.00000000,0.00000000,0.00000000,0.00000000
74.12000000,1.58302400,2.06700000,0.05267100,185.81708012,0.05133074,195.60425155,0.00075864,0.05544901,203.26403370,-0.03016134,-0.02528767,0.00000000,0.00000000,0.00000000,0.00000000
75.62000000,1.61773700,2.07700000,0.05384967,186.71605003,0.05244981,196.77064709,0.00073627,0.05653813,204.34723904,-0.03074379,-0.02579434,0.00000000,0.00000000,0.00000000,0.00000000
77.12000000,1.65208100,2.08800000,0.05499489,187.70491693,0.05353592,198.02772798,0.00079216,0.05761891,205.43087877,-0.03133065,-0.02628826,0.00000000,0.00000000,0.00000000,0.00000000
78.62000000,1.68659300,2.09900000,0.05611400,188.69378383,0.05459613,199.28214682,0.00071364,0.05871118,206.61492511,-0.03193722,-0.02677396,0.00000000,0.00000000,0.00000000,0.00000000
80.12000000,1.72181000,2.10900000,0.05731511,189.59275374,0.05573278,200.45928349,0.00074816,0.05981395,207.70754158,-0.03257281,-0.02724113,0.00000000,0.00000000,0.00000000,0.00000000
81.62000000,1.75692600,2.11900000,0.05848633,190.49172365,0.05683990,201.63288610,0.00078240,0.06086316,208.79113563,-0.03313618,-0.02772698,0.00000000,0.00000000,0.00000000,0.00000000
83.12000000,1.79211000,2.12900000,0.05967256,191.39069356,0.05795995,202.81146535,0.00077460,0.06194599,209.88388608,-0.03372885,-0.02821714,0.00000000,0.00000000,0.00000000,0.00000000
84.62000000,1.82722600,2.13900000,0.06081767,192.28966347,0.05903999,203.98427212,0.00074548,0.06308474,210.89430240,-0.03437315,-0.02871159,0.00000000,0.00000000,0.00000000,0.00000000
86.12000000,1.86254300,2.14800000,0.06200389,193.09873638,0.06015758,205.07160898,0.00077981,0.06420473,211.90279086,-0.03500392,-0.02920081,0.00000000,0.00000000,0.00000000,0.00000000
87.62000000,1.89782700,2.15700000,0.06319389,193.90780930,0.06127748,206.16159786,0.00073001,0.06526991,212.99813595,-0.03560319,-0.02966672,0.00000000,0.00000000,0.00000000,0.00000000
89.12000000,1.93280900,2.16600000,0.06437256,194.71688222,0.06238548,207.25130554,0.00084825,0.06636306,214.00496726,-0.03620974,-0.03015332,0.00000000,0.00000000,0.00000000,0.00000000
90.62000000,1.96789200,2.17600000,0.06548422,195.61585213,0.06342936,208.42560406,0.00070027,0.06748273,215.01949393,-0.03683331,-0.03064942,0.00000000,0.00000000,0.00000000,0.00000000
92.12000000,2.00341100,2.18500000,0.06667789,196.42492505,0.06454904,209.52212437,0.00072054,0.06858366,216.03199359,-0.03741562,-0.03116804,0.00000000,0.00000000,0.00000000,0.00000000
93.62000000,2.03926600,2.19300000,0.06791622,197.14410097,0.06570929,210.53338354,0.00076841,0.06969519,216.95182187,-0.03802322,-0.03167198,0.00000000,0.00000000,0.00000000,0.00000000
95.12000000,2.07475100,2.20100000,0.06906889,197.86327690,0.06678807,211.52947359,0.00075386,0.07080398,217.96993833,-0.03864365,-0.03216033,0.00000000,0.00000000,0.00000000,0.00000000
96.62000000,2.11047200,2.21000000,0.07027378,198.67234982,0.06791448,212.63380638,0.00077399,0.07188733,218.98448820,-0.03922874,-0.03265859,0.00000000,0.00000000,0.00000000,0.00000000
98.12000000,2.14609200,2.21800000,0.07144133,199.39152574,0.06900478,213.63632220,0.00071733,0.07299641,219.81207631,-0.03984545,-0.03315096,0.00000000,0.00000000,0.00000000,0.00000000
99.62000000,2.18198000,2.22700000,0.07264622,200.20059866,0.07012870,214.74441584,0.00073746,0.07408552,220.73424440,-0.04048287,-0.03360265,0.00000000,0.00000000,0.00000000,0.00000000
101.12000000,2.21807000,2.23400000,0.07385111,200.82987760,0.07125136,215.66138720,0.00076437,0.07519620,221.76050542,-0.04107838,-0.03411782,0.00000000,0.00000000,0.00000000,0.00000000
102.62000000,2.25422700,2.24200000,0.07506711,201.54905353,0.07238309,216.67875872,0.00075648,0.07631170,222.59460936,-0.04170772,-0.03460398,0.00000000,0.00000000,0.00000000,0.00000000
104.12000000,2.29021600,2.24900000,0.07625700,202.17833246,0.07348928,217.59584556,0.00079034,0.07739916,223.61952217,-0.04227614,-0.03512302,0.00000000,0.00000000,0.00000000,0.00000000
105.62000000,2.32620600,2.25700000,0.07746189,202.89750839,0.07460817,218.61433264,0.00076862,0.07853611,224.46186419,-0.04291943,-0.03561668,0.00000000,0.00000000,0.00000000,0.00000000
107.12000000,2.36222800,2.26400000,0.07865933,203.52678732,0.07571891,219.53606873,0.00071253,0.07961003,225.29160886,-0.04350147,-0.03610856,0.00000000,0.00000000,0.00000000,0.00000000
108.62000000,2.39821700,2.27100000,0.07985667,204.15606626,0.07682832,220.45928919,0.00073233,0.08073282,226.23205898,-0.04415006,-0.03658276,0.00000000,0.00000000,0.00000000,0.00000000
110.12000000,2.43420700,2.27800000,0.08107278,204.78534520,0.07795386,221.38786198,0.00077304,0.08184529,227.07382178,-0.04471239,-0.03713290,0.00000000,0.00000000,0.00000000,0.00000000
111.62000000,2.47016200,2.28600000,0.08227389,205.50452112,0.07906428,222.41217726,0.00076520,0.08293271,227.91146778,-0.04532684,-0.03760587,0.00000000,0.00000000,0.00000000,0.00000000
113.12000000,2.50736000,2.29200000,0.08350856,206.04390307,0.08020444,223.25033180,0.00079880,0.08404956,228.75744011,-0.04592604,-0.03812352,0.00000000,0.00000000,0.00000000,0.00000000
114.62000000,2.54368500,2.29800000,0.08472467,206.58328501,0.08132619,224.08598498,0.00074995,0.08513784,229.59845839,-0.04649406,-0.03864377,0.00000000,0.00000000,0.00000000,0.00000000
116.12000000,2.57974100,2.30500000,0.08587356,207.21256395,0.08238478,225.00664357,0.00064597,0.08626915,230.45100393,-0.04710131,-0.03916784,0.00000000,0.00000000,0.00000000,0.00000000
117.62000000,2.61646900,2.31200000,0.08713433,207.84184289,0.08354518,225.95200330,0.00072068,0.08739364,231.20487446,-0.04775354,-0.03964009,0.00000000,0.00000000,0.00000000,0.00000000
119.12000000,2.65272700,2.31800000,0.08836533,208.38122483,0.08467688,226.79490122,0.00080892,0.08850190,232.05524813,-0.04840170,-0.04010020,0.00000000,0.00000000,0.00000000,0.00000000
120.62000000,2.68938800,2.32400000,0.08957400,208.92060678,0.08578679,227.63446121,0.00078089,0.08960352,232.80671870,-0.04897140,-0.04063212,0.00000000,0.00000000,0.00000000,0.00000000
122.12000000,2.72591400,2.33000000,0.09078622,209.45998872,0.08689874,228.47606980,0.00076616,0.09072961,233.66439964,-0.04957681,-0.04115281,0.00000000,0.00000000,0.00000000,0.00000000
123.62000000,2.76294400,2.33600000,0.09201356,209.99937067,0.08802329,229.32215943,0.00077914,0.09186253,234.42614383,-0.05024119,-0.04162134,0.00000000,0.00000000,0.00000000,0.00000000
125.12000000,2.79906800,2.34200000,0.09323700,210.53875261,0.08914302,230.16875429,0.00080531,0.09298739,235.18742803,-0.05084311,-0.04214428,0.00000000,0.00000000,0.00000000,0.00000000
126.62000000,2.83636700,2.34800000,0.09446433,211.07813456,0.09026505,231.01748982,0.00073637,0.09409065,235.94503152,-0.05143405,-0.04265661,0.00000000,0.00000000,0.00000000,0.00000000
128.12000000,2.87366500,2.35300000,0.09571022,211.52761951,0.09140276,231.77297498,0.00076961,0.09521624,236.70933893,-0.05206624,-0.04315000,0.00000000,0.00000000,0.00000000,0.00000000
129.62000000,2.91093000,2.35900000,0.09697844,212.06700146,0.09255953,232.63292938,0.00082304,0.09633050,237.47238479,-0.05265129,-0.04367921,0.00000000,0.00000000,0.00000000,0.00000000
131.12000000,2.94765800,2.36400000,0.09817589,212.51648641,0.09365052,233.38048137,0.00074744,0.09745490,238.13950868,-0.05328330,-0.04417159,0.00000000,0.00000000,0.00000000,0.00000000
132.62000000,2.98515800,2.36900000,0.09938444,212.96597137,0.09475043,234.13147612,0.00070577,0.09858659,238.90947581,-0.05392006,-0.04466653,0.00000000,0.00000000,0.00000000,0.00000000
134.12000000,3.02205400,2.37500000,0.10065644,213.50535331,0.09590677,234.99604305,0.00074575,0.09969699,239.67577514,-0.05449184,-0.04520515,0.00000000,0.00000000,0.00000000,0.00000000
135.62000000,3.05911800,2.37900000,0.10190611,213.86494127,0.09704151,235.65908574,0.00071102,0.10083086,240.34905284,-0.05510314,-0.04572773,0.00000000,0.00000000,0.00000000,0.00000000
137.12000000,3.09685200,2.38400000,0.10313333,214.31442623,0.09815462,236.41738739,0.00068987,0.10192863,241.11505028,-0.05566683,-0.04626180,0.00000000,0.00000000,0.00000000,0.00000000
138.62000000,3.13415100,2.38900000,0.10438300,214.76391118,0.09928681,237.18161252,0.00070942,0.10308340,241.79595270,-0.05631867,-0.04676473,0.00000000,0.00000000,0.00000000,0.00000000
140.12000000,3.17192000,2.39400000,0.10564000,215.21339614,0.10042435,237.94853931,0.00078964,0.10422000,242.47369756,-0.05692571,-0.04729429,0.00000000,0.00000000,0.00000000,0.00000000
141.62000000,3.20972200,2.39800000,0.10685989,215.57298410,0.10152708,238.60908923,0.00070803,0.10535538,243.15238408,-0.05755704,-0.04779835,0.00000000,0.00000000,0.00000000,0.00000000
143.12000000,3.24708800,2.40400000,0.10810200,216.11236605,0.10264864,239.47454504,0.00069360,0.10649608,243.83361435,-0.05816262,-0.04833347,0.00000000,0.00000000,0.00000000,0.00000000
144.62000000,3.28532600,2.40800000,0.10939633,216.47195401,0.10381602,240.15319205,0.00078697,0.10762871,244.51411425,-0.05877502,-0.04885369,0.00000000,0.00000000,0.00000000,0.00000000
146.12000000,3.32329600,2.41200000,0.11065722,216.83154197,0.10495193,240.82551810,0.00079949,0.10875349,245.19392435,-0.05941225,-0.04934124,0.00000000,0.00000000,0.00000000,0.00000000
147.62000000,3.36143400,2.41700000,0.11195156,217.28102693,0.10611663,241.60597588,0.00081195,0.10990010,245.88035434,-0.06004713,-0.04985297,0.00000000,0.00000000,0.00000000,0.00000000
149.12000000,3.39933700,2.42100000,0.11322356,217.64061489,0.10725991,242.28265914,0.00083119,0.11106012,246.47020769,-0.06068067,-0.05037945,0.00000000,0.00000000,0.00000000,0.00000000
150.62000000,3.43737400,2.42500000,0.11450678,218.00020285,0.10841196,242.96270364,0.00081009,0.11220413,247.15841288,-0.06132237,-0.05088176,0.00000000,0.00000000,0.00000000,0.00000000
152.12000000,3.47645200,2.42900000,0.11576756,218.35979082,0.10954256,243.63877003,0.00076235,0.11333817,247.74401229,-0.06190172,-0.05143645,0.00000000,0.00000000,0.00000000,0.00000000
153.62000000,3.51428700,2.43300000,0.11703956,218.71937878,0.11068193,244.31819767,0.00074138,0.11445638,248.42819392,-0.06254964,-0.05190674,0.00000000,0.00000000,0.00000000,0.00000000
155.12000000,3.55306300,2.43600000,0.11834889,218.98906975,0.11185339,244.90618284,0.00076735,0.11555488,249.00706064,-0.06310433,-0.05245054,0.00000000,0.00000000,0.00000000,0.00000000
156.62000000,3.59210800,2.44100000,0.11963211,219.43855471,0.11300016,245.69045227,0.00072636,0.11672651,249.70696751,-0.06379940,-0.05292711,0.00000000,0.00000000,0.00000000,0.00000000
158.12000000,3.63101800,2.44400000,0.12091156,219.70824568,0.11414224,246.27351143,0.00073882,0.11787846,250.30137813,-0.06441574,-0.05346272,0.00000000,0.00000000,0.00000000,0.00000000
159.62000000,3.66952500,2.44800000,0.12220222,220.06783364,0.11529302,246.96061196,0.00076471,0.11896323,250.87992229,-0.06498614,-0.05397709,0.00000000,0.00000000,0.00000000,0.00000000
161.12000000,3.70809900,2.45100000,0.12346300,220.33752462,0.11641588,247.54105642,0.00075040,0.12014209,251.48318213,-0.06562887,-0.05451323,0.00000000,0.00000000,0.00000000,0.00000000
162.62000000,3.74747900,2.45500000,0.12477978,220.69711258,0.11758726,248.23564924,0.00075624,0.12129990,252.08219725,-0.06628254,-0.05501735,0.00000000,0.00000000,0.00000000,0.00000000
164.12000000,3.78625500,2.45800000,0.12602944,220.96680355,0.11869768,248.81512705,0.00068255,0.12246277,252.68355825,-0.06687320,-0.05558958,0.00000000,0.00000000,0.00000000,0.00000000
165.62000000,3.82509800,2.46200000,0.12729022,221.32639152,0.11981672,249.49907708,0.00070821,0.12360467,253.28065440,-0.06749735,-0.05610732,0.00000000,0.00000000,0.00000000,0.00000000
167.12000000,3.86400700,2.46500000,0.12858467,221.59608249,0.12096434,250.08994089,0.00072730,0.12483356,253.90095883,-0.06816878,-0.05666478,0.00000000,0.00000000,0.00000000,0.00000000
168.62000000,3.90372300,2.46800000,0.12988644,221.86577346,0.12211714,250.68312992,0.00077919,0.12604127,254.51700382,-0.06882823,-0.05721304,0.00000000,0.00000000,0.00000000,0.00000000
170.12000000,3.94300200,2.47100000,0.13120700,222.13546443,0.12328520,251.28119232,0.00075863,0.12722465,255.12795045,-0.06946469,-0.05775997,0.00000000,0.00000000,0.00000000,0.00000000
171.62000000,3.98325600,2.47400000,0.13254989,222.40515541,0.12447163,251.88493404,0.00088296,0.12843746,255.64458848,-0.07014161,-0.05829585,0.00000000,0.00000000,0.00000000,0.00000000
173.12000000,4.02236700,2.47700000,0.13382189,222.67484638,0.12559413,252.47361493,0.00075021,0.12963423,256.26107365,-0.07079406,-0.05884017,0.00000000,0.00000000,0.00000000,0.00000000
174.62000000,4.06275400,2.48000000,0.13522444,222.94453735,0.12683038,253.09208856,0.00081508,0.13079848,256.76708735,-0.07144175,-0.05935673,0.00000000,0.00000000,0.00000000,0.00000000
176.12000000,4.10247000,2.48300000,0.13656356,223.21422832,0.12800928,253.69715700,0.00082058,0.13195671,257.37570914,-0.07205846,-0.05989825,0.00000000,0.00000000,0.00000000,0.00000000
177.62000000,4.14346100,2.48600000,0.13792878,223.48391930,0.12920975,254.30878314,0.00083268,0.13309233,257.87610793,-0.07265696,-0.06043536,0.00000000,0.00000000,0.00000000,0.00000000
179.12000000,4.18405000,2.48800000,0.13932022,223.66371328,0.13043179,254.82459152,0.00074659,0.13422336,258.37612716,-0.07329705,-0.06092631,0.00000000,0.00000000,0.00000000,0.00000000
180.62000000,4.22467200,2.49100000,0.14071156,223.93340425,0.13165224,255.44342190,0.00083727,0.13526752,258.95805751,-0.07380712,-0.06146040,0.00000000,0.00000000,0.00000000,0.00000000
182.12000000,4.26542800,2.49400000,0.14208433,224.20309522,0.13285496,256.05884254,0.00081680,0.13637988,259.45490530,-0.07444636,-0.06193352,0.00000000,0.00000000,0.00000000,0.00000000
183.62000000,4.30648600,2.49700000,0.14338989,224.47278620,0.13399744,256.65991407,0.00076357,0.13743945,259.93877227,-0.07503477,-0.06240468,0.00000000,0.00000000,0.00000000,0.00000000
185.12000000,4.34663900,2.49900000,0.14473644,224.65258018,0.13517443,257.16799587,0.00072344,0.13849779,260.42305548,-0.07558998,-0.06290781,0.00000000,0.00000000,0.00000000,0.00000000
186.62000000,4.38716000,2.50100000,0.14609056,224.83237416,0.13635663,257.67826061,0.00084653,0.13957606,261.01742649,-0.07617902,-0.06339705,0.00000000,0.00000000,0.00000000,0.00000000
188.12000000,4.42771500,2.50400000,0.14731778,225.10206513,0.13742685,258.26360114,0.00077394,0.14069965,261.52043889,-0.07678862,-0.06391103,0.00000000,0.00000000,0.00000000,0.00000000
189.62000000,4.46827000,2.50600000,0.14861589,225.28185911,0.13855764,258.76232286,0.00070803,0.14183803,262.02814951,-0.07739083,-0.06444720,0.00000000,0.00000000,0.00000000,0.00000000
191.12000000,4.50818700,2.50800000,0.14989911,225.46165310,0.13967421,259.25815449,0.00074629,0.14304711,262.45082151,-0.07805758,-0.06498953,0.00000000,0.00000000,0.00000000,0.00000000
192.62000000,4.54897700,2.51000000,0.15111144,225.64144708,0.14072795,259.73845207,0.00077138,0.14433344,262.99914755,-0.07875436,-0.06557907,0.00000000,0.00000000,0.00000000,0.00000000
194.12000000,4.58872600,2.51300000,0.15232744,225.91113805,0.14178376,260.32360438,0.00070575,0.14565651,263.55817691,-0.07946298,-0.06619353,0.00000000,0.00000000,0.00000000,0.00000000
195.62000000,4.62955000,2.51500000,0.15365544,226.09093203,0.14293555,260.83103468,0.00084098,0.14707368,264.14317936,-0.08024236,-0.06683131,0.00000000,0.00000000,0.00000000,0.00000000
197.12000000,4.66997000,2.51700000,0.15489756,226.27072601,0.14401164,261.31950837,0.00079465,0.14855093,264.64021030,-0.08103412,-0.06751681,0.00000000,0.00000000,0.00000000,0.00000000
198.62000000,4.71159900,2.51900000,0.15619944,226.45052000,0.14513829,261.82196541,0.00080683,0.15005953,265.25171566,-0.08184466,-0.06821488,0.00000000,0.00000000,0.00000000,0.00000000
200.12000000,4.75322800,2.52100000,0.15762056,226.63031398,0.14636665,262.35190997,0.00087651,0.15162142,265.77329076,-0.08270387,-0.06891755,0.00000000,0.00000000,0.00000000,0.00000000
201.62000000,4.79546200,2.52300000,0.15907911,226.81010796,0.14762582,262.89085832,0.00084971,0.15311265,266.38252983,-0.08349461,-0.06961804,0.00000000,0.00000000,0.00000000,0.00000000
203.12000000,4.83813200,2.52400000,0.16060478,226.90000495,0.14894123,263.34122982,0.00093230,0.15453814,266.97538363,-0.08424040,-0.07029774,0.00000000,0.00000000,0.00000000,0.00000000
204.62000000,4.88137200,2.52600000,0.16221244,227.07979893,0.15032547,263.91496820,0.00091169,0.15593144,267.45488852,-0.08500687,-0.07092457,0.00000000,0.00000000,0.00000000,0.00000000
206.12000000,4.92484800,2.52800000,0.16388733,227.25959291,0.15176555,264.50456157,0.00093597,0.15716308,267.99773509,-0.08561970,-0.07154337,0.00000000,0.00000000,0.00000000,0.00000000
207.62000000,4.96949800,2.53000000,0.16562933,227.43938690,0.15326114,265.11002092,0.00095384,0.15829988,268.40984148,-0.08623188,-0.07206800,0.00000000,0.00000000,0.00000000,0.00000000
209.12000000,5.01394800,2.53100000,0.16741244,227.52928389,0.15478971,265.62051748,0.00095886,0.15930761,268.89393824,-0.08679866,-0.07250895,0.00000000,0.00000000,0.00000000,0.00000000
210.62000000,5.05896800,2.53300000,0.16924022,227.70907787,0.15635416,266.24661281,0.00108495,0.16022120,269.24696619,-0.08727768,-0.07294352,0.00000000,0.00000000,0.00000000,0.00000000
212.12000000,5.10402100,2.53400000,0.17095611,227.79897486,0.15782060,266.74260172,0.00101956,0.16107086,269.58311924,-0.08779054,-0.07328032,0.00000000,0.00000000,0.00000000,0.00000000
213.62000000,5.15008200,2.53600000,0.17259744,227.97876884,0.15922133,267.32732173,0.00089091,0.16182535,269.89386460,-0.08821914,-0.07360621,0.00000000,0.00000000,0.00000000,0.00000000
215.12000000,5.19540400,2.53700000,0.17412678,228.06866583,0.16052470,267.78152772,0.00082613,0.16251637,270.18771351,-0.08862409,-0.07389228,0.00000000,0.00000000,0.00000000,0.00000000
216.62000000,5.24005500,2.53900000,0.17546967,228.24845981,0.16166778,268.29914097,0.00069828,0.16317544,270.47316520,-0.08896737,-0.07420807,0.00000000,0.00000000,0.00000000,0.00000000
218.12000000,5.28403500,2.54000000,0.17670067,228.33835680,0.16271448,268.68589668,0.00069755,0.16380261,270.75020961,-0.08931049,-0.07449212,0.00000000,0.00000000,0.00000000,0.00000000
219.62000000,5.32878600,2.54100000,0.17785700,228.42825380,0.16369669,269.05581773,0.00057004,0.16436512,271.11667260,-0.08961566,-0.07474945,0.00000000,0.00000000,0.00000000,0.00000000
221.12000000,5.37209400,2.54300000,0.17890156,228.60804778,0.16458312,269.50638314,0.00056973,0.16502294,271.40260382,-0.09000348,-0.07501946,0.00000000,0.00000000,0.00000000,0.00000000
222.62000000,5.41550300,2.54400000,0.17987133,228.69794477,0.16540539,269.83414902,0.00056907,0.16564903,271.68013980,-0.09038859,-0.07526044,0.00000000,0.00000000,0.00000000,0.00000000
224.12000000,5.45733400,2.54500000,0.18069200,228.78784176,0.16610071,270.12797446,0.00050561,0.16630450,272.07291923,-0.09079960,-0.07550490,0.00000000,0.00000000,0.00000000,0.00000000
225.62000000,5.49886200,2.54600000,0.18147533,228.87773875,0.16676394,270.41340268,0.00037885,0.16699388,272.26126799,-0.09119791,-0.07579597,0.00000000,0.00000000,0.00000000,0.00000000
227.12000000,5.54015500,2.54700000,0.18222133,228.96763574,0.16739515,270.69042361,0.00037861,0.16786913,272.60773839,-0.09176390,-0.07610524,0.00000000,0.00000000,0.00000000,0.00000000
228.62000000,5.58111300,2.54900000,0.18296744,229.14742972,0.16802607,271.07394934,0.00037856,0.16883740,272.98009599,-0.09240142,-0.07643598,0.00000000,0.00000000,0.00000000,0.00000000
230.12000000,5.62113100,2.55000000,0.18367611,229.23732671,0.16862494,271.34274740,0.00050414,0.17018092,273.34851363,-0.09328732,-0.07689359,0.00000000,0.00000000,0.00000000,0.00000000
231.62000000,5.65967200,2.55100000,0.18438489,229.32722370,0.16922356,271.61169837,0.00037792,0.17195895,273.83685332,-0.09451662,-0.07744234,0.00000000,0.00000000,0.00000000,0.00000000
233.12000000,5.69821200,2.55200000,0.18524289,229.41712069,0.16994772,271.91501089,0.00050366,0.17435742,274.38912983,-0.09597945,-0.07837797,0.00000000,0.00000000,0.00000000,0.00000000
234.62000000,5.73544300,2.55300000,0.18602622,229.50701769,0.17060841,272.20134116,0.00044036,0.17715028,275.26767455,-0.09709430,-0.08005598,0.00000000,0.00000000,0.00000000,0.00000000
236.12000000,5.77344700,2.55400000,0.18699611,229.59691468,0.17142584,272.53064484,0.00062858,0.18036947,276.15870625,-0.09806451,-0.08230496,0.00000000,0.00000000,0.00000000,0.00000000
237.62000000,5.81289500,2.55500000,0.18804067,229.68681167,0.17230545,272.87727286,0.00062802,0.18382477,277.11831223,-0.09904254,-0.08478223,0.00000000,0.00000000,0.00000000,0.00000000
239.12000000,5.85489400,2.55500000,0.18949556,229.68681167,0.17352931,273.21144165,0.00087844,0.18745063,278.23817389,-0.10041015,-0.08704049,0.00000000,0.00000000,0.00000000,0.00000000
240.62000000,5.89927600,2.55500000,0.19139789,229.68681167,0.17512731,273.64838253,0.00119018,0.19100208,279.34166357,-0.10265394,-0.08834813,0.00000000,0.00000000,0.00000000,0.00000000
242.12000000,5.94567200,2.55400000,0.19393433,229.59691468,0.17725402,274.12363926,0.00156277,0.19405340,280.30872383,-0.10509365,-0.08895975,0.00000000,0.00000000,0.00000000,0.00000000
243.62000000,5.99606400,2.55400000,0.19732878,229.59691468,0.18009306,274.90299323,0.00199488,0.19569792,280.77190733,-0.10637275,-0.08932516,0.00000000,0.00000000,0.00000000,0.00000000
245.12000000,6.04669100,2.55500000,0.20094711,229.68681167,0.18311050,275.84171293,0.00211334,0.19666966,281.15626833,-0.10699903,-0.08967063,0.00000000,0.00000000,0.00000000,0.00000000
246.62000000,6.09950000,2.55500000,0.20508767,229.68681167,0.18655232,276.79274394,0.00229197,0.19727753,281.32790850,-0.10737512,-0.08990242,0.00000000,0.00000000,0.00000000,0.00000000
248.12000000,6.15334900,2.55600000,0.20945200,229.77670866,0.19016736,277.90389984,0.00240713,0.19782426,281.48237188,-0.10766119,-0.09016307,0.00000000,0.00000000,0.00000000,0.00000000
249.62000000,6.20689700,2.55700000,0.21381633,229.86660565,0.19376939,279.01584042,0.00239847,0.19827965,281.61109562,-0.10794987,-0.09032978,0.00000000,0.00000000,0.00000000,0.00000000
251.12000000,6.26121700,2.55800000,0.21788233,229.95650264,0.19711356,280.05996200,0.00214531,0.19861346,281.70549133,-0.10810437,-0.09050909,0.00000000,0.00000000,0.00000000,0.00000000
252.62000000,6.31681300,2.55800000,0.22049344,229.95650264,0.19925524,280.66040398,0.00103938,0.19894561,281.91000813,-0.10829045,-0.09065516,0.00000000,0.00000000,0.00000000,0.00000000
254.12000000,6.37160100,2.55900000,0.22179900,230.04639963,0.20032436,281.07046102,0.00054954,0.19918816,281.97866546,-0.10839834,-0.09078982,0.00000000,0.00000000,0.00000000,0.00000000
255.62000000,6.42719500,2.55900000,0.22269422,230.04639963,0.20105680,281.27640367,0.00048805,0.19942918,282.15752310,-0.10851738,-0.09091180,0.00000000,0.00000000,0.00000000,0.00000000
257.12000000,6.48245500,2.55900000,0.22336567,230.04639963,0.20160580,281.43086705,0.00036587,0.19967015,282.33643441,-0.10864074,-0.09102941,0.00000000,0.00000000,0.00000000,0.00000000
258.62000000,6.53707700,2.55900000,0.22392522,230.04639963,0.20206309,281.55959079,0.00024386,0.19988073,282.50679755,-0.10876229,-0.09111843,0.00000000,0.00000000,0.00000000,0.00000000
260.12000000,6.59576000,2.55900000,0.22444744,230.04639963,0.20248968,281.67972613,0.00018277,0.20012158,282.68581281,-0.10891403,-0.09120755,0.00000000,0.00000000,0.00000000,0.00000000
261.62000000,6.65189300,2.56000000,0.22478322,230.13629662,0.20276387,281.86707493,0.00006096,0.20033206,282.85627320,-0.10904779,-0.09128427,0.00000000,0.00000000,0.00000000,0.00000000
263.12000000,6.70805900,2.56000000,0.22519356,230.13629662,0.20309884,281.96150752,0.00024360,0.00000000,0.00000000,0.00000000,0.00000000,0.00000000,0.00000000,0.00000000,0.00000000
264.62000000,6.76392300,2.56000000,0.22549200,230.13629662,0.20334240,282.03019042,0.00018261,0.00000000,0.00000000,0.00000000,0.00000000,0.00000000,0.00000000,0.00000000,0.00000000
266.12000000,6.81246700,2.56100000,0.22575311,230.22619361,0.20355544,282.20047308,0.00012183,0.00000000,0.00000000,0.00000000,0.00000000,0.00000000,0.00000000,0.00000000,0.00000000
267.62000000,6.84493100,2.56300000,0.22608889,230.40598759,0.20382934,282.49822132,0.00018270,0.00000000,0.00000000,0.00000000,0.00000000,0.00000000,0.00000000,0.00000000,0.00000000
269.12000000,6.86530900,2.56400000,0.22631267,230.49588458,0.20401183,282.66002288,0.00006089,0.00000000,0.00000000,0.00000000,0.00000000,0.00000000,0.00000000,0.00000000,0.00000000
270.62000000,6.88323800,2.56500000,0.22653644,230.58578158,0.20419430,282.82186467,0.00006070,0.00000000,0.00000000,0.00000000,0.00000000,0.00000000,0.00000000,0.00000000,0.00000000
272.12000000,6.90308100,2.56700000,0.22687222,230.76557556,0.20446802,283.11987450,0.00018241,0.00000000,0.00000000,0.00000000,0.00000000,0.00000000,0.00000000,0.00000000,0.00000000
273.62000000,6.93393400,2.56500000,0.22705867,230.58578158,0.00000000,0.00000000,0.00000000,0.00000000,0.00000000,0.00000000,0.00000000,0.00000000,0.00000000,0.00000000,0.00000000
275.12000000,6.97989400,2.56100000,0.22728244,230.22619361,0.00000000,0.00000000,0.00000000,0.00000000,0.00000000,0.00000000,0.00000000,0.00000000,0.00000000,0.00000000,0.00000000
276.62000000,7.03206200,2.55900000,0.22750633,230.04639963,0.00000000,0.00000000,0.00000000,0.00000000,0.00000000,0.00000000,0.00000000,0.00000000,0.00000000,0.00000000,0.00000000
278.12000000,7.08631500,2.55700000,0.22761833,229.86660565,0.00000000,0.00000000,0.00000000,0.00000000,0.00000000,0.00000000,0.00000000,0.00000000,0.00000000,0.00000000,0.00000000
279.62000000,7.14238300,2.55400000,0.22780478,229.59691468,0.00000000,0.00000000,0.00000000,0.00000000,0.00000000,0.00000000,0.00000000,0.00000000,0.00000000,0.00000000,0.00000000
281.12000000,7.19831600,2.55300000,0.22795389,229.50701769,0.00000000,0.00000000,0.00000000,0.00000000,0.00000000,0.00000000,0.00000000,0.00000000,0.00000000,0.00000000,0.00000000
282.62000000,7.25303700,2.55100000,0.22802856,229.32722370,0.00000000,0.00000000,0.00000000,0.00000000,0.00000000,0.00000000,0.00000000,0.00000000,0.00000000,0.00000000,0.00000000
284.12000000,7.31091300,2.54800000,0.22810311,229.05753273,0.00000000,0.00000000,0.00000000,0.00000000,0.00000000,0.00000000,0.00000000,0.00000000,0.00000000,0.00000000,0.00000000
285.62000000,7.36939400,2.54200000,0.22817778,228.51815079,0.00000000,0.00000000,0.00000000,0.00000000,0.00000000,0.00000000,0.00000000,0.00000000,0.00000000,0.00000000,0.00000000
287.12000000,7.42680300,2.53800000,0.22825233,228.15856282,0.00000000,0.00000000,0.00000000,0.00000000,0.00000000,0.00000000,0.00000000,0.00000000,0.00000000,0.00000000,0.00000000
288.62000000,7.48374300,2.53300000,0.22828967,227.70907787,0.00000000,0.00000000,0.00000000,0.00000000,0.00000000,0.00000000,0.00000000,0.00000000,0.00000000,0.00000000,0.00000000
290.12000000,7.54212400,2.52500000,0.22836422,226.98990194,0.00000000,0.00000000,0.00000000,0.00000000,0.00000000,0.00000000,0.00000000,0.00000000,0.00000000,0.00000000,0.00000000
291.62000000,7.60080800,2.51600000,0.22836422,226.18082902,0.00000000,0.00000000,0.00000000,0.00000000,0.00000000,0.00000000,0.00000000,0.00000000,0.00000000,0.00000000,0.00000000
293.12000000,7.66006500,2.50100000,0.22832689,224.83237416,0.00000000,0.00000000,0.00000000,0.00000000,0.00000000,0.00000000,0.00000000,0.00000000,0.00000000,0.00000000,0.00000000
294.62000000,7.71925700,2.48300000,0.22836422,223.21422832,0.00000000,0.00000000,0.00000000,0.00000000,0.00000000,0.00000000,0.00000000,0.00000000,0.00000000,0.00000000,0.00000000
296.12000000,7.78073300,2.45500000,0.22828978,220.69711258,0.00000000,0.00000000,0.00000000,0.00000000,0.00000000,0.00000000,0.00000000,0.00000000,0.00000000,0.00000000,0.00000000
297.62000000,7.84412500,2.41700000,0.22821567,217.28102693,0.00000000,0.00000000,0.00000000,0.00000000,0.00000000,0.00000000,0.00000000,0.00000000,0.00000000,0.00000000,0.00000000
299.12000000,7.91000500,2.36200000,0.22810522,212.33669243,0.00000000,0.00000000,0.00000000,0.00000000,0.00000000,0.00000000,0.00000000,0.00000000,0.00000000,0.00000000,0.00000000
300.62000000,7.97904800,2.28300000,0.22792133,205.23483015,0.00000000,0.00000000,0.00000000,0.00000000,0.00000000,0.00000000,0.00000000,0.00000000,0.00000000,0.00000000,0.00000000
302.12000000,8.16713300,1.55600000,0.22554056,139.87971779,0.00000000,0.00000000,0.00000000,0.00000000,0.00000000,0.00000000,0.00000000,0.00000000,0.00000000,0.00000000,0.00000000
303.62000000,8.38691900,0.01100000,0.22332844,0.98886690,0.00000000,0.00000000,0.00000000,0.00000000,0.00000000,0.00000000,0.00000000,0.00000000,0.00000000,0.00000000,0.00000000
NaN,-100.00000000,NaN,-11.11111111,NaN,0.00000000,0.00000000,0.00000000,0.00000000,0.00000000,0.00000000,0.00000000,0.00000000,0.00000000,0.00000000,0.00000000