File: polyN_optimization/results_exp/AA6014-T4/UT_90_2.csv
Time[s],Displacement[mm],Force[kN],EngStrain_longi,EngStress[MPa],TrueStrain,TrueStress[MPa],TrueStrainRate[1/s],PlasticStrain_longi,PlasticStress[MPa],PlasticStrain_thick,PlasticStrain_width,R-Value,Thickness[mm],Width[mm], Young's Modulus [MPa]
0.61000000,0.00000000,-0.00100000,0.00000000,-0.08924454,0.00000000,-0.08924454,0.00000000,0.00054299,115.10657052,0.00008501,-0.00062801,0.81212209,1.11050000,10.09020000,78681.24006622
2.12000000,0.00652700,0.17800000,0.00020656,15.88552838,0.00020653,15.88880963,0.00021957,0.00185497,118.21819358,-0.00066281,-0.00119216,0.00000000,0.00000000,0.00000000,0.00000000
3.62000000,0.01468100,0.41800000,0.00047633,37.30421834,0.00047622,37.32198758,0.00017481,0.00307208,121.50618213,-0.00138763,-0.00168445,0.00000000,0.00000000,0.00000000,0.00000000
5.12000000,0.02339000,0.65500000,0.00078600,58.45517467,0.00078569,58.50112043,0.00033998,0.00424170,124.43661764,-0.00199274,-0.00224896,0.00000000,0.00000000,0.00000000,0.00000000
6.62000000,0.03238700,0.91700000,0.00106867,81.83724453,0.00106810,81.92470127,0.00031302,0.00542287,127.37546154,-0.00263921,-0.00278366,0.00000000,0.00000000,0.00000000,0.00000000
8.12000000,0.04296600,1.14500000,0.00133689,102.18499999,0.00133600,102.32160998,0.00023903,0.00669105,129.88181411,-0.00339793,-0.00329313,0.00000000,0.00000000,0.00000000,0.00000000
9.62000000,0.06826600,1.28700000,0.00216656,114.85772488,0.00216421,115.10657052,0.00050852,0.00784703,132.28933387,-0.00396837,-0.00387866,0.00000000,0.00000000,0.00000000,0.00000000
11.11000000,0.10761900,1.32000000,0.00352622,117.80279475,0.00352002,118.21819358,0.00089681,0.00903420,134.70662357,-0.00465223,-0.00438197,0.00000000,0.00000000,0.00000000,0.00000000
12.62000000,0.14448400,1.35500000,0.00479489,120.92635370,0.00478343,121.50618213,0.00096782,0.01018423,136.94351659,-0.00524878,-0.00493544,0.00000000,0.00000000,0.00000000,0.00000000
14.11000000,0.18128200,1.38600000,0.00601233,123.69293449,0.00599433,124.43661764,0.00093248,0.01135824,139.09824795,-0.00593191,-0.00542633,0.00000000,0.00000000,0.00000000,0.00000000
15.62000000,0.21877900,1.41700000,0.00724300,126.45951527,0.00721690,127.37546154,0.00084009,0.01249275,141.34311799,-0.00654582,-0.00594692,0.00000000,0.00000000,0.00000000,0.00000000
17.11000000,0.25535600,1.44300000,0.00855678,128.77987335,0.00852038,129.88181411,0.00094481,0.01361746,143.40996946,-0.00717838,-0.00643908,0.00000000,0.00000000,0.00000000,0.00000000
18.61000000,0.29223500,1.46800000,0.00975756,131.01098689,0.00971026,132.28933387,0.00084769,0.01474926,145.39150425,-0.00783081,-0.00691844,0.00000000,0.00000000,0.00000000,0.00000000
20.11000000,0.32987200,1.49300000,0.01099144,133.24210042,0.01093148,134.70662357,0.00083390,0.01590279,147.56276996,-0.00850126,-0.00740154,0.00000000,0.00000000,0.00000000,0.00000000
21.61000000,0.36542100,1.51600000,0.01218667,135.29472488,0.01211301,136.94351659,0.00073276,0.01700260,149.54860816,-0.00907988,-0.00792272,0.00000000,0.00000000,0.00000000,0.00000000
23.11000000,0.40177300,1.53800000,0.01340644,137.25810479,0.01331737,139.09824795,0.00080997,0.01813288,151.36084322,-0.00971211,-0.00842077,0.00000000,0.00000000,0.00000000,0.00000000
24.61000000,0.43746300,1.56100000,0.01458889,139.31072924,0.01448349,141.34311799,0.00077967,0.01923241,153.44647373,-0.01029688,-0.00893553,0.00000000,0.00000000,0.00000000,0.00000000
26.11000000,0.47302600,1.58200000,0.01576022,141.18486461,0.01563732,143.40996946,0.00076411,0.02036480,155.17583352,-0.01095433,-0.00941047,0.00000000,0.00000000,0.00000000,0.00000000
27.61000000,0.50852900,1.60200000,0.01693889,142.96975544,0.01679703,145.39150425,0.00065283,0.02146918,156.99618027,-0.01156060,-0.00990857,0.00000000,0.00000000,0.00000000,0.00000000
29.11000000,0.54435700,1.62400000,0.01814378,144.93313536,0.01798114,147.56276996,0.00076210,0.02256359,158.91055752,-0.01214844,-0.01041515,0.00000000,0.00000000,0.00000000,0.00000000
30.61000000,0.57915400,1.64400000,0.01929267,146.71802619,0.01910892,149.54860816,0.00073921,0.02369189,160.65090726,-0.01276751,-0.01092438,0.00000000,0.00000000,0.00000000,0.00000000
32.11000000,0.61424300,1.66200000,0.02047144,148.32442793,0.02026472,151.36084322,0.00066538,0.02479346,162.39071800,-0.01336150,-0.01143196,0.00000000,0.00000000,0.00000000,0.00000000
33.61000000,0.64895700,1.68300000,0.02162411,150.19856330,0.02139363,153.44647373,0.00067819,0.02589145,164.04165509,-0.01395426,-0.01193719,0.00000000,0.00000000,0.00000000,0.00000000
35.11000000,0.68389900,1.70000000,0.02280656,151.71572051,0.02255037,155.17583352,0.00079651,0.02699050,165.78839231,-0.01457631,-0.01241419,0.00000000,0.00000000,0.00000000,0.00000000
36.61000000,0.71873600,1.71800000,0.02396300,153.32212226,0.02368039,156.99618027,0.00075861,0.02807502,167.44419853,-0.01516796,-0.01290707,0.00000000,0.00000000,0.00000000,0.00000000
38.11000000,0.75322100,1.73700000,0.02511189,155.01776854,0.02480177,158.91055752,0.00073541,0.02917267,169.10570410,-0.01578693,-0.01338574,0.00000000,0.00000000,0.00000000,0.00000000
39.62000000,0.78790100,1.75400000,0.02629433,156.53492575,0.02595458,160.65090726,0.00074122,0.03029916,170.68324065,-0.01643559,-0.01386357,0.00000000,0.00000000,0.00000000,0.00000000
41.12000000,0.82278300,1.77100000,0.02745067,158.05208295,0.02708065,162.39071800,0.00075519,0.03134511,172.25027913,-0.01699202,-0.01435308,0.00000000,0.00000000,0.00000000,0.00000000
42.62000000,0.85756300,1.78700000,0.02860333,159.47999562,0.02820190,164.04165509,0.00072536,0.03243431,173.73537805,-0.01760937,-0.01482494,0.00000000,0.00000000,0.00000000,0.00000000
44.12000000,0.89190700,1.80400000,0.02975978,160.99715282,0.02932555,165.78839231,0.00073925,0.03354840,175.41343523,-0.01825747,-0.01529093,0.00000000,0.00000000,0.00000000,0.00000000
45.62000000,0.92611700,1.82000000,0.03090122,162.42506549,0.03043339,167.44419853,0.00074555,0.03464582,176.90643126,-0.01885414,-0.01579168,0.00000000,0.00000000,0.00000000,0.00000000
47.12000000,0.96059600,1.83600000,0.03205756,163.85297815,0.03155444,169.10570410,0.00076559,0.03572402,178.39912104,-0.01943552,-0.01628850,0.00000000,0.00000000,0.00000000,0.00000000
48.62000000,0.99557800,1.85100000,0.03324378,165.19164627,0.03270315,170.68324065,0.00080174,0.03680811,179.89595068,-0.02003772,-0.01677040,0.00000000,0.00000000,0.00000000,0.00000000
50.12000000,1.02938500,1.86600000,0.03434789,166.53031439,0.03377117,172.25027913,0.00071438,0.03788875,181.30208469,-0.02062583,-0.01726292,0.00000000,0.00000000,0.00000000,0.00000000
51.62000000,1.06376200,1.88000000,0.03549678,167.77973797,0.03488129,173.73537805,0.00073494,0.03898457,182.80716001,-0.02121690,-0.01776768,0.00000000,0.00000000,0.00000000,0.00000000
53.12000000,1.09824100,1.89600000,0.03667556,169.20765064,0.03601901,175.41343523,0.00074847,0.04007473,184.12757858,-0.02182937,-0.01824536,0.00000000,0.00000000,0.00000000,0.00000000
54.62000000,1.13251800,1.91000000,0.03783567,170.45707422,0.03713745,176.90643126,0.00078362,0.04113728,185.53905516,-0.02239800,-0.01873928,0.00000000,0.00000000,0.00000000,0.00000000
56.12000000,1.16733200,1.92400000,0.03897711,171.70649780,0.03823668,178.39912104,0.00074643,0.04221292,186.95583562,-0.02298857,-0.01922435,0.00000000,0.00000000,0.00000000,0.00000000
57.62000000,1.20144100,1.93800000,0.04012600,172.95592138,0.03934186,179.89595068,0.00078060,0.04329923,188.28383137,-0.02358279,-0.01971644,0.00000000,0.00000000,0.00000000,0.00000000
59.12000000,1.23571800,1.95100000,0.04127122,174.11610042,0.04044230,181.30208469,0.00074479,0.04437720,189.61295715,-0.02418704,-0.02019015,0.00000000,0.00000000,0.00000000,0.00000000
60.62000000,1.27073400,1.96500000,0.04243500,175.36552400,0.04155932,182.80716001,0.00078598,0.04544685,190.94318904,-0.02475528,-0.02069157,0.00000000,0.00000000,0.00000000,0.00000000
62.12000000,1.30534700,1.97700000,0.04359144,176.43645850,0.04266808,184.12757858,0.00073603,0.04654140,192.18689543,-0.02536991,-0.02117149,0.00000000,0.00000000,0.00000000,0.00000000
63.62000000,1.33989200,1.99000000,0.04472167,177.59663754,0.04375050,185.53905516,0.00070728,0.04764533,193.43495832,-0.02598835,-0.02165698,0.00000000,0.00000000,0.00000000,0.00000000
65.11000000,1.37410200,2.00300000,0.04586689,178.75681658,0.04484610,186.95583562,0.00069216,0.04873601,194.77721955,-0.02661546,-0.02212055,0.00000000,0.00000000,0.00000000,0.00000000
66.61000000,1.40834600,2.01500000,0.04702322,179.82775107,0.04595111,188.28383137,0.00074107,0.04979633,195.92761707,-0.02718903,-0.02260730,0.00000000,0.00000000,0.00000000,0.00000000
68.12000000,1.44282400,2.02700000,0.04817211,180.89868557,0.04704780,189.61295715,0.00069788,0.05089645,197.18256815,-0.02779457,-0.02310189,0.00000000,0.00000000,0.00000000,0.00000000
69.61000000,1.47750400,2.03900000,0.04931356,181.96962007,0.04813619,190.94318904,0.00067548,0.05197054,198.43490752,-0.02839555,-0.02357499,0.00000000,0.00000000,0.00000000,0.00000000
71.11000000,1.51228500,2.05000000,0.05048111,182.95131003,0.04924826,192.18689543,0.00066774,0.05306244,199.59868291,-0.02899891,-0.02406354,0.00000000,0.00000000,0.00000000,0.00000000
72.61000000,1.54689700,2.06100000,0.05165989,183.93299998,0.05036976,193.43495832,0.00071667,0.05416144,200.67148271,-0.02961244,-0.02454900,0.00000000,0.00000000,0.00000000,0.00000000
74.11000000,1.58177900,2.07300000,0.05282744,185.00393448,0.05147935,194.77721955,0.00077379,0.05524594,201.93320445,-0.03018304,-0.02506290,0.00000000,0.00000000,0.00000000,0.00000000
75.61000000,1.61625700,2.08300000,0.05396144,185.89637989,0.05255587,195.92761707,0.00070793,0.05634097,203.10465904,-0.03080398,-0.02553698,0.00000000,0.00000000,0.00000000,0.00000000
77.11000000,1.65103800,2.09400000,0.05514022,186.87806985,0.05367367,197.18256815,0.00074970,0.05745015,204.18630824,-0.03143547,-0.02601469,0.00000000,0.00000000,0.00000000,0.00000000
78.61000000,1.68568400,2.10500000,0.05629278,187.85975981,0.05476540,198.43490752,0.00072741,0.05851826,205.35685735,-0.03202457,-0.02649369,0.00000000,0.00000000,0.00000000,0.00000000
80.11000000,1.72076700,2.11500000,0.05746411,188.75220522,0.05587369,199.59868291,0.00076214,0.05960743,206.43879517,-0.03262677,-0.02698066,0.00000000,0.00000000,0.00000000,0.00000000
81.61000000,1.75534600,2.12400000,0.05864289,189.55540609,0.05698779,200.67148271,0.00076129,0.06071415,207.43114722,-0.03326302,-0.02745113,0.00000000,0.00000000,0.00000000,0.00000000
83.11000000,1.79042800,2.13500000,0.05981044,190.53709605,0.05809007,201.93320445,0.00076758,0.06178556,208.60907205,-0.03385086,-0.02793470,0.00000000,0.00000000,0.00000000,0.00000000
84.61000000,1.82561200,2.14500000,0.06098911,191.42954147,0.05920160,203.10465904,0.00078056,0.06289671,209.60648307,-0.03443823,-0.02845847,0.00000000,0.00000000,0.00000000,0.00000000
86.11000000,1.86093000,2.15400000,0.06218278,192.23274234,0.06032602,204.18630824,0.00079370,0.06399134,210.69810147,-0.03506524,-0.02892611,0.00000000,0.00000000,0.00000000,0.00000000
87.61000000,1.89591200,2.16400000,0.06333544,193.12518775,0.06141061,205.35685735,0.00075082,0.06508265,211.69536956,-0.03564759,-0.02943507,0.00000000,0.00000000,0.00000000,0.00000000
89.11000000,1.93119600,2.17300000,0.06451044,193.92838863,0.06251502,206.43879517,0.00074289,0.06617261,212.69430418,-0.03626523,-0.02990738,0.00000000,0.00000000,0.00000000,0.00000000
90.61000000,1.96631200,2.18100000,0.06570411,194.64234496,0.06363572,207.43114722,0.00079108,0.06728425,213.79587218,-0.03687282,-0.03041143,0.00000000,0.00000000,0.00000000,0.00000000
92.11000000,2.00186500,2.19100000,0.06686422,195.53479037,0.06472371,208.60907205,0.00075542,0.06839254,214.80279665,-0.03750033,-0.03089221,0.00000000,0.00000000,0.00000000,0.00000000
93.61000000,2.03731700,2.19900000,0.06806533,196.24874671,0.06584891,209.60648307,0.00076144,0.06949049,215.71323132,-0.03811062,-0.03137987,0.00000000,0.00000000,0.00000000,0.00000000
95.11000000,2.07313800,2.20800000,0.06925156,197.05194758,0.06695892,210.69810147,0.00075373,0.07062041,216.72873830,-0.03875968,-0.03186073,0.00000000,0.00000000,0.00000000,0.00000000
96.61000000,2.10855700,2.21600000,0.07043411,197.76590391,0.06806428,211.69536956,0.00074605,0.07171785,217.73920069,-0.03935474,-0.03236311,0.00000000,0.00000000,0.00000000,0.00000000
98.11000000,2.14370600,2.22400000,0.07161656,198.47986024,0.06916831,212.69430418,0.00073817,0.07278788,218.64905617,-0.03994143,-0.03284645,0.00000000,0.00000000,0.00000000,0.00000000
99.61000000,2.17949400,2.23300000,0.07282511,199.28306112,0.07029546,213.79587218,0.00077899,0.07390491,219.57098715,-0.04057414,-0.03333077,0.00000000,0.00000000,0.00000000,0.00000000
101.11000000,2.21575200,2.24100000,0.07403000,199.99701745,0.07141793,214.80279665,0.00075721,0.07499320,220.48836975,-0.04114805,-0.03384515,0.00000000,0.00000000,0.00000000,0.00000000
102.61000000,2.25154000,2.24800000,0.07522367,200.62172924,0.07252870,215.71323132,0.00077022,0.07610767,221.41333017,-0.04179004,-0.03431763,0.00000000,0.00000000,0.00000000,0.00000000
104.11000000,2.28709300,2.25600000,0.07645467,201.33568557,0.07367293,216.72873830,0.00079722,0.07723455,222.34286940,-0.04242028,-0.03481427,0.00000000,0.00000000,0.00000000,0.00000000
105.61000000,2.32331700,2.26400000,0.07765200,202.04964190,0.07478460,217.73920069,0.00076848,0.07832928,223.26704559,-0.04301233,-0.03531695,0.00000000,0.00000000,0.00000000,0.00000000
107.11000000,2.35930600,2.27100000,0.07881956,202.67435369,0.07586744,218.64905617,0.00069842,0.07943790,224.09889023,-0.04363268,-0.03580522,0.00000000,0.00000000,0.00000000,0.00000000
108.61000000,2.39522800,2.27800000,0.08003933,203.29906548,0.07699746,219.57098715,0.00069083,0.08054041,225.02829253,-0.04422811,-0.03631230,0.00000000,0.00000000,0.00000000,0.00000000
110.11000000,2.43098200,2.28500000,0.08122933,203.92377727,0.07809867,220.48836975,0.00067630,0.08168057,225.87057180,-0.04488914,-0.03679144,0.00000000,0.00000000,0.00000000,0.00000000
111.61000000,2.46724000,2.29200000,0.08244911,204.54848906,0.07922617,221.41333017,0.00073756,0.08277843,226.70487823,-0.04549224,-0.03728619,0.00000000,0.00000000,0.00000000,0.00000000
113.11000000,2.50393400,2.29900000,0.08368378,205.17320085,0.08036614,222.34286940,0.00073672,0.08391605,227.54984118,-0.04612705,-0.03778901,0.00000000,0.00000000,0.00000000,0.00000000
114.61000000,2.54059500,2.30600000,0.08488489,205.79791264,0.08147389,223.26704559,0.00069451,0.08501482,228.38755015,-0.04673323,-0.03828159,0.00000000,0.00000000,0.00000000,0.00000000
116.11000000,2.57631500,2.31200000,0.08610100,206.33337989,0.08259422,224.09889023,0.00073508,0.08610890,229.22576550,-0.04730418,-0.03880472,0.00000000,0.00000000,0.00000000,0.00000000
117.61000000,2.61304300,2.31900000,0.08731333,206.95809168,0.08370982,225.02829253,0.00074121,0.08724250,230.07468611,-0.04793931,-0.03930320,0.00000000,0.00000000,0.00000000,0.00000000
119.11000000,2.65000600,2.32500000,0.08856667,207.49355893,0.08486185,225.87057180,0.00079509,0.08836605,230.82480066,-0.04856135,-0.03980470,0.00000000,0.00000000,0.00000000,0.00000000
120.62000000,2.68572600,2.33100000,0.08977522,208.02902618,0.08597146,226.70487823,0.00071823,0.08949702,231.67628795,-0.04920063,-0.04029638,0.00000000,0.00000000,0.00000000,0.00000000
122.11000000,2.72262200,2.33700000,0.09102867,208.56449343,0.08712098,227.54984118,0.00080022,0.09059083,232.42241110,-0.04979705,-0.04079378,0.00000000,0.00000000,0.00000000,0.00000000
123.61000000,2.75908100,2.34300000,0.09224100,209.09996068,0.08823155,228.38755015,0.00078570,0.09173750,233.18226821,-0.05041623,-0.04132127,0.00000000,0.00000000,0.00000000,0.00000000
125.11000000,2.79591000,2.34900000,0.09344956,209.63542793,0.08933743,229.22576550,0.00073705,0.09283073,234.02961020,-0.05102755,-0.04180317,0.00000000,0.00000000,0.00000000,0.00000000
126.61000000,2.83260400,2.35500000,0.09470289,210.17089518,0.09048299,230.07468611,0.00078393,0.09394781,234.78548276,-0.05164572,-0.04230210,0.00000000,0.00000000,0.00000000,0.00000000
128.11000000,2.86960000,2.36000000,0.09594511,210.61711788,0.09161711,230.82480066,0.00076275,0.09505338,235.54004458,-0.05223074,-0.04282264,0.00000000,0.00000000,0.00000000,0.00000000
129.61000000,2.90693200,2.36600000,0.09719844,211.15258513,0.09276006,231.67628795,0.00083665,0.09616119,236.29653680,-0.05280682,-0.04335437,0.00000000,0.00000000,0.00000000,0.00000000
131.11000000,2.94376100,2.37100000,0.09841078,211.59880784,0.09386439,232.42241110,0.00079484,0.09731140,237.06451581,-0.05349399,-0.04381742,0.00000000,0.00000000,0.00000000,0.00000000
132.61000000,2.98099200,2.37600000,0.09968278,212.04503055,0.09502175,233.18226821,0.00076683,0.09847835,237.73881516,-0.05415130,-0.04432704,0.00000000,0.00000000,0.00000000,0.00000000
134.11000000,3.01785400,2.38200000,0.10089878,212.58049780,0.09612692,234.02961020,0.00075912,0.09955199,238.49131060,-0.05471146,-0.04484052,0.00000000,0.00000000,0.00000000,0.00000000
135.61000000,3.05461600,2.38700000,0.10214100,213.02672050,0.09725465,234.78548276,0.00075826,0.10072503,239.26902684,-0.05535772,-0.04536731,0.00000000,0.00000000,0.00000000,0.00000000
137.11000000,3.09191400,2.39200000,0.10337189,213.47294321,0.09837084,235.54004458,0.00077966,0.10181761,239.92939710,-0.05596357,-0.04585404,0.00000000,0.00000000,0.00000000,0.00000000
138.61000000,3.12938100,2.39700000,0.10460667,213.91916592,0.09948931,236.29653680,0.00070264,0.10295587,240.60196205,-0.05657471,-0.04638116,0.00000000,0.00000000,0.00000000,0.00000000
140.11000000,3.16738400,2.40200000,0.10588989,214.36538863,0.10065034,237.06451581,0.00078283,0.10409946,241.27705095,-0.05719045,-0.04690901,0.00000000,0.00000000,0.00000000,0.00000000
141.61000000,3.20501800,2.40600000,0.10719167,214.72236679,0.10182678,237.73881516,0.00086263,0.10525362,242.05577615,-0.05784600,-0.04740762,0.00000000,0.00000000,0.00000000,0.00000000
143.11000000,3.24167900,2.41100000,0.10839278,215.16858950,0.10291102,238.49131060,0.00074717,0.10639779,242.73361469,-0.05848723,-0.04791056,0.00000000,0.00000000,0.00000000,0.00000000
144.61000000,3.28075700,2.41600000,0.10970589,215.61481221,0.10409502,239.26902684,0.00087430,0.10751069,243.40506206,-0.05902684,-0.04848385,0.00000000,0.00000000,0.00000000,0.00000000
146.11000000,3.31735000,2.42000000,0.11092933,215.97179037,0.10519690,239.92939710,0.00076567,0.10871209,244.09939426,-0.05980414,-0.04890795,0.00000000,0.00000000,0.00000000,0.00000000
147.61000000,3.35568900,2.42400000,0.11220511,216.32876854,0.10634463,240.60196205,0.00065746,0.10981909,244.77186587,-0.06039875,-0.04942034,0.00000000,0.00000000,0.00000000,0.00000000
149.11000000,3.39416300,2.42800000,0.11348833,216.68574670,0.10749773,241.27705095,0.00075054,0.11100573,245.36474340,-0.06104934,-0.04995639,0.00000000,0.00000000,0.00000000,0.00000000
150.61000000,3.43253600,2.43300000,0.11478644,217.13196941,0.10866286,242.05577615,0.00074966,0.11214978,246.04871007,-0.06169666,-0.05045313,0.00000000,0.00000000,0.00000000,0.00000000
152.11000000,3.47060600,2.43700000,0.11607333,217.48894758,0.10981657,242.73361469,0.00070876,0.11327938,246.73035651,-0.06229906,-0.05098032,0.00000000,0.00000000,0.00000000,0.00000000
153.61000000,3.50834100,2.44100000,0.11732667,217.84592574,0.11093893,243.40506206,0.00072110,0.11444530,247.32149316,-0.06295759,-0.05148772,0.00000000,0.00000000,0.00000000,0.00000000
155.11000000,3.54839300,2.44500000,0.11868078,218.20290391,0.11215011,244.09939426,0.00092054,0.11555239,247.99992559,-0.06352426,-0.05202813,0.00000000,0.00000000,0.00000000,0.00000000
156.61000000,3.58626200,2.44900000,0.11993044,218.55988207,0.11326658,244.77186587,0.00075972,0.11677167,248.60656255,-0.06425455,-0.05251712,0.00000000,0.00000000,0.00000000,0.00000000
158.11000000,3.62513800,2.45200000,0.12126956,218.82761570,0.11446158,245.36474340,0.00082523,0.11785449,249.18019770,-0.06481397,-0.05304052,0.00000000,0.00000000,0.00000000,0.00000000
159.61000000,3.66361200,2.45600000,0.12256389,219.18459386,0.11561526,246.04871007,0.00089062,0.11898397,249.86771688,-0.06541373,-0.05357024,0.00000000,0.00000000,0.00000000,0.00000000
161.11000000,3.70289100,2.46000000,0.12384344,219.54157203,0.11675446,246.73035651,0.00089653,0.12018919,250.47417435,-0.06605863,-0.05413056,0.00000000,0.00000000,0.00000000,0.00000000
162.61000000,3.74166700,2.46300000,0.12516389,219.80930566,0.11792870,247.32149316,0.00076922,0.12134691,251.06977012,-0.06674036,-0.05460655,0.00000000,0.00000000,0.00000000,0.00000000
164.11000000,3.78000600,2.46700000,0.12642100,220.16628382,0.11904535,247.99992559,0.00075514,0.12252951,251.67270416,-0.06740941,-0.05512010,0.00000000,0.00000000,0.00000000,0.00000000
165.61000000,3.81931900,2.47000000,0.12780489,220.43401745,0.12027317,248.60656255,0.00090639,0.12371400,252.27720042,-0.06804998,-0.05566403,0.00000000,0.00000000,0.00000000,0.00000000
167.11000000,3.85799400,2.47300000,0.12903589,220.70175107,0.12136407,249.18019770,0.00062128,0.12488723,252.87992596,-0.06869485,-0.05619237,0.00000000,0.00000000,0.00000000,0.00000000
168.61000000,3.89623200,2.47700000,0.13032278,221.05872924,0.12250324,249.86771688,0.00074585,0.12610145,253.49415747,-0.06939263,-0.05670882,0.00000000,0.00000000,0.00000000,0.00000000
170.11000000,3.93682100,2.48000000,0.13169556,221.32646286,0.12371700,250.47417435,0.00070565,0.12725372,253.99163658,-0.07001469,-0.05723904,0.00000000,0.00000000,0.00000000,0.00000000
171.61000000,3.97660400,2.48300000,0.13301600,221.59419648,0.12488310,251.06977012,0.00077704,0.12845202,254.60389312,-0.07066993,-0.05778209,0.00000000,0.00000000,0.00000000,0.00000000
173.11000000,4.01615200,2.48600000,0.13436633,221.86193011,0.12607420,251.67270416,0.00076298,0.12966832,255.22187549,-0.07134610,-0.05832222,0.00000000,0.00000000,0.00000000,0.00000000
174.61000000,4.05680700,2.48900000,0.13572044,222.12966373,0.12726720,252.27720042,0.00085427,0.13082147,255.82477764,-0.07196275,-0.05885872,0.00000000,0.00000000,0.00000000,0.00000000
176.11000000,4.09565000,2.49200000,0.13706333,222.39739736,0.12844892,252.87992596,0.00086636,0.13199731,256.33200692,-0.07258579,-0.05941153,0.00000000,0.00000000,0.00000000,0.00000000
177.61000000,4.13637300,2.49500000,0.13845467,222.66513098,0.12967179,253.49415747,0.00085866,0.13313623,256.83056029,-0.07322647,-0.05990976,0.00000000,0.00000000,0.00000000,0.00000000
179.11000000,4.17699500,2.49700000,0.13977522,222.84362007,0.13083107,253.99163658,0.00079876,0.13429494,257.43785359,-0.07384383,-0.06045111,0.00000000,0.00000000,0.00000000,0.00000000
180.61000000,4.21744900,2.50000000,0.14115167,223.11135369,0.13203799,254.60389312,0.00081747,0.13546674,257.94666874,-0.07448499,-0.06098174,0.00000000,0.00000000,0.00000000,0.00000000
182.11000000,4.25783600,2.50300000,0.14255044,223.37908731,0.13326300,255.22187549,0.00083593,0.13659365,258.54774012,-0.07508780,-0.06150585,0.00000000,0.00000000,0.00000000,0.00000000
183.61000000,4.29822300,2.50600000,0.14387844,223.64682094,0.13442463,255.82477764,0.00087422,0.13778846,259.06433113,-0.07578329,-0.06200517,0.00000000,0.00000000,0.00000000,0.00000000
185.11000000,4.33877800,2.50800000,0.14523244,223.82531002,0.13560762,256.33200692,0.00078835,0.13893028,259.56798671,-0.07640842,-0.06252186,0.00000000,0.00000000,0.00000000,0.00000000
186.61000000,4.37926600,2.51000000,0.14654556,224.00379910,0.13675356,256.83056029,0.00069632,0.14011909,260.08472918,-0.07709017,-0.06302892,0.00000000,0.00000000,0.00000000,0.00000000
188.11000000,4.41925000,2.51300000,0.14788467,224.27153273,0.13792083,257.43785359,0.00079950,0.14127429,260.59354825,-0.07768229,-0.06359200,0.00000000,0.00000000,0.00000000,0.00000000
189.61000000,4.45983900,2.51500000,0.14923878,224.45002181,0.13909979,257.94666874,0.00076626,0.14250198,261.12219904,-0.07837775,-0.06412423,0.00000000,0.00000000,0.00000000,0.00000000
191.11000000,4.49968900,2.51800000,0.15054433,224.71775544,0.14023516,258.54774012,0.00073930,0.14368324,261.63956865,-0.07901410,-0.06466913,0.00000000,0.00000000,0.00000000,0.00000000
192.61000000,4.54041200,2.52000000,0.15192822,224.89624452,0.14143725,259.06433113,0.00075791,0.14495916,262.18271283,-0.07972095,-0.06523821,0.00000000,0.00000000,0.00000000,0.00000000
194.11000000,4.58046300,2.52200000,0.15325244,225.07473360,0.14258616,259.56798671,0.00077631,0.14623343,262.72638832,-0.08043996,-0.06579347,0.00000000,0.00000000,0.00000000,0.00000000
195.61000000,4.62138700,2.52400000,0.15463267,225.25322269,0.14378226,260.08472918,0.00082082,0.14751890,263.27398997,-0.08115347,-0.06636543,0.00000000,0.00000000,0.00000000,0.00000000
197.11000000,4.66200900,2.52600000,0.15597556,225.43171177,0.14494462,260.59354825,0.00078121,0.14880406,263.71815429,-0.08183588,-0.06696817,0.00000000,0.00000000,0.00000000,0.00000000
198.61000000,4.70350400,2.52800000,0.15740422,225.61020085,0.14617976,261.12219904,0.00085113,0.15014037,264.28107107,-0.08259011,-0.06755026,0.00000000,0.00000000,0.00000000,0.00000000
200.11000000,4.74536900,2.53000000,0.15878067,225.78868993,0.14736830,261.63956865,0.00077280,0.15150662,264.85298805,-0.08331264,-0.06819398,0.00000000,0.00000000,0.00000000,0.00000000
201.61000000,4.78760200,2.53200000,0.16026900,225.96717902,0.14865187,262.18271283,0.00090038,0.15284065,265.31263325,-0.08409901,-0.06874164,0.00000000,0.00000000,0.00000000,0.00000000
203.11000000,4.83060800,2.53400000,0.16175733,226.14566810,0.14993380,262.72638832,0.00078364,0.15410788,265.86011734,-0.08476218,-0.06934571,0.00000000,0.00000000,0.00000000,0.00000000
204.61000000,4.87438600,2.53600000,0.16326067,226.32415718,0.15122698,263.27398997,0.00091736,0.15531023,266.39121902,-0.08537838,-0.06993185,0.00000000,0.00000000,0.00000000,0.00000000
206.11000000,4.91722400,2.53700000,0.16476389,226.41340172,0.15251840,263.71815429,0.00083277,0.15657585,266.83501587,-0.08606870,-0.07050716,0.00000000,0.00000000,0.00000000,0.00000000
207.61000000,4.96086700,2.53900000,0.16633067,226.59189081,0.15386264,264.28107107,0.00089589,0.15774345,267.35849840,-0.08672719,-0.07101626,0.00000000,0.00000000,0.00000000,0.00000000
209.11000000,5.00565200,2.54100000,0.16793467,226.77037989,0.15523695,264.85298805,0.00089466,0.15887963,267.76899204,-0.08735503,-0.07152460,0.00000000,0.00000000,0.00000000,0.00000000
210.61000000,5.05033700,2.54200000,0.16950133,226.85962443,0.15657745,265.31263325,0.00095714,0.16001301,268.28485266,-0.08797397,-0.07203904,0.00000000,0.00000000,0.00000000,0.00000000
212.11000000,5.09535700,2.54400000,0.17099333,227.03811351,0.15785239,265.86011734,0.00095573,0.16114658,268.69594552,-0.08864042,-0.07250616,0.00000000,0.00000000,0.00000000,0.00000000
213.61000000,5.13849700,2.54600000,0.17241089,227.21660260,0.15906222,266.39121902,0.00070010,0.16215293,269.07326577,-0.08915199,-0.07300093,0.00000000,0.00000000,0.00000000,0.00000000
215.11000000,5.18301300,2.54700000,0.17390300,227.30584714,0.16033409,266.83501587,0.00076284,0.16331550,269.49333744,-0.08982729,-0.07348821,0.00000000,0.00000000,0.00000000,0.00000000
216.61000000,5.22554900,2.54900000,0.17528311,227.48433622,0.16150906,267.35849840,0.00076176,0.16441237,270.00221668,-0.09046460,-0.07394777,0.00000000,0.00000000,0.00000000,0.00000000
218.11000000,5.26801800,2.55000000,0.17662600,227.57358076,0.16265102,267.76899204,0.00076089,0.16547958,270.29162282,-0.09106647,-0.07441311,0.00000000,0.00000000,0.00000000,0.00000000
219.61000000,5.30833800,2.55200000,0.17796889,227.75206985,0.16379167,268.28485266,0.00082343,0.16654425,270.68687405,-0.09169029,-0.07485396,0.00000000,0.00000000,0.00000000,0.00000000
221.11000000,5.35040300,2.55300000,0.17931178,227.84131439,0.16493103,268.69594552,0.00082249,0.16754660,270.95937328,-0.09223496,-0.07531165,0.00000000,0.00000000,0.00000000,0.00000000
222.61000000,5.38877600,2.55400000,0.18050544,227.93055893,0.16594269,269.07326577,0.00069530,0.16851365,271.43540868,-0.09279857,-0.07571508,0.00000000,0.00000000,0.00000000,0.00000000
224.11000000,5.43027100,2.55500000,0.18188567,228.01980347,0.16711119,269.49333744,0.00075769,0.16945007,271.79721688,-0.09331837,-0.07613169,0.00000000,0.00000000,0.00000000,0.00000000
225.61000000,5.47082600,2.55700000,0.18319122,228.19829255,0.16821521,270.00221668,0.00069372,0.17047922,272.18480761,-0.09391249,-0.07656674,0.00000000,0.00000000,0.00000000,0.00000000
227.11000000,5.51275700,2.55700000,0.18445944,228.19829255,0.16928651,270.29162282,0.00075586,0.17156813,272.69602714,-0.09455628,-0.07701185,0.00000000,0.00000000,0.00000000,0.00000000
228.61000000,5.55586400,2.55800000,0.18572778,228.28753710,0.17035674,270.68687405,0.00075523,0.17290650,273.16955809,-0.09536861,-0.07753788,0.00000000,0.00000000,0.00000000,0.00000000
230.11000000,5.60007800,2.55800000,0.18692144,228.28753710,0.17136293,270.95937328,0.00062862,0.17449181,273.71171956,-0.09633928,-0.07815253,0.00000000,0.00000000,0.00000000,0.00000000
231.61000000,5.64516500,2.56000000,0.18807778,228.46602618,0.17233669,271.43540868,0.00056514,0.17651054,274.26697185,-0.09752876,-0.07898178,0.00000000,0.00000000,0.00000000,0.00000000
233.11000000,5.69082300,2.56100000,0.18919689,228.55527072,0.17327820,271.79721688,0.00062741,0.17889659,274.92471503,-0.09871330,-0.08018329,0.00000000,0.00000000,0.00000000,0.00000000
234.61000000,5.73658200,2.56200000,0.19042789,228.64451526,0.17431281,272.18480761,0.00068951,0.18164741,275.68497454,-0.09981523,-0.08183218,0.00000000,0.00000000,0.00000000,0.00000000
236.11000000,5.78237400,2.56400000,0.19173344,228.82300434,0.17540892,272.69602714,0.00068875,0.18460453,276.61278611,-0.10092158,-0.08368295,0.00000000,0.00000000,0.00000000,0.00000000
237.61000000,5.82762900,2.56500000,0.19333744,228.91224889,0.17675396,273.16955809,0.00093802,0.18779991,277.50155635,-0.10230291,-0.08549700,0.00000000,0.00000000,0.00000000,0.00000000
239.11000000,5.87362300,2.56600000,0.19523989,229.00149343,0.17834691,273.71171956,0.00112385,0.19095434,278.38174842,-0.10407690,-0.08687744,0.00000000,0.00000000,0.00000000,0.00000000
240.61000000,5.92085900,2.56600000,0.19766456,229.00149343,0.18037346,274.26697185,0.00143330,0.19367187,279.14227876,-0.10605611,-0.08761576,0.00000000,0.00000000,0.00000000,0.00000000
242.11000000,5.96822900,2.56600000,0.20053678,229.00149343,0.18276877,274.92471503,0.00167847,0.19549824,279.76395164,-0.10737967,-0.08811857,0.00000000,0.00000000,0.00000000,0.00000000
243.61000000,6.01788200,2.56600000,0.20385667,229.00149343,0.18553029,275.68497454,0.00192197,0.19659338,280.07171489,-0.10809683,-0.08849655,0.00000000,0.00000000,0.00000000,0.00000000
245.11000000,6.06803800,2.56700000,0.20743767,229.09073797,0.18850048,276.61278611,0.00191627,0.19738205,280.40314276,-0.10859333,-0.08878871,0.00000000,0.00000000,0.00000000,0.00000000
246.61000000,6.11980600,2.56700000,0.21131722,229.09073797,0.19170838,277.50155635,0.00209524,0.19802134,280.47351833,-0.10899230,-0.08902903,0.00000000,0.00000000,0.00000000,0.00000000
248.11000000,6.17248100,2.56700000,0.21515933,229.09073797,0.19487521,278.38174842,0.00208842,0.19853730,280.61884390,-0.10930886,-0.08922844,0.00000000,0.00000000,0.00000000,0.00000000
249.61000000,6.22592800,2.56700000,0.21847911,229.09073797,0.19760345,279.14227876,0.00153127,0.19899083,280.85640802,-0.10960025,-0.08939059,0.00000000,0.00000000,0.00000000,0.00000000
251.11000000,6.28011300,2.56800000,0.22071722,229.17998251,0.19943857,279.76395164,0.00103919,0.19935630,280.84967907,-0.10981056,-0.08954575,0.00000000,0.00000000,0.00000000,0.00000000
252.61000000,6.33470100,2.56800000,0.22206011,229.17998251,0.20053805,280.07171489,0.00067166,0.19968822,281.05312102,-0.11002101,-0.08966722,0.00000000,0.00000000,0.00000000,0.00000000
254.11000000,6.38959100,2.56900000,0.22303000,229.26922705,0.20133139,280.40314276,0.00048810,0.19993069,281.12154515,-0.11015754,-0.08977314,0.00000000,0.00000000,0.00000000,0.00000000
255.61000000,6.44585800,2.56800000,0.22381333,229.17998251,0.20197167,280.47351833,0.00036574,0.20017300,281.18994380,-0.11027761,-0.08989539,0.00000000,0.00000000,0.00000000,0.00000000
257.11000000,6.50118400,2.56800000,0.22444744,229.17998251,0.20248968,280.61884390,0.00030456,0.20044411,281.37641230,-0.11046791,-0.08997620,0.00000000,0.00000000,0.00000000,0.00000000
258.61000000,6.55812200,2.56900000,0.22500700,229.26922705,0.20294656,280.85640802,0.00024364,0.20059248,281.63820366,-0.11051548,-0.09007700,0.00000000,0.00000000,0.00000000,0.00000000
260.11000000,6.61452300,2.56800000,0.22545467,229.17998251,0.20331193,280.84967907,0.00030449,0.20080134,281.91718819,-0.11064370,-0.09015764,0.00000000,0.00000000,0.00000000,0.00000000
261.61000000,6.67048800,2.56900000,0.22586500,229.26922705,0.20364672,281.05312102,0.00024347,0.20103880,282.31437465,-0.11078913,-0.09024967,0.00000000,0.00000000,0.00000000,0.00000000
263.11000000,6.72151700,2.56900000,0.22616344,229.26922705,0.20389014,281.12154515,0.00018269,0.00000000,0.00000000,0.00000000,0.00000000,0.00000000,0.00000000,0.00000000,0.00000000
264.61000000,6.75545900,2.56900000,0.22646178,229.26922705,0.20413342,281.18994380,0.00012158,0.00000000,0.00000000,0.00000000,0.00000000,0.00000000,0.00000000,0.00000000,0.00000000
266.11000000,6.77503100,2.57000000,0.22679756,229.35847159,0.20440716,281.37641230,0.00018242,0.00000000,0.00000000,0.00000000,0.00000000,0.00000000,0.00000000,0.00000000,0.00000000
267.61000000,6.78856100,2.57200000,0.22698411,229.53696068,0.20455922,281.63820366,0.00012171,0.00000000,0.00000000,0.00000000,0.00000000,0.00000000,0.00000000,0.00000000,0.00000000
269.11000000,6.80209000,2.57400000,0.22724522,229.71544976,0.20477200,281.91718819,0.00006084,0.00000000,0.00000000,0.00000000,0.00000000,0.00000000,0.00000000,0.00000000,0.00000000
270.61000000,6.81776800,2.57700000,0.22754356,229.98318338,0.20501506,282.31437465,0.00018231,0.00000000,0.00000000,0.00000000,0.00000000,0.00000000,0.00000000,0.00000000,0.00000000
272.11000000,6.83992600,2.57800000,0.22776744,230.07242792,0.00000000,0.00000000,0.00000000,0.00000000,0.00000000,0.00000000,0.00000000,0.00000000,0.00000000,0.00000000,0.00000000
273.61000000,6.87876900,2.57000000,0.22799122,229.35847159,0.00000000,0.00000000,0.00000000,0.00000000,0.00000000,0.00000000,0.00000000,0.00000000,0.00000000,0.00000000,0.00000000
275.11000000,6.92466100,2.56900000,0.22817778,229.26922705,0.00000000,0.00000000,0.00000000,0.00000000,0.00000000,0.00000000,0.00000000,0.00000000,0.00000000,0.00000000,0.00000000
276.61000000,6.97367700,2.56700000,0.22836422,229.09073797,0.00000000,0.00000000,0.00000000,0.00000000,0.00000000,0.00000000,0.00000000,0.00000000,0.00000000,0.00000000,0.00000000
278.11000000,7.02564600,2.56500000,0.22851344,228.91224889,0.00000000,0.00000000,0.00000000,0.00000000,0.00000000,0.00000000,0.00000000,0.00000000,0.00000000,0.00000000,0.00000000
279.61000000,7.07808500,2.56400000,0.22862533,228.82300434,0.00000000,0.00000000,0.00000000,0.00000000,0.00000000,0.00000000,0.00000000,0.00000000,0.00000000,0.00000000,0.00000000
281.11000000,7.13180100,2.56200000,0.22877456,228.64451526,0.00000000,0.00000000,0.00000000,0.00000000,0.00000000,0.00000000,0.00000000,0.00000000,0.00000000,0.00000000,0.00000000
282.61000000,7.18665700,2.55900000,0.22884911,228.37678164,0.00000000,0.00000000,0.00000000,0.00000000,0.00000000,0.00000000,0.00000000,0.00000000,0.00000000,0.00000000,0.00000000
284.11000000,7.24326000,2.55200000,0.22888644,227.75206985,0.00000000,0.00000000,0.00000000,0.00000000,0.00000000,0.00000000,0.00000000,0.00000000,0.00000000,0.00000000,0.00000000
285.61000000,7.30076900,2.54800000,0.22903567,227.39509168,0.00000000,0.00000000,0.00000000,0.00000000,0.00000000,0.00000000,0.00000000,0.00000000,0.00000000,0.00000000,0.00000000
287.11000000,7.35727000,2.54200000,0.22899833,226.85962443,0.00000000,0.00000000,0.00000000,0.00000000,0.00000000,0.00000000,0.00000000,0.00000000,0.00000000,0.00000000,0.00000000
288.61000000,7.41652500,2.53400000,0.22911022,226.14566810,0.00000000,0.00000000,0.00000000,0.00000000,0.00000000,0.00000000,0.00000000,0.00000000,0.00000000,0.00000000,0.00000000
290.11000000,7.47561200,2.52300000,0.22907300,225.16397814,0.00000000,0.00000000,0.00000000,0.00000000,0.00000000,0.00000000,0.00000000,0.00000000,0.00000000,0.00000000,0.00000000
291.61000000,7.53617600,2.50800000,0.22907300,223.82531002,0.00000000,0.00000000,0.00000000,0.00000000,0.00000000,0.00000000,0.00000000,0.00000000,0.00000000,0.00000000,0.00000000
293.11000000,7.59764700,2.48600000,0.22907300,221.86193011,0.00000000,0.00000000,0.00000000,0.00000000,0.00000000,0.00000000,0.00000000,0.00000000,0.00000000,0.00000000,0.00000000
294.61000000,7.66049500,2.45700000,0.22899833,219.27383841,0.00000000,0.00000000,0.00000000,0.00000000,0.00000000,0.00000000,0.00000000,0.00000000,0.00000000,0.00000000,0.00000000
296.11000000,7.72589700,2.41700000,0.22892389,215.70405675,0.00000000,0.00000000,0.00000000,0.00000000,0.00000000,0.00000000,0.00000000,0.00000000,0.00000000,0.00000000,0.00000000
297.61000000,7.79284700,2.35600000,0.22877500,210.26013972,0.00000000,0.00000000,0.00000000,0.00000000,0.00000000,0.00000000,0.00000000,0.00000000,0.00000000,0.00000000,0.00000000
299.11000000,7.86520900,2.27400000,0.22862656,202.94208732,0.00000000,0.00000000,0.00000000,0.00000000,0.00000000,0.00000000,0.00000000,0.00000000,0.00000000,0.00000000,0.00000000
300.61000000,8.19510200,1.17500000,0.22373889,104.86233623,0.00000000,0.00000000,0.00000000,0.00000000,0.00000000,0.00000000,0.00000000,0.00000000,0.00000000,0.00000000,0.00000000
NaN,-100.00000000,NaN,-11.11111111,NaN,0.00000000,0.00000000,0.00000000,0.00000000,0.00000000,0.00000000,0.00000000,0.00000000,0.00000000,0.00000000,0.00000000